Workbook

Sheet About
A1: CECRCbI Cost Effective CCS Retrofit Capacity by Industry
A3: Source: | B3: Industry-specific CCS cost curves | D3: "Other" CCS Costs
B4: NREL | D4: indst/CC
B5: Carbon Capture Retrofit Database
B6: https://netl.doe.gov/node/12070
B7: 2022
B9: Iron & Steel Plant Data | D9: BAU Process Emissions
B10: Global Energy Monitor | D10: indst/BPE
B11: Global Iron & Steel Tracker
B12: https://globalenergymonitor.org/projects/global-iron-and-steel-tracker/
B13: 2025
B15: Refining CCS Cost Curves
B16: International Journal of Greenhouse Gas Control
B17: Quantifying carbon capture potential and cost of carbon capture technology application in the U.S. refining industry
B18: https://escholarship.org/content/qt3jt6n671/qt3jt6n671.pdf
B19: 2018
A21: Notes:

Sheet cpi
A1: Historical Consumer Price Index for All Urban Consumers (CPI-U): U.S. city average, all items, index
A2: averages — Continued
A3: [1982-84=100, unless otherwise noted]
A4: Year | B4: Semiannual averages | D4: Annual avg. | E4: Percent change from previous | G4: Multiply by to get 2012 Dollars
B5: 1st half | C5: 2nd half | E5: Dec. | F5: Annual avg.
A6: 1968............................................................................. . | B6: – | C6: – | D6: 34.8 | E6: 4.7 | F6: 4.2
A7: 1969............................................................................. . | B7: – | C7: – | D7: 36.7 | E7: 6.2 | F7: 5.5
A8: 1970............................................................................. . | B8: – | C8: – | D8: 38.8 | E8: 5.6 | F8: 5.7
A9: 1971............................................................................. . | B9: – | C9: – | D9: 40.5 | E9: 3.3 | F9: 4.4
A10: 1972............................................................................. . | B10: – | C10: – | D10: 41.8 | E10: 3.4 | F10: 3.2
A11: 1973............................................................................. . | B11: – | C11: – | D11: 44.4 | E11: 8.7 | F11: 6.2
A12: 1974............................................................................. . | B12: – | C12: – | D12: 49.3 | E12: 12.3 | F12: 11
A13: 1975............................................................................. . | B13: – | C13: – | D13: 53.8 | E13: 6.9 | F13: 9.1
A14: 1976............................................................................. . | B14: – | C14: – | D14: 56.9 | E14: 4.9 | F14: 5.8
A15: 1977............................................................................. . | B15: – | C15: – | D15: 60.6 | E15: 6.7 | F15: 6.5
A16: 1978............................................................................. . | B16: – | C16: – | D16: 65.2 | E16: 9 | F16: 7.6
A17: 1979............................................................................. . | B17: – | C17: – | D17: 72.6 | E17: 13.3 | F17: 11.3
... A21: 1983............................................................................. . | B21: – | C21: – | D21: 99.6 | E21: 3.8 | F21: 3.2
A22: 1984............................................................................. . | B22: 102.9 | C22: 104.9 | D22: 103.9 | E22: 3.9 | F22: 4.3
A23: 1985............................................................................. . | B23: 106.6 | C23: 108.5 | D23: 107.6 | E23: 3.8 | F23: 3.6
A24: 1986............................................................................. . | B24: 109.1 | C24: 110.1 | D24: 109.6 | E24: 1.1 | F24: 1.9
A25: 1987............................................................................. . | B25: 112.4 | C25: 114.9 | D25: 113.6 | E25: 4.4 | F25: 3.6
A26: 1988............................................................................. . | B26: 116.8 | C26: 119.7 | D26: 118.3 | E26: 4.4 | F26: 4.1
A27: 1989............................................................................. . | B27: 122.7 | C27: 125.3 | D27: 124 | E27: 4.6 | F27: 4.8
A28: 1990............................................................................. . | B28: 128.7 | C28: 132.6 | D28: 130.7 | E28: 6.1 | F28: 5.4 | G28: 1.7566488
A29: 1991............................................................................. . | B29: 135.2 | C29: 137.2 | D29: 136.2 | E29: 3.1 | F29: 4.2 | G29: 1.6857122
A30: 1992............................................................................. . | B30: 139.2 | C30: 141.4 | D30: 140.3 | E30: 2.9 | F30: 3 | G30: 1.6364505
A31: 1993............................................................................. . | B31: 143.7 | C31: 145.3 | D31: 144.5 | E31: 2.7 | F31: 3 | G31: 1.5888858
A32: 1994............................................................................. . | B32: 147.2 | C32: 149.3 | D32: 148.2 | E32: 2.7 | F32: 2.6 | G32: 1.5492173
A33: 1995............................................................................. . | B33: 151.5 | C33: 153.2 | D33: 152.4 | E33: 2.5 | F33: 2.8 | G33: 1.5065223
A34: 1996............................................................................. . | B34: 155.8 | C34: 157.9 | D34: 156.9 | E34: 3.3 | F34: 3 | G34: 1.4633142
A35: 1997............................................................................. . | B35: 159.9 | C35: 161.2 | D35: 160.5 | E35: 1.7 | F35: 2.3 | G35: 1.4304922
A36: 1998............................................................................. . | B36: 162.3 | C36: 163.7 | D36: 163 | E36: 1.6 | F36: 1.6 | G36: 1.4085521
A37: 1999............................................................................. . | B37: 165.4 | C37: 167.8 | D37: 166.6 | E37: 2.7 | F37: 2.2 | G37: 1.3781152
A38: 2000............................................................................. . | B38: 170.8 | C38: 173.6 | D38: 172.2 | E38: 3.4 | F38: 3.4 | G38: 1.3332985
A39: 2001............................................................................. . | B39: 176.6 | C39: 177.5 | D39: 177.1 | E39: 1.6 | F39: 2.8 | G39: 1.2964088
... A60: 2022............................................................................. . | B60: 288.347 | C60: 296.963 | D60: 292.655 | E60: 6.5 | F60: 8 | G60: 0.78452102
A61: 2023............................................................................. . | B61: 302.408 | C61: 306.996 | D61: 304.702 | G61: 0.75350342
A62: 2024............................................................................. . | B62: 312.145 | C62: 315.233 | D62: 313.689 | G62: 0.73191601

Sheet Retrofit Cost vs SOC Data
A1: *all costs in 2018 USD
B2: DO NOT FILTER OR SORT DATA HERE. IF NEEDED, USE "RESULTS" TABS TO FILTER AND/OR SORT DATA
B3: Ammonia | D3: Cement | F3: Ethanol | H3: Hydrogen | J3: Natural Gas with AGR
B4: Pre-retrofit total CO₂ emissions*, x1,000 TPY
B5: 37964.113 | C5: 1309.1073 | D5: 74664.849 | E5: 829.60944 | F5: 71351.376 | G5: 435.64292 | H5: 42242.863 | I5: 422.42863 | J5: 16316.935 | K5: 53.149625
B6: Cost of CO2 Avoided | C6: Cost of CO2 Captured | D6: Cost of CO2 Avoided | E6: Cost of CO2 Captured | F6: Cost of CO2 Avoided | G6: Cost of CO2 Captured | H6: Cost of CO2 Avoided | I6: Cost of CO2 Captured | J6: Cost of CO2 Avoided | K6: Cost of CO2 Captured
A7: T&S = $0/tonne | B7: 71.738249 | C7: 58.067922 | D7: 101.94958 | E7: 75.547457 | F7: 83.430431 | G7: 68.436788 | H7: 97.106488 | I7: 76.045227 | J7: 99.328025 | K7: 89.328025
A8: T&S = 10$/tonne | B8: 60.158203 | C8: 56.803171 | D8: 90.032265 | E8: 75.547457 | F8: 72.834266 | G8: 68.436788 | H8: 85.820971 | I8: 76.045227 | J8: 89.328025 | K8: 89.328025
A9: t&s cost assumption | B9: =B7-B8 -> 11.580046 | D9: =D7-D8 -> 11.917312 | F9: =F7-F8 -> 10.596165 | H9: =H7-H8 -> 11.285517 | J9: =J7-J8 -> 10
B10: Cost of CO₂ Avoided vs Cumulative Portion of Capacity | D10: Cost of CO₂ Avoided vs Cumulative Portion of Capacity | F10: Cost of CO₂ Avoided vs Cumulative Portion of Capacity | H10: Cost of CO₂ Avoided vs Cumulative Portion of Capacity | J10: Cost of CO₂ Avoided vs Cumulative Portion of Capacity
B11: Cost of CO₂ Avoided [$/tonne] | C11: Cumulative Portion of Capacity | D11: Cost of CO₂ Avoided [$/tonne] | E11: Cumulative Portion of Capacity | F11: Cost of CO₂ Avoided [$/tonne] | G11: Cumulative Portion of Capacity | H11: Cost of CO₂ Avoided [$/tonne] | I11: Cumulative Portion of Capacity | J11: Cost of CO₂ Avoided [$/tonne] | K11: Cumulative Portion of Capacity
B12: 33.410889 | C12: 0.27371651 | D12: 71.85449 | E12: 0.044531576 | F12: 39.733659 | G12: 0.0048640916 | H12: 54.99567 | I12: 0.047399647 | J12: 24.063621 | K12: 0.10295942
B13: 61.299601 | C13: 0.32345627 | D13: 78.02083 | E13: 0.072631908 | F13: 39.889084 | G13: 0.01037196 | H13: 56.512987 | I13: 0.077965842 | J13: 27.729504 | K13: 0.1436564
B14: 69.104743 | C14: 0.71271808 | D14: 79.271548 | E14: 0.094124553 | F14: 41.017282 | G14: 0.014449213 | H14: 57.342162 | I14: 0.11943986 | J14: 28.678436 | K14: 0.18050857
B15: 70.784247 | C15: 0.96831526 | D15: 80.819322 | E15: 0.11373608 | F15: 43.067224 | G15: 0.018383405 | H15: 57.441461 | I15: 0.14770529 | J15: 29.017078 | K15: 0.21496589
B16: 124.09176 | C16: 1 | D16: 80.952471 | E16: 0.13063396 | F16: 46.934473 | G16: 0.020886981 | H16: 57.449046 | I16: 0.19933207 | J16: 29.528675 | K16: 0.24996464
B17: #N/A | C17: #N/A | D17: 81.324551 | E17: 0.15662362 | F17: 47.102372 | G17: 0.026108727 | H17: 58.337848 | I17: 0.22559651 | J17: 30.250603 | K17: 0.28027082
B18: #N/A | C18: #N/A | D18: 81.862063 | E18: 0.17509357 | F18: 49.755709 | G18: 0.032403433 | H18: 58.349382 | I18: 0.25183649 | J18: 32.555733 | K18: 0.29899746
B19: #N/A | C19: #N/A | D19: 82.036775 | E19: 0.18834775 | F19: 50.218753 | G19: 0.034191702 | H19: 59.386041 | I19: 0.27600034 | J19: 32.656926 | K19: 0.31742775
B20: #N/A | C20: #N/A | D20: 82.506585 | E20: 0.20789705 | F20: 50.758939 | G20: 0.036194564 | H20: 59.873929 | I20: 0.29926495 | J20: 33.626154 | K20: 0.33147144
B21: #N/A | C21: #N/A | D21: 82.675298 | E21: 0.22506503 | F21: 53.918216 | G21: 0.037625179 | H21: 59.940422 | I21: 0.32857177 | J21: 33.838478 | K21: 0.34508341
B22: #N/A | C22: #N/A | D22: 83.454874 | E22: 0.24196096 | F22: 57.416132 | G22: 0.041917024 | H22: 60.648619 | I22: 0.35722978 | J22: 33.904647 | K22: 0.36033015
B23: #N/A | C23: #N/A | D23: 84.619375 | E23: 0.26301483 | F23: 62.522527 | G23: 0.071459227 | H23: 60.742704 | I23: 0.38567016 | J23: 34.038725 | K23: 0.37513117
B24: #N/A | C24: #N/A | D24: 85.222615 | E24: 0.27642288 | F24: 63.476319 | G24: 0.072174535 | H24: 62.047596 | I24: 0.41131323 | J24: 34.458134 | K24: 0.38758169
B25: #N/A | C25: #N/A | D25: 85.719295 | E25: 0.29138285 | F25: 64.151576 | G25: 0.096494993 | H25: 62.626899 | I25: 0.4358351 | J25: 34.841753 | K25: 0.39937977
B26: #N/A | C26: #N/A | D26: 85.837639 | E26: 0.30964086 | F26: 64.434547 | G26: 0.1351216 | H26: 63.015087 | I26: 0.45428305 | J26: 35.022004 | K26: 0.41103663
B27: #N/A | C27: #N/A | D27: 86.385221 | E27: 0.32309944 | F27: 64.447034 | G27: 0.13869814 | H27: 63.120619 | I27: 0.47790189 | J27: 35.029816 | K27: 0.42401964
B28: #N/A | C28: #N/A | D28: 86.615388 | E28: 0.33558657 | F28: 64.653953 | G28: 0.14763948 | H28: 66.591305 | I28: 0.49239138 | J28: 35.219857 | K28: 0.43916996
... B98: #N/A | C98: #N/A | D98: 137.83677 | E98: 0.99420303 | F98: 84.171241 | G98: 0.75400572 | H98: 193.91907 | I98: 1 | J98: 51.046965 | K98: 0.83502238
B99: #N/A | C99: #N/A | D99: 137.92407 | E99: 0.99702284 | F99: 84.200128 | G99: 0.75901288 | H99: #N/A | I99: #N/A | J99: 51.070452 | K99: 0.83728005
B100: #N/A | C100: #N/A | D100: 151.29458 | E100: 0.99867156 | F100: 84.500701 | G100: 0.76616595 | H100: #N/A | I100: #N/A | J100: 51.112868 | K100: 0.83953038
B101: #N/A | C101: #N/A | D101: 168.39645 | E101: 1 | F101: 84.735423 | G101: 0.77081545 | H101: #N/A | I101: #N/A | J101: 51.422292 | K101: 0.84172811
B102: #N/A | C102: #N/A | D102: #N/A | E102: #N/A | F102: 84.912512 | G102: 0.77653791 | H102: #N/A | I102: #N/A | J102: 51.849254 | K102: 0.84409986
B103: #N/A | C103: #N/A | D103: #N/A | E103: #N/A | F103: 84.914084 | G103: 0.78311874 | H103: #N/A | I103: #N/A | J103: 51.886875 | K103: 0.84646485
B104: #N/A | C104: #N/A | D104: #N/A | E104: #N/A | F104: 85.509463 | G104: 0.78848355 | H104: #N/A | I104: #N/A | J104: 51.902736 | K104: 0.84882701
B105: #N/A | C105: #N/A | D105: #N/A | E105: #N/A | F105: 85.638272 | G105: 0.79563662 | H105: #N/A | I105: #N/A | J105: 51.972944 | K105: 0.85117666
B106: #N/A | C106: #N/A | D106: #N/A | E106: #N/A | F106: 85.816539 | G106: 0.80207439 | H106: #N/A | I106: #N/A | J106: 52.096796 | K106: 0.85350447
B107: #N/A | C107: #N/A | D107: #N/A | E107: #N/A | F107: 85.951077 | G107: 0.80693848 | H107: #N/A | I107: #N/A | J107: 52.18696 | K107: 0.85581655
B108: #N/A | C108: #N/A | D108: #N/A | E108: #N/A | F108: 86.78987 | G108: 0.81087268 | H108: #N/A | I108: #N/A | J108: 52.388659 | K108: 0.85809397
B109: #N/A | C109: #N/A | D109: #N/A | E109: #N/A | F109: 87.039812 | G109: 0.81459227 | H109: #N/A | I109: #N/A | J109: 52.395071 | K109: 0.86013684
...

Sheet BPE - Table 4-1_2021
A1: Table 4-1: Emissions from Industrial Processes and Product Use (MMT CO2 Eq.)
AJ2: EPS industry | AK2: EPS pollutant
A3: Gas/Source | B3: 1990 | C3: 1991 | D3: 1992 | E3: 1993 | F3: 1994 | G3: 1995 | H3: 1996 | I3: 1997 | J3: 1998 | K3: 1999 | L3: 2000 | M3: 2001 | N3: 2002 | O3: 2003 | P3: 2004 | Q3: 2005 | R3: 2006 | S3: 2007 | T3: 2008 | U3: 2009 | V3: 2010 | W3: 2011 | X3: 2012 | Y3: 2013 | Z3: 2014 | AA3: 2015 | AB3: 2016 | AC3: 2017 | AD3: 2018 | AE3: 2019 | AF3: 2020 | AG3: 2021 | AH3: 2022
A4: CO2 | B4: 214 | C4: 204.4 | D4: 207.6 | E4: 205.4 | F4: 213 | G4: 221.4 | H4: 222.5 | I4: 227.2 | J4: 223.7 | K4: 222.7 | L4: 219.7 | M4: 198.3 | N4: 197.9 | O4: 192.8 | P4: 200.6 | Q4: 195.4 | R4: 200.2 | S4: 202.5 | T4: 187.5 | U4: 145.1 | V4: 173 | W4: 176.9 | X4: 174.4 | Y4: 175.3 | Z4: 180.6 | AA4: 173.4 | AB4: 165.1 | AC4: 165.3 | AD4: 164.4 | AE4: 168.2 | AF4: 160.7 | AG4: 168.8 | AH4: 168.9
A5: Cement Production | B5: 104.7 | C5: 95.2 | D5: 96 | E5: 91.6 | F5: 94.5 | G5: 98.4 | H5: 96.4 | I5: 97.6 | J5: 91.1 | K5: 89 | L5: 90.5 | M5: 79.8 | N5: 75.8 | O5: 72.7 | P5: 72.2 | Q5: 70.1 | R5: 72.8 | S5: 74.5 | T5: 69.9 | U5: 45.1 | V5: 58.6 | W5: 63 | X5: 57.3 | Y5: 55.2 | Z5: 58.2 | AA5: 39.9 | AB5: 39.4 | AC5: 40.3 | AD5: 39 | AE5: 40.9 | AF5: 40.7 | AG5: 41.3 | AH5: 41.9 | AJ5: cement and other nonmetallic minerals 239 | AK5: CO2
A6: Iron and Steel Production & Metallurgical Coke Production | B6: 99.1 | C6: 90.1 | D6: 92 | E6: 88.7 | F6: 89.4 | G6: 93.2 | H6: 92 | I6: 93.8 | J6: 86.4 | K6: 84.3 | L6: 85.9 | M6: 76.8 | N6: 71.6 | O6: 68.3 | P6: 68.4 | Q6: 66.2 | R6: 69 | S6: 70.6 | T6: 65.8 | U6: 42.9 | V6: 54.8 | W6: 59.8 | X6: 55 | Y6: 51.6 | Z6: 54.5 | AA6: 47.9 | AB6: 43.6 | AC6: 40.8 | AD6: 42.9 | AE6: 43.1 | AF6: 37.7 | AG6: 41.9 | AH6: 40.7
A7: Iron and Steel Production | B7: 5.6 | C7: 5.1 | D7: 4 | E7: 3 | F7: 5.2 | G7: 5.2 | H7: 4.4 | I7: 3.8 | J7: 4.8 | K7: 4.7 | L7: 4.5 | M7: 3 | N7: 4.2 | O7: 4.4 | P7: 3.8 | Q7: 3.9 | R7: 3.8 | S7: 3.9 | T7: 4.1 | U7: 2.2 | V7: 3.8 | W7: 3.1 | X7: 2.2 | Y7: 3.5 | Z7: 3.7 | AA7: 43.5 | AB7: 41 | AC7: 38.8 | AD7: 41.6 | AE7: 40.1 | AF7: 35.4 | AG7: 38.6 | AH7: 37.7 | AJ7: iron and steel 241 | AK7: CO2
A8: Metallurgical Coke Production | B8: 33.5 | C8: 32.7 | D8: 33 | E8: 34.8 | F8: 36.3 | G8: 37.1 | H8: 37.3 | I8: 38.6 | J8: 39.5 | K8: 40.2 | L8: 41.4 | M8: 41.6 | N8: 43.2 | O8: 43.3 | P8: 45.9 | Q8: 46.2 | R8: 46.9 | S8: 45.5 | T8: 41.4 | U8: 29.6 | V8: 31.4 | W8: 32.2 | X8: 35.3 | Y8: 36.4 | Z8: 39.4 | AA8: 4.4 | AB8: 2.6 | AC8: 2 | AD8: 1.3 | AE8: 3 | AF8: 2.3 | AG8: 3.2 | AH8: 3 | AJ8: refined petroleum and coke 19 | AK8: CO2
A9: Petrochemical Production | B9: 21.6 | C9: 23.1 | D9: 23.7 | E9: 24.6 | F9: 26.6 | G9: 27.9 | H9: 29.1 | I9: 30.5 | J9: 30.9 | K9: 32.3 | L9: 31.6 | M9: 27.6 | N9: 28.7 | O9: 28.5 | P9: 30.7 | Q9: 27.4 | R9: 27.6 | S9: 28.1 | T9: 24.7 | U9: 23.8 | V9: 27.3 | W9: 26.3 | X9: 26.5 | Y9: 26.4 | Z9: 26.5 | AA9: 27.2 | AB9: 26.8 | AC9: 27.3 | AD9: 27.2 | AE9: 28.5 | AF9: 27.9 | AG9: 30.7 | AH9: 28.8 | AJ9: chemicals 20 | AK9: CO2
A10: Ammonia Production | B10: 14.4 | C10: 14.7 | D10: 15.1 | E10: 14.5 | F10: 15.6 | G10: 14.9 | H10: 15.2 | I10: 15.4 | J10: 15.6 | K10: 14.3 | L10: 13.4 | M10: 10.3 | N10: 11.7 | O10: 9.8 | P10: 10.6 | Q10: 10.2 | R10: 9.8 | S10: 10.3 | T10: 9.4 | U10: 9.3 | V10: 9.8 | W10: 9 | X10: 10 | Y10: 9.9 | Z10: 10.6 | AA10: 10.1 | AB10: 10.2 | AC10: 12.5 | AD10: 12.7 | AE10: 12.4 | AF10: 13 | AG10: 12.2 | AH10: 12.6 | AJ10: chemicals 20 | AK10: CO2
A11: Lime Production | B11: 11.7 | C11: 11.5 | D11: 11.9 | E11: 12.3 | F11: 12.7 | G11: 13.5 | H11: 14.2 | I11: 14.5 | J11: 14.8 | K11: 14.4 | L11: 14.3 | M11: 13.7 | N11: 13.2 | O11: 13.9 | P11: 14.6 | Q11: 14.6 | R11: 15.2 | S11: 14.7 | T11: 14.5 | U11: 11.4 | V11: 13.4 | W11: 14 | X11: 13.8 | Y11: 14 | Z11: 14.2 | AA11: 13.3 | AB11: 12.6 | AC11: 12.9 | AD11: 13.1 | AE11: 12.1 | AF11: 11.3 | AG11: 11.9 | AH11: 12.2 | AJ11: cement and other nonmetallic minerals 239 | AK11: CO2
A12: Other Process Uses of Carbonates | B12: 6.2 | C12: 5.6 | D12: 5.6 | E12: 5.2 | F12: 5.5 | G12: 7.3 | H12: 8 | I12: 7.7 | J12: 7.8 | K12: 8.6 | L12: 5.8 | M12: 6 | N12: 6.3 | O12: 4.9 | P12: 6.7 | Q12: 7.5 | R12: 8.6 | S12: 7.9 | T12: 6.7 | U12: 8.7 | V12: 10.6 | W12: 9.7 | X12: 8.9 | Y12: 10.9 | Z12: 12.6 | AA12: 12.7 | AB12: 11.4 | AC12: 10.4 | AD12: 7.9 | AE12: 9 | AF12: 9 | AG12: 8.6 | AH12: 10.4 | AJ12: cement and other nonmetallic minerals 239 | AK12: CO2
A13: Urea Consumption for Non-Agricultural Purposes | B13: 3.8 | C13: 3.5 | D13: 3.9 | E13: 4.6 | F13: 4.3 | G13: 4.3 | H13: 3.9 | I13: 3.9 | J13: 4.8 | K13: 4.7 | L13: 4.2 | M13: 4.1 | N13: 3.7 | O13: 3.6 | P13: 3.7 | Q13: 3.7 | R13: 3.5 | S13: 4.9 | T13: 4.1 | U13: 3.4 | V13: 4.7 | W13: 5.1 | X13: 4.8 | Y13: 4.6 | Z13: 1.8 | AA13: 4.6 | AB13: 5.3 | AC13: 5.2 | AD13: 6.1 | AE13: 6.2 | AF13: 5.8 | AG13: 6.6 | AH13: 7.1 | AJ13: chemicals 20 | AK13: CO2
A14: Carbon Dioxide Consumption | B14: 1.5 | C14: 1.5 | D14: 1.5 | E14: 1.5 | F14: 1.5 | G14: 1.5 | H14: 1.5 | I14: 1.5 | J14: 1.5 | K14: 1.5 | L14: 1.5 | M14: 0.9 | N14: 1 | O14: 1.4 | P14: 1.3 | Q14: 1.4 | R14: 1.8 | S14: 1.9 | T14: 1.8 | U14: 1.8 | V14: 4.4 | W14: 4.1 | X14: 4 | Y14: 4.2 | Z14: 4.5 | AA14: 4.9 | AB14: 4.6 | AC14: 4.6 | AD14: 4.1 | AE14: 4.9 | AF14: 5 | AG14: 5 | AH14: 5 | AJ14: food beverage and tobacco 10T12 | AK14: CO2 | AL14: *according to the GHG report, this represents CO2 used in food and beverage applications that is emitted to the atmosphere (does not include CO2 used in EOR)
A15: Glass Production | B15: 1.9 | C15: 2.1 | D15: 2.2 | E15: 2.3 | F15: 2.3 | G15: 2.3 | H15: 2.4 | I15: 2.5 | J15: 2.5 | K15: 2.6 | L15: 2.5 | M15: 2.4 | N15: 2.4 | O15: 2.4 | P15: 2.4 | Q15: 2.4 | R15: 2.4 | S15: 2.3 | T15: 2.2 | U15: 1.9 | V15: 2.1 | W15: 2.1 | X15: 2 | Y15: 2 | Z15: 2 | AA15: 2 | AB15: 2.1 | AC15: 2 | AD15: 2 | AE15: 1.9 | AF15: 1.9 | AG15: 2 | AH15: 2 | AJ15: cement and other nonmetallic minerals 239 | AK15: CO2
A16: Soda Ash Production | B16: 6.8 | C16: 6.9 | D16: 6.8 | E16: 6.2 | F16: 5.5 | G16: 5.7 | H16: 6 | I16: 6 | J16: 6.2 | K16: 6.3 | L16: 6.1 | M16: 4.4 | N16: 4.5 | O16: 4.5 | P16: 4.2 | Q16: 4.1 | R16: 3.8 | S16: 4.3 | T16: 4.5 | U16: 3 | V16: 2.7 | W16: 3.3 | X16: 3.4 | Y16: 3.3 | Z16: 2.8 | AA16: 1.7 | AB16: 1.7 | AC16: 1.8 | AD16: 1.7 | AE16: 1.8 | AF16: 1.5 | AG16: 1.7 | AH16: 1.7 | AJ16: cement and other nonmetallic minerals 239 | AK16: CO2
A17: Titanium Dioxide Production | B17: 1.4 | C17: 1.4 | D17: 1.5 | E17: 1.4 | F17: 1.4 | G17: 1.6 | H17: 1.6 | I17: 1.7 | J17: 1.6 | K17: 1.5 | L17: 1.5 | M17: 1.5 | N17: 1.5 | O17: 1.5 | P17: 1.6 | Q17: 1.7 | R17: 1.6 | S17: 1.7 | T17: 1.7 | U17: 1.5 | V17: 1.5 | W17: 1.6 | X17: 1.7 | Y17: 1.7 | Z17: 1.7 | AA17: 1.6 | AB17: 1.7 | AC17: 1.7 | AD17: 1.5 | AE17: 1.3 | AF17: 1.3 | AG17: 1.5 | AH17: 1.5 | AJ17: other metals 242 | AK17: CO2
A18: Aluminum Production | B18: 2.2 | C18: 1.9 | D18: 2 | E18: 1.9 | F18: 2 | G18: 2 | H18: 2.1 | I18: 2.2 | J18: 2.2 | K18: 2.2 | L18: 1.9 | M18: 1.5 | N18: 1.3 | O18: 1.3 | P18: 1.4 | Q18: 1.4 | R18: 1.5 | S18: 1.6 | T18: 1.6 | U18: 1.5 | V18: 1.7 | W18: 1.7 | X18: 1.9 | Y18: 1.8 | Z18: 2 | AA18: 2.8 | AB18: 1.3 | AC18: 1.2 | AD18: 1.5 | AE18: 1.9 | AF18: 1.7 | AG18: 1.5 | AH18: 1.4 | AJ18: other metals 242 | AK18: CO2
A19: Ferroalloy Production | B19: 1.2 | C19: 1.2 | D19: 1.4 | E19: 1.4 | F19: 1.5 | G19: 1.5 | H19: 1.5 | I19: 1.7 | J19: 1.7 | K19: 1.7 | L19: 1.8 | M19: 1.7 | N19: 1.8 | O19: 1.8 | P19: 2.1 | Q19: 1.8 | R19: 1.8 | S19: 1.9 | T19: 1.8 | U19: 1.6 | V19: 1.8 | W19: 1.7 | X19: 1.5 | Y19: 1.7 | Z19: 1.7 | AA19: 2 | AB19: 1.8 | AC19: 2 | AD19: 2.1 | AE19: 1.6 | AF19: 1.4 | AG19: 1.6 | AH19: 1.3 | AJ19: iron and steel 241 | AK19: CO2
A20: Zinc Production | B20: 0.6 | C20: 0.8 | D20: 0.8 | E20: 0.9 | F20: 0.9 | G20: 0.9 | H20: 0.9 | I20: 1 | J20: 0.9 | K20: 0.9 | L20: 0.9 | M20: 0.7 | N20: 0.7 | O20: 1.1 | P20: 1 | Q20: 1 | R20: 1 | S20: 1 | T20: 1.2 | U20: 0.9 | V20: 1.2 | W20: 1.3 | X20: 1.5 | Y20: 1.4 | Z20: 0.9 | AA20: 0.9 | AB20: 0.8 | AC20: 0.9 | AD20: 1 | AE20: 1 | AF20: 1 | AG20: 1 | AH20: 0.9 | AJ20: other metals 242 | AK20: CO2
A21: Phosphoric Acid Production | B21: 1.5 | C21: 1.4 | D21: 1.5 | E21: 1.3 | F21: 1.5 | G21: 1.5 | H21: 1.6 | I21: 1.5 | J21: 1.6 | K21: 1.5 | L21: 1.4 | M21: 1.3 | N21: 1.3 | O21: 1.4 | P21: 1.4 | Q21: 1.3 | R21: 1.2 | S21: 1.2 | T21: 1.1 | U21: 1 | V21: 1.1 | W21: 1.2 | X21: 1.1 | Y21: 1.1 | Z21: 1 | AA21: 1 | AB21: 1 | AC21: 1 | AD21: 0.9 | AE21: 0.9 | AF21: 0.9 | AG21: 0.9 | AH21: 0.8 | AJ21: chemicals 20 | AK21: CO2
A22: Lead Production | B22: 0.5 | C22: 0.5 | D22: 0.5 | E22: 0.5 | F22: 0.5 | G22: 0.6 | H22: 0.6 | I22: 0.6 | J22: 0.6 | K22: 0.6 | L22: 0.6 | M22: 0.6 | N22: 0.6 | O22: 0.6 | P22: 0.5 | Q22: 0.6 | R22: 0.6 | S22: 0.6 | T22: 0.5 | U22: 0.5 | V22: 0.5 | W22: 0.5 | X22: 0.5 | Y22: 0.5 | Z22: 0.5 | AA22: 0.5 | AB22: 0.5 | AC22: 0.5 | AD22: 0.5 | AE22: 0.5 | AF22: 0.5 | AG22: 0.4 | AH22: 0.4 | AJ22: other metals 242 | AK22: CO2
A23: Carbide Production and Consumption | B23: 0.2 | C23: 0.2 | D23: 0.2 | E23: 0.2 | F23: 0.2 | G23: 0.2 | H23: 0.2 | I23: 0.2 | J23: 0.3 | K23: 0.2 | L23: 0.2 | M23: 0.2 | N23: 0.2 | O23: 0.2 | P23: 0.2 | Q23: 0.2 | R23: 0.2 | S23: 0.2 | T23: 0.2 | U23: 0.1 | V23: 0.2 | W23: 0.2 | X23: 0.2 | Y23: 0.2 | Z23: 0.2 | AA23: 0.2 | AB23: 0.2 | AC23: 0.2 | AD23: 0.2 | AE23: 0.2 | AF23: 0.2 | AG23: 0.2 | AH23: 0.2 | AJ23: chemicals 20 | AK23: CO2 | AL23: *carbide production is classified under the "industrial inorganic chemicals" SIC code
A24: Substitution of Ozone Depleting Substances | AA24: + | AB24: + | AC24: + | AD24: + | AE24: + | AF24: + | AG24: + | AH24: +
A25: Magnesium Production and Processing | B25: 0.1 | C25: 0.1 | D25: 0.1 | E25: 0.1 | F25: 0.1 | G25: 0.1 | H25: 0.1 | I25: 0.1 | J25: 0.1 | K25: 0.1 | L25: 0.1 | M25: 0.1 | N25: 0 | O25: 0 | P25: 0 | Q25: 0 | R25: 0 | S25: 0 | T25: 0 | U25: 0 | V25: 0 | W25: 0 | X25: 0 | Y25: 0 | Z25: 0 | AA25: + | AB25: + | AC25: + | AD25: + | AE25: + | AF25: + | AG25: + | AH25: +
A26: CH4 | B26: 0.3 | C26: 0.3 | D26: 0.3 | E26: 0.4 | F26: 0.4 | G26: 0.4 | H26: 0.4 | I26: 0.4 | J26: 0.4 | K26: 0.4 | L26: 0.4 | M26: 0.3 | N26: 0.3 | O26: 0.3 | P26: 0.2 | Q26: 0.1 | R26: 0.1 | S26: 0.1 | T26: 0.1 | U26: 0.1 | V26: 0.1 | W26: 0.1 | X26: 0.1 | Y26: 0.1 | Z26: 0.2 | AA26: + | AB26: + | AC26: + | AD26: + | AE26: + | AF26: + | AG26: + | AH26: +
A27: Carbide Production and Consumption | B27: 0 | C27: 0 | D27: 0 | E27: 0 | F27: 0 | G27: 0 | H27: 0 | I27: 0 | J27: 0 | K27: 0 | L27: 0 | M27: 0 | N27: 0 | O27: 0 | P27: 0 | Q27: 0 | R27: 0 | S27: 0 | T27: 0 | U27: 0 | V27: 0 | W27: 0 | X27: 0 | Y27: 0 | Z27: 0 | AA27: + | AB27: + | AC27: + | AD27: + | AE27: + | AF27: + | AG27: + | AH27: +
A28: Ferroalloy Production | B28: 0 | C28: 0 | D28: 0 | E28: 0 | F28: 0 | G28: 0 | H28: 0 | I28: 0 | J28: 0 | K28: 0 | L28: 0 | M28: 0 | N28: 0 | O28: 0 | P28: 0 | Q28: 0 | R28: 0 | S28: 0 | T28: 0 | U28: 0 | V28: 0 | W28: 0 | X28: 0 | Y28: 0 | Z28: 0 | AA28: + | AB28: + | AC28: + | AD28: + | AE28: + | AF28: + | AG28: + | AH28: +
A29: Iron and Steel Production & Metallurgical Coke Production | B29: 0 | C29: 0 | D29: 0 | E29: 0 | F29: 0 | G29: 0 | H29: 0 | I29: 0 | J29: 0 | K29: 0 | L29: 0 | M29: 0 | N29: 0 | O29: 0 | P29: 0 | Q29: 0 | R29: 0 | S29: 0 | T29: 0 | U29: 0 | V29: 0 | W29: 0 | X29: 0 | Y29: 0 | Z29: 0 | AA29: + | AB29: + | AC29: + | AD29: + | AE29: + | AF29: + | AG29: + | AH29: +
A30: Petrochemical Production | B30: 0.2 | C30: 0.3 | D30: 0.2 | E30: 0.3 | F30: 0.3 | G30: 0.3 | H30: 0.4 | I30: 0.4 | J30: 0.4 | K30: 0.4 | L30: 0.3 | M30: 0.2 | N30: 0.2 | O30: 0.2 | P30: 0.2 | Q30: 0.1 | R30: 0.1 | S30: 0.1 | T30: 0.1 | U30: 0.1 | V30: 0.1 | W30: 0.1 | X30: 0.1 | Y30: 0.1 | Z30: 0.1 | AA30: + | AB30: + | AC30: + | AD30: + | AE30: + | AF30: + | AG30: + | AH30: +
A31: N2O | B31: 29.6 | C31: 29.1 | D31: 27.6 | E31: 29.1 | F31: 29.5 | G31: 32.7 | H31: 33.1 | I31: 27.2 | J31: 23.2 | K31: 22.4 | L31: 22.6 | M31: 19.5 | N31: 20.4 | O31: 20.2 | P31: 18.7 | Q31: 22.2 | R31: 23.2 | S31: 26.8 | T31: 18.1 | U31: 16.8 | V31: 19.9 | W31: 24.7 | X31: 20 | Y31: 18.8 | Z31: 20.3 | AA31: 19.7 | AB31: 20.8 | AC31: 20.2 | AD31: 23.1 | AE31: 18.7 | AF31: 20.8 | AG31: 19.7 | AH31: 16.1
A32: Nitric Acid Production | B32: 10.8 | C32: 10.8 | D32: 11.1 | E32: 11.2 | F32: 11.9 | G32: 12 | H32: 12.5 | I32: 12.8 | J32: 12.6 | K32: 12.2 | L32: 11.8 | M32: 9.6 | N32: 10.4 | O32: 9.8 | P32: 9.7 | Q32: 10.1 | R32: 9.9 | S32: 11.7 | T32: 10 | U32: 8.6 | V32: 10.3 | W32: 9.7 | X32: 9.3 | Y32: 9.5 | Z32: 9.7 | AA32: 10.3 | AB32: 9 | AC32: 8.3 | AD32: 8.5 | AE32: 8.9 | AF32: 8.3 | AG32: 7.9 | AH32: 8.6 | AJ32: chemicals 20 | AK32: N2O
A33: N2O from Product Uses | B33: 3.8 | C33: 3.7 | D33: 3.5 | E33: 3.9 | F33: 3.9 | G33: 3.9 | H33: 3.9 | I33: 4.2 | J33: 4.2 | K33: 4.2 | L33: 4.2 | M33: 4.2 | N33: 3.8 | O33: 3.8 | P33: 3.8 | Q33: 3.8 | R33: 3.8 | S33: 3.8 | T33: 3.8 | U33: 3.8 | V33: 3.8 | W33: 3.8 | X33: 3.8 | Y33: 3.8 | Z33: 3.8 | AA33: 3.8 | AB33: 3.8 | AC33: 3.8 | AD33: 3.8 | AE33: 3.8 | AF33: 3.8 | AG33: 3.8 | AH33: 3.8 | AJ33: chemicals 20 | AK33: N2O
A34: Adipic Acid Production | B34: 13.5 | C34: 13.2 | D34: 11.5 | E34: 12.4 | F34: 12 | G34: 15 | H34: 14.9 | I34: 8.4 | J34: 4.6 | K34: 4.2 | L34: 4.7 | M34: 4 | N34: 4.4 | O34: 4.8 | P34: 3.3 | Q34: 6.3 | R34: 7.6 | S34: 9.1 | T34: 2.2 | U34: 2.4 | V34: 3.8 | W34: 9.1 | X34: 4.9 | Y34: 3.5 | Z34: 4.8 | AA34: 3.8 | AB34: 6.3 | AC34: 6.6 | AD34: 9.3 | AE34: 4.7 | AF34: 7.4 | AG34: 6.6 | AH34: 2.1 | AJ34: chemicals 20 | AK34: N2O
A35: Caprolactam, Glyoxal, and Glyoxylic Acid Production | B35: 1.5 | C35: 1.4 | D35: 1.5 | E35: 1.6 | F35: 1.7 | G35: 1.7 | H35: 1.7 | I35: 1.7 | J35: 1.8 | K35: 1.8 | L35: 1.8 | M35: 1.6 | N35: 1.8 | O35: 1.7 | P35: 1.9 | Q35: 1.9 | R35: 1.8 | S35: 2 | T35: 1.9 | U35: 1.9 | V35: 2 | W35: 2 | X35: 1.8 | Y35: 1.9 | Z35: 1.8 | AA35: 1.7 | AB35: 1.5 | AC35: 1.3 | AD35: 1.3 | AE35: 1.2 | AF35: 1.1 | AG35: 1.2 | AH35: 1.3 | AJ35: chemicals 20 | AK35: N2O
A36: Electronics Industry | B36: 0 | C36: 0 | D36: 0 | E36: 0 | F36: 0 | G36: 0.1 | H36: 0.1 | I36: 0.1 | J36: 0.1 | K36: 0.1 | L36: 0.1 | M36: 0.1 | N36: 0.1 | O36: 0.1 | P36: 0.1 | Q36: 0.1 | R36: 0.2 | S36: 0.2 | T36: 0.2 | U36: 0.1 | V36: 0.1 | W36: 0.2 | X36: 0.2 | Y36: 0.2 | Z36: 0.2 | AA36: 0.2 | AB36: 0.2 | AC36: 0.2 | AD36: 0.2 | AE36: 0.2 | AF36: 0.3 | AG36: 0.3 | AH36: 0.3 | AJ36: computers and electronics 26 | AK36: N2O
A37: HFCs | B37: 39 | C37: 35.4 | D37: 40.4 | E37: 40.8 | F37: 47.1 | G37: 64.7 | H37: 74.5 | I37: 84.4 | J37: 102.3 | K37: 100.9 | L37: 105.8 | M37: 102.9 | N37: 109.2 | O37: 104.3 | P37: 113.3 | Q37: 116.4 | R37: 120.7 | S37: 131.2 | T37: 135.7 | U37: 136.2 | V37: 144.7 | W37: 148.4 | X37: 148.1 | Y37: 149.1 | Z37: 154.1 | AA37: 160.8 | AB37: 160.6 | AC37: 163 | AD37: 163.9 | AE37: 168.2 | AF37: 170.3 | AG37: 177 | AH37: 182.8
A38: Substitution of Ozone Depleting Substances a | B38: 0.3 | C38: 0.5 | D38: 1.6 | E38: 5.5 | F38: 13.5 | G38: 29.4 | H38: 41.1 | I38: 52.2 | J38: 60.1 | K38: 68.2 | L38: 75.2 | M38: 81.8 | N38: 86.6 | O38: 91.1 | P38: 94.9 | Q38: 99.4 | R38: 105.8 | S38: 113 | T38: 121 | U38: 130.3 | V38: 137.7 | W38: 140.8 | X38: 143.2 | Y38: 145.3 | Z38: 149.5 | AA38: 154.1 | AB38: 155.8 | AC38: 156.2 | AD38: 157.9 | AE38: 162.1 | AF38: 166.2 | AG38: 172.6 | AH38: 178.1 | AJ38: chemicals 20 | AK38: F-gases
A39: Fluorochemical Production | B39: 38.6 | C39: 34.7 | D39: 38.6 | E39: 35.1 | F39: 33.4 | G39: 34.9 | H39: 33 | I39: 31.9 | J39: 41.8 | K39: 32.2 | L39: 30.3 | M39: 20.9 | N39: 22.4 | O39: 13 | P39: 18.3 | Q39: 16.8 | R39: 14.7 | S39: 18 | T39: 14.4 | U39: 5.7 | V39: 6.7 | W39: 7.3 | X39: 4.6 | Y39: 3.4 | Z39: 4.2 | AA39: 6.4 | AB39: 4.4 | AC39: 6.4 | AD39: 5.7 | AE39: 5.7 | AF39: 3.8 | AG39: 4 | AH39: 4.3 | AJ39: chemicals 20 | AK39: F-gases
A40: Electronics Industry | B40: 0.2 | C40: 0.2 | D40: 0.2 | E40: 0.2 | F40: 0.2 | G40: 0.3 | H40: 0.3 | I40: 0.4 | J40: 0.5 | K40: 0.5 | L40: 0.3 | M40: 0.2 | N40: 0.2 | O40: 0.2 | P40: 0.2 | Q40: 0.2 | R40: 0.2 | S40: 0.2 | T40: 0.2 | U40: 0.2 | V40: 0.2 | W40: 0.2 | X40: 0.3 | Y40: 0.2 | Z40: 0.3 | AA40: 0.3 | AB40: 0.3 | AC40: 0.3 | AD40: 0.3 | AE40: 0.3 | AF40: 0.3 | AG40: 0.4 | AH40: 0.3 | AJ40: chemicals 20 | AK40: F-gases | AL40: <this is really the electrical equipment industry, but we group with chemicals here
...

Sheet BPE - US specific multipliers
B1: Summary of Start Year EPA Data from Inventory
B3: EPA Summary (mmt CO2e AR5)
E4: 2021 | F4: 2022
C5: Industry | D5: Gas
B6: 5-1 | C6: agriculture and forestry 01T03 | D6: CO2 | E6: 7.6 | F6: 8.6
B7: 5-1 | C7: agriculture and forestry 01T03 | D7: CH4 | E7: 281.8 | F7: 276.8
B8: 5-1 | C8: agriculture and forestry 01T03 | D8: N2O | E8: 315.3 | F8: 308
B9: 3-1 | C9: coal mining 05 | D9: CO2 | E9: 2.5 | F9: 2.5
B10: 3-1 | C10: coal mining 05 | D10: CH4 | E10: 51 | F10: 49.9
B11: 3-68 | C11: oil and gas extraction 06 | D11: CO2 | E11: 34.8 | F11: 35.3
B12: 3-46 | C12: oil and gas extraction 06 | D12: CO2 | E12: 21.1 | F12: 19.1
B13: subtotal | C13: oil and gas extraction 06 | D13: CO2 | E13: 55.9 | F13: 54.4
B14: 3-44 | C14: oil and gas extraction 06 | D14: CH4 | E14: 47.7 | F14: 38.7
B15: 3-66 | C15: oil and gas extraction 06 | D15: CH4 | E15: 106.5 | F15: 105
B16: 3-1 | C16: oil and gas extraction 06 | D16: CH4 | E16: 8.6 | F16: 8.5
B17: subtotal | C17: oil and gas extraction 06 | D17: CH4 | E17: 162.8 | F17: 152.2
... B44: 7-1 | C44: water and waste 36T39 | D44: N2O | E44: 23.9 | F44: 23.7

Sheet Steel
A2: This graph is Figure 6-54 on pg. 138 of the NETL report.
A26: Plant ID | B26: Plant name (English) | C26: Plant name (other language) | D26: Country/Area | E26: Status | F26: Start date | G26: Nominal BOF steel capacity (ttpa) | H26: Nominal BF capacity (ttpa) | I26: Other/unspecified iron capacity (ttpa) | J26: CO2 available | K26: Steel Production Capacity | L26: COC, $/tonne | M26: COA, 2018 $/tonne | N26: COA, 2012 $/tonne | O26: Cumulative Capacity
A27: P100000120966 | B27: U.S. Steel Gary Works | D27: United States | E27: operating | F27: 1908 | G27: 7800 | H27: 6495 | I27: N/A | J27: 10.594409 | K27: 6.5041573 | L27: 54.647887 | M27: =L27+AVERAGE('Retrofit Cost vs SOC Data'!$B$9,'Retrofit Cost vs SOC Data'!$D$9,'Retrofit Cost vs SOC Data'!$F$9,'Retrofit Cost vs SOC Data'!$H$9,'Retrofit Cost vs SOC Data'!$J$9) -> 65.723695 | N27: =M27*cpi!$G$56 -> 60.092973 | O27: =SUM(H27:H$27)/SUM(H$27:H$33) -> 0.25150048
A28: P100000120923 | B28: Cleveland-Cliffs Burns Harbor steel plant | D28: United States | E28: operating | F28: 1964 | G28: 5001 | H28: 4960 | I28: N/A | J28: 8.0828734 | K28: 4.9455809 | L28: 57.042254 | M28: =L28+AVERAGE('Retrofit Cost vs SOC Data'!$B$9,'Retrofit Cost vs SOC Data'!$D$9,'Retrofit Cost vs SOC Data'!$F$9,'Retrofit Cost vs SOC Data'!$H$9,'Retrofit Cost vs SOC Data'!$J$9) -> 68.118062 | N28: =M28*cpi!$G$56 -> 62.282207 | O28: =SUM(H$27:H28)/SUM(H$27:H$33) -> 0.44356244
A29: P100000120926 | B29: Cleveland-Cliffs Indiana Harbor steel plant | D29: United States | E29: operating | F29: 1901 | G29: 6800 | H29: 4200 | I29: N/A | J29: 6.8402322 | K29: 4.2057503 | L29: 58.732394 | M29: =L29+AVERAGE('Retrofit Cost vs SOC Data'!$B$9,'Retrofit Cost vs SOC Data'!$D$9,'Retrofit Cost vs SOC Data'!$F$9,'Retrofit Cost vs SOC Data'!$H$9,'Retrofit Cost vs SOC Data'!$J$9) -> 69.808203 | N29: =M29*cpi!$G$56 -> 63.827549 | O29: =SUM(H$27:H29)/SUM(H$27:H$33) -> 0.60619555
A30: P100000120927 | B30: Cleveland-Cliffs Cleveland steel plant | D30: United States | E30: operating | F30: 1913 | G30: 4100 | H30: 2810 | I30: N/A | J30: 4.5649736 | K30: 2.8050044 | L30: 63.239437 | M30: =L30+AVERAGE('Retrofit Cost vs SOC Data'!$B$9,'Retrofit Cost vs SOC Data'!$D$9,'Retrofit Cost vs SOC Data'!$F$9,'Retrofit Cost vs SOC Data'!$H$9,'Retrofit Cost vs SOC Data'!$J$9) -> 74.315245 | N30: =M30*cpi!$G$56 -> 67.948461 | O30: =SUM(H$27:H30)/SUM(H$27:H$33) -> 0.71500484
A31: P100000120964 | B31: U.S. Steel Edgar Thomson Plant | D31: United States | E31: operating | F31: 1875 | G31: 2600 | H31: 2770 | I31: N/A | J31: 4.5212187 | K31: 2.7754111 | L31: 63.380282 | M31: =L31+AVERAGE('Retrofit Cost vs SOC Data'!$B$9,'Retrofit Cost vs SOC Data'!$D$9,'Retrofit Cost vs SOC Data'!$F$9,'Retrofit Cost vs SOC Data'!$H$9,'Retrofit Cost vs SOC Data'!$J$9) -> 74.45609 | N31: =M31*cpi!$G$56 -> 68.07724 | O31: =SUM(H$27:H31)/SUM(H$27:H$33) -> 0.82226525
A32: P100000120920 | B32: Cleveland-Cliffs Dearborn steel plant | D32: United States | E32: operating | F32: 1920 | G32: 3000 | H32: 2500 | I32: N/A | J32: 4.048665 | K32: 2.4992077 | L32: 64.71831 | M32: =L32+AVERAGE('Retrofit Cost vs SOC Data'!$B$9,'Retrofit Cost vs SOC Data'!$D$9,'Retrofit Cost vs SOC Data'!$F$9,'Retrofit Cost vs SOC Data'!$H$9,'Retrofit Cost vs SOC Data'!$J$9) -> 75.794118 | N32: =M32*cpi!$G$56 -> 69.300636 | O32: =SUM(H$27:H32)/SUM(H$27:H$33) -> 0.91907067
A33: P100000120921 | B33: Cleveland-Cliffs Middletown steel plant | D33: United States | E33: operating pre-retirement | F33: 1901 | G33: N/A | H33: 2090 | I33: N/A | J33: 3.4010914 | K33: 2.094767 | L33: 66.901408 | M33: =L33+AVERAGE('Retrofit Cost vs SOC Data'!$B$9,'Retrofit Cost vs SOC Data'!$D$9,'Retrofit Cost vs SOC Data'!$F$9,'Retrofit Cost vs SOC Data'!$H$9,'Retrofit Cost vs SOC Data'!$J$9) -> 77.977217 | N33: =M33*cpi!$G$56 -> 71.296702 | O33: =SUM(H$27:H33)/SUM(H$27:H$33) -> 1
B37: TABLE 2(I).A-H SECTORAL BACKGROUND DATA FOR INDUSTRIAL PROCESSES AND PRODUCT USE
B38: 1. Iron and steel production | H38: 41656.176
B39: a. Steel | C39: Steel Production | D39: 57306.86 | E39: 0.096273492 | F39: NA | H39: 5517.1315
B40: b. Pig iron | C40: Pig Iron Production | D40: 22246.358 | E40: 0.32078687 | F40: NA | H40: 7136.3397
B41: c. Direct reduced iron | C41: Production | D41: C | E41: C | F41: NE,NO | H41: 1984.2827
B42: d. Sinter | C42: Production | D42: 4181.708 | E42: 0.2 | F42: 7e-05 | H42: 836.3416
B43: e. Pellet | C43: Production | D43: 27949.069 | E43: 0.03 | F43: NA | H43: 838.47208
B44: f. Other (please specify) | H44: 25343.609
B45: Other Blast Furnace Gas Consumption | C45: Consumption | D45: 33176.627 | E45: 0.62333333 | F45: NO,IE | H45: 20680.098
B46: Coke | C46: Consumption | D46: 11380.824 | E46: 0.28331807 | F46: NO,IE | H46: 3224.3931
B47: Other Coke Oven Gas Consumption | C47: Consumption | D47: 835.07812 | E47: 1.7233333 | F47: NO,IE | H47: 1439.118
A51: Share of Steel emissions from these BF/BOFs
A52: =SUMIFS(Table2[GHG QUANTITY (METRIC TONS CO2e)],Table2[Column1],"Yes")/SUM(Table2[GHG QUANTITY (METRIC TONS CO2e)]) -> 0.59489255

Sheet FLIGHT Facilities and GHG Quant
A1: Data Extracted from EPA's FLIGHT Tool (http://ghgdata.epa.gov/ghgp)
A2: The data was reported to EPA by facilities as of 08/16/2024
A3: All emissions data is presented in units of metric tons of carbon dioxide equivalent using GWP's from IPCC's AR4
A4: Search Parameters: year=2023; GHGs=CO2; data type=All Direct Emitters;
A6: REPORTING YEAR | B6: FACILITY NAME | C6: GHGRP ID | D6: REPORTED ADDRESS | E6: LATITUDE | F6: LONGITUDE | G6: CITY NAME | H6: COUNTY NAME | I6: STATE | J6: ZIP CODE | K6: PARENT COMPANIES | L6: GHG QUANTITY (METRIC TONS CO2e) | M6: SUBPARTS | N6: Column1
A7: 2023 | B7: US Steel Corp - Gary Works | C7: 1000418 | D7: 1 NORTH BROADWAY | E7: 41.6133 | F7: -87.3281 | G7: GARY | H7: Lake | I7: IN | J7: 46402 | K7: US STEEL CORP (100%) | L7: 10812592 | M7: C,Q,TT | N7: Yes
A8: 2023 | B8: Cleveland-Cliffs Burns Harbor LLC | C8: 1003962 | D8: 250 W US 12 | E8: 41.634 | F8: -87.131 | G8: BURNS HARBOR | H8: PORTER COUNTY | I8: IN | J8: 46304 | K8: CLEVELAND-CLIFFS INC (100%) | L8: 7641790 | M8: C,Q | N8: Yes
A9: 2023 | B9: Cleveland-Cliffs Steel LLC | C9: 1000156 | D9: 3210 WATLING ST | E9: 41.68 | F9: -87.4264 | G9: EAST CHICAGO | H9: Lake | I9: IN | J9: 46312 | K9: CLEVELAND-CLIFFS INC (100%) | L9: 5640848 | M9: C,Q,S | N9: Yes
A10: 2023 | B10: Cleveland-Cliffs Cleveland Works LLC | C10: 1007177 | D10: 3060 EGGERS AVENUE | E10: 41.4739 | F10: -81.6728 | G10: CLEVELAND | H10: Cuyahoga | I10: OH | J10: 44105 | K10: CLEVELAND-CLIFFS INC (100%) | L10: 4268433 | M10: C,Q | N10: Yes
A11: 2023 | B11: US Steel (Edgar Thomson) | C11: 1000233 | D11: 13th Street and Braddock Avenue | E11: 40.3925 | F11: -79.8564 | G11: Braddock | H11: Allegheny | I11: PA | J11: 15104 | K11: US STEEL CORP (100%) | L11: 3575971 | M11: C,Q | N11: Yes
A12: 2023 | B12: Cleveland-Cliffs Steel Corporation - Middletown Works | C12: 1000274 | D12: 1801 CRAWFORD STREET | E12: 39.4968 | F12: -84.3901 | G12: MIDDLETOWN | H12: Butler | I12: OH | J12: 45043 | K12: CLEVELAND-CLIFFS INC (100%) | L12: 3510727 | M12: C,Q | N12: Yes
A13: 2023 | B13: US STEEL - GRANITE CITY | C13: 1006041 | D13: 1951 STATE ST | E13: 38.6954 | F13: -90.1367 | G13: GRANITE CITY | H13: MADISON COUNTY | I13: IL | J13: 62040 | K13: US STEEL CORP (100%) | L13: 1697023 | M13: C,Q,TT
A14: 2023 | B14: US STEEL - Minntac | C14: 1001621 | D14: 8819 OLD HIGHWAY 169 | E14: 47.565 | F14: -92.6328 | G14: MOUNTAIN IRON | H14: ST. LOUIS COUNTY | I14: MN | J14: 55768 | K14: US STEEL CORP (100%) | L14: 1305630 | M14: C,Q
A15: 2023 | B15: Nucor Steel Louisiana LLC | C15: 1010766 | D15: 9101 LA HWY 3125 | E15: 30.081306 | F15: -90.860528 | G15: Convent | H15: ST. JAMES PARISH | I15: LA | J15: 70723 | K15: NUCOR CORP (100%) | L15: 1086372 | M15: C,Q
A16: 2023 | B16: TILDEN MINING COMPANY L C | C16: 1004458 | E16: 46.439735 | F16: -87.649771 | G16: ISHPEMING | H16: MARQUETTE COUNTY | I16: MI | J16: 49849 | K16: CLEVELAND-CLIFFS INC (100%) | L16: 1065597 | M16: C,Q
A17: 2023 | B17: Indiana Harbor Coke Company | C17: 1007287 | D17: 3210 Watling St. | E17: 41.656321 | F17: -87.450142 | G17: East Chicago | H17: LAKE COUNTY | I17: IN | J17: 46312 | K17: SUNCOKE ENERGY INC (85%); DTE ENERGY CO (15%) | L17: 1065008 | M17: C,Q | N17: Yes
A18: 2023 | B18: CLEVELAND-CLIFFS STEEL CORPORATION DEARBORN WORKS | C18: 1003403 | D18: 4001 MILLER RD | E18: 42.301742 | F18: -83.162934 | G18: DEARBORN | H18: WAYNE COUNTY | I18: MI | J18: 48120 | K18: CLEVELAND-CLIFFS INC (100%) | L18: 1006617 | M18: C,Q | N18: Yes
A19: 2023 | B19: STEEL DYNAMICS INC | C19: 1005584 | D19: 4500 CR 59 | E19: 41.364278 | F19: -84.914083 | G19: BUTLER | H19: DEKALB COUNTY | I19: IN | J19: 46721 | K19: STEEL DYNAMICS INC (100%) | L19: 982345 | M19: C,Q
A20: 2023 | B20: HAVERHILL COKE COMPANY, LLC | C20: 1002777 | D20: 2446 GALLIA PIKE | E20: 38.5973 | F20: -82.8271 | G20: FRANKLIN FURNACE | H20: SCIOTO COUNTY | I20: OH | J20: 45629 | K20: SUNCOKE ENERGY INC (100%) | L20: 921306 | M20: C,Q
A21: 2023 | B21: IronUnits LLC | C21: 1014155 | D21: 300 Millard Avenue | E21: 41.675323 | F21: -83.477908 | G21: Toledo | H21: LUCAS COUNTY | I21: OH | J21: 43605 | K21: CLEVELAND-CLIFFS INC (100%) | L21: 802792 | M21: C,Q
A22: 2023 | B22: US Steel (Clairton Coke) | C22: 1000124 | D22: 400 STATE ST | E22: 40.3097 | F22: -79.8819 | G22: CLAIRTON | H22: Allegheny | I22: PA | J22: 15025 | K22: US STEEL CORP (100%) | L22: 768558 | M22: C,Q
A23: 2023 | B23: Cleveland-Cliffs Steel LLC | C23: 1000588 | D23: 3001 Dickey Road | E23: 41.651165 | F23: -87.459167 | G23: East Chicago | H23: LAKE COUNTY | I23: IN | J23: 46312 | K23: CLEVELAND-CLIFFS INC (100%) | L23: 703371 | M23: C,Q | N23: Yes
A24: 2023 | B24: NUCOR STEEL - BERKELEY | C24: 1002266 | D24: 1455 HAGAN AVENUE | E24: 33.004097 | F24: -79.8816 | G24: HUGER | H24: BERKELEY COUNTY | I24: SC | J24: 29450 | K24: NUCOR CORP (100%) | L24: 598742 | M24: C,Q
A25: 2023 | B25: ArcelorMittal Texas HBI | C25: 1012625 | D25: 2800 Kay Bailey Hutchison Road | E25: 27.888611 | F25: -97.277778 | G25: Portland | H25: SAN PATRICIO COUNTY | I25: TX | J25: 78374 | K25: ARCELORMITTAL HOLDINGS LLC (100%) | L25: 556898 | M25: C,Q
A26: 2023 | B26: Steel Dynamics Columbus, LLC | C26: 1004616 | D26: 1945 Airport Road | E26: 33.443611 | F26: -88.575556 | G26: Columbus | H26: LOWNDES COUNTY | I26: MS | J26: 39703 | K26: STEEL DYNAMICS INC (100%) | L26: 497936 | M26: C,Q
A27: 2023 | B27: GATEWAY ENERGY & COKE CO LLC | C27: 1003204 | D27: 2585 EDWARDSVILLE RD | E27: 38.695766 | F27: -90.132874 | G27: GRANITE CITY | H27: MADISON COUNTY | I27: IL | J27: 62040 | K27: SUNCOKE ENERGY INC (100%) | L27: 472572 | M27: C,Q
A28: 2023 | B28: NUCOR STEEL DECATUR | C28: 1005976 | D28: 4301 IVERSON BOULEVARD | E28: 34.638906 | F28: -87.089036 | G28: TRINITY | H28: MORGAN COUNTY | I28: AL | J28: 35673 | K28: NUCOR CORP (100%) | L28: 452004 | M28: C,Q
A29: 2023 | B29: NORTH STAR BLUESCOPE STEEL LLC * | C29: 1005163 | D29: 6767 COUNTY ROAD 9 | E29: 41.5684 | F29: -84.03759 | G29: DELTA | H29: FULTON COUNTY | I29: OH | J29: 43515 | K29: BLUESCOPE STEEL INVESTMENTS INC (50%); BLUESCOPE STEEL INVESTMENTS INC 3 (30%); BLUESCOPE STEEL INVESTMENTS INC 2 (20%) | L29: 442356 | M29: C,Q
A30: 2023 | B30: SunCoke Energy Middletown Operations | C30: 1006159 | D30: 3353 Yankee Road | E30: 39.47215 | F30: -84.39693 | G30: Middletown | H30: BUTLER COUNTY | I30: OH | J30: 45044 | K30: SUNCOKE ENERGY INC (100%) | L30: 429686 | M30: C,Q
A31: 2023 | B31: UNITED TACONITE LLC - FAIRLANE PLANT | C31: 1005294 | D31: 8470 Townline Road | E31: 47.3502 | F31: -92.5735 | G31: FORBES | H31: ST. LOUIS COUNTY | I31: MN | J31: 55738 | K31: CLEVELAND-CLIFFS INC (100%) | L31: 398411 | M31: C,Q
A32: 2023 | B32: Big River Steel LLC | C32: 1012997 | D32: 2027 E. State Hwy.198 | E32: 35.696993 | F32: -90.03732 | G32: Osceola | I32: AR | J32: 72370 | K32: US STEEL CORP (99.9%) | L32: 380122 | M32: C,Q
A33: 2023 | B33: Nucor Steel Gallatin LLC | C33: 1005700 | D33: 4831 US 42 W | E33: 38.766667 | F33: -85.004167 | G33: GHENT | H33: GALLATIN COUNTY | I33: KY | J33: 41045 | K33: NUCOR CORP (100%) | L33: 378072 | M33: C,Q
A34: 2023 | B34: JEWELL COAL & COKE | C34: 1005598 | D34: 1034 Dismal River Road | E34: 37.234374 | F34: -82.043024 | G34: Oakwood | H34: BUCHANAN COUNTY | I34: VA | J34: 24631 | K34: SUNCOKE ENERGY INC (100%) | L34: 376555 | M34: C,Q
A35: 2023 | B35: NUCOR-YAMATO STEEL CO | C35: 1007642 | D35: 5929 E. STATE HWY. 18 | E35: 35.8925 | F35: -89.784167 | G35: BLYTHEVILLE | H35: MISSISSIPPI COUNTY | I35: AR | J35: 72316 | K35: NUCOR CORP (51%); YAMATO KOGYO (USA) CORP (49%) | L35: 375181 | M35: C,Q
A36: 2023 | B36: NUCOR STEEL - ARKANSAS | C36: 1007921 | D36: 7301 EAST COUNTY ROAD 142 | E36: 35.944388 | F36: -89.723636 | G36: BLYTHEVILLE | H36: MISSISSIPPI COUNTY | I36: AR | J36: 72315 | K36: NUCOR CORP (100%) | L36: 372241 | M36: C,Q
A37: 2023 | B37: US STEEL - IRVIN WORKS | C37: 1000802 | E37: 40.3372 | F37: -79.9108 | G37: West Mifflin | H37: ALLEGHENY COUNTY | I37: PA | J37: 15122 | K37: US STEEL CORP (100%) | L37: 361981 | M37: C,Q
A38: 2023 | B38: SSAB ALABAMA INCORPORATED | C38: 1005283 | D38: 12400 HIGHWAY 43 NORTH | E38: 30.943048 | F38: -88.012823 | G38: AXIS | H38: MOBILE COUNTY | I38: AL | J38: 36505 | K38: SSAB US HOLDING INC (100%) | L38: 335572 | M38: C,Q
A39: 2023 | B39: EES COKE BATTERY | C39: 1007392 | D39: 1400 ZUG ISLAND | E39: 42.283105 | F39: -83.113962 | G39: RIVER ROUGE | H39: WAYNE COUNTY | I39: MI | J39: 48218 | K39: DTE ENERGY CO (100%) | L39: 331929 | M39: C,Q
A40: 2023 | B40: STEEL DYNAMICS. INC. (SDI), STRUCTUAL AND RAIL DIVISION | C40: 1005602 | D40: 2601 COUNTY ROAD 700 EAST | E40: 41.124348 | F40: -85.395659 | G40: COLUMBIA CITY | H40: WHITLEY COUNTY | I40: IN | J40: 46725 | K40: STEEL DYNAMICS INC (100%) | L40: 327943 | M40: C,Q
A41: 2023 | B41: TIMKENSTEEL CORP (1576000613) | C41: 1003860 | D41: 1835 DUEBER AVENUE, S.W. | E41: 40.780505 | F41: -81.397259 | G41: CANTON | H41: STARK COUNTY | I41: OH | J41: 44706 | K41: TIMKENSTEEL CORP (100%) | L41: 320101 | M41: C,Q
...

Sheet Refining
A1: assume 3 scenarios: low-cost post-combustion techs, average of low and high, and high-cost
K3: Plot digitizer
M5: x | N5: y | S5: 177 | T5: 2013 refining emissions (same source), Mt CO2
L6: CCU | M6: 31.267606 | N6: 53.646477 | O6: =M6 -> 31.267606
L7: steam | M7: 52.957746 | N7: 57.948084 | O7: =M7-M6 -> 21.690141 | Q7: scenario | R7: Column1 | S7: co2 potl | T7: cost | U7: avoidance cost | Y7: cost | Z7: share | AA7: cum
L8: SMR | M8: 77.323944 | N8: 59.728059 | O8: =M8-M7 -> 24.366197 | Q8: low | R8: =L6 -> CCU | S8: =O6/3 -> 10.422535 | T8: =N6 -> 53.646477 | U8: =T8*cpi!$G$52+AVERAGE('Retrofit Cost vs SOC Data'!$B$9,'Retrofit Cost vs SOC Data'!$D$9,'Retrofit Cost vs SOC Data'!$F$9,'Retrofit Cost vs SOC Data'!$H$9,'Retrofit Cost vs SOC Data'!$J$9)*cpi!$G$56 -> 62.154951 | V8: =RANK(U8,$U$8:$U$49,1) -> 1 | X8: 1 | Y8: =INDEX($U$8:$U$49,MATCH(X8,$V$8:$V$49,0)) -> 62.154951 | Z8: =INDEX($S$8:$S$49,MATCH(X8,$V$8:$V$49,0)) -> 10.422535 | AA8: =IFERROR(Z8+AA7,Z8) -> 10.422535
L9: ACU | M9: 90.422535 | N9: 64.400494 | O9: =M9-M8 -> 13.098592 | Q9: low | R9: =L7 -> steam | S9: =O7/3 -> 7.2300469 | T9: =N7 -> 57.948084 | U9: =T9*cpi!$G$52+AVERAGE('Retrofit Cost vs SOC Data'!$B$9,'Retrofit Cost vs SOC Data'!$D$9,'Retrofit Cost vs SOC Data'!$F$9,'Retrofit Cost vs SOC Data'!$H$9,'Retrofit Cost vs SOC Data'!$J$9)*cpi!$G$56 -> 66.326784 | V9: =RANK(U9,$U$8:$U$49,1) -> 2 | X9: 2 | Y9: =INDEX($U$8:$U$49,MATCH(X9,$V$8:$V$49,0)) -> 66.326784 | Z9: =INDEX($S$8:$S$49,MATCH(X9,$V$8:$V$49,0)) -> 7.2300469 | AA9: =IFERROR(Z9+AA8,Z9) -> 17.652582
L10: CRU | M10: 101.83099 | N10: 65.438813 | O10: =M10-M9 -> 11.408451 | Q10: low | R10: =L8 -> SMR | S10: =O8/3 -> 8.1220657 | T10: =N8 -> 59.728059 | U10: =T10*cpi!$G$52+AVERAGE('Retrofit Cost vs SOC Data'!$B$9,'Retrofit Cost vs SOC Data'!$D$9,'Retrofit Cost vs SOC Data'!$F$9,'Retrofit Cost vs SOC Data'!$H$9,'Retrofit Cost vs SOC Data'!$J$9)*cpi!$G$56 -> 68.05306 | V10: =RANK(U10,$U$8:$U$49,1) -> 3 | X10: 3 | Y10: =INDEX($U$8:$U$49,MATCH(X10,$V$8:$V$49,0)) -> 68.05306 | Z10: =INDEX($S$8:$S$49,MATCH(X10,$V$8:$V$49,0)) -> 8.1220657 | AA10: =IFERROR(Z10+AA9,Z10) -> 25.774648
L11: HCU | M11: 106.05634 | N11: 67.737948 | O11: =M11-M10 -> 4.2253521 | Q11: low | R11: =L9 -> ACU | S11: =O9/3 -> 4.3661972 | T11: =N9 -> 64.400494 | U11: =T11*cpi!$G$52+AVERAGE('Retrofit Cost vs SOC Data'!$B$9,'Retrofit Cost vs SOC Data'!$D$9,'Retrofit Cost vs SOC Data'!$F$9,'Retrofit Cost vs SOC Data'!$H$9,'Retrofit Cost vs SOC Data'!$J$9)*cpi!$G$56 -> 72.584534 | V11: =RANK(U11,$U$8:$U$49,1) -> 4 | X11: 4 | Y11: =INDEX($U$8:$U$49,MATCH(X11,$V$8:$V$49,0)) -> 72.584534 | Z11: =INDEX($S$8:$S$49,MATCH(X11,$V$8:$V$49,0)) -> 4.3661972 | AA11: =IFERROR(Z11+AA10,Z11) -> 30.140845
L12: CKU | M12: 110.28169 | N12: 70.556242 | O12: =M12-M11 -> 4.2253521 | Q12: low | R12: =L10 -> CRU | S12: =O10/3 -> 3.8028169 | T12: =N10 -> 65.438813 | U12: =T12*cpi!$G$52+AVERAGE('Retrofit Cost vs SOC Data'!$B$9,'Retrofit Cost vs SOC Data'!$D$9,'Retrofit Cost vs SOC Data'!$F$9,'Retrofit Cost vs SOC Data'!$H$9,'Retrofit Cost vs SOC Data'!$J$9)*cpi!$G$56 -> 73.591529 | V12: =RANK(U12,$U$8:$U$49,1) -> 5 | X12: 5 | Y12: =INDEX($U$8:$U$49,MATCH(X12,$V$8:$V$49,0)) -> 73.591529 | Z12: =INDEX($S$8:$S$49,MATCH(X12,$V$8:$V$49,0)) -> 3.8028169 | AA12: =IFERROR(Z12+AA11,Z12) -> 33.943662
L13: VCU | M13: 114.22535 | N13: 73.300371 | O13: =M13-M12 -> 3.943662 | Q13: low | R13: =L11 -> HCU | S13: =O11/3 -> 1.4084507 | T13: =N11 -> 67.737948 | U13: =T13*cpi!$G$52+AVERAGE('Retrofit Cost vs SOC Data'!$B$9,'Retrofit Cost vs SOC Data'!$D$9,'Retrofit Cost vs SOC Data'!$F$9,'Retrofit Cost vs SOC Data'!$H$9,'Retrofit Cost vs SOC Data'!$J$9)*cpi!$G$56 -> 75.821302 | V13: =RANK(U13,$U$8:$U$49,1) -> 6 | X13: 6 | Y13: =INDEX($U$8:$U$49,MATCH(X13,$V$8:$V$49,0)) -> 75.821302 | Z13: =INDEX($S$8:$S$49,MATCH(X13,$V$8:$V$49,0)) -> 1.4084507 | AA13: =IFERROR(Z13+AA12,Z13) -> 35.352113
L14: CTU | M14: 115.6338 | N14: 78.862794 | O14: =M14-M13 -> 1.4084507 | Q14: low | R14: =L12 -> CKU | S14: =O12/3 -> 1.4084507 | T14: =N12 -> 70.556242 | U14: =T14*cpi!$G$52+AVERAGE('Retrofit Cost vs SOC Data'!$B$9,'Retrofit Cost vs SOC Data'!$D$9,'Retrofit Cost vs SOC Data'!$F$9,'Retrofit Cost vs SOC Data'!$H$9,'Retrofit Cost vs SOC Data'!$J$9)*cpi!$G$56 -> 78.554572 | V14: =RANK(U14,$U$8:$U$49,1) -> 8 | X14: 7 | Y14: =INDEX($U$8:$U$49,MATCH(X14,$V$8:$V$49,0)) -> 78.454969 | Z14: =INDEX($S$8:$S$49,MATCH(X14,$V$8:$V$49,0)) -> 10.438806 | AA14: =IFERROR(Z14+AA13,Z14) -> 45.790918
L15: GTU | M15: 117.88732 | N15: 81.681088 | O15: =M15-M14 -> 2.2535211 | Q15: low | R15: =L13 -> VCU | S15: =O13/3 -> 1.314554 | T15: =N13 -> 73.300371 | U15: =T15*cpi!$G$52+AVERAGE('Retrofit Cost vs SOC Data'!$B$9,'Retrofit Cost vs SOC Data'!$D$9,'Retrofit Cost vs SOC Data'!$F$9,'Retrofit Cost vs SOC Data'!$H$9,'Retrofit Cost vs SOC Data'!$J$9)*cpi!$G$56 -> 81.215914 | V15: =RANK(U15,$U$8:$U$49,1) -> 9 | X15: 8 | Y15: =INDEX($U$8:$U$49,MATCH(X15,$V$8:$V$49,0)) -> 78.554572 | Z15: =INDEX($S$8:$S$49,MATCH(X15,$V$8:$V$49,0)) -> 1.4084507 | AA15: =IFERROR(Z15+AA14,Z15) -> 47.199369
L16: NTU | M16: 121.69014 | N16: 82.051916 | O16: =M16-M15 -> 3.8028169 | Q16: low | R16: =L14 -> CTU | S16: =O14/3 -> 0.46948357 | T16: =N14 -> 78.862794 | U16: =T16*cpi!$G$52+AVERAGE('Retrofit Cost vs SOC Data'!$B$9,'Retrofit Cost vs SOC Data'!$D$9,'Retrofit Cost vs SOC Data'!$F$9,'Retrofit Cost vs SOC Data'!$H$9,'Retrofit Cost vs SOC Data'!$J$9)*cpi!$G$56 -> 86.610526 | V16: =RANK(U16,$U$8:$U$49,1) -> 11 | X16: 9 | Y16: =INDEX($U$8:$U$49,MATCH(X16,$V$8:$V$49,0)) -> 81.215914 | Z16: =INDEX($S$8:$S$49,MATCH(X16,$V$8:$V$49,0)) -> 1.314554 | AA16: =IFERROR(Z16+AA15,Z16) -> 48.513923
L17: KTU | M17: 122.8169 | N17: 90.061805 | O17: =M17-M16 -> 1.1267606 | Q17: low | R17: =L15 -> GTU | S17: =O15/3 -> 0.75117371 | T17: =N15 -> 81.681088 | U17: =T17*cpi!$G$52+AVERAGE('Retrofit Cost vs SOC Data'!$B$9,'Retrofit Cost vs SOC Data'!$D$9,'Retrofit Cost vs SOC Data'!$F$9,'Retrofit Cost vs SOC Data'!$H$9,'Retrofit Cost vs SOC Data'!$J$9)*cpi!$G$56 -> 89.343796 | V17: =RANK(U17,$U$8:$U$49,1) -> 12 | X17: 10 | Y17: =INDEX($U$8:$U$49,MATCH(X17,$V$8:$V$49,0)) -> 84.507484 | Z17: =INDEX($S$8:$S$49,MATCH(X17,$V$8:$V$49,0)) -> 8.0983724 | AA17: =IFERROR(Z17+AA16,Z17) -> 56.612295
L18: DTU | M18: 125.35211 | N18: 90.210136 | O18: =M18-M17 -> 2.5352113 | Q18: low | R18: =L16 -> NTU | S18: =O16/3 -> 1.2676056 | T18: =N16 -> 82.051916 | U18: =T18*cpi!$G$52+AVERAGE('Retrofit Cost vs SOC Data'!$B$9,'Retrofit Cost vs SOC Data'!$D$9,'Retrofit Cost vs SOC Data'!$F$9,'Retrofit Cost vs SOC Data'!$H$9,'Retrofit Cost vs SOC Data'!$J$9)*cpi!$G$56 -> 89.703437 | V18: =RANK(U18,$U$8:$U$49,1) -> 13 | X18: 11 | Y18: =INDEX($U$8:$U$49,MATCH(X18,$V$8:$V$49,0)) -> 86.610526 | Z18: =INDEX($S$8:$S$49,MATCH(X18,$V$8:$V$49,0)) -> 0.46948357 | AA18: =IFERROR(Z18+AA17,Z18) -> 57.081779
L19: ISU | M19: 126.90141 | N19: 95.846724 | O19: =M19-M18 -> 1.5492958 | Q19: low | R19: =L17 -> KTU | S19: =O17/3 -> 0.37558685 | T19: =N17 -> 90.061805 | U19: =T19*cpi!$G$52+AVERAGE('Retrofit Cost vs SOC Data'!$B$9,'Retrofit Cost vs SOC Data'!$D$9,'Retrofit Cost vs SOC Data'!$F$9,'Retrofit Cost vs SOC Data'!$H$9,'Retrofit Cost vs SOC Data'!$J$9)*cpi!$G$56 -> 97.471678 | V19: =RANK(U19,$U$8:$U$49,1) -> 15 | X19: 12 | Y19: =INDEX($U$8:$U$49,MATCH(X19,$V$8:$V$49,0)) -> 89.343796 | Z19: =INDEX($S$8:$S$49,MATCH(X19,$V$8:$V$49,0)) -> 0.75117371 | AA19: =IFERROR(Z19+AA18,Z19) -> 57.832953
Q20: low | R20: =L18 -> DTU | S20: =O18/3 -> 0.84507042 | T20: =N18 -> 90.210136 | U20: =T20*cpi!$G$52+AVERAGE('Retrofit Cost vs SOC Data'!$B$9,'Retrofit Cost vs SOC Data'!$D$9,'Retrofit Cost vs SOC Data'!$F$9,'Retrofit Cost vs SOC Data'!$H$9,'Retrofit Cost vs SOC Data'!$J$9)*cpi!$G$56 -> 97.615534 | V20: =RANK(U20,$U$8:$U$49,1) -> 16 | X20: 13 | Y20: =INDEX($U$8:$U$49,MATCH(X20,$V$8:$V$49,0)) -> 89.703437 | Z20: =INDEX($S$8:$S$49,MATCH(X20,$V$8:$V$49,0)) -> 1.2676056 | AA20: =IFERROR(Z20+AA19,Z20) -> 59.100558
P21: =SUM(S36:S49) -> 42.287048 | Q21: low | R21: =L19 -> ISU | S21: =O19/3 -> 0.51643192 | T21: =N19 -> 95.846724 | U21: =T21*cpi!$G$52+AVERAGE('Retrofit Cost vs SOC Data'!$B$9,'Retrofit Cost vs SOC Data'!$D$9,'Retrofit Cost vs SOC Data'!$F$9,'Retrofit Cost vs SOC Data'!$H$9,'Retrofit Cost vs SOC Data'!$J$9)*cpi!$G$56 -> 103.08207 | V21: =RANK(U21,$U$8:$U$49,1) -> 18 | X21: 14 | Y21: =INDEX($U$8:$U$49,MATCH(X21,$V$8:$V$49,0)) -> 94.754988 | Z21: =INDEX($S$8:$S$49,MATCH(X21,$V$8:$V$49,0)) -> 10.455076 | AA21: =IFERROR(Z21+AA20,Z21) -> 69.555634
M22: x | N22: y | Q22: average | R22: =L6 -> CCU | S22: =AVERAGEIF($L$6:$L$36,R22,$O$6:$O$36)/3 -> 10.438806 | T22: =AVERAGEIF($L$6:$L$36,R22,$N$6:$N$36) -> 70.453542 | U22: =T22*cpi!$G$52+AVERAGE('Retrofit Cost vs SOC Data'!$B$9,'Retrofit Cost vs SOC Data'!$D$9,'Retrofit Cost vs SOC Data'!$F$9,'Retrofit Cost vs SOC Data'!$H$9,'Retrofit Cost vs SOC Data'!$J$9)*cpi!$G$56 -> 78.454969 | V22: =RANK(U22,$U$8:$U$49,1) -> 7 | X22: 15 | Y22: =INDEX($U$8:$U$49,MATCH(X22,$V$8:$V$49,0)) -> 97.471678 | Z22: =INDEX($S$8:$S$49,MATCH(X22,$V$8:$V$49,0)) -> 0.37558685 | AA22: =IFERROR(Z22+AA21,Z22) -> 69.931221
L23: CCU | M23: 31.365228 | N23: 87.260606 | O23: =M23 -> 31.365228 | Q23: average | R23: =L8 -> SMR | S23: =AVERAGEIF($L$6:$L$36,R23,$O$6:$O$36)/3 -> 8.0983724 | T23: =AVERAGEIF($L$6:$L$36,R23,$N$6:$N$36) -> 76.694333 | U23: =T23*cpi!$G$52+AVERAGE('Retrofit Cost vs SOC Data'!$B$9,'Retrofit Cost vs SOC Data'!$D$9,'Retrofit Cost vs SOC Data'!$F$9,'Retrofit Cost vs SOC Data'!$H$9,'Retrofit Cost vs SOC Data'!$J$9)*cpi!$G$56 -> 84.507484 | V23: =RANK(U23,$U$8:$U$49,1) -> 10 | X23: 16 | Y23: =INDEX($U$8:$U$49,MATCH(X23,$V$8:$V$49,0)) -> 97.615534 | Z23: =INDEX($S$8:$S$49,MATCH(X23,$V$8:$V$49,0)) -> 0.84507042 | AA23: =IFERROR(Z23+AA22,Z23) -> 70.776291
L24: SMR | M24: 55.589265 | N24: 93.660606 | O24: =M24-M23 -> 24.224037 | Q24: average | R24: =L7 -> steam | S24: =AVERAGEIF($L$6:$L$36,R24,$O$6:$O$36)/3 -> 7.232293 | T24: =AVERAGEIF($L$6:$L$36,R24,$N$6:$N$36) -> 96.55586 | U24: =T24*cpi!$G$52+AVERAGE('Retrofit Cost vs SOC Data'!$B$9,'Retrofit Cost vs SOC Data'!$D$9,'Retrofit Cost vs SOC Data'!$F$9,'Retrofit Cost vs SOC Data'!$H$9,'Retrofit Cost vs SOC Data'!$J$9)*cpi!$G$56 -> 103.76982 | V24: =RANK(U24,$U$8:$U$49,1) -> 19 | X24: 17 | Y24: =INDEX($U$8:$U$49,MATCH(X24,$V$8:$V$49,0)) -> 100.96191 | Z24: =INDEX($S$8:$S$49,MATCH(X24,$V$8:$V$49,0)) -> 8.0746791 | AA24: =IFERROR(Z24+AA23,Z24) -> 78.85097
L25: steam | M25: 77.292882 | N25: 135.16364 | O25: =M25-M24 -> 21.703617 | Q25: average | R25: =L9 -> ACU | S25: =AVERAGEIF($L$6:$L$36,R25,$O$6:$O$36)/3 -> 4.4001348 | T25: =AVERAGEIF($L$6:$L$36,R25,$N$6:$N$36) -> 107.15176 | U25: =T25*cpi!$G$52+AVERAGE('Retrofit Cost vs SOC Data'!$B$9,'Retrofit Cost vs SOC Data'!$D$9,'Retrofit Cost vs SOC Data'!$F$9,'Retrofit Cost vs SOC Data'!$H$9,'Retrofit Cost vs SOC Data'!$J$9)*cpi!$G$56 -> 114.04606 | V25: =RANK(U25,$U$8:$U$49,1) -> 20 | X25: 18 | Y25: =INDEX($U$8:$U$49,MATCH(X25,$V$8:$V$49,0)) -> 103.08207 | Z25: =INDEX($S$8:$S$49,MATCH(X25,$V$8:$V$49,0)) -> 0.51643192 | AA25: =IFERROR(Z25+AA24,Z25) -> 79.367402
L26: ACU | M26: 90.595099 | N26: 149.90303 | O26: =M26-M25 -> 13.302217 | Q26: average | R26: =L10 -> CRU | S26: =AVERAGEIF($L$6:$L$36,R26,$O$6:$O$36)/3 -> 3.8150607 | T26: =AVERAGEIF($L$6:$L$36,R26,$N$6:$N$36) -> 108.83456 | U26: =T26*cpi!$G$52+AVERAGE('Retrofit Cost vs SOC Data'!$B$9,'Retrofit Cost vs SOC Data'!$D$9,'Retrofit Cost vs SOC Data'!$F$9,'Retrofit Cost vs SOC Data'!$H$9,'Retrofit Cost vs SOC Data'!$J$9)*cpi!$G$56 -> 115.67808 | V26: =RANK(U26,$U$8:$U$49,1) -> 21 | X26: 19 | Y26: =INDEX($U$8:$U$49,MATCH(X26,$V$8:$V$49,0)) -> 103.76982 | Z26: =INDEX($S$8:$S$49,MATCH(X26,$V$8:$V$49,0)) -> 7.232293 | AA26: =IFERROR(Z26+AA25,Z26) -> 86.599695
L27: CRU | M27: 102.07701 | N27: 152.2303 | O27: =M27-M26 -> 11.481914 | Q27: average | R27: =L12 -> CKU | S27: =AVERAGEIF($L$6:$L$36,R27,$O$6:$O$36)/3 -> 1.3810048 | T27: =AVERAGEIF($L$6:$L$36,R27,$N$6:$N$36) -> 114.10842 | U27: =T27*cpi!$G$52+AVERAGE('Retrofit Cost vs SOC Data'!$B$9,'Retrofit Cost vs SOC Data'!$D$9,'Retrofit Cost vs SOC Data'!$F$9,'Retrofit Cost vs SOC Data'!$H$9,'Retrofit Cost vs SOC Data'!$J$9)*cpi!$G$56 -> 120.79284 | V27: =RANK(U27,$U$8:$U$49,1) -> 22 | X27: 20 | Y27: =INDEX($U$8:$U$49,MATCH(X27,$V$8:$V$49,0)) -> 114.04606 | Z27: =INDEX($S$8:$S$49,MATCH(X27,$V$8:$V$49,0)) -> 4.4001348 | AA27: =IFERROR(Z27+AA26,Z27) -> 90.99983
L28: CKU | M28: 106.13769 | N28: 157.66061 | O28: =M28-M27 -> 4.0606768 | Q28: average | R28: =L13 -> VCU | S28: =AVERAGEIF($L$6:$L$36,R28,$O$6:$O$36)/3 -> 1.3807309 | T28: =AVERAGEIF($L$6:$L$36,R28,$N$6:$N$36) -> 118.68049 | U28: =T28*cpi!$G$52+AVERAGE('Retrofit Cost vs SOC Data'!$B$9,'Retrofit Cost vs SOC Data'!$D$9,'Retrofit Cost vs SOC Data'!$F$9,'Retrofit Cost vs SOC Data'!$H$9,'Retrofit Cost vs SOC Data'!$J$9)*cpi!$G$56 -> 125.22698 | V28: =RANK(U28,$U$8:$U$49,1) -> 23 | X28: 21 | Y28: =INDEX($U$8:$U$49,MATCH(X28,$V$8:$V$49,0)) -> 115.67808 | Z28: =INDEX($S$8:$S$49,MATCH(X28,$V$8:$V$49,0)) -> 3.8150607 | AA28: =IFERROR(Z28+AA27,Z28) -> 94.814891
L29: VCU | M29: 110.47841 | N29: 164.06061 | O29: =M29-M28 -> 4.3407235 | Q29: average | R29: =L11 -> HCU | S29: =AVERAGEIF($L$6:$L$36,R29,$O$6:$O$36)/3 -> 1.3109931 | T29: =AVERAGEIF($L$6:$L$36,R29,$N$6:$N$36) -> 119.09928 | U29: =T29*cpi!$G$52+AVERAGE('Retrofit Cost vs SOC Data'!$B$9,'Retrofit Cost vs SOC Data'!$D$9,'Retrofit Cost vs SOC Data'!$F$9,'Retrofit Cost vs SOC Data'!$H$9,'Retrofit Cost vs SOC Data'!$J$9)*cpi!$G$56 -> 125.63313 | V29: =RANK(U29,$U$8:$U$49,1) -> 24 | X29: 22 | Y29: =INDEX($U$8:$U$49,MATCH(X29,$V$8:$V$49,0)) -> 120.79284 | Z29: =INDEX($S$8:$S$49,MATCH(X29,$V$8:$V$49,0)) -> 1.3810048 | AA29: =IFERROR(Z29+AA28,Z29) -> 96.195896
L30: HCU | M30: 114.11902 | N30: 170.46061 | O30: =M30-M29 -> 3.6406068 | Q30: average | R30: =L14 -> CTU | S30: =AVERAGEIF($L$6:$L$36,R30,$O$6:$O$36)/3 -> 0.46811401 | T30: =AVERAGEIF($L$6:$L$36,R30,$N$6:$N$36) -> 131.0617 | U30: =T30*cpi!$G$52+AVERAGE('Retrofit Cost vs SOC Data'!$B$9,'Retrofit Cost vs SOC Data'!$D$9,'Retrofit Cost vs SOC Data'!$F$9,'Retrofit Cost vs SOC Data'!$H$9,'Retrofit Cost vs SOC Data'!$J$9)*cpi!$G$56 -> 137.23466 | V30: =RANK(U30,$U$8:$U$49,1) -> 25 | X30: 23 | Y30: =INDEX($U$8:$U$49,MATCH(X30,$V$8:$V$49,0)) -> 125.22698 | Z30: =INDEX($S$8:$S$49,MATCH(X30,$V$8:$V$49,0)) -> 1.3807309 | AA30: =IFERROR(Z30+AA29,Z30) -> 97.576627
L31: CTU | M31: 115.51925 | N31: 183.26061 | O31: =M31-M30 -> 1.4002334 | Q31: average | R31: =L15 -> GTU | S31: =AVERAGEIF($L$6:$L$36,R31,$O$6:$O$36)/3 -> 0.79565687 | T31: =AVERAGEIF($L$6:$L$36,R31,$N$6:$N$36) -> 135.86479 | U31: =T31*cpi!$G$52+AVERAGE('Retrofit Cost vs SOC Data'!$B$9,'Retrofit Cost vs SOC Data'!$D$9,'Retrofit Cost vs SOC Data'!$F$9,'Retrofit Cost vs SOC Data'!$H$9,'Retrofit Cost vs SOC Data'!$J$9)*cpi!$G$56 -> 141.89285 | V31: =RANK(U31,$U$8:$U$49,1) -> 27 | X31: 24 | Y31: =INDEX($U$8:$U$49,MATCH(X31,$V$8:$V$49,0)) -> 125.63313 | Z31: =INDEX($S$8:$S$49,MATCH(X31,$V$8:$V$49,0)) -> 1.3109931 | AA31: =IFERROR(Z31+AA30,Z31) -> 98.88762
