Workbook

Sheet About
A1: CPRS Cement Preexisting Capacity Overhaul Decision Schedule
A3: Sources: | B3: U.S. kiln fleet age cohorts
B4: Princeton University, Net-Zero America project
B5: Net-Zero America: Potential Pathways, Infrastructure, and Impacts - Annex K (Industry), section 6.3 on cement
B6: 2021
B7: https://netzeroamerica.princeton.edu/img/Princeton_NZA_Annex_K.pdf
B8: About 92 U.S. kilns installed before 2000 with roughly 49.6 million metric tons per year of clinker capacity, and about 38 kilns installed since 2000 with roughly 46.7 million metric tons per year. The annex also assumes 7% per year turnover of the older cohort after 2025 and a 35-year kiln campaign. The cohort totals and kiln counts are on the 'NZA Annex K Cohorts' tab. The annex does not give kiln-level install years, so the timing within each cohort is our approximation.
B10: Why decision timing is spread out
B11: European Cement Research Academy (ECRA) and the Cement Sustainability Initiative (WBCSD)
B12: Development of State of the Art Techniques in Cement Manufacturing: Trying to Look Ahead (CSI/ECRA Technology Papers)
B13: 2017
B14: https://www.wbcsd.org/Sector-Projects/Cement-Sustainability-Initiative/Resources/Development-of-State-of-the-Art-Techniques-in-Cement-Manufacturing
B15: Page 9 describes kiln lifetimes of usually 30 to 50 years, with most original equipment replaced piecemeal after 20 to 30 years. We use this only to justify spreading each cohort's decisions over a window of plus or minus 5 years instead of putting them all in one year; the 5-year half-width is our judgment.
A18: Notes:
A19: Purpose and layout | B19: This file tells the EPS how much existing cement kiln capacity, in metric tons of clinker capacity per year, reaches an overhaul-or-replace decision in each year from 2026 to 2050. It applies to the capacity the region has at the start of the simulation; capacity built during the run is tracked separately. The file says only how much capacity comes up for a decision, by kiln pathway. Whether that capacity is overhauled or replaced, and with which technology, is decided inside the model by comparing costs (see the CRSW file). The tabs run from inputs to output. 'NZA Annex K Cohorts' holds the two fleet cohorts. 'Derivation' turns them into a year-by-year schedule, and 'Smoothing' spreads that schedule over neighboring years. 'Checks' confirms the smoothing keeps the total capacity unchanged and puts nothing before 2026. The 'CPRS' tab reads from 'Smoothing' (all capacity on the dry kiln with precalciner row, zeros for the other three pathways) and is what gets exported to CPRS.csv.
A20: U.S. values | B20: The older cohort (49.6 million metric tons) comes up for decision at 7% of its capacity per year starting in 2026, which is 3.472 million metric tons per year through 2039, with the remaining 0.992 million metric tons in 2040. The newer cohort (46.7 million metric tons) was installed over roughly 2000-2010 and reaches a 35-year campaign end across 2036-2045; we spread it evenly over those ten years at 4.67 million metric tons per year. The two cohorts overlap in 2036-2040. Turnover before 2025 is already reflected in the start-year capacity the model begins with, so nothing is scheduled before 2026.
A21: Smoothing | B21: Real kilns do not all reach a decision on the same date: campaign timing varies, and ECRA documents rolling 20-30 year component replacement cycles. Using the cohort schedule as-is would create sharp steps and a spike of decisions in the late 2030s, so each year's capacity is spread over the surrounding 11 years with triangular weights (the year itself counts most, years 5 away count least). Any weight that would fall before 2026 or after 2050 is shifted onto the years that remain, so the total capacity is unchanged. The unsmoothed schedule stays visible on the 'Derivation' tab.
A22: Limits and other regions | B22: The cohort timing is an approximation, because kiln-level install years come from the Portland Cement Association's proprietary plant data, which we do not have. If that data becomes available, the schedule could be built kiln by kiln and the cohort assumptions dropped. All capacity is assigned to the dry kiln with precalciner pathway, matching the start-year capacity by pathway; the other three pathways are zero in every year. For a non-U.S. region, replace the cohort sizes and timing on the 'NZA Annex K Cohorts' and 'Derivation' tabs with regional fleet-age data; the smoothing and export tabs will follow.

Sheet NZA Annex K Cohorts
A1: Cohort | B1: Kiln count | C1: Nameplate capacity (Mt/yr) | D1: Convention
A2: Pre-2000 | B2: 92 | C2: 49.6 | D2: 7%/yr turnover from 2026 (NZA post-2025 rate)
A3: Post-2000 | B3: 38 | C3: 46.7 | D3: 35-yr campaign, staggered installs ~2000-2010

Sheet Derivation
A1: Pre-2000 cohort: 7%/yr of 49.6 Mt, 2026-2039, remainder in 2040
A3: Pre-2000 cohort nameplate (Mt) | B3: ='NZA Annex K Cohorts'!C2 -> 49.6
A4: Annual rate = 7% x cohort | B4: =0.07*B3 -> 3.472
A5: Annual rate (t/yr) | B5: =B4*1000000 -> 3472000
A6: Years at full rate (2026-2039) | B6: 14
A7: Cumulative at full rate (Mt) | B7: =B5*B6/1000000 -> 48.608
A8: Remainder in 2040 (Mt) = cohort - cumulative | B8: =B3-B7 -> 0.992
A9: Remainder in 2040 (t/yr) | B9: =B8*1000000 -> 992000
A11: Post-2000 cohort: 35-yr staggered campaign end, 2036-2045
A13: Post-2000 cohort nameplate (Mt) | B13: ='NZA Annex K Cohorts'!C3 -> 46.7
A14: Years spanned (2036-2045) | B14: 10
A15: Annual rate = cohort / years (Mt/yr) | B15: =B13/B14 -> 4.67
A16: Annual rate (t/yr) | B16: =B15*1000000 -> 4670000
A18: Year-by-year schedule (t/yr), pre-2000 + post-2000
A19: Year | B19: Pre-2000 component | C19: Post-2000 component | D19: Total (dry kiln with precalciner)
A20: 2021 | B20: 0 | C20: 0 | D20: =B20+C20 -> 0
A21: 2022 | B21: 0 | C21: 0 | D21: =B21+C21 -> 0
A22: 2023 | B22: 0 | C22: 0 | D22: =B22+C22 -> 0
A23: 2024 | B23: 0 | C23: 0 | D23: =B23+C23 -> 0
A24: 2025 | B24: 0 | C24: 0 | D24: =B24+C24 -> 0
A25: 2026 | B25: =$B$5 -> 3472000 | C25: 0 | D25: =B25+C25 -> 3472000
A26: 2027 | B26: =$B$5 -> 3472000 | C26: 0 | D26: =B26+C26 -> 3472000
A27: 2028 | B27: =$B$5 -> 3472000 | C27: 0 | D27: =B27+C27 -> 3472000
A28: 2029 | B28: =$B$5 -> 3472000 | C28: 0 | D28: =B28+C28 -> 3472000
A29: 2030 | B29: =$B$5 -> 3472000 | C29: 0 | D29: =B29+C29 -> 3472000
A30: 2031 | B30: =$B$5 -> 3472000 | C30: 0 | D30: =B30+C30 -> 3472000
A31: 2032 | B31: =$B$5 -> 3472000 | C31: 0 | D31: =B31+C31 -> 3472000
A32: 2033 | B32: =$B$5 -> 3472000 | C32: 0 | D32: =B32+C32 -> 3472000
A33: 2034 | B33: =$B$5 -> 3472000 | C33: 0 | D33: =B33+C33 -> 3472000
A34: 2035 | B34: =$B$5 -> 3472000 | C34: 0 | D34: =B34+C34 -> 3472000
A35: 2036 | B35: =$B$5 -> 3472000 | C35: =$B$16 -> 4670000 | D35: =B35+C35 -> 8142000
A36: 2037 | B36: =$B$5 -> 3472000 | C36: =$B$16 -> 4670000 | D36: =B36+C36 -> 8142000
A37: 2038 | B37: =$B$5 -> 3472000 | C37: =$B$16 -> 4670000 | D37: =B37+C37 -> 8142000
A38: 2039 | B38: =$B$5 -> 3472000 | C38: =$B$16 -> 4670000 | D38: =B38+C38 -> 8142000
A39: 2040 | B39: =$B$9 -> 992000 | C39: =$B$16 -> 4670000 | D39: =B39+C39 -> 5662000
A40: 2041 | B40: 0 | C40: =$B$16 -> 4670000 | D40: =B40+C40 -> 4670000
A41: 2042 | B41: 0 | C41: =$B$16 -> 4670000 | D41: =B41+C41 -> 4670000
A42: 2043 | B42: 0 | C42: =$B$16 -> 4670000 | D42: =B42+C42 -> 4670000
A43: 2044 | B43: 0 | C43: =$B$16 -> 4670000 | D43: =B43+C43 -> 4670000
A44: 2045 | B44: 0 | C44: =$B$16 -> 4670000 | D44: =B44+C44 -> 4670000
...

Sheet Smoothing
A1: Campaign-timing smoothing: the Derivation tab's step schedule is spread with a +/-5-year triangular kernel. ECRA (2017, p.9) documents rolling 20-30 year kiln component-replacement cycles, so decisions do not all fall in one year. Kernel weight that would land before 2026 is moved onto 2026 and later (turnover before 2026 is already reflected in the USGS 2025 capacity the fleet starts from). Total capacity is conserved exactly.
A3: Kernel offset d | B3: -5 | C3: -4 | D3: -3 | E3: -2 | F3: -1 | G3: 0 | H3: 1 | I3: 2 | J3: 3 | K3: 4 | L3: 5
A4: Weight (6-ABS(d))/36 | B4: =(6-ABS(B3))/36 -> 0.027777778 | C4: =(6-ABS(C3))/36 -> 0.055555556 | D4: =(6-ABS(D3))/36 -> 0.083333333 | E4: =(6-ABS(E3))/36 -> 0.11111111 | F4: =(6-ABS(F3))/36 -> 0.13888889 | G4: =(6-ABS(G3))/36 -> 0.16666667 | H4: =(6-ABS(H3))/36 -> 0.13888889 | I4: =(6-ABS(I3))/36 -> 0.11111111 | ... L4: =(6-ABS(L3))/36 -> 0.027777778
A6: Source rows: raw = Derivation total; scale renormalizes each source year's kernel onto the window [2026, 2050].
A7: Year | B7: Raw (t/yr, Derivation) | C7: Edge scale
A8: 2021 | B8: =Derivation!D20 -> 0 | C8: =1/SUMPRODUCT($B$4:$L$4*((A8+$B$3:$L$3>=2026)*(A8+$B$3:$L$3<=2050))) -> 36
A9: 2022 | B9: =Derivation!D21 -> 0 | C9: =1/SUMPRODUCT($B$4:$L$4*((A9+$B$3:$L$3>=2026)*(A9+$B$3:$L$3<=2050))) -> 12
A10: 2023 | B10: =Derivation!D22 -> 0 | C10: =1/SUMPRODUCT($B$4:$L$4*((A10+$B$3:$L$3>=2026)*(A10+$B$3:$L$3<=2050))) -> 6
A11: 2024 | B11: =Derivation!D23 -> 0 | C11: =1/SUMPRODUCT($B$4:$L$4*((A11+$B$3:$L$3>=2026)*(A11+$B$3:$L$3<=2050))) -> 3.6
A12: 2025 | B12: =Derivation!D24 -> 0 | C12: =1/SUMPRODUCT($B$4:$L$4*((A12+$B$3:$L$3>=2026)*(A12+$B$3:$L$3<=2050))) -> 2.4
A13: 2026 | B13: =Derivation!D25 -> 3472000 | C13: =1/SUMPRODUCT($B$4:$L$4*((A13+$B$3:$L$3>=2026)*(A13+$B$3:$L$3<=2050))) -> 1.7142857
A14: 2027 | B14: =Derivation!D26 -> 3472000 | C14: =1/SUMPRODUCT($B$4:$L$4*((A14+$B$3:$L$3>=2026)*(A14+$B$3:$L$3<=2050))) -> 1.3846154
A15: 2028 | B15: =Derivation!D27 -> 3472000 | C15: =1/SUMPRODUCT($B$4:$L$4*((A15+$B$3:$L$3>=2026)*(A15+$B$3:$L$3<=2050))) -> 1.2
A16: 2029 | B16: =Derivation!D28 -> 3472000 | C16: =1/SUMPRODUCT($B$4:$L$4*((A16+$B$3:$L$3>=2026)*(A16+$B$3:$L$3<=2050))) -> 1.0909091
A17: 2030 | B17: =Derivation!D29 -> 3472000 | C17: =1/SUMPRODUCT($B$4:$L$4*((A17+$B$3:$L$3>=2026)*(A17+$B$3:$L$3<=2050))) -> 1.0285714
A18: 2031 | B18: =Derivation!D30 -> 3472000 | C18: =1/SUMPRODUCT($B$4:$L$4*((A18+$B$3:$L$3>=2026)*(A18+$B$3:$L$3<=2050))) -> 1
A19: 2032 | B19: =Derivation!D31 -> 3472000 | C19: =1/SUMPRODUCT($B$4:$L$4*((A19+$B$3:$L$3>=2026)*(A19+$B$3:$L$3<=2050))) -> 1
... A37: 2050 | B37: =Derivation!D49 -> 0 | C37: =1/SUMPRODUCT($B$4:$L$4*((A37+$B$3:$L$3>=2026)*(A37+$B$3:$L$3<=2050))) -> 1.7142857
A40: Smoothed schedule: smoothed(Y) = SUM over d of raw(Y-d) x weight(d) x scale(Y-d); columns E..O are the d = -5..+5 terms.
A41: Year | B41: Smoothed (t/yr) | C41: Smoothed (t/yr) | D41: Shipped (t/yr) | E41: term d=-5 | F41: term d=-4 | G41: term d=-3 | H41: term d=-2 | I41: term d=-1 | J41: term d=0 | K41: term d=1 | L41: term d=2 | M41: term d=3 | N41: term d=4 | O41: term d=5
A42: 2021 | B42: =IF(A42<2026,0,E42+F42+G42+H42+I42+J42+K42+L42+M42+N42+O42) -> 0 | C42: =(B42/1000)*1000 -> 0 | D42: =C42+IF(A42=INDEX($A$42:$A$71,MATCH(MAX($C$42:$C$71),$C$42:$C$71,0)),SUM($B$8:$B$37)-SUM($C$42:$C$71),0) -> 0 | E42: =IFERROR(INDEX($B$8:$B$37,MATCH(A42-B$3,$A$8:$A$37,0))*INDEX($C$8:$C$37,MATCH(A42-B$3,$A$8:$A$37,0))*B$4,0) -> 165333.33 | F42: =IFERROR(INDEX($B$8:$B$37,MATCH(A42-C$3,$A$8:$A$37,0))*INDEX($C$8:$C$37,MATCH(A42-C$3,$A$8:$A$37,0))*C$4,0) -> 0 | G42: =IFERROR(INDEX($B$8:$B$37,MATCH(A42-D$3,$A$8:$A$37,0))*INDEX($C$8:$C$37,MATCH(A42-D$3,$A$8:$A$37,0))*D$4,0) -> 0 | H42: =IFERROR(INDEX($B$8:$B$37,MATCH(A42-E$3,$A$8:$A$37,0))*INDEX($C$8:$C$37,MATCH(A42-E$3,$A$8:$A$37,0))*E$4,0) -> 0 | I42: =IFERROR(INDEX($B$8:$B$37,MATCH(A42-F$3,$A$8:$A$37,0))*INDEX($C$8:$C$37,MATCH(A42-F$3,$A$8:$A$37,0))*F$4,0) -> 0 | J42: =IFERROR(INDEX($B$8:$B$37,MATCH(A42-G$3,$A$8:$A$37,0))*INDEX($C$8:$C$37,MATCH(A42-G$3,$A$8:$A$37,0))*G$4,0) -> 0 | K42: =IFERROR(INDEX($B$8:$B$37,MATCH(A42-H$3,$A$8:$A$37,0))*INDEX($C$8:$C$37,MATCH(A42-H$3,$A$8:$A$37,0))*H$4,0) -> 0 | L42: =IFERROR(INDEX($B$8:$B$37,MATCH(A42-I$3,$A$8:$A$37,0))*INDEX($C$8:$C$37,MATCH(A42-I$3,$A$8:$A$37,0))*I$4,0) -> 0 | M42: =IFERROR(INDEX($B$8:$B$37,MATCH(A42-J$3,$A$8:$A$37,0))*INDEX($C$8:$C$37,MATCH(A42-J$3,$A$8:$A$37,0))*J$4,0) -> 0 | N42: =IFERROR(INDEX($B$8:$B$37,MATCH(A42-K$3,$A$8:$A$37,0))*INDEX($C$8:$C$37,MATCH(A42-K$3,$A$8:$A$37,0))*K$4,0) -> 0 | O42: =IFERROR(INDEX($B$8:$B$37,MATCH(A42-L$3,$A$8:$A$37,0))*INDEX($C$8:$C$37,MATCH(A42-L$3,$A$8:$A$37,0))*L$4,0) -> 0
A43: 2022 | B43: =IF(A43<2026,0,E43+F43+G43+H43+I43+J43+K43+L43+M43+N43+O43) -> 0 | C43: =(B43/1000)*1000 -> 0 | D43: =C43+IF(A43=INDEX($A$42:$A$71,MATCH(MAX($C$42:$C$71),$C$42:$C$71,0)),SUM($B$8:$B$37)-SUM($C$42:$C$71),0) -> 0 | E43: =IFERROR(INDEX($B$8:$B$37,MATCH(A43-B$3,$A$8:$A$37,0))*INDEX($C$8:$C$37,MATCH(A43-B$3,$A$8:$A$37,0))*B$4,0) -> 133538.46 | F43: =IFERROR(INDEX($B$8:$B$37,MATCH(A43-C$3,$A$8:$A$37,0))*INDEX($C$8:$C$37,MATCH(A43-C$3,$A$8:$A$37,0))*C$4,0) -> 330666.67 | G43: =IFERROR(INDEX($B$8:$B$37,MATCH(A43-D$3,$A$8:$A$37,0))*INDEX($C$8:$C$37,MATCH(A43-D$3,$A$8:$A$37,0))*D$4,0) -> 0 | H43: =IFERROR(INDEX($B$8:$B$37,MATCH(A43-E$3,$A$8:$A$37,0))*INDEX($C$8:$C$37,MATCH(A43-E$3,$A$8:$A$37,0))*E$4,0) -> 0 | I43: =IFERROR(INDEX($B$8:$B$37,MATCH(A43-F$3,$A$8:$A$37,0))*INDEX($C$8:$C$37,MATCH(A43-F$3,$A$8:$A$37,0))*F$4,0) -> 0 | J43: =IFERROR(INDEX($B$8:$B$37,MATCH(A43-G$3,$A$8:$A$37,0))*INDEX($C$8:$C$37,MATCH(A43-G$3,$A$8:$A$37,0))*G$4,0) -> 0 | K43: =IFERROR(INDEX($B$8:$B$37,MATCH(A43-H$3,$A$8:$A$37,0))*INDEX($C$8:$C$37,MATCH(A43-H$3,$A$8:$A$37,0))*H$4,0) -> 0 | L43: =IFERROR(INDEX($B$8:$B$37,MATCH(A43-I$3,$A$8:$A$37,0))*INDEX($C$8:$C$37,MATCH(A43-I$3,$A$8:$A$37,0))*I$4,0) -> 0 | M43: =IFERROR(INDEX($B$8:$B$37,MATCH(A43-J$3,$A$8:$A$37,0))*INDEX($C$8:$C$37,MATCH(A43-J$3,$A$8:$A$37,0))*J$4,0) -> 0 | N43: =IFERROR(INDEX($B$8:$B$37,MATCH(A43-K$3,$A$8:$A$37,0))*INDEX($C$8:$C$37,MATCH(A43-K$3,$A$8:$A$37,0))*K$4,0) -> 0 | O43: =IFERROR(INDEX($B$8:$B$37,MATCH(A43-L$3,$A$8:$A$37,0))*INDEX($C$8:$C$37,MATCH(A43-L$3,$A$8:$A$37,0))*L$4,0) -> 0
A44: 2023 | B44: =IF(A44<2026,0,E44+F44+G44+H44+I44+J44+K44+L44+M44+N44+O44) -> 0 | C44: =(B44/1000)*1000 -> 0 | D44: =C44+IF(A44=INDEX($A$42:$A$71,MATCH(MAX($C$42:$C$71),$C$42:$C$71,0)),SUM($B$8:$B$37)-SUM($C$42:$C$71),0) -> 0 | E44: =IFERROR(INDEX($B$8:$B$37,MATCH(A44-B$3,$A$8:$A$37,0))*INDEX($C$8:$C$37,MATCH(A44-B$3,$A$8:$A$37,0))*B$4,0) -> 115733.33 | F44: =IFERROR(INDEX($B$8:$B$37,MATCH(A44-C$3,$A$8:$A$37,0))*INDEX($C$8:$C$37,MATCH(A44-C$3,$A$8:$A$37,0))*C$4,0) -> 267076.92 | G44: =IFERROR(INDEX($B$8:$B$37,MATCH(A44-D$3,$A$8:$A$37,0))*INDEX($C$8:$C$37,MATCH(A44-D$3,$A$8:$A$37,0))*D$4,0) -> 496000 | H44: =IFERROR(INDEX($B$8:$B$37,MATCH(A44-E$3,$A$8:$A$37,0))*INDEX($C$8:$C$37,MATCH(A44-E$3,$A$8:$A$37,0))*E$4,0) -> 0 | I44: =IFERROR(INDEX($B$8:$B$37,MATCH(A44-F$3,$A$8:$A$37,0))*INDEX($C$8:$C$37,MATCH(A44-F$3,$A$8:$A$37,0))*F$4,0) -> 0 | J44: =IFERROR(INDEX($B$8:$B$37,MATCH(A44-G$3,$A$8:$A$37,0))*INDEX($C$8:$C$37,MATCH(A44-G$3,$A$8:$A$37,0))*G$4,0) -> 0 | K44: =IFERROR(INDEX($B$8:$B$37,MATCH(A44-H$3,$A$8:$A$37,0))*INDEX($C$8:$C$37,MATCH(A44-H$3,$A$8:$A$37,0))*H$4,0) -> 0 | L44: =IFERROR(INDEX($B$8:$B$37,MATCH(A44-I$3,$A$8:$A$37,0))*INDEX($C$8:$C$37,MATCH(A44-I$3,$A$8:$A$37,0))*I$4,0) -> 0 | M44: =IFERROR(INDEX($B$8:$B$37,MATCH(A44-J$3,$A$8:$A$37,0))*INDEX($C$8:$C$37,MATCH(A44-J$3,$A$8:$A$37,0))*J$4,0) -> 0 | N44: =IFERROR(INDEX($B$8:$B$37,MATCH(A44-K$3,$A$8:$A$37,0))*INDEX($C$8:$C$37,MATCH(A44-K$3,$A$8:$A$37,0))*K$4,0) -> 0 | O44: =IFERROR(INDEX($B$8:$B$37,MATCH(A44-L$3,$A$8:$A$37,0))*INDEX($C$8:$C$37,MATCH(A44-L$3,$A$8:$A$37,0))*L$4,0) -> 0
A45: 2024 | B45: =IF(A45<2026,0,E45+F45+G45+H45+I45+J45+K45+L45+M45+N45+O45) -> 0 | C45: =(B45/1000)*1000 -> 0 | D45: =C45+IF(A45=INDEX($A$42:$A$71,MATCH(MAX($C$42:$C$71),$C$42:$C$71,0)),SUM($B$8:$B$37)-SUM($C$42:$C$71),0) -> 0 | E45: =IFERROR(INDEX($B$8:$B$37,MATCH(A45-B$3,$A$8:$A$37,0))*INDEX($C$8:$C$37,MATCH(A45-B$3,$A$8:$A$37,0))*B$4,0) -> 105212.12 | F45: =IFERROR(INDEX($B$8:$B$37,MATCH(A45-C$3,$A$8:$A$37,0))*INDEX($C$8:$C$37,MATCH(A45-C$3,$A$8:$A$37,0))*C$4,0) -> 231466.67 | G45: =IFERROR(INDEX($B$8:$B$37,MATCH(A45-D$3,$A$8:$A$37,0))*INDEX($C$8:$C$37,MATCH(A45-D$3,$A$8:$A$37,0))*D$4,0) -> 400615.38 | H45: =IFERROR(INDEX($B$8:$B$37,MATCH(A45-E$3,$A$8:$A$37,0))*INDEX($C$8:$C$37,MATCH(A45-E$3,$A$8:$A$37,0))*E$4,0) -> 661333.33 | I45: =IFERROR(INDEX($B$8:$B$37,MATCH(A45-F$3,$A$8:$A$37,0))*INDEX($C$8:$C$37,MATCH(A45-F$3,$A$8:$A$37,0))*F$4,0) -> 0 | J45: =IFERROR(INDEX($B$8:$B$37,MATCH(A45-G$3,$A$8:$A$37,0))*INDEX($C$8:$C$37,MATCH(A45-G$3,$A$8:$A$37,0))*G$4,0) -> 0 | K45: =IFERROR(INDEX($B$8:$B$37,MATCH(A45-H$3,$A$8:$A$37,0))*INDEX($C$8:$C$37,MATCH(A45-H$3,$A$8:$A$37,0))*H$4,0) -> 0 | L45: =IFERROR(INDEX($B$8:$B$37,MATCH(A45-I$3,$A$8:$A$37,0))*INDEX($C$8:$C$37,MATCH(A45-I$3,$A$8:$A$37,0))*I$4,0) -> 0 | M45: =IFERROR(INDEX($B$8:$B$37,MATCH(A45-J$3,$A$8:$A$37,0))*INDEX($C$8:$C$37,MATCH(A45-J$3,$A$8:$A$37,0))*J$4,0) -> 0 | N45: =IFERROR(INDEX($B$8:$B$37,MATCH(A45-K$3,$A$8:$A$37,0))*INDEX($C$8:$C$37,MATCH(A45-K$3,$A$8:$A$37,0))*K$4,0) -> 0 | O45: =IFERROR(INDEX($B$8:$B$37,MATCH(A45-L$3,$A$8:$A$37,0))*INDEX($C$8:$C$37,MATCH(A45-L$3,$A$8:$A$37,0))*L$4,0) -> 0
A46: 2025 | B46: =IF(A46<2026,0,E46+F46+G46+H46+I46+J46+K46+L46+M46+N46+O46) -> 0 | C46: =(B46/1000)*1000 -> 0 | D46: =C46+IF(A46=INDEX($A$42:$A$71,MATCH(MAX($C$42:$C$71),$C$42:$C$71,0)),SUM($B$8:$B$37)-SUM($C$42:$C$71),0) -> 0 | E46: =IFERROR(INDEX($B$8:$B$37,MATCH(A46-B$3,$A$8:$A$37,0))*INDEX($C$8:$C$37,MATCH(A46-B$3,$A$8:$A$37,0))*B$4,0) -> 99200 | F46: =IFERROR(INDEX($B$8:$B$37,MATCH(A46-C$3,$A$8:$A$37,0))*INDEX($C$8:$C$37,MATCH(A46-C$3,$A$8:$A$37,0))*C$4,0) -> 210424.24 | G46: =IFERROR(INDEX($B$8:$B$37,MATCH(A46-D$3,$A$8:$A$37,0))*INDEX($C$8:$C$37,MATCH(A46-D$3,$A$8:$A$37,0))*D$4,0) -> 347200 | H46: =IFERROR(INDEX($B$8:$B$37,MATCH(A46-E$3,$A$8:$A$37,0))*INDEX($C$8:$C$37,MATCH(A46-E$3,$A$8:$A$37,0))*E$4,0) -> 534153.85 | I46: =IFERROR(INDEX($B$8:$B$37,MATCH(A46-F$3,$A$8:$A$37,0))*INDEX($C$8:$C$37,MATCH(A46-F$3,$A$8:$A$37,0))*F$4,0) -> 826666.67 | J46: =IFERROR(INDEX($B$8:$B$37,MATCH(A46-G$3,$A$8:$A$37,0))*INDEX($C$8:$C$37,MATCH(A46-G$3,$A$8:$A$37,0))*G$4,0) -> 0 | K46: =IFERROR(INDEX($B$8:$B$37,MATCH(A46-H$3,$A$8:$A$37,0))*INDEX($C$8:$C$37,MATCH(A46-H$3,$A$8:$A$37,0))*H$4,0) -> 0 | L46: =IFERROR(INDEX($B$8:$B$37,MATCH(A46-I$3,$A$8:$A$37,0))*INDEX($C$8:$C$37,MATCH(A46-I$3,$A$8:$A$37,0))*I$4,0) -> 0 | M46: =IFERROR(INDEX($B$8:$B$37,MATCH(A46-J$3,$A$8:$A$37,0))*INDEX($C$8:$C$37,MATCH(A46-J$3,$A$8:$A$37,0))*J$4,0) -> 0 | N46: =IFERROR(INDEX($B$8:$B$37,MATCH(A46-K$3,$A$8:$A$37,0))*INDEX($C$8:$C$37,MATCH(A46-K$3,$A$8:$A$37,0))*K$4,0) -> 0 | O46: =IFERROR(INDEX($B$8:$B$37,MATCH(A46-L$3,$A$8:$A$37,0))*INDEX($C$8:$C$37,MATCH(A46-L$3,$A$8:$A$37,0))*L$4,0) -> 0
A47: 2026 | B47: =IF(A47<2026,0,E47+F47+G47+H47+I47+J47+K47+L47+M47+N47+O47) -> 2733106.4 | C47: =(B47/1000)*1000 -> 2733106.4 | D47: =C47+IF(A47=INDEX($A$42:$A$71,MATCH(MAX($C$42:$C$71),$C$42:$C$71,0)),SUM($B$8:$B$37)-SUM($C$42:$C$71),0) -> 2733106.4 | E47: =IFERROR(INDEX($B$8:$B$37,MATCH(A47-B$3,$A$8:$A$37,0))*INDEX($C$8:$C$37,MATCH(A47-B$3,$A$8:$A$37,0))*B$4,0) -> 96444.444 | F47: =IFERROR(INDEX($B$8:$B$37,MATCH(A47-C$3,$A$8:$A$37,0))*INDEX($C$8:$C$37,MATCH(A47-C$3,$A$8:$A$37,0))*C$4,0) -> 198400 | G47: =IFERROR(INDEX($B$8:$B$37,MATCH(A47-D$3,$A$8:$A$37,0))*INDEX($C$8:$C$37,MATCH(A47-D$3,$A$8:$A$37,0))*D$4,0) -> 315636.36 | H47: =IFERROR(INDEX($B$8:$B$37,MATCH(A47-E$3,$A$8:$A$37,0))*INDEX($C$8:$C$37,MATCH(A47-E$3,$A$8:$A$37,0))*E$4,0) -> 462933.33 | I47: =IFERROR(INDEX($B$8:$B$37,MATCH(A47-F$3,$A$8:$A$37,0))*INDEX($C$8:$C$37,MATCH(A47-F$3,$A$8:$A$37,0))*F$4,0) -> 667692.31 | J47: =IFERROR(INDEX($B$8:$B$37,MATCH(A47-G$3,$A$8:$A$37,0))*INDEX($C$8:$C$37,MATCH(A47-G$3,$A$8:$A$37,0))*G$4,0) -> 992000 | K47: =IFERROR(INDEX($B$8:$B$37,MATCH(A47-H$3,$A$8:$A$37,0))*INDEX($C$8:$C$37,MATCH(A47-H$3,$A$8:$A$37,0))*H$4,0) -> 0 | L47: =IFERROR(INDEX($B$8:$B$37,MATCH(A47-I$3,$A$8:$A$37,0))*INDEX($C$8:$C$37,MATCH(A47-I$3,$A$8:$A$37,0))*I$4,0) -> 0 | M47: =IFERROR(INDEX($B$8:$B$37,MATCH(A47-J$3,$A$8:$A$37,0))*INDEX($C$8:$C$37,MATCH(A47-J$3,$A$8:$A$37,0))*J$4,0) -> 0 | N47: =IFERROR(INDEX($B$8:$B$37,MATCH(A47-K$3,$A$8:$A$37,0))*INDEX($C$8:$C$37,MATCH(A47-K$3,$A$8:$A$37,0))*K$4,0) -> 0 | O47: =IFERROR(INDEX($B$8:$B$37,MATCH(A47-L$3,$A$8:$A$37,0))*INDEX($C$8:$C$37,MATCH(A47-L$3,$A$8:$A$37,0))*L$4,0) -> 0
A48: 2027 | B48: =IF(A48<2026,0,E48+F48+G48+H48+I48+J48+K48+L48+M48+N48+O48) -> 3214345.9 | C48: =(B48/1000)*1000 -> 3214345.9 | D48: =C48+IF(A48=INDEX($A$42:$A$71,MATCH(MAX($C$42:$C$71),$C$42:$C$71,0)),SUM($B$8:$B$37)-SUM($C$42:$C$71),0) -> 3214345.9 | E48: =IFERROR(INDEX($B$8:$B$37,MATCH(A48-B$3,$A$8:$A$37,0))*INDEX($C$8:$C$37,MATCH(A48-B$3,$A$8:$A$37,0))*B$4,0) -> 96444.444 | F48: =IFERROR(INDEX($B$8:$B$37,MATCH(A48-C$3,$A$8:$A$37,0))*INDEX($C$8:$C$37,MATCH(A48-C$3,$A$8:$A$37,0))*C$4,0) -> 192888.89 | G48: =IFERROR(INDEX($B$8:$B$37,MATCH(A48-D$3,$A$8:$A$37,0))*INDEX($C$8:$C$37,MATCH(A48-D$3,$A$8:$A$37,0))*D$4,0) -> 297600 | H48: =IFERROR(INDEX($B$8:$B$37,MATCH(A48-E$3,$A$8:$A$37,0))*INDEX($C$8:$C$37,MATCH(A48-E$3,$A$8:$A$37,0))*E$4,0) -> 420848.48 | I48: =IFERROR(INDEX($B$8:$B$37,MATCH(A48-F$3,$A$8:$A$37,0))*INDEX($C$8:$C$37,MATCH(A48-F$3,$A$8:$A$37,0))*F$4,0) -> 578666.67 | J48: =IFERROR(INDEX($B$8:$B$37,MATCH(A48-G$3,$A$8:$A$37,0))*INDEX($C$8:$C$37,MATCH(A48-G$3,$A$8:$A$37,0))*G$4,0) -> 801230.77 | K48: =IFERROR(INDEX($B$8:$B$37,MATCH(A48-H$3,$A$8:$A$37,0))*INDEX($C$8:$C$37,MATCH(A48-H$3,$A$8:$A$37,0))*H$4,0) -> 826666.67 | L48: =IFERROR(INDEX($B$8:$B$37,MATCH(A48-I$3,$A$8:$A$37,0))*INDEX($C$8:$C$37,MATCH(A48-I$3,$A$8:$A$37,0))*I$4,0) -> 0 | M48: =IFERROR(INDEX($B$8:$B$37,MATCH(A48-J$3,$A$8:$A$37,0))*INDEX($C$8:$C$37,MATCH(A48-J$3,$A$8:$A$37,0))*J$4,0) -> 0 | N48: =IFERROR(INDEX($B$8:$B$37,MATCH(A48-K$3,$A$8:$A$37,0))*INDEX($C$8:$C$37,MATCH(A48-K$3,$A$8:$A$37,0))*K$4,0) -> 0 | O48: =IFERROR(INDEX($B$8:$B$37,MATCH(A48-L$3,$A$8:$A$37,0))*INDEX($C$8:$C$37,MATCH(A48-L$3,$A$8:$A$37,0))*L$4,0) -> 0
A49: 2028 | B49: =IF(A49<2026,0,E49+F49+G49+H49+I49+J49+K49+L49+M49+N49+O49) -> 3524952.9 | C49: =(B49/1000)*1000 -> 3524952.9 | D49: =C49+IF(A49=INDEX($A$42:$A$71,MATCH(MAX($C$42:$C$71),$C$42:$C$71,0)),SUM($B$8:$B$37)-SUM($C$42:$C$71),0) -> 3524952.9 | E49: =IFERROR(INDEX($B$8:$B$37,MATCH(A49-B$3,$A$8:$A$37,0))*INDEX($C$8:$C$37,MATCH(A49-B$3,$A$8:$A$37,0))*B$4,0) -> 96444.444 | F49: =IFERROR(INDEX($B$8:$B$37,MATCH(A49-C$3,$A$8:$A$37,0))*INDEX($C$8:$C$37,MATCH(A49-C$3,$A$8:$A$37,0))*C$4,0) -> 192888.89 | G49: =IFERROR(INDEX($B$8:$B$37,MATCH(A49-D$3,$A$8:$A$37,0))*INDEX($C$8:$C$37,MATCH(A49-D$3,$A$8:$A$37,0))*D$4,0) -> 289333.33 | H49: =IFERROR(INDEX($B$8:$B$37,MATCH(A49-E$3,$A$8:$A$37,0))*INDEX($C$8:$C$37,MATCH(A49-E$3,$A$8:$A$37,0))*E$4,0) -> 396800 | I49: =IFERROR(INDEX($B$8:$B$37,MATCH(A49-F$3,$A$8:$A$37,0))*INDEX($C$8:$C$37,MATCH(A49-F$3,$A$8:$A$37,0))*F$4,0) -> 526060.61 | J49: =IFERROR(INDEX($B$8:$B$37,MATCH(A49-G$3,$A$8:$A$37,0))*INDEX($C$8:$C$37,MATCH(A49-G$3,$A$8:$A$37,0))*G$4,0) -> 694400 | K49: =IFERROR(INDEX($B$8:$B$37,MATCH(A49-H$3,$A$8:$A$37,0))*INDEX($C$8:$C$37,MATCH(A49-H$3,$A$8:$A$37,0))*H$4,0) -> 667692.31 | L49: =IFERROR(INDEX($B$8:$B$37,MATCH(A49-I$3,$A$8:$A$37,0))*INDEX($C$8:$C$37,MATCH(A49-I$3,$A$8:$A$37,0))*I$4,0) -> 661333.33 | M49: =IFERROR(INDEX($B$8:$B$37,MATCH(A49-J$3,$A$8:$A$37,0))*INDEX($C$8:$C$37,MATCH(A49-J$3,$A$8:$A$37,0))*J$4,0) -> 0 | N49: =IFERROR(INDEX($B$8:$B$37,MATCH(A49-K$3,$A$8:$A$37,0))*INDEX($C$8:$C$37,MATCH(A49-K$3,$A$8:$A$37,0))*K$4,0) -> 0 | O49: =IFERROR(INDEX($B$8:$B$37,MATCH(A49-L$3,$A$8:$A$37,0))*INDEX($C$8:$C$37,MATCH(A49-L$3,$A$8:$A$37,0))*L$4,0) -> 0
A50: 2029 | B50: =IF(A50<2026,0,E50+F50+G50+H50+I50+J50+K50+L50+M50+N50+O50) -> 3700537.7 | C50: =(B50/1000)*1000 -> 3700537.7 | D50: =C50+IF(A50=INDEX($A$42:$A$71,MATCH(MAX($C$42:$C$71),$C$42:$C$71,0)),SUM($B$8:$B$37)-SUM($C$42:$C$71),0) -> 3700537.7 | E50: =IFERROR(INDEX($B$8:$B$37,MATCH(A50-B$3,$A$8:$A$37,0))*INDEX($C$8:$C$37,MATCH(A50-B$3,$A$8:$A$37,0))*B$4,0) -> 96444.444 | F50: =IFERROR(INDEX($B$8:$B$37,MATCH(A50-C$3,$A$8:$A$37,0))*INDEX($C$8:$C$37,MATCH(A50-C$3,$A$8:$A$37,0))*C$4,0) -> 192888.89 | G50: =IFERROR(INDEX($B$8:$B$37,MATCH(A50-D$3,$A$8:$A$37,0))*INDEX($C$8:$C$37,MATCH(A50-D$3,$A$8:$A$37,0))*D$4,0) -> 289333.33 | H50: =IFERROR(INDEX($B$8:$B$37,MATCH(A50-E$3,$A$8:$A$37,0))*INDEX($C$8:$C$37,MATCH(A50-E$3,$A$8:$A$37,0))*E$4,0) -> 385777.78 | I50: =IFERROR(INDEX($B$8:$B$37,MATCH(A50-F$3,$A$8:$A$37,0))*INDEX($C$8:$C$37,MATCH(A50-F$3,$A$8:$A$37,0))*F$4,0) -> 496000 | J50: =IFERROR(INDEX($B$8:$B$37,MATCH(A50-G$3,$A$8:$A$37,0))*INDEX($C$8:$C$37,MATCH(A50-G$3,$A$8:$A$37,0))*G$4,0) -> 631272.73 | K50: =IFERROR(INDEX($B$8:$B$37,MATCH(A50-H$3,$A$8:$A$37,0))*INDEX($C$8:$C$37,MATCH(A50-H$3,$A$8:$A$37,0))*H$4,0) -> 578666.67 | L50: =IFERROR(INDEX($B$8:$B$37,MATCH(A50-I$3,$A$8:$A$37,0))*INDEX($C$8:$C$37,MATCH(A50-I$3,$A$8:$A$37,0))*I$4,0) -> 534153.85 | M50: =IFERROR(INDEX($B$8:$B$37,MATCH(A50-J$3,$A$8:$A$37,0))*INDEX($C$8:$C$37,MATCH(A50-J$3,$A$8:$A$37,0))*J$4,0) -> 496000 | N50: =IFERROR(INDEX($B$8:$B$37,MATCH(A50-K$3,$A$8:$A$37,0))*INDEX($C$8:$C$37,MATCH(A50-K$3,$A$8:$A$37,0))*K$4,0) -> 0 | O50: =IFERROR(INDEX($B$8:$B$37,MATCH(A50-L$3,$A$8:$A$37,0))*INDEX($C$8:$C$37,MATCH(A50-L$3,$A$8:$A$37,0))*L$4,0) -> 0
A51: 2030 | B51: =IF(A51<2026,0,E51+F51+G51+H51+I51+J51+K51+L51+M51+N51+O51) -> 3762142.7 | C51: =(B51/1000)*1000 -> 3762142.7 | D51: =C51+IF(A51=INDEX($A$42:$A$71,MATCH(MAX($C$42:$C$71),$C$42:$C$71,0)),SUM($B$8:$B$37)-SUM($C$42:$C$71),0) -> 3762142.7 | E51: =IFERROR(INDEX($B$8:$B$37,MATCH(A51-B$3,$A$8:$A$37,0))*INDEX($C$8:$C$37,MATCH(A51-B$3,$A$8:$A$37,0))*B$4,0) -> 96444.444 | F51: =IFERROR(INDEX($B$8:$B$37,MATCH(A51-C$3,$A$8:$A$37,0))*INDEX($C$8:$C$37,MATCH(A51-C$3,$A$8:$A$37,0))*C$4,0) -> 192888.89 | G51: =IFERROR(INDEX($B$8:$B$37,MATCH(A51-D$3,$A$8:$A$37,0))*INDEX($C$8:$C$37,MATCH(A51-D$3,$A$8:$A$37,0))*D$4,0) -> 289333.33 | H51: =IFERROR(INDEX($B$8:$B$37,MATCH(A51-E$3,$A$8:$A$37,0))*INDEX($C$8:$C$37,MATCH(A51-E$3,$A$8:$A$37,0))*E$4,0) -> 385777.78 | I51: =IFERROR(INDEX($B$8:$B$37,MATCH(A51-F$3,$A$8:$A$37,0))*INDEX($C$8:$C$37,MATCH(A51-F$3,$A$8:$A$37,0))*F$4,0) -> 482222.22 | J51: =IFERROR(INDEX($B$8:$B$37,MATCH(A51-G$3,$A$8:$A$37,0))*INDEX($C$8:$C$37,MATCH(A51-G$3,$A$8:$A$37,0))*G$4,0) -> 595200 | K51: =IFERROR(INDEX($B$8:$B$37,MATCH(A51-H$3,$A$8:$A$37,0))*INDEX($C$8:$C$37,MATCH(A51-H$3,$A$8:$A$37,0))*H$4,0) -> 526060.61 | L51: =IFERROR(INDEX($B$8:$B$37,MATCH(A51-I$3,$A$8:$A$37,0))*INDEX($C$8:$C$37,MATCH(A51-I$3,$A$8:$A$37,0))*I$4,0) -> 462933.33 | M51: =IFERROR(INDEX($B$8:$B$37,MATCH(A51-J$3,$A$8:$A$37,0))*INDEX($C$8:$C$37,MATCH(A51-J$3,$A$8:$A$37,0))*J$4,0) -> 400615.38 | N51: =IFERROR(INDEX($B$8:$B$37,MATCH(A51-K$3,$A$8:$A$37,0))*INDEX($C$8:$C$37,MATCH(A51-K$3,$A$8:$A$37,0))*K$4,0) -> 330666.67 | O51: =IFERROR(INDEX($B$8:$B$37,MATCH(A51-L$3,$A$8:$A$37,0))*INDEX($C$8:$C$37,MATCH(A51-L$3,$A$8:$A$37,0))*L$4,0) -> 0
A52: 2031 | B52: =IF(A52<2026,0,E52+F52+G52+H52+I52+J52+K52+L52+M52+N52+O52) -> 3851514.3 | C52: =(B52/1000)*1000 -> 3851514.3 | D52: =C52+IF(A52=INDEX($A$42:$A$71,MATCH(MAX($C$42:$C$71),$C$42:$C$71,0)),SUM($B$8:$B$37)-SUM($C$42:$C$71),0) -> 3851514.3 | E52: =IFERROR(INDEX($B$8:$B$37,MATCH(A52-B$3,$A$8:$A$37,0))*INDEX($C$8:$C$37,MATCH(A52-B$3,$A$8:$A$37,0))*B$4,0) -> 226166.67 | F52: =IFERROR(INDEX($B$8:$B$37,MATCH(A52-C$3,$A$8:$A$37,0))*INDEX($C$8:$C$37,MATCH(A52-C$3,$A$8:$A$37,0))*C$4,0) -> 192888.89 | G52: =IFERROR(INDEX($B$8:$B$37,MATCH(A52-D$3,$A$8:$A$37,0))*INDEX($C$8:$C$37,MATCH(A52-D$3,$A$8:$A$37,0))*D$4,0) -> 289333.33 | H52: =IFERROR(INDEX($B$8:$B$37,MATCH(A52-E$3,$A$8:$A$37,0))*INDEX($C$8:$C$37,MATCH(A52-E$3,$A$8:$A$37,0))*E$4,0) -> 385777.78 | I52: =IFERROR(INDEX($B$8:$B$37,MATCH(A52-F$3,$A$8:$A$37,0))*INDEX($C$8:$C$37,MATCH(A52-F$3,$A$8:$A$37,0))*F$4,0) -> 482222.22 | J52: =IFERROR(INDEX($B$8:$B$37,MATCH(A52-G$3,$A$8:$A$37,0))*INDEX($C$8:$C$37,MATCH(A52-G$3,$A$8:$A$37,0))*G$4,0) -> 578666.67 | K52: =IFERROR(INDEX($B$8:$B$37,MATCH(A52-H$3,$A$8:$A$37,0))*INDEX($C$8:$C$37,MATCH(A52-H$3,$A$8:$A$37,0))*H$4,0) -> 496000 | L52: =IFERROR(INDEX($B$8:$B$37,MATCH(A52-I$3,$A$8:$A$37,0))*INDEX($C$8:$C$37,MATCH(A52-I$3,$A$8:$A$37,0))*I$4,0) -> 420848.48 | M52: =IFERROR(INDEX($B$8:$B$37,MATCH(A52-J$3,$A$8:$A$37,0))*INDEX($C$8:$C$37,MATCH(A52-J$3,$A$8:$A$37,0))*J$4,0) -> 347200 | N52: =IFERROR(INDEX($B$8:$B$37,MATCH(A52-K$3,$A$8:$A$37,0))*INDEX($C$8:$C$37,MATCH(A52-K$3,$A$8:$A$37,0))*K$4,0) -> 267076.92 | O52: =IFERROR(INDEX($B$8:$B$37,MATCH(A52-L$3,$A$8:$A$37,0))*INDEX($C$8:$C$37,MATCH(A52-L$3,$A$8:$A$37,0))*L$4,0) -> 165333.33
A53: 2032 | B53: =IF(A53<2026,0,E53+F53+G53+H53+I53+J53+K53+L53+M53+N53+O53) -> 3974163.7 | C53: =(B53/1000)*1000 -> 3974163.7 | D53: =C53+IF(A53=INDEX($A$42:$A$71,MATCH(MAX($C$42:$C$71),$C$42:$C$71,0)),SUM($B$8:$B$37)-SUM($C$42:$C$71),0) -> 3974163.7 | E53: =IFERROR(INDEX($B$8:$B$37,MATCH(A53-B$3,$A$8:$A$37,0))*INDEX($C$8:$C$37,MATCH(A53-B$3,$A$8:$A$37,0))*B$4,0) -> 226166.67 | F53: =IFERROR(INDEX($B$8:$B$37,MATCH(A53-C$3,$A$8:$A$37,0))*INDEX($C$8:$C$37,MATCH(A53-C$3,$A$8:$A$37,0))*C$4,0) -> 452333.33 | G53: =IFERROR(INDEX($B$8:$B$37,MATCH(A53-D$3,$A$8:$A$37,0))*INDEX($C$8:$C$37,MATCH(A53-D$3,$A$8:$A$37,0))*D$4,0) -> 289333.33 | H53: =IFERROR(INDEX($B$8:$B$37,MATCH(A53-E$3,$A$8:$A$37,0))*INDEX($C$8:$C$37,MATCH(A53-E$3,$A$8:$A$37,0))*E$4,0) -> 385777.78 | I53: =IFERROR(INDEX($B$8:$B$37,MATCH(A53-F$3,$A$8:$A$37,0))*INDEX($C$8:$C$37,MATCH(A53-F$3,$A$8:$A$37,0))*F$4,0) -> 482222.22 | J53: =IFERROR(INDEX($B$8:$B$37,MATCH(A53-G$3,$A$8:$A$37,0))*INDEX($C$8:$C$37,MATCH(A53-G$3,$A$8:$A$37,0))*G$4,0) -> 578666.67 | K53: =IFERROR(INDEX($B$8:$B$37,MATCH(A53-H$3,$A$8:$A$37,0))*INDEX($C$8:$C$37,MATCH(A53-H$3,$A$8:$A$37,0))*H$4,0) -> 482222.22 | L53: =IFERROR(INDEX($B$8:$B$37,MATCH(A53-I$3,$A$8:$A$37,0))*INDEX($C$8:$C$37,MATCH(A53-I$3,$A$8:$A$37,0))*I$4,0) -> 396800 | M53: =IFERROR(INDEX($B$8:$B$37,MATCH(A53-J$3,$A$8:$A$37,0))*INDEX($C$8:$C$37,MATCH(A53-J$3,$A$8:$A$37,0))*J$4,0) -> 315636.36 | N53: =IFERROR(INDEX($B$8:$B$37,MATCH(A53-K$3,$A$8:$A$37,0))*INDEX($C$8:$C$37,MATCH(A53-K$3,$A$8:$A$37,0))*K$4,0) -> 231466.67 | O53: =IFERROR(INDEX($B$8:$B$37,MATCH(A53-L$3,$A$8:$A$37,0))*INDEX($C$8:$C$37,MATCH(A53-L$3,$A$8:$A$37,0))*L$4,0) -> 133538.46
... A71: 2050 | B71: =IF(A71<2026,0,E71+F71+G71+H71+I71+J71+K71+L71+M71+N71+O71) -> 129722.22 | C71: =(B71/1000)*1000 -> 129722.22 | D71: =C71+IF(A71=INDEX($A$42:$A$71,MATCH(MAX($C$42:$C$71),$C$42:$C$71,0)),SUM($B$8:$B$37)-SUM($C$42:$C$71),0) -> 129722.22 | E71: =IFERROR(INDEX($B$8:$B$37,MATCH(A71-B$3,$A$8:$A$37,0))*INDEX($C$8:$C$37,MATCH(A71-B$3,$A$8:$A$37,0))*B$4,0) -> 0 | F71: =IFERROR(INDEX($B$8:$B$37,MATCH(A71-C$3,$A$8:$A$37,0))*INDEX($C$8:$C$37,MATCH(A71-C$3,$A$8:$A$37,0))*C$4,0) -> 0 | G71: =IFERROR(INDEX($B$8:$B$37,MATCH(A71-D$3,$A$8:$A$37,0))*INDEX($C$8:$C$37,MATCH(A71-D$3,$A$8:$A$37,0))*D$4,0) -> 0 | H71: =IFERROR(INDEX($B$8:$B$37,MATCH(A71-E$3,$A$8:$A$37,0))*INDEX($C$8:$C$37,MATCH(A71-E$3,$A$8:$A$37,0))*E$4,0) -> 0 | I71: =IFERROR(INDEX($B$8:$B$37,MATCH(A71-F$3,$A$8:$A$37,0))*INDEX($C$8:$C$37,MATCH(A71-F$3,$A$8:$A$37,0))*F$4,0) -> 0 | J71: =IFERROR(INDEX($B$8:$B$37,MATCH(A71-G$3,$A$8:$A$37,0))*INDEX($C$8:$C$37,MATCH(A71-G$3,$A$8:$A$37,0))*G$4,0) -> 0 | K71: =IFERROR(INDEX($B$8:$B$37,MATCH(A71-H$3,$A$8:$A$37,0))*INDEX($C$8:$C$37,MATCH(A71-H$3,$A$8:$A$37,0))*H$4,0) -> 0 | L71: =IFERROR(INDEX($B$8:$B$37,MATCH(A71-I$3,$A$8:$A$37,0))*INDEX($C$8:$C$37,MATCH(A71-I$3,$A$8:$A$37,0))*I$4,0) -> 0 | M71: =IFERROR(INDEX($B$8:$B$37,MATCH(A71-J$3,$A$8:$A$37,0))*INDEX($C$8:$C$37,MATCH(A71-J$3,$A$8:$A$37,0))*J$4,0) -> 0 | N71: =IFERROR(INDEX($B$8:$B$37,MATCH(A71-K$3,$A$8:$A$37,0))*INDEX($C$8:$C$37,MATCH(A71-K$3,$A$8:$A$37,0))*K$4,0) -> 0 | O71: =IFERROR(INDEX($B$8:$B$37,MATCH(A71-L$3,$A$8:$A$37,0))*INDEX($C$8:$C$37,MATCH(A71-L$3,$A$8:$A$37,0))*L$4,0) -> 129722.22
A73: Mass conservation check (raw total - shipped total; must be 0) | B73: =SUM(B8:B37)-SUM(D42:D71) -> 0
A74: PASS/FAIL | B74: =IF(ABS(B73)<0.5,"PASS","FAIL") -> PASS

Sheet Checks
A1: Checks
A3: Smoothing keeps total capacity unchanged (export total = Derivation total) | B3: =IF(ABS(SUM(CPRS!B2:AE2)-SUM(Derivation!D20:D49))<0.5,"PASS","FAIL") -> PASS
A4: No decisions before the first decision year (2026) | B4: =IF(SUM(CPRS!B2:F5)=0,"PASS","FAIL") -> PASS

Sheet CPRS
A1: Unit: metric tons clinker capacity/year | B1: 2021 | C1: 2022 | D1: 2023 | E1: 2024 | F1: 2025 | G1: 2026 | H1: 2027 | I1: 2028 | J1: 2029 | K1: 2030 | L1: 2031 | M1: 2032 | N1: 2033 | O1: 2034 | P1: 2035 | Q1: 2036 | R1: 2037 | S1: 2038 | T1: 2039 | U1: 2040 | V1: 2041 | W1: 2042 | X1: 2043 | Y1: 2044 | Z1: 2045 | AA1: 2046 | AB1: 2047 | AC1: 2048 | AD1: 2049 | AE1: 2050
A2: dry kiln with precalciner | B2: =Smoothing!D42 -> 0 | C2: =Smoothing!D43 -> 0 | D2: =Smoothing!D44 -> 0 | E2: =Smoothing!D45 -> 0 | F2: =Smoothing!D46 -> 0 | G2: =Smoothing!D47 -> 2733106.4 | H2: =Smoothing!D48 -> 3214345.9 | I2: =Smoothing!D49 -> 3524952.9 | J2: =Smoothing!D50 -> 3700537.7 | K2: =Smoothing!D51 -> 3762142.7 | L2: =Smoothing!D52 -> 3851514.3 | M2: =Smoothing!D53 -> 3974163.7 | N2: =Smoothing!D54 -> 4295424.2 | O2: =Smoothing!D55 -> 4783501 | P2: =Smoothing!D56 -> 5351700 | Q2: =Smoothing!D57 -> 5961944.4 | R2: =Smoothing!D58 -> 6348777.8 | S2: =Smoothing!D59 -> 6509444.4 | T2: =Smoothing!D60 -> 6443944.4 | U2: =Smoothing!D61 -> 6152277.8 | V2: =Smoothing!D62 -> 5642500 | W2: =Smoothing!D63 -> 4969722.2 | X2: =Smoothing!D64 -> 4263666.7 | Y2: =Smoothing!D65 -> 3524333.3 | Z2: =Smoothing!D66 -> 2751722.2 | AA2: =Smoothing!D67 -> 1945833.3 | AB2: =Smoothing!D68 -> 1297222.2 | AC2: =Smoothing!D69 -> 778333.33 | AD2: =Smoothing!D70 -> 389166.67 | AE2: =Smoothing!D71 -> 129722.22
A3: dry kiln with CCS | B3: 0 | C3: 0 | D3: 0 | E3: 0 | F3: 0 | G3: 0 | H3: 0 | I3: 0 | J3: 0 | K3: 0 | L3: 0 | M3: 0 | N3: 0 | O3: 0 | P3: 0 | Q3: 0 | R3: 0 | S3: 0 | T3: 0 | U3: 0 | V3: 0 | W3: 0 | X3: 0 | Y3: 0 | Z3: 0 | AA3: 0 | AB3: 0 | AC3: 0 | AD3: 0 | AE3: 0
A4: electric kiln | B4: 0 | C4: 0 | D4: 0 | E4: 0 | F4: 0 | G4: 0 | H4: 0 | I4: 0 | J4: 0 | K4: 0 | L4: 0 | M4: 0 | N4: 0 | O4: 0 | P4: 0 | Q4: 0 | R4: 0 | S4: 0 | T4: 0 | U4: 0 | V4: 0 | W4: 0 | X4: 0 | Y4: 0 | Z4: 0 | AA4: 0 | AB4: 0 | AC4: 0 | AD4: 0 | AE4: 0
A5: alternative chemistry cement | B5: 0 | C5: 0 | D5: 0 | E5: 0 | F5: 0 | G5: 0 | H5: 0 | I5: 0 | J5: 0 | K5: 0 | L5: 0 | M5: 0 | N5: 0 | O5: 0 | P5: 0 | Q5: 0 | R5: 0 | S5: 0 | T5: 0 | U5: 0 | V5: 0 | W5: 0 | X5: 0 | Y5: 0 | Z5: 0 | AA5: 0 | AB5: 0 | AC5: 0 | AD5: 0 | AE5: 0
