Workbook

Sheet About
A1: FoHERbA Fraction of Hydrogen Equipment Retiring by Age
A3: Source: | B3: Survival Curve Data by Industry
B4: Review of Income and Wealth
B5: 2008
B6: Lifetimes of Machinery and Equipment: Evidence from Dutch Manufacturing
B7: https://www.roiw.org/2008/2008-11.pdf
B8: A.A. Erumban
B10: Equipment Lifetime Assumption
B11: Life Cycle Assessment of Hydrogen Production via Natural Gas Steam Reforming
B12: 2001
B13: NREL
B14: https://docs.nrel.gov/docs/fy01osti/27637.pdf
B15: Pamela L. Spath; Margaret K. Mann
A17: Notes
A18: This variable contains survival curve data for industrial equipment in various sectors.
A20: We use the shape parameter for the Weibull curve in the chemicals sector and use Solver to find
A21: the scale parameter, λ, under an assumption around the lifetime of hydrogen production equipment.
A23: We use Spath et al.'s hydrogen production equipment lifetime assumption of:
A24: 20 | B24: years

Sheet Calcs
C2: TABLE 4 ESTIMATED REGRESSION COEFFICIENTS: MACHINERY (3 YEARS DISCARD)
B3: Industry | C3: a | D3: SE | E3: LC | F3: UC | G3: ii | H3: SE | I3: LC | J3: UC | K3: R2 | L3: DF
A4: 15+ 16 | B4: Food, beverages & tobacco | C4: 1.54 | D4: 0.03 | E4: 1.48 | F4: 1.601 | G4: 0.032 | H4: 0 | I4: 0.032 | J4: 0.033 | K4: 0.993 | L4: 69
A5: 17-19 | B5: Textile & leather products | C5: 1.705 | D5: 0.047 | E5: 1.61 | F5: 1.8 | G5: 0.039 | H5: 0 | I5: 0.038 | J5: 0.04 | K5: 0.989 | L5: 54
A6: 20 + 33 + 36 | B6: Wood & wood products, medical & optical equipment & other manufacturing | C6: 1.571 | D6: 0.074 | E6: 1.421 | F6: 1.72 | G6: 0.036 | H6: 0.001 | I6: 0.035 | J6: 0.037 | K6: 0.966 | L6: 48
A7: 21 | B7: Paper and paper products | C7: 1.434 | D7: 0.031 | E7: 1.372 | F7: 1.496 | G7: 0.04 | H7: 0 | I7: 0.04 | J7: 0.041 | K7: 0.992 | L7: 49
A8: 22 | B8: Publishing and printing | C8: 2.001 | D8: 0.092 | E8: 1.814 | F8: 2.188 | G8: 0.065 | H8: 0.001 | I8: 0.063 | J8: 0.067 | K8: 0.985 | L8: 34
A9: 23 | B9: Petroleum products; cokes, and nuclear fuel | C9: 1.307 | D9: 0.138 | E9: 1.03 | F9: 1.583 | G9: 0.026 | H9: 0.001 | I9: 0.023 | J9: 0.028 | K9: 0.795 | L9: 54
A10: 24 | B10: Basic chemicals and man-made fibers | C10: 1.721 | D10: 0.053 | E10: 1.615 | F10: 1.826 | G10: 0.036 | H10: 0 | I10: 0.035 | J10: 0.037 | K10: 0.986 | L10: 57
A11: 25 | B11: Rubber and plastic products | C11: 1.339 | D11: 0.032 | E11: 1.275 | F11: 1.404 | G11: 0.031 | H11: 0 | I11: 0.031 | J11: 0.032 | K11: 0.99 | L11: 44
A12: 26 | B12: Other non-metallic mineral products | C12: 2.231 | D12: 0.429 | E12: 1.368 | F12: 3.094 | G12: 0.031 | H12: 0.002 | I12: 0.027 | J12: 0.034 | K12: 0.679 | L12: 47
A13: 27 | B13: Basic metals | C13: 2.321 | D13: 0.055 | E13: 2.21 | F13: 2.431 | G13: 0.027 | H13: 0 | I13: 0.027 | J13: 0.027 | K13: 0.992 | L13: 55
A14: 28 | B14: Fabricated metal products | C14: 1.4 | D14: 0.047 | E14: 1.306 | F14: 1.494 | G14: 0.031 | H14: 0 | I14: 0.03 | J14: 0.032 | K14: 0.976 | L14: 65
A15: 29 | B15: Machinery and equipment n.e.c. | C15: 1.064 | D15: 0.047 | E15: 0.969 | F15: 1.159 | G15: 0.05 | H15: 0.001 | I15: 0.047 | J15: 0.052 | K15: 0.957 | L15: 49
A16: 30 + 32 | B16: Office machinery & computers, radio, TV & communication equipment | C16: 1.398 | D16: 0.011 | E16: 1.375 | F16: 1.421 | G16: 0.055 | H16: 0 | I16: 0.054 | J16: 0.055 | K16: 0.999 | L16: 65
A17: 31 | B17: Electrical machinery n.e.c. | C17: 1.028 | D17: 0.028 | E17: 0.972 | F17: 1.084 | G17: 0.024 | H17: 0 | I17: 0.023 | J17: 0.025 | K17: 0.983 | L17: 54
A18: 34 + 35 | B18: Transport equipment | C18: 1.318 | D18: 0.062 | E18: 1.193 | F18: 1.442 | G18: 0.039 | H18: 0.001 | I18: 0.037 | J18: 0.04 | K18: 0.961 | L18: 47
B19: HYDROGEN EQUIPMENT | C19: 1.721 | G19: 0.040409229
B21: Retirement Function (Cumulative Weibull)
B22: F(x) = ∫0xf(x')dx = 1 - e-(λx)^α
C26: 0 | D26: 1 | E26: 2 | F26: 3 | G26: 4 | H26: 5 | I26: 6 | J26: 7 | K26: 8 | L26: 9 | M26: 10 | N26: 11 | O26: 12 | P26: 13 | Q26: 14 | R26: 15 | S26: 16 | T26: 17 | U26: 18 | V26: 19 | W26: 20 | X26: 21 | Y26: 22 | Z26: 23 | AA26: 24 | AB26: 25 | AC26: 26 | AD26: 27 | AE26: 28 | AF26: 29 | AG26: 30 | AH26: 31 | AI26: 32 | AJ26: 33 | AK26: 34 | AL26: 35 | AM26: 36 | AN26: 37 | AO26: 38 | AP26: 39 | AQ26: 40 | AR26: 41 | AS26: 42 | AT26: 43 | AU26: 44 | AV26: 45 | AW26: 46 | AX26: 47 | AY26: 48 | AZ26: 49 | BA26: 50 | BB26: 51 | BC26: 52 | BD26: 53 | BE26: 54 | BF26: 55 | BG26: 56 | BH26: 57 | BI26: 58 | BJ26: 59 | BK26: 60 | BL26: 61 | BM26: 62 | BN26: 63 | BO26: 64 | BP26: 65 | BQ26: 66 | BR26: 67 | BS26: 68 | BT26: 69 | BU26: 70
B27: Food, beverages & tobacco | C27: =1-EXP(-(($G4*C$26)^$C4)) -> 0 | D27: =1-EXP(-(($G4*D$26)^$C4)) -> 0.0049756323 | E27: =1-EXP(-(($G4*E$26)^$C4)) -> 0.01440029 | F27: =1-EXP(-(($G4*F$26)^$C4)) -> 0.026719601 | G27: =1-EXP(-(($G4*G$26)^$C4)) -> 0.0413025 | H27: =1-EXP(-(($G4*H$26)^$C4)) -> 0.057742242 | I27: =1-EXP(-(($G4*I$26)^$C4)) -> 0.075734623 | J27: =1-EXP(-(($G4*J$26)^$C4)) -> 0.095033895 | ... BU27: =1-EXP(-(($G4*BU$26)^$C4)) -> 0.96864676
B28: Textile & leather products | C28: =1-EXP(-(($G5*C$26)^$C5)) -> 0 | D28: =1-EXP(-(($G5*D$26)^$C5)) -> 0.0039528051 | E28: =1-EXP(-(($G5*E$26)^$C5)) -> 0.012829813 | F28: =1-EXP(-(($G5*F$26)^$C5)) -> 0.025449028 | G28: =1-EXP(-(($G5*G$26)^$C5)) -> 0.041225669 | H28: =1-EXP(-(($G5*H$26)^$C5)) -> 0.059731523 | I28: =1-EXP(-(($G5*I$26)^$C5)) -> 0.080610323 | J28: =1-EXP(-(($G5*J$26)^$C5)) -> 0.10354694 | ... BU28: =1-EXP(-(($G5*BU$26)^$C5)) -> 0.99608086
B29: Wood & wood products, medical & optical equipment & other manufacturing | C29: =1-EXP(-(($G6*C$26)^$C6)) -> 0 | D29: =1-EXP(-(($G6*D$26)^$C6)) -> 0.0053799762 | E29: =1-EXP(-(($G6*E$26)^$C6)) -> 0.015899873 | F29: =1-EXP(-(($G6*F$26)^$C6)) -> 0.02985003 | G29: =1-EXP(-(($G6*G$26)^$C6)) -> 0.046503753 | H29: =1-EXP(-(($G6*H$26)^$C6)) -> 0.06537832 | I29: =1-EXP(-(($G6*I$26)^$C6)) -> 0.086103734 | J29: =1-EXP(-(($G6*J$26)^$C6)) -> 0.10837508 | ... BU29: =1-EXP(-(($G6*BU$26)^$C6)) -> 0.9860419
B30: Paper and paper products | C30: =1-EXP(-(($G7*C$26)^$C7)) -> 0 | D30: =1-EXP(-(($G7*D$26)^$C7)) -> 0.0098448121 | E30: =1-EXP(-(($G7*E$26)^$C7)) -> 0.026377838 | F30: =1-EXP(-(($G7*F$26)^$C7)) -> 0.046687951 | G30: =1-EXP(-(($G7*G$26)^$C7)) -> 0.069681623 | H30: =1-EXP(-(($G7*H$26)^$C7)) -> 0.094679759 | I30: =1-EXP(-(($G7*I$26)^$C7)) -> 0.12119146 | J30: =1-EXP(-(($G7*J$26)^$C7)) -> 0.14883382 | ... BU30: =1-EXP(-(($G7*BU$26)^$C7)) -> 0.98744309
B31: Publishing and printing | C31: =1-EXP(-(($G8*C$26)^$C8)) -> 0 | D31: =1-EXP(-(($G8*D$26)^$C8)) -> 0.0042046031 | E31: =1-EXP(-(($G8*E$26)^$C8)) -> 0.016724128 | F31: =1-EXP(-(($G8*F$26)^$C8)) -> 0.037251331 | G31: =1-EXP(-(($G8*G$26)^$C8)) -> 0.065280691 | H31: =1-EXP(-(($G8*H$26)^$C8)) -> 0.10013124 | I31: =1-EXP(-(($G8*I$26)^$C8)) -> 0.14097465 | J31: =1-EXP(-(($G8*J$26)^$C8)) -> 0.18686818 | ... BU31: =1-EXP(-(($G8*BU$26)^$C8)) -> 1
B32: Petroleum products; cokes, and nuclear fuel | C32: =1-EXP(-(($G9*C$26)^$C9)) -> 0 | D32: =1-EXP(-(($G9*D$26)^$C9)) -> 0.0084436489 | E32: =1-EXP(-(($G9*E$26)^$C9)) -> 0.020761966 | F32: =1-EXP(-(($G9*F$26)^$C9)) -> 0.035014745 | G32: =1-EXP(-(($G9*G$26)^$C9)) -> 0.050587 | H32: =1-EXP(-(($G9*H$26)^$C9)) -> 0.067130784 | I32: =1-EXP(-(($G9*I$26)^$C9)) -> 0.08441208 | J32: =1-EXP(-(($G9*J$26)^$C9)) -> 0.10225852 | ... BU32: =1-EXP(-(($G9*BU$26)^$C9)) -> 0.88778347
B33: Basic chemicals and man-made fibers | C33: =1-EXP(-(($G10*C$26)^$C10)) -> 0 | D33: =1-EXP(-(($G10*D$26)^$C10)) -> 0.0032710361 | E33: =1-EXP(-(($G10*E$26)^$C10)) -> 0.010743008 | F33: =1-EXP(-(($G10*F$26)^$C10)) -> 0.021469307 | G33: =1-EXP(-(($G10*G$26)^$C10)) -> 0.03498104 | H33: =1-EXP(-(($G10*H$26)^$C10)) -> 0.050935583 | I33: =1-EXP(-(($G10*I$26)^$C10)) -> 0.069048012 | J33: =1-EXP(-(($G10*J$26)^$C10)) -> 0.089065862 | ... BU33: =1-EXP(-(($G10*BU$26)^$C10)) -> 0.99260488
B34: Rubber and plastic products | C34: =1-EXP(-(($G11*C$26)^$C11)) -> 0 | D34: =1-EXP(-(($G11*D$26)^$C11)) -> 0.0095030177 | E34: =1-EXP(-(($G11*E$26)^$C11)) -> 0.023865898 | F34: =1-EXP(-(($G11*F$26)^$C11)) -> 0.040719529 | G34: =1-EXP(-(($G11*G$26)^$C11)) -> 0.059277512 | H34: =1-EXP(-(($G11*H$26)^$C11)) -> 0.079083711 | I34: =1-EXP(-(($G11*I$26)^$C11)) -> 0.099825459 | J34: =1-EXP(-(($G11*J$26)^$C11)) -> 0.12126904 | ... BU34: =1-EXP(-(($G11*BU$26)^$C11)) -> 0.94049868
B35: Other non-metallic mineral products | C35: =1-EXP(-(($G12*C$26)^$C12)) -> 0 | D35: =1-EXP(-(($G12*D$26)^$C12)) -> 0.00043065987 | E35: =1-EXP(-(($G12*E$26)^$C12)) -> 0.0020201649 | F35: =1-EXP(-(($G12*F$26)^$C12)) -> 0.0049842623 | G35: =1-EXP(-(($G12*G$26)^$C12)) -> 0.0094485232 | H35: =1-EXP(-(($G12*H$26)^$C12)) -> 0.015496834 | I35: =1-EXP(-(($G12*I$26)^$C12)) -> 0.023184599 | J35: =1-EXP(-(($G12*J$26)^$C12)) -> 0.032544454 | ... BU35: =1-EXP(-(($G12*BU$26)^$C12)) -> 0.99641762
B36: Basic metals | C36: =1-EXP(-(($G13*C$26)^$C13)) -> 0 | D36: =1-EXP(-(($G13*D$26)^$C13)) -> 0.00022863654 | E36: =1-EXP(-(($G13*E$26)^$C13)) -> 0.0011419257 | F36: =1-EXP(-(($G13*F$26)^$C13)) -> 0.0029238699 | G36: =1-EXP(-(($G13*G$26)^$C13)) -> 0.0056929502 | H36: =1-EXP(-(($G13*H$26)^$C13)) -> 0.0095372991 | I36: =1-EXP(-(($G13*I$26)^$C13)) -> 0.01452483 | J36: =1-EXP(-(($G13*J$26)^$C13)) -> 0.020707704 | ... BU36: =1-EXP(-(($G13*BU$26)^$C13)) -> 0.9874991
B37: Fabricated metal products | C37: =1-EXP(-(($G14*C$26)^$C14)) -> 0 | D37: =1-EXP(-(($G14*D$26)^$C14)) -> 0.007695378 | E37: =1-EXP(-(($G14*E$26)^$C14)) -> 0.020180362 | F37: =1-EXP(-(($G14*F$26)^$C14)) -> 0.035325629 | G37: =1-EXP(-(($G14*G$26)^$C14)) -> 0.052379337 | H37: =1-EXP(-(($G14*H$26)^$C14)) -> 0.070891698 | I37: =1-EXP(-(($G14*I$26)^$C14)) -> 0.09054644 | J37: =1-EXP(-(($G14*J$26)^$C14)) -> 0.11110168 | ... BU37: =1-EXP(-(($G14*BU$26)^$C14)) -> 0.94809342
B38: Machinery and equipment n.e.c. | C38: =1-EXP(-(($G15*C$26)^$C15)) -> 0 | D38: =1-EXP(-(($G15*D$26)^$C15)) -> 0.040436337 | E38: =1-EXP(-(($G15*E$26)^$C15)) -> 0.082679038 | F38: =1-EXP(-(($G15*F$26)^$C15)) -> 0.12440346 | G38: =1-EXP(-(($G15*G$26)^$C15)) -> 0.16508443 | H38: =1-EXP(-(($G15*H$26)^$C15)) -> 0.20449233 | I38: =1-EXP(-(($G15*I$26)^$C15)) -> 0.24251526 | J38: =1-EXP(-(($G15*J$26)^$C15)) -> 0.27910126 | ... BU38: =1-EXP(-(($G15*BU$26)^$C15)) -> 0.9774535
... B42: HYDROGEN EQUIPMENT | C42: =1-EXP(-(($G19*C$26)^$C19)) -> 0 | D42: =1-EXP(-(($G19*D$26)^$C19)) -> 0.0039891959 | E42: =1-EXP(-(($G19*E$26)^$C19)) -> 0.013090837 | F42: =1-EXP(-(($G19*F$26)^$C19)) -> 0.026130148 | G42: =1-EXP(-(($G19*G$26)^$C19)) -> 0.04251081 | H42: =1-EXP(-(($G19*H$26)^$C19)) -> 0.061788054 | I42: =1-EXP(-(($G19*I$26)^$C19)) -> 0.083586282 | J42: =1-EXP(-(($G19*J$26)^$C19)) -> 0.10756931 | ... BU42: =1-EXP(-(($G19*BU$26)^$C19)) -> 0.99748734
W43: ^The solver objective cell is set to 0.5 by varying the hydrogen equipment scale parameter
B44: n-th moment of Weibull probability density function
B45: μn = (λ)nΓ(1 + 1/α)
B46: where Γ(n) is the Gamma function of the shape parameter n, Γ(n) = ∫0∞ yn-1 e-y dy
B48: The first moment (the mean) of the Weibull, which is the expected average service life E(x), is therefore:
B49: μ1 = E(x) = (1/λ) Γ(1 + 1/α)
...

Sheet FoHERbA
B1: 0 | C1: 1 | D1: 2 | E1: 3 | F1: 4 | G1: 5 | H1: 6 | I1: 7 | J1: 8 | K1: 9 | L1: 10 | M1: 11 | N1: 12 | O1: 13 | P1: 14 | Q1: 15 | R1: 16 | S1: 17 | T1: 18 | U1: 19 | V1: 20 | W1: 21 | X1: 22 | Y1: 23 | Z1: 24 | AA1: 25 | AB1: 26 | AC1: 27 | AD1: 28 | AE1: 29 | AF1: 30 | AG1: 31 | AH1: 32 | AI1: 33 | AJ1: 34 | AK1: 35 | AL1: 36 | AM1: 37 | AN1: 38 | AO1: 39 | AP1: 40 | AQ1: 41 | AR1: 42 | AS1: 43 | AT1: 44 | AU1: 45 | AV1: 46 | AW1: 47 | AX1: 48 | AY1: 49 | AZ1: 50 | BA1: 51 | BB1: 52 | BC1: 53 | BD1: 54 | BE1: 55 | BF1: 56 | BG1: 57 | BH1: 58 | BI1: 59 | BJ1: 60 | BK1: 61 | BL1: 62 | BM1: 63 | BN1: 64 | BO1: 65 | BP1: 66 | BQ1: 67 | BR1: 68 | BS1: 69 | BT1: 70 | BU1: 71 | BV1: 72 | BW1: 73 | BX1: 74 | BY1: 75 | BZ1: 76 | CA1: 77 | CB1: 78 | CC1: 79 | CD1: 80 | CE1: 81 | CF1: 82 | CG1: 83 | CH1: 84 | CI1: 85 | CJ1: 86 | CK1: 87 | CL1: 88 | CM1: 89 | CN1: 90 | CO1: 91 | CP1: 92 | CQ1: 93 | CR1: 94 | CS1: 95 | CT1: 96 | CU1: 97 | CV1: 98 | CW1: 99 | CX1: 100 | CY1: 101 | CZ1: 102 | DA1: 103 | DB1: 104 | DC1: 105 | DD1: 106 | DE1: 107 | DF1: 108 | DG1: 109 | DH1: 110 | DI1: 111 | DJ1: 112 | DK1: 113 | DL1: 114 | DM1: 115 | DN1: 116 | DO1: 117 | DP1: 118 | DQ1: 119 | DR1: 120 | DS1: 121 | DT1: 122 | DU1: 123 | DV1: 124 | DW1: 125 | DX1: 126 | DY1: 127 | DZ1: 128 | EA1: 129 | EB1: 130 | EC1: 131 | ED1: 132 | EE1: 133 | EF1: 134 | EG1: 135 | EH1: 136 | EI1: 137 | EJ1: 138 | EK1: 139 | EL1: 140 | EM1: 141 | EN1: 142 | EO1: 143 | EP1: 144 | EQ1: 145 | ER1: 146 | ES1: 147 | ET1: 148 | EU1: 149 | EV1: 150 | EW1: 151
A2: Retired Share | B2: =Calcs!C89 -> 0 | C2: =Calcs!D89 -> 0.0039891959 | D2: =Calcs!E89 -> 0.0091380945 | E2: =Calcs!F89 -> 0.013212271 | F2: =Calcs!G89 -> 0.016820176 | G2: =Calcs!H89 -> 0.020133118 | H2: =Calcs!I89 -> 0.023233799 | I2: =Calcs!J89 -> 0.026170523 | ... BT2: =Calcs!BU89 -> 1 | BU2: 1 | BV2: 1 | BW2: 1 | BX2: 1 | BY2: 1 | BZ2: 1 | CA2: 1 | CB2: 1 | CC2: 1 | CD2: 1 | CE2: 1 | CF2: 1 | CG2: 1 | CH2: 1 | CI2: 1 | CJ2: 1 | CK2: 1 | CL2: 1 | CM2: 1 | CN2: 1 | CO2: 1 | CP2: 1 | CQ2: 1 | CR2: 1 | CS2: 1 | CT2: 1 | CU2: 1 | CV2: 1 | CW2: 1 | CX2: 1 | CY2: 1 | CZ2: 1 | DA2: 1 | DB2: 1 | DC2: 1 | DD2: 1 | DE2: 1 | DF2: 1 | DG2: 1 | DH2: 1 | DI2: 1 | DJ2: 1 | DK2: 1 | DL2: 1 | DM2: 1 | DN2: 1 | DO2: 1 | DP2: 1 | DQ2: 1 | DR2: 1 | DS2: 1 | DT2: 1 | DU2: 1 | DV2: 1 | DW2: 1 | DX2: 1 | DY2: 1 | DZ2: 1 | EA2: 1 | EB2: 1 | EC2: 1 | ED2: 1 | EE2: 1 | EF2: 1 | EG2: 1 | EH2: 1 | EI2: 1 | EJ2: 1 | EK2: 1 | EL2: 1 | EM2: 1 | EN2: 1 | EO2: 1 | EP2: 1 | EQ2: 1 | ER2: 1 | ES2: 1 | ET2: 1 | EU2: 1 | EV2: 1 | EW2: 1
