Workbook
Name Fraction_coal: [1]About!$C$50
Name Percent_rural: [1]About!$A$77
Name Percent_urban: [1]About!$A$76
Name quadrillion: [1]About!$B$79
Name Table4: #REF!
Name Table5: #REF!

Sheet About
A1: ICpUEfEBE Incremental Cost per Unit Energy for Electrified Building Equipment
A3: Sources: | B3: Cost of technologies except commerial heat pumps | D3: Commercial heating and water heating heat pump costs
B4: EIA | D4: NREL
B5: 2018 | D5: 2018
B6: Updated Buildings Sector Appliance and Equipment Costs and Efficiencies | D6: Electrification Futures Study Technology Report Figure Data
B7: https://www.eia.gov/analysis/studies/buildings/equipcosts/pdf/full.pdf | D7: https://data.nrel.gov/system/files/93/EFS_70485_figure_data.xlsx
B8: p. 9, 12, 29, 46, 51, 54, 58, 90, 92, 120, 123 | D8: Tables 22 and 23
B10: Residential building equipment stock and average annual energy consumption | D10: Commercial building equipment load factors
B11: EIA | D11: NREL
B12: 20222023 | D12: 2018
B13: AEO 2022, AEO 2023 | D13: Electrification Futures Study: End-Use Electric Technology Cost and Performance Projections through 2050
B14: https://www.eia.gov/outlooks/aeo/tables_side.php | D14: https://www.nrel.gov/docs/fy18osti/70485.pdf
B15: Tables 4 and 21 | D15: P.90
A17: Notes:
A18: All policy-driven electrification in the EPS is assumed to rely on heat pumps,
A19: not electric resistance heating
A21: Methodology:
A22: For residential buildings, we calculate the average energy used by equipment
A23: of different types, which allows us to find a $/BTU value. We then estimate
A24: the cost of switching to heat pump equipment based on the data from EIA
A25: and annual energy consumption.
A27: For commercial buildings, we lack data on annual energy use, but the NREL
A28: report provides data on annual heating and water heating utilization rates
A29: and the costs are normalized to $/(kBTU/hr) input, so we standardize the costs
A30: from EIA and then estimate the cost per BTU shifted using the annual load factors.
... A52: 2017 to 2012 USD
A53: 0.9366596
A54: 2016 to 2012 USD
A55: 0.95661377

Sheet Source Data>

Sheet EIA Costs
A1: Residential Gas Fired Furnaces
A2: DATA | B2: 2009 | C2: 2015 | D2: 2017 | H2: 2020 | J2: 2030 | L2: 2040 | N2: 2050
B3: Installed Base | C3: Installed Base | D3: Current Standard | E3: Typical | F3: ENERGY STAR (South) | G3: High | H3: Typical | I3: High | J3: Typical | K3: High | L3: Typical | M3: High | N3: Typical | O3: High
A4: Typical Input Capacity (kBtu/h) | B4: 80 | C4: 80 | D4: 80 | E4: 80 | F4: 80 | G4: 80 | H4: 80 | I4: 80 | J4: 80 | K4: 80 | L4: 80 | M4: 80 | N4: 80 | O4: 80
A5: AFUE (%) | B5: 80 | C5: 80 | D5: 80 | E5: 80 | F5: 90 | G5: 99 | H5: 80 | I5: 99 | J5: 80 | K5: 99 | L5: 80 | M5: 99 | N5: 80 | O5: 99
A6: Electric Consumption (kWh/yr)* | B6: 548 | C6: 522 | D6: 470 | E6: 470 | F6: 408 | G6: 418 | H6: 329 | I6: 334 | J6: 329 | K6: 334 | L6: 329 | M6: 334 | N6: 329 | O6: 334
A7: Average Life (yrs)** | B7: 16 | C7: 16 | D7: 16 | E7: 16 | F7: 16 | G7: 16 | H7: 16 | I7: 16 | J7: 16 | K7: 16 | L7: 16 | M7: 16 | N7: 16 | O7: 16
B8: 27 | C8: 27 | D8: 27 | E8: 27 | F8: 27 | G8: 27 | H8: 27 | I8: 27 | J8: 27 | K8: 27 | L8: 27 | M8: 27 | N8: 27 | O8: 27
A9: Retail Equipment Cost (2017$) | B9: 840 | C9: 860 | D9: 890 | E9: 890 | F9: 1150 | G9: 1620 | H9: 1080 | I9: 1620 | J9: 1080 | K9: 1620 | L9: 1080 | M9: 1620 | N9: 1080 | O9: 1620
A10: Total Installed Cost (2017$) | B10: 2000 | C10: 2020 | D10: 2050 | E10: 2050 | F10: 2560 | G10: 3040 | H10: 2240 | I10: 3040 | J10: 2240 | K10: 3040 | L10: 2240 | M10: 3040 | N10: 2240 | O10: 3040
A11: Annual Maintenance Cost (2017$) | B11: 40 | C11: 40 | D11: 40 | E11: 40 | F11: 40 | G11: 40 | H11: 40 | I11: 40 | J11: 40 | K11: 40 | L11: 40 | M11: 40 | N11: 40 | O11: 40
A13: Residential Oil Fired Furnaces
A14: DATA | B14: 2009 | C14: 2015 | D14: 2017 | H14: 2020 | J14: 2030 | L14: 2040 | N14: 2050
B15: Installed Base | C15: Installed Base | D15: Current Standard | E15: Typical | F15: ENERGY STAR | G15: High | H15: Typical | I15: High Typical | K15: High | L15: Typical | M15: High | N15: Typical | O15: High
A16: Typical Input Capacity (kBtu/h) | B16: 105 | C16: 105 | D16: 105 | E16: 105 | F16: 105 | G16: 105 | H16: 105 | I16: 105 | J16: 105 | K16: 105 | L16: 105 | M16: 105 | N16: 105 | O16: 105
A17: AFUE (%) | B17: 80 | C17: 83 | D17: 83 | E17: 83 | F17: 85 | G17: 97 | H17: 83 | I17: 97 | J17: 84 | K17: 97 | L17: 84 | M17: 97 | N17: 84 | O17: 97
A18: Electric Consumption (kWh/yr)* | B18: 490 | C18: 477 | D18: 477 | E18: 477 | F18: 466 | G18: 410 | H18: 477 | I18: 410 | J18: 472 | K18: 410 | L18: 472 | M18: 410 | N18: 472 | O18: 410
A19: Average Life (yrs)** | B19: 20 | C19: 20 | D19: 20 | E19: 20 | F19: 20 | G19: 20 | H19: 20 | I19: 20 | J19: 20 | K19: 20 | L19: 20 | M19: 20 | N19: 20 | O19: 20
B20: 33 | C20: 33 | D20: 33 | E20: 33 | F20: 33 | G20: 33 | H20: 33 | I20: 33 | J20: 33 | K20: 33 | L20: 33 | M20: 33 | N20: 33 | O20: 33
A21: Retail Equipment Cost (2017$) | B21: 2150 | C21: 2200 | D21: 2200 | E21: 2200 | F21: 2250 | G21: 2700 | H21: 2200 | I21: 2700 | J21: 2250 | K21: 2700 | L21: 2250 | M21: 2700 | N21: 2250 | O21: 2700
B22: 2350 | C22: 2900 | D22: 2900 | E22: 2900 | F22: 2950 | G22: 3450 | H22: 2900 | I22: 3450 | J22: 2950 | K22: 3450 | L22: 2950 | M22: 3450 | N22: 2950 | O22: 3450
A23: Total Installed Cost (2017$) | B23: 2700 | C23: 2750 | D23: 2750 | E23: 2750 | F23: 2950 | G23: 4350 | H23: 2750 | I23: 4350 | J23: 2750 | K23: 4350 | L23: 2750 | M23: 4350 | N23: 2750 | O23: 4350
B24: 3400 | C24: 5500 | D24: 5500 | E24: 5500 | F24: 5750 | G24: 8550 | H24: 5500 | I24: 8550 | J24: 5700 | K24: 8550 | L24: 5700 | M24: 8550 | N24: 5700 | O24: 8550
A25: Annual Maintenance Cost (2017$) | B25: 70 | C25: 70 | D25: 70 | E25: 70 | F25: 70 | G25: 200 | H25: 70 | I25: 200 | J25: 70 | K25: 200 | L25: 70 | M25: 200 | N25: 70 | O25: 200
A27: Residential Wood Pellet Stoves
A28: DATA | B28: 2009 | C28: 2015 | D28: 2017 | F28: 2020 | H28: 2030 | J28: 2040 | L28: 2050
B29: Installed Base | C29: Installed Base | D29: Typical | E29: High | F29: Typical | G29: High | H29: Typical | I29: High | J29: Typical | K29: High | L29: Typical | M29: High
A30: Typical Capacity (kBtu/h) | B30: 50 | C30: 50 | D30: 50 | E30: 50 | F30: 50 | G30: 50 | H30: 50 | I30: 50 | J30: 50 | K30: 50 | L30: 50 | M30: 50
A31: Efficiency (HHV) | B31: 65 | C31: 70 | D31: 76 | E31: 87 | F31: 76 | G31: 87 | H31: 77 | I31: 87 | J31: 78 | K31: 88 | L31: 79 | M31: 89
A32: Annual Electricity Consumption (kWh) | B32: 600 | C32: 600 | D32: 600 | E32: 600 | F32: 600 | G32: 600 | H32: 600 | I32: 600 | J32: 600 | K32: 600 | L32: 600 | M32: 600
A33: Average Life (yrs) | B33: 12 | C33: 12 | D33: 12 | E33: 12 | F33: 12 | G33: 12 | H33: 12 | I33: 12 | J33: 12 | K33: 12 | L33: 12 | M33: 12
B34: 25 | C34: 25 | D34: 25 | E34: 25 | F34: 25 | G34: 25 | H34: 25 | I34: 25 | J34: 25 | K34: 25 | L34: 25 | M34: 25
A35: Retail Equipment Cost (2017$) | B35: 3300 | C35: 3300 | D35: 3300 | E35: 4000 | F35: 3300 | G35: 4000 | H35: 3400 | I35: 4000 | J35: 3500 | K35: 4100 | L35: 3600 | M35: 4200
A36: Total Installed Cost (2017$) | B36: 4700 | C36: 4700 | D36: 4700 | E36: 5400 | F36: 4700 | G36: 5400 | H36: 4800 | I36: 5400 | J36: 4900 | K36: 5500 | L36: 5000 | M36: 5600
A37: Annual Maintenance Cost (2017$) | B37: 260 | C37: 260 | D37: 260 | E37: 260 | F37: 260 | G37: 260 | H37: 260 | I37: 260 | J37: 260 | K37: 260 | L37: 260 | M37: 260
A39: Residential Air Source Heat Pumps
A40: DATA | B40: 2009 | C40: 2015 | D40: 2017 | H40: 2020 | J40: 2030** | L40: 2040 | N40: 2050
B41: Installed Base | C41: Installed Base | D41: Current Standard | E41: Typical | F41: ENERGY STAR | G41: High | H41: Typical | I41: High | J41: Typical | K41: High | L41: Typical | M41: High | N41: Typical | O41: High
A42: Typical Capacity (kBtu/h) | B42: 36 | C42: 36 | D42: 36 | E42: 36 | F42: 36 | G42: 36 | H42: 36 | I42: 36 | J42: 36 | K42: 36 | L42: 36 | M42: 36 | N42: 36 | O42: 36
A43: SEER (Cooling)* | B43: 12 | C43: 13.1 | D43: 14 | E43: 15.3 | F43: 15 | G43: 19 | H43: 15.3 | I43: 19 | J43: 15.8 | K43: 19 | L43: 15.8 | M43: 19 | N43: 15.8 | O43: 19
...

Sheet Table_21._Residential_Sector_Eq
A1: Table 21. Residential Sector Equipment Stock and Efficiency, and Distributed Generation
A2: https://www.eia.gov/outlooks/aeo/data/browser/#/?id=30-AEO2025&cases=highZTC&sourcekey=0
A3: Tue Dec 02 2025 13:21:44 GMT-0800 (Pacific Standard Time)
A4: Source: U.S. Energy Information Administration
B5: full name | C5: api key | D5: units | E5: 2023 | F5: 2024 | G5: 2025 | H5: 2026 | I5: 2027 | J5: 2028 | K5: 2029 | L5: 2030 | M5: 2031 | N5: 2032 | O5: 2033 | P5: 2034 | Q5: 2035 | R5: 2036 | S5: 2037 | T5: 2038 | U5: 2039 | V5: 2040 | W5: 2041 | X5: 2042 | Y5: 2043 | Z5: 2044 | AA5: 2045 | AB5: 2046 | AC5: 2047 | AD5: 2048 | AE5: 2049 | AF5: 2050 | AG5: Growth (2024-2050)
A6: Equipment Stock (million units)
A7: Main Space Heaters
A8: Electric Heat Pumps | B8: Residential Equipment: Equipment Stock: Main Space Heaters: Electric Heat Pumps: High Zero-Carbon Technology Cost | C8: AEO.2025.HIGHZTC.EQNR_STK_RESD_MSHR_EHP_NA_NA_MILL.A | D8: millions | F8: 16.645529 | G8: 16.962238 | H8: 17.297937 | I8: 17.63735 | J8: 17.975958 | K8: 18.323191 | L8: 18.671122 | M8: 19.020292 | N8: 19.366976 | O8: 19.701832 | P8: 20.022341 | Q8: 20.338335 | R8: 20.648127 | S8: 20.94591 | T8: 21.232155 | U8: 21.506626 | V8: 21.772039 | W8: 22.026169 | X8: 22.27137 | Y8: 22.506741 | Z8: 22.737045 | AA8: 22.966516 | AB8: 23.194811 | AC8: 23.422667 | AD8: 23.650106 | AE8: 23.877323 | AF8: 24.103533 | AG8: 0.014
A9: Electric Other | B9: Residential Equipment: Equipment Stock: Main Space Heaters: Electric Other: High Zero-Carbon Technology Cost | C9: AEO.2025.HIGHZTC.EQNR_STK_RESD_MSHR_ELO_NA_NA_MILL.A | D9: millions | F9: 26.605318 | G9: 26.78159 | H9: 26.987282 | I9: 27.200581 | J9: 27.420454 | K9: 27.653374 | L9: 27.889208 | M9: 28.127293 | N9: 28.362696 | O9: 28.587048 | P9: 28.798485 | Q9: 29.005108 | R9: 29.206934 | S9: 29.397682 | T9: 29.579088 | U9: 29.751591 | V9: 29.918131 | W9: 30.076429 | X9: 30.228321 | Y9: 30.375742 | Z9: 30.522755 | AA9: 30.670509 | AB9: 30.818306 | AC9: 30.9662 | AD9: 31.114233 | AE9: 31.262747 | AF9: 31.41095 | AG9: 0.006
A10: Natural Gas Heat Pumps | B10: Residential Equipment: Equipment Stock: Main Space Heaters: Natural Gas Heat Pumps: High Zero-Carbon Technology Cost | C10: AEO.2025.HIGHZTC.EQNR_STK_RESD_MSHR_NHU_NA_NA_MILL.A | D10: millions | F10: 1.335856 | G10: 1.335485 | H10: 1.335121 | I10: 1.334763 | J10: 1.334411 | K10: 1.334067 | L10: 1.333728 | M10: 1.333394 | N10: 1.333067 | O10: 1.332746 | P10: 1.332431 | Q10: 1.33212 | R10: 1.331816 | S10: 1.331517 | T10: 1.331223 | U10: 1.330934 | V10: 1.330651 | W10: 1.330373 | X10: 1.330099 | Y10: 1.329831 | Z10: 1.329567 | AA10: 1.329308 | AB10: 1.329053 | AC10: 1.328804 | AD10: 1.328558 | AE10: 1.328316 | AF10: 1.328079 | AG10: 0
A11: Natural Gas Other | B11: Residential Equipment: Equipment Stock: Main Space Heaters: Natural Gas Other: High Zero-Carbon Technology Cost | C11: AEO.2025.HIGHZTC.EQNR_STK_RESD_MSHR_NGO_NA_NA_MILL.A | D11: millions | F11: 65.614693 | G11: 66.503311 | H11: 67.422646 | I11: 68.347206 | J11: 69.275345 | K11: 70.215851 | L11: 71.155624 | M11: 72.095222 | N11: 73.022018 | O11: 73.917961 | P11: 74.776138 | Q11: 75.619469 | R11: 76.443016 | S11: 77.232452 | T11: 77.991676 | U11: 78.71611 | V11: 79.412209 | W11: 80.076683 | X11: 80.717903 | Y11: 81.333214 | Z11: 81.934601 | AA11: 82.534103 | AB11: 83.129738 | AC11: 83.72612 | AD11: 84.322975 | AE11: 84.920403 | AF11: 85.516907 | AG11: 0.01
A12: Distillate Fuel Oil | B12: Residential Equipment: Equipment Stock: Main Space Heaters: Distillate Fuel Oil: High Zero-Carbon Technology Cost | C12: AEO.2025.HIGHZTC.EQNR_STK_RESD_MSHR_DFO_NA_NA_MILL.A | D12: millions | F12: 4.76794 | G12: 4.7259 | H12: 4.684821 | I12: 4.644579 | J12: 4.60502 | K12: 4.565969 | L12: 4.526826 | M12: 4.487612 | N12: 4.449521 | O12: 4.412687 | P12: 4.377314 | Q12: 4.343427 | R12: 4.310317 | S12: 4.277948 | T12: 4.246086 | U12: 4.214488 | V12: 4.183174 | W12: 4.152061 | X12: 4.122024 | Y12: 4.093054 | Z12: 4.065121 | AA12: 4.0385 | AB12: 4.012821 | AC12: 3.986746 | AD12: 3.960447 | AE12: 3.934162 | AF12: 3.908093 | AG12: -0.008
A13: Propane | B13: Residential Equipment: Equipment Stock: Main Space Heaters: Propane: High Zero-Carbon Technology Cost | C13: AEO.2025.HIGHZTC.EQNR_STK_RESD_MSHR_PROP_NA_NA_MILL.A | D13: millions | F13: 5.242597 | G13: 5.231007 | H13: 5.222726 | I13: 5.213856 | J13: 5.201762 | K13: 5.192317 | L13: 5.180441 | M13: 5.167188 | N13: 5.155312 | O13: 5.143894 | P13: 5.132373 | Q13: 5.121347 | R13: 5.111237 | S13: 5.101963 | T13: 5.09299 | U13: 5.084504 | V13: 5.077328 | W13: 5.070891 | X13: 5.064682 | Y13: 5.058537 | Z13: 5.052648 | AA13: 5.047476 | AB13: 5.043245 | AC13: 5.03766 | AD13: 5.030745 | AE13: 5.022702 | AF13: 5.01332 | AG13: -0.002
A14: Kerosene | B14: Residential Equipment: Equipment Stock: Main Space Heaters: Kerosene: High Zero-Carbon Technology Cost | C14: AEO.2025.HIGHZTC.EQNR_STK_RESD_MSHR_KRS_NA_NA_MILL.A | D14: millions | F14: 0.004925 | G14: 0.007897 | H14: 0.011523 | I14: 0.015072 | J14: 0.018269 | K14: 0.02133 | L14: 0.02419 | M14: 0.027018 | N14: 0.029863 | O14: 0.032679 | P14: 0.035394 | Q14: 0.038013 | R14: 0.040598 | S14: 0.043115 | T14: 0.045557 | U14: 0.047931 | V14: 0.050323 | W14: 0.052708 | X14: 0.055048 | Y14: 0.057337 | Z14: 0.059592 | AA14: 0.06182 | AB14: 0.063984 | AC14: 0.066125 | AD14: 0.068224 | AE14: 0.0703 | AF14: 0.072325 | AG14: 0.109
A15: Wood Stoves | B15: Residential Equipment: Equipment Stock: Main Space Heaters: Wood Stoves: High Zero-Carbon Technology Cost | C15: AEO.2025.HIGHZTC.EQNR_STK_RESD_MSHR_WDS_NA_NA_MILL.A | D15: millions | F15: 2.220637 | G15: 2.212639 | H15: 2.204829 | I15: 2.197059 | J15: 2.189375 | K15: 2.181753 | L15: 2.174187 | M15: 2.166692 | N15: 2.159028 | O15: 2.151248 | P15: 2.1434 | Q15: 2.135421 | R15: 2.127357 | S15: 2.119169 | T15: 2.11095 | U15: 2.102684 | V15: 2.094329 | W15: 2.085804 | X15: 2.077575 | Y15: 2.069646 | Z15: 2.062065 | AA15: 2.054862 | AB15: 2.048036 | AC15: 2.041663 | AD15: 2.035719 | AE15: 2.030173 | AF15: 2.025021 | AG15: -0.004
A16: Geothermal Heat Pumps | B16: Residential Equipment: Equipment Stock: Main Space Heaters: Geothermal Heat Pumps: High Zero-Carbon Technology Cost | C16: AEO.2025.HIGHZTC.EQNR_STK_RESD_MSHR_GEHP_NA_NA_MILL.A | D16: millions | F16: 1.360675 | G16: 1.408181 | H16: 1.455492 | I16: 1.50272 | J16: 1.549133 | K16: 1.595817 | L16: 1.642325 | M16: 1.688836 | N16: 1.73555 | O16: 1.781672 | P16: 1.826767 | Q16: 1.871948 | R16: 1.916753 | S16: 1.960757 | T16: 2.003791 | U16: 2.045475 | V16: 2.086105 | W16: 2.125625 | X16: 2.164013 | Y16: 2.200763 | Z16: 2.236357 | AA16: 2.271668 | AB16: 2.306613 | AC16: 2.34118 | AD16: 2.37536 | AE16: 2.409184 | AF16: 2.442582 | AG16: 0.023
A17: Total | B17: Residential Equipment: Equipment Stock: Main Space Heaters: Total: High Zero-Carbon Technology Cost | C17: AEO.2025.HIGHZTC.EQNR_STK_RESD_MSHR_TOT_NA_NA_MILL.A | D17: millions | F17: 123.79816 | G17: 125.16825 | H17: 126.62237 | I17: 128.09319 | J17: 129.56972 | K17: 131.08366 | L17: 132.59764 | M17: 134.11356 | N17: 135.61403 | O17: 137.06177 | P17: 138.44466 | Q17: 139.80519 | R17: 141.13614 | S17: 142.41052 | T17: 143.6335 | U17: 144.80035 | V17: 145.9243 | W17: 146.99674 | X17: 148.03105 | Y17: 149.02486 | Z17: 149.99976 | AA17: 150.97473 | AB17: 151.94659 | AC17: 152.91716 | AD17: 153.88637 | AE17: 154.8553 | AF17: 155.82082 | AG17: 0.009
A18: Space Cooling (million units)
A19: Electric Heat Pumps | B19: Residential Equipment: Equipment Stock: Space Cooling: Electric Heat Pumps: High Zero-Carbon Technology Cost | C19: AEO.2025.HIGHZTC.EQNR_STK_RESD_SPC_EHP_NA_NA_MILL.A | D19: millions | F19: 16.645529 | G19: 16.962236 | H19: 17.297932 | I19: 17.637352 | J19: 17.975958 | K19: 18.323191 | L19: 18.671116 | M19: 19.02029 | N19: 19.36697 | O19: 19.701841 | P19: 20.022339 | Q19: 20.338339 | R19: 20.648117 | S19: 20.945915 | T19: 21.232161 | U19: 21.506636 | V19: 21.772034 | W19: 22.026175 | X19: 22.271376 | Y19: 22.506746 | Z19: 22.737047 | AA19: 22.966528 | AB19: 23.194815 | AC19: 23.422672 | AD19: 23.650103 | AE19: 23.87734 | AF19: 24.103531 | AG19: 0.014
A20: Natural Gas Heat Pumps | B20: Residential Equipment: Equipment Stock: Space Cooling: Natural Gas Heat Pumps: High Zero-Carbon Technology Cost | C20: AEO.2025.HIGHZTC.EQNR_STK_RESD_SPC_NHU_NA_NA_MILL.A | D20: millions | F20: 1.335856 | G20: 1.335485 | H20: 1.335121 | I20: 1.334763 | J20: 1.334412 | K20: 1.334066 | L20: 1.333727 | M20: 1.333394 | N20: 1.333067 | O20: 1.332746 | P20: 1.33243 | Q20: 1.33212 | R20: 1.331816 | S20: 1.331517 | T20: 1.331223 | U20: 1.330934 | V20: 1.330651 | W20: 1.330372 | X20: 1.330099 | Y20: 1.329831 | Z20: 1.329567 | AA20: 1.329308 | AB20: 1.329053 | AC20: 1.328803 | AD20: 1.328558 | AE20: 1.328316 | AF20: 1.32808 | AG20: 0
A21: Geothermal Heat Pumps | B21: Residential Equipment: Equipment Stock: Space Cooling: Geothermal Heat Pumps: High Zero-Carbon Technology Cost | C21: AEO.2025.HIGHZTC.EQNR_STK_RESD_SPC_GEHP_NA_NA_MILL.A | D21: millions | F21: 1.360675 | G21: 1.40818 | H21: 1.455491 | I21: 1.50272 | J21: 1.549134 | K21: 1.595817 | L21: 1.642326 | M21: 1.688836 | N21: 1.73555 | O21: 1.781671 | P21: 1.826768 | Q21: 1.871948 | R21: 1.916753 | S21: 1.960756 | T21: 2.00379 | U21: 2.045475 | V21: 2.086105 | W21: 2.125626 | X21: 2.164013 | Y21: 2.200764 | Z21: 2.236356 | AA21: 2.271667 | AB21: 2.306613 | AC21: 2.341179 | AD21: 2.37536 | AE21: 2.409185 | AF21: 2.442581 | AG21: 0.023
A22: Central Air Conditioners | B22: Residential Equipment: Equipment Stock: Space Cooling: Central Air Conditioners: High Zero-Carbon Technology Cost | C22: AEO.2025.HIGHZTC.EQNR_STK_RESD_SPC_CAC_NA_NA_MILL.A | D22: millions | F22: 79.649452 | G22: 80.900047 | H22: 82.197365 | I22: 83.50415 | J22: 84.811256 | K22: 86.135658 | L22: 87.457458 | M22: 88.779007 | N22: 90.091568 | O22: 91.374115 | P22: 92.619194 | Q22: 93.851295 | R22: 95.065895 | S22: 96.248184 | T22: 97.400749 | U22: 98.520065 | V22: 99.614029 | W22: 100.67795 | X22: 101.7196 | Y22: 102.7365 | Z22: 103.74096 | AA22: 104.74514 | AB22: 105.74709 | AC22: 106.74812 | AD22: 107.74809 | AE22: 108.7477 | AF22: 109.74496 | AG22: 0.012
A23: Room Air Conditioners | B23: Residential Equipment: Equipment Stock: Space Cooling: Room Air Conditioners: High Zero-Carbon Technology Cost | C23: AEO.2025.HIGHZTC.EQNR_STK_RESD_SPC_RAC_NA_NA_MILL.A | D23: millions | F23: 43.140507 | G23: 43.232368 | H23: 43.345276 | I23: 43.46328 | J23: 43.586712 | K23: 43.719509 | L23: 43.854378 | M23: 43.990795 | N23: 44.124844 | O23: 44.250751 | P23: 44.367279 | Q23: 44.480221 | R23: 44.589432 | S23: 44.690407 | T23: 44.784588 | U23: 44.872437 | V23: 44.956017 | W23: 45.033756 | X23: 45.107018 | Y23: 45.177341 | Z23: 45.247604 | AA23: 45.318493 | AB23: 45.389637 | AC23: 45.461102 | AD23: 45.53299 | AE23: 45.605553 | AF23: 45.678272 | AG23: 0.002
A24: Total | B24: Residential Equipment: Equipment Stock: Space Cooling: Total: High Zero-Carbon Technology Cost | C24: AEO.2025.HIGHZTC.EQNR_STK_RESD_SPC_TOT_NA_NA_MILL.A | D24: millions | F24: 142.13202 | G24: 143.83832 | H24: 145.63118 | I24: 147.44226 | J24: 149.25748 | K24: 151.10825 | L24: 152.95901 | M24: 154.81233 | N24: 156.65199 | O24: 158.44113 | P24: 160.16801 | Q24: 161.87393 | R24: 163.55202 | S24: 165.17679 | T24: 166.75252 | U24: 168.27554 | V24: 169.75884 | W24: 171.19388 | X24: 172.5921 | Y24: 173.95119 | Z24: 175.29153 | AA24: 176.63113 | AB24: 177.96719 | AC24: 179.30188 | AD24: 180.6351 | AE24: 181.96808 | AF24: 183.29742 | AG24: 0.01
A25: Water Heaters (million units)
A26: Electric | B26: Residential Equipment: Equipment Stock: Water Heaters: Electric: High Zero-Carbon Technology Cost | C26: AEO.2025.HIGHZTC.EQNR_STK_RESD_WHT_ELE_NA_NA_MILL.A | D26: millions | F26: 62.064091 | G26: 62.296463 | H26: 62.600315 | I26: 62.92688 | J26: 63.228168 | K26: 64.053841 | L26: 64.829208 | M26: 65.567513 | N26: 66.280678 | O26: 66.984314 | P26: 67.653503 | Q26: 68.314453 | R26: 68.97834 | S26: 69.632027 | T26: 70.273941 | U26: 70.902107 | V26: 71.522514 | W26: 72.129929 | X26: 72.728317 | Y26: 73.317879 | Z26: 73.899185 | AA26: 74.478477 | AB26: 75.054726 | AC26: 75.626358 | AD26: 76.193161 | AE26: 76.757141 | AF26: 77.316254 | AG26: 0.008
A27: Natural Gas | B27: Residential Equipment: Equipment Stock: Water Heaters: Natural Gas: High Zero-Carbon Technology Cost | C27: AEO.2025.HIGHZTC.EQNR_STK_RESD_WHT_NG_NA_NA_MILL.A | D27: millions | F27: 64.896248 | G27: 65.896965 | H27: 66.916298 | I27: 67.939789 | J27: 68.981888 | K27: 69.718719 | L27: 70.479591 | M27: 71.256226 | N27: 72.025871 | O27: 72.786705 | P27: 73.528267 | Q27: 74.274551 | R27: 74.990112 | S27: 75.663231 | T27: 76.299583 | U27: 76.895554 | V27: 77.45697 | W27: 77.980125 | X27: 78.47403 | Y27: 78.935936 | Z27: 79.385979 | AA27: 79.836296 | AB27: 80.28476 | AC27: 80.734146 | AD27: 81.184738 | AE27: 81.635727 | AF27: 82.086113 | AG27: 0.009
A28: Distillate Fuel Oil | B28: Residential Equipment: Equipment Stock: Water Heaters: Distillate Fuel Oil: High Zero-Carbon Technology Cost | C28: AEO.2025.HIGHZTC.EQNR_STK_RESD_WHT_DFO_NA_NA_MILL.A | D28: millions | F28: 2.328812 | G28: 2.229761 | H28: 2.137233 | I28: 2.050461 | J28: 1.970477 | K28: 1.896038 | L28: 1.830604 | M28: 1.773455 | N28: 1.724959 | O28: 1.685178 | P28: 1.65441 | Q28: 1.632862 | R28: 1.610081 | S28: 1.586346 | T28: 1.561976 | U28: 1.537204 | V28: 1.512282 | W28: 1.487386 | X28: 1.462679 | Y28: 1.438287 | Z28: 1.414327 | AA28: 1.390946 | AB28: 1.368182 | AC28: 1.346109 | AD28: 1.32476 | AE28: 1.304158 | AF28: 1.284297 | AG28: -0.023
A29: Propane | B29: Residential Equipment: Equipment Stock: Water Heaters: Propane: High Zero-Carbon Technology Cost | C29: AEO.2025.HIGHZTC.EQNR_STK_RESD_WHT_PROP_NA_NA_MILL.A | D29: millions | F29: 3.994673 | G29: 3.890314 | H29: 3.796247 | I29: 3.708011 | J29: 3.626368 | K29: 3.531686 | L29: 3.447552 | M29: 3.374222 | N29: 3.31144 | O29: 3.259597 | P29: 3.218467 | Q29: 3.18944 | R29: 3.157171 | S29: 3.122084 | T29: 3.084893 | U29: 3.04617 | V29: 3.007124 | W29: 2.967928 | X29: 2.928841 | Y29: 2.889926 | Z29: 2.851814 | AA29: 2.814927 | AB29: 2.779243 | AC29: 2.745224 | AD29: 2.712765 | AE29: 2.681901 | AF29: 2.652292 | AG29: -0.016
A30: Solar Thermal | B30: Residential Equipment: Equipment Stock: Water Heaters: Solar Thermal: High Zero-Carbon Technology Cost | C30: AEO.2025.HIGHZTC.EQNR_STK_RESD_WHT_SLR_THERM_NA_MILL.A | D30: millions | F30: 1.564945 | G30: 1.899681 | H30: 2.211646 | I30: 2.501981 | J30: 2.791456 | K30: 2.906761 | L30: 3.028901 | M30: 3.155326 | N30: 3.279312 | O30: 3.349281 | P30: 3.38851 | Q30: 3.387712 | R30: 3.389602 | S30: 3.391462 | T30: 3.393306 | U30: 3.395105 | V30: 3.396857 | W30: 3.398571 | X30: 3.400233 | Y30: 3.401839 | Z30: 3.403495 | AA30: 3.405192 | AB30: 3.40693 | AC30: 3.408704 | AD30: 3.410507 | AE30: 3.412341 | AF30: 3.414205 | AG30: 0.03
A31: Total | B31: Residential Equipment: Equipment Stock: Water Heaters: Total: High Zero-Carbon Technology Cost | C31: AEO.2025.HIGHZTC.EQNR_STK_RESD_WHT_TOT_NA_NA_MILL.A | D31: millions | F31: 134.84877 | G31: 136.21318 | H31: 137.66174 | I31: 139.12712 | J31: 140.59836 | K31: 142.10706 | L31: 143.61586 | M31: 145.12672 | N31: 146.62227 | O31: 148.06508 | P31: 149.44313 | Q31: 150.79901 | R31: 152.12529 | S31: 153.39516 | T31: 154.61371 | U31: 155.77615 | V31: 156.89575 | W31: 157.96393 | X31: 158.99411 | Y31: 159.98387 | Z31: 160.95477 | AA31: 161.92584 | AB31: 162.89384 | AC31: 163.86055 | AD31: 164.82593 | AE31: 165.79126 | AF31: 166.75317 | AG31: 0.008
A32: Cooking Equipment (million units)
A33: Electric | B33: Residential Equipment: Equipment Stock: Cooking Equipment: Electric: High Zero-Carbon Technology Cost | C33: AEO.2025.HIGHZTC.EQNR_STK_RESD_CER_ELE_NA_NA_MILL.A | D33: millions | F33: 100.27812 | G33: 101.10259 | H33: 101.98053 | I33: 102.8632 | J33: 103.74537 | K33: 104.65044 | L33: 105.55076 | M33: 106.44516 | N33: 107.31894 | O33: 108.1434 | P33: 108.88472 | Q33: 109.57114 | R33: 110.1867 | S33: 110.70435 | T33: 111.20811 | U33: 111.71865 | V33: 112.24985 | W33: 112.80871 | X33: 113.41383 | Y33: 113.98341 | Z33: 114.53365 | AA33: 115.07655 | AB33: 115.60883 | AC33: 116.13017 | AD33: 116.6391 | AE33: 117.13462 | AF33: 117.61186 | AG33: 0.006
A34: Natural Gas | B34: Residential Equipment: Equipment Stock: Cooking Equipment: Natural Gas: High Zero-Carbon Technology Cost | C34: AEO.2025.HIGHZTC.EQNR_STK_RESD_CER_NG_NA_NA_MILL.A | D34: millions | F34: 53.97237 | G34: 54.503727 | H34: 55.061764 | I34: 55.632816 | J34: 56.213551 | K34: 56.80965 | L34: 57.412582 | M34: 58.02486 | N34: 58.644409 | O34: 59.262939 | P34: 59.903133 | Q34: 60.579704 | R34: 61.301079 | S34: 62.067856 | T34: 62.795506 | U34: 63.458031 | V34: 64.053505 | W34: 64.565849 | X34: 64.989624 | Y34: 65.410423 | Z34: 65.83329 | AA34: 66.264915 | AB34: 66.705818 | AC34: 67.157867 | AD34: 67.622643 | AE34: 68.102386 | AF34: 68.598465 | AG34: 0.009
A35: Propane | B35: Residential Equipment: Equipment Stock: Cooking Equipment: Propane: High Zero-Carbon Technology Cost | C35: AEO.2025.HIGHZTC.EQNR_STK_RESD_CER_PROP_NA_NA_MILL.A | D35: millions | F35: 6.249792 | G35: 6.24914 | H35: 6.252706 | I35: 6.255498 | J35: 6.255161 | K35: 6.254043 | L35: 6.251281 | M35: 6.247181 | N35: 6.241242 | O35: 6.233177 | P35: 6.221874 | Q35: 6.207108 | R35: 6.1889 | S35: 6.166887 | T35: 6.14676 | U35: 6.128918 | V35: 6.114851 | W35: 6.104977 | X35: 6.099405 | Y35: 6.092152 | Z35: 6.083468 | AA35: 6.07354 | AB35: 6.062016 | AC35: 6.049131 | AD35: 6.034698 | AE35: 6.018864 | AF35: 6.001561 | AG35: -0.002
A36: Total | B36: Residential Equipment: Equipment Stock: Cooking Equipment: Total: High Zero-Carbon Technology Cost | C36: AEO.2025.HIGHZTC.EQNR_STK_RESD_CER_TOT_NA_NA_MILL.A | D36: millions | F36: 160.50027 | G36: 161.85547 | H36: 163.295 | I36: 164.75151 | J36: 166.21408 | K36: 167.71414 | L36: 169.21463 | M36: 170.71719 | N36: 172.20459 | O36: 173.63953 | P36: 175.00974 | Q36: 176.35796 | R36: 177.67668 | S36: 178.93909 | T36: 180.15037 | U36: 181.3056 | V36: 182.41821 | W36: 183.47954 | X36: 184.50285 | Y36: 185.48598 | Z36: 186.45041 | AA36: 187.41501 | AB36: 188.37665 | AC36: 189.33717 | AD36: 190.29645 | AE36: 191.25586 | AF36: 192.21188 | AG36: 0.007
A37: Clothes Dryers (million units)
A38: Electric | B38: Residential Equipment: Equipment Stock: Clothes Dryers: Electric: High Zero-Carbon Technology Cost | C38: AEO.2025.HIGHZTC.EQNR_STK_RESD_CDR_ELE_NA_NA_MILL.A | D38: millions | F38: 92.221107 | G38: 94.908974 | H38: 97.661568 | I38: 100.4443 | J38: 103.24648 | K38: 106.05999 | L38: 108.87318 | M38: 111.66229 | N38: 114.41385 | O38: 117.12387 | P38: 119.78091 | Q38: 122.4272 | R38: 125.05272 | S38: 127.63446 | T38: 130.17616 | U38: 132.67476 | V38: 135.14604 | W38: 137.59196 | X38: 139.98711 | Y38: 142.33012 | Z38: 144.64094 | AA38: 146.94054 | AB38: 149.23036 | AC38: 151.51019 | AD38: 153.78226 | AE38: 156.04994 | AF38: 158.30891 | AG38: 0.021
A39: Natural Gas | B39: Residential Equipment: Equipment Stock: Clothes Dryers: Natural Gas: High Zero-Carbon Technology Cost | C39: AEO.2025.HIGHZTC.EQNR_STK_RESD_CDR_NG_NA_NA_MILL.A | D39: millions | F39: 20.353802 | G39: 20.727465 | H39: 21.108976 | I39: 21.498468 | J39: 21.905369 | K39: 22.331652 | L39: 22.776669 | M39: 23.24667 | N39: 23.740404 | O39: 24.225313 | P39: 24.699818 | Q39: 25.166246 | R39: 25.623446 | S39: 26.068548 | T39: 26.501984 | U39: 26.919897 | V39: 27.319826 | W39: 27.699757 | X39: 28.090372 | Y39: 28.489046 | Z39: 28.897078 | AA39: 29.31538 | AB39: 29.741957 | AC39: 30.175976 | AD39: 30.615866 | AE39: 31.060276 | AF39: 31.508205 | AG39: 0.017
A40: Total | B40: Residential Equipment: Equipment Stock: Clothes Dryers: Total: High Zero-Carbon Technology Cost | C40: AEO.2025.HIGHZTC.EQNR_STK_RESD_CDR_TOT_NA_NA_MILL.A | D40: millions | F40: 112.57491 | G40: 115.63644 | H40: 118.77055 | I40: 121.94276 | J40: 125.15185 | K40: 128.39165 | L40: 131.64984 | M40: 134.90897 | N40: 138.15425 | O40: 141.34918 | P40: 144.48073 | Q40: 147.59345 | R40: 150.67616 | S40: 153.703 | T40: 156.67815 | U40: 159.59465 | V40: 162.46587 | W40: 165.29172 | X40: 168.07748 | Y40: 170.81917 | Z40: 173.53803 | AA40: 176.25592 | AB40: 178.97232 | AC40: 181.68617 | AD40: 184.39812 | AE40: 187.11021 | AF40: 189.81712 | AG40: 0.02
...

Sheet Table_4._Residential_Sector_Key
A1: Table 4. Residential Sector Key Indicators and Consumption
A2: https://www.eia.gov/outlooks/aeo/data/browser/#/?id=4-AEO2025&cases=highZTC&sourcekey=0
A3: Tue Dec 02 2025 13:13:01 GMT-0800 (Pacific Standard Time)
A4: Source: U.S. Energy Information Administration
B5: full name | C5: api key | D5: units | E5: 2023 | F5: 2024 | G5: 2025 | H5: 2026 | I5: 2027 | J5: 2028 | K5: 2029 | L5: 2030 | M5: 2031 | N5: 2032 | O5: 2033 | P5: 2034 | Q5: 2035 | R5: 2036 | S5: 2037 | T5: 2038 | U5: 2039 | V5: 2040 | W5: 2041 | X5: 2042 | Y5: 2043 | Z5: 2044 | AA5: 2045 | AB5: 2046 | AC5: 2047 | AD5: 2048 | AE5: 2049 | AF5: 2050 | AG5: Growth (2024-2050)
A6: Key Indicators
A7: Households (millions)
A8: Single-Family | B8: Residential: Key Indicators: Households: Single-Family: High Zero-Carbon Technology Cost | C8: AEO.2025.HIGHZTC.KEI_HHD_RESD_SFR_NA_NA_USA_MILL.A | D8: millions | F8: 88.609744 | G8: 89.620168 | H8: 90.63056 | I8: 91.639144 | J8: 92.631344 | K8: 93.625568 | L8: 94.61288 | M8: 95.59792 | N8: 96.579056 | O8: 97.53976 | P8: 98.471496 | Q8: 99.397144 | R8: 100.30808 | S8: 101.19444 | T8: 102.05506 | U8: 102.88178 | V8: 103.68032 | W8: 104.44803 | X8: 105.19444 | Y8: 105.90901 | Z8: 106.60332 | AA8: 107.29699 | AB8: 107.98818 | AC8: 108.67842 | AD8: 109.36732 | AE8: 110.05501 | AF8: 110.7399 | AG8: 0.009
A9: Multifamily | B9: Residential: Key Indicators: Households: Multifamily: High Zero-Carbon Technology Cost | C9: AEO.2025.HIGHZTC.KEI_HHD_RESD_MFR_NA_NA_USA_MILL.A | D9: millions | F9: 34.017912 | G9: 34.38036 | H9: 34.797956 | I9: 35.233648 | J9: 35.702292 | K9: 36.208236 | L9: 36.726044 | M9: 37.24678 | N9: 37.753312 | O9: 38.226856 | P9: 38.666984 | Q9: 39.093076 | R9: 39.503836 | S9: 39.883568 | T9: 40.239072 | U9: 40.573248 | V9: 40.890328 | W9: 41.185544 | X9: 41.464128 | Y9: 41.734528 | Z9: 42.00598 | AA9: 42.277656 | AB9: 42.549808 | AC9: 42.820992 | AD9: 43.09248 | AE9: 43.364628 | AF9: 43.636816 | AG9: 0.01
A10: Mobile Homes | B10: Residential: Key Indicators: Households: Mobile Homes: High Zero-Carbon Technology Cost | C10: AEO.2025.HIGHZTC.KEI_HHD_RESD_MBH_NA_NA_USA_MILL.A | D10: millions | F10: 6.755902 | G10: 6.748634 | H10: 6.770403 | I10: 6.792666 | J10: 6.804218 | K10: 6.813859 | L10: 6.818653 | M10: 6.824849 | N10: 6.833779 | O10: 6.843395 | P10: 6.850643 | Q10: 6.855789 | R10: 6.86137 | S10: 6.866089 | T10: 6.869494 | U10: 6.871957 | V10: 6.87686 | W10: 6.883047 | X10: 6.889117 | Y10: 6.89479 | Z10: 6.900812 | AA10: 6.907353 | AB10: 6.912851 | AC10: 6.918932 | AD10: 6.924763 | AE10: 6.931044 | AF10: 6.936647 | AG10: 0.001
A11: Total | B11: Residential: Key Indicators: Households: Total: High Zero-Carbon Technology Cost | C11: AEO.2025.HIGHZTC.KEI_HHD_RESD_TEN_NA_NA_USA_MILL.A | D11: millions | F11: 129.38356 | G11: 130.74916 | H11: 132.19892 | I11: 133.66546 | J11: 135.13785 | K11: 136.64766 | L11: 138.15758 | M11: 139.66955 | N11: 141.16615 | O11: 142.61001 | P11: 143.98912 | Q11: 145.34601 | R11: 146.67328 | S11: 147.9441 | T11: 149.16362 | U11: 150.32698 | V11: 151.44751 | W11: 152.51662 | X11: 153.54769 | Y11: 154.53833 | Z11: 155.51011 | AA11: 156.482 | AB11: 157.45084 | AC11: 158.41834 | AD11: 159.38456 | AE11: 160.35068 | AF11: 161.31337 | AG11: 0.009
A12: Average House Square Footage | B12: Residential: Key Indicators: Average House Square Footage: High Zero-Carbon Technology Cost | C12: AEO.2025.HIGHZTC.KEI_HHD_RESD_NA_NA_NA_USA_SQFT.A | D12: sq ft | F12: 1643.9569 | G12: 1650.5161 | H12: 1656.462 | I12: 1662.1603 | J12: 1667.5287 | K12: 1672.5446 | L12: 1677.3794 | M12: 1682.076 | N12: 1686.7471 | O12: 1691.495 | P12: 1696.3218 | Q12: 1701.146 | R12: 1705.9552 | S12: 1710.8412 | T12: 1715.7644 | U12: 1720.6978 | V12: 1725.6134 | W12: 1730.5463 | X12: 1735.4882 | Y12: 1740.3724 | Z12: 1745.155 | AA12: 1749.8751 | AB12: 1754.5343 | AC12: 1759.1407 | AD12: 1763.6879 | AE12: 1768.1737 | AF12: 1772.6058 | AG12: 0.003
A13: Energy Intensity
A14: (MMBtu per household)
A15: Gross End-use Consumption | B15: Residential: Household Energy Intensity: Gross End-use Consumption: High Zero-Carbon Technology Cost | C15: AEO.2025.HIGHZTC.INY_HHD_RESD_DELE_NA_NA_USA_MILLBTUPHOSD.A | D15: MMBtu/household | F15: 85.992244 | G15: 87.9766 | H15: 87.58989 | I15: 87.167932 | J15: 86.534193 | K15: 85.477507 | L15: 84.242287 | M15: 82.878242 | N15: 81.472909 | O15: 80.23763 | P15: 79.124025 | Q15: 78.223224 | R15: 77.510909 | S15: 76.934631 | T15: 76.394609 | U15: 75.9338 | V15: 75.490184 | W15: 75.046198 | X15: 74.63335 | Y15: 74.262238 | Z15: 73.916539 | AA15: 73.581211 | AB15: 73.25364 | AC15: 72.937099 | AD15: 72.637647 | AE15: 72.361427 | AF15: 72.093053 | AG15: -0.007
A16: Delivered Energy Consumption | B16: Residential: Household Energy Intensity: Delivered Energy Consumption: High Zero-Carbon Technology Cost | C16: AEO.2025.HIGHZTC.INY_HHD_RESD_TEN_NA_NA_USA_MILLBTUPHOSD.A | D16: MMBtu/household | F16: 84.632913 | G16: 86.447232 | H16: 85.892414 | I16: 85.317887 | J16: 84.531319 | K16: 83.322996 | L16: 81.928291 | M16: 80.396377 | N16: 78.827237 | O16: 77.431217 | P16: 76.162388 | Q16: 75.148382 | R16: 74.320522 | S16: 73.627571 | T16: 72.966007 | U16: 72.382382 | V16: 71.813781 | W16: 71.24327 | X16: 70.700708 | Y16: 70.198181 | Z16: 69.719191 | AA16: 69.247444 | AB16: 68.781064 | AC16: 68.323618 | AD16: 67.880286 | AE16: 67.458633 | AF16: 67.043821 | AG16: -0.009
A17: (thousand Btu per square foot)
A18: Gross End-use Consumption | B18: Residential: Energy Intensity per Square Foot: Gross End-use Consumption: High Zero-Carbon Technology Cost | C18: AEO.2025.HIGHZTC.INY_HHD_RESD_DELE_NA_NA_USA_THBTUPSQFT.A | D18: thousand Btu/sq ft | F18: 52.308089 | G18: 53.302479 | H18: 52.877692 | I18: 52.442555 | J18: 51.893676 | K18: 51.106266 | L18: 50.22256 | M18: 49.2714 | N18: 48.301794 | O18: 47.435925 | P18: 46.644467 | Q18: 45.982663 | R18: 45.435489 | S18: 44.968891 | T18: 44.525116 | U18: 44.129656 | V18: 43.74687 | W18: 43.365612 | X18: 43.00424 | Y18: 42.670314 | Z18: 42.355285 | AA18: 42.049407 | AB18: 41.751045 | AC18: 41.461776 | AD18: 41.185092 | AE18: 40.924388 | AF18: 40.670662 | AG18: -0.01
A19: Delivered Energy Consumption | B19: Residential: Energy Intensity per Square Foot: Delivered Energy Consumption: High Zero-Carbon Technology Cost | C19: AEO.2025.HIGHZTC.INY_HHD_RESD_TEN_NA_NA_USA_THBTUPSQFT.A | D19: thousand Btu/sq ft | F19: 51.481224 | G19: 52.375879 | H19: 51.852933 | I19: 51.329518 | J19: 50.692573 | K19: 49.818103 | L19: 48.843029 | M19: 47.795923 | N19: 46.733288 | O19: 45.776794 | P19: 44.89855 | Q19: 44.175151 | R19: 43.565342 | S19: 43.035889 | T19: 42.526822 | U19: 42.065715 | V19: 41.616379 | W19: 41.168082 | X19: 40.738225 | Y19: 40.335149 | Z19: 39.950142 | AA19: 39.572792 | AB19: 39.201892 | AC19: 38.839199 | AD19: 38.487698 | AE19: 38.151587 | AF19: 37.822182 | AG19: -0.012
A20: Energy Consumption by Fuel
A21: Electricity
A22: Space Heating | B22: Residential: Electricity: Space Heating: High Zero-Carbon Technology Cost | C22: AEO.2025.HIGHZTC.CNSM_HHD_RESD_SPH_ELC_NA_USA_QBTU.A | D22: quads | F22: 0.528061 | G22: 0.582562 | H22: 0.585545 | I22: 0.589188 | J22: 0.589904 | K22: 0.586412 | L22: 0.580551 | M22: 0.573595 | N22: 0.566739 | O22: 0.560726 | P22: 0.554572 | Q22: 0.550309 | R22: 0.547657 | S22: 0.545295 | T22: 0.542041 | U22: 0.538591 | V22: 0.534952 | W22: 0.530828 | X22: 0.526828 | Y22: 0.522867 | Z22: 0.518328 | AA22: 0.513525 | AB22: 0.508348 | AC22: 0.502928 | AD22: 0.497403 | AE22: 0.492208 | AF22: 0.4868 | AG22: -0.003
A23: Space Cooling | B23: Residential: Electricity: Space Cooling: High Zero-Carbon Technology Cost | C23: AEO.2025.HIGHZTC.CNSM_NA_RESD_SPC_ELC_NA_USA_QBTU.A | D23: quads | F23: 0.997081 | G23: 0.952473 | H23: 0.971354 | I23: 0.98971 | J23: 1.002009 | K23: 1.00703 | L23: 1.009506 | M23: 1.010393 | N23: 1.012497 | O23: 1.019494 | P23: 1.028533 | Q23: 1.041697 | R23: 1.058786 | S23: 1.078113 | T23: 1.096537 | U23: 1.115933 | V23: 1.135576 | W23: 1.155665 | X23: 1.175584 | Y23: 1.195868 | Z23: 1.215889 | AA23: 1.235434 | AB23: 1.254577 | AC23: 1.273539 | AD23: 1.292448 | AE23: 1.311621 | AF23: 1.330636 | AG23: 0.011
A24: Water Heating | B24: Residential: Electricity: Water Heating: High Zero-Carbon Technology Cost | C24: AEO.2025.HIGHZTC.CNSM_NA_RESD_WTHT_ELC_NA_USA_QBTU.A | D24: quads | F24: 0.472693 | G24: 0.459259 | H24: 0.449699 | I24: 0.440442 | J24: 0.428544 | K24: 0.408148 | L24: 0.384946 | M24: 0.360722 | N24: 0.33842 | O24: 0.318282 | P24: 0.300561 | Q24: 0.285426 | R24: 0.272802 | S24: 0.262211 | T24: 0.253048 | U24: 0.245594 | V24: 0.239892 | W24: 0.23575 | X24: 0.233312 | Y24: 0.23256 | Z24: 0.231527 | AA24: 0.230325 | AB24: 0.228973 | AC24: 0.227549 | AD24: 0.226177 | AE24: 0.224938 | AF24: 0.223821 | AG24: -0.028
A25: Refrigeration | B25: Residential: Electricity: Refrigeration: High Zero-Carbon Technology Cost | C25: AEO.2025.HIGHZTC.CNSM_NA_RESD_REFR_ELC_NA_USA_QBTU.A | D25: quads | F25: 0.351479 | G25: 0.349737 | H25: 0.34897 | I25: 0.348118 | J25: 0.347168 | K25: 0.346545 | L25: 0.343717 | M25: 0.341147 | N25: 0.338816 | O25: 0.336635 | P25: 0.334581 | Q25: 0.332782 | R25: 0.331396 | S25: 0.330414 | T25: 0.32985 | U25: 0.329701 | V25: 0.329972 | W25: 0.33064 | X25: 0.331706 | Y25: 0.333167 | Z25: 0.335038 | AA25: 0.337389 | AB25: 0.340228 | AC25: 0.343544 | AD25: 0.346847 | AE25: 0.350126 | AF25: 0.353358 | AG25: 0
A26: Cooking | B26: Residential: Electricity: Cooking: High Zero-Carbon Technology Cost | C26: AEO.2025.HIGHZTC.CNSM_NA_RESD_CGR_ELC_NA_USA_QBTU.A | D26: quads | F26: 0.067364 | G26: 0.067851 | H26: 0.068571 | I26: 0.069303 | J26: 0.07004 | K26: 0.070797 | L26: 0.071554 | M26: 0.072311 | N26: 0.07306 | O26: 0.073778 | P26: 0.074459 | Q26: 0.075123 | R26: 0.075764 | S26: 0.076366 | T26: 0.076926 | U26: 0.077443 | V26: 0.077925 | W26: 0.078369 | X26: 0.078785 | Y26: 0.079176 | Z26: 0.079553 | AA26: 0.079923 | AB26: 0.080284 | AC26: 0.080637 | AD26: 0.080982 | AE26: 0.081316 | AF26: 0.081638 | AG26: 0.007
A27: Clothes Dryers | B27: Residential: Electricity: Clothes Dryers: High Zero-Carbon Technology Cost | C27: AEO.2025.HIGHZTC.CNSM_NA_RESD_CDR_ELC_NA_USA_QBTU.A | D27: quads | F27: 0.191812 | G27: 0.193075 | H27: 0.196545 | I27: 0.200855 | J27: 0.204061 | K27: 0.20567 | L27: 0.206345 | M27: 0.206255 | N27: 0.205808 | O27: 0.205284 | P27: 0.205276 | Q27: 0.206284 | R27: 0.208278 | S27: 0.210919 | T27: 0.213722 | U27: 0.216924 | V27: 0.220611 | W27: 0.224674 | X27: 0.228576 | Y27: 0.232386 | Z27: 0.235967 | AA27: 0.239332 | AB27: 0.242476 | AC27: 0.245414 | AD27: 0.248235 | AE27: 0.250977 | AF27: 0.253559 | AG27: 0.011
A28: Freezers | B28: Residential: Electricity: Freezers: High Zero-Carbon Technology Cost | C28: AEO.2025.HIGHZTC.CNSM_NA_RESD_FRZ_ELC_NA_USA_QBTU.A | D28: quads | F28: 0.079548 | G28: 0.079317 | H28: 0.079323 | I28: 0.079324 | J28: 0.079287 | K28: 0.079225 | L28: 0.07876 | M28: 0.078245 | N28: 0.07769 | O28: 0.077149 | P28: 0.076617 | Q28: 0.076115 | R28: 0.075638 | S28: 0.075175 | T28: 0.074736 | U28: 0.07432 | V28: 0.073932 | W28: 0.073581 | X28: 0.073268 | Y28: 0.072993 | Z28: 0.072761 | AA28: 0.072582 | AB28: 0.072468 | AC28: 0.072415 | AD28: 0.072435 | AE28: 0.072536 | AF28: 0.072717 | AG28: -0.003
A29: Lighting | B29: Residential: Electricity: Lighting: High Zero-Carbon Technology Cost | C29: AEO.2025.HIGHZTC.CNSM_NA_RESD_LGHTNG_ELC_NA_USA_QBTU.A | D29: quads | F29: 0.187371 | G29: 0.18539 | H29: 0.186964 | I29: 0.190632 | J29: 0.193727 | K29: 0.195604 | L29: 0.195166 | M29: 0.194531 | N29: 0.19432 | O29: 0.194149 | P29: 0.194404 | Q29: 0.195278 | R29: 0.196599 | S29: 0.198067 | T29: 0.199294 | U29: 0.200681 | V29: 0.198798 | W29: 0.197172 | X29: 0.195941 | Y29: 0.19514 | Z29: 0.194706 | AA29: 0.194468 | AB29: 0.194278 | AC29: 0.194106 | AD29: 0.194081 | AE29: 0.194207 | AF29: 0.194363 | AG29: 0.001
A30: Clothes Washers | B30: Residential: Electricity: Clothes Washers: High Zero-Carbon Technology Cost | C30: AEO.2025.HIGHZTC.CNSM_NA_RESD_CLW_ELC_NA_USA_QBTU.A | D30: quads | F30: 0.041807 | G30: 0.040731 | H30: 0.039766 | I30: 0.038787 | J30: 0.037633 | K30: 0.036454 | L30: 0.035086 | M30: 0.033659 | N30: 0.032143 | O30: 0.030826 | P30: 0.02971 | Q30: 0.028801 | R30: 0.028112 | S30: 0.027655 | T30: 0.027453 | U30: 0.027522 | V30: 0.02759 | W30: 0.027658 | X30: 0.027733 | Y30: 0.027815 | Z30: 0.027908 | AA30: 0.028016 | AB30: 0.028138 | AC30: 0.028273 | AD30: 0.02842 | AE30: 0.028576 | AF30: 0.028739 | AG30: -0.014
A31: Dishwashers | B31: Residential: Electricity: Dishwashers: High Zero-Carbon Technology Cost | C31: AEO.2025.HIGHZTC.CNSM_NA_RESD_DSW_ELC_NA_USA_QBTU.A | D31: quads | F31: 0.036367 | G31: 0.037219 | H31: 0.038216 | I31: 0.038546 | J31: 0.038751 | K31: 0.038915 | L31: 0.039032 | M31: 0.039101 | N31: 0.039118 | O31: 0.039202 | P31: 0.039359 | Q31: 0.039601 | R31: 0.039936 | S31: 0.040364 | T31: 0.040896 | U31: 0.041538 | V31: 0.042178 | W31: 0.042812 | X31: 0.043444 | Y31: 0.044074 | Z31: 0.044708 | AA31: 0.045349 | AB31: 0.045998 | AC31: 0.046655 | AD31: 0.047318 | AE31: 0.047988 | AF31: 0.048663 | AG31: 0.011
A32: Televisions and Related Equipment | B32: Residential: Electricity: Televisions: High Zero-Carbon Technology Cost | C32: AEO.2025.HIGHZTC.CNSM_NA_RESD_TVR_ELC_NA_USA_QBTU.A | D32: quads | F32: 0.129374 | G32: 0.126544 | H32: 0.125215 | I32: 0.124316 | J32: 0.122902 | K32: 0.120777 | L32: 0.118375 | M32: 0.115926 | N32: 0.113659 | O32: 0.11144 | P32: 0.1095 | Q32: 0.10799 | R32: 0.106861 | S32: 0.105954 | T32: 0.105066 | U32: 0.104306 | V32: 0.103691 | W32: 0.103142 | X32: 0.102677 | Y32: 0.102345 | Z32: 0.102119 | AA32: 0.102036 | AB32: 0.102082 | AC32: 0.102176 | AD32: 0.10236 | AE32: 0.102613 | AF32: 0.102926 | AG32: -0.009
A33: Computers and Related Equipment | B33: Residential: Electricity: Computers: High Zero-Carbon Technology Cost | C33: AEO.2025.HIGHZTC.CNSM_NA_RESD_CMPR_ELC_NA_USA_QBTU.A | D33: quads | F33: 0.100147 | G33: 0.098312 | H33: 0.097712 | I33: 0.097344 | J33: 0.096392 | K33: 0.094706 | L33: 0.092653 | M33: 0.090438 | N33: 0.088259 | O33: 0.086025 | P33: 0.083927 | Q33: 0.082077 | R33: 0.080451 | S33: 0.078944 | T33: 0.077403 | U33: 0.07593 | V33: 0.074545 | W33: 0.073196 | X33: 0.071926 | Y33: 0.070762 | Z33: 0.069712 | AA33: 0.068805 | AB33: 0.068054 | AC33: 0.067421 | AD33: 0.066941 | AE33: 0.066635 | AF33: 0.066465 | AG33: -0.016
... A39: Purchased Electricity at Residential Location | B39: Residential: Electricity: Purchased Electricity at Residential Location: High Zero-Carbon Technology Cost | C39: AEO.2025.HIGHZTC.CNSM_NA_RESD_PURCHELEC_ELC_NA_USA_QBTU.A | D39: quads | F39: 5.141959 | G39: 5.081856 | H39: 5.155061 | I39: 5.245214 | J39: 5.322819 | K39: 5.376949 | L39: 5.423333 | M39: 5.461133 | N39: 5.512463 | O39: 5.571132 | P39: 5.640814 | Q39: 5.72881 | R39: 5.829799 | S39: 5.937385 | T39: 6.039158 | U39: 6.141384 | V39: 6.238818 | W39: 6.331173 | X39: 6.419865 | Y39: 6.505672 | Z39: 6.584554 | AA39: 6.65771 | AB39: 6.726636 | AC39: 6.791243 | AD39: 6.851297 | AE39: 6.909533 | AF39: 6.964614 | AG39: 0.012
A40: Natural Gas
A41: Space Heating | B41: Residential: Natural Gas: Space Heating: High Zero-Carbon Technology Cost | C41: AEO.2025.HIGHZTC.CNSM_NA_RESD_SPH_NG_NA_USA_QBTU.A | D41: quads | F41: 2.777912 | G41: 3.12664 | H41: 3.141604 | I41: 3.146791 | J41: 3.143392 | K41: 3.126671 | L41: 3.103113 | M41: 3.069892 | N41: 3.026127 | O41: 2.987631 | P41: 2.946792 | Q41: 2.912199 | R41: 2.883551 | S41: 2.858295 | T41: 2.834296 | U41: 2.81154 | V41: 2.787776 | W41: 2.761015 | X41: 2.733698 | Y41: 2.706513 | Z41: 2.680865 | AA41: 2.657231 | AB41: 2.634207 | AC41: 2.611903 | AD41: 2.590528 | AE41: 2.569665 | AF41: 2.548368 | AG41: -0.003
A42: Space Cooling | B42: Residential: Natural Gas: Space Cooling: High Zero-Carbon Technology Cost | C42: AEO.2025.HIGHZTC.CNSM_NA_RESD_SPC_NG_NA_USA_QBTU.A | D42: quads | F42: 0.063499 | G42: 0.061038 | H42: 0.061464 | I42: 0.061531 | J42: 0.061383 | K42: 0.061147 | L42: 0.060918 | M42: 0.060665 | N42: 0.060395 | O42: 0.060147 | P42: 0.059927 | Q42: 0.059807 | R42: 0.059799 | S42: 0.059868 | T42: 0.059965 | U42: 0.060137 | V42: 0.060331 | W42: 0.060539 | X42: 0.060751 | Y42: 0.060975 | Z42: 0.061196 | AA42: 0.061401 | AB42: 0.061602 | AC42: 0.061793 | AD42: 0.061997 | AE42: 0.062199 | AF42: 0.062392 | AG42: -0.001
A43: Water Heating | B43: Residential: Natural Gas: Water Heating: High Zero-Carbon Technology Cost | C43: AEO.2025.HIGHZTC.CNSM_NA_RESD_WTHT_NG_NA_USA_QBTU.A | D43: quads | F43: 1.035874 | G43: 1.046498 | H43: 1.058767 | I43: 1.069351 | J43: 1.079818 | K43: 1.080751 | L43: 1.081037 | M43: 1.080496 | N43: 1.078113 | O43: 1.077774 | P43: 1.0797 | Q43: 1.084282 | R43: 1.088853 | S43: 1.093492 | T43: 1.09762 | U43: 1.101219 | V43: 1.10365 | W43: 1.104037 | X43: 1.102943 | Y43: 1.100647 | Z43: 1.097807 | AA43: 1.094437 | AB43: 1.09026 | AC43: 1.085951 | AD43: 1.081866 | AE43: 1.077826 | AF43: 1.074105 | AG43: 0.001
A44: Cooking | B44: Residential: Natural Gas: Cooking: High Zero-Carbon Technology Cost | C44: AEO.2025.HIGHZTC.CNSM_NA_RESD_CGR_NG_NA_USA_QBTU.A | D44: quads | F44: 0.077838 | G44: 0.077799 | H44: 0.077991 | I44: 0.078186 | J44: 0.078378 | K44: 0.078579 | L44: 0.078781 | M44: 0.078972 | N44: 0.079145 | O44: 0.079309 | P44: 0.079496 | Q44: 0.079723 | R44: 0.079999 | S44: 0.080326 | T44: 0.080726 | U44: 0.081166 | V44: 0.081648 | W44: 0.082162 | X44: 0.0827 | Y44: 0.083236 | Z44: 0.083776 | AA44: 0.084327 | AB44: 0.08489 | AC44: 0.085467 | AD44: 0.086059 | AE44: 0.08667 | AF44: 0.087302 | AG44: 0.004
A45: Clothes Dryers | B45: Residential: Natural Gas: Clothes Dryers: High Zero-Carbon Technology Cost | C45: AEO.2025.HIGHZTC.CNSM_NA_RESD_CDR_NG_NA_USA_QBTU.A | D45: quads | F45: 0.039583 | G45: 0.040486 | H45: 0.041405 | I45: 0.042257 | J45: 0.04311 | K45: 0.043956 | L45: 0.044797 | M45: 0.045565 | N45: 0.046229 | O45: 0.046833 | P45: 0.047464 | Q45: 0.048157 | R45: 0.04892 | S45: 0.049719 | T45: 0.050528 | U45: 0.051342 | V45: 0.052121 | W45: 0.052834 | X45: 0.053545 | Y45: 0.054265 | Z45: 0.055017 | AA45: 0.055794 | AB45: 0.056574 | AC45: 0.057377 | AD45: 0.058208 | AE45: 0.05904 | AF45: 0.059869 | AG45: 0.016
...

Sheet NREL EF Table 22
A1: Figure 22. Installed unit costs (left) and performance projections (right) for commercial air-source heat pumps
A2: Figure Notes: | B2: Installed costs include both capital and installation costs.
A4: Year | B4: Technology | C4: EFS Case | D4: Installed Cost ($/kBtu/hr) | E4: Efficiency (COP)
A5: 2015 | B5: Air Source Heat Pump | C5: Moderate Advancement | D5: 96 | E5: 3.3
A6: 2015 | B6: Air Source Heat Pump | C6: Rapid Advancement | D6: 96 | E6: 3.3
A7: 2015 | B7: Air Source Heat Pump | C7: Slow Advancement | D7: 96 | E7: 3.3
A8: 2015 | B8: Cold Climate Air Source Heat Pump | C8: Moderate Advancement | D8: 96 | E8: 1.5
A9: 2015 | B9: Cold Climate Air Source Heat Pump | C9: Rapid Advancement | D9: 96 | E9: 1.5
A10: 2015 | B10: Cold Climate Air Source Heat Pump | C10: Slow Advancement | D10: 96 | E10: 1.5
A11: 2020 | B11: Air Source Heat Pump | C11: Moderate Advancement | D11: 85 | E11: 3.75
A12: 2020 | B12: Air Source Heat Pump | C12: Rapid Advancement | D12: 80 | E12: 4
A13: 2020 | B13: Air Source Heat Pump | C13: Slow Advancement | D13: 92.873543 | E13: 3.4
A14: 2020 | B14: Cold Climate Air Source Heat Pump | C14: Moderate Advancement | D14: 85 | E14: 2
A15: 2020 | B15: Cold Climate Air Source Heat Pump | C15: Rapid Advancement | D15: 80 | E15: 2.5
A16: 2020 | B16: Cold Climate Air Source Heat Pump | C16: Slow Advancement | D16: 92.873543 | E16: 1.75
... A34: 2050 | B34: Cold Climate Air Source Heat Pump | C34: Slow Advancement | D34: 76.140668 | E34: 2.75

Sheet NREL EF Table 23
A1: Figure 23. Installed costs (left) and performance projections (right) for commercial HPWHs
A2: Figure Notes: | B2: Installed costs include both capital and installation costs.
A4: Year | B4: Technology | C4: EFS Case | D4: Installed Cost ($/kBtu/hr) | E4: Efficiency (COP)
A5: 2015 | B5: Heat Pump Water Heater | C5: Moderate Advancement | D5: 310 | E5: 2.45
A6: 2015 | B6: Heat Pump Water Heater | C6: Rapid Advancement | D6: 310 | E6: 2.45
A7: 2015 | B7: Heat Pump Water Heater | C7: Slow Advancement | D7: 310 | E7: 2.45
A8: 2020 | B8: Heat Pump Water Heater | C8: Moderate Advancement | D8: 287.51781 | E8: 3
A9: 2020 | B9: Heat Pump Water Heater | C9: Rapid Advancement | D9: 281.0389 | E9: 3
A10: 2020 | B10: Heat Pump Water Heater | C10: Slow Advancement | D10: 302.85283 | E10: 3
A11: 2030 | B11: Heat Pump Water Heater | C11: Moderate Advancement | D11: 247.32663 | E11: 3.25
A12: 2030 | B12: Heat Pump Water Heater | C12: Rapid Advancement | D12: 219.56945 | E12: 3.6
A13: 2030 | B13: Heat Pump Water Heater | C13: Slow Advancement | D13: 289.04903 | E13: 3
A14: 2040 | B14: Heat Pump Water Heater | C14: Moderate Advancement | D14: 212.75364 | E14: 3.35
A15: 2040 | B15: Heat Pump Water Heater | C15: Rapid Advancement | D15: 180 | E15: 3.85
A16: 2040 | B16: Heat Pump Water Heater | C16: Slow Advancement | D16: 275.8744 | E16: 3
... A19: 2050 | B19: Heat Pump Water Heater | C19: Slow Advancement | D19: 263.5 | E19: 3

Sheet Calcs>

Sheet Calculations
A1: Residential Equipment
A2: Heating
A3: Heating Energy Consumption per Unit per Year by Fuel (btu/unit) | B3: 2020 | C3: 2021 | D3: 2022 | E3: 2023 | F3: 2024 | G3: 2025 | H3: 2026 | I3: 2027 | J3: 2028 | K3: 2029 | L3: 2030 | M3: 2031 | N3: 2032 | O3: 2033 | P3: 2034 | Q3: 2035 | R3: 2036 | S3: 2037 | T3: 2038 | U3: 2039 | V3: 2040 | W3: 2041 | X3: 2042 | Y3: 2043 | Z3: 2044 | AA3: 2045 | AB3: 2046 | AC3: 2047 | AD3: 2048 | AE3: 2049 | AF3: 2050
A4: natural gas | C4: 0 | D4: 0 | E4: 0 | F4: =Table_4._Residential_Sector_Key!F41/SUM(Table_21._Residential_Sector_Eq!F10:F11)*10^15/10^6 -> 41491997 | G4: =Table_4._Residential_Sector_Key!G41/SUM(Table_21._Residential_Sector_Eq!G10:G11)*10^15/10^6 -> 46089261 | H4: =Table_4._Residential_Sector_Key!H41/SUM(Table_21._Residential_Sector_Eq!H10:H11)*10^15/10^6 -> 45690896 | I4: =Table_4._Residential_Sector_Key!I41/SUM(Table_21._Residential_Sector_Eq!I10:I11)*10^15/10^6 -> 45159330 | J4: =Table_4._Residential_Sector_Key!J41/SUM(Table_21._Residential_Sector_Eq!J10:J11)*10^15/10^6 -> 44517814 | K4: =Table_4._Residential_Sector_Key!K41/SUM(Table_21._Residential_Sector_Eq!K10:K11)*10^15/10^6 -> 43699156 | L4: =Table_4._Residential_Sector_Key!L41/SUM(Table_21._Residential_Sector_Eq!L10:L11)*10^15/10^6 -> 42807846 | M4: =Table_4._Residential_Sector_Key!M41/SUM(Table_21._Residential_Sector_Eq!M10:M11)*10^15/10^6 -> 41807842 | ... AF4: =Table_4._Residential_Sector_Key!AF41/SUM(Table_21._Residential_Sector_Eq!AF10:AF11)*10^15/10^6 -> 29343870
A5: oil | C5: 0 | D5: 0 | E5: 0 | F5: =Table_4._Residential_Sector_Key!F49/Table_21._Residential_Sector_Eq!F12*10^15/10^6 -> 79653267 | G5: =Table_4._Residential_Sector_Key!G49/Table_21._Residential_Sector_Eq!G12*10^15/10^6 -> 86956347 | H5: =Table_4._Residential_Sector_Key!H49/Table_21._Residential_Sector_Eq!H12*10^15/10^6 -> 86724765 | I5: =Table_4._Residential_Sector_Key!I49/Table_21._Residential_Sector_Eq!I12*10^15/10^6 -> 86019852 | J5: =Table_4._Residential_Sector_Key!J49/Table_21._Residential_Sector_Eq!J12*10^15/10^6 -> 85052399 | K5: =Table_4._Residential_Sector_Key!K49/Table_21._Residential_Sector_Eq!K12*10^15/10^6 -> 84013930 | L5: =Table_4._Residential_Sector_Key!L49/Table_21._Residential_Sector_Eq!L12*10^15/10^6 -> 82988611 | M5: =Table_4._Residential_Sector_Key!M49/Table_21._Residential_Sector_Eq!M12*10^15/10^6 -> 82160846 | ... AF5: =Table_4._Residential_Sector_Key!AF49/Table_21._Residential_Sector_Eq!AF12*10^15/10^6 -> 71026713
A6: biomass | C6: 0 | D6: 0 | E6: 0 | F6: =Table_4._Residential_Sector_Key!F59/Table_21._Residential_Sector_Eq!F15*10^15/10^6 -> 1.6102722e+08 | G6: =Table_4._Residential_Sector_Key!G59/Table_21._Residential_Sector_Eq!G15*10^15/10^6 -> 1.6500387e+08 | H6: =Table_4._Residential_Sector_Key!H59/Table_21._Residential_Sector_Eq!H15*10^15/10^6 -> 1.5994619e+08 | I6: =Table_4._Residential_Sector_Key!I59/Table_21._Residential_Sector_Eq!I15*10^15/10^6 -> 1.5807268e+08 | J6: =Table_4._Residential_Sector_Key!J59/Table_21._Residential_Sector_Eq!J15*10^15/10^6 -> 1.5790717e+08 | K6: =Table_4._Residential_Sector_Key!K59/Table_21._Residential_Sector_Eq!K15*10^15/10^6 -> 1.5836027e+08 | L6: =Table_4._Residential_Sector_Key!L59/Table_21._Residential_Sector_Eq!L15*10^15/10^6 -> 1.5881339e+08 | M6: =Table_4._Residential_Sector_Key!M59/Table_21._Residential_Sector_Eq!M15*10^15/10^6 -> 1.5807461e+08 | ... AF6: =Table_4._Residential_Sector_Key!AF59/Table_21._Residential_Sector_Eq!AF15*10^15/10^6 -> 1.32369e+08
A8: Incremental Equipment Cost | B8: 2017 | C8: 2020 | D8: 2030 | E8: 2040 | F8: 2050
A9: natural gas (2017 USD) | B9: ='EIA Costs'!E48-'EIA Costs'!E10 -> 3050 | C9: ='EIA Costs'!H48-'EIA Costs'!H10 -> 2860 | D9: ='EIA Costs'!J48-'EIA Costs'!J10 -> 2910 | E9: ='EIA Costs'!L48-'EIA Costs'!L10 -> 2910 | F9: ='EIA Costs'!N48-'EIA Costs'!N10 -> 2910
A10: oil (2017 USD) | B10: ='EIA Costs'!E48-AVERAGE('EIA Costs'!E23:E24) -> 975 | C10: ='EIA Costs'!H48-AVERAGE('EIA Costs'!H23:H24) -> 975 | D10: ='EIA Costs'!J48-AVERAGE('EIA Costs'!J23:J24) -> 925 | E10: ='EIA Costs'!L48-AVERAGE('EIA Costs'!L23:L24) -> 925 | F10: ='EIA Costs'!N48-AVERAGE('EIA Costs'!N23:N24) -> 925
A11: biomass (2017 USD) | B11: ='EIA Costs'!E48-'EIA Costs'!D36 -> 400 | C11: ='EIA Costs'!H48-'EIA Costs'!F36 -> 400 | D11: ='EIA Costs'!J48-'EIA Costs'!H36 -> 350 | E11: ='EIA Costs'!L48-'EIA Costs'!J36 -> 250 | F11: ='EIA Costs'!N48-'EIA Costs'!L36 -> 150
A13: Annualized Incremental Equipment Cost | B13: 2020 | C13: 2021 | D13: 2022 | E13: 2023 | F13: 2024 | G13: 2025 | H13: 2026 | I13: 2027 | J13: 2028 | K13: 2029 | L13: 2030 | M13: 2031 | N13: 2032 | O13: 2033 | P13: 2034 | Q13: 2035 | R13: 2036 | S13: 2037 | T13: 2038 | U13: 2039 | V13: 2040 | W13: 2041 | X13: 2042 | Y13: 2043 | Z13: 2044 | AA13: 2045 | AB13: 2046 | AC13: 2047 | AD13: 2048 | AE13: 2049 | AF13: 2050
A14: natural gas (2012 USD) | B14: =(TREND($B$9:$C$9,$B$8:$C$8,B$13))*(About!$A$53) -> 2678.8464 | C14: =(TREND($C$9:$D$9,$C$8:$D$8,C$13))*(About!$A$53) -> 2683.5297 | D14: =(TREND($C$9:$D$9,$C$8:$D$8,D$13))*(About!$A$53) -> 2688.213 | E14: =(TREND($C$9:$D$9,$C$8:$D$8,E$13))*(About!$A$53) -> 2692.8963 | F14: =(TREND($C$9:$D$9,$C$8:$D$8,F$13))*(About!$A$53) -> 2697.5796 | G14: =(TREND($C$9:$D$9,$C$8:$D$8,G$13))*(About!$A$53) -> 2702.2629 | H14: =(TREND($C$9:$D$9,$C$8:$D$8,H$13))*(About!$A$53) -> 2706.9462 | I14: =(TREND($C$9:$D$9,$C$8:$D$8,I$13))*(About!$A$53) -> 2711.6295 | J14: =(TREND($C$9:$D$9,$C$8:$D$8,J$13))*(About!$A$53) -> 2716.3128 | ... L14: =(TREND($C$9:$D$9,$C$8:$D$8,L$13))*(About!$A$53) -> 2725.6794 | M14: =(TREND($D$9:$F$9,$D$8:$F$8,M$13))*(About!$A$53) -> 2725.6794 | N14: =(TREND($D$9:$F$9,$D$8:$F$8,N$13))*(About!$A$53) -> 2725.6794 | O14: =(TREND($D$9:$F$9,$D$8:$F$8,O$13))*(About!$A$53) -> 2725.6794 | P14: =(TREND($D$9:$F$9,$D$8:$F$8,P$13))*(About!$A$53) -> 2725.6794 | Q14: =(TREND($D$9:$F$9,$D$8:$F$8,Q$13))*(About!$A$53) -> 2725.6794 | R14: =(TREND($D$9:$F$9,$D$8:$F$8,R$13))*(About!$A$53) -> 2725.6794 | S14: =(TREND($D$9:$F$9,$D$8:$F$8,S$13))*(About!$A$53) -> 2725.6794 | T14: =(TREND($D$9:$F$9,$D$8:$F$8,T$13))*(About!$A$53) -> 2725.6794 | ... AF14: =(TREND($D$9:$F$9,$D$8:$F$8,AF$13))*(About!$A$53) -> 2725.6794
A15: oil (2012 USD) | B15: =(TREND($B$10:$C$10,$B$8:$C$8,B$13))*(About!$A$53) -> 913.24311 | C15: =(TREND($C$10:$D$10,$C$8:$D$8,C$13))*(About!$A$53) -> 908.55981 | D15: =(TREND($C$10:$D$10,$C$8:$D$8,D$13))*(About!$A$53) -> 903.87651 | E15: =(TREND($C$10:$D$10,$C$8:$D$8,E$13))*(About!$A$53) -> 899.19321 | F15: =(TREND($C$10:$D$10,$C$8:$D$8,F$13))*(About!$A$53) -> 894.50991 | G15: =(TREND($C$10:$D$10,$C$8:$D$8,G$13))*(About!$A$53) -> 889.82662 | H15: =(TREND($C$10:$D$10,$C$8:$D$8,H$13))*(About!$A$53) -> 885.14332 | I15: =(TREND($C$10:$D$10,$C$8:$D$8,I$13))*(About!$A$53) -> 880.46002 | J15: =(TREND($C$10:$D$10,$C$8:$D$8,J$13))*(About!$A$53) -> 875.77672 | ... L15: =(TREND($C$10:$D$10,$C$8:$D$8,L$13))*(About!$A$53) -> 866.41013 | M15: =(TREND($D$10:$F$10,$D$8:$F$8,M$13))*(About!$A$53) -> 866.41013 | N15: =(TREND($D$10:$F$10,$D$8:$F$8,N$13))*(About!$A$53) -> 866.41013 | O15: =(TREND($D$10:$F$10,$D$8:$F$8,O$13))*(About!$A$53) -> 866.41013 | P15: =(TREND($D$10:$F$10,$D$8:$F$8,P$13))*(About!$A$53) -> 866.41013 | Q15: =(TREND($D$10:$F$10,$D$8:$F$8,Q$13))*(About!$A$53) -> 866.41013 | R15: =(TREND($D$10:$F$10,$D$8:$F$8,R$13))*(About!$A$53) -> 866.41013 | S15: =(TREND($D$10:$F$10,$D$8:$F$8,S$13))*(About!$A$53) -> 866.41013 | T15: =(TREND($D$10:$F$10,$D$8:$F$8,T$13))*(About!$A$53) -> 866.41013 | ... AF15: =(TREND($D$10:$F$10,$D$8:$F$8,AF$13))*(About!$A$53) -> 866.41013
A16: biomass (2012 USD) | B16: =(TREND($B$11:$C$11,$B$8:$C$8,B$13))*(About!$A$53) -> 374.66384 | C16: =(TREND($C$11:$D$11,$C$8:$D$8,C$13))*(About!$A$53) -> 369.98054 | D16: =(TREND($C$11:$D$11,$C$8:$D$8,D$13))*(About!$A$53) -> 365.29724 | E16: =(TREND($C$11:$D$11,$C$8:$D$8,E$13))*(About!$A$53) -> 360.61394 | F16: =(TREND($C$11:$D$11,$C$8:$D$8,F$13))*(About!$A$53) -> 355.93065 | G16: =(TREND($C$11:$D$11,$C$8:$D$8,G$13))*(About!$A$53) -> 351.24735 | H16: =(TREND($C$11:$D$11,$C$8:$D$8,H$13))*(About!$A$53) -> 346.56405 | I16: =(TREND($C$11:$D$11,$C$8:$D$8,I$13))*(About!$A$53) -> 341.88075 | J16: =(TREND($C$11:$D$11,$C$8:$D$8,J$13))*(About!$A$53) -> 337.19745 | ... L16: =(TREND($C$11:$D$11,$C$8:$D$8,L$13))*(About!$A$53) -> 327.83086 | M16: =(TREND($D$11:$F$11,$D$8:$F$8,M$13))*(About!$A$53) -> 318.46426 | N16: =(TREND($D$11:$F$11,$D$8:$F$8,N$13))*(About!$A$53) -> 309.09767 | O16: =(TREND($D$11:$F$11,$D$8:$F$8,O$13))*(About!$A$53) -> 299.73107 | P16: =(TREND($D$11:$F$11,$D$8:$F$8,P$13))*(About!$A$53) -> 290.36447 | Q16: =(TREND($D$11:$F$11,$D$8:$F$8,Q$13))*(About!$A$53) -> 280.99788 | R16: =(TREND($D$11:$F$11,$D$8:$F$8,R$13))*(About!$A$53) -> 271.63128 | S16: =(TREND($D$11:$F$11,$D$8:$F$8,S$13))*(About!$A$53) -> 262.26469 | T16: =(TREND($D$11:$F$11,$D$8:$F$8,T$13))*(About!$A$53) -> 252.89809 | ... AF16: =(TREND($D$11:$F$11,$D$8:$F$8,AF$13))*(About!$A$53) -> 140.49894
A18: Annualized Incremental Cost per BTU Shifted | B18: 2020 | C18: 2021 | D18: 2022 | E18: 2023 | F18: 2024 | G18: 2025 | H18: 2026 | I18: 2027 | J18: 2028 | K18: 2029 | L18: 2030 | M18: 2031 | N18: 2032 | O18: 2033 | P18: 2034 | Q18: 2035 | R18: 2036 | S18: 2037 | T18: 2038 | U18: 2039 | V18: 2040 | W18: 2041 | X18: 2042 | Y18: 2043 | Z18: 2044 | AA18: 2045 | AB18: 2046 | AC18: 2047 | AD18: 2048 | AE18: 2049 | AF18: 2050
A19: natural gas | C19: =C14/C4 -> #DIV/0! | D19: =D14/D4 -> #DIV/0! | E19: =E14/E4 -> #DIV/0! | F19: =F14/F4 -> 6.5014456e-05 | G19: =G14/G4 -> 5.8631075e-05 | H19: =H14/H4 -> 5.9244761e-05 | I19: =I14/I4 -> 6.0045832e-05 | J19: =J14/J4 -> 6.1016312e-05 | ... AF19: =AF14/AF4 -> 9.2887523e-05
A20: oil | C20: =C15/C5 -> #DIV/0! | D20: =D15/D5 -> #DIV/0! | E20: =E15/E5 -> #DIV/0! | F20: =F15/F5 -> 1.1230047e-05 | G20: =G15/G5 -> 1.0233027e-05 | H20: =H15/H5 -> 1.020635e-05 | I20: =I15/I5 -> 1.0235544e-05 | J20: =J15/J5 -> 1.0296908e-05 | ... AF20: =AF15/AF5 -> 1.219837e-05
A21: biomass | C21: =C16/C6 -> #DIV/0! | D21: =D16/D6 -> #DIV/0! | E21: =E16/E6 -> #DIV/0! | F21: =F16/F6 -> 2.2103757e-06 | G21: =G16/G6 -> 2.1287219e-06 | H21: =H16/H6 -> 2.166754e-06 | I21: =I16/I6 -> 2.1628074e-06 | J21: =J16/J6 -> 2.1354158e-06 | ... AF21: =AF16/AF6 -> 1.0614188e-06
A23: Appliances (water heaters)
