Workbook
Name CH4_Ar4_to_AR5: #REF!
Name gal_per_barrel: [1]About!$A$75
Name gal_per_barrel: #REF!
Name HHV_Adjust: [2]About!$A$211
Name IQ_CH: 110000
Name IQ_CQ: 5000
Name IQ_CY: 10000
Name IQ_DAILY: 500000
Name IQ_FH: 100000
Name IQ_FQ: 500
Name IQ_FY: 1000
Name IQ_LTM: 2000
Name IQ_MONTH: 15000
Name IQ_NTM: 6000
Name IQ_WEEK: 50000
Name IQ_YTD: 3000
Name metricton_to_shortton: #REF!
Name million: #REF!
Name N2O_AR4_to_AR5: #REF!
Name quadrillion: [2]About!$A$227
Name shorttons_to_grams: [2]About!$A$226
Name trillion: [2]About!$A$228
Name use_lifecycle_biofuel_EIs: [2]About!$A$97

Sheet About
A1: BPoEFUbVT BAU Perc of Each Fuel Used by Veh Technology
A3: Sources: | B3: most vehicles and fuels
B4: U.S. Energy Information Administration
B5: 2026
B6: Annual Energy Outlook 2026
B7: Alternative Electricity and Transportation
B8: https://www.eia.gov/outlooks/aeo/tables_side_xls.php
B9: Table 36, Table 17
B11: fraction of electricity used by plug-in hybrids
B12: DoE Alternative Fuels Data Center
B13: year unspecified
B14: Hybrid and Plug-In Electric Vehicle Emissions Data Sources and Assumptions
B15: https://www.afdc.energy.gov/vehicles/electric_emissions_sources.html
B16: Second-to-last parameter in the table
B18: Percent ethanol
B19: EIA
B20: 2020
B21: Monthly Energy Review, May 2020
B22: https://www.eia.gov/energyexplained//biofuels/charts/fuel-ethanol-motor-gasoline.csv
A25: About
A26: We include sheets for all possible vehicle type / cargo type / vehicle technology
A27: combinations that the model supports, even though some combinations are not used
A28: in the U.S. dataset. (For example, there are no freight motorbikes in the U.S. model.)
A29: This is to support adaptation to other countries that may wish to use that vehicle
A30: combination. (For example, some countries may wish to represent three-wheeled,
A31: motorized carts used for urban hauling and commerce as freight motorbikes.
A32: Another example: battery electric freight HDVs barely exist today, but the model
A33: includes a sheet for them, so it can support them in the future without changing
A34: the model structure.)
A36: For the U.S., we have the quantity of biodiesel used in the transportation sector, but
A37: not divided by vehicle type. The "Biodiesel Fraction" tab includes calculations to
... A52: for them here contain zeroes.

Sheet source data>

Sheet EIA-fuel-ethanol-motor-gasoline
A1: U.S. fuel ethanol consumption and percent of total U.S. motor gasoline consumption, 1981-2019
A2: fuel ethanol consumption - billion gallons
A3: fuel ethanol % of motor gasoline consumption
A4: Note: Motor gasoline is finished motor gasoline.
A5: Source: U.S. Energy Information Administration, <em>Monthly Energy Review</em> and <em>Petroleum Supply Monthly</em>, May 2020
B7: consumption | C7: % of gasoline consumption
A8: 1981 | B8: 0.083 | C8: 0.08
A9: 1982 | B9: 0.226 | C9: 0.22
A10: 1983 | B10: 0.415 | C10: 0.41
A11: 1984 | B11: 0.51 | C11: 0.5
A12: 1985 | B12: 0.617 | C12: 0.59
A13: 1986 | B13: 0.712 | C13: 0.66
A14: 1987 | B14: 0.819 | C14: 0.74
A15: 1988 | B15: 0.831 | C15: 0.74
A16: 1989 | B16: 0.843 | C16: 0.75
A17: 1990 | B17: 0.748 | C17: 0.67
A18: 1991 | B18: 0.866 | C18: 0.79
A19: 1992 | B19: 0.985 | C19: 0.88
... A47: 2020 | B47: 12.629 | C47: 10.23

Sheet AEO Table 73
B1: ref2019.d111618a | C1: 2017 | D1: 2018 | E1: 2019 | F1: 2020 | G1: 2021 | H1: 2022 | I1: 2023 | J1: 2024 | K1: 2025 | L1: 2026 | M1: 2027 | N1: 2028 | O1: 2029 | P1: 2030 | Q1: 2031 | R1: 2032 | S1: 2033 | T1: 2034 | U1: 2035 | V1: 2036 | W1: 2037 | X1: 2038 | Y1: 2039 | Z1: 2040 | AA1: 2041 | AB1: 2042 | AC1: 2043 | AD1: 2044 | AE1: 2045 | AF1: 2046 | AG1: 2047 | AH1: 2048 | AI1: 2049 | AJ1: 2050
C3: Report | D3: Annual Energy Outlook 2019
C4: Scenario | D4: ref2019 | G4: Reference case
C5: Datekey | D5: d111618a
C6: Release Date | E6: January 2019
C9: =C32/C35 -> 0.96828263 | F9: =(C33-((1-0.102)*C35))/0.102 -> 3.5983878
A10: CNV000 | B10: 73. Conversion Factors
B11: (from physical units to million Btu)
AK12: 2018-
C13: 2017 | D13: 2018 | E13: 2019 | F13: 2020 | G13: 2021 | H13: 2022 | I13: 2023 | J13: 2024 | K13: 2025 | L13: 2026 | M13: 2027 | N13: 2028 | O13: 2029 | P13: 2030 | Q13: 2031 | R13: 2032 | S13: 2033 | T13: 2034 | U13: 2035 | V13: 2036 | W13: 2037 | X13: 2038 | Y13: 2039 | Z13: 2040 | AA13: 2041 | AB13: 2042 | AC13: 2043 | AD13: 2044 | AE13: 2045 | AF13: 2046 | AG13: 2047 | AH13: 2048 | AI13: 2049 | AJ13: 2050 | AK13: 2050
B14: Petroleum and Other Liquids
B15: (million Btu per barrel)
A16: CNV000:aa_AsphaltandRoa | B16: Asphalt and Road Oil | C16: 6.636 | D16: 6.636 | E16: 6.636 | F16: 6.636 | G16: 6.636 | H16: 6.636 | I16: 6.636 | J16: 6.636 | K16: 6.636 | L16: 6.636 | M16: 6.636 | N16: 6.636 | O16: 6.636 | P16: 6.636 | Q16: 6.636 | R16: 6.636 | S16: 6.636 | T16: 6.636 | U16: 6.636 | V16: 6.636 | W16: 6.636 | X16: 6.636 | Y16: 6.636 | Z16: 6.636 | AA16: 6.636 | AB16: 6.636 | AC16: 6.636 | AD16: 6.636 | AE16: 6.636 | AF16: 6.636 | AG16: 6.636 | AH16: 6.636 | AI16: 6.636 | AJ16: 6.636 | AK16: 0
A17: CNV000:aa_AviationGasol | B17: Aviation Gasoline | C17: 5.048 | D17: 5.048 | E17: 5.048 | F17: 5.048 | G17: 5.048 | H17: 5.048 | I17: 5.048 | J17: 5.048 | K17: 5.048 | L17: 5.048 | M17: 5.048 | N17: 5.048 | O17: 5.048 | P17: 5.048 | Q17: 5.048 | R17: 5.048 | S17: 5.048 | T17: 5.048 | U17: 5.048 | V17: 5.048 | W17: 5.048 | X17: 5.048 | Y17: 5.048 | Z17: 5.048 | AA17: 5.048 | AB17: 5.048 | AC17: 5.048 | AD17: 5.048 | AE17: 5.048 | AF17: 5.048 | AG17: 5.048 | AH17: 5.048 | AI17: 5.048 | AJ17: 5.048 | AK17: 0
A18: CNV000:ea_Biodiesel | B18: Biodiesel | C18: 5.359 | D18: 5.359 | E18: 5.359 | F18: 5.359 | G18: 5.359 | H18: 5.359 | I18: 5.359 | J18: 5.359 | K18: 5.359 | L18: 5.359 | M18: 5.359 | N18: 5.359 | O18: 5.359 | P18: 5.359 | Q18: 5.359 | R18: 5.359 | S18: 5.359 | T18: 5.359 | U18: 5.359 | V18: 5.359 | W18: 5.359 | X18: 5.359 | Y18: 5.359 | Z18: 5.359 | AA18: 5.359 | AB18: 5.359 | AC18: 5.359 | AD18: 5.359 | AE18: 5.359 | AF18: 5.359 | AG18: 5.359 | AH18: 5.359 | AI18: 5.359 | AJ18: 5.359 | AK18: 0
A19: CNV000:aa_Distillate | B19: Distillate Fuel Oil | C19: 5.825 | D19: 5.825 | E19: 5.825 | F19: 5.825 | G19: 5.825 | H19: 5.825 | I19: 5.825 | J19: 5.825 | K19: 5.825 | L19: 5.825 | M19: 5.825 | N19: 5.825 | O19: 5.825 | P19: 5.825 | Q19: 5.825 | R19: 5.825 | S19: 5.825 | T19: 5.825 | U19: 5.825 | V19: 5.825 | W19: 5.825 | X19: 5.825 | Y19: 5.825 | Z19: 5.825 | AA19: 5.825 | AB19: 5.825 | AC19: 5.825 | AD19: 5.825 | AE19: 5.825 | AF19: 5.825 | AG19: 5.825 | AH19: 5.825 | AI19: 5.825 | AJ19: 5.825 | AK19: 0
A20: CNV000:aa_Residential | B20: Residential | C20: 5.774651 | D20: 5.773824 | E20: 5.773629 | F20: 5.772928 | G20: 5.773119 | H20: 5.773727 | I20: 5.772429 | J20: 5.773784 | K20: 5.772606 | L20: 5.773323 | M20: 5.774547 | N20: 5.774744 | O20: 5.773522 | P20: 5.773616 | Q20: 5.773581 | R20: 5.773493 | S20: 5.774485 | T20: 5.773373 | U20: 5.773317 | V20: 5.772994 | W20: 5.773236 | X20: 5.773163 | Y20: 5.773045 | Z20: 5.773002 | AA20: 5.772993 | AB20: 5.772738 | AC20: 5.772945 | AD20: 5.772616 | AE20: 5.772657 | AF20: 5.772504 | AG20: 5.772273 | AH20: 5.772147 | AI20: 5.771948 | AJ20: 5.771775 | AK20: -1.1e-05
A21: CNV000:aa_Commercial | B21: Commercial | C21: 5.774651 | D21: 5.773824 | E21: 5.773629 | F21: 5.772928 | G21: 5.773119 | H21: 5.773727 | I21: 5.772429 | J21: 5.773784 | K21: 5.772606 | L21: 5.773323 | M21: 5.774547 | N21: 5.774744 | O21: 5.773522 | P21: 5.773616 | Q21: 5.773581 | R21: 5.773493 | S21: 5.774485 | T21: 5.773373 | U21: 5.773317 | V21: 5.772994 | W21: 5.773236 | X21: 5.773163 | Y21: 5.773045 | Z21: 5.773002 | AA21: 5.772993 | AB21: 5.772738 | AC21: 5.772945 | AD21: 5.772616 | AE21: 5.772657 | AF21: 5.772504 | AG21: 5.772273 | AH21: 5.772147 | AI21: 5.771948 | AJ21: 5.771775 | AK21: -1.1e-05
A22: CNV000:aa_Transportatio | B22: Transportation | C22: 5.774651 | D22: 5.773824 | E22: 5.773629 | F22: 5.772928 | G22: 5.773119 | H22: 5.773727 | I22: 5.772429 | J22: 5.773784 | K22: 5.772606 | L22: 5.773323 | M22: 5.774547 | N22: 5.774744 | O22: 5.773522 | P22: 5.773616 | Q22: 5.773581 | R22: 5.773493 | S22: 5.774485 | T22: 5.773373 | U22: 5.773317 | V22: 5.772994 | W22: 5.773236 | X22: 5.773163 | Y22: 5.773045 | Z22: 5.773002 | AA22: 5.772993 | AB22: 5.772738 | AC22: 5.772945 | AD22: 5.772616 | AE22: 5.772657 | AF22: 5.772504 | AG22: 5.772273 | AH22: 5.772147 | AI22: 5.771948 | AJ22: 5.771775 | AK22: -1.1e-05
A23: CNV000:aa_Industrial | B23: Industrial | C23: 5.774651 | D23: 5.773824 | E23: 5.773629 | F23: 5.772928 | G23: 5.773119 | H23: 5.773727 | I23: 5.772429 | J23: 5.773784 | K23: 5.772606 | L23: 5.773323 | M23: 5.774547 | N23: 5.774744 | O23: 5.773522 | P23: 5.773616 | Q23: 5.773581 | R23: 5.773493 | S23: 5.774485 | T23: 5.773373 | U23: 5.773317 | V23: 5.772994 | W23: 5.773236 | X23: 5.773163 | Y23: 5.773045 | Z23: 5.773002 | AA23: 5.772993 | AB23: 5.772738 | AC23: 5.772945 | AD23: 5.772616 | AE23: 5.772657 | AF23: 5.772504 | AG23: 5.772273 | AH23: 5.772147 | AI23: 5.771948 | AJ23: 5.771775 | AK23: -1.1e-05
A24: CNV000:aa_ElectricPower | B24: Electric Power | C24: 5.774651 | D24: 5.773824 | E24: 5.773629 | F24: 5.772928 | G24: 5.773119 | H24: 5.773727 | I24: 5.772429 | J24: 5.773784 | K24: 5.772606 | L24: 5.773323 | M24: 5.774547 | N24: 5.774744 | O24: 5.773522 | P24: 5.773616 | Q24: 5.773581 | R24: 5.773493 | S24: 5.774485 | T24: 5.773373 | U24: 5.773317 | V24: 5.772994 | W24: 5.773236 | X24: 5.773163 | Y24: 5.773045 | Z24: 5.773002 | AA24: 5.772993 | AB24: 5.772738 | AC24: 5.772945 | AD24: 5.772616 | AE24: 5.772657 | AF24: 5.772504 | AG24: 5.772273 | AH24: 5.772147 | AI24: 5.771948 | AJ24: 5.771775 | AK24: -1.1e-05
A25: CNV000:aa_TotalDistilla | B25: Total Distillate | C25: 5.774651 | D25: 5.773824 | E25: 5.773628 | F25: 5.772927 | G25: 5.773119 | H25: 5.773727 | I25: 5.772429 | J25: 5.773784 | K25: 5.772606 | L25: 5.773322 | M25: 5.774548 | N25: 5.774744 | O25: 5.773522 | P25: 5.773616 | Q25: 5.77358 | R25: 5.773493 | S25: 5.774485 | T25: 5.773373 | U25: 5.773317 | V25: 5.772994 | W25: 5.773236 | X25: 5.773162 | Y25: 5.773044 | Z25: 5.773002 | AA25: 5.772993 | AB25: 5.772738 | AC25: 5.772945 | AD25: 5.772617 | AE25: 5.772656 | AF25: 5.772504 | AG25: 5.772274 | AH25: 5.772147 | AI25: 5.771948 | AJ25: 5.771775 | AK25: -1.1e-05
A26: CNV000:aa_DistLowSulf | B26: Distillate Fuel Oil - Low Sulfur Diesel | C26: 5.817 | D26: 5.817 | E26: 5.817 | F26: 5.817 | G26: 5.817 | H26: 5.817 | I26: 5.817 | J26: 5.817 | K26: 5.817 | L26: 5.817 | M26: 5.817 | N26: 5.817 | O26: 5.817 | P26: 5.817 | Q26: 5.817 | R26: 5.817 | S26: 5.817 | T26: 5.817 | U26: 5.817 | V26: 5.817 | W26: 5.817 | X26: 5.817 | Y26: 5.817 | Z26: 5.817 | AA26: 5.817 | AB26: 5.817 | AC26: 5.817 | AD26: 5.817 | AE26: 5.817 | AF26: 5.817 | AG26: 5.817 | AH26: 5.817 | AI26: 5.817 | AJ26: 5.817 | AK26: 0
A27: CNV000:aa_DistUltraLow | B27: Distillate Fuel Oil - Ultra Low Sulfur Diesel | C27: 5.77 | D27: 5.77 | E27: 5.77 | F27: 5.77 | G27: 5.77 | H27: 5.77 | I27: 5.77 | J27: 5.77 | K27: 5.77 | L27: 5.77 | M27: 5.77 | N27: 5.77 | O27: 5.77 | P27: 5.77 | Q27: 5.77 | R27: 5.77 | S27: 5.77 | T27: 5.77 | U27: 5.77 | V27: 5.77 | W27: 5.77 | X27: 5.77 | Y27: 5.77 | Z27: 5.77 | AA27: 5.77 | AB27: 5.77 | AC27: 5.77 | AD27: 5.77 | AE27: 5.77 | AF27: 5.77 | AG27: 5.77 | AH27: 5.77 | AI27: 5.77 | AJ27: 5.77 | AK27: 0
... A46: CNV000:aa_Exports | B46: Petroleum Product Exports | C46: 5.151 | D46: 5.274418 | E46: 5.250621 | F46: 5.275748 | G46: 5.243052 | H46: 5.234149 | I46: 5.231354 | J46: 5.245845 | K46: 5.231759 | L46: 5.195461 | M46: 5.187126 | N46: 5.189112 | O46: 5.179728 | P46: 5.182778 | Q46: 5.171607 | R46: 5.172073 | S46: 5.166301 | T46: 5.159403 | U46: 5.153961 | V46: 5.156905 | W46: 5.147167 | X46: 5.14539 | Y46: 5.135945 | Z46: 5.139299 | AA46: 5.137618 | AB46: 5.122315 | AC46: 5.131875 | AD46: 5.13061 | AE46: 5.139469 | AF46: 5.128032 | AG46: 5.124009 | AH46: 5.121249 | AI46: 5.111982 | AJ46: 5.1061 | AK46: -0.001013
B47: Crude Oil
A48: CNV000:aa_CrudeOilProdu | B48: Production | C48: 5.723 | D48: 5.719936 | E48: 5.709374 | F48: 5.702021 | G48: 5.699036 | H48: 5.702903 | I48: 5.701469 | J48: 5.697845 | K48: 5.696569 | L48: 5.695571 | M48: 5.691691 | N48: 5.689583 | O48: 5.687317 | P48: 5.686403 | Q48: 5.685931 | R48: 5.686055 | S48: 5.686259 | T48: 5.685382 | U48: 5.685214 | V48: 5.685896 | W48: 5.686885 | X48: 5.687922 | Y48: 5.69017 | Z48: 5.690964 | AA48: 5.689439 | AB48: 5.688754 | AC48: 5.686469 | AD48: 5.684444 | AE48: 5.683516 | AF48: 5.682888 | AG48: 5.681393 | AH48: 5.679274 | AI48: 5.678185 | AJ48: 5.676202 | AK48: -0.00024
A49: CNV000:aa_CrudeOilImpor | B49: Imports | C49: 6.05 | D49: 6.134721 | E49: 6.118438 | F49: 6.117281 | G49: 6.117947 | H49: 6.10254 | I49: 6.103374 | J49: 6.107163 | K49: 6.106585 | L49: 6.124556 | M49: 6.090179 | N49: 6.118682 | O49: 6.080531 | P49: 6.103808 | Q49: 6.113566 | R49: 6.107624 | S49: 6.084678 | T49: 6.134057 | U49: 6.131942 | V49: 6.08976 | W49: 6.138575 | X49: 6.138392 | Y49: 6.136396 | Z49: 6.138 | AA49: 6.141398 | AB49: 6.105396 | AC49: 6.119062 | AD49: 6.132329 | AE49: 6.140251 | AF49: 6.144131 | AG49: 6.141787 | AH49: 6.139135 | AI49: 6.137544 | AJ49: 6.134161 | AK49: -3e-06
A50: CNV000:aa_CrudeOilExpor | B50: Exports | C50: 5.738 | D50: 5.55477 | E50: 5.557237 | F50: 5.558167 | G50: 5.565951 | H50: 5.562354 | I50: 5.563715 | J50: 5.562271 | K50: 5.566788 | L50: 5.565995 | M50: 5.557513 | N50: 5.560513 | O50: 5.560773 | P50: 5.561747 | Q50: 5.562641 | R50: 5.562265 | S50: 5.569706 | T50: 5.594789 | U50: 5.596409 | V50: 5.603838 | W50: 5.603039 | X50: 5.612446 | Y50: 5.616357 | Z50: 5.622301 | AA50: 5.617278 | AB50: 5.611703 | AC50: 5.598722 | AD50: 5.586086 | AE50: 5.576109 | AF50: 5.561272 | AG50: 5.559134 | AH50: 5.558311 | AI50: 5.558477 | AJ50: 5.558816 | AK50: 2.3e-05
A51: CNV000:aa_NaturalGasPla | B51: Natural Gas Plant Liquids | C51: 3.699432 | D51: 3.680335 | E51: 3.675178 | F51: 3.67226 | G51: 3.661632 | H51: 3.661705 | I51: 3.660451 | J51: 3.65821 | K51: 3.656909 | L51: 3.655905 | M51: 3.655815 | N51: 3.654926 | O51: 3.65379 | P51: 3.654275 | Q51: 3.654194 | R51: 3.65518 | S51: 3.655222 | T51: 3.655784 | U51: 3.655432 | V51: 3.656329 | W51: 3.656425 | X51: 3.65846 | Y51: 3.659478 | Z51: 3.660426 | AA51: 3.659603 | AB51: 3.659032 | AC51: 3.657537 | AD51: 3.655983 | AE51: 3.654918 | AF51: 3.653574 | AG51: 3.651659 | AH51: 3.650127 | AI51: 3.64905 | AJ51: 3.6478 | AK51: -0.000277
B53: Natural Gas (thousand Btu per cubic foot)
A54: CNV000:ba_Consumption | B54: Consumption | C54: 1.037 | D54: 1.037 | E54: 1.037 | F54: 1.037 | G54: 1.037 | H54: 1.037 | I54: 1.037 | J54: 1.037 | K54: 1.037 | L54: 1.037 | M54: 1.037 | N54: 1.037 | O54: 1.037 | P54: 1.037 | Q54: 1.037 | R54: 1.037 | S54: 1.037 | T54: 1.037 | U54: 1.037 | V54: 1.037 | W54: 1.037 | X54: 1.037 | Y54: 1.037 | Z54: 1.037 | AA54: 1.037 | AB54: 1.037 | AC54: 1.037 | AD54: 1.037 | AE54: 1.037 | AF54: 1.037 | AG54: 1.037 | AH54: 1.037 | AI54: 1.037 | AJ54: 1.037 | AK54: 0
A55: CNV000:ba_Utility | B55: Electric Power Sector 2/ | C55: 1.033 | D55: 1.033 | E55: 1.033 | F55: 1.033 | G55: 1.033 | H55: 1.033 | I55: 1.033 | J55: 1.033 | K55: 1.033 | L55: 1.033 | M55: 1.033 | N55: 1.033 | O55: 1.033 | P55: 1.033 | Q55: 1.033 | R55: 1.033 | S55: 1.033 | T55: 1.033 | U55: 1.033 | V55: 1.033 | W55: 1.033 | X55: 1.033 | Y55: 1.033 | Z55: 1.033 | AA55: 1.033 | AB55: 1.033 | AC55: 1.033 | AD55: 1.033 | AE55: 1.033 | AF55: 1.033 | AG55: 1.033 | AH55: 1.033 | AI55: 1.033 | AJ55: 1.033 | AK55: 0
A56: CNV000:ba_Nonutility | B56: End-use Sector | C56: 1.039 | D56: 1.039 | E56: 1.039 | F56: 1.039 | G56: 1.039 | H56: 1.039 | I56: 1.039 | J56: 1.039 | K56: 1.039 | L56: 1.039 | M56: 1.039 | N56: 1.039 | O56: 1.039 | P56: 1.039 | Q56: 1.039 | R56: 1.039 | S56: 1.039 | T56: 1.039 | U56: 1.039 | V56: 1.039 | W56: 1.039 | X56: 1.039 | Y56: 1.039 | Z56: 1.039 | AA56: 1.039 | AB56: 1.039 | AC56: 1.039 | AD56: 1.039 | AE56: 1.039 | AF56: 1.039 | AG56: 1.039 | AH56: 1.039 | AI56: 1.039 | AJ56: 1.039 | AK56: 0
A57: CNV000:ba_Production | B57: Production | C57: 1.037 | D57: 1.037 | E57: 1.037 | F57: 1.037 | G57: 1.037 | H57: 1.037 | I57: 1.037 | J57: 1.037 | K57: 1.037 | L57: 1.037 | M57: 1.037 | N57: 1.037 | O57: 1.037 | P57: 1.037 | Q57: 1.037 | R57: 1.037 | S57: 1.037 | T57: 1.037 | U57: 1.037 | V57: 1.037 | W57: 1.037 | X57: 1.037 | Y57: 1.037 | Z57: 1.037 | AA57: 1.037 | AB57: 1.037 | AC57: 1.037 | AD57: 1.037 | AE57: 1.037 | AF57: 1.037 | AG57: 1.037 | AH57: 1.037 | AI57: 1.037 | AJ57: 1.037 | AK57: 0
A58: CNV000:ba_Imports | B58: Imports | C58: 1.025 | D58: 1.025 | E58: 1.025 | F58: 1.025 | G58: 1.025 | H58: 1.025 | I58: 1.025 | J58: 1.025 | K58: 1.025 | L58: 1.025 | M58: 1.025 | N58: 1.025 | O58: 1.025 | P58: 1.025 | Q58: 1.025 | R58: 1.025 | S58: 1.025 | T58: 1.025 | U58: 1.025 | V58: 1.025 | W58: 1.025 | X58: 1.025 | Y58: 1.025 | Z58: 1.025 | AA58: 1.025 | AB58: 1.025 | AC58: 1.025 | AD58: 1.025 | AE58: 1.025 | AF58: 1.025 | AG58: 1.025 | AH58: 1.025 | AI58: 1.025 | AJ58: 1.025 | AK58: 0
A59: CNV000:ba_Exports | B59: Exports | C59: 1.009 | D59: 1.009 | E59: 1.009 | F59: 1.009 | G59: 1.009 | H59: 1.009 | I59: 1.009 | J59: 1.009 | K59: 1.009 | L59: 1.009 | M59: 1.009 | N59: 1.009 | O59: 1.009 | P59: 1.009 | Q59: 1.009 | R59: 1.009 | S59: 1.009 | T59: 1.009 | U59: 1.009 | V59: 1.009 | W59: 1.009 | X59: 1.009 | Y59: 1.009 | Z59: 1.009 | AA59: 1.009 | AB59: 1.009 | AC59: 1.009 | AD59: 1.009 | AE59: 1.009 | AF59: 1.009 | AG59: 1.009 | AH59: 1.009 | AI59: 1.009 | AJ59: 1.009 | AK59: 0
A60: CNV000:ba_CompressedNat | B60: Compressed/Liquefied Natural Gas | C60: 0.96 | D60: 0.96 | E60: 0.96 | F60: 0.96 | G60: 0.96 | H60: 0.96 | I60: 0.96 | J60: 0.96 | K60: 0.96 | L60: 0.96 | M60: 0.96 | N60: 0.96 | O60: 0.96 | P60: 0.96 | Q60: 0.96 | R60: 0.96 | S60: 0.96 | T60: 0.96 | U60: 0.96 | V60: 0.96 | W60: 0.96 | X60: 0.96 | Y60: 0.96 | Z60: 0.96 | AA60: 0.96 | AB60: 0.96 | AC60: 0.96 | AD60: 0.96 | AE60: 0.96 | AF60: 0.96 | AG60: 0.96 | AH60: 0.96 | AI60: 0.96 | AJ60: 0.96 | AK60: 0
B62: Coal (million Btu per short ton)
A63: CNV000:ca_Production | B63: Production | C63: 20.53714 | D63: 20.439445 | E63: 20.349045 | F63: 20.46627 | G63: 20.363602 | H63: 20.554329 | I63: 20.653105 | J63: 20.626196 | K63: 20.621487 | L63: 20.64123 | M63: 20.627844 | N63: 20.53694 | O63: 20.501505 | P63: 20.413282 | Q63: 20.399071 | R63: 20.458256 | S63: 20.429285 | T63: 20.364529 | U63: 20.373262 | V63: 20.367174 | W63: 20.397617 | X63: 20.405455 | Y63: 20.39472 | Z63: 20.372593 | AA63: 20.382772 | AB63: 20.366734 | AC63: 20.354519 | AD63: 20.35523 | AE63: 20.38698 | AF63: 20.356945 | AG63: 20.336355 | AH63: 20.357395 | AI63: 20.34404 | AJ63: 20.347267 | AK63: -0.000141
...

Sheet ethanol content
A1: https://www.eia.gov/environment/emissions/co2_vol_mass.php
A3: Carbon Dioxide Emissions Coefficients by Fuel | I3: Percentage of BTUs per barrel from ethanol | J3: =1-J8 -> 0.072894654
B4: Pounds CO2 | C4: Kilograms CO2 | D4: Pounds CO2 | E4: Kilograms CO2
A5: Carbon Dioxide (CO2) Factors: | B5: Per Unit of Volume or Mass | C5: Per Unit of Volume or Mass | D5: Per Million Btu | E5: Per Million Btu | I5: BTU per barrel, finished gasoline | J5: ='AEO Table 73'!C32 -> 5.056643
A6: For homes and businesses | I6: BTU per barrel, motor gasoline before blending | J6: ='AEO Table 73'!C35 -> 5.22228
A7: Propane | B7: 12.68 gallon | C7: 5.75 gallon | D7: 138.63 | E7: 62.88 | I7: BTUs per barrel from motor gasoline | J7: =J6*(1-'EIA-fuel-ethanol-motor-gasoline'!C47/100) -> 4.6880408
A8: Diesel and Home Heating Fuel (Distillate Fuel Oil) | B8: 22.45 gallon | C8: 10.19 gallon | D8: 163.45 | E8: 74.14 | I8: Percentage of BTUs per barrel from motor gasoline | J8: =J7/J5 -> 0.92710535
A9: Kerosene | B9: 21.78 gallon | C9: 9.88 gallon | D9: 161.35 | E9: 73.19
A10: Coal (All types) | B10: 3,890.78 short ton | C10: 1,764.83 short ton | D10: 211.47 | E10: 95.92
A11: Natural Gas | B11: 120.96 thousand cubic feet | C11: 54.87 thousand cubic feet | D11: 116.65 | E11: 52.91
A12: Finished Motor Gasolinea | B12: 17.86 gallon | C12: 8.10 gallon | D12: 148.57 | E12: 67.39
A13: Motor Gasoline | B13: 19.37 gallon | C13: 8.78 gallon | D13: 155.77 | E13: 70.66
A14: Residual Heating Fuel (Businesses only) | B14: 24.78 gallon | C14: 11.24 gallon | D14: 165.55 | E14: 75.09
A15: Other transportation fuels
A16: Jet Fuel | B16: 21.50 gallon | C16: 9.75 gallon | D16: 159.25 | E16: 72.23
A17: Aviation Gas | B17: 18.32 gallon | C17: 8.31 gallon | D17: 152.46 | E17: 69.15
A18: Industrial fuels and others not listed above
A19: Petroleum coke | B19: 32.88 gallon | C19: 14.920 gallon | D19: 225.13 | E19: 102.12
A20: Nonfuel uses
A21: Asphalt and Road Oil | B21: 26.25 gallon | C21: 11.91 gallon | D21: 166.12 | E21: 75.35
A22: Lubricants | B22: 23.58 gallon | C22: 10.70 gallon | D22: 163.29 | E22: 74.07
A23: Naphthas for Petrochemical Feedstock Use | B23: 18.74 gallon | C23: 8.50 gallon | D23: 149.95 | E23: 68.02
A24: Other Oils for Petrochemical Feedstock Use | B24: 22.61 gallon | C24: 10.26 gallon | D24: 163.05 | E24: 73.96
A25: Special Naphthas (solvents) | B25: 19.94 gallon | C25: 9.04 gallon | D25: 159.57 | E25: 72.38
A26: Waxes | B26: 21.10 gallon | C26: 9.57 gallon | D26: 160.06 | E26: 72.6
A27: Coals by type
A28: Anthracite | B28: 5,735.68 short ton | C28: 2,601.67 short ton | D28: 228.6 | E28: 103.69
A29: Bituminous | B29: 4,783.52 short ton | C29: 2,169.77 short ton | D29: 205.57 | E29: 93.24
A30: Subbituminous | B30: 3,745.22 short ton | C30: 1,698.80 short ton | D30: 214.13 | E30: 97.13
A31: Lignite | B31: 2,809.83 short ton | C31: 1,274.52 short ton | D31: 216.64 | E31: 98.27
A32: Coke | B32: 7,183.46 short ton | C32: 3,258.37 short ton | D32: 250.59 | E32: 113.67
A33: Other fuels
A34: Geothermal (steam) | B34: NA | C34: NA | D34: 26.03 | E34: 11.81
A35: Geothermal (binary cycle) | B35: NA | C35: NA | D35: 0 | E35: 0
A36: Municipal solid wasteb,c | B36: 1,562.78 short ton | C36: 708.87 short ton | D36: 109.98 | E36: 49.89
A37: Tire-derived fuelb | B37: 5,306.87 short ton | C37: 2,407.16 short ton | D37: 189.53 | E37: 85.97
A38: Waste oilb | B38: 22.51 gallon | C38: 10.21 gallon | D38: 163.14 | E38: 74

Sheet AEO 2023 Table 17
B1: ref2023.d020623a | C1: 2022 | D1: 2023 | E1: 2024 | F1: 2025 | G1: 2026 | H1: 2027 | I1: 2028 | J1: 2029 | K1: 2030 | L1: 2031 | M1: 2032 | N1: 2033 | O1: 2034 | P1: 2035 | Q1: 2036 | R1: 2037 | S1: 2038 | T1: 2039 | U1: 2040 | V1: 2041 | W1: 2042 | X1: 2043 | Y1: 2044 | Z1: 2045 | AA1: 2046 | AB1: 2047 | AC1: 2048 | AD1: 2049 | AE1: 2050
C3: Report | D3: Annual Energy Outlook 2023
C4: Scenario | D4: ref2023 | G4: Reference
C5: Datekey | D5: d020623a
C6: Release Date | E6: March 2023
A10: REM000 | B10: 17. Renewable Energy Consumption by Sector and Source | AF10: Average
B11: (quadrillion Btu, unless otherwise noted) | AF11: Annual
AF12: Change
B13: Sector and Source | C13: 2022 | D13: 2023 | E13: 2024 | F13: 2025 | G13: 2026 | H13: 2027 | I13: 2028 | J13: 2029 | K13: 2030 | L13: 2031 | M13: 2032 | N13: 2033 | O13: 2034 | P13: 2035 | Q13: 2036 | R13: 2037 | S13: 2038 | T13: 2039 | U13: 2040 | V13: 2041 | W13: 2042 | X13: 2043 | Y13: 2044 | Z13: 2045 | AA13: 2046 | AB13: 2047 | AC13: 2048 | AD13: 2049 | AE13: 2050 | AF13: 2022–2050
B15: Marketed Renewable Energy 1/
A17: REM000:ca_Residential(w | B17: Residential (wood) | C17: 0.538932 | D17: 0.57441 | E17: 0.513068 | F17: 0.489864 | G17: 0.472164 | H17: 0.45764 | I17: 0.4452 | J17: 0.435137 | K17: 0.426017 | L17: 0.41791 | M17: 0.409804 | N17: 0.402631 | O17: 0.395039 | P17: 0.387514 | Q17: 0.379935 | R17: 0.372857 | S17: 0.366083 | T17: 0.359575 | U17: 0.353241 | V17: 0.347622 | W17: 0.342071 | X17: 0.337054 | Y17: 0.332011 | Z17: 0.327538 | AA17: 0.323872 | AB17: 0.320083 | AC17: 0.316089 | AD17: 0.312111 | AE17: 0.308024 | AF17: -0.019781
A19: REM000:da_Commercial(bi | B19: Commercial (biomass) | C19: 0.120805 | D19: 0.120805 | E19: 0.120805 | F19: 0.120805 | G19: 0.120805 | H19: 0.120805 | I19: 0.120805 | J19: 0.120805 | K19: 0.120805 | L19: 0.120805 | M19: 0.120805 | N19: 0.120805 | O19: 0.120805 | P19: 0.120805 | Q19: 0.120805 | R19: 0.120805 | S19: 0.120805 | T19: 0.120805 | U19: 0.120805 | V19: 0.120805 | W19: 0.120805 | X19: 0.120805 | Y19: 0.120805 | Z19: 0.120805 | AA19: 0.120805 | AB19: 0.120805 | AC19: 0.120805 | AD19: 0.120805 | AE19: 0.120805 | AF19: 0
A21: REM000:ea_Industrial | B21: Industrial 2/ | C21: 2.418849 | D21: 2.558293 | E21: 2.454399 | F21: 2.458783 | G21: 2.461936 | H21: 2.469083 | I21: 2.484627 | J21: 2.491801 | K21: 2.494826 | L21: 2.500568 | M21: 2.509977 | N21: 2.521396 | O21: 2.534965 | P21: 2.553261 | Q21: 2.557693 | R21: 2.567496 | S21: 2.576616 | T21: 2.588815 | U21: 2.604867 | V21: 2.630121 | W21: 2.648243 | X21: 2.664851 | Y21: 2.671741 | Z21: 2.681419 | AA21: 2.697925 | AB21: 2.720405 | AC21: 2.747052 | AD21: 2.763744 | AE21: 2.78549 | AF21: 0.005053
A22: REM000:ea_ConventionalH | B22: Conventional Hydroelectric Power | C22: 0.010773 | D22: 0.010913 | E22: 0.010875 | F22: 0.010837 | G22: 0.010801 | H22: 0.010767 | I22: 0.010736 | J22: 0.010707 | K22: 0.010682 | L22: 0.010661 | M22: 0.010644 | N22: 0.010632 | O22: 0.010624 | P22: 0.010622 | Q22: 0.010622 | R22: 0.010622 | S22: 0.010622 | T22: 0.010622 | U22: 0.010622 | V22: 0.010622 | W22: 0.010622 | X22: 0.010622 | Y22: 0.010622 | Z22: 0.010622 | AA22: 0.010622 | AB22: 0.010622 | AC22: 0.010622 | AD22: 0.010622 | AE22: 0.010622 | AF22: -0.000504
A23: REM000:ea_MunicipalSoli | B23: Municipal Waste 3/ | C23: 0.161768 | D23: 0.159976 | E23: 0.160365 | F23: 0.16234 | G23: 0.164713 | H23: 0.166676 | I23: 0.167756 | J23: 0.167014 | K23: 0.166274 | L23: 0.165657 | M23: 0.164915 | N23: 0.164057 | O23: 0.163178 | P23: 0.162395 | Q23: 0.161408 | R23: 0.16053 | S23: 0.159728 | T23: 0.159956 | U23: 0.160357 | V23: 0.160718 | W23: 0.160969 | X23: 0.161029 | Y23: 0.160963 | Z23: 0.161255 | AA23: 0.161468 | AB23: 0.161673 | AC23: 0.161871 | AD23: 0.162026 | AE23: 0.162219 | AF23: 9.9e-05
A24: REM000:ea_Biomass | B24: Biomass | C24: 1.328232 | D24: 1.402826 | E24: 1.37287 | F24: 1.379027 | G24: 1.38159 | H24: 1.387895 | I24: 1.399337 | J24: 1.41076 | K24: 1.418932 | L24: 1.429157 | M24: 1.443031 | N24: 1.456508 | O24: 1.470957 | P24: 1.482958 | Q24: 1.48898 | R24: 1.498773 | S24: 1.506998 | T24: 1.516537 | U24: 1.528081 | V24: 1.540243 | W24: 1.552132 | X24: 1.562002 | Y24: 1.568192 | Z24: 1.57093 | AA24: 1.577018 | AB24: 1.587632 | AC24: 1.593003 | AD24: 1.600503 | AE24: 1.615781 | AF24: 0.007023
A25: REM000:ea_BiomasHeat&Co | B25: Biofuels Heat and Coproducts | C25: 0.918076 | D25: 0.984578 | E25: 0.910289 | F25: 0.906579 | G25: 0.904831 | H25: 0.903745 | I25: 0.906798 | J25: 0.90332 | K25: 0.898938 | L25: 0.895093 | M25: 0.891387 | N25: 0.8902 | O25: 0.890206 | P25: 0.897286 | Q25: 0.896683 | R25: 0.897571 | S25: 0.899268 | T25: 0.901701 | U25: 0.905807 | V25: 0.918538 | W25: 0.924521 | X25: 0.931198 | Y25: 0.931964 | Z25: 0.938613 | AA25: 0.948817 | AB25: 0.960478 | AC25: 0.981557 | AD25: 0.990594 | AE25: 0.996868 | AF25: 0.002945
A27: REM000:fa_Transportatio | B27: Transportation | C27: 1.643957 | D27: 1.68746 | E27: 1.750144 | F27: 1.713519 | G27: 1.703839 | H27: 1.701528 | I27: 1.5877 | J27: 1.586966 | K27: 1.586138 | L27: 1.585172 | M27: 1.583934 | N27: 1.582892 | O27: 1.581595 | P27: 1.580019 | Q27: 1.578644 | R27: 1.57726 | S27: 1.575864 | T27: 1.574471 | U27: 1.57305 | V27: 1.571346 | W27: 1.569874 | X27: 1.568397 | Y27: 1.567132 | Z27: 1.565676 | AA27: 1.579699 | AB27: 1.603261 | AC27: 1.648387 | AD27: 1.678537 | AE27: 1.699064 | AF27: 0.001178
A28: REM000:fa_Ethanolusedin | B28: Ethanol used in E85 4/ | C28: 0.022316 | D28: 0.022565 | E28: 0.021182 | F28: 0.021098 | G28: 0.020573 | H28: 0.020002 | I28: 0.019309 | J28: 0.018533 | K28: 0.017717 | L28: 0.016916 | M28: 0.016133 | N28: 0.015434 | O28: 0.014803 | P28: 0.014241 | Q28: 0.013707 | R28: 0.013317 | S28: 0.013026 | T28: 0.012829 | U28: 0.012724 | V28: 0.012669 | W28: 0.012661 | X28: 0.012716 | Y28: 0.01278 | Z28: 0.012875 | AA28: 0.01296 | AB28: 0.013117 | AC28: 0.013259 | AD28: 0.013443 | AE28: 0.013617 | AF28: -0.017487
A29: REM000:ga_Ethanolusedin | B29: Ethanol used in Gasoline Blending | C29: 1.12509 | D29: 1.122732 | E29: 1.151931 | F29: 1.142379 | G29: 1.135865 | H29: 1.130649 | I29: 1.123475 | J29: 1.114464 | K29: 1.103905 | L29: 1.094237 | M29: 1.084963 | N29: 1.07876 | O29: 1.074166 | P29: 1.069304 | Q29: 1.063241 | R29: 1.058996 | S29: 1.055871 | T29: 1.053339 | U29: 1.052924 | V29: 1.052812 | W29: 1.054361 | X29: 1.056869 | Y29: 1.061329 | Z29: 1.067279 | AA29: 1.075243 | AB29: 1.084963 | AC29: 1.095266 | AD29: 1.106839 | AE29: 1.120543 | AF29: -0.000145
A30: REM000:ga_BioDieselBlen | B30: Biodiesel used in Distillate Blending | C30: 0.201563 | D30: 0.18984 | E30: 0.219119 | F30: 0.20335 | G30: 0.200004 | H30: 0.203061 | I30: 0.154942 | J30: 0.16418 | K30: 0.172856 | L30: 0.177873 | M30: 0.176632 | N30: 0.179796 | O30: 0.177057 | P30: 0.173708 | Q30: 0.17023 | R30: 0.166623 | S30: 0.162883 | T30: 0.159519 | U30: 0.155506 | V30: 0.151353 | W30: 0.147056 | X30: 0.142614 | Y30: 0.138021 | Z30: 0.133277 | AA30: 0.128377 | AB30: 0.123319 | AC30: 0.118099 | AD30: 0.112828 | AE30: 0.107556 | AF30: -0.022182
A31: REM000:trans_biobute | B31: Biobutanol | C31: 0 | D31: 0 | E31: 0 | F31: 0 | G31: 0 | H31: 0 | I31: 0 | J31: 0 | K31: 0 | L31: 0 | M31: 0 | N31: 0 | O31: 0 | P31: 0 | Q31: 0 | R31: 0 | S31: 0 | T31: 0 | U31: 0 | V31: 0 | W31: 0 | X31: 0 | Y31: 0 | Z31: 0 | AA31: 0 | AB31: 0 | AC31: 0 | AD31: 0 | AE31: 0 | AF31: --
A32: REM000:gb_LiquidfromBio | B32: Liquids from Biomass | C32: 0.001026 | D32: 0.001154 | E32: 0.001159 | F32: 0.001159 | G32: 0.001223 | H32: 0.001159 | I32: 0.001223 | J32: 0.00225 | K32: 0.00167 | L32: 0.001853 | M32: 0.001884 | N32: 0.00225 | O32: 0.00225 | P32: 0.00225 | Q32: 0.00225 | R32: 0.00225 | S32: 0.00225 | T32: 0.00225 | U32: 0.00225 | V32: 0.002682 | W32: 0.00225 | X32: 0.00225 | Y32: 0.001992 | Z32: 0.001223 | AA32: 0.002185 | AB32: 0.002185 | AC32: 0.002185 | AD32: 0.002225 | AE32: 0.001882 | AF32: 0.021892
A33: REM000:gb_GreenLiquids | B33: Renewable Diesel and Gasoline 5/ | C33: 0.293962 | D33: 0.35117 | E33: 0.356753 | F33: 0.345533 | G33: 0.346173 | H33: 0.346656 | I33: 0.288751 | J33: 0.287539 | K33: 0.28999 | L33: 0.294293 | M33: 0.304321 | N33: 0.306653 | O33: 0.313318 | P33: 0.320518 | Q33: 0.329216 | R33: 0.336075 | S33: 0.341834 | T33: 0.346535 | U33: 0.349645 | V33: 0.351831 | W33: 0.353546 | X33: 0.353948 | Y33: 0.353009 | Z33: 0.351022 | AA33: 0.360933 | AB33: 0.379677 | AC33: 0.419578 | AD33: 0.443202 | AE33: 0.455466 | AF33: 0.015761
A35: REM000:ha_ElectricPower | B35: Electric Power 6/ | C35: 8.08409 | D35: 8.605595 | E35: 9.2536 | F35: 10.769812 | G35: 12.489632 | H35: 14.207677 | I35: 15.657 | J35: 16.679596 | K35: 17.569942 | L35: 18.211523 | M35: 18.849072 | N35: 19.601135 | O35: 20.207752 | P35: 20.684017 | Q35: 21.174015 | R35: 21.527521 | S35: 21.819601 | T35: 21.990221 | U35: 22.281153 | V35: 22.423574 | W35: 22.664766 | X35: 22.940054 | Y35: 23.344435 | Z35: 23.717884 | AA35: 24.147013 | AB35: 24.507113 | AC35: 24.87258 | AD35: 25.165535 | AE35: 25.597914 | AF35: 0.042024
A36: REM000:ha_ConventionalH | B36: Conventional Hydroelectric Power | C36: 2.442681 | D36: 2.44755 | E36: 2.491689 | F36: 2.577846 | G36: 2.568922 | H36: 2.546059 | I36: 2.504646 | J36: 2.475489 | K36: 2.446743 | L36: 2.425799 | M36: 2.409033 | N36: 2.411749 | O36: 2.415782 | P36: 2.419376 | Q36: 2.424693 | R36: 2.41289 | S36: 2.399529 | T36: 2.375586 | U36: 2.3708 | V36: 2.35552 | W36: 2.358788 | X36: 2.352015 | Y36: 2.346977 | Z36: 2.343842 | AA36: 2.33262 | AB36: 2.325793 | AC36: 2.323454 | AD36: 2.310321 | AE36: 2.298403 | AF36: -0.002172
A37: REM000:ha_Geothermal | B37: Geothermal | C37: 0.138575 | D37: 0.134139 | E37: 0.138856 | F37: 0.146111 | G37: 0.152066 | H37: 0.156023 | I37: 0.159828 | J37: 0.167233 | K37: 0.174095 | L37: 0.178493 | M37: 0.184554 | N37: 0.187499 | O37: 0.195066 | P37: 0.201046 | Q37: 0.210441 | R37: 0.217342 | S37: 0.223436 | T37: 0.2259 | U37: 0.229147 | V37: 0.234246 | W37: 0.240622 | X37: 0.244772 | Y37: 0.249637 | Z37: 0.25794 | AA37: 0.269467 | AB37: 0.28115 | AC37: 0.288588 | AD37: 0.296086 | AE37: 0.302234 | AF37: 0.028241
A38: REM000:ha_MunicipalSoli | B38: Biogenic Municipal Waste 7/ | C38: 0.22191 | D38: 0.228224 | E38: 0.233892 | F38: 0.239109 | G38: 0.244032 | H38: 0.251669 | I38: 0.255155 | J38: 0.262267 | K38: 0.270317 | L38: 0.278272 | M38: 0.285579 | N38: 0.29683 | O38: 0.303756 | P38: 0.312192 | Q38: 0.321445 | R38: 0.330951 | S38: 0.342231 | T38: 0.35276 | U38: 0.36073 | V38: 0.369139 | W38: 0.377914 | X38: 0.386538 | Y38: 0.395555 | Z38: 0.404655 | AA38: 0.410119 | AB38: 0.416926 | AC38: 0.422851 | AD38: 0.42875 | AE38: 0.43555 | AF38: 0.024376
A39: REM000:ha_Biomass | B39: Biomass | C39: 0.180331 | D39: 0.192473 | E39: 0.180116 | F39: 0.181063 | G39: 0.177749 | H39: 0.175131 | I39: 0.165623 | J39: 0.161346 | K39: 0.161241 | L39: 0.162494 | M39: 0.162658 | N39: 0.163868 | O39: 0.163854 | P39: 0.164149 | Q39: 0.163862 | R39: 0.164537 | S39: 0.165233 | T39: 0.165279 | U39: 0.16548 | V39: 0.165659 | W39: 0.164763 | X39: 0.164765 | Y39: 0.164578 | Z39: 0.1647 | AA39: 0.170629 | AB39: 0.170972 | AC39: 0.171464 | AD39: 0.176981 | AE39: 0.177752 | AF39: -0.000514
A40: REM000:ha_DedicatedPlan | B40: Dedicated Plants | C40: 0.146924 | D40: 0.157217 | E40: 0.148088 | F40: 0.149106 | G40: 0.145807 | H40: 0.143338 | I40: 0.13548 | J40: 0.131939 | K40: 0.131949 | L40: 0.133298 | M40: 0.133607 | N40: 0.134069 | O40: 0.134178 | P40: 0.134068 | Q40: 0.133866 | R40: 0.134474 | S40: 0.135283 | T40: 0.135296 | U40: 0.13552 | V40: 0.135503 | W40: 0.134629 | X40: 0.1346 | Y40: 0.134432 | Z40: 0.134527 | AA40: 0.140319 | AB40: 0.140614 | AC40: 0.14099 | AD40: 0.146394 | AE40: 0.147057 | AF40: 3.2e-05
A41: REM000:ha_Cofiring | B41: Cofiring | C41: 0.033407 | D41: 0.035255 | E41: 0.032028 | F41: 0.031957 | G41: 0.031942 | H41: 0.031793 | I41: 0.030144 | J41: 0.029407 | K41: 0.029292 | L41: 0.029196 | M41: 0.029051 | N41: 0.029799 | O41: 0.029675 | P41: 0.030081 | Q41: 0.029995 | R41: 0.030063 | S41: 0.029951 | T41: 0.029983 | U41: 0.02996 | V41: 0.030157 | W41: 0.030133 | X41: 0.030165 | Y41: 0.030146 | Z41: 0.030173 | AA41: 0.03031 | AB41: 0.030358 | AC41: 0.030474 | AD41: 0.030587 | AE41: 0.030695 | AF41: -0.003019
A42: REM000:ha_SolarThermal | B42: Solar Thermal | C42: 0.026097 | D42: 0.026142 | E42: 0.02559 | F42: 0.025612 | G42: 0.025363 | H42: 0.025058 | I42: 0.024745 | J42: 0.024274 | K42: 0.024036 | L42: 0.02384 | M42: 0.022007 | N42: 0.021626 | O42: 0.020728 | P42: 0.020644 | Q42: 0.019789 | R42: 0.019886 | S42: 0.020183 | T42: 0.020373 | U42: 0.019944 | V42: 0.019694 | W42: 0.019015 | X42: 0.018082 | Y42: 0.017749 | Z42: 0.01733 | AA42: 0.017052 | AB42: 0.016774 | AC42: 0.016619 | AD42: 0.016455 | AE42: 0.016648 | AF42: -0.015926
A43: REM000:ha_SolarPhotovol | B43: Solar Photovoltaic 8/ | C43: 1.177112 | D43: 1.520191 | E43: 2.136887 | F43: 3.17957 | G43: 4.325841 | H43: 5.352685 | I43: 5.958737 | J43: 6.275979 | K43: 6.478005 | L43: 6.825141 | M43: 7.316296 | N43: 7.667536 | O43: 7.998652 | P43: 8.191917 | Q43: 8.540236 | R43: 8.880701 | S43: 9.202519 | T43: 9.377172 | U43: 9.679772 | V43: 9.812637 | W43: 10.01744 | X43: 10.248034 | Y43: 10.580895 | Z43: 10.882163 | AA43: 11.308514 | AB43: 11.581096 | AC43: 11.847967 | AD43: 12.144065 | AE43: 12.509926 | AF43: 0.088074
A44: REM000:ha_Wind | B44: Wind | C44: 3.897385 | D44: 4.056876 | E44: 4.046569 | F44: 4.420499 | G44: 4.995658 | H44: 5.701052 | I44: 6.588266 | J44: 7.313008 | K44: 8.015505 | L44: 8.317482 | M44: 8.468944 | N44: 8.852024 | O44: 9.109915 | P44: 9.374693 | Q44: 9.493549 | R44: 9.501213 | S44: 9.46647 | T44: 9.473149 | U44: 9.45528 | V44: 9.466681 | W44: 9.486225 | X44: 9.525846 | Y44: 9.589043 | Z44: 9.647252 | AA44: 9.63861 | AB44: 9.714403 | AC44: 9.801635 | AD44: 9.792878 | AE44: 9.857403 | AF44: 0.033695
A46: REM000:ia_TotalMarketed | B46: Total Marketed Renewable Energy | C46: 12.806632 | D46: 13.546563 | E46: 14.092015 | F46: 15.552782 | G46: 17.248375 | H46: 18.956732 | I46: 20.29533 | J46: 21.314304 | K46: 22.197727 | L46: 22.835978 | M46: 23.473591 | N46: 24.228859 | O46: 24.840157 | P46: 25.325615 | Q46: 25.811092 | R46: 26.165939 | S46: 26.458969 | T46: 26.633888 | U46: 26.933115 | V46: 27.093468 | W46: 27.34576 | X46: 27.631161 | Y46: 28.036123 | Z46: 28.413322 | AA46: 28.869314 | AB46: 29.271667 | AC46: 29.704914 | AD46: 30.040731 | AE46: 30.511297 | AF46: 0.03149
B48: Sources of Ethanol
A49: REM000:ja_FromCorn | B49: From Corn and Other Starch | C49: 1.263154 | D49: 1.23928 | E49: 1.324231 | F49: 1.318407 | G49: 1.315272 | H49: 1.313495 | I49: 1.317761 | J49: 1.313384 | K49: 1.305957 | L49: 1.300309 | M49: 1.295035 | N49: 1.293353 | O49: 1.293118 | P49: 1.302341 | Q49: 1.301225 | R49: 1.302217 | S49: 1.304563 | T49: 1.307725 | U49: 1.313264 | V49: 1.330781 | W49: 1.33853 | X49: 1.347896 | Y49: 1.349838 | Z49: 1.359517 | AA49: 1.375432 | AB49: 1.392505 | AC49: 1.423452 | AD49: 1.43737 | AE49: 1.447323 | AF49: 0.004873
A50: REM000:ja_FromCellulose | B50: From Cellulose | C50: 0.001455 | D50: 0.001397 | E50: 0.001468 | F50: 0.001468 | G50: 0.001468 | H50: 0.001468 | I50: 0.001468 | J50: 0.000463 | K50: 0.001031 | L50: 0.000851 | M50: 0.00082 | N50: 0.000463 | O50: 0.000463 | P50: 0.000463 | Q50: 0.000463 | R50: 0.000463 | S50: 0.000463 | T50: 0.000463 | U50: 0.000463 | V50: 3.9e-05 | W50: 0.000463 | X50: 0.000463 | Y50: 0.000715 | Z50: 0.001468 | AA50: 0.000463 | AB50: 0.000463 | AC50: 0.000463 | AD50: 0.000424 | AE50: 0.000823 | AF50: -0.020154
A51: REM000:ja_Imports | B51: Net Imports | C51: -0.117203 | D51: -0.09538 | E51: -0.152586 | F51: -0.156399 | G51: -0.160302 | H51: -0.164311 | I51: -0.176445 | J51: -0.18085 | K51: -0.185365 | L51: -0.190007 | M51: -0.194759 | N51: -0.199622 | O51: -0.204611 | P51: -0.219259 | Q51: -0.224739 | R51: -0.230367 | S51: -0.236128 | T51: -0.24202 | U51: -0.248078 | V51: -0.26534 | W51: -0.271971 | X51: -0.278774 | Y51: -0.276443 | Z51: -0.280831 | AA51: -0.287691 | AB51: -0.294887 | AC51: -0.31539 | AD51: -0.317511 | AE51: -0.313985 | AF51: 0.035821
A52: REM000:ja_Total | B52: Total U.S. Supply of Ethanol | C52: 1.147406 | D52: 1.145297 | E52: 1.173112 | F52: 1.163476 | G52: 1.156438 | H52: 1.150652 | I52: 1.142784 | J52: 1.132997 | K52: 1.121622 | L52: 1.111153 | M52: 1.101096 | N52: 1.094194 | O52: 1.088969 | P52: 1.083545 | Q52: 1.076948 | R52: 1.072313 | S52: 1.068897 | T52: 1.066168 | U52: 1.065649 | V52: 1.065481 | W52: 1.067022 | X52: 1.069585 | Y52: 1.074109 | Z52: 1.080154 | AA52: 1.088203 | AB52: 1.09808 | AC52: 1.108525 | AD52: 1.120282 | AE52: 1.134161 | AF52: -0.000415
...

Sheet AEO 2023 Table 36 Raw
A1: Table 36. Transportation Sector Energy Use by Fuel Type Within a Mode
A2: https://www.eia.gov/outlooks/aeo/data/browser/#/?id=46-AEO2023&sourcekey=0
A3: Mon Apr 17 2023 13:56:35 GMT-0400 (Eastern Daylight Time)
A4: Source: U.S. Energy Information Administration
B5: full name | C5: api key | D5: units | E5: 2021 | F5: 2022 | G5: 2023 | H5: 2024 | I5: 2025 | J5: 2026 | K5: 2027 | L5: 2028 | M5: 2029 | N5: 2030 | O5: 2031 | P5: 2032 | Q5: 2033 | R5: 2034 | S5: 2035 | T5: 2036 | U5: 2037 | V5: 2038 | W5: 2039 | X5: 2040 | Y5: 2041 | Z5: 2042 | AA5: 2043 | AB5: 2044 | AC5: 2045 | AD5: 2046 | AE5: 2047 | AF5: 2048 | AG5: 2049 | AH5: 2050 | AI5: Growth (2022-2050)
A6: Light-Duty Vehicle | B6: Transportation Energy Use: Light-Duty Vehicle: Total: Reference case | C6: AEO.2023.REF2023.CNSM_NA_TRN_LDTY_NA_NA_NA_TRLBTU.A | D6: trillion Btu | F6: 14541.973 | G6: 14586.113 | H6: 14429.691 | I6: 14201.925 | J6: 14016.908 | K6: 13860.762 | L6: 13679.086 | M6: 13473.831 | N6: 13253.083 | O6: 13044.085 | P6: 12836.978 | Q6: 12674.038 | R6: 12534.655 | S6: 12394.663 | T6: 12251.547 | U6: 12130.821 | V6: 12028.415 | W6: 11933.922 | X6: 11864.001 | Y6: 11805.396 | Z6: 11762.741 | AA6: 11733.644 | AB6: 11725.386 | AC6: 11735.774 | AD6: 11770.763 | AE6: 11824.349 | AF6: 11889.715 | AG6: 11962.909 | AH6: 12054.454 | AI6: -0.007
A7: Motor Gasoline excluding E85 | B7: Transportation Energy Use: Light-Duty Vehicle: Motor Gasoline: Reference case | C7: AEO.2023.REF2023.CNSM_NA_TRN_LDTY_MGS_NA_NA_TRLBTU.A | D7: trillion Btu | F7: 14415.272 | G7: 14443.936 | H7: 14272.424 | I7: 14024.321 | J7: 13815.495 | K7: 13632.25 | L7: 13419.692 | M7: 13179.96 | N7: 12922.15 | O7: 12678.574 | P7: 12437.037 | Q7: 12238.959 | R7: 12063.409 | S7: 11887.983 | T7: 11710.702 | U7: 11556.08 | V7: 11421.213 | W7: 11295.929 | X7: 11196.766 | Y7: 11110.767 | Z7: 11042.225 | AA7: 10988.435 | AB7: 10958.348 | AC7: 10949.109 | AD7: 10963.974 | AE7: 10998.307 | AF7: 11045.134 | AG7: 11100.26 | AH7: 11174.06 | AI7: -0.009
A8: E85 | B8: Transportation Energy Use: Light-Duty Vehicle: Ethanol: Reference case | C8: AEO.2023.REF2023.CNSM_NA_TRN_LDTY_ETH_NA_NA_TRLBTU.A | D8: trillion Btu | F8: 31.110834 | G8: 31.64006 | H8: 29.552767 | I8: 29.441513 | J8: 28.728485 | K8: 27.952177 | L8: 27.018059 | M8: 25.972713 | N8: 24.873795 | O8: 23.80064 | P8: 22.75461 | Q8: 21.823027 | R8: 20.987984 | S8: 20.244169 | T8: 19.537762 | U8: 19.024712 | V8: 18.648621 | W8: 18.39851 | X8: 18.275644 | Y8: 18.222813 | Z8: 18.236134 | AA8: 18.340065 | AB8: 18.452595 | AC8: 18.609615 | AD8: 18.756809 | AE8: 19.004078 | AF8: 19.229309 | AG8: 19.515997 | AH8: 19.788425 | AI8: -0.016
A9: Distillate Fuel Oil (diesel) | B9: Transportation Energy Use: Light-Duty Vehicle: Distillate Fuel Oil: Reference case | C9: AEO.2023.REF2023.CNSM_NA_TRN_LDTY_DFO_NA_NA_TRLBTU.A | D9: trillion Btu | F9: 61.460403 | G9: 64.69902 | H9: 67.503647 | I9: 70.684074 | J9: 74.503555 | K9: 77.63253 | L9: 81.324982 | M9: 84.520767 | N9: 86.959732 | O9: 89.758049 | P9: 91.490158 | Q9: 93.247543 | R9: 95.158997 | S9: 96.641708 | T9: 98.053238 | U9: 99.8647 | V9: 101.3619 | W9: 102.78562 | X9: 104.47522 | Y9: 105.74961 | Z9: 107.32461 | AA9: 109.77927 | AB9: 110.92001 | AC9: 111.97984 | AD9: 113.44128 | AE9: 115.03706 | AF9: 116.75106 | AG9: 118.59347 | AH9: 120.69574 | AI9: 0.024
A10: Compressed/Liquefied Natural Gas | B10: Transportation Energy Use: Light-Duty Vehicle: Natural Gas: Reference case | C10: AEO.2023.REF2023.CNSM_NA_TRN_LDTY_NG_NA_NA_TRLBTU.A | D10: trillion Btu | F10: 0.712888 | G10: 0.677668 | H10: 0.537752 | I10: 0.515005 | J10: 0.507019 | K10: 0.492443 | L10: 0.481839 | M10: 0.470472 | N10: 0.445942 | O10: 0.443445 | P10: 0.437883 | Q10: 0.433434 | R10: 0.431733 | S10: 0.430499 | T10: 0.427096 | U10: 0.424631 | V10: 0.426227 | W10: 0.378024 | X10: 0.335326 | Y10: 0.340053 | Z10: 0.343781 | AA10: 0.346656 | AB10: 0.349313 | AC10: 0.351864 | AD10: 0.356448 | AE10: 0.36171 | AF10: 0.367786 | AG10: 0.374043 | AH10: 0.381082 | AI10: -0.022
A11: Propane | B11: Transportation Energy Use: Light-Duty Vehicle: Propane: Reference case | C11: AEO.2023.REF2023.CNSM_NA_TRN_LDTY_PROP_NA_NA_TRLBTU.A | D11: trillion Btu | F11: 0.797388 | G11: 0.735487 | H11: 0.547456 | I11: 0.540668 | J11: 0.544193 | K11: 0.561282 | L11: 0.312092 | M11: 0.33014 | N11: 0.384077 | O11: 0.437626 | P11: 0.489719 | Q11: 0.540254 | R11: 0.590177 | S11: 0.638076 | T11: 0.684164 | U11: 0.72876 | V11: 0.771586 | W11: 0.812987 | X11: 0.85285 | Y11: 0.891809 | Z11: 0.930713 | AA11: 0.968622 | AB11: 1.007558 | AC11: 1.048031 | AD11: 1.096531 | AE11: 1.150243 | AF11: 1.209162 | AG11: 1.271896 | AH11: 1.341161 | AI11: 0.019
A12: Electricity | B12: Transportation Energy Use: Light-Duty Vehicle: Electricity: Reference case | C12: AEO.2023.REF2023.CNSM_NA_TRN_LDTY_ELC_NA_NA_TRLBTU.A | D12: trillion Btu | F12: 32.193668 | G12: 43.907116 | H12: 58.529484 | I12: 75.757942 | J12: 96.391159 | K12: 121.06613 | L12: 149.37682 | M12: 181.62849 | N12: 217.24832 | O12: 249.97737 | P12: 283.60272 | Q12: 317.79742 | R12: 352.76804 | S12: 387.34479 | T12: 420.6944 | U12: 453.18622 | V12: 484.42331 | W12: 513.9956 | X12: 541.63086 | Y12: 567.72461 | Z12: 591.9502 | AA12: 614.02081 | AB12: 634.53888 | AC12: 652.89734 | AD12: 671.34821 | AE12: 688.6897 | AF12: 705.21576 | AG12: 721.08112 | AH12: 736.37286 | AI12: 0.118
A13: Hydrogen | B13: Transportation Energy Use: Light-Duty Vehicle: Hydrogen: Reference case | C13: AEO.2023.REF2023.CNSM_NA_TRN_LDTY_HDG_NA_NA_TRLBTU.A | D13: trillion Btu | F13: 0.426139 | G13: 0.518183 | H13: 0.595767 | I13: 0.665118 | J13: 0.737872 | K13: 0.80678 | L13: 0.879698 | M13: 0.948358 | N13: 1.020552 | O13: 1.093446 | P13: 1.165657 | Q13: 1.237105 | R13: 1.309695 | S13: 1.380918 | T13: 1.447488 | U13: 1.512508 | V13: 1.570883 | W13: 1.623062 | X13: 1.665691 | Y13: 1.699897 | Z13: 1.731693 | AA13: 1.753623 | AB13: 1.769871 | AC13: 1.779117 | AD13: 1.789497 | AE13: 1.800149 | AF13: 1.807713 | AG13: 1.813287 | AH13: 1.816777 | AI13: 0.053
A14: Commercial Light Trucks | B14: Transportation Energy Use: Commercial Light Trucks: Total: Reference case | C14: AEO.2023.REF2023.CNSM_NA_TRN_CLTR_NA_NA_NA_TRLBTU.A | D14: trillion Btu | F14: 951.50281 | G14: 942.55829 | H14: 925.34039 | I14: 912.45154 | J14: 903.11096 | K14: 894.80664 | L14: 888.38452 | M14: 882.9956 | N14: 877.03247 | O14: 872.79089 | P14: 871.79065 | Q14: 871.86755 | R14: 873.03363 | S14: 875.07349 | T14: 877.49945 | U14: 881.02332 | V14: 885.54096 | W14: 889.79608 | X14: 896.14636 | Y14: 903.92438 | Z14: 911.92645 | AA14: 919.0462 | AB14: 925.474 | AC14: 932.77234 | AD14: 941.2807 | AE14: 951.49884 | AF14: 960.51416 | AG14: 969.5788 | AH14: 981.5957 | AI14: 0.001
A15: Motor Gasoline excluding E85 | B15: Transportation Energy Use: Commercial Light Trucks: Motor Gasoline: Reference case | C15: AEO.2023.REF2023.CNSM_NA_TRN_CLTR_MGS_NA_NA_TRLBTU.A | D15: trillion Btu | F15: 657.76746 | G15: 651.25983 | H15: 640.80762 | I15: 634.44543 | J15: 630.82428 | K15: 624.78125 | L15: 620.94763 | M15: 618.08075 | N15: 615.03595 | O15: 613.48315 | P15: 614.07129 | Q15: 615.42194 | R15: 617.64148 | S15: 620.38318 | T15: 623.32221 | U15: 627.02631 | V15: 631.23346 | W15: 635.20404 | X15: 640.80859 | Y15: 646.77948 | Z15: 653.38257 | AA15: 659.03369 | AB15: 663.90283 | AC15: 669.03552 | AD15: 675.10999 | AE15: 682.46606 | AF15: 688.97082 | AG15: 695.63995 | AH15: 704.23315 | AI15: 0.002
A16: E85 | B16: Transportation Energy Use: Commercial Light Trucks: E85: Reference case | C16: AEO.2023.REF2023.CNSM_NA_TRN_CLTR_E85_NA_NA_TRLBTU.A | D16: trillion Btu | F16: 3.51367 | G16: 3.389497 | H16: 2.991625 | I16: 2.903706 | J16: 2.76768 | K16: 2.708098 | L16: 2.664845 | M16: 2.671002 | N16: 2.68058 | O16: 2.705457 | P16: 2.745193 | Q16: 2.803118 | R16: 2.875419 | S16: 2.972388 | T16: 3.075218 | U16: 3.206507 | V16: 3.350161 | W16: 3.50104 | X16: 3.666781 | Y16: 3.843432 | Z16: 4.016943 | AA16: 4.194909 | AB16: 4.354052 | AC16: 4.515519 | AD16: 4.667729 | AE16: 4.835943 | AF16: 4.97936 | AG16: 5.131686 | AH16: 5.282454 | AI16: 0.015
A17: Distillate Fuel Oil (diesel) | B17: Transportation Energy Use: Commercial Light Trucks: Distillate Fuel Oil: Reference case | C17: AEO.2023.REF2023.CNSM_NA_TRN_CLTR_DFO_NA_NA_TRLBTU.A | D17: trillion Btu | F17: 289.12039 | G17: 286.82144 | H17: 280.46921 | I17: 274.07837 | J17: 268.54092 | K17: 266.37576 | L17: 263.84299 | M17: 261.31543 | N17: 258.40118 | O17: 255.69388 | P17: 254.05814 | Q17: 252.70514 | R17: 251.54263 | S17: 250.69047 | T17: 250.00555 | U17: 249.60524 | V17: 249.66022 | W17: 249.65735 | X17: 250.07077 | Y17: 251.50558 | Z17: 252.50731 | AA17: 253.54639 | AB17: 254.6667 | AC17: 256.36206 | AD17: 258.3045 | AE17: 260.63464 | AF17: 262.62152 | AG17: 264.4642 | AH17: 267.30786 | AI17: -0.003
... A19: Compressed/Liquefied Natural Gas | B19: Transportation Energy Use: Commercial Light Trucks: Natural Gas: Reference case | C19: AEO.2023.REF2023.CNSM_NA_TRN_CLTR_NG_NA_NA_TRLBTU.A | D19: trillion Btu | F19: 1.100109 | G19: 1.028096 | H19: 0.954857 | I19: 0.851628 | J19: 0.748517 | K19: 0.657968 | L19: 0.592555 | M19: 0.535011 | N19: 0.478159 | O19: 0.423993 | P19: 0.376664 | Q19: 0.335485 | R19: 0.300891 | S19: 0.271073 | T19: 0.243198 | U19: 0.217586 | V19: 0.194927 | W19: 0.176079 | X19: 0.160581 | Y19: 0.146182 | Z19: 0.133464 | AA19: 0.121475 | AB19: 0.110383 | AC19: 0.099974 | AD19: 0.087947 | AE19: 0.07232 | AF19: 0.057146 | AG19: 0.045076 | AH19: 0.03417 | AI19: -0.117
A20: Electricity | B20: Transportation Energy Use: Commercial Light Trucks: Electricity: Reference case | C20: AEO.2023.REF2023.CNSM_NA_TRN_CLTR_ELC_NA_NA_TRLBTU.A | D20: trillion Btu | F20: 0 | G20: 0 | H20: 0 | I20: 0 | J20: 0 | K20: 0 | L20: 0 | M20: 0 | N20: 0 | O20: 0 | P20: 0 | Q20: 0 | R20: 0 | S20: 0 | T20: 0 | U20: 0 | V20: 0 | W20: 0 | X20: 0 | Y20: 0 | Z20: 0 | AA20: 0 | AB20: 0 | AC20: 0 | AD20: 0 | AE20: 0 | AF20: 0 | AG20: 0 | AH20: 0 | AI20: - -
A21: Hydrogen | B21: Transportation Energy Use: Commercial Light Trucks: Hydrogen: Reference case | C21: AEO.2023.REF2023.CNSM_NA_TRN_CLTR_HDG_NA_NA_TRLBTU.A | D21: trillion Btu | F21: 0 | G21: 0 | H21: 0 | I21: 0 | J21: 0 | K21: 0 | L21: 0 | M21: 0 | N21: 0 | O21: 0 | P21: 0 | Q21: 0 | R21: 0 | S21: 0 | T21: 0 | U21: 0 | V21: 0 | W21: 0 | X21: 0 | Y21: 0 | Z21: 0 | AA21: 0 | AB21: 0 | AC21: 0 | AD21: 0 | AE21: 0 | AF21: 0 | AG21: 0 | AH21: 0 | AI21: - -
A22: Freight Trucks | B22: Transportation Energy Use: Freight Trucks: Total: Reference case | C22: AEO.2023.REF2023.CNSM_NA_TRN_FRTT_NA_NA_NA_TRLBTU.A | D22: trillion Btu | F22: 5922.791 | G22: 5816.7056 | H22: 5728.0952 | I22: 5673.0986 | J22: 5638.8965 | K22: 5591.7085 | L22: 5543.7119 | M22: 5483.6694 | N22: 5422.3887 | O22: 5371.3027 | P22: 5340.1582 | Q22: 5306.5049 | R22: 5278.7798 | S22: 5261.2471 | T22: 5242.999 | U22: 5237.6973 | V22: 5236.3618 | W22: 5238.3042 | X22: 5247.9146 | Y22: 5263.2085 | Z22: 5281.4541 | AA22: 5299.6816 | AB22: 5316.7681 | AC22: 5331.7002 | AD22: 5353.1992 | AE22: 5376.3164 | AF22: 5393.3179 | AG22: 5413.417 | AH22: 5450.0122 | AI22: -0.003
A23: Motor Gasoline | B23: Transportation Energy Use: Freight Trucks: Motor Gasoline: Reference case | C23: AEO.2023.REF2023.CNSM_NA_TRN_FRTT_MGS_NA_NA_TRLBTU.A | D23: trillion Btu | F23: 616.2052 | G23: 611.60089 | H23: 610.37268 | I23: 612.19367 | J23: 616.9259 | K23: 620.02863 | L23: 623.43561 | M23: 626.1109 | N23: 629.31873 | O23: 633.79578 | P23: 641.25617 | Q23: 647.76111 | R23: 654.28461 | S23: 661.13013 | T23: 667.05139 | U23: 674.55737 | V23: 681.19171 | W23: 688.82941 | X23: 697.0672 | Y23: 706.54358 | Z23: 715.97064 | AA23: 725.08044 | AB23: 734.18097 | AC23: 743.18781 | AD23: 753.50971 | AE23: 764.21655 | AF23: 774.0188 | AG23: 784.56543 | AH23: 797.65808 | AI23: 0.009
A24: Distillate Fuel Oil (diesel) | B24: Transportation Energy Use: Freight Trucks: Distillate Fuel Oil: Reference case | C24: AEO.2023.REF2023.CNSM_NA_TRN_FRTT_DFO_NA_NA_TRLBTU.A | D24: trillion Btu | F24: 5252.3306 | G24: 5150.2441 | H24: 5062.3154 | I24: 5004.9751 | J24: 4965.6987 | K24: 4915.5693 | L24: 4864.6592 | M24: 4802.8213 | N24: 4739.4141 | O24: 4684.7788 | P24: 4646.6831 | Q24: 4606.6587 | R24: 4572.083 | S24: 4546.9648 | T24: 4521.8164 | U24: 4507.6465 | V24: 4498.0513 | W24: 4490.4604 | X24: 4489.5615 | Y24: 4492.7368 | Z24: 4498.6597 | AA24: 4504.667 | AB24: 4509.3804 | AC24: 4511.9082 | AD24: 4519.4395 | AE24: 4527.9907 | AF24: 4531.3125 | AG24: 4536.8086 | AH24: 4555.8003 | AI24: -0.005
A25: Compressed/Liquefied Natural Gas | B25: Transportation Energy Use: Freight Trucks: Natural Gas: Reference case | C25: AEO.2023.REF2023.CNSM_NA_TRN_FRTT_NG_NA_NA_TRLBTU.A | D25: trillion Btu | F25: 51.344929 | G25: 51.773193 | H25: 51.965775 | I25: 52.061794 | J25: 52.003609 | K25: 51.453991 | L25: 50.587242 | M25: 49.35791 | N25: 47.935226 | O25: 46.656029 | P25: 45.774757 | Q25: 45.265823 | R25: 45.213749 | S25: 45.570152 | T25: 46.181812 | U25: 47.148071 | V25: 48.373516 | W25: 49.850357 | X25: 51.657871 | Y25: 53.785 | Z25: 56.128628 | AA25: 58.653038 | AB25: 61.32283 | AC25: 64.089226 | AD25: 67.060806 | AE25: 70.195709 | AF25: 73.347763 | AG25: 76.647514 | AH25: 80.336479 | AI25: 0.016
A26: Propane | B26: Transportation Energy Use: Freight Trucks: Propane: Reference case | C26: AEO.2023.REF2023.CNSM_NA_TRN_FRTT_LPG_NA_NA_TRLBTU.A | D26: trillion Btu | F26: 1.245265 | G26: 1.386178 | H26: 1.524881 | I26: 1.656008 | J26: 1.786266 | K26: 1.903707 | L26: 2.010578 | M26: 2.099689 | N26: 2.180499 | O26: 2.260465 | P26: 2.347809 | Q26: 2.440473 | R26: 2.541221 | S26: 2.644983 | T26: 2.752405 | U26: 2.87385 | V26: 3.004591 | W26: 3.149585 | X26: 3.313908 | Y26: 3.500602 | Z26: 3.702072 | AA26: 3.917007 | AB26: 4.141416 | AC26: 4.376885 | AD26: 4.632447 | AE26: 4.901746 | AF26: 5.174631 | AG26: 5.447477 | AH26: 5.745036 | AI26: 0.056
A27: E85 | B27: Transportation Energy Use: Freight Trucks: E85: Reference case | C27: AEO.2023.REF2023.CNSM_NA_TRN_FRTT_E85_NA_NA_TRLBTU.A | D27: trillion Btu | F27: 1.575329 | G27: 1.59209 | H27: 1.542675 | I27: 1.600683 | J27: 1.639342 | K27: 1.678971 | L27: 1.719318 | M27: 1.762707 | N27: 1.813895 | O27: 1.879181 | P27: 1.95436 | Q27: 2.033936 | R27: 2.113308 | S27: 2.196958 | T27: 2.268667 | U27: 2.353445 | V27: 2.433783 | W27: 2.515797 | X27: 2.611985 | Y27: 2.71994 | Z27: 2.833077 | AA27: 2.961128 | AB27: 3.087059 | AC27: 3.218797 | AD27: 3.346063 | AE27: 3.488648 | AF27: 3.617473 | AG27: 3.75576 | AH27: 3.895148 | AI27: 0.033
A28: Electricity | B28: Transportation Energy Use: Freight Trucks: Electricity: Reference case | C28: AEO.2023.REF2023.CNSM_NA_TRN_FRTT_ELC_NA_NA_TRLBTU.A | D28: trillion Btu | F28: 0.090132 | G28: 0.109146 | H28: 0.144005 | I28: 0.163405 | J28: 0.180895 | K28: 0.195757 | L28: 0.208274 | M28: 0.218016 | N28: 0.225574 | O28: 0.231714 | P28: 0.236945 | Q28: 0.240285 | R28: 0.242473 | S28: 0.244232 | T28: 0.245169 | U28: 0.246735 | V28: 0.249455 | W28: 0.25267 | X28: 0.257144 | Y28: 0.263999 | Z28: 0.273114 | AA28: 0.282851 | AB28: 0.293846 | AC28: 0.306597 | AD28: 0.321782 | AE28: 0.338025 | AF28: 0.354865 | AG28: 0.372904 | AH28: 0.39289 | AI28: 0.054
A29: Hydrogen | B29: Transportation Energy Use: Freight Trucks: Hydrogen: Reference case | C29: AEO.2023.REF2023.CNSM_NA_TRN_FRTT_HDG_NA_NA_TRLBTU.A | D29: trillion Btu | F29: 0 | G29: 0 | H29: 0.229727 | I29: 0.447252 | J29: 0.662312 | K29: 0.877515 | L29: 1.09125 | M29: 1.299036 | N29: 1.500679 | O29: 1.700765 | P29: 1.904776 | Q29: 2.104716 | R29: 2.301462 | S29: 2.495941 | T29: 2.683397 | U29: 2.871152 | V29: 3.057535 | W29: 3.245911 | X29: 3.444844 | Y29: 3.658572 | Z29: 3.886771 | AA29: 4.120397 | AB29: 4.36127 | AC29: 4.612166 | AD29: 4.888996 | AE29: 5.184831 | AF29: 5.492115 | AG29: 5.819783 | AH29: 6.18408 | AI29: - -
A30: Freight Rail | B30: Transportation Energy Use: Freight Rail: Total: Reference case | C30: AEO.2023.REF2023.CNSM_NA_TRN_FRAIL_NA_NA_NA_TRLBTU.A | D30: trillion Btu | F30: 481.38171 | G30: 474.82239 | H30: 494.12915 | I30: 482.20422 | J30: 461.88034 | K30: 446.09524 | L30: 439.74536 | M30: 444.5257 | N30: 441.89194 | O30: 443.42331 | P30: 447.43723 | Q30: 450.64798 | R30: 452.66559 | S30: 455.51504 | T30: 455.89371 | U30: 456.86227 | V30: 458.27463 | W30: 457.60877 | X30: 458.12836 | Y30: 461.67325 | Z30: 464.58835 | AA30: 464.93649 | AB30: 464.92282 | AC30: 464.77069 | AD30: 465.76679 | AE30: 468.15533 | AF30: 471.33984 | AG30: 472.59906 | AH30: 475.72867 | AI30: 0
A31: Distillate Fuel Oil (diesel) | B31: Transportation Energy Use: Freight Rail: Distillate Fuel Oil: Reference case | C31: AEO.2023.REF2023.CNSM_NA_TRN_FRAIL_DFO_NA_NA_TRLBTU.A | D31: trillion Btu | F31: 480.86655 | G31: 473.79251 | H31: 492.51502 | I31: 480.10034 | J31: 459.17535 | K31: 442.59573 | L31: 435.20493 | M31: 438.61609 | N31: 434.49127 | O31: 434.25302 | P31: 435.99301 | Q31: 436.48691 | R31: 435.37204 | S31: 434.60773 | T31: 431.05429 | U31: 427.65039 | V31: 424.25372 | W31: 418.55365 | X31: 413.58151 | Y31: 410.94678 | Z31: 407.33847 | AA31: 401.1214 | AB31: 394.29074 | AC31: 387.0668 | AD31: 380.52634 | AE31: 373.70102 | AF31: 367.60938 | AG31: 360.13336 | AH31: 354.19946 | AI31: -0.011
A32: Residual Fuel Oil | B32: Transportation Energy Use: Freight Rail: Residual Fuel Oil: Reference case | C32: AEO.2023.REF2023.CNSM_NA_TRN_FRAIL_RFO_NA_NA_TRLBTU.A | D32: trillion Btu | F32: 0 | G32: 0 | H32: 0 | I32: 0 | J32: 0 | K32: 0 | L32: 0 | M32: 0 | N32: 0 | O32: 0 | P32: 0 | Q32: 0 | R32: 0 | S32: 0 | T32: 0 | U32: 0 | V32: 0 | W32: 0 | X32: 0 | Y32: 0 | Z32: 0 | AA32: 0 | AB32: 0 | AC32: 0 | AD32: 0 | AE32: 0 | AF32: 0 | AG32: 0 | AH32: 0 | AI32: - -
A33: Compressed Natural Gas | B33: Transportation Energy Use: Freight Rail: CNG: Reference case | C33: AEO.2023.REF2023.CNSM_NA_TRN_FRAIL_CNG_NA_NA_TRLBTU.A | D33: trillion Btu | F33: 0 | G33: 0 | H33: 0 | I33: 0 | J33: 0 | K33: 0 | L33: 0 | M33: 0 | N33: 0 | O33: 0 | P33: 0 | Q33: 0 | R33: 0 | S33: 0 | T33: 0 | U33: 0 | V33: 0 | W33: 0 | X33: 0 | Y33: 0 | Z33: 0 | AA33: 0 | AB33: 0 | AC33: 0 | AD33: 0 | AE33: 0 | AF33: 0 | AG33: 0 | AH33: 0 | AI33: - -
A34: Liquefied Natural Gas | B34: Transportation Energy Use: Freight Rail: LNG: Reference case | C34: AEO.2023.REF2023.CNSM_NA_TRN_FRAIL_LNG_NA_NA_TRLBTU.A | D34: trillion Btu | F34: 0.515163 | G34: 1.02989 | H34: 1.614129 | I34: 2.103867 | J34: 2.704991 | K34: 3.499511 | L34: 4.540437 | M34: 5.909603 | N34: 7.400651 | O34: 9.170284 | P34: 11.444215 | Q34: 14.161068 | R34: 17.293554 | S34: 20.907318 | T34: 24.839417 | U34: 29.211893 | V34: 34.020897 | W34: 39.055111 | X34: 44.546833 | Y34: 50.726471 | Z34: 57.249889 | AA34: 63.815086 | AB34: 70.632088 | AC34: 77.703888 | AD34: 85.240448 | AE34: 94.45433 | AF34: 103.73048 | AG34: 112.46571 | AH34: 121.5292 | AI34: 0.215
A35: Domestic Shipping | B35: Transportation Energy Use: Domestic Shipping: Total: Reference case | C35: AEO.2023.REF2023.CNSM_NA_TRN_DMT_NA_NA_NA_TRLBTU.A | D35: trillion Btu | F35: 98.239021 | G35: 98.920753 | H35: 98.114662 | I35: 97.346069 | J35: 96.685867 | K35: 95.823471 | L35: 94.964699 | M35: 93.890503 | N35: 92.919189 | O35: 92.029816 | P35: 91.401108 | Q35: 90.674225 | R35: 89.934029 | S35: 89.168869 | T35: 88.333008 | U35: 87.614967 | V35: 86.833351 | W35: 86.156693 | X35: 85.473595 | Y35: 84.846123 | Z35: 84.273766 | AA35: 83.705399 | AB35: 83.103455 | AC35: 82.418205 | AD35: 81.856209 | AE35: 81.249023 | AF35: 80.57312 | AG35: 79.990395 | AH35: 79.59285 | AI35: -0.007
A36: Distillate Fuel Oil (diesel) | B36: Transportation Energy Use: Domestic Shipping: Distillate Fuel Oil: Reference case | C36: AEO.2023.REF2023.CNSM_NA_TRN_DMT_DFO_NA_NA_TRLBTU.A | D36: trillion Btu | F36: 95.724983 | G36: 96.410873 | H36: 95.648369 | I36: 94.922401 | J36: 94.299675 | K36: 93.480141 | L36: 92.663536 | M36: 91.636002 | N36: 90.709732 | O36: 89.864052 | P36: 89.27182 | Q36: 88.583908 | R36: 87.881882 | S36: 87.15461 | T36: 86.355026 | U36: 85.672012 | V36: 84.929306 | W36: 84.29055 | X36: 83.598648 | Y36: 82.885956 | Z36: 82.221779 | AA36: 81.555756 | AB36: 80.850998 | AC36: 80.05899 | AD36: 79.380051 | AE36: 78.650116 | AF36: 77.846336 | AG36: 77.124741 | AH36: 76.572762 | AI36: -0.008
A37: Residual Oil | B37: Transportation Energy Use: Domestic Shipping: Residual Oil: Reference case | C37: AEO.2023.REF2023.CNSM_NA_TRN_DMT_RFO_NA_NA_TRLBTU.A | D37: trillion Btu | F37: 1.875904 | G37: 1.807883 | H37: 1.713682 | I37: 1.621937 | J37: 1.541314 | K37: 1.455168 | L37: 1.371278 | M37: 1.286325 | N37: 1.199985 | O37: 1.112551 | P37: 1.031564 | Q37: 0.948396 | R37: 0.868606 | S37: 0.791824 | T37: 0.725306 | U37: 0.65481 | V37: 0.575319 | W37: 0.49193 | X37: 0.417902 | Y37: 0.414755 | Z37: 0.411875 | AA37: 0.409016 | AB37: 0.40599 | AC37: 0.402548 | AD37: 0.399741 | AE37: 0.396733 | AF37: 0.393356 | AG37: 0.390453 | AH37: 0.388505 | AI37: -0.055
