Workbook

Sheet About
A1: CCUP Cement Carbonation Uptake Parameters
A3: Sources: | B3: Concrete and mortar uptake shares, service life, mortar carbonation rate | D3: Cement use by type of customer, 1975-2003 (mortar share history)
B4: Xi, F., Davis, S. J., Ciais, P., et al. | D4: U.S. Geological Survey
B5: Substantial global carbon uptake by cement carbonation, Nature Geoscience 9, 880-883 (main text and Supplementary Information) | D5: Cement end-use statistics, Historical Statistics for Mineral and Material Commodities in the United States (Data Series 140)
B6: 2016 | D6: 2005
B7: https://doi.org/10.1038/ngeo2840 | D7: https://d9-wret.s3.us-west-2.amazonaws.com/assets/palladium/production/mineral-pubs/historical-statistics/cement-use.pdf
B8: Main text: concrete takes back up 16.1% of its calcination CO2 during its service life, 1.4% at demolition and 0.1% in disposal or reuse. Supplementary Information sections 2.2.2-2.2.3: mortar is typically about 20 mm thick and carbonates at about 19.6 mm per square-root year. The 65-year U.S. service life is the value Xi et al. use for the U.S. and Europe, citing Kapur et al. (2008). These are global averages over many exposure conditions and strength classes, from a model rather than from national measurements. We do not use Xi et al.'s mortar share or their near-100% mortar uptake (see the next two sources). Open manuscript: https://ueaeprints.uea.ac.uk/id/eprint/61678/1/Accepted_manuscript.pdf | D8: The table (metric tons) is typed on the 'USGS end use 1975-2003' tab from the PDF. USGS notes that 1993-1996 lump incomplete survey responses into 'government and miscellaneous', so those years understate the named customers; we use only the masonry, dealer and oil well/mining columns, which are less affected. Before 1975 we hold the 1975 shares, and between 2003 and 2023 we draw straight lines.
B10: Ceiling on how much of the lime can carbonate (degree of carbonation) | D10: Portland cement content of masonry cement
B11: Achternbosch, M., Stemmermann, P., et al., Karlsruhe Institute of Technology (KIT), reporting European standard EN 16757 | D11: U.S. Geological Survey (van Oss, H.G.)
B12: Critical review of the CO2 uptake of concrete by carbonation | D12: Background Facts and Issues Concerning Cement and Cement Data, Open-File Report 2005-1152
B13: 2021 | D13: 2005
B14: https://publikationen.bibliothek.kit.edu/1000131215/109575530 | D14: https://pubs.usgs.gov/of/2005/1152/2005-1152.pdf
B15: EN 16757 uses a degree of carbonation of 0.75 for concrete in general (0.85 exposed to rain, 0.40 indoors). We use 0.75 as the share of mortar's carbonatable CO2 taken up, since mortar carbonates through its whole thickness. The review argues measured degrees of carbonation are often lower (about 0.5-0.6) and that published uptake estimates tend to be high. The standard is cited as reported in this review. | D15: Masonry cements contain roughly 50-67% portland cement, the rest mostly ground limestone or lime. We use the midpoint (0.585) so that a ton of masonry cement carries correspondingly less clinker than a ton of portland cement.
B17: Lime content of clinker | D17: What global carbonation studies assume for the United States (comparison only)
B18: U.S. Environmental Protection Agency | D18: Guo, R., Wang, J., Bing, L., et al.
B19: Inventory of U.S. Greenhouse Gas Emissions and Sinks: 1990-2022, Chapter 4, Cement Production | D19: Global CO2 uptake by cement from 1930 to 2019, Earth System Science Data 13, 1791-1805 (parameter data, Zenodo 4459729)
B20: 2024 | D20: 2021
B21: https://www.epa.gov/system/files/documents/2024-02/us-ghg-inventory-2024-chapter-4-industrial-processes-and-product-use.pdf | D21: https://doi.org/10.5281/zenodo.4459729
B22: The inventory's clinker emission factor (0.51 t CO2 per t clinker) assumes 65% calcium oxide in clinker; we use the same 65%. The inventory itself does not estimate carbonation uptake. | D22: Their U.S. inputs put 12.5% of cement into mortar (range 9.1-29.6%), cited as derived from USGS; later studies (Bing et al. 2023, Niu et al. 2025) reuse the value. Reconstructing it from the 1975-2003 USGS table suggests it counts oil well and government/miscellaneous cement as mortar, and its 29.6% maximum matches the 1994 survey artifact. That is why we derive our own, lower share. Not used in any calculation.
B24: Cement use by type of customer, 2023 (mortar share today)
B25: U.S. Geological Survey
B26: Minerals Yearbook 2023: Cement, tables 12 and 14
B27: 2025
B28: https://d9-wret.s3.us-west-2.amazonaws.com/assets/palladium/production/s3fs-public/media/files/myb1-2023-cemen-ERT.xlsx
B29: Tables 12 (masonry cement shipped) and 14 (portland and blended cement by type of customer) are pasted verbatim on the 'USGS MYB 2023 T12' and 'USGS MYB 2023 T14' tabs; we use the grand totals including Puerto Rico. The split of the 'other or unspecified' concrete product and contractor tonnages comes from table 14's footnotes 8 and 9 and is typed on the Parameters tab. USGS notes these customer-type data are likely accurate to only two significant digits. USGS does not report what building material dealers' customers use their cement for.
A32: Notes:
A33: Purpose | B33: Concrete and mortar slowly take CO2 back up from the air as the lime in them turns back into limestone (carbonation). This file holds the parameters the EPS uses to estimate that uptake: how much CO2 a ton of clinker could take back up, how the cement used each year splits between concrete and mortar, and how fast and how far each one carbonates. The EPS applies them to the cement already in place before the model starts (from the HCCbV file) and to the cement used during the model run.
A34: Layout | B34: Edit the values on the 'Parameters' tab. The 'Calculation' tab works out the carbonatable CO2 per ton of clinker, the mortar's carbonation time and the 2023 customer shares; the 'Use Split' tab gives the concrete/mortar split for every year from 1950 to 2050. The five dark blue tabs are the exported files: carbonatable CO2 per ton of clinker by production pathway (CCUP-potential), the split by year (CCUP-use-share), and the in-service share, in-service time and end-of-life share for each use.
A35: How uptake is calculated | B35: For each year's cement, the share of its carbonatable CO2 taken up by a given age is the in-service share times the square root of age divided by the in-service time (carbonation advances inward by diffusion, which goes with the square root of time), capped at the full in-service share. When the in-service time is over, the end-of-life share is added in one year (demolition and crushing). Concrete: 16.1% over a 65-year service life, then 1.5% at end of life. Mortar: 75% within about a year.
A36: Mortar share | B36: Mortar here means masonry mortar, stucco, plaster and grout. It is masonry cement (all of it) plus the part of the portland cement sold through building material dealers that goes into site-mixed mortar and stucco (we assume half), plus small shares of the concrete product makers' and contractors' 'other' categories (bagged mortar mixes, plastering). The shares are on a clinker basis, because masonry cement contains less clinker per ton. Cement for oil wells, mining and waste stabilization is buried and takes up nothing, so it is left out of both uses; the concrete share is what remains. For the U.S. this gives about 4% mortar today (about 7-8% in the 1970s), well below the 12.5% that global carbonation studies assume for the U.S. The dealer assumption is the largest uncertainty: USGS does not report how dealers' customers use their cement.
A37: Pathways | B37: Carbonatable CO2 per ton of clinker is the lime content of the clinker times the ratio of the molar masses of CO2 and calcium oxide. It is the same for every pathway that makes conventional clinker, including the pathways with carbon capture: capturing the kiln's CO2 does not change the lime in the clinker, so concrete made from it still takes CO2 back up. Alternative chemistry cement is set to zero because its lime content depends on the specific product and we found no published value.
A38: Uncertainty | B38: Published estimates of annual U.S. uptake range from about 7 Mt CO2 (AzariJafari et al. 2025, PNAS) to about 35 Mt (Niu et al. 2025, ESSD), that is, from about an eighth of U.S. cement process emissions to nearly all of them. Most of the spread comes from the mortar share and from how fully mortar carbonates. The concrete values are global averages, not U.S. measurements. Treat results from this file as indicative.

Sheet Parameters
A1: Parameter | B1: Value | C1: Source
A2: Calcium oxide (lime) content of clinker, fraction | B2: 0.65 | C2: EPA GHG Inventory
A3: Molar mass of CO2, g/mol | B3: 44.01 | C3: Physical constant
A4: Molar mass of calcium oxide, g/mol | B4: 56.08 | C4: Physical constant
A5: Concrete: share of carbonatable CO2 taken up during service life | B5: 0.161 | C5: Xi et al. 2016
A6: Concrete: service life, years | B6: 65 | C6: Xi et al. 2016, citing Kapur et al. 2008
A7: Concrete: share taken up at demolition | B7: 0.014 | C7: Xi et al. 2016
A8: Concrete: share taken up in disposal or reuse | B8: 0.001 | C8: Xi et al. 2016
A9: Mortar: share of carbonatable CO2 taken up during use (degree of carbonation) | B9: 0.75 | C9: EN 16757 via KIT review
A10: Mortar: typical thickness, mm | B10: 20 | C10: Xi et al. 2016, Supplementary Information 2.2.2
A11: Mortar: carbonation rate, mm per square-root year | B11: 19.6 | C11: Xi et al. 2016, Supplementary Information 2.2.3
A12: Mortar: share taken up after use | B12: 0 | C12: Mortar has carbonated through during use
A13: Masonry cement: portland cement content, fraction | B13: 0.585 | C13: USGS OFR 2005-1152 (50-67%, midpoint)
... A18: Contractors, 'other or unspecified', 2023, thousand metric tons | B18: 1820 | C18: USGS MYB 2023 table 14, footnote 9

Sheet USGS MYB 2023 T12
A1: TABLE 12
A2: MASONRY CEMENT SHIPPED IN THE UNITED STATES, BY DISTRICT AND VALUE1, 2
C4: 2022 | J4: 2023
E5: Value5 | L5: Value5
C6: Quantity4 | G6: Average6 | J6: Quantity4 | N6: Average6
C7: (thousand | E7: Total | G7: (per | J7: (thousand | L7: Total | N7: (per
A8: District3 | C8: metric tons) | E8: (thousands) | G8: metric ton) | J8: metric tons) | L8: (thousands) | N8: metric ton)
A9: Maine and New York | C9: 22 | E9: 3273 | G9: 148.77 | J9: 16 | L9: 3042 | N9: 189.64
A10: Pennsylvania7 | C10: 171 | E10: 28100 | G10: 164.5 | J10: 144 | L10: 26200 | N10: 181.5
A11: Illinois, Indiana, Ohio | C11: 184 | D11: 7 | E11: 37600 | F11: 7 | G11: 204.5 | H11: 7 | J11: 158 | L11: 38922 | N11: 247.12
A12: Michigan | C12: 72 | E12: 13915 | G12: 193.26 | J12: 62 | L12: 11500 | M12: 7 | N12: 186 | O12: 7
A13: Iowa, Nebraska, South Dakota | C13: W | E13: W | G13: W | J13: W | L13: W | N13: W
A14: Kansas and Missouri | C14: 27 | E14: 6068 | G14: 224.74 | J14: 31 | L14: 8000 | M14: 7 | N14: 253 | O14: 7
A15: Florida | C15: 584 | E15: 90800 | F15: r, 7 | G15: 155.5 | H15: r, 7 | J15: 505 | L15: 82100 | M15: 7 | N15: 162.5 | O15: 7
A16: Georgia, Maryland, Virginia, West Virginia | C16: 266 | E16: 56416 | G16: 212.09 | J16: 258 | K16: 7 | L16: 61700 | M16: 7 | N16: 239 | O16: 7
A17: South Carolina | C17: 260 | E17: 55000 | F17: r, 7 | G17: 211.5 | H17: r, 7 | J17: 212 | L17: 38600 | M17: 7 | N17: 182.5 | O17: 7
A18: Alabama, Kentucky, Mississippi, Tennessee | C18: 250 | E18: 48000 | F18: r, 7 | G18: 192 | H18: r, 7 | J18: 262 | L18: 56300 | M18: 7 | N18: 215 | O18: 7
A19: Arkansas and Oklahoma | C19: 102 | E19: 15068 | G19: 147.73 | J19: 113 | L19: 19386 | N19: 170.94
A20: Texas7 | C20: 275 | E20: 53200 | G20: 193.5 | J20: 227 | L20: 46100 | N20: 203
A21: Arizona, New Mexico | C21: 57 | E21: 8653 | G21: 151.81 | J21: 58 | L21: 9700 | M21: 7 | N21: 166.5 | O21: 7
A22: Colorado, Montana, Nevada, Utah, Wyoming | C22: W | E22: W | G22: W | J22: W | L22: W | N22: W
A23: Alaska and Hawaii | C23: 1 | E23: 611 | G23: 424.5 | H23: r | J23: 2 | L23: 794 | M23: 7 | N23: 424.5 | O23: 7
A24: California, Oregon, Washington7 | C24: 153 | E24: 21300 | G24: 139 | J24: 142 | L24: 20000 | N24: 141.5
A25: Importers7, 8 | C25: 16 | E25: 3440 | G25: 211 | H25: r | J25: 99 | L25: 22100 | N25: 223
A26: Total or average7, 9 | C26: 2440 | E26: 442000 | G26: 181 | J26: 2290 | L26: 445000 | N26: 194
A27: Puerto Rico | C27: -- | E27: -- | G27: -- | J27: -- | L27: -- | N27: --
A28: Grand total or average7, 9 | C28: 2440 | E28: 442000 | G28: 181 | J28: 2290 | L28: 444000 | N28: 194
A29: rRevised. W Withheld to avoid disclosing company proprietary data; included in “Total.” -- Zero.
A30: 1Table includes data available through March 18, 2025. Even where presented unrounded, data are thought to be accurate to no more than three significant digits. Shipments are those by cement companies to final customers and include imported cement and cement made from imported clinker. Excludes sales of masonry cement by portland cement final customers who made masonry cement from purchased portland cement.
A31: 2Data include true masonry, plastic, portland-lime, and stucco cements.
A32: 3District is the location of the reporting entities, not necessarily the location of sales (see table 9 for sales data, by State). Specific districts include shipments by importers where district assignations were possible.
A33: 4Tonnages are those by reporting entities in the district but may include shipments into other districts. They differ from the data in table 9, which are the actual reported sales into the specific States.
A34: 5Values are mill net or ex-plant valuations of total sales to final customers, including sales from plants' external distribution terminals. The data are ex-terminal for independently reporting terminals. Data include both bulk and bag shipments. Unless otherwise specified, data are presented unrounded. Unrounded or not, unit value data should be viewed as value indicators, accurate to no more than the nearest $0.50 or even $1.00 per metric ton.
A35: 6Average value calculated from unrounded data.
A36: 7Data are rounded to no more than three significant digits (unit values to the nearest $0.50) because they include estimates.
A37: 8Importers for which district assignations were not possible.
A38: 9May not add to totals shown because of independent rounding.

Sheet USGS MYB 2023 T14
A1: TABLE 14
A2: PORTLAND AND BLENDED CEMENT SHIPMENTS IN 2023, BY DISTRICT AND TYPE OF CUSTOMER1
A4: (Thousand metric tons)
K6: Oil well,
C7: Ready- | E7: Concrete | I7: Building | K7: mining, | M7: Government
C8: mixed | E8: product | I8: material | K8: waste | M8: and
A9: District2 | C9: concrete | E9: manufacturers | G9: Contractors | I9: dealers | K9: stabilization | M9: other3 | O9: Total4
A10: Maine and New York | C10: 1970 | E10: 237 | G10: 53 | I10: 178 | K10: 6 | M10: 10 | O10: 2450
A11: Pennsylvania | C11: 1870 | E11: 810 | G11: 291 | I11: 310 | K11: 85 | M11: 113 | O11: 3480 | P11: 6
A12: Illinois | C12: 590 | E12: 58 | G12: 788 | I12: 124 | K12: 100 | M12: 2 | O12: 1660
A13: Indiana and Ohio | C13: 2930 | E13: 455 | G13: 323 | I13: 115 | K13: 138 | M13: 55 | O13: 4018
A14: Michigan | C14: 4230 | E14: 499 | G14: 585 | I14: 176 | K14: 6 | M14: 102 | O14: 5593
A15: Iowa, Nebraska, South Dakota | C15: 3060 | E15: 359 | G15: 346 | I15: 14 | K15: 151 | M15: 26 | O15: 3960
A16: Kansas | C16: 1590 | E16: 151 | G16: 187 | I16: 52 | K16: 8 | M16: 19 | O16: 2005
A17: Missouri | C17: 7670 | E17: 671 | G17: 1050 | I17: 150 | K17: 91 | M17: 100 | O17: 9727
A18: Florida | C18: 5500 | E18: 2190 | G18: 619 | I18: 120 | K18: (5) | M18: 138 | O18: 8566
A19: Georgia, Maryland, Virginia, West Virginia | C19: 4110 | E19: 870 | G19: 417 | I19: 407 | K19: 16 | M19: 25 | O19: 5850 | P19: 6
A20: South Carolina | C20: 2700 | E20: 523 | G20: 394 | I20: 68 | K20: 10 | M20: 9 | O20: 3701
A21: Alabama, Kentucky, Tennessee | C21: 6120 | E21: 603 | G21: 743 | I21: 522 | K21: 25 | M21: 25 | O21: 8041
A22: Arkansas and Oklahoma | C22: 1780 | E22: 95 | G22: 263 | I22: 91 | K22: 68 | M22: 6 | O22: 2301
A23: Texas, northern | C23: 4860 | E23: 322 | G23: 1140 | I23: 310 | K23: 949 | M23: 198 | O23: 7780 | P23: 6
A24: Texas, southern | C24: 6690 | E24: 1040 | G24: 1070 | I24: 355 | K24: 281 | M24: 124 | O24: 9670 | P24: 6
A25: Arizona and New Mexico | C25: 3580 | E25: 1050 | G25: 149 | I25: 86 | K25: 94 | M25: 46 | O25: 5014
A26: Colorado and Wyoming | C26: 2200 | E26: 164 | G26: 176 | I26: 61 | K26: 91 | M26: 46 | O26: 2732
A27: Montana, Nevada, Utah | C27: 1870 | E27: 134 | G27: 73 | I27: 29 | K27: 274 | M27: 101 | O27: 2479
A28: Alaska and Hawaii | C28: 361 | E28: 15 | G28: 3 | I28: 4 | K28: 47 | M28: -- | O28: 430 | P28: 6
A29: California | C29: 7390 | E29: 850 | G29: 566 | I29: 746 | K29: 110 | M29: 26 | O29: 9690 | P29: 6
A30: Oregon and Washington | C30: 1410 | E30: 260 | G30: 83 | I30: 44 | K30: 39 | M30: 183 | O30: 2019
A31: Importers7 | C31: 4860 | E31: 753 | G31: 176 | I31: 69 | K31: 22 | M31: 153 | O31: 6030 | P31: 6
A32: Total4 | C32: 77300 | E32: 12100 | G32: 9500 | I32: 4030 | K32: 2610 | M32: 1510 | O32: 107000 | P32: 6
A33: Puerto Rico | C33: 532 | E33: 34 | G33: -- | I33: 83 | K33: -- | M33: -- | O33: 648
A34: Grand total4 | C34: 77900 | E34: 12100 | F34: 8 | G34: 9500 | H34: 9 | I34: 4110 | K34: 2610 | L34: 10 | M34: 1510 | N34: 11 | O34: 108000 | P34: 6
A35: -- Zero.
A36: 1Table includes data available through March 18, 2024. Except for district totals, data have been rounded to three significant digits, but are likely accurate to only two significant digits. District totals are likely accurate to no more than three significant digits. Includes imported cement and cement made from imported clinker.
A37: 2The location of the reporting entity, not the location of sales (see table 9 for sales data, by State). Specific districts include shipments by importers where district assignations were possible.
A38: 3Includes shipments to miscellaneous customer types and for which customer types were not specified.
A39: 4May not add to totals shown because of independent rounding.
A40: 5Less than ½ unit.
A41: 6Includes estimates for nonrespondents or facilities that provided incomplete information.
A42: 7Shipments by importers where district assignations were not possible.
...

Sheet USGS end use 1975-2003
A1: USGS Data Series 140, cement end-use worksheet (metric tons), typed from cement-use.pdf. Government and miscellaneous is reported from 1993 only. Portland cement total and apparent consumption as published.
A2: Year | B2: Ready-mix concrete | C2: Concrete products | D2: Contractors | E2: Building material dealers | F2: Oil well, mining, and waste stabilization | G2: Government and miscellaneous | H2: Portland cement total | I2: Masonry cement | J2: Apparent consumption
A3: 1975 | B3: 39471000 | C3: 8425000 | D3: 7329000 | E3: 4503000 | F3: 1274000 | H3: 61002000 | I3: 2606000 | J3: 63608000
A4: 1976 | B4: 42244000 | C4: 9059000 | D4: 7550000 | E4: 4530000 | F4: 1164000 | H4: 64546000 | I4: 2963000 | J4: 67509000
A5: 1977 | B5: 46710000 | C5: 9751000 | D5: 7246000 | E5: 4951000 | F5: 1413000 | H5: 70071000 | I5: 3356000 | J5: 73427000
A6: 1978 | B6: 50932000 | C6: 10485000 | D6: 7205000 | E6: 5524000 | F6: 1450000 | H6: 75597000 | I6: 3691000 | J6: 79288000
A7: 1979 | B7: 50103000 | C7: 10757000 | D7: 7059000 | E7: 6313000 | F7: 1388000 | H7: 75620000 | I7: 3344000 | J7: 78964000
A8: 1980 | B8: 45818000 | C8: 8794000 | D8: 7097000 | E8: 4509000 | F8: 1230000 | H8: 67448000 | I8: 2724000 | J8: 70173000
A9: 1981 | B9: 43840000 | C9: 7609000 | D9: 7118000 | E9: 3530000 | F9: 1549000 | H9: 63645000 | I9: 2447000 | J9: 66092000
A10: 1982 | B10: 39335000 | C10: 6832000 | D10: 6604000 | E10: 3312000 | F10: 1332000 | H10: 57415000 | I10: 2157000 | J10: 59572000
A11: 1983 | B11: 43325000 | C11: 7464000 | D11: 7370000 | E11: 3824000 | F11: 1247000 | H11: 63229000 | I11: 2609000 | J11: 65838000
A12: 1984 | B12: 50732000 | C12: 9343000 | D12: 7551000 | E12: 4181000 | F12: 1438000 | H12: 73244000 | I12: 2942000 | J12: 76186000
A13: 1985 | B13: 53210000 | C13: 9293000 | D13: 7890000 | E13: 4149000 | F13: 1333000 | H13: 75875000 | I13: 2961000 | J13: 78836000
A14: 1986 | B14: 57233000 | C14: 9394000 | D14: 7440000 | E14: 3945000 | F14: 1599000 | H14: 79611000 | I14: 3226000 | J14: 82837000
... A20: 1992 | B20: 51419000 | C20: 8563000 | D20: 6642000 | E20: 3565000 | F20: 3282000 | H20: 73470000 | I20: 2699000 | J20: 76169000
A21: 1993 | B21: 45481000 | C21: 8780000 | D21: 6016000 | E21: 4657000 | F21: 1097000 | G21: 10686000 | H21: 76717000 | I21: 2984000 | J21: 79701000
A22: 1994 | B22: 45791000 | C22: 9070000 | D22: 4965000 | E22: 3890000 | F22: 1027000 | G22: 17490000 | H22: 82232000 | I22: 3250000 | J22: 85482000
A23: 1995 | B23: 50757000 | C23: 9509000 | D23: 5163000 | E23: 3471000 | F23: 1061000 | G23: 12964000 | H23: 82925000 | I23: 3150000 | J23: 86075000
A24: 1996 | B24: 52773000 | C24: 9899000 | D24: 5560000 | E24: 2937000 | F24: 1302000 | G24: 15037000 | H24: 87509000 | I24: 3569000 | J24: 91078000
A25: 1997 | B25: 67012000 | C25: 11390000 | D25: 7758000 | E25: 3235000 | F25: 2317000 | G25: 1103000 | H25: 92815000 | I25: 3627000 | J25: 96442000
A26: 1998 | B26: 74038000 | C26: 11885000 | D26: 7912000 | E26: 3237000 | F26: 1123000 | G26: 1080000 | H26: 99274000 | I26: 4101000 | J26: 103380000
A27: 1999 | B27: 76018000 | C27: 12844000 | D27: 8610000 | E27: 4468000 | F27: 1128000 | G27: 1128000 | H27: 104200000 | I27: 4353000 | J27: 108550000
A28: 2000 | B28: 77632000 | C28: 14002000 | D28: 7411000 | E28: 3690000 | F28: 1462000 | G28: 1125000 | H28: 105320000 | I28: 4333000 | J28: 109660000
A29: 2001 | B29: 80901000 | C29: 14074000 | D29: 6777000 | E29: 3713000 | F29: 1912000 | G29: 836000 | H29: 108210000 | I29: 4482000 | J29: 112690000
A30: 2002 | B30: 77784000 | C30: 13680000 | D30: 6560000 | E30: 3085000 | F30: 1178000 | G30: 1618000 | H30: 103910000 | I30: 4435000 | J30: 108340000
A31: 2003 | B31: 79883000 | C31: 14864000 | D31: 6866000 | E31: 3650000 | F31: 1456000 | G31: 980000 | H31: 107700000 | I31: 4745000 | J31: 112440000

Sheet Calculation
A1: Single values
A2: Carbonatable CO2 per ton of conventional clinker, g CO2 per metric ton (lime share x 44.01 / 56.08 x 1,000,000) | B2: =Parameters!B2*Parameters!B3/Parameters!B4*1000000 -> 510101.64
A3: Mortar: years to carbonate through ((thickness / rate) squared) | B3: =(Parameters!B10/Parameters!B11)^2 -> 1.0412328
A4: Concrete: end-of-life share (demolition + disposal or reuse) | B4: =Parameters!B7+Parameters!B8 -> 0.015
A5: 2023 masonry cement shipped, thousand metric tons | B5: ='USGS MYB 2023 T12'!J28 -> 2290
A6: 2023 portland and blended cement shipped, thousand metric tons | B6: ='USGS MYB 2023 T14'!O34 -> 108000
A7: 2023 total cement shipped, thousand metric tons | B7: =B5+B6 -> 110290
A8: 2023 masonry cement share of tons | B8: =B5/B7 -> 0.020763442
A9: 2023 building material dealer share of tons | B9: ='USGS MYB 2023 T14'!I34/B7 -> 0.037265391
A10: 2023 oil well, mining and waste stabilization share of tons | B10: ='USGS MYB 2023 T14'!K34/B7 -> 0.023664883
A11: Other mortar-like share of tons (products and contractors 'other', held at the 2023 share in every year) | B11: =(Parameters!B17*Parameters!B15+Parameters!B18*Parameters!B16)/B7 -> 0.0077024209

Sheet Use Split
A1: Which share of each year's cement (clinker basis) goes into mortar, concrete, or is buried? Column F is the mortar share and column H the concrete share that the output file reads.
A2: Year | B2: Masonry cement share of tons | C2: Dealers share of tons | D2: Buried (oil well, mining) share of tons | E2: Clinker weight masonry at its portland content, rest at 1 | F2: MORTAR SHARE USED IN THE OUTPUT FILE clinker basis | G2: Buried share clinker basis, no uptake | H2: CONCRETE SHARE USED IN THE OUTPUT FILE 1 - mortar - buried
A3: 1950 | B3: =B$28 -> 0.040969689 | C3: =C$28 -> 0.070792982 | D3: =D$28 -> 0.020028927 | E3: =B3*Parameters!$B$13+(1-B3) -> 0.98299758 | F3: =(B3*Parameters!$B$13+C3*Parameters!$B$14+Calculation!$B$11)/E3 -> 0.068226191 | G3: =D3/E3 -> 0.020375358 | H3: =1-F3-G3 -> 0.91139845
A4: 1951 | B4: =B$28 -> 0.040969689 | C4: =C$28 -> 0.070792982 | D4: =D$28 -> 0.020028927 | E4: =B4*Parameters!$B$13+(1-B4) -> 0.98299758 | F4: =(B4*Parameters!$B$13+C4*Parameters!$B$14+Calculation!$B$11)/E4 -> 0.068226191 | G4: =D4/E4 -> 0.020375358 | H4: =1-F4-G4 -> 0.91139845
A5: 1952 | B5: =B$28 -> 0.040969689 | C5: =C$28 -> 0.070792982 | D5: =D$28 -> 0.020028927 | E5: =B5*Parameters!$B$13+(1-B5) -> 0.98299758 | F5: =(B5*Parameters!$B$13+C5*Parameters!$B$14+Calculation!$B$11)/E5 -> 0.068226191 | G5: =D5/E5 -> 0.020375358 | H5: =1-F5-G5 -> 0.91139845
A6: 1953 | B6: =B$28 -> 0.040969689 | C6: =C$28 -> 0.070792982 | D6: =D$28 -> 0.020028927 | E6: =B6*Parameters!$B$13+(1-B6) -> 0.98299758 | F6: =(B6*Parameters!$B$13+C6*Parameters!$B$14+Calculation!$B$11)/E6 -> 0.068226191 | G6: =D6/E6 -> 0.020375358 | H6: =1-F6-G6 -> 0.91139845
A7: 1954 | B7: =B$28 -> 0.040969689 | C7: =C$28 -> 0.070792982 | D7: =D$28 -> 0.020028927 | E7: =B7*Parameters!$B$13+(1-B7) -> 0.98299758 | F7: =(B7*Parameters!$B$13+C7*Parameters!$B$14+Calculation!$B$11)/E7 -> 0.068226191 | G7: =D7/E7 -> 0.020375358 | H7: =1-F7-G7 -> 0.91139845
A8: 1955 | B8: =B$28 -> 0.040969689 | C8: =C$28 -> 0.070792982 | D8: =D$28 -> 0.020028927 | E8: =B8*Parameters!$B$13+(1-B8) -> 0.98299758 | F8: =(B8*Parameters!$B$13+C8*Parameters!$B$14+Calculation!$B$11)/E8 -> 0.068226191 | G8: =D8/E8 -> 0.020375358 | H8: =1-F8-G8 -> 0.91139845
A9: 1956 | B9: =B$28 -> 0.040969689 | C9: =C$28 -> 0.070792982 | D9: =D$28 -> 0.020028927 | E9: =B9*Parameters!$B$13+(1-B9) -> 0.98299758 | F9: =(B9*Parameters!$B$13+C9*Parameters!$B$14+Calculation!$B$11)/E9 -> 0.068226191 | G9: =D9/E9 -> 0.020375358 | H9: =1-F9-G9 -> 0.91139845
A10: 1957 | B10: =B$28 -> 0.040969689 | C10: =C$28 -> 0.070792982 | D10: =D$28 -> 0.020028927 | E10: =B10*Parameters!$B$13+(1-B10) -> 0.98299758 | F10: =(B10*Parameters!$B$13+C10*Parameters!$B$14+Calculation!$B$11)/E10 -> 0.068226191 | G10: =D10/E10 -> 0.020375358 | H10: =1-F10-G10 -> 0.91139845
A11: 1958 | B11: =B$28 -> 0.040969689 | C11: =C$28 -> 0.070792982 | D11: =D$28 -> 0.020028927 | E11: =B11*Parameters!$B$13+(1-B11) -> 0.98299758 | F11: =(B11*Parameters!$B$13+C11*Parameters!$B$14+Calculation!$B$11)/E11 -> 0.068226191 | G11: =D11/E11 -> 0.020375358 | H11: =1-F11-G11 -> 0.91139845
A12: 1959 | B12: =B$28 -> 0.040969689 | C12: =C$28 -> 0.070792982 | D12: =D$28 -> 0.020028927 | E12: =B12*Parameters!$B$13+(1-B12) -> 0.98299758 | F12: =(B12*Parameters!$B$13+C12*Parameters!$B$14+Calculation!$B$11)/E12 -> 0.068226191 | G12: =D12/E12 -> 0.020375358 | H12: =1-F12-G12 -> 0.91139845
A13: 1960 | B13: =B$28 -> 0.040969689 | C13: =C$28 -> 0.070792982 | D13: =D$28 -> 0.020028927 | E13: =B13*Parameters!$B$13+(1-B13) -> 0.98299758 | F13: =(B13*Parameters!$B$13+C13*Parameters!$B$14+Calculation!$B$11)/E13 -> 0.068226191 | G13: =D13/E13 -> 0.020375358 | H13: =1-F13-G13 -> 0.91139845
A14: 1961 | B14: =B$28 -> 0.040969689 | C14: =C$28 -> 0.070792982 | D14: =D$28 -> 0.020028927 | E14: =B14*Parameters!$B$13+(1-B14) -> 0.98299758 | F14: =(B14*Parameters!$B$13+C14*Parameters!$B$14+Calculation!$B$11)/E14 -> 0.068226191 | G14: =D14/E14 -> 0.020375358 | H14: =1-F14-G14 -> 0.91139845
... A27: 1974 | B27: =B$28 -> 0.040969689 | C27: =C$28 -> 0.070792982 | D27: =D$28 -> 0.020028927 | E27: =B27*Parameters!$B$13+(1-B27) -> 0.98299758 | F27: =(B27*Parameters!$B$13+C27*Parameters!$B$14+Calculation!$B$11)/E27 -> 0.068226191 | G27: =D27/E27 -> 0.020375358 | H27: =1-F27-G27 -> 0.91139845
A28: 1975 | B28: ='USGS end use 1975-2003'!I3/'USGS end use 1975-2003'!J3 -> 0.040969689 | C28: ='USGS end use 1975-2003'!E3/'USGS end use 1975-2003'!J3 -> 0.070792982 | D28: ='USGS end use 1975-2003'!F3/'USGS end use 1975-2003'!J3 -> 0.020028927 | E28: =B28*Parameters!$B$13+(1-B28) -> 0.98299758 | F28: =(B28*Parameters!$B$13+C28*Parameters!$B$14+Calculation!$B$11)/E28 -> 0.068226191 | G28: =D28/E28 -> 0.020375358 | H28: =1-F28-G28 -> 0.91139845
A29: 1976 | B29: ='USGS end use 1975-2003'!I4/'USGS end use 1975-2003'!J4 -> 0.043890444 | C29: ='USGS end use 1975-2003'!E4/'USGS end use 1975-2003'!J4 -> 0.067102164 | D29: ='USGS end use 1975-2003'!F4/'USGS end use 1975-2003'!J4 -> 0.017242145 | E29: =B29*Parameters!$B$13+(1-B29) -> 0.98178547 | F29: =(B29*Parameters!$B$13+C29*Parameters!$B$14+Calculation!$B$11)/E29 -> 0.068171118 | G29: =D29/E29 -> 0.01756203 | H29: =1-F29-G29 -> 0.91426685
A30: 1977 | B30: ='USGS end use 1975-2003'!I5/'USGS end use 1975-2003'!J5 -> 0.045705258 | C30: ='USGS end use 1975-2003'!E5/'USGS end use 1975-2003'!J5 -> 0.067427513 | D30: ='USGS end use 1975-2003'!F5/'USGS end use 1975-2003'!J5 -> 0.019243602 | E30: =B30*Parameters!$B$13+(1-B30) -> 0.98103232 | F30: =(B30*Parameters!$B$13+C30*Parameters!$B$14+Calculation!$B$11)/E30 -> 0.069471466 | G30: =D30/E30 -> 0.019615666 | H30: =1-F30-G30 -> 0.91091287
A31: 1978 | B31: ='USGS end use 1975-2003'!I6/'USGS end use 1975-2003'!J6 -> 0.046551811 | C31: ='USGS end use 1975-2003'!E6/'USGS end use 1975-2003'!J6 -> 0.069670064 | D31: ='USGS end use 1975-2003'!F6/'USGS end use 1975-2003'!J6 -> 0.018287761 | E31: =B31*Parameters!$B$13+(1-B31) -> 0.980681 | F31: =(B31*Parameters!$B$13+C31*Parameters!$B$14+Calculation!$B$11)/E31 -> 0.071144707 | G31: =D31/E31 -> 0.018648022 | H31: =1-F31-G31 -> 0.91020727
A32: 1979 | B32: ='USGS end use 1975-2003'!I7/'USGS end use 1975-2003'!J7 -> 0.042348412 | C32: ='USGS end use 1975-2003'!E7/'USGS end use 1975-2003'!J7 -> 0.079947824 | D32: ='USGS end use 1975-2003'!F7/'USGS end use 1975-2003'!J7 -> 0.01757763 | E32: =B32*Parameters!$B$13+(1-B32) -> 0.98242541 | F32: =(B32*Parameters!$B$13+C32*Parameters!$B$14+Calculation!$B$11)/E32 -> 0.073746214 | G32: =D32/E32 -> 0.017892076 | H32: =1-F32-G32 -> 0.90836171
A33: 1980 | B33: ='USGS end use 1975-2003'!I8/'USGS end use 1975-2003'!J8 -> 0.038818349 | C33: ='USGS end use 1975-2003'!E8/'USGS end use 1975-2003'!J8 -> 0.064255483 | D33: ='USGS end use 1975-2003'!F8/'USGS end use 1975-2003'!J8 -> 0.017528109 | E33: =B33*Parameters!$B$13+(1-B33) -> 0.98389039 | F33: =(B33*Parameters!$B$13+C33*Parameters!$B$14+Calculation!$B$11)/E33 -> 0.06356287 | G33: =D33/E33 -> 0.017815104 | H33: =1-F33-G33 -> 0.91862203
A34: 1981 | B34: ='USGS end use 1975-2003'!I9/'USGS end use 1975-2003'!J9 -> 0.037024148 | C34: ='USGS end use 1975-2003'!E9/'USGS end use 1975-2003'!J9 -> 0.053410398 | D34: ='USGS end use 1975-2003'!F9/'USGS end use 1975-2003'!J9 -> 0.023437027 | E34: =B34*Parameters!$B$13+(1-B34) -> 0.98463498 | F34: =(B34*Parameters!$B$13+C34*Parameters!$B$14+Calculation!$B$11)/E34 -> 0.056941656 | G34: =D34/E34 -> 0.023802757 | H34: =1-F34-G34 -> 0.91925559
A35: 1982 | B35: ='USGS end use 1975-2003'!I10/'USGS end use 1975-2003'!J10 -> 0.036208286 | C35: ='USGS end use 1975-2003'!E10/'USGS end use 1975-2003'!J10 -> 0.055596589 | D35: ='USGS end use 1975-2003'!F10/'USGS end use 1975-2003'!J10 -> 0.022359498 | E35: =B35*Parameters!$B$13+(1-B35) -> 0.98497356 | F35: =(B35*Parameters!$B$13+C35*Parameters!$B$14+Calculation!$B$11)/E35 -> 0.057547293 | G35: =D35/E35 -> 0.022700607 | H35: =1-F35-G35 -> 0.9197521
A36: 1983 | B36: ='USGS end use 1975-2003'!I11/'USGS end use 1975-2003'!J11 -> 0.039627571 | C36: ='USGS end use 1975-2003'!E11/'USGS end use 1975-2003'!J11 -> 0.058081959 | D36: ='USGS end use 1975-2003'!F11/'USGS end use 1975-2003'!J11 -> 0.01894043 | E36: =B36*Parameters!$B$13+(1-B36) -> 0.98355456 | F36: =(B36*Parameters!$B$13+C36*Parameters!$B$14+Calculation!$B$11)/E36 -> 0.060927509 | G36: =D36/E36 -> 0.019257121 | H36: =1-F36-G36 -> 0.91981537
A37: 1984 | B37: ='USGS end use 1975-2003'!I12/'USGS end use 1975-2003'!J12 -> 0.038616019 | C37: ='USGS end use 1975-2003'!E12/'USGS end use 1975-2003'!J12 -> 0.054878849 | D37: ='USGS end use 1975-2003'!F12/'USGS end use 1975-2003'!J12 -> 0.018874859 | E37: =B37*Parameters!$B$13+(1-B37) -> 0.98397435 | F37: =(B37*Parameters!$B$13+C37*Parameters!$B$14+Calculation!$B$11)/E37 -> 0.058672481 | G37: =D37/E37 -> 0.019182267 | H37: =1-F37-G37 -> 0.92214525
A38: 1985 | B38: ='USGS end use 1975-2003'!I13/'USGS end use 1975-2003'!J13 -> 0.037558983 | C38: ='USGS end use 1975-2003'!E13/'USGS end use 1975-2003'!J13 -> 0.052628241 | D38: ='USGS end use 1975-2003'!F13/'USGS end use 1975-2003'!J13 -> 0.016908519 | E38: =B38*Parameters!$B$13+(1-B38) -> 0.98441302 | F38: =(B38*Parameters!$B$13+C38*Parameters!$B$14+Calculation!$B$11)/E38 -> 0.056875057 | G38: =D38/E38 -> 0.017176245 | H38: =1-F38-G38 -> 0.9259487
A39: 1986 | B39: ='USGS end use 1975-2003'!I14/'USGS end use 1975-2003'!J14 -> 0.03894395 | C39: ='USGS end use 1975-2003'!E14/'USGS end use 1975-2003'!J14 -> 0.047623646 | D39: ='USGS end use 1975-2003'!F14/'USGS end use 1975-2003'!J14 -> 0.019302968 | E39: =B39*Parameters!$B$13+(1-B39) -> 0.98383826 | F39: =(B39*Parameters!$B$13+C39*Parameters!$B$14+Calculation!$B$11)/E39 -> 0.055188395 | G39: =D39/E39 -> 0.019620063 | H39: =1-F39-G39 -> 0.92519154
... A56: 2003 | B56: ='USGS end use 1975-2003'!I31/'USGS end use 1975-2003'!J31 -> 0.042200285 | C56: ='USGS end use 1975-2003'!E31/'USGS end use 1975-2003'!J31 -> 0.032461757 | D56: ='USGS end use 1975-2003'!F31/'USGS end use 1975-2003'!J31 -> 0.012949128 | E56: =B56*Parameters!$B$13+(1-B56) -> 0.98248688 | F56: =(B56*Parameters!$B$13+C56*Parameters!$B$14+Calculation!$B$11)/E56 -> 0.04948714 | G56: =D56/E56 -> 0.01317995 | H56: =1-F56-G56 -> 0.93733291
A57: 2004 | B57: =B56+(B76-B56)*(A57-A56)/(A76-A56) -> 0.041128442 | C57: =C56+(C76-C56)*(A57-A56)/(A76-A56) -> 0.032701939 | D57: =D56+(D76-D56)*(A57-A56)/(A76-A56) -> 0.013484916 | E57: =B57*Parameters!$B$13+(1-B57) -> 0.9829317 | F57: =(B57*Parameters!$B$13+C57*Parameters!$B$14+Calculation!$B$11)/E57 -> 0.048949006 | G57: =D57/E57 -> 0.013719078 | H57: =1-F57-G57 -> 0.93733192
A58: 2005 | B58: =B56+(B76-B56)*(A58-A56)/(A76-A56) -> 0.0400566 | C58: =C56+(C76-C56)*(A58-A56)/(A76-A56) -> 0.032942121 | D58: =D56+(D76-D56)*(A58-A56)/(A76-A56) -> 0.014020704 | E58: =B58*Parameters!$B$13+(1-B58) -> 0.98337651 | F58: =(B58*Parameters!$B$13+C58*Parameters!$B$14+Calculation!$B$11)/E58 -> 0.048411358 | G58: =D58/E58 -> 0.014257717 | H58: =1-F58-G58 -> 0.93733092
A59: 2006 | B59: =B56+(B76-B56)*(A59-A56)/(A76-A56) -> 0.038984758 | C59: =C56+(C76-C56)*(A59-A56)/(A76-A56) -> 0.033182302 | D59: =D56+(D76-D56)*(A59-A56)/(A76-A56) -> 0.014556492 | E59: =B59*Parameters!$B$13+(1-B59) -> 0.98382133 | F59: =(B59*Parameters!$B$13+C59*Parameters!$B$14+Calculation!$B$11)/E59 -> 0.047874197 | G59: =D59/E59 -> 0.014795869 | H59: =1-F59-G59 -> 0.93732993
A60: 2007 | B60: =B56+(B76-B56)*(A60-A56)/(A76-A56) -> 0.037912916 | C60: =C56+(C76-C56)*(A60-A56)/(A76-A56) -> 0.033422484 | D60: =D56+(D76-D56)*(A60-A56)/(A76-A56) -> 0.015092279 | E60: =B60*Parameters!$B$13+(1-B60) -> 0.98426614 | F60: =(B60*Parameters!$B$13+C60*Parameters!$B$14+Calculation!$B$11)/E60 -> 0.047337521 | G60: =D60/E60 -> 0.015333535 | H60: =1-F60-G60 -> 0.93732894
A61: 2008 | B61: =B56+(B76-B56)*(A61-A56)/(A76-A56) -> 0.036841074 | C61: =C56+(C76-C56)*(A61-A56)/(A76-A56) -> 0.033662666 | D61: =D56+(D76-D56)*(A61-A56)/(A76-A56) -> 0.015628067 | E61: =B61*Parameters!$B$13+(1-B61) -> 0.98471095 | F61: =(B61*Parameters!$B$13+C61*Parameters!$B$14+Calculation!$B$11)/E61 -> 0.04680133 | G61: =D61/E61 -> 0.015870715 | H61: =1-F61-G61 -> 0.93732796
A62: 2009 | B62: =B56+(B76-B56)*(A62-A56)/(A76-A56) -> 0.035769232 | C62: =C56+(C76-C56)*(A62-A56)/(A76-A56) -> 0.033902848 | D62: =D56+(D76-D56)*(A62-A56)/(A76-A56) -> 0.016163855 | E62: =B62*Parameters!$B$13+(1-B62) -> 0.98515577 | F62: =(B62*Parameters!$B$13+C62*Parameters!$B$14+Calculation!$B$11)/E62 -> 0.046265623 | G62: =D62/E62 -> 0.01640741 | H62: =1-F62-G62 -> 0.93732697
A63: 2010 | B63: =B56+(B76-B56)*(A63-A56)/(A76-A56) -> 0.03469739 | C63: =C56+(C76-C56)*(A63-A56)/(A76-A56) -> 0.034143029 | D63: =D56+(D76-D56)*(A63-A56)/(A76-A56) -> 0.016699643 | E63: =B63*Parameters!$B$13+(1-B63) -> 0.98560058 | F63: =(B63*Parameters!$B$13+C63*Parameters!$B$14+Calculation!$B$11)/E63 -> 0.0457304 | G63: =D63/E63 -> 0.016943621 | H63: =1-F63-G63 -> 0.93732598
A64: 2011 | B64: =B56+(B76-B56)*(A64-A56)/(A76-A56) -> 0.033625547 | C64: =C56+(C76-C56)*(A64-A56)/(A76-A56) -> 0.034383211 | D64: =D56+(D76-D56)*(A64-A56)/(A76-A56) -> 0.01723543 | E64: =B64*Parameters!$B$13+(1-B64) -> 0.9860454 | F64: =(B64*Parameters!$B$13+C64*Parameters!$B$14+Calculation!$B$11)/E64 -> 0.045195659 | G64: =D64/E64 -> 0.017479348 | H64: =1-F64-G64 -> 0.93732499
A65: 2012 | B65: =B56+(B76-B56)*(A65-A56)/(A76-A56) -> 0.032553705 | C65: =C56+(C76-C56)*(A65-A56)/(A76-A56) -> 0.034623393 | D65: =D56+(D76-D56)*(A65-A56)/(A76-A56) -> 0.017771218 | E65: =B65*Parameters!$B$13+(1-B65) -> 0.98649021 | F65: =(B65*Parameters!$B$13+C65*Parameters!$B$14+Calculation!$B$11)/E65 -> 0.044661401 | G65: =D65/E65 -> 0.018014592 | H65: =1-F65-G65 -> 0.93732401
A66: 2013 | B66: =B56+(B76-B56)*(A66-A56)/(A76-A56) -> 0.031481863 | C66: =C56+(C76-C56)*(A66-A56)/(A76-A56) -> 0.034863574 | D66: =D56+(D76-D56)*(A66-A56)/(A76-A56) -> 0.018307006 | E66: =B66*Parameters!$B$13+(1-B66) -> 0.98693503 | F66: =(B66*Parameters!$B$13+C66*Parameters!$B$14+Calculation!$B$11)/E66 -> 0.044127624 | G66: =D66/E66 -> 0.018549353 | H66: =1-F66-G66 -> 0.93732302
A67: 2014 | B67: =B56+(B76-B56)*(A67-A56)/(A76-A56) -> 0.030410021 | C67: =C56+(C76-C56)*(A67-A56)/(A76-A56) -> 0.035103756 | D67: =D56+(D76-D56)*(A67-A56)/(A76-A56) -> 0.018842794 | E67: =B67*Parameters!$B$13+(1-B67) -> 0.98737984 | F67: =(B67*Parameters!$B$13+C67*Parameters!$B$14+Calculation!$B$11)/E67 -> 0.043594329 | G67: =D67/E67 -> 0.019083632 | H67: =1-F67-G67 -> 0.93732204
A68: 2015 | B68: =B56+(B76-B56)*(A68-A56)/(A76-A56) -> 0.029338179 | C68: =C56+(C76-C56)*(A68-A56)/(A76-A56) -> 0.035343938 | D68: =D56+(D76-D56)*(A68-A56)/(A76-A56) -> 0.019378581 | E68: =B68*Parameters!$B$13+(1-B68) -> 0.98782466 | F68: =(B68*Parameters!$B$13+C68*Parameters!$B$14+Calculation!$B$11)/E68 -> 0.043061513 | G68: =D68/E68 -> 0.01961743 | H68: =1-F68-G68 -> 0.93732106
...

Sheet Checks
A1: CHECK: is carbonatable CO2 per ton of conventional clinker within 1% of the EPA calcination factor of 510,000 g/t? (1 = problem) | B1: =IF(ABS(Calculation!B2/510000-1)>0.01,1,0) -> 0
A2: CHECK: are the mortar shares between 0 and 0.3 in every year? (1 = problem) | B2: =IF(OR(MIN('Use Split'!F3:F103)<0,MAX('Use Split'!F3:F103)>0.3),1,0) -> 0
A3: CHECK: are the concrete shares between 0.5 and 1 in every year? (1 = problem) | B3: =IF(OR(MIN('Use Split'!H3:H103)<0.5,MAX('Use Split'!H3:H103)>1),1,0) -> 0
A4: CHECK: do in-service plus end-of-life shares stay at or below 1 for both uses? (1 = problem) | B4: =IF(OR(Parameters!B5+Calculation!B4>1,Parameters!B9+Parameters!B12>1),1,0) -> 0
A5: CHECK: does the 2023 portland total in table 14 match the sum of its customer columns within 2%? (1 = problem) | B5: =IF(ABS(SUM('USGS MYB 2023 T14'!C34,'USGS MYB 2023 T14'!E34,'USGS MYB 2023 T14'!G34,'USGS MYB 2023 T14'!I34,'USGS MYB 2023 T14'!K34,'USGS MYB 2023 T14'!M34)/'USGS MYB 2023 T14'!O34-1)>0.02,1,0) -> 0

Sheet CCUP-potential
A1: Unit: g CO2/metric ton clinker | B1: Carbonatable CO2 per Ton of Clinker
A2: dry kiln with precalciner | B2: =Calculation!$B$2 -> 510101.64
A3: dry kiln with CCS | B3: =Calculation!$B$2 -> 510101.64
A4: electric kiln | B4: =Calculation!$B$2 -> 510101.64
A5: electric kiln with CCS | B5: =Calculation!$B$2 -> 510101.64
A6: alternative chemistry cement | B6: 0

Sheet CCUP-use-share
A1: Unit: dimensionless | B1: 1950 | C1: 1951 | D1: 1952 | E1: 1953 | F1: 1954 | G1: 1955 | H1: 1956 | I1: 1957 | J1: 1958 | K1: 1959 | L1: 1960 | M1: 1961 | N1: 1962 | O1: 1963 | P1: 1964 | Q1: 1965 | R1: 1966 | S1: 1967 | T1: 1968 | U1: 1969 | V1: 1970 | W1: 1971 | X1: 1972 | Y1: 1973 | Z1: 1974 | AA1: 1975 | AB1: 1976 | AC1: 1977 | AD1: 1978 | AE1: 1979 | AF1: 1980 | AG1: 1981 | AH1: 1982 | AI1: 1983 | AJ1: 1984 | AK1: 1985 | AL1: 1986 | AM1: 1987 | AN1: 1988 | AO1: 1989 | AP1: 1990 | AQ1: 1991 | AR1: 1992 | AS1: 1993 | AT1: 1994 | AU1: 1995 | AV1: 1996 | AW1: 1997 | AX1: 1998 | AY1: 1999 | AZ1: 2000 | BA1: 2001 | BB1: 2002 | BC1: 2003 | BD1: 2004 | BE1: 2005 | BF1: 2006 | BG1: 2007 | BH1: 2008 | BI1: 2009 | BJ1: 2010 | BK1: 2011 | BL1: 2012 | BM1: 2013 | BN1: 2014 | BO1: 2015 | BP1: 2016 | BQ1: 2017 | BR1: 2018 | BS1: 2019 | BT1: 2020 | BU1: 2021 | BV1: 2022 | BW1: 2023 | BX1: 2024 | BY1: 2025 | BZ1: 2026 | CA1: 2027 | CB1: 2028 | CC1: 2029 | CD1: 2030 | CE1: 2031 | CF1: 2032 | CG1: 2033 | CH1: 2034 | CI1: 2035 | CJ1: 2036 | CK1: 2037 | CL1: 2038 | CM1: 2039 | CN1: 2040 | CO1: 2041 | CP1: 2042 | CQ1: 2043 | CR1: 2044 | CS1: 2045 | CT1: 2046 | CU1: 2047 | CV1: 2048 | CW1: 2049 | CX1: 2050
A2: concrete | B2: ='Use Split'!H3 -> 0.91139845 | C2: ='Use Split'!H4 -> 0.91139845 | D2: ='Use Split'!H5 -> 0.91139845 | E2: ='Use Split'!H6 -> 0.91139845 | F2: ='Use Split'!H7 -> 0.91139845 | G2: ='Use Split'!H8 -> 0.91139845 | H2: ='Use Split'!H9 -> 0.91139845 | I2: ='Use Split'!H10 -> 0.91139845 | J2: ='Use Split'!H11 -> 0.91139845 | K2: ='Use Split'!H12 -> 0.91139845 | L2: ='Use Split'!H13 -> 0.91139845 | M2: ='Use Split'!H14 -> 0.91139845 | N2: ='Use Split'!H15 -> 0.91139845 | O2: ='Use Split'!H16 -> 0.91139845 | P2: ='Use Split'!H17 -> 0.91139845 | Q2: ='Use Split'!H18 -> 0.91139845 | R2: ='Use Split'!H19 -> 0.91139845 | S2: ='Use Split'!H20 -> 0.91139845 | T2: ='Use Split'!H21 -> 0.91139845 | U2: ='Use Split'!H22 -> 0.91139845 | V2: ='Use Split'!H23 -> 0.91139845 | W2: ='Use Split'!H24 -> 0.91139845 | X2: ='Use Split'!H25 -> 0.91139845 | Y2: ='Use Split'!H26 -> 0.91139845 | Z2: ='Use Split'!H27 -> 0.91139845 | AA2: ='Use Split'!H28 -> 0.91139845 | AB2: ='Use Split'!H29 -> 0.91426685 | AC2: ='Use Split'!H30 -> 0.91091287 | AD2: ='Use Split'!H31 -> 0.91020727 | AE2: ='Use Split'!H32 -> 0.90836171 | AF2: ='Use Split'!H33 -> 0.91862203 | AG2: ='Use Split'!H34 -> 0.91925559 | AH2: ='Use Split'!H35 -> 0.9197521 | AI2: ='Use Split'!H36 -> 0.91981537 | AJ2: ='Use Split'!H37 -> 0.92214525 | AK2: ='Use Split'!H38 -> 0.9259487 | AL2: ='Use Split'!H39 -> 0.92519154 | AM2: ='Use Split'!H40 -> 0.92796019 | AN2: ='Use Split'!H41 -> 0.92415682 | AO2: ='Use Split'!H42 -> 0.92470798 | AP2: ='Use Split'!H43 -> 0.9158557 | AQ2: ='Use Split'!H44 -> 0.89833743 | AR2: ='Use Split'!H45 -> 0.90366149 | AS2: ='Use Split'!H46 -> 0.92627025 | AT2: ='Use Split'!H47 -> 0.9342511 | AU2: ='Use Split'!H48 -> 0.93744985 | AV2: ='Use Split'!H49 -> 0.93794553 | AW2: ='Use Split'!H50 -> 0.92838254 | AX2: ='Use Split'!H51 -> 0.9416112 | AY2: ='Use Split'!H52 -> 0.93681486 | AZ2: ='Use Split'!H53 -> 0.93800908 | BA2: ='Use Split'!H54 -> 0.93450819 | BB2: ='Use Split'!H55 -> 0.94225835 | BC2: ='Use Split'!H56 -> 0.93733291 | BD2: ='Use Split'!H57 -> 0.93733192 | BE2: ='Use Split'!H58 -> 0.93733092 | BF2: ='Use Split'!H59 -> 0.93732993 | BG2: ='Use Split'!H60 -> 0.93732894 | BH2: ='Use Split'!H61 -> 0.93732796 | BI2: ='Use Split'!H62 -> 0.93732697 | BJ2: ='Use Split'!H63 -> 0.93732598 | BK2: ='Use Split'!H64 -> 0.93732499 | BL2: ='Use Split'!H65 -> 0.93732401 | BM2: ='Use Split'!H66 -> 0.93732302 | BN2: ='Use Split'!H67 -> 0.93732204 | BO2: ='Use Split'!H68 -> 0.93732106 | BP2: ='Use Split'!H69 -> 0.93732007 | BQ2: ='Use Split'!H70 -> 0.93731909 | BR2: ='Use Split'!H71 -> 0.93731811 | BS2: ='Use Split'!H72 -> 0.93731713 | BT2: ='Use Split'!H73 -> 0.93731616 | BU2: ='Use Split'!H74 -> 0.93731518 | BV2: ='Use Split'!H75 -> 0.9373142 | BW2: ='Use Split'!H76 -> 0.93731323 | BX2: ='Use Split'!H77 -> 0.93731323 | BY2: ='Use Split'!H78 -> 0.93731323 | BZ2: ='Use Split'!H79 -> 0.93731323 | CA2: ='Use Split'!H80 -> 0.93731323 | CB2: ='Use Split'!H81 -> 0.93731323 | CC2: ='Use Split'!H82 -> 0.93731323 | CD2: ='Use Split'!H83 -> 0.93731323 | CE2: ='Use Split'!H84 -> 0.93731323 | CF2: ='Use Split'!H85 -> 0.93731323 | CG2: ='Use Split'!H86 -> 0.93731323 | CH2: ='Use Split'!H87 -> 0.93731323 | CI2: ='Use Split'!H88 -> 0.93731323 | CJ2: ='Use Split'!H89 -> 0.93731323 | CK2: ='Use Split'!H90 -> 0.93731323 | CL2: ='Use Split'!H91 -> 0.93731323 | CM2: ='Use Split'!H92 -> 0.93731323 | CN2: ='Use Split'!H93 -> 0.93731323 | CO2: ='Use Split'!H94 -> 0.93731323 | CP2: ='Use Split'!H95 -> 0.93731323 | CQ2: ='Use Split'!H96 -> 0.93731323 | CR2: ='Use Split'!H97 -> 0.93731323 | CS2: ='Use Split'!H98 -> 0.93731323 | CT2: ='Use Split'!H99 -> 0.93731323 | CU2: ='Use Split'!H100 -> 0.93731323 | CV2: ='Use Split'!H101 -> 0.93731323 | CW2: ='Use Split'!H102 -> 0.93731323 | CX2: ='Use Split'!H103 -> 0.93731323
A3: mortar | B3: ='Use Split'!F3 -> 0.068226191 | C3: ='Use Split'!F4 -> 0.068226191 | D3: ='Use Split'!F5 -> 0.068226191 | E3: ='Use Split'!F6 -> 0.068226191 | F3: ='Use Split'!F7 -> 0.068226191 | G3: ='Use Split'!F8 -> 0.068226191 | H3: ='Use Split'!F9 -> 0.068226191 | I3: ='Use Split'!F10 -> 0.068226191 | J3: ='Use Split'!F11 -> 0.068226191 | K3: ='Use Split'!F12 -> 0.068226191 | L3: ='Use Split'!F13 -> 0.068226191 | M3: ='Use Split'!F14 -> 0.068226191 | N3: ='Use Split'!F15 -> 0.068226191 | O3: ='Use Split'!F16 -> 0.068226191 | P3: ='Use Split'!F17 -> 0.068226191 | Q3: ='Use Split'!F18 -> 0.068226191 | R3: ='Use Split'!F19 -> 0.068226191 | S3: ='Use Split'!F20 -> 0.068226191 | T3: ='Use Split'!F21 -> 0.068226191 | U3: ='Use Split'!F22 -> 0.068226191 | V3: ='Use Split'!F23 -> 0.068226191 | W3: ='Use Split'!F24 -> 0.068226191 | X3: ='Use Split'!F25 -> 0.068226191 | Y3: ='Use Split'!F26 -> 0.068226191 | Z3: ='Use Split'!F27 -> 0.068226191 | AA3: ='Use Split'!F28 -> 0.068226191 | AB3: ='Use Split'!F29 -> 0.068171118 | AC3: ='Use Split'!F30 -> 0.069471466 | AD3: ='Use Split'!F31 -> 0.071144707 | AE3: ='Use Split'!F32 -> 0.073746214 | AF3: ='Use Split'!F33 -> 0.06356287 | AG3: ='Use Split'!F34 -> 0.056941656 | AH3: ='Use Split'!F35 -> 0.057547293 | AI3: ='Use Split'!F36 -> 0.060927509 | AJ3: ='Use Split'!F37 -> 0.058672481 | AK3: ='Use Split'!F38 -> 0.056875057 | AL3: ='Use Split'!F39 -> 0.055188395 | AM3: ='Use Split'!F40 -> 0.053803285 | AN3: ='Use Split'!F41 -> 0.050301575 | AO3: ='Use Split'!F42 -> 0.050385588 | AP3: ='Use Split'!F43 -> 0.050840856 | AQ3: ='Use Split'!F44 -> 0.049899386 | AR3: ='Use Split'!F45 -> 0.052607032 | AS3: ='Use Split'!F46 -> 0.059748571 | AT3: ='Use Split'!F47 -> 0.05354207 | AU3: ='Use Split'!F48 -> 0.050033602 | AV3: ='Use Split'!F49 -> 0.047522713 | AW3: ='Use Split'!F50 -> 0.047211746 | AX3: ='Use Split'!F51 -> 0.047344138 | AY3: ='Use Split'!F52 -> 0.052617747 | AZ3: ='Use Split'!F53 -> 0.048436539 | BA3: ='Use Split'!F54 -> 0.048240163 | BB3: ='Use Split'!F55 -> 0.046680561 | BC3: ='Use Split'!F56 -> 0.04948714 | BD3: ='Use Split'!F57 -> 0.048949006 | BE3: ='Use Split'!F58 -> 0.048411358 | BF3: ='Use Split'!F59 -> 0.047874197 | BG3: ='Use Split'!F60 -> 0.047337521 | BH3: ='Use Split'!F61 -> 0.04680133 | BI3: ='Use Split'!F62 -> 0.046265623 | BJ3: ='Use Split'!F63 -> 0.0457304 | BK3: ='Use Split'!F64 -> 0.045195659 | BL3: ='Use Split'!F65 -> 0.044661401 | BM3: ='Use Split'!F66 -> 0.044127624 | BN3: ='Use Split'!F67 -> 0.043594329 | BO3: ='Use Split'!F68 -> 0.043061513 | BP3: ='Use Split'!F69 -> 0.042529177 | BQ3: ='Use Split'!F70 -> 0.041997321 | BR3: ='Use Split'!F71 -> 0.041465942 | BS3: ='Use Split'!F72 -> 0.040935041 | BT3: ='Use Split'!F73 -> 0.040404618 | BU3: ='Use Split'!F74 -> 0.03987467 | BV3: ='Use Split'!F75 -> 0.039345199 | BW3: ='Use Split'!F76 -> 0.038816203 | BX3: ='Use Split'!F77 -> 0.038816203 | BY3: ='Use Split'!F78 -> 0.038816203 | BZ3: ='Use Split'!F79 -> 0.038816203 | CA3: ='Use Split'!F80 -> 0.038816203 | CB3: ='Use Split'!F81 -> 0.038816203 | CC3: ='Use Split'!F82 -> 0.038816203 | CD3: ='Use Split'!F83 -> 0.038816203 | CE3: ='Use Split'!F84 -> 0.038816203 | CF3: ='Use Split'!F85 -> 0.038816203 | CG3: ='Use Split'!F86 -> 0.038816203 | CH3: ='Use Split'!F87 -> 0.038816203 | CI3: ='Use Split'!F88 -> 0.038816203 | CJ3: ='Use Split'!F89 -> 0.038816203 | CK3: ='Use Split'!F90 -> 0.038816203 | CL3: ='Use Split'!F91 -> 0.038816203 | CM3: ='Use Split'!F92 -> 0.038816203 | CN3: ='Use Split'!F93 -> 0.038816203 | CO3: ='Use Split'!F94 -> 0.038816203 | CP3: ='Use Split'!F95 -> 0.038816203 | CQ3: ='Use Split'!F96 -> 0.038816203 | CR3: ='Use Split'!F97 -> 0.038816203 | CS3: ='Use Split'!F98 -> 0.038816203 | CT3: ='Use Split'!F99 -> 0.038816203 | CU3: ='Use Split'!F100 -> 0.038816203 | CV3: ='Use Split'!F101 -> 0.038816203 | CW3: ='Use Split'!F102 -> 0.038816203 | CX3: ='Use Split'!F103 -> 0.038816203

Sheet CCUP-inservice-share
A1: Unit: dimensionless | B1: CCUP-inservice-share
A2: concrete | B2: =Parameters!B5 -> 0.161
A3: mortar | B3: =Parameters!B9 -> 0.75

Sheet CCUP-inservice-time
A1: Unit: years | B1: CCUP-inservice-time
A2: concrete | B2: =Parameters!B6 -> 65
A3: mortar | B3: =Calculation!B3 -> 1.0412328

Sheet CCUP-eol-share
A1: Unit: dimensionless | B1: CCUP-eol-share
A2: concrete | B2: =Calculation!B4 -> 0.015
A3: mortar | B3: =Parameters!B12 -> 0
