Workbook

Sheet About
A1: GaHEbIC Government and Household Expenditures by ISIC Code (42-code)
A3: Sources: | B3: Government (GGFC) and household (HFCE) final consumption by industry, 2022
B4: OECD
B5: OECD Input-Output Tables (latest edition), total table
B6: 2024
B7: https://www.oecd.org/en/data/datasets/input-output-tables.html
B8: Tab OECD_TTL, verbatim. Government = GGFC column; household = HFCE column. 42-code output: the six OECD-native splits are summed back to their parent (01T03/07T08/30/49T53/69T82/90T96); the C23 and D carves stay split.
B10: Carve-child shares (231/239, 351/352T353)
B11: U.S. Bureau of Economic Analysis
B12: 2017 benchmark Use table: government final-demand columns (F06*/F07*/F10*) and PCE (F01000)
B13: 2023
B14: https://www.bea.gov/industry/input-output-accounts-data
B15: Tab 'BEA Use 2017', verbatim with crosswalk helpers. Carve children retained as their own 42 codes (not collapsed).
A18: Notes:
A19: Currency | B19: 2022 USD -> 2012 USD conversion factor below (editable): CPI-U annual averages 2012/2022 from InputData/cpi.xlsx (229.594/292.655) — the model-canonical currency converter, matching every stock factor.
A20: 0.78452102 | B20: 2012 USD per 2022 USD
A22: Collapse | B22: 42-code = 52-code with six OECD-native parents un-split. GaHEbIC is a level ($), so each 42 column is the exact sum of its 52 children (no re-weighting). Conservation of gov + hh totals vs the 52 build is verified in build_gahebic_42 (and the per-carve reaggregation on the Checks tab).

Sheet OECD_TTL
B1: A01 | C1: A02 | D1: A03 | E1: B05 | F1: B06 | G1: B07 | H1: B08 | I1: B09 | J1: C10T12 | K1: C13T15 | L1: C16 | M1: C17_18 | N1: C19 | O1: C20 | P1: C21 | Q1: C22 | R1: C23 | S1: C24A | T1: C24B | U1: C25 | V1: C26 | W1: C27 | X1: C28 | Y1: C29 | Z1: C301 | AA1: C302T309 | AB1: C31T33 | AC1: D | AD1: E | AE1: F | AF1: G | AG1: H49 | AH1: H50 | AI1: H51 | AJ1: H52 | AK1: H53 | AL1: I | AM1: J58T60 | AN1: J61 | AO1: J62_63 | AP1: K | AQ1: L | AR1: M | AS1: N | AT1: O | AU1: P | AV1: Q | AW1: R | AX1: S | AY1: T | AZ1: HFCE | BA1: NPISH | BB1: GGFC | BC1: GFCF | BD1: INVNT | BE1: DPABR | BF1: CONS_NONRES | BG1: EXPO | BH1: IMPO | BI1: TOTAL
A2: TTL_A01 | B2: 74779.371 | C2: 729.474 | D2: 48.606 | E2: 3.371 | F2: 32.701 | G2: 1.71 | H2: 8.438 | I2: 2.685 | J2: 244020.02 | K2: 1261.74 | L2: 765.633 | M2: 104.3 | N2: 10.732 | O2: 986.888 | P2: 750.978 | Q2: 567.622 | R2: 9.34 | S2: 2.31 | T2: 2.514 | U2: 8.955 | V2: 8.138 | W2: 3.681 | X2: 35.538 | Y2: 33.355 | Z2: 1.405 | AA2: 8.152 | AB2: 179.08 | AC2: 162.945 | AD2: 55.649 | AE2: 689.944 | AF2: 9434.576 | AG2: 113.147 | AH2: 14.435 | AI2: 4.136 | AJ2: 65.436 | AK2: 7.285 | AL2: 52185.807 | AM2: 78.16 | AN2: 19.382 | AO2: 17.162 | AP2: 74.636 | AQ2: 395.058 | AR2: 1051.573 | AS2: 1513.491 | AT2: 2681.544 | AU2: 1303.299 | AV2: 5182.226 | AW2: 586.576 | AX2: 834.92 | AY2: 0 | AZ2: 212576.91 | BA2: 517.39 | BB2: 0.473 | BC2: 98.44 | BD2: 208.618 | BE2: 1567.22 | BF2: 426.017 | BG2: 65992.048 | BH2: -51305.832 | BI2: 630919.41
A3: TTL_A02 | B3: 653.615 | C3: 2244.103 | D3: 0.905 | E3: 10.943 | F3: 19.423 | G3: 1.665 | H3: 2.56 | I3: 0.076 | J3: 767.453 | K3: 12.704 | L3: 7209.622 | M3: 661.867 | N3: 0.791 | O3: 47.507 | P3: 8.773 | Q3: 242.507 | R3: 11.813 | S3: 2.523 | T3: 2.073 | U3: 2.45 | V3: 0.286 | W3: 0.444 | X3: 2.963 | Y3: 2.663 | Z3: 0.552 | AA3: 0.803 | AB3: 297.692 | AC3: 208.093 | AD3: 1.209 | AE3: 209.583 | AF3: 448.729 | AG3: 3.267 | AH3: 0.483 | AI3: 0.252 | AJ3: 2.069 | AK3: 0.42 | AL3: 336.258 | AM3: 7.112 | AN3: 4.012 | AO3: 5.372 | AP3: 3.447 | AQ3: 42.151 | AR3: 14.444 | AS3: 25.652 | AT3: 245.703 | AU3: 49.752 | AV3: 66.658 | AW3: 37.577 | AX3: 34.3 | AY3: 0 | AZ3: 14849.907 | BA3: 150.645 | BB3: 0.067 | BC3: 48.963 | BD3: 5.547 | BE3: 22.263 | BF3: 0.025 | BG3: 1290.846 | BH3: -3873.05 | BI3: 26450.533
A4: TTL_A03 | B4: 23.876 | C4: 1.913 | D4: 92.259 | E4: 0.145 | F4: 1.362 | G4: 0.209 | H4: 0.239 | I4: 0.021 | J4: 8300.546 | K4: 0.37 | L4: 0.309 | M4: 0.459 | N4: 0.978 | O4: 2.989 | P4: 1.752 | Q4: 0.705 | R4: 0.382 | S4: 0.226 | T4: 0.215 | U4: 0.647 | V4: 0.218 | W4: 0.202 | X4: 0.632 | Y4: 0.465 | Z4: 0.271 | AA4: 0.236 | AB4: 0.524 | AC4: 0.461 | AD4: 0.274 | AE4: 2.689 | AF4: 179.46 | AG4: 2.043 | AH4: 4.171 | AI4: 0.243 | AJ4: 2.951 | AK4: 0.091 | AL4: 3857.341 | AM4: 3.326 | AN4: 0.933 | AO4: 2.532 | AP4: 5.635 | AQ4: 15.058 | AR4: 6.209 | AS4: 3.42 | AT4: 171.368 | AU4: 26.86 | AV4: 122.228 | AW4: 6.878 | AX4: 13.061 | AY4: 0 | AZ4: 6908.574 | BA4: 42.877 | BB4: 0.008 | BC4: 4.275 | BD4: 7.225 | BE4: 96.871 | BF4: 10.609 | BG4: 2385.951 | BH4: -15796.516 | BI4: 6519.255
A5: TTL_B05 | B5: 51.576 | C5: 2.362 | D5: 0.152 | E5: 418.917 | F5: 479.784 | G5: 40.782 | H5: 40.222 | I5: 38.481 | J5: 138.844 | K5: 11.553 | L5: 8.132 | M5: 95.255 | N5: 2046.457 | O5: 293.826 | P5: 6.161 | Q5: 31.046 | R5: 466.826 | S5: 1924.388 | T5: 306.992 | U5: 10.866 | V5: 2.089 | W5: 5.181 | X5: 14.052 | Y5: 16.93 | Z5: 1.96 | AA5: 12.526 | AB5: 6.004 | AC5: 12957.678 | AD5: 10.056 | AE5: 717.799 | AF5: 130.599 | AG5: 31.915 | AH5: 0.514 | AI5: 1.316 | AJ5: 17.128 | AK5: 1.676 | AL5: 47.221 | AM5: 5.173 | AN5: 15.351 | AO5: 4.489 | AP5: 21.679 | AQ5: 490.661 | AR5: 48.845 | AS5: 22.127 | AT5: 405.155 | AU5: 128.508 | AV5: 83.48 | AW5: 6.388 | AX5: 50.899 | AY5: 0 | AZ5: 18.116 | BA5: 0.709 | BB5: 0.033 | BC5: 5851.996 | BD5: 0.34 | BE5: 3.809 | BF5: 0.01 | BG5: 13417.78 | BH5: -461.32 | BI5: 40501.495
A6: TTL_B06 | B6: 1337.669 | C6: 80.35 | D6: 34.976 | E6: 608.574 | F6: 44951.12 | G6: 457.205 | H6: 800.07 | I6: 833.579 | J6: 2743.208 | K6: 118.636 | L6: 278.17 | M6: 1531.424 | N6: 460643.68 | O6: 13736.478 | P6: 199.208 | Q6: 773.971 | R6: 3251.794 | S6: 3524.119 | T6: 2182.671 | U6: 1054.101 | V6: 75.213 | W6: 125.611 | X6: 371.039 | Y6: 864.442 | Z6: 31.587 | AA6: 242.473 | AB6: 376.688 | AC6: 97219.223 | AD6: 479.417 | AE6: 3239.622 | AF6: 9710.059 | AG6: 7263.486 | AH6: 701.687 | AI6: 2661 | AJ6: 1246.527 | AK6: 305.473 | AL6: 1202.682 | AM6: 303.544 | AN6: 266.148 | AO6: 375.681 | AP6: 1055.687 | AQ6: 2669.84 | AR6: 2106.796 | AS6: 1946.822 | AT6: 6811.557 | AU6: 1427.372 | AV6: 1911.932 | AW6: 254.969 | AX6: 600.477 | AY6: 0 | AZ6: 15958.877 | BA6: 3.662 | BB6: 0.413 | BC6: 23691.18 | BD6: 10.843 | BE6: 29.63 | BF6: 115.74 | BG6: 177625.12 | BH6: -188381.39 | BI6: 714042.13
A7: TTL_B07 | B7: 21.136 | C7: 0.533 | D7: 0.107 | E7: 46.165 | F7: 391.474 | G7: 873.276 | H7: 175.266 | I7: 58.339 | J7: 87.68 | K7: 4.093 | L7: 3.291 | M7: 8.037 | N7: 445.071 | O7: 517.92 | P7: 11.419 | Q7: 21.192 | R7: 691.063 | S7: 8228.601 | T7: 11291.735 | U7: 586.573 | V7: 34.599 | W7: 72.131 | X7: 130.605 | Y7: 156.905 | Z7: 3.453 | AA7: 35.249 | AB7: 67.326 | AC7: 303.59 | AD7: 21.124 | AE7: 1234.964 | AF7: 91.334 | AG7: 17.811 | AH7: 0.485 | AI7: 1.429 | AJ7: 9.101 | AK7: 1.014 | AL7: 31.867 | AM7: 6.111 | AN7: 8.343 | AO7: 9.828 | AP7: 21.693 | AQ7: 190.596 | AR7: 66.025 | AS7: 30.671 | AT7: 105.289 | AU7: 21.494 | AV7: 30.898 | AW7: 5.304 | AX7: 21.159 | AY7: 0 | AZ7: 18.255 | BA7: 0.442 | BB7: 0.149 | BC7: 2085.398 | BD7: 0.909 | BE7: 12.043 | BF7: 0.007 | BG7: 9919.664 | BH7: -3762.406 | BI7: 34467.828
A8: TTL_B08 | B8: 657.848 | C8: 11.285 | D8: 3.064 | E8: 78.103 | F8: 1284.831 | G8: 160.48 | H8: 1619.92 | I8: 145.081 | J8: 641.961 | K8: 43.046 | L8: 26.572 | M8: 262.977 | N8: 957.263 | O8: 2588.614 | P8: 100.173 | Q8: 341.829 | R8: 10621.362 | S8: 1700.216 | T8: 655.116 | U8: 196.936 | V8: 29.023 | W8: 47.668 | X8: 90.372 | Y8: 114.291 | Z8: 5.087 | AA8: 21.409 | AB8: 174.778 | AC8: 779.713 | AD8: 133.34 | AE8: 20343.021 | AF8: 315.39 | AG8: 58.431 | AH8: 4.151 | AI8: 2.464 | AJ8: 33.276 | AK8: 2.734 | AL8: 155.171 | AM8: 23.325 | AN8: 19.451 | AO8: 9.824 | AP8: 30.602 | AQ8: 1663.727 | AR8: 163.819 | AS8: 492.267 | AT8: 1005.297 | AU8: 99.175 | AV8: 215.879 | AW8: 21.187 | AX8: 74.717 | AY8: 0 | AZ8: 835.751 | BA8: 1.271 | BB8: 0.087 | BC8: 7637.615 | BD8: 3.524 | BE8: 11.454 | BF8: 1.317 | BG8: 2273.556 | BH8: -6083.596 | BI8: 52907.245
A9: TTL_B09 | B9: 55.882 | C9: 3.645 | D9: 2.903 | E9: 134.428 | F9: 12123.063 | G9: 123.964 | H9: 308.364 | I9: 687.272 | J9: 69.293 | K9: 2.968 | L9: 10.614 | M9: 36.926 | N9: 877.196 | O9: 46.042 | P9: 7.316 | Q9: 25.535 | R9: 197.437 | S9: 66.588 | T9: 43.763 | U9: 120.43 | V9: 12.298 | W9: 12.56 | X9: 81.173 | Y9: 95.852 | Z9: 5.505 | AA9: 27.148 | AB9: 26.296 | AC9: 371.083 | AD9: 19.824 | AE9: 1911.021 | AF9: 234.337 | AG9: 54.741 | AH9: 3.407 | AI9: 7.854 | AJ9: 40.489 | AK9: 7.239 | AL9: 69.438 | AM9: 22.666 | AN9: 40.65 | AO9: 15.644 | AP9: 64.399 | AQ9: 1231.444 | AR9: 156.057 | AS9: 63.82 | AT9: 650.562 | AU9: 115.548 | AV9: 146.814 | AW9: 16.077 | AX9: 28.731 | AY9: 0 | AZ9: 316.966 | BA9: 2.393 | BB9: 0.239 | BC9: 44724.572 | BD9: 9.369 | BE9: 6.612 | BF9: 0.716 | BG9: 1828.476 | BH9: -3726.442 | BI9: 63639.207
A10: TTL_C10T12 | B10: 23749.497 | C10: 21.377 | D10: 104.292 | E10: 7.941 | F10: 139.048 | G10: 10.165 | H10: 19.262 | I10: 6.929 | J10: 73351.166 | K10: 164.633 | L10: 68.485 | M10: 327.96 | N10: 160.633 | O10: 1908.486 | P10: 838.38 | Q10: 376.828 | R10: 78.062 | S10: 47.314 | T10: 38.913 | U10: 121.907 | V10: 67.323 | W10: 40.203 | X10: 128.333 | Y10: 179.42 | Z10: 9.776 | AA10: 68.081 | AB10: 169.901 | AC10: 71.939 | AD10: 77.559 | AE10: 463.247 | AF10: 8331.551 | AG10: 193.764 | AH10: 66.607 | AI10: 46.558 | AJ10: 132.102 | AK10: 32.534 | AL10: 96328.35 | AM10: 554.378 | AN10: 183.999 | AO10: 288.438 | AP10: 469.104 | AQ10: 1077.84 | AR10: 824.711 | AS10: 790.394 | AT10: 3978.887 | AU10: 3191.159 | AV10: 7598.644 | AW10: 1038.856 | AX10: 854.465 | AY10: 0 | AZ10: 968789.27 | BA10: 984.672 | BB10: 3.673 | BC10: 1049.887 | BD10: 448.556 | BE10: 4784.054 | BF10: 2628.502 | BG10: 63542.457 | BH10: -145888.8 | BI10: 1125141.7
A11: TTL_C13T15 | B11: 423.683 | C11: 12.743 | D11: 13.901 | E11: 12.378 | F11: 188.667 | G11: 19.021 | H11: 15.732 | I11: 8.359 | J11: 397.391 | K11: 7337.367 | L11: 106.907 | M11: 763.498 | N11: 93.229 | O11: 981.663 | P11: 201.119 | Q11: 1050.294 | R11: 196.72 | S11: 47.963 | T11: 30.208 | U11: 189.439 | V11: 83.141 | W11: 57.98 | X11: 199.721 | Y11: 1639.653 | Z11: 32.226 | AA11: 159.676 | AB11: 1657.128 | AC11: 45.135 | AD11: 62.756 | AE11: 847.621 | AF11: 2868.688 | AG11: 93.392 | AH11: 7.01 | AI11: 18.703 | AJ11: 66.775 | AK11: 36.353 | AL11: 1408.628 | AM11: 161.295 | AN11: 54.848 | AO11: 74.25 | AP11: 156.54 | AQ11: 447.165 | AR11: 727.695 | AS11: 997.591 | AT11: 2368.708 | AU11: 576.602 | AV11: 2824.933 | AW11: 416.885 | AX11: 956.039 | AY11: 0 | AZ11: 187948.66 | BA11: 55.915 | BB11: 2.504 | BC11: 4284.175 | BD11: 591.696 | BE11: 1847.983 | BF11: 370.502 | BG11: 14412.892 | BH11: -168328.41 | BI11: 72323.338
A12: TTL_C16 | B12: 1370.992 | C12: 250.222 | D12: 6.42 | E12: 80.038 | F12: 413.417 | G12: 59.921 | H12: 65.011 | I12: 21.885 | J12: 2620.526 | K12: 158.071 | L12: 35331.09 | M12: 4414.547 | N12: 52.925 | O12: 1134.51 | P12: 180.322 | Q12: 786.795 | R12: 1204.839 | S12: 124.72 | T12: 167.017 | U12: 1237.41 | V12: 204.245 | W12: 288.456 | X12: 728.74 | Y12: 2710.93 | Z12: 307.637 | AA12: 400.221 | AB12: 16380.022 | AC12: 545.32 | AD12: 131.397 | AE12: 56706.308 | AF12: 7515.633 | AG12: 455.581 | AH12: 13.071 | AI12: 30.557 | AJ12: 705.158 | AK12: 22.385 | AL12: 2462.48 | AM12: 553.071 | AN12: 147.408 | AO12: 165.695 | AP12: 336.02 | AQ12: 7227.976 | AR12: 2783.534 | AS12: 1946.892 | AT12: 1349.059 | AU12: 1106.632 | AV12: 2128.705 | AW12: 417.824 | AX12: 2058.027 | AY12: 0 | AZ12: 13170.585 | BA12: 1.262 | BB12: 13.303 | BC12: 23976.196 | BD12: 2004.728 | BE12: 185.783 | BF12: 138.729 | BG12: 6137.611 | BH12: -32413.007 | BI12: 172724.85
A13: TTL_C17_18 | B13: 859.992 | C13: 19.611 | D13: 9.324 | E13: 16.102 | F13: 541.076 | G13: 43.629 | H13: 32.552 | I13: 19.372 | J13: 15327.946 | K13: 562.347 | L13: 773.943 | M13: 51164.289 | N13: 178.812 | O13: 1875.671 | P13: 2136.615 | Q13: 1634.007 | R13: 1226.791 | S13: 164.819 | T13: 175.347 | U13: 1127.231 | V13: 562.906 | W13: 430.81 | X13: 1086.086 | Y13: 1628.998 | Z13: 39.775 | AA13: 395.315 | AB13: 1772.799 | AC13: 338.533 | AD13: 261.248 | AE13: 2434.654 | AF13: 21436.154 | AG13: 736.798 | AH13: 64.025 | AI13: 95.047 | AJ13: 637.625 | AK13: 617.288 | AL13: 4624.998 | AM13: 26113.503 | AN13: 1820.503 | AO13: 4495.782 | AP13: 10753.952 | AQ13: 3422.122 | AR13: 12625.146 | AS13: 10049.4 | AT13: 19370.123 | AU13: 12128.673 | AV13: 11480.726 | AW13: 1600.043 | AX13: 3824.653 | AY13: 0 | AZ13: 62578.522 | BA13: 6.275 | BB13: 9.314 | BC13: 1503.291 | BD13: 122.618 | BE13: 609.33 | BF13: 542.306 | BG13: 25795.812 | BH13: -32256.014 | BI13: 291648.62
... A60: OUTPUT | B60: 630919.34 | C60: 26450.53 | D60: 6519.255 | E60: 40501.495 | F60: 714042.12 | G60: 34467.829 | H60: 52907.241 | I60: 63639.201 | J60: 1125141.5 | K60: 72323.331 | L60: 172724.83 | M60: 291648.59 | N60: 881098.57 | O60: 637748.79 | P60: 360489.35 | Q60: 303657.86 | R60: 190055.6 | S60: 198465.51 | T60: 161745.51 | U60: 453544.3 | V60: 489552.04 | W60: 156843.22 | X60: 446815.25 | Y60: 733534.89 | Z60: 48269.629 | AA60: 305724.2 | AB60: 309942.68 | AC60: 688239.61 | AD60: 154252.56 | AE60: 2164368 | AF60: 4883363.6 | AG60: 807593.73 | AH60: 66024.925 | AI60: 252594.38 | AJ60: 428397.57 | AK60: 206299.23 | AL60: 1397055.9 | AM60: 957179.2 | AN60: 674242.33 | AO60: 1337497.2 | AP60: 3528094 | AQ60: 4501781.2 | AR60: 3258688.3 | AS60: 1849347.7 | AT60: 3428364.4 | AU60: 1717572.2 | AV60: 3028529.7 | AW60: 430560.73 | AX60: 605611.37 | AY60: 25206.277 | AZ60: 0 | BA60: 0 | BB60: 0 | BC60: 0 | BD60: 0 | BE60: 0 | BF60: 0 | BG60: 0 | BH60: 0 | BI60: 45299637

Sheet BEA Use 2017
A1: The Use Table (Supply-Use Framework), 2017
A2: [Millions of dollars]
A3: Bureau of Economic Analysis
A5: Commodities/Industries | C5: Oilseed farming | D5: Grain farming | E5: Vegetable and melon farming | F5: Fruit and tree nut farming | G5: Greenhouse, nursery, and floriculture production | H5: Other crop farming | I5: Dairy cattle and milk production | J5: Beef cattle ranching and farming, including feedlots and dual-purpose ranching and farming | K5: Poultry and egg production | L5: Animal production, except cattle and poultry and eggs | M5: Forestry and logging | N5: Fishing, hunting and trapping | O5: Support activities for agriculture and forestry | P5: Oil and gas extraction | Q5: Coal mining | R5: Copper, nickel, lead, and zinc mining | S5: Iron, gold, silver, and other metal ore mining | T5: Stone mining and quarrying | U5: Other nonmetallic mineral mining and quarrying | V5: Drilling oil and gas wells | W5: Other support activities for mining | X5: Electric power generation, transmission, and distribution | Y5: Natural gas distribution | Z5: Water, sewage and other systems | AA5: Health care structures | AB5: Educational and vocational structures | AC5: Nonresidential maintenance and repair | AD5: Residential maintenance and repair | AE5: Office and commercial structures | AF5: Multifamily residential structures | AG5: Other residential structures | AH5: Manufacturing structures | AI5: Other nonresidential structures | AJ5: Power and communication structures | AK5: Single-family residential structures | AL5: Transportation structures and highways and streets | AM5: Sawmills and wood preservation | AN5: Veneer, plywood, and engineered wood product manufacturing | AO5: Millwork | AP5: All other wood product manufacturing | AQ5: Clay product and refractory manufacturing | AR5: Glass and glass product manufacturing | AS5: Cement manufacturing | AT5: Ready-mix concrete manufacturing | AU5: Concrete pipe, brick, and block manufacturing | AV5: Other concrete product manufacturing | AW5: Lime and gypsum product manufacturing | AX5: Abrasive product manufacturing | AY5: Cut stone and stone product manufacturing | AZ5: Ground or treated mineral and earth manufacturing | BA5: Mineral wool manufacturing | BB5: Miscellaneous nonmetallic mineral products | BC5: Iron and steel mills and ferroalloy manufacturing | BD5: Steel product manufacturing from purchased steel | BE5: Secondary smelting and alloying of aluminum | BF5: Alumina refining and primary aluminum production | BG5: Aluminum product manufacturing from purchased aluminum | BH5: Nonferrous metal (except aluminum) smelting and refining | BI5: Copper rolling, drawing, extruding and alloying | BJ5: Nonferrous metal (except copper and aluminum) rolling, drawing, extruding and alloying | BK5: Ferrous metal foundries | BL5: Nonferrous metal foundries | BM5: Custom roll forming | BN5: All other forging, stamping, and sintering | BO5: Metal crown, closure, and other metal stamping (except automotive) | BP5: Cutlery and handtool manufacturing | BQ5: Plate work and fabricated structural product manufacturing | BR5: Ornamental and architectural metal products manufacturing | BS5: Power boiler and heat exchanger manufacturing | BT5: Metal tank (heavy gauge) manufacturing | BU5: Metal can, box, and other metal container (light gauge) manufacturing | BV5: Hardware manufacturing | BW5: Spring and wire product manufacturing | BX5: Machine shops | BY5: Turned product and screw, nut, and bolt manufacturing | BZ5: Coating, engraving, heat treating and allied activities | CA5: Plumbing fixture fitting and trim manufacturing | CB5: Valve and fittings other than plumbing | CC5: Ball and roller bearing manufacturing | CD5: Fabricated pipe and pipe fitting manufacturing | CE5: Ammunition, arms, ordnance, and accessories manufacturing | CF5: Other fabricated metal manufacturing | CG5: Farm machinery and equipment manufacturing | CH5: Lawn and garden equipment manufacturing | CI5: Construction machinery manufacturing | CJ5: Mining and oil and gas field machinery manufacturing | CK5: Semiconductor machinery manufacturing | CL5: Other industrial machinery manufacturing | CM5: Optical instrument and lens manufacturing | CN5: Photographic and photocopying equipment manufacturing | CO5: Other commercial and service industry machinery manufacturing | CP5: Heating equipment (except warm air furnaces) manufacturing | CQ5: Air conditioning, refrigeration, and warm air heating equipment manufacturing | CR5: Industrial and commercial fan and blower and air purification equipment manufacturing | CS5: Industrial mold manufacturing | CT5: Special tool, die, jig, and fixture manufacturing | CU5: Machine tool manufacturing | CV5: Cutting and machine tool accessory, rolling mill, and other metalworking machinery manufacturing | CW5: Turbine and turbine generator set units manufacturing | CX5: Speed changer, industrial high-speed drive, and gear manufacturing | CY5: Mechanical power transmission equipment manufacturing | CZ5: Other engine equipment manufacturing | DA5: Air and gas compressor manufacturing | DB5: Measuring, dispensing, and other pumping equipment manufacturing | DC5: Material handling equipment manufacturing | DD5: Power-driven handtool manufacturing | DE5: Packaging machinery manufacturing | DF5: Industrial process furnace and oven manufacturing | DG5: Other general purpose machinery manufacturing | DH5: Fluid power process machinery | DI5: Electronic computer manufacturing | DJ5: Computer storage device manufacturing | DK5: Computer terminals and other computer peripheral equipment manufacturing | DL5: Telephone apparatus manufacturing | DM5: Broadcast and wireless communications equipment | DN5: Other communications equipment manufacturing | DO5: Semiconductor and related device manufacturing | DP5: Printed circuit assembly (electronic assembly) manufacturing | DQ5: Other electronic component manufacturing | DR5: Electromedical and electrotherapeutic apparatus manufacturing | DS5: Search, detection, and navigation instruments manufacturing | DT5: Automatic environmental control manufacturing | DU5: Industrial process variable instruments manufacturing | DV5: Totalizing fluid meter and counting device manufacturing | DW5: Electricity and signal testing instruments manufacturing | DX5: Analytical laboratory instrument manufacturing | DY5: Irradiation apparatus manufacturing | DZ5: Watch, clock, and other measuring and controlling device manufacturing | EA5: Audio and video equipment manufacturing | EB5: Manufacturing and reproducing magnetic and optical media | EC5: Electric lamp bulb and part manufacturing | ED5: Lighting fixture manufacturing | EE5: Small electrical appliance manufacturing | EF5: Major household appliance manufacturing | EG5: Power, distribution, and specialty transformer manufacturing | EH5: Motor and generator manufacturing | EI5: Switchgear and switchboard apparatus manufacturing | EJ5: Relay and industrial control manufacturing | EK5: Storage battery manufacturing | EL5: Primary battery manufacturing | EM5: Communication and energy wire and cable manufacturing | EN5: Wiring device manufacturing | EO5: Carbon and graphite product manufacturing | EP5: All other miscellaneous electrical equipment and component manufacturing | EQ5: Automobile manufacturing | ER5: Light truck and utility vehicle manufacturing | ES5: Heavy duty truck manufacturing | ET5: Motor vehicle body manufacturing | EU5: Truck trailer manufacturing | EV5: Motor home manufacturing | EW5: Travel trailer and camper manufacturing | EX5: Motor vehicle gasoline engine and engine parts manufacturing | EY5: Motor vehicle electrical and electronic equipment manufacturing | EZ5: Motor vehicle transmission and power train parts manufacturing | FA5: Motor vehicle seating and interior trim manufacturing | FB5: Motor vehicle metal stamping | FC5: Other motor vehicle parts manufacturing | FD5: Motor vehicle steering, suspension component (except spring), and brake systems manufacturing | FE5: Aircraft manufacturing | FF5: Aircraft engine and engine parts manufacturing | FG5: Other aircraft parts and auxiliary equipment manufacturing | FH5: Guided missile and space vehicle manufacturing | FI5: Propulsion units and parts for space vehicles and guided missiles | FJ5: Railroad rolling stock manufacturing | FK5: Ship building and repairing | FL5: Boat building | FM5: Motorcycle, bicycle, and parts manufacturing | FN5: Military armored vehicle, tank, and tank component manufacturing | FO5: All other transportation equipment manufacturing | FP5: Wood kitchen cabinet and countertop manufacturing | FQ5: Upholstered household furniture manufacturing | FR5: Nonupholstered wood household furniture manufacturing | FS5: Institutional furniture manufacturing | FT5: Other household nonupholstered furniture | FU5: Showcase, partition, shelving, and locker manufacturing | FV5: Office furniture and custom architectural woodwork and millwork manufacturing | FW5: Other furniture related product manufacturing | FX5: Surgical and medical instrument manufacturing | FY5: Surgical appliance and supplies manufacturing | FZ5: Dental equipment and supplies manufacturing | GA5: Ophthalmic goods manufacturing | GB5: Dental laboratories | GC5: Jewelry and silverware manufacturing | GD5: Sporting and athletic goods manufacturing | GE5: Doll, toy, and game manufacturing | GF5: Office supplies (except paper) manufacturing | GG5: Sign manufacturing | GH5: All other miscellaneous manufacturing | GI5: Dog and cat food manufacturing | GJ5: Other animal food manufacturing | GK5: Flour milling and malt manufacturing | GL5: Wet corn milling | GM5: Fats and oils refining and blending | GN5: Soybean and other oilseed processing | GO5: Breakfast cereal manufacturing | GP5: Sugar and confectionery product manufacturing | GQ5: Frozen food manufacturing | GR5: Fruit and vegetable canning, pickling, and drying | GS5: Cheese manufacturing | GT5: Dry, condensed, and evaporated dairy product manufacturing | GU5: Fluid milk and butter manufacturing | GV5: Ice cream and frozen dessert manufacturing | GW5: Poultry processing | GX5: Animal (except poultry) slaughtering, rendering, and processing | GY5: Seafood product preparation and packaging | GZ5: Bread and bakery product manufacturing | HA5: Cookie, cracker, pasta, and tortilla manufacturing | HB5: Snack food manufacturing | HC5: Coffee and tea manufacturing | HD5: Flavoring syrup and concentrate manufacturing | HE5: Seasoning and dressing manufacturing | HF5: All other food manufacturing | HG5: Soft drink and ice manufacturing | HH5: Breweries | HI5: Wineries | HJ5: Distilleries | HK5: Tobacco manufacturing | HL5: Fiber, yarn, and thread mills | HM5: Fabric mills | HN5: Textile and fabric finishing and fabric coating mills | HO5: Carpet and rug mills | HP5: Curtain and linen mills | HQ5: Other textile product mills | HR5: Apparel manufacturing | HS5: Leather and allied product manufacturing | HT5: Pulp mills | HU5: Paper mills | HV5: Paperboard mills | HW5: Paperboard container manufacturing | HX5: Paper bag and coated and treated paper manufacturing | HY5: Stationery product manufacturing | HZ5: Sanitary paper product manufacturing | IA5: All other converted paper product manufacturing | IB5: Printing | IC5: Support activities for printing | ID5: Petroleum refineries | IE5: Asphalt paving mixture and block manufacturing | IF5: Asphalt shingle and coating materials manufacturing | IG5: Other petroleum and coal products manufacturing | IH5: Petrochemical manufacturing | II5: Industrial gas manufacturing | IJ5: Synthetic dye and pigment manufacturing | IK5: Other basic inorganic chemical manufacturing | IL5: Other basic organic chemical manufacturing | IM5: Plastics material and resin manufacturing | IN5: Synthetic rubber and artificial and synthetic fibers and filaments manufacturing | IO5: Medicinal and botanical manufacturing | IP5: Pharmaceutical preparation manufacturing | IQ5: In-vitro diagnostic substance manufacturing | IR5: Biological product (except diagnostic) manufacturing | IS5: Fertilizer manufacturing | IT5: Pesticide and other agricultural chemical manufacturing | IU5: Paint and coating manufacturing | IV5: Adhesive manufacturing | IW5: Soap and cleaning compound manufacturing | IX5: Toilet preparation manufacturing | IY5: Printing ink manufacturing | IZ5: All other chemical product and preparation manufacturing | JA5: Plastics packaging materials and unlaminated film and sheet manufacturing | JB5: Plastics pipe, pipe fitting, and unlaminated profile shape manufacturing | JC5: Laminated plastics plate, sheet (except packaging), and shape manufacturing | JD5: Polystyrene foam product manufacturing | JE5: Urethane and other foam product (except polystyrene) manufacturing | JF5: Plastics bottle manufacturing | JG5: Other plastics product manufacturing | JH5: Tire manufacturing | JI5: Rubber and plastics hoses and belting manufacturing | JJ5: Other rubber product manufacturing | JK5: Motor vehicle and motor vehicle parts and supplies | JL5: Professional and commercial equipment and supplies | JM5: Household appliances and electrical and electronic goods | JN5: Machinery, equipment, and supplies | JO5: Other durable goods merchant wholesalers | JP5: Drugs and druggists’ sundries | JQ5: Grocery and related product wholesalers | JR5: Petroleum and petroleum products | JS5: Other nondurable goods merchant wholesalers | JT5: Wholesale electronic markets and agents and brokers | JU5: Customs duties | JV5: Motor vehicle and parts dealers | JW5: Food and beverage stores | JX5: General merchandise stores | JY5: Building material and garden equipment and supplies dealers | JZ5: Health and personal care stores | KA5: Gasoline stations | KB5: Clothing and clothing accessories stores | KC5: Nonstore retailers | KD5: All other retail | KE5: Air transportation | KF5: Rail transportation | KG5: Water transportation | KH5: Truck transportation | KI5: Transit and ground passenger transportation | KJ5: Pipeline transportation | KK5: Scenic and sightseeing transportation and support activities for transportation | KL5: Couriers and messengers | KM5: Warehousing and storage | KN5: Newspaper publishers | KO5: Periodical Publishers | KP5: Book publishers | KQ5: Directory, mailing list, and other publishers | KR5: Software publishers | KS5: Motion picture and video industries | KT5: Sound recording industries | KU5: Radio and television broadcasting | KV5: Cable and other subscription programming | KW5: Wired telecommunications carriers | KX5: Wireless telecommunications carriers (except satellite) | KY5: Satellite, telecommunications resellers, and all other telecommunications | KZ5: Data processing, hosting, and related services | LA5: Internet publishing and broadcasting and Web search portals | LB5: News syndicates, libraries, archives and all other information services | LC5: Nondepository credit intermediation and related activities | LD5: Monetary authorities and depository credit intermediation | LE5: Other financial investment activities | LF5: Securities and commodity contracts intermediation and brokerage | LG5: Direct life insurance carriers | LH5: Insurance carriers, except direct life | LI5: Insurance agencies, brokerages, and related activities | LJ5: Funds, trusts, and other financial vehicles | LK5: Owner-occupied housing | LL5: Tenant-occupied housing | LM5: Other real estate | LN5: Automotive equipment rental and leasing | LO5: Commercial and industrial machinery and equipment rental and leasing | LP5: General and consumer goods rental | LQ5: Lessors of nonfinancial intangible assets | LR5: Legal services | LS5: Custom computer programming services | LT5: Computer systems design services | LU5: Other computer related services, including facilities management | LV5: Accounting, tax preparation, bookkeeping, and payroll services | LW5: Architectural, engineering, and related services | LX5: Management consulting services | LY5: Environmental and other technical consulting services | LZ5: Scientific research and development services | MA5: Advertising, public relations, and related services | MB5: Specialized design services | MC5: Photographic services | MD5: Veterinary services | ME5: All other miscellaneous professional, scientific, and technical services | MF5: Management of companies and enterprises | MG5: Employment services | MH5: Services to buildings and dwellings | MI5: Office administrative services | MJ5: Facilities support services | MK5: Business support services | ML5: Travel arrangement and reservation services | MM5: Investigation and security services | MN5: Other support services | MO5: Waste management and remediation services | MP5: Elementary and secondary schools | MQ5: Junior colleges, colleges, universities, and professional schools | MR5: Other educational services | MS5: Offices of physicians | MT5: Offices of dentists | MU5: Offices of other health practitioners | MV5: Outpatient care centers | MW5: Medical and diagnostic laboratories | MX5: Home health care services | MY5: Other ambulatory health care services | MZ5: Hospitals | NA5: Nursing and community care facilities | NB5: Residential mental health, substance abuse, and other residential care facilities | NC5: Individual and family services | ND5: Child day care services | NE5: Community food, housing, and other relief services, including rehabilitation services | NF5: Performing arts companies | NG5: Spectator sports | NH5: Independent artists, writers, and performers | NI5: Promoters of performing arts and sports and agents for public figures | NJ5: Museums, historical sites, zoos, and parks | NK5: Amusement parks and arcades | NL5: Gambling industries (except casino hotels) | NM5: Other amusement and recreation industries | NN5: Accommodation | NO5: Full-service restaurants | NP5: Limited-service restaurants | NQ5: All other food and drinking places | NR5: Automotive repair and maintenance (including car washes) | NS5: Electronic and precision equipment repair and maintenance | NT5: Commercial and industrial machinery and equipment repair and maintenance | NU5: Personal and household goods repair and maintenance | NV5: Personal care services | NW5: Death care services | NX5: Dry-cleaning and laundry services | NY5: Other personal services | NZ5: Religious organizations | OA5: Grantmaking, giving, and social advocacy organizations | OB5: Civic, social, professional, and similar organizations | OC5: Private households | OD5: Federal general government (defense) | OE5: Federal general government (nondefense) | OF5: Postal service | OG5: Federal electric utilities | OH5: Other federal government enterprises | OI5: State and local government (educational services) | OJ5: State and local government (hospitals and health services) | OK5: State and local government (other services) | OL5: State and local government passenger transit | OM5: State and local government electric utilities | ON5: Other state and local government enterprises | OO5: Total Intermediate | OP5: Personal consumption expenditures | OQ5: Nonresidential private fixed investment in equipment | OR5: Nonresidential private fixed investment in intellectual property products | OS5: Residential private fixed investment | OT5: Nonresidential private fixed investment in structures | OU5: Change in private inventories | OV5: Exports of goods and services | OW5: Federal Government defense: Consumption expenditures | OX5: Federal national defense: Gross investment in equipment | OY5: Federal national defense: Gross investment in intellectual property products | OZ5: Federal national defense: Gross investment in structures | PA5: Federal Government nondefense: Consumption expenditures | PB5: Federal nondefense: Gross investment in equipment | PC5: Federal nondefense: Gross investment in intellectual property products | PD5: Federal nondefense: Gross investment in structures | PE5: State and local government consumption expenditures | PF5: State and local: Gross investment in equipment | PG5: State and local: Gross investment in intellectual property products | PH5: State and local: Gross investment in structures | PI5: Total use of products
A6: Code | B6: Commodity Description | C6: 1111A0 | D6: 1111B0 | E6: 111200 | F6: 111300 | G6: 111400 | H6: 111900 | I6: 112120 | J6: 1121A0 | K6: 112300 | L6: 112A00 | M6: 113000 | N6: 114000 | O6: 115000 | P6: 211000 | Q6: 212100 | R6: 212230 | S6: 2122A0 | T6: 212310 | U6: 2123A0 | V6: 213111 | W6: 21311A | X6: 221100 | Y6: 221200 | Z6: 221300 | AA6: 233210 | AB6: 233262 | AC6: 230301 | AD6: 230302 | AE6: 2332A0 | AF6: 233412 | AG6: 2334A0 | AH6: 233230 | AI6: 2332D0 | AJ6: 233240 | AK6: 233411 | AL6: 2332C0 | AM6: 321100 | AN6: 321200 | AO6: 321910 | AP6: 3219A0 | AQ6: 327100 | AR6: 327200 | AS6: 327310 | AT6: 327320 | AU6: 327330 | AV6: 327390 | AW6: 327400 | AX6: 327910 | AY6: 327991 | AZ6: 327992 | BA6: 327993 | BB6: 327999 | BC6: 331110 | BD6: 331200 | BE6: 331314 | BF6: 331313 | BG6: 33131B | BH6: 331410 | BI6: 331420 | BJ6: 331490 | BK6: 331510 | BL6: 331520 | BM6: 332114 | BN6: 33211A | BO6: 332119 | BP6: 332200 | BQ6: 332310 | BR6: 332320 | BS6: 332410 | BT6: 332420 | BU6: 332430 | BV6: 332500 | BW6: 332600 | BX6: 332710 | BY6: 332720 | BZ6: 332800 | CA6: 332913 | CB6: 33291A | CC6: 332991 | CD6: 332996 | CE6: 33299A | CF6: 332999 | CG6: 333111 | CH6: 333112 | CI6: 333120 | CJ6: 333130 | CK6: 333242 | CL6: 33329A | CM6: 333314 | CN6: 333316 | CO6: 333318 | CP6: 333414 | CQ6: 333415 | CR6: 333413 | CS6: 333511 | CT6: 333514 | CU6: 333517 | CV6: 33351B | CW6: 333611 | CX6: 333612 | CY6: 333613 | CZ6: 333618 | DA6: 333912 | DB6: 333914 | DC6: 333920 | DD6: 333991 | DE6: 333993 | DF6: 333994 | DG6: 33399A | DH6: 33399B | DI6: 334111 | DJ6: 334112 | DK6: 334118 | DL6: 334210 | DM6: 334220 | DN6: 334290 | DO6: 334413 | DP6: 334418 | DQ6: 33441A | DR6: 334510 | DS6: 334511 | DT6: 334512 | DU6: 334513 | DV6: 334514 | DW6: 334515 | DX6: 334516 | DY6: 334517 | DZ6: 33451A | EA6: 334300 | EB6: 334610 | EC6: 335110 | ED6: 335120 | EE6: 335210 | EF6: 335220 | EG6: 335311 | EH6: 335312 | EI6: 335313 | EJ6: 335314 | EK6: 335911 | EL6: 335912 | EM6: 335920 | EN6: 335930 | EO6: 335991 | EP6: 335999 | EQ6: 336111 | ER6: 336112 | ES6: 336120 | ET6: 336211 | EU6: 336212 | EV6: 336213 | EW6: 336214 | EX6: 336310 | EY6: 336320 | EZ6: 336350 | FA6: 336360 | FB6: 336370 | FC6: 336390 | FD6: 3363A0 | FE6: 336411 | FF6: 336412 | FG6: 336413 | FH6: 336414 | FI6: 33641A | FJ6: 336500 | FK6: 336611 | FL6: 336612 | FM6: 336991 | FN6: 336992 | FO6: 336999 | FP6: 337110 | FQ6: 337121 | FR6: 337122 | FS6: 337127 | FT6: 33712N | FU6: 337215 | FV6: 33721A | FW6: 337900 | FX6: 339112 | FY6: 339113 | FZ6: 339114 | GA6: 339115 | GB6: 339116 | GC6: 339910 | GD6: 339920 | GE6: 339930 | GF6: 339940 | GG6: 339950 | GH6: 339990 | GI6: 311111 | GJ6: 311119 | GK6: 311210 | GL6: 311221 | GM6: 311225 | GN6: 311224 | GO6: 311230 | GP6: 311300 | GQ6: 311410 | GR6: 311420 | GS6: 311513 | GT6: 311514 | GU6: 31151A | GV6: 311520 | GW6: 311615 | GX6: 31161A | GY6: 311700 | GZ6: 311810 | HA6: 3118A0 | HB6: 311910 | HC6: 311920 | HD6: 311930 | HE6: 311940 | HF6: 311990 | HG6: 312110 | HH6: 312120 | HI6: 312130 | HJ6: 312140 | HK6: 312200 | HL6: 313100 | HM6: 313200 | HN6: 313300 | HO6: 314110 | HP6: 314120 | HQ6: 314900 | HR6: 315000 | HS6: 316000 | HT6: 322110 | HU6: 322120 | HV6: 322130 | HW6: 322210 | HX6: 322220 | HY6: 322230 | HZ6: 322291 | IA6: 322299 | IB6: 323110 | IC6: 323120 | ID6: 324110 | IE6: 324121 | IF6: 324122 | IG6: 324190 | IH6: 325110 | II6: 325120 | IJ6: 325130 | IK6: 325180 | IL6: 325190 | IM6: 325211 | IN6: 3252A0 | IO6: 325411 | IP6: 325412 | IQ6: 325413 | IR6: 325414 | IS6: 325310 | IT6: 325320 | IU6: 325510 | IV6: 325520 | IW6: 325610 | IX6: 325620 | IY6: 325910 | IZ6: 3259A0 | JA6: 326110 | JB6: 326120 | JC6: 326130 | JD6: 326140 | JE6: 326150 | JF6: 326160 | JG6: 326190 | JH6: 326210 | JI6: 326220 | JJ6: 326290 | JK6: 423100 | JL6: 423400 | JM6: 423600 | JN6: 423800 | JO6: 423A00 | JP6: 424200 | JQ6: 424400 | JR6: 424700 | JS6: 424A00 | JT6: 425000 | JU6: 4200ID | JV6: 441000 | JW6: 445000 | JX6: 452000 | JY6: 444000 | JZ6: 446000 | KA6: 447000 | KB6: 448000 | KC6: 454000 | KD6: 4B0000 | KE6: 481000 | KF6: 482000 | KG6: 483000 | KH6: 484000 | KI6: 485000 | KJ6: 486000 | KK6: 48A000 | KL6: 492000 | KM6: 493000 | KN6: 511110 | KO6: 511120 | KP6: 511130 | KQ6: 5111A0 | KR6: 511200 | KS6: 512100 | KT6: 512200 | KU6: 515100 | KV6: 515200 | KW6: 517110 | KX6: 517210 | KY6: 517A00 | KZ6: 518200 | LA6: 519130 | LB6: 5191A0 | LC6: 522A00 | LD6: 52A000 | LE6: 523900 | LF6: 523A00 | LG6: 524113 | LH6: 5241XX | LI6: 524200 | LJ6: 525000 | LK6: 531HSO | LL6: 531HST | LM6: 531ORE | LN6: 532100 | LO6: 532400 | LP6: 532A00 | LQ6: 533000 | LR6: 541100 | LS6: 541511 | LT6: 541512 | LU6: 54151A | LV6: 541200 | LW6: 541300 | LX6: 541610 | LY6: 5416A0 | LZ6: 541700 | MA6: 541800 | MB6: 541400 | MC6: 541920 | MD6: 541940 | ME6: 5419A0 | MF6: 550000 | MG6: 561300 | MH6: 561700 | MI6: 561100 | MJ6: 561200 | MK6: 561400 | ML6: 561500 | MM6: 561600 | MN6: 561900 | MO6: 562000 | MP6: 611100 | MQ6: 611A00 | MR6: 611B00 | MS6: 621100 | MT6: 621200 | MU6: 621300 | MV6: 621400 | MW6: 621500 | MX6: 621600 | MY6: 621900 | MZ6: 622000 | NA6: 623A00 | NB6: 623B00 | NC6: 624100 | ND6: 624400 | NE6: 624A00 | NF6: 711100 | NG6: 711200 | NH6: 711500 | NI6: 711A00 | NJ6: 712000 | NK6: 713100 | NL6: 713200 | NM6: 713900 | NN6: 721000 | NO6: 722110 | NP6: 722211 | NQ6: 722A00 | NR6: 811100 | NS6: 811200 | NT6: 811300 | NU6: 811400 | NV6: 812100 | NW6: 812200 | NX6: 812300 | NY6: 812900 | NZ6: 813100 | OA6: 813A00 | OB6: 813B00 | OC6: 814000 | OD6: S00500 | OE6: S00600 | OF6: 491000 | OG6: S00101 | OH6: S00102 | OI6: GSLGE | OJ6: GSLGH | OK6: GSLGO | OL6: S00201 | OM6: S00202 | ON6: S00203 | OO6: T001 | OP6: F01000 | OQ6: F02E00 | OR6: F02N00 | OS6: F02R00 | OT6: F02S00 | OU6: F03000 | OV6: F04000 | OW6: F06C00 | OX6: F06E00 | OY6: F06N00 | OZ6: F06S00 | PA6: F07C00 | PB6: F07E00 | PC6: F07N00 | PD6: F07S00 | PE6: F10C00 | PF6: F10E00 | PG6: F10N00 | PH6: F10S00 | PI6: T019 | PM6: EPS ISIC (commodity)
A7: 1111A0 | B7: Oilseed farming | C7: 12160 | D7: 665 | E7: 59 | H7: 4 | GL7: 1207 | GM7: 913 | GN7: 24360 | HB7: 328 | HD7: 13 | HE7: 12 | HF7: 13 | IH7: 4 | II7: 0 | IJ7: 0 | IL7: 1421 | IO7: 28 | IP7: 0 | IQ7: 0 | IR7: 3 | OE7: -240 | OO7: 40949 | OU7: -1032 | OV7: 21287 | PI7: 61204 | PM7: =IFERROR(VLOOKUP($A7&"",Key!$A:$C,3,FALSE),"") -> ISIC 01
A8: 1111B0 | B8: Grain farming | D8: 11802 | H8: 692 | I8: 2579 | J8: 6513 | K8: 2436 | L8: 267 | GI8: 1888 | GJ8: 10292 | GK8: 10083 | GL8: 4774 | GM8: 142 | GN8: 10 | GO8: 383 | GQ8: 4174 | GR8: 213 | GT8: 3 | GV8: 6 | GZ8: 1948 | HA8: 746 | HB8: 1392 | HF8: 1306 | HH8: 921 | HJ8: 241 | II8: 38 | IL8: 11805 | JQ8: 0 | JR8: 0 | JS8: 0 | JW8: 643 | JX8: 154 | KC8: 0 | LZ8: 204 | MF8: 5 | MP8: 2 | MQ8: 25 | NN8: 11 | NO8: 0 | NP8: 1 | OE8: -32 | OI8: 144 | OJ8: 0 | OK8: 138 | OO8: 75948 | OP8: 4939 | OU8: -1547 | OV8: 16940 | PI8: 96281 | PM8: =IFERROR(VLOOKUP($A8&"",Key!$A:$C,3,FALSE),"") -> ISIC 01
A9: 111200 | B9: Vegetable and melon farming | E9: 962 | F9: 3 | GQ9: 1860 | GR9: 188 | GT9: 5 | HA9: 12 | HB9: 1028 | HD9: 37 | HE9: 144 | HF9: 2922 | JW9: 12 | KA9: 20 | KK9: 12 | MP9: 10 | MQ9: 27 | NM9: 1 | NN9: 4 | NO9: 135 | NP9: 165 | NQ9: 25 | NZ9: 2 | OB9: 2 | OI9: 96 | OJ9: 49 | OK9: 36 | OO9: 7756 | OP9: 39518 | OU9: -585 | OV9: 3649 | PI9: 50338 | PM9: =IFERROR(VLOOKUP($A9&"",Key!$A:$C,3,FALSE),"") -> ISIC 01
A10: 111300 | B10: Fruit and tree nut farming | F10: 1037 | GO10: 102 | GP10: 1438 | GQ10: 1733 | GR10: 3163 | GT10: 22 | GV10: 35 | GZ10: 192 | HA10: 177 | HB10: 2715 | HC10: 4156 | HD10: 43 | HE10: 1130 | HF10: 4696 | HI10: 5595 | HJ10: 4 | KK10: 32 | LZ10: 2 | MP10: 14 | MQ10: 116 | NM10: 5 | NN10: 16 | NO10: 122 | NP10: 132 | NQ10: 154 | NZ10: 8 | OI10: 185 | OJ10: 165 | OK10: 142 | OO10: 27330 | OP10: 48125 | OU10: -676 | OV10: 7907 | PI10: 82686 | PM10: =IFERROR(VLOOKUP($A10&"",Key!$A:$C,3,FALSE),"") -> ISIC 01
A11: 111400 | B11: Greenhouse, nursery, and floriculture production | G11: 3604 | O11: 134 | AD11: 36 | AG11: 163 | AK11: 72 | GH11: 222 | GR11: 1 | HB11: 159 | HF11: 311 | IL11: 2688 | JL11: 1 | JQ11: 2 | JR11: 2 | JS11: 49 | JT11: 1 | JV11: 744 | JW11: 312 | KA11: 346 | KD11: 23 | LD11: 1 | LK11: 0 | LL11: 0 | LM11: 7 | LR11: 2 | LU11: 1 | LV11: 13 | LW11: 18 | LX11: 10 | MA11: 29 | MH11: 1473 | MI11: 1 | MK11: 1 | MN11: 1 | MP11: 0 | MQ11: 1 | NK11: 9 | NL11: 14 | NM11: 6 | NN11: 0 | NZ11: 9 | OB11: 4 | OI11: 5 | OK11: 1406 | OO11: 11879 | OP11: 31499 | OU11: 119 | OV11: 995 | PI11: 44491 | PM11: =IFERROR(VLOOKUP($A11&"",Key!$A:$C,3,FALSE),"") -> ISIC 01
A12: 111900 | B12: Other crop farming | C12: 197 | D12: 797 | G12: 0 | H12: 1190 | I12: 535 | J12: 612 | L12: 29 | Q12: 5 | R12: 1 | S12: 8 | T12: 3 | U12: 8 | V12: 6 | W12: 14 | AA12: 17 | AB12: 16 | AC12: 118 | AD12: 515 | AE12: 58 | AF12: 16 | AG12: 416 | AH12: 14 | AI12: 46 | AJ12: 30 | AK12: 167 | AL12: 32 | GM12: 73 | GN12: 273 | GO12: 1 | GP12: 2750 | GV12: 3 | HA12: 8 | HB12: 3125 | HC12: 1149 | HD12: 65 | HE12: 1578 | HF12: 14 | HH12: 633 | HK12: 2156 | HL12: 1928 | HM12: 300 | II12: 52 | IJ12: 0 | IL12: 4699 | IO12: 30 | JX12: 17 | KD12: 0 | LZ12: 47 | MF12: 1 | MH12: 77 | MP12: 1 | MQ12: 1 | NK12: 3 | NM12: 19 | OE12: 252 | OI12: 21 | OK12: 320 | OO12: 24449 | OP12: 7475 | OU12: -754 | OV12: 7368 | PI12: 38538 | PM12: =IFERROR(VLOOKUP($A12&"",Key!$A:$C,3,FALSE),"") -> ISIC 01
A13: 112120 | B13: Dairy cattle and milk production | L13: 10 | GS13: 19471 | GT13: 5497 | GU13: 19215 | GV13: 591 | HF13: 813 | LZ13: 10 | MP13: 3 | MQ13: 3 | OI13: 18 | OO13: 45632 | OP13: 165 | OU13: 122 | OV13: 70 | PI13: 45989 | PM13: =IFERROR(VLOOKUP($A13&"",Key!$A:$C,3,FALSE),"") -> ISIC 01
A14: 1121A0 | B14: Beef cattle ranching and farming, including feedlots and dual-purpose ranching and farming | C14: 37 | D14: 245 | E14: 20 | F14: 84 | G14: 22 | H14: 29 | I14: 3088 | J14: 36030 | L14: 724 | O14: 42 | GX14: 58747 | JQ14: 576 | LZ14: 303 | MF14: 10 | OO14: 99956 | OP14: 97 | OU14: 1214 | OV14: 192 | PI14: 101458 | PM14: =IFERROR(VLOOKUP($A14&"",Key!$A:$C,3,FALSE),"") -> ISIC 01
A15: 112300 | B15: Poultry and egg production | C15: 12 | H15: 5 | K15: 10227 | GI15: 1 | GP15: 52 | GQ15: 146 | GR15: 31 | GV15: 188 | GW15: 30467 | GZ15: 347 | HA15: 393 | HE15: 455 | HF15: 370 | JQ15: 1 | JW15: 114 | JX15: 27 | LZ15: 7 | MP15: 1 | MQ15: 48 | NN15: 19 | NO15: 34 | NP15: 71 | OB15: 1 | OI15: 22 | OJ15: 131 | OK15: 244 | OO15: 43415 | OP15: 8774 | OU15: 357 | OV15: 778 | PI15: 53324 | PM15: =IFERROR(VLOOKUP($A15&"",Key!$A:$C,3,FALSE),"") -> ISIC 01
A16: 112A00 | B16: Animal production, except cattle and poultry and eggs | C16: 20 | D16: 163 | E16: 10 | F16: 44 | G16: 10 | H16: 59 | I16: 334 | J16: 542 | L16: 2961 | M16: 0 | O16: 438 | GH16: 14 | GW16: 184 | GX16: 24168 | GY16: 407 | GZ16: 2 | HA16: 2 | HB16: 60 | HD16: 21 | HE16: 153 | HF16: 1114 | HG16: 3 | HL16: 102 | HM16: 173 | HQ16: 80 | JQ16: 230 | JX16: 3 | KK16: 17 | LZ16: 659 | MF16: 19 | MM16: 12 | MQ16: 3 | NK16: 72 | NL16: 57 | NM16: 301 | NN16: 4 | NO16: 1020 | NP16: 1907 | NQ16: 356 | OD16: 14 | OK16: 106 | OO16: 35842 | OP16: 12574 | OU16: 474 | OV16: 1522 | PI16: 50413 | PM16: =IFERROR(VLOOKUP($A16&"",Key!$A:$C,3,FALSE),"") -> ISIC 01
A17: 113000 | B17: Forestry and logging | M17: 4822 | O17: 4 | Q17: 101 | AM17: 10990 | AN17: 2288 | AO17: 1342 | AP17: 606 | BB17: 1 | FT17: 122 | GD17: 109 | GH17: 187 | GP17: 57 | HB17: 17 | HD17: 682 | HE17: 54 | HF17: 37 | HG17: 140 | HR17: 58 | HS17: 6 | HT17: 677 | HU17: 772 | HV17: 2393 | IC17: 30 | IH17: 1 | IL17: 276 | IN17: 9 | IT17: 35 | IU17: 82 | IV17: 25 | IZ17: 7 | JH17: 1719 | JI17: 61 | JJ17: 615 | KB17: 0 | LZ17: 27 | MH17: 2 | MQ17: 4 | OI17: 42 | OK17: 125 | OO17: 28528 | OU17: 596 | OV17: 2551 | PI17: 31674 | PM17: =IFERROR(VLOOKUP($A17&"",Key!$A:$C,3,FALSE),"") -> ISIC 02
A18: 114000 | B18: Fishing, hunting and trapping | GI18: 16 | GJ18: 419 | GQ18: 97 | GR18: 420 | GW18: 192 | GX18: 1143 | GY18: 6285 | IS18: 17 | JW18: 818 | KK18: 1 | LZ18: 24 | MF18: 0 | MP18: 53 | MQ18: 16 | NK18: 29 | NL18: 26 | NM18: 186 | NN18: 443 | NO18: 2635 | NP18: 2559 | NQ18: 239 | NZ18: 34 | OB18: 96 | OH18: 18 | OI18: 59 | OJ18: 303 | OK18: 174 | OO18: 16304 | OP18: 8695 | OU18: 59 | OV18: 5391 | PI18: 30450 | PM18: =IFERROR(VLOOKUP($A18&"",Key!$A:$C,3,FALSE),"") -> ISIC 03
A19: 115000 | B19: Support activities for agriculture and forestry | C19: 1326 | D19: 8007 | E19: 2320 | F19: 3658 | G19: 1218 | H19: 3169 | I19: 1087 | J19: 913 | K19: 720 | L19: 497 | M19: 2963 | N19: 9 | LZ19: 245 | MF19: 21 | OE19: 51 | OK19: 3444 | OO19: 29649 | OP19: 124 | OV19: 86 | PI19: 29859 | PM19: =IFERROR(VLOOKUP($A19&"",Key!$A:$C,3,FALSE),"") -> ISIC 01
A20: 211000 | B20: Oil and gas extraction | P20: 21742 | S20: 0 | T20: 0 | U20: 0 | V20: 0 | W20: 4 | X20: 7017 | Y20: 5089 | Z20: 308 | AM20: 1 | AN20: 0 | AO20: 2 | AS20: 0 | BC20: 0 | BF20: 2 | BN20: 0 | BZ20: 0 | EQ20: 0 | GL20: 0 | GX20: 0 | GY20: 0 | HH20: 0 | HT20: 0 | HU20: 0 | HV20: 0 | IB20: 0 | ID20: 322173 | IG20: 1460 | IH20: 4463 | II20: 91 | IJ20: 5 | IK20: 231 | IL20: 699 | IM20: 10 | IN20: 5 | IO20: 0 | IP20: 3 | IQ20: 0 | IR20: 2 | IS20: 1 | IT20: 0 | IU20: 0 | IV20: 1 | IW20: 2 | IX20: 0 | IZ20: 52 | JA20: 0 | JD20: 0 | JG20: 0 | JH20: 0 | JJ20: 0 | JK20: 0 | JL20: 0 | JM20: 1 | JN20: 0 | JO20: 0 | JQ20: 0 | JR20: 0 | JS20: 1 | JT20: 0 | JV20: 4 | JW20: 0 | JX20: 1 | JY20: 4 | JZ20: 0 | KB20: 0 | KC20: 0 | KD20: 0 | KJ20: 7 | KM20: 80 | KN20: 0 | KO20: 0 | KP20: 2 | KQ20: 0 | KR20: 2 | KS20: 0 | KT20: 0 | KU20: 0 | KV20: 0 | KW20: 0 | KX20: 0 | KY20: 2 | KZ20: 1 | LA20: 6 | LB20: 0 | LM20: 35 | LS20: 0 | LV20: 2 | LW20: 1 | LX20: 0 | LZ20: 1 | MA20: 0 | MD20: 0 | MF20: 3 | MG20: 0 | MI20: 0 | MN20: 0 | MO20: 2 | MQ20: 7 | MR20: 189 | MS20: 1 | MT20: 0 | MU20: 0 | MV20: 0 | MW20: 0 | MX20: 0 | MY20: 0 | MZ20: 0 | NA20: 0 | NB20: 0 | NC20: 0 | ND20: 0 | NE20: 0 | NF20: 0 | NG20: 0 | NI20: 0 | NJ20: 0 | NK20: 0 | NL20: 1 | NM20: 22 | NN20: 0 | NO20: 0 | NP20: 0 | NQ20: 0 | NR20: 0 | NS20: 0 | NT20: 0 | NU20: 0 | NV20: 0 | NW20: 0 | NX20: 1 | NY20: 0 | OA20: 0 | OB20: 1 | OE20: 0 | OF20: 0 | OG20: 1910 | OH20: 0 | OM20: 20045 | ON20: 3340 | OO20: 389039 | OU20: -7577 | OV20: 41909 | PI20: 423371 | PM20: =IFERROR(VLOOKUP($A20&"",Key!$A:$C,3,FALSE),"") -> ISIC 06
A21: 212100 | B21: Coal mining | K21: 596 | M21: 0 | P21: 110 | Q21: 3167 | R21: 80 | S21: 42 | T21: 17 | U21: 66 | V21: 6 | W21: 17 | X21: 3973 | Z21: 0 | AM21: 6 | AN21: 5 | AO21: 3 | AP21: 4 | AQ21: 141 | AR21: 412 | AS21: 447 | AT21: 179 | AU21: 30 | AV21: 36 | AW21: 373 | AX21: 11 | AY21: 11 | AZ21: 65 | BA21: 72 | BB21: 34 | BC21: 2119 | BD21: 61 | BE21: 42 | BF21: 58 | BG21: 120 | BH21: 39 | BI21: 27 | BJ21: 43 | BK21: 60 | BL21: 68 | BN21: 2 | BQ21: 2 | BR21: 3 | BX21: 2 | BY21: 2 | BZ21: 4 | CB21: 1 | CD21: 1 | EC21: 0 | ED21: 2 | EF21: 0 | EG21: 0 | EI21: 1 | EK21: 3 | EN21: 2 | EO21: 1 | EP21: 1 | EQ21: 0 | ER21: 10 | ET21: 2 | EW21: 1 | EX21: 7 | EY21: 3 | EZ21: 5 | FB21: 6 | FC21: 7 | FD21: 4 | FE21: 6 | FF21: 14 | FI21: 6 | FJ21: 2 | FK21: 4 | FP21: 4 | FR21: 1 | FT21: 2 | FU21: 2 | FV21: 2 | GI21: 42 | GJ21: 45 | GK21: 25 | GL21: 81 | GM21: 8 | GN21: 50 | GO21: 79 | GP21: 211 | GQ21: 77 | GR21: 120 | GS21: 69 | GT21: 74 | GU21: 77 | GV21: 13 | GW21: 56 | GX21: 167 | GY21: 65 | GZ21: 128 | HA21: 58 | HB21: 86 | HC21: 12 | HD21: 12 | HE21: 21 | HF21: 45 | HG21: 66 | HH21: 65 | HI21: 16 | HJ21: 24 | HK21: 60 | HL21: 8 | HM21: 32 | HN21: 30 | HO21: 4 | HQ21: 2 | HT21: 142 | HU21: 871 | HV21: 746 | HW21: 188 | HX21: 86 | HY21: 3 | HZ21: 27 | IA21: 22 | ID21: 1663 | IE21: 108 | IF21: 20 | IG21: 318 | IH21: 109 | II21: 30 | IJ21: 4 | IK21: 32 | IL21: 327 | IM21: 103 | IN21: 10 | IO21: 3 | IP21: 10 | IR21: 5 | IS21: 17 | IT21: 2 | IU21: 2 | IV21: 3 | IW21: 9 | IX21: 2 | IZ21: 10 | JA21: 39 | JB21: 15 | JC21: 7 | JD21: 19 | JE21: 10 | JF21: 9 | JG21: 89 | JH21: 40 | JI21: 7 | JJ21: 21 | JL21: 4 | JO21: 4 | JQ21: 4 | JS21: 7 | KM21: 4 | KV21: 2 | LW21: 23 | LZ21: 114 | MF21: 50 | MG21: 0 | MJ21: 10 | MO21: 20 | MP21: 17 | MQ21: 4 | MZ21: 34 | NA21: 15 | NB21: 2 | NC21: 2 | ND21: 4 | NE21: 1 | NJ21: 2 | NL21: 4 | NM21: 8 | NN21: 23 | NO21: 563 | NP21: 542 | NQ21: 145 | NR21: 9 | NT21: 4 | NW21: 0 | NX21: 8 | OB21: 13 | OE21: 4456 | OI21: 416 | OJ21: 537 | OK21: 210 | OM21: 6995 | OO21: 33971 | OP21: 221 | OU21: -1172 | OV21: 9597 | PI21: 42616 | PM21: =IFERROR(VLOOKUP($A21&"",Key!$A:$C,3,FALSE),"") -> ISIC 05
A22: 212230 | B22: Copper, nickel, lead, and zinc mining | R22: 408 | S22: 4 | AQ22: 3 | AZ22: 41 | BC22: 389 | BD22: 22 | BE22: 117 | BH22: 261 | BI22: 66 | BJ22: 485 | BW22: 72 | BZ22: 418 | CF22: 46 | CG22: 52 | CJ22: 35 | CU22: 15 | DL22: 2 | EA22: 2 | EH22: 7 | EJ22: 22 | FF22: 3 | FY22: 26 | II22: 285 | IJ22: 744 | IK22: 171 | IL22: 11 | IU22: 65 | KN22: 9 | KP22: 19 | KQ22: 12 | KR22: 0 | KS22: 12 | KT22: 10 | KU22: 88 | KV22: 42 | KW22: 181 | KY22: 43 | KZ22: 36 | LA22: 417 | LB22: 0 | LW22: 292 | LZ22: 174 | MF22: 2 | MH22: 611 | MM22: 404 | MO22: 70 | MR22: 471 | MZ22: 6 | NA22: 7 | NB22: 24 | NF22: 299 | NG22: 5 | NH22: 2 | NI22: 19 | NK22: 2 | NM22: 1022 | NN22: 175 | NO22: 15 | NP22: 12 | NQ22: 2 | NR22: 10 | NS22: 123 | NT22: 58 | NV22: 1027 | NW22: 0 | NY22: 22 | OA22: 17 | OB22: 209 | OO22: 9722 | OU22: 108 | OV22: 4060 | PI22: 13889 | PM22: =IFERROR(VLOOKUP($A22&"",Key!$A:$C,3,FALSE),"") -> ISIC 07
A23: 2122A0 | B23: Iron, gold, silver, and other metal ore mining | R23: 2401 | S23: 2004 | AQ23: 3 | AR23: 2 | AS23: 2 | AX23: 57 | AZ23: 26 | BC23: 3816 | BD23: 137 | BE23: 22 | BF23: 152 | BH23: 550 | BI23: 5 | BJ23: 1859 | BW23: 13 | CF23: 4 | CU23: 19 | DK23: 0 | DL23: 1 | EJ23: 34 | EP23: 2 | EX23: 12 | EZ23: 7 | FC23: 10 | FD23: 17 | FZ23: 2 | GB23: 1 | GC23: 24 | ID23: 29 | IH23: 13 | II23: 87 | IJ23: 868 | IK23: 928 | IL23: 44 | IS23: 54 | IU23: 79 | IZ23: 28 | JO23: 10 | KB23: 2 | LW23: 95 | LZ23: 181 | MF23: 1 | OE23: 2 | OO23: 13604 | OQ23: 121 | OU23: -205 | OV23: 6797 | PI23: 20317 | PM23: =IFERROR(VLOOKUP($A23&"",Key!$A:$C,3,FALSE),"") -> ISIC 07
A24: 212310 | B24: Stone mining and quarrying | C24: 30 | D24: 261 | E24: 47 | F24: 22 | G24: 15 | H24: 68 | I24: 39 | J24: 36 | K24: 6 | L24: 34 | Q24: 270 | R24: 0 | S24: 0 | T24: 585 | U24: 162 | W24: 46 | X24: 55 | Z24: 10 | AA24: 21 | AB24: 34 | AC24: 3324 | AD24: 587 | AE24: 1513 | AF24: 523 | AG24: 2233 | AH24: 547 | AI24: 392 | AJ24: 372 | AK24: 2069 | AL24: 2588 | AS24: 464 | AT24: 939 | AU24: 143 | AV24: 77 | AW24: 428 | AY24: 628 | AZ24: 278 | FS24: 12 | FZ24: 4 | GB24: 4 | IE24: 11 | IF24: 26 | IZ24: 797 | JK24: 0 | JL24: 0 | JM24: 0 | JN24: 0 | JR24: 0 | JT24: 0 | KC24: 0 | KD24: 0 | KF24: 128 | KG24: 0 | KH24: 7 | KI24: 1 | KK24: 3 | KO24: 0 | KP24: 0 | KQ24: 0 | KR24: 0 | KV24: 2 | KW24: 4 | KX24: 0 | KY24: 1 | KZ24: 3 | LK24: 4 | LL24: 0 | LW24: 134 | LZ24: 53 | MF24: 1 | OK24: 174 | ON24: 125 | OO24: 20342 | OU24: -11 | OV24: 140 | PI24: 20470 | PM24: =IFERROR(VLOOKUP($A24&"",Key!$A:$C,3,FALSE),"") -> ISIC 08
A25: 2123A0 | B25: Other nonmetallic mineral mining and quarrying | C25: 1 | D25: 482 | E25: 2 | F25: 5 | H25: 192 | I25: 3 | L25: 2 | Q25: 10 | R25: 1 | S25: 1 | T25: 34 | U25: 515 | V25: 23 | W25: 38 | X25: 982 | Y25: 29 | Z25: 260 | AA25: 66 | AB25: 173 | AC25: 127 | AD25: 171 | AE25: 595 | AF25: 209 | AG25: 670 | AH25: 215 | AI25: 152 | AJ25: 122 | AK25: 2250 | AL25: 406 | AQ25: 860 | AR25: 214 | AS25: 106 | AT25: 5023 | AU25: 542 | AV25: 252 | AW25: 463 | AX25: 83 | AY25: 176 | AZ25: 289 | BA25: 243 | BB25: 428 | BC25: 343 | BK25: 550 | BL25: 19 | BP25: 2 | CF25: 8 | CP25: 1 | CS25: 0 | CT25: 0 | CU25: 1 | CV25: 8 | DL25: 3 | DQ25: 0 | EE25: 21 | EF25: 4 | FE25: 152 | FF25: 1 | FG25: 61 | FH25: 1 | FI25: 4 | FZ25: 17 | GB25: 17 | GF25: 1 | GI25: 10 | GJ25: 278 | HU25: 337 | HV25: 132 | ID25: 106 | IE25: 2065 | IF25: 818 | II25: 14 | IJ25: 28 | IK25: 614 | IL25: 8 | IS25: 1043 | IU25: 569 | IV25: 379 | IX25: 42 | KD25: 0 | KW25: 3 | KX25: 18 | LK25: 1 | LL25: 6 | LW25: 126 | LZ25: 316 | MF25: 15 | ND25: 175 | OE25: 199 | OK25: 1318 | ON25: 85 | OO25: 26331 | OP25: 113 | OU25: -454 | OV25: 2030 | PI25: 28021 | PM25: =IFERROR(VLOOKUP($A25&"",Key!$A:$C,3,FALSE),"") -> ISIC 08
A26: 213111 | B26: Drilling oil and gas wells | P26: 39 | OO26: 39 | OT26: 28550 | OU26: -10 | PI26: 28579 | PM26: =IFERROR(VLOOKUP($A26&"",Key!$A:$C,3,FALSE),"") -> ISIC 09
A27: 21311A | B27: Other support activities for mining | P27: 12471 | Q27: 186 | R27: 151 | S27: 139 | T27: 361 | U27: 203 | V27: 1112 | W27: 1808 | LZ27: 22 | MF27: 2 | OO27: 16455 | OQ27: 2288 | OT27: 69029 | OU27: -77 | OV27: 3045 | PI27: 90739 | PM27: =IFERROR(VLOOKUP($A27&"",Key!$A:$C,3,FALSE),"") -> ISIC 09
A28: 221100 | B28: Electric power generation, transmission, and distribution | C28: 153 | D28: 204 | E28: 318 | F28: 331 | G28: 75 | H28: 392 | I28: 1021 | J28: 187 | K28: 236 | L28: 153 | M28: 8 | N28: 9 | O28: 67 | P28: 2613 | Q28: 880 | R28: 325 | S28: 1183 | T28: 510 | U28: 665 | V28: 156 | W28: 504 | X28: 9500 | Y28: 102 | Z28: 268 | AA28: 169 | AB28: 494 | AC28: 1058 | AD28: 405 | AE28: 826 | AF28: 464 | AG28: 1465 | AH28: 252 | AI28: 480 | AJ28: 364 | AK28: 1579 | AL28: 678 | AM28: 621 | AN28: 529 | AO28: 266 | AP28: 249 | AQ28: 227 | AR28: 1128 | AS28: 703 | AT28: 193 | AU28: 72 | AV28: 89 | AW28: 238 | AX28: 62 | AY28: 45 | AZ28: 200 | BA28: 252 | BB28: 93 | BC28: 2149 | BD28: 321 | BE28: 50 | BF28: 430 | BG28: 407 | BH28: 282 | BI28: 169 | BJ28: 172 | BK28: 465 | BL28: 310 | BM28: 109 | BN28: 331 | BO28: 144 | BP28: 109 | BQ28: 341 | BR28: 307 | BS28: 54 | BT28: 65 | BU28: 201 | BV28: 71 | BW28: 98 | BX28: 481 | BY28: 476 | BZ28: 607 | CA28: 38 | CB28: 227 | CC28: 97 | CD28: 53 | CE28: 114 | CF28: 148 | CG28: 126 | CH28: 18 | CI28: 149 | CJ28: 147 | CK28: 20 | CL28: 243 | CM28: 36 | CN28: 4 | CO28: 121 | CP28: 39 | CQ28: 150 | CR28: 40 | CS28: 107 | CT28: 104 | CU28: 48 | CV28: 118 | CW28: 73 | CX28: 30 | CY28: 60 | CZ28: 171 | DA28: 42 | DB28: 120 | DC28: 132 | DD28: 22 | DE28: 30 | DF28: 18 | DG28: 157 | DH28: 98 | DI28: 4 | DJ28: 4 | DK28: 11 | DL28: 7 | DM28: 68 | DN28: 3 | DO28: 1180 | DP28: 38 | DQ28: 114 | DR28: 89 | DS28: 153 | DT28: 0 | DU28: 9 | DV28: 10 | DW28: 21 | DX28: 39 | DY28: 25 | DZ28: 20 | EA28: 0 | EB28: 3 | EC28: 1 | ED28: 53 | EE28: 7 | EF28: 72 | EG28: 21 | EH28: 44 | EI28: 53 | EJ28: 31 | EK28: 88 | EL28: 1 | EM28: 59 | EN28: 92 | EO28: 55 | EP28: 74 | EQ28: 51 | ER28: 241 | ES28: 32 | ET28: 63 | EU28: 46 | EV28: 1 | EW28: 63 | EX28: 407 | EY28: 172 | EZ28: 305 | FA28: 367 | FB28: 326 | FC28: 402 | FD28: 239 | FE28: 490 | FF28: 561 | FG28: 188 | FH28: 171 | FI28: 247 | FJ28: 90 | FK28: 185 | FL28: 60 | FM28: 39 | FN28: 23 | FO28: 28 | FP28: 142 | FQ28: 65 | FR28: 35 | FS28: 44 | FT28: 27 | FU28: 77 | FV28: 142 | FW28: 40 | FX28: 191 | FY28: 124 | FZ28: 30 | GA28: 33 | GB28: 34 | GC28: 30 | GD28: 106 | GE28: 5 | GF28: 25 | GG28: 82 | GH28: 193 | GI28: 139 | GJ28: 223 | GK28: 229 | GL28: 285 | GM28: 22 | GN28: 91 | GO28: 93 | GP28: 432 | GQ28: 353 | GR28: 272 | GS28: 271 | GT28: 186 | GU28: 328 | GV28: 106 | GW28: 403 | GX28: 755 | GY28: 102 | GZ28: 485 | HA28: 285 | HB28: 244 | HC28: 56 | HD28: 52 | HE28: 112 | HF28: 207 | HG28: 420 | HH28: 230 | HI28: 95 | HJ28: 49 | HK28: 211 | HL28: 175 | HM28: 293 | HN28: 109 | HO28: 89 | HP28: 20 | HQ28: 90 | HR28: 4 | HS28: 13 | HT28: 230 | HU28: 1245 | HV28: 2280 | HW28: 870 | HX28: 250 | HY28: 79 | HZ28: 134 | IA28: 106 | IB28: 1279 | IC28: 42 | ID28: 3932 | IE28: 305 | IF28: 98 | IG28: 124 | IH28: 503 | II28: 1469 | IJ28: 132 | IK28: 1598 | IL28: 2282 | IM28: 1919 | IN28: 262 | IO28: 153 | IP28: 532 | IQ28: 37 | IR28: 264 | IS28: 432 | IT28: 69 | IU28: 126 | IV28: 110 | IW28: 296 | IX28: 137 | IY28: 28 | IZ28: 478 | JA28: 787 | JB28: 370 | JC28: 61 | JD28: 168 | JE28: 93 | JF28: 440 | JG28: 1959 | JH28: 278 | JI28: 68 | JJ28: 274 | JK28: 943 | JL28: 959 | JM28: 1055 | JN28: 1292 | JO28: 2566 | JP28: 1142 | JQ28: 2089 | JR28: 322 | JS28: 3089 | JT28: 445 | JV28: 4475 | JW28: 9322 | JX28: 8193 | JY28: 2037 | JZ28: 2024 | KA28: 4693 | KB28: 1872 | KC28: 2485 | KD28: 2977 | KE28: 240 | KF28: 26 | KG28: 103 | KH28: 3635 | KI28: 251 | KJ28: 528 | KK28: 830 | KL28: 233 | KM28: 2174 | KN28: 109 | KO28: 59 | KP28: 148 | KQ28: 50 | KR28: 626 | KS28: 489 | KT28: 4 | KU28: 294 | KV28: 99 | KW28: 2603 | KX28: 1017 | KY28: 165 | KZ28: 1440 | LA28: 744 | LB28: 22 | LC28: 708 | LD28: 3411 | LE28: 692 | LF28: 242 | LG28: 67 | LH28: 329 | LI28: 308 | LJ28: 7 | LL28: 602 | LM28: 36155 | LN28: 216 | LO28: 347 | LP28: 264 | LQ28: 113 | LR28: 687 | LS28: 249 | LT28: 210 | LU28: 45 | LV28: 381 | LW28: 799 | LX28: 1124 | LY28: 110 | LZ28: 1923 | MA28: 440 | MB28: 119 | MC28: 100 | MD28: 111 | ME28: 398 | MF28: 5064 | MG28: 291 | MH28: 735 | MI28: 366 | MJ28: 214 | MK28: 441 | ML28: 168 | MM28: 151 | MN28: 348 | MO28: 679 | MP28: 240 | MQ28: 2483 | MR28: 96 | MS28: 1585 | MT28: 383 | MU28: 390 | MV28: 1498 | MW28: 121 | MX28: 162 | MY28: 159 | MZ28: 8314 | NA28: 3165 | NB28: 480 | NC28: 424 | ND28: 607 | NE28: 266 | NF28: 79 | NG28: 211 | NH28: 58 | NI28: 324 | NJ28: 289 | NK28: 373 | NL28: 427 | NM28: 2379 | NN28: 5840 | NO28: 6833 | NP28: 10455 | NQ28: 879 | NR28: 1421 | NS28: 99 | NT28: 225 | NU28: 187 | NV28: 1028 | NW28: 42 | NX28: 606 | NY28: 541 | NZ28: 54 | OA28: 86 | OB28: 1111 | OD28: 1580 | OE28: 302 | OF28: 65 | OG28: 1723 | OH28: 138 | OI28: 2981 | OJ28: 622 | OK28: 1897 | OL28: 103 | OM28: 258 | ON28: 903 | OO28: 277787 | OP28: 177661 | OV28: 2744 | PI28: 458193 | PM28: =IFERROR(VLOOKUP($A28&"",Key!$A:$C,3,FALSE),"") -> ISIC 351
