Workbook

Sheet About
A1: NoH Number of Households
A3: Source: | B3: 2022-2050
B4: Energy Information Administration
B5: 2023
B6: Annual Energy Outlook 2023
B7: https://www.eia.gov/outlooks/archive/aeo23/tables_ref.php
B8: Table 4
B10: 2021
B11: Energy Information Administration
B12: 2022
B13: Annual Energy Outlook 2022
B14: https://www.eia.gov/outlooks/archive/aeo22/tables_ref.php
B15: Table 4

Sheet AEO 2023 Table 4
B1: ref2023.d020623a | C1: 2022 | D1: 2023 | E1: 2024 | F1: 2025 | G1: 2026 | H1: 2027 | I1: 2028 | J1: 2029 | K1: 2030 | L1: 2031 | M1: 2032 | N1: 2033 | O1: 2034 | P1: 2035 | Q1: 2036 | R1: 2037 | S1: 2038 | T1: 2039 | U1: 2040 | V1: 2041 | W1: 2042 | X1: 2043 | Y1: 2044 | Z1: 2045 | AA1: 2046 | AB1: 2047 | AC1: 2048 | AD1: 2049 | AE1: 2050
C3: Report | D3: Annual Energy Outlook 2023
C4: Scenario | D4: ref2023 | G4: Reference
C5: Datekey | D5: d020623a
C6: Release Date | E6: March 2023
A10: RKI000 | B10: 4. Residential Sector Key Indicators and Consumption | AF10: Average
B11: (quadrillion Btu, unless otherwise noted) | AF11: Annual
AF12: Change
B13: Key Indicators and Consumption | C13: 2022 | D13: 2023 | E13: 2024 | F13: 2025 | G13: 2026 | H13: 2027 | I13: 2028 | J13: 2029 | K13: 2030 | L13: 2031 | M13: 2032 | N13: 2033 | O13: 2034 | P13: 2035 | Q13: 2036 | R13: 2037 | S13: 2038 | T13: 2039 | U13: 2040 | V13: 2041 | W13: 2042 | X13: 2043 | Y13: 2044 | Z13: 2045 | AA13: 2046 | AB13: 2047 | AC13: 2048 | AD13: 2049 | AE13: 2050 | AF13: 2022–2050
B15: Key Indicators
B16: Households (millions)
A17: RKI000:ba_Single-Family | B17: Single-Family | C17: 86.924255 | D17: 87.748611 | E17: 88.618675 | F17: 89.519981 | G17: 90.411308 | H17: 91.302132 | I17: 92.198265 | J17: 93.091507 | K17: 93.970619 | L17: 94.836555 | M17: 95.694557 | N17: 96.533203 | O17: 97.347885 | P17: 98.154381 | Q17: 98.959145 | R17: 99.75724 | S17: 100.55006 | T17: 101.33466 | U17: 102.12499 | V17: 102.91761 | W17: 103.69783 | X17: 104.47331 | Y17: 105.24597 | Z17: 106.01605 | AA17: 106.78051 | AB17: 107.53815 | AC17: 108.28622 | AD17: 109.02242 | AE17: 109.74868 | AF17: 0.008362
A18: RKI000:ba_Multifamily | B18: Multifamily | C18: 32.842152 | D18: 33.209229 | E18: 33.535469 | F18: 33.85815 | G18: 34.181629 | H18: 34.507633 | I18: 34.834255 | J18: 35.155056 | K18: 35.46513 | L18: 35.769081 | M18: 36.0718 | N18: 36.366608 | O18: 36.650593 | P18: 36.930111 | Q18: 37.212017 | R18: 37.496159 | S18: 37.783924 | T18: 38.073307 | U18: 38.36647 | V18: 38.656506 | W18: 38.941956 | X18: 39.223991 | Y18: 39.501945 | Z18: 39.776779 | AA18: 40.048443 | AB18: 40.322777 | AC18: 40.595905 | AD18: 40.869537 | AE18: 41.144089 | AF18: 0.008081
A19: RKI000:ba_MobileHomes | B19: Mobile Homes | C19: 6.648376 | D19: 6.654435 | E19: 6.657747 | F19: 6.660283 | G19: 6.66859 | H19: 6.680898 | I19: 6.695705 | J19: 6.709839 | K19: 6.717811 | L19: 6.722091 | M19: 6.727011 | N19: 6.734098 | O19: 6.740673 | P19: 6.744905 | Q19: 6.74995 | R19: 6.752422 | S19: 6.751948 | T19: 6.750166 | U19: 6.750861 | V19: 6.753187 | W19: 6.756266 | X19: 6.759341 | Y19: 6.761881 | Z19: 6.763837 | AA19: 6.764435 | AB19: 6.765501 | AC19: 6.766449 | AD19: 6.766767 | AE19: 6.767235 | AF19: 0.000633
A20: RKI000:ba_Total | B20: Total | C20: 126.41478 | D20: 127.61227 | E20: 128.81189 | F20: 130.03841 | G20: 131.26154 | H20: 132.49066 | I20: 133.72823 | J20: 134.95641 | K20: 136.15355 | L20: 137.32773 | M20: 138.49336 | N20: 139.63391 | O20: 140.73915 | P20: 141.82939 | Q20: 142.92111 | R20: 144.00583 | S20: 145.08594 | T20: 146.15813 | U20: 147.24231 | V20: 148.3273 | W20: 149.39606 | X20: 150.45664 | Y20: 151.50981 | Z20: 152.55667 | AA20: 153.59338 | AB20: 154.62643 | AC20: 155.64857 | AD20: 156.65874 | AE20: 157.66 | AF20: 0.00792
A22: RKI000:ca_AverageHouseS | B22: Average House Square Footage | C22: 1798.9158 | D22: 1803.5209 | E22: 1808.4264 | F22: 1813.3185 | G22: 1818.0804 | H22: 1822.7229 | I22: 1827.2777 | J22: 1831.8 | K22: 1836.3394 | L22: 1840.8495 | M22: 1845.2855 | N22: 1849.6774 | O22: 1854.0608 | P22: 1858.4113 | Q22: 1862.6759 | R22: 1866.8663 | S22: 1870.9755 | T22: 1875.0114 | U22: 1878.9578 | V22: 1882.8684 | W22: 1886.7397 | X22: 1890.5779 | Y22: 1894.3921 | Z22: 1898.1798 | AA22: 1901.9388 | AB22: 1905.6209 | AC22: 1909.2523 | AD22: 1912.8229 | AE22: 1916.3303 | AF22: 0.002261
B24: Energy Intensity
B25: (million Btu per household)
A26: RKI000:da_DeliveredEner | B26: Gross End-use Consumption 1/ | C26: 93.909477 | D26: 92.769119 | E26: 89.479935 | F26: 89.052956 | G26: 88.647408 | H26: 88.231392 | I26: 87.719673 | J26: 87.082458 | K26: 86.372932 | L26: 85.637901 | M26: 84.930008 | N26: 84.330368 | O26: 83.726021 | P26: 83.229088 | Q26: 82.803543 | R26: 82.42997 | S26: 82.039726 | T26: 81.693481 | U26: 81.360573 | V26: 81.06002 | W26: 80.817673 | X26: 80.633194 | Y26: 80.500008 | Z26: 80.389549 | AA26: 80.279945 | AB26: 80.223389 | AC26: 80.211197 | AD26: 80.229492 | AE26: 80.285049 | AF26: -0.005583
A27: RKI000:da_TotalEnergyCo | B27: Delivered Energy Consumption | C27: 93.023323 | D27: 91.801674 | E27: 88.420021 | F27: 87.901169 | G27: 87.405548 | H27: 86.898582 | I27: 86.294922 | J27: 85.563858 | K27: 84.758438 | L27: 83.924873 | M27: 83.114105 | N27: 82.411514 | O27: 81.703484 | P27: 81.117577 | Q27: 80.600105 | R27: 80.131668 | S27: 79.641068 | T27: 79.188065 | U27: 78.743118 | V27: 78.324791 | W27: 77.958664 | X27: 77.644554 | Y27: 77.377632 | Z27: 77.127983 | AA27: 76.87487 | AB27: 76.670601 | AC27: 76.504471 | AD27: 76.365883 | AE27: 76.260414 | AF27: -0.007071
B28: (thousand Btu per square foot)
A29: RKI000:ea_DeliveredEner | B29: Gross End-use Consumption 1/ | C29: 52.203377 | D29: 51.437782 | E29: 49.479443 | F29: 49.110489 | G29: 48.758793 | H29: 48.406364 | I29: 48.005661 | J29: 47.539284 | K29: 47.035389 | L29: 46.520859 | M29: 46.025402 | N29: 45.591934 | O29: 45.158184 | P29: 44.785076 | Q29: 44.454079 | R29: 44.15419 | S29: 43.848637 | T29: 43.569595 | U29: 43.300903 | V29: 43.051346 | W29: 42.83456 | X29: 42.650024 | Y29: 42.493847 | Z29: 42.350861 | AA29: 42.209534 | AB29: 42.098293 | AC29: 42.011837 | AD29: 41.942982 | AE29: 41.895203 | AF29: -0.007825
A30: RKI000:ea_TotalEnergyCo | B30: Delivered Energy Consumption | C30: 51.710773 | D30: 50.901363 | E30: 48.893349 | F30: 48.475307 | G30: 48.075733 | H30: 47.675148 | I30: 47.225948 | J30: 46.710258 | K30: 46.156193 | L30: 45.590298 | M30: 45.041325 | N30: 44.554535 | O30: 44.067314 | P30: 43.648884 | Q30: 43.271141 | R30: 42.923088 | S30: 42.566601 | T30: 42.233379 | U30: 41.907867 | V30: 41.598656 | W30: 41.319248 | X30: 41.069218 | Y30: 40.845627 | Z30: 40.632603 | AA30: 40.419212 | AB30: 40.233921 | AC30: 40.070381 | AD30: 39.923134 | AE30: 39.795025 | AF30: -0.009311
B32: Energy Consumption by Fuel
B33: Electricity 1/
A34: RKI000:fa_SpaceHeating | B34: Space Heating | C34: 0.74562 | D34: 0.744025 | E34: 0.657572 | F34: 0.656949 | G34: 0.655732 | H34: 0.653215 | I34: 0.649408 | J34: 0.644338 | K34: 0.637851 | L34: 0.630493 | M34: 0.623023 | N34: 0.615132 | O34: 0.606908 | P34: 0.599838 | Q34: 0.593122 | R34: 0.586547 | S34: 0.579423 | T34: 0.572275 | U34: 0.565611 | V34: 0.559325 | W34: 0.553414 | X34: 0.54783 | Y34: 0.542214 | Z34: 0.536676 | AA34: 0.531381 | AB34: 0.526393 | AC34: 0.521432 | AD34: 0.516688 | AE34: 0.512384 | AF34: -0.013309
A35: RKI000:fa_SpaceCooling | B35: Space Cooling | C35: 0.853587 | D35: 0.735192 | E35: 0.890909 | F35: 0.91105 | G35: 0.930181 | H35: 0.950142 | I35: 0.969709 | J35: 0.988224 | K35: 1.004471 | L35: 1.019774 | M35: 1.036202 | N35: 1.052583 | O35: 1.069291 | P35: 1.088333 | Q35: 1.109122 | R35: 1.130924 | S35: 1.152515 | T35: 1.174549 | U35: 1.196908 | V35: 1.219416 | W35: 1.242558 | X35: 1.266365 | Y35: 1.29112 | Z35: 1.3168 | AA35: 1.344624 | AB35: 1.373569 | AC35: 1.403082 | AD35: 1.432529 | AE35: 1.463148 | AF35: 0.019433
A36: RKI000:fa_WaterHeating | B36: Water Heating | C36: 0.599797 | D36: 0.598845 | E36: 0.598786 | F36: 0.599582 | G36: 0.599536 | H36: 0.599125 | I36: 0.59802 | J36: 0.596113 | K36: 0.593223 | L36: 0.589911 | M36: 0.586847 | N36: 0.586124 | O36: 0.586146 | P36: 0.588552 | Q36: 0.591464 | R36: 0.594365 | S36: 0.596931 | T36: 0.599321 | U36: 0.601795 | V36: 0.604464 | W36: 0.607404 | X36: 0.610584 | Y36: 0.613738 | Z36: 0.616835 | AA36: 0.620251 | AB36: 0.623921 | AC36: 0.627667 | AD36: 0.631618 | AE36: 0.63608 | AF36: 0.0021
A37: RKI000:fa_Refrigeration | B37: Refrigeration | C37: 0.295558 | D37: 0.293987 | E37: 0.292668 | F37: 0.29163 | G37: 0.290783 | H37: 0.290158 | I37: 0.289778 | J37: 0.289615 | K37: 0.289659 | L37: 0.289986 | M37: 0.29063 | N37: 0.29157 | O37: 0.292795 | P37: 0.294343 | Q37: 0.296242 | R37: 0.298447 | S37: 0.30096 | T37: 0.303745 | U37: 0.306848 | V37: 0.310249 | W37: 0.313888 | X37: 0.317482 | Y37: 0.321024 | Z37: 0.324507 | AA37: 0.327915 | AB37: 0.33125 | AC37: 0.334496 | AD37: 0.337645 | AE37: 0.340702 | AF37: 0.00509
A38: RKI000:fa_Cooking | B38: Cooking | C38: 0.055863 | D38: 0.056202 | E38: 0.056536 | F38: 0.056875 | G38: 0.057205 | H38: 0.05753 | I38: 0.057848 | J38: 0.058138 | K38: 0.058391 | L38: 0.058604 | M38: 0.058781 | N38: 0.058966 | O38: 0.05917 | P38: 0.059404 | Q38: 0.05968 | R38: 0.059996 | S38: 0.060304 | T38: 0.060601 | U38: 0.060895 | V38: 0.061182 | W38: 0.061454 | X38: 0.061714 | Y38: 0.061964 | Z38: 0.062203 | AA38: 0.062434 | AB38: 0.062659 | AC38: 0.06288 | AD38: 0.063098 | AE38: 0.063319 | AF38: 0.004485
A39: RKI000:fa_ClothesDryers | B39: Clothes Dryers | C39: 0.222467 | D39: 0.227024 | E39: 0.231891 | F39: 0.237295 | G39: 0.242448 | H39: 0.247266 | I39: 0.251793 | J39: 0.25596 | K39: 0.259671 | L39: 0.263071 | M39: 0.266436 | N39: 0.269392 | O39: 0.272342 | P39: 0.275723 | Q39: 0.279342 | R39: 0.282799 | S39: 0.285963 | T39: 0.289075 | U39: 0.292206 | V39: 0.295411 | W39: 0.298723 | X39: 0.30216 | Y39: 0.305635 | Z39: 0.309109 | AA39: 0.31273 | AB39: 0.31651 | AC39: 0.320307 | AD39: 0.324172 | AE39: 0.328278 | AF39: 0.013993
A40: RKI000:fa_Freezers | B40: Freezers | C40: 0.069007 | D40: 0.06885 | E40: 0.068687 | F40: 0.068516 | G40: 0.068318 | H40: 0.068105 | I40: 0.067922 | J40: 0.067761 | K40: 0.067615 | L40: 0.067486 | M40: 0.067377 | N40: 0.067287 | O40: 0.067216 | P40: 0.067169 | Q40: 0.067159 | R40: 0.067178 | S40: 0.067229 | T40: 0.067311 | U40: 0.067431 | V40: 0.067596 | W40: 0.067794 | X40: 0.068036 | Y40: 0.068326 | Z40: 0.068666 | AA40: 0.069053 | AB40: 0.069481 | AC40: 0.069904 | AD40: 0.070319 | AE40: 0.070729 | AF40: 0.000881
A41: RKI000:fa_Lighting | B41: Lighting | C41: 0.22927 | D41: 0.21316 | E41: 0.206794 | F41: 0.205129 | G41: 0.2052 | H41: 0.206404 | I41: 0.20833 | J41: 0.210226 | K41: 0.209704 | L41: 0.209164 | M41: 0.208855 | N41: 0.208568 | O41: 0.208536 | P41: 0.209016 | Q41: 0.209627 | R41: 0.210178 | S41: 0.210558 | T41: 0.210954 | U41: 0.207703 | V41: 0.205012 | W41: 0.202911 | X41: 0.201467 | Y41: 0.200848 | Z41: 0.20064 | AA41: 0.200592 | AB41: 0.20073 | AC41: 0.200991 | AD41: 0.201423 | AE41: 0.202056 | AF41: -0.004503
A42: RKI000:fa_ClothesWasher | B42: Clothes Washers 2/ | C42: 0.037489 | D42: 0.037813 | E42: 0.038144 | F42: 0.038486 | G42: 0.038827 | H42: 0.039168 | I42: 0.039519 | J42: 0.039875 | K42: 0.040246 | L42: 0.040617 | M42: 0.040992 | N42: 0.041365 | O42: 0.041733 | P42: 0.042099 | Q42: 0.042465 | R42: 0.042828 | S42: 0.043187 | T42: 0.043542 | U42: 0.043898 | V42: 0.044252 | W42: 0.044599 | X42: 0.044942 | Y42: 0.045282 | Z42: 0.045619 | AA42: 0.045952 | AB42: 0.046283 | AC42: 0.046611 | AD42: 0.046936 | AE42: 0.047258 | AF42: 0.008305
A43: RKI000:fa_Dishwashers | B43: Dishwashers 2/ | C43: 0.027618 | D43: 0.028064 | E43: 0.028506 | F43: 0.028945 | G43: 0.02937 | H43: 0.029782 | I43: 0.030233 | J43: 0.030722 | K43: 0.031242 | L43: 0.031797 | M43: 0.032392 | N43: 0.033027 | O43: 0.033702 | P43: 0.034373 | Q43: 0.035043 | R43: 0.03571 | S43: 0.036375 | T43: 0.037036 | U43: 0.037698 | V43: 0.038359 | W43: 0.039015 | X43: 0.039667 | Y43: 0.040316 | Z43: 0.040962 | AA43: 0.041605 | AB43: 0.042245 | AC43: 0.042882 | AD43: 0.043514 | AE43: 0.044143 | AF43: 0.01689
A44: RKI000:fa_ColorTelevisi | B44: Televisions and Related Equipment 3/ | C44: 0.185092 | D44: 0.181559 | E44: 0.178365 | F44: 0.175692 | G44: 0.172951 | H44: 0.170143 | I44: 0.167198 | J44: 0.164139 | K44: 0.160987 | L44: 0.157867 | M44: 0.154866 | N44: 0.151867 | O44: 0.148998 | P44: 0.146585 | Q44: 0.144473 | R44: 0.142566 | S44: 0.14076 | T44: 0.139189 | U44: 0.13791 | V44: 0.136911 | W44: 0.136207 | X44: 0.135755 | Y44: 0.135537 | Z44: 0.135552 | AA44: 0.135802 | AB44: 0.136265 | AC44: 0.13685 | AD44: 0.137593 | AE44: 0.138527 | AF44: -0.010296
A45: RKI000:fa_PersonalCompu | B45: Computers and Related Equipment 4/ | C45: 0.120106 | D45: 0.118562 | E45: 0.116931 | F45: 0.115363 | G45: 0.113493 | H45: 0.111328 | I45: 0.108857 | J45: 0.106117 | K45: 0.103168 | L45: 0.100088 | M45: 0.09698 | N45: 0.093786 | O45: 0.09061 | P45: 0.087647 | Q45: 0.084848 | R45: 0.082133 | S45: 0.079493 | T45: 0.077008 | U45: 0.074726 | V45: 0.072652 | W45: 0.070825 | X45: 0.069227 | Y45: 0.067875 | Z45: 0.066753 | AA45: 0.065956 | AB45: 0.065417 | AC45: 0.065087 | AD45: 0.064993 | AE45: 0.065107 | AF45: -0.021632
... A50: RKI000:fa_PurchasedElec | B50: Purchased Electricity | C50: 5.147618 | D50: 5.046671 | E50: 5.113911 | F50: 5.157499 | G50: 5.199634 | H50: 5.245647 | I50: 5.28379 | J50: 5.31335 | K50: 5.334268 | L50: 5.351949 | M50: 5.371014 | N50: 5.391346 | O50: 5.410297 | P50: 5.442602 | Q50: 5.480425 | R50: 5.521421 | S50: 5.559047 | T50: 5.597267 | U50: 5.6349 | V50: 5.674541 | W50: 5.718532 | X50: 5.765529 | Y50: 5.815574 | Z50: 5.868124 | AA50: 5.925225 | AB50: 5.986255 | AC50: 6.048272 | AD50: 6.112339 | AE50: 6.182475 | AF50: 0.006564
B52: Natural Gas
A53: RKI000:ga_SpaceHeating | B53: Space Heating | C53: 3.73693 | D53: 3.786134 | E53: 3.524206 | F53: 3.534772 | G53: 3.540792 | H53: 3.53828 | I53: 3.529304 | J53: 3.510945 | K53: 3.487897 | L53: 3.462235 | M53: 3.436536 | N53: 3.41919 | O53: 3.398954 | P53: 3.379413 | Q53: 3.362053 | R53: 3.346112 | S53: 3.329438 | T53: 3.314799 | U53: 3.301509 | V53: 3.288682 | W53: 3.276622 | X53: 3.266367 | Y53: 3.257648 | Z53: 3.247816 | AA53: 3.234627 | AB53: 3.222775 | AC53: 3.212637 | AD53: 3.202551 | AE53: 3.191122 | AF53: -0.005623
...

Sheet AEO 2022 Table 4
B1: ref2021.d113020a | C1: 2020 | D1: 2021 | E1: 2022 | F1: 2023 | G1: 2024 | H1: 2025 | I1: 2026 | J1: 2027 | K1: 2028 | L1: 2029 | M1: 2030 | N1: 2031 | O1: 2032 | P1: 2033 | Q1: 2034 | R1: 2035 | S1: 2036 | T1: 2037 | U1: 2038 | V1: 2039 | W1: 2040 | X1: 2041 | Y1: 2042 | Z1: 2043 | AA1: 2044 | AB1: 2045 | AC1: 2046 | AD1: 2047 | AE1: 2048 | AF1: 2049 | AG1: 2050
C3: Report | D3: Annual Energy Outlook 2021
C4: Scenario | D4: ref2021 | G4: Reference case
C5: Datekey | D5: d113020a
C6: Release Date | E6: January 2021
A10: RKI000 | B10: 4. Residential Sector Key Indicators and Consumption | AH10: Compound
B11: (quadrillion Btu, unless otherwise noted) | AH11: Growth
AH12: 2020-2050
B13: Key Indicators and Consumption | C13: 2020 | D13: 2021 | E13: 2022 | F13: 2023 | G13: 2024 | H13: 2025 | I13: 2026 | J13: 2027 | K13: 2028 | L13: 2029 | M13: 2030 | N13: 2031 | O13: 2032 | P13: 2033 | Q13: 2034 | R13: 2035 | S13: 2036 | T13: 2037 | U13: 2038 | V13: 2039 | W13: 2040 | X13: 2041 | Y13: 2042 | Z13: 2043 | AA13: 2044 | AB13: 2045 | AC13: 2046 | AD13: 2047 | AE13: 2048 | AF13: 2049 | AG13: 2050 | AH13: (percent)
B15: Key Indicators
B16: Households (millions)
A17: RKI000:ba_Single-Family | B17: Single-Family | C17: 84.750443 | D17: 85.593697 | E17: 86.438118 | F17: 87.263756 | G17: 88.078079 | H17: 88.908073 | I17: 89.73056 | J17: 90.531715 | K17: 91.318695 | L17: 92.095459 | M17: 92.86319 | N17: 93.620483 | O17: 94.374603 | P17: 95.112335 | Q17: 95.831551 | R17: 96.548988 | S17: 97.25177 | T17: 97.942635 | U17: 98.626312 | V17: 99.30011 | W17: 99.974014 | X17: 100.64284 | Y17: 101.30791 | Z17: 101.97792 | AA17: 102.65668 | AB17: 103.34093 | AC17: 104.02688 | AD17: 104.70899 | AE17: 105.38845 | AF17: 106.0673 | AG17: 106.7465 | AH17: 0.007721
A18: RKI000:ba_Multifamily | B18: Multifamily | C18: 31.968704 | D18: 32.227859 | E18: 32.481697 | F18: 32.722111 | G18: 32.964333 | H18: 33.21796 | I18: 33.469734 | J18: 33.709866 | K18: 33.941967 | L18: 34.169193 | M18: 34.396915 | N18: 34.621048 | O18: 34.840218 | P18: 35.051422 | Q18: 35.255718 | R18: 35.458874 | S18: 35.655647 | T18: 35.851791 | U18: 36.050476 | V18: 36.251507 | W18: 36.451229 | X18: 36.649303 | Y18: 36.850163 | Z18: 37.053848 | AA18: 37.255768 | AB18: 37.454777 | AC18: 37.649311 | AD18: 37.844074 | AE18: 38.040798 | AF18: 38.240433 | AG18: 38.443745 | AH18: 0.006167
A19: RKI000:ba_MobileHomes | B19: Mobile Homes | C19: 6.663464 | D19: 6.648386 | E19: 6.634101 | F19: 6.620814 | G19: 6.610516 | H19: 6.604194 | I19: 6.605052 | J19: 6.602856 | K19: 6.597648 | L19: 6.586789 | M19: 6.571608 | N19: 6.555332 | O19: 6.53966 | P19: 6.524387 | Q19: 6.51122 | R19: 6.502039 | S19: 6.493465 | T19: 6.483514 | U19: 6.472738 | V19: 6.462773 | W19: 6.455459 | X19: 6.449031 | Y19: 6.444581 | Z19: 6.44286 | AA19: 6.443233 | AB19: 6.444091 | AC19: 6.442573 | AD19: 6.438198 | AE19: 6.432255 | AF19: 6.425656 | AG19: 6.41708 | AH19: -0.001255
A20: RKI000:ba_Total | B20: Total | C20: 123.38261 | D20: 124.46994 | E20: 125.55392 | F20: 126.60668 | G20: 127.65293 | H20: 128.73022 | I20: 129.80534 | J20: 130.84444 | K20: 131.85831 | L20: 132.85144 | M20: 133.83171 | N20: 134.79686 | O20: 135.75447 | P20: 136.68814 | Q20: 137.59848 | R20: 138.5099 | S20: 139.40088 | T20: 140.27795 | U20: 141.14952 | V20: 142.01439 | W20: 142.88071 | X20: 143.74118 | Y20: 144.60265 | Z20: 145.47463 | AA20: 146.35568 | AB20: 147.23979 | AC20: 148.11876 | AD20: 148.99127 | AE20: 149.8615 | AF20: 150.7334 | AG20: 151.60733 | AH20: 0.00689
A22: RKI000:ca_AverageHouseS | B22: Average House Square Footage | C22: 1789.3104 | D22: 1795.3578 | E22: 1801.4011 | F22: 1807.4683 | G22: 1813.4492 | H22: 1819.314 | I22: 1825.1085 | J22: 1830.9334 | K22: 1836.7738 | L22: 1842.624 | M22: 1848.4427 | N22: 1854.2422 | O22: 1860.0408 | P22: 1865.8373 | Q22: 1871.6088 | R22: 1877.3394 | S22: 1883.0591 | T22: 1888.739 | U22: 1894.366 | V22: 1899.9277 | W22: 1905.464 | X22: 1910.9752 | Y22: 1916.4247 | Z22: 1921.8323 | AA22: 1927.2421 | AB22: 1932.6647 | AC22: 1938.1177 | AD22: 1943.5543 | AE22: 1948.9592 | AF22: 1954.3284 | AG22: 1959.6641 | AH22: 0.003036
B24: Energy Intensity
B25: (million Btu per household)
A26: RKI000:da_DeliveredEner | B26: Gross End-use Consumption 1/ | C26: 92.738022 | D26: 91.586784 | E26: 91.880096 | F26: 91.11187 | G26: 90.4701 | H26: 89.770355 | I26: 89.065895 | J26: 88.379463 | K26: 87.773743 | L26: 87.20845 | M26: 86.633553 | N26: 86.134857 | O26: 85.702553 | P26: 85.281403 | Q26: 84.91935 | R26: 84.596985 | S26: 84.326233 | T26: 84.093864 | U26: 83.883667 | V26: 83.681618 | W26: 83.477539 | X26: 83.281693 | Y26: 83.101692 | Z26: 82.956818 | AA26: 82.820435 | AB26: 82.683517 | AC26: 82.575638 | AD26: 82.460793 | AE26: 82.357018 | AF26: 82.265587 | AG26: 82.199287 | AH26: -0.004013
A27: RKI000:da_TotalEnergyCo | B27: Delivered Energy Consumption | C27: 92.104782 | D27: 90.868225 | E27: 91.091621 | F27: 90.256592 | G27: 89.550323 | H27: 88.786705 | I27: 88.017479 | J27: 87.266571 | K27: 86.596436 | L27: 85.966888 | M27: 85.326958 | N27: 84.76181 | O27: 84.262253 | P27: 83.772934 | Q27: 83.341469 | R27: 82.949066 | S27: 82.607262 | T27: 82.303116 | U27: 82.020409 | V27: 81.745148 | W27: 81.466759 | X27: 81.195541 | Y27: 80.938629 | Z27: 80.715416 | AA27: 80.499275 | AB27: 80.280556 | AC27: 80.088921 | AD27: 79.888603 | AE27: 79.697121 | AF27: 79.516228 | AG27: 79.358765 | AH27: -0.004953
B28: (thousand Btu per square foot)
A29: RKI000:ea_DeliveredEner | B29: Gross End-use Consumption 1/ | C29: 51.828918 | D29: 51.013107 | E29: 51.004799 | F29: 50.408558 | G29: 49.888409 | H29: 49.342972 | I29: 48.800327 | J29: 48.270168 | K29: 47.786911 | L29: 47.3284 | M29: 46.868401 | N29: 46.452862 | O29: 46.07563 | P29: 45.706776 | Q29: 45.372383 | R29: 45.062168 | S29: 44.781513 | T29: 44.523811 | U29: 44.280605 | V29: 44.044632 | W29: 43.809559 | X29: 43.58073 | Y29: 43.362877 | Z29: 43.165482 | AA29: 42.973553 | AB29: 42.782131 | AC29: 42.606102 | AD29: 42.42783 | AE29: 42.25692 | AF29: 42.094044 | AG29: 41.945602 | AH29: -0.007028
A30: RKI000:ea_TotalEnergyCo | B30: Delivered Energy Consumption | C30: 51.475014 | D30: 50.612877 | E30: 50.567093 | F30: 49.935368 | G30: 49.381214 | H30: 48.802299 | I30: 48.225887 | J30: 47.662338 | K30: 47.145943 | L30: 46.654602 | M30: 46.161537 | N30: 45.712376 | O30: 45.301292 | P30: 44.898304 | Q30: 44.529324 | R30: 44.184376 | S30: 43.868649 | T30: 43.575695 | U30: 43.297024 | V30: 43.025398 | W30: 42.754288 | X30: 42.489059 | Y30: 42.234184 | Z30: 41.999199 | AA30: 41.769157 | AB30: 41.538795 | AC30: 41.323044 | AD30: 41.104385 | AE30: 40.892143 | AF30: 40.687241 | AG30: 40.496109 | AH30: -0.007964
B32: Energy Consumption by Fuel
B33: Electricity 1/
A34: RKI000:fa_SpaceHeating | B34: Space Heating | C34: 0.648975 | D34: 0.698359 | E34: 0.705675 | F34: 0.700579 | G34: 0.697104 | H34: 0.693829 | I34: 0.689615 | J34: 0.684867 | K34: 0.680389 | L34: 0.675741 | M34: 0.671278 | N34: 0.667093 | O34: 0.663156 | P34: 0.658869 | Q34: 0.654543 | R34: 0.650647 | S34: 0.646979 | T34: 0.643454 | U34: 0.640012 | V34: 0.636487 | W34: 0.633042 | X34: 0.629411 | Y34: 0.62568 | Z34: 0.622594 | AA34: 0.61931 | AB34: 0.61588 | AC34: 0.612716 | AD34: 0.609319 | AE34: 0.605898 | AF34: 0.602859 | AG34: 0.60021 | AH34: -0.0026
A35: RKI000:fa_SpaceCooling | B35: Space Cooling | C35: 0.805393 | D35: 0.766594 | E35: 0.861182 | F35: 0.874083 | G35: 0.887777 | H35: 0.902099 | I35: 0.915943 | J35: 0.929715 | K35: 0.944123 | L35: 0.958867 | M35: 0.974193 | N35: 0.990744 | O35: 1.008481 | P35: 1.025846 | Q35: 1.043779 | R35: 1.062911 | S35: 1.0832 | T35: 1.105031 | U35: 1.127032 | V35: 1.149105 | W35: 1.171538 | X35: 1.19348 | Y35: 1.216245 | Z35: 1.239965 | AA35: 1.264531 | AB35: 1.288882 | AC35: 1.313945 | AD35: 1.338515 | AE35: 1.364224 | AF35: 1.390646 | AG35: 1.418784 | AH35: 0.019053
A36: RKI000:fa_WaterHeating | B36: Water Heating | C36: 0.607549 | D36: 0.610272 | E36: 0.612486 | F36: 0.613276 | G36: 0.614697 | H36: 0.615558 | I36: 0.615516 | J36: 0.615339 | K36: 0.615263 | L36: 0.615159 | M36: 0.615446 | N36: 0.616189 | O36: 0.617558 | P36: 0.61869 | Q36: 0.620048 | R36: 0.621836 | S36: 0.624211 | T36: 0.626908 | U36: 0.629862 | V36: 0.632567 | W36: 0.635049 | X36: 0.637403 | Y36: 0.639668 | Z36: 0.642614 | AA36: 0.645529 | AB36: 0.648506 | AC36: 0.651785 | AD36: 0.655048 | AE36: 0.658462 | AF36: 0.662375 | AG36: 0.666767 | AH36: 0.003105
A37: RKI000:fa_Refrigeration | B37: Refrigeration | C37: 0.297571 | D37: 0.295346 | E37: 0.293784 | F37: 0.292026 | G37: 0.290424 | H37: 0.289083 | I37: 0.287936 | J37: 0.286922 | K37: 0.286075 | L37: 0.285419 | M37: 0.285 | N37: 0.284881 | O37: 0.285089 | P37: 0.285596 | Q37: 0.286414 | R37: 0.287589 | S37: 0.289068 | T37: 0.290839 | U37: 0.292919 | V37: 0.295274 | W37: 0.297926 | X37: 0.300858 | Y37: 0.304065 | Z37: 0.307271 | AA37: 0.310466 | AB37: 0.313629 | AC37: 0.316735 | AD37: 0.319768 | AE37: 0.322732 | AF37: 0.325633 | AG37: 0.32847 | AH37: 0.003299
A38: RKI000:fa_Cooking | B38: Cooking | C38: 0.055007 | D38: 0.055161 | E38: 0.055458 | F38: 0.055738 | G38: 0.056009 | H38: 0.056286 | I38: 0.056556 | J38: 0.056803 | K38: 0.057032 | L38: 0.057229 | M38: 0.057396 | N38: 0.057526 | O38: 0.057621 | P38: 0.057725 | Q38: 0.057854 | R38: 0.058017 | S38: 0.058215 | T38: 0.05845 | U38: 0.058677 | V38: 0.058894 | W38: 0.059105 | X38: 0.059305 | Y38: 0.059498 | Z38: 0.059687 | AA38: 0.059871 | AB38: 0.06005 | AC38: 0.060221 | AD38: 0.060386 | AE38: 0.060551 | AF38: 0.060719 | AG38: 0.060893 | AH38: 0.003394
A39: RKI000:fa_ClothesDryers | B39: Clothes Dryers | C39: 0.216421 | D39: 0.220387 | E39: 0.223927 | F39: 0.227024 | G39: 0.230421 | H39: 0.233791 | I39: 0.236868 | J39: 0.239735 | K39: 0.24266 | L39: 0.245586 | M39: 0.248642 | N39: 0.251748 | O39: 0.254999 | P39: 0.258105 | Q39: 0.261348 | R39: 0.264724 | S39: 0.268346 | T39: 0.271985 | U39: 0.27562 | V39: 0.279211 | W39: 0.282735 | X39: 0.286192 | Y39: 0.289572 | Z39: 0.293211 | AA39: 0.296797 | AB39: 0.300345 | AC39: 0.303959 | AD39: 0.307505 | AE39: 0.311091 | AF39: 0.314901 | AG39: 0.318894 | AH39: 0.013005
A40: RKI000:fa_Freezers | B40: Freezers | C40: 0.069181 | D40: 0.068847 | E40: 0.068696 | F40: 0.068514 | G40: 0.068303 | H40: 0.06808 | I40: 0.067833 | J40: 0.067552 | K40: 0.067286 | L40: 0.067036 | M40: 0.066805 | N40: 0.066594 | O40: 0.066407 | P40: 0.066239 | Q40: 0.066095 | R40: 0.065983 | S40: 0.0659 | T40: 0.065845 | U40: 0.065824 | V40: 0.065833 | W40: 0.065878 | X40: 0.065963 | Y40: 0.066088 | Z40: 0.066264 | AA40: 0.066497 | AB40: 0.066784 | AC40: 0.067123 | AD40: 0.067501 | AE40: 0.067876 | AF40: 0.068251 | AG40: 0.068624 | AH40: -0.00027
A41: RKI000:fa_Lighting | B41: Lighting | C41: 0.211247 | D41: 0.204709 | E41: 0.202325 | F41: 0.201331 | G41: 0.201363 | H41: 0.199969 | I41: 0.198834 | J41: 0.198385 | K41: 0.198653 | L41: 0.199213 | M41: 0.197419 | N41: 0.196248 | O41: 0.195597 | P41: 0.195114 | Q41: 0.194978 | R41: 0.195143 | S41: 0.195525 | T41: 0.196 | U41: 0.196543 | V41: 0.197114 | W41: 0.1944 | X41: 0.192285 | Y41: 0.190588 | Z41: 0.189504 | AA41: 0.18876 | AB41: 0.188243 | AC41: 0.187897 | AD41: 0.187552 | AE41: 0.187251 | AF41: 0.187096 | AG41: 0.187254 | AH41: -0.004011
A42: RKI000:fa_ClothesWasher | B42: Clothes Washers 2/ | C42: 0.036779 | D42: 0.037026 | E42: 0.037373 | F42: 0.03771 | G42: 0.038044 | H42: 0.038387 | I42: 0.038727 | J42: 0.039055 | K42: 0.039377 | L42: 0.039694 | M42: 0.040025 | N42: 0.040352 | O42: 0.040679 | P42: 0.041 | Q42: 0.041315 | R42: 0.041632 | S42: 0.041942 | T42: 0.042249 | U42: 0.042553 | V42: 0.042854 | W42: 0.043155 | X42: 0.043454 | Y42: 0.043751 | Z42: 0.044052 | AA42: 0.044355 | AB42: 0.044659 | AC42: 0.044962 | AD42: 0.045263 | AE42: 0.045562 | AF42: 0.045862 | AG42: 0.046163 | AH42: 0.007603
A43: RKI000:fa_Dishwashers | B43: Dishwashers 2/ | C43: 0.026617 | D43: 0.026992 | E43: 0.02743 | F43: 0.027852 | G43: 0.028262 | H43: 0.028667 | I43: 0.029058 | J43: 0.029425 | K43: 0.029825 | L43: 0.030258 | M43: 0.030725 | N43: 0.031229 | O43: 0.031774 | P43: 0.032359 | Q43: 0.032987 | R43: 0.033613 | S43: 0.034234 | T43: 0.03485 | U43: 0.035463 | V43: 0.036073 | W43: 0.036682 | X43: 0.037289 | Y43: 0.037894 | Z43: 0.038501 | AA43: 0.039109 | AB43: 0.039717 | AC43: 0.040323 | AD43: 0.040927 | AE43: 0.041529 | AF43: 0.04213 | AG43: 0.042731 | AH43: 0.015905
A44: RKI000:fa_ColorTelevisi | B44: Televisions and Related Equipment 3/ | C44: 0.209133 | D44: 0.205207 | E44: 0.202543 | F44: 0.200232 | G44: 0.198892 | H44: 0.198295 | I44: 0.19823 | J44: 0.19879 | K44: 0.200061 | L44: 0.202003 | M44: 0.204636 | N44: 0.207823 | O44: 0.2116 | P44: 0.215644 | Q44: 0.220005 | R44: 0.224683 | S44: 0.22967 | T44: 0.234747 | U44: 0.239803 | V44: 0.244645 | W44: 0.249117 | X44: 0.253057 | Y44: 0.25642 | Z44: 0.259709 | AA44: 0.262872 | AB44: 0.265931 | AC44: 0.268959 | AD44: 0.271838 | AE44: 0.274645 | AF44: 0.277515 | AG44: 0.280476 | AH44: 0.009832
A45: RKI000:fa_PersonalCompu | B45: Computers and Related Equipment 4/ | C45: 0.086664 | D45: 0.083833 | E45: 0.081495 | F45: 0.079249 | G45: 0.077311 | H45: 0.07555 | I45: 0.073889 | J45: 0.072344 | K45: 0.07094 | L45: 0.069648 | M45: 0.068455 | N45: 0.067301 | O45: 0.066194 | P45: 0.065015 | Q45: 0.063786 | R45: 0.062497 | S45: 0.061143 | T45: 0.059822 | U45: 0.058526 | V45: 0.05722 | W45: 0.055892 | X45: 0.054535 | Y45: 0.053136 | Z45: 0.051763 | AA45: 0.050343 | AB45: 0.048862 | AC45: 0.047324 | AD45: 0.045688 | AE45: 0.043971 | AF45: 0.042151 | AG45: 0.040223 | AH45: -0.025262
... A50: RKI000:fa_PurchasedElec | B50: Purchased Electricity | C50: 5.052812 | D50: 5.085636 | E50: 5.091427 | F50: 5.101829 | G50: 5.115852 | H50: 5.13157 | I50: 5.153872 | J50: 5.175931 | K50: 5.201604 | L50: 5.229164 | M50: 5.258111 | N50: 5.290325 | O50: 5.326496 | P50: 5.361025 | Q50: 5.400707 | R50: 5.442327 | S50: 5.487264 | T50: 5.534616 | U50: 5.582767 | V50: 5.630761 | W50: 5.67496 | X50: 5.718818 | Y50: 5.76369 | Z50: 5.813079 | AA50: 5.862924 | AB50: 5.91239 | AC50: 5.963741 | AD50: 6.01394 | AE50: 6.065893 | AF50: 6.12035 | AG50: 6.178349 | AH50: 0.006726
B52: Natural Gas
A53: RKI000:ga_SpaceHeating | B53: Space Heating | C53: 3.527199 | D53: 3.405752 | E53: 3.53601 | F53: 3.523748 | G53: 3.517663 | H53: 3.505749 | I53: 3.487102 | J53: 3.467178 | K53: 3.44851 | L53: 3.429626 | M53: 3.408028 | N53: 3.390023 | O53: 3.374133 | P53: 3.358309 | Q53: 3.342819 | R53: 3.329606 | S53: 3.317669 | T53: 3.306064 | U53: 3.295281 | V53: 3.284991 | W53: 3.276392 | X53: 3.267857 | Y53: 3.259522 | Z53: 3.251126 | AA53: 3.243215 | AB53: 3.234619 | AC53: 3.226072 | AD53: 3.216632 | AE53: 3.206716 | AF53: 3.195817 | AG53: 3.184887 | AH53: -0.003397
...

Sheet AEO 2026 Table 4
A1: Table 4. Residential Sector Key Indicators and Consumption
A2: https://www.eia.gov/outlooks/aeo/data/browser/#/?id=4-AEO2026&cases=electrnp&sourcekey=0
A3: Thu Apr 23 2026 14:30:24 GMT-0700 (Pacific Daylight Time)
A4: Source: U.S. Energy Information Administration
B5: full name | C5: api key | D5: units | E5: 2025 | F5: 2026 | G5: 2027 | H5: 2028 | I5: 2029 | J5: 2030 | K5: 2031 | L5: 2032 | M5: 2033 | N5: 2034 | O5: 2035 | P5: 2036 | Q5: 2037 | R5: 2038 | S5: 2039 | T5: 2040 | U5: 2041 | V5: 2042 | W5: 2043 | X5: 2044 | Y5: 2045 | Z5: 2046 | AA5: 2047 | AB5: 2048 | AC5: 2049 | AD5: 2050 | AE5: Growth (2025-2050)
A6: Key Indicators
A7: Households (millions)
A8: Single-Family | B8: Residential: Key Indicators: Households: Single-Family: Alternative Electricity and Transportation | C8: AEO.2026.ELECTRNP.KEI_HHD_RESD_SFR_NA_NA_USA_MILL.A | D8: millions | E8: 89.551808 | F8: 90.49932 | G8: 91.445952 | H8: 92.375528 | I8: 93.308328 | J8: 94.24312 | K8: 95.158208 | L8: 96.071576 | M8: 96.973696 | N8: 97.85328 | O8: 98.71644 | P8: 99.555664 | Q8: 100.3796 | R8: 101.17977 | S8: 101.94854 | T8: 102.6897 | U8: 103.40026 | V8: 104.0939 | W8: 104.76102 | X8: 105.40485 | Y8: 106.04946 | Z8: 106.69842 | AA8: 107.34532 | AB8: 107.99104 | AC8: 108.63598 | AD8: 109.28382 | AE8: 0.008
A9: Multifamily | B9: Residential: Key Indicators: Households: Multifamily: Alternative Electricity and Transportation | C9: AEO.2026.ELECTRNP.KEI_HHD_RESD_MFR_NA_NA_USA_MILL.A | D9: millions | E9: 34.432312 | F9: 34.836668 | G9: 35.242792 | H9: 35.639104 | I9: 36.037196 | J9: 36.453672 | K9: 36.90364 | L9: 37.355532 | M9: 37.797056 | N9: 38.222764 | O9: 38.636756 | P9: 39.039476 | Q9: 39.397844 | R9: 39.73052 | S9: 40.040472 | T9: 40.33182 | U9: 40.601424 | V9: 40.85396 | W9: 41.099856 | X9: 41.347656 | Y9: 41.597008 | Z9: 41.846876 | AA9: 42.095096 | AB9: 42.342736 | AC9: 42.590232 | AD9: 42.838628 | AE9: 0.009
A10: Mobile Homes | B10: Residential: Key Indicators: Households: Mobile Homes: Alternative Electricity and Transportation | C10: AEO.2026.ELECTRNP.KEI_HHD_RESD_MBH_NA_NA_USA_MILL.A | D10: millions | E10: 6.745095 | F10: 6.759423 | G10: 6.806991 | H10: 6.858165 | I10: 6.903711 | J10: 6.913014 | K10: 6.915089 | L10: 6.918252 | M10: 6.921087 | N10: 6.923413 | O10: 6.926996 | P10: 6.931356 | Q10: 6.932999 | R10: 6.932745 | S10: 6.927611 | T10: 6.924169 | U10: 6.922683 | V10: 6.921756 | W10: 6.922089 | X10: 6.924877 | Y10: 6.929586 | Z10: 6.934404 | AA10: 6.93933 | AB10: 6.943018 | AC10: 6.946523 | AD10: 6.950291 | AE10: 0.001
A11: Total | B11: Residential: Key Indicators: Households: Total: Alternative Electricity and Transportation | C11: AEO.2026.ELECTRNP.KEI_HHD_RESD_TEN_NA_NA_USA_MILL.A | D11: millions | E11: 130.72922 | F11: 132.09541 | G11: 133.49573 | H11: 134.8728 | I11: 136.24923 | J11: 137.60981 | K11: 138.97694 | L11: 140.34536 | M11: 141.69184 | N11: 142.99946 | O11: 144.28019 | P11: 145.5265 | Q11: 146.71044 | R11: 147.84303 | S11: 148.91662 | T11: 149.94569 | U11: 150.92436 | V11: 151.86962 | W11: 152.78297 | X11: 153.67738 | Y11: 154.57605 | Z11: 155.4797 | AA11: 156.37975 | AB11: 157.27679 | AC11: 158.17273 | AD11: 159.07273 | AE11: 0.008
A12: Average House Square Footage | B12: Residential: Key Indicators: Average House Square Footage: Alternative Electricity and Transportation | C12: AEO.2026.ELECTRNP.KEI_HHD_RESD_NA_NA_NA_USA_SQFT.A | D12: sq ft | E12: 1648.5809 | F12: 1653.8009 | G12: 1658.7534 | H12: 1663.6196 | I12: 1668.3839 | J12: 1673.0569 | K12: 1677.3986 | L12: 1681.6154 | M12: 1685.7919 | N12: 1689.9557 | O12: 1694.0829 | P12: 1698.1729 | Q12: 1702.4686 | R12: 1706.8398 | S12: 1711.274 | T12: 1715.7278 | U12: 1720.2239 | V12: 1724.7522 | W12: 1729.2341 | X12: 1733.6156 | Y12: 1737.9188 | Z12: 1742.1624 | AA12: 1746.3572 | AB12: 1750.5023 | AC12: 1754.593 | AD12: 1758.624 | AE12: 0.003
A13: Energy Intensity
A14: (MMBtu per household)
A15: Gross End-use Consumption | B15: Residential: Household Energy Intensity: Gross End-use Consumption: Alternative Electricity and Transportation | C15: AEO.2026.ELECTRNP.INY_HHD_RESD_DELE_NA_NA_USA_MILLBTUPHOSD.A | D15: MMBtu/household | E15: 89.060958 | F15: 86.654179 | G15: 85.803576 | H15: 85.129928 | I15: 84.070611 | J15: 82.772625 | K15: 81.43822 | L15: 80.199732 | M15: 79.037515 | N15: 78.012084 | O15: 77.086948 | P15: 76.247253 | Q15: 75.471804 | R15: 74.779412 | S15: 74.147297 | T15: 73.529513 | U15: 72.98766 | V15: 72.550301 | W15: 72.19137 | X15: 71.873314 | Y15: 71.554366 | Z15: 71.242594 | AA15: 70.912942 | AB15: 70.590441 | AC15: 70.298459 | AD15: 70.025753 | AE15: -0.01
A16: Delivered Energy Consumption | B16: Residential: Household Energy Intensity: Delivered Energy Consumption: Alternative Electricity and Transportation | C16: AEO.2026.ELECTRNP.INY_HHD_RESD_TEN_NA_NA_USA_MILLBTUPHOSD.A | D16: MMBtu/household | E16: 87.644801 | F16: 85.169031 | G16: 84.24495 | H16: 83.496612 | I16: 82.368483 | J16: 80.999154 | K16: 79.589086 | L16: 78.275952 | M16: 77.036292 | N16: 75.928768 | O16: 74.916513 | P16: 73.985585 | Q16: 73.112308 | R16: 72.31741 | S16: 71.577848 | T16: 70.8491 | U16: 70.192104 | V16: 69.636396 | W16: 69.156582 | X16: 68.713555 | Y16: 68.267577 | Z16: 67.825555 | AA16: 67.362432 | AB16: 66.902169 | AC16: 66.470931 | AD16: 66.055663 | AE16: -0.011
A17: (thousand Btu per square foot)
A18: Gross End-use Consumption | B18: Residential: Energy Intensity per Square Foot: Gross End-use Consumption: Alternative Electricity and Transportation | C18: AEO.2026.ELECTRNP.INY_HHD_RESD_DELE_NA_NA_USA_THBTUPSQFT.A | D18: thousand Btu/sq ft | E18: 54.0228 | F18: 52.396983 | G18: 51.727746 | H18: 51.17151 | I18: 50.390447 | J18: 49.473886 | K18: 48.55031 | L18: 47.692079 | M18: 46.884504 | N18: 46.162207 | O18: 45.503646 | P18: 44.899583 | Q18: 44.330805 | R18: 43.811616 | S18: 43.32871 | T18: 42.856165 | U18: 42.429164 | V18: 42.064188 | W18: 41.747597 | X18: 41.458622 | Y18: 41.172444 | Z18: 40.8932 | AA18: 40.606208 | AB18: 40.32582 | AC18: 40.065393 | AD18: 39.81849 | AE18: -0.012
A19: Delivered Energy Consumption | B19: Residential: Energy Intensity per Square Foot: Delivered Energy Consumption: Alternative Electricity and Transportation | C19: AEO.2026.ELECTRNP.INY_HHD_RESD_TEN_NA_NA_USA_THBTUPSQFT.A | D19: thousand Btu/sq ft | E19: 53.163785 | F19: 51.498963 | G19: 50.788109 | H19: 50.189725 | I19: 49.370221 | J19: 48.413867 | K19: 47.447928 | L19: 46.548072 | M19: 45.697392 | N19: 44.929443 | O19: 44.22246 | P19: 43.567759 | Q19: 42.944878 | R19: 42.369183 | S19: 41.827227 | T19: 41.293905 | U19: 40.804052 | V19: 40.374725 | W19: 39.992608 | X19: 39.635981 | Y19: 39.281223 | Z19: 38.931822 | AA19: 38.573113 | AB19: 38.21884 | AC19: 37.88396 | AD19: 37.560992 | AE19: -0.014
A20: Energy Consumption by Fuel
A21: Electricity
A22: Space Heating | B22: Residential: Electricity: Space Heating: Alternative Electricity and Transportation | C22: AEO.2026.ELECTRNP.CNSM_HHD_RESD_SPH_ELC_NA_USA_QBTU.A | D22: quads | E22: 0.594987 | F22: 0.565591 | G22: 0.56617 | H22: 0.56695 | I22: 0.565817 | J22: 0.562275 | K22: 0.557641 | L22: 0.553019 | M22: 0.548665 | N22: 0.544101 | O22: 0.539627 | P22: 0.535383 | Q22: 0.530849 | R22: 0.526527 | S22: 0.522045 | T22: 0.517517 | U22: 0.512782 | V22: 0.508507 | W22: 0.504388 | X22: 0.500026 | Y22: 0.495959 | Z22: 0.491539 | AA22: 0.48666 | AB22: 0.481831 | AC22: 0.477193 | AD22: 0.472459 | AE22: -0.009
A23: Space Cooling | B23: Residential: Electricity: Space Cooling: Alternative Electricity and Transportation | C23: AEO.2026.ELECTRNP.CNSM_NA_RESD_SPC_ELC_NA_USA_QBTU.A | D23: quads | E23: 0.924574 | F23: 0.983886 | G23: 0.997782 | H23: 1.011565 | I23: 1.022745 | J23: 1.029994 | K23: 1.036595 | L23: 1.044131 | M23: 1.052389 | N23: 1.061989 | O23: 1.072572 | P23: 1.084402 | Q23: 1.097 | R23: 1.11012 | S23: 1.123595 | T23: 1.137956 | U23: 1.153139 | V23: 1.170164 | W23: 1.188274 | X23: 1.206452 | Y23: 1.225277 | Z23: 1.243111 | AA23: 1.260267 | AB23: 1.276902 | AC23: 1.294258 | AD23: 1.31138 | AE23: 0.014
A24: Water Heating | B24: Residential: Electricity: Water Heating: Alternative Electricity and Transportation | C24: AEO.2026.ELECTRNP.CNSM_NA_RESD_WTHT_ELC_NA_USA_QBTU.A | D24: quads | E24: 0.452529 | F24: 0.444829 | G24: 0.439241 | H24: 0.434669 | I24: 0.417931 | J24: 0.396813 | K24: 0.37455 | L24: 0.353889 | M24: 0.334859 | N24: 0.31755 | O24: 0.301886 | P24: 0.288067 | Q24: 0.276008 | R24: 0.265726 | S24: 0.257168 | T24: 0.250335 | U24: 0.24518 | V24: 0.24183 | W24: 0.240263 | X24: 0.238624 | Y24: 0.236984 | Z24: 0.235242 | AA24: 0.233407 | AB24: 0.23158 | AC24: 0.229981 | AD24: 0.228558 | AE24: -0.027
A25: Refrigeration | B25: Residential: Electricity: Refrigeration: Alternative Electricity and Transportation | C25: AEO.2026.ELECTRNP.CNSM_NA_RESD_REFR_ELC_NA_USA_QBTU.A | D25: quads | E25: 0.349563 | F25: 0.348527 | G25: 0.347433 | H25: 0.346209 | I25: 0.345259 | J25: 0.342024 | K25: 0.33903 | L25: 0.336304 | M25: 0.333799 | N25: 0.331468 | O25: 0.329366 | P25: 0.327653 | Q25: 0.326343 | R25: 0.325461 | S25: 0.32499 | T25: 0.324938 | U25: 0.325294 | V25: 0.326072 | W25: 0.327281 | X25: 0.328913 | Y25: 0.33105 | Z25: 0.333714 | AA25: 0.336865 | AB25: 0.340006 | AC25: 0.343129 | AD25: 0.346229 | AE25: 0
A26: Cooking | B26: Residential: Electricity: Cooking: Alternative Electricity and Transportation | C26: AEO.2026.ELECTRNP.CNSM_NA_RESD_CGR_ELC_NA_USA_QBTU.A | D26: quads | E26: 0.068362 | F26: 0.069242 | G26: 0.07015 | H26: 0.071053 | I26: 0.07196 | J26: 0.07286 | K26: 0.07377 | L26: 0.074686 | M26: 0.075595 | N26: 0.076502 | O26: 0.077415 | P26: 0.078332 | Q26: 0.079236 | R26: 0.080074 | S26: 0.080823 | T26: 0.081486 | U26: 0.082052 | V26: 0.082525 | W26: 0.082965 | X26: 0.083381 | Y26: 0.083789 | Z26: 0.084191 | AA26: 0.084584 | AB26: 0.084967 | AC26: 0.085342 | AD26: 0.085709 | AE26: 0.009
A27: Clothes Dryers | B27: Residential: Electricity: Clothes Dryers: Alternative Electricity and Transportation | C27: AEO.2026.ELECTRNP.CNSM_NA_RESD_CDR_ELC_NA_USA_QBTU.A | D27: quads | E27: 0.190333 | F27: 0.190841 | G27: 0.191803 | H27: 0.193076 | I27: 0.193741 | J27: 0.193361 | K27: 0.192361 | L27: 0.191029 | M27: 0.19012 | N27: 0.1896 | O27: 0.189483 | P27: 0.189817 | Q27: 0.190518 | R27: 0.191708 | S27: 0.19336 | T27: 0.195529 | U27: 0.198302 | V27: 0.20107 | W27: 0.20391 | X27: 0.206758 | Y27: 0.209611 | Z27: 0.212328 | AA27: 0.214859 | AB27: 0.217261 | AC27: 0.21971 | AD27: 0.222073 | AE27: 0.006
A28: Freezers | B28: Residential: Electricity: Freezers: Alternative Electricity and Transportation | C28: AEO.2026.ELECTRNP.CNSM_NA_RESD_FRZ_ELC_NA_USA_QBTU.A | D28: quads | E28: 0.079278 | F28: 0.079241 | G28: 0.079217 | H28: 0.07916 | I28: 0.079073 | J28: 0.07857 | K28: 0.078007 | L28: 0.077404 | M28: 0.076823 | N28: 0.076257 | O28: 0.075716 | P28: 0.075195 | Q28: 0.074693 | R28: 0.074214 | S28: 0.073757 | T28: 0.073328 | U28: 0.072937 | V28: 0.072586 | W28: 0.072278 | X28: 0.072012 | Y28: 0.071802 | Z28: 0.07166 | AA28: 0.071579 | AB28: 0.071571 | AC28: 0.071643 | AD28: 0.0718 | AE28: -0.004
A29: Lighting | B29: Residential: Electricity: Lighting: Alternative Electricity and Transportation | C29: AEO.2026.ELECTRNP.CNSM_NA_RESD_LGHTNG_ELC_NA_USA_QBTU.A | D29: quads | E29: 0.182847 | F29: 0.182216 | G29: 0.183569 | H29: 0.18564 | I29: 0.187439 | J29: 0.186994 | K29: 0.186424 | L29: 0.186261 | M29: 0.186404 | N29: 0.186742 | O29: 0.187215 | P29: 0.187754 | Q29: 0.188226 | R29: 0.188723 | S29: 0.1894 | T29: 0.187035 | U29: 0.185089 | V29: 0.183691 | W29: 0.182846 | X29: 0.182477 | Y29: 0.182384 | Z29: 0.18231 | AA29: 0.182202 | AB29: 0.182192 | AC29: 0.182375 | AD29: 0.182588 | AE29: 0
A30: Clothes Washers | B30: Residential: Electricity: Clothes Washers: Alternative Electricity and Transportation | C30: AEO.2026.ELECTRNP.CNSM_NA_RESD_CLW_ELC_NA_USA_QBTU.A | D30: quads | E30: 0.040723 | F30: 0.039741 | G30: 0.03875 | H30: 0.037583 | I30: 0.036385 | J30: 0.034992 | K30: 0.03354 | L30: 0.032 | M30: 0.030665 | N30: 0.029534 | O30: 0.028609 | P30: 0.027904 | Q30: 0.027429 | R30: 0.02721 | S30: 0.027261 | T30: 0.027311 | U30: 0.027362 | V30: 0.02742 | W30: 0.027486 | X30: 0.027564 | Y30: 0.027658 | Z30: 0.027768 | AA30: 0.02789 | AB30: 0.028024 | AC30: 0.028167 | AD30: 0.028319 | AE30: -0.014
A31: Dishwashers | B31: Residential: Electricity: Dishwashers: Alternative Electricity and Transportation | C31: AEO.2026.ELECTRNP.CNSM_NA_RESD_DSW_ELC_NA_USA_QBTU.A | D31: quads | E31: 0.037162 | F31: 0.038076 | G31: 0.03836 | H31: 0.038523 | I31: 0.038637 | J31: 0.038703 | K31: 0.03872 | L31: 0.038689 | M31: 0.038734 | N31: 0.038861 | O31: 0.039071 | P31: 0.039371 | Q31: 0.039764 | R31: 0.040262 | S31: 0.040872 | T31: 0.041477 | U31: 0.042076 | V31: 0.042674 | W31: 0.043273 | X31: 0.043876 | Y31: 0.044488 | Z31: 0.045111 | AA31: 0.045741 | AB31: 0.046379 | AC31: 0.047023 | AD31: 0.047676 | AE31: 0.01
A32: Televisions and Related Equipment | B32: Residential: Electricity: Televisions: Alternative Electricity and Transportation | C32: AEO.2026.ELECTRNP.CNSM_NA_RESD_TVR_ELC_NA_USA_QBTU.A | D32: quads | E32: 0.124839 | F32: 0.122177 | G32: 0.119963 | H32: 0.118088 | I32: 0.116097 | J32: 0.113806 | K32: 0.111516 | L32: 0.109399 | M32: 0.107489 | N32: 0.105735 | O32: 0.104144 | P32: 0.102719 | Q32: 0.101411 | R32: 0.100273 | S32: 0.099267 | T32: 0.098398 | U32: 0.097694 | V32: 0.097154 | W32: 0.096815 | X32: 0.096643 | Y32: 0.096638 | Z32: 0.096759 | AA32: 0.096903 | AB32: 0.097108 | AC32: 0.097404 | AD32: 0.097758 | AE32: -0.01
A33: Computers and Related Equipment | B33: Residential: Electricity: Computers: Alternative Electricity and Transportation | C33: AEO.2026.ELECTRNP.CNSM_NA_RESD_CMPR_ELC_NA_USA_QBTU.A | D33: quads | E33: 0.097012 | F33: 0.095324 | G33: 0.093865 | H33: 0.092524 | I33: 0.090934 | J33: 0.088982 | K33: 0.086906 | L33: 0.084865 | M33: 0.082885 | N33: 0.080946 | O33: 0.079062 | P33: 0.07725 | Q33: 0.075484 | R33: 0.073799 | S33: 0.072189 | T33: 0.070667 | U33: 0.069258 | V33: 0.06799 | W33: 0.066879 | X33: 0.065919 | Y33: 0.065114 | Z33: 0.064456 | AA33: 0.063893 | AB33: 0.063459 | AC33: 0.063206 | AD33: 0.063082 | AE33: -0.017
... A39: Purchased Electricity at Residential Location | B39: Residential: Electricity: Purchased Electricity at Residential Location: Alternative Electricity and Transportation | C39: AEO.2026.ELECTRNP.CNSM_NA_RESD_PURCHELEC_ELC_NA_USA_QBTU.A | D39: quads | E39: 5.216623 | F39: 5.257673 | G39: 5.182968 | H39: 5.247639 | I39: 5.291314 | J39: 5.309832 | K39: 5.3177 | L39: 5.32703 | M39: 5.34066 | N39: 5.361271 | O39: 5.386619 | P39: 5.416244 | Q39: 5.448967 | R39: 5.485255 | S39: 5.522946 | T39: 5.555702 | U39: 5.592755 | V39: 5.63542 | W39: 5.683198 | X39: 5.73157 | Y39: 5.777129 | Z39: 5.824309 | AA39: 5.868561 | AB39: 5.911637 | AC39: 5.95669 | AD39: 6.00164 | AE39: 0.006
A40: Natural Gas
A41: Space Heating | B41: Residential: Natural Gas: Space Heating: Alternative Electricity and Transportation | C41: AEO.2026.ELECTRNP.CNSM_NA_RESD_SPH_NG_NA_USA_QBTU.A | D41: quads | E41: 3.118029 | F41: 2.929732 | G41: 3.047068 | H41: 3.028339 | I41: 2.991961 | J41: 2.947513 | K41: 2.90039 | L41: 2.856502 | M41: 2.813128 | N41: 2.772394 | O41: 2.732819 | P41: 2.695713 | Q41: 2.658051 | R41: 2.62224 | S41: 2.587139 | T41: 2.553313 | U41: 2.519939 | V41: 2.490338 | W41: 2.462606 | X41: 2.436644 | Y41: 2.412093 | Z41: 2.386654 | AA41: 2.359964 | AB41: 2.333602 | AC41: 2.307677 | AD41: 2.28263 | AE41: -0.012
A42: Space Cooling | B42: Residential: Natural Gas: Space Cooling: Alternative Electricity and Transportation | C42: AEO.2026.ELECTRNP.CNSM_NA_RESD_SPC_NG_NA_USA_QBTU.A | D42: quads | E42: 0.058598 | F42: 0.062155 | G42: 0.06259 | H42: 0.062752 | I42: 0.062711 | J42: 0.062576 | K42: 0.062453 | L42: 0.06243 | M42: 0.062446 | N42: 0.062545 | O42: 0.062667 | P42: 0.062853 | Q42: 0.06307 | R42: 0.063308 | S42: 0.063572 | T42: 0.063894 | U42: 0.064259 | V42: 0.064725 | W42: 0.065211 | X42: 0.065681 | Y42: 0.066162 | Z42: 0.066587 | AA42: 0.066993 | AB42: 0.067365 | AC42: 0.067759 | AD42: 0.068145 | AE42: 0.006
A43: Water Heating | B43: Residential: Natural Gas: Water Heating: Alternative Electricity and Transportation | C43: AEO.2026.ELECTRNP.CNSM_NA_RESD_WTHT_NG_NA_USA_QBTU.A | D43: quads | E43: 1.024266 | F43: 1.035179 | G43: 1.045421 | H43: 1.055186 | I43: 1.053344 | J43: 1.049761 | K43: 1.0469 | L43: 1.0452 | M43: 1.042567 | N43: 1.041999 | O43: 1.043007 | P43: 1.043505 | Q43: 1.043021 | R43: 1.042215 | S43: 1.04091 | T43: 1.039289 | U43: 1.037016 | V43: 1.034723 | W43: 1.032111 | X43: 1.029129 | Y43: 1.025429 | Z43: 1.020672 | AA43: 1.015129 | AB43: 1.009384 | AC43: 1.003914 | AD43: 0.99913 | AE43: -0.001
A44: Cooking | B44: Residential: Natural Gas: Cooking: Alternative Electricity and Transportation | C44: AEO.2026.ELECTRNP.CNSM_NA_RESD_CGR_NG_NA_USA_QBTU.A | D44: quads | E44: 0.077268 | F44: 0.077256 | G44: 0.077247 | H44: 0.077222 | I44: 0.077195 | J44: 0.077167 | K44: 0.077124 | L44: 0.077065 | M44: 0.077006 | N44: 0.07697 | O44: 0.076962 | P44: 0.076991 | Q44: 0.07706 | R44: 0.077217 | S44: 0.077432 | T44: 0.077712 | U44: 0.078045 | V44: 0.07843 | W44: 0.078816 | X44: 0.079203 | Y44: 0.079599 | Z44: 0.080006 | AA44: 0.080424 | AB44: 0.080855 | AC44: 0.081299 | AD44: 0.081761 | AE44: 0.002
A45: Clothes Dryers | B45: Residential: Natural Gas: Clothes Dryers: Alternative Electricity and Transportation | C45: AEO.2026.ELECTRNP.CNSM_NA_RESD_CDR_NG_NA_USA_QBTU.A | D45: quads | E45: 0.039574 | F45: 0.040284 | G45: 0.04092 | H45: 0.041544 | I45: 0.042109 | J45: 0.042643 | K45: 0.043187 | L45: 0.043759 | M45: 0.044208 | N45: 0.044701 | O45: 0.045238 | P45: 0.045826 | Q45: 0.046396 | R45: 0.046978 | S45: 0.047561 | T45: 0.048146 | U45: 0.048724 | V45: 0.049352 | W45: 0.050015 | X45: 0.050707 | Y45: 0.051406 | Z45: 0.052088 | AA45: 0.052756 | AB45: 0.053424 | AC45: 0.0541 | AD45: 0.054789 | AE45: 0.013
...

Sheet NoH
A1: Dmnl | B1: 2024 | C1: 2025 | D1: 2026 | E1: 2027 | F1: 2028 | G1: 2029 | H1: 2030 | I1: 2031 | J1: 2032 | K1: 2033 | L1: 2034 | M1: 2035 | N1: 2036 | O1: 2037 | P1: 2038 | Q1: 2039 | R1: 2040 | S1: 2041 | T1: 2042 | U1: 2043 | V1: 2044 | W1: 2045 | X1: 2046 | Y1: 2047 | Z1: 2048 | AA1: 2049 | AB1: 2050
A2: Households | B2: ='AEO 2023 Table 4'!E20*10^6 -> 128811890 | C2: ='AEO 2026 Table 4'!E11*10^6 -> 1.3072922e+08 | D2: ='AEO 2026 Table 4'!F11*10^6 -> 1.3209541e+08 | E2: ='AEO 2026 Table 4'!G11*10^6 -> 133495735 | F2: ='AEO 2026 Table 4'!H11*10^6 -> 134872797 | G2: ='AEO 2026 Table 4'!I11*10^6 -> 136249235 | H2: ='AEO 2026 Table 4'!J11*10^6 -> 137609806 | I2: ='AEO 2026 Table 4'!K11*10^6 -> 138976937 | J2: ='AEO 2026 Table 4'!L11*10^6 -> 140345360 | ... AB2: ='AEO 2026 Table 4'!AD11*10^6 -> 159072735
