Workbook

Sheet About
A1: BEaCP BAU Employment and Compensation Projections
A3: Sources: | B3: Population Projection
B4: U.S. Census Bureau
B5: 2023
B6: 2023 National Population Projections Datasets
B7: https://www.census.gov/data/tables/2023/demo/popproj/2023-summary-tables.html
B8: Table 1
B10: Employment-to-Population Ratio
B11: St. Louis Federal Reserve Bank
B12: 2025
B13: Employment-Population Ratio
B14: https://fred.stlouisfed.org/series/EMRATIO
B16: Total Employee Compensation (from IO tables, historical year)
B17: BEA
B18: 2024
B19: Components of Value Added by Industry
B20: https://www.bea.gov/itable/gdp-by-industry
B21: Interactive Data Tables > Value Added > Components
B23: Annual Change in Compensation per EE Hour Worked
B24: U.S. Bureau of Labor Statistics
B25: 2025
B26: Employer Costs for Employee Compensation
B27: https://www.bls.gov/data/
B28: Use data finder to create table for all civilian workers nationally
A30: Notes
A32: Population
A33: Population projections are available directly from the U.S. Census department.
A35: Number of Employees
A36: To project future numbers of employees, we sample the share of the population that is
A37: employed over a wide historical rage, and use that average going forward. The share of
A38: the population that is employed has remained relatively stable over time despite tremendous
A39: increases in productivity (output per employee), so we believe this is likely to continue to
A40: happen in the future, and we do not need to adjust for productivity increases. (That is,
A41: any displaced workers are integrated elsewhere in the economy.)
A43: Total Compensation
A44: We start with the total compensation number from the Bureau of Economic Analysis in
... A47: and (2) change in inflation-adjusted compensation per hour worked.

Sheet Census Pop Proj
A2: Projected Population and Components of Change
A3: Projections for the United States: 2022-2100
A4: Main series. Table 1
A5: (Resident population as of July 1. Numbers in thousands)
A6: Year | B6: Population | C6: Numeric change since prior year | D6: Percent change since prior year | E6: Vital events | G6: Natural change (births – deaths) | H6: Net international migration1
E7: Births | F7: Deaths
A8: 2022 | B8: 333288
A9: 2023 | B9: 334906 | C9: 1619 | D9: 0.49 | E9: 3627 | F9: 2862 | G9: 766 | H9: 853
A10: 2024 | B10: 336482 | C10: 1576 | D10: 0.47 | E10: 3632 | F10: 2912 | G10: 721 | H10: 855
A11: 2025 | B11: 338016 | C11: 1534 | D11: 0.46 | E11: 3637 | F11: 2960 | G11: 676 | H11: 858
A12: 2026 | B12: 339513 | C12: 1497 | D12: 0.44 | E12: 3641 | F12: 3009 | G12: 632 | H12: 865
A13: 2027 | B13: 340970 | C13: 1457 | D13: 0.43 | E13: 3645 | F13: 3058 | G13: 587 | H13: 871
A14: 2028 | B14: 342385 | C14: 1414 | D14: 0.41 | E14: 3648 | F14: 3108 | G14: 540 | H14: 874
A15: 2029 | B15: 343754 | C15: 1369 | D15: 0.4 | E15: 3651 | F15: 3160 | G15: 491 | H15: 878
A16: 2030 | B16: 345074 | C16: 1320 | D16: 0.38 | E16: 3653 | F16: 3212 | G16: 441 | H16: 879
A17: 2031 | B17: 346339 | C17: 1266 | D17: 0.37 | E17: 3654 | F17: 3265 | G17: 389 | H17: 877
A18: 2032 | B18: 347545 | C18: 1206 | D18: 0.35 | E18: 3654 | F18: 3319 | G18: 336 | H18: 870
A19: 2033 | B19: 348702 | C19: 1157 | D19: 0.33 | E19: 3653 | F19: 3373 | G19: 280 | H19: 876
A20: 2034 | B20: 349808 | C20: 1106 | D20: 0.32 | E20: 3650 | F20: 3426 | G20: 224 | H20: 882
... A86: 2100 | B86: 365558 | C86: -283 | D86: -0.08 | E86: 3125 | F86: 4352 | G86: -1227 | H86: 944
A87: 1 Net international migration includes the international migration of both native and foreign-born populations. Specifically, it includes: (a) the net international migration of the foreign born, (b) the net international migration of the native born, including migration to and from Puerto Rico.
A88: Notes: 2023 National Population Projections data products are associated with Data Management System projects P-6000042, P-7501659, and P-7527355. The U.S. Census Bureau reviewed these data products for unauthorized disclosure of confidential information and approved the disclosure avoidance practices applied to this release (CBDRB‑FY24‑0008).
A89: For population projections methodology statements, see https://www.census.gov/programs-surveys/popproj/technical-documentation/methodology.html.
A90: 2022 is the base population estimate for the projections. Data on population change and components of change refer to events occurring between July 1 of the preceding year and June 30 of the indicated year.
A91: Suggested Citation:
A92: Projected Population and Components of Change for the United States, Main Series: 2022-2100.
A93: Source: U.S. Census Bureau, Population Division
A94: Release Date: November 2023

Sheet Emp Pop Ratio
A1: FRED Graph Observations
A2: Federal Reserve Economic Data
A3: Link: https://fred.stlouisfed.org
A4: Help: https://fred.stlouisfed.org/help-faq
A5: Economic Research Division
A6: Federal Reserve Bank of St. Louis
A8: EMRATIO | B8: Employment-Population Ratio, Percent, Monthly, Seasonally Adjusted
A10: Frequency: Monthly
A11: observation_date | B11: EMRATIO
A12: 17533 | B12: 56.6
A13: 17564 | B13: 56.7
A14: 17593 | B14: 56.1
A15: 17624 | B15: 56.7
A16: 17654 | B16: 56.2
A17: 17685 | B17: 57
A18: 17715 | B18: 57.1
A19: 17746 | B19: 56.6
A20: 17777 | B20: 56.6
A21: 17807 | B21: 56.5
A22: 17838 | B22: 56.5
A23: 17868 | B23: 56.8
... A944: 45901 | B944: 59.7
A945: 45931
A946: 45962 | B946: 59.6
A947: 45992 | B947: 59.7

Sheet Avg Emp-Pop Ratio
A1: Average Employment-to-Population Ratio
A2: from date | B2: 40179
A3: to date | B3: 43891
A5: is: | B5: =AVERAGEIFS('Emp Pop Ratio'!B:B,'Emp Pop Ratio'!A:A,">="&'Avg Emp-Pop Ratio'!B2,'Emp Pop Ratio'!A:A,"<="&'Avg Emp-Pop Ratio'!B3)/100 -> 0.5937561

Sheet BLS Comp per Hr Worked
A1: Employer Costs for Employee Compensation
A2: Original Data Value
A4: Series Id: | B4: CMU1010000000000D
A5: Series Title: | B5: All Civilian Total compensation for All occupations; Cost per hour worked
A6: Ownership: | B6: Civilian workers
A7: Component: | B7: Total compensation
A8: Occupation: | B8: All workers
A9: Industry: | B9: All workers
A10: Subcategory: | B10: All workers
A11: Area: | B11: United States (National)
A12: Data Type: | B12: Cost of compensation (Cost per hour worked)
A13: Years: | B13: 2004 to 2025
A15: Year | B15: Period | C15: Estimate Value | D15: Relative Standard Error
A16: 2004 | B16: Qtr1 | C16: 24.95
A17: 2004 | B17: Qtr2 | C17: 24.96
A18: 2004 | B18: Qtr3 | C18: 25.36
A19: 2004 | B19: Qtr4 | C19: 25.57
A20: 2005 | B20: Qtr1 | C20: 25.87
A21: 2005 | B21: Qtr2 | C21: 25.86
A22: 2005 | B22: Qtr3 | C22: 26.05
A23: 2005 | B23: Qtr4 | C23: 26.46
A24: 2006 | B24: Qtr1 | C24: 26.86
A25: 2006 | B25: Qtr2 | C25: 26.86
A26: 2006 | B26: Qtr3 | C26: 27.31
A27: 2006 | B27: Qtr4 | C27: 27.54
... A73: 2018 | B73: Qtr2 | C73: 36.22
A74: 2018 | B74: Qtr3 | C74: 36.63 | D74: 1.4
A75: 2018 | B75: Qtr4 | C75: 36.32 | D75: 1.3
A76: 2019 | B76: Qtr1 | C76: 36.77 | D76: 1.3
A77: 2019 | B77: Qtr2 | C77: 36.61 | D77: 1.3
A78: 2019 | B78: Qtr3 | C78: 37.03 | D78: 1.3
A79: 2019 | B79: Qtr4 | C79: 37.1 | D79: 1.2
A80: 2020 | B80: Qtr1 | C80: 37.73 | D80: 1.2
A81: 2020 | B81: Qtr2 | C81: 38.2
A82: 2020 | B82: Qtr3 | C82: 38.26
A83: 2020 | B83: Qtr4 | C83: 38.6
A84: 2021 | B84: Qtr1 | C84: 39.01
A85: 2021 | B85: Qtr2 | C85: 38.91
A86: 2021 | B86: Qtr3 | C86: 39.55
A87: 2021 | B87: Qtr4 | C87: 40.35
...

Sheet BECbIC
A1: Unit: $ | B1: ISIC 01T03 | C1: ISIC 05 | D1: ISIC 06 | E1: ISIC 07T08 | F1: ISIC 09 | G1: ISIC 10T12 | H1: ISIC 13T15 | I1: ISIC 16 | J1: ISIC 17T18 | K1: ISIC 19 | L1: ISIC 20 | M1: ISIC 21 | N1: ISIC 22 | O1: ISIC 231 | P1: ISIC 239 | Q1: ISIC 241 | R1: ISIC 242 | S1: ISIC 25 | T1: ISIC 26 | U1: ISIC 27 | V1: ISIC 28 | W1: ISIC 29 | X1: ISIC 30 | Y1: ISIC 31T33 | Z1: ISIC 351 | AA1: ISIC 352T353 | AB1: ISIC 36T39 | AC1: ISIC 41T43 | AD1: ISIC 45T47 | AE1: ISIC 49T53 | AF1: ISIC 55T56 | AG1: ISIC 58T60 | AH1: ISIC 61 | AI1: ISIC 62T63 | AJ1: ISIC 64T66 | AK1: ISIC 68 | AL1: ISIC 69T82 | AM1: ISIC 84 | AN1: ISIC 85 | AO1: ISIC 86T88 | AP1: ISIC 90T96 | AQ1: ISIC 97T98
A2: Employee Compensation | B2: 5.8613298e+10 | C2: 5.6978074e+09 | D2: 2.3292495e+10 | E2: 1.1617861e+10 | F2: 2.7069182e+10 | G2: 1.1736712e+11 | H2: 1.491718e+10 | I2: 2.3638691e+10 | J2: 4.6374198e+10 | K2: 1.5975433e+10 | L2: 6.6689598e+10 | M2: 3.3563865e+10 | N2: 4.562618e+10 | O2: 5.4800306e+09 | P2: 2.3022242e+10 | Q2: 2.0406375e+10 | R2: 1.0435199e+10 | S2: 9.3757708e+10 | T2: 1.3714349e+11 | U2: 3.4612308e+10 | V2: 8.7838704e+10 | W2: 7.0697963e+10 | X2: 7.7821701e+10 | Y2: 8.7591009e+10 | Z2: 5.9184564e+10 | AA2: 1.3910481e+10 | AB2: 3.8827355e+10 | AC2: 5.8502632e+11 | AD2: 1.2209546e+12 | AE2: 4.224912e+11 | AF2: 4.149305e+11 | AG2: 1.8944516e+11 | AH2: 7.158683e+10 | AI2: 4.9894055e+11 | AJ2: 8.1635862e+11 | AK2: 1.6364251e+11 | AL2: 1.6335728e+12 | AM2: 1.8923388e+12 | AN2: 1.9615495e+11 | AO2: 1.2965438e+12 | AP2: 3.5352683e+11 | AQ2: 8.006921e+09

Sheet EE Comp Projection
A1: To calculate future total employee compensation, we begin by establishing a trend of
A2: cost change per hour worked. We then will scale the historical total EE compensation
A3: figure from the BEA (io-model/BECbIC) by the number of employees, adjusting for the
A4: change in cost per hour worked.
A6: These figures refer to total employee compensation, not just wages and salaries.
A7: E.g. this includes employer-paid benefits, employer contribution to retirement plans, etc.
A9: Average Employee Compensation per Hour Worked
B10: 2004 | C10: 2005 | D10: 2006 | E10: 2007 | F10: 2008 | G10: 2009 | H10: 2010 | I10: 2011 | J10: 2012 | K10: 2013 | L10: 2014 | M10: 2015 | N10: 2016 | O10: 2017 | P10: 2018 | Q10: 2019 | R10: 2020 | S10: 2021 | T10: 2022 | U10: 2023 | V10: 2024
A11: nominal $/hr | B11: =AVERAGEIFS('BLS Comp per Hr Worked'!$C:$C,'BLS Comp per Hr Worked'!$A:$A,B10) -> 25.21 | C11: =AVERAGEIFS('BLS Comp per Hr Worked'!$C:$C,'BLS Comp per Hr Worked'!$A:$A,C10) -> 26.06 | D11: =AVERAGEIFS('BLS Comp per Hr Worked'!$C:$C,'BLS Comp per Hr Worked'!$A:$A,D10) -> 27.1425 | E11: =AVERAGEIFS('BLS Comp per Hr Worked'!$C:$C,'BLS Comp per Hr Worked'!$A:$A,E10) -> 27.9275 | F11: =AVERAGEIFS('BLS Comp per Hr Worked'!$C:$C,'BLS Comp per Hr Worked'!$A:$A,F10) -> 28.7475 | G11: =AVERAGEIFS('BLS Comp per Hr Worked'!$C:$C,'BLS Comp per Hr Worked'!$A:$A,G10) -> 29.3675 | H11: =AVERAGEIFS('BLS Comp per Hr Worked'!$C:$C,'BLS Comp per Hr Worked'!$A:$A,H10) -> 29.675 | I11: =AVERAGEIFS('BLS Comp per Hr Worked'!$C:$C,'BLS Comp per Hr Worked'!$A:$A,I10) -> 30.1525 | ... V11: =AVERAGEIFS('BLS Comp per Hr Worked'!$C:$C,'BLS Comp per Hr Worked'!$A:$A,V10) -> 46.5975
A12: 2012 $ / nominal $ (from CPI) | B12: 1.2154262 | C12: 1.1755965 | D12: 1.1388591 | E12: 1.1073203 | F12: 1.0663762 | G12: 1.0701837 | H12: 1.052913 | I12: 1.0206945 | J12: 1 | K12: 0.98556386 | L12: 0.96983137 | M12: 0.96868157 | N12: 0.95661377 | O12: 0.9366596 | P12: 0.91432736 | Q12: 0.89805482 | R12: 0.88711067 | S12: 0.84730413 | T12: 0.78452102 | U12: 0.75350342 | V12: 0.73191601
A13: 2012 $/hr | B13: =B11*B12 -> 30.640893 | C13: =C11*C12 -> 30.636045 | D13: =D11*D12 -> 30.911484 | E13: =E11*E12 -> 30.924687 | F13: =F11*F12 -> 30.65565 | G13: =G11*G12 -> 31.42862 | H13: =H11*H12 -> 31.245194 | I13: =I11*I12 -> 30.776491 | ... V13: =V11*V12 -> 34.105456
A14: Annual Perc Change | C14: =(C13-B13)/B13 -> -0.00015822036 | D14: =(D13-C13)/C13 -> 0.0089906706 | E14: =(E13-D13)/D13 -> 0.00042712489 | F14: =(F13-E13)/E13 -> -0.0086997304 | G14: =(G13-F13)/F13 -> 0.025214577 | H14: =(H13-G13)/G13 -> -0.0058362755 | I14: =(I13-H13)/H13 -> -0.015000796 | J14: =(J13-I13)/I13 -> -0.0016730593 | ... V14: =(V13-U13)/U13 -> 0.030567164
A15: Avg Annual Perc Cng / Yr | B15: =AVERAGE(C14:V14) -> 0.0054888889
A18: Projected Future Employee Compensation (2012 USD)
B19: 2024 | C19: 2025 | D19: 2026 | E19: 2027 | F19: 2028 | G19: 2029 | H19: 2030 | I19: 2031 | J19: 2032 | K19: 2033 | L19: 2034 | M19: 2035 | N19: 2036 | O19: 2037 | P19: 2038 | Q19: 2039 | R19: 2040 | S19: 2041 | T19: 2042 | U19: 2043 | V19: 2044 | W19: 2045 | X19: 2046 | Y19: 2047 | Z19: 2048 | AA19: 2049 | AB19: 2050
A20: Perc Change in Number of EEs (vs. 2015) | B20: =VLOOKUP(B$19,'Census Pop Proj'!$A:$B,2,FALSE)/'Census Pop Proj'!$B$10-1 -> 0 | C20: =VLOOKUP(C$19,'Census Pop Proj'!$A:$B,2,FALSE)/'Census Pop Proj'!$B$10-1 -> 0.0045589363 | D20: =VLOOKUP(D$19,'Census Pop Proj'!$A:$B,2,FALSE)/'Census Pop Proj'!$B$10-1 -> 0.0090079113 | E20: =VLOOKUP(E$19,'Census Pop Proj'!$A:$B,2,FALSE)/'Census Pop Proj'!$B$10-1 -> 0.013338009 | F20: =VLOOKUP(F$19,'Census Pop Proj'!$A:$B,2,FALSE)/'Census Pop Proj'!$B$10-1 -> 0.017543286 | G20: =VLOOKUP(G$19,'Census Pop Proj'!$A:$B,2,FALSE)/'Census Pop Proj'!$B$10-1 -> 0.021611854 | H20: =VLOOKUP(H$19,'Census Pop Proj'!$A:$B,2,FALSE)/'Census Pop Proj'!$B$10-1 -> 0.025534798 | I20: =VLOOKUP(I$19,'Census Pop Proj'!$A:$B,2,FALSE)/'Census Pop Proj'!$B$10-1 -> 0.029294286 | ... AB20: =VLOOKUP(AB$19,'Census Pop Proj'!$A:$B,2,FALSE)/'Census Pop Proj'!$B$10-1 -> 0.071792845
A21: Perc Change in Compensation / EE (vs. 2015) | B21: 0 | C21: =B21*(1+$B$15)+$B$15 -> 0.0054888889 | D21: =C21*(1+$B$15)+$B$15 -> 0.011007906 | E21: =D21*(1+$B$15)+$B$15 -> 0.016557216 | F21: =E21*(1+$B$15)+$B$15 -> 0.022136985 | G21: =F21*(1+$B$15)+$B$15 -> 0.027747382 | H21: =G21*(1+$B$15)+$B$15 -> 0.033388573 | I21: =H21*(1+$B$15)+$B$15 -> 0.039060728 | J21: =I21*(1+$B$15)+$B$15 -> 0.044764017 | ... AB21: =AA21*(1+$B$15)+$B$15 -> 0.15294654
A22: Projected Compensation (2012 $) | B22: =SUM(BECbIC!B2:AQ2) -> 1.1014693e+13 | C22: =$B22*(1+C20)*(1+C21) -> 1.1125642e+13 | D22: =$B22*(1+D20)*(1+D21) -> 1.1236253e+13 | E22: =$B22*(1+E20)*(1+E21) -> 1.1346412e+13 | F22: =$B22*(1+F20)*(1+F21) -> 1.1456036e+13 | G22: =$B22*(1+G20)*(1+G21) -> 1.1564975e+13 | H22: =$B22*(1+H20)*(1+H21) -> 1.1673106e+13 | I22: =$B22*(1+I20)*(1+I21) -> 1.1780206e+13 | J22: =$B22*(1+J20)*(1+J21) -> 1.1886111e+13 | ... AB22: =$B22*(1+AB20)*(1+AB21) -> 1.3611074e+13

Sheet population
A1: Unit: people | B1: 2022 | C1: 2023 | D1: 2024 | E1: 2025 | F1: 2026 | G1: 2027 | H1: 2028 | I1: 2029 | J1: 2030 | K1: 2031 | L1: 2032 | M1: 2033 | N1: 2034 | O1: 2035 | P1: 2036 | Q1: 2037 | R1: 2038 | S1: 2039 | T1: 2040 | U1: 2041 | V1: 2042 | W1: 2043 | X1: 2044 | Y1: 2045 | Z1: 2046 | AA1: 2047 | AB1: 2048 | AC1: 2049 | AD1: 2050 | AE1: 2051 | AF1: 2052 | AG1: 2053 | AH1: 2054 | AI1: 2055 | AJ1: 2056 | AK1: 2057 | AL1: 2058 | AM1: 2059 | AN1: 2060 | AO1: 2061 | AP1: 2062 | AQ1: 2063 | AR1: 2064 | AS1: 2065 | AT1: 2066 | AU1: 2067 | AV1: 2068 | AW1: 2069 | AX1: 2070 | AY1: 2071 | AZ1: 2072 | BA1: 2073 | BB1: 2074 | BC1: 2075 | BD1: 2076 | BE1: 2077 | BF1: 2078 | BG1: 2079 | BH1: 2080 | BI1: 2081 | BJ1: 2082 | BK1: 2083 | BL1: 2084 | BM1: 2085 | BN1: 2086 | BO1: 2087 | BP1: 2088 | BQ1: 2089 | BR1: 2090 | BS1: 2091 | BT1: 2092 | BU1: 2093 | BV1: 2094 | BW1: 2095 | BX1: 2096 | BY1: 2097 | BZ1: 2098 | CA1: 2099 | CB1: 2100
A2: Population | B2: {=TRANSPOSE('Census Pop Proj'!B8:B86)*10^3} -> 333288000 | C2: 334906000 | D2: 336482000 | E2: 338016000 | F2: 339513000 | G2: 340970000 | H2: 342385000 | I2: 343754000 | J2: 345074000 | K2: 346339000 | L2: 347545000 | M2: 348702000 | N2: 349808000 | O2: 350861000 | P2: 351861000 | Q2: 352806000 | R2: 353696000 | S2: 354530000 | T2: 355309000 | U2: 356034000 | V2: 356705000 | W2: 357327000 | X2: 357903000 | Y2: 358438000 | Z2: 358936000 | AA2: 359400000 | AB2: 359836000 | AC2: 360247000 | AD2: 360639000 | AE2: 361015000 | AF2: 361381000 | AG2: 361739000 | AH2: 362095000 | AI2: 362450000 | AJ2: 362807000 | AK2: 363169000 | AL2: 363536000 | AM2: 363909000 | AN2: 364287000 | AO2: 364670000 | AP2: 365057000 | AQ2: 365443000 | AR2: 365828000 | AS2: 366207000 | AT2: 366579000 | AU2: 366938000 | AV2: 367283000 | AW2: 367609000 | AX2: 367913000 | AY2: 368190000 | AZ2: 368441000 | BA2: 368663000 | BB2: 368856000 | BC2: 369018000 | BD2: 369150000 | BE2: 369250000 | BF2: 369319000 | BG2: 369356000 | BH2: 369363000 | BI2: 369340000 | BJ2: 369289000 | BK2: 369213000 | BL2: 369114000 | BM2: 368993000 | BN2: 368852000 | BO2: 368693000 | BP2: 368518000 | BQ2: 368326000 | BR2: 368120000 | BS2: 367901000 | BT2: 367670000 | BU2: 367429000 | BV2: 367179000 | BW2: 366923000 | BX2: 366661000 | BY2: 366393000 | BZ2: 366120000 | CA2: 365841000 | CB2: 365558000

Sheet BEaCP-employedpop
A1: Unit: people | B1: 2024 | C1: 2025 | D1: 2026 | E1: 2027 | F1: 2028 | G1: 2029 | H1: 2030 | I1: 2031 | J1: 2032 | K1: 2033 | L1: 2034 | M1: 2035 | N1: 2036 | O1: 2037 | P1: 2038 | Q1: 2039 | R1: 2040 | S1: 2041 | T1: 2042 | U1: 2043 | V1: 2044 | W1: 2045 | X1: 2046 | Y1: 2047 | Z1: 2048 | AA1: 2049 | AB1: 2050
A2: Employed Population | B2: =population!D2*'Avg Emp-Pop Ratio'!$B$5 -> 1.9978824e+08 | C2: =population!E2*'Avg Emp-Pop Ratio'!$B$5 -> 2.0069906e+08 | D2: =population!F2*'Avg Emp-Pop Ratio'!$B$5 -> 2.0158791e+08 | E2: =population!G2*'Avg Emp-Pop Ratio'!$B$5 -> 2.0245302e+08 | F2: =population!H2*'Avg Emp-Pop Ratio'!$B$5 -> 2.0329318e+08 | G2: =population!I2*'Avg Emp-Pop Ratio'!$B$5 -> 2.0410603e+08 | H2: =population!J2*'Avg Emp-Pop Ratio'!$B$5 -> 2.0488979e+08 | I2: =population!K2*'Avg Emp-Pop Ratio'!$B$5 -> 2.0564089e+08 | ... AB2: =population!AD2*'Avg Emp-Pop Ratio'!$B$5 -> 2.1413161e+08

Sheet BEaCP-employeecomp
A1: Unit: 2012 $ | B1: 2024 | C1: 2025 | D1: 2026 | E1: 2027 | F1: 2028 | G1: 2029 | H1: 2030 | I1: 2031 | J1: 2032 | K1: 2033 | L1: 2034 | M1: 2035 | N1: 2036 | O1: 2037 | P1: 2038 | Q1: 2039 | R1: 2040 | S1: 2041 | T1: 2042 | U1: 2043 | V1: 2044 | W1: 2045 | X1: 2046 | Y1: 2047 | Z1: 2048 | AA1: 2049 | AB1: 2050
A2: Total EE Compensation | B2: ='EE Comp Projection'!B22 -> 1.1014693e+13 | C2: ='EE Comp Projection'!C22 -> 1.1125642e+13 | D2: ='EE Comp Projection'!D22 -> 1.1236253e+13 | E2: ='EE Comp Projection'!E22 -> 1.1346412e+13 | F2: ='EE Comp Projection'!F22 -> 1.1456036e+13 | G2: ='EE Comp Projection'!G22 -> 1.1564975e+13 | H2: ='EE Comp Projection'!H22 -> 1.1673106e+13 | I2: ='EE Comp Projection'!I22 -> 1.1780206e+13 | ... AB2: ='EE Comp Projection'!AB22 -> 1.3611074e+13
