Workbook

Sheet About
A1: BFoCDMbNI BAU Fraction of Clinker Demand Met by Net Imports
A3: Sources: | B3: U.S. clinker production, consumption, and trade, 2021-2025 | D3: EU-27 net trade, 2025 (comparison)
B4: U.S. Geological Survey | D4: Cement Europe (from Eurostat)
B5: Mineral Commodity Summaries 2026: Cement | D5: Cement Europe trade report, full year 2025
B6: 2026 | D6: 2026
B7: https://pubs.usgs.gov/periodicals/mcs2026/mcs2026-cement.pdf | D7: https://www.cementeurope.eu/media/bw4j1sxx/cement-europe-trade-report-full-year-2025-april-2026.pdf
B8: Clinker production (69.0 million metric tons in 2025, an estimate), apparent consumption (110.0), cement and clinker imports, and exports, pasted as published on the 'USGS MCS 2026 Cement' tab. USGS rounds apparent consumption to two significant figures, and it reports net import reliance of 19-22% of apparent consumption. The same table has 2024 clinker capacity and production figures for other countries, which are not used here. | D8: 2025 imports of 14.2 and exports of 9.1 million tons, a net import of 5.1 million tons, or +0.034 of 2024 consumption. Shown in the row note for comparison; the 2024 value is the one used.
B10: Longer import history and the outlook | D10: Brazil consumption (denominator)
B11: Argus Media | D11: Grandes Construcoes (reporting SNIC data)
B12: US cement market 2026 outlook shaky (Intercem Americas) | D12: SNIC divulga relatorio anual da industria do cimento
B13: 2025
B14: https://www.argusmedia.com/news-and-insights/latest-market-news/2758546-us-cement-market-2026-outlook-shaky | D14: https://grandesconstrucoes.com.br/Noticias/Exibir/snic-divulga-relatorio-anual-da-industria-do-cimento
B15: Industry forecasters expected consumption to bottom near 100 million tons in 2026 with plants running at about 76% and import terminal additions continuing. Combined with USGS data for 2001-2025, the share on this file's basis was 0.26 at the 2006 peak, 0.06-0.08 in 2009-2014, and back to 0.20-0.24 in 2021-2025. | D15: 2024 consumption of 64.8 million tons (SNIPPET).
B17: Recent import trends and trade policy | D17: Mexico consumption (denominator)
B18: Global Cement | D18: Global Cement
B19: Tariffs in July 2026 | D19: Mexican cement consumption falls in first half of 2025
B20: 2026 | D20: 2025
B21: https://www.globalcement.com/news/analysis/21057-tariffs-in-july-2026 | D21: https://www.globalcement.com/news/19770-mexican-cement-consumption-falls-in-first-half-of-2025
B22: Imports grew from 13.5 million tons (2017) to 25.4 million tons (2025). Emergency tariffs were struck down in February 2026; first-half 2026 imports were 11.9 million tons, about flat on 2025 (Argus, August 2026). | D22: About 42 million tons of 2024 sales (SNIPPET). Another press report puts 2024 at 46.4 million tons, which would turn Mexico into a small net importer; CANACEM's own statistics should settle it. The Mexico row note also says about 1.5 million tons went to the U.S. in 2024 (SNIPPET); we did not trace which article gives that figure.
B24: Trade flows for China, India, Brazil, Mexico, and Canada | D24: Canada consumption (denominator)
B25: United Nations | D25: Cement Association of Canada
B26: UN Comtrade Database, HS 2523 (cement and clinker), 2023-2025 | D26: Concrete Zero: Action Plan
B27: 2026 | D27: 2023
B28: https://comtradeplus.un.org/ | D28: https://cement.ca/wp-content/uploads/ConcreteZero-Report-FINAL-reduced.pdf
B29: 2024 imports and exports of cement and clinker in million tons. China: cement 0.06 imported, 5.02 exported; clinker 0.28 imported, 0.34 exported. India: cement 0.74 imported, 0.98 exported; clinker 1.55 imported, 0.02 exported. Brazil: cement 0.14 imported, 0.07 exported; clinker 0.92 imported. Mexico: cement 0.10 imported, 1.38 exported; clinker reported as about zero, which may mean not reported. Canada: imports 1.20 (treated as cement); exports 4.39 of cement and 0.47 of clinker. Comtrade's public preview shows zeros for flows that countries did not report, so the full series should be re-pulled before relying on these. Accessed 2026. | D29: Production of 12.7 million tons in 2020. Combined with 2024 trade, this gives an estimated consumption of about 9 million tons (12.7 + 1.2 - 4.86), which mixes two years and is low confidence.
B31: China consumption (denominator) | D31: Canada exports to the U.S.
B32: CemNet (International Cement Review) | D32: Innovation, Science and Economic Development Canada / Natural Resources Canada
B33: Chinese cement dropped sharply in 2024, and will continue to fall | D33: Roadmap to Net-Zero Carbon Concrete by 2050
B34: 2025 | D34: 2022
B35: https://www.cemnet.com/News/story/178600/chinese-cement-dropped-sharply-in-2024-and-will-continue-to-fall.html | D35: https://ised-isde.canada.ca/site/clean-growth-hub/sites/default/files/documents/2022-11/roadmap-net-zero-carbon-concrete-2050_0.pdf
B36: 2024 demand of 1,858.9 million tons (SNIPPET), the denominator for China's net import share. | D36: Says the U.S. imports about 6 million tons a year from Canada, 35% of its cement imports. Consistent with Canada being a large net exporter.
B38: India consumption (denominator) | D38: Indonesia clinker and cement exports
B39: American Council for an Energy-Efficient Economy (ACEEE) | D39: Asosiasi Pengusaha Semen Indonesia (Asperssi)
B40: Decarbonisation in the Indian Cement Industry | D40: Asperssi ungkap volume produksi & penjualan semen di 2025 dan proyeksi untuk 2026
B41: 2026 | D41: 2026
B42: https://www.aceee.org/wp-content/uploads/2026/07/ACEEE_Decarbonisation_in_Cement_Industry.pdf | D42: https://asperssi.id/asperssi-ungkap-volume-produksi-penjualan-semen-di-2025-dan-proyeksi-untuk-2026/
B43: Consumption of 435 million tons in fiscal year 2024-25 (SNIPPET), treated as 2024. The clinker-to-cement ratio of 0.73 used with the trade flows comes from the same report; see BCtCR. | D43: 2025 clinker exports of 12.34 million tons and cement exports of 1.32 million tons (DIRECT); Comtrade matches. Domestic clinker use is 57.301 - 12.34 = 44.96 million tons.
B45: EU-27 consumption (denominator) | D45: Japan clinker exports
B46: Cement Europe | D46: World Bank, World Integrated Trade Solution (WITS)
B47: Cement Europe Statistics Report 2025 | D47: Japan cement clinker (HS 252310) exports, 2024
...

Sheet Regions
A1: Selected region (drop-down): | B1: United States
A2: Pick a region from the drop-down in B1. The Derivation and the export tab update on their own; re-export the CSV afterward. A blank cell means no sourced value yet.
A4: Region | B4: Anchor year | C4: Net import share of clinker demand (fraction; blank = 0) | D4: Flag | E4: Source / note
A5: United States | B5: 2025 | C5: =Derivation!G10 -> 0.24359878 | D5: DIRECT | E5: identity on USGS MCS 2026 (Derivation tab)
A6: China | B6: 2024 | C6: =(((0.06-5.02)+(0.28-0.34))/1858.9) -> -0.0027005218 | D6: JUDGMENT | E6: Comtrade 2024: cement M 0.06 / X 5.02, clinker M 0.28 / X 0.34 Mt (DIRECT) over consumption 1,858.9. Tonnage basis because the China ratio is TO FILL; the clinker-basis value differs by <0.001 for any ratio 0.5-0.9. 2025 clinker exports not reported.
A7: India | B7: 2024 | C7: =(((0.74-0.98)*0.73+(1.55-0.02))/(435*0.73)) -> 0.0042664147 | D7: JUDGMENT | E7: Comtrade 2024: cement M 0.74 / X 0.98, clinker M 1.55 / X 0.02 Mt (DIRECT); ratio 0.73, consumption 435. Clinker basis (+0.003 on tonnage basis).
A8: EU-27 | B8: 2024 | C8: =((11.3-11.2)/148.1) -> 0.00067521945 | D8: JUDGMENT | E8: Eurostat via Cement Europe 2024: imports 11.3 / exports 11.2 Mt cement+clinker combined (DIRECT) - tonnage basis, no cement/clinker split. 2025: imports 14.2 / exports 9.1 = +0.034 of 2024 consumption. Conflicts with the +12.7 Mt production-consumption gap (see BCD note).
A9: Japan | B9: 2024 | E9: TO FILL - net exporter (clinker exports ~3.9 Mt 2024)
A10: Brazil | B10: 2024 | C10: =(((0.14-0.07)*0.71+0.92)/(64.8*0.71)) -> 0.021076769 | D10: JUDGMENT | E10: Comtrade 2024: clinker M 0.92, cement M 0.14 / X 0.07 Mt (DIRECT); ratio 0.71, 2024 consumption 64.8 (SNIPPET). Clinker basis; tonnage basis +0.015 (2024), +0.012 (2023). Staff plan quoted +0.013.
A11: Mexico | B11: 2024 | C11: =(((0.1-1.38)*0.75+0)/(42*0.75)) -> -0.03047619 | D11: JUDGMENT | E11: Comtrade 2024: cement M 0.10 / X 1.38 Mt, clinker ~0 (DIRECT; zero may mean not reported); ratio 0.75, consumption 42. Net exporter (~1.5 Mt to the US in 2024, SNIPPET). A CANACEM consumption forecast of 46.4 against USGS production of 44 would instead imply a net importer - resolve against CANACEM statistics.
A12: Canada | B12: 2024 | C12: =(((1.2-4.39)*0.89-0.47)/((12.7+1.2-(4.39+0.47))*0.89)) -> -0.41129313 | D12: JUDGMENT | E12: LOW CONFIDENCE. Comtrade 2024: cement X 4.39, clinker X 0.47, imports 1.20 Mt (DIRECT; imports treated as cement) over the ~9.0 Mt JUDGMENT consumption, ratio 0.89. Clinker basis -3.65/9 = -0.41; tonnage basis -0.40. ISED: ~6 Mt/yr to the US.
A13: Indonesia | B13: 2025 | C13: =(-(12.34+1.32*0.68)/(57.301-12.34)) -> -0.29442406 | D13: JUDGMENT | E13: ASI 2025: clinker exports 12.34, cement exports 1.32 Mt (DIRECT; Comtrade matches) at ratio 0.68 over domestic clinker use 44.96 - clinker basis. Tonnage basis -0.21.
A14: Australia | E14: TO FILL - large net importer (~40% of consumption imported per CIF)

Sheet USGS MCS 2026 Cement
A1: USGS Mineral Commodity Summaries 2026 - Cement (Ashley K. Hatfield). Pasted from the PDF text; 'e' = estimated. Data in thousand metric tons unless otherwise specified.
A3: Salient Statistics - United States (thousand metric tons unless noted) | B3: 2021 | C3: 2022 | D3: 2023 | E3: 2024 | F3: 2025e
A4: Production: Portland, blended, and masonry cement (includes cement made from imported clinker) | B4: 91000 | C4: 91200 | D4: 89700 | E4: 85000 | F4: 84000
A5: Production: Clinker | B5: 79616 | C5: 79489 | D5: 76789 | E5: 72000 | F5: 69000
A6: Shipments to final customers, includes exports | B6: 108969 | C6: 111092 | D6: 110290 | E6: 100000 | F6: 100000
A7: Imports for consumption: Hydraulic cement | B7: 19937 | C7: 24985 | D7: 24986 | E7: 23675 | F7: 23000
A8: Imports for consumption: Clinker | B8: 1563 | C8: 1021 | D8: 921 | E8: 685 | F8: 660
A9: Exports, hydraulic cement and clinker | B9: 939 | C9: 904 | D9: 889 | E9: 932 | F9: 1000
A10: Consumption, apparent (production incl. from imported clinker + imports excl. clinker - exports - stock changes) | B10: 111000 | C10: 114000 | D10: 113000 | E10: 110000 | F10: 110000
A11: Price, average mill unit value, dollars per metric ton | B11: 127 | C11: 139 | D11: 152 | E11: 160 | F11: 160
A12: Stocks, cement, yearend | B12: 6280 | C12: 8010 | D12: 8830 | E12: 9700 | F12: 8200
A13: Net import reliance as a percentage of apparent consumption | B13: 19 | C13: 22 | D13: 22 | E13: 22 | F13: 21
A15: World Production and Capacity (thousand metric tons) | B15: Cement production 2024 | C15: Cement production 2025e | D15: Clinker capacity 2024 | E15: Clinker capacity 2025e
A16: United States (includes Puerto Rico) | B16: 85000 | C16: 84000 | D16: 100000 | E16: 100000
A17: Brazil | B17: 65000 | C17: 67000 | D17: 60000 | E17: 61000
A18: China | B18: 1800000 | C18: 1700000 | D18: 1900000 | E18: 1800000
A19: Egypt | B19: 53000 | C19: 64000 | D19: 60000 | E19: 75000
A20: India | B20: 440000 | C20: 470000 | D20: 380000 | E20: 400000
A21: Indonesia | B21: 68000 | C21: 64000 | D21: 79000 | E21: 83000
A22: Iran | B22: 71000 | C22: 68000 | D22: 85000 | E22: 85000
A23: Japan | B23: 46000 | C23: 44000 | D23: 50000 | E23: 50000
A24: Korea, Republic of | B24: 44000 | C24: 37000 | D24: 62000 | E24: 62000
A25: Mexico | B25: 44000 | C25: 42000 | D25: 42000 | E25: 42000
A26: Russia | B26: 67000 | C26: 59000 | D26: 80000 | E26: 80000
A27: Saudi Arabia | B27: 51000 | C27: 54000 | D27: 75000 | E27: 75000
... A31: World total (rounded) | B31: 3900000 | C31: 3800000 | D31: 3800000 | E31: 3800000

Sheet Derivation
A1: Selected region | B1: =Regions!B1 -> United States
A2: Anchor share (blank region = 0) | B2: =IF(ISNUMBER(INDEX(Regions!$C$5:$C$14,MATCH(Regions!$B$1,Regions!$A$5:$A$14,0))),INDEX(Regions!$C$5:$C$14,MATCH(Regions!$B$1,Regions!$A$5:$A$14,0)),0) -> 0.24359878
A3: Is US? (history from USGS tab) | B3: =IF(B1="United States",1,0) -> 1
A5: US identity: 1 - clinker production / (apparent consumption x blend ratio)
A6: Year | B6: 2021 | C6: 2022 | D6: 2023 | E6: 2024 | F6: 2025
A7: Blend ratio (as BCtCR) | B7: =(('USGS MCS 2026 Cement'!B5+'USGS MCS 2026 Cement'!B8)/'USGS MCS 2026 Cement'!B4) -> 0.89207692 | C7: =(('USGS MCS 2026 Cement'!C5+'USGS MCS 2026 Cement'!C8)/'USGS MCS 2026 Cement'!C4) -> 0.88278509 | D7: =(('USGS MCS 2026 Cement'!D5+'USGS MCS 2026 Cement'!D8)/'USGS MCS 2026 Cement'!D4) -> 0.86633222 | E7: =(('USGS MCS 2026 Cement'!E5+'USGS MCS 2026 Cement'!E8)/'USGS MCS 2026 Cement'!E4) -> 0.85511765 | F7: =(('USGS MCS 2026 Cement'!F5+'USGS MCS 2026 Cement'!F8)/'USGS MCS 2026 Cement'!F4) -> 0.82928571
A8: Apparent consumption x ratio (clinker demand, kt) | B8: ='USGS MCS 2026 Cement'!B10*B7 -> 99020.538 | C8: ='USGS MCS 2026 Cement'!C10*C7 -> 100637.5 | D8: ='USGS MCS 2026 Cement'!D10*D7 -> 97895.541 | E8: ='USGS MCS 2026 Cement'!E10*E7 -> 94062.941 | F8: ='USGS MCS 2026 Cement'!F10*F7 -> 91221.429
A9: Domestic clinker production (kt) | B9: ='USGS MCS 2026 Cement'!B5 -> 79616 | C9: ='USGS MCS 2026 Cement'!C5 -> 79489 | D9: ='USGS MCS 2026 Cement'!D5 -> 76789 | E9: ='USGS MCS 2026 Cement'!E5 -> 72000 | F9: ='USGS MCS 2026 Cement'!F5 -> 69000
A10: Net import share | B10: =(1-B9/B8) -> 0.19596478 | C10: =(1-C9/C8) -> 0.21014532 | D10: =(1-D9/D8) -> 0.21560268 | E10: =(1-E9/E8) -> 0.23455509 | F10: =(1-F9/F8) -> 0.24359878 | G10: =F10 -> 0.24359878 | H10: <- 2025 anchor, used by the Regions US row
A11: Trade-flow cross-check: (cement imports x ratio + clinker imports - exports x ratio) / clinker demand | B11: =('USGS MCS 2026 Cement'!B7*B7+'USGS MCS 2026 Cement'!B8-'USGS MCS 2026 Cement'!B9*B7)/B8 -> 0.18693776 | C11: =('USGS MCS 2026 Cement'!C7*C7+'USGS MCS 2026 Cement'!C8-'USGS MCS 2026 Cement'!C9*C7)/C8 -> 0.22138217 | D11: =('USGS MCS 2026 Cement'!D7*D7+'USGS MCS 2026 Cement'!D8-'USGS MCS 2026 Cement'!D9*D7)/D8 -> 0.22265577 | E11: =('USGS MCS 2026 Cement'!E7*E7+'USGS MCS 2026 Cement'!E8-'USGS MCS 2026 Cement'!E9*E7)/E8 -> 0.2140369 | F11: =('USGS MCS 2026 Cement'!F7*F7+'USGS MCS 2026 Cement'!F8-'USGS MCS 2026 Cement'!F9*F7)/F8 -> 0.20723514
A13: Year | B13: 2021 | C13: 2022 | D13: 2023 | E13: 2024 | F13: 2025 | G13: 2026 | H13: 2027 | I13: 2028 | J13: 2029 | K13: 2030 | L13: 2031 | M13: 2032 | N13: 2033 | O13: 2034 | P13: 2035 | Q13: 2036 | R13: 2037 | S13: 2038 | T13: 2039 | U13: 2040 | V13: 2041 | W13: 2042 | X13: 2043 | Y13: 2044 | Z13: 2045 | AA13: 2046 | AB13: 2047 | AC13: 2048 | AD13: 2049 | AE13: 2050
A14: BAU Fraction of Clinker Demand Met by Net Imports | B14: =IF($B$3=1,B10,$B$2) -> 0.19596478 | C14: =IF($B$3=1,C10,$B$2) -> 0.21014532 | D14: =IF($B$3=1,D10,$B$2) -> 0.21560268 | E14: =IF($B$3=1,E10,$B$2) -> 0.23455509 | F14: =IF($B$3=1,F10,$B$2) -> 0.24359878 | G14: =$B$2 -> 0.24359878 | H14: =$B$2 -> 0.24359878 | I14: =$B$2 -> 0.24359878 | J14: =$B$2 -> 0.24359878 | K14: =$B$2 -> 0.24359878 | L14: =$B$2 -> 0.24359878 | M14: =$B$2 -> 0.24359878 | N14: =$B$2 -> 0.24359878 | ... AE14: =$B$2 -> 0.24359878

Sheet Checks
A1: Checks
A3: 2025 balance: consumption x ratio x (1 - share), kt (should be 69,000) | B3: ='USGS MCS 2026 Cement'!F10*Derivation!F7*(1-Derivation!F10) -> 69000
A4: Selected region has a sourced value? | B4: =IF(ISNUMBER(INDEX(Regions!$C$5:$C$14,MATCH(Regions!$B$1,Regions!$A$5:$A$14,0))),"PASS","WARN - blank row treated as 0 (self-sufficient)") -> PASS

Sheet BFoCDMbNI
A1: Unit: dimensionless | B1: 2021 | C1: 2022 | D1: 2023 | E1: 2024 | F1: 2025 | G1: 2026 | H1: 2027 | I1: 2028 | J1: 2029 | K1: 2030 | L1: 2031 | M1: 2032 | N1: 2033 | O1: 2034 | P1: 2035 | Q1: 2036 | R1: 2037 | S1: 2038 | T1: 2039 | U1: 2040 | V1: 2041 | W1: 2042 | X1: 2043 | Y1: 2044 | Z1: 2045 | AA1: 2046 | AB1: 2047 | AC1: 2048 | AD1: 2049 | AE1: 2050
A2: BAU Fraction of Clinker Demand Met by Net Imports | B2: =Derivation!B14 -> 0.19596478 | C2: =Derivation!C14 -> 0.21014532 | D2: =Derivation!D14 -> 0.21560268 | E2: =Derivation!E14 -> 0.23455509 | F2: =Derivation!F14 -> 0.24359878 | G2: =Derivation!G14 -> 0.24359878 | H2: =Derivation!H14 -> 0.24359878 | I2: =Derivation!I14 -> 0.24359878 | ... AE2: =Derivation!AE14 -> 0.24359878
