Workbook
Name Fraction_coal: [1]About!$C$53
Name gal_per_barrel: #REF!
Name Percent_rural: [1]About!$A$75
Name Percent_urban: [1]About!$A$74
Name quadrillion: [1]About!$B$77
Name Table4: #REF!
Name Table4_1: #REF!
Name Table4_1_22: #REF!
Name Table4_22: #REF!
Name Table4_A: #REF!
Name Table4_A_22: #REF!
Name Table5: #REF!
Name Table5_1: #REF!
Name Table5_1_22: #REF!
Name Table5_22: #REF!
Name Table5_A: #REF!
Name Table5_A_22: #REF!

Sheet About
A1: BDCL BAU Data Center Load
A3: Sources: | B3: Projected Demand through 2030 | D3: Historic Demand, Projected Demand for mid and high scenarios
B4: EPRI | D4: IEA
B5: 2026 | D5: 2026
B6: Powering Intelligence 2026 | D6: Key Questions on Energy and AI
B7: https://powering-intelligence.epri.com/ | D7: https://www.iea.org/reports/key-questions-on-energy-and-ai
B8: U.S. National data download | D8: Table A.4: Data centres electricity consumption by region
B10: Low Demand Scenario
B11: EIA
B12: 2025
B13: Annual Energy Outlook 2026
B14: https://www.eia.gov/outlooks/aeo/
B15: Table 5
B17: 2030-2050 Demand for Mid and High Scenarios
B18: Evolved Energy Research
B19: 2024
B20: 2024 U.S. Annual Decarbonization Perspective
B21: https://www.evolved.energy/us-adp-2024
A23: We use EPRI forecasts through 2030 for our low-, medium-, and high-demand projections.
A24: After 2030, we use AEO for the low scenario, and Evolved Energy's Annual Decarbonization
A25: Perspective mid- and high-growth scenarios for the EPS equivalents.
A27: Notes on Data Center Load in AEO
A28: AEO 2026 breaks out data center server demand explicitly, but leaves associated cooling and
A29: ventilation baked into other commercial building end uses. We use the data center server
A30: demand alone for the "low" scenario forecasting in EPS.
A33: quad to TWh
A34: 293
A36: End-use split | B36: Each scenario's data center load is split into two end uses that the model treats separately: IT load (the 'other component' row) and facility load for cooling, ventilation and power distribution (the 'cooling and ventilation' row). The split comes from the power usage effectiveness (PUE) path on the 'End Use Split' tab. Totals are unchanged by the split.

Sheet Low_Mid_High Scenarios
B1: Full Time Series
A2: Scenario | B2: 2024 | C2: =B2+1 -> 2025 | D2: =C2+1 -> 2026 | E2: =D2+1 -> 2027 | F2: =E2+1 -> 2028 | G2: =F2+1 -> 2029 | H2: =G2+1 -> 2030 | I2: =H2+1 -> 2031 | J2: =I2+1 -> 2032 | ... AB2: =AA2+1 -> 2050
A3: low | B3: =EPRI!$F$5 -> 184 | C3: =IEA!$D$24 -> 224 | D3: {=$C$3+TRANSPOSE(EPRI!G8:G12)} -> 263 | E3: 308 | F3: 345 | G3: 371 | H3: 396 | I3: =H3+('AEO 2026 Table 5'!K24-'AEO 2026 Table 5'!J24)*About!$A$34 -> 411.49091 | J3: =I3+('AEO 2026 Table 5'!L24-'AEO 2026 Table 5'!K24)*About!$A$34 -> 427.27921 | K3: =J3+('AEO 2026 Table 5'!M24-'AEO 2026 Table 5'!L24)*About!$A$34 -> 443.357 | L3: =K3+('AEO 2026 Table 5'!N24-'AEO 2026 Table 5'!M24)*About!$A$34 -> 459.66919 | M3: =L3+('AEO 2026 Table 5'!O24-'AEO 2026 Table 5'!N24)*About!$A$34 -> 476.16832 | N3: =M3+('AEO 2026 Table 5'!P24-'AEO 2026 Table 5'!O24)*About!$A$34 -> 492.77204 | O3: =N3+('AEO 2026 Table 5'!Q24-'AEO 2026 Table 5'!P24)*About!$A$34 -> 509.4036 | P3: =O3+('AEO 2026 Table 5'!R24-'AEO 2026 Table 5'!Q24)*About!$A$34 -> 525.85731 | ... AB3: =AA3+('AEO 2026 Table 5'!AD24-'AEO 2026 Table 5'!AC24)*About!$A$34 -> 663.20985
A4: mid | B4: =B3 -> 184 | C4: =IEA!$D$24 -> 224 | D4: {=$C$4+TRANSPOSE(EPRI!G15:G19)} -> 290 | E4: 369 | F4: 448 | G4: 518 | H4: 585 | I4: =H4+I27-H27 -> 615.4 | J4: =I4+J27-I27 -> 645.8 | K4: =J4+K27-J27 -> 676.2 | L4: =K4+L27-K27 -> 706.6 | M4: =L4+M27-L27 -> 737 | N4: =M4+N27-M27 -> 753.6 | O4: =N4+O27-N27 -> 770.2 | P4: =O4+P27-O27 -> 786.8 | ... AB4: =AA4+AB27-AA27 -> 914
A5: high | B5: =B3 -> 184 | C5: =IEA!$D$24 -> 224 | D5: {=C5+TRANSPOSE(EPRI!G22:G26)} -> 314 | E5: 425 | F5: 544 | G5: 653 | H5: 760 | I5: =H5+I31-H31 -> 825 | J5: =I5+J31-I31 -> 890 | K5: =J5+K31-J31 -> 955 | L5: =K5+L31-K31 -> 1020 | M5: =L5+M31-L31 -> 1085 | N5: =M5+N31-M31 -> 1120.8 | O5: =N5+O31-N31 -> 1156.6 | P5: =O5+P31-O31 -> 1192.4 | ... AB5: =AA5+AB31-AA31 -> 1721
A6: mid share of AEO commercial | C6: =C4/'AEO 2026 Table 5'!E30/About!$A$34 -> 0.15212903 | D6: =D4/'AEO 2026 Table 5'!F30/About!$A$34 -> 0.18839537 | E6: =E4/'AEO 2026 Table 5'!G30/About!$A$34 -> 0.23731045 | F6: =F4/'AEO 2026 Table 5'!H30/About!$A$34 -> 0.28444522 | G6: =G4/'AEO 2026 Table 5'!I30/About!$A$34 -> 0.32478631 | H6: =H4/'AEO 2026 Table 5'!J30/About!$A$34 -> 0.36370223 | I6: =I4/'AEO 2026 Table 5'!K30/About!$A$34 -> 0.37910936 | J6: =J4/'AEO 2026 Table 5'!L30/About!$A$34 -> 0.39388989 | ... AB6: =AB4/'AEO 2026 Table 5'!AD30/About!$A$34 -> 0.45488002
A8: Color Code
B9: EPRI Historical
B10: IEA Historical
B11: AEO
B12: EPRI Low
B13: EPRI Mid
B14: EPRI High
B15: ADP mid growth rate
B16: ADP high growth rate
B18: Extrapolated ADO Trajectories
B19: use mid case growth trajectory from Evolved Energy
B20: Growth Rate Estimates
C21: 2025 | D21: 2030 | E21: 2035 | F21: 2040 | G21: 2050
B22: evolved energy mid | C22: ='Evolved Energy ADP 2024'!C4 -> 279 | D22: ='Evolved Energy ADP 2024'!D4 -> 541 | E22: ='Evolved Energy ADP 2024'!E4 -> 693 | F22: ='Evolved Energy ADP 2024'!F4 -> 776 | G22: ='Evolved Energy ADP 2024'!G4 -> 870
B23: evolved energy high | C23: ='Evolved Energy ADP 2024'!C5 -> 279 | D23: ='Evolved Energy ADP 2024'!D5 -> 718 | E23: ='Evolved Energy ADP 2024'!E5 -> 1043 | F23: ='Evolved Energy ADP 2024'!F5 -> 1222 | G23: ='Evolved Energy ADP 2024'!G5 -> 1679
C26: 2025 | D26: 2026 | E26: 2027 | F26: 2028 | G26: 2029 | H26: =G26+1 -> 2030 | I26: =H26+1 -> 2031 | J26: =I26+1 -> 2032 | K26: =J26+1 -> 2033 | L26: =K26+1 -> 2034 | M26: =L26+1 -> 2035 | N26: =M26+1 -> 2036 | O26: =N26+1 -> 2037 | ... AB26: =AA26+1 -> 2050
B27: evolved energy mid | C27: =HLOOKUP(C26,$C$21:$G$22,2,FALSE) -> 279 | D27: {=TREND($C$22:$D$22,$C$21:$D$21,D26)} -> 331.4 | E27: {=TREND($C$22:$D$22,$C$21:$D$21,E26)} -> 383.8 | F27: {=TREND($C$22:$D$22,$C$21:$D$21,F26)} -> 436.2 | G27: {=TREND($C$22:$D$22,$C$21:$D$21,G26)} -> 488.6 | H27: =HLOOKUP(H26,$C$21:$G$22,2,FALSE) -> 541 | I27: {=TREND($D$22:$E$22,$D$21:$E$21,I26)} -> 571.4 | J27: {=TREND($D$22:$E$22,$D$21:$E$21,J26)} -> 601.8 | K27: {=TREND($D$22:$E$22,$D$21:$E$21,K26)} -> 632.2 | L27: {=TREND($D$22:$E$22,$D$21:$E$21,L26)} -> 662.6 | M27: =HLOOKUP(M26,$C$21:$G$22,2,FALSE) -> 693 | N27: {=TREND($E$22:$F$22,$E$21:$F$21,N26)} -> 709.6 | O27: {=TREND($E$22:$F$22,$E$21:$F$21,O26)} -> 726.2 | P27: {=TREND($E$22:$F$22,$E$21:$F$21,P26)} -> 742.8 | Q27: {=TREND($E$22:$F$22,$E$21:$F$21,Q26)} -> 759.4 | R27: =HLOOKUP(R26,$C$21:$G$22,2,FALSE) -> 776 | S27: {=TREND($F$22:$G$22,$F$21:$G$21,S26)} -> 785.4 | T27: {=TREND($F$22:$G$22,$F$21:$G$21,T26)} -> 794.8 | U27: {=TREND($F$22:$G$22,$F$21:$G$21,U26)} -> 804.2 | V27: {=TREND($F$22:$G$22,$F$21:$G$21,V26)} -> 813.6 | W27: {=TREND($F$22:$G$22,$F$21:$G$21,W26)} -> 823 | X27: {=TREND($F$22:$G$22,$F$21:$G$21,X26)} -> 832.4 | Y27: {=TREND($F$22:$G$22,$F$21:$G$21,Y26)} -> 841.8 | Z27: {=TREND($F$22:$G$22,$F$21:$G$21,Z26)} -> 851.2 | AA27: {=TREND($F$22:$G$22,$F$21:$G$21,AA26)} -> 860.6 | AB27: =HLOOKUP(AB26,$C$21:$G$22,2,FALSE) -> 870
A28: ADP | B28: growth rate | D28: =E28 -> 0.056192237 | E28: =F28 -> 0.056192237 | F28: =G28 -> 0.056192237 | G28: =H28 -> 0.056192237 | H28: =I28 -> 0.056192237 | I28: =I27/H27-1 -> 0.056192237 | J28: =J27/I27-1 -> 0.05320266 | K28: =K27/J27-1 -> 0.050515121 | L28: =L27/K27-1 -> 0.048086049 | M28: =M27/L27-1 -> 0.045879867 | N28: =N27/M27-1 -> 0.023953824 | O28: =O27/N27-1 -> 0.023393461 | P28: =P27/O27-1 -> 0.022858717 | ... AB28: =AB27/AA27-1 -> 0.010922612
C30: 2025 | D30: 2026 | E30: 2027 | F30: 2028 | G30: 2029 | H30: =G30+1 -> 2030 | I30: =H30+1 -> 2031 | J30: =I30+1 -> 2032 | K30: =J30+1 -> 2033 | L30: =K30+1 -> 2034 | M30: =L30+1 -> 2035 | N30: =M30+1 -> 2036 | O30: =N30+1 -> 2037 | ... AB30: =AA30+1 -> 2050
B31: evolved energy high | C31: =HLOOKUP(C30,$C$21:$G$23,3,FALSE) -> 279 | D31: {=TREND($C$23:$D$23,$C$21:$D$21,D30)} -> 366.8 | E31: {=TREND($C$23:$D$23,$C$21:$D$21,E30)} -> 454.6 | F31: {=TREND($C$23:$D$23,$C$21:$D$21,F30)} -> 542.4 | G31: {=TREND($C$23:$D$23,$C$21:$D$21,G30)} -> 630.2 | H31: =HLOOKUP(H30,$C$21:$G$23,3,FALSE) -> 718 | I31: {=TREND($D$23:$E$23,$D$21:$E$21,I30)} -> 783 | J31: {=TREND($D$23:$E$23,$D$21:$E$21,J30)} -> 848 | K31: {=TREND($D$23:$E$23,$D$21:$E$21,K30)} -> 913 | L31: {=TREND($D$23:$E$23,$D$21:$E$21,L30)} -> 978 | M31: =HLOOKUP(M30,$C$21:$G$23,3,FALSE) -> 1043 | N31: {=TREND($E$23:$F$23,$E$21:$F$21,N30)} -> 1078.8 | O31: {=TREND($E$23:$F$23,$E$21:$F$21,O30)} -> 1114.6 | P31: {=TREND($E$23:$F$23,$E$21:$F$21,P30)} -> 1150.4 | Q31: {=TREND($E$23:$F$23,$E$21:$F$21,Q30)} -> 1186.2 | R31: =HLOOKUP(R30,$C$21:$G$23,3,FALSE) -> 1222 | S31: {=TREND($F$23:$G$23,$F$21:$G$21,S30)} -> 1267.7 | T31: {=TREND($F$23:$G$23,$F$21:$G$21,T30)} -> 1313.4 | U31: {=TREND($F$23:$G$23,$F$21:$G$21,U30)} -> 1359.1 | V31: {=TREND($F$23:$G$23,$F$21:$G$21,V30)} -> 1404.8 | W31: {=TREND($F$23:$G$23,$F$21:$G$21,W30)} -> 1450.5 | X31: {=TREND($F$23:$G$23,$F$21:$G$21,X30)} -> 1496.2 | Y31: {=TREND($F$23:$G$23,$F$21:$G$21,Y30)} -> 1541.9 | Z31: {=TREND($F$23:$G$23,$F$21:$G$21,Z30)} -> 1587.6 | AA31: {=TREND($F$23:$G$23,$F$21:$G$21,AA30)} -> 1633.3 | AB31: =HLOOKUP(AB30,$C$21:$G$23,3,FALSE) -> 1679
A32: ADP high | B32: growth rate | C32: =D32 -> 0.090529248 | D32: =E32 -> 0.090529248 | E32: =F32 -> 0.090529248 | F32: =G32 -> 0.090529248 | G32: =H32 -> 0.090529248 | H32: =I32 -> 0.090529248 | I32: =I31/H31-1 -> 0.090529248 | J32: =J31/I31-1 -> 0.083014049 | K32: =K31/J31-1 -> 0.076650943 | L32: =L31/K31-1 -> 0.071193866 | M32: =M31/L31-1 -> 0.066462168 | N32: =N31/M31-1 -> 0.034324065 | O32: =O31/N31-1 -> 0.03318502 | P32: =P31/O31-1 -> 0.032119146 | ... AB32: =AB31/AA31-1 -> 0.027980163

Sheet End Use Split
A1: Data center end-use split (facility vs IT load)
A2: PUE = total facility electricity / IT electricity. IT load goes to the 'other component' row, facility load (cooling, ventilation, power distribution) to 'cooling and ventilation'. Source: LBNL, 2024 United States Data Center Energy Usage Report (Shehabi et al., LBNL-2001637, Dec 2024): US average PUE 1.4 in 2023 (p. 47; infrastructure 30% of total electricity, p. 53) falling to 1.15-1.35 by 2028 (p. 47, Fig. 4.6). The path used here starts at 1.40 in 2024 and falls in a straight line to 1.25 in 2028 (the middle of LBNL's range), then holds flat; the same path is used for all three load scenarios. To use a different path, change cells B4:B7.
A4: PUE in first year | B4: 1.4
A5: First year | B5: 2024
A6: PUE in target year | B6: 1.25
A7: Target year (held flat after) | B7: 2028
A9: Year | B9: 2024 | C9: 2025 | D9: 2026 | E9: 2027 | F9: 2028 | G9: 2029 | H9: 2030 | I9: 2031 | J9: 2032 | K9: 2033 | L9: 2034 | M9: 2035 | N9: 2036 | O9: 2037 | P9: 2038 | Q9: 2039 | R9: 2040 | S9: 2041 | T9: 2042 | U9: 2043 | V9: 2044 | W9: 2045 | X9: 2046 | Y9: 2047 | Z9: 2048 | AA9: 2049 | AB9: 2050
A10: PUE | B10: =IF(B$9<=$B$5,$B$4,IF(B$9>=$B$7,$B$6,$B$4+($B$6-$B$4)*(B$9-$B$5)/($B$7-$B$5))) -> 1.4 | C10: =IF(C$9<=$B$5,$B$4,IF(C$9>=$B$7,$B$6,$B$4+($B$6-$B$4)*(C$9-$B$5)/($B$7-$B$5))) -> 1.3625 | D10: =IF(D$9<=$B$5,$B$4,IF(D$9>=$B$7,$B$6,$B$4+($B$6-$B$4)*(D$9-$B$5)/($B$7-$B$5))) -> 1.325 | E10: =IF(E$9<=$B$5,$B$4,IF(E$9>=$B$7,$B$6,$B$4+($B$6-$B$4)*(E$9-$B$5)/($B$7-$B$5))) -> 1.2875 | F10: =IF(F$9<=$B$5,$B$4,IF(F$9>=$B$7,$B$6,$B$4+($B$6-$B$4)*(F$9-$B$5)/($B$7-$B$5))) -> 1.25 | G10: =IF(G$9<=$B$5,$B$4,IF(G$9>=$B$7,$B$6,$B$4+($B$6-$B$4)*(G$9-$B$5)/($B$7-$B$5))) -> 1.25 | H10: =IF(H$9<=$B$5,$B$4,IF(H$9>=$B$7,$B$6,$B$4+($B$6-$B$4)*(H$9-$B$5)/($B$7-$B$5))) -> 1.25 | I10: =IF(I$9<=$B$5,$B$4,IF(I$9>=$B$7,$B$6,$B$4+($B$6-$B$4)*(I$9-$B$5)/($B$7-$B$5))) -> 1.25 | ... AB10: =IF(AB$9<=$B$5,$B$4,IF(AB$9>=$B$7,$B$6,$B$4+($B$6-$B$4)*(AB$9-$B$5)/($B$7-$B$5))) -> 1.25
A11: Facility share (cooling and ventilation) = 1 - 1/PUE | B11: =1-1/B10 -> 0.28571429 | C11: =1-1/C10 -> 0.26605505 | D11: =1-1/D10 -> 0.24528302 | E11: =1-1/E10 -> 0.22330097 | F11: =1-1/F10 -> 0.2 | G11: =1-1/G10 -> 0.2 | H11: =1-1/H10 -> 0.2 | I11: =1-1/I10 -> 0.2 | ... AB11: =1-1/AB10 -> 0.2
A12: IT share (other component) = 1/PUE | B12: =1/B10 -> 0.71428571 | C12: =1/C10 -> 0.73394495 | D12: =1/D10 -> 0.75471698 | E12: =1/E10 -> 0.77669903 | F12: =1/F10 -> 0.8 | G12: =1/G10 -> 0.8 | H12: =1/H10 -> 0.8 | I12: =1/I10 -> 0.8 | ... AB12: =1/AB10 -> 0.8

Sheet EPRI
A1: Scenario | B1: State | C1: Year | D1: Nominal Capacity (GW) | E1: Peak Load (GW) | F1: Annual Energy (TWh)
A2: Historical | B2: US | C2: 2021 | D2: 10.5 | E2: 10.3 | F2: 91.4
A3: Historical | B3: US | C3: 2022 | D3: 16 | E3: 13.9 | F3: 116
A4: Historical | B4: US | C4: 2023 | D4: 25.5 | E4: 16.7 | F4: 141
A5: Historical | B5: US | C5: 2024 | D5: 39.8 | E5: 21.5 | F5: 184
A6: Low | B6: US | C6: 2024 | D6: 35.1 | E6: 20.7 | F6: 177
A7: Low | B7: US | C7: 2025 | D7: 38.7 | E7: 24.8 | F7: 212
A8: Low | B8: US | C8: 2026 | D8: 42.2 | E8: 29.7 | F8: 251 | G8: =F8-$F$7 -> 39
A9: Low | B9: US | C9: 2027 | D9: 45.6 | E9: 35.1 | F9: 296 | G9: =F9-$F$7 -> 84
A10: Low | B10: US | C10: 2028 | D10: 49.1 | E10: 39.4 | F10: 333 | G10: =F10-$F$7 -> 121
A11: Low | B11: US | C11: 2029 | D11: 52.6 | E11: 42.5 | F11: 359 | G11: =F11-$F$7 -> 147
A12: Low | B12: US | C12: 2030 | D12: 56.1 | E12: 45.4 | F12: 384 | G12: =F12-$F$7 -> 172
A13: Medium | B13: US | C13: 2024 | D13: 39.8 | E13: 21.5 | F13: 184
A14: Medium | B14: US | C14: 2025 | D14: 49.1 | E14: 27.7 | F14: 235
A15: Medium | B15: US | C15: 2026 | D15: 58.5 | E15: 35.5 | F15: 301 | G15: =F15-$F$14 -> 66
A16: Medium | B16: US | C16: 2027 | D16: 67.8 | E16: 45 | F16: 380 | G16: =F16-$F$14 -> 145
A17: Medium | B17: US | C17: 2028 | D17: 77.2 | E17: 54.4 | F17: 459 | G17: =F17-$F$14 -> 224
A18: Medium | B18: US | C18: 2029 | D18: 86.5 | E18: 62.6 | F18: 529 | G18: =F18-$F$14 -> 294
A19: Medium | B19: US | C19: 2030 | D19: 95.9 | E19: 70.7 | F19: 596 | G19: =F19-$F$14 -> 361
A20: High | B20: US | C20: 2024 | D20: 44.5 | E20: 22.4 | F20: 192
A21: High | B21: US | C21: 2025 | D21: 59.1 | E21: 30.4 | F21: 258
A22: High | B22: US | C22: 2026 | D22: 73.8 | E22: 41.1 | F22: 348 | G22: =F22-$F$21 -> 90
A23: High | B23: US | C23: 2027 | D23: 88.5 | E23: 54.4 | F23: 459 | G23: =F23-$F$21 -> 201
A24: High | B24: US | C24: 2028 | D24: 103 | E24: 68.5 | F24: 578 | G24: =F24-$F$21 -> 320
A25: High | B25: US | C25: 2029 | D25: 118 | E25: 81.5 | F25: 687 | G25: =F25-$F$21 -> 429
A26: High | B26: US | C26: 2030 | D26: 132 | E26: 94 | F26: 794 | G26: =F26-$F$21 -> 536

Sheet IEA
B23: TWh | C23: 2024 | D23: 2025 | E23: 2030
B24: United States | C24: 183 | D24: 224 | E24: 426

Sheet AEO 2026 Table 5
A1: Table 5. Commercial Sector Key Indicators and Consumption
A2: https://www.eia.gov/outlooks/aeo/data/browser/#/?id=5-AEO2026&cases=electrnp&sourcekey=0
A3: Wed May 13 2026 10:18:16 GMT-0400 (Eastern Daylight Time)
A4: Source: U.S. Energy Information Administration
B5: full name | C5: api key | D5: units | E5: 2025 | F5: 2026 | G5: 2027 | H5: 2028 | I5: 2029 | J5: 2030 | K5: 2031 | L5: 2032 | M5: 2033 | N5: 2034 | O5: 2035 | P5: 2036 | Q5: 2037 | R5: 2038 | S5: 2039 | T5: 2040 | U5: 2041 | V5: 2042 | W5: 2043 | X5: 2044 | Y5: 2045 | Z5: 2046 | AA5: 2047 | AB5: 2048 | AC5: 2049 | AD5: 2050 | AE5: Growth (2025-2050)
A6: Key Indicators
A7: Total Floorspace (billion square feet)
A8: Surviving | B8: Commercial: Total Floorspace: Surviving: Alternative Electricity and Transportation | C8: AEO.2026.ELECTRNP.KEI_NA_COMM_NA_TFP_SURV_USA_BLNSQFT.A | D8: billion sq ft | E8: 101.84551 | F8: 103.10442 | G8: 104.31425 | H8: 105.48232 | I8: 106.62843 | J8: 107.75984 | K8: 108.90231 | L8: 110.07059 | M8: 111.26775 | N8: 112.50001 | O8: 113.76868 | P8: 115.07391 | Q8: 116.41436 | R8: 117.78051 | S8: 119.11474 | T8: 120.4153 | U8: 121.68447 | V8: 122.89786 | W8: 124.06418 | X8: 125.19847 | Y8: 126.30771 | Z8: 127.40099 | AA8: 128.48196 | AB8: 129.55205 | AC8: 130.61298 | AD8: 131.66556 | AE8: 0.01
A9: New Additions | B9: Commercial: Total Floorspace: New Additions: Alternative Electricity and Transportation | C9: AEO.2026.ELECTRNP.KEI_NA_COMM_NA_TFP_NADN_USA_BLNSQFT.A | D9: billion sq ft | E9: 2.798354 | F9: 2.763133 | G9: 2.73562 | H9: 2.728133 | I9: 2.728127 | J9: 2.754144 | K9: 2.795398 | L9: 2.840164 | M9: 2.891744 | N9: 2.945178 | O9: 2.999384 | P9: 3.052837 | Q9: 3.097313 | R9: 3.084287 | S9: 3.069424 | T9: 3.056657 | U9: 3.019132 | V9: 2.989726 | W9: 2.974996 | X9: 2.966822 | Y9: 2.967411 | Z9: 2.971346 | AA9: 2.976496 | AB9: 2.983037 | AC9: 2.990272 | AD9: 2.998542 | AE9: 0.003
A10: Total | B10: Commercial: Total Floorspace: Total: Alternative Electricity and Transportation | C10: AEO.2026.ELECTRNP.KEI_NA_COMM_NA_TFP_TOT_USA_BLNSQFT.A | D10: billion sq ft | E10: 104.64386 | F10: 105.86755 | G10: 107.04987 | H10: 108.21046 | I10: 109.35656 | J10: 110.51399 | K10: 111.69771 | L10: 112.91075 | M10: 114.15949 | N10: 115.44518 | O10: 116.76806 | P10: 118.12675 | Q10: 119.51167 | R10: 120.8648 | S10: 122.18417 | T10: 123.47195 | U10: 124.70361 | V10: 125.88759 | W10: 127.03918 | X10: 128.1653 | Y10: 129.27512 | Z10: 130.37233 | AA10: 131.45847 | AB10: 132.53508 | AC10: 133.60324 | AD10: 134.66409 | AE10: 0.01
A11: Energy Consumption Intensity
A12: (thousand Btu per square foot)
A13: Gross End-use Consumption | B13: Commercial: Energy Use Intensity: Gross End-use Consumption: Alternative Electricity and Transportation | C13: AEO.2026.ELECTRNP.INY_NA_COMM_NA_EUI_DLENCONS_USA_THBTUPSQFT.A | D13: thousand Btu/sq ft | E13: 94.608612 | F13: 95.200951 | G13: 94.894547 | H13: 94.391609 | I13: 93.678154 | J13: 92.73333 | K13: 91.840523 | L13: 91.140854 | M13: 90.533226 | N13: 90.025192 | O13: 89.527039 | P13: 89.104965 | Q13: 88.683937 | R13: 88.304733 | S13: 87.952103 | T13: 87.609711 | U13: 87.320465 | V13: 87.099518 | W13: 86.907028 | X13: 86.73526 | Y13: 86.553421 | Z13: 86.303925 | AA13: 85.985275 | AB13: 85.63308 | AC13: 85.264458 | AD13: 84.897255 | AE13: -0.004
A14: Delivered Energy Consumption | B14: Commercial: Energy Use Intensity: Delivered Energy Consumption: Alternative Electricity and Transportation | C14: AEO.2026.ELECTRNP.INY_NA_COMM_NA_EUI_ERL_USA_THBTUPSQFT.A | D14: thousand Btu/sq ft | E14: 93.084305 | F14: 93.513206 | G14: 93.074776 | H14: 92.51963 | I14: 91.782715 | J14: 90.809181 | K14: 89.899635 | L14: 89.19178 | M14: 88.573189 | N14: 88.038452 | O14: 87.524017 | P14: 87.092613 | Q14: 86.638893 | R14: 86.228638 | S14: 85.833717 | T14: 85.458237 | U14: 85.160706 | V14: 84.916267 | W14: 84.720146 | X14: 84.541443 | Y14: 84.357269 | Z14: 84.093651 | AA14: 83.753242 | AB14: 83.378761 | AC14: 82.997833 | AD14: 82.609665 | AE14: -0.005
A15: Energy Consumption by Fuel
A16: Electricity
A17: Space Heating | B17: Commercial: Purchased Electricity: Space Heating: Alternative Electricity and Transportation | C17: AEO.2026.ELECTRNP.CNSM_NA_COMM_NA_PRC_SPH_USA_QBTU.A | D17: quads | E17: 0.20086 | F17: 0.193991 | G17: 0.19233 | H17: 0.191237 | I17: 0.18969 | J17: 0.187902 | K17: 0.186031 | L17: 0.184106 | M17: 0.18223 | N17: 0.180242 | O17: 0.1782 | P17: 0.176227 | Q17: 0.174101 | R17: 0.171933 | S17: 0.169663 | T17: 0.167366 | U17: 0.165099 | V17: 0.162808 | W17: 0.160509 | X17: 0.158156 | Y17: 0.155824 | Z17: 0.153355 | AA17: 0.150715 | AB17: 0.148032 | AC17: 0.145385 | AD17: 0.142671 | AE17: -0.014
A18: Space Cooling | B18: Commercial: Purchased Electricity: Space Cooling: Alternative Electricity and Transportation | C18: AEO.2026.ELECTRNP.CNSM_NA_COMM_NA_PRC_SPC_USA_QBTU.A | D18: quads | E18: 0.566839 | F18: 0.594472 | G18: 0.600861 | H18: 0.609032 | I18: 0.61581 | J18: 0.620066 | K18: 0.624956 | L18: 0.630446 | M18: 0.636408 | N18: 0.642945 | O18: 0.649799 | P18: 0.657449 | Q18: 0.665266 | R18: 0.673226 | S18: 0.681101 | T18: 0.689312 | U18: 0.697981 | V18: 0.707102 | W18: 0.716932 | X18: 0.727006 | Y18: 0.737548 | Z18: 0.747668 | AA18: 0.757338 | AB18: 0.766944 | AC18: 0.777089 | AD18: 0.787237 | AE18: 0.013
A19: Water Heating | B19: Commercial: Purchased Electricity: Water Heating: Alternative Electricity and Transportation | C19: AEO.2026.ELECTRNP.CNSM_NA_COMM_NA_PRC_WTHT_USA_QBTU.A | D19: quads | E19: 0.073797 | F19: 0.072726 | G19: 0.072052 | H19: 0.07164 | I19: 0.071071 | J19: 0.070187 | K19: 0.069283 | L19: 0.068399 | M19: 0.067566 | N19: 0.066746 | O19: 0.065932 | P19: 0.065184 | Q19: 0.064425 | R19: 0.063673 | S19: 0.062916 | T19: 0.062153 | U19: 0.061431 | V19: 0.060716 | W19: 0.060034 | X19: 0.059364 | Y19: 0.058695 | Z19: 0.058002 | AA19: 0.057258 | AB19: 0.056503 | AC19: 0.055764 | AD19: 0.055011 | AE19: -0.012
A20: Ventilation | B20: Commercial: Purchased Electricity: Ventilation: Alternative Electricity and Transportation | C20: AEO.2026.ELECTRNP.CNSM_NA_COMM_NA_PRC_VNTC_USA_QBTU.A | D20: quads | E20: 0.772579 | F20: 0.778081 | G20: 0.787216 | H20: 0.798948 | I20: 0.808617 | J20: 0.812848 | K20: 0.817403 | L20: 0.822489 | M20: 0.828422 | N20: 0.834734 | O20: 0.841408 | P20: 0.84894 | Q20: 0.856496 | R20: 0.864206 | S20: 0.871853 | T20: 0.879611 | U20: 0.887874 | V20: 0.896257 | W20: 0.905085 | X20: 0.914164 | Y20: 0.923373 | Z20: 0.932169 | AA20: 0.940261 | AB20: 0.948153 | AC20: 0.956425 | AD20: 0.964518 | AE20: 0.009
A21: Cooking | B21: Commercial: Purchased Electricity: Cooking: Alternative Electricity and Transportation | C21: AEO.2026.ELECTRNP.CNSM_NA_COMM_NA_PRC_CGR_USA_QBTU.A | D21: quads | E21: 0.083991 | F21: 0.083245 | G21: 0.082882 | H21: 0.08275 | I21: 0.082396 | J21: 0.081708 | K21: 0.080997 | L21: 0.080317 | M21: 0.079704 | N21: 0.079116 | O21: 0.078533 | P21: 0.077998 | Q21: 0.077442 | R21: 0.076881 | S21: 0.076298 | T21: 0.075702 | U21: 0.075151 | V21: 0.074597 | W21: 0.074065 | X21: 0.073538 | Y21: 0.073002 | Z21: 0.072417 | AA21: 0.071763 | AB21: 0.071082 | AC21: 0.070415 | AD21: 0.069721 | AE21: -0.007
A22: Lighting | B22: Commercial: Purchased Electricity: Lighting: Alternative Electricity and Transportation | C22: AEO.2026.ELECTRNP.CNSM_NA_COMM_NA_PRC_LGHTNG_USA_QBTU.A | D22: quads | E22: 0.564649 | F22: 0.553328 | G22: 0.547329 | H22: 0.54543 | I22: 0.543588 | J22: 0.532318 | K22: 0.522622 | L22: 0.5142 | M22: 0.506779 | N22: 0.499778 | O22: 0.492952 | P22: 0.487289 | Q22: 0.482486 | R22: 0.478498 | S22: 0.475119 | T22: 0.470122 | U22: 0.466407 | V22: 0.463482 | W22: 0.461297 | X22: 0.459643 | Y22: 0.458401 | Z22: 0.457258 | AA22: 0.455994 | AB22: 0.454706 | AC22: 0.453692 | AD22: 0.452695 | AE22: -0.009
A23: Refrigeration | B23: Commercial: Purchased Electricity: Refrigeration: Alternative Electricity and Transportation | C23: AEO.2026.ELECTRNP.CNSM_NA_COMM_NA_PRC_REFR_USA_QBTU.A | D23: quads | E23: 0.366734 | F23: 0.365953 | G23: 0.366174 | H23: 0.367 | I23: 0.367563 | J23: 0.366644 | K23: 0.366206 | L23: 0.366109 | M23: 0.36639 | N23: 0.36695 | O23: 0.367756 | P23: 0.368848 | Q23: 0.370046 | R23: 0.371239 | S23: 0.372383 | T23: 0.373485 | U23: 0.374828 | V23: 0.376102 | W23: 0.37739 | X23: 0.378663 | Y23: 0.379901 | Z23: 0.381014 | AA23: 0.381955 | AB23: 0.382807 | AC23: 0.383654 | AD23: 0.384415 | AE23: 0.002
A24: Data Center Servers | B24: Commercial: Purchased Electricity: Data Center Servers: Alternative Electricity and Transportation | C24: AEO.2026.ELECTRNP.CNSM_NA_COMM_NA_PRC_DATACTRSERV_USA_QBTU.A | D24: quads | E24: 0.357691 | F24: 0.403698 | G24: 0.452968 | H24: 0.503864 | I24: 0.555801 | J24: 0.608106 | K24: 0.660976 | L24: 0.714861 | M24: 0.769734 | N24: 0.825407 | O24: 0.881718 | P24: 0.938386 | Q24: 0.995149 | R24: 1.051305 | S24: 1.106359 | T24: 1.159801 | U24: 1.211428 | V24: 1.260422 | W24: 1.30683 | X24: 1.349851 | Y24: 1.389499 | Z24: 1.424823 | AA24: 1.455517 | AB24: 1.481245 | AC24: 1.501816 | AD24: 1.520085 | AE24: 0.06
A25: Computers and office equipment | B25: Commercial: Purchased Electricity: Computers and Office Equipment: Alternative Electricity and Transportation | C25: AEO.2026.ELECTRNP.CNSM_NA_COMM_NA_PRC_OTHEQP_USA_QBTU.A | D25: quads | E25: 0.216953 | F25: 0.211745 | G25: 0.207122 | H25: 0.202684 | I25: 0.198262 | J25: 0.193913 | K25: 0.189829 | L25: 0.18572 | M25: 0.182465 | N25: 0.179709 | O25: 0.177067 | P25: 0.175041 | Q25: 0.173177 | R25: 0.171447 | S25: 0.170381 | T25: 0.169034 | U25: 0.167367 | V25: 0.16648 | W25: 0.164809 | X25: 0.163452 | Y25: 0.161864 | Z25: 0.16063 | AA25: 0.158545 | AB25: 0.15621 | AC25: 0.153638 | AD25: 0.150807 | AE25: -0.014
A26: Other Uses | B26: Commercial: Purchased Electricity: Other Uses: Alternative Electricity and Transportation | C26: AEO.2026.ELECTRNP.CNSM_NA_COMM_NA_PRC_OTHU_USA_QBTU.A | D26: quads | E26: 1.949163 | F26: 2.133727 | G26: 2.139688 | H26: 2.13915 | I26: 2.138203 | J26: 2.13603 | K26: 2.134272 | L26: 2.133495 | M26: 2.134242 | N26: 2.136272 | O26: 2.139616 | P26: 2.144953 | Q26: 2.15116 | R26: 2.157878 | S26: 2.164868 | T26: 2.172189 | U26: 2.179389 | V26: 2.186837 | W26: 2.194853 | X26: 2.203038 | Y26: 2.212115 | Z26: 2.221061 | AA26: 2.230132 | AB26: 2.239662 | AC26: 2.249701 | AD26: 2.260383 | AE26: 0.006
A27: Gross End-use Electricity Consumption | B27: Commercial: Energy Consumption by Fuel: Electricity Subtotal: Alternative Electricity and Transportation | C27: AEO.2026.ELECTRNP.CNSM_NA_COMM_NA_PRC_DELE_USA_QBTU.A | D27: quads | E27: 5.153255 | F27: 5.390966 | G27: 5.448623 | H27: 5.511735 | I27: 5.571003 | J27: 5.609722 | K27: 5.652576 | L27: 5.700143 | M27: 5.753941 | N27: 5.811899 | O27: 5.872981 | P27: 5.940315 | Q27: 6.009748 | R27: 6.080286 | S27: 6.150941 | T27: 6.218776 | U27: 6.286955 | V27: 6.354805 | W27: 6.421803 | X27: 6.486873 | Y27: 6.550223 | Z27: 6.608398 | AA27: 6.659479 | AB27: 6.705345 | AC27: 6.747578 | AD27: 6.787544 | AE27: 0.011
A28: Purchased Electricity for Electric Vehicle Charging | B28: Commercial: Energy Consumption by Fuel: Purchased Electricity for EV Charging: Alternative Electricity and Transportation | C28: AEO.2026.ELECTRNP.GEN_NA_COMM_NA_PRC_EVCHA_USA_QBTU.A | D28: quads | E28: 0.031625 | F28: 0.041349 | G28: 0.053095 | H28: 0.066244 | I28: 0.079603 | J28: 0.092543 | K28: 0.104416 | L28: 0.115643 | M28: 0.126972 | N28: 0.138502 | O28: 0.150392 | P28: 0.162461 | Q28: 0.174804 | R28: 0.187239 | S28: 0.19959 | T28: 0.212288 | U28: 0.225364 | V28: 0.239243 | W28: 0.253973 | X28: 0.269944 | Y28: 0.287121 | Z28: 0.304738 | AA28: 0.322704 | AB28: 0.341035 | AC28: 0.359608 | AD28: 0.378263 | AE28: 0.104
... A30: Purchased Electricity at Commercial Location | B30: Commercial: Energy Consumption by Fuel: Purchased Electricity: Alternative Electricity and Transportation | C30: AEO.2026.ELECTRNP.CNSM_NA_COMM_NA_DELE_ELC_USA_QBTU.A | D30: quads | E30: 5.025373 | F30: 5.253638 | G30: 5.306912 | H30: 5.375412 | I30: 5.443327 | J30: 5.48962 | K30: 5.540199 | L30: 5.595715 | M30: 5.657156 | N30: 5.72104 | O30: 5.789485 | P30: 5.865063 | Q30: 5.940146 | R30: 6.016598 | S30: 6.091698 | T30: 6.165417 | U30: 6.24299 | V30: 6.319204 | W30: 6.397956 | X30: 6.475646 | Y30: 6.553437 | Z30: 6.624979 | AA30: 6.688763 | AB30: 6.747605 | AC30: 6.804358 | AD30: 6.857751 | AE30: 0.013
A31: Natural Gas
A32: Space Heating | B32: Commercial: Natural Gas: Space Heating: Alternative Electricity and Transportation | C32: AEO.2026.ELECTRNP.CNSM_NA_COMM_NA_NG_SPH_USA_QBTU.A | D32: quads | E32: 1.677395 | F32: 1.658977 | G32: 1.655333 | H32: 1.640213 | I32: 1.614623 | J32: 1.585396 | K32: 1.558153 | L32: 1.539679 | M32: 1.52558 | N32: 1.514998 | O32: 1.504151 | P32: 1.494749 | Q32: 1.484763 | R32: 1.474809 | S32: 1.464232 | T32: 1.453817 | U32: 1.443761 | V32: 1.435541 | W32: 1.427792 | X32: 1.420772 | Y32: 1.413245 | Z32: 1.403235 | AA32: 1.391638 | AB32: 1.379734 | AC32: 1.367849 | AD32: 1.356255 | AE32: -0.008
A33: Space Cooling | B33: Commercial: Natural Gas: Space Cooling: Alternative Electricity and Transportation | C33: AEO.2026.ELECTRNP.CNSM_NA_COMM_NA_NG_SPC_USA_QBTU.A | D33: quads | E33: 0.015692 | F33: 0.017612 | G33: 0.017945 | H33: 0.018169 | I33: 0.018287 | J33: 0.018392 | K33: 0.018555 | L33: 0.018871 | M33: 0.01928 | N33: 0.019785 | O33: 0.020338 | P33: 0.020947 | Q33: 0.021603 | R33: 0.022292 | S33: 0.023007 | T33: 0.023771 | U33: 0.024568 | V33: 0.025421 | W33: 0.026326 | X33: 0.027285 | Y33: 0.028298 | Z33: 0.029311 | AA33: 0.030356 | AB33: 0.031435 | AC33: 0.03257 | AD33: 0.033763 | AE33: 0.031
A34: Water Heating | B34: Commercial: Natural Gas: Water Heating: Alternative Electricity and Transportation | C34: AEO.2026.ELECTRNP.CNSM_NA_COMM_NA_NG_WTHT_USA_QBTU.A | D34: quads | E34: 0.27397 | F34: 0.280341 | G34: 0.283018 | H34: 0.283701 | I34: 0.282807 | J34: 0.281323 | K34: 0.280138 | L34: 0.280657 | M34: 0.281792 | N34: 0.283857 | O34: 0.2861 | P34: 0.288783 | Q34: 0.291449 | R34: 0.294131 | S34: 0.29673 | T34: 0.299366 | U34: 0.302164 | V34: 0.305317 | W34: 0.308628 | X34: 0.312135 | Y34: 0.315522 | Z34: 0.318429 | AA34: 0.321005 | AB34: 0.323466 | AC34: 0.325923 | AD34: 0.328429 | AE34: 0.007
A35: Cooking | B35: Commercial: Natural Gas: Cooking: Alternative Electricity and Transportation | C35: AEO.2026.ELECTRNP.CNSM_NA_COMM_NA_NG_CGR_USA_QBTU.A | D35: quads | E35: 0.40539 | F35: 0.412698 | G35: 0.416201 | H35: 0.416769 | I35: 0.415153 | J35: 0.412603 | K35: 0.410522 | L35: 0.410815 | M35: 0.412028 | N35: 0.414518 | O35: 0.417203 | P35: 0.420466 | Q35: 0.423673 | R35: 0.426868 | S35: 0.429898 | T35: 0.432934 | U35: 0.436245 | V35: 0.440058 | W35: 0.444076 | X35: 0.448351 | Y35: 0.452416 | Z35: 0.455738 | AA35: 0.458542 | AB35: 0.461147 | AC35: 0.463721 | AD35: 0.466344 | AE35: 0.006
A36: Other Uses | B36: Commercial: Natural Gas: Other Uses: Alternative Electricity and Transportation | C36: AEO.2026.ELECTRNP.CNSM_NA_COMM_NA_NG_OTHU_USA_QBTU.A | D36: quads | E36: 1.267356 | F36: 1.194333 | G36: 1.199043 | H36: 1.197086 | I36: 1.188333 | J36: 1.177144 | K36: 1.166085 | L36: 1.160668 | M36: 1.157207 | N36: 1.156334 | O36: 1.155312 | P36: 1.155334 | Q36: 1.155167 | R36: 1.155125 | S36: 1.154979 | T36: 1.155163 | U36: 1.155525 | V36: 1.157366 | W36: 1.159725 | X36: 1.162961 | Y36: 1.165869 | Z36: 1.167382 | AA36: 1.168018 | AB36: 1.16842 | AC36: 1.168869 | AD36: 1.169652 | AE36: -0.003
A37: Delivered Energy | B37: Commercial: Natural Gas: Delivered Energy: Alternative Electricity and Transportation | C37: AEO.2026.ELECTRNP.CNSM_NA_COMM_NA_NG_DELE_USA_QBTU.A | D37: quads | E37: 3.639804 | F37: 3.563961 | G37: 3.57154 | H37: 3.555938 | I37: 3.519203 | J37: 3.474857 | K37: 3.433453 | L37: 3.41069 | M37: 3.395886 | N37: 3.389492 | O37: 3.383103 | P37: 3.380279 | Q37: 3.376655 | R37: 3.373224 | S37: 3.368847 | T37: 3.365051 | U37: 3.362263 | V37: 3.363703 | W37: 3.366547 | X37: 3.371504 | Y37: 3.37535 | Z37: 3.374094 | AA37: 3.369559 | AB37: 3.364201 | AC37: 3.358932 | AD37: 3.354442 | AE37: -0.003
A38: Distillate Fuel Oil
A39: Space Heating | B39: Commercial: Distillate Fuel Oil: Space Heating: Alternative Electricity and Transportation | C39: AEO.2026.ELECTRNP.CNSM_NA_COMM_NA_DFO_SPH_USA_QBTU.A | D39: quads | E39: 0.074528 | F39: 0.072814 | G39: 0.072147 | H39: 0.071328 | I39: 0.07024 | J39: 0.06939 | K39: 0.068552 | L39: 0.067389 | M39: 0.065912 | N39: 0.064453 | O39: 0.063009 | P39: 0.06167 | Q39: 0.060346 | R39: 0.059039 | S39: 0.05778 | T39: 0.056542 | U39: 0.055331 | V39: 0.054154 | W39: 0.052975 | X39: 0.051814 | Y39: 0.050657 | Z39: 0.049516 | AA39: 0.048376 | AB39: 0.047276 | AC39: 0.046179 | AD39: 0.045136 | AE39: -0.02
A40: Water Heating | B40: Commercial: Distillate Fuel Oil: Water Heating: Alternative Electricity and Transportation | C40: AEO.2026.ELECTRNP.CNSM_NA_COMM_NA_DFO_WTHT_USA_QBTU.A | D40: quads | E40: 0.003768 | F40: 0.003783 | G40: 0.003772 | H40: 0.003756 | I40: 0.003738 | J40: 0.003734 | K40: 0.00373 | L40: 0.00371 | M40: 0.003672 | N40: 0.003636 | O40: 0.003602 | P40: 0.003574 | Q40: 0.003547 | R40: 0.003521 | S40: 0.003496 | T40: 0.003472 | U40: 0.003448 | V40: 0.003424 | W40: 0.0034 | X40: 0.003376 | Y40: 0.00335 | Z40: 0.003324 | AA40: 0.003298 | AB40: 0.003273 | AC40: 0.003246 | AD40: 0.003222 | AE40: -0.006
A41: Other Uses | B41: Commercial: Distillate Fuel Oil: Other Uses: Alternative Electricity and Transportation | C41: AEO.2026.ELECTRNP.CNSM_NA_COMM_NA_DFO_OTHU_USA_QBTU.A | D41: quads | E41: 0.237124 | F41: 0.242392 | G41: 0.250526 | H41: 0.25241 | I41: 0.253941 | J41: 0.256359 | K41: 0.258468 | L41: 0.259219 | M41: 0.258164 | N41: 0.257158 | O41: 0.256193 | P41: 0.255626 | Q41: 0.254962 | R41: 0.25428 | S41: 0.253748 | T41: 0.253289 | U41: 0.25278 | V41: 0.252306 | W41: 0.251799 | X41: 0.251265 | Y41: 0.25063 | Z41: 0.249962 | AA41: 0.249195 | AB41: 0.248498 | AC41: 0.247697 | AD41: 0.247076 | AE41: 0.002
...

Sheet Evolved Energy ADP 2024
B1: Source | C1: 2024 Annual Decarbonization Perspective (ADP 2024)
B2: Link | C2: https://www.evolved.energy/us-adp-2024
B3: Projections | C3: 2025 | D3: =C3+5 -> 2030 | E3: 2035 | F3: 2040 | G3: 2050
A4: mid | C4: =E13 -> 279 | D4: =F13 -> 541 | E4: =G13 -> 693 | F4: =H13 -> 776 | G4: =I13 -> 870
A5: high | C5: 279 | D5: 718 | E5: 1043 | F5: 1222 | G5: 1679
E6: Current Policy | F6: Current Policy | G6: Current Policy | H6: Current Policy | I6: Current Policy | J6: Current Policy
C7: To||Outputs Group Aggregate (group) | E7: 2024 | F7: 2030 | G7: 2035 | H7: 2040 | I7: 2045 | J7: 2050
C8: Hydrogen Electrolysis | D8: % of Total SUM([Value])/1e3 along To||Outputs Group Aggregate (group) | F8: 0.0209 | G8: 0.0703 | H8: 0.0716 | I8: 0.0637 | J8: 0.0603
C9: Hydrogen Electrolysis | D9: SUM([Value])/1e3 | F9: 105 | G9: 422 | H9: 489 | I9: 467 | J9: 476
C10: Industrial Boilers | D10: % of Total SUM([Value])/1e3 along To||Outputs Group Aggregate (group) | F10: 0.0009 | G10: 0.0038 | H10: 0.0081 | I10: 0.004 | J10: 0.0027
C11: Industrial Boilers | D11: SUM([Value])/1e3 | F11: 4 | G11: 23 | H11: 55 | I11: 29 | J11: 21
C12: Data Centers | D12: % of Total SUM([Value])/1e3 along To||Outputs Group Aggregate (group) | E12: 0.0644 | F12: 0.108 | G12: 0.1154 | H12: 0.1138 | I12: 0.1186 | J12: 0.1235
C13: Data Centers | D13: SUM([Value])/1e3 | E13: 279 | F13: 541 | G13: 693 | H13: 776 | I13: 870 | J13: 975
C14: Other End-Use Loads | D14: % of Total SUM([Value])/1e3 along To||Outputs Group Aggregate (group) | E14: 0.9356 | F14: 0.8703 | G14: 0.8105 | H14: 0.8064 | I14: 0.8137 | J14: 0.8134
C15: Other End-Use Loads | D15: SUM([Value])/1e3 | E15: 4055 | F15: 4361 | G15: 4865 | H15: 5498 | I15: 5966 | J15: 6418
C20: Run Name | D20: Year | E20: To||Outputs Group Aggregate (group) | F20: Zone | G20: Latitude | H20: Longitude | I20: Value
C21: Current Policy | D21: 2024 | E21: Data Centers | F21: northwest_emm | G21: 46.230785 | H21: -117.13535 | I21: 28096.825
C22: Current Policy | D22: 2024 | E22: Data Centers | F22: upper mississippi valley_emm | G22: 44.216161 | H22: -92.060173 | I22: 5610.7274
C23: Current Policy | D23: 2024 | E23: Data Centers | F23: northern great plains_emm | G23: 43.892257 | H23: -98.937462 | I23: 11607.794
C24: Current Policy | D24: 2024 | E24: Data Centers | F24: michigan_emm | G24: 43.659916 | H24: -84.577797 | I24: 584.34284
C25: Current Policy | D25: 2024 | E25: Data Centers | F25: new england_emm | G25: 43.275272 | H25: -71.404255 | I25: 3608.5366
C26: Current Policy | D26: 2024 | E26: Data Centers | F26: upstate new york_emm | G26: 42.781516 | H26: -75.700387 | I26: 5256.3649
C27: Current Policy | D27: 2024 | E27: Data Centers | F27: metropolitan chicago_emm | G27: 41.581748 | H27: -89.046286 | I27: 13781.693
C28: Current Policy | D28: 2024 | E28: Data Centers | F28: great basin_emm | G28: 41.490666 | H28: -113.39926 | I28: 9760.7392
C29: Current Policy | D29: 2024 | E29: Data Centers | F29: metropolitan new york_emm | G29: 40.795662 | H29: -73.749075 | I29: 1856.4129
C30: Current Policy | D30: 2024 | E30: Data Centers | F30: rockies_emm | G30: 40.419862 | H30: -105.04323 | I30: 6223.8796
C31: Current Policy | D31: 2024 | E31: Data Centers | F31: mid-atlantic_emm | G31: 40.223694 | H31: -76.229496 | I31: 9637.6345
C32: Current Policy | D32: 2024 | E32: Data Centers | F32: ohio valley_emm | G32: 39.628317 | H32: -82.005115 | I32: 12588.085
... C170: Current Policy | D170: 2050 | E170: Data Centers | F170: florida_emm | G170: 28.708317 | H170: -82.234217 | I170: 7197.4108

Sheet BDCL-low
A1: Year | B1: 2024 | C1: 2025 | D1: 2026 | E1: 2027 | F1: 2028 | G1: 2029 | H1: 2030 | I1: 2031 | J1: 2032 | K1: 2033 | L1: 2034 | M1: 2035 | N1: 2036 | O1: 2037 | P1: 2038 | Q1: 2039 | R1: 2040 | S1: 2041 | T1: 2042 | U1: 2043 | V1: 2044 | W1: 2045 | X1: 2046 | Y1: 2047 | Z1: 2048 | AA1: 2049 | AB1: 2050
A2: heating | B2: =0 -> 0 | C2: =0 -> 0 | D2: =0 -> 0 | E2: =0 -> 0 | F2: =0 -> 0 | G2: =0 -> 0 | H2: =0 -> 0 | I2: =0 -> 0 | ... AB2: =0 -> 0
A3: cooling and ventilation | B3: ='Low_Mid_High Scenarios'!B3*10^6*'End Use Split'!B$11 -> 52571429 | C3: ='Low_Mid_High Scenarios'!C3*10^6*'End Use Split'!C$11 -> 59596330 | D3: ='Low_Mid_High Scenarios'!D3*10^6*'End Use Split'!D$11 -> 64509434 | E3: ='Low_Mid_High Scenarios'!E3*10^6*'End Use Split'!E$11 -> 68776699 | F3: ='Low_Mid_High Scenarios'!F3*10^6*'End Use Split'!F$11 -> 69000000 | G3: ='Low_Mid_High Scenarios'!G3*10^6*'End Use Split'!G$11 -> 74200000 | H3: ='Low_Mid_High Scenarios'!H3*10^6*'End Use Split'!H$11 -> 79200000 | I3: ='Low_Mid_High Scenarios'!I3*10^6*'End Use Split'!I$11 -> 82298182 | ... AB3: ='Low_Mid_High Scenarios'!AB3*10^6*'End Use Split'!AB$11 -> 1.3264197e+08
A4: envelope | B4: =0 -> 0 | C4: =0 -> 0 | D4: =0 -> 0 | E4: =0 -> 0 | F4: =0 -> 0 | G4: =0 -> 0 | H4: =0 -> 0 | I4: =0 -> 0 | ... AB4: =0 -> 0
A5: lighting | B5: =0 -> 0 | C5: =0 -> 0 | D5: =0 -> 0 | E5: =0 -> 0 | F5: =0 -> 0 | G5: =0 -> 0 | H5: =0 -> 0 | I5: =0 -> 0 | ... AB5: =0 -> 0
A6: appliances | B6: =0 -> 0 | C6: =0 -> 0 | D6: =0 -> 0 | E6: =0 -> 0 | F6: =0 -> 0 | G6: =0 -> 0 | H6: =0 -> 0 | I6: =0 -> 0 | ... AB6: =0 -> 0
A7: other component | B7: ='Low_Mid_High Scenarios'!B3*10^6*'End Use Split'!B$12 -> 1.3142857e+08 | C7: ='Low_Mid_High Scenarios'!C3*10^6*'End Use Split'!C$12 -> 1.6440367e+08 | D7: ='Low_Mid_High Scenarios'!D3*10^6*'End Use Split'!D$12 -> 1.9849057e+08 | E7: ='Low_Mid_High Scenarios'!E3*10^6*'End Use Split'!E$12 -> 2.392233e+08 | F7: ='Low_Mid_High Scenarios'!F3*10^6*'End Use Split'!F$12 -> 276000000 | G7: ='Low_Mid_High Scenarios'!G3*10^6*'End Use Split'!G$12 -> 296800000 | H7: ='Low_Mid_High Scenarios'!H3*10^6*'End Use Split'!H$12 -> 316800000 | I7: ='Low_Mid_High Scenarios'!I3*10^6*'End Use Split'!I$12 -> 329192728 | ... AB7: ='Low_Mid_High Scenarios'!AB3*10^6*'End Use Split'!AB$12 -> 5.3056788e+08

Sheet BDCL-mid
A1: Year | B1: 2024 | C1: 2025 | D1: 2026 | E1: 2027 | F1: 2028 | G1: 2029 | H1: 2030 | I1: 2031 | J1: 2032 | K1: 2033 | L1: 2034 | M1: 2035 | N1: 2036 | O1: 2037 | P1: 2038 | Q1: 2039 | R1: 2040 | S1: 2041 | T1: 2042 | U1: 2043 | V1: 2044 | W1: 2045 | X1: 2046 | Y1: 2047 | Z1: 2048 | AA1: 2049 | AB1: 2050
A2: heating | B2: =0 -> 0 | C2: =0 -> 0 | D2: =0 -> 0 | E2: =0 -> 0 | F2: =0 -> 0 | G2: =0 -> 0 | H2: =0 -> 0 | I2: =0 -> 0 | ... AB2: =0 -> 0
A3: cooling and ventilation | B3: ='Low_Mid_High Scenarios'!B4*10^6*'End Use Split'!B$11 -> 52571429 | C3: ='Low_Mid_High Scenarios'!C4*10^6*'End Use Split'!C$11 -> 59596330 | D3: ='Low_Mid_High Scenarios'!D4*10^6*'End Use Split'!D$11 -> 71132075 | E3: ='Low_Mid_High Scenarios'!E4*10^6*'End Use Split'!E$11 -> 82398058 | F3: ='Low_Mid_High Scenarios'!F4*10^6*'End Use Split'!F$11 -> 89600000 | G3: ='Low_Mid_High Scenarios'!G4*10^6*'End Use Split'!G$11 -> 1.036e+08 | H3: ='Low_Mid_High Scenarios'!H4*10^6*'End Use Split'!H$11 -> 1.17e+08 | I3: ='Low_Mid_High Scenarios'!I4*10^6*'End Use Split'!I$11 -> 1.2308e+08 | ... AB3: ='Low_Mid_High Scenarios'!AB4*10^6*'End Use Split'!AB$11 -> 1.828e+08
A4: envelope | B4: =0 -> 0 | C4: =0 -> 0 | D4: =0 -> 0 | E4: =0 -> 0 | F4: =0 -> 0 | G4: =0 -> 0 | H4: =0 -> 0 | I4: =0 -> 0 | ... AB4: =0 -> 0
A5: lighting | B5: =0 -> 0 | C5: =0 -> 0 | D5: =0 -> 0 | E5: =0 -> 0 | F5: =0 -> 0 | G5: =0 -> 0 | H5: =0 -> 0 | I5: =0 -> 0 | ... AB5: =0 -> 0
A6: appliances | B6: =0 -> 0 | C6: =0 -> 0 | D6: =0 -> 0 | E6: =0 -> 0 | F6: =0 -> 0 | G6: =0 -> 0 | H6: =0 -> 0 | I6: =0 -> 0 | ... AB6: =0 -> 0
A7: other component | B7: ='Low_Mid_High Scenarios'!B4*10^6*'End Use Split'!B$12 -> 1.3142857e+08 | C7: ='Low_Mid_High Scenarios'!C4*10^6*'End Use Split'!C$12 -> 1.6440367e+08 | D7: ='Low_Mid_High Scenarios'!D4*10^6*'End Use Split'!D$12 -> 2.1886792e+08 | E7: ='Low_Mid_High Scenarios'!E4*10^6*'End Use Split'!E$12 -> 2.8660194e+08 | F7: ='Low_Mid_High Scenarios'!F4*10^6*'End Use Split'!F$12 -> 358400000 | G7: ='Low_Mid_High Scenarios'!G4*10^6*'End Use Split'!G$12 -> 414400000 | H7: ='Low_Mid_High Scenarios'!H4*10^6*'End Use Split'!H$12 -> 468000000 | I7: ='Low_Mid_High Scenarios'!I4*10^6*'End Use Split'!I$12 -> 4.9232e+08 | ... AB7: ='Low_Mid_High Scenarios'!AB4*10^6*'End Use Split'!AB$12 -> 731200000

Sheet BDCL-high
A1: Year | B1: 2024 | C1: 2025 | D1: 2026 | E1: 2027 | F1: 2028 | G1: 2029 | H1: 2030 | I1: 2031 | J1: 2032 | K1: 2033 | L1: 2034 | M1: 2035 | N1: 2036 | O1: 2037 | P1: 2038 | Q1: 2039 | R1: 2040 | S1: 2041 | T1: 2042 | U1: 2043 | V1: 2044 | W1: 2045 | X1: 2046 | Y1: 2047 | Z1: 2048 | AA1: 2049 | AB1: 2050
A2: heating | B2: =0 -> 0 | C2: =0 -> 0 | D2: =0 -> 0 | E2: =0 -> 0 | F2: =0 -> 0 | G2: =0 -> 0 | H2: =0 -> 0 | I2: =0 -> 0 | ... AB2: =0 -> 0
A3: cooling and ventilation | B3: ='Low_Mid_High Scenarios'!B5*10^6*'End Use Split'!B$11 -> 52571429 | C3: ='Low_Mid_High Scenarios'!C5*10^6*'End Use Split'!C$11 -> 59596330 | D3: ='Low_Mid_High Scenarios'!D5*10^6*'End Use Split'!D$11 -> 77018868 | E3: ='Low_Mid_High Scenarios'!E5*10^6*'End Use Split'!E$11 -> 94902913 | F3: ='Low_Mid_High Scenarios'!F5*10^6*'End Use Split'!F$11 -> 1.088e+08 | G3: ='Low_Mid_High Scenarios'!G5*10^6*'End Use Split'!G$11 -> 1.306e+08 | H3: ='Low_Mid_High Scenarios'!H5*10^6*'End Use Split'!H$11 -> 1.52e+08 | I3: ='Low_Mid_High Scenarios'!I5*10^6*'End Use Split'!I$11 -> 1.65e+08 | ... AB3: ='Low_Mid_High Scenarios'!AB5*10^6*'End Use Split'!AB$11 -> 3.442e+08
A4: envelope | B4: =0 -> 0 | C4: =0 -> 0 | D4: =0 -> 0 | E4: =0 -> 0 | F4: =0 -> 0 | G4: =0 -> 0 | H4: =0 -> 0 | I4: =0 -> 0 | ... AB4: =0 -> 0
A5: lighting | B5: =0 -> 0 | C5: =0 -> 0 | D5: =0 -> 0 | E5: =0 -> 0 | F5: =0 -> 0 | G5: =0 -> 0 | H5: =0 -> 0 | I5: =0 -> 0 | ... AB5: =0 -> 0
A6: appliances | B6: =0 -> 0 | C6: =0 -> 0 | D6: =0 -> 0 | E6: =0 -> 0 | F6: =0 -> 0 | G6: =0 -> 0 | H6: =0 -> 0 | I6: =0 -> 0 | ... AB6: =0 -> 0
A7: other component | B7: ='Low_Mid_High Scenarios'!B5*10^6*'End Use Split'!B$12 -> 1.3142857e+08 | C7: ='Low_Mid_High Scenarios'!C5*10^6*'End Use Split'!C$12 -> 1.6440367e+08 | D7: ='Low_Mid_High Scenarios'!D5*10^6*'End Use Split'!D$12 -> 2.3698113e+08 | E7: ='Low_Mid_High Scenarios'!E5*10^6*'End Use Split'!E$12 -> 3.3009709e+08 | F7: ='Low_Mid_High Scenarios'!F5*10^6*'End Use Split'!F$12 -> 435200000 | G7: ='Low_Mid_High Scenarios'!G5*10^6*'End Use Split'!G$12 -> 522400000 | H7: ='Low_Mid_High Scenarios'!H5*10^6*'End Use Split'!H$12 -> 608000000 | I7: ='Low_Mid_High Scenarios'!I5*10^6*'End Use Split'!I$12 -> 660000000 | ... AB7: ='Low_Mid_High Scenarios'!AB5*10^6*'End Use Split'!AB$12 -> 1376800000
