Workbook

Sheet About
A1: CPRS Cement Preexisting Capacity Overhaul Decision Schedule
A3: Sources: | B3: US cement kiln fleet age cohorts (pre-2000 / post-2000)
B4: Princeton University Net-Zero America (NZA) project
B5: NZA Annex K, section 6.3 (cement)
B6: 2021
B7: https://netzeroamerica.princeton.edu/img/Princeton_NZA_Annex_K.pdf
B8: Annex K sec 6.3: ~92 pre-2000 US kilns totaling ~49.6 Mt/yr nameplate clinker capacity, and ~38 post-2000 kilns totaling ~46.7 Mt/yr; a 35-year kiln campaign convention (EIA IDM 30-yr assumption extended by 5). Retrieved via reader proxy 2026-08-25 (direct PDF access restricted) - cohort totals CONFIRMED exactly against the Annex K text in Phase 4 verification. [DIRECT via proxy]
A11: Notes:
A12: Decision-schedule semantics (Phase 2b) | B12: CPRS[Y] = nameplate clinker capacity whose kiln campaign ends in year Y and therefore reaches an overhaul-vs-replace DECISION that year. The decision OUTCOME (overhaul vs. replace) is endogenous, made by the CRSW-weighted two-option relative-cost logit (overhaul capex, CRCC, annuitized, vs. the pathway's share-weighted new-build cost). CPRS does not say what retires - it says how much nameplate capacity, by pathway, reaches a decision each year. GEM's cement tracker records no kiln-level vintages, so this schedule is built from fleet age cohorts rather than a unit-by-unit table (contrast with steel's GEM-sourced SPRS).
A13: Pre-2000 cohort schedule | B13: NZA's own convention: post-2025 turnover at 7%/yr of the 49.6 Mt pre-2000 cohort, from 2026. 7% x 49.6 Mt = 3.472 Mt/yr, rounded to the shipped 3,470,000, applied 2026-2039 (14 years); the remainder (49.6 Mt - 14 x 3.47 Mt = 1.02 Mt) decides in 2040. NZA's pre-2025 3%/yr retirement convention (2018-2025) is already embedded in the USGS 2025 capacity figure the module's start-year stock initializes from, so it is not re-applied here. See the Derivation tab.
A14: Post-2000 cohort schedule | B14: The 46.7 Mt post-2000 cohort was installed roughly 2000-2010 and reaches its 35-year campaign end individually staggered across that installation window. Approximated as a flat 46.7 Mt / 10 yr = 4.67 Mt/yr (rounded to the shipped 4,700,000/yr) over 2036-2045 - a documented simplification in the absence of kiln-level install-year data. See the Derivation tab.
A15: Overlap years 2036-2039 | B15: Both cohort schedules are active 2036-2039, so CPRS in those years is the SUM of the pre-2000 remainder-period rate (3.47 Mt/yr through 2039) and the post-2000 flat rate (4.70 Mt/yr): 8,170,000/yr. 2040 sums the pre-2000 remainder (1,020,000) and the post-2000 rate (4,700,000) = 5,720,000. 2041-2045 carries only the post-2000 rate (4,700,000).
A16: Pathway attribution | B16: All decision capacity is attributed to the dry kiln with precalciner pathway (the entire preexisting fleet); the other three pathways are 0 in every year, consistent with SYCPbP.
A17: Upgrade path | B17: PCA's Plant Information Summary carries kiln-level vintage data but is a proprietary/member-only product; upgrading this schedule to unit-level (as steel's GEM-sourced SPRS does) requires EI access to that data set.
A18: DRAFT status | B18: DRAFT - verify against primary sources before release. This workbook is an input for staff review, not a finished or approved EI position.
A19: Provenance | B19: Written by Claude Code (Fable/Sonnet agent session), cement industry breakout, worktree cement-industry-breakout-f901fc, 2026-08-26. This is a DRAFT input for staff review, not a finished or approved EI position; verify all figures against primary sources before use in any work product. Reviewed by: (pending).

Sheet NZA Annex K Cohorts
A1: Cohort | B1: Kiln count | C1: Nameplate capacity (Mt/yr) | D1: Convention
A2: Pre-2000 | B2: 92 | C2: 49.6 | D2: 7%/yr turnover from 2026 (NZA post-2025 rate)
A3: Post-2000 | B3: 38 | C3: 46.7 | D3: 35-yr campaign, staggered installs ~2000-2010

Sheet Derivation
A1: Pre-2000 cohort: 7%/yr of 49.6 Mt, 2026-2039, remainder in 2040
A3: Pre-2000 cohort nameplate (Mt) | B3: ='NZA Annex K Cohorts'!C2
A4: Annual rate = 7% x cohort | B4: =0.07*B3
A5: Annual rate, rounded to nearest 10,000 t/yr (shipped) | B5: 3470000
A6: Years at full rate (2026-2039) | B6: 14
A7: Cumulative at full rate (Mt) | B7: =B5*B6/1000000
A8: Remainder in 2040 (Mt) = cohort - cumulative | B8: =B3-B7
A9: Remainder in 2040, shipped (t/yr) | B9: 1020000
A11: Post-2000 cohort: 35-yr staggered campaign end, 2036-2045
A13: Post-2000 cohort nameplate (Mt) | B13: ='NZA Annex K Cohorts'!C3
A14: Years spanned (2036-2045) | B14: 10
A15: Annual rate = cohort / years (Mt/yr) | B15: =B13/B14
A16: Annual rate, shipped (t/yr) | B16: 4700000
A18: Year-by-year schedule (t/yr), pre-2000 + post-2000
A19: Year | B19: Pre-2000 component | C19: Post-2000 component | D19: Total (dry kiln with precalciner)
A20: 2021 | B20: 0 | C20: 0 | D20: =B20+C20
A21: 2022 | B21: 0 | C21: 0 | D21: =B21+C21
A22: 2023 | B22: 0 | C22: 0 | D22: =B22+C22
A23: 2024 | B23: 0 | C23: 0 | D23: =B23+C23
A24: 2025 | B24: 0 | C24: 0 | D24: =B24+C24
A25: 2026 | B25: =$B$5 | C25: 0 | D25: =B25+C25
A26: 2027 | B26: =$B$5 | C26: 0 | D26: =B26+C26
A27: 2028 | B27: =$B$5 | C27: 0 | D27: =B27+C27
A28: 2029 | B28: =$B$5 | C28: 0 | D28: =B28+C28
A29: 2030 | B29: =$B$5 | C29: 0 | D29: =B29+C29
A30: 2031 | B30: =$B$5 | C30: 0 | D30: =B30+C30
A31: 2032 | B31: =$B$5 | C31: 0 | D31: =B31+C31
A32: 2033 | B32: =$B$5 | C32: 0 | D32: =B32+C32
A33: 2034 | B33: =$B$5 | C33: 0 | D33: =B33+C33
A34: 2035 | B34: =$B$5 | C34: 0 | D34: =B34+C34
A35: 2036 | B35: =$B$5 | C35: =$B$16 | D35: =B35+C35
A36: 2037 | B36: =$B$5 | C36: =$B$16 | D36: =B36+C36
A37: 2038 | B37: =$B$5 | C37: =$B$16 | D37: =B37+C37
A38: 2039 | B38: =$B$5 | C38: =$B$16 | D38: =B38+C38
A39: 2040 | B39: =$B$9 | C39: =$B$16 | D39: =B39+C39
A40: 2041 | B40: 0 | C40: =$B$16 | D40: =B40+C40
A41: 2042 | B41: 0 | C41: =$B$16 | D41: =B41+C41
A42: 2043 | B42: 0 | C42: =$B$16 | D42: =B42+C42
A43: 2044 | B43: 0 | C43: =$B$16 | D43: =B43+C43
A44: 2045 | B44: 0 | C44: =$B$16 | D44: =B44+C44
...

Sheet Checks
A1: Cross-check: export tab (dry kiln with precalciner row) literal vs. Derivation formula total, all 30 years
A3: Year | B3: Export tab value | C3: Derivation total | D3: Result
A4: 2021 | B4: =CPRS!B2 | C4: =Derivation!D20 | D4: =IF(ABS(B4-C4)<0.5,"PASS","FAIL")
A5: 2022 | B5: =CPRS!C2 | C5: =Derivation!D21 | D5: =IF(ABS(B5-C5)<0.5,"PASS","FAIL")
A6: 2023 | B6: =CPRS!D2 | C6: =Derivation!D22 | D6: =IF(ABS(B6-C6)<0.5,"PASS","FAIL")
A7: 2024 | B7: =CPRS!E2 | C7: =Derivation!D23 | D7: =IF(ABS(B7-C7)<0.5,"PASS","FAIL")
A8: 2025 | B8: =CPRS!F2 | C8: =Derivation!D24 | D8: =IF(ABS(B8-C8)<0.5,"PASS","FAIL")
A9: 2026 | B9: =CPRS!G2 | C9: =Derivation!D25 | D9: =IF(ABS(B9-C9)<0.5,"PASS","FAIL")
A10: 2027 | B10: =CPRS!H2 | C10: =Derivation!D26 | D10: =IF(ABS(B10-C10)<0.5,"PASS","FAIL")
A11: 2028 | B11: =CPRS!I2 | C11: =Derivation!D27 | D11: =IF(ABS(B11-C11)<0.5,"PASS","FAIL")
A12: 2029 | B12: =CPRS!J2 | C12: =Derivation!D28 | D12: =IF(ABS(B12-C12)<0.5,"PASS","FAIL")
A13: 2030 | B13: =CPRS!K2 | C13: =Derivation!D29 | D13: =IF(ABS(B13-C13)<0.5,"PASS","FAIL")
A14: 2031 | B14: =CPRS!L2 | C14: =Derivation!D30 | D14: =IF(ABS(B14-C14)<0.5,"PASS","FAIL")
A15: 2032 | B15: =CPRS!M2 | C15: =Derivation!D31 | D15: =IF(ABS(B15-C15)<0.5,"PASS","FAIL")
A16: 2033 | B16: =CPRS!N2 | C16: =Derivation!D32 | D16: =IF(ABS(B16-C16)<0.5,"PASS","FAIL")
A17: 2034 | B17: =CPRS!O2 | C17: =Derivation!D33 | D17: =IF(ABS(B17-C17)<0.5,"PASS","FAIL")
A18: 2035 | B18: =CPRS!P2 | C18: =Derivation!D34 | D18: =IF(ABS(B18-C18)<0.5,"PASS","FAIL")
A19: 2036 | B19: =CPRS!Q2 | C19: =Derivation!D35 | D19: =IF(ABS(B19-C19)<0.5,"PASS","FAIL")
A20: 2037 | B20: =CPRS!R2 | C20: =Derivation!D36 | D20: =IF(ABS(B20-C20)<0.5,"PASS","FAIL")
A21: 2038 | B21: =CPRS!S2 | C21: =Derivation!D37 | D21: =IF(ABS(B21-C21)<0.5,"PASS","FAIL")
A22: 2039 | B22: =CPRS!T2 | C22: =Derivation!D38 | D22: =IF(ABS(B22-C22)<0.5,"PASS","FAIL")
A23: 2040 | B23: =CPRS!U2 | C23: =Derivation!D39 | D23: =IF(ABS(B23-C23)<0.5,"PASS","FAIL")
A24: 2041 | B24: =CPRS!V2 | C24: =Derivation!D40 | D24: =IF(ABS(B24-C24)<0.5,"PASS","FAIL")
A25: 2042 | B25: =CPRS!W2 | C25: =Derivation!D41 | D25: =IF(ABS(B25-C25)<0.5,"PASS","FAIL")
A26: 2043 | B26: =CPRS!X2 | C26: =Derivation!D42 | D26: =IF(ABS(B26-C26)<0.5,"PASS","FAIL")
A27: 2044 | B27: =CPRS!Y2 | C27: =Derivation!D43 | D27: =IF(ABS(B27-C27)<0.5,"PASS","FAIL")
A28: 2045 | B28: =CPRS!Z2 | C28: =Derivation!D44 | D28: =IF(ABS(B28-C28)<0.5,"PASS","FAIL")
A29: 2046 | B29: =CPRS!AA2 | C29: =Derivation!D45 | D29: =IF(ABS(B29-C29)<0.5,"PASS","FAIL")
A30: 2047 | B30: =CPRS!AB2 | C30: =Derivation!D46 | D30: =IF(ABS(B30-C30)<0.5,"PASS","FAIL")
A31: 2048 | B31: =CPRS!AC2 | C31: =Derivation!D47 | D31: =IF(ABS(B31-C31)<0.5,"PASS","FAIL")
A32: 2049 | B32: =CPRS!AD2 | C32: =Derivation!D48 | D32: =IF(ABS(B32-C32)<0.5,"PASS","FAIL")
A33: 2050 | B33: =CPRS!AE2 | C33: =Derivation!D49 | D33: =IF(ABS(B33-C33)<0.5,"PASS","FAIL")
A35: Overall | B35: =IF(COUNTIF(D4:D33,"FAIL")=0,"ALL PASS","CHECK FAILURES ABOVE")

Sheet CPRS
A1: Unit: metric tons/year nameplate reaching campaign-end decision (NZA Annex K cohorts confirmed exact; pre-2000 at NZA 7%/yr from 2026, post-2000 35-yr staggered 2036-45) | B1: 2021 | C1: 2022 | D1: 2023 | E1: 2024 | F1: 2025 | G1: 2026 | H1: 2027 | I1: 2028 | J1: 2029 | K1: 2030 | L1: 2031 | M1: 2032 | N1: 2033 | O1: 2034 | P1: 2035 | Q1: 2036 | R1: 2037 | S1: 2038 | T1: 2039 | U1: 2040 | V1: 2041 | W1: 2042 | X1: 2043 | Y1: 2044 | Z1: 2045 | AA1: 2046 | AB1: 2047 | AC1: 2048 | AD1: 2049 | AE1: 2050
A2: dry kiln with precalciner | B2: 0 | C2: 0 | D2: 0 | E2: 0 | F2: 0 | G2: 3470000 | H2: 3470000 | I2: 3470000 | J2: 3470000 | K2: 3470000 | L2: 3470000 | M2: 3470000 | N2: 3470000 | O2: 3470000 | P2: 3470000 | Q2: 8170000 | R2: 8170000 | S2: 8170000 | T2: 8170000 | U2: 5720000 | V2: 4700000 | W2: 4700000 | X2: 4700000 | Y2: 4700000 | Z2: 4700000 | AA2: 0 | AB2: 0 | AC2: 0 | AD2: 0 | AE2: 0
A3: dry kiln with CCS | B3: 0 | C3: 0 | D3: 0 | E3: 0 | F3: 0 | G3: 0 | H3: 0 | I3: 0 | J3: 0 | K3: 0 | L3: 0 | M3: 0 | N3: 0 | O3: 0 | P3: 0 | Q3: 0 | R3: 0 | S3: 0 | T3: 0 | U3: 0 | V3: 0 | W3: 0 | X3: 0 | Y3: 0 | Z3: 0 | AA3: 0 | AB3: 0 | AC3: 0 | AD3: 0 | AE3: 0
A4: electric kiln | B4: 0 | C4: 0 | D4: 0 | E4: 0 | F4: 0 | G4: 0 | H4: 0 | I4: 0 | J4: 0 | K4: 0 | L4: 0 | M4: 0 | N4: 0 | O4: 0 | P4: 0 | Q4: 0 | R4: 0 | S4: 0 | T4: 0 | U4: 0 | V4: 0 | W4: 0 | X4: 0 | Y4: 0 | Z4: 0 | AA4: 0 | AB4: 0 | AC4: 0 | AD4: 0 | AE4: 0
A5: alternative chemistry cement | B5: 0 | C5: 0 | D5: 0 | E5: 0 | F5: 0 | G5: 0 | H5: 0 | I5: 0 | J5: 0 | K5: 0 | L5: 0 | M5: 0 | N5: 0 | O5: 0 | P5: 0 | Q5: 0 | R5: 0 | S5: 0 | T5: 0 | U5: 0 | V5: 0 | W5: 0 | X5: 0 | Y5: 0 | Z5: 0 | AA5: 0 | AB5: 0 | AC5: 0 | AD5: 0 | AE5: 0
