Workbook

Sheet About
A1: EoIEPwEEI Elasticity of Industrial Equipment Price with Respect to Energy Efficiency Improvements
A2: CONSIDER MARKUP SECTIONS
A3: Source: | B3: U.S. Department of Energy
B4: 2022
B5: TSD: EE PROGRAM FOR CONSUMER PRODUCTS AND COMM AND INDST EQPT: PUMPS
B6: https://www.regulations.gov/document/EERE-2021-BT-STD-0018-0013
B7: Table 2.6.10, 2.6.13
B9: U.S. Department of Energy
B10: 2023
B11: TSD: EE PROGRAM FOR CONSUMER PRODUCTS AND COMM AND INDST EQPT: Electric Motors
B12: https://www.regulations.gov/document/EERE-2020-BT-STD-0007-0040
B13: Table 5.3.3, 5.5.1
B15: U.S. Department of Energy
B16: 2016
B17: TSD: EE PROGRAM FOR CONSUMER PRODUCTS AND COMM AND INDST EQPT: COMMERCIAL PACKAGED BOILERS
B18: https://www.regulations.gov/document/EERE-2013-BT-STD-0030-0044
B19: Table 5.6.1
B21: U.S. Department of Energy
B22: 2024
B23: TSD: EE PROGRAM FOR CONSUMER PRODUCTS AND COMM AND INDST EQPT: COMMERCIAL REFRIGERATION EQUIPMENT
B24: https://www.regulations.gov/document/EERE-2017-BT-STD-0007-0118
B25: See Table 5.10.1
B27: U.S. Department of Energy
B28: 2023
B29: TSD: EE PROGRAM FOR CONSUMER PRODUCTS AND COMM AND INDST EQPT: COMMERCIAL WATER HEATING EQUIPMENT
B30: https://www.regulations.gov/document/EERE-2021-BT-STD-0027-0038
B31: Section 5.12
B33: U.S. Department of Energy
B34: 2023
B35: TSD: EE PROGRAM FOR CONSUMER PRODUCTS AND COMM AND INDST EQPT: Fans and Blowers
B36: https://www.regulations.gov/document/EERE-2022-BT-STD-0002-0133
B37: Table 5.6.9/10/5
B39: European Commission
B40: 2014
B41: Ecodesign Preparatory Study on Steam Boilers
B42: https://publications.europa.eu/resource/genpub/PUB_NB0714109ENN.1.1
B43: Tables 62, 79
B45: European Commission
B46: 2022
B47: Professional Refrigeration Ecodesign and Energy Labelling: Final Report
...

Sheet cpi
A1: Historical Consumer Price Index for All Urban Consumers (CPI-U): U.S. city average, all items, index
A2: averages — Continued
A3: [1982-84=100, unless otherwise noted]
A4: Year | B4: Semiannual averages | D4: Annual avg. | E4: Percent change from previous | G4: Multiply by to get 2012 Dollars
B5: 1st half | C5: 2nd half | E5: Dec. | F5: Annual avg.
A6: 1968............................................................................. . | B6: – | C6: – | D6: 34.8 | E6: 4.7 | F6: 4.2
A7: 1969............................................................................. . | B7: – | C7: – | D7: 36.7 | E7: 6.2 | F7: 5.5
A8: 1970............................................................................. . | B8: – | C8: – | D8: 38.8 | E8: 5.6 | F8: 5.7
A9: 1971............................................................................. . | B9: – | C9: – | D9: 40.5 | E9: 3.3 | F9: 4.4
A10: 1972............................................................................. . | B10: – | C10: – | D10: 41.8 | E10: 3.4 | F10: 3.2
A11: 1973............................................................................. . | B11: – | C11: – | D11: 44.4 | E11: 8.7 | F11: 6.2
A12: 1974............................................................................. . | B12: – | C12: – | D12: 49.3 | E12: 12.3 | F12: 11
A13: 1975............................................................................. . | B13: – | C13: – | D13: 53.8 | E13: 6.9 | F13: 9.1
A14: 1976............................................................................. . | B14: – | C14: – | D14: 56.9 | E14: 4.9 | F14: 5.8
A15: 1977............................................................................. . | B15: – | C15: – | D15: 60.6 | E15: 6.7 | F15: 6.5
A16: 1978............................................................................. . | B16: – | C16: – | D16: 65.2 | E16: 9 | F16: 7.6
A17: 1979............................................................................. . | B17: – | C17: – | D17: 72.6 | E17: 13.3 | F17: 11.3
... A21: 1983............................................................................. . | B21: – | C21: – | D21: 99.6 | E21: 3.8 | F21: 3.2
A22: 1984............................................................................. . | B22: 102.9 | C22: 104.9 | D22: 103.9 | E22: 3.9 | F22: 4.3
A23: 1985............................................................................. . | B23: 106.6 | C23: 108.5 | D23: 107.6 | E23: 3.8 | F23: 3.6
A24: 1986............................................................................. . | B24: 109.1 | C24: 110.1 | D24: 109.6 | E24: 1.1 | F24: 1.9
A25: 1987............................................................................. . | B25: 112.4 | C25: 114.9 | D25: 113.6 | E25: 4.4 | F25: 3.6
A26: 1988............................................................................. . | B26: 116.8 | C26: 119.7 | D26: 118.3 | E26: 4.4 | F26: 4.1
A27: 1989............................................................................. . | B27: 122.7 | C27: 125.3 | D27: 124 | E27: 4.6 | F27: 4.8
A28: 1990............................................................................. . | B28: 128.7 | C28: 132.6 | D28: 130.7 | E28: 6.1 | F28: 5.4 | G28: =$D$50/D28 -> 1.7566488
A29: 1991............................................................................. . | B29: 135.2 | C29: 137.2 | D29: 136.2 | E29: 3.1 | F29: 4.2 | G29: =$D$50/D29 -> 1.6857122
A30: 1992............................................................................. . | B30: 139.2 | C30: 141.4 | D30: 140.3 | E30: 2.9 | F30: 3 | G30: =$D$50/D30 -> 1.6364505
A31: 1993............................................................................. . | B31: 143.7 | C31: 145.3 | D31: 144.5 | E31: 2.7 | F31: 3 | G31: =$D$50/D31 -> 1.5888858
A32: 1994............................................................................. . | B32: 147.2 | C32: 149.3 | D32: 148.2 | E32: 2.7 | F32: 2.6 | G32: =$D$50/D32 -> 1.5492173
A33: 1995............................................................................. . | B33: 151.5 | C33: 153.2 | D33: 152.4 | E33: 2.5 | F33: 2.8 | G33: =$D$50/D33 -> 1.5065223
A34: 1996............................................................................. . | B34: 155.8 | C34: 157.9 | D34: 156.9 | E34: 3.3 | F34: 3 | G34: =$D$50/D34 -> 1.4633142
A35: 1997............................................................................. . | B35: 159.9 | C35: 161.2 | D35: 160.5 | E35: 1.7 | F35: 2.3 | G35: =$D$50/D35 -> 1.4304922
A36: 1998............................................................................. . | B36: 162.3 | C36: 163.7 | D36: 163 | E36: 1.6 | F36: 1.6 | G36: =$D$50/D36 -> 1.4085521
A37: 1999............................................................................. . | B37: 165.4 | C37: 167.8 | D37: 166.6 | E37: 2.7 | F37: 2.2 | G37: =$D$50/D37 -> 1.3781152
A38: 2000............................................................................. . | B38: 170.8 | C38: 173.6 | D38: 172.2 | E38: 3.4 | F38: 3.4 | G38: =$D$50/D38 -> 1.3332985
A39: 2001............................................................................. . | B39: 176.6 | C39: 177.5 | D39: 177.1 | E39: 1.6 | F39: 2.8 | G39: =$D$50/D39 -> 1.2964088
... A60: 2022............................................................................. . | B60: 288.347 | C60: 296.963 | D60: 292.655 | E60: 6.5 | F60: 8 | G60: =$D$50/D60 -> 0.78452102
A61: 2023............................................................................. . | B61: 302.408 | C61: 306.996 | D61: 304.702 | G61: =$D$50/D61 -> 0.75350342
A62: 2024............................................................................. . | B62: 312.145 | C62: 315.233 | D62: 313.689 | G62: =$D$50/D62 -> 0.73191601

Sheet indst motors
A1: we use the average of single-phase industrial motors > 0.75 kW, the 8-pole motor, and the addition of a VSD
A2: we ignore the small capacity motor option as industrial motors are typically larger than this (see NEMA Table 19)
A3: https://www.nema.org/docs/default-source/motor-and-generator-guides-and-resources-library/u.s._industrial_and_commerical_motor_system_market_assessment_report_vol_1_4cbc82a3-a08a-462d-a774-e637c9998c8a.pdf
B5: https://eur-lex.europa.eu/legal-content/EN/TXT/?uri=celex:52019SC0343
B7: Table 9.4: LCC calculations for small single-phase industrial motors >= 0.75kW
B8: Motor type | C8: efficiency | D8: acquisition (EUR)
B9: 1-phase IEO | C9: 0.592 | D9: 112.5
B10: 1-phase IE1 | C10: 0.66 | D10: 150 | H10: single-phase > 0.75 kW
B11: 1-phase IE2 | C11: 0.727 | D11: 188 | F11: =((D11-$D$10)/$D$10)/((C11-$C$10)/$C$10) -> 2.4955224 | H11: =AVERAGE(F11,F15) -> 2.0029851
B13: 1-phase IEO | C13: 0.592 | D13: 127.5
B14: 1-phase IE1 | C14: 0.66 | D14: 150
B15: 1-phase IE2 | C15: 0.727 | D15: 173 | F15: =((D15-$D$14)/$D$14)/((C15-$C$14)/$C$14) -> 1.5104478
B17: Table 9.5: LCC calculations for 8-pole industrial motors
B18: Motor type | C18: efficiency | D18: acquisition (EUR)
A19: (1.1 kW) | B19: 8-poles IE0 | C19: 0.598 | D19: 192 | H19: 8-pole motor
B20: 8-poles IE1 | C20: 0.665 | D20: 214 | H20: =AVERAGE(F21:F32) -> 6.4942922
B21: 8-poles IE2 | C21: 0.708 | D21: 241 | F21: =((D21-$D$20)/$D$20)/((C21-$C$20)/$C$20) -> 1.9512063
B22: 8-poles IE3 | C22: 0.777 | D22: 317 | F22: =((D22-$D$20)/$D$20)/((C22-$C$20)/$C$20) -> 2.8577687
A24: (11 kW) | B24: 8-poles IE0 | C24: 0.82 | D24: 762
B25: 8-poles IE1 | C25: 0.85 | D25: 853
B26: 8-poles IE2 | C26: 0.869 | D26: 966 | F26: =((D26-$D$25)/$D$25)/((C26-$C$25)/$C$25) -> 5.9264515
B27: 8-poles IE3 | C27: 0.886 | D27: 1106 | F27: =((D27-$D$25)/$D$25)/((C27-$C$25)/$C$25) -> 7.0030611
A29: (110 kW) | B29: 8-poles IE0 | C29: 0.893 | D29: 7000
B30: 8-poles IE1 | C30: 0.911 | D30: 7802
B31: 8-poles IE2 | C31: 0.923 | D31: 8874 | F31: =((D31-$D$30)/$D$30)/((C31-$C$30)/$C$30) -> 10.431001
B32: 8-poles IE3 | C32: 0.937 | D32: 10206 | F32: =((D32-$D$30)/$D$30)/((C32-$C$30)/$C$30) -> 10.796265
B34: Table 9.8: LCC calculations for VSDs for 3-phase motors 7.5-75 kW
A35: medium 3-phase IE2 | B35: Motor type | C35: input energy (kWh/a) | D35: acquisition + install
B36: no VSD | C36: 24595 | D36: 683
B37: VSD IE0 | C37: 16135 | D37: 2303 | F37: =((D37-$D$36)/$D$36)/((C37-$C$36)/$C$36) -> -6.8955796 | H37: addition of a VSD
B38: VSD IE1 | C38: 15922 | D38: 2393 | F38: =((D38-$D$36)/$D$36)/((C38-$C$36)/$C$36) -> -7.0999107 | H38: =-AVERAGE(F37:F47) -> 6.9105031
B39: VSD IE2 | C39: 15709 | D39: 2518 | F39: =((D39-$D$36)/$D$36)/((C39-$C$36)/$C$36) -> -7.4362825
B40: VSD IE3 | C40: 15497 | D40: 2643 | F40: =((D40-$D$36)/$D$36)/((C40-$C$36)/$C$36) -> -7.7577586
A42: medium 3-phase IE3 | B42: Motor type | C42: input energy (kWh/a) | D42: acquisition + install
B43: no VSD | C43: 23805 | D43: 761
B44: VSD IE0 | C44: 15593 | D44: 2381 | F44: =((D44-$D$43)/$D$43)/((C44-$C$43)/$C$43) -> -6.1709155
B45: VSD IE1 | C45: 15381 | D45: 2471 | F45: =((D45-$D$43)/$D$43)/((C45-$C$43)/$C$43) -> -6.3498181
B46: VSD IE2 | C46: 15168 | D46: 2596 | F46: =((D46-$D$43)/$D$43)/((C46-$C$43)/$C$43) -> -6.645944
B47: VSD IE3 | C47: 14955 | D47: 2721 | F47: =((D47-$D$43)/$D$43)/((C47-$C$43)/$C$43) -> -6.9278158
H48: average abatement technology
...

Sheet furnaces
B2: Table 5.10.1 MPC and MSP for Gas-Fired CWAF- Aluminized Steel Heat Exchanger and Inducer Assembly Components at 80% TE, 81% TE, and 82% TE
B3: Efficiency level | C3: TE | D3: MSP 2014$
B4: Baseline | C4: 0.8 | D4: 441.74
B5: EL1 | C5: 0.81 | D5: 459.03 | F5: =((D5-$D$4)/($D$4))/((C5-$C$4)/($C$4)) -> 3.1312537 | H5: =AVERAGE(F5:F7) -> 6.914374
B6: EL2 | C6: 0.82 | D6: 468.22 | F6: =((D6-$D$4)/($D$4))/((C6-$C$4)/($C$4)) -> 2.3977906
B7: Max-tech | C7: 0.92 | D7: 1449.84 | F7: =((D7-$D$4)/($D$4))/((C7-$C$4)/($C$4)) -> 15.214078
B9: Table 5.10.2 MPC and MSP for Gas-Fired CWAF- SS409 Heat Exchanger and Inducer Assembly Components at 80% TE, 81% TE, and 82% TE
B10: Efficiency level | C10: TE | D10: MSP 2014$
B11: Baseline | C11: 0.8 | D11: 585.58
B12: EL1 | C12: 0.81 | D12: 614.9 | F12: =((D12-$D$11)/($D$11))/((C12-$C$11)/($C$11)) -> 4.0056013 | H12: =AVERAGE(F12:F14) -> 5.7666663
B13: EL2 | C13: 0.82 | D13: 636.16 | F13: =((D13-$D$11)/($D$11))/((C13-$C$11)/($C$11)) -> 3.455036
B14: Max-tech | C14: 0.92 | D14: 1449.84 | F14: =((D14-$D$11)/($D$11))/((C14-$C$11)/($C$11)) -> 9.8393615
B16: Table 5.10.3 MPC and MSP for Gas-Fired CWAF- SS316 Heat Exchanger and Inducer Assembly Components at 80% TE, 81% TE, and 82% TE
B17: Efficiency level | C17: TE | D17: MSP 2014$
B18: Baseline | C18: 0.8 | D18: 785.32
B19: EL1 | C19: 0.81 | D19: 831.67 | F19: =((D19-$D$18)/($D$18))/((C19-$C$18)/($C$18)) -> 4.7216421 | H19: =AVERAGE(F19:F21) -> 4.8914809
B20: EL2 | C20: 0.82 | D20: 869.97 | F20: =((D20-$D$18)/($D$18))/((C20-$C$18)/($C$18)) -> 4.3116182
B21: Max-tech | C21: 0.92 | D21: 1449.84 | F21: =((D21-$D$18)/($D$18))/((C21-$C$18)/($C$18)) -> 5.6411824
B23: Table 5.10.4 MPC and MSP for Oil-Fired CWAF
B24: Efficiency level | C24: TE | D24: MSP 2014$
B25: Baseline | C25: 0.81 | D25: 2065.19
B26: EL1 | C26: 0.82 | D26: 2096.89 | F26: =((D26-$D$25)/($D$25))/((C26-$C$25)/($C$25)) -> 1.2433239 | H26: =AVERAGE(F26:F27) -> 2.1980839
B27: Max-tech | C27: 0.92 | D27: 2949.43 | F27: =((D27-$D$25)/($D$25))/((C27-$C$25)/($C$25)) -> 3.152844
H29: =AVERAGE(H5:H26) -> 4.9426513

Sheet comm refrigerators
B2: Table 5.10.2 Cost-Efficiency Data for the VOP.RC.M Equipment Class | K2: Table 6.8.1 Summary of Overall Markups for Commercial Refrigeration Equipment
B3: Design Option Level | D3: Percent Below Baseline | E3: Daily Energy Use (kWh/day) | F3: MPC Mfg. Cost ($) | L3: Wholesale Channel
B4: DO | C4: 0 | D4: 0 | E4: 38.169 | F4: 4249.4 | G4: Baseline | L4: Baseline MU | M4: Incremental MU
B5: DO | C5: 1 | D5: 0.077 | E5: 35.251 | F5: 4356.92 | G5: Night Curtains | K5: Wholesaler | L5: 1.403 | M5: 1.177
B6: DO | C6: 2 | D6: 0.123 | E6: 33.502 | F6: 4481.92 | G6: Occupancy Sensors with Dimming | K6: Mechanical Contractor | L6: - | M6: -
K7: General Contractor | L7: - | M7: -
B8: Table 5.10.3 Cost-Efficiency Data for the VOP.RC.L Equipment Class | K8: Sales Tax | L8: 1.073 | M8: 1.073
B9: DO | C9: 0 | D9: 0 | E9: 105.083 | F9: 4657.34 | G9: Baseline | K9: Overall Markup | L9: 1.506 | M9: 1.263
B10: DO | C10: 1 | D10: 0.055 | E10: 99.305 | F10: 4764.86 | G10: Night Curtains
B11: DO | C11: 2 | D11: 0.072 | E11: 97.557 | F11: 4889.86 | G11: Occupancy Sensors with Dimming
B13: Table 5.10.4 Cost-Efficiency Data for the VOP.SC.M Non -Large Equipment Class
B14: DO | C14: 0 | D14: 0 | E14: 29.566 | F14: 3169.49 | G14: Baseline (R-290 Single Speed Reciprocating Compressor) | H14: =F14*$L$9 -> 4773.2519
B15: DO | C15: 1 | D15: 0.087 | E15: 27.004 | F15: 3205.33 | G15: Night Curtains | H15: =$H$14+(F15-$F$14)*$M$9 -> 4818.5179
B16: DO | C16: 2 | D16: 0.105 | E16: 26.458 | F16: 3216.04 | G16: Permanent Split Cap. Cond. Fan Motor | H16: =$H$14+(F16-$F$14)*$M$9 -> 4832.0446 | I16: =((F16-F15)/(F15))/((E16-E15)/(E15)) -> -0.16525408 | J16: *only considering motor & compressor upgrades, not doors/curtains
B17: DO | C17: 3 | D17: 0.128 | E17: 25.778 | F17: 3241.63 | G17: Brushless DC Cond. Fan Motor | H17: =$H$14+(F17-$F$14)*$M$9 -> 4864.3648 | I17: =((F17-F16)/(F16))/((E17-E16)/(E16)) -> -0.30959714 | J17: which don't apply to industrial equipment
B18: DO | C18: 4 | D18: 0.263 | E18: 21.793 | F18: 3429.63 | G18: R-290 Variable Speed Reciprocating Compressor | H18: =$H$14+(F18-$F$14)*$M$9 -> 5101.8088 | I18: =((F18-F17)/(F17))/((E18-E17)/(E17)) -> -0.37515894
B19: DO | C19: 5 | D19: 0.281 | E19: 21.263 | F19: 3509.63 | G19: Occupancy Sensors with Dimming | H19: =$H$14+(F19-$F$14)*$M$9 -> 5202.8488
B21: Table 5.10.5 Cost-Efficiency Data for the VCT.RC.M Equipment Class
B22: DO | C22: 0 | D22: 0 | E22: 11.649 | F22: 4315.12 | G22: Baseline
B23: DO | C23: 1 | D23: 0.014 | E23: 11.531 | F23: 4409.65 | G23: Triple
B24: DO | C24: 2 | D24: 0.098 | E24: 10.551 | F24: 4534.65
B25: DO | C25: 3 | D25: 0.101 | E25: 10.513 | F25: 4689.23
B26: DO | C26: 4 | D26: 0.109 | E26: 10.423 | F26: 6537.7
B28: Table 5.10.6 Cost-Efficiency Data for the VCT.RC.L Equipment Class
B29: DO | C29: 0 | D29: 0 | E29: 34.558 | F29: 4411.04 | G29: Baseline
B30: DO | C30: 1 | D30: 0.026 | E30: 33.578 | F30: 4536.04
B31: DO | C31: 2 | D31: 0.03 | E31: 33.414 | F31: 4690.62
B32: DO | C32: 3 | D32: 0.06 | E32: 32.399 | F32: 6539.09
B34: Table 5.10.7 Cost-Efficiency Data for the VCT.SC.H Equipment Class
B35: DO | C35: 0 | D35: 0 | E35: 2.938 | F35: 2181.32 | G35: Baseline (R-290 Single Speed Reciprocating Compressor) | H35: =F35*$L$9 -> 3285.0679
B36: DO | C36: 1 | D36: 0.023 | E36: 2.871 | F36: 2184.89 | G36: Permanent Split Cap. Cond. Fan Motor | H36: =$H$35+(F36-$F$35)*$M$9 -> 3289.5768 | I36: =((F36-F35)/(F35))/((E36-E35)/(E35)) -> -0.07176717
B37: DO | C37: 2 | D37: 0.051 | E37: 2.788 | F37: 2193.42 | G37: Brushless DC Cond. Fan Motor | H37: =$H$35+(F37-$F$35)*$M$9 -> 3300.3502 | I37: =((F37-F36)/(F36))/((E37-E36)/(E36)) -> -0.13504377
B38: DO | C38: 3 | D38: 0.188 | E38: 2.387 | F38: 2287.42 | G38: R290 Variable Speed Reciprocating Compressor | H38: =$H$35+(F38-$F$35)*$M$9 -> 3419.0722 | I38: =((F38-F37)/(F37))/((E38-E37)/(E37)) -> -0.29795759
B39: DO | C39: 4 | D39: 0.201 | E39: 2.347 | F39: 2325.23 | G39: Triple Pane, Ar Fill Door | H39: =$H$35+(F39-$F$35)*$M$9 -> 3466.8263
B40: DO | C40: 5 | D40: 0.237 | E40: 2.241 | F40: 2390.23 | G40: Occupancy Sensors with Dimming | H40: =$H$35+(F40-$F$35)*$M$9 -> 3548.9213
B41: DO | C41: 6 | D41: 0.242 | E41: 2.228 | F41: 2452.06 | G41: Triple Pane, Kr Fill Door | H41: =$H$35+(F41-$F$35)*$M$9 -> 3627.0125
B42: DO | C42: 7 | D42: 0.252 | E42: 2.197 | F42: 3191.45 | G42: Double Pane, Vacuum Insulated Door | H42: =$H$35+(F42-$F$35)*$M$9 -> 4560.8621
B44: Table 5.10.10 Cost-Efficiency Data for the VCT.SC.I Equipment Class
B45: DO | C45: 0 | D45: 0 | E45: 19.486 | F45: 3301.27 | G45: Baseline (R-290 Single Speed Reciprocating Compressor)
B46: DO | C46: 1 | D46: 0.004 | E46: 19.327 | F46: 3366.27 | G46: Occupancy Sensors with Dimming
...

Sheet process chillers
A1: https://ecoprorefrigeration.eu/documents.htm#a20230206
C3: Table 77: Price and efficiency relationship
D4: Prices (EUR 2020) | G4: Efficiency Metric (SEPR) | K4: Elasticity
D5: BC | E5: Mid | F5: BAT | G5: BC | H5: Mid | I5: BAT | K5: Mid | L5: BAT
C6: АС МТ <300 | D6: 31831 | E6: 35000 | F6: 47588 | G6: 2.7 | H6: 3.2 | I6: 3.81 | K6: =((E6-$D6)/($D6))/((H6-$G6)/($G6)) -> 0.53760799 | L6: =((F6-$D6)/($D6))/((I6-$G6)/($G6)) -> 1.2041041
C7: АС МТ >300 | D7: 102315 | E7: 110000 | F7: 146311 | G7: 3 | H7: 3.4 | I7: 4.21 | K7: =((E7-$D7)/($D7))/((H7-$G7)/($G7)) -> 0.56333382 | L7: =((F7-$D7)/($D7))/((I7-$G7)/($G7)) -> 1.066129
C8: АС LT <200 | D8: 35242 | E8: 40000 | F8: 52687 | G8: 1.59 | H8: 1.9 | I8: 2.22 | K8: =((E8-$D8)/($D8))/((H8-$G8)/($G8)) -> 0.69246738 | L8: =((F8-$D8)/($D8))/((I8-$G8)/($G8)) -> 1.2493008
C9: АС LT >200 | D9: 106863 | E9: 115000 | F9: 152814 | G9: 1.7 | H9: 1.95 | I9: 2.38 | K9: =((E9-$D9)/($D9))/((H9-$G9)/($G9)) -> 0.51778071 | L9: =((F9-$D9)/($D9))/((I9-$G9)/($G9)) -> 1.0749979
C10: wc мт <300 | D10: 47747 | E10: 51000 | F10: 71382 | G10: 3.6 | H10: 4.1 | I10: 5.08 | K10: =((E10-$D10)/($D10))/((H10-$G10)/($G10)) -> 0.49053553 | L10: =((F10-$D10)/($D10))/((I10-$G10)/($G10)) -> 1.204066
C11: wc мт >300 | D11: 153473 | E11: 165000 | F11: 219466 | G11: 3.9 | H11: 4.5 | I11: 5.46 | K11: =((E11-$D11)/($D11))/((H11-$G11)/($G11)) -> 0.48819988 | L11: =((F11-$D11)/($D11))/((I11-$G11)/($G11)) -> 1.0749936
C12: wc 1-т <200 | D12: 52863 | E12: 57000 | F12: 79030 | G12: 2 | H12: 2.3 | I12: 2.81 | K12: =((E12-$D12)/($D12))/((H12-$G12)/($G12)) -> 0.52172597 | L12: =((F12-$D12)/($D12))/((I12-$G12)/($G12)) -> 1.2222136
C13: wc LT >200 | D13: 160294 | E13: 172000 | F13: 229221 | G13: 2.25 | H13: 2.55 | I13: 3.16 | K13: =((E13-$D13)/($D13))/((H13-$G13)/($G13)) -> 0.54771233 | L13: =((F13-$D13)/($D13))/((I13-$G13)/($G13)) -> 1.0631958
C14: *200/300 = capacity in kW
K15: =AVERAGE(K6:L13) -> 0.84489778

Sheet water heaters
B2: Table 5.12.1 MPC and MSP Estimates for Commercial Gas-Fired Storage Water Heaters, 100 Gallon Rated Storage Volume, 199,000 Btu/h Input Capacity
B3: Thermal efficiency level | C3: thermal efficiency | D3: MPC 2022$ | E3: MSP 2022$
B4: Et EL0 | C4: 0.8 | D4: 1453.78 | E4: 2107.98
B5: Et EL1 | C5: 0.82 | D5: 1489.43 | E5: 2159.68 | G5: =((E5-$E$4)/(E5+$E$4))/((C5-$C$4)/($C$4)) -> 0.48457468
B6: Et EL2 | C6: 0.9 | D6: 1610.08 | E6: 2334.62 | G6: =((E6-$E$4)/(E6+$E$4))/((C6-$C$4)/($C$4)) -> 0.40812137
B7: Et EL3 | C7: 0.92 | D7: 1629.39 | E7: 2362.61 | G7: =((E7-$E$4)/(E7+$E$4))/((C7-$C$4)/($C$4)) -> 0.37971125
B8: Et EL4 | C8: 0.95 | D8: 1666.24 | E8: 2416.05 | G8: =((E8-$E$4)/(E8+$E$4))/((C8-$C$4)/($C$4)) -> 0.36318062
B9: Et EL5 | C9: 0.99 | D9: 1733.86 | E9: 2514.1 | G9: =((E9-$E$4)/(E9+$E$4))/((C9-$C$4)/($C$4)) -> 0.36995875
G10: =AVERAGE(G5:G9) -> 0.40110934
B12: Table 5.12.4 MPC and MSP Estimates for Gas-Fired Circulating Water Heaters and Hot Water Supply Boilers, 399,000 Btu/h Input Capacity
B13: Thermal efficiency level | C13: thermal efficiency | D13: MPC 2022$ | E13: MSP 2022$
B14: Et EL0 | C14: 0.8 | D14: 1259.7 | E14: 1801.36
B15: Et EL1 | C15: 0.82 | D15: 1270.95 | E15: 1817.46 | G15: =((E15-$E$14)/(E15+$E$14))/((C15-$C$14)/($C$14)) -> 0.17795856
B16: Et EL2 | C16: 0.84 | D16: 1355.79 | E16: 1938.78 | G16: =((E16-$E$14)/(E16+$E$14))/((C16-$C$14)/($C$14)) -> 0.7348388
B17: Et EL3 | C17: 0.92 | D17: 3146.59 | E17: 4499.63 | G17: =((E17-$E$14)/(E17+$E$14))/((C17-$C$14)/($C$14)) -> 2.8548635
B18: Et EL4 | C18: 0.94 | D18: 3329.25 | E18: 4760.83 | G18: =((E18-$E$14)/(E18+$E$14))/((C18-$C$14)/($C$14)) -> 2.5770752
B19: Et EL5 | C19: 0.96 | D19: 3511.91 | E19: 5022.03 | G19: =((E19-$E$14)/(E19+$E$14))/((C19-$C$14)/($C$14)) -> 2.3600219
G20: =AVERAGE(G15:G19) -> 1.7409516

Sheet pumps
B2: Table 2.6.10 PEI by representative Unit and EL forPum s Greater Than or Equal to 1 HP | J2: Table 2.6.13 Manufacturer Production Cost bv Re resentative Unit and EL
B3: Pump | C3: BEP Head | D3: BEP Flow | E3: EL O PEI | F3: EL 1 PEI | G3: EL 2 PEI | J3: Pump Category | K3: BEP Head | L3: BEP Flow | M3: EL O MPC | N3: EL 1 NIPC | O3: EL 2 MPC | R3: ε
B4: Category | C4: (ft) | D4: (GPM) | K4: (ft) | L4: (GPM) | R4: EL 1 | S4: EL 2
C5: 50 | D5: 200 | E5: 1 | F5: 0.94 | G5: 0.51 | K5: 50 | L5: 200 | M5: 1188.41 | N5: 1420.43 | O5: 1561.02 | R5: =((N5-M5)/(M5))/((F5-E5)/(E5)) -> -3.2539275 | S5: =((O5-N5)/(N5))/((G5-F5)/(F5)) -> -0.21636848 | T5: =AVERAGE(R5:S5) -> -1.735148
B6: ESFM. 1800 | C6: 85 | D6: 300 | E6: 1 | F6: 0.94 | G6: 0.5 | J6: ESFM.1800 | K6: 85 | L6: 300 | M6: 1812.76 | N6: 2126.94 | O6: 2095.01 | R6: =((N6-M6)/(M6))/((F6-E6)/(E6)) -> -2.8885971 | S6: =((O6-N6)/(N6))/((G6-F6)/(F6)) -> 0.032071469 | T6: =AVERAGE(R6:S6) -> -1.4282628
C7: 85 | D7: 750 | E7: 1 | F7: 0.96 | G7: 0.5 | K7: 85 | L7: 750 | M7: 2769.52 | N7: 3357.9 | O7: 3278.4 | R7: =((N7-M7)/(M7))/((F7-E7)/(E7)) -> -5.3112092 | S7: =((O7-N7)/(N7))/((G7-F7)/(F7)) -> 0.049409763 | T7: =AVERAGE(R7:S7) -> -2.6308997
C8: 100 | D8: 75 | E8: 1 | F8: 0.94 | G8: 0.51 | K8: 100 | L8: 75 | M8: 955.99 | N8: 1188.01 | O8: 1096.58 | R8: =((N8-M8)/(M8))/((F8-E8)/(E8)) -> -4.0450214 | S8: =((O8-N8)/(N8))/((G8-F8)/(F8)) -> 0.16823952 | T8: =AVERAGE(R8:S8) -> -1.9383909
B9: ESFM.3600 | C9: 190 | D9: 300 | E9: 1 | F9: 0.96 | G9: 0.51 | J9: ESFM.3600 | K9: 190 | L9: 300 | M9: 2385.52 | N9: 2973.9 | O9: 2894.4 | R9: =((N9-M9)/(M9))/((F9-E9)/(E9)) -> -6.1661608 | S9: =((O9-N9)/(N9))/((G9-F9)/(F9)) -> 0.05702949 | T9: =AVERAGE(R9:S9) -> -3.0545657
C10: 160 | D10: 160 | E10: 1 | F10: 0.95 | G10: 0.5 | K10: 160 | L10: 160 | M10: 1520.39 | N10: 1834.57 | O10: 1802.64 | R10: =((N10-M10)/(M10))/((F10-E10)/(E10)) -> -4.132887 | S10: =((O10-N10)/(N10))/((G10-F10)/(F10)) -> 0.036743094 | T10: =AVERAGE(R10:S10) -> -2.0480719
C11: 40 | D11: 350 | E11: 1 | F11: 0.94 | G11: 0.51 | K11: 40 | L11: 350 | M11: 1305.11 | N11: 1548.07 | O11: 1474.03 | R11: =((N11-M11)/(M11))/((F11-E11)/(E11)) -> -3.1026759 | S11: =((O11-N11)/(N11))/((G11-F11)/(F11)) -> 0.10455269 | T11: =AVERAGE(R11:S11) -> -1.4990616
B12: ESCC. 1800 | C12: 85 | D12: 400 | E12: 1 | F12: 0.95 | G12: 0.5 | J12: ESCC.1800 | K12: 85 | L12: 400 | M12: 1862.5 | N12: 2176.68 | O12: 2144.74 | R12: =((N12-M12)/(M12))/((F12-E12)/(E12)) -> -3.373745 | S12: =((O12-N12)/(N12))/((G12-F12)/(F12)) -> 0.03097786 | T12: =AVERAGE(R12:S12) -> -1.6713836
C13: 150 | D13: 600 | E13: 1 | F13: 0.96 | G13: 0.5 | K13: 150 | L13: 600 | M13: 3768.52 | N13: 4806.78 | O13: 4504.04 | R13: =((N13-M13)/(M13))/((F13-E13)/(E13)) -> -6.8877172 | S13: =((O13-N13)/(N13))/((G13-F13)/(F13)) -> 0.13144043 | T13: =AVERAGE(R13:S13) -> -3.3781384
C14: 200 | D14: 200 | E14: 1 | F14: 0.96 | G14: 0.51 | K14: 200 | L14: 200 | M14: 1954.24 | N14: 2383.56 | O14: 2349.81 | R14: =((N14-M14)/(M14))/((F14-E14)/(E14)) -> -5.4921606 | S14: =((O14-N14)/(N14))/((G14-F14)/(F14)) -> 0.030206917 | T14: =AVERAGE(R14:S14) -> -2.7309769
B15: ESCC.3600 | C15: 75 | D15: 75 | E15: 1 | F15: 0.92 | G15: 0.57 | J15: ESCC.3600 | K15: 75 | L15: 75 | M15: 841.5 | N15: 1065.32 | O15: 953.77 | R15: =((N15-M15)/(M15))/((F15-E15)/(E15)) -> -3.3247178 | S15: =((O15-N15)/(N15))/((G15-F15)/(F15)) -> 0.27523856 | T15: =AVERAGE(R15:S15) -> -1.5247396
C16: 130 | D16: 130 | E16: 1 | F16: 0.95 | G16: 0.5 | K16: 130 | L16: 130 | M16: 1292.7 | N16: 1565.78 | O16: 1518.28 | R16: =((N16-M16)/(M16))/((F16-E16)/(E16)) -> -4.2249555 | S16: =((O16-N16)/(N16))/((G16-F16)/(F16)) -> 0.064043338 | T16: =AVERAGE(R16:S16) -> -2.0804561
C17: 125 | D17: 3500 | E17: 1 | F17: 0.95 | G17: 0.49 | J17: BB.1800 | K17: 125 | L17: 3500 | M17: 15345.63 | N17: 29419.79 | O17: 18234.24 | R17: =((N17-M17)/(M17))/((F17-E17)/(E17)) -> -18.34289 | S17: =((O17-N17)/(N17))/((G17-F17)/(F17)) -> 0.78520589 | T17: =AVERAGE(R17:S17) -> -8.778842
B18: BB.1800 | C18: 110 | D18: 1000 | E18: 1 | F18: 0.96 | G18: 0.5 | K18: 110 | L18: 1000 | M18: 4451.4 | N18: 5942.36 | O18: 5356.91 | R18: =((N18-M18)/(M18))/((F18-E18)/(E18)) -> -8.3735454 | S18: =((O18-N18)/(N18))/((G18-F18)/(F18)) -> 0.20561001 | T18: =AVERAGE(R18:S18) -> -4.0839677
C19: 210 | D19: 1500 | E19: 1 | F19: 0.95 | G19: 0.49 | K19: 210 | L19: 1500 | M19: 11891.93 | N19: 20998.39 | O19: 14213.93 | R19: =((N19-M19)/(M19))/((F19-E19)/(E19)) -> -15.315361 | S19: =((O19-N19)/(N19))/((G19-F19)/(F19)) -> 0.66725996 | T19: =AVERAGE(R19:S19) -> -7.3240505
C20: 330 | D20: 400 | E20: 1 | F20: 0.96 | G20: 0.5 | K20: 330 | L20: 400 | M20: 5225.67 | N20: 7690.73 | O20: 6414.48 | R20: =((N20-M20)/(M20))/((F20-E20)/(E20)) -> -11.793033 | S20: =((O20-N20)/(N20))/((G20-F20)/(F20)) -> 0.3463232 | T20: =AVERAGE(R20:S20) -> -5.723355
B21: BB.3600 | C21: 350 | D21: 750 | E21: 1 | F21: 0.95 | G21: 0.49 | K21: 350 | L21: 750 | M21: 11045.9 | N21: 20152.36 | O21: 13367.9 | R21: =((N21-M21)/(M21))/((F21-E21)/(E21)) -> -16.488398 | S21: =((O21-N21)/(N21))/((G21-F21)/(F21)) -> 0.69527265 | T21: =AVERAGE(R21:S21) -> -7.8965629
C22: 320 | D22: 1150 | E22: 1 | F22: 0.95 | G22: 0.49 | K22: 320 | L22: 1150 | M22: 14516.81 | N22: 28590.97 | O22: 17405.41 | R22: =((N22-M22)/(M22))/((F22-E22)/(E22)) -> -19.390155 | S22: =((O22-N22)/(N22))/((G22-F22)/(F22)) -> 0.80796885 | T22: =AVERAGE(R22:S22) -> -9.2910932
C23: 40 | D23: 150 | E23: 1 | F23: 0.92 | G23: 0.58 | K23: 40 | L23: 150 | M23: 1215.61 | N23: 1439.43 | O23: 1327.87 | R23: =((N23-M23)/(M23))/((F23-E23)/(E23)) -> -2.3015194 | S23: =((O23-N23)/(N23))/((G23-F23)/(F23)) -> 0.20971373 | T23: =AVERAGE(R23:S23) -> -1.0459028
B24: IL. 1800 | C24: 85 | D24: 200 | E24: 1 | F24: 0.95 | G24: 0.5 | K24: 85 | L24: 200 | M24: 1803.03 | N24: 2076.11 | O24: 2028.61 | R24: =((N24-M24)/(M24))/((F24-E24)/(E24)) -> -3.0291232 | S24: =((O24-N24)/(N24))/((G24-F24)/(F24)) -> 0.048300802 | T24: =AVERAGE(R24:S24) -> -1.4904112
C25: 100 | D25: 600 | E25: 1 | F25: 0.96 | G25: 0.5 | K25: 100 | L25: 600 | M25: 3096.76 | N25: 3685.14 | O25: 3605.64 | R25: =((N25-M25)/(M25))/((F25-E25)/(E25)) -> -4.7499645 | S25: =((O25-N25)/(N25))/((G25-F25)/(F25)) -> 0.045022182 | T25: =AVERAGE(R25:S25) -> -2.3524711
C26: 75 | D26: 100 | E26: 1 | F26: 0.94 | G26: 0.51 | K26: 75 | L26: 100 | M26: 1076.22 | N26: 1308.24 | O26: 1216.82 | R26: =((N26-M26)/(M26))/((F26-E26)/(E26)) -> -3.5931315 | S26: =((O26-N26)/(N26))/((G26-F26)/(F26)) -> 0.15276125 | T26: =AVERAGE(R26:S26) -> -1.7201851
B27: IL.3600 | C27: 150 | D27: 175 | E27: 1 | F27: 0.95 | G27: 0.5 | K27: 150 | L27: 175 | M27: 1684.25 | N27: 1998.43 | O27: 1966.5 | R27: =((N27-M27)/(M27))/((F27-E27)/(E27)) -> -3.7308001 | S27: =((O27-N27)/(N27))/((G27-F27)/(F27)) -> 0.033730367 | T27: =AVERAGE(R27:S27) -> -1.8485348
C28: 175 | D28: 400 | E28: 1 | F28: 0.95 | G28: 0.5 | K28: 175 | L28: 400 | M28: 3013.43 | N28: 3804.79 | O28: 3635.63 | R28: =((N28-M28)/(M28))/((F28-E28)/(E28)) -> -5.2522209 | S28: =((O28-N28)/(N28))/((G28-F28)/(F28)) -> 0.093859465 | T28: =AVERAGE(R28:S28) -> -2.5791807
C29: 175 | D29: 50 | E29: 1 | F29: 0.95 | G29: 0.62 | K29: 175 | L29: 50 | M29: 701.14 | N29: 933.16 | O29: 841.74 | R29: =((N29-M29)/(M29))/((F29-E29)/(E29)) -> -6.6183644 | S29: =((O29-N29)/(N29))/((G29-F29)/(F29)) -> 0.28202965 | T29: =AVERAGE(R29:S29) -> -3.1681674
B30: ST.3600 | C30: 400 | D30: 100 | E30: 1 | F30: 0.94 | G30: 0.59 | K30: 400 | L30: 100 | M30: 1591.94 | N30: 1906.12 | O30: 1874.18 | R30: =((N30-M30)/(M30))/((F30-E30)/(E30)) -> -3.2892781 | S30: =((O30-N30)/(N30))/((G30-F30)/(F30)) -> 0.045003313 | T30: =AVERAGE(R30:S30) -> -1.6221374
C31: 350 | D31: 250 | E31: 1 | F31: 0.94 | G31: 0.58 | K31: 350 | L31: 250 | M31: 2508.53 | N31: 3096.91 | O31: 3017.41 | R31: =((N31-M31)/(M31))/((F31-E31)/(E31)) -> -3.9091952 | S31: =((O31-N31)/(N31))/((G31-F31)/(F31)) -> 0.067029179 | T31: =AVERAGE(R31:S31) -> -1.921083
C32: 40 | D32: 350 | E32: 1 | F32: 0.93 | G32: 0.54 | K32: 40 | L32: 350 | M32: 1244.35 | N32: 1476.37 | O32: 1384.94 | R32: =((N32-M32)/(M32))/((F32-E32)/(E32)) -> -2.6636971 | S32: =((O32-N32)/(N32))/((G32-F32)/(F32)) -> 0.14767666 | T32: =AVERAGE(R32:S32) -> -1.2580102
B33: VT.1800 | C33: 85 | D33: 400 | E33: 1 | F33: 0.89 | G33: 0.44 | K33: 85 | L33: 400 | M33: 2694.87 | N33: 3283.25 | O33: 3203.75 | R33: =((N33-M33)/(M33))/((F33-E33)/(E33)) -> -1.9848487 | S33: =((O33-N33)/(N33))/((G33-F33)/(F33)) -> 0.04788954 | T33: =AVERAGE(R33:S33) -> -0.96847956
C34: 150 | D34: 600 | E34: 1 | F34: 0.93 | G34: 0.54 | K34: 150 | L34: 600 | M34: 2085.12 | N34: 2399.3 | O34: 2367.37 | R34: =((N34-M34)/(M34))/((F34-E34)/(E34)) -> -2.1525311 | S34: =((O34-N34)/(N34))/((G34-F34)/(F34)) -> 0.031734576 | T34: =AVERAGE(R34:S34) -> -1.0603983
C35: 200 | D35: 200 | E35: 1 | F35: 0.92 | G35: 0.52 | K35: 200 | L35: 200 | M35: 1153.6 | N35: 1396.56 | O35: 1322.53 | R35: =((N35-M35)/(M35))/((F35-E35)/(E35)) -> -2.6326283 | S35: =((O35-N35)/(N35))/((G35-F35)/(F35)) -> 0.12192029 | T35: =AVERAGE(R35:S35) -> -1.255354
B36: VT.3600 | C36: 75 | D36: 75 | E36: 1 | F36: 0.87 | G36: 0.21 | K36: 75 | L36: 75 | M36: 933.12 | N36: 1247.3 | O36: 1215.37 | R36: =((N36-M36)/(M36))/((F36-E36)/(E36)) -> -2.5899876 | S36: =((O36-N36)/(N36))/((G36-F36)/(F36)) -> 0.033744525 | T36: =AVERAGE(R36:S36) -> -1.2781215
C37: 130 | D37: 130 | E37: 1 | F37: 0.85 | G37: 0.44 | K37: 130 | L37: 130 | M37: 2903.11 | N37: 3941.37 | O37: 3638.63 | R37: =((N37-M37)/(M37))/((F37-E37)/(E37)) -> -2.3842477 | S37: =((O37-N37)/(N37))/((G37-F37)/(F37)) -> 0.15924202 | T37: =AVERAGE(R37:S37) -> -1.1125028
T38: =-AVERAGE(T5:T37) -> 2.8333002
A39: Table 2.6.11 PEI b •Re resentative Unit and EL for SVIL | J39: Table 2.6.14 SVIL Manufacturer Production Cost bv Re resentative Unit and EL
B40: Pump | C40: BEP Head | D40: BEP Flow | E40: EL OPEI | F40: EL 1 PEI | G40: EL 2 PEI | H40: EL3 PEI | J40: Pump Category | K40: BEP Head | L40: BEP Flow | M40: EL ONIPC | N40: ELI MPC | O40: EL 2 MPC | P40: EL 3 MPC
B41: Category | C41: 15 | D41: 40 | E41: 1 | F41: 0.79 | G41: 0.86 | H41: 0.4 | K41: 15 | L41: 40 | M41: 776.29 | N41: 834.96 | O41: 739.32 | P41: 896.23 | R41: =((N41-$M41)/($M41))/((F41-$E41)/($E41)) -> -0.3598925 | S41: =((O41-$M41)/($M41))/((G41-$E41)/($E41)) -> 0.34017111 | T41: =((P41-$M41)/($M41))/((H41-$E41)/($E41)) -> -0.25750686 | U41: =-AVERAGE(R41:T41) -> 0.092409419
...

Sheet motors
B2: Table 5.3.3 Efficienc Levels b Re resentative Unit | K2: Table 5.5.1 | M2: MSP 2021S of Each Re resentative Unit
B3: ECG | C3: RU | K3: C | L3: RU # | M3: Rep. Unit | N3: ELO | O3: ELI | P3: EL2 | Q3: EL3 | R3: EL4
D4: Rep. Unit Description | E4: ELO | F4: ELI | G4: EL2 | H4: EL3 | I4: EL4 | M4: esign A/B. 5-horsepower, 4-
C5: # | L5: #
C6: 1 | D6: Design A/B, 5-horsepower, 4ole, enclosed | E6: 0.895 | F6: 0.91 | G6: 0.91 | H6: 0.917 | I6: 0.924 | L6: 1 | M6: Design A/B, 5-horsepower, 4ole, enclosed | N6: 340.95 | O6: 424.52 | P6: 424.52 | Q6: 459.91 | R6: 614.47 | T6: =((O6-$N6)/($N6))/((F6-$E6)/($E6)) -> 14.624852 | U6: =((P6-$N6)/($N6))/((G6-$E6)/($E6)) -> 14.624852 | V6: =((Q6-$N6)/($N6))/((H6-$E6)/($E6)) -> 14.19419 | W6: =((R6-$N6)/($N6))/((I6-$E6)/($E6)) -> 24.758449 | X6: =AVERAGE(T6:W6) -> 17.050586
C7: 2 | D7: Design A/B, 30-horsepower, 4ole, enclosed | E7: 0.936 | F7: 0.945 | G7: 0.945 | H7: 0.95 | I7: 0.954 | L7: 2 | M7: Design A/B, 30-horsepower, 4ole, enclosed | N7: 1331.4 | O7: 1792.24 | P7: 1792.24 | Q7: 1928.42 | R7: 1999.62 | T7: =((O7-$N7)/($N7))/((F7-$E7)/($E7)) -> 35.997717 | U7: =((P7-$N7)/($N7))/((G7-$E7)/($E7)) -> 35.997717 | V7: =((Q7-$N7)/($N7))/((H7-$E7)/($E7)) -> 29.979759 | W7: =((R7-$N7)/($N7))/((I7-$E7)/($E7)) -> 26.098423 | X7: =AVERAGE(T7:W7) -> 32.018404
B8: 1 | C8: 3 | D8: Design A/B, 75-horsepower, 4ole, enclosed | E8: 0.954 | F8: 0.958 | G8: 0.962 | H8: 0.965 | I8: 0.968 | K8: 1 | L8: 3 | M8: Design A/B, 75-horsepower, 4ole, enclosed | N8: 3724.25 | O8: 4577.13 | P8: 4943.96 | Q8: 5219.07 | R8: 5541.73 | T8: =((O8-$N8)/($N8))/((F8-$E8)/($E8)) -> 54.618213 | U8: =((P8-$N8)/($N8))/((G8-$E8)/($E8)) -> 39.054955 | V8: =((Q8-$N8)/($N8))/((H8-$E8)/($E8)) -> 34.810139 | W8: =((R8-$N8)/($N8))/((I8-$E8)/($E8)) -> 33.254556 | X8: =AVERAGE(T8:W8) -> 40.434466
C9: 4 | D9: Design A/B, 150-hosepower, 4- | E9: 0.958 | F9: 0.962 | G9: 0.965 | H9: 0.968 | I9: 0.971 | L9: 4 | M9: Design A/B, 150-hosepower, 4- | N9: 6181.17 | O9: 6378.33 | P9: 8205.53 | Q9: 8662.15 | R9: 9197.66 | T9: =((O9-$N9)/($N9))/((F9-$E9)/($E9)) -> 7.6393013 | U9: =((P9-$N9)/($N9))/((G9-$E9)/($E9)) -> 44.821308 | V9: =((Q9-$N9)/($N9))/((H9-$E9)/($E9)) -> 38.451925 | W9: =((R9-$N9)/($N9))/((I9-$E9)/($E9)) -> 35.962788 | X9: =AVERAGE(T9:W9) -> 31.718831
C10: 5 | D10: Design A/B, 350-horsepower, 4ole, enclosed | E10: 0.962 | F10: 0.968 | G10: 0.968 | H10: 0.971 | I10: 0.974 | L10: 5 | M10: Design A/B, 350-horsepower, 4ole, enclosed | N10: 12885.6 | O10: 15313.54 | P10: 15313.54 | Q10: 18042.15 | R10: 19157.57 | T10: =((O10-$N10)/($N10))/((F10-$E10)/($E10)) -> 30.210445 | U10: =((P10-$N10)/($N10))/((G10-$E10)/($E10)) -> 30.210445 | V10: =((Q10-$N10)/($N10))/((H10-$E10)/($E10)) -> 42.774718 | W10: =((R10-$N10)/($N10))/((I10-$E10)/($E10)) -> 39.020529 | X10: =AVERAGE(T10:W10) -> 35.554034
B11: 2 | C11: 6 | D11: Design A/B, 600-hosepower, 4ole, enclosed | E11: 0.958 | F11: 0.962 | G11: 0.968 | H11: 0.968 | I11: 0.974 | K11: 2 | L11: 6 | M11: Design A/B, 600-hosepower, 4ole, enclosed | N11: 19711.6 | O11: 20532.73 | P11: 24422.41 | Q11: 24422.41 | R11: 30552.96 | T11: =((O11-$N11)/($N11))/((F11-$E11)/($E11)) -> 9.9768986 | U11: =((P11-$N11)/($N11))/((G11-$E11)/($E11)) -> 22.894925 | V11: =((Q11-$N11)/($N11))/((H11-$E11)/($E11)) -> 22.894925 | W11: =((R11-$N11)/($N11))/((I11-$E11)/($E11)) -> 32.931189 | X11: =AVERAGE(T11:W11) -> 22.174484
C12: 7 | D12: Air-over NEMA Design A/B, 5 horse ower, 4- ole, enclosed | E12: 0.875 | F12: 0.895 | G12: 0.91 | H12: 0.91 | I12: 0.924 | L12: 7 | M12: Air-over NEMA Design A/B, 5 horse ower, 4- ole, enclosed | N12: 304.59 | O12: 332.96 | P12: 414.57 | Q12: 414.57 | R12: 554.4 | T12: =((O12-$N12)/($N12))/((F12-$E12)/($E12)) -> 4.074945 | U12: =((P12-$N12)/($N12))/((G12-$E12)/($E12)) -> 9.0268886 | V12: =((Q12-$N12)/($N12))/((H12-$E12)/($E12)) -> 9.0268886 | W12: =((R12-$N12)/($N12))/((I12-$E12)/($E12)) -> 14.645566 | X12: =AVERAGE(T12:W12) -> 9.193572
C13: 8 | D13: Air-over NEMA Design A/B, 30- | E13: 0.924 | F13: 0.936 | G13: 0.945 | H13: 0.945 | I13: 0.954 | L13: 8 | M13: Air-over NEMA Design A/B, 30- | N13: 1281.82 | O13: 1326.36 | P13: 1785.38 | Q13: 1785.38 | R13: 1975.97 | T13: =((O13-$N13)/($N13))/((F13-$E13)/($E13)) -> 2.6755551 | U13: =((P13-$N13)/($N13))/((G13-$E13)/($E13)) -> 17.285297 | V13: =((Q13-$N13)/($N13))/((H13-$E13)/($E13)) -> 17.285297 | W13: =((R13-$N13)/($N13))/((I13-$E13)/($E13)) -> 16.679269 | X13: =AVERAGE(T13:W13) -> 13.481355
C14: 9 | D14: horse ower, 4- ole, enclosed | E14: 0.941 | F14: 0.954 | G14: 0.958 | H14: 0.962 | I14: 0.968 | L14: 9 | M14: horse ower, 4- ole, enclosed | N14: 3097.87 | O14: 3703.79 | P14: 4551.99 | Q14: 4910.11 | R14: 5510.57 | T14: =((O14-$N14)/($N14))/((F14-$E14)/($E14)) -> 14.157885 | U14: =((P14-$N14)/($N14))/((G14-$E14)/($E14)) -> 25.98231 | V14: =((Q14-$N14)/($N14))/((H14-$E14)/($E14)) -> 26.21337 | W14: =((R14-$N14)/($N14))/((I14-$E14)/($E14)) -> 27.143509 | X14: =AVERAGE(T14:W14) -> 23.374268
B15: 3 | C15: 10 | E15: 0.95 | F15: 0.958 | G15: 0.962 | H15: 0.965 | I15: 0.971 | K15: 3 | L15: 10 | N15: 5352.67 | O15: 6199.2 | P15: 6396.94 | Q15: 8229.41 | R15: 8687.42 | T15: =((O15-$N15)/($N15))/((F15-$E15)/($E15)) -> 18.780429 | U15: =((P15-$N15)/($N15))/((G15-$E15)/($E15)) -> 15.444885 | V15: =((Q15-$N15)/($N15))/((H15-$E15)/($E15)) -> 34.037879 | W15: =((R15-$N15)/($N15))/((I15-$E15)/($E15)) -> 28.183643 | X15: =AVERAGE(T15:W15) -> 24.111709
C16: 11 | D16: Air-over NEMA Design A/B 75- | E16: 0.855 | F16: 0.875 | G16: 0.895 | H16: 0.91 | I16: 0.91 | L16: 11 | M16: Air-over NEMA Design A/B 75- | N16: 304.59 | O16: 332.96 | P16: 414.57 | Q16: 554.4 | R16: 554.4 | T16: =((O16-$N16)/($N16))/((F16-$E16)/($E16)) -> 3.9818034 | U16: =((P16-$N16)/($N16))/((G16-$E16)/($E16)) -> 7.7179898 | V16: =((Q16-$N16)/($N16))/((H16-$E16)/($E16)) -> 12.749631 | W16: =((R16-$N16)/($N16))/((I16-$E16)/($E16)) -> 12.749631 | X16: =AVERAGE(T16:W16) -> 9.2997636
X17: =AVERAGE(X6:X16) -> 23.491952

Sheet comm boilers
B2: Table 5.6.1 En ineerin Analvsis Results for Commercial Packa ed Boilers
B3: Equipment Class | C3: Efficiency Level" | D3: Incremental MSP | E3: Baseline MSP
C4: 0.8 | D4: 0 | F4: =D4+$E$6 -> 6928 | L4: Small Gas Hot Water | M4: =AVERAGE(H5:H11) -> 7.5361437
C5: 0.81 | D5: 472 | F5: =D5+$E$6 -> 7400 | H5: =((F5-$F$4)/($F$4))/((C5-$C$4)/($C$4)) -> 5.4503464 | L5: Large Gas Hot Water | M5: =AVERAGE(H13:H17) -> 10.236696
B6: Small Gas Hot Water | C6: 0.82 | D6: 977 | E6: 6928 | F6: =D6+$E$6 -> 7905 | H6: =((F6-$F$4)/($F$4))/((C6-$C$4)/($C$4)) -> 5.6408776 | L6: Small Oil Hot Water | M6: =AVERAGE(H19:H24) -> 7.5709279
C7: 0.84 | D7: 2759 | F7: =D7+$E$6 -> 9687 | H7: =((F7-$F$4)/($F$4))/((C7-$C$4)/($C$4)) -> 7.9647806 | L7: Large Oil Hot Water | M7: =AVERAGE(H26:H29) -> 13.093143
C8: 0.85 | D8: 3561 | F8: =D8+$E$6 -> 10489 | H8: =((F8-$F$4)/($F$4))/((C8-$C$4)/($C$4)) -> 8.2240185 | L8: Small Gas Steam | M8: =AVERAGE(H31:H35) -> 6.8445087
C9: 0.93 | D9: 10027 | F9: =D9+$E$6 -> 16955 | H9: =((F9-$F$4)/($F$4))/((C9-$C$4)/($C$4)) -> 8.9065553 | L9: Large Gas Steam | M9: =AVERAGE(H37:H42) -> 4.7753003
C10: 0.95 | D10: 10494 | F10: =D10+$E$6 -> 17422 | H10: =((F10-$F$4)/($F$4))/((C10-$C$4)/($C$4)) -> 8.0785219 | L10: Small Oil Steam | M10: =AVERAGE(H44:H46) -> 10.329147
C11: 0.99 | D11: 13966 | F11: =D11+$E$6 -> 20894 | H11: =((F11-$F$4)/($F$4))/((C11-$C$4)/($C$4)) -> 8.4879057 | L11: Large Oil Steam | M11: =AVERAGE(H48:H50) -> 7.1185034
C12: 0.82 | D12: 0 | F12: =D12+$E$14 -> 21244
C13: 0.83 | D13: 2534 | F13: =D13+$E$14 -> 23778 | H13: =((F13-$F$12)/($F$12))/((C13-$C$12)/($C$12)) -> 9.7810205
B14: Large Gas Hot Water | C14: 0.84 | D14: 5370 | E14: 21244 | F14: =D14+$E$14 -> 26614 | H14: =((F14-$F$12)/($F$12))/((C14-$C$12)/($C$12)) -> 10.363867
C15: 0.85 | D15: 8544 | F15: =D15+$E$14 -> 29788 | H15: =((F15-$F$12)/($F$12))/((C15-$C$12)/($C$12)) -> 10.993033
C16: 0.94 | D16: 32796 | F16: =D16+$E$14 -> 54040 | H16: =((F16-$F$12)/($F$12))/((C16-$C$12)/($C$12)) -> 10.549143
C17: 0.97 | D17: 36904 | F17: =D17+$E$14 -> 58148 | H17: =((F17-$F$12)/($F$12))/((C17-$C$12)/($C$12)) -> 9.4964162
C18: 0.82 | D18: 0 | F18: =D18+$E$21 -> 8404
C19: 0.83 | D19: 634 | F19: =D19+$E$21 -> 9038 | H19: =((F19-$F$18)/($F$18))/((C19-$C$18)/($C$18)) -> 6.1861019
C20: 0.84 | D20: 1315 | F20: =D20+$E$21 -> 9719 | H20: =((F20-$F$18)/($F$18))/((C20-$C$18)/($C$18)) -> 6.4153974
B21: Small Oil Hot Water | C21: 0.85 | D21: 2048 | E21: 8404 | F21: =D21+$E$21 -> 10452 | H21: =((F21-$F$18)/($F$18))/((C21-$C$18)/($C$18)) -> 6.6609551
C22: 0.87 | D22: 3683 | F22: =D22+$E$21 -> 12087 | H22: =((F22-$F$18)/($F$18))/((C22-$C$18)/($C$18)) -> 7.1871966
C23: 0.88 | D23: 4594 | F23: =D23+$E$21 -> 12998 | H23: =((F23-$F$18)/($F$18))/((C23-$C$18)/($C$18)) -> 7.4708076
C24: 0.97 | D24: 17687 | F24: =D24+$E$21 -> 26091 | H24: =((F24-$F$18)/($F$18))/((C24-$C$18)/($C$18)) -> 11.505109
C25: 0.84 | D25: 0 | F25: =D25+$E$27 -> 18915
C26: 0.86 | D26: 4785 | F26: =D26+$E$27 -> 23700 | H26: =((F26-$F$25)/($F$25))/((C26-$C$25)/($C$25)) -> 10.624901
B27: Large Oil Hot Water | C27: 0.88 | D27: 10781 | E27: 18915 | F27: =D27+$E$27 -> 29696 | H27: =((F27-$F$25)/($F$25))/((C27-$C$25)/($C$25)) -> 11.969389
C28: 0.89 | D28: 14326 | F28: =D28+$E$27 -> 33241 | H28: =((F28-$F$25)/($F$25))/((C28-$C$25)/($C$25)) -> 12.724124
C29: 0.97 | D29: 49923 | F29: =D29+$E$27 -> 68838 | H29: =((F29-$F$25)/($F$25))/((C29-$C$25)/($C$25)) -> 17.054157
C30: 0.77 | D30: 0 | F30: =D30+$E$32 -> 6659
C31: 0.78 | D31: 540 | F31: =D31+$E$32 -> 7199 | H31: =((F31-$F$30)/($F$30))/((C31-$C$30)/($C$30)) -> 6.2441808
B32: Small Gas Steam | C32: 0.79 | D32: 1124 | E32: 6659 | F32: =D32+$E$32 -> 7783 | H32: =((F32-$F$30)/($F$30))/((C32-$C$30)/($C$30)) -> 6.4985734
C33: 0.8 | D33: 1756 | F33: =D33+$E$32 -> 8415 | H33: =((F33-$F$30)/($F$30))/((C33-$C$30)/($C$30)) -> 6.7683836
C34: 0.81 | D34: 2439 | F34: =D34+$E$32 -> 9098 | H34: =((F34-$F$30)/($F$30))/((C34-$C$30)/($C$30)) -> 7.0507208
C35: 0.83 | D35: 3975 | F35: =D35+$E$32 -> 10634 | H35: =((F35-$F$30)/($F$30))/((C35-$C$30)/($C$30)) -> 7.6606848
C36: 0.77 | D36: 0 | F36: =D36+$E$39 -> 19122
C37: 0.78 | D37: 1097 | F37: =D37+$E$39 -> 20219 | H37: =((F37-$F$36)/($F$36))/((C37-$C$36)/($C$36)) -> 4.4173727
C38: 0.79 | D38: 2256 | F38: =D38+$E$39 -> 21378 | H38: =((F38-$F$36)/($F$36))/((C38-$C$36)/($C$36)) -> 4.5422027
B39: Large Gas Steam | C39: 0.8 | D39: 3483 | E39: 19122 | F39: =D39+$E$39 -> 22605 | H39: =((F39-$F$36)/($F$36))/((C39-$C$36)/($C$36)) -> 4.6750863
C40: 0.81 | D40: 4779 | F40: =D40+$E$39 -> 23901 | H40: =((F40-$F$36)/($F$36))/((C40-$C$36)/($C$36)) -> 4.81099
C41: 0.82 | D41: 6150 | F41: =D41+$E$39 -> 25272 | H41: =((F41-$F$36)/($F$36))/((C41-$C$36)/($C$36)) -> 4.9529338
...

Sheet indst boilers
B2: Table 62 – Costs and prices of Base Case
B3: Base case | C3: Size (MWth) | D3: Steam production (kg/h) | E3: Boiler unit cost (eur) | F3: Main accessories cost (eur) | G3: Installation cost (eur) | H3: Overall cost of the product (eur) | I3: O&M (eur) | J3: O&m accessories (eur) | K3: Product sale price
B4: 1 | C4: 2,5 | D4: 3290 | E4: 59.1 | F4: 36.000,00 | G4: 20.000,00 | H4: 115.1 | I4: 2.300,00 | J4: 2.400,00 | K4: 138.1
B5: 2 | C5: 2,5 | D5: 3260 | E5: 59.1 | F5: 36.000,00 | G5: 20.000,00 | H5: 115.1 | I5: 2.300,00 | J5: 2.400,00 | K5: 138.1
B6: 3 | C6: 7 | D6: 9200 | E6: 97 | F6: 75.000,00 | G6: 100.000,00 | H6: 271.1 | I6: 4.000,00 | J6: 3.000,00 | K6: 326.38
B7: 4 | C7: 7 | D7: 9130 | E7: 97 | F7: 75.000,00 | G7: 100.000,00 | H7: 272 | I7: 4.000,00 | J7: 3.000,00 | K7: 326.38
B8: 5 | C8: 20 | D8: 26280 | E8: 135.6 | F8: 115.000,00 | G8: 136.000,00 | H8: 386.6 | I8: 6.000,00 | J8: 4.000,00 | K8: 463.955
B9: 6 | C9: 20 | D9: 26070 | E9: 135.6 | F9: 115.000,00 | G9: 136.000,00 | H9: 386.6 | I9: 6.000,00 | J9: 4.000,00 | K9: 463.955
B10: 7 | C10: 35 | D10: 46000 | E10: 156.2 | F10: 130.000,00 | G10: 150.000,00 | H10: 436.2 | I10: 7.000,00 | J10: 5.000,00 | K10: 523.48
B11: 8 | C11: 35 | D11: 45630 | E11: 156.2 | F11: 130.000,00 | G11: 150.000,00 | H11: 436.2 | I11: 7.000,00 | J11: 5.000,00 | K11: 523.48
B13: Table 79 - Efficiency increase and investment per case per design option (rounded figures)
F14: economizer | H14: air pre-heater | J14: combustion control
B15: Base case | C15: Size (MWth) | D15: Thermal efficiency (%) | E15: Operational pressure (bar) | F15: Efficiency increase (%) | G15: Investment (eur) | H15: Efficiency increase (%) | I15: Investment (eur) | J15: Efficiency increase (%) | K15: Investment (eur) | L15: New efficiency with all options (%) | M15: boiler base cost | N15: boiler cost with all options (eur)
B16: 1 | C16: 2,5 | D16: 87 | E16: 15 | F16: 5,5 | G16: 15 | H16: 1,0 | I16: 21 | J16: 1,75 | K16: 30 | L16: 95.25 | M16: 59.1 | N16: 125.1 | O16: =((N16-M16)/(M16))/((L16-D16)/(D16)) -> 11.77665
B17: 2 | C17: 2,5 | D17: 86 | E17: 25 | F17: 5,5 | G17: 14 | H17: 1,0 | I17: 30 | J17: 1,75 | K17: 30 | L17: 94.25 | M17: 59.1 | N17: 133.1 | O17: =((N17-M17)/(M17))/((L17-D17)/(D17)) -> 13.052351
B18: 3 | C18: 7 | D18: 87 | E18: 15 | F18: 5,5 | G18: 23 | H18: 1,0 | I18: 62 | J18: 1,75 | K18: 30 | L18: 95.25 | M18: 97 | N18: 212 | O18: =((N18-M18)/(M18))/((L18-D18)/(D18)) -> 12.502343
B19: 4 | C19: 7 | D19: 86 | E19: 25 | F19: 5,5 | G19: 21 | H19: 1,0 | I19: 59 | J19: 1,75 | K19: 30 | L19: 94.25 | M19: 97 | N19: 207 | O19: =((N19-M19)/(M19))/((L19-D19)/(D19)) -> 11.821306
B20: 5 | C20: 20 | D20: 87 | E20: 15 | F20: 5,5 | G20: 48 | H20: 1,0 | I20: 128 | J20: 1,75 | K20: 30 | L20: 95.25 | M20: 135.6 | N20: 341.6 | O20: =((N20-M20)/(M20))/((L20-D20)/(D20)) -> 16.020381
B21: 6 | C21: 20 | D21: 86 | E21: 25 | F21: 5,5 | G21: 42 | H21: 1,0 | I21: 169 | J21: 1,75 | K21: 30 | L21: 94.25 | M21: 135.6 | N21: 376.6 | O21: =((N21-M21)/(M21))/((L21-D21)/(D21)) -> 18.526862
B22: 7 | C22: 35 | D22: 87 | E22: 15 | F22: 5,5 | G22: 75 | H22: 1,0 | I22: 124 | J22: 1,75 | K22: 30 | L22: 95.25 | M22: 156.2 | N22: 385.2 | O22: =((N22-M22)/(M22))/((L22-D22)/(D22)) -> 15.460365
B23: 8 | C23: 35 | D23: 86 | E23: 25 | F23: 5,5 | G23: 66 | H23: 1,0 | I23: 106 | J23: 1,75 | K23: 30 | L23: 94.25 | M23: 156.2 | N23: 358.2 | O23: =((N23-M23)/(M23))/((L23-D23)/(D23)) -> 13.480774
B24: 9 | C24: 35 | D24: 85 | E24: 15 | F24: 5,5 | G24: 80 | H24: 1,0 | I24: 201 | J24: 1,75 | K24: 30 | L24: 93.25 | M24: 156.2 | N24: 467.2 | O24: =((N24-M24)/(M24))/((L24-D24)/(D24)) -> 20.513716
B25: 10 | C25: 35 | D25: 84 | E25: 25 | F25: 5,5 | G25: 65 | H25: 1,0 | I25: 255 | J25: 1,75 | K25: 30 | L25: 92.25 | M25: 156.2 | N25: 506.2 | O25: =((N25-M25)/(M25))/((L25-D25)/(D25)) -> 22.814573
O26: =AVERAGE(O16:O25) -> 15.596932

Sheet indst heat pumps
A1: Source #1 | B1: (not used)
A2: https://heatpumpingtechnologies.org/content/uploads/sites/70/2023/09/annex-58-task-1-technologies-task-report.pdf
F4: Tlift | G4: Tlift | H4: Tlift | I4: Tlift | J4: Tlift | K4: Tlift | L4: Tlift | M4: Tlift | N4: Tlift | O4: Tlift | P4: Tlift | Q4: Tlift | R4: Tlift | S4: Tlift | T4: Tlift | U4: Tlift | V4: Tlift | W4: Tlift | X4: Tlift | Y4: Tlift | Z4: Tlift | AA4: Tlift | AB4: Tlift | AC4: Tlift | AD4: Tlift
C5: MW | D5: Tmax | E5: eur/kw | F5: =183-34 -> 149 | G5: =120-60 -> 60 | H5: =90-30 -> 60 | I5: =140-85 -> 55 | J5: =165-115 -> 50 | K5: 100 | L5: 109 | M5: 115 | N5: 135 | O5: =160-113 -> 47 | P5: =160-50 -> 110 | Q5: =212-65 -> 147 | R5: =160-12 -> 148 | S5: =212-12 -> 200 | T5: =201-105 -> 96 | U5: =211-105 -> 106 | V5: =95--1 -> 96 | W5: =110-7 -> 103 | X5: =150-17 -> 133 | Y5: =131-60 -> 71 | Z5: =150-105 -> 45 | AA5: =120-30 -> 90 | AB5: =105-0.5 -> 104.5 | AC5: =190-60 -> 130 | AD5: =185-120 -> 65
A6: Skala Fabrikk | B6: SkaleUp | C6: 0.3 | D6: 115 | E6: 600 | K6: 1.95 | L6: 2.3 | M6: 2.5 | N6: 2.8
A7: ecop | C7: 0.7 | D7: 150 | E7: 700
A8: Mayekawa | B8: HS comp | C8: 0.75 | D8: 120 | E8: 450
A9: Mayekawa | B9: SFC comp | C9: 1 | D9: 145 | E9: 720
A10: GEA Refrigeration Netherlands | C10: .1-1.2 | D10: 130 | E10: 250
A11: Fenagy | C11: 0.3-1.8 | D11: 120 | E11: =AVERAGE(250,425) -> 337.5 | X11: ~50-70K lift | AA11: ~100K lift
A12: Rank | C12: 0.12-2 | D12: 160 | E12: 300 | X12: =E25 -> 850 | Y12: =Y25 -> 4.4 | AA12: =E19 -> 700 | AB12: =P19 -> 2.325
A13: COMBITHERM GmbH | C13: 0.3-3.3 | D13: 120 | E13: 300 | X13: =E19 -> 700 | Y13: =O19 -> 3.5 | AA13: =E6 -> 600 | AB13: =K6 -> 1.95
A14: Sustainable Process Heat | C14: .3-5 | D14: 165 | E14: =AVERAGE(150,1000) -> 575 | X14: =E26 -> 525 | Y14: =Z26 -> 4.1 | AA14: =E26 -> 525 | AB14: =AVERAGE(AA26:AB26) -> 2.6
A15: Hybrid Energy | C15: 0.5-5 | D15: 188 | E15: =AVERAGE(250,430) -> 340 | X15: =E18 -> 300 | Y15: =G18 -> 3.4 | AA15: =E24 -> 400 | AB15: =AVERAGE(V24:W24) -> 3.15
A16: Weel & Sandvig | C16: 2.0-5 | D16: 160 | E16: =AVERAGE(150,250) -> 200 | AA16: =E21 -> 250 | AB16: =AVERAGE(T21:U21) -> 4.75
A17: Olvondo | C17: 5 | D17: 200 | E17: 1200 | F17: 1.7
A18: Heaten | B18: HeatBooster | C18: 1-6. | D18: 200 | E18: 300 | G18: 3.4 | H18: 3.3 | I18: 3.9 | J18: 4.6
A19: enerin | C19: 0.3-10 | D19: 250 | E19: 700 | O19: 3.5 | P19: 2.325 | Q19: =AVERAGE(2,2.15) -> 2.075 | R19: =AVERAGE(1.75,1.9) -> 1.825 | S19: 1.65
A20: Enertime | C20: 2-10. | D20: 160 | E20: 350
A21: Spilling | C21: 1-15. | D21: 280 | E21: 250 | T21: 4.2 | U21: 5.3
A22: Epcon | C22: .5-30 | D22: 150 | E22: 300
A23: Turboden | C23: 3-30. | D23: 200 | E23: 300-700
A24: MAN Energy Solutions | C24: 10.-50 | D24: 150 | E24: 400 | V24: 3.25 | W24: 3.05 | X24: 2.85
A25: Piller | C25: 1-70. | D25: 212 | E25: 850 | K25: *we find no correlation between higher upfront costs and higher COPs | Y25: 4.4
A26: Siemens Energy | C26: 8-80. | D26: 160 | E26: =AVERAGE(250,800) -> 525 | K26: we hypothesize other factors (capacity, compressor type, refrigerant) contribute | Z26: 4.1 | AA26: 2.7 | AB26: 2.5 | AC26: 2.9
A27: Qpinch | C27: >2 | D27: 230 | E27: 1500 | K27: more to capital investment given the industrial heat pump market is nascent | AD27: =0.45 -> 0.45
A30: Source #2
A31: https://doi.org/10.1016/j.enconman.2020.113488
B34: Configuration effect on COP
B35: For 80/120 T_source/sink
C36: SEC | D36: COP | E36: COP improvement by switching to 2-stage compression cycle
B37: single, no IHX | C37: 144.2 | D37: 2.8444 | E37: =((C39-C37)/(C39+C37))/((D39-D37)/(D39+D37)) -> 0.31975937
B38: single, IHX | C38: 136.5 | D38: 3.4495 | E38: =((C39-C38)/(C39+C38))/((D39-D38)/(D39+D38)) -> 1.2461224
B39: two-stage | C39: 159.5 | D39: 3.9083 | F39: =AVERAGE(E37:E38) -> 0.78294088
B41: Pinch Point effect on COP (sc w/o IHX) | F41: w/ IHX | J41: 2-stage
C42: evap | G42: evap | K42: evap
B43: condensor | C43: 3K | D43: 5K | F43: condensor | G43: 3K | H43: 5K | J43: condensor | K43: 3K | L43: 5K
B44: 3K | C44: 3.587 | D44: 3.085 | F44: 3K | G44: 3.982 | H44: 3.602 | J44: 3K | K44: 4.347 | L44: 4.058
B45: 5K | C45: 3.404 | D45: 2.888 | F45: 5K | G45: 3.815 | H45: 3.465 | J45: 5K | K45: 4.179 | L45: 3.905
B47: Pinch Point effect on SEC (sc w/o IHX) | F47: w/ IHX | J47: 2-stage
...

Sheet fans-blowers
B2: Table 5.6.10 Summary of Efficiency Levels for all ACF Representative Units (CFM/W)
D3: Representative Units
B4: EL | C4: Design Option | D4: 24-in. Axial ACF | E4: 36-in. Axial ACF | F4: 52-in. Axial ACF | G4: 11-in. Housed Centrifugal ACF
B5: EL0 | C5: Baseline | D5: 2.98 | E5: 5.21 | F5: 8.39 | G5: 1.33
B6: EL1 | C6: Direct-drive | D6: 2.98 | E6: 5.91 | F6: 9.26 | G6: 1.33
B7: EL2 | C7: High-efficiency PSC motor | D7: 3.18 | E7: 6.48 | F7: 10.6 | G7: 1.44
B8: EL3 | C8: Aerodynamic redesign 1 | D8: 6.14 | E8: 10.1 | F8: 14.2 | G8: 2.17
B9: EL4 | C9: Aerodynamic redesign 2 | D9: 12.2 | E9: 17.3 | F9: 21.5 | G9: 3.65
B10: EL5 | C10: Aerodynamic redesign 3 | D10: 20 | E10: 25.2 | F10: 27.2 | G10: 5.87
B11: EL6 | C11: ECM | D11: 24.3 | E11: 29.8 | F11: 30.8 | G11: 7.02
B15: Table 5.7.7 MPCs for each Efficiency Level and Representative Unit for ACFs
B17: Representative Unit | C17: Design Option | D17: 24-in. axial ACF | E17: 36-in. axial ACF | F17: 52-in. axial ACF | G17: 11-in. housed centrifugal ACF
B18: EL0 MPC | C18: Baseline | D18: 111.11 | E18: 274.95 | F18: 429.63 | G18: 62.88
B19: EL1 MPC | C19: Direct-drive | D19: 111.11 | E19: 212.86 | F19: 366.35 | G19: 62.88
B20: EL2 MPC | C20: High-efficiency PSC motor | D20: 129.29 | E20: 231.12 | F20: 393.16 | G20: 90.44
B21: EL3 MPC | C21: Aerodynamic redesign 1 | D21: 129.29 | E21: 231.12 | F21: 393.16 | G21: 90.44
B22: EL4 MPC | C22: Aerodynamic redesign 2 | D22: 129.29 | E22: 231.12 | F22: 393.16 | G22: 90.44
B23: EL5 MPC | C23: Aerodynamic redesign 3 | D23: 129.29 | E23: 231.12 | F23: 393.16 | G23: 90.44
B24: EL6 MPC | C24: ECM | D24: 159.99 | E24: 264.57 | F24: 433.88 | G24: 116.11
B26: Elasticities
B27: Representative Unit | C27: Design Option | D27: 24-in. axial ACF | E27: 36-in. axial ACF | F27: 52-in. axial ACF | G27: 11-in. housed centrifugal ACF
B28: EL0 MPC | C28: Baseline
B29: EL1 MPC | C29: Direct-drive | D29: =((D19-D$18)/(D19+D$18))/((D6-D$5)/(D6+D$5)) -> #DIV/0! | E29: =((E19-E$18)/(E$18))/((E6-E$5)/(E$5)) -> -1.6807674 | F29: =((F19-F$18)/(F$18))/((F6-F$5)/(F$5)) -> -1.4204128 | G29: =((G19-G$18)/(G19+G$18))/((G6-G$5)/(G6+G$5)) -> #DIV/0!
B30: EL2 MPC | C30: High-efficiency PSC motor | D30: =((D20-D$18)/(D$18))/((D7-D$5)/(D$5)) -> 2.4379624 | E30: =((E20-E$18)/(E$18))/((E7-E$5)/(E$5)) -> -0.65396085 | F30: =((F20-F$18)/(F$18))/((F7-F$5)/(F$5)) -> -0.3222633 | G30: =((G20-G$18)/(G$18))/((G7-G$5)/(G$5)) -> 5.299387
B31: EL3 MPC | C31: Aerodynamic redesign 1 | D31: =((D21-D$18)/(D$18))/((D8-D$5)/(D$5)) -> 0.15430142 | E31: =((E21-E$18)/(E$18))/((E8-E$5)/(E$5)) -> -0.16984259 | F31: =((F21-F$18)/(F$18))/((F8-F$5)/(F$5)) -> -0.12258208 | G31: =((G21-G$18)/(G$18))/((G8-G$5)/(G$5)) -> 0.69396735
B32: EL4 MPC | C32: Aerodynamic redesign 2 | D32: =((D22-D$18)/(D$18))/((D9-D$5)/(D$5)) -> 0.052884216 | E32: =((E22-E$18)/(E$18))/((E9-E$5)/(E$5)) -> -0.068695639 | F32: =((F22-F$18)/(F$18))/((F9-F$5)/(F$5)) -> -0.054325087 | G32: =((G22-G$18)/(G$18))/((G9-G$5)/(G$5)) -> 0.25126404
B33: EL5 MPC | C33: Aerodynamic redesign 3 | D33: =((D23-D$18)/(D$18))/((D10-D$5)/(D$5)) -> 0.028648207 | E33: =((E23-E$18)/(E$18))/((E10-E$5)/(E$5)) -> -0.041547288 | F33: =((F23-F$18)/(F$18))/((F10-F$5)/(F$5)) -> -0.03786294 | G33: =((G23-G$18)/(G$18))/((G10-G$5)/(G$5)) -> 0.12839924
B34: EL6 MPC | C34: ECM | D34: =((D24-D$18)/(D$18))/((D11-D$5)/(D$5)) -> 0.061490371 | E34: =((E24-E$18)/(E$18))/((E11-E$5)/(E$5)) -> -0.0079987629 | F34: =((F24-F$18)/(F$18))/((F11-F$5)/(F$5)) -> 0.0037035178 | G34: =((G24-G$18)/(G$18))/((G11-G$5)/(G$5)) -> 0.19787153
D36: =AVERAGE(D30:D34,G30:G34) -> 0.93061757

Sheet solid fuel boilers
B2: https://ec.europa.eu/smart-regulation/impact/ia_carried_out/docs/ia_2015/swd_2015_0092_en.pdf
A3: https://ec.europa.eu/smart-regulation/impact/ia_carried_out/docs/ia_2015/swd_2015_0092_en.pdf
B4: Table 18: Overview of the Base Cases
C5: heat output (kW) | D5: efficiency | E5: fuel | F5: price | G5: installation | H5: total
B6: small domestic man. Boiler | C6: 18 | D6: 0.66 | E6: wood | F6: 3000 | G6: 1500 | H6: =SUM(F6:G6) -> 4500
B7: small domestic: DD gasifying boiler | C7: 20 | D7: 0.88 | E7: wood | F7: 5000 | G7: 1500 | H7: =SUM(F7:G7) -> 6500
B8: retort boiler | C8: 25 | D8: 0.82 | E8: coal | F8: 4000 | G8: 1500 | H8: =SUM(F8:G8) -> 5500
B9: pellet boiler | C9: 25 | D9: 0.88 | E9: pellet | F9: 6000 | G9: 2000 | H9: =SUM(F9:G9) -> 8000
B10: non-domestic chip boiler | C10: 160 | D10: 0.88 | E10: chips | F10: 30000 | G10: 3500 | H10: =SUM(F10:G10) -> 33500
B12: Table 19: Overview of the Best Available Technologies
C13: heat output (kW) | D13: efficiency | E13: fuel | F13: price | G13: installation | H13: total | J13: elasticity
B14: small domestic man. Boiler | C14: 18 | D14: 0.91 | E14: wood | F14: 6305 | G14: 1500 | H14: =SUM(F14:G14) -> 7805 | J14: =((H14-$H6)/$H6)/((D14-$D6)/$D6) -> 1.9389333
B15: small domestic: DD gasifying boiler | C15: 20 | D15: 0.91 | E15: wood | F15: 6305 | G15: 1500 | H15: =SUM(F15:G15) -> 7805 | J15: =((H15-$H7)/$H7)/((D15-$D7)/$D7) -> 5.8892308
B16: retort boiler | C16: 25 | D16: 0.88 | E16: coal | F16: 4000 | G16: 1500 | H16: =SUM(F16:G16) -> 5500 | J16: =((H16-$H8)/$H8)/((D16-$D8)/$D8) -> 0
B17: pellet boiler | C17: 25 | D17: 0.93 | E17: pellet | F17: 6990 | G17: 2000 | H17: =SUM(F17:G17) -> 8990 | J17: =((H17-$H9)/$H9)/((D17-$D9)/$D9) -> 2.178
B18: non-domestic chip boiler | C18: 160 | D18: 0.92 | E18: chips | F18: 35000 | G18: 3500 | H18: =SUM(F18:G18) -> 38500 | J18: =((H18-$H10)/$H10)/((D18-$D10)/$D10) -> 3.2835821
J19: =AVERAGE(J14:J18) -> 2.6579492

Sheet Lighting
A1: https://www.bulkofficesupply.com/Categories/Janitorial-and-Facility-Supplies/Lighting/Light-Bulbs.aspx?srsltid=AfmBOorWkgJMp4H4zdZKPjbhWJ39KPaQWfcg1JIX1YpF1EunQjEtuY1Z | P1: lightstoreusa.com
C3: incand | D3: LED | E3: LED | F3: LED | G3: LED | H3: LED | I3: LED | J3: LED | K3: fluorescent | L3: fluorescent | M3: fluorescent | N3: CFL | O3: CFL | P3: HID | Q3: HID | R3: HID | S3: HID | T3: HID
C4: bulb | D4: parabolic | E4: reflector | F4: parabolic | G4: parabolic | H4: bulb | I4: tube | J4: tube | K4: twin tube | L4: tube | M4: tube | N4: bulb | O4: bulb | P4: bulb | Q4: bulb | R4: bulb | S4: floodlight | T4: floodlight
C5: Satco A15 Appliance Light Bulb | D5: Satco 6.5W PAR 20/FL 3000K LED Bulb | E5: Satco 7.5W BR30 3000K LED Bulb | F5: Satco 12W PAR 30/LN/FL 3000K LED Bulb | G5: Satco 15W PAR38 3000K LED Bulb | H5: Satco 10W A19 LED 5000K Light Bulbs | I5: Satco 40W T8 4000K LED Tube Light | J5: Satco 11 Watt LED T8 Bulb | K5: Satco 13W GX23 Pin-Based 2700K Compact Fluorescent Bulb | L5: Satco 54W T5 3500K Fluorescent Tube | M5: Satco Flourescent Light Bulbs 32W 6/box | N5: Satco 23W T2 2700K Spiral CFL Bulb | O5: Satco 23W T2 2700K Spiral CFL Bulb | P5: Plusrite 1035 | Q5: M47 BT37 Mogul | R5: Plusrite 1056 | S5: Plusrite 1061 | T5: PLUSRITE Par 38
B6: $ | C6: 1.3 | D6: 5.15 | E6: 7.48 | F6: 8.3 | G6: 11.84 | H6: =12.98/4 -> 3.245 | I6: =124.94/10 -> 12.494 | J6: =172.75/25 -> 6.91 | K6: =5.21 -> 5.21 | L6: =206.09/40 -> 5.15225 | M6: =28.85/6 -> 4.8083333 | N6: =16.57/3 -> 5.5233333 | O6: =198.86/12/3 -> 5.5238889 | P6: 15.99 | Q6: 27.95 | R6: 39.95 | S6: 17 | T6: 12 | W6: $
B7: W | C7: 40 | D7: 6.5 | E7: 7.5 | F7: 12 | G7: 15 | H7: 10 | I7: 40 | J7: 11 | K7: 13 | L7: 54 | M7: 32 | N7: 23 | O7: 23 | P7: 100 | Q7: 1000 | R7: 1000 | S7: 70 | T7: 100
B8: lm | C8: 225 | D8: 520 | E8: 650 | F8: 1000 | G8: 1200 | H8: 800 | I8: 5500 | J8: 1800 | K8: 800 | L8: 5000 | M8: 3050 | N8: 1600 | O8: 1600 | P8: 8500 | Q8: 110000
B9: hr life | C9: 2500 | D9: 25000 | E9: 25000 | F9: 25000 | G9: 25000 | H9: 15000 | I9: 50000 | J9: 50000 | K9: 12000 | L9: 24000 | M9: 24000 | N9: 12000 | O9: 12000 | P9: 15000 | Q9: 10000 | R9: 5000 | S9: 6000
B10: W equiv. incandesc. | D10: 50 | E10: 65 | F10: 75 | G10: 90 | H10: 60 | I10: 59 | J10: ? | N10: 100 | O10: 100
C11: =C6/C7 -> 0.0325 | D11: =D6/D7 -> 0.79230769 | E11: =E6/E7 -> 0.99733333 | F11: =F6/F7 -> 0.69166667 | G11: =G6/G7 -> 0.78933333 | H11: =H6/H7 -> 0.3245 | I11: =I6/I7 -> 0.31235 | J11: =J6/J7 -> 0.62818182 | ... T11: =T6/T7 -> 0.12
H13: https://www.mordorintelligence.com/industry-reports/industrial-lighting-market
C14: $ | D14: BTU/yr | E14: lifetime | F14: W | H14: Industrial lighting market
B15: incand | C15: =AVERAGEIFS($C$6:$T$6,$C$3:$T$3,$B15) -> 1.3 | D15: =AVERAGEIFS($C$7:$T$7,$C$3:$T$3,$B15)*$O$19/1000*$O$21 -> 377565.42 | E15: =AVERAGEIFS($C$9:$T$9,$C$3:$T$3,$B15) -> 2500 | F15: =AVERAGEIFS($C$7:$T$7,$C$3:$T$3,$B15) -> 40 | H15: LED | I15: 0.652 | J15: =I15*E16 -> 20025.714 | K15: =I15*D16 -> 89677.181 | L15: =C16*I15 -> 5.161884 | M15: =I15*F16 -> 9.5005714
