Workbook

Sheet About
A1: COSP Cost of Service vs Procurement Shares (2024)
A3: Sources: | B3: Retail electricity sales by serving entity (utility / marketer / CCA)
B4: U.S. Energy Information Administration (EIA)
B5: Form EIA-861 detailed data, Sales_Ult_Cust_2024.xlsx (sheet 'States')
B6: 2024
B7: https://www.eia.gov/electricity/data/eia861/
B8: Authoritative source from which EIA's published Table 10 (utility bundled sales) and Table 16 (power marketers) are built. 'Service Type' = Bundled / Energy / Delivery; 'Ownership' = Investor Owned, Municipal, Cooperative, Federal, State, Political Subdivision, Retail Power Marketer, Community Choice Aggregator, Behind the Meter. TOTAL sales (MWh) is column W.
B10: Validation benchmark — published state retail sales (all sectors)
B11: U.S. Energy Information Administration (EIA)
B12: EIA API v2, electricity/retail-sales
B13: 2024
B14: https://www.eia.gov/opendata/
B15: Used by validate_against_eia.py. The detailed file (Bundled+Energy incl. EIA Adjustment rows) ties to these published state totals to within 0.00%.
A18: Notes:
A19: Question | B19: Share of each state's retail electricity sales served by cost-of-service providers (embedded-cost recovery) vs. procurement-based providers, attributed by the entity that sells to the retail customer (LSE-based).
A20: Double-count fix | B20: Retail total = rows with Service Type Bundled or Energy. 'Delivery' rows are the wires-only half of choice-state load already counted under 'Energy'; they are classified 'excluded' so they never enter the totals (including Delivery would overstate sales ~14% nationally).
A21: Cost-of-service | B21: Bundled sales of municipals, cooperatives, federal, state, and political-subdivision utilities, plus Investor Owned utilities in states NOT on the restructured list (and the TX override utilities below).
A22: Procurement | B22: Retail Power Marketers + Community Choice Aggregators (and any 'Energy' service-type sales), plus Investor Owned utilities in restructured states.
A23: Restructured states | B23: Editable on the Parameters tab (column A). Baseline: CT, DC, DE, IL, MA, MD, ME, NH, NJ, NY, OH, PA, RI, TX.
A24: Texas override | B24: Non-ERCOT, vertically integrated, regulated TX IOUs are held as cost-of-service despite TX being restructured. Keyed on EIA Utility Number (Parameters column B): 55937 Entergy Texas, 17718 Southwestern Public Service, 17698 Southwestern Electric Power, 5701 El Paso Electric. ERCOT wires-only IOUs carry zero bundled sales, so they need no override.
A25: Exclusions | B25: EIA 'Adjustment' reconciliation rows (utility name contains 'Adjustment') and 'Behind the Meter' ownership are classified 'excluded' (~3.5% of US load). They are visible in the source tab but kept out of the share basis.
A26: How it computes | B26: Source tab column 'bucket' classifies each row via formula reading the Parameters tab (COUNTIF on the restructured-state and override-utility ranges). 'State Shares' and 'US National' use SUMIFS over that bucket column. Edit a Parameters cell -> all outputs recompute.
A27: Method precedent | B27: EPA's Retail Price Model (ICF) uses the same approach: blend a competitive price and a cost-of-service price by each region's deregulation vs. cost-of-service share. See EXTERNAL_VALIDATION.md.
A28: EPS usage (SoEDtICoS) | B28: In the EPS, total electricity rates = cost-of-service costs x (share that is cost of service) + capacity-market costs x (1 - that share). The 'SoEDtICoS' tab supplies that share to eps-us, held flat at the latest data-year value across 2021-2050.
A29: This rebuild | B29: This SoEDtICoS file was rebuilt from EIA-861, replacing the prior version (EPA Retail Price Model regional shares x AEO net-load weighting) with the EIA-861 LSE-based national cost-of-service share.
A30: Caveat | B30: Output is an input for analysis; verify against EIA primary sources. The restructured-state list and TX overrides are adjustable assumptions.

Sheet Parameters
A1: Parameters (editable — outputs recompute)
A3: Fully Restructured States | B3: Override Utility # | C3: Override Utility Name (reference)
A4: CT | B4: 55937 | C4: Entergy Texas Inc.
A5: DC | B5: 17718 | C5: Southwestern Public Service Co
A6: DE | B6: 17698 | C6: Southwestern Electric Power Co
A7: IL | B7: 5701 | C7: El Paso Electric Co
A8: MA
A9: MD
A10: ME
A11: NH
A12: NJ
A13: NY
A14: OH
A15: PA
A16: RI
A17: TX
A20: Ownership classes (fixed EIA taxonomy, hardcoded in the bucket formula):
A21: Procurement: Retail Power Marketer, Community Choice Aggregator. Cost-of-service (non-IOU): Municipal, Cooperative, Federal, State, Political Subdivision. Excluded: Behind the Meter, Adjustment rows.

Sheet EIA-861 Sales 2024
A1: Utility Characteristics | J1: RESIDENTIAL | M1: COMMERCIAL | P1: INDUSTRIAL | S1: TRANSPORTATION | V1: TOTAL
J2: Revenues | K2: Sales | L2: Customers | M2: Revenues | N2: Sales | O2: Customers | P2: Revenues | Q2: Sales | R2: Customers | S2: Revenues | T2: Sales | U2: Customers | V2: Revenues | W2: Sales | X2: Customers
A3: Data Year | B3: Utility Number | C3: Utility Name | D3: Part | E3: Service Type | F3: Data Type O = Observed I = Imputed | G3: State | H3: Ownership | I3: BA Code | J3: Thousand Dollars | K3: Megawatthours | L3: Count | M3: Thousand Dollars | N3: Megawatthours | O3: Count | P3: Thousand Dollars | Q3: Megawatthours | R3: Count | S3: Thousand Dollars | T3: Megawatthours | U3: Count | V3: Thousand Dollars | W3: Megawatthours | X3: Count | Y3: sales_mwh (derived) | Z3: bucket (derived)
A4: 2024 | B4: 55 | C4: City of Aberdeen - (MS) | D4: A | E4: Bundled | F4: O | G4: MS | H4: Municipal | I4: TVA | J4: 4211 | K4: 34239 | L4: 2592 | M4: 3550 | N4: 29391 | O4: 736 | P4: 7185 | Q4: 127260 | R4: 2 | S4: 0 | T4: 0 | U4: 0 | V4: 14946 | W4: 190890 | X4: 3330 | Y4: =IF(ISNUMBER($W4),$W4,0) -> 190890 | Z4: =IF(ISNUMBER(SEARCH("Adjustment",$C4)),"excluded",IF($H4="Behind the Meter","excluded",IF(NOT(OR($E4="Bundled",$E4="Energy")),"excluded",IF(OR($H4="Retail Power Marketer",$H4="Community Choice Aggregator",$E4="Energy"),"procurement",IF(OR($H4="Municipal",$H4="Cooperative",$H4="Federal",$H4="State",$H4="Political Subdivision"),"cost_service",IF($H4="Investor Owned",IF(AND(COUNTIF(Parameters!$A$4:$A$33,$G4)>0,COUNTIF(Parameters!$B$4:$B$33,$B4)=0),"procurement","cost_service"),"unclassified")))))) -> cost_service
A5: 2024 | B5: 84 | C5: A & N Electric Coop | D5: A | E5: Bundled | F5: O | G5: MD | H5: Cooperative | I5: PJM | J5: 304.8 | K5: 2226 | L5: 253 | M5: 76.8 | N5: 567 | O5: 42 | P5: 0 | Q5: 0 | R5: 0 | S5: 0 | T5: 0 | U5: 0 | V5: 381.6 | W5: 2793 | X5: 295 | Y5: =IF(ISNUMBER($W5),$W5,0) -> 2793 | Z5: =IF(ISNUMBER(SEARCH("Adjustment",$C5)),"excluded",IF($H5="Behind the Meter","excluded",IF(NOT(OR($E5="Bundled",$E5="Energy")),"excluded",IF(OR($H5="Retail Power Marketer",$H5="Community Choice Aggregator",$E5="Energy"),"procurement",IF(OR($H5="Municipal",$H5="Cooperative",$H5="Federal",$H5="State",$H5="Political Subdivision"),"cost_service",IF($H5="Investor Owned",IF(AND(COUNTIF(Parameters!$A$4:$A$33,$G5)>0,COUNTIF(Parameters!$B$4:$B$33,$B5)=0),"procurement","cost_service"),"unclassified")))))) -> cost_service
A6: 2024 | B6: 84 | C6: A & N Electric Coop | D6: A | E6: Bundled | F6: O | G6: VA | H6: Cooperative | I6: PJM | J6: 47920.5 | K6: 368014 | L6: 33096 | M6: 20100.4 | N6: 172568 | O6: 4238 | P6: 16022 | Q6: 165066 | R6: 7 | S6: 0 | T6: 0 | U6: 0 | V6: 84042.9 | W6: 705648 | X6: 37341 | Y6: =IF(ISNUMBER($W6),$W6,0) -> 705648 | Z6: =IF(ISNUMBER(SEARCH("Adjustment",$C6)),"excluded",IF($H6="Behind the Meter","excluded",IF(NOT(OR($E6="Bundled",$E6="Energy")),"excluded",IF(OR($H6="Retail Power Marketer",$H6="Community Choice Aggregator",$E6="Energy"),"procurement",IF(OR($H6="Municipal",$H6="Cooperative",$H6="Federal",$H6="State",$H6="Political Subdivision"),"cost_service",IF($H6="Investor Owned",IF(AND(COUNTIF(Parameters!$A$4:$A$33,$G6)>0,COUNTIF(Parameters!$B$4:$B$33,$B6)=0),"procurement","cost_service"),"unclassified")))))) -> cost_service
A7: 2024 | B7: 108 | C7: Adams-Columbia Electric Coop | D7: A | E7: Bundled | F7: O | G7: WI | H7: Cooperative | I7: MISO | J7: 46745 | K7: 265097 | L7: 35910 | M7: 11973 | N7: 92563 | O7: 2518 | P7: 22091 | Q7: 241188 | R7: 1027 | S7: . | T7: . | U7: . | V7: 80809 | W7: 598848 | X7: 39455 | Y7: =IF(ISNUMBER($W7),$W7,0) -> 598848 | Z7: =IF(ISNUMBER(SEARCH("Adjustment",$C7)),"excluded",IF($H7="Behind the Meter","excluded",IF(NOT(OR($E7="Bundled",$E7="Energy")),"excluded",IF(OR($H7="Retail Power Marketer",$H7="Community Choice Aggregator",$E7="Energy"),"procurement",IF(OR($H7="Municipal",$H7="Cooperative",$H7="Federal",$H7="State",$H7="Political Subdivision"),"cost_service",IF($H7="Investor Owned",IF(AND(COUNTIF(Parameters!$A$4:$A$33,$G7)>0,COUNTIF(Parameters!$B$4:$B$33,$B7)=0),"procurement","cost_service"),"unclassified")))))) -> cost_service
A8: 2024 | B8: 113 | C8: Agway Energy Services, LLC | D8: B | E8: Energy | F8: O | G8: MD | H8: Retail Power Marketer | I8: PJM | J8: 2.5 | K8: 22 | L8: 2 | M8: 0 | N8: 0 | O8: 0 | P8: 0 | Q8: 0 | R8: 0 | S8: 0 | T8: 0 | U8: 0 | V8: 2.5 | W8: 22 | X8: 2 | Y8: =IF(ISNUMBER($W8),$W8,0) -> 22 | Z8: =IF(ISNUMBER(SEARCH("Adjustment",$C8)),"excluded",IF($H8="Behind the Meter","excluded",IF(NOT(OR($E8="Bundled",$E8="Energy")),"excluded",IF(OR($H8="Retail Power Marketer",$H8="Community Choice Aggregator",$E8="Energy"),"procurement",IF(OR($H8="Municipal",$H8="Cooperative",$H8="Federal",$H8="State",$H8="Political Subdivision"),"cost_service",IF($H8="Investor Owned",IF(AND(COUNTIF(Parameters!$A$4:$A$33,$G8)>0,COUNTIF(Parameters!$B$4:$B$33,$B8)=0),"procurement","cost_service"),"unclassified")))))) -> procurement
A9: 2024 | B9: 113 | C9: Agway Energy Services, LLC | D9: B | E9: Energy | F9: O | G9: NY | H9: Retail Power Marketer | I9: NYIS | J9: 12807.3 | K9: 96155 | L9: 13406 | M9: 3389.3 | N9: 26847 | O9: 2248 | P9: 0 | Q9: 0 | R9: 0 | S9: 0 | T9: 0 | U9: 0 | V9: 16196.6 | W9: 123002 | X9: 15654 | Y9: =IF(ISNUMBER($W9),$W9,0) -> 123002 | Z9: =IF(ISNUMBER(SEARCH("Adjustment",$C9)),"excluded",IF($H9="Behind the Meter","excluded",IF(NOT(OR($E9="Bundled",$E9="Energy")),"excluded",IF(OR($H9="Retail Power Marketer",$H9="Community Choice Aggregator",$E9="Energy"),"procurement",IF(OR($H9="Municipal",$H9="Cooperative",$H9="Federal",$H9="State",$H9="Political Subdivision"),"cost_service",IF($H9="Investor Owned",IF(AND(COUNTIF(Parameters!$A$4:$A$33,$G9)>0,COUNTIF(Parameters!$B$4:$B$33,$B9)=0),"procurement","cost_service"),"unclassified")))))) -> procurement
A10: 2024 | B10: 113 | C10: Agway Energy Services, LLC | D10: B | E10: Energy | F10: O | G10: PA | H10: Retail Power Marketer | I10: PJM | J10: 972.7 | K10: 8449 | L10: 945 | M10: 95.2 | N10: 918 | O10: 46 | P10: 0 | Q10: 0 | R10: 0 | S10: 0 | T10: 0 | U10: 0 | V10: 1067.9 | W10: 9367 | X10: 991 | Y10: =IF(ISNUMBER($W10),$W10,0) -> 9367 | Z10: =IF(ISNUMBER(SEARCH("Adjustment",$C10)),"excluded",IF($H10="Behind the Meter","excluded",IF(NOT(OR($E10="Bundled",$E10="Energy")),"excluded",IF(OR($H10="Retail Power Marketer",$H10="Community Choice Aggregator",$E10="Energy"),"procurement",IF(OR($H10="Municipal",$H10="Cooperative",$H10="Federal",$H10="State",$H10="Political Subdivision"),"cost_service",IF($H10="Investor Owned",IF(AND(COUNTIF(Parameters!$A$4:$A$33,$G10)>0,COUNTIF(Parameters!$B$4:$B$33,$B10)=0),"procurement","cost_service"),"unclassified")))))) -> procurement
A11: 2024 | B11: 155 | C11: Agralite Electric Coop | D11: A | E11: Bundled | F11: O | G11: MN | H11: Cooperative | I11: MISO | J11: 9568 | K11: 68617 | L11: 4333 | M11: 6218 | N11: 68440 | O11: 436 | P11: 9562 | Q11: 105823 | R11: 628 | S11: . | T11: . | U11: . | V11: 25348 | W11: 242880 | X11: 5397 | Y11: =IF(ISNUMBER($W11),$W11,0) -> 242880 | Z11: =IF(ISNUMBER(SEARCH("Adjustment",$C11)),"excluded",IF($H11="Behind the Meter","excluded",IF(NOT(OR($E11="Bundled",$E11="Energy")),"excluded",IF(OR($H11="Retail Power Marketer",$H11="Community Choice Aggregator",$E11="Energy"),"procurement",IF(OR($H11="Municipal",$H11="Cooperative",$H11="Federal",$H11="State",$H11="Political Subdivision"),"cost_service",IF($H11="Investor Owned",IF(AND(COUNTIF(Parameters!$A$4:$A$33,$G11)>0,COUNTIF(Parameters!$B$4:$B$33,$B11)=0),"procurement","cost_service"),"unclassified")))))) -> cost_service
A12: 2024 | B12: 162 | C12: Aiken Electric Coop Inc | D12: A | E12: Bundled | F12: O | G12: SC | H12: Cooperative | I12: SC | J12: 101066.1 | K12: 650960 | L12: 49460 | M12: 18578.6 | N12: 142543 | O12: 3364 | P12: 14478.7 | Q12: 200397 | R12: 15 | S12: . | T12: . | U12: . | V12: 134123.4 | W12: 993900 | X12: 52839 | Y12: =IF(ISNUMBER($W12),$W12,0) -> 993900 | Z12: =IF(ISNUMBER(SEARCH("Adjustment",$C12)),"excluded",IF($H12="Behind the Meter","excluded",IF(NOT(OR($E12="Bundled",$E12="Energy")),"excluded",IF(OR($H12="Retail Power Marketer",$H12="Community Choice Aggregator",$E12="Energy"),"procurement",IF(OR($H12="Municipal",$H12="Cooperative",$H12="Federal",$H12="State",$H12="Political Subdivision"),"cost_service",IF($H12="Investor Owned",IF(AND(COUNTIF(Parameters!$A$4:$A$33,$G12)>0,COUNTIF(Parameters!$B$4:$B$33,$B12)=0),"procurement","cost_service"),"unclassified")))))) -> cost_service
A13: 2024 | B13: 176 | C13: Ajo Improvement Co | D13: A | E13: Bundled | F13: O | G13: AZ | H13: Investor Owned | I13: AZPS | J13: 678 | K13: 5396 | L13: 821 | M13: 379.2 | N13: 3315 | O13: 210 | P13: 0 | Q13: 0 | R13: 0 | S13: 0 | T13: 0 | U13: 0 | V13: 1057.2 | W13: 8711 | X13: 1031 | Y13: =IF(ISNUMBER($W13),$W13,0) -> 8711 | Z13: =IF(ISNUMBER(SEARCH("Adjustment",$C13)),"excluded",IF($H13="Behind the Meter","excluded",IF(NOT(OR($E13="Bundled",$E13="Energy")),"excluded",IF(OR($H13="Retail Power Marketer",$H13="Community Choice Aggregator",$E13="Energy"),"procurement",IF(OR($H13="Municipal",$H13="Cooperative",$H13="Federal",$H13="State",$H13="Political Subdivision"),"cost_service",IF($H13="Investor Owned",IF(AND(COUNTIF(Parameters!$A$4:$A$33,$G13)>0,COUNTIF(Parameters!$B$4:$B$33,$B13)=0),"procurement","cost_service"),"unclassified")))))) -> cost_service
A14: 2024 | B14: 195 | C14: Alabama Power Co | D14: A | E14: Bundled | F14: O | G14: AL | H14: Investor Owned | I14: SOCO | J14: 3028741 | K14: 18058325 | L14: 1332911 | M14: 1979164 | N14: 13336758 | O14: 207465 | P14: 1631001 | Q14: 20504435 | R14: 6107 | S14: . | T14: . | U14: . | V14: 6638906 | W14: 51899518 | X14: 1546483 | Y14: =IF(ISNUMBER($W14),$W14,0) -> 51899518 | Z14: =IF(ISNUMBER(SEARCH("Adjustment",$C14)),"excluded",IF($H14="Behind the Meter","excluded",IF(NOT(OR($E14="Bundled",$E14="Energy")),"excluded",IF(OR($H14="Retail Power Marketer",$H14="Community Choice Aggregator",$E14="Energy"),"procurement",IF(OR($H14="Municipal",$H14="Cooperative",$H14="Federal",$H14="State",$H14="Political Subdivision"),"cost_service",IF($H14="Investor Owned",IF(AND(COUNTIF(Parameters!$A$4:$A$33,$G14)>0,COUNTIF(Parameters!$B$4:$B$33,$B14)=0),"procurement","cost_service"),"unclassified")))))) -> cost_service
A15: 2024 | B15: 207 | C15: Alameda Municipal Power | D15: A | E15: Bundled | F15: O | G15: CA | H15: Municipal | I15: CISO | J15: 32111.2 | K15: 139744 | L15: 33174 | M15: 43430.5 | N15: 216203 | O15: 4052 | P15: . | Q15: . | R15: . | S15: . | T15: . | U15: . | V15: 75541.7 | W15: 355947 | X15: 37226 | Y15: =IF(ISNUMBER($W15),$W15,0) -> 355947 | Z15: =IF(ISNUMBER(SEARCH("Adjustment",$C15)),"excluded",IF($H15="Behind the Meter","excluded",IF(NOT(OR($E15="Bundled",$E15="Energy")),"excluded",IF(OR($H15="Retail Power Marketer",$H15="Community Choice Aggregator",$E15="Energy"),"procurement",IF(OR($H15="Municipal",$H15="Cooperative",$H15="Federal",$H15="State",$H15="Political Subdivision"),"cost_service",IF($H15="Investor Owned",IF(AND(COUNTIF(Parameters!$A$4:$A$33,$G15)>0,COUNTIF(Parameters!$B$4:$B$33,$B15)=0),"procurement","cost_service"),"unclassified")))))) -> cost_service
A16: 2024 | B16: 213 | C16: Alaska Electric Light & Power Co. | D16: A | E16: Bundled | F16: O | G16: AK | H16: Investor Owned | I16: NA | J16: 22067.7 | K16: 170626 | L16: 15407 | M16: 13567 | N16: 126119 | O16: 2459 | P16: 14392.1 | Q16: 130040 | R16: 139 | S16: . | T16: . | U16: . | V16: 50026.8 | W16: 426785 | X16: 18005 | Y16: =IF(ISNUMBER($W16),$W16,0) -> 426785 | Z16: =IF(ISNUMBER(SEARCH("Adjustment",$C16)),"excluded",IF($H16="Behind the Meter","excluded",IF(NOT(OR($E16="Bundled",$E16="Energy")),"excluded",IF(OR($H16="Retail Power Marketer",$H16="Community Choice Aggregator",$E16="Energy"),"procurement",IF(OR($H16="Municipal",$H16="Cooperative",$H16="Federal",$H16="State",$H16="Political Subdivision"),"cost_service",IF($H16="Investor Owned",IF(AND(COUNTIF(Parameters!$A$4:$A$33,$G16)>0,COUNTIF(Parameters!$B$4:$B$33,$B16)=0),"procurement","cost_service"),"unclassified")))))) -> cost_service
A17: 2024 | B17: 219 | C17: Alaska Power and Telephone Co | D17: A | E17: Bundled | F17: O | G17: AK | H17: Investor Owned | I17: NA | J17: 10397 | K17: 27967 | L17: 5737 | M17: 15878 | N17: 50720 | O17: 2719 | P17: 0 | Q17: 0 | R17: 0 | S17: 0 | T17: 0 | U17: 0 | V17: 26275 | W17: 78687 | X17: 8456 | Y17: =IF(ISNUMBER($W17),$W17,0) -> 78687 | Z17: =IF(ISNUMBER(SEARCH("Adjustment",$C17)),"excluded",IF($H17="Behind the Meter","excluded",IF(NOT(OR($E17="Bundled",$E17="Energy")),"excluded",IF(OR($H17="Retail Power Marketer",$H17="Community Choice Aggregator",$E17="Energy"),"procurement",IF(OR($H17="Municipal",$H17="Cooperative",$H17="Federal",$H17="State",$H17="Political Subdivision"),"cost_service",IF($H17="Investor Owned",IF(AND(COUNTIF(Parameters!$A$4:$A$33,$G17)>0,COUNTIF(Parameters!$B$4:$B$33,$B17)=0),"procurement","cost_service"),"unclassified")))))) -> cost_service
A18: 2024 | B18: 221 | C18: Alaska Village Elec Coop, Inc | D18: A | E18: Bundled | F18: O | G18: AK | H18: Cooperative | I18: NA | J18: 30675.3 | K18: 43854 | L18: 7689 | M18: 46345.7 | N18: 81597 | O18: 3829 | P18: 0 | Q18: 0 | R18: 0 | S18: 0 | T18: 0 | U18: 0 | V18: 77021 | W18: 125451 | X18: 11518 | Y18: =IF(ISNUMBER($W18),$W18,0) -> 125451 | Z18: =IF(ISNUMBER(SEARCH("Adjustment",$C18)),"excluded",IF($H18="Behind the Meter","excluded",IF(NOT(OR($E18="Bundled",$E18="Energy")),"excluded",IF(OR($H18="Retail Power Marketer",$H18="Community Choice Aggregator",$E18="Energy"),"procurement",IF(OR($H18="Municipal",$H18="Cooperative",$H18="Federal",$H18="State",$H18="Political Subdivision"),"cost_service",IF($H18="Investor Owned",IF(AND(COUNTIF(Parameters!$A$4:$A$33,$G18)>0,COUNTIF(Parameters!$B$4:$B$33,$B18)=0),"procurement","cost_service"),"unclassified")))))) -> cost_service
A19: 2024 | B19: 230 | C19: Albany Utility Board | D19: A | E19: Bundled | F19: O | G19: GA | H19: Municipal | I19: SOCO | J19: 44345 | K19: 344628 | L19: 29517 | M19: 36021.7 | N19: 489134 | O19: 4386 | P19: 16.1 | Q19: 595 | R19: 18 | S19: . | T19: . | U19: . | V19: 80382.8 | W19: 834357 | X19: 33921 | Y19: =IF(ISNUMBER($W19),$W19,0) -> 834357 | Z19: =IF(ISNUMBER(SEARCH("Adjustment",$C19)),"excluded",IF($H19="Behind the Meter","excluded",IF(NOT(OR($E19="Bundled",$E19="Energy")),"excluded",IF(OR($H19="Retail Power Marketer",$H19="Community Choice Aggregator",$E19="Energy"),"procurement",IF(OR($H19="Municipal",$H19="Cooperative",$H19="Federal",$H19="State",$H19="Political Subdivision"),"cost_service",IF($H19="Investor Owned",IF(AND(COUNTIF(Parameters!$A$4:$A$33,$G19)>0,COUNTIF(Parameters!$B$4:$B$33,$B19)=0),"procurement","cost_service"),"unclassified")))))) -> cost_service
A20: 2024 | B20: 232 | C20: City of Albemarle - (NC) | D20: A | E20: Bundled | F20: O | G20: NC | H20: Municipal | I20: DUK | J20: 15540.1 | K20: 143278 | L20: 11248 | M20: 11813.5 | N20: 124076 | O20: 2325 | P20: 2043.8 | Q20: 26186 | R20: 12 | S20: . | T20: . | U20: . | V20: 29397.4 | W20: 293540 | X20: 13585 | Y20: =IF(ISNUMBER($W20),$W20,0) -> 293540 | Z20: =IF(ISNUMBER(SEARCH("Adjustment",$C20)),"excluded",IF($H20="Behind the Meter","excluded",IF(NOT(OR($E20="Bundled",$E20="Energy")),"excluded",IF(OR($H20="Retail Power Marketer",$H20="Community Choice Aggregator",$E20="Energy"),"procurement",IF(OR($H20="Municipal",$H20="Cooperative",$H20="Federal",$H20="State",$H20="Political Subdivision"),"cost_service",IF($H20="Investor Owned",IF(AND(COUNTIF(Parameters!$A$4:$A$33,$G20)>0,COUNTIF(Parameters!$B$4:$B$33,$B20)=0),"procurement","cost_service"),"unclassified")))))) -> cost_service
A21: 2024 | B21: 240 | C21: Albemarle Electric Member Corp | D21: A | E21: Bundled | F21: O | G21: NC | H21: Cooperative | I21: PJM | J21: 27083 | K21: 187141 | L21: 12728 | M21: 4363 | N21: 34972 | O21: 1117 | P21: 623 | Q21: 6942 | R21: 25 | S21: 0 | T21: 0 | U21: 0 | V21: 32069 | W21: 229055 | X21: 13870 | Y21: =IF(ISNUMBER($W21),$W21,0) -> 229055 | Z21: =IF(ISNUMBER(SEARCH("Adjustment",$C21)),"excluded",IF($H21="Behind the Meter","excluded",IF(NOT(OR($E21="Bundled",$E21="Energy")),"excluded",IF(OR($H21="Retail Power Marketer",$H21="Community Choice Aggregator",$E21="Energy"),"procurement",IF(OR($H21="Municipal",$H21="Cooperative",$H21="Federal",$H21="State",$H21="Political Subdivision"),"cost_service",IF($H21="Investor Owned",IF(AND(COUNTIF(Parameters!$A$4:$A$33,$G21)>0,COUNTIF(Parameters!$B$4:$B$33,$B21)=0),"procurement","cost_service"),"unclassified")))))) -> cost_service
A22: 2024 | B22: 241 | C22: Albertville Municipal Utilities Board | D22: A | E22: Bundled | F22: O | G22: AL | H22: Municipal | I22: TVA | J22: 13258 | K22: 124264 | L22: 8318 | M22: 21539 | N22: 194750 | O22: 2393 | P22: 21329 | Q22: 333519 | R22: 15 | S22: 0 | T22: 0 | U22: 0 | V22: 56126 | W22: 652533 | X22: 10726 | Y22: =IF(ISNUMBER($W22),$W22,0) -> 652533 | Z22: =IF(ISNUMBER(SEARCH("Adjustment",$C22)),"excluded",IF($H22="Behind the Meter","excluded",IF(NOT(OR($E22="Bundled",$E22="Energy")),"excluded",IF(OR($H22="Retail Power Marketer",$H22="Community Choice Aggregator",$E22="Energy"),"procurement",IF(OR($H22="Municipal",$H22="Cooperative",$H22="Federal",$H22="State",$H22="Political Subdivision"),"cost_service",IF($H22="Investor Owned",IF(AND(COUNTIF(Parameters!$A$4:$A$33,$G22)>0,COUNTIF(Parameters!$B$4:$B$33,$B22)=0),"procurement","cost_service"),"unclassified")))))) -> cost_service
A23: 2024 | B23: 261 | C23: AGC Division of APGI Inc | D23: A | E23: Bundled | F23: O | G23: IN | H23: Investor Owned | I23: MISO | J23: 0 | K23: 0 | L23: 0 | M23: 0 | N23: 0 | O23: 0 | P23: 159579.9 | Q23: 2639245 | R23: 2 | S23: 0 | T23: 0 | U23: 0 | V23: 159579.9 | W23: 2639245 | X23: 2 | Y23: =IF(ISNUMBER($W23),$W23,0) -> 2639245 | Z23: =IF(ISNUMBER(SEARCH("Adjustment",$C23)),"excluded",IF($H23="Behind the Meter","excluded",IF(NOT(OR($E23="Bundled",$E23="Energy")),"excluded",IF(OR($H23="Retail Power Marketer",$H23="Community Choice Aggregator",$E23="Energy"),"procurement",IF(OR($H23="Municipal",$H23="Cooperative",$H23="Federal",$H23="State",$H23="Political Subdivision"),"cost_service",IF($H23="Investor Owned",IF(AND(COUNTIF(Parameters!$A$4:$A$33,$G23)>0,COUNTIF(Parameters!$B$4:$B$33,$B23)=0),"procurement","cost_service"),"unclassified")))))) -> cost_service
A24: 2024 | B24: 276 | C24: Alcorn County Elec Power Assn | D24: A | E24: Bundled | F24: O | G24: MS | H24: Cooperative | I24: TVA | J24: 27784 | K24: 214981 | L24: 14965 | M24: 21450 | N24: 156737 | O24: 4209 | P24: 15258 | Q24: 259874 | R24: 7 | S24: 0 | T24: 0 | U24: 0 | V24: 64492 | W24: 631592 | X24: 19181 | Y24: =IF(ISNUMBER($W24),$W24,0) -> 631592 | Z24: =IF(ISNUMBER(SEARCH("Adjustment",$C24)),"excluded",IF($H24="Behind the Meter","excluded",IF(NOT(OR($E24="Bundled",$E24="Energy")),"excluded",IF(OR($H24="Retail Power Marketer",$H24="Community Choice Aggregator",$E24="Energy"),"procurement",IF(OR($H24="Municipal",$H24="Cooperative",$H24="Federal",$H24="State",$H24="Political Subdivision"),"cost_service",IF($H24="Investor Owned",IF(AND(COUNTIF(Parameters!$A$4:$A$33,$G24)>0,COUNTIF(Parameters!$B$4:$B$33,$B24)=0),"procurement","cost_service"),"unclassified")))))) -> cost_service
A25: 2024 | B25: 295 | C25: City of Alexandria - (MN) | D25: A | E25: Bundled | F25: O | G25: MN | H25: Municipal | I25: MISO | J25: 8900.4 | K25: 76955 | L25: 8758 | M25: 3893.7 | N25: 32821 | O25: 1706 | P25: 15171 | Q25: 168628 | R25: 228 | S25: . | T25: . | U25: . | V25: 27965.1 | W25: 278404 | X25: 10692 | Y25: =IF(ISNUMBER($W25),$W25,0) -> 278404 | Z25: =IF(ISNUMBER(SEARCH("Adjustment",$C25)),"excluded",IF($H25="Behind the Meter","excluded",IF(NOT(OR($E25="Bundled",$E25="Energy")),"excluded",IF(OR($H25="Retail Power Marketer",$H25="Community Choice Aggregator",$E25="Energy"),"procurement",IF(OR($H25="Municipal",$H25="Cooperative",$H25="Federal",$H25="State",$H25="Political Subdivision"),"cost_service",IF($H25="Investor Owned",IF(AND(COUNTIF(Parameters!$A$4:$A$33,$G25)>0,COUNTIF(Parameters!$B$4:$B$33,$B25)=0),"procurement","cost_service"),"unclassified")))))) -> cost_service
A26: 2024 | B26: 296 | C26: Alfalfa Electric Coop, Inc | D26: A | E26: Bundled | F26: O | G26: KS | H26: Cooperative | I26: SWPP | J26: 373 | K26: 3583 | L26: 205 | M26: 744 | N26: 4593 | O26: 670 | P26: 1121 | Q26: 12621 | R26: 55 | S26: . | T26: . | U26: . | V26: 2238 | W26: 20797 | X26: 930 | Y26: =IF(ISNUMBER($W26),$W26,0) -> 20797 | Z26: =IF(ISNUMBER(SEARCH("Adjustment",$C26)),"excluded",IF($H26="Behind the Meter","excluded",IF(NOT(OR($E26="Bundled",$E26="Energy")),"excluded",IF(OR($H26="Retail Power Marketer",$H26="Community Choice Aggregator",$E26="Energy"),"procurement",IF(OR($H26="Municipal",$H26="Cooperative",$H26="Federal",$H26="State",$H26="Political Subdivision"),"cost_service",IF($H26="Investor Owned",IF(AND(COUNTIF(Parameters!$A$4:$A$33,$G26)>0,COUNTIF(Parameters!$B$4:$B$33,$B26)=0),"procurement","cost_service"),"unclassified")))))) -> cost_service
A27: 2024 | B27: 296 | C27: Alfalfa Electric Coop, Inc | D27: A | E27: Bundled | F27: O | G27: OK | H27: Cooperative | I27: SWPP | J27: 5044 | K27: 49434 | L27: 2630 | M27: 5371 | N27: 37743 | O27: 4294 | P27: 23807 | Q27: 301906 | R27: 612 | S27: . | T27: . | U27: . | V27: 34222 | W27: 389083 | X27: 7536 | Y27: =IF(ISNUMBER($W27),$W27,0) -> 389083 | Z27: =IF(ISNUMBER(SEARCH("Adjustment",$C27)),"excluded",IF($H27="Behind the Meter","excluded",IF(NOT(OR($E27="Bundled",$E27="Energy")),"excluded",IF(OR($H27="Retail Power Marketer",$H27="Community Choice Aggregator",$E27="Energy"),"procurement",IF(OR($H27="Municipal",$H27="Cooperative",$H27="Federal",$H27="State",$H27="Political Subdivision"),"cost_service",IF($H27="Investor Owned",IF(AND(COUNTIF(Parameters!$A$4:$A$33,$G27)>0,COUNTIF(Parameters!$B$4:$B$33,$B27)=0),"procurement","cost_service"),"unclassified")))))) -> cost_service
A28: 2024 | B28: 298 | C28: City of Alexandria - (LA) | D28: A | E28: Bundled | F28: O | G28: LA | H28: Municipal | I28: MISO | J28: 30931.1 | K28: 278634 | L28: 19541 | M28: 38444.3 | N28: 363017 | O28: 3913 | P28: 479.8 | Q28: 5167 | R28: 6 | S28: . | T28: . | U28: . | V28: 69855.2 | W28: 646818 | X28: 23460 | Y28: =IF(ISNUMBER($W28),$W28,0) -> 646818 | Z28: =IF(ISNUMBER(SEARCH("Adjustment",$C28)),"excluded",IF($H28="Behind the Meter","excluded",IF(NOT(OR($E28="Bundled",$E28="Energy")),"excluded",IF(OR($H28="Retail Power Marketer",$H28="Community Choice Aggregator",$E28="Energy"),"procurement",IF(OR($H28="Municipal",$H28="Cooperative",$H28="Federal",$H28="State",$H28="Political Subdivision"),"cost_service",IF($H28="Investor Owned",IF(AND(COUNTIF(Parameters!$A$4:$A$33,$G28)>0,COUNTIF(Parameters!$B$4:$B$33,$B28)=0),"procurement","cost_service"),"unclassified")))))) -> cost_service
A29: 2024 | B29: 305 | C29: Alger-Delta Coop Electric Assn | D29: A | E29: Bundled | F29: O | G29: MI | H29: Cooperative | I29: MISO | J29: 11995.9 | K29: 51600 | L29: 9817 | M29: 1834.5 | N29: 11320 | O29: 495 | P29: 4014.9 | Q29: 31953 | R29: 1 | S29: 0 | T29: 0 | U29: 0 | V29: 17845.3 | W29: 94873 | X29: 10313 | Y29: =IF(ISNUMBER($W29),$W29,0) -> 94873 | Z29: =IF(ISNUMBER(SEARCH("Adjustment",$C29)),"excluded",IF($H29="Behind the Meter","excluded",IF(NOT(OR($E29="Bundled",$E29="Energy")),"excluded",IF(OR($H29="Retail Power Marketer",$H29="Community Choice Aggregator",$E29="Energy"),"procurement",IF(OR($H29="Municipal",$H29="Cooperative",$H29="Federal",$H29="State",$H29="Political Subdivision"),"cost_service",IF($H29="Investor Owned",IF(AND(COUNTIF(Parameters!$A$4:$A$33,$G29)>0,COUNTIF(Parameters!$B$4:$B$33,$B29)=0),"procurement","cost_service"),"unclassified")))))) -> cost_service
A30: 2024 | B30: 307 | C30: Algoma Utility Comm | D30: A | E30: Bundled | F30: O | G30: WI | H30: Municipal | I30: MISO | J30: 1403.2 | K30: 10775 | L30: 1654 | M30: 1881.4 | N30: 17010 | O30: 395 | P30: 510.1 | Q30: 5869 | R30: 1 | S30: 0 | T30: 0 | U30: 0 | V30: 3794.7 | W30: 33654 | X30: 2050 | Y30: =IF(ISNUMBER($W30),$W30,0) -> 33654 | Z30: =IF(ISNUMBER(SEARCH("Adjustment",$C30)),"excluded",IF($H30="Behind the Meter","excluded",IF(NOT(OR($E30="Bundled",$E30="Energy")),"excluded",IF(OR($H30="Retail Power Marketer",$H30="Community Choice Aggregator",$E30="Energy"),"procurement",IF(OR($H30="Municipal",$H30="Cooperative",$H30="Federal",$H30="State",$H30="Political Subdivision"),"cost_service",IF($H30="Investor Owned",IF(AND(COUNTIF(Parameters!$A$4:$A$33,$G30)>0,COUNTIF(Parameters!$B$4:$B$33,$B30)=0),"procurement","cost_service"),"unclassified")))))) -> cost_service
A31: 2024 | B31: 392 | C31: Alpena Power Co | D31: A | E31: Bundled | F31: O | G31: MI | H31: Investor Owned | I31: MISO | J31: 15157.9 | K31: 86989 | L31: 13763 | M31: 13651.6 | N31: 89556 | O31: 3041 | P31: 7916.1 | Q31: 109161 | R31: 3 | S31: 0 | T31: 0 | U31: 0 | V31: 36725.6 | W31: 285706 | X31: 16807 | Y31: =IF(ISNUMBER($W31),$W31,0) -> 285706 | Z31: =IF(ISNUMBER(SEARCH("Adjustment",$C31)),"excluded",IF($H31="Behind the Meter","excluded",IF(NOT(OR($E31="Bundled",$E31="Energy")),"excluded",IF(OR($H31="Retail Power Marketer",$H31="Community Choice Aggregator",$E31="Energy"),"procurement",IF(OR($H31="Municipal",$H31="Cooperative",$H31="Federal",$H31="State",$H31="Political Subdivision"),"cost_service",IF($H31="Investor Owned",IF(AND(COUNTIF(Parameters!$A$4:$A$33,$G31)>0,COUNTIF(Parameters!$B$4:$B$33,$B31)=0),"procurement","cost_service"),"unclassified")))))) -> cost_service
A32: 2024 | B32: 407 | C32: Altamaha Electric Member Corp | D32: A | E32: Bundled | F32: O | G32: GA | H32: Cooperative | I32: SOCO | J32: 37983.5 | K32: 236866 | L32: 19628 | M32: 29917.2 | N32: 332113 | O32: 1984 | P32: 1234.2 | Q32: 8400 | R32: 258 | S32: . | T32: . | U32: . | V32: 69134.9 | W32: 577379 | X32: 21870 | Y32: =IF(ISNUMBER($W32),$W32,0) -> 577379 | Z32: =IF(ISNUMBER(SEARCH("Adjustment",$C32)),"excluded",IF($H32="Behind the Meter","excluded",IF(NOT(OR($E32="Bundled",$E32="Energy")),"excluded",IF(OR($H32="Retail Power Marketer",$H32="Community Choice Aggregator",$E32="Energy"),"procurement",IF(OR($H32="Municipal",$H32="Cooperative",$H32="Federal",$H32="State",$H32="Political Subdivision"),"cost_service",IF($H32="Investor Owned",IF(AND(COUNTIF(Parameters!$A$4:$A$33,$G32)>0,COUNTIF(Parameters!$B$4:$B$33,$B32)=0),"procurement","cost_service"),"unclassified")))))) -> cost_service
A33: 2024 | B33: 416 | C33: City of Altus - (OK) | D33: A | E33: Bundled | F33: O | G33: OK | H33: Municipal | I33: SWPP | J33: 13567 | K33: 104947 | L33: 8167 | M33: 6814 | N33: 64630 | O33: 1268 | P33: 3079 | Q33: 39809 | R33: 8 | S33: . | T33: . | U33: . | V33: 23460 | W33: 209386 | X33: 9443 | Y33: =IF(ISNUMBER($W33),$W33,0) -> 209386 | Z33: =IF(ISNUMBER(SEARCH("Adjustment",$C33)),"excluded",IF($H33="Behind the Meter","excluded",IF(NOT(OR($E33="Bundled",$E33="Energy")),"excluded",IF(OR($H33="Retail Power Marketer",$H33="Community Choice Aggregator",$E33="Energy"),"procurement",IF(OR($H33="Municipal",$H33="Cooperative",$H33="Federal",$H33="State",$H33="Political Subdivision"),"cost_service",IF($H33="Investor Owned",IF(AND(COUNTIF(Parameters!$A$4:$A$33,$G33)>0,COUNTIF(Parameters!$B$4:$B$33,$B33)=0),"procurement","cost_service"),"unclassified")))))) -> cost_service
A34: 2024 | B34: 471 | C34: Amana Society Service Co | D34: A | E34: Bundled | F34: O | G34: IA | H34: Investor Owned | I34: MISO | J34: 1061 | K34: 6833 | L34: 709 | M34: 1221 | N34: 8358 | O34: 179 | P34: 5506 | Q34: 51780 | R34: 1 | S34: 0 | T34: 0 | U34: 0 | V34: 7788 | W34: 66971 | X34: 889 | Y34: =IF(ISNUMBER($W34),$W34,0) -> 66971 | Z34: =IF(ISNUMBER(SEARCH("Adjustment",$C34)),"excluded",IF($H34="Behind the Meter","excluded",IF(NOT(OR($E34="Bundled",$E34="Energy")),"excluded",IF(OR($H34="Retail Power Marketer",$H34="Community Choice Aggregator",$E34="Energy"),"procurement",IF(OR($H34="Municipal",$H34="Cooperative",$H34="Federal",$H34="State",$H34="Political Subdivision"),"cost_service",IF($H34="Investor Owned",IF(AND(COUNTIF(Parameters!$A$4:$A$33,$G34)>0,COUNTIF(Parameters!$B$4:$B$33,$B34)=0),"procurement","cost_service"),"unclassified")))))) -> cost_service
A35: 2024 | B35: 540 | C35: BP Energy Company | D35: B | E35: Energy | F35: O | G35: WA | H35: Retail Power Marketer | I35: PSEI | J35: . | K35: . | L35: . | M35: . | N35: . | O35: . | P35: 60883.1 | Q35: 887803 | R35: 2 | S35: . | T35: . | U35: . | V35: 60883.1 | W35: 887803 | X35: 2 | Y35: =IF(ISNUMBER($W35),$W35,0) -> 887803 | Z35: =IF(ISNUMBER(SEARCH("Adjustment",$C35)),"excluded",IF($H35="Behind the Meter","excluded",IF(NOT(OR($E35="Bundled",$E35="Energy")),"excluded",IF(OR($H35="Retail Power Marketer",$H35="Community Choice Aggregator",$E35="Energy"),"procurement",IF(OR($H35="Municipal",$H35="Cooperative",$H35="Federal",$H35="State",$H35="Political Subdivision"),"cost_service",IF($H35="Investor Owned",IF(AND(COUNTIF(Parameters!$A$4:$A$33,$G35)>0,COUNTIF(Parameters!$B$4:$B$33,$B35)=0),"procurement","cost_service"),"unclassified")))))) -> procurement
A36: 2024 | B36: 540 | C36: BP Energy Company | D36: D | E36: Bundled | F36: O | G36: TX | H36: Retail Power Marketer | I36: ERCO | J36: . | K36: . | L36: . | M36: . | N36: . | O36: . | P36: 62297 | Q36: 989891 | R36: 1 | S36: . | T36: . | U36: . | V36: 62297 | W36: 989891 | X36: 1 | Y36: =IF(ISNUMBER($W36),$W36,0) -> 989891 | Z36: =IF(ISNUMBER(SEARCH("Adjustment",$C36)),"excluded",IF($H36="Behind the Meter","excluded",IF(NOT(OR($E36="Bundled",$E36="Energy")),"excluded",IF(OR($H36="Retail Power Marketer",$H36="Community Choice Aggregator",$E36="Energy"),"procurement",IF(OR($H36="Municipal",$H36="Cooperative",$H36="Federal",$H36="State",$H36="Political Subdivision"),"cost_service",IF($H36="Investor Owned",IF(AND(COUNTIF(Parameters!$A$4:$A$33,$G36)>0,COUNTIF(Parameters!$B$4:$B$33,$B36)=0),"procurement","cost_service"),"unclassified")))))) -> procurement
A37: 2024 | B37: 554 | C37: City of Ames - (IA) | D37: A | E37: Bundled | F37: O | G37: IA | H37: Municipal | I37: MISO | J37: 20680.5 | K37: 170973 | L37: 24979 | M37: 28463.1 | N37: 334597 | O37: 3121 | P37: 11868.2 | Q37: 145193 | R37: 8 | S37: . | T37: . | U37: . | V37: 61011.8 | W37: 650763 | X37: 28108 | Y37: =IF(ISNUMBER($W37),$W37,0) -> 650763 | Z37: =IF(ISNUMBER(SEARCH("Adjustment",$C37)),"excluded",IF($H37="Behind the Meter","excluded",IF(NOT(OR($E37="Bundled",$E37="Energy")),"excluded",IF(OR($H37="Retail Power Marketer",$H37="Community Choice Aggregator",$E37="Energy"),"procurement",IF(OR($H37="Municipal",$H37="Cooperative",$H37="Federal",$H37="State",$H37="Political Subdivision"),"cost_service",IF($H37="Investor Owned",IF(AND(COUNTIF(Parameters!$A$4:$A$33,$G37)>0,COUNTIF(Parameters!$B$4:$B$33,$B37)=0),"procurement","cost_service"),"unclassified")))))) -> cost_service
A38: 2024 | B38: 562 | C38: Amicalola Electric Member Corp | D38: A | E38: Bundled | F38: O | G38: GA | H38: Cooperative | I38: SOCO | J38: 92851.8 | K38: 748163 | L38: 50337 | M38: 18240.6 | N38: 131462 | O38: 6070 | P38: . | Q38: . | R38: . | S38: . | T38: . | U38: . | V38: 111092.4 | W38: 879625 | X38: 56407 | Y38: =IF(ISNUMBER($W38),$W38,0) -> 879625 | Z38: =IF(ISNUMBER(SEARCH("Adjustment",$C38)),"excluded",IF($H38="Behind the Meter","excluded",IF(NOT(OR($E38="Bundled",$E38="Energy")),"excluded",IF(OR($H38="Retail Power Marketer",$H38="Community Choice Aggregator",$E38="Energy"),"procurement",IF(OR($H38="Municipal",$H38="Cooperative",$H38="Federal",$H38="State",$H38="Political Subdivision"),"cost_service",IF($H38="Investor Owned",IF(AND(COUNTIF(Parameters!$A$4:$A$33,$G38)>0,COUNTIF(Parameters!$B$4:$B$33,$B38)=0),"procurement","cost_service"),"unclassified")))))) -> cost_service
A39: 2024 | B39: 571 | C39: City of Amory | D39: A | E39: Bundled | F39: O | G39: MS | H39: Municipal | I39: TVA | J39: 4410 | K39: 37764 | L39: 2822 | M39: 5977 | N39: 47462 | O39: 1134 | P39: 3039 | Q39: 35349 | R39: 3 | S39: 0 | T39: 0 | U39: 0 | V39: 13426 | W39: 120575 | X39: 3959 | Y39: =IF(ISNUMBER($W39),$W39,0) -> 120575 | Z39: =IF(ISNUMBER(SEARCH("Adjustment",$C39)),"excluded",IF($H39="Behind the Meter","excluded",IF(NOT(OR($E39="Bundled",$E39="Energy")),"excluded",IF(OR($H39="Retail Power Marketer",$H39="Community Choice Aggregator",$E39="Energy"),"procurement",IF(OR($H39="Municipal",$H39="Cooperative",$H39="Federal",$H39="State",$H39="Political Subdivision"),"cost_service",IF($H39="Investor Owned",IF(AND(COUNTIF(Parameters!$A$4:$A$33,$G39)>0,COUNTIF(Parameters!$B$4:$B$33,$B39)=0),"procurement","cost_service"),"unclassified")))))) -> cost_service
A40: 2024 | B40: 577 | C40: City of Alcoa Utilities | D40: A | E40: Bundled | F40: O | G40: TN | H40: Municipal | I40: TVA | J40: 50103 | K40: 410299 | L40: 28183 | M40: 30222 | N40: 261925 | O40: 4543 | P40: 158 | Q40: 1098 | R40: 1 | S40: 0 | T40: 0 | U40: 0 | V40: 80483 | W40: 673322 | X40: 32727 | Y40: =IF(ISNUMBER($W40),$W40,0) -> 673322 | Z40: =IF(ISNUMBER(SEARCH("Adjustment",$C40)),"excluded",IF($H40="Behind the Meter","excluded",IF(NOT(OR($E40="Bundled",$E40="Energy")),"excluded",IF(OR($H40="Retail Power Marketer",$H40="Community Choice Aggregator",$E40="Energy"),"procurement",IF(OR($H40="Municipal",$H40="Cooperative",$H40="Federal",$H40="State",$H40="Political Subdivision"),"cost_service",IF($H40="Investor Owned",IF(AND(COUNTIF(Parameters!$A$4:$A$33,$G40)>0,COUNTIF(Parameters!$B$4:$B$33,$B40)=0),"procurement","cost_service"),"unclassified")))))) -> cost_service
...

Sheet State Shares
A1: state | B1: cost_service_mwh | C1: procurement_mwh | D1: unclassified_mwh | E1: total_mwh | F1: share_cost_service | G1: share_procurement
A2: AK | B2: =SUMIFS('EIA-861 Sales 2024'!$Y$4:$Y$2819,'EIA-861 Sales 2024'!$G$4:$G$2819,$A2,'EIA-861 Sales 2024'!$Z$4:$Z$2819,"cost_service") -> 5414197 | C2: =SUMIFS('EIA-861 Sales 2024'!$Y$4:$Y$2819,'EIA-861 Sales 2024'!$G$4:$G$2819,$A2,'EIA-861 Sales 2024'!$Z$4:$Z$2819,"procurement") -> 0 | D2: =SUMIFS('EIA-861 Sales 2024'!$Y$4:$Y$2819,'EIA-861 Sales 2024'!$G$4:$G$2819,$A2,'EIA-861 Sales 2024'!$Z$4:$Z$2819,"unclassified") -> 0 | E2: =B2+C2+D2 -> 5414197 | F2: =IF($E2=0,0,B2/$E2) -> 1 | G2: =IF($E2=0,0,C2/$E2) -> 0
A3: AL | B3: =SUMIFS('EIA-861 Sales 2024'!$Y$4:$Y$2819,'EIA-861 Sales 2024'!$G$4:$G$2819,$A3,'EIA-861 Sales 2024'!$Z$4:$Z$2819,"cost_service") -> 86075772 | C3: =SUMIFS('EIA-861 Sales 2024'!$Y$4:$Y$2819,'EIA-861 Sales 2024'!$G$4:$G$2819,$A3,'EIA-861 Sales 2024'!$Z$4:$Z$2819,"procurement") -> 0 | D3: =SUMIFS('EIA-861 Sales 2024'!$Y$4:$Y$2819,'EIA-861 Sales 2024'!$G$4:$G$2819,$A3,'EIA-861 Sales 2024'!$Z$4:$Z$2819,"unclassified") -> 0 | E3: =B3+C3+D3 -> 86075772 | F3: =IF($E3=0,0,B3/$E3) -> 1 | G3: =IF($E3=0,0,C3/$E3) -> 0
A4: AR | B4: =SUMIFS('EIA-861 Sales 2024'!$Y$4:$Y$2819,'EIA-861 Sales 2024'!$G$4:$G$2819,$A4,'EIA-861 Sales 2024'!$Z$4:$Z$2819,"cost_service") -> 49188526 | C4: =SUMIFS('EIA-861 Sales 2024'!$Y$4:$Y$2819,'EIA-861 Sales 2024'!$G$4:$G$2819,$A4,'EIA-861 Sales 2024'!$Z$4:$Z$2819,"procurement") -> 0 | D4: =SUMIFS('EIA-861 Sales 2024'!$Y$4:$Y$2819,'EIA-861 Sales 2024'!$G$4:$G$2819,$A4,'EIA-861 Sales 2024'!$Z$4:$Z$2819,"unclassified") -> 0 | E4: =B4+C4+D4 -> 49188526 | F4: =IF($E4=0,0,B4/$E4) -> 1 | G4: =IF($E4=0,0,C4/$E4) -> 0
A5: AZ | B5: =SUMIFS('EIA-861 Sales 2024'!$Y$4:$Y$2819,'EIA-861 Sales 2024'!$G$4:$G$2819,$A5,'EIA-861 Sales 2024'!$Z$4:$Z$2819,"cost_service") -> 87228368 | C5: =SUMIFS('EIA-861 Sales 2024'!$Y$4:$Y$2819,'EIA-861 Sales 2024'!$G$4:$G$2819,$A5,'EIA-861 Sales 2024'!$Z$4:$Z$2819,"procurement") -> 0 | D5: =SUMIFS('EIA-861 Sales 2024'!$Y$4:$Y$2819,'EIA-861 Sales 2024'!$G$4:$G$2819,$A5,'EIA-861 Sales 2024'!$Z$4:$Z$2819,"unclassified") -> 0 | E5: =B5+C5+D5 -> 87228368 | F5: =IF($E5=0,0,B5/$E5) -> 1 | G5: =IF($E5=0,0,C5/$E5) -> 0
A6: CA | B6: =SUMIFS('EIA-861 Sales 2024'!$Y$4:$Y$2819,'EIA-861 Sales 2024'!$G$4:$G$2819,$A6,'EIA-861 Sales 2024'!$Z$4:$Z$2819,"cost_service") -> 147133678 | C6: =SUMIFS('EIA-861 Sales 2024'!$Y$4:$Y$2819,'EIA-861 Sales 2024'!$G$4:$G$2819,$A6,'EIA-861 Sales 2024'!$Z$4:$Z$2819,"procurement") -> 87940406 | D6: =SUMIFS('EIA-861 Sales 2024'!$Y$4:$Y$2819,'EIA-861 Sales 2024'!$G$4:$G$2819,$A6,'EIA-861 Sales 2024'!$Z$4:$Z$2819,"unclassified") -> 0 | E6: =B6+C6+D6 -> 235074084 | F6: =IF($E6=0,0,B6/$E6) -> 0.62590344 | G6: =IF($E6=0,0,C6/$E6) -> 0.37409656
A7: CO | B7: =SUMIFS('EIA-861 Sales 2024'!$Y$4:$Y$2819,'EIA-861 Sales 2024'!$G$4:$G$2819,$A7,'EIA-861 Sales 2024'!$Z$4:$Z$2819,"cost_service") -> 55242525 | C7: =SUMIFS('EIA-861 Sales 2024'!$Y$4:$Y$2819,'EIA-861 Sales 2024'!$G$4:$G$2819,$A7,'EIA-861 Sales 2024'!$Z$4:$Z$2819,"procurement") -> 0 | D7: =SUMIFS('EIA-861 Sales 2024'!$Y$4:$Y$2819,'EIA-861 Sales 2024'!$G$4:$G$2819,$A7,'EIA-861 Sales 2024'!$Z$4:$Z$2819,"unclassified") -> 0 | E7: =B7+C7+D7 -> 55242525 | F7: =IF($E7=0,0,B7/$E7) -> 1 | G7: =IF($E7=0,0,C7/$E7) -> 0
A8: CT | B8: =SUMIFS('EIA-861 Sales 2024'!$Y$4:$Y$2819,'EIA-861 Sales 2024'!$G$4:$G$2819,$A8,'EIA-861 Sales 2024'!$Z$4:$Z$2819,"cost_service") -> 1420820 | C8: =SUMIFS('EIA-861 Sales 2024'!$Y$4:$Y$2819,'EIA-861 Sales 2024'!$G$4:$G$2819,$A8,'EIA-861 Sales 2024'!$Z$4:$Z$2819,"procurement") -> 24787246 | D8: =SUMIFS('EIA-861 Sales 2024'!$Y$4:$Y$2819,'EIA-861 Sales 2024'!$G$4:$G$2819,$A8,'EIA-861 Sales 2024'!$Z$4:$Z$2819,"unclassified") -> 0 | E8: =B8+C8+D8 -> 26208066 | F8: =IF($E8=0,0,B8/$E8) -> 0.054213081 | G8: =IF($E8=0,0,C8/$E8) -> 0.94578692
A9: DC | B9: =SUMIFS('EIA-861 Sales 2024'!$Y$4:$Y$2819,'EIA-861 Sales 2024'!$G$4:$G$2819,$A9,'EIA-861 Sales 2024'!$Z$4:$Z$2819,"cost_service") -> 0 | C9: =SUMIFS('EIA-861 Sales 2024'!$Y$4:$Y$2819,'EIA-861 Sales 2024'!$G$4:$G$2819,$A9,'EIA-861 Sales 2024'!$Z$4:$Z$2819,"procurement") -> 9751813 | D9: =SUMIFS('EIA-861 Sales 2024'!$Y$4:$Y$2819,'EIA-861 Sales 2024'!$G$4:$G$2819,$A9,'EIA-861 Sales 2024'!$Z$4:$Z$2819,"unclassified") -> 0 | E9: =B9+C9+D9 -> 9751813 | F9: =IF($E9=0,0,B9/$E9) -> 0 | G9: =IF($E9=0,0,C9/$E9) -> 1
A10: DE | B10: =SUMIFS('EIA-861 Sales 2024'!$Y$4:$Y$2819,'EIA-861 Sales 2024'!$G$4:$G$2819,$A10,'EIA-861 Sales 2024'!$Z$4:$Z$2819,"cost_service") -> 3256100 | C10: =SUMIFS('EIA-861 Sales 2024'!$Y$4:$Y$2819,'EIA-861 Sales 2024'!$G$4:$G$2819,$A10,'EIA-861 Sales 2024'!$Z$4:$Z$2819,"procurement") -> 7710796 | D10: =SUMIFS('EIA-861 Sales 2024'!$Y$4:$Y$2819,'EIA-861 Sales 2024'!$G$4:$G$2819,$A10,'EIA-861 Sales 2024'!$Z$4:$Z$2819,"unclassified") -> 0 | E10: =B10+C10+D10 -> 10966896 | F10: =IF($E10=0,0,B10/$E10) -> 0.29690261 | G10: =IF($E10=0,0,C10/$E10) -> 0.70309739
A11: FL | B11: =SUMIFS('EIA-861 Sales 2024'!$Y$4:$Y$2819,'EIA-861 Sales 2024'!$G$4:$G$2819,$A11,'EIA-861 Sales 2024'!$Z$4:$Z$2819,"cost_service") -> 253722435 | C11: =SUMIFS('EIA-861 Sales 2024'!$Y$4:$Y$2819,'EIA-861 Sales 2024'!$G$4:$G$2819,$A11,'EIA-861 Sales 2024'!$Z$4:$Z$2819,"procurement") -> 0 | D11: =SUMIFS('EIA-861 Sales 2024'!$Y$4:$Y$2819,'EIA-861 Sales 2024'!$G$4:$G$2819,$A11,'EIA-861 Sales 2024'!$Z$4:$Z$2819,"unclassified") -> 0 | E11: =B11+C11+D11 -> 253722435 | F11: =IF($E11=0,0,B11/$E11) -> 1 | G11: =IF($E11=0,0,C11/$E11) -> 0
A12: GA | B12: =SUMIFS('EIA-861 Sales 2024'!$Y$4:$Y$2819,'EIA-861 Sales 2024'!$G$4:$G$2819,$A12,'EIA-861 Sales 2024'!$Z$4:$Z$2819,"cost_service") -> 146179036 | C12: =SUMIFS('EIA-861 Sales 2024'!$Y$4:$Y$2819,'EIA-861 Sales 2024'!$G$4:$G$2819,$A12,'EIA-861 Sales 2024'!$Z$4:$Z$2819,"procurement") -> 0 | D12: =SUMIFS('EIA-861 Sales 2024'!$Y$4:$Y$2819,'EIA-861 Sales 2024'!$G$4:$G$2819,$A12,'EIA-861 Sales 2024'!$Z$4:$Z$2819,"unclassified") -> 0 | E12: =B12+C12+D12 -> 146179036 | F12: =IF($E12=0,0,B12/$E12) -> 1 | G12: =IF($E12=0,0,C12/$E12) -> 0
A13: HI | B13: =SUMIFS('EIA-861 Sales 2024'!$Y$4:$Y$2819,'EIA-861 Sales 2024'!$G$4:$G$2819,$A13,'EIA-861 Sales 2024'!$Z$4:$Z$2819,"cost_service") -> 8691377 | C13: =SUMIFS('EIA-861 Sales 2024'!$Y$4:$Y$2819,'EIA-861 Sales 2024'!$G$4:$G$2819,$A13,'EIA-861 Sales 2024'!$Z$4:$Z$2819,"procurement") -> 0 | D13: =SUMIFS('EIA-861 Sales 2024'!$Y$4:$Y$2819,'EIA-861 Sales 2024'!$G$4:$G$2819,$A13,'EIA-861 Sales 2024'!$Z$4:$Z$2819,"unclassified") -> 0 | E13: =B13+C13+D13 -> 8691377 | F13: =IF($E13=0,0,B13/$E13) -> 1 | G13: =IF($E13=0,0,C13/$E13) -> 0
... A52: WY | B52: =SUMIFS('EIA-861 Sales 2024'!$Y$4:$Y$2819,'EIA-861 Sales 2024'!$G$4:$G$2819,$A52,'EIA-861 Sales 2024'!$Z$4:$Z$2819,"cost_service") -> 16066797 | C52: =SUMIFS('EIA-861 Sales 2024'!$Y$4:$Y$2819,'EIA-861 Sales 2024'!$G$4:$G$2819,$A52,'EIA-861 Sales 2024'!$Z$4:$Z$2819,"procurement") -> 0 | D52: =SUMIFS('EIA-861 Sales 2024'!$Y$4:$Y$2819,'EIA-861 Sales 2024'!$G$4:$G$2819,$A52,'EIA-861 Sales 2024'!$Z$4:$Z$2819,"unclassified") -> 0 | E52: =B52+C52+D52 -> 16066797 | F52: =IF($E52=0,0,B52/$E52) -> 1 | G52: =IF($E52=0,0,C52/$E52) -> 0

Sheet US National
A1: region | B1: cost_service_mwh | C1: procurement_mwh | D1: excluded_mwh | E1: total_mwh | F1: share_cost_service | G1: share_procurement
A2: US | B2: =SUMIFS('EIA-861 Sales 2024'!$Y$4:$Y$2819,'EIA-861 Sales 2024'!$Z$4:$Z$2819,"cost_service") -> 2669507383 | C2: =SUMIFS('EIA-861 Sales 2024'!$Y$4:$Y$2819,'EIA-861 Sales 2024'!$Z$4:$Z$2819,"procurement") -> 1165882590 | D2: =SUMIFS('EIA-861 Sales 2024'!$Y$4:$Y$2819,'EIA-861 Sales 2024'!$Z$4:$Z$2819,"excluded") -> 733508256 | E2: =B2+C2 -> 3835389973 | F2: =IF($E2=0,0,B2/$E2) -> 0.69601981 | G2: =IF($E2=0,0,C2/$E2) -> 0.30398019

Sheet SoEDtICoS
A1: Unit: dimensionless (% of demand) | B1: 2021 | C1: 2022 | D1: 2023 | E1: 2024 | F1: 2025 | G1: 2026 | H1: 2027 | I1: 2028 | J1: 2029 | K1: 2030 | L1: 2031 | M1: 2032 | N1: 2033 | O1: 2034 | P1: 2035 | Q1: 2036 | R1: 2037 | S1: 2038 | T1: 2039 | U1: 2040 | V1: 2041 | W1: 2042 | X1: 2043 | Y1: 2044 | Z1: 2045 | AA1: 2046 | AB1: 2047 | AC1: 2048 | AD1: 2049 | AE1: 2050
A2: Share that is Cost of Service | B2: =ROUND('US National'!$F$2,3) -> 0.696 | C2: =ROUND('US National'!$F$2,3) -> 0.696 | D2: =ROUND('US National'!$F$2,3) -> 0.696 | E2: =ROUND('US National'!$F$2,3) -> 0.696 | F2: =ROUND('US National'!$F$2,3) -> 0.696 | G2: =ROUND('US National'!$F$2,3) -> 0.696 | H2: =ROUND('US National'!$F$2,3) -> 0.696 | I2: =ROUND('US National'!$F$2,3) -> 0.696 | ... AE2: =ROUND('US National'!$F$2,3) -> 0.696
