Workbook

Sheet About
A1: TTS Transportation Technology Shareweights
A3: Source: | B3: Onroad modes
B4: See supporting Python calibration file and excel/csv files in this folder.
B5: Given logit exponents from the GCAM model, we use a solver to solve
B6: for historical shareweights given recent sales data. We then allow the
B7: shareweights for BEV and PHEV technologies to grow, as explained below.
B9: passenger rail
B10: See data from EPS file trans/SYVbT
A12: Notes
A13: This variable provides the shareweights used in the modified logit equation for vehicle
A14: technology selection. We base them on estimated potential maximum sales shares in each year.
A15: For more on this, see the "Unmodified Logit" equation description at:
A16: https://jgcri.github.io/gcam-doc/choice.html
A18: When adapting the model to a new country or region, it may be helpful
A19: to calibrate this variable after replacing the input data for other variables.
A21: The solver we used is saved as transport_calibration.py in the TTS folder. It is set up
A22: to take in data on the cost per thing*mile for each vehicle type (taken from Vensim),
A23: the observed sales share (from historical data sets), the exponent (trans/TTLE), and
A24: the number of vehicles of that type demanded each year (taken from Vensim).
A25: The file calibration_parameters specifies all those pieces of input data. Sources for the
... A37: such as those from ICCT.
B39: passenger LDVs
B40: The historical data we use for calibration is for states that do not have
B41: their own vehicle standards (ACCI) that put an additional constraint on sales
B42: that is not purely cost-based. This gives us our 2024 and 2025 shareweights.
B44: passenger rail
B45: We use calculated data from SYVbT to calculate the historical sales shares.
A55: Calibration record (2026-10-16)
A56: On-road anchors (Data tab columns D-E) rewritten by calibration/steps/03-trans-shareweights/solve_base_year.py:
A57: logit inversion at the start year from 'BAU New Vehicle Cost per Mile' in the BAU export and observed technology shares
A58: (calibration/benchmarks/vehicle-technology-shares.csv), ZEV-mandate correction for passenger LDVs (3 passes), then the
A59: existing s-curve formulas carry the trajectory to the unchanged 2050 targets. Confirmed by a headless run after the third pass.
A60: TTS-LDVs-frgt hydrogen vehicle: weight set to 0 - observed share unreachable at placeholder cost inputs (step 3a); provisional
A61: TTS-HDVs-frgt hydrogen vehicle: weight set to 0 - observed share unreachable at placeholder cost inputs (step 3a); provisional
A62: TTS-LDVs-psgr natural gas vehicle: IT-year cell set to =E11 (was an s-curve formula)
A63: TTS-LDVs-psgr gasoline vehicle: IT-year cell set to =E12 (was an s-curve formula)
A64: TTS-LDVs-psgr diesel vehicle: IT-year cell set to =E13 (was an s-curve formula)
A65: TTS-LDVs-psgr plugin hybrid vehicle: 2050 target pinned at its pre-calibration value 0.102391 (was =D14/D10*F10)
A66: TTS-LDVs-psgr LPG vehicle: IT-year cell set to =E15 (was an s-curve formula)
... A70: Passenger rail (2026-10-19): Data!E52 and E55 now read the solved shareweights on 'Calibration rail' (step 3a, observed 2015-2024 deliveries, 8.3% diesel) instead of the start-year fleet shares; pasted SYVbT-passenger refreshed.

Sheet Calibration rail
A1: Passenger-rail shareweights at the start year, solved by eps-calibrate step 3a (solve_base_year.py: logit inversion from 'BAU New Vehicle Cost per Mile' in a BAU export and the observed new-vehicle shares), 2026-10-19. Observed shares: vehicles delivered 2015-2024, NTD transit + Amtrak, 376 diesel of 4,528 (vehicle-vintaging-4.0.7/data/fleet-utilization/ntd-energy/rail_purchase_share.py). Held flat through 2050.
A3: technology | B3: observed share of new vehicles | C3: shareweight (solved)
A4: battery electric vehicle | B4: 0.917 | C4: 1
A5: diesel vehicle | B5: 0.083 | C5: 0.10755845

Sheet SYVbT-passenger
A1: Number of Vehicles | B1: battery electric vehicle | C1: natural gas vehicle | D1: gasoline vehicle | E1: diesel vehicle | F1: plugin hybrid vehicle | G1: LPG vehicle | H1: hydrogen vehicle
A2: LDVs | B2: 4769953 | C2: 14506 | D2: 257649823 | E2: 1553093 | F2: 1417825 | G2: 13525 | H2: 17094
A3: HDVs | B3: 2445 | C3: 67549 | D3: 53161 | E3: 422350 | F3: 0 | G3: 24746 | H3: 91
A4: aircraft | B4: 0 | C4: 0 | D4: 0 | E4: 6767 | F4: 0 | G4: 0 | H4: 0
A5: rail | B5: 18776 | C5: 0 | D5: 0 | E5: 6889 | F5: 0 | G5: 0 | H5: 0
A6: ships | B6: 0 | C6: 0 | D6: 9385963 | E6: 2288110 | F6: 0 | G6: 0 | H6: 0
A7: motorbikes | B7: 0 | C7: 0 | D7: 9261249 | E7: 0 | F7: 0 | G7: 0 | H7: 0

Sheet Data
A1: We use sigmoidal interpolation for relatively new technologies (battery electric vehicles, natural gas vehicles, and | H1: Sigmoidal Curve Values for Vehicle Technologies (all except battery electric passenger LDVs) | N1: Sigmoidal Curve Values for battery electric passenger LDV Technologies | Q1: Sigmoidal Curve Values for battery electric freight HDV Technologies | T1: Sigmoidal Curve Values for PHEV passenger LDV Technologies | W1: Sigmoidal Curve Values for battery electric/PHEV passenger HDV and freight LDV Technologies
A2: plugin hybrid vehicles) and linear interpolation for other vehicle technologies. Technologies with constant values | H2: L | I2: 1 | N2: L | O2: 1 | Q2: L | R2: 1 | T2: L | U2: 1 | W2: L | X2: 1
A3: do not require interpolation. | H3: k | I3: -0.3 | N3: k | O3: -0.3 | P3: -0.35 | Q3: k | R3: -0.3 | T3: k | U3: -0.4 | W3: k | X3: -0.3
A4: The values (to the right) that define the shape of the sigmoidal curve are assumptions, which neatly approach the | H4: Xo | I4: -16 | N4: Xo | O4: -11 | P4: -10 | Q4: Xo | R4: -12 | T4: Xo | U4: -11 | W4: Xo | X4: -14
A5: specified 2050 max sales share with a flattening curve. (Of course, linear interpolation is similarly an assumption.)
E6: Max Potential Sales Share | F6: Max Potential Sales Share | G6: Interpolation Method
C7: Psgr LDVs only | E7: 2020 | F7: 2050
D8: 2024 and 2025 shareweights for onroad vehicle types copied/pasted from the Python solver outputs, explained on the About page | G8: *for passenger LDVs only, see Assumptions page
A9: Vehicle Type | B9: Cargo Type | C9: Vehicle Technology | D9: 2024 | E9: 2025 | F9: 2050 | I9: 2024 | J9: =E9 -> 2025 | K9: =J9+1 -> 2026 | L9: =K9+1 -> 2027 | M9: =L9+1 -> 2028 | N9: =M9+1 -> 2029 | O9: =N9+1 -> 2030 | P9: =O9+1 -> 2031 | Q9: =P9+1 -> 2032 | R9: =Q9+1 -> 2033 | ... AI9: =AH9+1 -> 2050
A10: LDVs | B10: passenger | C10: battery electric vehicle | D10: 0.14828895 | E10: 0.14828895 | F10: 1 | G10: =IF(E10=F10,"n/a",IF(OR(C10="battery electric vehicle",C10="natural gas vehicle",C10="plugin hybrid vehicle"),"s-curve","linear")) -> s-curve | I10: =D10 -> 0.14828895 | J10: =E10 -> 0.14828895 | K10: =IF($G10="s-curve",$E10+($F10-$E10)*$O$2/(1+EXP($O$3*(COUNT($K$9:K$9)+$O$4))),TREND($E10:$F10,$E$9:$F$9,K$9)) -> 0.18868209 | L10: =IF($G10="s-curve",$E10+($F10-$E10)*$O$2/(1+EXP($O$3*(COUNT($K$9:L$9)+$O$4))),TREND($E10:$F10,$E$9:$F$9,L$9)) -> 0.20192405 | M10: =IF($G10="s-curve",$E10+($F10-$E10)*$O$2/(1+EXP($O$3*(COUNT($K$9:M$9)+$O$4))),TREND($E10:$F10,$E$9:$F$9,M$9)) -> 0.21912805 | N10: =IF($G10="s-curve",$E10+($F10-$E10)*$O$2/(1+EXP($O$3*(COUNT($K$9:N$9)+$O$4))),TREND($E10:$F10,$E$9:$F$9,N$9)) -> 0.24120792 | O10: =IF($G10="s-curve",$E10+($F10-$E10)*$O$2/(1+EXP($O$3*(COUNT($K$9:O$9)+$O$4))),TREND($E10:$F10,$E$9:$F$9,O$9)) -> 0.26910507 | P10: =IF($G10="s-curve",$E10+($F10-$E10)*$O$2/(1+EXP($O$3*(COUNT($K$9:P$9)+$O$4))),TREND($E10:$F10,$E$9:$F$9,P$9)) -> 0.30366278 | Q10: =IF($G10="s-curve",$E10+($F10-$E10)*$O$2/(1+EXP($O$3*(COUNT($K$9:Q$9)+$O$4))),TREND($E10:$F10,$E$9:$F$9,Q$9)) -> 0.34543895 | R10: =IF($G10="s-curve",$E10+($F10-$E10)*$O$2/(1+EXP($O$3*(COUNT($K$9:R$9)+$O$4))),TREND($E10:$F10,$E$9:$F$9,R$9)) -> 0.39447645 | ... AI10: =IF($G10="s-curve",$E10+($F10-$E10)*$O$2/(1+EXP($O$3*(COUNT($K$9:AI$9)+$O$4))),TREND($E10:$F10,$E$9:$F$9,AI$9)) -> 0.98741679
C11: natural gas vehicle | D11: 0.00010097 | E11: 0.00010097 | F11: =E11 -> 0.00010097 | G11: =IF(E11=F11,"n/a",IF(OR(C11="battery electric vehicle",C11="natural gas vehicle",C11="plugin hybrid vehicle"),"s-curve","linear")) -> n/a | I11: =E11 -> 0.00010097 | J11: =E11 -> 0.00010097 | K11: =IF($G11="s-curve",$E11+($F11-$E11)*$I$2/(1+EXP($I$3*(COUNT($I$9:K$9)+$I$4))),TREND($E11:$F11,$E$9:$F$9,K$9)) -> 0.00010097 | L11: =IF($G11="s-curve",$E11+($F11-$E11)*$I$2/(1+EXP($I$3*(COUNT($I$9:L$9)+$I$4))),TREND($E11:$F11,$E$9:$F$9,L$9)) -> 0.00010097 | M11: =IF($G11="s-curve",$E11+($F11-$E11)*$I$2/(1+EXP($I$3*(COUNT($I$9:M$9)+$I$4))),TREND($E11:$F11,$E$9:$F$9,M$9)) -> 0.00010097 | N11: =IF($G11="s-curve",$E11+($F11-$E11)*$I$2/(1+EXP($I$3*(COUNT($I$9:N$9)+$I$4))),TREND($E11:$F11,$E$9:$F$9,N$9)) -> 0.00010097 | O11: =IF($G11="s-curve",$E11+($F11-$E11)*$I$2/(1+EXP($I$3*(COUNT($I$9:O$9)+$I$4))),TREND($E11:$F11,$E$9:$F$9,O$9)) -> 0.00010097 | P11: =IF($G11="s-curve",$E11+($F11-$E11)*$I$2/(1+EXP($I$3*(COUNT($I$9:P$9)+$I$4))),TREND($E11:$F11,$E$9:$F$9,P$9)) -> 0.00010097 | Q11: =IF($G11="s-curve",$E11+($F11-$E11)*$I$2/(1+EXP($I$3*(COUNT($I$9:Q$9)+$I$4))),TREND($E11:$F11,$E$9:$F$9,Q$9)) -> 0.00010097 | R11: =IF($G11="s-curve",$E11+($F11-$E11)*$I$2/(1+EXP($I$3*(COUNT($I$9:R$9)+$I$4))),TREND($E11:$F11,$E$9:$F$9,R$9)) -> 0.00010097 | ... AI11: =IF($G11="s-curve",$E11+($F11-$E11)*$I$2/(1+EXP($I$3*(COUNT($I$9:AI$9)+$I$4))),TREND($E11:$F11,$E$9:$F$9,AI$9)) -> 0.00010097
C12: gasoline vehicle | D12: 1 | E12: 1 | F12: 1 | G12: =IF(E12=F12,"n/a",IF(OR(C12="battery electric vehicle",C12="natural gas vehicle",C12="plugin hybrid vehicle"),"s-curve","linear")) -> n/a | I12: =E12 -> 1 | J12: =E12 -> 1 | K12: =IF($G12="s-curve",$E12+($F12-$E12)*$I$2/(1+EXP($I$3*(COUNT($I$9:K$9)+$I$4))),TREND($E12:$F12,$E$9:$F$9,K$9)) -> 1 | L12: =IF($G12="s-curve",$E12+($F12-$E12)*$I$2/(1+EXP($I$3*(COUNT($I$9:L$9)+$I$4))),TREND($E12:$F12,$E$9:$F$9,L$9)) -> 1 | M12: =IF($G12="s-curve",$E12+($F12-$E12)*$I$2/(1+EXP($I$3*(COUNT($I$9:M$9)+$I$4))),TREND($E12:$F12,$E$9:$F$9,M$9)) -> 1 | N12: =IF($G12="s-curve",$E12+($F12-$E12)*$I$2/(1+EXP($I$3*(COUNT($I$9:N$9)+$I$4))),TREND($E12:$F12,$E$9:$F$9,N$9)) -> 1 | O12: =IF($G12="s-curve",$E12+($F12-$E12)*$I$2/(1+EXP($I$3*(COUNT($I$9:O$9)+$I$4))),TREND($E12:$F12,$E$9:$F$9,O$9)) -> 1 | P12: =IF($G12="s-curve",$E12+($F12-$E12)*$I$2/(1+EXP($I$3*(COUNT($I$9:P$9)+$I$4))),TREND($E12:$F12,$E$9:$F$9,P$9)) -> 1 | Q12: =IF($G12="s-curve",$E12+($F12-$E12)*$I$2/(1+EXP($I$3*(COUNT($I$9:Q$9)+$I$4))),TREND($E12:$F12,$E$9:$F$9,Q$9)) -> 1 | R12: =IF($G12="s-curve",$E12+($F12-$E12)*$I$2/(1+EXP($I$3*(COUNT($I$9:R$9)+$I$4))),TREND($E12:$F12,$E$9:$F$9,R$9)) -> 1 | ... AI12: =IF($G12="s-curve",$E12+($F12-$E12)*$I$2/(1+EXP($I$3*(COUNT($I$9:AI$9)+$I$4))),TREND($E12:$F12,$E$9:$F$9,AI$9)) -> 1
C13: diesel vehicle | D13: 0.06738296 | E13: 0.06738296 | F13: =E13 -> 0.06738296 | G13: =IF(E13=F13,"n/a",IF(OR(C13="battery electric vehicle",C13="natural gas vehicle",C13="plugin hybrid vehicle"),"s-curve","linear")) -> n/a | I13: =E13 -> 0.06738296 | J13: =E13 -> 0.06738296 | K13: =IF($G13="s-curve",$E13+($F13-$E13)*$I$2/(1+EXP($I$3*(COUNT($I$9:K$9)+$I$4))),TREND($E13:$F13,$E$9:$F$9,K$9)) -> 0.06738296 | L13: =IF($G13="s-curve",$E13+($F13-$E13)*$I$2/(1+EXP($I$3*(COUNT($I$9:L$9)+$I$4))),TREND($E13:$F13,$E$9:$F$9,L$9)) -> 0.06738296 | M13: =IF($G13="s-curve",$E13+($F13-$E13)*$I$2/(1+EXP($I$3*(COUNT($I$9:M$9)+$I$4))),TREND($E13:$F13,$E$9:$F$9,M$9)) -> 0.06738296 | N13: =IF($G13="s-curve",$E13+($F13-$E13)*$I$2/(1+EXP($I$3*(COUNT($I$9:N$9)+$I$4))),TREND($E13:$F13,$E$9:$F$9,N$9)) -> 0.06738296 | O13: =IF($G13="s-curve",$E13+($F13-$E13)*$I$2/(1+EXP($I$3*(COUNT($I$9:O$9)+$I$4))),TREND($E13:$F13,$E$9:$F$9,O$9)) -> 0.06738296 | P13: =IF($G13="s-curve",$E13+($F13-$E13)*$I$2/(1+EXP($I$3*(COUNT($I$9:P$9)+$I$4))),TREND($E13:$F13,$E$9:$F$9,P$9)) -> 0.06738296 | Q13: =IF($G13="s-curve",$E13+($F13-$E13)*$I$2/(1+EXP($I$3*(COUNT($I$9:Q$9)+$I$4))),TREND($E13:$F13,$E$9:$F$9,Q$9)) -> 0.06738296 | R13: =IF($G13="s-curve",$E13+($F13-$E13)*$I$2/(1+EXP($I$3*(COUNT($I$9:R$9)+$I$4))),TREND($E13:$F13,$E$9:$F$9,R$9)) -> 0.06738296 | ... AI13: =IF($G13="s-curve",$E13+($F13-$E13)*$I$2/(1+EXP($I$3*(COUNT($I$9:AI$9)+$I$4))),TREND($E13:$F13,$E$9:$F$9,AI$9)) -> 0.06738296
C14: plugin hybrid vehicle | D14: 0.014073499 | E14: 0.014073499 | F14: 0.10239067 | G14: =IF(E14=F14,"n/a",IF(OR(C14="battery electric vehicle",C14="natural gas vehicle",C14="plugin hybrid vehicle",C14="hydrogen vehicle"),"s-curve","linear")) -> s-curve | I14: =D14 -> 0.014073499 | J14: =E14 -> 0.014073499 | K14: =IF($G14="s-curve",$E14+($F14-$E14)*$U$2/(1+EXP($U$3*(COUNT($I$9:K$9)+$U$4))),TREND($E14:$F14,$E$9:$F$9,K$9)) -> 0.017532505 | L14: =IF($G14="s-curve",$E14+($F14-$E14)*$U$2/(1+EXP($U$3*(COUNT($I$9:L$9)+$U$4))),TREND($E14:$F14,$E$9:$F$9,L$9)) -> 0.019136208 | M14: =IF($G14="s-curve",$E14+($F14-$E14)*$U$2/(1+EXP($U$3*(COUNT($I$9:M$9)+$U$4))),TREND($E14:$F14,$E$9:$F$9,M$9)) -> 0.021419076 | N14: =IF($G14="s-curve",$E14+($F14-$E14)*$U$2/(1+EXP($U$3*(COUNT($I$9:N$9)+$U$4))),TREND($E14:$F14,$E$9:$F$9,N$9)) -> 0.024601163 | O14: =IF($G14="s-curve",$E14+($F14-$E14)*$U$2/(1+EXP($U$3*(COUNT($I$9:O$9)+$U$4))),TREND($E14:$F14,$E$9:$F$9,O$9)) -> 0.028909159 | P14: =IF($G14="s-curve",$E14+($F14-$E14)*$U$2/(1+EXP($U$3*(COUNT($I$9:P$9)+$U$4))),TREND($E14:$F14,$E$9:$F$9,P$9)) -> 0.034516734 | Q14: =IF($G14="s-curve",$E14+($F14-$E14)*$U$2/(1+EXP($U$3*(COUNT($I$9:Q$9)+$U$4))),TREND($E14:$F14,$E$9:$F$9,Q$9)) -> 0.041454075 | R14: =IF($G14="s-curve",$E14+($F14-$E14)*$U$2/(1+EXP($U$3*(COUNT($I$9:R$9)+$U$4))),TREND($E14:$F14,$E$9:$F$9,R$9)) -> 0.049516268 | ... AI14: =IF($G14="s-curve",$E14+($F14-$E14)*$U$2/(1+EXP($U$3*(COUNT($I$9:AI$9)+$U$4))),TREND($E14:$F14,$E$9:$F$9,AI$9)) -> 0.10224417
C15: LPG vehicle | D15: 0 | E15: 0 | F15: =E15 -> 0 | G15: =IF(E15=F15,"n/a",IF(OR(C15="battery electric vehicle",C15="natural gas vehicle",C15="plugin hybrid vehicle",C15="hydrogen vehicle"),"s-curve","linear")) -> n/a | I15: =E15 -> 0 | J15: =E15 -> 0 | K15: =IF($G15="s-curve",$E15+($F15-$E15)*$I$2/(1+EXP($I$3*(COUNT($I$9:K$9)+$I$4))),TREND($E15:$F15,$E$9:$F$9,K$9)) -> 0 | L15: =IF($G15="s-curve",$E15+($F15-$E15)*$I$2/(1+EXP($I$3*(COUNT($I$9:L$9)+$I$4))),TREND($E15:$F15,$E$9:$F$9,L$9)) -> 0 | M15: =IF($G15="s-curve",$E15+($F15-$E15)*$I$2/(1+EXP($I$3*(COUNT($I$9:M$9)+$I$4))),TREND($E15:$F15,$E$9:$F$9,M$9)) -> 0 | N15: =IF($G15="s-curve",$E15+($F15-$E15)*$I$2/(1+EXP($I$3*(COUNT($I$9:N$9)+$I$4))),TREND($E15:$F15,$E$9:$F$9,N$9)) -> 0 | O15: =IF($G15="s-curve",$E15+($F15-$E15)*$I$2/(1+EXP($I$3*(COUNT($I$9:O$9)+$I$4))),TREND($E15:$F15,$E$9:$F$9,O$9)) -> 0 | P15: =IF($G15="s-curve",$E15+($F15-$E15)*$I$2/(1+EXP($I$3*(COUNT($I$9:P$9)+$I$4))),TREND($E15:$F15,$E$9:$F$9,P$9)) -> 0 | Q15: =IF($G15="s-curve",$E15+($F15-$E15)*$I$2/(1+EXP($I$3*(COUNT($I$9:Q$9)+$I$4))),TREND($E15:$F15,$E$9:$F$9,Q$9)) -> 0 | R15: =IF($G15="s-curve",$E15+($F15-$E15)*$I$2/(1+EXP($I$3*(COUNT($I$9:R$9)+$I$4))),TREND($E15:$F15,$E$9:$F$9,R$9)) -> 0 | ... AI15: =IF($G15="s-curve",$E15+($F15-$E15)*$I$2/(1+EXP($I$3*(COUNT($I$9:AI$9)+$I$4))),TREND($E15:$F15,$E$9:$F$9,AI$9)) -> 0
C16: hydrogen vehicle | D16: 0 | E16: 0 | F16: =E16 -> 0 | G16: =IF(E16=F16,"n/a",IF(OR(C16="battery electric vehicle",C16="natural gas vehicle",C16="plugin hybrid vehicle",C16="hydrogen vehicle"),"s-curve","linear")) -> n/a | I16: =E16 -> 0 | J16: =E16 -> 0 | K16: =IF($G16="s-curve",$E16+($F16-$E16)*$I$2/(1+EXP($I$3*(COUNT($I$9:K$9)+$I$4))),TREND($E16:$F16,$E$9:$F$9,K$9)) -> 0 | L16: =IF($G16="s-curve",$E16+($F16-$E16)*$I$2/(1+EXP($I$3*(COUNT($I$9:L$9)+$I$4))),TREND($E16:$F16,$E$9:$F$9,L$9)) -> 0 | M16: =IF($G16="s-curve",$E16+($F16-$E16)*$I$2/(1+EXP($I$3*(COUNT($I$9:M$9)+$I$4))),TREND($E16:$F16,$E$9:$F$9,M$9)) -> 0 | N16: =IF($G16="s-curve",$E16+($F16-$E16)*$I$2/(1+EXP($I$3*(COUNT($I$9:N$9)+$I$4))),TREND($E16:$F16,$E$9:$F$9,N$9)) -> 0 | O16: =IF($G16="s-curve",$E16+($F16-$E16)*$I$2/(1+EXP($I$3*(COUNT($I$9:O$9)+$I$4))),TREND($E16:$F16,$E$9:$F$9,O$9)) -> 0 | P16: =IF($G16="s-curve",$E16+($F16-$E16)*$I$2/(1+EXP($I$3*(COUNT($I$9:P$9)+$I$4))),TREND($E16:$F16,$E$9:$F$9,P$9)) -> 0 | Q16: =IF($G16="s-curve",$E16+($F16-$E16)*$I$2/(1+EXP($I$3*(COUNT($I$9:Q$9)+$I$4))),TREND($E16:$F16,$E$9:$F$9,Q$9)) -> 0 | R16: =IF($G16="s-curve",$E16+($F16-$E16)*$I$2/(1+EXP($I$3*(COUNT($I$9:R$9)+$I$4))),TREND($E16:$F16,$E$9:$F$9,R$9)) -> 0 | ... AI16: =IF($G16="s-curve",$E16+($F16-$E16)*$I$2/(1+EXP($I$3*(COUNT($I$9:AI$9)+$I$4))),TREND($E16:$F16,$E$9:$F$9,AI$9)) -> 0
A17: LDVs | B17: freight | C17: battery electric vehicle | D17: 0.32863913 | E17: 0.32863913 | F17: 0.3 | G17: =IF(E17=F17,"n/a",IF(OR(C17="battery electric vehicle",C17="natural gas vehicle",C17="plugin hybrid vehicle"),"s-curve","linear")) -> s-curve | I17: =D17 -> 0.32863913 | J17: =E17 -> 0.32863913 | K17: =IF($G17="s-curve",$E17+($F17-$E17)*$X$2/(1+EXP($X$3*(COUNT($I$9:K$9)+$X$4))),TREND($E17:$F17,$E$9:$F$9,K$9)) -> 0.3276204 | L17: =IF($G17="s-curve",$E17+($F17-$E17)*$X$2/(1+EXP($X$3*(COUNT($I$9:L$9)+$X$4))),TREND($E17:$F17,$E$9:$F$9,L$9)) -> 0.32728089 | M17: =IF($G17="s-curve",$E17+($F17-$E17)*$X$2/(1+EXP($X$3*(COUNT($I$9:M$9)+$X$4))),TREND($E17:$F17,$E$9:$F$9,M$9)) -> 0.32683563 | N17: =IF($G17="s-curve",$E17+($F17-$E17)*$X$2/(1+EXP($X$3*(COUNT($I$9:N$9)+$X$4))),TREND($E17:$F17,$E$9:$F$9,N$9)) -> 0.32625713 | O17: =IF($G17="s-curve",$E17+($F17-$E17)*$X$2/(1+EXP($X$3*(COUNT($I$9:O$9)+$X$4))),TREND($E17:$F17,$E$9:$F$9,O$9)) -> 0.32551469 | P17: =IF($G17="s-curve",$E17+($F17-$E17)*$X$2/(1+EXP($X$3*(COUNT($I$9:P$9)+$X$4))),TREND($E17:$F17,$E$9:$F$9,P$9)) -> 0.32457664 | Q17: =IF($G17="s-curve",$E17+($F17-$E17)*$X$2/(1+EXP($X$3*(COUNT($I$9:Q$9)+$X$4))),TREND($E17:$F17,$E$9:$F$9,Q$9)) -> 0.32341462 | R17: =IF($G17="s-curve",$E17+($F17-$E17)*$X$2/(1+EXP($X$3*(COUNT($I$9:R$9)+$X$4))),TREND($E17:$F17,$E$9:$F$9,R$9)) -> 0.32200988 | ... AI17: =IF($G17="s-curve",$E17+($F17-$E17)*$X$2/(1+EXP($X$3*(COUNT($I$9:AI$9)+$X$4))),TREND($E17:$F17,$E$9:$F$9,AI$9)) -> 0.30056821
C18: natural gas vehicle | D18: 0.25047807 | E18: 0.25047807 | F18: =E18 -> 0.25047807 | G18: linear | I18: =D18 -> 0.25047807 | J18: =E18 -> 0.25047807 | K18: =IF($G18="s-curve",$E18+($F18-$E18)*$I$2/(1+EXP($I$3*(COUNT($I$9:K$9)+$I$4))),TREND($E18:$F18,$E$9:$F$9,K$9)) -> 0.25047807 | L18: =IF($G18="s-curve",$E18+($F18-$E18)*$I$2/(1+EXP($I$3*(COUNT($I$9:L$9)+$I$4))),TREND($E18:$F18,$E$9:$F$9,L$9)) -> 0.25047807 | M18: =IF($G18="s-curve",$E18+($F18-$E18)*$I$2/(1+EXP($I$3*(COUNT($I$9:M$9)+$I$4))),TREND($E18:$F18,$E$9:$F$9,M$9)) -> 0.25047807 | N18: =IF($G18="s-curve",$E18+($F18-$E18)*$I$2/(1+EXP($I$3*(COUNT($I$9:N$9)+$I$4))),TREND($E18:$F18,$E$9:$F$9,N$9)) -> 0.25047807 | O18: =IF($G18="s-curve",$E18+($F18-$E18)*$I$2/(1+EXP($I$3*(COUNT($I$9:O$9)+$I$4))),TREND($E18:$F18,$E$9:$F$9,O$9)) -> 0.25047807 | P18: =IF($G18="s-curve",$E18+($F18-$E18)*$I$2/(1+EXP($I$3*(COUNT($I$9:P$9)+$I$4))),TREND($E18:$F18,$E$9:$F$9,P$9)) -> 0.25047807 | Q18: =IF($G18="s-curve",$E18+($F18-$E18)*$I$2/(1+EXP($I$3*(COUNT($I$9:Q$9)+$I$4))),TREND($E18:$F18,$E$9:$F$9,Q$9)) -> 0.25047807 | R18: =IF($G18="s-curve",$E18+($F18-$E18)*$I$2/(1+EXP($I$3*(COUNT($I$9:R$9)+$I$4))),TREND($E18:$F18,$E$9:$F$9,R$9)) -> 0.25047807 | ... AI18: =IF($G18="s-curve",$E18+($F18-$E18)*$I$2/(1+EXP($I$3*(COUNT($I$9:AI$9)+$I$4))),TREND($E18:$F18,$E$9:$F$9,AI$9)) -> 0.25047807
C19: gasoline vehicle | D19: 0.76148266 | E19: 0.76148266 | F19: =E19 -> 0.76148266 | G19: =IF(E19=F19,"n/a",IF(OR(C19="battery electric vehicle",C19="natural gas vehicle",C19="plugin hybrid vehicle"),"s-curve","linear")) -> n/a | I19: =D19 -> 0.76148266 | J19: =E19 -> 0.76148266 | K19: =IF($G19="s-curve",$E19+($F19-$E19)*$I$2/(1+EXP($I$3*(COUNT($I$9:K$9)+$I$4))),TREND($E19:$F19,$E$9:$F$9,K$9)) -> 0.76148266 | L19: =IF($G19="s-curve",$E19+($F19-$E19)*$I$2/(1+EXP($I$3*(COUNT($I$9:L$9)+$I$4))),TREND($E19:$F19,$E$9:$F$9,L$9)) -> 0.76148266 | M19: =IF($G19="s-curve",$E19+($F19-$E19)*$I$2/(1+EXP($I$3*(COUNT($I$9:M$9)+$I$4))),TREND($E19:$F19,$E$9:$F$9,M$9)) -> 0.76148266 | N19: =IF($G19="s-curve",$E19+($F19-$E19)*$I$2/(1+EXP($I$3*(COUNT($I$9:N$9)+$I$4))),TREND($E19:$F19,$E$9:$F$9,N$9)) -> 0.76148266 | O19: =IF($G19="s-curve",$E19+($F19-$E19)*$I$2/(1+EXP($I$3*(COUNT($I$9:O$9)+$I$4))),TREND($E19:$F19,$E$9:$F$9,O$9)) -> 0.76148266 | P19: =IF($G19="s-curve",$E19+($F19-$E19)*$I$2/(1+EXP($I$3*(COUNT($I$9:P$9)+$I$4))),TREND($E19:$F19,$E$9:$F$9,P$9)) -> 0.76148266 | Q19: =IF($G19="s-curve",$E19+($F19-$E19)*$I$2/(1+EXP($I$3*(COUNT($I$9:Q$9)+$I$4))),TREND($E19:$F19,$E$9:$F$9,Q$9)) -> 0.76148266 | R19: =IF($G19="s-curve",$E19+($F19-$E19)*$I$2/(1+EXP($I$3*(COUNT($I$9:R$9)+$I$4))),TREND($E19:$F19,$E$9:$F$9,R$9)) -> 0.76148266 | ... AI19: =IF($G19="s-curve",$E19+($F19-$E19)*$I$2/(1+EXP($I$3*(COUNT($I$9:AI$9)+$I$4))),TREND($E19:$F19,$E$9:$F$9,AI$9)) -> 0.76148266
C20: diesel vehicle | D20: 1 | E20: 1 | F20: 1 | G20: =IF(E20=F20,"n/a",IF(OR(C20="battery electric vehicle",C20="natural gas vehicle",C20="plugin hybrid vehicle"),"s-curve","linear")) -> n/a | I20: =D20 -> 1 | J20: =E20 -> 1 | K20: =IF($G20="s-curve",$E20+($F20-$E20)*$I$2/(1+EXP($I$3*(COUNT($I$9:K$9)+$I$4))),TREND($E20:$F20,$E$9:$F$9,K$9)) -> 1 | L20: =IF($G20="s-curve",$E20+($F20-$E20)*$I$2/(1+EXP($I$3*(COUNT($I$9:L$9)+$I$4))),TREND($E20:$F20,$E$9:$F$9,L$9)) -> 1 | M20: =IF($G20="s-curve",$E20+($F20-$E20)*$I$2/(1+EXP($I$3*(COUNT($I$9:M$9)+$I$4))),TREND($E20:$F20,$E$9:$F$9,M$9)) -> 1 | N20: =IF($G20="s-curve",$E20+($F20-$E20)*$I$2/(1+EXP($I$3*(COUNT($I$9:N$9)+$I$4))),TREND($E20:$F20,$E$9:$F$9,N$9)) -> 1 | O20: =IF($G20="s-curve",$E20+($F20-$E20)*$I$2/(1+EXP($I$3*(COUNT($I$9:O$9)+$I$4))),TREND($E20:$F20,$E$9:$F$9,O$9)) -> 1 | P20: =IF($G20="s-curve",$E20+($F20-$E20)*$I$2/(1+EXP($I$3*(COUNT($I$9:P$9)+$I$4))),TREND($E20:$F20,$E$9:$F$9,P$9)) -> 1 | Q20: =IF($G20="s-curve",$E20+($F20-$E20)*$I$2/(1+EXP($I$3*(COUNT($I$9:Q$9)+$I$4))),TREND($E20:$F20,$E$9:$F$9,Q$9)) -> 1 | R20: =IF($G20="s-curve",$E20+($F20-$E20)*$I$2/(1+EXP($I$3*(COUNT($I$9:R$9)+$I$4))),TREND($E20:$F20,$E$9:$F$9,R$9)) -> 1 | ... AI20: =IF($G20="s-curve",$E20+($F20-$E20)*$I$2/(1+EXP($I$3*(COUNT($I$9:AI$9)+$I$4))),TREND($E20:$F20,$E$9:$F$9,AI$9)) -> 1
C21: plugin hybrid vehicle | D21: 0.001003192 | E21: 0.001003192 | F21: 0.0012357083 | G21: s-curve | I21: =D21 -> 0.001003192 | J21: =E21 -> 0.001003192 | K21: =IF($G21="s-curve",$E21+($F21-$E21)*$X$2/(1+EXP($X$3*(COUNT($I$9:K$9)+$X$4))),TREND($E21:$F21,$E$9:$F$9,K$9)) -> 0.0010114629 | L21: =IF($G21="s-curve",$E21+($F21-$E21)*$X$2/(1+EXP($X$3*(COUNT($I$9:L$9)+$X$4))),TREND($E21:$F21,$E$9:$F$9,L$9)) -> 0.0010142193 | M21: =IF($G21="s-curve",$E21+($F21-$E21)*$X$2/(1+EXP($X$3*(COUNT($I$9:M$9)+$X$4))),TREND($E21:$F21,$E$9:$F$9,M$9)) -> 0.0010178343 | N21: =IF($G21="s-curve",$E21+($F21-$E21)*$X$2/(1+EXP($X$3*(COUNT($I$9:N$9)+$X$4))),TREND($E21:$F21,$E$9:$F$9,N$9)) -> 0.001022531 | O21: =IF($G21="s-curve",$E21+($F21-$E21)*$X$2/(1+EXP($X$3*(COUNT($I$9:O$9)+$X$4))),TREND($E21:$F21,$E$9:$F$9,O$9)) -> 0.0010285588 | P21: =IF($G21="s-curve",$E21+($F21-$E21)*$X$2/(1+EXP($X$3*(COUNT($I$9:P$9)+$X$4))),TREND($E21:$F21,$E$9:$F$9,P$9)) -> 0.0010361747 | Q21: =IF($G21="s-curve",$E21+($F21-$E21)*$X$2/(1+EXP($X$3*(COUNT($I$9:Q$9)+$X$4))),TREND($E21:$F21,$E$9:$F$9,Q$9)) -> 0.0010456089 | R21: =IF($G21="s-curve",$E21+($F21-$E21)*$X$2/(1+EXP($X$3*(COUNT($I$9:R$9)+$X$4))),TREND($E21:$F21,$E$9:$F$9,R$9)) -> 0.0010570138 | ... AI21: =IF($G21="s-curve",$E21+($F21-$E21)*$X$2/(1+EXP($X$3*(COUNT($I$9:AI$9)+$X$4))),TREND($E21:$F21,$E$9:$F$9,AI$9)) -> 0.0012310951
C22: LPG vehicle | D22: 0.000602232 | E22: 0.000602232 | F22: =E22 -> 0.000602232 | G22: =IF(E22=F22,"n/a",IF(OR(C22="battery electric vehicle",C22="natural gas vehicle",C22="plugin hybrid vehicle",C22="hydrogen vehicle"),"s-curve","linear")) -> n/a | I22: =D22 -> 0.000602232 | J22: =E22 -> 0.000602232 | K22: =IF($G22="s-curve",$E22+($F22-$E22)*$I$2/(1+EXP($I$3*(COUNT($I$9:K$9)+$I$4))),TREND($E22:$F22,$E$9:$F$9,K$9)) -> 0.000602232 | L22: =IF($G22="s-curve",$E22+($F22-$E22)*$I$2/(1+EXP($I$3*(COUNT($I$9:L$9)+$I$4))),TREND($E22:$F22,$E$9:$F$9,L$9)) -> 0.000602232 | M22: =IF($G22="s-curve",$E22+($F22-$E22)*$I$2/(1+EXP($I$3*(COUNT($I$9:M$9)+$I$4))),TREND($E22:$F22,$E$9:$F$9,M$9)) -> 0.000602232 | N22: =IF($G22="s-curve",$E22+($F22-$E22)*$I$2/(1+EXP($I$3*(COUNT($I$9:N$9)+$I$4))),TREND($E22:$F22,$E$9:$F$9,N$9)) -> 0.000602232 | O22: =IF($G22="s-curve",$E22+($F22-$E22)*$I$2/(1+EXP($I$3*(COUNT($I$9:O$9)+$I$4))),TREND($E22:$F22,$E$9:$F$9,O$9)) -> 0.000602232 | P22: =IF($G22="s-curve",$E22+($F22-$E22)*$I$2/(1+EXP($I$3*(COUNT($I$9:P$9)+$I$4))),TREND($E22:$F22,$E$9:$F$9,P$9)) -> 0.000602232 | Q22: =IF($G22="s-curve",$E22+($F22-$E22)*$I$2/(1+EXP($I$3*(COUNT($I$9:Q$9)+$I$4))),TREND($E22:$F22,$E$9:$F$9,Q$9)) -> 0.000602232 | R22: =IF($G22="s-curve",$E22+($F22-$E22)*$I$2/(1+EXP($I$3*(COUNT($I$9:R$9)+$I$4))),TREND($E22:$F22,$E$9:$F$9,R$9)) -> 0.000602232 | ... AI22: =IF($G22="s-curve",$E22+($F22-$E22)*$I$2/(1+EXP($I$3*(COUNT($I$9:AI$9)+$I$4))),TREND($E22:$F22,$E$9:$F$9,AI$9)) -> 0.000602232
C23: hydrogen vehicle | D23: 0 | E23: 0 | F23: =E23 -> 0 | G23: =IF(E23=F23,"n/a",IF(OR(C23="battery electric vehicle",C23="natural gas vehicle",C23="plugin hybrid vehicle",C23="hydrogen vehicle"),"s-curve","linear")) -> n/a | I23: =D23 -> 0 | J23: =E23 -> 0 | K23: =IF($G23="s-curve",$E23+($F23-$E23)*$I$2/(1+EXP($I$3*(COUNT($I$9:K$9)+$I$4))),TREND($E23:$F23,$E$9:$F$9,K$9)) -> 0 | L23: =IF($G23="s-curve",$E23+($F23-$E23)*$I$2/(1+EXP($I$3*(COUNT($I$9:L$9)+$I$4))),TREND($E23:$F23,$E$9:$F$9,L$9)) -> 0 | M23: =IF($G23="s-curve",$E23+($F23-$E23)*$I$2/(1+EXP($I$3*(COUNT($I$9:M$9)+$I$4))),TREND($E23:$F23,$E$9:$F$9,M$9)) -> 0 | N23: =IF($G23="s-curve",$E23+($F23-$E23)*$I$2/(1+EXP($I$3*(COUNT($I$9:N$9)+$I$4))),TREND($E23:$F23,$E$9:$F$9,N$9)) -> 0 | O23: =IF($G23="s-curve",$E23+($F23-$E23)*$I$2/(1+EXP($I$3*(COUNT($I$9:O$9)+$I$4))),TREND($E23:$F23,$E$9:$F$9,O$9)) -> 0 | P23: =IF($G23="s-curve",$E23+($F23-$E23)*$I$2/(1+EXP($I$3*(COUNT($I$9:P$9)+$I$4))),TREND($E23:$F23,$E$9:$F$9,P$9)) -> 0 | Q23: =IF($G23="s-curve",$E23+($F23-$E23)*$I$2/(1+EXP($I$3*(COUNT($I$9:Q$9)+$I$4))),TREND($E23:$F23,$E$9:$F$9,Q$9)) -> 0 | R23: =IF($G23="s-curve",$E23+($F23-$E23)*$I$2/(1+EXP($I$3*(COUNT($I$9:R$9)+$I$4))),TREND($E23:$F23,$E$9:$F$9,R$9)) -> 0 | ... AI23: =IF($G23="s-curve",$E23+($F23-$E23)*$I$2/(1+EXP($I$3*(COUNT($I$9:AI$9)+$I$4))),TREND($E23:$F23,$E$9:$F$9,AI$9)) -> 0
A24: HDVs | B24: passenger | C24: battery electric vehicle | D24: 0.1218401 | E24: 0.1218401 | F24: 0.75 | G24: =IF(E24=F24,"n/a",IF(OR(C24="battery electric vehicle",C24="natural gas vehicle",C24="plugin hybrid vehicle"),"s-curve","linear")) -> s-curve | I24: =D24 -> 0.1218401 | J24: =E24 -> 0.1218401 | K24: =IF($G24="s-curve",$E24+($F24-$E24)*$X$2/(1+EXP($X$3*(COUNT($I$9:K$9)+$X$4))),TREND($E24:$F24,$E$9:$F$9,K$9)) -> 0.14418449 | L24: =IF($G24="s-curve",$E24+($F24-$E24)*$X$2/(1+EXP($X$3*(COUNT($I$9:L$9)+$X$4))),TREND($E24:$F24,$E$9:$F$9,L$9)) -> 0.15163113 | M24: =IF($G24="s-curve",$E24+($F24-$E24)*$X$2/(1+EXP($X$3*(COUNT($I$9:M$9)+$X$4))),TREND($E24:$F24,$E$9:$F$9,M$9)) -> 0.16139744 | N24: =IF($G24="s-curve",$E24+($F24-$E24)*$X$2/(1+EXP($X$3*(COUNT($I$9:N$9)+$X$4))),TREND($E24:$F24,$E$9:$F$9,N$9)) -> 0.17408585 | O24: =IF($G24="s-curve",$E24+($F24-$E24)*$X$2/(1+EXP($X$3*(COUNT($I$9:O$9)+$X$4))),TREND($E24:$F24,$E$9:$F$9,O$9)) -> 0.19037035 | P24: =IF($G24="s-curve",$E24+($F24-$E24)*$X$2/(1+EXP($X$3*(COUNT($I$9:P$9)+$X$4))),TREND($E24:$F24,$E$9:$F$9,P$9)) -> 0.21094525 | Q24: =IF($G24="s-curve",$E24+($F24-$E24)*$X$2/(1+EXP($X$3*(COUNT($I$9:Q$9)+$X$4))),TREND($E24:$F24,$E$9:$F$9,Q$9)) -> 0.2364325 | R24: =IF($G24="s-curve",$E24+($F24-$E24)*$X$2/(1+EXP($X$3*(COUNT($I$9:R$9)+$X$4))),TREND($E24:$F24,$E$9:$F$9,R$9)) -> 0.26724355 | ... AI24: =IF($G24="s-curve",$E24+($F24-$E24)*$X$2/(1+EXP($X$3*(COUNT($I$9:AI$9)+$X$4))),TREND($E24:$F24,$E$9:$F$9,AI$9)) -> 0.73753712
C25: natural gas vehicle | D25: 0.015737248 | E25: 0.015737248 | F25: =E25 -> 0.015737248 | G25: =IF(E25=F25,"n/a",IF(OR(C25="battery electric vehicle",C25="natural gas vehicle",C25="plugin hybrid vehicle"),"s-curve","linear")) -> n/a | I25: =D25 -> 0.015737248 | J25: =E25 -> 0.015737248 | K25: =IF($G25="s-curve",$E25+($F25-$E25)*$I$2/(1+EXP($I$3*(COUNT($I$9:K$9)+$I$4))),TREND($E25:$F25,$E$9:$F$9,K$9)) -> 0.015737248 | L25: =IF($G25="s-curve",$E25+($F25-$E25)*$I$2/(1+EXP($I$3*(COUNT($I$9:L$9)+$I$4))),TREND($E25:$F25,$E$9:$F$9,L$9)) -> 0.015737248 | M25: =IF($G25="s-curve",$E25+($F25-$E25)*$I$2/(1+EXP($I$3*(COUNT($I$9:M$9)+$I$4))),TREND($E25:$F25,$E$9:$F$9,M$9)) -> 0.015737248 | N25: =IF($G25="s-curve",$E25+($F25-$E25)*$I$2/(1+EXP($I$3*(COUNT($I$9:N$9)+$I$4))),TREND($E25:$F25,$E$9:$F$9,N$9)) -> 0.015737248 | O25: =IF($G25="s-curve",$E25+($F25-$E25)*$I$2/(1+EXP($I$3*(COUNT($I$9:O$9)+$I$4))),TREND($E25:$F25,$E$9:$F$9,O$9)) -> 0.015737248 | P25: =IF($G25="s-curve",$E25+($F25-$E25)*$I$2/(1+EXP($I$3*(COUNT($I$9:P$9)+$I$4))),TREND($E25:$F25,$E$9:$F$9,P$9)) -> 0.015737248 | Q25: =IF($G25="s-curve",$E25+($F25-$E25)*$I$2/(1+EXP($I$3*(COUNT($I$9:Q$9)+$I$4))),TREND($E25:$F25,$E$9:$F$9,Q$9)) -> 0.015737248 | R25: =IF($G25="s-curve",$E25+($F25-$E25)*$I$2/(1+EXP($I$3*(COUNT($I$9:R$9)+$I$4))),TREND($E25:$F25,$E$9:$F$9,R$9)) -> 0.015737248 | ... AI25: =IF($G25="s-curve",$E25+($F25-$E25)*$I$2/(1+EXP($I$3*(COUNT($I$9:AI$9)+$I$4))),TREND($E25:$F25,$E$9:$F$9,AI$9)) -> 0.015737248
C26: gasoline vehicle | D26: 0.37956814 | E26: 0.37956814 | F26: =E26 -> 0.37956814 | G26: =IF(E26=F26,"n/a",IF(OR(C26="battery electric vehicle",C26="natural gas vehicle",C26="plugin hybrid vehicle"),"s-curve","linear")) -> n/a | I26: =D26 -> 0.37956814 | J26: =E26 -> 0.37956814 | K26: =IF($G26="s-curve",$E26+($F26-$E26)*$I$2/(1+EXP($I$3*(COUNT($I$9:K$9)+$I$4))),TREND($E26:$F26,$E$9:$F$9,K$9)) -> 0.37956814 | L26: =IF($G26="s-curve",$E26+($F26-$E26)*$I$2/(1+EXP($I$3*(COUNT($I$9:L$9)+$I$4))),TREND($E26:$F26,$E$9:$F$9,L$9)) -> 0.37956814 | M26: =IF($G26="s-curve",$E26+($F26-$E26)*$I$2/(1+EXP($I$3*(COUNT($I$9:M$9)+$I$4))),TREND($E26:$F26,$E$9:$F$9,M$9)) -> 0.37956814 | N26: =IF($G26="s-curve",$E26+($F26-$E26)*$I$2/(1+EXP($I$3*(COUNT($I$9:N$9)+$I$4))),TREND($E26:$F26,$E$9:$F$9,N$9)) -> 0.37956814 | O26: =IF($G26="s-curve",$E26+($F26-$E26)*$I$2/(1+EXP($I$3*(COUNT($I$9:O$9)+$I$4))),TREND($E26:$F26,$E$9:$F$9,O$9)) -> 0.37956814 | P26: =IF($G26="s-curve",$E26+($F26-$E26)*$I$2/(1+EXP($I$3*(COUNT($I$9:P$9)+$I$4))),TREND($E26:$F26,$E$9:$F$9,P$9)) -> 0.37956814 | Q26: =IF($G26="s-curve",$E26+($F26-$E26)*$I$2/(1+EXP($I$3*(COUNT($I$9:Q$9)+$I$4))),TREND($E26:$F26,$E$9:$F$9,Q$9)) -> 0.37956814 | R26: =IF($G26="s-curve",$E26+($F26-$E26)*$I$2/(1+EXP($I$3*(COUNT($I$9:R$9)+$I$4))),TREND($E26:$F26,$E$9:$F$9,R$9)) -> 0.37956814 | ... AI26: =IF($G26="s-curve",$E26+($F26-$E26)*$I$2/(1+EXP($I$3*(COUNT($I$9:AI$9)+$I$4))),TREND($E26:$F26,$E$9:$F$9,AI$9)) -> 0.37956814
C27: diesel vehicle | D27: 1 | E27: 1 | F27: 1 | G27: =IF(E27=F27,"n/a",IF(OR(C27="battery electric vehicle",C27="natural gas vehicle",C27="plugin hybrid vehicle"),"s-curve","linear")) -> n/a | I27: =D27 -> 1 | J27: =E27 -> 1 | K27: =IF($G27="s-curve",$E27+($F27-$E27)*$I$2/(1+EXP($I$3*(COUNT($I$9:K$9)+$I$4))),TREND($E27:$F27,$E$9:$F$9,K$9)) -> 1 | L27: =IF($G27="s-curve",$E27+($F27-$E27)*$I$2/(1+EXP($I$3*(COUNT($I$9:L$9)+$I$4))),TREND($E27:$F27,$E$9:$F$9,L$9)) -> 1 | M27: =IF($G27="s-curve",$E27+($F27-$E27)*$I$2/(1+EXP($I$3*(COUNT($I$9:M$9)+$I$4))),TREND($E27:$F27,$E$9:$F$9,M$9)) -> 1 | N27: =IF($G27="s-curve",$E27+($F27-$E27)*$I$2/(1+EXP($I$3*(COUNT($I$9:N$9)+$I$4))),TREND($E27:$F27,$E$9:$F$9,N$9)) -> 1 | O27: =IF($G27="s-curve",$E27+($F27-$E27)*$I$2/(1+EXP($I$3*(COUNT($I$9:O$9)+$I$4))),TREND($E27:$F27,$E$9:$F$9,O$9)) -> 1 | P27: =IF($G27="s-curve",$E27+($F27-$E27)*$I$2/(1+EXP($I$3*(COUNT($I$9:P$9)+$I$4))),TREND($E27:$F27,$E$9:$F$9,P$9)) -> 1 | Q27: =IF($G27="s-curve",$E27+($F27-$E27)*$I$2/(1+EXP($I$3*(COUNT($I$9:Q$9)+$I$4))),TREND($E27:$F27,$E$9:$F$9,Q$9)) -> 1 | R27: =IF($G27="s-curve",$E27+($F27-$E27)*$I$2/(1+EXP($I$3*(COUNT($I$9:R$9)+$I$4))),TREND($E27:$F27,$E$9:$F$9,R$9)) -> 1 | ... AI27: =IF($G27="s-curve",$E27+($F27-$E27)*$I$2/(1+EXP($I$3*(COUNT($I$9:AI$9)+$I$4))),TREND($E27:$F27,$E$9:$F$9,AI$9)) -> 1
C28: plugin hybrid vehicle | D28: 0 | E28: 0 | F28: =E28 -> 0 | G28: =IF(E28=F28,"n/a",IF(OR(C28="battery electric vehicle",C28="natural gas vehicle",C28="plugin hybrid vehicle"),"s-curve","linear")) -> n/a | I28: =D28 -> 0 | J28: =E28 -> 0 | K28: =IF($G28="s-curve",$E28+($F28-$E28)*$I$2/(1+EXP($I$3*(COUNT($I$9:K$9)+$I$4))),TREND($E28:$F28,$E$9:$F$9,K$9)) -> 0 | L28: =IF($G28="s-curve",$E28+($F28-$E28)*$I$2/(1+EXP($I$3*(COUNT($I$9:L$9)+$I$4))),TREND($E28:$F28,$E$9:$F$9,L$9)) -> 0 | M28: =IF($G28="s-curve",$E28+($F28-$E28)*$I$2/(1+EXP($I$3*(COUNT($I$9:M$9)+$I$4))),TREND($E28:$F28,$E$9:$F$9,M$9)) -> 0 | N28: =IF($G28="s-curve",$E28+($F28-$E28)*$I$2/(1+EXP($I$3*(COUNT($I$9:N$9)+$I$4))),TREND($E28:$F28,$E$9:$F$9,N$9)) -> 0 | O28: =IF($G28="s-curve",$E28+($F28-$E28)*$I$2/(1+EXP($I$3*(COUNT($I$9:O$9)+$I$4))),TREND($E28:$F28,$E$9:$F$9,O$9)) -> 0 | P28: =IF($G28="s-curve",$E28+($F28-$E28)*$I$2/(1+EXP($I$3*(COUNT($I$9:P$9)+$I$4))),TREND($E28:$F28,$E$9:$F$9,P$9)) -> 0 | Q28: =IF($G28="s-curve",$E28+($F28-$E28)*$I$2/(1+EXP($I$3*(COUNT($I$9:Q$9)+$I$4))),TREND($E28:$F28,$E$9:$F$9,Q$9)) -> 0 | R28: =IF($G28="s-curve",$E28+($F28-$E28)*$I$2/(1+EXP($I$3*(COUNT($I$9:R$9)+$I$4))),TREND($E28:$F28,$E$9:$F$9,R$9)) -> 0 | ... AI28: =IF($G28="s-curve",$E28+($F28-$E28)*$I$2/(1+EXP($I$3*(COUNT($I$9:AI$9)+$I$4))),TREND($E28:$F28,$E$9:$F$9,AI$9)) -> 0
C29: LPG vehicle | D29: 0.055449391 | E29: 0.055449391 | F29: =E29 -> 0.055449391 | G29: =IF(E29=F29,"n/a",IF(OR(C29="battery electric vehicle",C29="natural gas vehicle",C29="plugin hybrid vehicle",C29="hydrogen vehicle"),"s-curve","linear")) -> n/a | I29: =D29 -> 0.055449391 | J29: =E29 -> 0.055449391 | K29: =IF($G29="s-curve",$E29+($F29-$E29)*$I$2/(1+EXP($I$3*(COUNT($I$9:K$9)+$I$4))),TREND($E29:$F29,$E$9:$F$9,K$9)) -> 0.055449391 | L29: =IF($G29="s-curve",$E29+($F29-$E29)*$I$2/(1+EXP($I$3*(COUNT($I$9:L$9)+$I$4))),TREND($E29:$F29,$E$9:$F$9,L$9)) -> 0.055449391 | M29: =IF($G29="s-curve",$E29+($F29-$E29)*$I$2/(1+EXP($I$3*(COUNT($I$9:M$9)+$I$4))),TREND($E29:$F29,$E$9:$F$9,M$9)) -> 0.055449391 | N29: =IF($G29="s-curve",$E29+($F29-$E29)*$I$2/(1+EXP($I$3*(COUNT($I$9:N$9)+$I$4))),TREND($E29:$F29,$E$9:$F$9,N$9)) -> 0.055449391 | O29: =IF($G29="s-curve",$E29+($F29-$E29)*$I$2/(1+EXP($I$3*(COUNT($I$9:O$9)+$I$4))),TREND($E29:$F29,$E$9:$F$9,O$9)) -> 0.055449391 | P29: =IF($G29="s-curve",$E29+($F29-$E29)*$I$2/(1+EXP($I$3*(COUNT($I$9:P$9)+$I$4))),TREND($E29:$F29,$E$9:$F$9,P$9)) -> 0.055449391 | Q29: =IF($G29="s-curve",$E29+($F29-$E29)*$I$2/(1+EXP($I$3*(COUNT($I$9:Q$9)+$I$4))),TREND($E29:$F29,$E$9:$F$9,Q$9)) -> 0.055449391 | R29: =IF($G29="s-curve",$E29+($F29-$E29)*$I$2/(1+EXP($I$3*(COUNT($I$9:R$9)+$I$4))),TREND($E29:$F29,$E$9:$F$9,R$9)) -> 0.055449391 | ... AI29: =IF($G29="s-curve",$E29+($F29-$E29)*$I$2/(1+EXP($I$3*(COUNT($I$9:AI$9)+$I$4))),TREND($E29:$F29,$E$9:$F$9,AI$9)) -> 0.055449391
C30: hydrogen vehicle | D30: 0.002028695 | E30: 0.002028695 | F30: =E30 -> 0.002028695 | G30: =IF(E30=F30,"n/a",IF(OR(C30="battery electric vehicle",C30="natural gas vehicle",C30="plugin hybrid vehicle",C30="hydrogen vehicle"),"s-curve","linear")) -> n/a | I30: =D30 -> 0.002028695 | J30: =E30 -> 0.002028695 | K30: =IF($G30="s-curve",$E30+($F30-$E30)*$I$2/(1+EXP($I$3*(COUNT($I$9:K$9)+$I$4))),TREND($E30:$F30,$E$9:$F$9,K$9)) -> 0.002028695 | L30: =IF($G30="s-curve",$E30+($F30-$E30)*$I$2/(1+EXP($I$3*(COUNT($I$9:L$9)+$I$4))),TREND($E30:$F30,$E$9:$F$9,L$9)) -> 0.002028695 | M30: =IF($G30="s-curve",$E30+($F30-$E30)*$I$2/(1+EXP($I$3*(COUNT($I$9:M$9)+$I$4))),TREND($E30:$F30,$E$9:$F$9,M$9)) -> 0.002028695 | N30: =IF($G30="s-curve",$E30+($F30-$E30)*$I$2/(1+EXP($I$3*(COUNT($I$9:N$9)+$I$4))),TREND($E30:$F30,$E$9:$F$9,N$9)) -> 0.002028695 | O30: =IF($G30="s-curve",$E30+($F30-$E30)*$I$2/(1+EXP($I$3*(COUNT($I$9:O$9)+$I$4))),TREND($E30:$F30,$E$9:$F$9,O$9)) -> 0.002028695 | P30: =IF($G30="s-curve",$E30+($F30-$E30)*$I$2/(1+EXP($I$3*(COUNT($I$9:P$9)+$I$4))),TREND($E30:$F30,$E$9:$F$9,P$9)) -> 0.002028695 | Q30: =IF($G30="s-curve",$E30+($F30-$E30)*$I$2/(1+EXP($I$3*(COUNT($I$9:Q$9)+$I$4))),TREND($E30:$F30,$E$9:$F$9,Q$9)) -> 0.002028695 | R30: =IF($G30="s-curve",$E30+($F30-$E30)*$I$2/(1+EXP($I$3*(COUNT($I$9:R$9)+$I$4))),TREND($E30:$F30,$E$9:$F$9,R$9)) -> 0.002028695 | ... AI30: =IF($G30="s-curve",$E30+($F30-$E30)*$I$2/(1+EXP($I$3*(COUNT($I$9:AI$9)+$I$4))),TREND($E30:$F30,$E$9:$F$9,AI$9)) -> 0.002028695
A31: HDVs | B31: freight | C31: battery electric vehicle | D31: 0.004808968 | E31: 0.004808968 | F31: 0.25 | G31: =IF(E31=F31,"n/a",IF(OR(C31="battery electric vehicle",C31="natural gas vehicle",C31="plugin hybrid vehicle"),"s-curve","linear")) -> s-curve | I31: =D31 -> 0.004808968 | J31: =E31 -> 0.004808968 | K31: =IF($G31="s-curve",$E31+($F31-$E31)*$R$2/(1+EXP($R$3*(COUNT($K$9:K$9)+$R$4))),TREND($E31:$F31,$E$9:$F$9,K$9)) -> 0.013530705 | L31: =IF($G31="s-curve",$E31+($F31-$E31)*$R$2/(1+EXP($R$3*(COUNT($K$9:L$9)+$R$4))),TREND($E31:$F31,$E$9:$F$9,L$9)) -> 0.016437367 | M31: =IF($G31="s-curve",$E31+($F31-$E31)*$R$2/(1+EXP($R$3*(COUNT($K$9:M$9)+$R$4))),TREND($E31:$F31,$E$9:$F$9,M$9)) -> 0.02024947 | N31: =IF($G31="s-curve",$E31+($F31-$E31)*$R$2/(1+EXP($R$3*(COUNT($K$9:N$9)+$R$4))),TREND($E31:$F31,$E$9:$F$9,N$9)) -> 0.025202167 | O31: =IF($G31="s-curve",$E31+($F31-$E31)*$R$2/(1+EXP($R$3*(COUNT($K$9:O$9)+$R$4))),TREND($E31:$F31,$E$9:$F$9,O$9)) -> 0.03155853 | P31: =IF($G31="s-curve",$E31+($F31-$E31)*$R$2/(1+EXP($R$3*(COUNT($K$9:P$9)+$R$4))),TREND($E31:$F31,$E$9:$F$9,P$9)) -> 0.039589577 | Q31: =IF($G31="s-curve",$E31+($F31-$E31)*$R$2/(1+EXP($R$3*(COUNT($K$9:Q$9)+$R$4))),TREND($E31:$F31,$E$9:$F$9,Q$9)) -> 0.04953807 | R31: =IF($G31="s-curve",$E31+($F31-$E31)*$R$2/(1+EXP($R$3*(COUNT($K$9:R$9)+$R$4))),TREND($E31:$F31,$E$9:$F$9,R$9)) -> 0.061564615 | ... AI31: =IF($G31="s-curve",$E31+($F31-$E31)*$R$2/(1+EXP($R$3*(COUNT($K$9:AI$9)+$R$4))),TREND($E31:$F31,$E$9:$F$9,AI$9)) -> 0.24513533
C32: natural gas vehicle | D32: 0.022159679 | E32: 0.022159679 | F32: =E32 -> 0.022159679 | G32: =IF(E32=F32,"n/a",IF(OR(C32="battery electric vehicle",C32="natural gas vehicle",C32="plugin hybrid vehicle"),"s-curve","linear")) -> n/a | I32: =D32 -> 0.022159679 | J32: =E32 -> 0.022159679 | K32: =IF($G32="s-curve",$E32+($F32-$E32)*$I$2/(1+EXP($I$3*(COUNT($I$9:K$9)+$I$4))),TREND($E32:$F32,$E$9:$F$9,K$9)) -> 0.022159679 | L32: =IF($G32="s-curve",$E32+($F32-$E32)*$I$2/(1+EXP($I$3*(COUNT($I$9:L$9)+$I$4))),TREND($E32:$F32,$E$9:$F$9,L$9)) -> 0.022159679 | M32: =IF($G32="s-curve",$E32+($F32-$E32)*$I$2/(1+EXP($I$3*(COUNT($I$9:M$9)+$I$4))),TREND($E32:$F32,$E$9:$F$9,M$9)) -> 0.022159679 | N32: =IF($G32="s-curve",$E32+($F32-$E32)*$I$2/(1+EXP($I$3*(COUNT($I$9:N$9)+$I$4))),TREND($E32:$F32,$E$9:$F$9,N$9)) -> 0.022159679 | O32: =IF($G32="s-curve",$E32+($F32-$E32)*$I$2/(1+EXP($I$3*(COUNT($I$9:O$9)+$I$4))),TREND($E32:$F32,$E$9:$F$9,O$9)) -> 0.022159679 | P32: =IF($G32="s-curve",$E32+($F32-$E32)*$I$2/(1+EXP($I$3*(COUNT($I$9:P$9)+$I$4))),TREND($E32:$F32,$E$9:$F$9,P$9)) -> 0.022159679 | Q32: =IF($G32="s-curve",$E32+($F32-$E32)*$I$2/(1+EXP($I$3*(COUNT($I$9:Q$9)+$I$4))),TREND($E32:$F32,$E$9:$F$9,Q$9)) -> 0.022159679 | R32: =IF($G32="s-curve",$E32+($F32-$E32)*$I$2/(1+EXP($I$3*(COUNT($I$9:R$9)+$I$4))),TREND($E32:$F32,$E$9:$F$9,R$9)) -> 0.022159679 | ... AI32: =IF($G32="s-curve",$E32+($F32-$E32)*$I$2/(1+EXP($I$3*(COUNT($I$9:AI$9)+$I$4))),TREND($E32:$F32,$E$9:$F$9,AI$9)) -> 0.022159679
C33: gasoline vehicle | D33: 0.000753581 | E33: 0.000753581 | F33: =E33 -> 0.000753581 | G33: =IF(E33=F33,"n/a",IF(OR(C33="battery electric vehicle",C33="natural gas vehicle",C33="plugin hybrid vehicle"),"s-curve","linear")) -> n/a | I33: =D33 -> 0.000753581 | J33: =E33 -> 0.000753581 | K33: =IF($G33="s-curve",$E33+($F33-$E33)*$I$2/(1+EXP($I$3*(COUNT($I$9:K$9)+$I$4))),TREND($E33:$F33,$E$9:$F$9,K$9)) -> 0.000753581 | L33: =IF($G33="s-curve",$E33+($F33-$E33)*$I$2/(1+EXP($I$3*(COUNT($I$9:L$9)+$I$4))),TREND($E33:$F33,$E$9:$F$9,L$9)) -> 0.000753581 | M33: =IF($G33="s-curve",$E33+($F33-$E33)*$I$2/(1+EXP($I$3*(COUNT($I$9:M$9)+$I$4))),TREND($E33:$F33,$E$9:$F$9,M$9)) -> 0.000753581 | N33: =IF($G33="s-curve",$E33+($F33-$E33)*$I$2/(1+EXP($I$3*(COUNT($I$9:N$9)+$I$4))),TREND($E33:$F33,$E$9:$F$9,N$9)) -> 0.000753581 | O33: =IF($G33="s-curve",$E33+($F33-$E33)*$I$2/(1+EXP($I$3*(COUNT($I$9:O$9)+$I$4))),TREND($E33:$F33,$E$9:$F$9,O$9)) -> 0.000753581 | P33: =IF($G33="s-curve",$E33+($F33-$E33)*$I$2/(1+EXP($I$3*(COUNT($I$9:P$9)+$I$4))),TREND($E33:$F33,$E$9:$F$9,P$9)) -> 0.000753581 | Q33: =IF($G33="s-curve",$E33+($F33-$E33)*$I$2/(1+EXP($I$3*(COUNT($I$9:Q$9)+$I$4))),TREND($E33:$F33,$E$9:$F$9,Q$9)) -> 0.000753581 | R33: =IF($G33="s-curve",$E33+($F33-$E33)*$I$2/(1+EXP($I$3*(COUNT($I$9:R$9)+$I$4))),TREND($E33:$F33,$E$9:$F$9,R$9)) -> 0.000753581 | ... AI33: =IF($G33="s-curve",$E33+($F33-$E33)*$I$2/(1+EXP($I$3*(COUNT($I$9:AI$9)+$I$4))),TREND($E33:$F33,$E$9:$F$9,AI$9)) -> 0.000753581
C34: diesel vehicle | D34: 1 | E34: 1 | F34: 1 | G34: =IF(E34=F34,"n/a",IF(OR(C34="battery electric vehicle",C34="natural gas vehicle",C34="plugin hybrid vehicle"),"s-curve","linear")) -> n/a | I34: =D34 -> 1 | J34: =E34 -> 1 | K34: =IF($G34="s-curve",$E34+($F34-$E34)*$I$2/(1+EXP($I$3*(COUNT($I$9:K$9)+$I$4))),TREND($E34:$F34,$E$9:$F$9,K$9)) -> 1 | L34: =IF($G34="s-curve",$E34+($F34-$E34)*$I$2/(1+EXP($I$3*(COUNT($I$9:L$9)+$I$4))),TREND($E34:$F34,$E$9:$F$9,L$9)) -> 1 | M34: =IF($G34="s-curve",$E34+($F34-$E34)*$I$2/(1+EXP($I$3*(COUNT($I$9:M$9)+$I$4))),TREND($E34:$F34,$E$9:$F$9,M$9)) -> 1 | N34: =IF($G34="s-curve",$E34+($F34-$E34)*$I$2/(1+EXP($I$3*(COUNT($I$9:N$9)+$I$4))),TREND($E34:$F34,$E$9:$F$9,N$9)) -> 1 | O34: =IF($G34="s-curve",$E34+($F34-$E34)*$I$2/(1+EXP($I$3*(COUNT($I$9:O$9)+$I$4))),TREND($E34:$F34,$E$9:$F$9,O$9)) -> 1 | P34: =IF($G34="s-curve",$E34+($F34-$E34)*$I$2/(1+EXP($I$3*(COUNT($I$9:P$9)+$I$4))),TREND($E34:$F34,$E$9:$F$9,P$9)) -> 1 | Q34: =IF($G34="s-curve",$E34+($F34-$E34)*$I$2/(1+EXP($I$3*(COUNT($I$9:Q$9)+$I$4))),TREND($E34:$F34,$E$9:$F$9,Q$9)) -> 1 | R34: =IF($G34="s-curve",$E34+($F34-$E34)*$I$2/(1+EXP($I$3*(COUNT($I$9:R$9)+$I$4))),TREND($E34:$F34,$E$9:$F$9,R$9)) -> 1 | ... AI34: =IF($G34="s-curve",$E34+($F34-$E34)*$I$2/(1+EXP($I$3*(COUNT($I$9:AI$9)+$I$4))),TREND($E34:$F34,$E$9:$F$9,AI$9)) -> 1
C35: plugin hybrid vehicle | D35: 0 | E35: 0 | F35: =E35 -> 0 | G35: =IF(E35=F35,"n/a",IF(OR(C35="battery electric vehicle",C35="natural gas vehicle",C35="plugin hybrid vehicle"),"s-curve","linear")) -> n/a | I35: =D35 -> 0 | J35: =E35 -> 0 | K35: =IF($G35="s-curve",$E35+($F35-$E35)*$I$2/(1+EXP($I$3*(COUNT($I$9:K$9)+$I$4))),TREND($E35:$F35,$E$9:$F$9,K$9)) -> 0 | L35: =IF($G35="s-curve",$E35+($F35-$E35)*$I$2/(1+EXP($I$3*(COUNT($I$9:L$9)+$I$4))),TREND($E35:$F35,$E$9:$F$9,L$9)) -> 0 | M35: =IF($G35="s-curve",$E35+($F35-$E35)*$I$2/(1+EXP($I$3*(COUNT($I$9:M$9)+$I$4))),TREND($E35:$F35,$E$9:$F$9,M$9)) -> 0 | N35: =IF($G35="s-curve",$E35+($F35-$E35)*$I$2/(1+EXP($I$3*(COUNT($I$9:N$9)+$I$4))),TREND($E35:$F35,$E$9:$F$9,N$9)) -> 0 | O35: =IF($G35="s-curve",$E35+($F35-$E35)*$I$2/(1+EXP($I$3*(COUNT($I$9:O$9)+$I$4))),TREND($E35:$F35,$E$9:$F$9,O$9)) -> 0 | P35: =IF($G35="s-curve",$E35+($F35-$E35)*$I$2/(1+EXP($I$3*(COUNT($I$9:P$9)+$I$4))),TREND($E35:$F35,$E$9:$F$9,P$9)) -> 0 | Q35: =IF($G35="s-curve",$E35+($F35-$E35)*$I$2/(1+EXP($I$3*(COUNT($I$9:Q$9)+$I$4))),TREND($E35:$F35,$E$9:$F$9,Q$9)) -> 0 | R35: =IF($G35="s-curve",$E35+($F35-$E35)*$I$2/(1+EXP($I$3*(COUNT($I$9:R$9)+$I$4))),TREND($E35:$F35,$E$9:$F$9,R$9)) -> 0 | ... AI35: =IF($G35="s-curve",$E35+($F35-$E35)*$I$2/(1+EXP($I$3*(COUNT($I$9:AI$9)+$I$4))),TREND($E35:$F35,$E$9:$F$9,AI$9)) -> 0
C36: LPG vehicle | D36: 0 | E36: 0 | F36: =E36 -> 0 | G36: =IF(E36=F36,"n/a",IF(OR(C36="battery electric vehicle",C36="natural gas vehicle",C36="plugin hybrid vehicle",C36="hydrogen vehicle"),"s-curve","linear")) -> n/a | I36: =D36 -> 0 | J36: =E36 -> 0 | K36: =IF($G36="s-curve",$E36+($F36-$E36)*$I$2/(1+EXP($I$3*(COUNT($I$9:K$9)+$I$4))),TREND($E36:$F36,$E$9:$F$9,K$9)) -> 0 | L36: =IF($G36="s-curve",$E36+($F36-$E36)*$I$2/(1+EXP($I$3*(COUNT($I$9:L$9)+$I$4))),TREND($E36:$F36,$E$9:$F$9,L$9)) -> 0 | M36: =IF($G36="s-curve",$E36+($F36-$E36)*$I$2/(1+EXP($I$3*(COUNT($I$9:M$9)+$I$4))),TREND($E36:$F36,$E$9:$F$9,M$9)) -> 0 | N36: =IF($G36="s-curve",$E36+($F36-$E36)*$I$2/(1+EXP($I$3*(COUNT($I$9:N$9)+$I$4))),TREND($E36:$F36,$E$9:$F$9,N$9)) -> 0 | O36: =IF($G36="s-curve",$E36+($F36-$E36)*$I$2/(1+EXP($I$3*(COUNT($I$9:O$9)+$I$4))),TREND($E36:$F36,$E$9:$F$9,O$9)) -> 0 | P36: =IF($G36="s-curve",$E36+($F36-$E36)*$I$2/(1+EXP($I$3*(COUNT($I$9:P$9)+$I$4))),TREND($E36:$F36,$E$9:$F$9,P$9)) -> 0 | Q36: =IF($G36="s-curve",$E36+($F36-$E36)*$I$2/(1+EXP($I$3*(COUNT($I$9:Q$9)+$I$4))),TREND($E36:$F36,$E$9:$F$9,Q$9)) -> 0 | R36: =IF($G36="s-curve",$E36+($F36-$E36)*$I$2/(1+EXP($I$3*(COUNT($I$9:R$9)+$I$4))),TREND($E36:$F36,$E$9:$F$9,R$9)) -> 0 | ... AI36: =IF($G36="s-curve",$E36+($F36-$E36)*$I$2/(1+EXP($I$3*(COUNT($I$9:AI$9)+$I$4))),TREND($E36:$F36,$E$9:$F$9,AI$9)) -> 0
C37: hydrogen vehicle | D37: 0 | E37: 0 | F37: =E37 -> 0 | G37: =IF(E37=F37,"n/a",IF(OR(C37="battery electric vehicle",C37="natural gas vehicle",C37="plugin hybrid vehicle",C37="hydrogen vehicle"),"s-curve","linear")) -> n/a | I37: =D37 -> 0 | J37: =E37 -> 0 | K37: =IF($G37="s-curve",$E37+($F37-$E37)*$I$2/(1+EXP($I$3*(COUNT($I$9:K$9)+$I$4))),TREND($E37:$F37,$E$9:$F$9,K$9)) -> 0 | L37: =IF($G37="s-curve",$E37+($F37-$E37)*$I$2/(1+EXP($I$3*(COUNT($I$9:L$9)+$I$4))),TREND($E37:$F37,$E$9:$F$9,L$9)) -> 0 | M37: =IF($G37="s-curve",$E37+($F37-$E37)*$I$2/(1+EXP($I$3*(COUNT($I$9:M$9)+$I$4))),TREND($E37:$F37,$E$9:$F$9,M$9)) -> 0 | N37: =IF($G37="s-curve",$E37+($F37-$E37)*$I$2/(1+EXP($I$3*(COUNT($I$9:N$9)+$I$4))),TREND($E37:$F37,$E$9:$F$9,N$9)) -> 0 | O37: =IF($G37="s-curve",$E37+($F37-$E37)*$I$2/(1+EXP($I$3*(COUNT($I$9:O$9)+$I$4))),TREND($E37:$F37,$E$9:$F$9,O$9)) -> 0 | P37: =IF($G37="s-curve",$E37+($F37-$E37)*$I$2/(1+EXP($I$3*(COUNT($I$9:P$9)+$I$4))),TREND($E37:$F37,$E$9:$F$9,P$9)) -> 0 | Q37: =IF($G37="s-curve",$E37+($F37-$E37)*$I$2/(1+EXP($I$3*(COUNT($I$9:Q$9)+$I$4))),TREND($E37:$F37,$E$9:$F$9,Q$9)) -> 0 | R37: =IF($G37="s-curve",$E37+($F37-$E37)*$I$2/(1+EXP($I$3*(COUNT($I$9:R$9)+$I$4))),TREND($E37:$F37,$E$9:$F$9,R$9)) -> 0 | ... AI37: =IF($G37="s-curve",$E37+($F37-$E37)*$I$2/(1+EXP($I$3*(COUNT($I$9:AI$9)+$I$4))),TREND($E37:$F37,$E$9:$F$9,AI$9)) -> 0
A38: aircraft | B38: passenger | C38: battery electric vehicle | E38: 0 | F38: 0 | G38: =IF(E38=F38,"n/a",IF(OR(C38="battery electric vehicle",C38="natural gas vehicle",C38="plugin hybrid vehicle"),"s-curve","linear")) -> n/a | I38: =E38 -> 0 | J38: =IF($G38="s-curve",$E38+($F38-$E38)*$I$2/(1+EXP($I$3*(COUNT($I$9:J$9)+$I$4))),TREND($E38:$F38,$E$9:$F$9,J$9)) -> 0 | K38: =IF($G38="s-curve",$E38+($F38-$E38)*$I$2/(1+EXP($I$3*(COUNT($I$9:K$9)+$I$4))),TREND($E38:$F38,$E$9:$F$9,K$9)) -> 0 | L38: =IF($G38="s-curve",$E38+($F38-$E38)*$I$2/(1+EXP($I$3*(COUNT($I$9:L$9)+$I$4))),TREND($E38:$F38,$E$9:$F$9,L$9)) -> 0 | M38: =IF($G38="s-curve",$E38+($F38-$E38)*$I$2/(1+EXP($I$3*(COUNT($I$9:M$9)+$I$4))),TREND($E38:$F38,$E$9:$F$9,M$9)) -> 0 | N38: =IF($G38="s-curve",$E38+($F38-$E38)*$I$2/(1+EXP($I$3*(COUNT($I$9:N$9)+$I$4))),TREND($E38:$F38,$E$9:$F$9,N$9)) -> 0 | O38: =IF($G38="s-curve",$E38+($F38-$E38)*$I$2/(1+EXP($I$3*(COUNT($I$9:O$9)+$I$4))),TREND($E38:$F38,$E$9:$F$9,O$9)) -> 0 | P38: =IF($G38="s-curve",$E38+($F38-$E38)*$I$2/(1+EXP($I$3*(COUNT($I$9:P$9)+$I$4))),TREND($E38:$F38,$E$9:$F$9,P$9)) -> 0 | Q38: =IF($G38="s-curve",$E38+($F38-$E38)*$I$2/(1+EXP($I$3*(COUNT($I$9:Q$9)+$I$4))),TREND($E38:$F38,$E$9:$F$9,Q$9)) -> 0 | ... AI38: =IF($G38="s-curve",$E38+($F38-$E38)*$I$2/(1+EXP($I$3*(COUNT($I$9:AI$9)+$I$4))),TREND($E38:$F38,$E$9:$F$9,AI$9)) -> 0
C39: natural gas vehicle | E39: 0 | F39: 0 | G39: =IF(E39=F39,"n/a",IF(OR(C39="battery electric vehicle",C39="natural gas vehicle",C39="plugin hybrid vehicle"),"s-curve","linear")) -> n/a | I39: =E39 -> 0 | J39: =IF($G39="s-curve",$E39+($F39-$E39)*$I$2/(1+EXP($I$3*(COUNT($I$9:J$9)+$I$4))),TREND($E39:$F39,$E$9:$F$9,J$9)) -> 0 | K39: =IF($G39="s-curve",$E39+($F39-$E39)*$I$2/(1+EXP($I$3*(COUNT($I$9:K$9)+$I$4))),TREND($E39:$F39,$E$9:$F$9,K$9)) -> 0 | L39: =IF($G39="s-curve",$E39+($F39-$E39)*$I$2/(1+EXP($I$3*(COUNT($I$9:L$9)+$I$4))),TREND($E39:$F39,$E$9:$F$9,L$9)) -> 0 | M39: =IF($G39="s-curve",$E39+($F39-$E39)*$I$2/(1+EXP($I$3*(COUNT($I$9:M$9)+$I$4))),TREND($E39:$F39,$E$9:$F$9,M$9)) -> 0 | N39: =IF($G39="s-curve",$E39+($F39-$E39)*$I$2/(1+EXP($I$3*(COUNT($I$9:N$9)+$I$4))),TREND($E39:$F39,$E$9:$F$9,N$9)) -> 0 | O39: =IF($G39="s-curve",$E39+($F39-$E39)*$I$2/(1+EXP($I$3*(COUNT($I$9:O$9)+$I$4))),TREND($E39:$F39,$E$9:$F$9,O$9)) -> 0 | P39: =IF($G39="s-curve",$E39+($F39-$E39)*$I$2/(1+EXP($I$3*(COUNT($I$9:P$9)+$I$4))),TREND($E39:$F39,$E$9:$F$9,P$9)) -> 0 | Q39: =IF($G39="s-curve",$E39+($F39-$E39)*$I$2/(1+EXP($I$3*(COUNT($I$9:Q$9)+$I$4))),TREND($E39:$F39,$E$9:$F$9,Q$9)) -> 0 | ... AI39: =IF($G39="s-curve",$E39+($F39-$E39)*$I$2/(1+EXP($I$3*(COUNT($I$9:AI$9)+$I$4))),TREND($E39:$F39,$E$9:$F$9,AI$9)) -> 0
C40: gasoline vehicle | E40: 0 | F40: 0 | G40: =IF(E40=F40,"n/a",IF(OR(C40="battery electric vehicle",C40="natural gas vehicle",C40="plugin hybrid vehicle"),"s-curve","linear")) -> n/a | I40: =E40 -> 0 | J40: =IF($G40="s-curve",$E40+($F40-$E40)*$I$2/(1+EXP($I$3*(COUNT($I$9:J$9)+$I$4))),TREND($E40:$F40,$E$9:$F$9,J$9)) -> 0 | K40: =IF($G40="s-curve",$E40+($F40-$E40)*$I$2/(1+EXP($I$3*(COUNT($I$9:K$9)+$I$4))),TREND($E40:$F40,$E$9:$F$9,K$9)) -> 0 | L40: =IF($G40="s-curve",$E40+($F40-$E40)*$I$2/(1+EXP($I$3*(COUNT($I$9:L$9)+$I$4))),TREND($E40:$F40,$E$9:$F$9,L$9)) -> 0 | M40: =IF($G40="s-curve",$E40+($F40-$E40)*$I$2/(1+EXP($I$3*(COUNT($I$9:M$9)+$I$4))),TREND($E40:$F40,$E$9:$F$9,M$9)) -> 0 | N40: =IF($G40="s-curve",$E40+($F40-$E40)*$I$2/(1+EXP($I$3*(COUNT($I$9:N$9)+$I$4))),TREND($E40:$F40,$E$9:$F$9,N$9)) -> 0 | O40: =IF($G40="s-curve",$E40+($F40-$E40)*$I$2/(1+EXP($I$3*(COUNT($I$9:O$9)+$I$4))),TREND($E40:$F40,$E$9:$F$9,O$9)) -> 0 | P40: =IF($G40="s-curve",$E40+($F40-$E40)*$I$2/(1+EXP($I$3*(COUNT($I$9:P$9)+$I$4))),TREND($E40:$F40,$E$9:$F$9,P$9)) -> 0 | Q40: =IF($G40="s-curve",$E40+($F40-$E40)*$I$2/(1+EXP($I$3*(COUNT($I$9:Q$9)+$I$4))),TREND($E40:$F40,$E$9:$F$9,Q$9)) -> 0 | ... AI40: =IF($G40="s-curve",$E40+($F40-$E40)*$I$2/(1+EXP($I$3*(COUNT($I$9:AI$9)+$I$4))),TREND($E40:$F40,$E$9:$F$9,AI$9)) -> 0
...

Sheet TTS-LDVs-psgr
A1: Max Fraction of Production (dimensionless) | B1: =Data!I9 -> 2024 | C1: =Data!J9 -> 2025 | D1: =Data!K9 -> 2026 | E1: =Data!L9 -> 2027 | F1: =Data!M9 -> 2028 | G1: =Data!N9 -> 2029 | H1: =Data!O9 -> 2030 | I1: =Data!P9 -> 2031 | ... AB1: =Data!AI9 -> 2050
A2: battery electric vehicle | B2: =Data!I10 -> 0.14828895 | C2: =Data!J10 -> 0.14828895 | D2: =Data!K10 -> 0.18868209 | E2: =Data!L10 -> 0.20192405 | F2: =Data!M10 -> 0.21912805 | G2: =Data!N10 -> 0.24120792 | H2: =Data!O10 -> 0.26910507 | I2: =Data!P10 -> 0.30366278 | ... AB2: =Data!AI10 -> 0.98741679
A3: natural gas vehicle | B3: =Data!I11 -> 0.00010097 | C3: =Data!J11 -> 0.00010097 | D3: =Data!K11 -> 0.00010097 | E3: =Data!L11 -> 0.00010097 | F3: =Data!M11 -> 0.00010097 | G3: =Data!N11 -> 0.00010097 | H3: =Data!O11 -> 0.00010097 | I3: =Data!P11 -> 0.00010097 | ... AB3: =Data!AI11 -> 0.00010097
A4: gasoline vehicle | B4: =Data!I12 -> 1 | C4: =Data!J12 -> 1 | D4: =Data!K12 -> 1 | E4: =Data!L12 -> 1 | F4: =Data!M12 -> 1 | G4: =Data!N12 -> 1 | H4: =Data!O12 -> 1 | I4: =Data!P12 -> 1 | ... AB4: =Data!AI12 -> 1
A5: diesel vehicle | B5: =Data!I13 -> 0.06738296 | C5: =Data!J13 -> 0.06738296 | D5: =Data!K13 -> 0.06738296 | E5: =Data!L13 -> 0.06738296 | F5: =Data!M13 -> 0.06738296 | G5: =Data!N13 -> 0.06738296 | H5: =Data!O13 -> 0.06738296 | I5: =Data!P13 -> 0.06738296 | ... AB5: =Data!AI13 -> 0.06738296
A6: plugin hybrid vehicle | B6: =Data!I14 -> 0.014073499 | C6: =Data!J14 -> 0.014073499 | D6: =Data!K14 -> 0.017532505 | E6: =Data!L14 -> 0.019136208 | F6: =Data!M14 -> 0.021419076 | G6: =Data!N14 -> 0.024601163 | H6: =Data!O14 -> 0.028909159 | I6: =Data!P14 -> 0.034516734 | ... AB6: =Data!AI14 -> 0.10224417
A7: LPG vehicle | B7: =Data!I15 -> 0 | C7: =Data!J15 -> 0 | D7: =Data!K15 -> 0 | E7: =Data!L15 -> 0 | F7: =Data!M15 -> 0 | G7: =Data!N15 -> 0 | H7: =Data!O15 -> 0 | I7: =Data!P15 -> 0 | ... AB7: =Data!AI15 -> 0
A8: hydrogen vehicle | B8: =Data!I16 -> 0 | C8: =Data!J16 -> 0 | D8: =Data!K16 -> 0 | E8: =Data!L16 -> 0 | F8: =Data!M16 -> 0 | G8: =Data!N16 -> 0 | H8: =Data!O16 -> 0 | I8: =Data!P16 -> 0 | ... AB8: =Data!AI16 -> 0

Sheet TTS-LDVs-frgt
A1: Max Fraction of Production (dimensionless) | B1: =Data!I9 -> 2024 | C1: =Data!J9 -> 2025 | D1: =Data!K9 -> 2026 | E1: =Data!L9 -> 2027 | F1: =Data!M9 -> 2028 | G1: =Data!N9 -> 2029 | H1: =Data!O9 -> 2030 | I1: =Data!P9 -> 2031 | ... AB1: =Data!AI9 -> 2050
A2: battery electric vehicle | B2: =Data!I17 -> 0.32863913 | C2: =Data!J17 -> 0.32863913 | D2: =Data!K17 -> 0.3276204 | E2: =Data!L17 -> 0.32728089 | F2: =Data!M17 -> 0.32683563 | G2: =Data!N17 -> 0.32625713 | H2: =Data!O17 -> 0.32551469 | I2: =Data!P17 -> 0.32457664 | ... AB2: =Data!AI17 -> 0.30056821
A3: natural gas vehicle | B3: =Data!I18 -> 0.25047807 | C3: =Data!J18 -> 0.25047807 | D3: =Data!K18 -> 0.25047807 | E3: =Data!L18 -> 0.25047807 | F3: =Data!M18 -> 0.25047807 | G3: =Data!N18 -> 0.25047807 | H3: =Data!O18 -> 0.25047807 | I3: =Data!P18 -> 0.25047807 | ... AB3: =Data!AI18 -> 0.25047807
A4: gasoline vehicle | B4: =Data!I19 -> 0.76148266 | C4: =Data!J19 -> 0.76148266 | D4: =Data!K19 -> 0.76148266 | E4: =Data!L19 -> 0.76148266 | F4: =Data!M19 -> 0.76148266 | G4: =Data!N19 -> 0.76148266 | H4: =Data!O19 -> 0.76148266 | I4: =Data!P19 -> 0.76148266 | ... AB4: =Data!AI19 -> 0.76148266
A5: diesel vehicle | B5: =Data!I20 -> 1 | C5: =Data!J20 -> 1 | D5: =Data!K20 -> 1 | E5: =Data!L20 -> 1 | F5: =Data!M20 -> 1 | G5: =Data!N20 -> 1 | H5: =Data!O20 -> 1 | I5: =Data!P20 -> 1 | ... AB5: =Data!AI20 -> 1
A6: plugin hybrid vehicle | B6: =Data!I21 -> 0.001003192 | C6: =Data!J21 -> 0.001003192 | D6: =Data!K21 -> 0.0010114629 | E6: =Data!L21 -> 0.0010142193 | F6: =Data!M21 -> 0.0010178343 | G6: =Data!N21 -> 0.001022531 | H6: =Data!O21 -> 0.0010285588 | I6: =Data!P21 -> 0.0010361747 | ... AB6: =Data!AI21 -> 0.0012310951
A7: LPG vehicle | B7: =Data!I22 -> 0.000602232 | C7: =Data!J22 -> 0.000602232 | D7: =Data!K22 -> 0.000602232 | E7: =Data!L22 -> 0.000602232 | F7: =Data!M22 -> 0.000602232 | G7: =Data!N22 -> 0.000602232 | H7: =Data!O22 -> 0.000602232 | I7: =Data!P22 -> 0.000602232 | ... AB7: =Data!AI22 -> 0.000602232
A8: hydrogen vehicle | B8: =Data!I23 -> 0 | C8: =Data!J23 -> 0 | D8: =Data!K23 -> 0 | E8: =Data!L23 -> 0 | F8: =Data!M23 -> 0 | G8: =Data!N23 -> 0 | H8: =Data!O23 -> 0 | I8: =Data!P23 -> 0 | ... AB8: =Data!AI23 -> 0

Sheet TTS-HDVs-psgr
A1: Max Fraction of Production (dimensionless) | B1: =Data!I9 -> 2024 | C1: =Data!J9 -> 2025 | D1: =Data!K9 -> 2026 | E1: =Data!L9 -> 2027 | F1: =Data!M9 -> 2028 | G1: =Data!N9 -> 2029 | H1: =Data!O9 -> 2030 | I1: =Data!P9 -> 2031 | ... AB1: =Data!AI9 -> 2050
A2: battery electric vehicle | B2: =Data!I24 -> 0.1218401 | C2: =Data!J24 -> 0.1218401 | D2: =Data!K24 -> 0.14418449 | E2: =Data!L24 -> 0.15163113 | F2: =Data!M24 -> 0.16139744 | G2: =Data!N24 -> 0.17408585 | H2: =Data!O24 -> 0.19037035 | I2: =Data!P24 -> 0.21094525 | ... AB2: =Data!AI24 -> 0.73753712
A3: natural gas vehicle | B3: =Data!I25 -> 0.015737248 | C3: =Data!J25 -> 0.015737248 | D3: =Data!K25 -> 0.015737248 | E3: =Data!L25 -> 0.015737248 | F3: =Data!M25 -> 0.015737248 | G3: =Data!N25 -> 0.015737248 | H3: =Data!O25 -> 0.015737248 | I3: =Data!P25 -> 0.015737248 | ... AB3: =Data!AI25 -> 0.015737248
A4: gasoline vehicle | B4: =Data!I26 -> 0.37956814 | C4: =Data!J26 -> 0.37956814 | D4: =Data!K26 -> 0.37956814 | E4: =Data!L26 -> 0.37956814 | F4: =Data!M26 -> 0.37956814 | G4: =Data!N26 -> 0.37956814 | H4: =Data!O26 -> 0.37956814 | I4: =Data!P26 -> 0.37956814 | ... AB4: =Data!AI26 -> 0.37956814
A5: diesel vehicle | B5: =Data!I27 -> 1 | C5: =Data!J27 -> 1 | D5: =Data!K27 -> 1 | E5: =Data!L27 -> 1 | F5: =Data!M27 -> 1 | G5: =Data!N27 -> 1 | H5: =Data!O27 -> 1 | I5: =Data!P27 -> 1 | ... AB5: =Data!AI27 -> 1
A6: plugin hybrid vehicle | B6: =Data!I28 -> 0 | C6: =Data!J28 -> 0 | D6: =Data!K28 -> 0 | E6: =Data!L28 -> 0 | F6: =Data!M28 -> 0 | G6: =Data!N28 -> 0 | H6: =Data!O28 -> 0 | I6: =Data!P28 -> 0 | ... AB6: =Data!AI28 -> 0
A7: LPG vehicle | B7: =Data!I29 -> 0.055449391 | C7: =Data!J29 -> 0.055449391 | D7: =Data!K29 -> 0.055449391 | E7: =Data!L29 -> 0.055449391 | F7: =Data!M29 -> 0.055449391 | G7: =Data!N29 -> 0.055449391 | H7: =Data!O29 -> 0.055449391 | I7: =Data!P29 -> 0.055449391 | ... AB7: =Data!AI29 -> 0.055449391
A8: hydrogen vehicle | B8: =Data!I30 -> 0.002028695 | C8: =Data!J30 -> 0.002028695 | D8: =Data!K30 -> 0.002028695 | E8: =Data!L30 -> 0.002028695 | F8: =Data!M30 -> 0.002028695 | G8: =Data!N30 -> 0.002028695 | H8: =Data!O30 -> 0.002028695 | I8: =Data!P30 -> 0.002028695 | ... AB8: =Data!AI30 -> 0.002028695

Sheet TTS-HDVs-frgt
A1: Max Fraction of Production (dimensionless) | B1: =Data!I9 -> 2024 | C1: =Data!J9 -> 2025 | D1: =Data!K9 -> 2026 | E1: =Data!L9 -> 2027 | F1: =Data!M9 -> 2028 | G1: =Data!N9 -> 2029 | H1: =Data!O9 -> 2030 | I1: =Data!P9 -> 2031 | ... AB1: =Data!AI9 -> 2050
A2: battery electric vehicle | B2: =Data!I31 -> 0.004808968 | C2: =Data!J31 -> 0.004808968 | D2: =Data!K31 -> 0.013530705 | E2: =Data!L31 -> 0.016437367 | F2: =Data!M31 -> 0.02024947 | G2: =Data!N31 -> 0.025202167 | H2: =Data!O31 -> 0.03155853 | I2: =Data!P31 -> 0.039589577 | ... AB2: =Data!AI31 -> 0.24513533
A3: natural gas vehicle | B3: =Data!I32 -> 0.022159679 | C3: =Data!J32 -> 0.022159679 | D3: =Data!K32 -> 0.022159679 | E3: =Data!L32 -> 0.022159679 | F3: =Data!M32 -> 0.022159679 | G3: =Data!N32 -> 0.022159679 | H3: =Data!O32 -> 0.022159679 | I3: =Data!P32 -> 0.022159679 | ... AB3: =Data!AI32 -> 0.022159679
A4: gasoline vehicle | B4: =Data!I33 -> 0.000753581 | C4: =Data!J33 -> 0.000753581 | D4: =Data!K33 -> 0.000753581 | E4: =Data!L33 -> 0.000753581 | F4: =Data!M33 -> 0.000753581 | G4: =Data!N33 -> 0.000753581 | H4: =Data!O33 -> 0.000753581 | I4: =Data!P33 -> 0.000753581 | ... AB4: =Data!AI33 -> 0.000753581
A5: diesel vehicle | B5: =Data!I34 -> 1 | C5: =Data!J34 -> 1 | D5: =Data!K34 -> 1 | E5: =Data!L34 -> 1 | F5: =Data!M34 -> 1 | G5: =Data!N34 -> 1 | H5: =Data!O34 -> 1 | I5: =Data!P34 -> 1 | ... AB5: =Data!AI34 -> 1
A6: plugin hybrid vehicle | B6: =Data!I35 -> 0 | C6: =Data!J35 -> 0 | D6: =Data!K35 -> 0 | E6: =Data!L35 -> 0 | F6: =Data!M35 -> 0 | G6: =Data!N35 -> 0 | H6: =Data!O35 -> 0 | I6: =Data!P35 -> 0 | ... AB6: =Data!AI35 -> 0
A7: LPG vehicle | B7: =Data!I36 -> 0 | C7: =Data!J36 -> 0 | D7: =Data!K36 -> 0 | E7: =Data!L36 -> 0 | F7: =Data!M36 -> 0 | G7: =Data!N36 -> 0 | H7: =Data!O36 -> 0 | I7: =Data!P36 -> 0 | ... AB7: =Data!AI36 -> 0
A8: hydrogen vehicle | B8: =Data!I37 -> 0 | C8: =Data!J37 -> 0 | D8: =Data!K37 -> 0 | E8: =Data!L37 -> 0 | F8: =Data!M37 -> 0 | G8: =Data!N37 -> 0 | H8: =Data!O37 -> 0 | I8: =Data!P37 -> 0 | ... AB8: =Data!AI37 -> 0

Sheet TTS-aircraft-psgr
A1: Max Fraction of Production (dimensionless) | B1: =Data!I9 -> 2024 | C1: =Data!J9 -> 2025 | D1: =Data!K9 -> 2026 | E1: =Data!L9 -> 2027 | F1: =Data!M9 -> 2028 | G1: =Data!N9 -> 2029 | H1: =Data!O9 -> 2030 | I1: =Data!P9 -> 2031 | ... AB1: =Data!AI9 -> 2050
A2: battery electric vehicle | B2: =Data!I38 -> 0 | C2: =Data!J38 -> 0 | D2: =Data!K38 -> 0 | E2: =Data!L38 -> 0 | F2: =Data!M38 -> 0 | G2: =Data!N38 -> 0 | H2: =Data!O38 -> 0 | I2: =Data!P38 -> 0 | ... AB2: =Data!AI38 -> 0
A3: natural gas vehicle | B3: =Data!I39 -> 0 | C3: =Data!J39 -> 0 | D3: =Data!K39 -> 0 | E3: =Data!L39 -> 0 | F3: =Data!M39 -> 0 | G3: =Data!N39 -> 0 | H3: =Data!O39 -> 0 | I3: =Data!P39 -> 0 | ... AB3: =Data!AI39 -> 0
A4: gasoline vehicle | B4: =Data!I40 -> 0 | C4: =Data!J40 -> 0 | D4: =Data!K40 -> 0 | E4: =Data!L40 -> 0 | F4: =Data!M40 -> 0 | G4: =Data!N40 -> 0 | H4: =Data!O40 -> 0 | I4: =Data!P40 -> 0 | ... AB4: =Data!AI40 -> 0
