Workbook

Sheet About
A1: HE Hydrogen Exports
A3: Sources: | B3: World hydrogen trade by 2030
B4: International Energy Agency (IEA)
B5: Global Hydrogen Review 2025
B6: 2025
B7: https://www.iea.org/reports/global-hydrogen-review-2025
B8: Trade chapter: about 0.8 Mt/yr of hydrogen-equivalent trade is operational, at final investment decision or under construction for 2030, with another 1.0 Mt of strong and 1.8 Mt of moderate potential, out of more than 16 Mt announced; about 85% of planned trade is shipped as ammonia. Used for the 2030 anchor of world import demand and the range check on the Checks tab. These are project counts, not a demand forecast.
B10: EU import demand
B11: European Court of Auditors
B12: Special report 11/2024: The EU's industrial policy on renewable hydrogen
B13: 2024
B14: https://www.eca.europa.eu/ECAPublications/SR-2024-11/SR-2024-11_EN.pdf
B15: Finds the REPowerEU target of 10 Mt of renewable hydrogen imports by 2030 unrealistic. Used only to justify an EU-led green import demand far below that target; not a source for any number in this file.
B17: Japan import demand and contracted US supply
B18: JERA
B19: Certification under the Hydrogen Society Promotion Act (press release, 19 December 2025)
B20: 2025
B21: https://www.jera.co.jp/en/news/information/20251219_2329
B22: JERA's supply plan for low-carbon ammonia from the Blue Point project (Louisiana) was certified for Japan's price-gap contract-for-difference support. Shows Japanese import demand accepts low-carbon (blue) supply.
B24: Contracted US low-carbon exports
B25: CF Industries Holdings
B26: Form 10-Q for the quarter ended 30 June 2026
B27: 2026
B28: https://www.sec.gov/Archives/edgar/data/0001324404/000132440426000019/cf-20260630.htm
B29: Blue Point joint venture (CF 40%, JERA 35%, Mitsui 25%): construction started, production expected in 2029, owners take product pro rata. The 1.4 Mt/yr ammonia capacity is as reported in trade press at the investment decision; check it against company filings before relying on it.
B31: Energy content of hydrogen
B32: Energy Innovation
B33: Energy Policy Simulator input BCF-BpMMTH (BTU per MMT hydrogen)
B34: 2026
B35: https://github.com/EnergyInnovation/eps-us
B36: The model converts hydrogen mass to energy at 1.34511E+14 BTU per million metric tons (higher heating value). This file uses the same factor so volumes match the model's hydrogen ledger.
B38: Price elasticity of export demand
B39: Energy Innovation
B40: Energy Policy Simulator input IESE (chemicals, ISIC 20)
B41: 2026
B42: https://github.com/EnergyInnovation/eps-us
B43: No hydrogen-specific trade elasticity was found. The model's Armington elasticity for chemicals (2.4), the sector that trades ammonia today, is used. Treat it as a placeholder for sensitivity runs (1 to 5).
A46: Notes:
A47: Purpose | B47: This file sets up hydrogen export demand for the EPS. Only the clean grades are traded: green hydrogen (electrolysis with dedicated clean power) and low carbon hydrogen (any pathway the region counts as low carbon). Ordinary hydrogen and its derivatives trade inside the chemicals industry instead. The model adds exports to the demand for each grade, so the hydrogen sector builds capacity for them, and books them in the fuel export ledger. In policy runs exports rise or fall with the change in the grade's modeled production cost, relative to the world hydrogen price, through the same market-share formula the model uses for exports of other goods.
A48: Layout | B48: Edit the Assumptions tab. The Calcs tab fills in every year and converts to BTU; the Checks tab tests the results; the four dark blue tabs at the end are exported as CSVs: HE-BHEbG (BAU exports by grade), HE-WHIDbG (world import demand by grade), HE-HEPE (price elasticity) and HE-HERT (response time).
...

Sheet Assumptions
A1: Assumptions (edit the values on this tab)
A3: World import demand, Mt H2-equivalent per year (anchor years; Calcs interpolates linearly)
A4: Year | B4: 2021 | C4: 2025 | D4: 2027 | E4: 2030 | F4: 2035 | G4: 2040 | H4: 2050
A5: Green hydrogen (EU-led) | B5: 0 | C5: 0 | D5: 0.1 | E5: 1 | F5: 3 | G5: 6 | H5: 18
A6: Low carbon hydrogen (Japan, Korea, Singapore) | B6: 0 | C6: 0 | D6: 0.05 | E6: 1 | F6: 2.5 | G6: 5 | H6: 12
A8: Contracted U.S. low carbon exports (Blue Point)
A9: Ammonia capacity, Mt NH3 per year | B9: 1.4
A10: Hydrogen mass fraction of ammonia | B10: =3*1.00794/(14.0067+3*1.00794) -> 0.177553
A11: First production year | B11: 2029
A12: Share of full output in the first year | B12: 0.5
A13: Hydrogen content at full output, Mt H2 per year | B13: =B9*B10 -> 0.24857421
A15: U.S. share of world import demand
A16: Green, all years | B16: 0.01
A17: Low carbon, 2030 (Blue Point share of world demand) | B17: =B13/INDEX(B6:H6,MATCH(2030,B4:H4,0)) -> 0.24857421
A18: Low carbon, 2050 | B18: 0.15
A20: Model parameters
A21: BTU per million metric tons of hydrogen (EPS BpMMTH, HHV) | B21: 134511000000000
A22: Price elasticity of export demand (dimensionless) | B22: 2.4
A23: Response time of exports, years | B23: 4

Sheet Calcs
A1: Annual values: how much the U.S. exports of each grade in BAU, and how big the world market is
A2: Linear interpolation between the anchor years, the contracted volume and the U.S. share, then conversion to BTU.
A4: Year | B4: 2021 | C4: 2022 | D4: 2023 | E4: 2024 | F4: 2025 | G4: 2026 | H4: 2027 | I4: 2028 | J4: 2029 | K4: 2030 | L4: 2031 | M4: 2032 | N4: 2033 | O4: 2034 | P4: 2035 | Q4: 2036 | R4: 2037 | S4: 2038 | T4: 2039 | U4: 2040 | V4: 2041 | W4: 2042 | X4: 2043 | Y4: 2044 | Z4: 2045 | AA4: 2046 | AB4: 2047 | AC4: 2048 | AD4: 2049 | AE4: 2050
A5: Anchor interval (position of the anchor year at or before this year) | B5: =MIN(MATCH(B4,Assumptions!$B$4:$H$4,1),6) -> 1 | C5: =MIN(MATCH(C4,Assumptions!$B$4:$H$4,1),6) -> 1 | D5: =MIN(MATCH(D4,Assumptions!$B$4:$H$4,1),6) -> 1 | E5: =MIN(MATCH(E4,Assumptions!$B$4:$H$4,1),6) -> 1 | F5: =MIN(MATCH(F4,Assumptions!$B$4:$H$4,1),6) -> 2 | G5: =MIN(MATCH(G4,Assumptions!$B$4:$H$4,1),6) -> 2 | H5: =MIN(MATCH(H4,Assumptions!$B$4:$H$4,1),6) -> 3 | I5: =MIN(MATCH(I4,Assumptions!$B$4:$H$4,1),6) -> 3 | ... AE5: =MIN(MATCH(AE4,Assumptions!$B$4:$H$4,1),6) -> 6
A6: World green import demand, Mt H2 | B6: =INDEX(Assumptions!$B$5:$H$5,B5)+(B4-INDEX(Assumptions!$B$4:$H$4,B5))*(INDEX(Assumptions!$B$5:$H$5,B5+1)-INDEX(Assumptions!$B$5:$H$5,B5))/(INDEX(Assumptions!$B$4:$H$4,B5+1)-INDEX(Assumptions!$B$4:$H$4,B5)) -> 0 | C6: =INDEX(Assumptions!$B$5:$H$5,C5)+(C4-INDEX(Assumptions!$B$4:$H$4,C5))*(INDEX(Assumptions!$B$5:$H$5,C5+1)-INDEX(Assumptions!$B$5:$H$5,C5))/(INDEX(Assumptions!$B$4:$H$4,C5+1)-INDEX(Assumptions!$B$4:$H$4,C5)) -> 0 | D6: =INDEX(Assumptions!$B$5:$H$5,D5)+(D4-INDEX(Assumptions!$B$4:$H$4,D5))*(INDEX(Assumptions!$B$5:$H$5,D5+1)-INDEX(Assumptions!$B$5:$H$5,D5))/(INDEX(Assumptions!$B$4:$H$4,D5+1)-INDEX(Assumptions!$B$4:$H$4,D5)) -> 0 | E6: =INDEX(Assumptions!$B$5:$H$5,E5)+(E4-INDEX(Assumptions!$B$4:$H$4,E5))*(INDEX(Assumptions!$B$5:$H$5,E5+1)-INDEX(Assumptions!$B$5:$H$5,E5))/(INDEX(Assumptions!$B$4:$H$4,E5+1)-INDEX(Assumptions!$B$4:$H$4,E5)) -> 0 | F6: =INDEX(Assumptions!$B$5:$H$5,F5)+(F4-INDEX(Assumptions!$B$4:$H$4,F5))*(INDEX(Assumptions!$B$5:$H$5,F5+1)-INDEX(Assumptions!$B$5:$H$5,F5))/(INDEX(Assumptions!$B$4:$H$4,F5+1)-INDEX(Assumptions!$B$4:$H$4,F5)) -> 0 | G6: =INDEX(Assumptions!$B$5:$H$5,G5)+(G4-INDEX(Assumptions!$B$4:$H$4,G5))*(INDEX(Assumptions!$B$5:$H$5,G5+1)-INDEX(Assumptions!$B$5:$H$5,G5))/(INDEX(Assumptions!$B$4:$H$4,G5+1)-INDEX(Assumptions!$B$4:$H$4,G5)) -> 0.05 | H6: =INDEX(Assumptions!$B$5:$H$5,H5)+(H4-INDEX(Assumptions!$B$4:$H$4,H5))*(INDEX(Assumptions!$B$5:$H$5,H5+1)-INDEX(Assumptions!$B$5:$H$5,H5))/(INDEX(Assumptions!$B$4:$H$4,H5+1)-INDEX(Assumptions!$B$4:$H$4,H5)) -> 0.1 | I6: =INDEX(Assumptions!$B$5:$H$5,I5)+(I4-INDEX(Assumptions!$B$4:$H$4,I5))*(INDEX(Assumptions!$B$5:$H$5,I5+1)-INDEX(Assumptions!$B$5:$H$5,I5))/(INDEX(Assumptions!$B$4:$H$4,I5+1)-INDEX(Assumptions!$B$4:$H$4,I5)) -> 0.4 | ... AE6: =INDEX(Assumptions!$B$5:$H$5,AE5)+(AE4-INDEX(Assumptions!$B$4:$H$4,AE5))*(INDEX(Assumptions!$B$5:$H$5,AE5+1)-INDEX(Assumptions!$B$5:$H$5,AE5))/(INDEX(Assumptions!$B$4:$H$4,AE5+1)-INDEX(Assumptions!$B$4:$H$4,AE5)) -> 18
A7: World low carbon import demand, Mt H2 | B7: =INDEX(Assumptions!$B$6:$H$6,B5)+(B4-INDEX(Assumptions!$B$4:$H$4,B5))*(INDEX(Assumptions!$B$6:$H$6,B5+1)-INDEX(Assumptions!$B$6:$H$6,B5))/(INDEX(Assumptions!$B$4:$H$4,B5+1)-INDEX(Assumptions!$B$4:$H$4,B5)) -> 0 | C7: =INDEX(Assumptions!$B$6:$H$6,C5)+(C4-INDEX(Assumptions!$B$4:$H$4,C5))*(INDEX(Assumptions!$B$6:$H$6,C5+1)-INDEX(Assumptions!$B$6:$H$6,C5))/(INDEX(Assumptions!$B$4:$H$4,C5+1)-INDEX(Assumptions!$B$4:$H$4,C5)) -> 0 | D7: =INDEX(Assumptions!$B$6:$H$6,D5)+(D4-INDEX(Assumptions!$B$4:$H$4,D5))*(INDEX(Assumptions!$B$6:$H$6,D5+1)-INDEX(Assumptions!$B$6:$H$6,D5))/(INDEX(Assumptions!$B$4:$H$4,D5+1)-INDEX(Assumptions!$B$4:$H$4,D5)) -> 0 | E7: =INDEX(Assumptions!$B$6:$H$6,E5)+(E4-INDEX(Assumptions!$B$4:$H$4,E5))*(INDEX(Assumptions!$B$6:$H$6,E5+1)-INDEX(Assumptions!$B$6:$H$6,E5))/(INDEX(Assumptions!$B$4:$H$4,E5+1)-INDEX(Assumptions!$B$4:$H$4,E5)) -> 0 | F7: =INDEX(Assumptions!$B$6:$H$6,F5)+(F4-INDEX(Assumptions!$B$4:$H$4,F5))*(INDEX(Assumptions!$B$6:$H$6,F5+1)-INDEX(Assumptions!$B$6:$H$6,F5))/(INDEX(Assumptions!$B$4:$H$4,F5+1)-INDEX(Assumptions!$B$4:$H$4,F5)) -> 0 | G7: =INDEX(Assumptions!$B$6:$H$6,G5)+(G4-INDEX(Assumptions!$B$4:$H$4,G5))*(INDEX(Assumptions!$B$6:$H$6,G5+1)-INDEX(Assumptions!$B$6:$H$6,G5))/(INDEX(Assumptions!$B$4:$H$4,G5+1)-INDEX(Assumptions!$B$4:$H$4,G5)) -> 0.025 | H7: =INDEX(Assumptions!$B$6:$H$6,H5)+(H4-INDEX(Assumptions!$B$4:$H$4,H5))*(INDEX(Assumptions!$B$6:$H$6,H5+1)-INDEX(Assumptions!$B$6:$H$6,H5))/(INDEX(Assumptions!$B$4:$H$4,H5+1)-INDEX(Assumptions!$B$4:$H$4,H5)) -> 0.05 | I7: =INDEX(Assumptions!$B$6:$H$6,I5)+(I4-INDEX(Assumptions!$B$4:$H$4,I5))*(INDEX(Assumptions!$B$6:$H$6,I5+1)-INDEX(Assumptions!$B$6:$H$6,I5))/(INDEX(Assumptions!$B$4:$H$4,I5+1)-INDEX(Assumptions!$B$4:$H$4,I5)) -> 0.36666667 | ... AE7: =INDEX(Assumptions!$B$6:$H$6,AE5)+(AE4-INDEX(Assumptions!$B$4:$H$4,AE5))*(INDEX(Assumptions!$B$6:$H$6,AE5+1)-INDEX(Assumptions!$B$6:$H$6,AE5))/(INDEX(Assumptions!$B$4:$H$4,AE5+1)-INDEX(Assumptions!$B$4:$H$4,AE5)) -> 12
A8: Contracted U.S. low carbon exports, Mt H2 | B8: =IF(B4<Assumptions!$B$11,0,IF(B4=Assumptions!$B$11,Assumptions!$B$12,1))*Assumptions!$B$13 -> 0 | C8: =IF(C4<Assumptions!$B$11,0,IF(C4=Assumptions!$B$11,Assumptions!$B$12,1))*Assumptions!$B$13 -> 0 | D8: =IF(D4<Assumptions!$B$11,0,IF(D4=Assumptions!$B$11,Assumptions!$B$12,1))*Assumptions!$B$13 -> 0 | E8: =IF(E4<Assumptions!$B$11,0,IF(E4=Assumptions!$B$11,Assumptions!$B$12,1))*Assumptions!$B$13 -> 0 | F8: =IF(F4<Assumptions!$B$11,0,IF(F4=Assumptions!$B$11,Assumptions!$B$12,1))*Assumptions!$B$13 -> 0 | G8: =IF(G4<Assumptions!$B$11,0,IF(G4=Assumptions!$B$11,Assumptions!$B$12,1))*Assumptions!$B$13 -> 0 | H8: =IF(H4<Assumptions!$B$11,0,IF(H4=Assumptions!$B$11,Assumptions!$B$12,1))*Assumptions!$B$13 -> 0 | I8: =IF(I4<Assumptions!$B$11,0,IF(I4=Assumptions!$B$11,Assumptions!$B$12,1))*Assumptions!$B$13 -> 0 | ... AE8: =IF(AE4<Assumptions!$B$11,0,IF(AE4=Assumptions!$B$11,Assumptions!$B$12,1))*Assumptions!$B$13 -> 0.24857421
A9: U.S. share of world green demand | B9: =Assumptions!$B$16 -> 0.01 | C9: =Assumptions!$B$16 -> 0.01 | D9: =Assumptions!$B$16 -> 0.01 | E9: =Assumptions!$B$16 -> 0.01 | F9: =Assumptions!$B$16 -> 0.01 | G9: =Assumptions!$B$16 -> 0.01 | H9: =Assumptions!$B$16 -> 0.01 | I9: =Assumptions!$B$16 -> 0.01 | ... AE9: =Assumptions!$B$16 -> 0.01
A10: U.S. share of world low carbon demand | B10: =IF(B4<2030,0,Assumptions!$B$17+(Assumptions!$B$18-Assumptions!$B$17)*(B4-2030)/(2050-2030)) -> 0 | C10: =IF(C4<2030,0,Assumptions!$B$17+(Assumptions!$B$18-Assumptions!$B$17)*(C4-2030)/(2050-2030)) -> 0 | D10: =IF(D4<2030,0,Assumptions!$B$17+(Assumptions!$B$18-Assumptions!$B$17)*(D4-2030)/(2050-2030)) -> 0 | E10: =IF(E4<2030,0,Assumptions!$B$17+(Assumptions!$B$18-Assumptions!$B$17)*(E4-2030)/(2050-2030)) -> 0 | F10: =IF(F4<2030,0,Assumptions!$B$17+(Assumptions!$B$18-Assumptions!$B$17)*(F4-2030)/(2050-2030)) -> 0 | G10: =IF(G4<2030,0,Assumptions!$B$17+(Assumptions!$B$18-Assumptions!$B$17)*(G4-2030)/(2050-2030)) -> 0 | H10: =IF(H4<2030,0,Assumptions!$B$17+(Assumptions!$B$18-Assumptions!$B$17)*(H4-2030)/(2050-2030)) -> 0 | I10: =IF(I4<2030,0,Assumptions!$B$17+(Assumptions!$B$18-Assumptions!$B$17)*(I4-2030)/(2050-2030)) -> 0 | ... AE10: =IF(AE4<2030,0,Assumptions!$B$17+(Assumptions!$B$18-Assumptions!$B$17)*(AE4-2030)/(2050-2030)) -> 0.15
A11: U.S. BAU GREEN EXPORTS, Mt H2 (used in the output file) | B11: =B9*B6 -> 0 | C11: =C9*C6 -> 0 | D11: =D9*D6 -> 0 | E11: =E9*E6 -> 0 | F11: =F9*F6 -> 0 | G11: =G9*G6 -> 0.0005 | H11: =H9*H6 -> 0.001 | I11: =I9*I6 -> 0.004 | ... AE11: =AE9*AE6 -> 0.18
A12: U.S. BAU LOW CARBON EXPORTS, Mt H2 (used in the output file) | B12: =MAX(B8,B10*B7) -> 0 | C12: =MAX(C8,C10*C7) -> 0 | D12: =MAX(D8,D10*D7) -> 0 | E12: =MAX(E8,E10*E7) -> 0 | F12: =MAX(F8,F10*F7) -> 0 | G12: =MAX(G8,G10*G7) -> 0 | H12: =MAX(H8,H10*H7) -> 0 | I12: =MAX(I8,I10*I7) -> 0 | ... AE12: =MAX(AE8,AE10*AE7) -> 1.8

Sheet Checks
A1: Checks (1 = problem)
A3: CHECK: do BAU green exports ever exceed world green import demand? / 1 = problem | B3: =IF(SUMPRODUCT(--(Calcs!B11:AE11>Calcs!B6:AE6+0.000000000001))>0,1,0) -> 0
A4: CHECK: do BAU low carbon exports ever exceed world low carbon import demand? / 1 = problem | B4: =IF(SUMPRODUCT(--(Calcs!B12:AE12>Calcs!B7:AE7+0.000000000001))>0,1,0) -> 0
A5: CHECK: is 2030 world import demand outside 0.8-3.6 Mt (IEA committed to committed + strong + moderate)? / 1 = problem | B5: =IF(OR(Calcs!K6+Calcs!K7<0.8,Calcs!K6+Calcs!K7>3.6),1,0) -> 0
A6: For reference: 2030 world import demand, Mt H2 | B6: =Calcs!K6+Calcs!K7 -> 2
A7: For reference: 2050 U.S. BAU exports, Mt H2 | B7: =Calcs!AE11+Calcs!AE12 -> 1.98

Sheet HE-BHEbG
A1: BTU per year (below: grade / right: year) | B1: 2021 | C1: 2022 | D1: 2023 | E1: 2024 | F1: 2025 | G1: 2026 | H1: 2027 | I1: 2028 | J1: 2029 | K1: 2030 | L1: 2031 | M1: 2032 | N1: 2033 | O1: 2034 | P1: 2035 | Q1: 2036 | R1: 2037 | S1: 2038 | T1: 2039 | U1: 2040 | V1: 2041 | W1: 2042 | X1: 2043 | Y1: 2044 | Z1: 2045 | AA1: 2046 | AB1: 2047 | AC1: 2048 | AD1: 2049 | AE1: 2050
A2: green hydrogen exports | B2: =Calcs!B11*Assumptions!$B$21 -> 0 | C2: =Calcs!C11*Assumptions!$B$21 -> 0 | D2: =Calcs!D11*Assumptions!$B$21 -> 0 | E2: =Calcs!E11*Assumptions!$B$21 -> 0 | F2: =Calcs!F11*Assumptions!$B$21 -> 0 | G2: =Calcs!G11*Assumptions!$B$21 -> 67255500000 | H2: =Calcs!H11*Assumptions!$B$21 -> 134511000000 | I2: =Calcs!I11*Assumptions!$B$21 -> 538044000000 | ... AE2: =Calcs!AE11*Assumptions!$B$21 -> 24211980000000
A3: low carbon hydrogen exports | B3: =Calcs!B12*Assumptions!$B$21 -> 0 | C3: =Calcs!C12*Assumptions!$B$21 -> 0 | D3: =Calcs!D12*Assumptions!$B$21 -> 0 | E3: =Calcs!E12*Assumptions!$B$21 -> 0 | F3: =Calcs!F12*Assumptions!$B$21 -> 0 | G3: =Calcs!G12*Assumptions!$B$21 -> 0 | H3: =Calcs!H12*Assumptions!$B$21 -> 0 | I3: =Calcs!I12*Assumptions!$B$21 -> 0 | ... AE3: =Calcs!AE12*Assumptions!$B$21 -> 2.421198e+14

Sheet HE-WHIDbG
A1: BTU per year (below: grade / right: year) | B1: 2021 | C1: 2022 | D1: 2023 | E1: 2024 | F1: 2025 | G1: 2026 | H1: 2027 | I1: 2028 | J1: 2029 | K1: 2030 | L1: 2031 | M1: 2032 | N1: 2033 | O1: 2034 | P1: 2035 | Q1: 2036 | R1: 2037 | S1: 2038 | T1: 2039 | U1: 2040 | V1: 2041 | W1: 2042 | X1: 2043 | Y1: 2044 | Z1: 2045 | AA1: 2046 | AB1: 2047 | AC1: 2048 | AD1: 2049 | AE1: 2050
A2: green hydrogen exports | B2: =Calcs!B6*Assumptions!$B$21 -> 0 | C2: =Calcs!C6*Assumptions!$B$21 -> 0 | D2: =Calcs!D6*Assumptions!$B$21 -> 0 | E2: =Calcs!E6*Assumptions!$B$21 -> 0 | F2: =Calcs!F6*Assumptions!$B$21 -> 0 | G2: =Calcs!G6*Assumptions!$B$21 -> 6725550000000 | H2: =Calcs!H6*Assumptions!$B$21 -> 13451100000000 | I2: =Calcs!I6*Assumptions!$B$21 -> 53804400000000 | ... AE2: =Calcs!AE6*Assumptions!$B$21 -> 2.421198e+15
A3: low carbon hydrogen exports | B3: =Calcs!B7*Assumptions!$B$21 -> 0 | C3: =Calcs!C7*Assumptions!$B$21 -> 0 | D3: =Calcs!D7*Assumptions!$B$21 -> 0 | E3: =Calcs!E7*Assumptions!$B$21 -> 0 | F3: =Calcs!F7*Assumptions!$B$21 -> 0 | G3: =Calcs!G7*Assumptions!$B$21 -> 3362775000000 | H3: =Calcs!H7*Assumptions!$B$21 -> 6725550000000 | I3: =Calcs!I7*Assumptions!$B$21 -> 49320700000000 | ... AE3: =Calcs!AE7*Assumptions!$B$21 -> 1.614132e+15

Sheet HE-HEPE
A1: Parameter | B1: Value
A2: Hydrogen Export Price Elasticity (dimensionless) | B2: =Assumptions!B22 -> 2.4

Sheet HE-HERT
A1: Parameter | B1: Value
A2: Hydrogen Export Response Time (years) | B2: =Assumptions!B23 -> 4
