Workbook
Name CH4_Ar4_to_AR5: #REF!
Name CH4_Ar4_to_AR5: Overview!$B$25
Name CH4_to_CO2e: #REF!
Name Fraction_coal: [1]About!$C$66
Name gal_per_barrel: [2]About!$A$63
Name gwp_ch4: Overview!$B$21
Name gwp_n2o: Overview!$B$20
Name HHV_Adjust: [3]About!$A$203
Name IQ_CH: 110000
Name IQ_CQ: 5000
Name IQ_CY: 10000
Name IQ_DAILY: 500000
Name IQ_FH: 100000
Name IQ_FQ: 500
Name IQ_FY: 1000
Name IQ_LTM: 2000
Name IQ_MONTH: 15000
Name IQ_NTM: 6000
Name IQ_WEEK: 50000
Name IQ_YTD: 3000
Name metricton_to_shortton: [4]Overview!$B$19
Name metricton_to_shortton: Overview!$B$19
Name million: [4]Overview!$B$22
Name million: Overview!$B$22
Name N2O_AR4_to_AR5: Overview!$B$26
Name N2O_to_CO2e: '[5]Cross-Page Data'!$C$13
Name Percent_rural: [1]About!$A$105
Name Percent_urban: [1]About!$A$104
Name quadrillion: [1]About!$B$107
Name Table4_1_22: '[1]AEO23 Table 4'!$C$1:$AG$1
Name Table4_22: '[1]AEO23 Table 4'!$C$34:$AG$74
Name Table4_A_22: '[1]AEO23 Table 4'!$A$34:$A$74
Name Table5_1_22: '[1]AEO23 Table 5'!$C$1:$AG$1
Name Table5_22: '[1]AEO23 Table 5'!$C$29:$AG$58
Name Table5_A_22: '[1]AEO23 Table 5'!$A$29:$A$58
Name unit_conv: [6]About!$A$108

Sheet Overview
B2: This spreadsheet compares start year EPS emissions to EPA and EIA emissions estimates.
B3: EPS Outputs
B4: US EPS
B5: https://us.energypolicy.solutions/
B7: EPA
B8: Inventory of U.S. Greenhouse Gas Emissions and Sinks
B9: https://www.epa.gov/ghgemissions/inventory-us-greenhouse-gas-emissions-and-sinks-1990-2021
B11: EIA
B12: Annual Energy Outlook
B13: 2022
B14: https://www.eia.gov/outlooks/aeo/tables_ref.php
B18: Conversions
B19: 1.10231 | C19: metricton_to_shortton
B20: 265 | C20: GWP N2O
B21: 28 | C21: GWP CH4
B22: =10^6 -> 1000000 | C22: million
B24: GWP Conversions
B25: =28/25 -> 1.12 | C25: CH4_Ar4_to_AR5
B26: =265/298 -> 0.88926174 | C26: N2O_AR4_to_AR5
B28: Toggle AR4 to AR5
B29: AR5 GWP
B30: AR4 GWP | C30: AR5 GWP

Sheet 1. Transportation
H1: Transportation
H2: MMTCO2e
A5: EIA | B5: EPS Sub 4 | C5: EPS Sub 3 | D5: EPS Sub 2 | E5: EPS Sub 1 | F5: EPS Variable | G5: EPA Table
H7: 1.1 | I7: Total Transportation Sector Greenhouse Gas Emissions by Pollutant Type
K8: EPS 2024 | L8: EPA 2023 | M8: EIA 2021
F9: Transportation Pollutant Emissions Disaggregated | G9: EPA_Table 3-7 | J9: CO2 | K9: =SUMIFS(EPS!$L:$L,EPS!$B:$B,F9,EPS!$I:$I,J9) -> 1720.5574 | L9: =SUM('Table 3-13'!F5:F10,'Table 3-13'!F12:F18,'Table 3-13'!F21:F23,'Table 3-13'!F27,'Table 3-13'!F29,'Table 3-13'!F34:F35,'Table 3-13'!F41) -> 1704.5214
F10: Transportation Pollutant Emissions Disaggregated | G10: EPA_Table 3-7 | J10: CH4 | K10: =SUMIFS(EPS!$L:$L,EPS!$B:$B,F10,EPS!$I:$I,J10) -> 2.0116845 | L10: ='Table 3-10'!C6 -> 2.5398312
F11: Transportation Pollutant Emissions Disaggregated | G11: EPA_Table 3-7 | J11: N2O | K11: =SUMIFS(EPS!$L:$L,EPS!$B:$B,F11,EPS!$I:$I,J11) -> 11.32663 | L11: ='Table 3-10'!C7 -> 16.183964
J12: Total CO2e | K12: =SUM(K9:K11) -> 1733.8957 | L12: =SUM(L9:L11) -> 1723.2452 | M12: ='Table 11.5'!M62-'Table 11.5'!L62-M32 -> 1741.377 | N12: *natural gas total removed for EIA
H25: 1.2 | I25: Transportation CO2 Emissions by Fuel Type
K26: EPS 2024 | L26: EPA 2023 | M26: EIA 2021
A27: motor gasoline | B27: petroleum gasoline tf | F27: Transportation Pollutant Emissions Disaggregated | G27: EPA_Table 3-13 | J27: Gasoline | K27: =SUMIFS(EPS!$L:$L,EPS!$B:$B,F27,EPS!$F:$F,"*"&B27&"*",EPS!$I:$I,"CO2") -> 1070.4536 | L27: ='Table 3-13'!F4 -> 1035.6964 | M27: =SUMIFS('Table 11.5'!$62:$62,'Table 11.5'!$1:$1,A27) -> 1024.604
A28: distillate fuel oil | B28: petroleum diesel tf | F28: Transportation Pollutant Emissions Disaggregated | G28: EPA_Table 3-13 | J28: Distillate Fuel Oil | K28: =SUMIFS(EPS!$L:$L,EPS!$B:$B,F28,EPS!$F:$F,"*"&B28&"*",EPS!$I:$I,"CO2") -> 463.07397 | L28: ='Table 3-13'!F11 -> 478.27614 | M28: =SUMIFS('Table 11.5'!$62:$62,'Table 11.5'!$1:$1,A28) -> 459.304
A29: jet fuel | B29: jet fuel tf | F29: Transportation Pollutant Emissions Disaggregated | G29: EPA_Table 3-13 | J29: Jet Fuel | K29: =SUMIFS(EPS!$L:$L,EPS!$B:$B,F29,EPS!$F:$F,"*"&B29&"*",EPS!$I:$I,"CO2") -> 154.9037 | L29: ='Table 3-13'!F20-SUM('Table 3-13'!F24:F25) -> 115.43943 | M29: =SUMIFS('Table 11.5'!$62:$62,'Table 11.5'!$1:$1,A29) -> 204.785
A30: aviation gasoline | B30: aviation gasoline | F30: Transportation Pollutant Emissions Disaggregated | G30: EPA_Table 3-13 | J30: Aviation Gasoline | K30: =SUMIFS(EPS!$L:$L,EPS!$B:$B,F30,EPS!$F:$F,"*"&B30&"*",EPS!$I:$I,"CO2") -> 0 | L30: ='Table 3-13'!F26 -> 1.4636844 | M30: =SUMIFS('Table 11.5'!$62:$62,'Table 11.5'!$1:$1,A30) -> 1.49
A31: residual fuel oil | B31: heavy or residual fuel oil tf | F31: Transportation Pollutant Emissions Disaggregated | G31: EPA_Table 3-13 | J31: Residual Fuel Oil | K31: =SUMIFS(EPS!$L:$L,EPS!$B:$B,F31,EPS!$F:$F,"*"&B31&"*",EPS!$I:$I,"CO2") -> 28.1638 | L31: ='Table 3-13'!F28 -> 39.274714 | M31: =SUMIFS('Table 11.5'!$62:$62,'Table 11.5'!$1:$1,A31) -> 46.172
A32: natural gas | B32: natural gas tf | F32: Transportation Pollutant Emissions Disaggregated | G32: EPA_Table 3-13 | J32: Natural Gas | K32: =SUMIFS(EPS!$L:$L,EPS!$B:$B,F32,EPS!$F:$F,"*"&B32&"*",EPS!$I:$I,"CO2") -> 3.0906256 | L32: ='Table 3-13'!F31-'Table 3-13'!F36 -> 0.40178148 | M32: =SUMIFS('Table 11.5'!$62:$62,'Table 11.5'!$1:$1,A32) -> 65.091 | N32: *EIA includes gas pipeline transport
A33: hydrocarbon gas liquids | B33: LPG propane or butane tf | F33: Transportation Pollutant Emissions Disaggregated | G33: EPA_Table 3-13 | J33: LPG | K33: =SUMIFS(EPS!$L:$L,EPS!$B:$B,F33,EPS!$F:$F,"*"&B33&"*",EPS!$I:$I,"CO2") -> 0.8716378 | L33: ='Table 3-13'!F37 -> 0.70043467 | M33: =SUMIFS('Table 11.5'!$62:$62,'Table 11.5'!$1:$1,A33) -> 0.614
B34: electricity tf | F34: Transportation Pollutant Emissions Disaggregated | G34: EPA_Table 3-13 | J34: Electricity | K34: =SUMIFS(EPS!$L:$L,EPS!$B:$B,F34,EPS!$F:$F,"*"&B34&"*",EPS!$I:$I,"CO2") -> 0
B35: hydrogen tf | F35: Transportation Pollutant Emissions Disaggregated | J35: Hydrogen | K35: =SUMIFS(EPS!$L:$L,EPS!$B:$B,F35,EPS!$F:$F,"*"&B35&"*",EPS!$I:$I,"CO2") -> 0
B36: biofuel gasoline tf | F36: Transportation Pollutant Emissions Disaggregated | J36: Biofuel Ethanol | K36: =SUMIFS(EPS!$L:$L,EPS!$B:$B,F36,EPS!$F:$F,"*"&B36&"*",EPS!$I:$I,"CO2") -> 0
B37: biofuel diesel tf | F37: Transportation Pollutant Emissions Disaggregated | J37: Biofuel Diesel | K37: =SUMIFS(EPS!$L:$L,EPS!$B:$B,F37,EPS!$F:$F,"*"&B37&"*",EPS!$I:$I,"CO2") -> 0
A38: other | J38: Other | K38: =SUMIFS(EPS!$L:$L,EPS!$B:$B,F38,EPS!$F:$F,"*"&B38&"*",EPS!$I:$I,"CO2") -> 0 | M38: =SUMIFS('Table 11.5'!$62:$62,'Table 11.5'!$1:$1,A38) -> 4.408
K39: =SUM(K27:K37) -> 1720.5574 | L39: =SUM(L27:L37) -> 1671.2526 | M39: =SUM(M27:M38) -> 1806.468
L46: =L55/K55 -> 0.99422827
O48: Note: EPS classifies light and medium duty trucks together, whereas
O49: EPA classifies medium and heavy duty trucks together. That leads to the
H50: 1.3 | I50: Transportation CO2 Emissions by Vehicle Type | O50: discrepancy below. See the table to the left, which shows we are aligned for
K51: EPS 2024 | L51: EPA 2023 | O51: combined cars and trucks.
B52: CO2 | E52: LDVs | F52: Transportation Pollutant Emissions Disaggregated | G52: EPA_Table 3-13 | J52: Passenger Cars and Light-Duty Trucks | K52: =SUMIFS(EPS!$L:$L,EPS!$B:$B,F52,EPS!$C:$C,E52,EPS!$I:$I,"CO2") -> 1155.0796 | L52: =SUMIFS('Table 3-13'!$F:$F,'Table 3-13'!$H:$H,J52) -> 1005.3056 | M52: =K52/L52 -> 1.1489836
B53: CO2 | C53: freight | E53: HDVs | F53: Transportation Pollutant Emissions Disaggregated | G53: EPA_Table 3-13 | J53: Medium and Heavy Duty Trucks | K53: =SUMIFS(EPS!$L:$L,EPS!$B:$B,F53,EPS!$C:$C,E53,EPS!$E:$E,C53,EPS!$I:$I,"CO2") -> 299.27887 | L53: =SUMIFS('Table 3-13'!$F:$F,'Table 3-13'!$H:$H,J53) -> 417.98977 | M53: =K53/L53 -> 0.71599567
B54: CO2 | C54: passenger | E54: HDVs | F54: Transportation Pollutant Emissions Disaggregated | G54: EPA_Table 3-13 | J54: All Cars and Trucks | K54: =SUM(K52:K53) -> 1454.3585 | L54: =SUM(L52:L53) -> 1423.2954 | M54: =K54/L54 -> 1.0218248
B55: CO2 | E55: motorbikes | F55: Transportation Pollutant Emissions Disaggregated | G55: EPA_Table 3-13 | J55: Buses | K55: =SUMIFS(EPS!$L:$L,EPS!$B:$B,F54,EPS!$C:$C,E54,EPS!$E:$E,C54,EPS!$I:$I,"CO2") -> 23.941138 | L55: =SUMIFS('Table 3-13'!$F:$F,'Table 3-13'!$H:$H,J55) -> 23.802956 | M55: =K55/L55 -> 1.0058052
B56: CO2 | C56: passenger | E56: ships | F56: Transportation Pollutant Emissions Disaggregated | G56: EPA_Table 3-13 | J56: Motorcycles | K56: =SUMIFS(EPS!$L:$L,EPS!$B:$B,F55,EPS!$C:$C,E55,EPS!$I:$I,"CO2") -> 1.27057 | L56: =SUMIFS('Table 3-13'!$F:$F,'Table 3-13'!$H:$H,J56) -> 8.5536064 | M56: =K56/L56 -> 0.14854202
B57: CO2 | C57: freight | E57: ships | F57: Transportation Pollutant Emissions Disaggregated | G57: EPA_Table 3-13 | J57: Recreational Boats | K57: =SUMIFS(EPS!$L:$L,EPS!$B:$B,F56,EPS!$C:$C,E56,EPS!$E:$E,C56,EPS!$I:$I,"CO2") -> 14.82397 | L57: =SUMIFS('Table 3-13'!$F:$F,'Table 3-13'!$H:$H,J57) -> 13.734628 | M57: =K57/L57 -> 1.0793136
B58: CO2 | E58: rail | F58: Transportation Pollutant Emissions Disaggregated | G58: EPA_Table 3-13 | J58: Rail | K58: =SUMIFS(EPS!$L:$L,EPS!$B:$B,F58,EPS!$C:$C,E58,EPS!$I:$I,"CO2") -> 33.70777 | L58: =SUMIFS('Table 3-13'!$F:$F,'Table 3-13'!$H:$H,J58) -> 30.938897 | M58: =K58/L58 -> 1.0894949
B59: CO2 | E59: aircraft | F59: Transportation Pollutant Emissions Disaggregated | J59: All ships and aircraft | K59: =SUM(K60:K62) -> 192.45543 | L59: =SUM(L60:L62) -> 204.78304 | M59: =K59/L59 -> 0.93980163
B60: CO2 | F60: Transportation Pollutant Emissions Disaggregated | J60: Ships | K60: =SUMIFS(EPS!$L:$L,EPS!$B:$B,F57,EPS!$C:$C,E57,EPS!$E:$E,C57,EPS!$I:$I,"CO2") -> 37.55173 | L60: =SUMIFS('Table 3-13'!$F:$F,'Table 3-13'!$H:$H,J60) -> 24.379925 | M60: =K60/L60 -> 1.5402726
B61: CO2 | C61: passenger | E61: aircraft | F61: Transportation Pollutant Emissions Disaggregated | J61: Passenger Aircraft | K61: =SUMIFS(EPS!$L:$L,EPS!$B:$B,F61,EPS!$C:$C,E61,EPS!$E:$E,C61,EPS!$I:$I,"CO2") -> 133.291 | L61: =SUMIFS('Table 3-13'!$F:$F,'Table 3-13'!$H:$H,J61) -> 129.7 | M61: =K61/L61 -> 1.027687
B62: CO2 | C62: freight | E62: aircraft | F62: Transportation Pollutant Emissions Disaggregated | J62: Military and Other Aircraft | K62: =SUMIFS(EPS!$L:$L,EPS!$B:$B,F62,EPS!$C:$C,E62,EPS!$E:$E,C62,EPS!$I:$I,"CO2") -> 21.6127 | L62: =SUMIFS('Table 3-13'!$F:$F,'Table 3-13'!$H:$H,J62) -> 50.70311 | M62: =K62/L62 -> 0.42625984
...

Sheet 2. Electricity
H1: Electricity
H2: MMTCO2e
M4: =L9-K9 -> -165.68138
A6: EIA | B6: EPS Sub 4 | C6: EPS Sub 3 | D6: EPS Sub 2 | E6: EPS Sub 1 | F6: EPS Variable | G6: EPA Table
H7: 2.1 | I7: Total Electricity Sector Greenhouse Gas Emissions by Pollutant Type
K8: EPS 2024 | L8: EPA 2023 | M8: EIA 2021
E9: CO2 | F9: Electricity Sector Pollutant Emissions | G9: EPA_Table 3-7 | J9: CO2 | K9: =SUMIFS(EPS!$L:$L,EPS!$B:$B,F9,EPS!$I:$I,E9) -> 1592.2839 | L9: ='Table 3-10'!C9+'Table 3-1'!C15 -> 1426.6025 | M9: ='Table 11.6'!J62 -> 1551.144
E10: CH4 | F10: Electricity Sector Pollutant Emissions | G10: EPA_Table 3-7 | J10: CH4 | K10: =SUMIFS(EPS!$L:$L,EPS!$B:$B,F10,EPS!$I:$I,E10) -> 1.8685541 | L10: ='Table 3-10'!C10 -> 1.5057991
E11: N2O | F11: Electricity Sector Pollutant Emissions | G11: EPA_Table 3-7 | J11: N2O | K11: =SUMIFS(EPS!$L:$L,EPS!$B:$B,F11,EPS!$I:$I,E11) -> 17.593559 | L11: ='Table 3-10'!C11+'Table 3-1'!C37 -> 16.910483
J12: Total CO2e | K12: =SUM(K9:K11) -> 1611.746 | L12: =SUM(L9:L11) -> 1445.0188 | M12: =SUM(M9:M11) -> 1551.144
H26: 2.2 | I26: Electric Sector CO2 Emissions by Fuel Type
K27: EPS 2024 | L27: EPA 2023 | M27: EIA 2021
A28: coal | D28: hard coal es | E28: CO2 | F28: Electricity Sector Pollutant Emissions | G28: EPA_Table 3-9 | J28: Coal | K28: =SUM(SUMIFS(EPS!$L:$L,EPS!$B:$B,F29,EPS!$I:$I,E29,EPS!$D:$D,D29),SUMIFS(EPS!$L:$L,EPS!$B:$B,F28,EPS!$I:$I,E28,EPS!$D:$D,D28)) -> 801.2266 | L28: ='Table 3-7'!C5 -> 694.55699 | M28: =SUMIFS('Table 11.6'!$62:$62,'Table 11.6'!$1:$1,A28) -> 909.624
D29: lignite es | E29: CO2 | F29: Electricity Sector Pollutant Emissions | G29: EPA_Table 3-9
A30: natural gas | D30: natural gas | E30: CO2 | F30: Electricity Sector Pollutant Emissions | G30: EPA_Table 3-9 | J30: Natural Gas | K30: =SUMIFS(EPS!$L:$L,EPS!$B:$B,F30,EPS!$I:$I,E30,EPS!$D:$D,"*"&D30&"*") -> 784.997 | L30: ='Table 3-7'!C6 -> 704.54465 | M30: =SUMIFS('Table 11.6'!$62:$62,'Table 11.6'!$1:$1,A30) -> 612.831
A31: petroleum | D31: heavy or residual fuel oil es | E31: CO2 | F31: Electricity Sector Pollutant Emissions | G31: EPA_Table 3-9 | J31: Petroleum | K31: =SUMIFS(EPS!$L:$L,EPS!$B:$B,F31,EPS!$I:$I,E31,EPS!$D:$D,"*"&D31&"*") -> 0 | L31: ='Table 3-7'!C7 -> 14.708588 | M31: =SUMIFS('Table 11.6'!$62:$62,'Table 11.6'!$1:$1,A31) -> 35.429
A32: geothermal | D32: geothermal es | E32: CO2 | F32: Electricity Sector Pollutant Emissions | G32: EPA_Table 3-9 | J32: Geothermal | K32: =SUMIFS(EPS!$L:$L,EPS!$B:$B,F32,EPS!$I:$I,E32,EPS!$D:$D,"*"&D32&"*") -> 0 | L32: ='Table 3-7'!C8 -> 0.36724082 | M32: =SUMIFS('Table 11.6'!$62:$62,'Table 11.6'!$1:$1,A32) -> 0.47
A33: MSW | D33: municipal solid waste es | E33: CO2 | F33: Electricity Sector Pollutant Emissions | J33: MSW | K33: =SUM(SUMIFS(EPS!$L:$L,EPS!$B:$B,F34,EPS!$I:$I,E34,EPS!$D:$D,D34),SUMIFS(EPS!$L:$L,EPS!$B:$B,F33,EPS!$I:$I,E33,EPS!$D:$D,D33)) -> 6.06025 | M33: =SUMIFS('Table 11.6'!$62:$62,'Table 11.6'!$1:$1,A33) -> 10.505
D34: petroleum es | E34: CO2 | F34: Electricity Sector Pollutant Emissions
K35: =SUM(K28:K34) -> 1592.2839 | L35: =SUM(L28:L34) -> 1414.1775 | M35: =SUM(M28:M34) -> 1568.859
H44: 2.3 | I44: Electric Sector CH4 Emissions by Fuel Type
K45: EPS 2024 | L45: EPA 2023
D46: hard coal es | E46: CH4 | F46: Electricity Sector Pollutant Emissions | G46: EPA_Table 3-10 | J46: Coal | K46: =SUM(SUMIFS(EPS!$L:$L,EPS!$B:$B,F47,EPS!$I:$I,E47,EPS!$D:$D,D47),SUMIFS(EPS!$L:$L,EPS!$B:$B,F46,EPS!$I:$I,E46,EPS!$D:$D,D46)) -> 0.1636936 | L46: ='Table 3-8'!C5 -> 0.15473752
D47: lignite | E47: CH4 | F47: Electricity Sector Pollutant Emissions | G47: EPA_Table 3-10
D48: heavy or residual fuel oil es | E48: CH4 | F48: Electricity Sector Pollutant Emissions | G48: EPA_Table 3-10 | J48: Fuel Oil | K48: =SUMIFS(EPS!$L:$L,EPS!$B:$B,F48,EPS!$I:$I,E48,EPS!$D:$D,"*"&D48&"*") -> 0 | L48: ='Table 3-8'!C6 -> 0.000766985
D49: natural gas | E49: CH4 | F49: Electricity Sector Pollutant Emissions | G49: EPA_Table 3-10 | J49: Natural Gas | K49: =SUMIFS(EPS!$L:$L,EPS!$B:$B,F49,EPS!$I:$I,E49,EPS!$D:$D,"*"&D49&"*") -> 1.5459693 | L49: ='Table 3-8'!C7 -> 1.3484968
H51: 2.4 | I51: Electric Sector N2O Emissions by Fuel Type
K52: EPS 2024 | L52: EPA 2023
D53: hard coal es | E53: N2O | F53: Electricity Sector Pollutant Emissions | G53: EPA_Table 3-11 | J53: Coal | K53: =SUM(SUMIFS(EPS!$L:$L,EPS!$B:$B,F54,EPS!$I:$I,E54,EPS!$D:$D,D54),SUMIFS(EPS!$L:$L,EPS!$B:$B,F53,EPS!$I:$I,E53,EPS!$D:$D,D53)) -> 12.357401 | L53: ='Table 3-9'!C5 -> 12.13077
D54: lignite | E54: N2O | F54: Electricity Sector Pollutant Emissions | G54: EPA_Table 3-11
D55: heavy or residual fuel oil es | E55: N2O | F55: Electricity Sector Pollutant Emissions | G55: EPA_Table 3-11 | J55: Fuel Oil | K55: =SUMIFS(EPS!$L:$L,EPS!$B:$B,F55,EPS!$I:$I,E55,EPS!$D:$D,"*"&D55&"*") -> 0 | L55: ='Table 3-9'!C6 -> 0.002999408
D56: natural gas | E56: N2O | F56: Electricity Sector Pollutant Emissions | G56: EPA_Table 3-11 | J56: Natural Gas | K56: =SUMIFS(EPS!$L:$L,EPS!$B:$B,F56,EPS!$I:$I,E56,EPS!$D:$D,"*"&D56&"*") -> 5.0261411 | L56: ='Table 3-9'!C7 -> 4.4324812

Sheet 3. Industry Energy
J1: Industry
J2: MMTCO2e
J3: Note that EIA emissions cateogries are different than EPS and EPA
J4: Note that EIA rebased its AEO model to the most recent MECS in AEO 2022, which is why there is a large discrepancy here
A7: EIA | B7: EPS Sub 4 | C7: EPS Sub 3 | D7: EPS Sub 2 | E7: EPS Sub 1 | F7: Exclude1 | G7: Exclude2 | H7: EPS Variable | I7: EPA Table
J8: 3.1 | K8: Industry Energy Greenhouse Gas Emissions by Pollutant Type
M9: EPS 2021 | N9: EPA 2021 | O9: EIA 2021
H10: Industrial Sector Energy Related Emissions after CCS | I10: EPA_Table 3-7 | L10: CO2 | M10: =SUMIFS(EPS!$L:$L,EPS!$B:$B,H10,EPS!$I:$I,L10) -> #N/A | N10: ='Table 3-10'!C13+'Table 3-13'!F36 -> 863.95131 | O10: ='Table 11.4'!O62-'Table 11.4'!N62 -> 975.411
H11: Industrial Sector Energy Related Emissions after CCS | I11: EPA_Table 3-7 | L11: CH4 | M11: =SUMIFS(EPS!$L:$L,EPS!$B:$B,H11,EPS!$I:$I,L11) -> #N/A | N11: ='Table 3-10'!C14 -> 1.4973585
H12: Industrial Sector Energy Related Emissions after CCS | I12: EPA_Table 3-7 | L12: N2O | M12: =SUMIFS(EPS!$L:$L,EPS!$B:$B,H12,EPS!$I:$I,L12) -> #N/A | N12: ='Table 3-10'!C15 -> 1.9174828
L13: Total CO2e | M13: =SUM(M10:M12) -> #N/A | N13: =SUM(N10:N12) -> 867.36615 | O13: =SUM(O10:O12) -> 975.411
L14: *EPS total roughly 50 MMT higher when considering
L15: emissions from hydrogen production, captured in
L16: the hydrogen sector
J28: 3.2 | K28: Industry Sector CO2 Emissions by Fuel Type
M29: EPS 2021 | N29: EPA 2021 | O29: EIA 2021
A30: coal | C30: CO2 | E30: hard coal if | H30: Industrial Energy Related Emissions Excluding Fuels to Power CCS | I30: EPA_Table 3-9 | L30: Coal | M30: =SUMIFS(EPS!$L:$L,EPS!$B:$B,H30,EPS!$C:$C,E30,EPS!$E:$E,C30) -> 0 | N30: ='Table 3-7'!C10 -> 36.484927 | O30: =SUMIFS('Table 11.4'!$62:$62,'Table 11.4'!$1:$1,A30) -> 91.594
A31: natural gas | C31: CO2 | E31: natural gas if | H31: Industrial Energy Related Emissions Excluding Fuels to Power CCS | I31: EPA_Table 3-9 | L31: Natural Gas | M31: =SUMIFS(EPS!$L:$L,EPS!$B:$B,H31,EPS!$C:$C,E31,EPS!$E:$E,C31) -> 0 | N31: ='Table 3-7'!C11+'Table 3-13'!F36 -> 586.12311 | O31: =SUMIFS('Table 11.4'!$62:$62,'Table 11.4'!$1:$1,A31) -> 537.676 | P31: * + 50 MMT from hydrogen
A32: fuel oil | C32: CO2 | E32: heavy or residual fuel oil if | H32: Industrial Energy Related Emissions Excluding Fuels to Power CCS | I32: EPA_Table 3-9 | L32: Petroleum Products | M32: =SUMIFS(EPS!$L:$L,EPS!$B:$B,H32,EPS!$C:$C,E32,EPS!$E:$E,C32)+SUMIFS(EPS!$L:$L,EPS!$B:$B,H34,EPS!$C:$C,E34,EPS!$E:$E,C34)+SUMIFS(EPS!$L:$L,EPS!$B:$B,H36,EPS!$C:$C,E36,EPS!$E:$E,C36)+SUMIFS(EPS!$L:$L,EPS!$B:$B,H37,EPS!$C:$C,E37,EPS!$E:$E,C37) -> 0 | N32: ='Table 3-7'!C12 -> 241.34327 | O32: =SUMIFS('Table 11.4'!$62:$62,'Table 11.4'!$1:$1,A32)+SUMIFS('Table 11.4'!$62:$62,'Table 11.4'!$1:$1,A34)+SUMIFS('Table 11.4'!$62:$62,'Table 11.4'!$1:$1,A35) -> 142.147
C33: CO2 | E33: biomass if | H33: Industrial Energy Related Emissions Excluding Fuels to Power CCS | I33: EPA_Table 3-9 | L33: biomass | M33: =SUMIFS(EPS!$L:$L,EPS!$B:$B,H33,EPS!$C:$C,E33,EPS!$E:$E,C33) -> 0 | O33: =SUMIFS('Table 11.4'!$62:$62,'Table 11.4'!$1:$1,A33) -> 0
A34: diesel | C34: CO2 | E34: petroleum diesel if | H34: Industrial Energy Related Emissions Excluding Fuels to Power CCS | I34: EPA_Table 3-9 | L34: diesel
A35: crude oil | C35: CO2 | E35: heat if | H35: Industrial Energy Related Emissions Excluding Fuels to Power CCS | I35: EPA_Table 3-9 | L35: heat
C36: CO2 | E36: crude oil if | H36: Industrial Energy Related Emissions Excluding Fuels to Power CCS | I36: EPA_Table 3-9 | L36: crude oil | O36: =SUMIFS('Table 11.4'!$62:$62,'Table 11.4'!$1:$1,A36) -> 0
C37: CO2 | E37: LPG propane or butane if | H37: Industrial Energy Related Emissions Excluding Fuels to Power CCS | I37: EPA_Table 3-9 | L37: LPG | O37: =SUMIFS('Table 11.4'!$62:$62,'Table 11.4'!$1:$1,A37) -> 0
A38: other | L38: other | M38: =SUMIFS(EPS!$L:$L,EPS!$B:$B,H38,EPS!$C:$C,E38,EPS!$E:$E,C38) -> 0 | O38: =SUMIFS('Table 11.4'!$62:$62,'Table 11.4'!$1:$1,A38) -> 203.994
M39: =SUM(M30:M37) -> 0 | N39: =SUM(N30:N37) -> 863.95131 | O39: =SUM(O30:O38) -> 975.411
J51: 3.3 | K51: Industry Sector CH4 Emissions by Fuel Type
M52: EPS 2021 | N52: EPA 2021
C53: CH4 | E53: hard coal if | H53: Industrial Energy Related Emissions Excluding Fuels to Power CCS | I53: EPA_Table 3-10 | L53: Coal | M53: =SUMIFS(EPS!$L:$L,EPS!$B:$B,H53,EPS!$C:$C,E53,EPS!$E:$E,C53) -> 0 | N53: ='Table 3-8'!C10 -> 0.10690672
C54: CH4 | E54: natural gas if | H54: Industrial Energy Related Emissions Excluding Fuels to Power CCS | I54: EPA_Table 3-10 | L54: Natural Gas | M54: =SUMIFS(EPS!$L:$L,EPS!$B:$B,H54,EPS!$C:$C,E54,EPS!$E:$E,C54) -> 0 | N54: ='Table 3-8'!C11 -> 0.14691013
C55: CH4 | E55: heavy or residual fuel oil if | H55: Industrial Energy Related Emissions Excluding Fuels to Power CCS | I55: EPA_Table 3-10 | L55: Fuel Oil | M55: =SUMIFS(EPS!$L:$L,EPS!$B:$B,H55,EPS!$C:$C,E55,EPS!$E:$E,C55) -> 0 | N55: ='Table 3-8'!C12 -> 0.25864888
C56: CH4 | E56: biomass if | H56: Industrial Energy Related Emissions Excluding Fuels to Power CCS | L56: biomass | M56: =SUMIFS(EPS!$L:$L,EPS!$B:$B,H56,EPS!$C:$C,E56,EPS!$E:$E,C56) -> 0
C57: CH4 | E57: petroleum diesel if | H57: Industrial Energy Related Emissions Excluding Fuels to Power CCS | L57: diesel | M57: =SUMIFS(EPS!$L:$L,EPS!$B:$B,H57,EPS!$C:$C,E57,EPS!$E:$E,C57) -> 0
C58: CH4 | E58: heat if | H58: Industrial Energy Related Emissions Excluding Fuels to Power CCS | L58: heat | M58: =SUMIFS(EPS!$L:$L,EPS!$B:$B,H58,EPS!$C:$C,E58,EPS!$E:$E,C58) -> 0
C59: CH4 | E59: crude oil if | H59: Industrial Energy Related Emissions Excluding Fuels to Power CCS | L59: crude oil | M59: =SUMIFS(EPS!$L:$L,EPS!$B:$B,H59,EPS!$C:$C,E59,EPS!$E:$E,C59) -> 0
C60: CH4 | E60: LPG propane or butane if | H60: Industrial Energy Related Emissions Excluding Fuels to Power CCS | L60: LPG | M60: =SUMIFS(EPS!$L:$L,EPS!$B:$B,H60,EPS!$C:$C,E60,EPS!$E:$E,C60) -> 0
M61: =SUM(M53:M60) -> 0 | N61: =SUM(N53:N60) -> 0.51246572
J64: 3.4 | K64: Industry Sector N2O Emissions by Fuel Type
M65: EPS 2021 | N65: EPA 2021
C66: N2O | E66: hard coal if | H66: Industrial Energy Related Emissions Excluding Fuels to Power CCS | I66: EPA_Table 3-11 | L66: Coal | M66: =SUMIFS(EPS!$L:$L,EPS!$B:$B,H66,EPS!$C:$C,E66,EPS!$E:$E,C66)-SUMIFS(EPS!$L:$L,EPS!$B:$B,H66,EPS!$C:$C,E66,EPS!$E:$E,C66,EPS!$D:$D,F66) -> 0 | N66: ='Table 3-9'!C10 -> 0.15176936
...

Sheet 4. Buildings
I1: Buildings
I2: MMTCO2e
A6: EIA | B6: EPS Sub 4 | C6: EPS Sub 3 | D6: EPS Sub 2 | E6: EPS Sub 1 | F6: EPS Subsector | G6: EPS Variable | H6: EPA Table
I7: 4.1 | J7: Total Residential Sector Greenhouse Gas Emissions by Pollutant Type
L8: EPS 2021 | M8: EPA 2021 | N8: EIA 2021
D9: CO2 | E9: residential | G9: Buildings Sector Pollutant Emissions | H9: EPA_Table 3-7 | K9: CO2 | L9: =SUMIFS(EPS!$L:$L,EPS!$B:$B,G9,EPS!$I:$I,D9,EPS!$C:$C,"*"&E9&"*") -> #N/A | M9: ='Table 3-10'!C17 -> 307.07737 | N9: ='Table 11.2'!I62-'Table 11.2'!H62 -> 324.915
D10: CH4 | E10: residential | G10: Buildings Sector Pollutant Emissions | H10: EPA_Table 3-7 | K10: CH4 | L10: =SUMIFS(EPS!$L:$L,EPS!$B:$B,G10,EPS!$I:$I,D10,EPS!$C:$C,"*"&E10&"*") -> #N/A | M10: ='Table 3-10'!C18 -> 4.459395
D11: N2O | E11: residential | G11: Buildings Sector Pollutant Emissions | H11: EPA_Table 3-7 | K11: N2O | L11: =SUMIFS(EPS!$L:$L,EPS!$B:$B,G11,EPS!$I:$I,D11,EPS!$C:$C,"*"&E11&"*") -> #N/A | M11: ='Table 3-10'!C19 -> 0.71053789
K12: Total CO2e | L12: =SUM(L9:L11) -> #N/A | M12: =SUM(M9:M11) -> 312.2473 | N12: =SUM(N9:N11) -> 324.915
I24: 4.2 | J24: Total Commercial Sector Greenhouse Gas Emissions by Pollutant Type
L25: EPS 2021 | M25: EPA 2021 | N25: EIA 2021
D26: CO2 | E26: commercial | G26: Buildings Sector Pollutant Emissions | H26: EPA_Table 3-7 | K26: CO2 | L26: =SUMIFS(EPS!$L:$L,EPS!$B:$B,G26,EPS!$I:$I,D26,EPS!$C:$C,"*"&E26&"*") -> #N/A | M26: ='Table 3-10'!C21 -> 244.16078 | N26: ='Table 11.3'!L62-'Table 11.3'!K62 -> 245.249
D27: CH4 | E27: commercial | G27: Buildings Sector Pollutant Emissions | H27: EPA_Table 3-7 | K27: CH4 | L27: =SUMIFS(EPS!$L:$L,EPS!$B:$B,G27,EPS!$I:$I,D27,EPS!$C:$C,"*"&E27&"*") -> #N/A | M27: ='Table 3-10'!C22 -> 1.2761028
D28: N2O | E28: commercial | G28: Buildings Sector Pollutant Emissions | H28: EPA_Table 3-7 | K28: N2O | L28: =SUMIFS(EPS!$L:$L,EPS!$B:$B,G28,EPS!$I:$I,D28,EPS!$C:$C,"*"&E28&"*") -> #N/A | M28: ='Table 3-10'!C23 -> 0.30078619
K29: Total CO2e | L29: =SUM(L26:L28) -> #N/A | M29: =SUM(M26:M28) -> 245.73767 | N29: =SUM(N26:N28) -> 245.249

Sheet 5. Industry Process
G1: Industry
G2: MMTCO2e
A6: EPS Sub 4 | B6: EPS Sub 3 | C6: EPS Sub 2 | D6: EPS Sub 1 | E6: EPS Variable | F6: EPA Table
G7: 5.1 | H7: Industry Process Greenhouse Gas Emissions by Pollutant Type
J8: EPS 2021 | K8: EPA 2021
E9: Process Emissions after CCS | F9: EPA Tables 3-1, 4-1, Table 5-1, Table 7-1 | I9: CO2 | J9: =SUMIFS(EPS!$L:$L,EPS!$B:$B,E9,EPS!$I:$I,I9) -> #N/A | K9: =SUM('Table 4-1'!C4,'Table 5-1'!C4)+SUMIFS('Table 3-1'!$C:$C,'Table 3-1'!$D:$D,"process",'Table 3-1'!$F:$F,I9)+SUMIFS('Table 3-24'!K:K,'Table 3-24'!N:N,I9) -> 353.90247
E10: Process Emissions after CCS | F10: EPA Tables 3-1, 4-1, Table 5-1, Table 7-1 | I10: CH4 | J10: =SUMIFS(EPS!$L:$L,EPS!$B:$B,E10,EPS!$I:$I,I10) -> #N/A | K10: =(SUM('Table 4-1'!C25,'Table 5-1'!C7,'Table 7-1'!C4)+SUMIFS('Table 3-1'!$C:$C,'Table 3-1'!$D:$D,"process",'Table 3-1'!$F:$F,I10)) -> 675.30666
E11: Process Emissions after CCS | F11: EPA Tables 3-1, 4-1, Table 5-1, Table 7-1 | I11: N2O | J11: =SUMIFS(EPS!$L:$L,EPS!$B:$B,E11,EPS!$I:$I,I11) -> #N/A | K11: =(SUM('Table 4-1'!C31,'Table 5-1'!C12,'Table 7-1'!C9)+SUMIFS('Table 3-1'!$C:$C,'Table 3-1'!$D:$D,"process",'Table 3-1'!$F:$F,I11)) -> 355.64667
E12: Process Emissions after CCS | F12: EPA Tables 3-1, 4-1, Table 5-1, Table 7-1 | I12: F gases | J12: =SUMIFS(EPS!$L:$L,EPS!$B:$B,E12,EPS!$I:$I,I12) -> #N/A | K12: =SUM('Table 4-1'!C37,'Table 4-1'!C42,'Table 4-1'!C49,'Table 4-1'!C55) -> 192.9
J13: =SUM(J9:J12) -> #N/A | K13: =SUM(K9:K12) -> 1577.7558
K14: =K13+53 -> 1630.7558
I15: *The discrepancy between the EPA total and the
I16: EPA plus ethanol total is due to CCS in gas processing
G26: 5.3 | H26: Industry Process Greenhouse Gas Emissions by Sector | J26: EPS 2021 | K26: EPA 2021
D27: cement and other nonmetallic minerals 239 | E27: Process Emissions after CCS | F27: EPA Tables 3-1, 4-1, Table 5-1, Table 7-1 | I27: cement and other carbonates | J27: =SUMIFS(EPS!$L:$L,EPS!$B:$B,E27,EPS!$C:$C,D27) -> #N/A | K27: =SUMIFS('Table 4-1'!$C:$C,'Table 4-1'!$E:$E,'5. Industry Process'!D27)+SUMIFS('Table 3-1'!$C:$C,'Table 3-1'!$E:$E,'5. Industry Process'!D27) -> 65.5
B28: refined petroleum and coke 19 | C28: oil and gas extraction 06 | D28: energy pipelines and gas processing 352T353 | E28: Process Emissions after CCS | F28: EPA Tables 3-1, 4-1, Table 5-1, Table 7-1 | I28: natural gas and petroleum systems | J28: =SUM(SUMIFS(EPS!$L:$L,EPS!$B:$B,E28,EPS!$C:$C,B28),SUMIFS(EPS!$L:$L,EPS!$B:$B,E28,EPS!$C:$C,C28),SUMIFS(EPS!$L:$L,EPS!$B:$B,E28,EPS!$C:$C,D28)) -> #N/A | K28: =SUM(SUMIFS('Table 3-1'!C:C,'Table 3-1'!E:E,C28),SUMIFS('Table 3-1'!C:C,'Table 3-1'!E:E,D28),SUMIFS('Table 4-1'!C:C,'Table 4-1'!E:E,B28))+SUMIFS('Table 3-24'!$K:$K,'Table 3-24'!$M:$M,'5. Industry Process'!D28)+SUMIFS('Table 3-24'!$K:$K,'Table 3-24'!$M:$M,'5. Industry Process'!B28)+SUMIFS('Table 3-24'!$K:$K,'Table 3-24'!$M:$M,'5. Industry Process'!C28) -> 316.02235 | L28: *EPA total would be 53 MMT higher with the inclusion of ethanol
D29: iron and steel 241 | E29: Process Emissions after CCS | F29: EPA Tables 3-1, 4-1, Table 5-1, Table 7-1 | I29: iron and steel | J29: =SUMIFS(EPS!$L:$L,EPS!$B:$B,E29,EPS!$C:$C,D29) -> #N/A | K29: =SUMIFS('Table 4-1'!$C:$C,'Table 4-1'!$E:$E,'5. Industry Process'!D29)+SUMIFS('Table 3-1'!$C:$C,'Table 3-1'!$E:$E,'5. Industry Process'!D29) -> 40.2
D30: chemicals 20 | E30: Process Emissions after CCS | F30: EPA Tables 3-1, 4-1, Table 5-1, Table 7-1 | I30: chemicals | J30: =SUMIFS(EPS!$L:$L,EPS!$B:$B,E30,EPS!$C:$C,D30) -> #N/A | K30: =SUMIFS('Table 4-1'!$C:$C,'Table 4-1'!$E:$E,'5. Industry Process'!D30)+SUMIFS('Table 3-1'!$C:$C,'Table 3-1'!$E:$E,'5. Industry Process'!D30)+SUMIFS('Table 3-24'!$K:$K,'Table 3-24'!$M:$M,'5. Industry Process'!D30) -> 328.8
D31: coal mining 05 | E31: Process Emissions after CCS | F31: EPA Tables 3-1, 4-1, Table 5-1, Table 7-1 | I31: coal mining | J31: =SUMIFS(EPS!$L:$L,EPS!$B:$B,E31,EPS!$C:$C,D31) -> #N/A | K31: =SUMIFS('Table 4-1'!$C:$C,'Table 4-1'!$E:$E,'5. Industry Process'!D31)+SUMIFS('Table 3-1'!$C:$C,'Table 3-1'!$E:$E,'5. Industry Process'!D31) -> 53.970029
D32: water and waste 36T39 | E32: Process Emissions after CCS | F32: EPA Tables 3-1, 4-1, Table 5-1, Table 7-1 | I32: waste management | J32: =SUMIFS(EPS!$L:$L,EPS!$B:$B,E32,EPS!$C:$C,D32) -> #N/A | K32: =SUMIFS('Table 4-1'!$C:$C,'Table 4-1'!$E:$E,'5. Industry Process'!D32)+SUMIFS('Table 3-1'!$C:$C,'Table 3-1'!$E:$E,'5. Industry Process'!D32)+'Table 7-1'!$C$12 -> 165.84952
D33: agriculture and forestry 01T03 | E33: Process Emissions after CCS | F33: EPA Tables 3-1, 4-1, Table 5-1, Table 7-1 | I33: agriculture | J33: =SUMIFS(EPS!$L:$L,EPS!$B:$B,E33,EPS!$C:$C,D33) -> #N/A | K33: ='Table 5-1'!C16 -> 595.39797
D34: other | E34: Process Emissions after CCS | F34: EPA Tables 3-1, 4-1, Table 5-1, Table 7-1 | I34: other industries | J34: =SUMIFS(EPS!$L:$L,EPS!$B:$B,E34)-SUM(J27:J33) -> #N/A | K34: =SUMIFS('Table 4-1'!$C:$C,'Table 4-1'!$E:$E,'5. Industry Process'!D34)+SUMIFS('Table 3-1'!$C:$C,'Table 3-1'!$E:$E,'5. Industry Process'!D34) -> 0
I35: Total process | J35: =SUM(J27:J34) -> #N/A | K35: =SUM(K27:K34) -> 1565.7399
G42: 5.4 | H42: Industry Process CH4 Emissions by Sector | J42: EPS 2021 | K42: EPA 2021
A43: CH4 | D43: cement and other nonmetallic minerals 239 | E43: Process Emissions before CCS | I43: cement and other carbonates | J43: =SUMIFS(EPS!L:L,EPS!D:D,A43,EPS!B:B,E43,EPS!C:C,D43) -> 0
A44: CH4 | B44: refined petroleum and coke 19 | C44: oil and gas extraction 06 | D44: energy pipelines and gas processing 352T353 | E44: Process Emissions before CCS | I44: natural gas and petroleum systems | J44: =SUM(SUMIFS(EPS!L:L,EPS!D:D,A44,EPS!B:B,E44,EPS!C:C,D44),SUMIFS(EPS!L:L,EPS!D:D,A44,EPS!B:B,E44,EPS!C:C,C44),SUMIFS(EPS!L:L,EPS!D:D,A44,EPS!B:B,E44,EPS!C:C,B44)) -> 0 | K44: =SUMIFS('Table 3-1'!C:C,'Table 3-1'!D:D,"process",'Table 3-1'!F:F,A44,'Table 3-1'!E:E,C44) -> 208.96919
A45: CH4 | D45: iron and steel 241 | E45: Process Emissions before CCS | I45: iron and steel | J45: =SUMIFS(EPS!L:L,EPS!D:D,A45,EPS!B:B,E45,EPS!C:C,D45) -> 0
A46: CH4 | D46: chemicals 20 | E46: Process Emissions before CCS | I46: chemicals | J46: =SUMIFS(EPS!L:L,EPS!D:D,A46,EPS!B:B,E46,EPS!C:C,D46) -> 0 | K46: ='Table 4-1'!C25 -> +
A47: CH4 | D47: coal mining 05 | E47: Process Emissions before CCS | I47: coal mining | J47: =SUMIFS(EPS!L:L,EPS!D:D,A47,EPS!B:B,E47,EPS!C:C,D47) -> 0 | K47: =SUMIFS('Table 3-1'!C:C,'Table 3-1'!D:D,"process",'Table 3-1'!F:F,A47,'Table 3-1'!E:E,D47) -> 51.56631
A48: CH4 | D48: water and waste 36T39 | E48: Process Emissions before CCS | I48: waste management | J48: =SUMIFS(EPS!L:L,EPS!D:D,A48,EPS!B:B,E48,EPS!C:C,D48) -> 0 | K48: ='Table 7-1'!C4 -> 143.20296
A49: CH4 | D49: agriculture and forestry 01T03 | E49: Process Emissions before CCS | I49: agriculture | J49: =SUMIFS(EPS!L:L,EPS!D:D,A49,EPS!B:B,E49,EPS!C:C,D49) -> 0 | K49: ='Table 5-1'!C7 -> 271.5682
A50: CH4 | D50: other | E50: Process Emissions before CCS | I50: other industries | J50: =SUMIFS(EPS!L:L,EPS!D:D,A50,EPS!B:B,E50)-SUM(J43:J49) -> 0
I51: Total process | J51: =SUM(J43:J50) -> 0 | K51: =SUM(K43:K50) -> 675.30666

Sheet 6. Total
G1: Total
G2: MMTCO2e
A5: EPS Sub 4 | B5: EPS Sub 3 | C5: EPS Sub 2 | D5: EPS Sub 1 | E5: EPS Variable | F5: EPA Table
G7: 6.1 | H7: Total Economy-wide Greenhouse Gas Emissions by Sector
J8: EPS 2021 | K8: EPA 2021 | L8: EIA 2021 | M8: EPA - EPS Difference
D9: transportation sector | E9: Output Total CO2e Emissions by Sector | I9: Transportation Sector | J9: ='1. Transportation'!K12 -> 1733.8957 | K9: =SUM('1. Transportation'!L9:L11) -> 1723.2452 | L9: ='1. Transportation'!M12 -> 1741.377 | M9: =K9-J9 -> -10.650468
D10: electricity sector | E10: Output Total CO2e Emissions by Sector | I10: Electricity Sector | J10: ='2. Electricity'!K12 -> 1611.746 | K10: =SUM('2. Electricity'!L9:L11) -> 1445.0188 | L10: ='2. Electricity'!M35 -> 1568.859 | M10: =K10-J10 -> -166.72721
D11: LULUCF sector | E11: Output Total CO2e Emissions by Sector | I11: LULUCF Sector | J11: =SUMIFS(EPS!$L:$L,EPS!$B:$B,'6. Total'!E11,EPS!$C:$C,'6. Total'!D11) -> #N/A | K11: ='Table 6-1'!C42 -> -939.9 | M11: =K11-J11 -> #N/A
D12: geoengineering sector | E12: Output Total CO2e Emissions by Sector | I12: Geoengineering sector | J12: =SUMIFS(EPS!$L:$L,EPS!$B:$B,'6. Total'!E12,EPS!$C:$C,'6. Total'!D12) -> #N/A | M12: =K12-J12 -> #N/A
E13: Process Emissions after CCS | I13: Industry Process | J13: =SUMIFS(EPS!$L:$L,EPS!$B:$B,'6. Total'!E13)-SUM(J15:J16) -> #N/A | K13: =SUM('5. Industry Process'!K9:K12)-K15-K16 -> 816.5083 | M13: =K13-J13 -> #N/A | N13: *discrepancy from ethanol
D14: industry sector | E14: Output Total CO2e Emissions by Sector | I14: Industry Energy | J14: ='3. Industry Energy'!M13 -> #N/A | K14: =SUM('3. Industry Energy'!N10:N12) -> 867.36615 | L14: ='3. Industry Energy'!O13 -> 975.411 | M14: =K14-J14 -> #N/A
D15: agriculture and forestry 01T03 | E15: Process Emissions after CCS | I15: Agriculture Process | J15: =SUMIFS(EPS!$L:$L,EPS!$B:$B,'6. Total'!E15,EPS!C:C,'6. Total'!D15) -> #N/A | K15: ='5. Industry Process'!K33 -> 595.39797 | M15: =K15-J15 -> #N/A
D16: water and waste 36T39 | E16: Process Emissions after CCS | I16: Waste Process | J16: =SUMIFS(EPS!$L:$L,EPS!$B:$B,'6. Total'!E16,EPS!C:C,'6. Total'!D16) -> #N/A | K16: ='5. Industry Process'!K32 -> 165.84952 | M16: =K16-J16 -> #N/A
E17: Output Buildings Sector CO2e Emissions | I17: Buildings | J17: ='4. Buildings'!L12+'4. Buildings'!L29 -> #N/A | K17: =SUM('4. Buildings'!M9:M11,'4. Buildings'!M26:M28) -> 557.98497 | L17: =SUM('4. Buildings'!N12,'4. Buildings'!N29) -> 570.164 | M17: =K17-J17 -> #N/A
E18: Output Total CO2e Emissions by Sector[district heat and hydrogen sector] | I18: District Heat and Hydrogen | J18: =INDEX(NoSettings!C:C,MATCH(E18,NoSettings!A:A,0)) -> #N/A | M18: =K18-J18 -> #N/A
J19: =SUM(J13,J14,J15,J16,J9,J10,J17,J18,J11) -> #N/A | K19: =SUM(K9:K17) -> 5231.4709 | L19: =SUM(L9:L17) -> 4855.811 | M19: =K19-J19 -> #N/A
J20: *we should be ~53 MMT higher from
J21: ethanol refining
J23: **the EPA column does not include emissions from US terriroties,
J24: since those are not apportioned by sector in the Inventory
G33: 6.2 | H33: Total CH4 Emissions
J34: EPS 2021 | K34: EPA 2021
I35: Transportation Sector | J35: ='1. Transportation'!K10 -> 2.0116845 | K35: ='1. Transportation'!L10 -> 2.5398312
I36: Electricity Sector | J36: ='2. Electricity'!K10 -> 1.8685541 | K36: ='2. Electricity'!L10 -> 1.5057991
I37: District Heat Sector
C38: CH4 | D38: LULUCF sector | E38: Total Pollutant Emissions by Sector | I38: LULUCF Sector | J38: =SUMIFS(EPS!L:L,EPS!B:B,E38,EPS!C:C,D38,EPS!D:D,C38) -> #N/A | K38: ='Table 6-1'!C40 -> 5.9
I39: Geoengineering sector
I40: Industry Process | J40: ='5. Industry Process'!J10 -> #N/A | K40: ='5. Industry Process'!K10 -> 675.30666
I41: Industry Energy | J41: ='3. Industry Energy'!M11 -> #N/A | K41: ='3. Industry Energy'!N11 -> 1.4973585
I42: Agriculture
I43: Waste
I44: Buildings
J45: =SUM(J35:J44) -> #N/A | K45: =SUM(K35:K44) -> 686.74964
K46: =K45-J45 -> #N/A
G47: 6.3 | H47: Total N2O
J48: EPS 2021 | K48: EPA 2021
I49: Transportation Sector | J49: ='1. Transportation'!K11 -> 11.32663 | K49: ='1. Transportation'!L11 -> 16.183964
I50: Electricity Sector | J50: ='2. Electricity'!K11 -> 17.593559 | K50: ='2. Electricity'!L11 -> 16.910483
I51: District Heat Sector
C52: N2O | D52: LULUCF sector | E52: Total Pollutant Emissions by Sector | I52: LULUCF Sector | J52: =SUMIFS(EPS!L:L,EPS!B:B,E52,EPS!C:C,D52,EPS!D:D,C52) -> #N/A | K52: ='Table 6-1'!C41 -> -1000.5
...

Sheet 7. Particulates
G1: Total Pollutant Emissions by Sector
G2: metric tons pollutant
A6: EPS Sub 4 | B6: EPS Sub 3 | C6: EPS Sub 2 | D6: EPS Sub 1 | E6: EPS Variable | F6: EPA Table
G8: 7.1
J9: EPS 2021 | K9: EPA 2020
C10: NOx | D10: transportation sector | E10: Total Pollutant Emissions by Sector | I10: Transportation Sector | J10: =SUMIFS(EPS!$J:$J,EPS!$D:$D,'7. Particulates'!C10,EPS!$C:$C,'7. Particulates'!D10,EPS!$B:$B,'7. Particulates'!E10)/10^6 -> #N/A | K10: =SUMIFS('2020 EPA Data'!$D:$D,'2020 EPA Data'!$G:$G,C10,'2020 EPA Data'!$F:$F,I10)/metricton_to_shortton -> 2840387
C11: NOx | D11: electricity sector | E11: Total Pollutant Emissions by Sector | I11: Electricity Sector | J11: =SUMIFS(EPS!$J:$J,EPS!$D:$D,'7. Particulates'!C11,EPS!$C:$C,'7. Particulates'!D11,EPS!$B:$B,'7. Particulates'!E11)/10^6 -> #N/A | K11: =SUMIFS('2020 EPA Data'!$D:$D,'2020 EPA Data'!$G:$G,C11,'2020 EPA Data'!$F:$F,I11)/metricton_to_shortton -> 762145.86
C12: NOx | D12: residential buildings sector | E12: Total Pollutant Emissions by Sector | I12: Residential Buildings Sector | J12: =SUMIFS(EPS!$J:$J,EPS!$D:$D,'7. Particulates'!C12,EPS!$C:$C,'7. Particulates'!D12,EPS!$B:$B,'7. Particulates'!E12)/10^6 -> #N/A | K12: =SUMIFS('2020 EPA Data'!$D:$D,'2020 EPA Data'!$G:$G,C12,'2020 EPA Data'!$F:$F,I12)/metricton_to_shortton -> 299876.62
C13: NOx | D13: commercial buildings sector | E13: Total Pollutant Emissions by Sector | I13: Commercial Buildings Sector | J13: =SUMIFS(EPS!$J:$J,EPS!$D:$D,'7. Particulates'!C13,EPS!$C:$C,'7. Particulates'!D13,EPS!$B:$B,'7. Particulates'!E13)/10^6 -> #N/A | K13: =SUMIFS('2020 EPA Data'!$D:$D,'2020 EPA Data'!$G:$G,C13,'2020 EPA Data'!$F:$F,I13)/metricton_to_shortton -> 192228.14
C14: NOx | D14: industry sector | E14: Total Pollutant Emissions by Sector | I14: Industry | J14: =SUMIFS(EPS!$J:$J,EPS!$D:$D,'7. Particulates'!C14,EPS!$C:$C,'7. Particulates'!D14,EPS!$B:$B,'7. Particulates'!E14)/10^6 -> #N/A | K14: =SUMIFS('2020 EPA Data'!$D:$D,'2020 EPA Data'!$G:$G,C14,'2020 EPA Data'!$F:$F,"*"&I14&"*")/metricton_to_shortton -> 1875963.2
C15: NOx | I15: Nonroad | J15: =SUMIFS(EPS!$J:$J,EPS!$D:$D,'7. Particulates'!C15,EPS!$C:$C,'7. Particulates'!D15,EPS!$B:$B,'7. Particulates'!E15)/10^6 -> 0 | K15: =SUMIFS('2020 EPA Data'!$D:$D,'2020 EPA Data'!$G:$G,C15,'2020 EPA Data'!$F:$F,I15)/metricton_to_shortton*INDEX(GWP!$C$2:$C$13,MATCH(C15,GWP!$B$2:$B$13,0)) -> 0
C16: NOx | D16: district heat and hydrogen sector | E16: Total Pollutant Emissions by Sector | I16: District Heat Sector | J16: =SUMIFS(EPS!$J:$J,EPS!$D:$D,'7. Particulates'!C16,EPS!$C:$C,'7. Particulates'!D16,EPS!$B:$B,'7. Particulates'!E16)/10^6 -> #N/A | K16: =SUMIFS('2020 EPA Data'!$D:$D,'2020 EPA Data'!$G:$G,C16,'2020 EPA Data'!$F:$F,I16)/metricton_to_shortton*INDEX(GWP!$C$2:$C$13,MATCH(C16,GWP!$B$2:$B$13,0)) -> 0
C17: NOx | D17: LULUCF sector | E17: Total Pollutant Emissions by Sector | I17: LULUCF Sector | J17: =SUMIFS(EPS!$J:$J,EPS!$D:$D,'7. Particulates'!C17,EPS!$C:$C,'7. Particulates'!D17,EPS!$B:$B,'7. Particulates'!E17)/10^6 -> #N/A | K17: =SUMIFS('2020 EPA Data'!$D:$D,'2020 EPA Data'!$G:$G,C17,'2020 EPA Data'!$F:$F,I17)/metricton_to_shortton*INDEX(GWP!$C$2:$C$13,MATCH(C17,GWP!$B$2:$B$13,0)) -> 0
C18: NOx | D18: geoengineering sector | E18: Total Pollutant Emissions by Sector | I18: Geoengineering Sector | J18: =SUMIFS(EPS!$J:$J,EPS!$D:$D,'7. Particulates'!C18,EPS!$C:$C,'7. Particulates'!D18,EPS!$B:$B,'7. Particulates'!E18)/10^6 -> #N/A | K18: =SUMIFS('2020 EPA Data'!$D:$D,'2020 EPA Data'!$G:$G,C18,'2020 EPA Data'!$F:$F,I18)/metricton_to_shortton*INDEX(GWP!$C$2:$C$13,MATCH(C18,GWP!$B$2:$B$13,0)) -> 0
C19: NOx | I19: Other-EPA | J19: =SUMIFS(EPS!$J:$J,EPS!$D:$D,'7. Particulates'!C19,EPS!$C:$C,'7. Particulates'!D19,EPS!$B:$B,'7. Particulates'!E19)/10^6 -> 0 | K19: =SUMIFS('2020 EPA Data'!$D:$D,'2020 EPA Data'!$G:$G,C19,'2020 EPA Data'!$F:$F,I19)/metricton_to_shortton -> 2116542.5
I20: Total | J20: =SUM(J10:J19) -> #N/A | K20: =SUM(K10:K16) -> 5970600.8
G29: 7.2
J30: EPS 2021 | K30: EPA 2020
C31: SOx | D31: transportation sector | E31: Total Pollutant Emissions by Sector | I31: Transportation Sector | J31: =SUMIFS(EPS!$J:$J,EPS!$D:$D,'7. Particulates'!C31,EPS!$C:$C,'7. Particulates'!D31,EPS!$B:$B,'7. Particulates'!E31)/10^6 -> #N/A | K31: =SUMIFS('2020 EPA Data'!$D:$D,'2020 EPA Data'!$G:$G,C31,'2020 EPA Data'!$F:$F,I31)/metricton_to_shortton -> 20906.097
C32: SOx | D32: electricity sector | E32: Total Pollutant Emissions by Sector | I32: Electricity Sector | J32: =SUMIFS(EPS!$J:$J,EPS!$D:$D,'7. Particulates'!C32,EPS!$C:$C,'7. Particulates'!D32,EPS!$B:$B,'7. Particulates'!E32)/10^6 -> #N/A | K32: =SUMIFS('2020 EPA Data'!$D:$D,'2020 EPA Data'!$G:$G,C32,'2020 EPA Data'!$F:$F,I32)/metricton_to_shortton -> 758009.09
C33: SOx | D33: residential buildings sector | E33: Total Pollutant Emissions by Sector | I33: Residential Buildings Sector | J33: =SUMIFS(EPS!$J:$J,EPS!$D:$D,'7. Particulates'!C33,EPS!$C:$C,'7. Particulates'!D33,EPS!$B:$B,'7. Particulates'!E33)/10^6 -> #N/A | K33: =SUMIFS('2020 EPA Data'!$D:$D,'2020 EPA Data'!$G:$G,C33,'2020 EPA Data'!$F:$F,I33)/metricton_to_shortton -> 13103.392
C34: SOx | D34: commercial buildings sector | E34: Total Pollutant Emissions by Sector | I34: Commercial Buildings Sector | J34: =SUMIFS(EPS!$J:$J,EPS!$D:$D,'7. Particulates'!C34,EPS!$C:$C,'7. Particulates'!D34,EPS!$B:$B,'7. Particulates'!E34)/10^6 -> #N/A | K34: =SUMIFS('2020 EPA Data'!$D:$D,'2020 EPA Data'!$G:$G,C34,'2020 EPA Data'!$F:$F,I34)/metricton_to_shortton -> 12396.694
C35: SOx | D35: industry sector | E35: Total Pollutant Emissions by Sector | I35: Industry | J35: =SUMIFS(EPS!$J:$J,EPS!$D:$D,'7. Particulates'!C35,EPS!$C:$C,'7. Particulates'!D35,EPS!$B:$B,'7. Particulates'!E35)/10^6 -> #N/A | K35: =SUMIFS('2020 EPA Data'!$D:$D,'2020 EPA Data'!$G:$G,C35,'2020 EPA Data'!$F:$F,"*"&I35&"*")/metricton_to_shortton -> 663082.98
C36: SOx | I36: Nonroad | J36: =SUMIFS(EPS!$J:$J,EPS!$D:$D,'7. Particulates'!C36,EPS!$C:$C,'7. Particulates'!D36,EPS!$B:$B,'7. Particulates'!E36)/10^6 -> 0 | K36: =SUMIFS('2020 EPA Data'!$D:$D,'2020 EPA Data'!$G:$G,C36,'2020 EPA Data'!$F:$F,I36)/metricton_to_shortton*INDEX(GWP!$C$2:$C$13,MATCH(C36,GWP!$B$2:$B$13,0)) -> 0
C37: SOx | D37: district heat and hydrogen sector | E37: Total Pollutant Emissions by Sector | I37: District Heat Sector | J37: =SUMIFS(EPS!$J:$J,EPS!$D:$D,'7. Particulates'!C37,EPS!$C:$C,'7. Particulates'!D37,EPS!$B:$B,'7. Particulates'!E37)/10^6 -> #N/A | K37: =SUMIFS('2020 EPA Data'!$D:$D,'2020 EPA Data'!$G:$G,C37,'2020 EPA Data'!$F:$F,I37)/metricton_to_shortton*INDEX(GWP!$C$2:$C$13,MATCH(C37,GWP!$B$2:$B$13,0)) -> 0
C38: SOx | D38: LULUCF sector | E38: Total Pollutant Emissions by Sector | I38: LULUCF Sector | J38: =SUMIFS(EPS!$J:$J,EPS!$D:$D,'7. Particulates'!C38,EPS!$C:$C,'7. Particulates'!D38,EPS!$B:$B,'7. Particulates'!E38)/10^6 -> #N/A | K38: =SUMIFS('2020 EPA Data'!$D:$D,'2020 EPA Data'!$G:$G,C38,'2020 EPA Data'!$F:$F,I38)/metricton_to_shortton*INDEX(GWP!$C$2:$C$13,MATCH(C38,GWP!$B$2:$B$13,0)) -> 0
C39: SOx | D39: geoengineering sector | E39: Total Pollutant Emissions by Sector | I39: Geoengineering Sector | J39: =SUMIFS(EPS!$J:$J,EPS!$D:$D,'7. Particulates'!C39,EPS!$C:$C,'7. Particulates'!D39,EPS!$B:$B,'7. Particulates'!E39)/10^6 -> #N/A | K39: =SUMIFS('2020 EPA Data'!$D:$D,'2020 EPA Data'!$G:$G,C39,'2020 EPA Data'!$F:$F,I39)/metricton_to_shortton*INDEX(GWP!$C$2:$C$13,MATCH(C39,GWP!$B$2:$B$13,0)) -> 0
C40: SOx | I40: Other-EPA | J40: =SUMIFS(EPS!$J:$J,EPS!$D:$D,'7. Particulates'!C40,EPS!$C:$C,'7. Particulates'!D40,EPS!$B:$B,'7. Particulates'!E40)/10^6 -> 0 | K40: =SUMIFS('2020 EPA Data'!$D:$D,'2020 EPA Data'!$G:$G,C40,'2020 EPA Data'!$F:$F,I40)/metricton_to_shortton -> 202975.57
I41: Total | J41: =SUM(J31:J40) -> #N/A | K41: =SUM(K31:K40) -> 1670473.8
G50: 7.3
J51: EPS 2021 | K51: EPA 2020
C52: PM25 | D52: transportation sector | E52: Total Pollutant Emissions by Sector | I52: Transportation Sector | J52: =SUMIFS(EPS!$J:$J,EPS!$D:$D,'7. Particulates'!C52,EPS!$C:$C,'7. Particulates'!D52,EPS!$B:$B,'7. Particulates'!E52)/10^6 -> #N/A | K52: =SUMIFS('2020 EPA Data'!$D:$D,'2020 EPA Data'!$G:$G,C52,'2020 EPA Data'!$F:$F,I52)/metricton_to_shortton -> 93376.636
C53: PM25 | D53: electricity sector | E53: Total Pollutant Emissions by Sector | I53: Electricity Sector | J53: =SUMIFS(EPS!$J:$J,EPS!$D:$D,'7. Particulates'!C53,EPS!$C:$C,'7. Particulates'!D53,EPS!$B:$B,'7. Particulates'!E53)/10^6 -> #N/A | K53: =SUMIFS('2020 EPA Data'!$D:$D,'2020 EPA Data'!$G:$G,C53,'2020 EPA Data'!$F:$F,I53)/metricton_to_shortton -> 77467.319
C54: PM25 | D54: residential buildings sector | E54: Total Pollutant Emissions by Sector | I54: Residential Buildings Sector | J54: =SUMIFS(EPS!$J:$J,EPS!$D:$D,'7. Particulates'!C54,EPS!$C:$C,'7. Particulates'!D54,EPS!$B:$B,'7. Particulates'!E54)/10^6 -> #N/A | K54: =SUMIFS('2020 EPA Data'!$D:$D,'2020 EPA Data'!$G:$G,C54,'2020 EPA Data'!$F:$F,I54)/metricton_to_shortton -> 445198.72
C55: PM25 | D55: commercial buildings sector | E55: Total Pollutant Emissions by Sector | I55: Commercial Buildings Sector | J55: =SUMIFS(EPS!$J:$J,EPS!$D:$D,'7. Particulates'!C55,EPS!$C:$C,'7. Particulates'!D55,EPS!$B:$B,'7. Particulates'!E55)/10^6 -> #N/A | K55: =SUMIFS('2020 EPA Data'!$D:$D,'2020 EPA Data'!$G:$G,C55,'2020 EPA Data'!$F:$F,I55)/metricton_to_shortton -> 191830.79
C56: PM25 | D56: industry sector | E56: Total Pollutant Emissions by Sector | I56: Industry | J56: =SUMIFS(EPS!$J:$J,EPS!$D:$D,'7. Particulates'!C56,EPS!$C:$C,'7. Particulates'!D56,EPS!$B:$B,'7. Particulates'!E56)/10^6 -> #N/A | K56: =SUMIFS('2020 EPA Data'!$D:$D,'2020 EPA Data'!$G:$G,C56,'2020 EPA Data'!$F:$F,"*"&I56&"*")/metricton_to_shortton -> 654635.27
C57: PM25 | I57: Nonroad | J57: =SUMIFS(EPS!$J:$J,EPS!$D:$D,'7. Particulates'!C57,EPS!$C:$C,'7. Particulates'!D57,EPS!$B:$B,'7. Particulates'!E57)/10^6 -> 0 | K57: =SUMIFS('2020 EPA Data'!$D:$D,'2020 EPA Data'!$G:$G,C57,'2020 EPA Data'!$F:$F,I57)/metricton_to_shortton*INDEX(GWP!$C$2:$C$13,MATCH(C57,GWP!$B$2:$B$13,0)) -> 0
C58: PM25 | D58: district heat and hydrogen sector | E58: Total Pollutant Emissions by Sector | I58: District Heat Sector | J58: =SUMIFS(EPS!$J:$J,EPS!$D:$D,'7. Particulates'!C58,EPS!$C:$C,'7. Particulates'!D58,EPS!$B:$B,'7. Particulates'!E58)/10^6 -> #N/A | K58: =SUMIFS('2020 EPA Data'!$D:$D,'2020 EPA Data'!$G:$G,C58,'2020 EPA Data'!$F:$F,I58)/metricton_to_shortton*INDEX(GWP!$C$2:$C$13,MATCH(C58,GWP!$B$2:$B$13,0)) -> 0
C59: PM25 | D59: LULUCF sector | E59: Total Pollutant Emissions by Sector | I59: LULUCF Sector | J59: =SUMIFS(EPS!$J:$J,EPS!$D:$D,'7. Particulates'!C59,EPS!$C:$C,'7. Particulates'!D59,EPS!$B:$B,'7. Particulates'!E59)/10^6 -> #N/A | K59: =SUMIFS('2020 EPA Data'!$D:$D,'2020 EPA Data'!$G:$G,C59,'2020 EPA Data'!$F:$F,I59)/metricton_to_shortton*INDEX(GWP!$C$2:$C$13,MATCH(C59,GWP!$B$2:$B$13,0)) -> 0
C60: PM25 | D60: geoengineering sector | E60: Total Pollutant Emissions by Sector | I60: Geoengineering Sector | J60: =SUMIFS(EPS!$J:$J,EPS!$D:$D,'7. Particulates'!C60,EPS!$C:$C,'7. Particulates'!D60,EPS!$B:$B,'7. Particulates'!E60)/10^6 -> #N/A | K60: =SUMIFS('2020 EPA Data'!$D:$D,'2020 EPA Data'!$G:$G,C60,'2020 EPA Data'!$F:$F,I60)/metricton_to_shortton*INDEX(GWP!$C$2:$C$13,MATCH(C60,GWP!$B$2:$B$13,0)) -> 0
...

Sheet EPS
A1: NoSettings Tag | B1: Variable Name | C1: Sub 1 | D1: Sub 2 | E1: Sub 3 | F1: Sub 4 | G1: Sector | H1: units | I1: Pollutant | J1: 2021 (g pollutant) | K1: GWP | L1: Value (MMTCO2e; MMT; MWh) | N1: =SUBTOTAL(9,L62:L1281)*million -> 5.7879197e+08
A2: Transportation Pollutant Emissions Disaggregated[LDVs,CO2,passenger,electricity tf] | B2: Transportation Pollutant Emissions Disaggregated | C2: LDVs | D2: CO2 | E2: passenger | F2: electricity tf | H2: =INDEX('Vensim Variables'!$B:$B,MATCH(EPS!$B2,'Vensim Variables'!$A:$A,0)) -> g pollutant | I2: =IF(OR(C2="CO2",C2="CH4",C2="N2O",C2="F gases",C2="VOC",C2="CO",C2="NOx",C2="PM10",C2="PM25",C2="SOx",C2="BC",C2="OC"),C2,IF(OR(D2="CO2",D2="CH4",D2="N2O",D2="F gases",D2="VOC",D2="CO",D2="NOx",D2="PM10",D2="PM25",D2="SOx",D2="BC",D2="OC"),D2,IF(OR(E2="CO2",E2="CH4",E2="N2O",E2="F gases",E2="VOC",E2="CO",E2="NOx",E2="PM10",E2="PM25",E2="SOx",E2="BC",E2="OC"),E2,"NA"))) -> CO2 | J2: =INDEX(NoSettings!$C:$C,MATCH(EPS!$A2,NoSettings!$A:$A,0)) -> 0 | K2: =INDEX(GWP!$C$2:$C$13,MATCH(EPS!I2,GWP!$B$2:$B$13,0)) -> 1 | L2: =IF(H2="g pollutant",K2*J2/10^12,IF(H2="MMTCO2e",J2,IF(H2="MWh",J2,0))) -> 0
A3: Transportation Pollutant Emissions Disaggregated[LDVs,CO2,passenger,natural gas tf] | B3: Transportation Pollutant Emissions Disaggregated | C3: LDVs | D3: CO2 | E3: passenger | F3: natural gas tf | H3: =INDEX('Vensim Variables'!$B:$B,MATCH(EPS!$B3,'Vensim Variables'!$A:$A,0)) -> g pollutant | I3: =IF(OR(C3="CO2",C3="CH4",C3="N2O",C3="F gases",C3="VOC",C3="CO",C3="NOx",C3="PM10",C3="PM25",C3="SOx",C3="BC",C3="OC"),C3,IF(OR(D3="CO2",D3="CH4",D3="N2O",D3="F gases",D3="VOC",D3="CO",D3="NOx",D3="PM10",D3="PM25",D3="SOx",D3="BC",D3="OC"),D3,IF(OR(E3="CO2",E3="CH4",E3="N2O",E3="F gases",E3="VOC",E3="CO",E3="NOx",E3="PM10",E3="PM25",E3="SOx",E3="BC",E3="OC"),E3,"NA"))) -> CO2 | J3: =INDEX(NoSettings!$C:$C,MATCH(EPS!$A3,NoSettings!$A:$A,0)) -> 53417600000 | K3: =INDEX(GWP!$C$2:$C$13,MATCH(EPS!I3,GWP!$B$2:$B$13,0)) -> 1 | L3: =IF(H3="g pollutant",K3*J3/10^12,IF(H3="MMTCO2e",J3,IF(H3="MWh",J3,0))) -> 0.0534176
A4: Transportation Pollutant Emissions Disaggregated[LDVs,CO2,passenger,petroleum gasoline tf] | B4: Transportation Pollutant Emissions Disaggregated | C4: LDVs | D4: CO2 | E4: passenger | F4: petroleum gasoline tf | H4: =INDEX('Vensim Variables'!$B:$B,MATCH(EPS!$B4,'Vensim Variables'!$A:$A,0)) -> g pollutant | I4: =IF(OR(C4="CO2",C4="CH4",C4="N2O",C4="F gases",C4="VOC",C4="CO",C4="NOx",C4="PM10",C4="PM25",C4="SOx",C4="BC",C4="OC"),C4,IF(OR(D4="CO2",D4="CH4",D4="N2O",D4="F gases",D4="VOC",D4="CO",D4="NOx",D4="PM10",D4="PM25",D4="SOx",D4="BC",D4="OC"),D4,IF(OR(E4="CO2",E4="CH4",E4="N2O",E4="F gases",E4="VOC",E4="CO",E4="NOx",E4="PM10",E4="PM25",E4="SOx",E4="BC",E4="OC"),E4,"NA"))) -> CO2 | J4: =INDEX(NoSettings!$C:$C,MATCH(EPS!$A4,NoSettings!$A:$A,0)) -> 968772000000000 | K4: =INDEX(GWP!$C$2:$C$13,MATCH(EPS!I4,GWP!$B$2:$B$13,0)) -> 1 | L4: =IF(H4="g pollutant",K4*J4/10^12,IF(H4="MMTCO2e",J4,IF(H4="MWh",J4,0))) -> 968.772
A5: Transportation Pollutant Emissions Disaggregated[LDVs,CO2,passenger,petroleum diesel tf] | B5: Transportation Pollutant Emissions Disaggregated | C5: LDVs | D5: CO2 | E5: passenger | F5: petroleum diesel tf | H5: =INDEX('Vensim Variables'!$B:$B,MATCH(EPS!$B5,'Vensim Variables'!$A:$A,0)) -> g pollutant | I5: =IF(OR(C5="CO2",C5="CH4",C5="N2O",C5="F gases",C5="VOC",C5="CO",C5="NOx",C5="PM10",C5="PM25",C5="SOx",C5="BC",C5="OC"),C5,IF(OR(D5="CO2",D5="CH4",D5="N2O",D5="F gases",D5="VOC",D5="CO",D5="NOx",D5="PM10",D5="PM25",D5="SOx",D5="BC",D5="OC"),D5,IF(OR(E5="CO2",E5="CH4",E5="N2O",E5="F gases",E5="VOC",E5="CO",E5="NOx",E5="PM10",E5="PM25",E5="SOx",E5="BC",E5="OC"),E5,"NA"))) -> CO2 | J5: =INDEX(NoSettings!$C:$C,MATCH(EPS!$A5,NoSettings!$A:$A,0)) -> 4619900000000 | K5: =INDEX(GWP!$C$2:$C$13,MATCH(EPS!I5,GWP!$B$2:$B$13,0)) -> 1 | L5: =IF(H5="g pollutant",K5*J5/10^12,IF(H5="MMTCO2e",J5,IF(H5="MWh",J5,0))) -> 4.6199
A6: Transportation Pollutant Emissions Disaggregated[LDVs,CO2,passenger,biofuel gasoline tf] | B6: Transportation Pollutant Emissions Disaggregated | C6: LDVs | D6: CO2 | E6: passenger | F6: biofuel gasoline tf | H6: =INDEX('Vensim Variables'!$B:$B,MATCH(EPS!$B6,'Vensim Variables'!$A:$A,0)) -> g pollutant | I6: =IF(OR(C6="CO2",C6="CH4",C6="N2O",C6="F gases",C6="VOC",C6="CO",C6="NOx",C6="PM10",C6="PM25",C6="SOx",C6="BC",C6="OC"),C6,IF(OR(D6="CO2",D6="CH4",D6="N2O",D6="F gases",D6="VOC",D6="CO",D6="NOx",D6="PM10",D6="PM25",D6="SOx",D6="BC",D6="OC"),D6,IF(OR(E6="CO2",E6="CH4",E6="N2O",E6="F gases",E6="VOC",E6="CO",E6="NOx",E6="PM10",E6="PM25",E6="SOx",E6="BC",E6="OC"),E6,"NA"))) -> CO2 | J6: =INDEX(NoSettings!$C:$C,MATCH(EPS!$A6,NoSettings!$A:$A,0)) -> 0 | K6: =INDEX(GWP!$C$2:$C$13,MATCH(EPS!I6,GWP!$B$2:$B$13,0)) -> 1 | L6: =IF(H6="g pollutant",K6*J6/10^12,IF(H6="MMTCO2e",J6,IF(H6="MWh",J6,0))) -> 0
A7: Transportation Pollutant Emissions Disaggregated[LDVs,CO2,passenger,biofuel diesel tf] | B7: Transportation Pollutant Emissions Disaggregated | C7: LDVs | D7: CO2 | E7: passenger | F7: biofuel diesel tf | H7: =INDEX('Vensim Variables'!$B:$B,MATCH(EPS!$B7,'Vensim Variables'!$A:$A,0)) -> g pollutant | I7: =IF(OR(C7="CO2",C7="CH4",C7="N2O",C7="F gases",C7="VOC",C7="CO",C7="NOx",C7="PM10",C7="PM25",C7="SOx",C7="BC",C7="OC"),C7,IF(OR(D7="CO2",D7="CH4",D7="N2O",D7="F gases",D7="VOC",D7="CO",D7="NOx",D7="PM10",D7="PM25",D7="SOx",D7="BC",D7="OC"),D7,IF(OR(E7="CO2",E7="CH4",E7="N2O",E7="F gases",E7="VOC",E7="CO",E7="NOx",E7="PM10",E7="PM25",E7="SOx",E7="BC",E7="OC"),E7,"NA"))) -> CO2 | J7: =INDEX(NoSettings!$C:$C,MATCH(EPS!$A7,NoSettings!$A:$A,0)) -> 0 | K7: =INDEX(GWP!$C$2:$C$13,MATCH(EPS!I7,GWP!$B$2:$B$13,0)) -> 1 | L7: =IF(H7="g pollutant",K7*J7/10^12,IF(H7="MMTCO2e",J7,IF(H7="MWh",J7,0))) -> 0
A8: Transportation Pollutant Emissions Disaggregated[LDVs,CO2,passenger,jet fuel tf] | B8: Transportation Pollutant Emissions Disaggregated | C8: LDVs | D8: CO2 | E8: passenger | F8: jet fuel tf | H8: =INDEX('Vensim Variables'!$B:$B,MATCH(EPS!$B8,'Vensim Variables'!$A:$A,0)) -> g pollutant | I8: =IF(OR(C8="CO2",C8="CH4",C8="N2O",C8="F gases",C8="VOC",C8="CO",C8="NOx",C8="PM10",C8="PM25",C8="SOx",C8="BC",C8="OC"),C8,IF(OR(D8="CO2",D8="CH4",D8="N2O",D8="F gases",D8="VOC",D8="CO",D8="NOx",D8="PM10",D8="PM25",D8="SOx",D8="BC",D8="OC"),D8,IF(OR(E8="CO2",E8="CH4",E8="N2O",E8="F gases",E8="VOC",E8="CO",E8="NOx",E8="PM10",E8="PM25",E8="SOx",E8="BC",E8="OC"),E8,"NA"))) -> CO2 | J8: =INDEX(NoSettings!$C:$C,MATCH(EPS!$A8,NoSettings!$A:$A,0)) -> 0 | K8: =INDEX(GWP!$C$2:$C$13,MATCH(EPS!I8,GWP!$B$2:$B$13,0)) -> 1 | L8: =IF(H8="g pollutant",K8*J8/10^12,IF(H8="MMTCO2e",J8,IF(H8="MWh",J8,0))) -> 0
A9: Transportation Pollutant Emissions Disaggregated[LDVs,CO2,passenger,heavy or residual fuel oil tf] | B9: Transportation Pollutant Emissions Disaggregated | C9: LDVs | D9: CO2 | E9: passenger | F9: heavy or residual fuel oil tf | H9: =INDEX('Vensim Variables'!$B:$B,MATCH(EPS!$B9,'Vensim Variables'!$A:$A,0)) -> g pollutant | I9: =IF(OR(C9="CO2",C9="CH4",C9="N2O",C9="F gases",C9="VOC",C9="CO",C9="NOx",C9="PM10",C9="PM25",C9="SOx",C9="BC",C9="OC"),C9,IF(OR(D9="CO2",D9="CH4",D9="N2O",D9="F gases",D9="VOC",D9="CO",D9="NOx",D9="PM10",D9="PM25",D9="SOx",D9="BC",D9="OC"),D9,IF(OR(E9="CO2",E9="CH4",E9="N2O",E9="F gases",E9="VOC",E9="CO",E9="NOx",E9="PM10",E9="PM25",E9="SOx",E9="BC",E9="OC"),E9,"NA"))) -> CO2 | J9: =INDEX(NoSettings!$C:$C,MATCH(EPS!$A9,NoSettings!$A:$A,0)) -> 0 | K9: =INDEX(GWP!$C$2:$C$13,MATCH(EPS!I9,GWP!$B$2:$B$13,0)) -> 1 | L9: =IF(H9="g pollutant",K9*J9/10^12,IF(H9="MMTCO2e",J9,IF(H9="MWh",J9,0))) -> 0
A10: Transportation Pollutant Emissions Disaggregated[LDVs,CO2,passenger,LPG propane or butane tf] | B10: Transportation Pollutant Emissions Disaggregated | C10: LDVs | D10: CO2 | E10: passenger | F10: LPG propane or butane tf | H10: =INDEX('Vensim Variables'!$B:$B,MATCH(EPS!$B10,'Vensim Variables'!$A:$A,0)) -> g pollutant | I10: =IF(OR(C10="CO2",C10="CH4",C10="N2O",C10="F gases",C10="VOC",C10="CO",C10="NOx",C10="PM10",C10="PM25",C10="SOx",C10="BC",C10="OC"),C10,IF(OR(D10="CO2",D10="CH4",D10="N2O",D10="F gases",D10="VOC",D10="CO",D10="NOx",D10="PM10",D10="PM25",D10="SOx",D10="BC",D10="OC"),D10,IF(OR(E10="CO2",E10="CH4",E10="N2O",E10="F gases",E10="VOC",E10="CO",E10="NOx",E10="PM10",E10="PM25",E10="SOx",E10="BC",E10="OC"),E10,"NA"))) -> CO2 | J10: =INDEX(NoSettings!$C:$C,MATCH(EPS!$A10,NoSettings!$A:$A,0)) -> 90425500000 | K10: =INDEX(GWP!$C$2:$C$13,MATCH(EPS!I10,GWP!$B$2:$B$13,0)) -> 1 | L10: =IF(H10="g pollutant",K10*J10/10^12,IF(H10="MMTCO2e",J10,IF(H10="MWh",J10,0))) -> 0.0904255
A11: Transportation Pollutant Emissions Disaggregated[LDVs,CO2,passenger,hydrogen tf] | B11: Transportation Pollutant Emissions Disaggregated | C11: LDVs | D11: CO2 | E11: passenger | F11: hydrogen tf | H11: =INDEX('Vensim Variables'!$B:$B,MATCH(EPS!$B11,'Vensim Variables'!$A:$A,0)) -> g pollutant | I11: =IF(OR(C11="CO2",C11="CH4",C11="N2O",C11="F gases",C11="VOC",C11="CO",C11="NOx",C11="PM10",C11="PM25",C11="SOx",C11="BC",C11="OC"),C11,IF(OR(D11="CO2",D11="CH4",D11="N2O",D11="F gases",D11="VOC",D11="CO",D11="NOx",D11="PM10",D11="PM25",D11="SOx",D11="BC",D11="OC"),D11,IF(OR(E11="CO2",E11="CH4",E11="N2O",E11="F gases",E11="VOC",E11="CO",E11="NOx",E11="PM10",E11="PM25",E11="SOx",E11="BC",E11="OC"),E11,"NA"))) -> CO2 | J11: =INDEX(NoSettings!$C:$C,MATCH(EPS!$A11,NoSettings!$A:$A,0)) -> 0 | K11: =INDEX(GWP!$C$2:$C$13,MATCH(EPS!I11,GWP!$B$2:$B$13,0)) -> 1 | L11: =IF(H11="g pollutant",K11*J11/10^12,IF(H11="MMTCO2e",J11,IF(H11="MWh",J11,0))) -> 0
A12: Transportation Pollutant Emissions Disaggregated[LDVs,CO2,freight,electricity tf] | B12: Transportation Pollutant Emissions Disaggregated | C12: LDVs | D12: CO2 | E12: freight | F12: electricity tf | H12: =INDEX('Vensim Variables'!$B:$B,MATCH(EPS!$B12,'Vensim Variables'!$A:$A,0)) -> g pollutant | I12: =IF(OR(C12="CO2",C12="CH4",C12="N2O",C12="F gases",C12="VOC",C12="CO",C12="NOx",C12="PM10",C12="PM25",C12="SOx",C12="BC",C12="OC"),C12,IF(OR(D12="CO2",D12="CH4",D12="N2O",D12="F gases",D12="VOC",D12="CO",D12="NOx",D12="PM10",D12="PM25",D12="SOx",D12="BC",D12="OC"),D12,IF(OR(E12="CO2",E12="CH4",E12="N2O",E12="F gases",E12="VOC",E12="CO",E12="NOx",E12="PM10",E12="PM25",E12="SOx",E12="BC",E12="OC"),E12,"NA"))) -> CO2 | J12: =INDEX(NoSettings!$C:$C,MATCH(EPS!$A12,NoSettings!$A:$A,0)) -> 0 | K12: =INDEX(GWP!$C$2:$C$13,MATCH(EPS!I12,GWP!$B$2:$B$13,0)) -> 1 | L12: =IF(H12="g pollutant",K12*J12/10^12,IF(H12="MMTCO2e",J12,IF(H12="MWh",J12,0))) -> 0
A13: Transportation Pollutant Emissions Disaggregated[LDVs,CO2,freight,natural gas tf] | B13: Transportation Pollutant Emissions Disaggregated | C13: LDVs | D13: CO2 | E13: freight | F13: natural gas tf | H13: =INDEX('Vensim Variables'!$B:$B,MATCH(EPS!$B13,'Vensim Variables'!$A:$A,0)) -> g pollutant | I13: =IF(OR(C13="CO2",C13="CH4",C13="N2O",C13="F gases",C13="VOC",C13="CO",C13="NOx",C13="PM10",C13="PM25",C13="SOx",C13="BC",C13="OC"),C13,IF(OR(D13="CO2",D13="CH4",D13="N2O",D13="F gases",D13="VOC",D13="CO",D13="NOx",D13="PM10",D13="PM25",D13="SOx",D13="BC",D13="OC"),D13,IF(OR(E13="CO2",E13="CH4",E13="N2O",E13="F gases",E13="VOC",E13="CO",E13="NOx",E13="PM10",E13="PM25",E13="SOx",E13="BC",E13="OC"),E13,"NA"))) -> CO2 | J13: =INDEX(NoSettings!$C:$C,MATCH(EPS!$A13,NoSettings!$A:$A,0)) -> 113334000000 | K13: =INDEX(GWP!$C$2:$C$13,MATCH(EPS!I13,GWP!$B$2:$B$13,0)) -> 1 | L13: =IF(H13="g pollutant",K13*J13/10^12,IF(H13="MMTCO2e",J13,IF(H13="MWh",J13,0))) -> 0.113334
... A1441: Transportation Pollutant Emissions Disaggregated[motorbikes,F gases,freight,hydrogen tf] | B1441: Transportation Pollutant Emissions Disaggregated | C1441: motorbikes | D1441: F gases | E1441: freight | F1441: hydrogen tf | H1441: =INDEX('Vensim Variables'!$B:$B,MATCH(EPS!$B1441,'Vensim Variables'!$A:$A,0)) -> g pollutant | I1441: =IF(OR(C1441="CO2",C1441="CH4",C1441="N2O",C1441="F gases",C1441="VOC",C1441="CO",C1441="NOx",C1441="PM10",C1441="PM25",C1441="SOx",C1441="BC",C1441="OC"),C1441,IF(OR(D1441="CO2",D1441="CH4",D1441="N2O",D1441="F gases",D1441="VOC",D1441="CO",D1441="NOx",D1441="PM10",D1441="PM25",D1441="SOx",D1441="BC",D1441="OC"),D1441,IF(OR(E1441="CO2",E1441="CH4",E1441="N2O",E1441="F gases",E1441="VOC",E1441="CO",E1441="NOx",E1441="PM10",E1441="PM25",E1441="SOx",E1441="BC",E1441="OC"),E1441,"NA"))) -> F gases | J1441: =INDEX(NoSettings!$C:$C,MATCH(EPS!$A1441,NoSettings!$A:$A,0)) -> 0 | K1441: =INDEX(GWP!$C$2:$C$13,MATCH(EPS!I1441,GWP!$B$2:$B$13,0)) -> 1 | L1441: =IF(H1441="g pollutant",K1441*J1441/10^12,IF(H1441="MMTCO2e",J1441,IF(H1441="MWh",J1441,0))) -> 0
