Workbook

Sheet About
A1: BCD BAU Cement Demand
A3: Sources: | B3: U.S. cement consumption, 2021-2025 | D3: Brazil consumption
B4: U.S. Geological Survey | D4: Sindicato Nacional da Industria do Cimento (SNIC)
B5: Mineral Commodity Summaries 2026: Cement | D5: SNIC Annual Report 2023
B6: 2026 | D6: 2024
B7: https://pubs.usgs.gov/periodicals/mcs2026/mcs2026-cement.pdf | D7: http://snic.org.br/assets/pdf/relatorio_anual/1732731328.pdf
B8: We used apparent consumption (production plus imports minus exports): 111, 114, 113, 110, and 110 million metric tons for 2021-2025, with 2025 an estimate. USGS rounds these to the nearest million tons. The table is pasted as published on the 'USGS MCS 2026 Cement' tab. | D8: 2023 apparent consumption of 62.21 million tons (production 66.53, domestic sales 62.08, imports 0.14, exports 0.20).
B10: U.S. demand growth, 2026-2050 | D10: Brazil demand growth
B11: U.S. Energy Information Administration | D11: SNIC, International Energy Agency, and World Business Council for Sustainable Development
B12: Annual Energy Outlook 2026, Table 23: Industrial Sector Macroeconomic Indicators | D12: Cement Technology Roadmap: Brazil
B13: 2026 | D13: 2019
B14: https://www.eia.gov/outlooks/aeo/tables_ref.php | D14: http://snic.org.br/assets/pdf/roadmap/cement-technology-roadmap-brazil.pdf
B15: Cement and lime value of shipments (billion 2012 dollars) in the Alternative Electricity and Transportation case, pasted on the 'AEO 2026 Table 23' tab. We use it only as a growth index: it includes lime, and because it is measured in dollars it also reflects changes in prices and product mix, not just tonnage. | D15: The roadmap expects 2050 demand to be 60% (low case) to 120% (high case) above 2014, or about 1.3% to 2.2% per year. We chose 1.7% per year from within that range. Because our 2023 starting point is below the 2014 level, the resulting 2050 demand lands under the roadmap's low case.
B17: China consumption | D17: Mexico consumption
B18: CemNet (International Cement Review) | D18: Global Cement
B19: Chinese cement dropped sharply in 2024, and will continue to fall | D19: Mexican cement consumption falls in first half of 2025
B20: 2025 | D20: 2025
B21: https://www.cemnet.com/News/story/178600/chinese-cement-dropped-sharply-in-2024-and-will-continue-to-fall.html | D21: https://www.globalcement.com/news/19770-mexican-cement-consumption-falls-in-first-half-of-2025
B22: 2024 demand of 1,858.9 million tons, down 8% from 2023. This is a trade-press figure; check it against China Cement Association or National Bureau of Statistics data before relying on it. | D22: About 42 million tons of 2024 sales, as stated by the CEO of Cementos Moctezuma. Another trade-press report puts 2024 at 46.4 million tons (a CANACEM forecast); CANACEM's own statistics should settle which is right.
B24: India consumption | D24: Canada consumption and growth
B25: American Council for an Energy-Efficient Economy (ACEEE) | D25: Cement Association of Canada
B26: Decarbonisation in the Indian Cement Industry | D26: Concrete Zero: Action Plan
B27: 2026 | D27: 2023
B28: https://www.aceee.org/wp-content/uploads/2026/07/ACEEE_Decarbonisation_in_Cement_Industry.pdf | D28: https://cement.ca/wp-content/uploads/ConcreteZero-Report-FINAL-reduced.pdf
B29: Consumption of 435 million tons in fiscal year 2024-25 (April to March), which we treat as calendar 2024. ACEEE cites the India Brand Equity Foundation for this figure. | D29: Production of 12.7 million tons in 2020 by the association's member companies, and an assumed 1% per year growth in cement volume from 2020, which we use as the growth rate. We estimate consumption by combining this 2020 production with 2024 trade data (next source), so the starting value is low confidence. Statistics Canada's monthly cement table or Natural Resources Canada's Minerals Yearbook would give a better figure.
B31: India demand growth | D31: Canada trade
B32: Indian Cement Review | D32: United Nations
B33: NITI Aayog unveils decarbonisation roadmaps | D33: UN Comtrade Database, HS 2523 (cement and clinker), reporter Canada, 2024
B34: 2026 | D34: 2026
B35: https://indiancementreview.com/2026/01/28/niti-aayog-unveils-decarbonisation-roadmaps/ | D35: https://comtradeplus.un.org/
B36: NITI Aayog's roadmap projects demand rising from 391 million tons in 2023 to 2,100 million tons in 2070. The growth rate on the 'Regions' tab is the constant annual rate between those two points (about 3.6% per year). The roadmap's path is front-loaded (about 7.8% per year to 2030), so a constant rate understates near-term growth. | D36: 2024 imports of 1.20 million tons; exports of 4.39 million tons of cement and 0.47 million tons of clinker. Accessed 2026.
B38: EU-27 consumption | D38: Indonesia consumption
B39: Cement Europe | D39: Asosiasi Pengusaha Semen Indonesia (Asperssi)
B40: Cement Europe Statistics Report 2025 | D40: Asperssi ungkap volume produksi & penjualan semen di 2025 dan proyeksi untuk 2026
B41: 2025 | D41: 2026
B42: https://www.cementeurope.eu/media/ncylewmn/cement-europe-statistics-report-2025.pdf | D42: https://asperssi.id/asperssi-ungkap-volume-produksi-penjualan-semen-di-2025-dan-proyeksi-untuk-2026/
B43: EU-27 consumption of 148.1 million tons in 2024. Use the EU-27 figure, not the 165.1 million tons reported for Cement Europe's wider membership. The report's EU-27 production (160.8 million tons) exceeds consumption by more than Eurostat's net trade would explain; we have not resolved this. | D43: 2025 domestic sales of 63.9 million tons, used as consumption because Indonesia imports very little cement. 2025 production was 64.7 million tons.
B45: Japan consumption
B46: World Bank, World Integrated Trade Solution (WITS)
B47: Japan cement clinker (HS 252310) exports, 2024
...

Sheet Regions
A1: Selected region (drop-down): | B1: United States
A2: Pick a region from the drop-down in B1. The Derivation and the export tab update on their own; re-export the CSV afterward. A blank cell means no sourced value yet.
A4: Region | B4: Anchor year | C4: Apparent consumption anchor (Mt) | D4: Flag | E4: Growth CAGR to 2050 (fraction/yr; blank = flat; US uses AEO index instead) | F4: Flag | G4: Cement production, USGS 2025e (Mt, context) | H4: Source / note
A5: United States | B5: 2025 | C5: 110 | D5: DIRECT | F5: AEO | G5: 84 | H5: USGS MCS 2026 apparent consumption; growth = AEO 2026 Table 23 cement & lime index
A6: China | B6: 2024 | C6: 1858.9 | D6: SNIPPET | G6: 1700 | H6: CemNet citing demand data (SNIPPET). 2025 projection 1,790 (ICR via Cement Europe, SNIPPET); NBS 2025 production 1,670-1,693 (SNIPPET); 2024 fell ~8-10% y/y. Long-run CAGR TO FILL (IEA 2018 roadmap: China declines to 2050, no number).
A7: India | B7: 2024 | C7: 435 | D7: SNIPPET | E7: =((2100/391)^(1/(2070-2023))-1) -> 0.036412924 | F7: JUDGMENT | G7: 470 | H7: FY2024-25 (Apr 2024-Mar 2025, assigned to 2024) consumption 435 / production 427, ACEEE Jul-2026 citing IBEF. USGS gives calendar-year production of 440 (2024e) and 470 (2025e). | CAGR (2023-70): NITI Aayog Jan-2026 path 391 (2023) -> 2,100 Mt (2070) (SNIPPET); CAGR is own arithmetic. Front-loaded path: 7.8%/yr 2023-30, 5.9%/yr 2030-47; GCCA India/TERI ~3.1%/yr; IEA 2018 'triple by 2050' ~3.1%/yr. A flat CAGR understates near-term growth.
A8: EU-27 | B8: 2024 | C8: 148.1 | D8: DIRECT | H8: Cement Europe Statistics Report 2025, EU-27 scope (DIRECT). Production 160.8 (2024, DIRECT). UNRESOLVED: production - consumption = +12.7 Mt vs ~0 Eurostat net trade - ask Cement Europe. Do not mix with the 165.1 wider-membership figure.
A9: Japan | B9: 2024 | C9: 40 | D9: JUDGMENT | G9: 44 | H9: production minus net clinker exports, rough; JCA not opened
A10: Brazil | B10: 2023 | C10: 62.21 | D10: DIRECT | E10: 0.017 | F10: JUDGMENT | G10: 67 | H10: SNIC Annual Report 2023 apparent consumption (DIRECT). Other figures: 2024 SNIC sales 64.652 (via CemNet, SNIPPET); 2024 consumption 64.8 and 2025 dispatches 66.984 (SNIPPET). A 73 Mt 2024 'consumption' figure in secondary sources is unreliable. | CAGR (2014-50): SNIC/IEA/WBCSD 2019 roadmap: demand +60% (low) to +120% (high) vs 2014 by 2050 (DIRECT) = 1.3-2.2%/yr; 1.7%/yr chosen within the range (judgment). Applied from the 2023 anchor, which sits below the 2014 base, so 2050 lands under the roadmap low case.
A11: Mexico | B11: 2024 | C11: 42 | D11: SNIPPET | G11: 42 | H11: ~42 Mt 2024 sales (Cementos Moctezuma CEO via Global Cement, SNIPPET). CONFLICT: a 2024 CANACEM forecast via Global Cement gives 46.4 - resolve against CANACEM statistics. 2025 consumption -6% (SNIPPET).
A12: Canada | B12: 2024 | C12: =12.7+1.2-(4.39+0.47) -> 9.04 | D12: JUDGMENT | E12: 0.01 | F12: DIRECT | H12: LOW CONFIDENCE: 2020 CAC-member production 12.7 (DIRECT, Concrete Zero) + 2024 Comtrade imports 1.20 - exports (cement 4.39 + clinker 0.47) (DIRECT trade); mixes years. StatCan 16-10-0009-01 ends 2018. Next: StatCan monthly cement table / NRCan Minerals Yearbook. | CAGR (2020-50): CAC Concrete Zero Action Plan assumes cement volume +1%/yr from 2020 (DIRECT).
A13: Indonesia | B13: 2025 | C13: 63.912 | D13: DIRECT | G13: 64 | H13: Asperssi (ASI) 2025 domestic sales, used as apparent consumption (imports negligible) (DIRECT). 2024: 64.895. Production 64.720 (2025).
A14: Australia | H14: TO FILL - CIF Industry Report (secondary market-report figures rejected as low confidence)

Sheet USGS MCS 2026 Cement
A1: USGS Mineral Commodity Summaries 2026 - Cement (Ashley K. Hatfield). Pasted from the PDF text; 'e' = estimated. Data in thousand metric tons unless otherwise specified.
A3: Salient Statistics - United States (thousand metric tons unless noted) | B3: 2021 | C3: 2022 | D3: 2023 | E3: 2024 | F3: 2025e
A4: Production: Portland, blended, and masonry cement (includes cement made from imported clinker) | B4: 91000 | C4: 91200 | D4: 89700 | E4: 85000 | F4: 84000
A5: Production: Clinker | B5: 79616 | C5: 79489 | D5: 76789 | E5: 72000 | F5: 69000
A6: Shipments to final customers, includes exports | B6: 108969 | C6: 111092 | D6: 110290 | E6: 100000 | F6: 100000
A7: Imports for consumption: Hydraulic cement | B7: 19937 | C7: 24985 | D7: 24986 | E7: 23675 | F7: 23000
A8: Imports for consumption: Clinker | B8: 1563 | C8: 1021 | D8: 921 | E8: 685 | F8: 660
A9: Exports, hydraulic cement and clinker | B9: 939 | C9: 904 | D9: 889 | E9: 932 | F9: 1000
A10: Consumption, apparent (production incl. from imported clinker + imports excl. clinker - exports - stock changes) | B10: 111000 | C10: 114000 | D10: 113000 | E10: 110000 | F10: 110000
A11: Price, average mill unit value, dollars per metric ton | B11: 127 | C11: 139 | D11: 152 | E11: 160 | F11: 160
A12: Stocks, cement, yearend | B12: 6280 | C12: 8010 | D12: 8830 | E12: 9700 | F12: 8200
A13: Net import reliance as a percentage of apparent consumption | B13: 19 | C13: 22 | D13: 22 | E13: 22 | F13: 21
A15: World Production and Capacity (thousand metric tons) | B15: Cement production 2024 | C15: Cement production 2025e | D15: Clinker capacity 2024 | E15: Clinker capacity 2025e
A16: United States (includes Puerto Rico) | B16: 85000 | C16: 84000 | D16: 100000 | E16: 100000
A17: Brazil | B17: 65000 | C17: 67000 | D17: 60000 | E17: 61000
A18: China | B18: 1800000 | C18: 1700000 | D18: 1900000 | E18: 1800000
A19: Egypt | B19: 53000 | C19: 64000 | D19: 60000 | E19: 75000
A20: India | B20: 440000 | C20: 470000 | D20: 380000 | E20: 400000
A21: Indonesia | B21: 68000 | C21: 64000 | D21: 79000 | E21: 83000
A22: Iran | B22: 71000 | C22: 68000 | D22: 85000 | E22: 85000
A23: Japan | B23: 46000 | C23: 44000 | D23: 50000 | E23: 50000
A24: Korea, Republic of | B24: 44000 | C24: 37000 | D24: 62000 | E24: 62000
A25: Mexico | B25: 44000 | C25: 42000 | D25: 42000 | E25: 42000
A26: Russia | B26: 67000 | C26: 59000 | D26: 80000 | E26: 80000
A27: Saudi Arabia | B27: 51000 | C27: 54000 | D27: 75000 | E27: 75000
... A31: World total (rounded) | B31: 3900000 | C31: 3800000 | D31: 3800000 | E31: 3800000

Sheet AEO 2026 Table 23
A1: EIA Annual Energy Outlook 2026, Table 23 Industrial Sector Macroeconomic Indicators, Value of Shipments (billion 2012 dollars), case ELECTRNP (Alternative Electricity and Transportation - the case the io-model BPCiObIC workbook uses). Row pasted from that workbook's 'AEO 2026 Table 23 ' tab.
A3: api id | B3: full name | C3: series key | D3: units | E3: 2025 | F3: 2026 | G3: 2027 | H3: 2028 | I3: 2029 | J3: 2030 | K3: 2031 | L3: 2032 | M3: 2033 | N3: 2034 | O3: 2035 | P3: 2036 | Q3: 2037 | R3: 2038 | S3: 2039 | T3: 2040 | U3: 2041 | V3: 2042 | W3: 2043 | X3: 2044 | Y3: 2045 | Z3: 2046 | AA3: 2047 | AB3: 2048 | AC3: 2049 | AD3: 2050
A4: ISM000:fa_CementandHydr | B4: Cement and Lime | C4: AEO.2026.ELECTRNP.ECI_VOS_MANF_SCGCL_NA_NA_NA_BLNY09DLR.A | D4: billion 2012 $ | E4: 9.336027 | F4: 9.138749 | G4: 8.976787 | H4: 8.899744 | I4: 8.858376 | J4: 8.879111 | K4: 8.939971 | L4: 9.02407 | M4: 9.135289 | N4: 9.258553 | O4: 9.389754 | P4: 9.524654 | Q4: 9.657454 | R4: 9.793234 | S4: 9.925656 | T4: 10.036542 | U4: 10.121435 | V4: 10.178687 | W4: 10.198941 | X4: 10.195507 | Y4: 10.222628 | Z4: 10.289026 | AA4: 10.381219 | AB4: 10.489734 | AC4: 10.605895 | AD4: 10.7287

Sheet Derivation
A1: Selected region | B1: =Regions!B1 -> United States
A2: Anchor year | B2: =INDEX(Regions!$B$5:$B$14,MATCH(Regions!$B$1,Regions!$A$5:$A$14,0)) -> 2025
A3: Anchor apparent consumption (Mt) | B3: =INDEX(Regions!$C$5:$C$14,MATCH(Regions!$B$1,Regions!$A$5:$A$14,0)) -> 110
A4: Growth CAGR (fraction/yr, blank = 0) | B4: =IF(ISNUMBER(INDEX(Regions!$E$5:$E$14,MATCH(Regions!$B$1,Regions!$A$5:$A$14,0))),INDEX(Regions!$E$5:$E$14,MATCH(Regions!$B$1,Regions!$A$5:$A$14,0)),0) -> 0
A5: Is US? (history + AEO index) | B5: =IF(B1="United States",1,0) -> 1
A7: Year | B7: 2021 | C7: 2022 | D7: 2023 | E7: 2024 | F7: 2025 | G7: 2026 | H7: 2027 | I7: 2028 | J7: 2029 | K7: 2030 | L7: 2031 | M7: 2032 | N7: 2033 | O7: 2034 | P7: 2035 | Q7: 2036 | R7: 2037 | S7: 2038 | T7: 2039 | U7: 2040 | V7: 2041 | W7: 2042 | X7: 2043 | Y7: 2044 | Z7: 2045 | AA7: 2046 | AB7: 2047 | AC7: 2048 | AD7: 2049 | AE7: 2050
A8: USGS apparent consumption (Mt; US only, 2021-2025) | B8: ='USGS MCS 2026 Cement'!B10/1000 -> 111 | C8: ='USGS MCS 2026 Cement'!C10/1000 -> 114 | D8: ='USGS MCS 2026 Cement'!D10/1000 -> 113 | E8: ='USGS MCS 2026 Cement'!E10/1000 -> 110 | F8: ='USGS MCS 2026 Cement'!F10/1000 -> 110
A9: AEO cement & lime index (US only; = shipments(y) / shipments(2025)) | F9: ='AEO 2026 Table 23'!E4/'AEO 2026 Table 23'!$E$4 -> 1 | G9: ='AEO 2026 Table 23'!F4/'AEO 2026 Table 23'!$E$4 -> 0.97886917 | H9: ='AEO 2026 Table 23'!G4/'AEO 2026 Table 23'!$E$4 -> 0.96152111 | I9: ='AEO 2026 Table 23'!H4/'AEO 2026 Table 23'!$E$4 -> 0.95326888 | J9: ='AEO 2026 Table 23'!I4/'AEO 2026 Table 23'!$E$4 -> 0.94883787 | K9: ='AEO 2026 Table 23'!J4/'AEO 2026 Table 23'!$E$4 -> 0.95105884 | L9: ='AEO 2026 Table 23'!K4/'AEO 2026 Table 23'!$E$4 -> 0.95757767 | M9: ='AEO 2026 Table 23'!L4/'AEO 2026 Table 23'!$E$4 -> 0.96658568 | ... AE9: ='AEO 2026 Table 23'!AD4/'AEO 2026 Table 23'!$E$4 -> 1.1491719
A10: Generic index ((1+CAGR)^(y - anchor year)) | B10: =(1+$B$4)^(B7-$B$2) -> 1 | C10: =(1+$B$4)^(C7-$B$2) -> 1 | D10: =(1+$B$4)^(D7-$B$2) -> 1 | E10: =(1+$B$4)^(E7-$B$2) -> 1 | F10: =(1+$B$4)^(F7-$B$2) -> 1 | G10: =(1+$B$4)^(G7-$B$2) -> 1 | H10: =(1+$B$4)^(H7-$B$2) -> 1 | I10: =(1+$B$4)^(I7-$B$2) -> 1 | ... AE10: =(1+$B$4)^(AE7-$B$2) -> 1
A11: BAU Cement Demand (metric tons/year) | B11: =1000000*IF($B$5=1,IF(B7<=2025,B8,$B$3*B9),$B$3*B10) -> 111000000 | C11: =1000000*IF($B$5=1,IF(C7<=2025,C8,$B$3*C9),$B$3*C10) -> 114000000 | D11: =1000000*IF($B$5=1,IF(D7<=2025,D8,$B$3*D9),$B$3*D10) -> 113000000 | E11: =1000000*IF($B$5=1,IF(E7<=2025,E8,$B$3*E9),$B$3*E10) -> 110000000 | F11: =1000000*IF($B$5=1,IF(F7<=2025,F8,$B$3*F9),$B$3*F10) -> 110000000 | G11: =1000000*IF($B$5=1,IF(G7<=2025,G8,$B$3*G9),$B$3*G10) -> 1.0767561e+08 | H11: =1000000*IF($B$5=1,IF(H7<=2025,H8,$B$3*H9),$B$3*H10) -> 1.0576732e+08 | I11: =1000000*IF($B$5=1,IF(I7<=2025,I8,$B$3*I9),$B$3*I10) -> 1.0485958e+08 | ... AE11: =1000000*IF($B$5=1,IF(AE7<=2025,AE8,$B$3*AE9),$B$3*AE10) -> 1.2640891e+08

Sheet BCD
A1: Unit: metric tons/year | B1: 2021 | C1: 2022 | D1: 2023 | E1: 2024 | F1: 2025 | G1: 2026 | H1: 2027 | I1: 2028 | J1: 2029 | K1: 2030 | L1: 2031 | M1: 2032 | N1: 2033 | O1: 2034 | P1: 2035 | Q1: 2036 | R1: 2037 | S1: 2038 | T1: 2039 | U1: 2040 | V1: 2041 | W1: 2042 | X1: 2043 | Y1: 2044 | Z1: 2045 | AA1: 2046 | AB1: 2047 | AC1: 2048 | AD1: 2049 | AE1: 2050
A2: BAU Cement Demand | B2: =(Derivation!B11) -> 111000000 | C2: =(Derivation!C11) -> 114000000 | D2: =(Derivation!D11) -> 113000000 | E2: =(Derivation!E11) -> 110000000 | F2: =(Derivation!F11) -> 110000000 | G2: =(Derivation!G11) -> 1.0767561e+08 | H2: =(Derivation!H11) -> 1.0576732e+08 | I2: =(Derivation!I11) -> 1.0485958e+08 | ... AE2: =(Derivation!AE11) -> 1.2640891e+08
