Workbook
Name Eno_TM: #REF!
Name Eno_Tons: #REF!
Name Sum_T2: #REF!
Name Sum_TTM: #REF!
Name ti_tbl_50: #REF!
Name ti_tbl_69: #REF!
Name TitleRegion1.f2.y3.5: #REF!
Name TitleRegion1.f3.n4.5: #REF!
Name TitleRegion2.e6.y15.5: #REF!
Name TitleRegion2.e8.n17.5: #REF!
Name TitleRegion3.c19.y51.5: #REF!
Name TitleRegion3.c24.n53.5: #REF!
Name TitleRegion4.e54.y63.5: #REF!
Name TitleRegion4.e57.n66.5: #REF!
Name TitleRegion5.d68.y124.5: #REF!
Name TitleRegion5.d73.n129.5: #REF!

Sheet About
A1: SYVbT Start Year Vehicles by Technology
A3: Sources: | B3: passenger LDVs | D3: School buses
B4: EIA | D4: U.S. Federal Highway Administration
B5: 2025 | D5: Highway Statistics 2023, Table MV-10 (publicly owned vehicles)
B6: Annual Energy Outlook 2025 | D6: 2024
B7: https://www.eia.gov/outlooks/aeo/supplement/excel/suptab_40.xlsx | D7: https://www.fhwa.dot.gov/policyinformation/statistics.cfm
B8: Table 39 | D8: School buses, 424,199 in 2023, on tab 'calcs' (bus block). The 2024 edition jumps to 509,196 with a reporting change, so 2023 is used; DOE's Fact of the Week 1320 cites about 450,000.
B10: freight LDVs | D10: Transit buses
B11: EIA | D11: Federal Transit Administration, National Transit Database
B12: 2025 | D12: 2024 NTD Annual Data - Vehicles (Age Distribution), bus modes
B13: Annual Energy Outlook 2025 | D13: 2025
B14: https://www.eia.gov/outlooks/aeo/supplement/excel/suptab_40.xlsx | D14: https://data.transportation.gov/Public-Transit/2022-2025-NTD-Annual-Data-Vehicles-Age-Distribution-/6abt-uhgq
B15: Tables 45, 49 | D15: Transit buses including cutaways, 103,013 in 2024, on tab 'calcs' (bus block).
B17: passenger HDVs, rail, motorbikes | D17: Motorcoaches
B18: DoT | D18: American Bus Association Foundation
B19: 2019 | D19: Motorcoach Census 2025
B20: National Transportation Statistics 2018 Q4 | D20: 2025
B21: https://www.bts.gov/content/number-us-aircraft-vehicles-vessels-and-other-conveyances | D21: https://www.buses.org/foundation/
B22: Table 1-11 | D22: Motorcoaches in service, 49,543, on tab 'calcs' (bus block). Not to be used for school or transit buses, which the census excludes.
B24: passenger ships | D24: Class I locomotives by year built (freight rail fleet)
B25: U.S. Coast Guard | D25: Bureau of Transportation Statistics (AAR Railroad Facts data)
B26: 2013 | D26: National Transportation Statistics Table 1-32, Jul 2026 edition
B27: National Recreational Boating Survey 2012 | D27: 2026
B28: http://www.uscgboating.org/library/recreational-boating-servey/2012survey%20report.pdf | D28: https://www.bts.gov/content/class-i-railroad-locomotive-fleet-year-built
B29: Page 63, Table 40 | D29: Transcribed from the BTS online viewer on tab 'NTS 1-32' (2015-2024); the fleet total is the locomotives OWNED by Class I railroads, including units in storage. The Table 1-11 locomotive row reads it for the lookup year. Not comparable to editions before 2023.
B31: electric buses (passenger HDVs) | D31: Transit and commuter rail revenue vehicles (passenger rail fleet)
B32: DoT | D32: Federal Transit Administration, National Transit Database
B33: 2016 | D33: 2022-2025 NTD Annual Data - Vehicles (Age Distribution), 2024 report year
B34: Zero Emissions Bus Operators | D34: 2025
B35: https://www.transportation.gov/r2ze/fleets-zero-emission-buses-us-and-china | D35: https://data.transportation.gov/Public-Transit/2022-2025-NTD-Annual-Data-Vehicles-Age-Distribution-/6abt-uhgq
B36: First paragraph | D36: Rail revenue vehicles by state (heavy rail cars, light rail vehicles, commuter rail coaches, self-propelled cars and locomotives, automated guideway, monorail, cable car, inclined plane), 23,648 in 2024, in column Y of 'psgr rail calcs'. Amtrak is not in the NTD.
B38: freight HDVs | D38: Registered recreational boats (passenger ships)
B39: EIA | D39: U.S. Coast Guard, via Bureau of Transportation Statistics
B40: 2025 | D40: National Transportation Statistics Table 1-11, recreational vessels
B41: Annual Energy Outlook 2025 | D41: 2026
B42: https://www.eia.gov/outlooks/aeo/supplement/excel/suptab_40.xlsx | D42: https://www.bts.gov/content/number-us-aircraft-vehicles-vessels-and-other-conveyances
B43: Table 49 | D43: State-registered recreational vessels, 11,674,073 in 2024, on tab 'NTS 1-11' (row 32). Counts registered boats only; the 2012 National Recreational Boating Survey counts boats owned, registered or not, and is kept for the boating-activity figures the distance file reads.
B45: Class II and Class III (Small) Railroad Statistics
B46: Federal Railroad Administration
B47: 2014
...

Sheet source data>

Sheet AEO 2025 48
A1: Table 48. Aircraft Stock
A2: https://www.eia.gov/outlooks/aeo/data/browser/#/?id=148-AEO2025&cases=alttrnp&sourcekey=0
A3: Fri Dec 05 2025 14:51:35 GMT-0800 (Pacific Standard Time)
A4: Source: U.S. Energy Information Administration
B5: full name | C5: api key | D5: units | E5: 2023 | F5: 2024 | G5: 2025 | H5: 2026 | I5: 2027 | J5: 2028 | K5: 2029 | L5: 2030 | M5: 2031 | N5: 2032 | O5: 2033 | P5: 2034 | Q5: 2035 | R5: 2036 | S5: 2037 | T5: 2038 | U5: 2039 | V5: 2040 | W5: 2041 | X5: 2042 | Y5: 2043 | Z5: 2044 | AA5: 2045 | AB5: 2046 | AC5: 2047 | AD5: 2048 | AE5: 2049 | AF5: 2050 | AG5: Growth (2024-2050)
A6: Aircraft Stock
A7: United States | B7: Aircraft Stock: Total: United States: Alternative Transportation | C7: AEO.2025.ALTTRNP.STK_AIRC_NA_NA_NA_NA_USA_UNIT.A | D7: units | F7: 7961.8115 | G7: 8114.1367 | H7: 8300.208 | I7: 8472.6797 | J7: 8615.5264 | K7: 8770.4619 | L7: 8906.6885 | M7: 9018.9092 | N7: 9150.0859 | O7: 9291.1201 | P7: 9427 | Q7: 9577.3438 | R7: 9730.7988 | S7: 9894.377 | T7: 10070.628 | U7: 10247.342 | V7: 10424.303 | W7: 10598.201 | X7: 10787.068 | Y7: 10971.893 | Z7: 11144.199 | AA7: 11313.209 | AB7: 11479.342 | AC7: 11674.663 | AD7: 11883.264 | AE7: 12083.06 | AF7: 12280.138 | AG7: 0.017
A8: Narrow Body Aircraft | B8: Aircraft Stock: Total: U.S.: Narrow Body: Alternative Transportation | C8: AEO.2025.ALTTRNP.STK_AIRC_NA_NBTR_NA_NA_USA_UNIT.A | D8: units | F8: 4534.3237 | G8: 4622.3657 | H8: 4731.4341 | I8: 4832.5688 | J8: 4915.7568 | K8: 5005.9546 | L8: 5084.6533 | M8: 5148.8311 | N8: 5224.1782 | O8: 5305.2598 | P8: 5383.1099 | Q8: 5469.4731 | R8: 5557.561 | S8: 5651.5591 | T8: 5752.9863 | U8: 5854.5542 | V8: 5956.1094 | W8: 6055.6904 | X8: 6164.0645 | Y8: 6269.8765 | Z8: 6368.0674 | AA8: 6464.1421 | AB8: 6558.3506 | AC8: 6669.813 | AD8: 6789.0283 | AE8: 6902.8228 | AF8: 7014.8237 | AG8: 0.017
A9: Wide Body Aircraft | B9: Aircraft Stock: Total: U.S.: Wide Body: Alternative Transportation | C9: AEO.2025.ALTTRNP.STK_AIRC_NA_WBE_NA_NA_USA_UNIT.A | D9: units | F9: 1427.4531 | G9: 1453.4775 | H9: 1483.8342 | I9: 1512.0002 | J9: 1536.448 | K9: 1563.0217 | L9: 1587.4502 | M9: 1608.8027 | N9: 1633.135 | O9: 1659.1536 | P9: 1684.7163 | Q9: 1712.5679 | R9: 1741.1058 | S9: 1771.3318 | T9: 1803.6108 | U9: 1836.2004 | V9: 1869.115 | W9: 1901.854 | X9: 1936.9888 | Y9: 1971.8098 | Z9: 2005.1033 | AA9: 2038.1897 | AB9: 2071.126 | AC9: 2108.541 | AD9: 2148.1633 | AE9: 2186.8159 | AF9: 2225.3818 | AG9: 0.017
A10: Regional Jets | B10: Aircraft Stock: Total: U.S.: Regional: Alternative Transportation | C10: AEO.2025.ALTTRNP.STK_AIRC_NA_REGJ_NA_NA_USA_UNIT.A | D10: units | F10: 2000.0345 | G10: 2038.2933 | H10: 2084.9392 | I10: 2128.1108 | J10: 2163.3215 | K10: 2201.4856 | L10: 2234.5852 | M10: 2261.2756 | N10: 2292.7725 | O10: 2326.707 | P10: 2359.1736 | Q10: 2395.3032 | R10: 2432.1321 | S10: 2471.4868 | T10: 2514.0305 | U10: 2556.5864 | V10: 2599.0776 | W10: 2640.6567 | X10: 2686.0154 | Y10: 2730.2063 | Z10: 2771.0278 | AA10: 2810.8772 | AB10: 2849.8652 | AC10: 2896.3093 | AD10: 2946.0725 | AE10: 2993.4209 | AF10: 3039.9329 | AG10: 0.016
A11: Canada | B11: Aircraft Stock: Total: Canada: Alternative Transportation | C11: AEO.2025.ALTTRNP.STK_AIRC_NA_NA_NA_NA_CAN_UNIT.A | D11: units | F11: 1045.515 | G11: 1086.1995 | H11: 1104.7103 | I11: 1122.7003 | J11: 1142.9819 | K11: 1163.1829 | L11: 1183.8596 | M11: 1205.4216 | N11: 1227.449 | O11: 1249.7292 | P11: 1272.2689 | Q11: 1295.0771 | R11: 1318.1355 | S11: 1341.4487 | T11: 1365.0251 | U11: 1388.9478 | V11: 1413.1947 | W11: 1437.8293 | X11: 1462.8436 | Y11: 1488.2216 | Z11: 1513.927 | AA11: 1539.9189 | AB11: 1566.2828 | AC11: 1593.059 | AD11: 1620.2205 | AE11: 1647.7993 | AF11: 1675.7305 | AG11: 0.018
A12: Narrow Body Aircraft | B12: Aircraft Stock: Total: Canada: Narrow Body: Alternative Transportation | C12: AEO.2025.ALTTRNP.STK_AIRC_NA_NBTR_NA_NA_CAN_UNIT.A | D12: units | F12: 420.19367 | G12: 425.83136 | H12: 432.16135 | I12: 438.43942 | J12: 445.81635 | K12: 453.26407 | L12: 461.75687 | M12: 470.56143 | N12: 479.45486 | O12: 488.50922 | P12: 497.71417 | Q12: 507.06262 | R12: 516.5368 | S12: 526.13245 | T12: 535.84699 | U12: 545.71399 | V12: 555.71594 | W12: 565.87915 | X12: 576.19659 | Y12: 586.65692 | Z12: 597.24078 | AA12: 607.92712 | AB12: 618.75446 | AC12: 629.73834 | AD12: 640.86383 | AE12: 652.14502 | AF12: 663.55017 | AG12: 0.018
A13: Wide Body Aircraft | B13: Aircraft Stock: Total: Canada: Wide Body: Alternative Transportation | C13: AEO.2025.ALTTRNP.STK_AIRC_NA_WBE_NA_NA_CAN_UNIT.A | D13: units | F13: 157.06796 | G13: 159.9415 | H13: 162.65036 | I13: 165.27896 | J13: 168.38463 | K13: 171.49913 | L13: 174.4761 | M13: 178.14674 | N13: 182.28209 | O13: 186.49304 | P13: 190.78061 | Q13: 195.14665 | R13: 199.59021 | S13: 204.108 | T13: 208.70079 | U13: 213.37495 | V13: 218.13171 | W13: 222.97687 | X13: 227.91153 | Y13: 232.93675 | Z13: 238.05083 | AA13: 243.25034 | AB13: 248.54253 | AC13: 253.93512 | AD13: 259.42844 | AE13: 265.02573 | AF13: 270.72223 | AG13: 0.021
A14: Regional Jets | B14: Aircraft Stock: Total: Canada: Regional: Alternative Transportation | C14: AEO.2025.ALTTRNP.STK_AIRC_NA_REGJ_NA_NA_CAN_UNIT.A | D14: units | F14: 468.25342 | G14: 500.42664 | H14: 509.89865 | I14: 518.98193 | J14: 528.78088 | K14: 538.41974 | L14: 547.62659 | M14: 556.7135 | N14: 565.71198 | O14: 574.72699 | P14: 583.77417 | Q14: 592.8678 | R14: 602.00842 | S14: 611.20825 | T14: 620.4773 | U14: 629.85876 | V14: 639.34705 | W14: 648.97327 | X14: 658.73547 | Y14: 668.62787 | Z14: 678.63531 | AA14: 688.74139 | AB14: 698.98584 | AC14: 709.3855 | AD14: 719.92816 | AE14: 730.62848 | AF14: 741.45807 | AG14: 0.018
A15: Mexico | B15: Aircraft Stock: Total: Mexico: Alternative Transportation | C15: AEO.2025.ALTTRNP.STK_AIRC_NA_NA_NA_NA_MXC_UNIT.A | D15: units | F15: 540.1615 | G15: 556.52325 | H15: 575.39532 | I15: 594.44739 | J15: 614.54077 | K15: 635.01807 | L15: 655.422 | M15: 676.27539 | N15: 697.64594 | O15: 719.57391 | P15: 742.06122 | Q15: 765.12726 | R15: 788.78986 | S15: 813.06592 | T15: 837.97253 | U15: 863.49707 | V15: 889.63281 | W15: 916.41718 | X15: 943.85809 | Y15: 971.95386 | Z15: 1000.7256 | AA15: 1030.1832 | AB15: 1060.3245 | AC15: 1091.16 | AD15: 1122.7195 | AE15: 1155.0024 | AF15: 1188.0142 | AG15: 0.031
A16: Narrow Body Aircraft | B16: Aircraft Stock: Total: Mexico: Narrow Body: Alternative Transportation | C16: AEO.2025.ALTTRNP.STK_AIRC_NA_NBTR_NA_NA_MXC_UNIT.A | D16: units | F16: 372.43515 | G16: 383.86862 | H16: 397.54465 | I16: 411.40888 | J16: 425.37628 | K16: 439.6015 | L16: 453.79144 | M16: 468.31793 | N16: 483.22195 | O16: 498.52759 | P16: 514.23358 | Q16: 530.35175 | R16: 546.89294 | S16: 563.86774 | T16: 581.28699 | U16: 599.14032 | V16: 617.42285 | W16: 636.16009 | X16: 655.35675 | Y16: 675.01086 | Z16: 695.1369 | AA16: 715.74127 | AB16: 736.82178 | AC16: 758.38556 | AD16: 780.45325 | AE16: 803.02423 | AF16: 826.10168 | AG16: 0.031
A17: Wide Body Aircraft | B17: Aircraft Stock: Total: Mexico: Wide Body: Alternative Transportation | C17: AEO.2025.ALTTRNP.STK_AIRC_NA_WBE_NA_NA_MXC_UNIT.A | D17: units | F17: 32.296688 | G17: 33.435856 | H17: 34.641533 | I17: 35.837578 | J17: 37.016834 | K17: 38.198772 | L17: 39.361656 | M17: 40.537773 | N17: 41.732506 | O17: 42.949036 | P17: 44.187912 | Q17: 45.450607 | R17: 46.738403 | S17: 48.052429 | T17: 49.393745 | U17: 50.761532 | V17: 52.156345 | W17: 53.579803 | X17: 55.032196 | Y17: 56.513191 | Z17: 58.023872 | AA17: 59.564514 | AB17: 61.134727 | AC17: 62.734871 | AD17: 64.366364 | AE17: 66.028862 | AF17: 67.722321 | AG17: 0.029
A18: Regional Jets | B18: Aircraft Stock: Total: Mexico: Regional: Alternative Transportation | C18: AEO.2025.ALTTRNP.STK_AIRC_NA_REGJ_NA_NA_MXC_UNIT.A | D18: units | F18: 135.42967 | G18: 139.2188 | H18: 143.20914 | I18: 147.2009 | J18: 152.14763 | K18: 157.21779 | L18: 162.26888 | M18: 167.41965 | N18: 172.69147 | O18: 178.09731 | P18: 183.63971 | Q18: 189.32489 | R18: 195.15851 | S18: 201.14572 | T18: 207.29181 | U18: 213.59525 | V18: 220.05362 | W18: 226.67729 | X18: 233.46919 | Y18: 240.42978 | Z18: 247.56483 | AA18: 254.87744 | AB18: 262.36798 | AC18: 270.03961 | AD18: 277.89984 | AE18: 285.94937 | AF18: 294.19025 | AG18: 0.03
... A74: Regional Jets | B74: Aircraft Stock: Total: World: Regional: Alternative Transportation | C74: AEO.2025.ALTTRNP.STK_AIRC_NA_REGJ_NA_NA_WRLD_UNIT.A | D74: units | F74: 6683.3315 | G74: 6872.4297 | H74: 7077.6719 | I74: 7275.396 | J74: 7468.8457 | K74: 7665.2983 | L74: 7855.5493 | M74: 8043.2485 | N74: 8239.0908 | O74: 8440.8867 | P74: 8644.3721 | Q74: 8854.4512 | R74: 9068.1016 | S74: 9287.6221 | T74: 9513.5752 | U74: 9743.0391 | V74: 9976.0107 | W74: 10211.86 | X74: 10455.14 | Y74: 10701.038 | Z74: 10947.061 | AA74: 11195.722 | AB74: 11446.907 | AC74: 11708.855 | AD74: 11977.27 | AE74: 12246.56 | AF74: 12518.561 | AG74: 0.024
A75: Aircraft Active Stock
A76: United States | B76: Aircraft Stock: Active: United States: Alternative Transportation | C76: AEO.2025.ALTTRNP.STK_AIRC_ACTV_NA_NA_NA_USA_UNIT.A | D76: units | F76: 6646.0996 | G76: 6787.3228 | H76: 6959.5649 | I76: 7119.3955 | J76: 7251.2363 | K76: 7393.5234 | L76: 7517.5342 | M76: 7618.918 | N76: 7737.2568 | O76: 7864.2241 | P76: 7986.041 | Q76: 8120.8369 | R76: 8258.1699 | S76: 8404.5098 | T76: 8562.2236 | U76: 8720.083 | V76: 8877.8691 | W76: 9032.5605 | X76: 9200.7852 | Y76: 9365.0215 | Z76: 9517.457 | AA76: 9666.5918 | AB76: 9812.8145 | AC76: 9985.6748 | AD76: 10170.506 | AE76: 10346.943 | AF76: 10520.595 | AG76: 0.018
A77: Narrow Body Aircraft | B77: Aircraft Stock: Active: U.S.: Narrow Body: Alternative Transportation | C77: AEO.2025.ALTTRNP.STK_AIRC_ACTV_NBTR_NA_NA_USA_UNIT.A | D77: units | F77: 4174.9043 | G77: 4262.7964 | H77: 4370.377 | I77: 4470.1128 | J77: 4552.0737 | K77: 4640.6099 | L77: 4717.627 | M77: 4780.2969 | N77: 4853.6816 | O77: 4932.5059 | P77: 5008.0464 | Q77: 5091.7778 | R77: 5177.0903 | S77: 5268.0747 | T77: 5366.2231 | U77: 5464.4341 | V77: 5562.5566 | W77: 5658.6851 | X77: 5763.3345 | Y77: 5865.4238 | Z77: 5960.0146 | AA77: 6052.4819 | AB77: 6143.0708 | AC77: 6250.4526 | AD77: 6365.3525 | AE77: 6474.9053 | AF77: 6582.6523 | AG77: 0.018
A78: Wide Body Aircraft | B78: Aircraft Stock: Active: U.S.: Wide Body: Alternative Transportation | C78: AEO.2025.ALTTRNP.STK_AIRC_ACTV_WBE_NA_NA_USA_UNIT.A | D78: units | F78: 645.4779 | G78: 661.09021 | H78: 679.2514 | I78: 696.315 | J78: 711.10754 | K78: 726.88391 | L78: 740.97394 | M78: 753.17523 | N78: 766.87543 | O78: 781.36987 | P78: 795.47552 | Q78: 810.75238 | R78: 826.30658 | S78: 842.70465 | T78: 860.15942 | U78: 877.69745 | V78: 895.32642 | W78: 912.76917 | X78: 931.48254 | Y78: 949.93524 | Z78: 967.4389 | AA78: 984.73907 | AB78: 1001.8687 | AC78: 1021.4485 | AD78: 1042.1921 | AE78: 1062.2957 | AF78: 1082.2571 | AG78: 0.02
A79: Regional Jets | B79: Aircraft Stock: Active: U.S.: Regional: Alternative Transportation | C79: AEO.2025.ALTTRNP.STK_AIRC_ACTV_REGJ_NA_NA_USA_UNIT.A | D79: units | F79: 1825.7172 | G79: 1863.436 | H79: 1909.9364 | I79: 1952.9679 | J79: 1988.0549 | K79: 2026.03 | L79: 2058.9329 | M79: 2085.4458 | N79: 2116.6997 | O79: 2150.3481 | P79: 2182.5188 | Q79: 2218.3066 | R79: 2254.7727 | S79: 2293.7307 | T79: 2335.8408 | U79: 2377.9517 | V79: 2419.9866 | W79: 2461.1062 | X79: 2505.9685 | Y79: 2549.6628 | Z79: 2590.0037 | AA79: 2629.3708 | AB79: 2667.875 | AC79: 2713.7737 | AD79: 2762.9604 | AE79: 2809.7419 | AF79: 2855.6853 | AG79: 0.017
A80: Canada | B80: Aircraft Stock: Active: Canada: Alternative Transportation | C80: AEO.2025.ALTTRNP.STK_AIRC_ACTV_NA_NA_NA_CAN_UNIT.A | D80: units | F80: 873.66583 | G80: 891.78436 | H80: 910.15338 | I80: 928.56018 | J80: 949.76843 | K80: 971.30713 | L80: 992.35303 | M80: 1013.6388 | N80: 1035.147 | O80: 1057.0162 | P80: 1079.2329 | Q80: 1101.7898 | R80: 1124.6567 | S80: 1147.8235 | T80: 1171.2878 | U80: 1195.1177 | V80: 1219.2852 | W80: 1243.8455 | X80: 1268.7885 | Y80: 1294.0977 | Z80: 1319.7375 | AA80: 1345.6681 | AB80: 1371.9661 | AC80: 1398.6697 | AD80: 1425.7544 | AE80: 1453.2494 | AF80: 1481.0938 | AG80: 0.021
A81: Narrow Body Aircraft | B81: Aircraft Stock: Active: Canada: Narrow Body: Alternative Transportation | C81: AEO.2025.ALTTRNP.STK_AIRC_ACTV_NBTR_NA_NA_CAN_UNIT.A | D81: units | F81: 388.28046 | G81: 395.8197 | H81: 403.58762 | I81: 411.37412 | J81: 420.32391 | K81: 429.40134 | L81: 438.25647 | M81: 447.1925 | N81: 456.203 | O81: 465.36081 | P81: 474.65741 | Q81: 484.08725 | R81: 493.634 | S81: 503.29434 | T81: 513.06665 | U81: 522.98474 | V81: 533.03192 | W81: 543.23499 | X81: 553.58752 | Y81: 564.07886 | Z81: 574.69019 | AA81: 585.401 | AB81: 596.24982 | AC81: 607.25226 | AD81: 618.39398 | AE81: 629.68909 | AF81: 641.10632 | AG81: 0.019
A82: Wide Body Aircraft | B82: Aircraft Stock: Active: Canada: Wide Body: Alternative Transportation | C82: AEO.2025.ALTTRNP.STK_AIRC_ACTV_WBE_NA_NA_CAN_UNIT.A | D82: units | F82: 140.13766 | G82: 143.70186 | H82: 147.15714 | I82: 150.61616 | J82: 154.62968 | K82: 158.72098 | L82: 162.73741 | M82: 166.82529 | N82: 170.98029 | O82: 175.21014 | P82: 179.51578 | Q82: 183.89903 | R82: 188.35898 | S82: 192.89217 | T82: 197.4993 | U82: 202.18636 | V82: 206.95464 | W82: 211.80978 | X82: 216.75305 | Y82: 221.78569 | Z82: 226.9062 | AA82: 232.11136 | AB82: 237.40808 | AC82: 242.80411 | AD82: 248.3 | AE82: 253.8989 | AF82: 259.59634 | AG82: 0.024
A83: Regional Jets | B83: Aircraft Stock: Active: Canada: Regional: Alternative Transportation | C83: AEO.2025.ALTTRNP.STK_AIRC_ACTV_REGJ_NA_NA_CAN_UNIT.A | D83: units | F83: 345.24774 | G83: 352.26282 | H83: 359.40863 | I83: 366.56988 | J83: 374.81482 | K83: 383.18484 | L83: 391.35916 | M83: 399.621 | N83: 407.96362 | O83: 416.44528 | P83: 425.05975 | Q83: 433.8035 | R83: 442.66376 | S83: 451.63693 | T83: 460.72195 | U83: 469.94659 | V83: 479.29861 | W83: 488.80066 | X83: 498.44791 | Y83: 508.23303 | Z83: 518.14117 | AA83: 528.15576 | AB83: 538.30817 | AC83: 548.61322 | AD83: 559.06043 | AE83: 569.66138 | AF83: 580.39117 | AG83: 0.02
A84: Mexico | B84: Aircraft Stock: Active: Mexico: Alternative Transportation | C84: AEO.2025.ALTTRNP.STK_AIRC_ACTV_NA_NA_NA_MXC_UNIT.A | D84: units | F84: 477.24744 | G84: 494.50125 | H84: 512.9198 | I84: 531.68073 | J84: 550.67419 | K84: 570.08154 | L84: 589.48267 | M84: 609.38702 | N84: 629.84228 | O84: 650.8764 | P84: 672.48499 | Q84: 694.68237 | R84: 717.48206 | S84: 740.89716 | T84: 764.94177 | U84: 789.60065 | V84: 814.86499 | W84: 840.77057 | X84: 867.32355 | Y84: 894.52118 | Z84: 922.38355 | AA84: 950.91962 | AB84: 980.12653 | AC84: 1010.0144 | AD84: 1040.6122 | AE84: 1071.9193 | AF84: 1103.9407 | AG84: 0.033
A85: Narrow Body Aircraft | B85: Aircraft Stock: Active: Mexico: Narrow Body: Alternative Transportation | C85: AEO.2025.ALTTRNP.STK_AIRC_ACTV_NBTR_NA_NA_MXC_UNIT.A | D85: units | F85: 341.38211 | G85: 353.66058 | H85: 366.75617 | I85: 380.09473 | J85: 393.60022 | K85: 407.39887 | L85: 421.1843 | M85: 435.32352 | N85: 449.84979 | O85: 464.78253 | P85: 480.11826 | Q85: 495.86697 | R85: 512.03802 | S85: 528.64062 | T85: 545.68445 | U85: 563.15826 | V85: 581.0564 | W85: 599.40369 | X85: 618.20422 | Y85: 637.45557 | Z85: 657.17175 | AA85: 677.35889 | AB85: 698.0144 | AC85: 719.14526 | AD85: 740.77179 | AE85: 762.89319 | AF85: 785.51245 | AG85: 0.033
A86: Wide Body Aircraft | B86: Aircraft Stock: Active: Mexico: Wide Body: Alternative Transportation | C86: AEO.2025.ALTTRNP.STK_AIRC_ACTV_WBE_NA_NA_MXC_UNIT.A | D86: units | F86: 26.209848 | G86: 27.106581 | H86: 28.051792 | I86: 29.014189 | J86: 29.989714 | K86: 30.985434 | L86: 31.973667 | M86: 32.984386 | N86: 34.019489 | O86: 35.080032 | P86: 36.165482 | Q86: 37.276417 | R86: 38.413368 | S86: 39.57682 | T86: 40.767315 | U86: 41.983589 | V86: 43.225822 | W86: 44.495335 | X86: 45.792141 | Y86: 47.115711 | Z86: 48.466942 | AA86: 49.845959 | AB86: 51.252251 | AC86: 52.686073 | AD86: 54.148758 | AE86: 55.639908 | AF86: 57.159416 | AG86: 0.03
A87: Regional Jets | B87: Aircraft Stock: Active: Mexico: Regional: Alternative Transportation | C87: AEO.2025.ALTTRNP.STK_AIRC_ACTV_REGJ_NA_NA_MXC_UNIT.A | D87: units | F87: 109.6555 | G87: 113.73409 | H87: 118.11187 | I87: 122.57181 | J87: 127.08423 | K87: 131.69725 | L87: 136.32472 | M87: 141.07912 | N87: 145.97299 | O87: 151.01384 | P87: 156.20126 | Q87: 161.539 | R87: 167.03065 | S87: 172.67969 | T87: 178.48996 | U87: 184.45879 | V87: 190.58279 | W87: 196.87151 | X87: 203.32722 | Y87: 209.94989 | Z87: 216.74484 | AA87: 223.7148 | AB87: 230.85988 | AC87: 238.18306 | AD87: 245.69163 | AE87: 253.38625 | AF87: 261.2688 | AG87: 0.034
... A143: Regional Jets | B143: Aircraft Stock: Active: World: Regional: Alternative Transportation | C143: AEO.2025.ALTTRNP.STK_AIRC_ACTV_REGJ_NA_NA_WRLD_UNIT.A | D143: units | F143: 5997.3208 | G143: 6162.1938 | H143: 6366.5259 | I143: 6563.937 | J143: 6756.6304 | K143: 6952.6118 | L143: 7142.6685 | M143: 7329.8457 | N143: 7525.1392 | O143: 7726.2046 | P143: 7929.1499 | Q143: 8138.8125 | R143: 8352.1768 | S143: 8571.0342 | T143: 8796.2881 | U143: 9025.1113 | V143: 9257.4639 | W143: 9492.7637 | X143: 9735.7031 | Y143: 9981.1523 | Z143: 10226.74 | AA143: 10474.75 | AB143: 10725.33 | AC143: 10986.657 | AD143: 11254.471 | AE143: 11523.215 | AF143: 11794.718 | AG143: 0.026
A144: Aircraft Parked Stock
A145: United States | B145: Aircraft Stock: Parked: United States: Alternative Transportation | C145: AEO.2025.ALTTRNP.STK_AIRC_ACTV_NA_PRKD_NA_USA_UNIT.A | D145: units | F145: 247 | G145: 247 | H145: 247 | I145: 247 | J145: 247 | K145: 247 | L145: 247 | M145: 247 | N145: 247 | O145: 247 | P145: 247 | Q145: 247 | R145: 247 | S145: 247 | T145: 247 | U145: 247 | V145: 247 | W145: 247 | X145: 247 | Y145: 247 | Z145: 247 | AA145: 247 | AB145: 247 | AC145: 247 | AD145: 247 | AE145: 247 | AF145: 247 | AG145: 0
A146: Narrow Body Aircraft | B146: Aircraft Stock: Parked: U.S.: Narrow Body: Alternative Transportation | C146: AEO.2025.ALTTRNP.STK_AIRC_ACTV_NBTR_PRKD_NA_USA_UNIT.A | D146: units | F146: 90 | G146: 90 | H146: 90 | I146: 90 | J146: 90 | K146: 90 | L146: 90 | M146: 90 | N146: 90 | O146: 90 | P146: 90 | Q146: 90 | R146: 90 | S146: 90 | T146: 90 | U146: 90 | V146: 90 | W146: 90 | X146: 90 | Y146: 90 | Z146: 90 | AA146: 90 | AB146: 90 | AC146: 90 | AD146: 90 | AE146: 90 | AF146: 90 | AG146: 0
A147: Wide Body Aircraft | B147: Aircraft Stock: Parked: U.S.: Wide Body: Alternative Transportation | C147: AEO.2025.ALTTRNP.STK_AIRC_ACTV_WBE_PRKD_NA_USA_UNIT.A | D147: units | F147: 22 | G147: 22 | H147: 22 | I147: 22 | J147: 22 | K147: 22 | L147: 22 | M147: 22 | N147: 22 | O147: 22 | P147: 22 | Q147: 22 | R147: 22 | S147: 22 | T147: 22 | U147: 22 | V147: 22 | W147: 22 | X147: 22 | Y147: 22 | Z147: 22 | AA147: 22 | AB147: 22 | AC147: 22 | AD147: 22 | AE147: 22 | AF147: 22 | AG147: 0
A148: Regional Jets | B148: Aircraft Stock: Parked: U.S.: Regional: Alternative Transportation | C148: AEO.2025.ALTTRNP.STK_AIRC_ACTV_REGJ_PRKD_NA_USA_UNIT.A | D148: units | F148: 135 | G148: 135 | H148: 135 | I148: 135 | J148: 135 | K148: 135 | L148: 135 | M148: 135 | N148: 135 | O148: 135 | P148: 135 | Q148: 135 | R148: 135 | S148: 135 | T148: 135 | U148: 135 | V148: 135 | W148: 135 | X148: 135 | Y148: 135 | Z148: 135 | AA148: 135 | AB148: 135 | AC148: 135 | AD148: 135 | AE148: 135 | AF148: 135 | AG148: 0
A149: Canada | B149: Aircraft Stock: Parked: Canada: Alternative Transportation | C149: AEO.2025.ALTTRNP.STK_AIRC_ACTV_NA_PRKD_NA_CAN_UNIT.A | D149: units | F149: 38.933678 | G149: 38.32901 | H149: 38.32901 | I149: 38.32901 | J149: 38.32901 | K149: 38.32901 | L149: 38.32901 | M149: 38.32901 | N149: 38.32901 | O149: 38.32901 | P149: 38.32901 | Q149: 38.32901 | R149: 38.32901 | S149: 38.32901 | T149: 38.32901 | U149: 38.32901 | V149: 38.32901 | W149: 38.32901 | X149: 38.32901 | Y149: 38.32901 | Z149: 38.32901 | AA149: 38.32901 | AB149: 38.32901 | AC149: 38.32901 | AD149: 38.32901 | AE149: 38.32901 | AF149: 38.32901 | AG149: -0.001
A150: Narrow Body Aircraft | B150: Aircraft Stock: Parked: Canada: Narrow Body: Alternative Transportation | C150: AEO.2025.ALTTRNP.STK_AIRC_ACTV_NBTR_PRKD_NA_CAN_UNIT.A | D150: units | F150: 9.144273 | G150: 8.569413 | H150: 8.569413 | I150: 8.569413 | J150: 8.569413 | K150: 8.569413 | L150: 8.569413 | M150: 8.569413 | N150: 8.569413 | O150: 8.569413 | P150: 8.569413 | Q150: 8.569413 | R150: 8.569413 | S150: 8.569413 | T150: 8.569413 | U150: 8.569413 | V150: 8.569413 | W150: 8.569413 | X150: 8.569413 | Y150: 8.569413 | Z150: 8.569413 | AA150: 8.569413 | AB150: 8.569413 | AC150: 8.569413 | AD150: 8.569413 | AE150: 8.569413 | AF150: 8.569413 | AG150: -0.002
...

Sheet AEO 2025 47
A1: Table 47. Air Travel Energy Use
A2: https://www.eia.gov/outlooks/aeo/data/browser/#/?id=57-AEO2025&cases=alttrnp&sourcekey=0
A3: Fri Dec 05 2025 14:51:22 GMT-0800 (Pacific Standard Time)
A4: Source: U.S. Energy Information Administration
B5: full name | C5: api key | D5: units | E5: 2023 | F5: 2024 | G5: 2025 | H5: 2026 | I5: 2027 | J5: 2028 | K5: 2029 | L5: 2030 | M5: 2031 | N5: 2032 | O5: 2033 | P5: 2034 | Q5: 2035 | R5: 2036 | S5: 2037 | T5: 2038 | U5: 2039 | V5: 2040 | W5: 2041 | X5: 2042 | Y5: 2043 | Z5: 2044 | AA5: 2045 | AB5: 2046 | AC5: 2047 | AD5: 2048 | AE5: 2049 | AF5: 2050 | AG5: Growth (2024-2050)
A6: Fuel Cost (1987 dollars per MMBtu) | B6: Air Travel: Fuel Cost: Alternative Transportation | C6: AEO.2025.ALTTRNP.PRCE_FUL_AIRT_NA_NA_NA_NA_87DLRPMBTU.A | D6: 1987 $/MMBtu | F6: 7.491065 | G6: 6.962784 | H6: 6.897642 | I6: 7.05128 | J6: 7.298514 | K6: 7.594258 | L6: 7.893686 | M6: 8.04295 | N6: 7.993549 | O6: 8.049672 | P6: 8.217111 | Q6: 8.285393 | R6: 8.268172 | S6: 8.371435 | T6: 8.447915 | U6: 8.533866 | V6: 8.599489 | W6: 8.639607 | X6: 8.654531 | Y6: 8.748531 | Z6: 8.813139 | AA6: 8.959833 | AB6: 9.050186 | AC6: 9.053982 | AD6: 9.101374 | AE6: 9.185375 | AF6: 9.302144 | AG6: 0.008
A7: Load Factor (fraction of seats filled)
A8: U.S. Domestic | B8: Air Travel: Load Factor: U.S. Domestic: Alternative Transportation | C8: AEO.2025.ALTTRNP.CAP_LDFAC_AIRT_DMS_NA_NA_NA_FRAC.A | D8: fraction | F8: 0.85 | G8: 0.85898 | H8: 0.859933 | I8: 0.860784 | J8: 0.861546 | K8: 0.862228 | L8: 0.862842 | M8: 0.863394 | N8: 0.863894 | O8: 0.864348 | P8: 0.864762 | Q8: 0.86514 | R8: 0.865488 | S8: 0.865808 | T8: 0.866103 | U8: 0.866376 | V8: 0.866672 | W8: 0.866967 | X8: 0.867263 | Y8: 0.867559 | Z8: 0.867855 | AA8: 0.868151 | AB8: 0.868447 | AC8: 0.868743 | AD8: 0.869039 | AE8: 0.869336 | AF8: 0.869632 | AG8: 0.001
A9: U.S. International | B9: Air Travel: Load Factor: U.S. International: Alternative Transportation | C9: AEO.2025.ALTTRNP.CAP_LDFAC_AIRT_INTA_NA_NA_NA_FRAC.A | D9: fraction | F9: 0.846 | G9: 0.85932 | H9: 0.860179 | I9: 0.86104 | J9: 0.861901 | K9: 0.862762 | L9: 0.863625 | M9: 0.864489 | N9: 0.865353 | O9: 0.866219 | P9: 0.867085 | Q9: 0.867952 | R9: 0.86882 | S9: 0.869689 | T9: 0.870558 | U9: 0.871429 | V9: 0.8723 | W9: 0.873173 | X9: 0.874046 | Y9: 0.87492 | Z9: 0.875795 | AA9: 0.876671 | AB9: 0.877547 | AC9: 0.878425 | AD9: 0.879303 | AE9: 0.880183 | AF9: 0.881063 | AG9: 0.002
A10: Driver Variables
A11: Population (millions)
A12: United States | B12: Air Travel: Drivers: Population: U.S.: Alternative Transportation | C12: AEO.2025.ALTTRNP.ECI_POP_NA_NA_NA_NA_USA_MILL.A | D12: millions | F12: 342.00198 | G12: 344.85077 | H12: 346.96423 | I12: 348.43741 | J12: 349.87805 | K12: 351.28119 | L12: 352.64179 | M12: 353.9574 | N12: 355.23047 | O12: 356.45853 | P12: 357.63406 | Q12: 358.73593 | R12: 359.77283 | S12: 360.75125 | T12: 361.67264 | U12: 362.53564 | V12: 363.34354 | W12: 364.09573 | X12: 364.79132 | Y12: 365.43613 | Z12: 366.03445 | AA12: 366.59067 | AB12: 367.10648 | AC12: 367.58792 | AD12: 368.03946 | AE12: 368.46582 | AF12: 368.87057 | AG12: 0.003
A13: Canada | B13: Air Travel: Drivers: Population: Canada: Alternative Transportation | C13: AEO.2025.ALTTRNP.ECI_POP_NA_NA_NA_NA_CAN_MILL.A | D13: millions | F13: 41.11554 | G13: 41.536888 | H13: 41.87455 | I13: 42.188862 | J13: 42.649399 | K13: 43.106659 | L13: 43.563068 | M13: 44.018311 | N13: 44.470509 | O13: 44.918892 | P13: 45.363789 | Q13: 45.805729 | R13: 46.244751 | S13: 46.679371 | T13: 47.1096 | U13: 47.535721 | V13: 47.958038 | W13: 48.377232 | X13: 48.793659 | Y13: 49.207779 | Z13: 49.619549 | AA13: 50.028412 | AB13: 50.434639 | AC13: 50.839611 | AD13: 51.243679 | AE13: 51.646778 | AF13: 52.048401 | AG13: 0.009
A14: Mexico | B14: Air Travel: Drivers: Population: Mexico: Alternative Transportation | C14: AEO.2025.ALTTRNP.ECI_POP_NA_NA_NA_NA_MAOOAS_MILL.A | D14: millions | F14: 130.86099 | G14: 131.9469 | H14: 132.9977 | I14: 134.0177 | J14: 135.0087 | K14: 135.9709 | L14: 136.9048 | M14: 137.8111 | N14: 138.6902 | O14: 139.5421 | P14: 140.362 | Q14: 141.1508 | R14: 141.9092 | S14: 142.6375 | T14: 143.3363 | U14: 143.99831 | V14: 144.6243 | W14: 145.2178 | X14: 145.7775 | Y14: 146.3 | Z14: 146.7877 | AA14: 147.2401 | AB14: 147.6542 | AC14: 148.0302 | AD14: 148.37219 | AE14: 148.6779 | AF14: 148.9463 | AG14: 0.005
A15: Western Europe | B15: Air Travel: Drivers: Population: Western Europe: Alternative Transportation | C15: AEO.2025.ALTTRNP.ECI_POP_NA_NA_NA_NA_OCDEU_MILL.A | D15: millions | F15: 638.29211 | G15: 638.9436 | H15: 639.36072 | I15: 639.66699 | J15: 639.91583 | K15: 640.17175 | L15: 640.43732 | M15: 640.70172 | N15: 640.95203 | O15: 641.18213 | P15: 641.40845 | Q15: 641.61481 | R15: 641.79181 | S15: 641.93884 | T15: 642.04028 | U15: 642.09296 | V15: 642.09369 | W15: 642.03827 | X15: 641.92572 | Y15: 641.74835 | Z15: 641.50354 | AA15: 641.18671 | AB15: 640.79913 | AC15: 640.33795 | AD15: 639.78851 | AE15: 639.146 | AF15: 638.40759 | AG15: 0
A16: Japan | B16: Air Travel: Drivers: Population: Japan: Alternative Transportation | C16: AEO.2025.ALTTRNP.ECI_POP_NA_NA_NA_NA_JPN_MILL.A | D16: millions | F16: 123.753 | G16: 123.1035 | H16: 122.4278 | I16: 121.7324 | J16: 121.0243 | K16: 120.3081 | L16: 119.5842 | M16: 118.8521 | N16: 118.1141 | O16: 117.3725 | P16: 116.6268 | Q16: 115.8761 | R16: 115.1255 | S16: 114.3774 | T16: 113.6336 | U16: 112.8945 | V16: 112.1583 | W16: 111.4225 | X16: 110.6923 | Y16: 109.9724 | Z16: 109.2595 | AA16: 108.552 | AB16: 107.8506 | AC16: 107.158 | AD16: 106.4743 | AE16: 105.7969 | AF16: 105.1231 | AG16: -0.006
A17: Australia and New Zealand | B17: Air Travel: Drivers: Population: Australia and New Zealand: Alternative Transportation | C17: AEO.2025.ALTTRNP.ECI_POP_NA_NA_NA_NA_AUNZ_MILL.A | D17: millions | F17: 32.57275 | G17: 32.958988 | H17: 33.324001 | I17: 33.701229 | J17: 34.10144 | K17: 34.498112 | L17: 34.888981 | M17: 35.273869 | N17: 35.652161 | O17: 36.023972 | P17: 36.38942 | Q17: 36.748821 | R17: 37.102631 | S17: 37.450699 | T17: 37.79353 | U17: 38.131569 | V17: 38.464809 | W17: 38.793442 | X17: 39.117519 | Y17: 39.437038 | Z17: 39.751869 | AA17: 40.061821 | AB17: 40.366779 | AC17: 40.666439 | AD17: 40.9608 | AE17: 41.249821 | AF17: 41.533428 | AG17: 0.009
A18: South Korea | B18: Air Travel: Drivers: Population: South Korea: Alternative Transportation | C18: AEO.2025.ALTTRNP.ECI_POP_NA_NA_NA_NA_SOK_MILL.A | D18: millions | F18: 51.71759 | G18: 51.66703 | H18: 51.600391 | I18: 51.518848 | J18: 51.423431 | K18: 51.314018 | L18: 51.18858 | M18: 51.04818 | N18: 50.891289 | O18: 50.714298 | P18: 50.516811 | Q18: 50.300732 | R18: 50.06654 | S18: 49.813431 | T18: 49.541161 | U18: 49.251888 | V18: 48.948681 | W18: 48.630428 | X18: 48.29974 | Y18: 47.959042 | Z18: 47.603371 | AA18: 47.232948 | AB18: 46.850899 | AC18: 46.452061 | AD18: 46.033798 | AE18: 45.597301 | AF18: 45.143131 | AG18: -0.005
A19: Russia | B19: Air Travel: Drivers: Population: Russia: Alternative Transportation | C19: AEO.2025.ALTTRNP.ECI_POP_NA_NA_NA_NA_RUS_MILL.A | D19: millions | F19: 144.8204 | G19: 143.99741 | H19: 143.39439 | I19: 143.0441 | J19: 142.6698 | K19: 142.2851 | L19: 141.8894 | M19: 141.47549 | N19: 141.06039 | O19: 140.6646 | P19: 140.28081 | Q19: 139.9097 | R19: 139.5515 | S19: 139.20489 | T19: 138.8768 | U19: 138.5674 | V19: 138.2818 | W19: 138.02181 | X19: 137.78281 | Y19: 137.55791 | Z19: 137.345 | AA19: 137.15221 | AB19: 136.97369 | AC19: 136.7894 | AD19: 136.586 | AE19: 136.36839 | AF19: 136.1328 | AG19: -0.002
A20: Eastern Europe and Eurasia | B20: Air Travel: Drivers: Population: Eastern Europe and Eurasia: Alternative Transportation | C20: AEO.2025.ALTTRNP.ECI_POP_NA_NA_NA_NA_OEUAS_MILL.A | D20: millions | F20: 149.55203 | G20: 151.9012 | H20: 153.64238 | I20: 154.55901 | J20: 155.43941 | K20: 156.31045 | L20: 157.19643 | M20: 158.05125 | N20: 158.90607 | O20: 159.74928 | P20: 160.57231 | Q20: 161.38737 | R20: 162.21719 | S20: 163.06296 | T20: 163.90462 | U20: 164.75026 | V20: 165.59624 | W20: 166.43773 | X20: 167.2859 | Y20: 168.13182 | Z20: 168.96674 | AA20: 169.78477 | AB20: 170.56317 | AC20: 171.30804 | AD20: 172.02151 | AE20: 172.71736 | AF20: 173.40846 | AG20: 0.006
A21: China | B21: Air Travel: Drivers: Population: China: Alternative Transportation | C21: AEO.2025.ALTTRNP.ECI_POP_NA_NA_NA_NA_CHN_MILL.A | D21: millions | F21: 1419.321 | G21: 1416.0959 | H21: 1412.9139 | I21: 1409.679 | J21: 1406.137 | K21: 1402.283 | L21: 1398.1541 | M21: 1393.749 | N21: 1389.0601 | O21: 1384.097 | P21: 1378.877 | Q21: 1373.428 | R21: 1367.743 | S21: 1361.83 | T21: 1355.723 | U21: 1349.395 | V21: 1342.817 | W21: 1335.99 | X21: 1328.9091 | Y21: 1321.5909 | Z21: 1314.016 | AA21: 1306.114 | AB21: 1297.818 | AC21: 1289.12 | AD21: 1279.993 | AE21: 1270.381 | AF21: 1260.2889 | AG21: -0.005
A22: India | B22: Air Travel: Drivers: Population: India: Alternative Transportation | C22: AEO.2025.ALTTRNP.ECI_POP_NA_NA_NA_NA_IND_MILL.A | D22: millions | F22: 1450.936 | G22: 1463.866 | H22: 1476.626 | I22: 1489.165 | J22: 1501.433 | K22: 1513.424 | L22: 1525.139 | M22: 1536.541 | N22: 1547.6071 | O22: 1558.324 | P22: 1568.688 | Q22: 1578.6949 | R22: 1588.325 | S22: 1597.537 | T22: 1606.301 | U22: 1614.639 | V22: 1622.58 | W22: 1630.119 | X22: 1637.235 | Y22: 1643.915 | Z22: 1650.187 | AA22: 1656.068 | AB22: 1661.548 | AC22: 1666.6281 | AD22: 1671.3101 | AE22: 1675.62 | AF22: 1679.589 | AG22: 0.006
A23: Other Asia Pacific | B23: Air Travel: Drivers: Population: Other Asia Pacific: Alternative Transportation | C23: AEO.2025.ALTTRNP.ECI_POP_NA_NA_NA_NA_ONCDAS_MILL.A | D23: millions | F23: 1291.4583 | G23: 1304.0575 | H23: 1316.5952 | I23: 1329.1713 | J23: 1341.8307 | K23: 1354.4788 | L23: 1367.0858 | M23: 1379.6105 | N23: 1391.9745 | O23: 1404.1891 | P23: 1416.1998 | Q23: 1427.9586 | R23: 1439.533 | S23: 1450.932 | T23: 1462.1069 | U23: 1473.066 | V23: 1483.7819 | W23: 1494.2134 | X23: 1504.3381 | Y23: 1514.1906 | Z23: 1523.7782 | AA23: 1533.0756 | AB23: 1542.127 | AC23: 1550.8334 | AD23: 1559.179 | AE23: 1567.2681 | AF23: 1575.0332 | AG23: 0.008
... A27: Other Americas | B27: Air Travel: Drivers: Population: Other Americas: Alternative Transportation | C27: AEO.2025.ALTTRNP.ECI_POP_NA_NA_NA_NA_ONOAS_MILL.A | D27: millions | F27: 320.53473 | G27: 323.0799 | H27: 325.5528 | I27: 327.96841 | J27: 330.324 | K27: 332.61664 | L27: 334.85278 | M27: 337.03165 | N27: 339.14975 | O27: 341.20331 | P27: 343.19653 | Q27: 345.12198 | R27: 346.96936 | S27: 348.73593 | T27: 350.42746 | U27: 352.04385 | V27: 353.57599 | W27: 355.02155 | X27: 356.38486 | Y27: 357.66562 | Z27: 358.8631 | AA27: 359.98111 | AB27: 361.01959 | AC27: 361.98383 | AD27: 362.87286 | AE27: 363.68106 | AF27: 364.41592 | AG27: 0.005
A28: Travel Demand
A29: Revenue Passenger Miles (billion miles)
A30: Domestic
A31: United States | B31: Air Travel: Travel Demand: Revenue Passenger Miles: Domestic: U.S.: Alternative Transportation | C31: AEO.2025.ALTTRNP.ECI_RPM_AIRT_DMS_NA_NA_USA_BLNMLS.A | D31: billion miles | F31: 769.0744 | G31: 784.82141 | H31: 804.30225 | I31: 822.31329 | J31: 836.94464 | K31: 852.79474 | L31: 867.11853 | M31: 878.67957 | N31: 892.21368 | O31: 906.729 | P31: 920.58386 | Q31: 935.94891 | R31: 951.57721 | S31: 968.24323 | T31: 986.23108 | U31: 1004.2006 | V31: 1022.1676 | W31: 1039.7505 | X31: 1058.9343 | Y31: 1077.6267 | Z31: 1094.8949 | AA31: 1111.7531 | AB31: 1128.2476 | AC31: 1147.9022 | AD31: 1168.9659 | AE31: 1189.0094 | AF31: 1208.7004 | AG31: 0.018
A32: Canada | B32: Air Travel: Travel Demand: Revenue Passenger Miles: Domestic: Canada: Alternative Transportation | C32: AEO.2025.ALTTRNP.ECI_RPM_AIRT_DMS_NA_NA_CAN_BLNMLS.A | D32: billion miles | F32: 37.600502 | G32: 38.178329 | H32: 38.814651 | I32: 39.45327 | J32: 40.180599 | K32: 40.9147 | L32: 41.655926 | M32: 42.395454 | N32: 43.133369 | O32: 43.88018 | P32: 44.634605 | Q32: 45.395569 | R32: 46.160698 | S32: 46.930233 | T32: 47.703876 | U32: 48.486118 | V32: 49.276463 | W32: 50.077091 | X32: 50.886642 | Y32: 51.703285 | Z32: 52.524178 | AA32: 53.346607 | AB32: 54.175564 | AC32: 55.012207 | AD32: 55.854134 | AE32: 56.703068 | AF32: 57.554737 | AG32: 0.017
A33: Mexico | B33: Air Travel: Travel Demand: Revenue Passenger Miles: Domestic: Mexico: Alternative Transportation | C33: AEO.2025.ALTTRNP.ECI_RPM_AIRT_DMS_NA_NA_MAOOAS_BLNMLS.A | D33: billion miles | F33: 44.937325 | G33: 46.664017 | H33: 48.52676 | I33: 50.424767 | J33: 52.343803 | K33: 54.30658 | L33: 56.32291 | M33: 58.395287 | N33: 60.529984 | O33: 62.730732 | P33: 64.997902 | Q33: 67.333366 | R33: 69.738976 | S33: 72.216545 | T33: 74.767998 | U33: 77.392761 | V33: 80.092697 | W33: 82.870613 | X33: 85.727814 | Y33: 88.664772 | Z33: 91.684021 | AA33: 94.787086 | AB33: 97.974487 | AC33: 101.24791 | AD33: 104.61065 | AE33: 108.06347 | AF33: 111.60763 | AG33: 0.036
A34: Western Europe | B34: Air Travel: Travel Demand: Revenue Passenger Miles: Domestic: Western Europe: Alternative Transportation | C34: AEO.2025.ALTTRNP.ECI_RPM_AIRT_DMS_NA_NA_OCDEU_BLNMLS.A | D34: billion miles | F34: 695.7085 | G34: 711.492 | H34: 727.84601 | I34: 744.4021 | J34: 761.14691 | K34: 778.06952 | L34: 795.17676 | M34: 812.43671 | N34: 829.91644 | O34: 847.72449 | P34: 865.89209 | Q34: 884.39624 | R34: 903.27612 | S34: 922.48926 | T34: 942.00446 | U34: 961.84662 | V34: 982.01569 | W34: 1002.5041 | X34: 1023.3381 | Y34: 1044.5065 | Z34: 1065.9882 | AA34: 1087.7701 | AB34: 1109.8762 | AC34: 1132.3049 | AD34: 1155.0436 | AE34: 1178.1086 | AF34: 1201.5139 | AG34: 0.021
A35: Japan | B35: Air Travel: Travel Demand: Revenue Passenger Miles: Domestic: Japan: Alternative Transportation | C35: AEO.2025.ALTTRNP.ECI_RPM_AIRT_DMS_NA_NA_JPN_BLNMLS.A | D35: billion miles | F35: 61.775593 | G35: 62.381695 | H35: 62.855656 | I35: 63.321266 | J35: 63.739643 | K35: 64.132576 | L35: 64.504501 | M35: 64.848396 | N35: 65.182808 | O35: 65.504845 | P35: 65.807434 | Q35: 66.092278 | R35: 66.364037 | S35: 66.631622 | T35: 66.89563 | U35: 67.155266 | V35: 67.418846 | W35: 67.688339 | X35: 67.966217 | Y35: 68.255569 | Z35: 68.556664 | AA35: 68.875145 | AB35: 69.210426 | AC35: 69.559624 | AD35: 69.9188 | AE35: 70.284042 | AF35: 70.661758 | AG35: 0.005
A36: Australia and New Zealand | B36: Air Travel: Travel Demand: Revenue Passenger Miles: Domestic: Australia and New Zealand: Alternative Transportation | C36: AEO.2025.ALTTRNP.ECI_RPM_AIRT_DMS_NA_NA_AUNZ_BLNMLS.A | D36: billion miles | F36: 59.104053 | G36: 60.491245 | H36: 62.26804 | I36: 64.084373 | J36: 65.934128 | K36: 67.765549 | L36: 69.591827 | M36: 71.438934 | N36: 73.293076 | O36: 75.14917 | P36: 77.013268 | Q36: 78.860535 | R36: 80.713531 | S36: 82.578789 | T36: 84.400665 | U36: 86.218666 | V36: 88.039467 | W36: 89.874641 | X36: 91.723427 | Y36: 93.586189 | Z36: 95.459198 | AA36: 97.339409 | AB36: 99.226044 | AC36: 101.11935 | AD36: 103.02018 | AE36: 104.92896 | AF36: 106.8463 | AG36: 0.023
A37: South Korea | B37: Air Travel: Travel Demand: Revenue Passenger Miles: Domestic: South Korea: Alternative Transportation | C37: AEO.2025.ALTTRNP.ECI_RPM_AIRT_DMS_NA_NA_SOK_BLNMLS.A | D37: billion miles | F37: 8.896751 | G37: 9.059666 | H37: 9.254403 | I37: 9.439147 | J37: 9.616467 | K37: 9.78886 | L37: 9.958011 | M37: 10.118227 | N37: 10.269077 | O37: 10.411737 | P37: 10.545367 | Q37: 10.670194 | R37: 10.79082 | S37: 10.900813 | T37: 11.004025 | U37: 11.099137 | V37: 11.190952 | W37: 11.280606 | X37: 11.364059 | Y37: 11.438848 | Z37: 11.500485 | AA37: 11.546016 | AB37: 11.579747 | AC37: 11.604859 | AD37: 11.625552 | AE37: 11.645999 | AF37: 11.664306 | AG37: 0.01
A38: Russia | B38: Air Travel: Travel Demand: Revenue Passenger Miles: Domestic: Russia: Alternative Transportation | C38: AEO.2025.ALTTRNP.ECI_RPM_AIRT_DMS_NA_NA_RUS_BLNMLS.A | D38: billion miles | F38: 79.585274 | G38: 80.866997 | H38: 81.715607 | I38: 82.199478 | J38: 83.152344 | K38: 84.156509 | L38: 85.16629 | M38: 86.18206 | N38: 87.230774 | O38: 88.321007 | P38: 89.456703 | Q38: 90.623169 | R38: 91.766724 | S38: 92.878967 | T38: 93.975449 | U38: 95.062119 | V38: 96.155243 | W38: 97.370361 | X38: 98.666924 | Y38: 99.982994 | Z38: 101.3106 | AA38: 102.64252 | AB38: 104.00653 | AC38: 105.41545 | AD38: 106.80108 | AE38: 108.16437 | AF38: 109.53309 | AG38: 0.012
A39: Eastern Europe and Eurasia | B39: Air Travel: Travel Demand: Revenue Passenger Miles: Domestic: Eastern Europe and Eurasia: Alternative Transportation | C39: AEO.2025.ALTTRNP.ECI_RPM_AIRT_DMS_NA_NA_OEUAS_BLNMLS.A | D39: billion miles | F39: 10.941443 | G39: 11.379101 | H39: 11.839906 | I39: 12.262307 | J39: 12.709543 | K39: 13.170254 | L39: 13.621606 | M39: 14.066698 | N39: 14.516427 | O39: 14.975104 | P39: 15.443627 | Q39: 15.927789 | R39: 16.429544 | S39: 16.944839 | T39: 17.472025 | U39: 18.011406 | V39: 18.559582 | W39: 19.116617 | X39: 19.688261 | Y39: 20.275387 | Z39: 20.877848 | AA39: 21.49608 | AB39: 22.1259 | AC39: 22.769482 | AD39: 23.426699 | AE39: 24.098751 | AF39: 24.786325 | AG39: 0.032
A40: China | B40: Air Travel: Travel Demand: Revenue Passenger Miles: Domestic: China: Alternative Transportation | C40: AEO.2025.ALTTRNP.ECI_RPM_AIRT_DMS_NA_NA_CHN_BLNMLS.A | D40: billion miles | F40: 559.27313 | G40: 594.13141 | H40: 627.76331 | I40: 661.1781 | J40: 695.78857 | K40: 731.95825 | L40: 769.54248 | M40: 808.29694 | N40: 848.34277 | O40: 889.39392 | P40: 931.4057 | Q40: 974.31799 | R40: 1017.7333 | S40: 1061.8749 | T40: 1106.921 | U40: 1152.8358 | V40: 1199.5791 | W40: 1247.1012 | X40: 1295.3479 | Y40: 1344.2566 | Z40: 1393.769 | AA40: 1443.848 | AB40: 1494.4528 | AC40: 1545.5237 | AD40: 1596.9993 | AE40: 1648.838 | AF40: 1700.9683 | AG40: 0.044
A41: India | B41: Air Travel: Travel Demand: Revenue Passenger Miles: Domestic: India: Alternative Transportation | C41: AEO.2025.ALTTRNP.ECI_RPM_AIRT_DMS_NA_NA_IND_BLNMLS.A | D41: billion miles | F41: 92.931549 | G41: 101.3761 | H41: 110.33313 | I41: 120.11643 | J41: 130.41547 | K41: 141.29529 | L41: 152.72458 | M41: 164.62189 | N41: 176.90376 | O41: 189.48221 | P41: 202.3152 | Q41: 215.34853 | R41: 228.49815 | S41: 241.86232 | T41: 255.35088 | U41: 269.00149 | V41: 282.92517 | W41: 297.09122 | X41: 311.47659 | Y41: 326.04114 | Z41: 340.75421 | AA41: 355.61545 | AB41: 370.64233 | AC41: 385.80408 | AD41: 401.07306 | AE41: 416.42178 | AF41: 431.8197 | AG41: 0.061
A42: Other Asia Pacific | B42: Air Travel: Travel Demand: Revenue Passenger Miles: Domestic: Other Asia Pacific: Alternative Transportation | C42: AEO.2025.ALTTRNP.ECI_RPM_AIRT_DMS_NA_NA_ONCDAS_BLNMLS.A | D42: billion miles | F42: 207.68857 | G42: 218.51015 | H42: 230.73056 | I42: 243.18684 | J42: 255.80749 | K42: 268.62222 | L42: 281.77997 | M42: 295.35715 | N42: 309.3494 | O42: 323.70145 | P42: 338.353 | Q42: 353.25491 | R42: 368.41959 | S42: 383.78339 | T42: 399.58884 | U42: 415.85287 | V42: 432.55576 | W42: 449.64737 | X42: 467.16397 | Y42: 485.0939 | Z42: 503.41666 | AA42: 522.11938 | AB42: 541.1651 | AC42: 560.50476 | AD42: 580.16614 | AE42: 600.20392 | AF42: 620.71033 | AG42: 0.043
... A47: Total World Domestic | B47: Air Travel: Travel Demand: Revenue Passenger Miles: Domestic: World: Alternative Transportation | C47: AEO.2025.ALTTRNP.ECI_RPM_AIRT_DMS_NA_NA_WRLD_BLNMLS.A | D47: billion miles | F47: 2861.9478 | G47: 2963.04 | H47: 3070.0647 | I47: 3175.623 | J47: 3280.3511 | K47: 3388.8789 | L47: 3498.4436 | M47: 3607.6426 | N47: 3721.2859 | O47: 3838.1045 | P47: 3956.3628 | Q47: 4078.0508 | R47: 4201.4858 | S47: 4327.668 | T47: 4457.1421 | U47: 4588.6489 | V47: 4722.3101 | W47: 4857.7559 | X47: 4996.9341 | Y47: 5137.5679 | Z47: 5278.5747 | AA47: 5420.8921 | AB47: 5564.561 | AC47: 5713.002 | AD47: 5864.3223 | AE47: 6016.1069 | AF47: 6169.0723 | AG47: 0.03
...

Sheet AEO 2025 39
B1: full name | C1: api key | D1: units | E1: 2023 | F1: 2024 | G1: 2025 | H1: 2026 | I1: 2027 | J1: 2028 | K1: 2029 | L1: 2030 | M1: 2031 | N1: 2032 | O1: 2033 | P1: 2034 | Q1: 2035 | R1: 2036 | S1: 2037 | T1: 2038 | U1: 2039 | V1: 2040 | W1: 2041 | X1: 2042 | Y1: 2043 | Z1: 2044 | AA1: 2045 | AB1: 2046 | AC1: 2047 | AD1: 2048 | AE1: 2049 | AF1: 2050 | AG1: Growth (2024-2050)
A10: Table 39. Light-Duty Vehicle Stock by Technology Type
A11: https://www.eia.gov/outlooks/aeo/data/browser/#/?id=49-AEO2025&cases=alttrnp&sourcekey=0
A12: Fri Dec 05 2025 14:49:43 GMT-0800 (Pacific Standard Time)
A13: Source: U.S. Energy Information Administration
B14: full name | C14: api key | D14: units | E14: 2023 | F14: 2024 | G14: 2025 | H14: 2026 | I14: 2027 | J14: 2028 | K14: 2029 | L14: 2030 | M14: 2031 | N14: 2032 | O14: 2033 | P14: 2034 | Q14: 2035 | R14: 2036 | S14: 2037 | T14: 2038 | U14: 2039 | V14: 2040 | W14: 2041 | X14: 2042 | Y14: 2043 | Z14: 2044 | AA14: 2045 | AB14: 2046 | AC14: 2047 | AD14: 2048 | AE14: 2049 | AF14: 2050 | AG14: Growth (2024-2050)
A15: Car Stock
A16: Conventional Cars
A17: Gasoline ICE Vehicles | B17: Light-Duty Vehicle Stock: Conventional Cars: Gasoline: Alternative Transportation | C17: AEO.2025.ALTTRNP.ECI_STK_TRN_CAR_GSL_NA_NA_MILL.A | D17: millions | F17: 108.74242 | G17: 106.02588 | H17: 103.03122 | I17: 99.755089 | J17: 96.325905 | K17: 92.986259 | L17: 89.637253 | M17: 86.243225 | N17: 82.736351 | O17: 79.426987 | P17: 76.303139 | Q17: 73.195068 | R17: 70.23175 | S17: 67.489212 | T17: 64.999939 | U17: 62.70229 | V17: 60.584476 | W17: 58.661816 | X17: 56.918571 | Y17: 55.322689 | Z17: 53.84594 | AA17: 52.475899 | AB17: 51.17017 | AC17: 49.920616 | AD17: 48.72295 | AE17: 47.584213 | AF17: 46.522465 | AG17: -0.032
A18: TDI Diesel ICE | B18: Light-Duty Vehicle Stock: Conventional Cars: TDI Diesel: Alternative Transportation | C18: AEO.2025.ALTTRNP.ECI_STK_TRN_CAR_TDS_NA_NA_MILL.A | D18: millions | F18: 0.482061 | G18: 0.448589 | H18: 0.415826 | I18: 0.383631 | J18: 0.351762 | K18: 0.32012 | L18: 0.289235 | M18: 0.259841 | N18: 0.231577 | O18: 0.204986 | P18: 0.180605 | Q18: 0.158948 | R18: 0.140461 | S18: 0.125146 | T18: 0.11297 | U18: 0.103879 | V18: 0.096941 | W18: 0.090629 | X18: 0.084924 | Y18: 0.079743 | Z18: 0.074916 | AA18: 0.070396 | AB18: 0.066163 | AC18: 0.062198 | AD18: 0.058482 | AE18: 0.054999 | AF18: 0.051733 | AG18: -0.082
A19: Total Conventional Cars | B19: Light-Duty Vehicle Stock: Conventional Cars: Total: Alternative Transportation | C19: AEO.2025.ALTTRNP.ECI_STK_TRN_CAR_CNV_NA_NA_MILL.A | D19: millions | F19: 109.22448 | G19: 106.47446 | H19: 103.44704 | I19: 100.13872 | J19: 96.677666 | K19: 93.306381 | L19: 89.926491 | M19: 86.503067 | N19: 82.967926 | O19: 79.631973 | P19: 76.483742 | Q19: 73.354019 | R19: 70.372208 | S19: 67.614357 | T19: 65.112907 | U19: 62.806168 | V19: 60.681419 | W19: 58.752445 | X19: 57.003494 | Y19: 55.402431 | Z19: 53.920856 | AA19: 52.546295 | AB19: 51.236332 | AC19: 49.982815 | AD19: 48.781433 | AE19: 47.639214 | AF19: 46.574196 | AG19: -0.032
A20: Alternative-Fuel Cars
A21: Ethanol-Flex Fuel ICE | B21: Light-Duty Vehicle Stock: Alternative-Fuel Cars: Ethanol-Flex Fuel ICE: Alternative Transportation | C21: AEO.2025.ALTTRNP.ECI_STK_TRN_CAR_EFFI_NA_NA_MILL.A | D21: millions | F21: 3.77801 | G21: 3.54341 | H21: 3.295883 | I21: 3.036592 | J21: 2.769824 | K21: 2.500095 | L21: 2.23284 | M21: 1.975712 | N21: 1.734107 | O21: 1.513086 | P21: 1.313327 | Q21: 1.137563 | R21: 0.990114 | S21: 0.871486 | T21: 0.774501 | U21: 0.698651 | V21: 0.640099 | W21: 0.591817 | X21: 0.550913 | Y21: 0.515667 | Z21: 0.485515 | AA21: 0.458421 | AB21: 0.432894 | AC21: 0.408849 | AD21: 0.386237 | AE21: 0.364965 | AF21: 0.344932 | AG21: -0.088
A22: 100-Mile Electric Vehicle | B22: Light-Duty Vehicle Stock: Alternative-Fuel Cars: 100-Mile Electric Vehicle: Alternative Transportation | C22: AEO.2025.ALTTRNP.ECI_STK_TRN_CAR_100MIEV_NA_NA_MILL.A | D22: millions | F22: 0.189364 | G22: 0.194556 | H22: 0.197308 | I22: 0.198579 | J22: 0.197598 | K22: 0.194962 | L22: 0.192379 | M22: 0.189522 | N22: 0.186697 | O22: 0.1813 | P22: 0.17685 | Q22: 0.173177 | R22: 0.170455 | S22: 0.1687 | T22: 0.168413 | U22: 0.169129 | V22: 0.170275 | W22: 0.172011 | X22: 0.1741 | Y22: 0.176482 | Z22: 0.178797 | AA22: 0.181057 | AB22: 0.183124 | AC22: 0.185013 | AD22: 0.186906 | AE22: 0.188767 | AF22: 0.190928 | AG22: 0
A23: 200-Mile Electric Vehicle | B23: Light-Duty Vehicle Stock: Alternative-Fuel Cars: 200-Mile Electric Vehicle: Alternative Transportation | C23: AEO.2025.ALTTRNP.ECI_STK_TRN_CAR_200MIEV_NA_NA_MILL.A | D23: millions | F23: 0.596058 | G23: 0.799342 | H23: 1.026953 | I23: 1.278539 | J23: 1.515127 | K23: 1.736084 | L23: 1.981423 | M23: 2.23317 | N23: 2.67837 | O23: 3.148493 | P23: 3.650867 | Q23: 4.249054 | R23: 4.831384 | S23: 5.406848 | T23: 5.981627 | U23: 6.62559 | V23: 7.243782 | W23: 7.838796 | X23: 8.409168 | Y23: 8.965648 | Z23: 9.495731 | AA23: 10.010146 | AB23: 10.490636 | AC23: 10.937266 | AD23: 11.354158 | AE23: 11.739839 | AF23: 12.117647 | AG23: 0.123
A24: 300-Mile Electric Vehicle | B24: Light-Duty Vehicle Stock: Alternative-Fuel Cars: 300-Mile Electric Vehicle: Alternative Transportation | C24: AEO.2025.ALTTRNP.ECI_STK_TRN_CAR_300MIEV_NA_NA_MILL.A | D24: millions | F24: 3.350819 | G24: 4.553581 | H24: 6.089294 | I24: 7.783081 | J24: 9.427256 | K24: 10.973656 | L24: 12.551533 | M24: 14.073189 | N24: 15.524174 | O24: 16.764969 | P24: 18.055681 | Q24: 19.304041 | R24: 20.498693 | S24: 21.636648 | T24: 22.716852 | U24: 23.720339 | V24: 24.676342 | W24: 25.531099 | X24: 26.285509 | Y24: 26.945652 | Z24: 27.518177 | AA24: 28.014536 | AB24: 28.438889 | AC24: 28.795073 | AD24: 29.093327 | AE24: 29.345419 | AF24: 29.574322 | AG24: 0.087
A25: Plug-in 20 Gasoline Hybrid | B25: Light-Duty Vehicle Stock: Alternative-Fuel Cars: Plug-in 20 Gasoline Hybrid: Alternative Transportation | C25: AEO.2025.ALTTRNP.ECI_STK_TRN_CAR_PI20GH_NA_NA_MILL.A | D25: millions | F25: 0.390254 | G25: 0.419011 | H25: 0.450794 | I25: 0.485306 | J25: 0.518643 | K25: 0.542608 | L25: 0.563214 | M25: 0.580764 | N25: 0.590699 | O25: 0.593232 | P25: 0.597107 | Q25: 0.598967 | R25: 0.599886 | S25: 0.600578 | T25: 0.601549 | U25: 0.601843 | V25: 0.601758 | W25: 0.601269 | X25: 0.600973 | Y25: 0.600784 | Z25: 0.599934 | AA25: 0.598818 | AB25: 0.596954 | AC25: 0.594592 | AD25: 0.591897 | AE25: 0.588975 | AF25: 0.587037 | AG25: 0.016
A26: Plug-in 50 Gasoline Hybrid | B26: Light-Duty Vehicle Stock: Alternative-Fuel Cars: Plug-in 50 Gasoline Hybrid: Alternative Transportation | C26: AEO.2025.ALTTRNP.ECI_STK_TRN_CAR_PI50GH_NA_NA_MILL.A | D26: millions | F26: 0.233882 | G26: 0.256353 | H26: 0.306792 | I26: 0.362194 | J26: 0.418569 | K26: 0.467199 | L26: 0.512948 | M26: 0.556618 | N26: 0.585146 | O26: 0.600141 | P26: 0.618645 | Q26: 0.631887 | R26: 0.645047 | S26: 0.658045 | T26: 0.671084 | U26: 0.678903 | V26: 0.685034 | W26: 0.689021 | X26: 0.691151 | Y26: 0.691509 | Z26: 0.689113 | AA26: 0.684504 | AB26: 0.677677 | AC26: 0.66927 | AD26: 0.659956 | AE26: 0.6502 | AF26: 0.641142 | AG26: 0.04
A27: Electric-Diesel Hybrid | B27: Light-Duty Vehicle Stock: Alternative-Fuel Cars: Electric-Diesel Hybrid: Alternative Transportation | C27: AEO.2025.ALTTRNP.ECI_STK_TRN_CAR_EDH_NA_NA_MILL.A | D27: millions | F27: 0 | G27: 0 | H27: 0 | I27: 0 | J27: 0 | K27: 0 | L27: 0 | M27: 0 | N27: 0 | O27: 0 | P27: 0 | Q27: 0 | R27: 0 | S27: 0 | T27: 0 | U27: 0 | V27: 0 | W27: 0 | X27: 0 | Y27: 0 | Z27: 0 | AA27: 0 | AB27: 0 | AC27: 0 | AD27: 0 | AE27: 0 | AF27: 0 | AG27: - -
A28: Electric-Gasoline Hybrid | B28: Light-Duty Vehicle Stock: Alternative-Fuel Cars: Electric-Gasoline Hybrid: Alternative Transportation | C28: AEO.2025.ALTTRNP.ECI_STK_TRN_CAR_EGH_NA_NA_MILL.A | D28: millions | F28: 4.383496 | G28: 4.667344 | H28: 4.920022 | I28: 5.189314 | J28: 5.417542 | K28: 5.647294 | L28: 5.877103 | M28: 6.101753 | N28: 6.293952 | O28: 6.500947 | P28: 6.728318 | Q28: 6.956541 | R28: 7.180038 | S28: 7.405491 | T28: 7.633335 | U28: 7.851522 | V28: 8.052346 | W28: 8.241234 | X28: 8.419258 | Y28: 8.584496 | Z28: 8.739201 | AA28: 8.8846 | AB28: 9.019283 | AC28: 9.144209 | AD28: 9.259831 | AE28: 9.369863 | AF28: 9.480382 | AG28: 0.03
A29: Natural Gas ICE | B29: Light-Duty Vehicle Stock: Alternative-Fuel Cars: Natural Gas ICE: Alternative Transportation | C29: AEO.2025.ALTTRNP.ECI_STK_TRN_CAR_NGI_NA_NA_MILL.A | D29: millions | F29: 0.009966 | G29: 0.009083 | H29: 0.008202 | I29: 0.007321 | J29: 0.006467 | K29: 0.005656 | L29: 0.004985 | M29: 0.004352 | N29: 0.003794 | O29: 0.003313 | P29: 0.002917 | Q29: 0.002586 | R29: 0.002315 | S29: 0.002137 | T29: 0.001984 | U29: 0.001857 | V29: 0.001744 | W29: 0.001638 | X29: 0.001538 | Y29: 0.001445 | Z29: 0.001357 | AA29: 0.001274 | AB29: 0.001197 | AC29: 0.001124 | AD29: 0.001056 | AE29: 0.000991 | AF29: 0.000931 | AG29: -0.087
A30: Natural Gas Bi-fuel | B30: Light-Duty Vehicle Stock: Alternative-Fuel Cars: Natural Gas Bi-fuel: Alternative Transportation | C30: AEO.2025.ALTTRNP.ECI_STK_TRN_CAR_NBF_NA_NA_MILL.A | D30: millions | F30: 0.000236 | G30: 0.000222 | H30: 0.000209 | I30: 0.000196 | J30: 0.000184 | K30: 0.000173 | L30: 0.000162 | M30: 0.000152 | N30: 0.000143 | O30: 0.000134 | P30: 0.000126 | Q30: 0.000119 | R30: 0.000111 | S30: 0.000105 | T30: 9.8e-05 | U30: 9.2e-05 | V30: 8.7e-05 | W30: 8.1e-05 | X30: 7.6e-05 | Y30: 7.2e-05 | Z30: 6.7e-05 | AA30: 6.3e-05 | AB30: 5.9e-05 | AC30: 5.6e-05 | AD30: 5.2e-05 | AE30: 4.9e-05 | AF30: 4.6e-05 | AG30: -0.061
A31: Propane ICE | B31: Light-Duty Vehicle Stock: Alternative-Fuel Cars: Propane ICE: Alternative Transportation | C31: AEO.2025.ALTTRNP.ECI_STK_TRN_CAR_PROP_NA_NA_MILL.A | D31: millions | F31: 0.001531 | G31: 0.001331 | H31: 0.001207 | I31: 0.00113 | J31: 0.001062 | K31: 0.000997 | L31: 0.000936 | M31: 0.000879 | N31: 0.000826 | O31: 0.000776 | P31: 0.000728 | Q31: 0.000684 | R31: 0.000642 | S31: 0.000603 | T31: 0.000567 | U31: 0.000532 | V31: 0.0005 | W31: 0.000469 | X31: 0.000441 | Y31: 0.000414 | Z31: 0.000389 | AA31: 0.000365 | AB31: 0.000343 | AC31: 0.000322 | AD31: 0.000302 | AE31: 0.000284 | AF31: 0.000267 | AG31: -0.065
A32: Propane Bi-fuel | B32: Light-Duty Vehicle Stock: Alternative-Fuel Cars: Propane Bi-fuel: Alternative Transportation | C32: AEO.2025.ALTTRNP.ECI_STK_TRN_CAR_PBF_NA_NA_MILL.A | D32: millions | F32: 0.002995 | G32: 0.002586 | H32: 0.002306 | I32: 0.002135 | J32: 0.00199 | K32: 0.001869 | L32: 0.001755 | M32: 0.001649 | N32: 0.001548 | O32: 0.001454 | P32: 0.001366 | Q32: 0.001282 | R32: 0.001204 | S32: 0.001131 | T32: 0.001062 | U32: 0.000998 | V32: 0.000937 | W32: 0.00088 | X32: 0.000826 | Y32: 0.000776 | Z32: 0.000729 | AA32: 0.000684 | AB32: 0.000643 | AC32: 0.000604 | AD32: 0.000567 | AE32: 0.000532 | AF32: 0.0005 | AG32: -0.067
A33: Fuel Cell Methanol | B33: Light-Duty Vehicle Stock: Alternative-Fuel Cars: Fuel Cell Methanol: Alternative Transportation | C33: AEO.2025.ALTTRNP.ECI_STK_TRN_CAR_FCLMTH_NA_NA_MILL.A | D33: millions | F33: 0 | G33: 0 | H33: 0 | I33: 0 | J33: 0 | K33: 0 | L33: 0 | M33: 0 | N33: 0 | O33: 0 | P33: 0 | Q33: 0 | R33: 0 | S33: 0 | T33: 0 | U33: 0 | V33: 0 | W33: 0 | X33: 0 | Y33: 0 | Z33: 0 | AA33: 0 | AB33: 0 | AC33: 0 | AD33: 0 | AE33: 0 | AF33: 0 | AG33: - -
A34: Fuel Cell Hydrogen | B34: Light-Duty Vehicle Stock: Alternative-Fuel Cars: Fuel Cell Hydrogen: Alternative Transportation | C34: AEO.2025.ALTTRNP.ECI_STK_TRN_CAR_FCH_NA_NA_MILL.A | D34: millions | F34: 0.017094 | G34: 0.017212 | H34: 0.017324 | I34: 0.017491 | J34: 0.017678 | K34: 0.017376 | L34: 0.017114 | M34: 0.016773 | N34: 0.016348 | O34: 0.015785 | P34: 0.01516 | Q34: 0.014505 | R34: 0.013759 | S34: 0.012953 | T34: 0.012103 | U34: 0.011241 | V34: 0.010391 | W34: 0.009571 | X34: 0.008848 | Y34: 0.008194 | Z34: 0.007631 | AA34: 0.007123 | AB34: 0.006709 | AC34: 0.006371 | AD34: 0.006108 | AE34: 0.005877 | AF34: 0.005689 | AG34: -0.041
A35: Total Alternative Cars | B35: Light-Duty Vehicle Stock: Alternative-Fuel Cars: Total: Alternative Transportation | C35: AEO.2025.ALTTRNP.ECI_STK_TRN_CAR_ALT_NA_NA_MILL.A | D35: millions | F35: 12.953705 | G35: 14.464029 | H35: 16.316294 | I35: 18.361877 | J35: 20.291939 | K35: 22.087965 | L35: 23.936394 | M35: 25.734533 | N35: 27.615805 | O35: 29.323631 | P35: 31.161091 | Q35: 33.070404 | R35: 34.933651 | S35: 36.764729 | T35: 38.563175 | U35: 40.360699 | V35: 42.083294 | W35: 43.677887 | X35: 45.142799 | Y35: 46.491135 | Z35: 47.716637 | AA35: 48.841591 | AB35: 49.848408 | AC35: 50.742748 | AD35: 51.540394 | AE35: 52.255764 | AF35: 52.943821 | AG35: 0.056
A36: Total Car Stock | B36: Light-Duty Vehicle Stock: Car Stock: Total: Alternative Transportation | C36: AEO.2025.ALTTRNP.ECI_STK_TRN_CAR_NA_NA_NA_MILL.A | D36: millions | F36: 122.17818 | G36: 120.93849 | H36: 119.76334 | I36: 118.5006 | J36: 116.9696 | K36: 115.39435 | L36: 113.86289 | M36: 112.2376 | N36: 110.58373 | O36: 108.95561 | P36: 107.64484 | Q36: 106.42442 | R36: 105.30586 | S36: 104.37909 | T36: 103.67609 | U36: 103.16687 | V36: 102.76471 | W36: 102.43033 | X36: 102.14629 | Y36: 101.89357 | Z36: 101.6375 | AA36: 101.38789 | AB36: 101.08474 | AC36: 100.72556 | AD36: 100.32182 | AE36: 99.894974 | AF36: 99.518021 | AG36: -0.008
A37: Light Truck Stock
A38: Conventional Light Trucks
A39: Gasoline ICE Vehicles | B39: Light-Duty Vehicle Stock: Conventional Light Trucks: Gasoline: Alternative Transportation | C39: AEO.2025.ALTTRNP.ECI_STK_TRN_LTK_GSL_NA_NA_MILL.A | D39: millions | F39: 122.60221 | G39: 123.59712 | H39: 124.0777 | I39: 125.18516 | J39: 126.13748 | K39: 126.96192 | L39: 127.49052 | M39: 127.7161 | N39: 127.73701 | O39: 127.8717 | P39: 127.63397 | Q39: 127.17414 | R39: 126.509 | S39: 125.67581 | T39: 124.71436 | U39: 123.67287 | V39: 122.62404 | W39: 121.54941 | X39: 120.4689 | Y39: 119.37255 | Z39: 118.3205 | AA39: 117.26869 | AB39: 116.23584 | AC39: 115.2121 | AD39: 114.16058 | AE39: 113.1001 | AF39: 111.9896 | AG39: -0.003
A40: TDI Diesel ICE | B40: Light-Duty Vehicle Stock: Conventional Light Trucks: TDI Diesel: Alternative Transportation | C40: AEO.2025.ALTTRNP.ECI_STK_TRN_LTK_TDS_NA_NA_MILL.A | D40: millions | F40: 1.071032 | G40: 1.213133 | H40: 1.346547 | I40: 1.46787 | J40: 1.579756 | K40: 1.690676 | L40: 1.7601 | M40: 1.822996 | N40: 1.881844 | O40: 1.944335 | P40: 1.999323 | Q40: 2.048566 | R40: 2.09306 | S40: 2.130848 | T40: 2.162724 | U40: 2.189977 | V40: 2.21308 | W40: 2.232274 | X40: 2.246032 | Y40: 2.255191 | Z40: 2.260015 | AA40: 2.261415 | AB40: 2.261849 | AC40: 2.260939 | AD40: 2.258072 | AE40: 2.254604 | AF40: 2.250386 | AG40: 0.029
