Workbook
Name a: #REF!
Name a: #REF!
Name AsphaltStore: [1]Control!$D$50
Name base.year: #REF!
Name BaseYear: 2018
Name BTV11_15: #REF!
Name BTV11_15: #REF!
Name BVT17_15: #REF!
Name BVT17_15: #REF!
Name CAAGR_tolerance: 200
Name CH4_to_CO2e: '[2]Cross-Page Data'!$C$12
Name CH4GWP: #REF!
Name CO2_T4_APS: #REF!
Name CO2_T4_APS: #REF!
Name CO2_T4_NZE: #REF!
Name CO2_T4_NZE: #REF!
Name CO2_T4_STEPS: #REF!
Name CO2_T4_STEPS: #REF!
Name CO2_T5_APS: #REF!
Name CO2_T5_APS: #REF!
Name CO2_T5_CPS: #REF!
Name CO2_T5_CPS: #REF!
Name CO2_T5_NZE: #REF!
Name CO2_T5_NZE: #REF!
Name CO2_T5_STEPS: #REF!
Name CO2_T5_STEPS: #REF!
Name coal.past: #REF!
Name COAL_PRODUCTION: #REF!
Name COAL_PRODUCTION: #REF!
Name Coal_trade: #REF!
Name Coal_trade: #REF!
Name coaldemand: #REF!
Name coaldemand: #REF!
Name CokeCoalStore: [1]Control!$D$63
Name Constants.Density.Diesel: #REF!
Name Constants.Density.Ethanol: #REF!
Name Constants.Density.JetFuel: #REF!
Name Constants.Density.MotorSpirit: #REF!
Name ConsumeBlock1: '[1]Default State Energy Data Table'!$A$6:$AM$67
Name Conversion.to.average.power: #REF!
Name Conversion.water.L: #REF!
Name Conversion.water.units: #REF!
Name Conversions.Area.m2: #REF!
Name Conversions.Area.Units: #REF!
Name Conversions.Energy.Joules: #REF!
Name Conversions.Energy.Units: #REF!
Name Conversions.Money.GBP: #REF!
Name Conversions.Money.Units: #REF!
Name Conversions.Power.Units: #REF!
Name Conversions.Power.Watts: #REF!
Name Cost.Capital.Scenario: #REF!
Name Cost.Finance.Scenario: #REF!
Name Cost.Fuel.Scenario: #REF!
Name Cost.Infrastructure.Scenario: #REF!
Name cpi_2010to2012: #REF!
Name cpi_2010to2012: #REF!
Name cpi_2013to2012: #REF!
Name cpi_2013to2012: #REF!
Name cpi_2014to2012: #REF!
Name cpi_2014to2012: #REF!

Sheet About
A1: IECCpUAEU Industrial Equipment Capital Cost per Unit Annual Energy Use
A2: Check the heat pump capex against other sources (kWth vs kWheat?)
A3: Sources: | B3: Industrial heat pumps cost per unit heat delivered | D3: Electric and gas-fired ovens
B4: Zühlsdorf, B., Andersen, M. P., Tammone, C. et.al. | D4: DOE (EERE)
B5: 2025 | D5: 2016
B6: Industrial High-Temperature Heat Pumps. Task 1 – Technologies: Yearly Report 2025 | D6: Energy Savings Potential and RD&D Opportunities for Commercial Building Appliances (2015 Update)
B7: https://heatpumpingtechnologies.org/project68/task1/ | D7: https://www.energy.gov/sites/prod/files/2016/06/f32/DOE-BTO%20Comml%20Appl%20Report%20-%20Full%20Report_0.pdf
B8: Page 16, Figure 1-4
D9: Natural gas-fired distillation columns
B10: Industrial heat pumps capacity factor | D10: DOE (OSTI)
B11: Copeland (formerly Emerson Climate Technologies) | D11: 2013
B12: 2011 | D12: Distributive Distillation Enabled by Microchannel Process Technology
B13: Industrial Heat Pumps | D13: https://www.osti.gov/servlets/purl/1077001
B14: https://media.copeland.com/1da81099-2c21-4ce5-8096-b16d0037b111/VILTER%20Heat%20Pump%20White%20Paper.pdf
B15: Page 6-8. Capacity factor is based on the average annual operating hours across the four examples, assuming each operates at full capacity.
B17: Three fossil fuel type industrial boiler costs | D17: Hydrogen boiler capital cost price ratio
B18: IRENA | D18: E3
B19: 2016 | D19: "Achieving Carbon Neutrality in California (Revised Report): 2045 Abatement Cost Estimates"
B20: Remap Technology and Performance Assumptions (for year 2030) | D20: 2020
B21: https://www.irena.org/-/media/Irena/Files/REmap/IRENA_REmap_2030_technology_cost.xlsx | D21: https://ww2.arb.ca.gov/sites/default/files/2020-09/e3_cn_draft_report_supp_data_aug2020.xlsx
B23: NOT USED - Included for reference/comparison - natural gas boiler costs | D23: Electrochemical
B24: State of Michigan | D24: Data from the DOE's Pathways to Commercial Liftoff: Clean Hydrogen , 2023, p.13, p.88
B25: 2003
B26: Miscellaneous Industrial Costs | D26: China capex numbers provided by:
B27: https://www.michigan.gov/-/media/Project/Websites/treasury/VOL/Vol236UIP12MiscellaneousIndustrialCosts.pdf?rev=b2a14a143c11493e8d0a30587afaa282 | D27: Wang et al., 2023. "The multi-scenario projection of cost reduction in hydrogen production by proton exchange membrane (PEM) water electrolysis in the near future (2020–2060) of China." Fuel, Vol. 354
B28: Page 1
B30: NOT USED - Included for reference/comparison - natural gas boiler costs | D30: Natural gas-fired chillers
B31: National Renewable Energy Laboratory | D31: EnergistX
B32: 2017 | D32: undated
B33: Electrification Futures Study | D33: 500 Ton Natural Gas-Fired Absorption Chiller replacement of Aged Centrifugal Electric Chiller
B34: https://docs.nrel.gov/docs/fy18osti/70485.pdf | D34: https://enrgistx.com/natural-gas-fired-chillers/
B35: Page 64, Table 17
B37: Nonboiler High Temp | D37: Electric chillers
B38: Electric Example (EAF) References: | D38: Florida Power & Light
B39: Capex costs per ton: | D39: undated
B40: Deutsches Institut für Wirtschaftsforschung | D40: Water-Cooled Chillers
B41: 2024 | D41: https://www.fpl.com/content/dam/fplgp/us/en/business/save/programs/pdf/water-cooled-chillers-primer.pdf
B42: "Revisiting Investment Costs for Green Steel: Capital Expenditures, Firm Level Impacts, and Policy Implications"
B43: https://www.diw.de/documents/publikationen/73/diw_01.c.901039.de/dp2082.pdf
B45: Energy expenditure/output:
...

Sheet cpi
A1: Historical Consumer Price Index for All Urban Consumers (CPI-U): U.S. city average, all items, index
A2: averages — Continued
A3: [1982-84=100, unless otherwise noted]
A4: Year | B4: Semiannual averages | D4: Annual avg. | E4: Percent change from previous | G4: Multiply by to get 2012 Dollars
B5: 1st half | C5: 2nd half | E5: Dec. | F5: Annual avg.
A6: 1968............................................................................. . | B6: – | C6: – | D6: 34.8 | E6: 4.7 | F6: 4.2
A7: 1969............................................................................. . | B7: – | C7: – | D7: 36.7 | E7: 6.2 | F7: 5.5
A8: 1970............................................................................. . | B8: – | C8: – | D8: 38.8 | E8: 5.6 | F8: 5.7
A9: 1971............................................................................. . | B9: – | C9: – | D9: 40.5 | E9: 3.3 | F9: 4.4
A10: 1972............................................................................. . | B10: – | C10: – | D10: 41.8 | E10: 3.4 | F10: 3.2
A11: 1973............................................................................. . | B11: – | C11: – | D11: 44.4 | E11: 8.7 | F11: 6.2
A12: 1974............................................................................. . | B12: – | C12: – | D12: 49.3 | E12: 12.3 | F12: 11
A13: 1975............................................................................. . | B13: – | C13: – | D13: 53.8 | E13: 6.9 | F13: 9.1
A14: 1976............................................................................. . | B14: – | C14: – | D14: 56.9 | E14: 4.9 | F14: 5.8
A15: 1977............................................................................. . | B15: – | C15: – | D15: 60.6 | E15: 6.7 | F15: 6.5
A16: 1978............................................................................. . | B16: – | C16: – | D16: 65.2 | E16: 9 | F16: 7.6
A17: 1979............................................................................. . | B17: – | C17: – | D17: 72.6 | E17: 13.3 | F17: 11.3
... A21: 1983............................................................................. . | B21: – | C21: – | D21: 99.6 | E21: 3.8 | F21: 3.2
A22: 1984............................................................................. . | B22: 102.9 | C22: 104.9 | D22: 103.9 | E22: 3.9 | F22: 4.3
A23: 1985............................................................................. . | B23: 106.6 | C23: 108.5 | D23: 107.6 | E23: 3.8 | F23: 3.6
A24: 1986............................................................................. . | B24: 109.1 | C24: 110.1 | D24: 109.6 | E24: 1.1 | F24: 1.9
A25: 1987............................................................................. . | B25: 112.4 | C25: 114.9 | D25: 113.6 | E25: 4.4 | F25: 3.6
A26: 1988............................................................................. . | B26: 116.8 | C26: 119.7 | D26: 118.3 | E26: 4.4 | F26: 4.1
A27: 1989............................................................................. . | B27: 122.7 | C27: 125.3 | D27: 124 | E27: 4.6 | F27: 4.8
A28: 1990............................................................................. . | B28: 128.7 | C28: 132.6 | D28: 130.7 | E28: 6.1 | F28: 5.4 | G28: =$D$50/D28 -> 1.7566488
A29: 1991............................................................................. . | B29: 135.2 | C29: 137.2 | D29: 136.2 | E29: 3.1 | F29: 4.2 | G29: =$D$50/D29 -> 1.6857122
A30: 1992............................................................................. . | B30: 139.2 | C30: 141.4 | D30: 140.3 | E30: 2.9 | F30: 3 | G30: =$D$50/D30 -> 1.6364505
A31: 1993............................................................................. . | B31: 143.7 | C31: 145.3 | D31: 144.5 | E31: 2.7 | F31: 3 | G31: =$D$50/D31 -> 1.5888858
A32: 1994............................................................................. . | B32: 147.2 | C32: 149.3 | D32: 148.2 | E32: 2.7 | F32: 2.6 | G32: =$D$50/D32 -> 1.5492173
A33: 1995............................................................................. . | B33: 151.5 | C33: 153.2 | D33: 152.4 | E33: 2.5 | F33: 2.8 | G33: =$D$50/D33 -> 1.5065223
A34: 1996............................................................................. . | B34: 155.8 | C34: 157.9 | D34: 156.9 | E34: 3.3 | F34: 3 | G34: =$D$50/D34 -> 1.4633142
A35: 1997............................................................................. . | B35: 159.9 | C35: 161.2 | D35: 160.5 | E35: 1.7 | F35: 2.3 | G35: =$D$50/D35 -> 1.4304922
A36: 1998............................................................................. . | B36: 162.3 | C36: 163.7 | D36: 163 | E36: 1.6 | F36: 1.6 | G36: =$D$50/D36 -> 1.4085521
A37: 1999............................................................................. . | B37: 165.4 | C37: 167.8 | D37: 166.6 | E37: 2.7 | F37: 2.2 | G37: =$D$50/D37 -> 1.3781152
A38: 2000............................................................................. . | B38: 170.8 | C38: 173.6 | D38: 172.2 | E38: 3.4 | F38: 3.4 | G38: =$D$50/D38 -> 1.3332985
A39: 2001............................................................................. . | B39: 176.6 | C39: 177.5 | D39: 177.1 | E39: 1.6 | F39: 2.8 | G39: =$D$50/D39 -> 1.2964088
... A60: 2022............................................................................. . | B60: 288.347 | C60: 296.963 | D60: 292.655 | E60: 6.5 | F60: 8 | G60: =$D$50/D60 -> 0.78452102
A61: 2023............................................................................. . | B61: 302.408 | C61: 306.996 | D61: 304.702 | G61: =$D$50/D61 -> 0.75350342
A62: 2024............................................................................. . | B62: 312.145 | C62: 315.233 | D62: 313.689 | G62: =$D$50/D62 -> 0.73191601
A63: 2025............................................................................. . | B63: 320.13 | C63: 324.16 | D63: 321.962 | G63: =$D$50/D63 -> 0.713109

Sheet Boilers & Heat Pumps
A1: Industrial heat pumps
A2: For electricity in the "boilers" end use, we use industrial heat pumps rather than electric boilers because industrial heat pumps
A3: are more efficient and are therefore recommended over electrical boilers wherever practical.
A5: Metric | B5: Value | C5: Unit
A6: Per-kW CAPEX | B6: 600 | C6: 2024€/kW | D6: € / power draw
A7: Currency adj. EUR to USD 2024 | B7: 1.0822 | C7: 2024$/2024€
A8: Per-kW CAPEX | B8: =B6*B7 -> 649.32 | C8: 2024$/kW
A9: Annual hours | B9: 8760 | C9: hrs/yr
A10: Capacity factor | B10: =AVERAGE(5944,2503,6257,6257)/B9 -> 0.59820205 | C10: %
A11: Per-kWh/yr CAPEX | B11: =B8/(B9*B10) -> 0.12391012 | C11: 2024$/(kWh/yr) | D11: $ / electricity consumption each year
A13: Conversion factor | B13: 3412.14 | C13: BTU/kWh
A15: Per-BTU/yr CAPEX | B15: =B11/B13 -> 3.6314489e-05 | C15: 2024$/(BTU/yr) | D15: $ / electricity consumption (in BTU of electricity) each year
D16: FLAGGED — see note on B6: this assertion appears to be incorrect. The source figure is per kW of heat output, so a COP conversion IS required.
A19: Industrial fossil fuel boilers
B20: Reference capacity (kW) | C20: Overnight capital cost (USD/kW) — IRENA REmap 2030 (see About rows 17-21) | D20: Boiler cost ($) | E20: Conversion efficiency | F20: Annual Energy Input (BTU) | G20: Cost per annual energy input (2015$/(BTU/yr)) | H20: Cost per annual energy input (2024$/(BTU/yr))
A21: coal (steam boiler) | B21: 2000 | C21: 300 | D21: =B21*C21 -> 600000 | E21: 0.903 | F21: =$B$29/E21 -> 3.9902767e+10 | G21: =D21/F21 -> 1.5036551e-05 | H21: =G21*$B$30 -> 1.9888846e-05
A22: petroleum products (steam boiler) | B22: 2000 | C22: 200 | D22: =B22*C22 -> 400000 | E22: 0.892 | F22: =$B$29/E22 -> 4.0394841e+10 | G22: =D22/F22 -> 9.9022545e-06 | H22: =G22*$B$30 -> 1.3097712e-05
A23: natural gas (steam boiler) | B23: 2000 | C23: 100 | D23: =B23*C23 -> 200000 | E23: 0.857 | F23: =$B$29/E23 -> 4.2044572e+10 | G23: =D23/F23 -> 4.7568566e-06 | H23: =G23*$B$30 -> 6.2918942e-06
B25: Value | C25: Unit
A26: Annual operating hours | B26: 5280 | C26: hours / year
A27: Annual heat output | B27: =B21*B26 -> 10560000 | C27: kWh
A28: Conversion factor | B28: 3412.14 | C28: BTU/kWh
A29: Annual heat output | B29: =B27*B28 -> 36032198400 | C29: BTU
A30: 2015 to 2024 inflation adj. | B30: 1.3227 | C30: dmnl
A32: Hydrogen boiler
A34: The ARB document suggests that a hydrogen boiler under a "conservative" scenario would cost
A35: 50% more than a natural gas boiler.
A37: =H23*1.5 -> 9.4378413e-06 | B37: 2024$/(BTU/yr)
A40: NOT USED - State of Michigan 2003 reference for natural gas boiler costs
A42: Using a 400-horsepower boiler as our example:
A44: water tube boiler | B44: 80375 | C44: 2003 USD
A45: fire tube boiler | B45: 91475 | C45: 2003 USD
A46: average cost | B46: =AVERAGE(B44:B45) -> 85925 | C46: 2003 USD
A48: 2003 to 2024 inflation adj. | B48: 1.7042 | C48: dmnl
A50: average cost (inflation adjusted) | B50: =B46*B48 -> 146433.38 | C50: 2024 USD
A52: boiler horsepower | B52: 400
A53: kW / boiler horsepower | B53: 9.8095 | C53: Unit conversion ref: | D53: https://www.unitconverters.net/power/horsepower-boiler-to-kilowatt.htm
A54: kW | B54: =B52*B53 -> 3923.8
A56: Annual operating hours: | B56: 5280
A58: annual energy consumption | B58: =B54*B56 -> 20717664 | C58: kWh/year
...

Sheet Cooling
A1: Natural Gas-Fired Chillers
A3: Based on a 500-ton natural gas-fired absorption chiller
A5: Capital cost | B5: 307500 | C5: $
A6: Operating hours | B6: 4000 | C6: hours/yr
A8: Natural gas charges | B8: 75863 | C8: $
A9: Electricity charges (for pumps) | B9: 6226 | C9: $
A11: Natural gas rate | B11: 0.45 | C11: $/therm
A12: Electricity rate | B12: 0.15 | C12: $/kWh
A14: NG use | B14: =B8/B11 -> 168584.44 | C14: therms
A15: Electricity use | B15: =B9/B12 -> 41506.667 | C15: kWh
A17: Conversion factor | B17: 100000 | C17: BTU/therm
A18: Conversion factor | B18: 3412.14 | C18: BTU/kWh
A20: NG use | B20: =B14*B17 -> 1.6858444e+10 | C20: BTU
A21: Electricity use | B21: =B15*B18 -> 1.4162656e+08 | C21: BTU
A23: The vast majority of the energy use is natural gas. But we don't want to disregard the
A24: cost of the electricity used to power the pumps. So we sum it with natural gas.
A26: Energy use (over 99% natural gas) | B26: =SUM(B20:B21) -> 1.7000071e+10 | C26: BTU
A27: Cost per BTU consumed | B27: =B5/B26 -> 1.808816e-05 | C27: $/(BTU/yr)
A29: Electric Chiller
A31: Centrifugal chillers >400 tons
A32: Low-end capital cost | B32: 200 | C32: $/ton
A33: High-end capital cost | B33: 500 | C33: $/ton
A34: Average capital cost | B34: =AVERAGE(B32:B33) -> 350 | C34: $/ton
A36: Capacity of reference chiller | B36: 500 | C36: tons | D36: Assumed to be the same as the NG-fired chiller above
A38: Capital cost of electric chiller | B38: =B34*B36 -> 175000 | C38: $
A41: Energy intensity of centrifugal chiller 300 - 600 tons capacity | B41: 0.576 | C41: kW/ton
A42: Power of centrifugal chiller 300 - 600 tons capacity | B42: =B41*B36 -> 288 | C42: kW
A44: Operating hours | B44: =B6 -> 4000 | C44: hours/yr | D44: Assumed to be the same as the NG-fired chiller above
A46: Electricity use | B46: =B42*B44 -> 1152000 | C46: kWh
A47: Electricity use | B47: =B46*B18 -> 3930785280 | C47: BTU
A49: Cost per BTU consumed | B49: =B38/B47 -> 4.4520366e-05 | C49: $/(BTU/yr)

Sheet NB Medium Temp
A1: Commercial Ovens (used as our model for medium-temperature, non-boiler industrial heating equipment)
A3: Commercial Oven Installed Base by Equipment Type | C3: p. 42, table 2-8
A4: Oven Type | B4: Installed Base
A5: deck | B5: 492000
A6: convection (1/2) | B6: 135000
A7: convection (full) | B7: 474000
A8: combiantion | B8: 70000
A9: rotary rack | B9: 22000
A10: rorary | B10: 18000
A11: cook & hold | B11: 216000
A12: conveyor | B12: 51000
A13: dough proofer | B13: 125000
A15: Commercial oven capital cost breakdown by oven type | C15: p. 44, table 2-10
A16: Oven Type | B16: Average Cost
A17: deck | B17: 13400
A18: convection | B18: 5300
A19: proofer | B19: 13600
A21: Commercial oven use characteristics | E21: p. 45, table 2-11
A22: Fuel Type | B22: Operating Hrs/Yr | C22: Capacity (btu/hr) | D22: Capacity (kW)
A23: electric | B23: 4380 | D23: 15
A24: gas | B24: 4380 | C24: 56000
A27: Adjustment to Operating Hours per Year
A28: The operating hours per year reported in the table above are for commercial ovens.
A29: We would expect an industrial facility to operate more hours per year than a commercial bakery.
A30: For this reason, and for consistency across different industrial equipment categories in this spreadsheet,
A31: we use the number of operating hours per year from the "Boilers" tab to also represent the operating hours
A32: per year for medium-temperature industrial heating equipment.
A33: Operating hours per year: | B33: ='Boilers & Heat Pumps'!B56 -> 5280
A36: Conversion factor | B36: 3412.14 | C36: BTU/kWh
A38: Calculated energy use by fuel type
A39: Fuel Type | B39: Energy Use (btu/yr) | C39: Weighted avg CapEx | D39: CapEx/(BTU/yr)
A40: electric | B40: =$B$33*D23*B36 -> 270241488 | C40: =($B$17*$B$5+$B$18*SUM($B$6:$B$7)+$B$19*$B$13)/SUM($B$5:$B$7,$B$13) -> 9396.8189 | D40: =C40/B40 -> 3.4771933e-05
A41: gas | B41: =$B$33*C24 -> 295680000 | C41: =($B$17*$B$5+$B$18*SUM($B$6:$B$7)+$B$19*$B$13)/SUM($B$5:$B$7,$B$13) -> 9396.8189 | D41: =C41/B41 -> 3.1780367e-05
A50: For reference, not used in calculations above:
A51: Commercial oven installed base by fuel type | D51: p. 43, table 2-9
A52: Fuel type | B52: installed base | C52: Percent
A53: electric | B53: 722000 | C53: =B53/SUM($B$53:$B$54) -> 0.45012469
A54: gas | B54: 882000 | C54: =B54/SUM($B$53:$B$54) -> 0.54987531
A56: FOSSIL 200-500 °C: BOILER / DIRECT-FIRED DUTY BLEND (July 2026)
A57: Mirrors the T1 duty split in the efficiency workbooks: 55% of 200-500 °C heat is boiler-served steam, 45% direct-fired. Previously this band used a single direct-fired (oven) figure for every fossil fuel, so coal, petroleum and gas were all identical in Summary row 4 despite very different boiler costs. Boiler share source: McMillan et al. 2016 (NREL/TP-6A50-66743 / INL/EXT-16-39680) — steam boilers + CHP ≈ 70% of heat loads across the 14 most energy-intensive industries, chemicals ~40% via steam loops, pulp & paper ~70% steam; offset because ~45% of US process heat is below 200 °C and steam systems top out near 250-300 °C. Suggested range 45-65%.
...

Sheet NB High Temp
A1: Electric Arc Furnace (Electric nonboiler high temp example)
I2: Source
A3: CapEx costs: | F3: =254*1.04 -> 264.16 | G3: $/tonne | I3: DIW Berlin 2024
A4: Energy expenditure/output: | F4: 450 | G4: kWh/tonne | I4: Paeng & Azimi 2024
A5: Annual production capacity: | F5: 800000 | G5: tonnes/year | I5: Energy Transitions Commission
A7: Annual energy consumption/year (kWh): | F7: =F4*F5 -> 360000000 | G7: kWh/year
A8: Annual energy consumption/year (mmBTU): | F8: =F7*0.003412 -> 1228320 | G8: mmBTU/year
A9: CapEx costs per annual yield: | F9: =F3*F5 -> 2.11328e+08 | G9: $/year
A10: $/BTU/year | F10: =F9/(F8*10^6) -> 0.00017204637 | G10: $/BTU/year | I10: Note: since the CapEx here scales with tonnes capacity, the final cost per unit capacity isn't affected by the annual production capacity figure above.
A12: 130-180 tonnes per hour essentially means | E12: =8760*155 -> 1357800 | F12: tonnes/year.
A14: Coal-fueled cement kiln
A16: Cement plant (whole plant) capital cost per unit capacity | F16: 170 | G16: $/ton cement annual production capacity
F17: =F16/F23 -> 26.356589 | G17: $/(GJ/yr)
F18: =F17/277.778 -> 0.094883645 | G18: $/(kWh/yr)
F19: =F18/3412 -> 2.7808806e-05 | G19: $/(BTU/yr) | I19: Not used because it is the whole plant, not just the kiln. Kiln-only data are just below.
A21: Kiln capital cost | F21: 36000000 | G21: RMB | I21: China Ruibin Information Network article
A22: Kiln capital cost | F22: =F21*0.14 -> 5040000 | G22: $
A23: Energy expenditure/output | F23: =AVERAGE(5.1,7.8) -> 6.45 | G23: GJ/tonne | I23: Average for rotary kiln, CemZero study
A24: Annual hours of operation: | F24: 8000 | G24: hours/year | I24: CemZero study
A25: Daily production capacity | F25: 600 | G25: tons/day | I25: China Ruibin Information Network article
F26: =F23*F25 -> 3870 | G26: GJ/day
F27: =F26*(F24/24) -> 1290000 | G27: GJ/year
A28: Annual energy consumption/year (kWh): | F28: =F27*277.778 -> 3.5833362e+08 | G28: kWh/year | I28: includes conversion factor for GJ to kWh (1:277.778)
A29: Annual energy consumption/year (mmBTU): | F29: =F28*0.003412 -> 1222634.3 | G29: mmBTU/year
A30: $/BTU/year | F30: =(F21*0.14)/(F29*10^6) -> 4.1222465e-06 | G30: $/BTU/year | I30: includes RMB to USD conversion (1:0.14)
A32: Since these are Chinese prices, we double-checked using prices from Europe. They come out about the same:
A34: CapEx of cement kiln witout CCS | F34: 21.08 | G34: 2014 euros / ton clinker (annual capacity) | I34: https://www.researchgate.net/publication/330875028_Techno-economic_analysis_of_calcium_looping_processes_for_low_CO_2_emission_cement_plants
A35: Average share of clinker in cement (global average) | F35: 0.76 | G35: % | I35: https://www.wri.org/insights/lower-carbon-blended-cement#:~:text=U.S.%20cement%20produces%20more%20emissions,is%20between%200.64%20and%200.76.
A36: CapEx of cement kiln witout CCS | F36: =F34*F35 -> 16.0208 | G36: 2014 euros / ton cement (annual capacity)
F37: 1.3284 | G37: 2014 USD / 2014 euro
F38: =F36*F37 -> 21.282031 | G38: 2014 USD / ton cement (annual capacity)
F39: 1.32 | G39: 2024 USD / 2014 USD
F40: =F38*F39 -> 28.092281 | G40: 2024 USD / ton cement (annual capacity)
F41: =F40/F23 -> 4.3553923 | G41: 2024 USD / (GJ/yr)
F42: 277.778 | G42: kWh / GJ
F43: =F41/F42 -> 0.0156794 | G43: USD / (kWh/yr)
F44: 3412.14 | G44: BTU / kWh
F45: =F43/F44 -> 4.5951807e-06 | G45: USD / (BTU/yr)
A47: Natural Gas-fueled Glass Melting Furnace (NG nonboiler high temp example)
A49: Furnace capital cost | F49: 6000000 | G49: ₤ | I49: Glass Technology Services Ltd.
...

Sheet Machine Drive
A1: Electric Motors
A2: Equipment CapEx cost derived from the AssessCCUS's Capital Equipment Cost Database's equation, based on data from Woods 2007 (see sources in About):
A3: Equipment cost = minimum equipment cost * (desired equipment scale value / minimum equipment scale value)scaling factor * (current CEPCI / listed CEPCI); 2024 CEPCI is ~800
A4: To derive Annual BTU, motor operating hours are based on the equivalent horsepower (HP) bin from the U.S. Industrial Electric Motor Systems Market Opportunities Assessment (2002). kWh are converted to mmBTU with a conversion factor of 0.003412, then multiplied by annual operating hours.
A5: Bins represented in the data by horsepower (HP) are 1-5, 6-20, 21-50,101-200,1000+. Not represented are 51-100 (12.7% of motor energy use), 201-500 (15.8%), 501-1000 (13.4%). Weighted averages thus take % of motor energy use in a given HP bin and divide by the remaining 58.1%. Weighted averages also average the energy values within a bin (e.g., averaging $/BTU/yr across all equipment in the 101-200 HP bin).
A6: The example gas diesel engine is assumed to be in operation the simple average annual operating hours (5267) of other motors/machine drives.
B8: Equipment Name | C8: Scaling Unit | D8: Min Scale | E8: Max Scale | F8: Min Cost | G8: Max Cost | H8: Scaling Factor | I8: CEPCI | J8: kW (scale average) | L8: equiv. HP | N8: Capital Cost (USD) | P8: Annual Operating Hrs | R8: % Distr. by Energy Use of Motor HP Category | T8: Annual energy use (MMbtu) | W8: $/BTU/yr
B9: Electric motor: induction, squirrel cage, 3 phase, AC, TEFC, 1800 rpm excluding starter, gearing | C9: kW | D9: 0.3 | E9: 1500 | F9: 43.754184 | G9: 512727.48 | H9: 1.1 | I9: 1000 | J9: =AVERAGE(D9,E9) -> 750.15 | L9: =J9*1.34102 -> 1005.9662 | N9: =F9*(((D9+E9)/2)/D9)^H9*(800/I9) -> 191398.76 | P9: 7436 | R9: =0.157/0.581 -> 0.27022375 | T9: =J9*0.003412*P9 -> 19032.53 | W9: =N9/(T9*10^6) -> 1.0056402e-05
B10: Electric motor: induction, wound rotor, 3 phase, AC, open drip proof, 1800 rpm, excluding starter | C10: kW | D10: 8 | E10: 150 | F10: 1455.1963 | G10: 22223.515 | H10: 0.93 | I10: 1000 | J10: =AVERAGE(D10,E10) -> 79 | L10: =J10*1.34102 -> 105.94058 | N10: =F10*(((D10+E10)/2)/D10)^H10*(800/I10) -> 9793.3452 | P10: 4174 | R10: =0.144/0.581 -> 0.24784854 | T10: =J10*0.003412*P10 -> 1125.0934 | W10: =N10/(T10*10^6) -> 8.7044735e-06
B11: Electric motor: synchronous, AC open drip proof, 1800 rpm excluding gears | C11: kW | D11: 350 | E11: 7000 | F11: 64088.852 | G11: 1137028.3 | H11: 0.96 | I11: 1000 | J11: =AVERAGE(D11,E11) -> 3675 | L11: =J11*1.34102 -> 4928.2485 | N11: =F11*(((D11+E11)/2)/D11)^H11*(800/I11) -> 490020.45 | P11: 7436 | R11: =0.157/0.581 -> 0.27022375 | T11: =J11*0.003412*P11 -> 93240.748 | W11: =N11/(T11*10^6) -> 5.2554325e-06
B12: Electric motor: synchronous, open drip proof, AC, 1200 rpm excluding gears | C12: kW | D12: 500 | E12: 7000 | F12: 77307.967 | G12: 655523.04 | H12: 0.81 | I12: 1000 | J12: =AVERAGE(D12,E12) -> 3750 | L12: =J12*1.34102 -> 5028.825 | N12: =F12*(((D12+E12)/2)/D12)^H12*(800/I12) -> 316310.69 | P12: 7436 | R12: =0.157/0.581 -> 0.27022375 | T12: =J12*0.003412*P12 -> 95143.62 | W12: =N12/(T12*10^6) -> 3.3245601e-06
B13: Electric motor: gear reduced TEFC, 1800 rpm plus gear reducer to give fixed output rpm | C13: kW | D13: 0.35 | E13: 1.8 | F13: 1297.2737 | G13: 1800 | H13: 0.2 | I13: 1000 | J13: =AVERAGE(D13,E13) -> 1.075 | L13: =J13*1.34102 -> 1.4415965 | N13: =F13*(((D13+E13)/2)/D13)^H13*(800/I13) -> 1298.9418 | P13: 2745 | R13: =0.048/0.581 -> 0.082616179 | T13: =J13*0.003412*P13 -> 10.068385 | W13: =N13/(T13*10^6) -> 0.00012901192
B14: Electric motor: gear reduced TEFC, 1800 rpm plus gear reducer to give fixed output rpm | C14: kW | D14: 1.8 | E14: 15 | F14: 1800 | G14: 5537.407 | H14: 0.53 | I14: 1000 | J14: =AVERAGE(D14,E14) -> 8.4 | L14: =J14*1.34102 -> 11.264568 | N14: =F14*(((D14+E14)/2)/D14)^H14*(800/I14) -> 3257.8875 | P14: 3391 | R14: =0.104/0.581 -> 0.17900172 | T14: =J14*0.003412*P14 -> 97.188773 | W14: =N14/(T14*10^6) -> 3.3521233e-05
B15: Electric motor: variable speed TEFC, 1800 rpm plus V-belt unit for speed control 2/1 to 5/1 at 3480, 520 and 30 rpm | C15: kW (at 1800 rpm) | D15: 0.35 | E15: 7.5 | F15: 3198.2717 | G15: 22051.65 | H15: 0.63 | I15: 1000 | J15: =AVERAGE(D15,E15) -> 3.925 | L15: =J15*1.34102 -> 5.2635035 | N15: =F15*(((D15+E15)/2)/D15)^H15*(800/I15) -> 11731.714 | P15: 2745 | R15: =0.048/0.581 -> 0.082616179 | T15: =J15*0.003412*P15 -> 36.761315 | W15: =N15/(T15*10^6) -> 0.00031913206
B16: Drive: gear unit, general, single, double, triple reduction on concentric, offset or vertical right angle drives, excluding lubrication system and motor | C16: kW (w/ reduction ratio) | D16: 3 | E16: 50 | F16: 1691.6843 | G16: 6000 | H16: 0.45 | I16: 1000 | J16: =AVERAGE(D16,E16) -> 26.5 | L16: =J16*1.34102 -> 35.53703 | N16: =F16*(((D16+E16)/2)/D16)^H16*(800/I16) -> 3607.1598 | P16: 3530 | R16: =0.127/0.581 -> 0.21858864 | T16: =J16*0.003412*P16 -> 319.17554 | W16: =N16/(T16*10^6) -> 1.1301492e-05
B17: Drive: gear unit, general, single, double, triple reduction on concentric, offset or vertical right angle drives, excluding lubrication system and motor (large) | C17: kW (w/ reduction ratio) | D17: 50 | E17: 1500 | F17: 6000 | G17: 76911.661 | H17: 0.75 | I17: 1000 | J17: =AVERAGE(D17,E17) -> 775 | L17: =J17*1.34102 -> 1039.2905 | N17: =F17*(((D17+E17)/2)/D17)^H17*(800/I17) -> 37496.438 | P17: 7436 | R17: =0.157/0.581 -> 0.27022375 | T17: =J17*0.003412*P17 -> 19663.015 | W17: =N17/(T17*10^6) -> 1.9069526e-06
B18: Drive: gear unit, medium duty, single reduction 20/1 to 50/1 excluding lubrication system and motor (large) | C18: kW (w/ reduction ratio) | D18: 3 | E18: 180 | F18: 580.86364 | G18: 5300 | H18: 0.54 | I18: 1000 | J18: =AVERAGE(D18,E18) -> 91.5 | L18: =J18*1.34102 -> 122.70333 | N18: =F18*(((D18+E18)/2)/D18)^H18*(800/I18) -> 2942.2942 | P18: 4174 | R18: =0.144/0.581 -> 0.24784854 | T18: =J18*0.003412*P18 -> 1303.1145 | W18: =N18/(T18*10^6) -> 2.2578939e-06
B19: Drive: gear unit, medium duty, single reduction 20/1 to 50/1 excluding lubrication system and motor (large) | C19: kW (w/ reduction ratio) | D19: 180 | E19: 1500 | F19: 5300 | G19: 297736.1 | H19: 1.9 | I19: 1000 | J19: =AVERAGE(D19,E19) -> 840 | L19: =J19*1.34102 -> 1126.4568 | N19: =F19*(((D19+E19)/2)/D19)^H19*(800/I19) -> 79155.071 | P19: 7436 | R19: =0.157/0.581 -> 0.27022375 | T19: =J19*0.003412*P19 -> 21312.171 | W19: =N19/(T19*10^6) -> 3.7140783e-06
B21: Simple Average for electric motors/drive units: | T21: =AVERAGE(T9:T19) -> 22843.953 | W21: =AVERAGE(W9:W19) -> 4.8016955e-05
B22: Weighted Average (by distribution of energy use) for electric motors/drive units (see below for breakdown): | T22: =SUMPRODUCT(F24:F28, I24:I28) -> 13814.302 | W22: =SUMPRODUCT(F24:F28, N24:N28) -> 2.9652198e-05
C23: Representative Horsepower Bin | F23: % Distr. by Energy Use Per HP Bin | I23: Average Annual Energy Use by HP Bin (MMbtu) | N23: $/BTU/yr
C24: 1-5 | F24: =0.048/0.581 -> 0.082616179 | I24: =((T13+T15)/2) -> 23.41485 | N24: =((W13+W15)/2) -> 0.00022407199
C25: 6-20 | F25: =0.104/0.581 -> 0.17900172 | I25: =T14 -> 97.188773 | N25: =W14 -> 3.3521233e-05
C26: 21-50 | F26: =0.127/0.581 -> 0.21858864 | I26: =T16 -> 319.17554 | N26: =W16 -> 1.1301492e-05
C27: 101-200 | F27: =0.144/0.581 -> 0.24784854 | I27: =((T10+T18)/2) -> 1214.1039 | N27: =((W10+W18)/2) -> 5.4811837e-06
C28: 1000+ | F28: =0.157/0.581 -> 0.27022375 | I28: =((T9+T11+T12+T17+T19)/5) -> 49678.417 | N28: =((W9+W11+W12+W17+W19)/5) -> 4.851485e-06
A31: Gas Diesel Engine
G32: Source
B33: Capital expenditures | D33: 502 | E33: $/kW | G33: Rockefeller Foundation: Electrifying Economies: Detailed Cost Models and Benchmarks
B34: Representative engine bhp | D34: 250 | E34: bhp | G34: EPA General Conformity Training Modules: Appendix A Sample Emissions Calculations
B35: Representative engine kW | D35: =D34/1.341 -> 186.42804 | E35: kW
B36: Representative annual operating hours | D36: 2080 | E36: hrs/year | G36: EPA General Conformity Training Modules: Appendix A Sample Emissions Calculations
B37: Annual energy consumed (MMbtu) | D37: =D35*0.003412*D36 -> 1323.0723 | E37: Mmbtu
B38: $/BTU | D38: =(D33*D35)/(D37*10^6) -> 7.0734512e-05 | E38: $/BTU

Sheet Electrochemical
A1: Hydrogen Electrolyzers
A2: Based on DoE "Pathways to Commercial Liftoff: Clean Hydrogen" p.13 CAPEX costs
A3: China capex costs based on Wang et al. 2023
A5: Alkaline Water Electrolysis
A6: Capital expenditures (U.S./Western markets) | D6: =AVERAGE(760,1000) -> 880 | E6: $/kW
A7: Capital expenditures (China): | D7: =AVERAGE(373.1,597) -> 485.05 | E7: $/kW
A9: Proton Exchange Membrane Electrolyzer
A11: Capital expenditures (U.S./Western markets): | D11: =AVERAGE(975,1200) -> 1087.5 | E11: $/kW
A12: Capital expenditures (China): | D12: =AVERAGE(1492.5,2238.8) -> 1865.65 | E12: $/kW
A14: DOE Electrolyzer Capacity Example Case (p.88):
A15: Average size | D15: 1.5 | E15: GW/yr
A16: Average total operating capacity (first 3 years) | D16: 70 | E16: %
A18: Capex for AWE electrolyzer at 1.5 GW capacity (US): | G18: =(D6)*(1.5*1000000) -> 1320000000
A19: Energy use in kWh/year: | G19: =(1.5*1000000)*(0.7*8760) -> 9198000000
A20: Energy use in BTU/year | G20: =G19*3412 -> 31383576000000
A21: $/BTU/yr (US) | G21: =G18/G20 -> 4.2060216e-05
A22: $/BTU/yr (China) | G22: =(D7*(1.5*1000000))/G20 -> 2.3183305e-05
A24: Capex for PEM electrolyzer at 1.5 GW capacity (US): | G24: =(D11)*(1.5*1000000) -> 1631250000
A25: Energy use in kWh/year: | G25: =(1.5*1000000)*(0.7*8760) -> 9198000000
A26: Energy use in BTU/year | G26: =G25*3412 -> 31383576000000
A27: $/BTU/yr (US) | G27: =G24/G26 -> 5.1977824e-05
A28: $/BTU/yr (China) | G28: =(D12*(1.5*1000000))/G26 -> 8.9170049e-05
A30: DOE report cites potential penetrance of PEM of 25% of the U.S. market by 2030
A32: U.S. Weighted CapEx/BTU/yr: | G32: =(G21*0.75)+(G27*0.25) -> 4.4539618e-05
A33: DOE projected capex cost reduction by 2030: | G33: =G32*0.6 -> 2.6723771e-05
A35: China Data with US Weighted CapEx/BTU/yr: | G35: =(G22*0.75)+(G28*0.25) -> 3.9679991e-05

Sheet Lighting
A1: https://www.bulkofficesupply.com/Categories/Janitorial-and-Facility-Supplies/Lighting/Light-Bulbs.aspx?srsltid=AfmBOorWkgJMp4H4zdZKPjbhWJ39KPaQWfcg1JIX1YpF1EunQjEtuY1Z | P1: lightstoreusa.com
C3: incand | D3: LED | E3: LED | F3: LED | G3: LED | H3: LED | I3: LED | J3: LED | K3: fluorescent | L3: fluorescent | M3: fluorescent | N3: CFL | O3: CFL | P3: HID | Q3: HID | R3: HID | S3: HID | T3: HID
C4: bulb | D4: parabolic | E4: reflector | F4: parabolic | G4: parabolic | H4: bulb | I4: tube | J4: tube | K4: twin tube | L4: tube | M4: tube | N4: bulb | O4: bulb | P4: bulb | Q4: bulb | R4: bulb | S4: floodlight | T4: floodlight
C5: Satco A15 Appliance Light Bulb | D5: Satco 6.5W PAR 20/FL 3000K LED Bulb | E5: Satco 7.5W BR30 3000K LED Bulb | F5: Satco 12W PAR 30/LN/FL 3000K LED Bulb | G5: Satco 15W PAR38 3000K LED Bulb | H5: Satco 10W A19 LED 5000K Light Bulbs | I5: Satco 40W T8 4000K LED Tube Light | J5: Satco 11 Watt LED T8 Bulb | K5: Satco 13W GX23 Pin-Based 2700K Compact Fluorescent Bulb | L5: Satco 54W T5 3500K Fluorescent Tube | M5: Satco Flourescent Light Bulbs 32W 6/box | N5: Satco 23W T2 2700K Spiral CFL Bulb | O5: Satco 23W T2 2700K Spiral CFL Bulb | P5: Plusrite 1035 | Q5: M47 BT37 Mogul | R5: Plusrite 1056 | S5: Plusrite 1061 | T5: PLUSRITE Par 38
B6: $ | C6: 1.3 | D6: 5.15 | E6: 7.48 | F6: 8.3 | G6: 11.84 | H6: =12.98/4 -> 3.245 | I6: =124.94/10 -> 12.494 | J6: =172.75/25 -> 6.91 | K6: =5.21 -> 5.21 | L6: =206.09/40 -> 5.15225 | M6: =28.85/6 -> 4.8083333 | N6: =16.57/3 -> 5.5233333 | O6: =198.86/12/3 -> 5.5238889 | P6: 15.99 | Q6: 27.95 | R6: 39.95 | S6: 17 | T6: 12 | W6: $
B7: W | C7: 40 | D7: 6.5 | E7: 7.5 | F7: 12 | G7: 15 | H7: 10 | I7: 40 | J7: 11 | K7: 13 | L7: 54 | M7: 32 | N7: 23 | O7: 23 | P7: 100 | Q7: 1000 | R7: 1000 | S7: 70 | T7: 100
B8: lm | C8: 225 | D8: 520 | E8: 650 | F8: 1000 | G8: 1200 | H8: 800 | I8: 5500 | J8: 1800 | K8: 800 | L8: 5000 | M8: 3050 | N8: 1600 | O8: 1600 | P8: 8500 | Q8: 110000
B9: hr life | C9: 2500 | D9: 25000 | E9: 25000 | F9: 25000 | G9: 25000 | H9: 15000 | I9: 50000 | J9: 50000 | K9: 12000 | L9: 24000 | M9: 24000 | N9: 12000 | O9: 12000 | P9: 15000 | Q9: 10000 | R9: 5000 | S9: 6000
B10: W equiv. incandesc. | D10: 50 | E10: 65 | F10: 75 | G10: 90 | H10: 60 | I10: 59 | J10: ? | N10: 100 | O10: 100
C11: =C6/C7 -> 0.0325 | D11: =D6/D7 -> 0.79230769 | E11: =E6/E7 -> 0.99733333 | F11: =F6/F7 -> 0.69166667 | G11: =G6/G7 -> 0.78933333 | H11: =H6/H7 -> 0.3245 | I11: =I6/I7 -> 0.31235 | J11: =J6/J7 -> 0.62818182 | ... T11: =T6/T7 -> 0.12
H13: https://www.mordorintelligence.com/industry-reports/industrial-lighting-market
C14: $ | D14: lifetime | E14: BTU/yr | F14: W | H14: Industrial lighting market
B15: incand | C15: =AVERAGEIFS($C$6:$T$6,$C$3:$T$3,$B15) -> 1.3 | D15: =AVERAGEIFS($C$9:$T$9,$C$3:$T$3,$B15) -> 2500 | E15: =AVERAGEIFS($C$7:$T$7,$C$3:$T$3,$B15)*$O$19/1000*$O$21 -> 377565.42 | F15: =AVERAGEIFS($C$7:$T$7,$C$3:$T$3,$B15) -> 40 | H15: LED | I15: 0.652 | J15: =I15*D16 -> 20025.714 | K15: =I15*E16 -> 89677.181 | L15: =C16*I15 -> 5.161884 | M15: =I15*F16 -> 9.5005714
B16: LED | C16: =AVERAGEIFS($C$6:$T$6,$C$3:$T$3,$B16) -> 7.917 | D16: =AVERAGEIFS($C$9:$T$9,$C$3:$T$3,$B16) -> 30714.286 | E16: =AVERAGEIFS($C$7:$T$7,$C$3:$T$3,$B16)*$O$19/1000*$O$21 -> 137541.69 | F16: =AVERAGEIFS($C$7:$T$7,$C$3:$T$3,$B16) -> 14.571429 | H16: Fluorescent | I16: 0.1365 | J16: =I16*D17 -> 2730 | K16: =I16*E17 -> 42518.586 | L16: =I16*C17 -> 0.69026154 | M16: =I16*F17 -> 4.5045 | O16: assumed lighting lifetime (IESD)
B17: fluorescent | C17: =AVERAGEIFS($C$6:$T$6,$C$3:$T$3,$B17) -> 5.0568611 | D17: =AVERAGEIFS($C$9:$T$9,$C$3:$T$3,$B17) -> 20000 | E17: =AVERAGEIFS($C$7:$T$7,$C$3:$T$3,$B17)*$O$19/1000*$O$21 -> 311491.47 | F17: =AVERAGEIFS($C$7:$T$7,$C$3:$T$3,$B17) -> 33 | H17: HID fixtures | I17: 0.2005 | J17: =I17*D19 -> 1804.5 | K17: =I17*E19 -> 859216.19 | L17: =I17*C19 -> 4.526889 | M17: =I17*F19 -> 91.027 | O17: 9 | P17: years
B18: CFL | C18: =AVERAGEIFS($C$6:$T$6,$C$3:$T$3,$B18) -> 5.5236111 | D18: =AVERAGEIFS($C$9:$T$9,$C$3:$T$3,$B18) -> 12000 | E18: =AVERAGEIFS($C$7:$T$7,$C$3:$T$3,$B18)*$O$19/1000*$O$21 -> 217100.12 | F18: =AVERAGEIFS($C$7:$T$7,$C$3:$T$3,$B18) -> 23 | H18: OLED | I18: 0.011 | J18: =I18*D16 -> 337.85714 | K18: =I18*E16 -> 1512.9586 | L18: =I18*C16 -> 0.087087 | M18: =I18*F16 -> 0.16028571
B19: HID | C19: =AVERAGEIFS($C$6:$T$6,$C$3:$T$3,$B19) -> 22.578 | D19: =AVERAGEIFS($C$9:$T$9,$C$3:$T$3,$B19) -> 9000 | E19: =AVERAGEIFS($C$7:$T$7,$C$3:$T$3,$B19)*$O$19/1000*$O$21 -> 4285367.5 | F19: =AVERAGEIFS($C$7:$T$7,$C$3:$T$3,$B19) -> 454 | J19: =SUM(J15:J18) -> 24898.071 | K19: =SUM(K15:K18) -> 992924.92 | L19: =SUM(L15:L18) -> 10.466122 | M19: =SUM(M15:M18) -> 105.19236 | O19: =J19/9 -> 2766.4524 | P19: hours/yr use
J20: hour life | K20: BTU/yr | L20: $ | M20: W
O21: 3412 | P21: BTU/kWh
O23: =L19/K19 -> 1.0540698e-05 | P23: $/(BTU/yr)
B24: Lighting is generally electric. Other fuels can be used to power a generator to power lighting.
B25: So we apply an efficiency loss for using a generator to power lighting.
B27: =0.35 -> 0.35 | C27: generator efficiency
B28: =O23*B27 -> 3.6892443e-06 | C28: lightbulb contribution to cost
B31: And must account for the cost of a generator:
B32: Generac | C32: Westinghouse Wgen 5300c | D32: Westinghouse Wgen7500c | E32: Westinghouse WGen9500c | F32: WEN DF5600X | G32: DuroMax XP13000HX | H32: Firman Tri Fuel
A33: $ | B33: 3579 | C33: 649 | D33: 849 | E33: 926 | F33: 399.99 | G33: 1299 | H33: 999 | I33: =AVERAGE(Lighting!B33:H33) -> 1242.9986 | J33: avg $
A34: W | B34: 10000 | C34: 5300 | D34: 7500 | E34: 9500 | F34: 5600 | G34: 13000 | H34: =AVERAGE(10000,8000) -> 9000 | I34: =AVERAGE(Lighting!B34:H34) -> 8557.1429 | J34: avg watts
B35: =B33/B34 -> 0.3579 | C35: =C33/C34 -> 0.12245283 | D35: =D33/D34 -> 0.1132 | E35: =E33/E34 -> 0.097473684 | F35: =F33/F34 -> 0.071426786 | G35: =G33/G34 -> 0.099923077 | H35: =H33/H34 -> 0.111
I37: =I33*M19/I34 -> 15.280094 | J37: $ | K37: generator upfront cost per lightbulb powered
I38: =I37/K19*B27 -> 5.3861404e-06 | K38: generator contribution to cost
I39: =I38+B28 -> 9.0753847e-06 | K39: total cost per BTU

Sheet Other
A1: Electric example (Infrared Heater for Processed Foods)
A3: CapEx costs: | E3: =2758*1.03 -> 2840.74 | F3: USD | H3: Industrial infrared heater vendor
A4: Capacity: | E4: 18 | F4: kW | H4: Shadow Industrial Infrared model
A5: Annual operating hours: | E5: =18*365 -> 6570 | F5: hours/year | H5: Based on 16-20 hour operation of food processing plants
A7: Annual energy consumption/year (kWh): | E7: =E4*E5 -> 118260 | F7: kWh/year
A8: Annual energy consumption/year (mmBTU): | E8: =E7*0.003412 -> 403.50312 | F8: mmBTU/year
A9: $/BTU/year | E9: =E3/(E8*10^6) -> 7.0401934e-06 | F9: $/BTU/year
A12: Natural Gas-Fired Distillation Columns
A14: Based on a methanol/water separation column.
A16: Capital cost - low | B16: 862500 | C16: $
A17: Capital cost - high | B17: 1500000 | C17: $
A18: Capital cost - mean | B18: =AVERAGE(B16,B17) -> 1181250 | C18: $
A20: Operating hours | B20: 8760 | C20: hours/year
A21: Capacity | B21: 6051100 | C21: Btu/hour
A23: Annual fuel use | B23: =B20*B21 -> 53007636000 | C23: Btu/year
A24: Capital cost | B24: =B18/B23 -> 2.2284525e-05 | C24: $/Btu/year
A28: Remaining "Other Processes" cells use natural gas distillation column values modified by the ratios of capital costs for
A29: boilers using each fuel type to boilers using natural gas.

Sheet Other (mobile)
A1: Ag tractors
A2: 0.57060049 | B2: PIFURfE for ag tractors (other processes)
A3: =4000/15 -> 266.66667 | B3: Assumed annual usage (hours)
A5: =AVERAGE(O29,H39,H83) -> 0.00082719018 | B5: Diesel tractor price $/BTU
A6: =AVERAGE(O30,H40,H82) -> 0.0031381977 | B6: Electric tractor price $/BTU
A9: from https://environmentaldevices.com/wp-content/uploads/2023/09/Impacts-of-electrifying-agricultural-tractors.pdf
C28: Capital costs | D28: Tank capacity (gal) | E28: Battery capacity (kWh) | F28: Runtime/tank (hr) | G28: Energy content/tank | H28: E Intensity (BTU/hr) | I28: Annual usage (hr) | M28: price ($) | N28: annual E | O28: $/BTU
B29: DT #1 | C29: 17000 | D29: 7.1 | F29: 9.5 | G29: =D29*About!$A$112 -> 983279 | H29: =G29/F29 -> 103503.05 | I29: 250 | L29: Diesel | M29: =AVERAGE(C29:C31)*About!A117 -> 21966.589 | N29: =AVERAGE(H29:H31)*A3 -> 27574616 | O29: =M29/N29 -> 0.00079662355
B30: DT #2 | C30: 17000 | D30: 7.1 | F30: 10 | G30: =D30*About!$A$112 -> 983279 | H30: =G30/F30 -> 98327.9 | I30: 250 | L30: Electric | M30: =C32*About!A117 -> 43148.656 | N30: =N29*(1-A2) -> 11840527 | O30: =M30/N30 -> 0.0036441501
B31: DT #3 | C31: 50000 | D31: 18 | F31: 23 | G31: =D31*About!$A$112 -> 2492820 | H31: =G31/F31 -> 108383.48 | I31: 250
B32: eT | C32: 55000 | E32: 24 | F32: 16 | G32: =E32*About!$A$114 -> 81891.36 | I32: 250
C33: =C32/AVERAGE(C29:C31) -> 1.9642857
E34: =E32/38.1 -> 0.62992126
A36: from https://www.cadeogroup.com/wp-content/uploads/2022/04/PNW-Tractor-Electrification-Study.pdf
C38: Energy reservoir (kWh) | D38: hours/year | E38: price | F38: E intensity (BTU/hr) | G38: Annual BTUs | H38: $/BTU
B39: diesel | C39: 2940 | D39: 545 | E39: =37500 -> 37500 | F39: =AVERAGE(60400,120900,214300) -> 131866.67 | G39: =F39*$A$3 -> 35164444 | H39: =E39*About!$A$118/G39 -> 0.00090358046
B40: battery | C40: 113 | D40: 995 | E40: =AVERAGE(58000,74999) -> 66499.5 | F40: =F39*(1-A2) -> 56623.482 | G40: =F40*$A$3 -> 15099595 | H40: =E40*About!$A$118/G40 -> 0.0037315769
F41: ^assuming equal distribution of tasks
A53: from https://pub.epsilon.slu.se/id/document/20368600
C54: % energy consumption (bev vs diesel)
B55: example 1 | C55: 0.54 | E55: ** costs in table 3
B56: example 2 | C56: 0.52
A58: from https://static1.squarespace.com/static/5eab584a296dca09a66e85a6/t/627946f6c12c786debe434c7/1652115191705/TCO_report_May%2B2022.pdf
C81: capital cost | D81: operating hours/yr | E81: Annual energy (gal) | F81: Annual energy (kWh) | G81: Annual BTU | H81: $/BTU
B82: e-tractor | C82: 28398 | D82: 250 | G82: =G83*(1-A2) -> 11801531 | H82: =C82*About!$A$118/G82 -> 0.0020388662
B83: IC | C83: 25345 | D83: 250 | E83: =AVERAGE(144,228.1) -> 186.05 | G83: =E83*About!A112*A3/D83 -> 27483802 | H83: =C83*About!$A$118/G83 -> 0.00078136653

Sheet Summary
A1: Unit: $/(BTU/yr) - dollars of capital cost for equipment per BTU consumed annually by that equipment | B1: electricity if | C1: hard coal if | D1: natural gas if | E1: biomass if | F1: petroleum diesel if | G1: heat if | H1: crude oil if | I1: heavy or residual fuel oil if | J1: LPG propane or butane if | K1: hydrogen if
A2: heat below 100 °C | B2: =B3 -> 3.6314489e-05 | C2: =C3 -> 1.9888846e-05 | D2: =D3 -> 6.2918942e-06 | E2: =E3 -> 1.9888846e-05 | F2: =F3 -> 1.3097712e-05 | G2: 0 | H2: =H3 -> 1.3097712e-05 | I2: =I3 -> 1.3097712e-05 | J2: =J3 -> 1.3097712e-05 | K2: =K3 -> 9.4378413e-06
A3: heat 100 to 200 °C | B3: ='Boilers & Heat Pumps'!B15 -> 3.6314489e-05 | C3: ='Boilers & Heat Pumps'!$H$21 -> 1.9888846e-05 | D3: ='Boilers & Heat Pumps'!$H$23 -> 6.2918942e-06 | E3: =C3 -> 1.9888846e-05 | F3: ='Boilers & Heat Pumps'!$H$22 -> 1.3097712e-05 | G3: 0 | H3: =F3 -> 1.3097712e-05 | I3: =F3 -> 1.3097712e-05 | J3: =F3 -> 1.3097712e-05 | K3: ='Boilers & Heat Pumps'!A37 -> 9.4378413e-06
A4: heat 200 to 500 °C | B4: ='NB High Temp'!B93 -> 1.3373592e-05 | C4: ='NB Medium Temp'!D59 -> 2.963048e-05 | D4: ='NB Medium Temp'!D61 -> 2.2152156e-05 | E4: =C4 -> 2.963048e-05 | F4: ='NB Medium Temp'!D60 -> 2.5895356e-05 | G4: 0 | H4: =F4 -> 2.5895356e-05 | I4: =F4 -> 2.5895356e-05 | J4: =D4 -> 2.2152156e-05 | K4: =D4*(K3/D3) -> 3.3228234e-05
A5: heat 500 to 1000 °C | B5: ='NB High Temp'!B94 -> 1.6537985e-05 | C5: ='NB High Temp'!B117 -> 2.0652868e-05 | D5: ='NB High Temp'!D117 -> 1.7959171e-05 | E5: =C5 -> 2.0652868e-05 | F5: ='NB High Temp'!C117 -> 1.8777712e-05 | G5: 0 | H5: =F5 -> 1.8777712e-05 | I5: =F5 -> 1.8777712e-05 | J5: =D5 -> 1.7959171e-05 | K5: ='NB High Temp'!F67 -> 3.2657846e-05
A6: heat above 1000 °C | B6: ='NB High Temp'!F10 -> 0.00017204637 | C6: ='NB High Temp'!E140 -> 4.8979618e-06 | D6: ='NB High Temp'!E141 -> 1.4075502e-05 | E6: =C6 -> 4.8979618e-06 | F6: ='NB High Temp'!E142 -> 1.3887716e-05 | G6: 0 | H6: =F6 -> 1.3887716e-05 | I6: =F6 -> 1.3887716e-05 | J6: =D6 -> 1.4075502e-05 | K6: ='NB High Temp'!F67 -> 3.2657846e-05
A7: cooling | B7: =Cooling!$B$49 -> 4.4520366e-05 | C7: =$D$7 -> 1.808816e-05 | D7: =Cooling!$B$27 -> 1.808816e-05 | E7: =$D$7 -> 1.808816e-05 | F7: =$D$7 -> 1.808816e-05 | G7: 0 | H7: =$D$7 -> 1.808816e-05 | I7: =$D$7 -> 1.808816e-05 | J7: =$D$7 -> 1.808816e-05 | K7: =$D$7*(K3/D3) -> 2.713224e-05
A8: machine drive | B8: ='Machine Drive'!$W$22 -> 2.9652198e-05 | C8: =$F$8 -> 7.0734512e-05 | D8: =$F$8 -> 7.0734512e-05 | E8: =$F$8 -> 7.0734512e-05 | F8: ='Machine Drive'!D38 -> 7.0734512e-05 | G8: 0 | H8: =$F$8 -> 7.0734512e-05 | I8: =$F$8 -> 7.0734512e-05 | J8: =$F$8 -> 7.0734512e-05 | K8: =$F$8 -> 7.0734512e-05
A9: other processes | B9: =Other!E9 -> 7.0401934e-06 | C9: =C4 -> 2.963048e-05 | D9: =Other!B24 -> 2.2284525e-05 | E9: =C9 -> 2.963048e-05 | F9: =F4 -> 2.5895356e-05 | G9: 0 | H9: =F9 -> 2.5895356e-05 | I9: =F9 -> 2.5895356e-05 | J9: =F9 -> 2.5895356e-05 | K9: =D9*(K3/D3) -> 3.3426788e-05
A10: facility HVAC | B10: =B2 -> 3.6314489e-05 | C10: =C2 -> 1.9888846e-05 | D10: =D2 -> 6.2918942e-06 | E10: =E2 -> 1.9888846e-05 | F10: =F2 -> 1.3097712e-05 | G10: 0 | H10: =H2 -> 1.3097712e-05 | I10: =I2 -> 1.3097712e-05 | J10: =J2 -> 1.3097712e-05 | K10: =K2 -> 9.4378413e-06
A11: facility lighting | B11: =Lighting!O23 -> 1.0540698e-05 | C11: =$F$11 -> 9.0753847e-06 | D11: =$F$11 -> 9.0753847e-06 | E11: =$F$11 -> 9.0753847e-06 | F11: =Lighting!I39 -> 9.0753847e-06 | G11: 0 | H11: =$F$11 -> 9.0753847e-06 | I11: =$F$11 -> 9.0753847e-06 | J11: =$F$11 -> 9.0753847e-06 | K11: =$F$11 -> 9.0753847e-06
A12: other nonprocess | B12: =AVERAGE(B2:B11) -> 4.0265487e-05 | C12: =AVERAGE(C2:C11) -> 2.4237638e-05 | D12: =AVERAGE(D2:D11) -> 1.9324509e-05 | E12: =AVERAGE(E2:E11) -> 2.4237638e-05 | F12: =AVERAGE(F2:F11) -> 2.2164733e-05 | G12: 0 | H12: =AVERAGE(H2:H11) -> 2.2164733e-05 | I12: =AVERAGE(I2:I11) -> 2.2164733e-05 | J12: =AVERAGE(J2:J11) -> 2.1727338e-05 | K12: =AVERAGE(K2:K11) -> 2.6722637e-05
A13: Green cells are known explicitly. Orange cells are assumptions based on similar fuel types.
A14: Gray cells are not applicable, either because the energy is already in the form of heat or because the equipmen type cannot use that fuel type.
A42: The data on electric arc furnaces (our model for electric high-temp heat) has been double-checked and seem solid, and there are few other good examples of
A43: fully commercialized, electrified, high-temperature heating equipment. For instance, cement kilns burn coal and steam crackers use natural gas. Other electrical furnaces
A44: exist (like induction furnaces), but electric arc furnaces are likely the most common type and are likely the best choice to use as our model equipment type for high-temp
A45: electrified industrial heating equipment. So we do not consider them to be an outlier - i.e., the higher cost is justified.

Sheet IECCpUAEU
A1: Unit: $/(BTU/yr) in 2012 USD - capital cost per BTU consumed annually, deflated to 2012 USD via CPI-U (see About) | B1: electricity if | C1: hard coal if | D1: natural gas if | E1: biomass if | F1: petroleum diesel if | G1: heat if | H1: crude oil if | I1: heavy or residual fuel oil if | J1: LPG propane or butane if | K1: hydrogen if
A2: heat below 100 °C | B2: =Summary!B2*About!$C$130 -> 2.6579155e-05 | C2: =Summary!C2*About!$C$130 -> 1.4556965e-05 | D2: =Summary!D2*About!$C$130 -> 4.6051381e-06 | E2: =Summary!E2*About!$C$130 -> 1.4556965e-05 | F2: =Summary!F2*About!$C$130 -> 9.5864251e-06 | G2: =Summary!G2*About!$C$130 -> 0 | H2: =Summary!H2*About!$C$130 -> 9.5864251e-06 | I2: =Summary!I2*About!$C$130 -> 9.5864251e-06 | ... K2: =Summary!K2*About!$C$130 -> 6.9077071e-06
A3: heat 100 to 200 °C | B3: =Summary!B3*About!$C$130 -> 2.6579155e-05 | C3: =Summary!C3*About!$C$130 -> 1.4556965e-05 | D3: =Summary!D3*About!$C$130 -> 4.6051381e-06 | E3: =Summary!E3*About!$C$130 -> 1.4556965e-05 | F3: =Summary!F3*About!$C$130 -> 9.5864251e-06 | G3: =Summary!G3*About!$C$130 -> 0 | H3: =Summary!H3*About!$C$130 -> 9.5864251e-06 | I3: =Summary!I3*About!$C$130 -> 9.5864251e-06 | ... K3: =Summary!K3*About!$C$130 -> 6.9077071e-06
A4: heat 200 to 500 °C | B4: =Summary!B4*About!$C$130 -> 9.7883458e-06 | C4: =Summary!C4*About!$C$130 -> 2.1687022e-05 | D4: =Summary!D4*About!$C$130 -> 1.6213517e-05 | E4: =Summary!E4*About!$C$130 -> 2.1687022e-05 | F4: =Summary!F4*About!$C$130 -> 1.8953225e-05 | G4: =Summary!G4*About!$C$126 -> 0 | H4: =Summary!H4*About!$C$130 -> 1.8953225e-05 | I4: =Summary!I4*About!$C$130 -> 1.8953225e-05 | J4: =Summary!J4*About!$C$130 -> 1.6213517e-05 | K4: =Summary!K4*About!$C$130 -> 2.4320276e-05
A5: heat 500 to 1000 °C | B5: =Summary!B5*About!$C$130 -> 1.2104416e-05 | C5: =Summary!C5*About!$C$130 -> 1.5116165e-05 | D5: =Summary!D5*About!$C$130 -> 1.3144605e-05 | E5: =Summary!E5*About!$C$130 -> 1.5116165e-05 | F5: =Summary!F5*About!$C$130 -> 1.3743708e-05 | G5: =Summary!G5*About!$C$130 -> 0 | H5: =Summary!H5*About!$C$130 -> 1.3743708e-05 | I5: =Summary!I5*About!$C$130 -> 1.3743708e-05 | J5: =Summary!J5*About!$C$130 -> 1.3144605e-05 | K5: =Summary!K5*About!$C$127 -> 2.8971124e-05
A6: heat above 1000 °C | B6: =Summary!B6*About!$C$130 -> 0.00012592349 | C6: =Summary!C6*About!$C$130 -> 3.5848966e-06 | D6: =Summary!D6*About!$C$130 -> 1.0302085e-05 | E6: =Summary!E6*About!$C$130 -> 3.5848966e-06 | F6: =Summary!F6*About!$C$130 -> 1.0164641e-05 | G6: =Summary!G6*About!$C$130 -> 0 | H6: =Summary!H6*About!$C$130 -> 1.0164641e-05 | I6: =Summary!I6*About!$C$130 -> 1.0164641e-05 | J6: =Summary!J6*About!$C$130 -> 1.0302085e-05 | K6: =Summary!K6*About!$C$127 -> 2.8971124e-05
A7: cooling | B7: =Summary!B7*About!$C$130 -> 3.2585169e-05 | C7: =Summary!C7*About!$C$130 -> 1.3239014e-05 | D7: =Summary!D7*About!$C$130 -> 1.3239014e-05 | E7: =Summary!E7*About!$C$130 -> 1.3239014e-05 | F7: =Summary!F7*About!$C$130 -> 1.3239014e-05 | G7: =Summary!G7*About!$C$130 -> 0 | H7: =Summary!H7*About!$C$130 -> 1.3239014e-05 | I7: =Summary!I7*About!$C$130 -> 1.3239014e-05 | ... K7: =Summary!K7*About!$C$130 -> 1.985852e-05
A8: machine drive | B8: =Summary!B8*About!$C$130 -> 2.1702918e-05 | C8: =Summary!C8*About!$C$130 -> 5.1771721e-05 | D8: =Summary!D8*About!$C$130 -> 5.1771721e-05 | E8: =Summary!E8*About!$C$130 -> 5.1771721e-05 | F8: =Summary!F8*About!$C$130 -> 5.1771721e-05 | G8: =Summary!G8*About!$C$130 -> 0 | H8: =Summary!H8*About!$C$130 -> 5.1771721e-05 | I8: =Summary!I8*About!$C$130 -> 5.1771721e-05 | ... K8: =Summary!K8*About!$C$130 -> 5.1771721e-05
A9: other processes | B9: =Summary!B9*About!$C$130 -> 5.1528302e-06 | C9: =Summary!C9*About!$C$126 -> 2.8344925e-05 | D9: =Summary!D9*About!$C$124 -> 2.1962823e-05 | E9: =Summary!E9*About!$C$126 -> 2.8344925e-05 | F9: =Summary!F9*About!$C$126 -> 2.4771854e-05 | G9: =Summary!G9*About!$C$130 -> 0 | H9: =Summary!H9*About!$C$126 -> 2.4771854e-05 | I9: =Summary!I9*About!$C$126 -> 2.4771854e-05 | J9: =Summary!J9*About!$C$126 -> 2.4771854e-05 | K9: =Summary!K9*About!$C$124 -> 3.2944234e-05
A10: facility HVAC | B10: =Summary!B10*About!$C$130 -> 2.6579155e-05 | C10: =Summary!C10*About!$C$130 -> 1.4556965e-05 | D10: =Summary!D10*About!$C$130 -> 4.6051381e-06 | E10: =Summary!E10*About!$C$130 -> 1.4556965e-05 | F10: =Summary!F10*About!$C$130 -> 9.5864251e-06 | G10: =Summary!G10*About!$C$130 -> 0 | H10: =Summary!H10*About!$C$130 -> 9.5864251e-06 | I10: =Summary!I10*About!$C$130 -> 9.5864251e-06 | ... K10: =Summary!K10*About!$C$130 -> 6.9077071e-06
A11: facility lighting | B11: =Summary!B11*About!$C$130 -> 7.7149055e-06 | C11: =Summary!C11*About!$C$130 -> 6.6424193e-06 | D11: =Summary!D11*About!$C$130 -> 6.6424193e-06 | E11: =Summary!E11*About!$C$130 -> 6.6424193e-06 | F11: =Summary!F11*About!$C$130 -> 6.6424193e-06 | G11: =Summary!G11*About!$C$130 -> 0 | H11: =Summary!H11*About!$C$130 -> 6.6424193e-06 | I11: =Summary!I11*About!$C$130 -> 6.6424193e-06 | ... K11: =Summary!K11*About!$C$130 -> 6.6424193e-06
A12: other nonprocess | B12: =AVERAGE(B2:B11) -> 2.9470954e-05 | C12: =AVERAGE(C2:C11) -> 1.8405706e-05 | D12: =AVERAGE(D2:D11) -> 1.470916e-05 | E12: =AVERAGE(E2:E11) -> 1.8405706e-05 | F12: =AVERAGE(F2:F11) -> 1.6804586e-05 | G12: =AVERAGE(G2:G11) -> 0 | H12: =AVERAGE(H2:H11) -> 1.6804586e-05 | I12: =AVERAGE(I2:I11) -> 1.6804586e-05 | ... K12: =AVERAGE(K2:K11) -> 2.1420254e-05

Sheet IECCpUAEU-mobile
A1: Unit: $/(BTU/yr) in 2012 USD - capital cost per BTU consumed annually, deflated to 2012 USD via CPI-U (see About)
A2: electricity if | B2: ='Other (mobile)'!A6 -> 0.0031381977
A3: hard coal if | B3: =B6 -> 0.00082719018
A4: natural gas if | B4: =B6 -> 0.00082719018
A5: biomass if | B5: =B6 -> 0.00082719018
A6: petroleum diesel if | B6: ='Other (mobile)'!A5 -> 0.00082719018
A7: heat if | B7: 0
A8: crude oil if | B8: =B6 -> 0.00082719018
A9: heavy or residual fuel oil if | B9: =B6 -> 0.00082719018
A10: LPG propane or butane if | B10: =B6 -> 0.00082719018
A11: hydrogen if | B11: =B6 -> 0.00082719018

Sheet 1.1 Traditional heat pump
A1: Technology | C1: Heat pump, up to 60 °C, Temp lift = 40 K
A2: year | C2: 2025 | D2: 2030 | E2: 2035 | F2: 2040 | G2: 2050 | H2: 2025 | I2: 2025 | J2: 2050 | K2: 2050 | L2: Note | M2: Ref
A3: est | C3: ctrl | D3: ctrl | E3: ctrl | F3: ctrl | G3: ctrl | H3: lower | I3: upper | J3: lower | K3: upper | L3: - | M3: -
A4: cat | B4: par
A5: Energy/technical data
B6: Heat generation capacity for one unit [MW] | C6: 3 | D6: 3 | E6: 3 | F6: 3 | G6: 3 | H6: 0.5 | I6: 5 | J6: 0.5 | K6: 5 | L6: A | M6: [1, 2]
B7: Total efficiency, net [%], nominel load | C7: 5.33 | D7: =C7*1.03 -> 5.4899 | E7: 5.55 | F7: =D7*1.02 -> 5.599698 | G7: =F7*1.01 -> 5.655695 | H7: =C7 -> 5.33 | I7: =C7*1.05 -> 5.5965 | J7: =G7*0.97 -> 5.4860241 | K7: =G7*1.02 -> 5.7688089 | L7: B | M7: [1, 3]
B8: Total efficiency, net [%], annual average | C8: =C7-5% -> 5.28 | D8: =D7-5% -> 5.4399 | E8: =E7-5% -> 5.5 | F8: =F7-5% -> 5.549698 | G8: =G7-5% -> 5.605695 | H8: =H7-5% -> 5.28 | I8: =I7-5% -> 5.5465 | J8: =J7-5% -> 5.4360241 | K8: =K7-5% -> 5.7188089 | L8: B,C
B9: Auxiliary electricity consumption [% of heat gen] | C9: 0.01 | D9: 0.01 | E9: 0.01 | F9: 0.01 | G9: 0.01 | H9: 0.01 | I9: 0.04 | J9: 0.01 | K9: 0.04 | M9: 2
B10: Forced outage [%] | C10: 0 | D10: 0 | E10: 0 | F10: 0 | G10: 0 | H10: 0 | I10: 0.01 | J10: 0 | K10: 0.01 | L10: D | M10: 2
B11: Planned outage [weeks per year] | C11: 1 | D11: 1 | E11: 1 | F11: 1 | G11: 1 | H11: 0.5 | I11: 2 | J11: 0.5 | K11: 2 | M11: 2
B12: Technical lifetime [years] | C12: 25 | D12: 25 | E12: 25 | F12: 25 | G12: 25 | H12: 15 | I12: 40 | J12: 15 | K12: 40 | M12: 2
B13: Construction time [years] | C13: 0.5 | D13: 0.5 | E13: 0.5 | F13: 0.5 | G13: 0.5 | H13: 0.3 | I13: 1 | J13: 0.3 | K13: 1 | M13: 2
A14: Regulation Ability
B15: Minimum load [% of full load] | C15: 0.25 | D15: 0.25 | E15: 0.25 | F15: 0.25 | G15: 0.25 | H15: 0.1 | I15: 0.5 | J15: 0.1 | K15: 0.5 | M15: 2
B16: Warm start-up time [hours] | C16: 0.1 | D16: 0.1 | E16: 0.1 | F16: 0.1 | G16: 0.1 | H16: 0.1 | I16: 0.2 | J16: 0.1 | K16: 0.2 | M16: 2
B17: Cold start-up time [hours] | C17: 1 | D17: 1 | E17: 1 | F17: 1 | G17: 1 | H17: 0.2 | I17: 1 | J17: 0.2 | K17: 1 | M17: 2
A18: Financial data
B19: Nominal investment [M€/MW] | C19: 0.95 | D19: 0.94 | E19: 0.91 | F19: 0.91 | G19: 0.89 | H19: 0.91 | I19: 0.95 | J19: 0.88 | K19: 0.95 | M19: 2
B20: - of which equipment [%] | C20: 0.4 | D20: 0.4 | E20: 0.4 | F20: 0.4 | G20: 0.4 | L20: E | M20: 2
B21: - of which installation and other costs [%] | C21: 0.6 | D21: 0.6 | E21: 0.6 | F21: 0.6 | G21: 0.6 | L21: F | M21: 2
B22: Fixed O&M [€/MJ/s/year] | C22: 2127 | D22: 2095 | E22: 2032 | F22: 2032 | G22: 2001 | H22: 2032 | I22: 2127 | J22: 1970 | K22: 2127 | M22: 2
B23: Variable O&M [€/MWh] | C23: 3.07 | D23: 3.02 | E23: 2.93 | F23: 2.93 | G23: 2.89 | H23: 2.93 | I23: 3.07 | J23: 2.84 | K23: 3.07 | M23: 2
A24: Technology-specific data
B25: Indirect investments cost [M€/MW] | C25: =C19*0.2 -> 0.19 | D25: =D19*0.2 -> 0.188 | E25: =E19*0.2 -> 0.182 | F25: =F19*0.2 -> 0.182 | G25: =G19*0.2 -> 0.178 | L25: H
B26: Non energy gains [M€/MW] | C26: - | D26: - | E26: - | F26: - | G26: -
B27: Startup cost [€/MW/startup] | C27: 10 | D27: 10 | E27: 10 | F27: 10 | G27: 10
B28: Temperature heat source supply [°C] | C28: 30 | D28: 30 | E28: 30 | F28: 30 | G28: 30 | L28: I
B29: Temperature heat source return [°C] | C29: 20 | D29: 20 | E29: 20 | F29: 20 | G29: 20 | L29: I
B30: - Total efficiency, net [%], nominel load. Based on a temperature lift of 50 K, 70°C max | C30: 4.52 | D30: 4.6 | E30: 4.65 | F30: 4.7 | G30: 4.74 | H30: 4.47 | I30: 4.69 | J30: 4.6 | K30: 4.84 | L30: G
B31: - Total efficiency, net [%], nominel load. Based on a temperature lift of 60 K, 80°C max | C31: 3.95 | D31: 4 | E31: 4.04 | F31: 4.08 | G31: 4.12 | H31: 3.88 | I31: 4.07 | J31: 3.99 | K31: 4.2 | L31: G
B32: Cooling generation capacity for one unit [MW] | C32: - | D32: - | E32: - | F32: - | G32: -
A35: Notes:
A36: A | B36: 0,5-5 MW
A37: B | B37: Estimated based on cases presented in [3]
A38: C | B38: Based on lost produktion during startup/shutdown
A39: D | B39: May vary depending on heat source availability
A40: E | B40: Very individual, can vary ÷ 20 %
A41: F | B41: Very individual, can vary + 20 %
A42: G | B42: Based on the old technology catalogue on process heat from 2020.
...

Sheet 1.2 heat_cool hp 80 C 75 K 
A1: Technology | C1: Combined heating and cooling heat pump, up to 80 °C, Temp lift = 75 K
A2: year | C2: 2025 | D2: 2030 | E2: 2035 | F2: 2040 | G2: 2050 | H2: 2025 | I2: 2025 | J2: 2050 | K2: 2050 | L2: Note | M2: Ref
A3: est | C3: ctrl | D3: ctrl | E3: ctrl | F3: ctrl | G3: ctrl | H3: lower | I3: upper | J3: lower | K3: upper | L3: - | M3: -
A4: cat | B4: par
A5: Energy/technical data
B6: Heat generation capacity for one unit [MW] | C6: 3 | D6: 3 | E6: 3 | F6: 3 | G6: 3 | H6: 0.5 | I6: 5 | J6: 0.5 | K6: 5 | L6: A | M6: [1, 2]
B7: Total efficiency, net [%], nominel load | C7: 3.35 | D7: 3.43 | E7: 3.48 | F7: =D7*1.02 -> 3.4986 | G7: =F7*1.01 -> 3.533586 | H7: 3.33 | I7: =C7*1.05 -> 3.5175 | J7: =G7*0.97 -> 3.4275784 | K7: =G7*1.02 -> 3.6042577 | L7: B | M7: [1, 3]
B8: Total efficiency, net [%], annual average | C8: =C7-5% -> 3.3 | D8: =D7-5% -> 3.38 | E8: =E7-5% -> 3.43 | F8: =F7-5% -> 3.4486 | G8: =G7-5% -> 3.483586 | H8: =H7-5% -> 3.28 | I8: =I7-5% -> 3.4675 | J8: =J7-5% -> 3.3775784 | K8: =K7-5% -> 3.5542577 | L8: B,C
