Workbook
Name CH4_Ar4_to_AR5: #REF!
Name CH4_to_CO2e: '[1]Cross-Page Data'!$C$12
Name dollars_2009_2012: [2]About!$B$90
Name gal_per_barrel: [3]About!$A$63
Name HHV_Adjust: [4]About!$A$203
Name IQ_CH: 110000
Name IQ_CQ: 5000
Name IQ_CY: 10000
Name IQ_DAILY: 500000
Name IQ_FH: 100000
Name IQ_FQ: 500
Name IQ_FY: 1000
Name IQ_LTM: 2000
Name IQ_MONTH: 15000
Name IQ_NTM: 6000
Name IQ_WEEK: 50000
Name IQ_YTD: 3000
Name metricton_to_shortton: [5]Overview!$B$19
Name million: [5]Overview!$B$22
Name N2O_to_CO2e: '[1]Cross-Page Data'!$C$13
Name unit_conv: [6]About!$A$120

Sheet About
A1: BLAPE BAU LULUCF Anthropogenic Pollutant Emissions
A3: Source: | B3: pre-IRA BAU
B4: US EPA
B5: 2024
B6: Inventory of US Greenhouse Gas Emissions Emissions and Sinks
B7: https://www.epa.gov/system/files/documents/2023-04/US-GHG-Inventory-2023-Main-Text.pdf
B8: Table 6-1
B10: IRA impacts
B11: EPA
B12: 2024
B13: Forestry and Agriculture Sector Mitigation Analysis
B14: https://www.epa.gov/climate-change/climate-economic-analysis#Forestry%20and%20Agriculture%20Mitigation
B15: Figure 3-8
A17: CH4 GWP | B17: 28
A18: N2O GWP | B18: 265
A20: Notes
A21: We project the 1990-2020 trend forward to 2050.
A23: We also adjust BAU LULUCF emissions by our calculated forestry impacts
A24: of the Inflation Reduction Act (see tab for explanation of methodology).
A27: 2020 to 2012 USD | B27: 0.88711067

Sheet Calcs
A1: Excerpt from Table 3:
A2: Emissions (Tg CO2e)
B3: 2020 | C3: 2021 | D3: 2022 | E3: 2023 | F3: 2024 | G3: 2025 | H3: 2026 | I3: 2027 | J3: 2028 | K3: 2029 | L3: 2030 | M3: 2031 | N3: 2032 | O3: 2033 | P3: 2034 | Q3: 2035 | R3: 2036 | S3: 2037 | T3: 2038 | U3: 2039 | V3: 2040 | W3: 2041 | X3: 2042 | Y3: 2043 | Z3: 2044 | AA3: 2045 | AB3: 2046 | AC3: 2047 | AD3: 2048 | AE3: 2049 | AF3: 2050
A4: Land Use and Forestry (CO2) | B4: ='EPA Table 6-1'!AF42 -> -972.8 | C4: ='EPA Table 6-1'!AG42 -> -983.4 | D4: ='EPA Table 6-1'!AH42 -> -921.8 | E4: {=TREND($Y13:$AH13,$Y$12:$AH$12,E$3)} -> -956.47333 | F4: {=TREND($Y13:$AH13,$Y$12:$AH$12,F$3)} -> -956.38485 | G4: {=TREND($Y13:$AH13,$Y$12:$AH$12,G$3)} -> -956.29636 | H4: {=TREND($Y13:$AH13,$Y$12:$AH$12,H$3)} -> -956.20788 | I4: {=TREND($Y13:$AH13,$Y$12:$AH$12,I$3)} -> -956.11939 | J4: {=TREND($Y13:$AH13,$Y$12:$AH$12,J$3)} -> -956.03091 | K4: {=TREND($Y13:$AH13,$Y$12:$AH$12,K$3)} -> -955.94242 | L4: {=TREND($Y13:$AH13,$Y$12:$AH$12,L$3)} -> -955.85394 | ... AF4: {=TREND($Y13:$AH13,$Y$12:$AH$12,AF$3)} -> -954.08424
A5: Land Use and Forestry (CH4) | B5: ='EPA Table 6-1'!AF40 -> 59.3 | C5: ='EPA Table 6-1'!AG40 -> 62.1 | D5: ='EPA Table 6-1'!AH40 -> 58.4 | E5: {=TREND($X14:$AG14,$X$12:$AG$12,E$3)} -> 59.389697 | F5: {=TREND($X14:$AG14,$X$12:$AG$12,F$3)} -> 59.832727 | G5: {=TREND($X14:$AG14,$X$12:$AG$12,G$3)} -> 60.275758 | H5: {=TREND($X14:$AG14,$X$12:$AG$12,H$3)} -> 60.718788 | I5: {=TREND($X14:$AG14,$X$12:$AG$12,I$3)} -> 61.161818 | J5: {=TREND($X14:$AG14,$X$12:$AG$12,J$3)} -> 61.604848 | K5: {=TREND($X14:$AG14,$X$12:$AG$12,K$3)} -> 62.047879 | L5: {=TREND($X14:$AG14,$X$12:$AG$12,L$3)} -> 62.490909 | ... AF5: {=TREND($X14:$AG14,$X$12:$AG$12,AF$3)} -> 71.351515
A6: Land Use and Forestry (N2O) | B6: ='EPA Table 6-1'!AF41 -> 9.1 | C6: ='EPA Table 6-1'!AG41 -> 10.7 | D6: ='EPA Table 6-1'!AH41 -> 9.1 | E6: {=TREND($X15:$AG15,$X$12:$AG$12,E$3)} -> 9.2248485 | F6: {=TREND($X15:$AG15,$X$12:$AG$12,F$3)} -> 9.4563636 | G6: {=TREND($X15:$AG15,$X$12:$AG$12,G$3)} -> 9.6878788 | H6: {=TREND($X15:$AG15,$X$12:$AG$12,H$3)} -> 9.9193939 | I6: {=TREND($X15:$AG15,$X$12:$AG$12,I$3)} -> 10.150909 | J6: {=TREND($X15:$AG15,$X$12:$AG$12,J$3)} -> 10.382424 | K6: {=TREND($X15:$AG15,$X$12:$AG$12,K$3)} -> 10.613939 | L6: {=TREND($X15:$AG15,$X$12:$AG$12,L$3)} -> 10.845455 | ... AF6: {=TREND($X15:$AG15,$X$12:$AG$12,AF$3)} -> 15.475758
A9: We assume that all of the sequestered CO2e in the Land Use and Forestry sector is in the form of
A10: CO2, not other GHGs.
AG11: Start Year Forecast
A12: EPS | B12: 1990 | C12: 1991 | D12: 1992 | E12: 1993 | F12: 1994 | G12: 1995 | H12: 1996 | I12: 1997 | J12: 1998 | K12: 1999 | L12: 2000 | M12: 2001 | N12: 2002 | O12: 2003 | P12: 2004 | Q12: 2005 | R12: 2006 | S12: 2007 | T12: 2008 | U12: 2009 | V12: 2010 | W12: 2011 | X12: 2012 | Y12: 2013 | Z12: 2014 | AA12: 2015 | AB12: 2016 | AC12: 2017 | AD12: 2018 | AE12: 2019 | AF12: 2020 | AG12: 2021 | AH12: 2022
A13: CO2 | B13: ='EPA Table 6-1'!B42 -> -1034.7 | C13: ='EPA Table 6-1'!C42 -> -1045.6 | D13: ='EPA Table 6-1'!D42 -> -1061.1 | E13: ='EPA Table 6-1'!E42 -> -1045.7 | F13: ='EPA Table 6-1'!F42 -> -1062.7 | G13: ='EPA Table 6-1'!G42 -> -1033.8 | H13: ='EPA Table 6-1'!H42 -> -1067.8 | I13: ='EPA Table 6-1'!I42 -> -1038.3 | ... AH13: ='EPA Table 6-1'!AH42 -> -921.8
A14: CH4 | B14: ='EPA Table 6-1'!B40 -> 53.1 | C14: ='EPA Table 6-1'!C40 -> 52.2 | D14: ='EPA Table 6-1'!D40 -> 50.5 | E14: ='EPA Table 6-1'!E40 -> 50.7 | F14: ='EPA Table 6-1'!F40 -> 52.6 | G14: ='EPA Table 6-1'!G40 -> 50.1 | H14: ='EPA Table 6-1'!H40 -> 51.9 | I14: ='EPA Table 6-1'!I40 -> 49.7 | ... AH14: ='EPA Table 6-1'!AH40 -> 58.4
A15: N2O | B15: ='EPA Table 6-1'!B41 -> 4.8 | C15: ='EPA Table 6-1'!C41 -> 4.4 | D15: ='EPA Table 6-1'!D41 -> 3.3 | E15: ='EPA Table 6-1'!E41 -> 3.7 | F15: ='EPA Table 6-1'!F41 -> 4.8 | G15: ='EPA Table 6-1'!G41 -> 3.4 | H15: ='EPA Table 6-1'!H41 -> 4.8 | I15: ='EPA Table 6-1'!I41 -> 3.4 | ... AH15: ='EPA Table 6-1'!AH41 -> 9.1

Sheet EPA Table 6-1
A1: Table 6-1: Emissions and Removals (Net Flux) from Land Use, Land-Use Change, and Forestry (MMT CO2 Eq.)
A3: Land-Use Category | B3: 1990 | C3: 1991 | D3: 1992 | E3: 1993 | F3: 1994 | G3: 1995 | H3: 1996 | I3: 1997 | J3: 1998 | K3: 1999 | L3: 2000 | M3: 2001 | N3: 2002 | O3: 2003 | P3: 2004 | Q3: 2005 | R3: 2006 | S3: 2007 | T3: 2008 | U3: 2009 | V3: 2010 | W3: 2011 | X3: 2012 | Y3: 2013 | Z3: 2014 | AA3: 2015 | AB3: 2016 | AC3: 2017 | AD3: 2018 | AE3: 2019 | AF3: 2020 | AG3: 2021 | AH3: 2022
A4: Forest Land Remaining Forest Land | B4: -968.8 | C4: -971.7 | D4: -977.8 | E4: -972.8 | F4: -963.1 | G4: -957.4 | H4: -956 | I4: -955.7 | J4: -950.4 | K4: -933.9 | L4: -908.4 | M4: -921.3 | N4: -868.1 | O4: -907.5 | P4: -805.6 | Q4: -860 | R4: -897.3 | S4: -863.6 | T4: -848.4 | U4: -807.9 | V4: -852.1 | W4: -860.9 | X4: -857.3 | Y4: -840.4 | Z4: -874.8 | AA4: -763 | AB4: -881.5 | AC4: -875 | AD4: -863.4 | AE4: -807 | AF4: -846.3 | AG4: -823.8 | AH4: -771.7
A5: Changes in Forest Carbon Stocksa | B5: -974.8 | C5: -976.3 | D5: -979.2 | E5: -974.8 | F5: -968 | G5: -958.7 | H5: -959.7 | I5: -956.7 | J5: -952.7 | K5: -939.5 | L5: -918.6 | M5: -925.5 | N5: -883.2 | O5: -917.4 | P5: -829.8 | Q5: -876 | R5: -905.6 | S5: -876.2 | T5: -855.7 | U5: -819.1 | V5: -855.7 | W5: -867.9 | X5: -866.8 | Y5: -851.5 | Z5: -879.4 | AA5: -786.9 | AB5: -886.1 | AC5: -887.9 | AD5: -873.5 | AE5: -813.2 | AF5: -862 | AG5: -844.2 | AH5: -787
A6: Non-CO2 Emissions from Forest Firesb | B6: 5.8 | C6: 4.5 | D6: 1.3 | E6: 1.8 | F6: 4.7 | G6: 1 | H6: 3.3 | I6: 0.6 | J6: 1.8 | K6: 5 | L6: 9.8 | M6: 3.7 | N6: 14.5 | O6: 9.4 | P6: 23.8 | Q6: 15.5 | R6: 7.8 | S6: 12.1 | T6: 6.9 | U6: 10.8 | V6: 3.1 | W6: 6.5 | X6: 9 | Y6: 10.6 | Z6: 4.1 | AA6: 23.3 | AB6: 4.1 | AC6: 12.4 | AD6: 9.7 | AE6: 5.7 | AF6: 15.3 | AG6: 19.9 | AH6: 14.8
A7: N2O Emissions from Forest Soilsc | B7: 0.1 | C7: 0.1 | D7: 0.1 | E7: 0.1 | F7: 0.2 | G7: 0.2 | H7: 0.3 | I7: 0.4 | J7: 0.4 | K7: 0.5 | L7: 0.5 | M7: 0.5 | N7: 0.5 | O7: 0.5 | P7: 0.4 | Q7: 0.4 | R7: 0.4 | S7: 0.4 | T7: 0.4 | U7: 0.4 | V7: 0.4 | W7: 0.4 | X7: 0.4 | Y7: 0.4 | Z7: 0.4 | AA7: 0.4 | AB7: 0.4 | AC7: 0.4 | AD7: 0.4 | AE7: 0.4 | AF7: 0.4 | AG7: 0.4 | AH7: 0.4
A8: Non-CO2 Emissions from Drained Organic Soilsd | B8: 0.1 | C8: 0.1 | D8: 0.1 | E8: 0.1 | F8: 0.1 | G8: 0.1 | H8: 0.1 | I8: 0.1 | J8: 0.1 | K8: 0.1 | L8: 0.1 | M8: 0.1 | N8: 0.1 | O8: 0.1 | P8: 0.1 | Q8: 0.1 | R8: 0.1 | S8: 0.1 | T8: 0.1 | U8: 0.1 | V8: 0.1 | W8: 0.1 | X8: 0.1 | Y8: 0.1 | Z8: 0.1 | AA8: 0.1 | AB8: 0.1 | AC8: 0.1 | AD8: 0.1 | AE8: 0.1 | AF8: 0.1 | AG8: 0.1 | AH8: 0.1
A9: Land Converted to Forest Land | B9: -100.2 | C9: -100.1 | D9: -100 | E9: -100 | F9: -100 | G9: -100.1 | H9: -100.1 | I9: -100 | J9: -100.1 | K9: -100.1 | L9: -100.1 | M9: -100.1 | N9: -100.1 | O9: -100.1 | P9: -100.1 | Q9: -100.2 | R9: -100.2 | S9: -100.2 | T9: -100.2 | U9: -100.2 | V9: -100.2 | W9: -100.2 | X9: -100.2 | Y9: -100.3 | Z9: -100.3 | AA9: -100.3 | AB9: -100.4 | AC9: -100.4 | AD9: -100.4 | AE9: -100.3 | AF9: -100.3 | AG9: -100.3 | AH9: -100.3
A10: Changes in Forest Carbon Stockse | B10: -100.2 | C10: -100.1 | D10: -100 | E10: -100 | F10: -100 | G10: -100.1 | H10: -100.1 | I10: -100 | J10: -100.1 | K10: -100.1 | L10: -100.1 | M10: -100.1 | N10: -100.1 | O10: -100.1 | P10: -100.1 | Q10: -100.2 | R10: -100.2 | S10: -100.2 | T10: -100.2 | U10: -100.2 | V10: -100.2 | W10: -100.2 | X10: -100.2 | Y10: -100.3 | Z10: -100.3 | AA10: -100.3 | AB10: -100.4 | AC10: -100.4 | AD10: -100.4 | AE10: -100.3 | AF10: -100.3 | AG10: -100.3 | AH10: -100.3
A11: Cropland Remaining Cropland | B11: -5 | C11: -18.6 | D11: -26.7 | E11: -13.6 | F11: -21.5 | G11: -18.2 | H11: -38.2 | I11: -35 | J11: -30.4 | K11: -32.2 | L11: -38 | M11: -35.8 | N11: -38.1 | O11: -29 | P11: -33.7 | Q11: -31.6 | R11: -28.3 | S11: -27 | T11: -33.8 | U11: -15.6 | V11: -19.9 | W11: -38.5 | X11: -27.1 | Y11: -16 | Z11: -22.4 | AA11: -24 | AB11: -22.5 | AC11: -18.8 | AD11: -17.8 | AE11: -19.4 | AF11: -8.8 | AG11: -32 | AH11: -31.7
A12: Changes in Mineral and Organic Soil Carbon Stocks | B12: -5 | C12: -18.6 | D12: -26.7 | E12: -13.6 | F12: -21.5 | G12: -18.2 | H12: -38.2 | I12: -35 | J12: -30.4 | K12: -32.2 | L12: -38 | M12: -35.8 | N12: -38.1 | O12: -29 | P12: -33.7 | Q12: -31.6 | R12: -28.3 | S12: -27 | T12: -33.8 | U12: -15.6 | V12: -19.9 | W12: -38.5 | X12: -27.1 | Y12: -16 | Z12: -22.4 | AA12: -24 | AB12: -22.5 | AC12: -18.8 | AD12: -17.8 | AE12: -19.4 | AF12: -8.8 | AG12: -32 | AH12: -31.7
A13: Land Converted to Cropland | B13: 45.4 | C13: 46.6 | D13: 43.2 | E13: 40.7 | F13: 40.7 | G13: 42.7 | H13: 40.4 | I13: 40.7 | J13: 38.5 | K13: 40.9 | L13: 37.4 | M13: 36 | N13: 35.7 | O13: 35.8 | P13: 34.6 | Q13: 34.5 | R13: 32.4 | S13: 33.6 | T13: 30.3 | U13: 30.9 | V13: 32.3 | W13: 29.6 | X13: 32 | Y13: 33.5 | Z13: 32 | AA13: 33.3 | AB13: 34.1 | AC13: 33.2 | AD13: 31.9 | AE13: 31.4 | AF13: 29.3 | AG13: 34.9 | AH13: 35.1
A14: Changes in all Ecosystem Carbon Stocksf | B14: 45.4 | C14: 46.6 | D14: 43.2 | E14: 40.7 | F14: 40.7 | G14: 42.7 | H14: 40.4 | I14: 40.7 | J14: 38.5 | K14: 40.9 | L14: 37.4 | M14: 36 | N14: 35.7 | O14: 35.8 | P14: 34.6 | Q14: 34.5 | R14: 32.4 | S14: 33.6 | T14: 30.3 | U14: 30.9 | V14: 32.3 | W14: 29.6 | X14: 32 | Y14: 33.5 | Z14: 32 | AA14: 33.3 | AB14: 34.1 | AC14: 33.2 | AD14: 31.9 | AE14: 31.4 | AF14: 29.3 | AG14: 34.9 | AH14: 35.1
... A21: Changes in Organic Soil Carbon Stocks in Peatlands | B21: 1.1 | C21: 1 | D21: 0.9 | E21: 1 | F21: 0.9 | G21: 1.1 | H21: 0.9 | I21: 1.1 | J21: 1.1 | K21: 1.2 | L21: 1.3 | M21: 1.2 | N21: 1 | O21: 1 | P21: 1.2 | Q21: 1.1 | R21: 0.9 | S21: 1 | T21: 1 | U21: 1 | V21: 1 | W21: 0.9 | X21: 0.8 | Y21: 0.8 | Z21: 0.8 | AA21: 0.8 | AB21: 0.7 | AC21: 0.8 | AD21: 0.7 | AE21: 0.6 | AF21: 0.6 | AG21: 0.5 | AH21: 0.6
A22: Non-CO2 Emissions from Peatlands Remaining Peatlands | B22: + | C22: + | D22: + | E22: + | F22: + | G22: + | H22: + | I22: + | J22: + | K22: + | L22: + | M22: + | N22: + | O22: + | P22: + | Q22: + | R22: + | S22: + | T22: + | U22: + | V22: + | W22: + | X22: + | Y22: + | Z22: + | AA22: + | AB22: + | AC22: + | AD22: + | AE22: + | AF22: + | AG22: + | AH22: +
A23: Changes in Biomass, DOM, and Soil Carbon Stocks in Coastal Wetlands | B23: -10.8 | C23: -10.8 | D23: -10.8 | E23: -10.8 | F23: -10.8 | G23: -10.8 | H23: -10.8 | I23: -10.8 | J23: -10.8 | K23: -10.8 | L23: -10.8 | M23: -10.1 | N23: -10.1 | O23: -10.1 | P23: -10.1 | Q23: -10.1 | R23: -1.2 | S23: -0.9 | T23: -0.9 | U23: -0.9 | V23: -0.8 | W23: -10.8 | X23: -11.1 | Y23: -11.1 | Z23: -11.1 | AA23: -11.1 | AB23: -11.1 | AC23: -11.1 | AD23: -11.1 | AE23: -11.1 | AF23: -11.1 | AG23: -11.1 | AH23: -11.1
A24: CH4 Emissions from Coastal Wetlands Remaining Coastal Wetlands | B24: 4.2 | C24: 4.2 | D24: 4.2 | E24: 4.2 | F24: 4.2 | G24: 4.2 | H24: 4.2 | I24: 4.2 | J24: 4.2 | K24: 4.3 | L24: 4.3 | M24: 4.3 | N24: 4.3 | O24: 4.2 | P24: 4.2 | Q24: 4.2 | R24: 4.2 | S24: 4.2 | T24: 4.2 | U24: 4.2 | V24: 4.2 | W24: 4.2 | X24: 4.2 | Y24: 4.2 | Z24: 4.3 | AA24: 4.3 | AB24: 4.3 | AC24: 4.3 | AD24: 4.3 | AE24: 4.3 | AF24: 4.3 | AG24: 4.3 | AH24: 4.3
A25: N2O Emissions from Coastal Wetlands Remaining Coastal Wetlands | B25: 0.1 | C25: 0.1 | D25: 0.1 | E25: 0.1 | F25: 0.1 | G25: 0.1 | H25: 0.1 | I25: 0.2 | J25: 0.2 | K25: 0.2 | L25: 0.2 | M25: 0.2 | N25: 0.2 | O25: 0.2 | P25: 0.2 | Q25: 0.2 | R25: 0.2 | S25: 0.2 | T25: 0.2 | U25: 0.1 | V25: 0.2 | W25: 0.1 | X25: 0.1 | Y25: 0.1 | Z25: 0.1 | AA25: 0.1 | AB25: 0.1 | AC25: 0.1 | AD25: 0.1 | AE25: 0.1 | AF25: 0.1 | AG25: 0.1 | AH25: 0.1
A26: CH4 Emissions from Flooded Land Remaining Flooded Land | B26: 42.3 | C26: 42.4 | D26: 42.5 | E26: 42.7 | F26: 42.8 | G26: 42.9 | H26: 43 | I26: 43.1 | J26: 43.3 | K26: 43.5 | L26: 43.6 | M26: 43.8 | N26: 43.9 | O26: 43.9 | P26: 43.9 | Q26: 44 | R26: 44 | S26: 44 | T26: 44.1 | U26: 44.1 | V26: 44.1 | W26: 44.2 | X26: 44.2 | Y26: 44.2 | Z26: 44.2 | AA26: 44.2 | AB26: 44.2 | AC26: 44.2 | AD26: 44.2 | AE26: 44.2 | AF26: 44.2 | AG26: 44.2 | AH26: 44.2
A27: Land Converted to Wetlands | B27: 7.2 | C27: 6.8 | D27: 6.5 | E27: 5.9 | F27: 5.4 | G27: 5 | H27: 4.7 | I27: 4.4 | J27: 3.9 | K27: 3.1 | L27: 2.9 | M27: 2.3 | N27: 2 | O27: 1.9 | P27: 1.8 | Q27: 1.8 | R27: 1.6 | S27: 1.6 | T27: 1.2 | U27: 1.2 | V27: 1.1 | W27: 0.6 | X27: 0.6 | Y27: 0.5 | Z27: 0.5 | AA27: 0.8 | AB27: 0.8 | AC27: 0.8 | AD27: 0.7 | AE27: 0.7 | AF27: 0.7 | AG27: 0.7 | AH27: 0.7
A28: Changes in Biomass, DOM, and Soil Carbon Stocks in Land Converted to Coastal Wetlands | B28: 0.5 | C28: 0.5 | D28: 0.5 | E28: 0.5 | F28: 0.5 | G28: 0.5 | H28: 0.5 | I28: 0.5 | J28: 0.5 | K28: 0.5 | L28: 0.5 | M28: 0.5 | N28: 0.5 | O28: 0.5 | P28: 0.5 | Q28: 0.5 | R28: 0.5 | S28: 0.5 | T28: 0.5 | U28: 0.5 | V28: 0.5 | W28: (+) | X28: (+) | Y28: (+) | Z28: (+) | AA28: (+) | AB28: (+) | AC28: (+) | AD28: (+) | AE28: (+) | AF28: (+) | AG28: (+) | AH28: (+)
A29: CH4 Emissions from Land Converted to Coastal Wetlands | B29: 0.3 | C29: 0.3 | D29: 0.3 | E29: 0.3 | F29: 0.3 | G29: 0.3 | H29: 0.3 | I29: 0.3 | J29: 0.3 | K29: 0.3 | L29: 0.3 | M29: 0.3 | N29: 0.3 | O29: 0.3 | P29: 0.3 | Q29: 0.3 | R29: 0.3 | S29: 0.3 | T29: 0.3 | U29: 0.3 | V29: 0.3 | W29: 0.3 | X29: 0.3 | Y29: 0.3 | Z29: 0.2 | AA29: 0.2 | AB29: 0.2 | AC29: 0.2 | AD29: 0.2 | AE29: 0.2 | AF29: 0.2 | AG29: 0.2 | AH29: 0.2
A30: Changes in Land Converted to Flooded Land | B30: 3.6 | C30: 3.4 | D30: 3.2 | E30: 2.8 | F30: 2.6 | G30: 2.3 | H30: 2.2 | I30: 2 | J30: 1.8 | K30: 1.3 | L30: 1.2 | M30: 0.8 | N30: 0.7 | O30: 0.7 | P30: 0.6 | Q30: 0.6 | R30: 0.5 | S30: 0.5 | T30: 0.3 | U30: 0.2 | V30: 0.2 | W30: 0.2 | X30: 0.2 | Y30: 0.2 | Z30: 0.2 | AA30: 0.4 | AB30: 0.3 | AC30: 0.3 | AD30: 0.3 | AE30: 0.3 | AF30: 0.3 | AG30: 0.3 | AH30: 0.3
A31: CH4 Emissions from Land Converted to Flooded Land | B31: 2.9 | C31: 2.7 | D31: 2.5 | E31: 2.3 | F31: 2.1 | G31: 1.9 | H31: 1.8 | I31: 1.6 | J31: 1.4 | K31: 1 | L31: 0.9 | M31: 0.7 | N31: 0.5 | O31: 0.5 | P31: 0.4 | Q31: 0.4 | R31: 0.4 | S31: 0.4 | T31: 0.2 | U31: 0.2 | V31: 0.2 | W31: 0.2 | X31: 0.2 | Y31: 0.1 | Z31: 0.1 | AA31: 0.3 | AB31: 0.3 | AC31: 0.2 | AD31: 0.2 | AE31: 0.2 | AF31: 0.2 | AG31: 0.2 | AH31: 0.2
A32: Settlements Remaining Settlements | B32: -109.1 | C32: -109.7 | D32: -107.6 | E32: -106.5 | F32: -104.8 | G32: -104.3 | H32: -105.3 | I32: -105.7 | J32: -107.8 | K32: -110.3 | L32: -111.1 | M32: -112.8 | N32: -112.1 | O32: -113 | P32: -113.9 | Q32: -115.2 | R32: -115.8 | S32: -117 | T32: -120.2 | U32: -122.2 | V32: -123.5 | W32: -123.8 | X32: -123.9 | Y32: -125.2 | Z32: -126.2 | AA32: -126 | AB32: -125.6 | AC32: -130.7 | AD32: -131 | AE32: -131.5 | AF32: -131.8 | AG32: -132.3 | AH32: -132.3
A33: Changes in Organic Soil Carbon Stocks | B33: 9.9 | C33: 9.9 | D33: 9.9 | E33: 9.9 | F33: 9.8 | G33: 9.9 | H33: 9.9 | I33: 9.8 | J33: 9.8 | K33: 9.8 | L33: 9.8 | M33: 9.4 | N33: 9.4 | O33: 9.6 | P33: 9.8 | Q33: 10.1 | R33: 10.3 | S33: 10.6 | T33: 10.8 | U33: 11 | V33: 11.4 | W33: 11.6 | X33: 11.9 | Y33: 12.3 | Z33: 12.8 | AA33: 13.1 | AB33: 13.5 | AC33: 13.9 | AD33: 14.4 | AE33: 14.6 | AF33: 15.1 | AG33: 15.4 | AH33: 15.4
A34: Changes in Settlement Tree Carbon Stocks | B34: -96.6 | C34: -97.7 | D34: -98.7 | E34: -100.2 | F34: -101.6 | G34: -103.2 | H34: -104.8 | I34: -106.3 | J34: -107.5 | K34: -108.9 | L34: -110.1 | M34: -111.2 | N34: -112.1 | O34: -113.8 | P34: -115.5 | Q34: -117 | R34: -118.5 | S34: -120 | T34: -121.6 | U34: -123 | V34: -124.4 | W34: -125.6 | X34: -126.4 | Y34: -127.8 | Z34: -129.1 | AA34: -130.2 | AB34: -131.4 | AC34: -133.2 | AD34: -134.4 | AE34: -135.6 | AF34: -136.7 | AG34: -137.8 | AH34: -138.5
A35: N2O Emissions from Settlement Soilsh | B35: 2.1 | C35: 2.1 | D35: 2.3 | E35: 2.5 | F35: 2.5 | G35: 2.5 | H35: 2.6 | I35: 2.5 | J35: 2.1 | K35: 2.2 | L35: 2.6 | M35: 2.6 | N35: 2.3 | O35: 2.4 | P35: 3.1 | Q35: 3.1 | R35: 3.2 | S35: 3.2 | T35: 3.2 | U35: 3 | V35: 2.3 | W35: 2.5 | X35: 2.3 | Y35: 2.4 | Z35: 2.4 | AA35: 2.3 | AB35: 2.3 | AC35: 2.4 | AD35: 2.4 | AE35: 2.5 | AF35: 2.5 | AG35: 2.5 | AH35: 2.5
A36: Changes in Yard Trimming and Food Scrap Carbon Stocks in Landfills | B36: -24.5 | C36: -24 | D36: -21 | E36: -18.6 | F36: -15.5 | G36: -13.5 | H36: -13 | I36: -11.8 | J36: -12.2 | K36: -13.4 | L36: -13.4 | M36: -13.6 | N36: -11.8 | O36: -11.3 | P36: -11.4 | Q36: -11.4 | R36: -10.7 | S36: -10.7 | T36: -12.6 | U36: -13.3 | V36: -12.7 | W36: -12.3 | X36: -11.7 | Y36: -12.1 | Z36: -12.3 | AA36: -11.1 | AB36: -10 | AC36: -13.8 | AD36: -13.4 | AE36: -13.1 | AF36: -12.8 | AG36: -12.5 | AH36: -11.8
A37: Land Converted to Settlements | B37: 57.2 | C37: 58.6 | D37: 59.9 | E37: 61.6 | F37: 63.2 | G37: 64.9 | H37: 66.7 | I37: 68.6 | J37: 70.3 | K37: 71.9 | L37: 73.7 | M37: 75.1 | N37: 76.1 | O37: 76.6 | P37: 76.9 | Q37: 77.1 | R37: 77.1 | S37: 77.3 | T37: 77.2 | U37: 77 | V37: 76.7 | W37: 76.3 | X37: 75.9 | Y37: 75.3 | Z37: 74.8 | AA37: 74 | AB37: 73 | AC37: 72.6 | AD37: 71.4 | AE37: 70.2 | AF37: 68.8 | AG37: 68.2 | AH37: 68.2
A38: Changes in all Ecosystem Carbon Stocksf | B38: 57.2 | C38: 58.6 | D38: 59.9 | E38: 61.6 | F38: 63.2 | G38: 64.9 | H38: 66.7 | I38: 68.6 | J38: 70.3 | K38: 71.9 | L38: 73.7 | M38: 75.1 | N38: 76.1 | O38: 76.6 | P38: 76.9 | Q38: 77.1 | R38: 77.1 | S38: 77.3 | T38: 77.2 | U38: 77 | V38: 76.7 | W38: 76.3 | X38: 75.9 | Y38: 75.3 | Z38: 74.8 | AA38: 74 | AB38: 73 | AC38: 72.6 | AD38: 71.4 | AE38: 70.2 | AF38: 68.8 | AG38: 68.2 | AH38: 68.2
A39: LULUCF Emissionsi | B39: 58 | C39: 56.6 | D39: 53.7 | E39: 54.4 | F39: 57.4 | G39: 53.5 | H39: 56.6 | I39: 53.1 | J39: 54.1 | K39: 57.9 | L39: 63.1 | M39: 56.4 | N39: 66.9 | O39: 61.9 | P39: 76.7 | Q39: 68.9 | R39: 61.9 | S39: 65.9 | T39: 60.3 | U39: 64.1 | V39: 55.2 | W39: 60.1 | X39: 62.1 | Y39: 62.7 | Z39: 56.7 | AA39: 76 | AB39: 57 | AC39: 65.9 | AD39: 62.8 | AE39: 58 | AF39: 68.4 | AG39: 72.9 | AH39: 67.6
A40: CH4 | B40: 53.1 | C40: 52.2 | D40: 50.5 | E40: 50.7 | F40: 52.6 | G40: 50.1 | H40: 51.9 | I40: 49.7 | J40: 50.5 | K40: 52.5 | L40: 55.7 | M40: 51.5 | N40: 58.1 | O40: 55.1 | P40: 63.1 | Q40: 58.5 | R40: 54.5 | S40: 57 | T40: 53.5 | U40: 55.7 | V40: 50.8 | W40: 53.6 | X40: 55.2 | Y40: 55.6 | Z40: 51.7 | AA40: 63.7 | AB40: 51.9 | AC40: 57.6 | AD40: 55.5 | AE40: 52.5 | AF40: 59.3 | AG40: 62.1 | AH40: 58.4
... A43: LULUCF Sector Net Totalk | B43: -976.7 | C43: -989 | D43: -1007.4 | E43: -991.3 | F43: -1005.2 | G43: -980.2 | H43: -1011.2 | I43: -985.2 | J43: -996.3 | K43: -968.5 | L43: -983.7 | M43: -979.8 | N43: -924.8 | O43: -957.9 | P43: -860.2 | Q43: -907.7 | R43: -951.9 | S43: -900.3 | T43: -912.8 | U43: -850.9 | V43: -886.3 | W43: -941.7 | X43: -929.2 | Y43: -886.6 | Z43: -923.7 | AA43: -820.2 | AB43: -916.8 | AC43: -926 | AD43: -915.5 | AE43: -863.6 | AF43: -904.4 | AG43: -910.6 | AH43: -854.2
A44: + Absolute value does not exceed 0.05 MMT CO2 Eq.
A45: a Includes the net changes to carbon stocks stored in all forest ecosystem pools (estimates include C stock changes from drained organic soils from both Forest Land Remaining Forest Land and Land Converted to Forest Land) and harvested wood products.
A46: b Estimates include CH4 and N2O emissions from fires on both Forest Land Remaining Forest Land and Land Converted to Forest Land.
A47: c Estimates include N2O emissions from N fertilizer additions on both Forest Land Remaining Forest Land and Land Converted to Forest Land.
A48: d Estimates include CH4 and N2O emissions from drained organic soils on both Forest Land Remaining Forest Land and Land Converted to Forest Land. Carbon stock changes from drained organic soils are included with the Forest Land Remaining Forest Land forest ecosystem pools.
A49: e Includes the net changes to carbon stocks stored in all forest ecosystem pools.
...

Sheet EPA land and ag potential
A1: Average annual change in GHG flux in the land sector from the baseline across scenarios and models by GHG category. Results are presented in MtCO2e yr-1 from 2025 to 2050. Baseline GHG emissions from the land sector by GHG category are presented in Figure 31. GHG categories are described in Figure 23. FASOMGHG includes all GHG categories, while GLOBIOM does not include forest products, forest soils, or cropland CO2. As the results are presented in atmospheric accounting terms, negative values equal more mitigation than the Baseline. GTM is not included because it does not explicitly model emissions from agriculture. Initial values differ between models because they measure the change from baseline values and models respond differently to different GHG prices. See Box 2 for further discussion on movement of soil carbon across land use categories when LUC land use change occurs in FASOMGHG.
A2: Figure | B2: Position | C2: Year | D2: Model | E2: Group | F2: Growth.Rate | G2: Starting.Price | H2: Value | I2: Units | K2: EPS Map
A3: Fig_3.8 | B3: Bar | C3: 2025 | D3: FASOMGHG | E3: Ag Soils | F3: 3% Growth | G3: $50 | H3: 126.9 | I3: MtCO2e/yr | K3: =INDEX('EPA land and ag calcs'!$G$7:$G$14,MATCH('EPA land and ag potential'!E3,'EPA land and ag calcs'!$A$7:$A$15,0)) -> afforestation and reforestation
A4: Fig_3.8 | B4: Bar | C4: 2035 | D4: FASOMGHG | E4: Ag Soils | F4: 3% Growth | G4: $50 | H4: 116.2 | I4: MtCO2e/yr | K4: =INDEX('EPA land and ag calcs'!$G$7:$G$14,MATCH('EPA land and ag potential'!E4,'EPA land and ag calcs'!$A$7:$A$15,0)) -> afforestation and reforestation
A5: Fig_3.8 | B5: Bar | C5: 2045 | D5: FASOMGHG | E5: Ag Soils | F5: 3% Growth | G5: $50 | H5: 78.6 | I5: MtCO2e/yr | K5: =INDEX('EPA land and ag calcs'!$G$7:$G$14,MATCH('EPA land and ag potential'!E5,'EPA land and ag calcs'!$A$7:$A$15,0)) -> afforestation and reforestation
A6: Fig_3.8 | B6: Bar | C6: 2055 | D6: FASOMGHG | E6: Ag Soils | F6: 3% Growth | G6: $50 | H6: 49.6 | I6: MtCO2e/yr | K6: =INDEX('EPA land and ag calcs'!$G$7:$G$14,MATCH('EPA land and ag potential'!E6,'EPA land and ag calcs'!$A$7:$A$15,0)) -> afforestation and reforestation
A7: Fig_3.8 | B7: Bar | C7: 2025 | D7: FASOMGHG | E7: Ag Soils | F7: 1% Growth | G7: $50 | H7: 39.4 | I7: MtCO2e/yr
A8: Fig_3.8 | B8: Bar | C8: 2035 | D8: FASOMGHG | E8: Ag Soils | F8: 1% Growth | G8: $50 | H8: 17.1 | I8: MtCO2e/yr
A9: Fig_3.8 | B9: Bar | C9: 2045 | D9: FASOMGHG | E9: Ag Soils | F9: 1% Growth | G9: $50 | H9: 8.9 | I9: MtCO2e/yr
A10: Fig_3.8 | B10: Bar | C10: 2055 | D10: FASOMGHG | E10: Ag Soils | F10: 1% Growth | G10: $50 | H10: 4.2 | I10: MtCO2e/yr
A11: Fig_3.8 | B11: Bar | C11: 2025 | D11: FASOMGHG | E11: Ag Soils | F11: 3% Growth | G11: $5 | H11: 24 | I11: MtCO2e/yr | K11: =INDEX('EPA land and ag calcs'!$G$7:$G$14,MATCH('EPA land and ag potential'!E11,'EPA land and ag calcs'!$A$7:$A$15,0)) -> afforestation and reforestation
A12: Fig_3.8 | B12: Bar | C12: 2035 | D12: FASOMGHG | E12: Ag Soils | F12: 3% Growth | G12: $5 | H12: 38.8 | I12: MtCO2e/yr | K12: =INDEX('EPA land and ag calcs'!$G$7:$G$14,MATCH('EPA land and ag potential'!E12,'EPA land and ag calcs'!$A$7:$A$15,0)) -> afforestation and reforestation
A13: Fig_3.8 | B13: Bar | C13: 2025 | D13: FASOMGHG | E13: Cropland Non-CO2 | F13: 3% Growth | G13: $50 | H13: -2.9 | I13: MtCO2e/yr | K13: =INDEX('EPA land and ag calcs'!$G$7:$G$14,MATCH('EPA land and ag potential'!E13,'EPA land and ag calcs'!$A$7:$A$15,0)) -> *handled in agriculture files
A14: Fig_3.8 | B14: Bar | C14: 2035 | D14: FASOMGHG | E14: Cropland Non-CO2 | F14: 3% Growth | G14: $50 | H14: -6.6 | I14: MtCO2e/yr | K14: =INDEX('EPA land and ag calcs'!$G$7:$G$14,MATCH('EPA land and ag potential'!E14,'EPA land and ag calcs'!$A$7:$A$15,0)) -> *handled in agriculture files
A15: Fig_3.8 | B15: Bar | C15: 2045 | D15: FASOMGHG | E15: Cropland Non-CO2 | F15: 3% Growth | G15: $50 | H15: -9.2 | I15: MtCO2e/yr | K15: =INDEX('EPA land and ag calcs'!$G$7:$G$14,MATCH('EPA land and ag potential'!E15,'EPA land and ag calcs'!$A$7:$A$15,0)) -> *handled in agriculture files
A16: Fig_3.8 | B16: Bar | C16: 2055 | D16: FASOMGHG | E16: Cropland Non-CO2 | F16: 3% Growth | G16: $50 | H16: -11.1 | I16: MtCO2e/yr | K16: =INDEX('EPA land and ag calcs'!$G$7:$G$14,MATCH('EPA land and ag potential'!E16,'EPA land and ag calcs'!$A$7:$A$15,0)) -> *handled in agriculture files
A17: Fig_3.8 | B17: Bar | C17: 2025 | D17: FASOMGHG | E17: Cropland Non-CO2 | F17: 1% Growth | G17: $50 | H17: -4.5 | I17: MtCO2e/yr
A18: Fig_3.8 | B18: Bar | C18: 2035 | D18: FASOMGHG | E18: Cropland Non-CO2 | F18: 1% Growth | G18: $50 | H18: -7.4 | I18: MtCO2e/yr
A19: Fig_3.8 | B19: Bar | C19: 2045 | D19: FASOMGHG | E19: Cropland Non-CO2 | F19: 1% Growth | G19: $50 | H19: -9.7 | I19: MtCO2e/yr
A20: Fig_3.8 | B20: Bar | C20: 2055 | D20: FASOMGHG | E20: Cropland Non-CO2 | F20: 1% Growth | G20: $50 | H20: -11.2 | I20: MtCO2e/yr
A21: Fig_3.8 | B21: Bar | C21: 2025 | D21: FASOMGHG | E21: Cropland Non-CO2 | F21: 3% Growth | G21: $5 | H21: -0.2 | I21: MtCO2e/yr | K21: =INDEX('EPA land and ag calcs'!$G$7:$G$14,MATCH('EPA land and ag potential'!E21,'EPA land and ag calcs'!$A$7:$A$15,0)) -> *handled in agriculture files
A22: Fig_3.8 | B22: Bar | C22: 2035 | D22: FASOMGHG | E22: Cropland Non-CO2 | F22: 3% Growth | G22: $5 | H22: -0.9 | I22: MtCO2e/yr | K22: =INDEX('EPA land and ag calcs'!$G$7:$G$14,MATCH('EPA land and ag potential'!E22,'EPA land and ag calcs'!$A$7:$A$15,0)) -> *handled in agriculture files
A23: Fig_3.8 | B23: Bar | C23: 2025 | D23: FASOMGHG | E23: Cropland CO2 | F23: 3% Growth | G23: $50 | H23: -0.9 | I23: MtCO2e/yr | K23: =INDEX('EPA land and ag calcs'!$G$7:$G$14,MATCH('EPA land and ag potential'!E23,'EPA land and ag calcs'!$A$7:$A$15,0)) -> *handled in agriculture files
A24: Fig_3.8 | B24: Bar | C24: 2035 | D24: FASOMGHG | E24: Cropland CO2 | F24: 3% Growth | G24: $50 | H24: -4.8 | I24: MtCO2e/yr | K24: =INDEX('EPA land and ag calcs'!$G$7:$G$14,MATCH('EPA land and ag potential'!E24,'EPA land and ag calcs'!$A$7:$A$15,0)) -> *handled in agriculture files
A25: Fig_3.8 | B25: Bar | C25: 2045 | D25: FASOMGHG | E25: Cropland CO2 | F25: 3% Growth | G25: $50 | H25: -9.3 | I25: MtCO2e/yr | K25: =INDEX('EPA land and ag calcs'!$G$7:$G$14,MATCH('EPA land and ag potential'!E25,'EPA land and ag calcs'!$A$7:$A$15,0)) -> *handled in agriculture files
A26: Fig_3.8 | B26: Bar | C26: 2055 | D26: FASOMGHG | E26: Cropland CO2 | F26: 3% Growth | G26: $50 | H26: -12.5 | I26: MtCO2e/yr | K26: =INDEX('EPA land and ag calcs'!$G$7:$G$14,MATCH('EPA land and ag potential'!E26,'EPA land and ag calcs'!$A$7:$A$15,0)) -> *handled in agriculture files
A27: Fig_3.8 | B27: Bar | C27: 2025 | D27: FASOMGHG | E27: Cropland CO2 | F27: 1% Growth | G27: $50 | H27: -3.5 | I27: MtCO2e/yr
A28: Fig_3.8 | B28: Bar | C28: 2035 | D28: FASOMGHG | E28: Cropland CO2 | F28: 1% Growth | G28: $50 | H28: -6 | I28: MtCO2e/yr
A29: Fig_3.8 | B29: Bar | C29: 2045 | D29: FASOMGHG | E29: Cropland CO2 | F29: 1% Growth | G29: $50 | H29: -9.3 | I29: MtCO2e/yr
A30: Fig_3.8 | B30: Bar | C30: 2055 | D30: FASOMGHG | E30: Cropland CO2 | F30: 1% Growth | G30: $50 | H30: -11.9 | I30: MtCO2e/yr
A31: Fig_3.8 | B31: Bar | C31: 2025 | D31: FASOMGHG | E31: Cropland CO2 | F31: 3% Growth | G31: $5 | H31: -0.4 | I31: MtCO2e/yr | K31: =INDEX('EPA land and ag calcs'!$G$7:$G$14,MATCH('EPA land and ag potential'!E31,'EPA land and ag calcs'!$A$7:$A$15,0)) -> *handled in agriculture files
A32: Fig_3.8 | B32: Bar | C32: 2035 | D32: FASOMGHG | E32: Cropland CO2 | F32: 3% Growth | G32: $5 | H32: -0.6 | I32: MtCO2e/yr | K32: =INDEX('EPA land and ag calcs'!$G$7:$G$14,MATCH('EPA land and ag potential'!E32,'EPA land and ag calcs'!$A$7:$A$15,0)) -> *handled in agriculture files
A33: Fig_3.8 | B33: Bar | C33: 2025 | D33: FASOMGHG | E33: Forest (Existing forests) | F33: 3% Growth | G33: $50 | H33: -19 | I33: MtCO2e/yr | K33: =INDEX('EPA land and ag calcs'!$G$7:$G$14,MATCH('EPA land and ag potential'!E33,'EPA land and ag calcs'!$A$7:$A$15,0)) -> forest management
A34: Fig_3.8 | B34: Bar | C34: 2035 | D34: FASOMGHG | E34: Forest (Existing forests) | F34: 3% Growth | G34: $50 | H34: -54.9 | I34: MtCO2e/yr | K34: =INDEX('EPA land and ag calcs'!$G$7:$G$14,MATCH('EPA land and ag potential'!E34,'EPA land and ag calcs'!$A$7:$A$15,0)) -> forest management
A35: Fig_3.8 | B35: Bar | C35: 2045 | D35: FASOMGHG | E35: Forest (Existing forests) | F35: 3% Growth | G35: $50 | H35: -65.7 | I35: MtCO2e/yr | K35: =INDEX('EPA land and ag calcs'!$G$7:$G$14,MATCH('EPA land and ag potential'!E35,'EPA land and ag calcs'!$A$7:$A$15,0)) -> forest management
A36: Fig_3.8 | B36: Bar | C36: 2055 | D36: FASOMGHG | E36: Forest (Existing forests) | F36: 3% Growth | G36: $50 | H36: -78 | I36: MtCO2e/yr | K36: =INDEX('EPA land and ag calcs'!$G$7:$G$14,MATCH('EPA land and ag potential'!E36,'EPA land and ag calcs'!$A$7:$A$15,0)) -> forest management
A37: Fig_3.8 | B37: Bar | C37: 2025 | D37: FASOMGHG | E37: Forest (Existing forests) | F37: 1% Growth | G37: $50 | H37: -36.5 | I37: MtCO2e/yr
A38: Fig_3.8 | B38: Bar | C38: 2035 | D38: FASOMGHG | E38: Forest (Existing forests) | F38: 1% Growth | G38: $50 | H38: -61.2 | I38: MtCO2e/yr
A39: Fig_3.8 | B39: Bar | C39: 2045 | D39: FASOMGHG | E39: Forest (Existing forests) | F39: 1% Growth | G39: $50 | H39: -62.5 | I39: MtCO2e/yr
A40: Fig_3.8 | B40: Bar | C40: 2055 | D40: FASOMGHG | E40: Forest (Existing forests) | F40: 1% Growth | G40: $50 | H40: -61.3 | I40: MtCO2e/yr
...

Sheet EPA land and ag calcs
A1: Model | B1: FASOMGHG
A2: Growth.Rate | B2: 3% Growth
A3: Starting.Price | B3: $100
A5: Sum of Value | B5: Column Labels
A6: Row Labels | B6: 2025 | C6: 2035 | D6: 2045 | E6: 2055 | F6: Grand Total
A7: Ag Soils | B7: 124.1 | C7: 109.7 | D7: 73.5 | E7: 45.3 | F7: 352.6 | G7: afforestation and reforestation
A8: Cropland CO2 | B8: -4 | C8: -8.8 | D8: -13 | E8: -15.8 | F8: -41.6 | G8: *handled in agriculture files
A9: Cropland Non-CO2 | B9: -3.8 | C9: -7.6 | D9: -10.2 | E9: -12 | F9: -33.6 | G9: *handled in agriculture files
A10: Forest (Existing forests) | B10: -30.3 | C10: -67.1 | D10: -77.8 | E10: -91.9 | F10: -267.1 | G10: forest management
A11: Forest (New forests) | C11: -59 | D11: -77.6 | E11: -107 | F11: -243.6 | G11: afforestation and reforestation
A12: Forest Products | B12: 3.6 | C12: 3 | D12: 2.6 | E12: 2.4 | F12: 11.6 | G12: forest management
A13: Forest Soils | B13: -153.2 | C13: -173.5 | D13: -154.1 | E13: -130.2 | F13: -611 | G13: afforestation and reforestation
A14: Livestock Non-CO2 | B14: -33.3 | C14: -44.3 | D14: -51.2 | E14: -59.2 | F14: -188 | G14: *handled in agriculture files
A15: Total | B15: -96.9 | C15: -247.6 | D15: -307.8 | E15: -368.4 | F15: -1020.7
A16: Grand Total | B16: -193.8 | C16: -495.2 | D16: -615.6 | E16: -736.8 | F16: -2041.4
A18: Check on Total | B18: =SUM(B7:B14) -> -96.9 | C18: =SUM(C7:C14) -> -247.6 | D18: =SUM(D7:D14) -> -307.8 | E18: =SUM(E7:E14) -> -368.4
A20: forest management
B21: cumulative | H21: broken out
B22: 2025 | C22: 2035 | D22: 2045 | E22: 2055 | H22: 2025 | I22: 2035 | J22: 2045 | K22: 2055
A23: 5 | B23: =SUMIFS('EPA land and ag potential'!$H:$H,'EPA land and ag potential'!$C:$C,'EPA land and ag calcs'!B$22,'EPA land and ag potential'!$G:$G,'EPA land and ag calcs'!$A23,'EPA land and ag potential'!$D:$D,"FASOMGHG",'EPA land and ag potential'!$F:$F,"3% Growth",'EPA land and ag potential'!$K:$K,'EPA land and ag calcs'!$A$20) -> -6.2 | C23: =SUMIFS('EPA land and ag potential'!$H:$H,'EPA land and ag potential'!$C:$C,'EPA land and ag calcs'!C$22,'EPA land and ag potential'!$G:$G,'EPA land and ag calcs'!$A23,'EPA land and ag potential'!$D:$D,"FASOMGHG",'EPA land and ag potential'!$F:$F,"3% Growth",'EPA land and ag potential'!$K:$K,'EPA land and ag calcs'!$A$20) -> -15.7 | D23: =SUMIFS('EPA land and ag potential'!$H:$H,'EPA land and ag potential'!$C:$C,'EPA land and ag calcs'!D$22,'EPA land and ag potential'!$G:$G,'EPA land and ag calcs'!$A23,'EPA land and ag potential'!$D:$D,"FASOMGHG",'EPA land and ag potential'!$F:$F,"3% Growth",'EPA land and ag potential'!$K:$K,'EPA land and ag calcs'!$A$20) -> -21.9 | E23: =SUMIFS('EPA land and ag potential'!$H:$H,'EPA land and ag potential'!$C:$C,'EPA land and ag calcs'!E$22,'EPA land and ag potential'!$G:$G,'EPA land and ag calcs'!$A23,'EPA land and ag potential'!$D:$D,"FASOMGHG",'EPA land and ag potential'!$F:$F,"3% Growth",'EPA land and ag potential'!$K:$K,'EPA land and ag calcs'!$A$20) -> -27.9 | G23: 5 | H23: =SUMIFS('EPA land and ag potential'!$H:$H,'EPA land and ag potential'!$C:$C,'EPA land and ag calcs'!B$22,'EPA land and ag potential'!$G:$G,'EPA land and ag calcs'!$A23,'EPA land and ag potential'!$K:$K,'EPA land and ag calcs'!$A$20,'EPA land and ag potential'!$D:$D,"FASOMGHG",'EPA land and ag potential'!$F:$F,"3% Growth") -> -6.2 | I23: =SUMIFS('EPA land and ag potential'!$H:$H,'EPA land and ag potential'!$C:$C,'EPA land and ag calcs'!C$22,'EPA land and ag potential'!$G:$G,'EPA land and ag calcs'!$A23,'EPA land and ag potential'!$K:$K,'EPA land and ag calcs'!$A$20,'EPA land and ag potential'!$D:$D,"FASOMGHG",'EPA land and ag potential'!$F:$F,"3% Growth") -> -15.7 | J23: =SUMIFS('EPA land and ag potential'!$H:$H,'EPA land and ag potential'!$C:$C,'EPA land and ag calcs'!D$22,'EPA land and ag potential'!$G:$G,'EPA land and ag calcs'!$A23,'EPA land and ag potential'!$K:$K,'EPA land and ag calcs'!$A$20,'EPA land and ag potential'!$D:$D,"FASOMGHG",'EPA land and ag potential'!$F:$F,"3% Growth") -> -21.9 | K23: =SUMIFS('EPA land and ag potential'!$H:$H,'EPA land and ag potential'!$C:$C,'EPA land and ag calcs'!E$22,'EPA land and ag potential'!$G:$G,'EPA land and ag calcs'!$A23,'EPA land and ag potential'!$K:$K,'EPA land and ag calcs'!$A$20,'EPA land and ag potential'!$D:$D,"FASOMGHG",'EPA land and ag potential'!$F:$F,"3% Growth") -> -27.9
A24: 20 | B24: =SUMIFS('EPA land and ag potential'!$H:$H,'EPA land and ag potential'!$C:$C,'EPA land and ag calcs'!B$22,'EPA land and ag potential'!$G:$G,'EPA land and ag calcs'!$A24,'EPA land and ag potential'!$D:$D,"FASOMGHG",'EPA land and ag potential'!$F:$F,"3% Growth",'EPA land and ag potential'!$K:$K,'EPA land and ag calcs'!$A$20) -> -12.3 | C24: =SUMIFS('EPA land and ag potential'!$H:$H,'EPA land and ag potential'!$C:$C,'EPA land and ag calcs'!C$22,'EPA land and ag potential'!$G:$G,'EPA land and ag calcs'!$A24,'EPA land and ag potential'!$D:$D,"FASOMGHG",'EPA land and ag potential'!$F:$F,"3% Growth",'EPA land and ag potential'!$K:$K,'EPA land and ag calcs'!$A$20) -> -39.1 | D24: =SUMIFS('EPA land and ag potential'!$H:$H,'EPA land and ag potential'!$C:$C,'EPA land and ag calcs'!D$22,'EPA land and ag potential'!$G:$G,'EPA land and ag calcs'!$A24,'EPA land and ag potential'!$D:$D,"FASOMGHG",'EPA land and ag potential'!$F:$F,"3% Growth",'EPA land and ag potential'!$K:$K,'EPA land and ag calcs'!$A$20) -> -48.1 | E24: =SUMIFS('EPA land and ag potential'!$H:$H,'EPA land and ag potential'!$C:$C,'EPA land and ag calcs'!E$22,'EPA land and ag potential'!$G:$G,'EPA land and ag calcs'!$A24,'EPA land and ag potential'!$D:$D,"FASOMGHG",'EPA land and ag potential'!$F:$F,"3% Growth",'EPA land and ag potential'!$K:$K,'EPA land and ag calcs'!$A$20) -> -58.3 | G24: 20 | H24: =B24-B23 -> -6.1 | I24: =C24-C23 -> -23.4 | J24: =D24-D23 -> -26.2 | K24: =E24-E23 -> -30.4
A25: 35 | B25: =SUMIFS('EPA land and ag potential'!$H:$H,'EPA land and ag potential'!$C:$C,'EPA land and ag calcs'!B$22,'EPA land and ag potential'!$G:$G,'EPA land and ag calcs'!$A25,'EPA land and ag potential'!$D:$D,"FASOMGHG",'EPA land and ag potential'!$F:$F,"3% Growth",'EPA land and ag potential'!$K:$K,'EPA land and ag calcs'!$A$20) -> -14.8 | C25: =SUMIFS('EPA land and ag potential'!$H:$H,'EPA land and ag potential'!$C:$C,'EPA land and ag calcs'!C$22,'EPA land and ag potential'!$G:$G,'EPA land and ag calcs'!$A25,'EPA land and ag potential'!$D:$D,"FASOMGHG",'EPA land and ag potential'!$F:$F,"3% Growth",'EPA land and ag potential'!$K:$K,'EPA land and ag calcs'!$A$20) -> -49.5 | D25: =SUMIFS('EPA land and ag potential'!$H:$H,'EPA land and ag potential'!$C:$C,'EPA land and ag calcs'!D$22,'EPA land and ag potential'!$G:$G,'EPA land and ag calcs'!$A25,'EPA land and ag potential'!$D:$D,"FASOMGHG",'EPA land and ag potential'!$F:$F,"3% Growth",'EPA land and ag potential'!$K:$K,'EPA land and ag calcs'!$A$20) -> -59.9 | E25: =SUMIFS('EPA land and ag potential'!$H:$H,'EPA land and ag potential'!$C:$C,'EPA land and ag calcs'!E$22,'EPA land and ag potential'!$G:$G,'EPA land and ag calcs'!$A25,'EPA land and ag potential'!$D:$D,"FASOMGHG",'EPA land and ag potential'!$F:$F,"3% Growth",'EPA land and ag potential'!$K:$K,'EPA land and ag calcs'!$A$20) -> -72 | G25: 35 | H25: =B25-B24 -> -2.5 | I25: =C25-C24 -> -10.4 | J25: =D25-D24 -> -11.8 | K25: =E25-E24 -> -13.7
A26: 50 | B26: =SUMIFS('EPA land and ag potential'!$H:$H,'EPA land and ag potential'!$C:$C,'EPA land and ag calcs'!B$22,'EPA land and ag potential'!$G:$G,'EPA land and ag calcs'!$A26,'EPA land and ag potential'!$D:$D,"FASOMGHG",'EPA land and ag potential'!$F:$F,"3% Growth",'EPA land and ag potential'!$K:$K,'EPA land and ag calcs'!$A$20) -> -17.4 | C26: =SUMIFS('EPA land and ag potential'!$H:$H,'EPA land and ag potential'!$C:$C,'EPA land and ag calcs'!C$22,'EPA land and ag potential'!$G:$G,'EPA land and ag calcs'!$A26,'EPA land and ag potential'!$D:$D,"FASOMGHG",'EPA land and ag potential'!$F:$F,"3% Growth",'EPA land and ag potential'!$K:$K,'EPA land and ag calcs'!$A$20) -> -53.3 | D26: =SUMIFS('EPA land and ag potential'!$H:$H,'EPA land and ag potential'!$C:$C,'EPA land and ag calcs'!D$22,'EPA land and ag potential'!$G:$G,'EPA land and ag calcs'!$A26,'EPA land and ag potential'!$D:$D,"FASOMGHG",'EPA land and ag potential'!$F:$F,"3% Growth",'EPA land and ag potential'!$K:$K,'EPA land and ag calcs'!$A$20) -> -64.1 | E26: =SUMIFS('EPA land and ag potential'!$H:$H,'EPA land and ag potential'!$C:$C,'EPA land and ag calcs'!E$22,'EPA land and ag potential'!$G:$G,'EPA land and ag calcs'!$A26,'EPA land and ag potential'!$D:$D,"FASOMGHG",'EPA land and ag potential'!$F:$F,"3% Growth",'EPA land and ag potential'!$K:$K,'EPA land and ag calcs'!$A$20) -> -76.7 | G26: 50 | H26: =B26-B25 -> -2.6 | I26: =C26-C25 -> -3.8 | J26: =D26-D25 -> -4.2 | K26: =E26-E25 -> -4.7
A27: 100 | B27: =SUMIFS('EPA land and ag potential'!$H:$H,'EPA land and ag potential'!$C:$C,'EPA land and ag calcs'!B$22,'EPA land and ag potential'!$G:$G,'EPA land and ag calcs'!$A27,'EPA land and ag potential'!$D:$D,"FASOMGHG",'EPA land and ag potential'!$F:$F,"3% Growth",'EPA land and ag potential'!$K:$K,'EPA land and ag calcs'!$A$20) -> -26.7 | C27: =SUMIFS('EPA land and ag potential'!$H:$H,'EPA land and ag potential'!$C:$C,'EPA land and ag calcs'!C$22,'EPA land and ag potential'!$G:$G,'EPA land and ag calcs'!$A27,'EPA land and ag potential'!$D:$D,"FASOMGHG",'EPA land and ag potential'!$F:$F,"3% Growth",'EPA land and ag potential'!$K:$K,'EPA land and ag calcs'!$A$20) -> -64.1 | D27: =SUMIFS('EPA land and ag potential'!$H:$H,'EPA land and ag potential'!$C:$C,'EPA land and ag calcs'!D$22,'EPA land and ag potential'!$G:$G,'EPA land and ag calcs'!$A27,'EPA land and ag potential'!$D:$D,"FASOMGHG",'EPA land and ag potential'!$F:$F,"3% Growth",'EPA land and ag potential'!$K:$K,'EPA land and ag calcs'!$A$20) -> -75.2 | E27: =SUMIFS('EPA land and ag potential'!$H:$H,'EPA land and ag potential'!$C:$C,'EPA land and ag calcs'!E$22,'EPA land and ag potential'!$G:$G,'EPA land and ag calcs'!$A27,'EPA land and ag potential'!$D:$D,"FASOMGHG",'EPA land and ag potential'!$F:$F,"3% Growth",'EPA land and ag potential'!$K:$K,'EPA land and ag calcs'!$A$20) -> -89.5 | G27: 100 | H27: =B27-B26 -> -9.3 | I27: =C27-C26 -> -10.8 | J27: =D27-D26 -> -11.1 | K27: =E27-E26 -> -12.8
A29: afforestation and reforestation
B30: cumulative | H30: broken out
B31: 2025 | C31: 2035 | D31: 2045 | E31: 2055 | H31: 2025 | I31: 2035 | J31: 2045 | K31: 2055
A32: 5 | B32: =SUMIFS('EPA land and ag potential'!$H:$H,'EPA land and ag potential'!$C:$C,'EPA land and ag calcs'!B$22,'EPA land and ag potential'!$G:$G,'EPA land and ag calcs'!$A23,'EPA land and ag potential'!$D:$D,"FASOMGHG",'EPA land and ag potential'!$F:$F,"3% Growth",'EPA land and ag potential'!$K:$K,'EPA land and ag calcs'!$A$29) -> 15.6 | C32: =SUMIFS('EPA land and ag potential'!$H:$H,'EPA land and ag potential'!$C:$C,'EPA land and ag calcs'!C$22,'EPA land and ag potential'!$G:$G,'EPA land and ag calcs'!$A23,'EPA land and ag potential'!$D:$D,"FASOMGHG",'EPA land and ag potential'!$F:$F,"3% Growth",'EPA land and ag potential'!$K:$K,'EPA land and ag calcs'!$A$29) -> 1.7 | D32: =SUMIFS('EPA land and ag potential'!$H:$H,'EPA land and ag potential'!$C:$C,'EPA land and ag calcs'!D$22,'EPA land and ag potential'!$G:$G,'EPA land and ag calcs'!$A23,'EPA land and ag potential'!$D:$D,"FASOMGHG",'EPA land and ag potential'!$F:$F,"3% Growth",'EPA land and ag potential'!$K:$K,'EPA land and ag calcs'!$A$29) -> -1.5 | E32: =SUMIFS('EPA land and ag potential'!$H:$H,'EPA land and ag potential'!$C:$C,'EPA land and ag calcs'!E$22,'EPA land and ag potential'!$G:$G,'EPA land and ag calcs'!$A23,'EPA land and ag potential'!$D:$D,"FASOMGHG",'EPA land and ag potential'!$F:$F,"3% Growth",'EPA land and ag potential'!$K:$K,'EPA land and ag calcs'!$A$29) -> -0.6 | G32: 5 | H32: =SUMIFS('EPA land and ag potential'!$H:$H,'EPA land and ag potential'!$C:$C,'EPA land and ag calcs'!B$22,'EPA land and ag potential'!$G:$G,'EPA land and ag calcs'!$A32,'EPA land and ag potential'!$K:$K,'EPA land and ag calcs'!$A$29,'EPA land and ag potential'!$D:$D,"FASOMGHG",'EPA land and ag potential'!$F:$F,"3% Growth") -> 15.6 | I32: =SUMIFS('EPA land and ag potential'!$H:$H,'EPA land and ag potential'!$C:$C,'EPA land and ag calcs'!C$22,'EPA land and ag potential'!$G:$G,'EPA land and ag calcs'!$A32,'EPA land and ag potential'!$K:$K,'EPA land and ag calcs'!$A$29,'EPA land and ag potential'!$D:$D,"FASOMGHG",'EPA land and ag potential'!$F:$F,"3% Growth") -> 1.7 | J32: =SUMIFS('EPA land and ag potential'!$H:$H,'EPA land and ag potential'!$C:$C,'EPA land and ag calcs'!D$22,'EPA land and ag potential'!$G:$G,'EPA land and ag calcs'!$A32,'EPA land and ag potential'!$K:$K,'EPA land and ag calcs'!$A$29,'EPA land and ag potential'!$D:$D,"FASOMGHG",'EPA land and ag potential'!$F:$F,"3% Growth") -> -1.5 | K32: =SUMIFS('EPA land and ag potential'!$H:$H,'EPA land and ag potential'!$C:$C,'EPA land and ag calcs'!E$22,'EPA land and ag potential'!$G:$G,'EPA land and ag calcs'!$A32,'EPA land and ag potential'!$K:$K,'EPA land and ag calcs'!$A$29,'EPA land and ag potential'!$D:$D,"FASOMGHG",'EPA land and ag potential'!$F:$F,"3% Growth") -> -0.6
A33: 20 | B33: =SUMIFS('EPA land and ag potential'!$H:$H,'EPA land and ag potential'!$C:$C,'EPA land and ag calcs'!B$22,'EPA land and ag potential'!$G:$G,'EPA land and ag calcs'!$A24,'EPA land and ag potential'!$D:$D,"FASOMGHG",'EPA land and ag potential'!$F:$F,"3% Growth",'EPA land and ag potential'!$K:$K,'EPA land and ag calcs'!$A$29) -> 15.1 | C33: =SUMIFS('EPA land and ag potential'!$H:$H,'EPA land and ag potential'!$C:$C,'EPA land and ag calcs'!C$22,'EPA land and ag potential'!$G:$G,'EPA land and ag calcs'!$A24,'EPA land and ag potential'!$D:$D,"FASOMGHG",'EPA land and ag potential'!$F:$F,"3% Growth",'EPA land and ag potential'!$K:$K,'EPA land and ag calcs'!$A$29) -> -25.5 | D33: =SUMIFS('EPA land and ag potential'!$H:$H,'EPA land and ag potential'!$C:$C,'EPA land and ag calcs'!D$22,'EPA land and ag potential'!$G:$G,'EPA land and ag calcs'!$A24,'EPA land and ag potential'!$D:$D,"FASOMGHG",'EPA land and ag potential'!$F:$F,"3% Growth",'EPA land and ag potential'!$K:$K,'EPA land and ag calcs'!$A$29) -> -40.1 | E33: =SUMIFS('EPA land and ag potential'!$H:$H,'EPA land and ag potential'!$C:$C,'EPA land and ag calcs'!E$22,'EPA land and ag potential'!$G:$G,'EPA land and ag calcs'!$A24,'EPA land and ag potential'!$D:$D,"FASOMGHG",'EPA land and ag potential'!$F:$F,"3% Growth",'EPA land and ag potential'!$K:$K,'EPA land and ag calcs'!$A$29) -> -62.5 | G33: 20 | H33: =B33-B32 -> -0.5 | I33: =C33-C32 -> -27.2 | J33: =D33-D32 -> -38.6 | K33: =E33-E32 -> -61.9
A34: 35 | B34: =SUMIFS('EPA land and ag potential'!$H:$H,'EPA land and ag potential'!$C:$C,'EPA land and ag calcs'!B$22,'EPA land and ag potential'!$G:$G,'EPA land and ag calcs'!$A25,'EPA land and ag potential'!$D:$D,"FASOMGHG",'EPA land and ag potential'!$F:$F,"3% Growth",'EPA land and ag potential'!$K:$K,'EPA land and ag calcs'!$A$29) -> 20.5 | C34: =SUMIFS('EPA land and ag potential'!$H:$H,'EPA land and ag potential'!$C:$C,'EPA land and ag calcs'!C$22,'EPA land and ag potential'!$G:$G,'EPA land and ag calcs'!$A25,'EPA land and ag potential'!$D:$D,"FASOMGHG",'EPA land and ag potential'!$F:$F,"3% Growth",'EPA land and ag potential'!$K:$K,'EPA land and ag calcs'!$A$29) -> -59.3 | D34: =SUMIFS('EPA land and ag potential'!$H:$H,'EPA land and ag potential'!$C:$C,'EPA land and ag calcs'!D$22,'EPA land and ag potential'!$G:$G,'EPA land and ag calcs'!$A25,'EPA land and ag potential'!$D:$D,"FASOMGHG",'EPA land and ag potential'!$F:$F,"3% Growth",'EPA land and ag potential'!$K:$K,'EPA land and ag calcs'!$A$29) -> -99.2 | E34: =SUMIFS('EPA land and ag potential'!$H:$H,'EPA land and ag potential'!$C:$C,'EPA land and ag calcs'!E$22,'EPA land and ag potential'!$G:$G,'EPA land and ag calcs'!$A25,'EPA land and ag potential'!$D:$D,"FASOMGHG",'EPA land and ag potential'!$F:$F,"3% Growth",'EPA land and ag potential'!$K:$K,'EPA land and ag calcs'!$A$29) -> -124.1 | G34: 35 | H34: =B34-B33 -> 5.4 | I34: =C34-C33 -> -33.8 | J34: =D34-D33 -> -59.1 | K34: =E34-E33 -> -61.6
A35: 50 | B35: =SUMIFS('EPA land and ag potential'!$H:$H,'EPA land and ag potential'!$C:$C,'EPA land and ag calcs'!B$22,'EPA land and ag potential'!$G:$G,'EPA land and ag calcs'!$A26,'EPA land and ag potential'!$D:$D,"FASOMGHG",'EPA land and ag potential'!$F:$F,"3% Growth",'EPA land and ag potential'!$K:$K,'EPA land and ag calcs'!$A$29) -> -26.5 | C35: =SUMIFS('EPA land and ag potential'!$H:$H,'EPA land and ag potential'!$C:$C,'EPA land and ag calcs'!C$22,'EPA land and ag potential'!$G:$G,'EPA land and ag calcs'!$A26,'EPA land and ag potential'!$D:$D,"FASOMGHG",'EPA land and ag potential'!$F:$F,"3% Growth",'EPA land and ag potential'!$K:$K,'EPA land and ag calcs'!$A$29) -> -103.5 | D35: =SUMIFS('EPA land and ag potential'!$H:$H,'EPA land and ag potential'!$C:$C,'EPA land and ag calcs'!D$22,'EPA land and ag potential'!$G:$G,'EPA land and ag calcs'!$A26,'EPA land and ag potential'!$D:$D,"FASOMGHG",'EPA land and ag potential'!$F:$F,"3% Growth",'EPA land and ag potential'!$K:$K,'EPA land and ag calcs'!$A$29) -> -141.9 | E35: =SUMIFS('EPA land and ag potential'!$H:$H,'EPA land and ag potential'!$C:$C,'EPA land and ag calcs'!E$22,'EPA land and ag potential'!$G:$G,'EPA land and ag calcs'!$A26,'EPA land and ag potential'!$D:$D,"FASOMGHG",'EPA land and ag potential'!$F:$F,"3% Growth",'EPA land and ag potential'!$K:$K,'EPA land and ag calcs'!$A$29) -> -168.4 | G35: 50 | H35: =B35-B34 -> -47 | I35: =C35-C34 -> -44.2 | J35: =D35-D34 -> -42.7 | K35: =E35-E34 -> -44.3
A36: 100 | B36: =SUMIFS('EPA land and ag potential'!$H:$H,'EPA land and ag potential'!$C:$C,'EPA land and ag calcs'!B$22,'EPA land and ag potential'!$G:$G,'EPA land and ag calcs'!$A27,'EPA land and ag potential'!$D:$D,"FASOMGHG",'EPA land and ag potential'!$F:$F,"3% Growth",'EPA land and ag potential'!$K:$K,'EPA land and ag calcs'!$A$29) -> -29.1 | C36: =SUMIFS('EPA land and ag potential'!$H:$H,'EPA land and ag potential'!$C:$C,'EPA land and ag calcs'!C$22,'EPA land and ag potential'!$G:$G,'EPA land and ag calcs'!$A27,'EPA land and ag potential'!$D:$D,"FASOMGHG",'EPA land and ag potential'!$F:$F,"3% Growth",'EPA land and ag potential'!$K:$K,'EPA land and ag calcs'!$A$29) -> -122.8 | D36: =SUMIFS('EPA land and ag potential'!$H:$H,'EPA land and ag potential'!$C:$C,'EPA land and ag calcs'!D$22,'EPA land and ag potential'!$G:$G,'EPA land and ag calcs'!$A27,'EPA land and ag potential'!$D:$D,"FASOMGHG",'EPA land and ag potential'!$F:$F,"3% Growth",'EPA land and ag potential'!$K:$K,'EPA land and ag calcs'!$A$29) -> -158.2 | E36: =SUMIFS('EPA land and ag potential'!$H:$H,'EPA land and ag potential'!$C:$C,'EPA land and ag calcs'!E$22,'EPA land and ag potential'!$G:$G,'EPA land and ag calcs'!$A27,'EPA land and ag potential'!$D:$D,"FASOMGHG",'EPA land and ag potential'!$F:$F,"3% Growth",'EPA land and ag potential'!$K:$K,'EPA land and ag calcs'!$A$29) -> -191.9 | G36: 100 | H36: =B36-B35 -> -2.6 | I36: =C36-C35 -> -19.3 | J36: =D36-D35 -> -16.3 | K36: =E36-E35 -> -23.5
A38: forest management
A39: Cost Bucket | B39: 2021 | C39: 2022 | D39: 2023 | E39: 2024 | F39: 2025 | G39: 2026 | H39: 2027 | I39: 2028 | J39: 2029 | K39: 2030 | L39: 2031 | M39: 2032 | N39: 2033 | O39: 2034 | P39: 2035 | Q39: 2036 | R39: 2037 | S39: 2038 | T39: 2039 | U39: 2040 | V39: 2041 | W39: 2042 | X39: 2043 | Y39: 2044 | Z39: 2045 | AA39: 2046 | AB39: 2047 | AC39: 2048 | AD39: 2049 | AE39: 2050
A40: 5 | B40: {=MAX(TREND($H23:$I23,$H$31:$I$31,B$39)*10^12*-1,0)} -> 2.4e+12 | C40: {=MAX(TREND($H23:$I23,$H$31:$I$31,C$39)*10^12*-1,0)} -> 3.35e+12 | D40: {=MAX(TREND($H23:$I23,$H$31:$I$31,D$39)*10^12*-1,0)} -> 4.3e+12 | E40: {=MAX(TREND($H23:$I23,$H$31:$I$31,E$39)*10^12*-1,0)} -> 5250000000000 | F40: {=MAX(TREND($H23:$I23,$H$31:$I$31,F$39)*10^12*-1,0)} -> 6.2e+12 | G40: {=MAX(TREND($H23:$I23,$H$31:$I$31,G$39)*10^12*-1,0)} -> 7.15e+12 | H40: {=MAX(TREND($H23:$I23,$H$31:$I$31,H$39)*10^12*-1,0)} -> 8.1e+12 | I40: {=MAX(TREND($H23:$I23,$H$31:$I$31,I$39)*10^12*-1,0)} -> 9.05e+12 | ... P40: {=MAX(TREND($H23:$I23,$H$31:$I$31,P$39)*10^12*-1,0)} -> 1.57e+13 | Q40: {=MAX(TREND($I23:$J23,$I$31:$J$31,Q$39)*10^12*-1,0)} -> 1.632e+13 | R40: {=MAX(TREND($I23:$J23,$I$31:$J$31,R$39)*10^12*-1,0)} -> 1.694e+13 | S40: {=MAX(TREND($I23:$J23,$I$31:$J$31,S$39)*10^12*-1,0)} -> 1.756e+13 | T40: {=MAX(TREND($I23:$J23,$I$31:$J$31,T$39)*10^12*-1,0)} -> 1.818e+13 | U40: {=MAX(TREND($I23:$J23,$I$31:$J$31,U$39)*10^12*-1,0)} -> 1.88e+13 | V40: {=MAX(TREND($I23:$J23,$I$31:$J$31,V$39)*10^12*-1,0)} -> 1.942e+13 | W40: {=MAX(TREND($I23:$J23,$I$31:$J$31,W$39)*10^12*-1,0)} -> 2.004e+13 | X40: {=MAX(TREND($I23:$J23,$I$31:$J$31,X$39)*10^12*-1,0)} -> 2.066e+13 | ... Z40: {=MAX(TREND($I23:$J23,$I$31:$J$31,Z$39)*10^12*-1,0)} -> 2.19e+13 | AA40: {=MAX(TREND($J23:$K23,$J$31:$K$31,AA$39)*10^12*-1,0)} -> 22500000000000 | AB40: {=MAX(TREND($J23:$K23,$J$31:$K$31,AB$39)*10^12*-1,0)} -> 2.31e+13 | AC40: {=MAX(TREND($J23:$K23,$J$31:$K$31,AC$39)*10^12*-1,0)} -> 2.37e+13 | AD40: {=MAX(TREND($J23:$K23,$J$31:$K$31,AD$39)*10^12*-1,0)} -> 2.43e+13 | AE40: {=MAX(TREND($J23:$K23,$J$31:$K$31,AE$39)*10^12*-1,0)} -> 2.49e+13
A41: 20 | B41: {=MAX(TREND($H24:$I24,$H$31:$I$31,B$39)*10^12*-1,0)} -> 0 | C41: {=MAX(TREND($H24:$I24,$H$31:$I$31,C$39)*10^12*-1,0)} -> 9.1e+11 | D41: {=MAX(TREND($H24:$I24,$H$31:$I$31,D$39)*10^12*-1,0)} -> 2.64e+12 | E41: {=MAX(TREND($H24:$I24,$H$31:$I$31,E$39)*10^12*-1,0)} -> 4.37e+12 | F41: {=MAX(TREND($H24:$I24,$H$31:$I$31,F$39)*10^12*-1,0)} -> 6.1e+12 | G41: {=MAX(TREND($H24:$I24,$H$31:$I$31,G$39)*10^12*-1,0)} -> 7.83e+12 | H41: {=MAX(TREND($H24:$I24,$H$31:$I$31,H$39)*10^12*-1,0)} -> 9.56e+12 | I41: {=MAX(TREND($H24:$I24,$H$31:$I$31,I$39)*10^12*-1,0)} -> 1.129e+13 | ... P41: {=MAX(TREND($H24:$I24,$H$31:$I$31,P$39)*10^12*-1,0)} -> 2.34e+13 | Q41: {=MAX(TREND($I24:$J24,$I$31:$J$31,Q$39)*10^12*-1,0)} -> 2.368e+13 | R41: {=MAX(TREND($I24:$J24,$I$31:$J$31,R$39)*10^12*-1,0)} -> 2.396e+13 | S41: {=MAX(TREND($I24:$J24,$I$31:$J$31,S$39)*10^12*-1,0)} -> 2.424e+13 | T41: {=MAX(TREND($I24:$J24,$I$31:$J$31,T$39)*10^12*-1,0)} -> 2.452e+13 | U41: {=MAX(TREND($I24:$J24,$I$31:$J$31,U$39)*10^12*-1,0)} -> 2.48e+13 | V41: {=MAX(TREND($I24:$J24,$I$31:$J$31,V$39)*10^12*-1,0)} -> 2.508e+13 | W41: {=MAX(TREND($I24:$J24,$I$31:$J$31,W$39)*10^12*-1,0)} -> 2.536e+13 | X41: {=MAX(TREND($I24:$J24,$I$31:$J$31,X$39)*10^12*-1,0)} -> 2.564e+13 | ... Z41: {=MAX(TREND($I24:$J24,$I$31:$J$31,Z$39)*10^12*-1,0)} -> 2.62e+13 | AA41: {=MAX(TREND($J24:$K24,$J$31:$K$31,AA$39)*10^12*-1,0)} -> 2.662e+13 | AB41: {=MAX(TREND($J24:$K24,$J$31:$K$31,AB$39)*10^12*-1,0)} -> 2.704e+13 | AC41: {=MAX(TREND($J24:$K24,$J$31:$K$31,AC$39)*10^12*-1,0)} -> 2.746e+13 | AD41: {=MAX(TREND($J24:$K24,$J$31:$K$31,AD$39)*10^12*-1,0)} -> 2.788e+13 | AE41: {=MAX(TREND($J24:$K24,$J$31:$K$31,AE$39)*10^12*-1,0)} -> 2.83e+13
A42: 35 | B42: {=MAX(TREND($H25:$I25,$H$31:$I$31,B$39)*10^12*-1,0)} -> 0 | C42: {=MAX(TREND($H25:$I25,$H$31:$I$31,C$39)*10^12*-1,0)} -> 1.3e+11 | D42: {=MAX(TREND($H25:$I25,$H$31:$I$31,D$39)*10^12*-1,0)} -> 9.2e+11 | E42: {=MAX(TREND($H25:$I25,$H$31:$I$31,E$39)*10^12*-1,0)} -> 1.71e+12 | F42: {=MAX(TREND($H25:$I25,$H$31:$I$31,F$39)*10^12*-1,0)} -> 2500000000000 | G42: {=MAX(TREND($H25:$I25,$H$31:$I$31,G$39)*10^12*-1,0)} -> 3.29e+12 | H42: {=MAX(TREND($H25:$I25,$H$31:$I$31,H$39)*10^12*-1,0)} -> 4.08e+12 | I42: {=MAX(TREND($H25:$I25,$H$31:$I$31,I$39)*10^12*-1,0)} -> 4.87e+12 | ... P42: {=MAX(TREND($H25:$I25,$H$31:$I$31,P$39)*10^12*-1,0)} -> 1.04e+13 | Q42: {=MAX(TREND($I25:$J25,$I$31:$J$31,Q$39)*10^12*-1,0)} -> 1.054e+13 | R42: {=MAX(TREND($I25:$J25,$I$31:$J$31,R$39)*10^12*-1,0)} -> 1.068e+13 | S42: {=MAX(TREND($I25:$J25,$I$31:$J$31,S$39)*10^12*-1,0)} -> 1.082e+13 | T42: {=MAX(TREND($I25:$J25,$I$31:$J$31,T$39)*10^12*-1,0)} -> 1.096e+13 | U42: {=MAX(TREND($I25:$J25,$I$31:$J$31,U$39)*10^12*-1,0)} -> 1.11e+13 | V42: {=MAX(TREND($I25:$J25,$I$31:$J$31,V$39)*10^12*-1,0)} -> 1.124e+13 | W42: {=MAX(TREND($I25:$J25,$I$31:$J$31,W$39)*10^12*-1,0)} -> 1.138e+13 | X42: {=MAX(TREND($I25:$J25,$I$31:$J$31,X$39)*10^12*-1,0)} -> 1.152e+13 | ... Z42: {=MAX(TREND($I25:$J25,$I$31:$J$31,Z$39)*10^12*-1,0)} -> 1.18e+13 | AA42: {=MAX(TREND($J25:$K25,$J$31:$K$31,AA$39)*10^12*-1,0)} -> 1.199e+13 | AB42: {=MAX(TREND($J25:$K25,$J$31:$K$31,AB$39)*10^12*-1,0)} -> 1.218e+13 | AC42: {=MAX(TREND($J25:$K25,$J$31:$K$31,AC$39)*10^12*-1,0)} -> 1.237e+13 | AD42: {=MAX(TREND($J25:$K25,$J$31:$K$31,AD$39)*10^12*-1,0)} -> 1.256e+13 | AE42: {=MAX(TREND($J25:$K25,$J$31:$K$31,AE$39)*10^12*-1,0)} -> 12750000000000
A43: 50 | B43: {=MAX(TREND($H26:$I26,$H$31:$I$31,B$39)*10^12*-1,0)} -> 2.12e+12 | C43: {=MAX(TREND($H26:$I26,$H$31:$I$31,C$39)*10^12*-1,0)} -> 2.24e+12 | D43: {=MAX(TREND($H26:$I26,$H$31:$I$31,D$39)*10^12*-1,0)} -> 2.36e+12 | E43: {=MAX(TREND($H26:$I26,$H$31:$I$31,E$39)*10^12*-1,0)} -> 2.48e+12 | F43: {=MAX(TREND($H26:$I26,$H$31:$I$31,F$39)*10^12*-1,0)} -> 2.6e+12 | G43: {=MAX(TREND($H26:$I26,$H$31:$I$31,G$39)*10^12*-1,0)} -> 2.72e+12 | H43: {=MAX(TREND($H26:$I26,$H$31:$I$31,H$39)*10^12*-1,0)} -> 2.84e+12 | I43: {=MAX(TREND($H26:$I26,$H$31:$I$31,I$39)*10^12*-1,0)} -> 2.96e+12 | ... P43: {=MAX(TREND($H26:$I26,$H$31:$I$31,P$39)*10^12*-1,0)} -> 3.8e+12 | Q43: {=MAX(TREND($I26:$J26,$I$31:$J$31,Q$39)*10^12*-1,0)} -> 3.84e+12 | R43: {=MAX(TREND($I26:$J26,$I$31:$J$31,R$39)*10^12*-1,0)} -> 3.88e+12 | S43: {=MAX(TREND($I26:$J26,$I$31:$J$31,S$39)*10^12*-1,0)} -> 3.92e+12 | T43: {=MAX(TREND($I26:$J26,$I$31:$J$31,T$39)*10^12*-1,0)} -> 3.96e+12 | U43: {=MAX(TREND($I26:$J26,$I$31:$J$31,U$39)*10^12*-1,0)} -> 4000000000000 | V43: {=MAX(TREND($I26:$J26,$I$31:$J$31,V$39)*10^12*-1,0)} -> 4.04e+12 | W43: {=MAX(TREND($I26:$J26,$I$31:$J$31,W$39)*10^12*-1,0)} -> 4.08e+12 | X43: {=MAX(TREND($I26:$J26,$I$31:$J$31,X$39)*10^12*-1,0)} -> 4.12e+12 | ... Z43: {=MAX(TREND($I26:$J26,$I$31:$J$31,Z$39)*10^12*-1,0)} -> 4.2e+12 | AA43: {=MAX(TREND($J26:$K26,$J$31:$K$31,AA$39)*10^12*-1,0)} -> 4.25e+12 | AB43: {=MAX(TREND($J26:$K26,$J$31:$K$31,AB$39)*10^12*-1,0)} -> 4.3e+12 | AC43: {=MAX(TREND($J26:$K26,$J$31:$K$31,AC$39)*10^12*-1,0)} -> 4.35e+12 | AD43: {=MAX(TREND($J26:$K26,$J$31:$K$31,AD$39)*10^12*-1,0)} -> 4.4e+12 | AE43: {=MAX(TREND($J26:$K26,$J$31:$K$31,AE$39)*10^12*-1,0)} -> 4.45e+12
A44: 100 | B44: {=MAX(TREND($H27:$I27,$H$31:$I$31,B$39)*10^12*-1,0)} -> 8.7e+12 | C44: {=MAX(TREND($H27:$I27,$H$31:$I$31,C$39)*10^12*-1,0)} -> 8.85e+12 | D44: {=MAX(TREND($H27:$I27,$H$31:$I$31,D$39)*10^12*-1,0)} -> 9000000000000 | E44: {=MAX(TREND($H27:$I27,$H$31:$I$31,E$39)*10^12*-1,0)} -> 9.15e+12 | F44: {=MAX(TREND($H27:$I27,$H$31:$I$31,F$39)*10^12*-1,0)} -> 9.3e+12 | G44: {=MAX(TREND($H27:$I27,$H$31:$I$31,G$39)*10^12*-1,0)} -> 9.45e+12 | H44: {=MAX(TREND($H27:$I27,$H$31:$I$31,H$39)*10^12*-1,0)} -> 9.6e+12 | I44: {=MAX(TREND($H27:$I27,$H$31:$I$31,I$39)*10^12*-1,0)} -> 9750000000000 | ... P44: {=MAX(TREND($H27:$I27,$H$31:$I$31,P$39)*10^12*-1,0)} -> 1.08e+13 | Q44: {=MAX(TREND($I27:$J27,$I$31:$J$31,Q$39)*10^12*-1,0)} -> 1.083e+13 | R44: {=MAX(TREND($I27:$J27,$I$31:$J$31,R$39)*10^12*-1,0)} -> 1.086e+13 | S44: {=MAX(TREND($I27:$J27,$I$31:$J$31,S$39)*10^12*-1,0)} -> 1.089e+13 | T44: {=MAX(TREND($I27:$J27,$I$31:$J$31,T$39)*10^12*-1,0)} -> 1.092e+13 | U44: {=MAX(TREND($I27:$J27,$I$31:$J$31,U$39)*10^12*-1,0)} -> 1.095e+13 | V44: {=MAX(TREND($I27:$J27,$I$31:$J$31,V$39)*10^12*-1,0)} -> 1.098e+13 | W44: {=MAX(TREND($I27:$J27,$I$31:$J$31,W$39)*10^12*-1,0)} -> 1.101e+13 | X44: {=MAX(TREND($I27:$J27,$I$31:$J$31,X$39)*10^12*-1,0)} -> 1.104e+13 | ... Z44: {=MAX(TREND($I27:$J27,$I$31:$J$31,Z$39)*10^12*-1,0)} -> 1.11e+13 | AA44: {=MAX(TREND($J27:$K27,$J$31:$K$31,AA$39)*10^12*-1,0)} -> 1.127e+13 | AB44: {=MAX(TREND($J27:$K27,$J$31:$K$31,AB$39)*10^12*-1,0)} -> 1.144e+13 | AC44: {=MAX(TREND($J27:$K27,$J$31:$K$31,AC$39)*10^12*-1,0)} -> 1.161e+13 | AD44: {=MAX(TREND($J27:$K27,$J$31:$K$31,AD$39)*10^12*-1,0)} -> 1.178e+13 | AE44: {=MAX(TREND($J27:$K27,$J$31:$K$31,AE$39)*10^12*-1,0)} -> 1.195e+13
A46: afforestation and reforestation
...

Sheet Inflation Reduction Act
A1: Methodology:
A2: We sum IRA forestry funding that aligns with the scope of the Energy Policy Simulator's LULUCF sector, then assign it to either the model's 'forest management' or 'afforestation and reforestation' levers. We then find the policy setting that matches total government spend over the period of 2023-2031. For Section 23001, we only include the protection of old-growth forests funding and exclude hazardous fuels reduction and vegetation management, which are outside the scope of the model. The EPS assumes forest management practices need to be consistently implemented in every year in order to maintain emissions reductions. To be conservative, we phase out forest management practices incentivized by the IRA over a period of 4 years rather than assume permanent reductions.
A4: Calculations:
A5: 2022 to 2012 USD | B5: 0.785
A7: Forestry Funding in Inflation Reduction Act of 2022 (Billion USD)
A8: hazardous fuels reduction | B8: 1.8 | D8: N/A
A9: vegetation management | B9: 0.2 | D9: N/A
A10: environmental reviews | B10: 0.1 | D10: N/A
A11: protection of old-growth forests | B11: 0.05 | D11: forest management
A12: competitive grants for climate mitigation | B12: 0.15 | D12: forest management
A13: competitive grants for climate mitigation | B13: 0.15 | D13: forest management
A14: competitive grants for climate mitigation | B14: 0.1 | D14: forest management
A15: competitive grants for climate mitigation | B15: 0.05 | D15: forest management
