Workbook

Sheet About
A1: SoBRCbIC Shr of Bldg Retrofitting Costs by ISIC Code
A3: Sources: | B3: Single-family deep retrofit: envelope work vs. heating and cooling equipment | D3: Which industry makes each piece of equipment
B4: Lawrence Berkeley National Laboratory (Less, Walker, Casquero-Modrego & Rainer) | D4: U.S. Census Bureau
B5: The Cost of Decarbonization and Energy Upgrade Retrofits for US Homes | D5: 2017 NAICS to ISIC Rev. 4 concordance
B6: 2021 | D6: 2017
B7: https://eta-publications.lbl.gov/sites/default/files/final_walker_-_the_cost_of_decarbonization_and_energy.pdf | D7: https://www.census.gov/naics/concordances/2017_NAICS_to_ISIC_4.xlsx
B8: Tables 4, 6, 7 and 8 (pp. 24-27), typed on the "LBNL 2021 Res Costs" tab for the two deep-retrofit clusters. Table 7 gives the median cost of each measure category among the projects that had it, and Table 8 the share of projects that had it; multiplying the two gives an expected cost per project. Medians do not add up to the cluster total, so use these only for shares, never as a project cost. | D8: Rows for the industries used here are on the "NAICS-ISIC Concordance" tab. Building automation controls map to ISIC 26, motors and drives to 27, pumps, burners and HVAC equipment to 28, and central heating boilers to 25.
B10: Which kind of project BRESaC's single-family cost describes | D10: Why envelope work and installation count as construction
B11: Lawrence Berkeley National Laboratory (Less & Walker) | D11: U.S. Bureau of Economic Analysis
B12: A Meta-Analysis of Single-Family Deep Energy Retrofit Performance in the U.S. | D12: NIPA Handbook, Chapter 6: Private Fixed Investment
B13: 2014 | D13: 2024
B14: https://www.osti.gov/servlets/purl/1129577 | D14: https://www.bea.gov/resources/methodologies/nipa-handbook/pdf/chapter-06.pdf
B15: This is the source of BRESaC's single-family cost. It did not record which measures each project installed (p. 6), so it cannot give the split by itself. It does describe the projects: they targeted "all or nearly all building assemblies" (p. 2), fuel switching was "relatively infrequent" (p. 17), and most came from cold-climate envelope programs. No numbers from it are used in this file. | D15: Table 6.1: investment in structures includes improvements (additions, alterations and major structural replacements) and equipment that is an integral part of the structure. The construction industry is the seller; its own purchases of insulation, lumber, windows and so on reach the makers through the input-output model. No numbers from it are used.
B17: Multifamily retrofit: envelope work vs. heating and cooling equipment | D17: Equipment vs. installation shares for heating and cooling equipment
B18: Building Energy Exchange | D18: EPS input file SoBCaICbIC
B19: Evaluating New York City's Multifamily Building Energy Data for Savings Opportunities: Retrofitting Affordability | D19: Share of Buildings Capital and Installation Costs by ISIC Code (built from EIA 2018, "Updated Buildings Sector Appliance and Equipment Costs and Efficiencies")
B20: 2015 | D20: 2026
B21: https://be-exchange.org/wp-content/uploads/2017/11/BEEx_Retrofitting_Affordability_Update_Nov2015-1.pdf | D21: https://www.eia.gov/analysis/studies/buildings/equipcosts/pdf/full.pdf
B22: Table 6 (p. 31), typed on the "BEEx 2015 MF Costs" tab: citywide cost of the measures recommended in NYC energy audits, by category. These are audit recommendations for large NYC buildings, not deep retrofits. Domestic hot water, lighting and "other" are left out, as BRESaC does for its multifamily cost. | D22: The published SoBCaICbIC values are copied to the "EPS Inputs" tab; the heating and cooling rows give the equipment part of an installed heating or cooling system. Update the tab if SoBCaICbIC changes.
B24: Commercial retrofit: equipment and installation cost of each measure | D24: Weights that match how BRESaC builds its retrofit cost
B25: Pacific Northwest National Laboratory | D25: EPS input file BRESaC
B26: Advanced Energy Retrofit Guides: Office Buildings (PNNL-20761) | D26: Bldg Retrofitting E Savings and Costs
B27: 2011 | D27: 2026
B28: https://www.pnnl.gov/main/publications/external/technical_reports/PNNL-20761.pdf | D28: https://www.eia.gov/outlooks/aeo/tables_side_xls.php
B29: Appendix 10 financial analysis tables for each measure (Equipment Cost and Install Cost columns), and Table 5.3 (p. 78) for which measures make up the deep retrofit package in each climate zone; both on the "PNNL Office Measures" tab. Equipment cost is "equipment and associated materials" with no labor (p. 119). Costs are for one large reference office building in January 2012 dollars and are totals, not increments over a code-minimum replacement. Not a cost survey of the US commercial stock. | D29: Household counts (AEO 2026 Table 4) and single-family / multifamily cost per BTU saved; commercial floorspace shares, cost per BTU saved by climate zone, and the list of measures counted. Values are on the "EPS Inputs" tab with the BRESaC cell each came from. Update the tab if BRESaC changes. The URL is AEO's table page.
B31: Wholesale, retail and freight markups on equipment bought by contractors
B32: U.S. Bureau of Economic Analysis
B33: Margins, Before Redefinitions, Detail (input-output accounts)
B34: 2017
B35: https://apps.bea.gov/industry/release/xlsx/Margins_Before_Redefinitions_Detail.xlsx
B36: Sheet "2017": rows for the five equipment commodities this file uses, bought by the construction industries (industry codes starting with 23), copied verbatim on the "BEA 2017 Margins" tab. Accessed October 2026. The shares are national averages over all construction purchases of each commodity, not retrofit-specific.
A39: Notes:
A40: What this file does | B40: When the building retrofitting policy is on, the EPS works out how much is spent on retrofits ("Amount Spent on Retrofitting Buildings"). This file says which industries receive that money, so the input-output model can work out the jobs and GDP effects. The retrofit cost is booked against the heating and cooling components, because that is where the energy savings are counted, so those two rows carry the retrofit split. The other rows copy SoBCaICbIC and carry no retrofit spending today.
A41: How the workbook is laid out | B41: The source tabs hold the published tables (typed from PDFs or copied from spreadsheets). "EPS Inputs" holds values from two other EPS input files. "Calcs" does the work in four sections: A, residential envelope share; B, equipment markups; C, commercial measures; D, the shares by industry. "Checks" should show zero problems. The three dark blue tabs are exported as the CSV files the model reads.
A42: The three rules | B42: Envelope work (insulation, air sealing, windows, roofing) and all installation labor go to construction (ISIC 41T43), the way the national accounts treat building improvements; the materials contractors buy then reach their makers through the input-output model. Equipment that is actually replaced (heat pumps, controls, motors, pumps, burners) goes to the industry that makes it. Of each equipment dollar, the wholesale and retail markup goes to trade (ISIC 45T47) and freight to transport (ISIC 49), using BEA's 2017 margins for equipment bought by contractors.
A43: Residential | B43: BRESaC's residential cost blends a single-family deep-retrofit study with a New York multifamily study, weighted by household counts. Here, the single-family envelope share comes from LBNL's 2021 "Superinsulation" cluster, the group of classic envelope-led deep retrofits that matches the projects in BRESaC's single-family source. LBNL's other deep cluster, "Electrification with PV", is mostly heat pumps and solar; you can switch to it with the selector in Calcs!B4 to see how much the split depends on this choice. The multifamily envelope share comes from the NYC audit data. The heating and cooling part is then split into equipment and installation the same way SoBCaICbIC splits a new system.
A44: Commercial | B44: For each measure BRESaC counts, PNNL gives an equipment cost and an installation cost in five climate zones. Each climate zone is weighted by its share of BRESaC's average cost per BTU (floorspace times cost per BTU), and within a zone each measure by its share of that zone's cost. Commercial heating and cooling get the same split, because the measures serve both. PNNL prices four of the measures (HA13, HA14, HA15 and HW15) as if each one had to upgrade the building's zone controls from pneumatic to digital. A building only does that once, so it is counted once, in HA13, as BRESaC does; the upgrade's cost is HA14 minus HA12, two versions of the same measure with and without it.
A45: What is not covered | B45: PNNL adds a planning and design allowance of 10% of construction cost for deep retrofit packages (p. 121). BRESaC does not include it, so this file has no professional services share; add one here if BRESaC adds that cost. Multifamily "fuel switching" (oil-to-gas boiler conversions) is treated as heating equipment. The commercial split rests on one reference office building.

Sheet LBNL 2021 Res Costs
A1: Less, Walker, Casquero-Modrego & Rainer (2021), "The Cost of Decarbonization and Energy Upgrade Retrofits for US Homes", Lawrence Berkeley National Laboratory. Typed from the report, Tables 4, 6, 7 and 8 (pp. 24-27).
A2: Only the two deep-retrofit clusters are transcribed (the report has six). Costs are 2019 dollars, medians across the projects in each cluster.
A4: Table 4. Cluster label descriptions
A5: Cluster | B5: Description
A6: Superinsulation | B6: Comprehensive deep retrofits focused on aggressive envelope upgrades (e.g. exterior wall insulation; triple pane windows; etc.) with some gas equipment and little or no PV
A7: Electrification with PV | B7: Equipment electrification projects that include moderate envelope upgrades and PV in all cases
A9: Table 6. Median cluster project characteristics
A10: Cluster | B10: Number of projects | C10: Number of measures | D10: Vintage | E10: Floor area (ft2) | F10: Project length (months) | G10: Total cost ($) | H10: Total cost ($/ft2)
A11: Superinsulation | B11: 15 | C11: 16 | D11: 1941 | E11: 1670 | F11: 15 | G11: 109059 | H11: 57
A12: Electrification with PV | B12: 43 | C12: 10 | D12: 1953 | E12: 1987 | F12: 4 | G12: 54098 | H12: 28
A14: Table 7. Median category cost for clusters with recorded costs in the measure category ($)
A15: Cluster | B15: PV | C15: HVAC | D15: House | E15: Appliance | F15: Doors and Windows | G15: Lighting | H15: DHW | I15: Electrical | J15: Seal and Insulate
A16: Superinsulation | B16: 29262 | C16: 13722 | D16: 34581 | E16: 1125 | F16: 11189 | G16: 1052 | H16: 3538 | I16: 643 | J16: 53421
A17: Electrification with PV | B17: 29443 | C17: 12314 | D17: 1900 | E17: 1832 | F17: 5347 | G17: 2864 | H17: 2503 | I17: 170 | J17: 11193
A19: Table 8. Fraction of cluster projects with each measure
A20: Cluster | B20: PV | C20: HVAC | D20: House | E20: Appliance | F20: Doors and Windows | G20: Lighting | H20: DHW | I20: Electrical | J20: Seal and Insulate
A21: Superinsulation | B21: 0.07 | C21: 1 | D21: 0.47 | E21: 0.07 | F21: 0.4 | G21: 0.07 | H21: 0.4 | I21: 0.33 | J21: 1
A22: Electrification with PV | B22: 1 | C22: 0.98 | D22: 0.02 | E22: 0.05 | F22: 0.09 | G22: 0.07 | H22: 0.53 | I22: 0.02 | J22: 0.91

Sheet BEEx 2015 MF Costs
A1: Building Energy Exchange (2015), "Evaluating New York City's Multifamily Building Energy Data for Savings Opportunities: Retrofitting Affordability". Typed from Table 6, p. 31.
A2: Table 6: Potential Source Energy Savings by ECM Category (citywide totals for covered multifamily buildings).
A4: Category | B4: Potential source energy savings (TBTU) | C4: Percent of total source energy potential savings | D4: GHG potential reduction (MMT CO2e) | E4: Percent of total GHG emissions reduction potential | F4: Citywide cost (million $) | G4: Percent of citywide cost | H4: Payback (years) | I4: Kept in BRESaC? 1 = yes (heating; cooling; envelope work) | J4: Envelope work? 1 = yes
A5: Heating & Distribution | B5: 7.9 | C5: 0.38 | D5: 0.4 | E5: 0.39 | F5: 350 | G5: 0.16 | H5: 4 | I5: 1 | J5: 0
A6: Domestic Hot Water | B6: 5.8 | C6: 0.28 | D6: 0.28 | E6: 0.27 | F6: 240 | G6: 0.11 | H6: 4 | I6: 0 | J6: 0
A7: Envelope | B7: 3.1 | C7: 0.15 | D7: 0.15 | E7: 0.15 | F7: 750 | G7: 0.34 | H7: 17 | I7: 1 | J7: 1
A8: Lighting | B8: 1.5 | C8: 0.07 | D8: 0.07 | E8: 0.07 | F8: 330 | G8: 0.15 | H8: 6 | I8: 0 | J8: 0
A9: Fuel Switching | B9: 1.1 | C9: 0.05 | D9: 0.06 | E9: 0.06 | F9: 350 | G9: 0.16 | H9: 4 | I9: 1 | J9: 0
A10: Ventilation & Cooling | B10: 0.8 | C10: 0.04 | D10: 0.04 | E10: 0.04 | F10: 60 | G10: 0.03 | H10: 9 | I10: 1 | J10: 0
A11: Other | B11: 0.8 | C11: 0.04 | D11: 0.03 | E11: 0.03 | F11: 110 | G11: 0.05 | H11: 4 | I11: 0 | J11: 0
A12: Total | B12: 20.9 | C12: 1 | D12: 1.03 | E12: 1 | F12: 2180 | G12: 1 | H12: 6
A14: The last two columns are added for this file. BRESaC removed domestic hot water, lighting and other measures from the multifamily costs, so the same categories are left out here.

Sheet PNNL Office Measures
A1: PNNL (2011), "Advanced Energy Retrofit Guides: Office Buildings", PNNL-20761. Appendix 10 financial analysis tables, Equipment Cost and Install Cost columns (January 2012 dollars, one large reference office).
A2: Equipment cost is "equipment and associated materials" and excludes labor; install cost is labor (p. 119). Values are total costs, not increments over a code baseline. E7 uses the AEDG-level table.
A4: Measure | B4: Measure name (PNNL) | C4: Appendix page | D4: Climate zone | E4: Equipment cost ($) | F4: Install cost ($) | G4: Total cost ($) | H4: In deep retrofit package (Table 5.3)? 1 = yes
A5: E7 | B5: Add roof insulation (AEDG level) | C5: 155 | D5: Hot & Humid | E5: 104502 | F5: 207856 | G5: 312358 | H5: 0
A6: E7 | B6: Add roof insulation (AEDG level) | C6: 155 | D6: Hot & Dry | E6: 139044 | F6: 237533 | G6: 376577 | H6: 1
A7: E7 | B7: Add roof insulation (AEDG level) | C7: 155 | D7: Marine | E7: 144000 | F7: 246000 | G7: 390000 | H7: 1
A8: E7 | B8: Add roof insulation (AEDG level) | C8: 155 | D8: Cold | E8: 136291 | F8: 232830 | G8: 369120 | H8: 1
A9: E7 | B9: Add roof insulation (AEDG level) | C9: 155 | D9: Very Cold | E9: 152707 | F9: 260168 | G9: 412876 | H9: 1
A10: HA12 | B10: Lower VAV box minimum flow setpoints (rebalance pneumatic boxes) | C10: 161 | D10: Hot & Humid | E10: 0 | F10: 36684 | G10: 36684 | H10: 0
A11: HA12 | B11: Lower VAV box minimum flow setpoints (rebalance pneumatic boxes) | C11: 161 | D11: Hot & Dry | E11: 0 | F11: 37014 | G11: 37014 | H11: 0
A12: HA12 | B12: Lower VAV box minimum flow setpoints (rebalance pneumatic boxes) | C12: 161 | D12: Marine | E12: 0 | F12: 38333 | G12: 38333 | H12: 0
A13: HA12 | B13: Lower VAV box minimum flow setpoints (rebalance pneumatic boxes) | C13: 161 | D13: Cold | E13: 0 | F13: 36281 | G13: 36281 | H13: 0
A14: HA12 | B14: Lower VAV box minimum flow setpoints (rebalance pneumatic boxes) | C14: 161 | D14: Very Cold | E14: 0 | F14: 36134 | G14: 36134 | H14: 0
A15: HA13 | B15: Widen zone temperature deadband; add conference room standby control (upgrade to DDC zone control) | C15: 163 | D15: Hot & Humid | E15: 66500 | F15: 147308 | G15: 213808 | H15: 1
A16: HA13 | B16: Widen zone temperature deadband; add conference room standby control (upgrade to DDC zone control) | C16: 163 | D16: Hot & Dry | E16: 67098 | F16: 148632 | G16: 215730 | H16: 1
... A69: HW16 | B69: Replace boiler burners with modulating burners | C69: 183 | D69: Very Cold | E69: 5656 | F69: 42463 | G69: 48119 | H69: 0
A71: The last column is typed from Table 5.3 (p. 78). HA12 and HW16 are not in the deep package; HA12 is kept because it is the same VAV setpoint measure as HA14 done without upgrading the controls to DDC.

Sheet BEA 2017 Margins
A1: Margins, Before Redefinitions, 2017
A2: [Millions of dollars]
A3: Bureau of Economic Analysis
E4: Producers' Value | F4: Transportation Costs | G4: Trade Margins | I4: Purchasers' Value
A5: Industry Code | B5: Industry Description | C5: Commodity Code | D5: Commodity Description | G5: Wholesale | H5: Retail
A6: 1111A0 | B6: Oilseed farming | C6: 1111A0 | D6: Oilseed farming | E6: 8332 | F6: 1105 | G6: 2723 | H6: 0 | I6: 12160
A7: 230301 | B7: Nonresidential maintenance and repair | C7: 333414 | D7: Heating equipment (except warm air furnaces) manufacturing | E7: 292 | F7: 9 | G7: 132 | H7: 132 | I7: 565
A8: 230301 | B8: Nonresidential maintenance and repair | C8: 333415 | D8: Air conditioning, refrigeration, and warm air heating equipment manufacturing | E8: 1367 | F8: 40 | G8: 202 | H8: 1248 | I8: 2857
A9: 230301 | B9: Nonresidential maintenance and repair | C9: 333914 | D9: Pump and pumping equipment manufacturing | E9: 248 | F9: 7 | G9: 47 | H9: 0 | I9: 302
A10: 230301 | B10: Nonresidential maintenance and repair | C10: 334512 | D10: Automatic environmental control manufacturing | E10: 206 | F10: 6 | G10: 40 | H10: 0 | I10: 252
A11: 230301 | B11: Nonresidential maintenance and repair | C11: 335312 | D11: Motor and generator manufacturing | E11: 174 | F11: 2 | G11: 55 | H11: 232 | I11: 462
A12: 230302 | B12: Residential maintenance and repair | C12: 333414 | D12: Heating equipment (except warm air furnaces) manufacturing | E12: 137 | F12: 4 | G12: 62 | H12: 70 | I12: 272
A13: 230302 | B13: Residential maintenance and repair | C13: 333415 | D13: Air conditioning, refrigeration, and warm air heating equipment manufacturing | E13: 662 | F13: 19 | G13: 83 | H13: 611 | I13: 1375
A14: 230302 | B14: Residential maintenance and repair | C14: 333914 | D14: Pump and pumping equipment manufacturing | E14: 335 | F14: 10 | G14: 64 | H14: 0 | I14: 408
A15: 230302 | B15: Residential maintenance and repair | C15: 334512 | D15: Automatic environmental control manufacturing | E15: 118 | F15: 3 | G15: 23 | H15: 0 | I15: 145
A16: 230302 | B16: Residential maintenance and repair | C16: 335312 | D16: Motor and generator manufacturing | E16: 58 | F16: 1 | G16: 18 | H16: 87 | I16: 164
A17: 233210 | B17: Health care structures | C17: 333413 | D17: Industrial and commercial fan and blower and air purification equipment manufacturing | E17: 121 | F17: 4 | G17: 54 | H17: 0 | I17: 179
A18: 233210 | B18: Health care structures | C18: 333414 | D18: Heating equipment (except warm air furnaces) manufacturing | E18: 96 | F18: 3 | G18: 43 | H18: 1 | I18: 143
... A42: 233262 | B42: Educational and vocational structures | C42: 335314 | D42: Relay and industrial control manufacturing | E42: 0 | F42: 0 | G42: 0 | H42: 0 | I42: 0
A43: 2332A0 | B43: Office and commercial structures | C43: 333413 | D43: Industrial and commercial fan and blower and air purification equipment manufacturing | E43: 245 | F43: 7 | G43: 68 | H43: 0 | I43: 320
A44: 2332A0 | B44: Office and commercial structures | C44: 333414 | D44: Heating equipment (except warm air furnaces) manufacturing | E44: 401 | F44: 12 | G44: 181 | H44: 0 | I44: 594
A45: 2332A0 | B45: Office and commercial structures | C45: 333415 | D45: Air conditioning, refrigeration, and warm air heating equipment manufacturing | E45: 2372 | F45: 69 | G45: 382 | H45: 30 | I45: 2852
A46: 2332A0 | B46: Office and commercial structures | C46: 333914 | D46: Pump and pumping equipment manufacturing | E46: 168 | F46: 5 | G46: 32 | H46: 0 | I46: 205
A47: 2332A0 | B47: Office and commercial structures | C47: 334512 | D47: Automatic environmental control manufacturing | E47: 340 | F47: 10 | G47: 66 | H47: 0 | I47: 416
A48: 2332A0 | B48: Office and commercial structures | C48: 335312 | D48: Motor and generator manufacturing | E48: 89 | F48: 1 | G48: 28 | H48: 0 | I48: 118
A49: 2332A0 | B49: Office and commercial structures | C49: 335314 | D49: Relay and industrial control manufacturing | E49: 0 | F49: 0 | G49: 0 | H49: 0 | I49: 0
A50: 2332C0 | B50: Transportation structures and highways and streets | C50: 333413 | D50: Industrial and commercial fan and blower and air purification equipment manufacturing | E50: 147 | F50: 4 | G50: 67 | H50: 0 | I50: 218
A51: 2332C0 | B51: Transportation structures and highways and streets | C51: 333414 | D51: Heating equipment (except warm air furnaces) manufacturing | E51: 139 | F51: 4 | G51: 63 | H51: 0 | I51: 206
A52: 2332C0 | B52: Transportation structures and highways and streets | C52: 333415 | D52: Air conditioning, refrigeration, and warm air heating equipment manufacturing | E52: 393 | F52: 11 | G52: 105 | H52: 0 | I52: 509
A53: 2332C0 | B53: Transportation structures and highways and streets | C53: 333914 | D53: Pump and pumping equipment manufacturing | E53: 319 | F53: 9 | G53: 61 | H53: 0 | I53: 389
A54: 2332C0 | B54: Transportation structures and highways and streets | C54: 334512 | D54: Automatic environmental control manufacturing | E54: 12 | F54: 0 | G54: 2 | H54: 0 | I54: 15
... A61: 2332D0 | B61: Other nonresidential structures | C61: 335312 | D61: Motor and generator manufacturing | E61: 62 | F61: 1 | G61: 19 | H61: 85 | I61: 167
A62: 233411 | B62: Single-family residential structures | C62: 333413 | D62: Industrial and commercial fan and blower and air purification equipment manufacturing | E62: 63 | F62: 2 | G62: 28 | H62: 0 | I62: 93
A63: 233411 | B63: Single-family residential structures | C63: 333414 | D63: Heating equipment (except warm air furnaces) manufacturing | E63: 294 | F63: 9 | G63: 133 | H63: 249 | I63: 684
A64: 233411 | B64: Single-family residential structures | C64: 333415 | D64: Air conditioning, refrigeration, and warm air heating equipment manufacturing | E64: 992 | F64: 29 | G64: 364 | H64: 1094 | I64: 2480
A65: 233411 | B65: Single-family residential structures | C65: 333914 | D65: Pump and pumping equipment manufacturing | E65: 1511 | F65: 44 | G65: 288 | H65: 0 | I65: 1842
A66: 233411 | B66: Single-family residential structures | C66: 334512 | D66: Automatic environmental control manufacturing | E66: 126 | F66: 4 | G66: 25 | H66: 0 | I66: 154
A67: 233411 | B67: Single-family residential structures | C67: 335312 | D67: Motor and generator manufacturing | E67: 95 | F67: 1 | G67: 30 | H67: 142 | I67: 267
A68: 233412 | B68: Multifamily residential structures | C68: 333413 | D68: Industrial and commercial fan and blower and air purification equipment manufacturing | E68: 66 | F68: 2 | G68: 28 | H68: 0 | I68: 97
A69: 233412 | B69: Multifamily residential structures | C69: 333414 | D69: Heating equipment (except warm air furnaces) manufacturing | E69: 87 | F69: 3 | G69: 39 | H69: 60 | I69: 189
...

Sheet NAICS-ISIC Concordance
A1: U.S. Census Bureau, 2017 NAICS to ISIC Rev. 4 concordance (technical version). Rows for the industries this file uses.
A3: Part of NAICS US | B3: 2017 NAICS US | C3: 2017 NAICS US title | D3: ISIC 4.0 | E3: ISIC Revision 4.0 title | F3: Notes (link content based on NAICS definition; entire NAICS industry if blank)
B4: 334512 | C4: Automatic Environmental Control Manufacturing for Residential, Commercial, and Appliance Use | D4: 2651 | E4: Manufacture of measuring, testing, navigating, and control equipment
B5: 335312 | C5: Motor and Generator Manufacturing | D5: 2710 | E5: Manufacture of electric motors, generators, transformers and electricity distribution and control apparatus
B6: 333914 | C6: Measuring, Dispensing, and Other Pumping Equipment Manufacturing | D6: 2813 | E6: Manufacture of other pumps, compressors, taps and valves
A7: * | B7: 333414 | C7: Heating Equipment (except Warm Air Furnaces) Manufacturing | D7: 2512 | E7: Manufacture of tanks, reservoirs and containers of metal | F7: central heating boilers and radiators
A8: * | B8: 333414 | C8: Heating Equipment (except Warm Air Furnaces) Manufacturing | D8: 2815 | E8: Manufacture of ovens, furnaces and furnace burners | F8: except central heating boilers and radiators
A9: * | B9: 333415 | C9: Air-Conditioning and Warm Air Heating Equipment and Commercial and Industrial Refrigeration Equipment Manufacturing | D9: 2813 | E9: Manufacture of other pumps, compressors, taps and valves | F9: air-conditioning compressors
A10: * | B10: 333415 | C10: Air-Conditioning and Warm Air Heating Equipment and Commercial and Industrial Refrigeration Equipment Manufacturing | D10: 2815 | E10: Manufacture of ovens, furnaces and furnace burners | F10: forced air heating furnaces and heat pumps
A11: * | B11: 333415 | C11: Air-Conditioning and Warm Air Heating Equipment and Commercial and Industrial Refrigeration Equipment Manufacturing | D11: 2819 | E11: Manufacture of other general-purpose machinery | F11: except separate air-conditioning compressors and forced air heating furnaces
B12: 236118 | C12: Residential Remodelers | D12: 4100 | E12: Construction of buildings
A13: * | B13: 238220 | C13: Plumbing, Heating, and Air-Conditioning Contractors | D13: 4322 | E13: Plumbing, heat and air-conditioning installation | F13: except boiler chipping, cleaning, and scaling; industrial furnace and power boiler installation; chimney liner installation
A14: * | B14: 238310 | C14: Drywall and Insulation Contractors | D14: 4329 | E14: Other construction installation | F14: soundproofing and building insulation contractors (wall cavity, attic, for example)
B15: 238160 | C15: Roofing Contractors | D15: 4390 | E15: Other specialized construction activities
B16: 238210 | C16: Electrical Contractors and Other Wiring Installation Contractors | D16: 4321 | E16: Electrical installation
A18: Commas in the source titles are kept; this tab is not exported. Census marks rows that cover only part of a NAICS industry with *, and the notes column says which part.

Sheet EPS Inputs
A1: Values taken from other EPS input files. Update them if those files change.
A3: SoBCaICbIC Share of Buildings Capital and Installation Costs by ISIC Code: urban residential (InputData/bldgs/SoBCaICbIC/SoBCaICbIC-urbanresidential.csv, pasted as published)
A4: Unit: dimensionless (%) | B4: ISIC 01 | C4: ISIC 02 | D4: ISIC 03 | E4: ISIC 05 | F4: ISIC 06 | G4: ISIC 07 | H4: ISIC 08 | I4: ISIC 09 | J4: ISIC 10T12 | K4: ISIC 13T15 | L4: ISIC 16 | M4: ISIC 17T18 | N4: ISIC 19 | O4: ISIC 20 | P4: ISIC 21 | Q4: ISIC 22 | R4: ISIC 231 | S4: ISIC 239 | T4: ISIC 241 | U4: ISIC 242 | V4: ISIC 25 | W4: ISIC 26 | X4: ISIC 27 | Y4: ISIC 28 | Z4: ISIC 29 | AA4: ISIC 301 | AB4: ISIC 302T309 | AC4: ISIC 31T33 | AD4: ISIC 351 | AE4: ISIC 352T353 | AF4: ISIC 36T39 | AG4: ISIC 41T43 | AH4: ISIC 45T47 | AI4: ISIC 49 | AJ4: ISIC 50 | AK4: ISIC 51 | AL4: ISIC 52 | AM4: ISIC 53 | AN4: ISIC 55T56 | AO4: ISIC 58T60 | AP4: ISIC 61 | AQ4: ISIC 62T63 | AR4: ISIC 64T66 | AS4: ISIC 68 | AT4: ISIC 69T75 | AU4: ISIC 77T82 | AV4: ISIC 84 | AW4: ISIC 85 | AX4: ISIC 86T88 | AY4: ISIC 90T93 | AZ4: ISIC 94T96 | BA4: ISIC 97T98
A5: Heating | B5: 0 | C5: 0 | D5: 0 | E5: 0 | F5: 0 | G5: 0 | H5: 0 | I5: 0 | J5: 0 | K5: 0 | L5: 0 | M5: 0 | N5: 0 | O5: 0 | P5: 0 | Q5: 0 | R5: 0 | S5: 0 | T5: 0 | U5: 0 | V5: 0 | W5: 0 | X5: 0 | Y5: 0.55028127 | Z5: 0 | AA5: 0 | AB5: 0 | AC5: 0 | AD5: 0 | AE5: 0 | AF5: 0 | AG5: 0.44971873 | AH5: 0 | AI5: 0 | AJ5: 0 | AK5: 0 | AL5: 0 | AM5: 0 | AN5: 0 | AO5: 0 | AP5: 0 | AQ5: 0 | AR5: 0 | AS5: 0 | AT5: 0 | AU5: 0 | AV5: 0 | AW5: 0 | AX5: 0 | AY5: 0 | AZ5: 0 | BA5: 0
A6: Cooling | B6: 0 | C6: 0 | D6: 0 | E6: 0 | F6: 0 | G6: 0 | H6: 0 | I6: 0 | J6: 0 | K6: 0 | L6: 0 | M6: 0 | N6: 0 | O6: 0 | P6: 0 | Q6: 0 | R6: 0 | S6: 0 | T6: 0 | U6: 0 | V6: 0 | W6: 0 | X6: 0 | Y6: 0.73624569 | Z6: 0 | AA6: 0 | AB6: 0 | AC6: 0 | AD6: 0 | AE6: 0 | AF6: 0 | AG6: 0.26375431 | AH6: 0 | AI6: 0 | AJ6: 0 | AK6: 0 | AL6: 0 | AM6: 0 | AN6: 0 | AO6: 0 | AP6: 0 | AQ6: 0 | AR6: 0 | AS6: 0 | AT6: 0 | AU6: 0 | AV6: 0 | AW6: 0 | AX6: 0 | AY6: 0 | AZ6: 0 | BA6: 0
A7: Envelope | B7: 0 | C7: 0 | D7: 0 | E7: 0 | F7: 0 | G7: 0 | H7: 0 | I7: 0 | J7: 0 | K7: 0 | L7: 0 | M7: 0 | N7: 0 | O7: 0 | P7: 0 | Q7: 0 | R7: 0 | S7: 0 | T7: 0 | U7: 0 | V7: 0 | W7: 0 | X7: 0 | Y7: 0 | Z7: 0 | AA7: 0 | AB7: 0 | AC7: 0 | AD7: 0 | AE7: 0 | AF7: 0 | AG7: 0 | AH7: 0 | AI7: 0 | AJ7: 0 | AK7: 0 | AL7: 0 | AM7: 0 | AN7: 0 | AO7: 0 | AP7: 0 | AQ7: 0 | AR7: 0 | AS7: 0 | AT7: 0 | AU7: 0 | AV7: 0 | AW7: 0 | AX7: 0 | AY7: 0 | AZ7: 0 | BA7: 0
A8: Lighting | B8: 0 | C8: 0 | D8: 0 | E8: 0 | F8: 0 | G8: 0 | H8: 0 | I8: 0 | J8: 0 | K8: 0 | L8: 0 | M8: 0 | N8: 0 | O8: 0 | P8: 0 | Q8: 0 | R8: 0 | S8: 0 | T8: 0 | U8: 0 | V8: 0 | W8: 0 | X8: 1 | Y8: 0 | Z8: 0 | AA8: 0 | AB8: 0 | AC8: 0 | AD8: 0 | AE8: 0 | AF8: 0 | AG8: 0 | AH8: 0 | AI8: 0 | AJ8: 0 | AK8: 0 | AL8: 0 | AM8: 0 | AN8: 0 | AO8: 0 | AP8: 0 | AQ8: 0 | AR8: 0 | AS8: 0 | AT8: 0 | AU8: 0 | AV8: 0 | AW8: 0 | AX8: 0 | AY8: 0 | AZ8: 0 | BA8: 0
A9: Appliances | B9: 0 | C9: 0 | D9: 0 | E9: 0 | F9: 0 | G9: 0 | H9: 0 | I9: 0 | J9: 0 | K9: 0 | L9: 0 | M9: 0 | N9: 0 | O9: 0 | P9: 0 | Q9: 0 | R9: 0 | S9: 0 | T9: 0 | U9: 0 | V9: 0 | W9: 0 | X9: 0.75435142 | Y9: 0 | Z9: 0 | AA9: 0 | AB9: 0 | AC9: 0 | AD9: 0 | AE9: 0 | AF9: 0 | AG9: 0.24564858 | AH9: 0 | AI9: 0 | AJ9: 0 | AK9: 0 | AL9: 0 | AM9: 0 | AN9: 0 | AO9: 0 | AP9: 0 | AQ9: 0 | AR9: 0 | AS9: 0 | AT9: 0 | AU9: 0 | AV9: 0 | AW9: 0 | AX9: 0 | AY9: 0 | AZ9: 0 | BA9: 0
A10: Other | B10: 0 | C10: 0 | D10: 0 | E10: 0 | F10: 0 | G10: 0 | H10: 0 | I10: 0 | J10: 0 | K10: 0 | L10: 0 | M10: 0 | N10: 0 | O10: 0 | P10: 0 | Q10: 0 | R10: 0 | S10: 0 | T10: 0 | U10: 0 | V10: 0 | W10: 0 | X10: 0.75435142 | Y10: 0 | Z10: 0 | AA10: 0 | AB10: 0 | AC10: 0 | AD10: 0 | AE10: 0 | AF10: 0 | AG10: 0.24564858 | AH10: 0 | AI10: 0 | AJ10: 0 | AK10: 0 | AL10: 0 | AM10: 0 | AN10: 0 | AO10: 0 | AP10: 0 | AQ10: 0 | AR10: 0 | AS10: 0 | AT10: 0 | AU10: 0 | AV10: 0 | AW10: 0 | AX10: 0 | AY10: 0 | AZ10: 0 | BA10: 0
A12: SoBCaICbIC Share of Buildings Capital and Installation Costs by ISIC Code: rural residential (InputData/bldgs/SoBCaICbIC/SoBCaICbIC-ruralresidential.csv, pasted as published)
A13: Unit: dimensionless (%) | B13: ISIC 01 | C13: ISIC 02 | D13: ISIC 03 | E13: ISIC 05 | F13: ISIC 06 | G13: ISIC 07 | H13: ISIC 08 | I13: ISIC 09 | J13: ISIC 10T12 | K13: ISIC 13T15 | L13: ISIC 16 | M13: ISIC 17T18 | N13: ISIC 19 | O13: ISIC 20 | P13: ISIC 21 | Q13: ISIC 22 | R13: ISIC 231 | S13: ISIC 239 | T13: ISIC 241 | U13: ISIC 242 | V13: ISIC 25 | W13: ISIC 26 | X13: ISIC 27 | Y13: ISIC 28 | Z13: ISIC 29 | AA13: ISIC 301 | AB13: ISIC 302T309 | AC13: ISIC 31T33 | AD13: ISIC 351 | AE13: ISIC 352T353 | AF13: ISIC 36T39 | AG13: ISIC 41T43 | AH13: ISIC 45T47 | AI13: ISIC 49 | AJ13: ISIC 50 | AK13: ISIC 51 | AL13: ISIC 52 | AM13: ISIC 53 | AN13: ISIC 55T56 | AO13: ISIC 58T60 | AP13: ISIC 61 | AQ13: ISIC 62T63 | AR13: ISIC 64T66 | AS13: ISIC 68 | AT13: ISIC 69T75 | AU13: ISIC 77T82 | AV13: ISIC 84 | AW13: ISIC 85 | AX13: ISIC 86T88 | AY13: ISIC 90T93 | AZ13: ISIC 94T96 | BA13: ISIC 97T98
A14: Heating | B14: 0 | C14: 0 | D14: 0 | E14: 0 | F14: 0 | G14: 0 | H14: 0 | I14: 0 | J14: 0 | K14: 0 | L14: 0 | M14: 0 | N14: 0 | O14: 0 | P14: 0 | Q14: 0 | R14: 0 | S14: 0 | T14: 0 | U14: 0 | V14: 0 | W14: 0 | X14: 0 | Y14: 0.55028127 | Z14: 0 | AA14: 0 | AB14: 0 | AC14: 0 | AD14: 0 | AE14: 0 | AF14: 0 | AG14: 0.44971873 | AH14: 0 | AI14: 0 | AJ14: 0 | AK14: 0 | AL14: 0 | AM14: 0 | AN14: 0 | AO14: 0 | AP14: 0 | AQ14: 0 | AR14: 0 | AS14: 0 | AT14: 0 | AU14: 0 | AV14: 0 | AW14: 0 | AX14: 0 | AY14: 0 | AZ14: 0 | BA14: 0
A15: Cooling | B15: 0 | C15: 0 | D15: 0 | E15: 0 | F15: 0 | G15: 0 | H15: 0 | I15: 0 | J15: 0 | K15: 0 | L15: 0 | M15: 0 | N15: 0 | O15: 0 | P15: 0 | Q15: 0 | R15: 0 | S15: 0 | T15: 0 | U15: 0 | V15: 0 | W15: 0 | X15: 0 | Y15: 0.73624569 | Z15: 0 | AA15: 0 | AB15: 0 | AC15: 0 | AD15: 0 | AE15: 0 | AF15: 0 | AG15: 0.26375431 | AH15: 0 | AI15: 0 | AJ15: 0 | AK15: 0 | AL15: 0 | AM15: 0 | AN15: 0 | AO15: 0 | AP15: 0 | AQ15: 0 | AR15: 0 | AS15: 0 | AT15: 0 | AU15: 0 | AV15: 0 | AW15: 0 | AX15: 0 | AY15: 0 | AZ15: 0 | BA15: 0
A16: Envelope | B16: 0 | C16: 0 | D16: 0 | E16: 0 | F16: 0 | G16: 0 | H16: 0 | I16: 0 | J16: 0 | K16: 0 | L16: 0 | M16: 0 | N16: 0 | O16: 0 | P16: 0 | Q16: 0 | R16: 0 | S16: 0 | T16: 0 | U16: 0 | V16: 0 | W16: 0 | X16: 0 | Y16: 0 | Z16: 0 | AA16: 0 | AB16: 0 | AC16: 0 | AD16: 0 | AE16: 0 | AF16: 0 | AG16: 0 | AH16: 0 | AI16: 0 | AJ16: 0 | AK16: 0 | AL16: 0 | AM16: 0 | AN16: 0 | AO16: 0 | AP16: 0 | AQ16: 0 | AR16: 0 | AS16: 0 | AT16: 0 | AU16: 0 | AV16: 0 | AW16: 0 | AX16: 0 | AY16: 0 | AZ16: 0 | BA16: 0
A17: Lighting | B17: 0 | C17: 0 | D17: 0 | E17: 0 | F17: 0 | G17: 0 | H17: 0 | I17: 0 | J17: 0 | K17: 0 | L17: 0 | M17: 0 | N17: 0 | O17: 0 | P17: 0 | Q17: 0 | R17: 0 | S17: 0 | T17: 0 | U17: 0 | V17: 0 | W17: 0 | X17: 1 | Y17: 0 | Z17: 0 | AA17: 0 | AB17: 0 | AC17: 0 | AD17: 0 | AE17: 0 | AF17: 0 | AG17: 0 | AH17: 0 | AI17: 0 | AJ17: 0 | AK17: 0 | AL17: 0 | AM17: 0 | AN17: 0 | AO17: 0 | AP17: 0 | AQ17: 0 | AR17: 0 | AS17: 0 | AT17: 0 | AU17: 0 | AV17: 0 | AW17: 0 | AX17: 0 | AY17: 0 | AZ17: 0 | BA17: 0
A18: Appliances | B18: 0 | C18: 0 | D18: 0 | E18: 0 | F18: 0 | G18: 0 | H18: 0 | I18: 0 | J18: 0 | K18: 0 | L18: 0 | M18: 0 | N18: 0 | O18: 0 | P18: 0 | Q18: 0 | R18: 0 | S18: 0 | T18: 0 | U18: 0 | V18: 0 | W18: 0 | X18: 0.75435142 | Y18: 0 | Z18: 0 | AA18: 0 | AB18: 0 | AC18: 0 | AD18: 0 | AE18: 0 | AF18: 0 | AG18: 0.24564858 | AH18: 0 | AI18: 0 | AJ18: 0 | AK18: 0 | AL18: 0 | AM18: 0 | AN18: 0 | AO18: 0 | AP18: 0 | AQ18: 0 | AR18: 0 | AS18: 0 | AT18: 0 | AU18: 0 | AV18: 0 | AW18: 0 | AX18: 0 | AY18: 0 | AZ18: 0 | BA18: 0
A19: Other | B19: 0 | C19: 0 | D19: 0 | E19: 0 | F19: 0 | G19: 0 | H19: 0 | I19: 0 | J19: 0 | K19: 0 | L19: 0 | M19: 0 | N19: 0 | O19: 0 | P19: 0 | Q19: 0 | R19: 0 | S19: 0 | T19: 0 | U19: 0 | V19: 0 | W19: 0 | X19: 0.75435142 | Y19: 0 | Z19: 0 | AA19: 0 | AB19: 0 | AC19: 0 | AD19: 0 | AE19: 0 | AF19: 0 | AG19: 0.24564858 | AH19: 0 | AI19: 0 | AJ19: 0 | AK19: 0 | AL19: 0 | AM19: 0 | AN19: 0 | AO19: 0 | AP19: 0 | AQ19: 0 | AR19: 0 | AS19: 0 | AT19: 0 | AU19: 0 | AV19: 0 | AW19: 0 | AX19: 0 | AY19: 0 | AZ19: 0 | BA19: 0
A21: SoBCaICbIC Share of Buildings Capital and Installation Costs by ISIC Code: commercial (InputData/bldgs/SoBCaICbIC/SoBCaICbIC-commercial.csv, pasted as published)
A22: Unit: dimensionless (%) | B22: ISIC 01 | C22: ISIC 02 | D22: ISIC 03 | E22: ISIC 05 | F22: ISIC 06 | G22: ISIC 07 | H22: ISIC 08 | I22: ISIC 09 | J22: ISIC 10T12 | K22: ISIC 13T15 | L22: ISIC 16 | M22: ISIC 17T18 | N22: ISIC 19 | O22: ISIC 20 | P22: ISIC 21 | Q22: ISIC 22 | R22: ISIC 231 | S22: ISIC 239 | T22: ISIC 241 | U22: ISIC 242 | V22: ISIC 25 | W22: ISIC 26 | X22: ISIC 27 | Y22: ISIC 28 | Z22: ISIC 29 | AA22: ISIC 301 | AB22: ISIC 302T309 | AC22: ISIC 31T33 | AD22: ISIC 351 | AE22: ISIC 352T353 | AF22: ISIC 36T39 | AG22: ISIC 41T43 | AH22: ISIC 45T47 | AI22: ISIC 49 | AJ22: ISIC 50 | AK22: ISIC 51 | AL22: ISIC 52 | AM22: ISIC 53 | AN22: ISIC 55T56 | AO22: ISIC 58T60 | AP22: ISIC 61 | AQ22: ISIC 62T63 | AR22: ISIC 64T66 | AS22: ISIC 68 | AT22: ISIC 69T75 | AU22: ISIC 77T82 | AV22: ISIC 84 | AW22: ISIC 85 | AX22: ISIC 86T88 | AY22: ISIC 90T93 | AZ22: ISIC 94T96 | BA22: ISIC 97T98
A23: Heating | B23: 0 | C23: 0 | D23: 0 | E23: 0 | F23: 0 | G23: 0 | H23: 0 | I23: 0 | J23: 0 | K23: 0 | L23: 0 | M23: 0 | N23: 0 | O23: 0 | P23: 0 | Q23: 0 | R23: 0 | S23: 0 | T23: 0 | U23: 0 | V23: 0 | W23: 0 | X23: 0 | Y23: 0.7039875 | Z23: 0 | AA23: 0 | AB23: 0 | AC23: 0 | AD23: 0 | AE23: 0 | AF23: 0 | AG23: 0.2960125 | AH23: 0 | AI23: 0 | AJ23: 0 | AK23: 0 | AL23: 0 | AM23: 0 | AN23: 0 | AO23: 0 | AP23: 0 | AQ23: 0 | AR23: 0 | AS23: 0 | AT23: 0 | AU23: 0 | AV23: 0 | AW23: 0 | AX23: 0 | AY23: 0 | AZ23: 0 | BA23: 0
A24: Cooling | B24: 0 | C24: 0 | D24: 0 | E24: 0 | F24: 0 | G24: 0 | H24: 0 | I24: 0 | J24: 0 | K24: 0 | L24: 0 | M24: 0 | N24: 0 | O24: 0 | P24: 0 | Q24: 0 | R24: 0 | S24: 0 | T24: 0 | U24: 0 | V24: 0 | W24: 0 | X24: 0 | Y24: 0.57983011 | Z24: 0 | AA24: 0 | AB24: 0 | AC24: 0 | AD24: 0 | AE24: 0 | AF24: 0 | AG24: 0.42016989 | AH24: 0 | AI24: 0 | AJ24: 0 | AK24: 0 | AL24: 0 | AM24: 0 | AN24: 0 | AO24: 0 | AP24: 0 | AQ24: 0 | AR24: 0 | AS24: 0 | AT24: 0 | AU24: 0 | AV24: 0 | AW24: 0 | AX24: 0 | AY24: 0 | AZ24: 0 | BA24: 0
A25: Envelope | B25: 0 | C25: 0 | D25: 0 | E25: 0 | F25: 0 | G25: 0 | H25: 0 | I25: 0 | J25: 0 | K25: 0 | L25: 0 | M25: 0 | N25: 0 | O25: 0 | P25: 0 | Q25: 0 | R25: 0 | S25: 0 | T25: 0 | U25: 0 | V25: 0 | W25: 0 | X25: 0 | Y25: 0 | Z25: 0 | AA25: 0 | AB25: 0 | AC25: 0 | AD25: 0 | AE25: 0 | AF25: 0 | AG25: 0 | AH25: 0 | AI25: 0 | AJ25: 0 | AK25: 0 | AL25: 0 | AM25: 0 | AN25: 0 | AO25: 0 | AP25: 0 | AQ25: 0 | AR25: 0 | AS25: 0 | AT25: 0 | AU25: 0 | AV25: 0 | AW25: 0 | AX25: 0 | AY25: 0 | AZ25: 0 | BA25: 0
A26: Lighting | B26: 0 | C26: 0 | D26: 0 | E26: 0 | F26: 0 | G26: 0 | H26: 0 | I26: 0 | J26: 0 | K26: 0 | L26: 0 | M26: 0 | N26: 0 | O26: 0 | P26: 0 | Q26: 0 | R26: 0 | S26: 0 | T26: 0 | U26: 0 | V26: 0 | W26: 0 | X26: 0.40766895 | Y26: 0 | Z26: 0 | AA26: 0 | AB26: 0 | AC26: 0 | AD26: 0 | AE26: 0 | AF26: 0 | AG26: 0.59233105 | AH26: 0 | AI26: 0 | AJ26: 0 | AK26: 0 | AL26: 0 | AM26: 0 | AN26: 0 | AO26: 0 | AP26: 0 | AQ26: 0 | AR26: 0 | AS26: 0 | AT26: 0 | AU26: 0 | AV26: 0 | AW26: 0 | AX26: 0 | AY26: 0 | AZ26: 0 | BA26: 0
A27: Appliances | B27: 0 | C27: 0 | D27: 0 | E27: 0 | F27: 0 | G27: 0 | H27: 0 | I27: 0 | J27: 0 | K27: 0 | L27: 0 | M27: 0 | N27: 0 | O27: 0 | P27: 0 | Q27: 0 | R27: 0 | S27: 0 | T27: 0 | U27: 0 | V27: 0 | W27: 0 | X27: 0.75439887 | Y27: 0 | Z27: 0 | AA27: 0 | AB27: 0 | AC27: 0 | AD27: 0 | AE27: 0 | AF27: 0 | AG27: 0.24560113 | AH27: 0 | AI27: 0 | AJ27: 0 | AK27: 0 | AL27: 0 | AM27: 0 | AN27: 0 | AO27: 0 | AP27: 0 | AQ27: 0 | AR27: 0 | AS27: 0 | AT27: 0 | AU27: 0 | AV27: 0 | AW27: 0 | AX27: 0 | AY27: 0 | AZ27: 0 | BA27: 0
A28: Other | B28: 0 | C28: 0 | D28: 0 | E28: 0 | F28: 0 | G28: 0 | H28: 0 | I28: 0 | J28: 0 | K28: 0 | L28: 0 | M28: 0 | N28: 0 | O28: 0 | P28: 0 | Q28: 0 | R28: 0 | S28: 0 | T28: 0 | U28: 0 | V28: 0 | W28: 0 | X28: 0.75439887 | Y28: 0 | Z28: 0 | AA28: 0 | AB28: 0 | AC28: 0 | AD28: 0 | AE28: 0 | AF28: 0 | AG28: 0.24560113 | AH28: 0 | AI28: 0 | AJ28: 0 | AK28: 0 | AL28: 0 | AM28: 0 | AN28: 0 | AO28: 0 | AP28: 0 | AQ28: 0 | AR28: 0 | AS28: 0 | AT28: 0 | AU28: 0 | AV28: 0 | AW28: 0 | AX28: 0 | AY28: 0 | AZ28: 0 | BA28: 0
A30: BRESaC Retrofitting Cost per Unit Energy Saved: residential inputs (InputData/bldgs/BRESaC/Bldg Retrofitting E Savings and Costs.xlsx)
A31: Building group | B31: Households (millions), AEO26 Table 4 | C31: Retrofit cost per unit energy saved ($/BTU) | D31: BRESaC cell
A32: Single-family | B32: 89.551808 | C32: 0.00054255034 | D32: 'AEO26 Table 4'!E8; 'Residential'!B6
A33: Multifamily | B33: 34.432312 | C33: 0.00011262662 | D33: 'AEO26 Table 4'!E9; 'Residential'!C50
A35: BRESaC: commercial inputs (same workbook, Commercial tab)
A36: Climate zone | B36: Share of commercial floorspace (Commercial!I) | C36: Retrofit cost per unit energy saved ($/BTU) (Commercial!N)
A37: Hot & Humid | B37: 0.40566318 | C37: 9.1827575e-05
A38: Hot & Dry | B38: 0.061563025 | C38: 0.00019596788
A39: Marine | B39: 0.037672564 | C39: 0.00019606405
A40: Cold | B40: 0.45140543 | C40: 0.00021417365
A41: Very Cold | B41: 0.043695805 | C41: 0.00021527233
A43: BRESaC: commercial measures included in the retrofit cost (Commercial tab, columns A, B and F)
A44: Climate zone | B44: Measure (as labeled in BRESaC) | C44: Included? 1 = yes | D44: Measure code
A45: Hot & Humid | B45: E7 Add AEDG roof insulation | C45: 0 | D45: =LEFT(B45,FIND(" ",B45)-1) -> E7
A46: Hot & Dry | B46: E7 Add AEDG roof insulation | C46: 1 | D46: =LEFT(B46,FIND(" ",B46)-1) -> E7
...

Sheet Calcs
A1: A. Residential: how much of retrofit spending is envelope work
A2: What share of a residential retrofit dollar pays for envelope work (insulation, air sealing, windows) rather than heating and cooling equipment? Answer in B16.
A4: Single-family stand-in cluster (pick one) | B4: Superinsulation | C4: LBNL 2021 cluster that best matches the projects in BRESaC's single-family source (see About).
A6: Expected cost per project by category median cost x share of projects with it ($) | B6: PV | C6: HVAC | D6: House | E6: Appliance | F6: Doors and Windows | G6: Lighting | H6: DHW | I6: Electrical | J6: Seal and Insulate
A7: Superinsulation | B7: ='LBNL 2021 Res Costs'!B16*'LBNL 2021 Res Costs'!B21 -> 2048.34 | C7: ='LBNL 2021 Res Costs'!C16*'LBNL 2021 Res Costs'!C21 -> 13722 | D7: ='LBNL 2021 Res Costs'!D16*'LBNL 2021 Res Costs'!D21 -> 16253.07 | E7: ='LBNL 2021 Res Costs'!E16*'LBNL 2021 Res Costs'!E21 -> 78.75 | F7: ='LBNL 2021 Res Costs'!F16*'LBNL 2021 Res Costs'!F21 -> 4475.6 | G7: ='LBNL 2021 Res Costs'!G16*'LBNL 2021 Res Costs'!G21 -> 73.64 | H7: ='LBNL 2021 Res Costs'!H16*'LBNL 2021 Res Costs'!H21 -> 1415.2 | I7: ='LBNL 2021 Res Costs'!I16*'LBNL 2021 Res Costs'!I21 -> 212.19 | J7: ='LBNL 2021 Res Costs'!J16*'LBNL 2021 Res Costs'!J21 -> 53421
A8: Electrification with PV | B8: ='LBNL 2021 Res Costs'!B17*'LBNL 2021 Res Costs'!B22 -> 29443 | C8: ='LBNL 2021 Res Costs'!C17*'LBNL 2021 Res Costs'!C22 -> 12067.72 | D8: ='LBNL 2021 Res Costs'!D17*'LBNL 2021 Res Costs'!D22 -> 38 | E8: ='LBNL 2021 Res Costs'!E17*'LBNL 2021 Res Costs'!E22 -> 91.6 | F8: ='LBNL 2021 Res Costs'!F17*'LBNL 2021 Res Costs'!F22 -> 481.23 | G8: ='LBNL 2021 Res Costs'!G17*'LBNL 2021 Res Costs'!G22 -> 200.48 | H8: ='LBNL 2021 Res Costs'!H17*'LBNL 2021 Res Costs'!H22 -> 1326.59 | I8: ='LBNL 2021 Res Costs'!I17*'LBNL 2021 Res Costs'!I22 -> 3.4 | J8: ='LBNL 2021 Res Costs'!J17*'LBNL 2021 Res Costs'!J22 -> 10185.63
B9: Envelope work house + doors & windows + seal & insulate ($) | C9: Heating and cooling equipment HVAC ($) | D9: Envelope share of envelope + HVAC
A10: Superinsulation | B10: =D7+F7+J7 -> 74149.67 | C10: =C7 -> 13722 | D10: =B10/(B10+C10) -> 0.84384046
A11: Electrification with PV | B11: =D8+F8+J8 -> 10704.86 | C11: =C8 -> 12067.72 | D11: =B11/(B11+C11) -> 0.47007673
A12: Single-family envelope share used | B12: =INDEX(D10:D11,MATCH(B4,A10:A11,0)) -> 0.84384046
A13: Multifamily envelope share (BEEx) | B13: =SUMIFS('BEEx 2015 MF Costs'!F5:F11,'BEEx 2015 MF Costs'!I5:I11,1,'BEEx 2015 MF Costs'!J5:J11,1)/SUMIFS('BEEx 2015 MF Costs'!F5:F11,'BEEx 2015 MF Costs'!I5:I11,1) -> 0.49668874 | C13: Envelope cost / cost of the categories BRESaC keeps (heating & distribution, envelope, fuel switching, ventilation & cooling).
A14: Single-family weight in BRESaC residential cost | B14: ='EPS Inputs'!B32*'EPS Inputs'!C32/('EPS Inputs'!B32*'EPS Inputs'!C32+'EPS Inputs'!B33*'EPS Inputs'!C33) -> 0.92608325 | C14: BRESaC averages the two $/BTU figures by household count, so each group's share of the average is households x $/BTU.
A15: Multifamily weight | B15: =1-B14 -> 0.07391675
A16: RESIDENTIAL ENVELOPE SHARE USED IN THE OUTPUT FILE | B16: =B14*B12+B15*B13 -> 0.81818013
A18: B. Markups on equipment bought by construction contractors (BEA 2017)
A19: Of each dollar a contractor pays for a piece of equipment, how much is the manufacturer's price, freight, and wholesale + retail markup?
A20: BEA commodity code | B20: Commodity | C20: Producers' value ($M) | D20: Transportation costs ($M) | E20: Wholesale margin ($M) | F20: Retail margin ($M) | G20: Purchasers' value ($M) | H20: Manufacturer's share (to the making industry) | I20: Freight share (to ISIC 49) | J20: Wholesale + retail share (to ISIC 45T47)
A21: 333415 | B21: Air conditioning, refrigeration, and warm air heating equipment | C21: =SUMIFS('BEA 2017 Margins'!E$7:E$78,'BEA 2017 Margins'!$C$7:$C$78,$A21) -> 10554 | D21: =SUMIFS('BEA 2017 Margins'!F$7:F$78,'BEA 2017 Margins'!$C$7:$C$78,$A21) -> 306 | E21: =SUMIFS('BEA 2017 Margins'!G$7:G$78,'BEA 2017 Margins'!$C$7:$C$78,$A21) -> 2454 | F21: =SUMIFS('BEA 2017 Margins'!H$7:H$78,'BEA 2017 Margins'!$C$7:$C$78,$A21) -> 5133 | G21: =SUMIFS('BEA 2017 Margins'!I$7:I$78,'BEA 2017 Margins'!$C$7:$C$78,$A21) -> 18449 | H21: =C21/SUM(C21:F21) -> 0.57212555 | I21: =D21/SUM(C21:F21) -> 0.016588063 | J21: =(E21+F21)/SUM(C21:F21) -> 0.41128639
A22: 334512 | B22: Automatic environmental controls | C22: =SUMIFS('BEA 2017 Margins'!E$7:E$78,'BEA 2017 Margins'!$C$7:$C$78,$A22) -> 2595 | D22: =SUMIFS('BEA 2017 Margins'!F$7:F$78,'BEA 2017 Margins'!$C$7:$C$78,$A22) -> 75 | E22: =SUMIFS('BEA 2017 Margins'!G$7:G$78,'BEA 2017 Margins'!$C$7:$C$78,$A22) -> 506 | F22: =SUMIFS('BEA 2017 Margins'!H$7:H$78,'BEA 2017 Margins'!$C$7:$C$78,$A22) -> 0 | G22: =SUMIFS('BEA 2017 Margins'!I$7:I$78,'BEA 2017 Margins'!$C$7:$C$78,$A22) -> 3176 | H22: =C22/SUM(C22:F22) -> 0.81706549 | I22: =D22/SUM(C22:F22) -> 0.02361461 | J22: =(E22+F22)/SUM(C22:F22) -> 0.1593199
A23: 335312 | B23: Motors and generators | C23: =SUMIFS('BEA 2017 Margins'!E$7:E$78,'BEA 2017 Margins'!$C$7:$C$78,$A23) -> 1064 | D23: =SUMIFS('BEA 2017 Margins'!F$7:F$78,'BEA 2017 Margins'!$C$7:$C$78,$A23) -> 11 | E23: =SUMIFS('BEA 2017 Margins'!G$7:G$78,'BEA 2017 Margins'!$C$7:$C$78,$A23) -> 334 | F23: =SUMIFS('BEA 2017 Margins'!H$7:H$78,'BEA 2017 Margins'!$C$7:$C$78,$A23) -> 691 | G23: =SUMIFS('BEA 2017 Margins'!I$7:I$78,'BEA 2017 Margins'!$C$7:$C$78,$A23) -> 2095 | H23: =C23/SUM(C23:F23) -> 0.50666667 | I23: =D23/SUM(C23:F23) -> 0.0052380952 | J23: =(E23+F23)/SUM(C23:F23) -> 0.48809524
A24: 333914 | B24: Pumps and pumping equipment | C24: =SUMIFS('BEA 2017 Margins'!E$7:E$78,'BEA 2017 Margins'!$C$7:$C$78,$A24) -> 4848 | D24: =SUMIFS('BEA 2017 Margins'!F$7:F$78,'BEA 2017 Margins'!$C$7:$C$78,$A24) -> 142 | E24: =SUMIFS('BEA 2017 Margins'!G$7:G$78,'BEA 2017 Margins'!$C$7:$C$78,$A24) -> 924 | F24: =SUMIFS('BEA 2017 Margins'!H$7:H$78,'BEA 2017 Margins'!$C$7:$C$78,$A24) -> 0 | G24: =SUMIFS('BEA 2017 Margins'!I$7:I$78,'BEA 2017 Margins'!$C$7:$C$78,$A24) -> 5911 | H24: =C24/SUM(C24:F24) -> 0.81974975 | I24: =D24/SUM(C24:F24) -> 0.024010822 | J24: =(E24+F24)/SUM(C24:F24) -> 0.15623943
A25: 333414 | B25: Heating equipment (except warm air furnaces) | C25: =SUMIFS('BEA 2017 Margins'!E$7:E$78,'BEA 2017 Margins'!$C$7:$C$78,$A25) -> 2540 | D25: =SUMIFS('BEA 2017 Margins'!F$7:F$78,'BEA 2017 Margins'!$C$7:$C$78,$A25) -> 77 | E25: =SUMIFS('BEA 2017 Margins'!G$7:G$78,'BEA 2017 Margins'!$C$7:$C$78,$A25) -> 1148 | F25: =SUMIFS('BEA 2017 Margins'!H$7:H$78,'BEA 2017 Margins'!$C$7:$C$78,$A25) -> 903 | G25: =SUMIFS('BEA 2017 Margins'!I$7:I$78,'BEA 2017 Margins'!$C$7:$C$78,$A25) -> 4666 | H25: =C25/SUM(C25:F25) -> 0.54413025 | I25: =D25/SUM(C25:F25) -> 0.016495287 | J25: =(E25+F25)/SUM(C25:F25) -> 0.43937446
A26: envelope work | B26: Envelope work: all of it counts as construction (see About) | H26: 1 | I26: 0 | J26: 0
A27: none | B27: No equipment bought (programming change only) | H27: 1 | I27: 0 | J27: 0
A28: BEA rounds each figure to the nearest million dollars, so the four parts can differ slightly from purchasers' value; the shares divide by the sum of the four parts so they add to exactly 100%.
A29: C. Commercial: which industries the retrofit measures buy from (PNNL office building)
A30: For the measures BRESaC counts, what share of commercial retrofit spending is equipment (by maker) and what share is installation labor? Answers in columns AA-AC.
A31: Climate zone | B31: Share of commercial floorspace | C31: Retrofit cost per unit energy saved ($/BTU) | D31: Share of BRESaC average cost floorspace x $/BTU | E31: Total cost of the counted measures in one building ($) | F31: Digital zone control upgrade equipment ($) HA14 minus HA12 | G31: Digital zone control upgrade installation ($) HA14 minus HA12
A32: Hot & Humid | B32: ='EPS Inputs'!B37 -> 0.40566318 | C32: ='EPS Inputs'!C37 -> 9.1827575e-05 | D32: =B32*C32/SUMPRODUCT($B$32:$B$36,$C$32:$C$36) -> 0.22883272 | E32: =G51 -> 477093 | F32: =SUMIFS('PNNL Office Measures'!$E$5:$E$69,'PNNL Office Measures'!$A$5:$A$69,"HA14",'PNNL Office Measures'!$D$5:$D$69,$A32)-SUMIFS('PNNL Office Measures'!$E$5:$E$69,'PNNL Office Measures'!$A$5:$A$69,"HA12",'PNNL Office Measures'!$D$5:$D$69,$A32) -> 61907 | G32: =SUMIFS('PNNL Office Measures'!$F$5:$F$69,'PNNL Office Measures'!$A$5:$A$69,"HA14",'PNNL Office Measures'!$D$5:$D$69,$A32)-SUMIFS('PNNL Office Measures'!$F$5:$F$69,'PNNL Office Measures'!$A$5:$A$69,"HA12",'PNNL Office Measures'!$D$5:$D$69,$A32) -> 128296
A33: Hot & Dry | B33: ='EPS Inputs'!B38 -> 0.061563025 | C33: ='EPS Inputs'!C38 -> 0.00019596788 | D33: =B33*C33/SUMPRODUCT($B$32:$B$36,$C$32:$C$36) -> 0.074111273 | E33: =J51 -> 1000130 | F33: =SUMIFS('PNNL Office Measures'!$E$5:$E$69,'PNNL Office Measures'!$A$5:$A$69,"HA14",'PNNL Office Measures'!$D$5:$D$69,$A33)-SUMIFS('PNNL Office Measures'!$E$5:$E$69,'PNNL Office Measures'!$A$5:$A$69,"HA12",'PNNL Office Measures'!$D$5:$D$69,$A33) -> 62463 | G33: =SUMIFS('PNNL Office Measures'!$F$5:$F$69,'PNNL Office Measures'!$A$5:$A$69,"HA14",'PNNL Office Measures'!$D$5:$D$69,$A33)-SUMIFS('PNNL Office Measures'!$F$5:$F$69,'PNNL Office Measures'!$A$5:$A$69,"HA12",'PNNL Office Measures'!$D$5:$D$69,$A33) -> 129449
A34: Marine | B34: ='EPS Inputs'!B39 -> 0.037672564 | C34: ='EPS Inputs'!C39 -> 0.00019606405 | D34: =B34*C34/SUMPRODUCT($B$32:$B$36,$C$32:$C$36) -> 0.04537353 | E34: =M51 -> 1018935 | F34: =SUMIFS('PNNL Office Measures'!$E$5:$E$69,'PNNL Office Measures'!$A$5:$A$69,"HA14",'PNNL Office Measures'!$D$5:$D$69,$A34)-SUMIFS('PNNL Office Measures'!$E$5:$E$69,'PNNL Office Measures'!$A$5:$A$69,"HA12",'PNNL Office Measures'!$D$5:$D$69,$A34) -> 64690 | G34: =SUMIFS('PNNL Office Measures'!$F$5:$F$69,'PNNL Office Measures'!$A$5:$A$69,"HA14",'PNNL Office Measures'!$D$5:$D$69,$A34)-SUMIFS('PNNL Office Measures'!$F$5:$F$69,'PNNL Office Measures'!$A$5:$A$69,"HA12",'PNNL Office Measures'!$D$5:$D$69,$A34) -> 134064
A35: Cold | B35: ='EPS Inputs'!B40 -> 0.45140543 | C35: ='EPS Inputs'!C40 -> 0.00021417365 | D35: =B35*C35/SUMPRODUCT($B$32:$B$36,$C$32:$C$36) -> 0.59389851 | E35: =P51 -> 1051099 | F35: =SUMIFS('PNNL Office Measures'!$E$5:$E$69,'PNNL Office Measures'!$A$5:$A$69,"HA14",'PNNL Office Measures'!$D$5:$D$69,$A35)-SUMIFS('PNNL Office Measures'!$E$5:$E$69,'PNNL Office Measures'!$A$5:$A$69,"HA12",'PNNL Office Measures'!$D$5:$D$69,$A35) -> 61226 | G35: =SUMIFS('PNNL Office Measures'!$F$5:$F$69,'PNNL Office Measures'!$A$5:$A$69,"HA14",'PNNL Office Measures'!$D$5:$D$69,$A35)-SUMIFS('PNNL Office Measures'!$F$5:$F$69,'PNNL Office Measures'!$A$5:$A$69,"HA12",'PNNL Office Measures'!$D$5:$D$69,$A35) -> 126886
A36: Very Cold | B36: ='EPS Inputs'!B41 -> 0.043695805 | C36: ='EPS Inputs'!C41 -> 0.00021527233 | D36: =B36*C36/SUMPRODUCT($B$32:$B$36,$C$32:$C$36) -> 0.05778397 | E36: =S51 -> 1056492 | F36: =SUMIFS('PNNL Office Measures'!$E$5:$E$69,'PNNL Office Measures'!$A$5:$A$69,"HA14",'PNNL Office Measures'!$D$5:$D$69,$A36)-SUMIFS('PNNL Office Measures'!$E$5:$E$69,'PNNL Office Measures'!$A$5:$A$69,"HA12",'PNNL Office Measures'!$D$5:$D$69,$A36) -> 60979 | G36: =SUMIFS('PNNL Office Measures'!$F$5:$F$69,'PNNL Office Measures'!$A$5:$A$69,"HA14",'PNNL Office Measures'!$D$5:$D$69,$A36)-SUMIFS('PNNL Office Measures'!$F$5:$F$69,'PNNL Office Measures'!$A$5:$A$69,"HA12",'PNNL Office Measures'!$D$5:$D$69,$A36) -> 126374
A37: HA13, HA14, HA15 and HW15 each include the full upgrade from pneumatic to digital zone controls. It is counted once, in HA13; the other three have it subtracted.
A39: BRESaC measure | B39: PNNL measure costed | C39: Main hardware bought | D39: BEA commodity for markups | E39: Industry that makes the hardware | F39: Hot & Humid counted? 1 = yes | G39: Hot & Humid equipment ($) | H39: Hot & Humid installation ($) | I39: Hot & Dry counted? 1 = yes | J39: Hot & Dry equipment ($) | K39: Hot & Dry installation ($) | L39: Marine counted? 1 = yes | M39: Marine equipment ($) | N39: Marine installation ($) | O39: Cold counted? 1 = yes | P39: Cold equipment ($) | Q39: Cold installation ($) | R39: Very Cold counted? 1 = yes | S39: Very Cold equipment ($) | T39: Very Cold installation ($) | U39: EQUIPMENT SHARE OF COMMERCIAL RETROFIT SPENDING | V39: INSTALLATION SHARE OF COMMERCIAL RETROFIT SPENDING | W39: Manufacturer's share of equipment | X39: Freight share | Y39: Wholesale + retail share | Z39: TO THE HARDWARE MAKER | AA39: TO WHOLESALE + RETAIL TRADE (ISIC 45T47) | AB39: TO FREIGHT (ISIC 49)
A40: E7 | B40: E7 | C40: Roof insulation and new membrane | D40: envelope work | E40: ISIC 41T43 | F40: =SUMIFS('EPS Inputs'!$C$45:$C$99,'EPS Inputs'!$A$45:$A$99,"Hot & Humid",'EPS Inputs'!$D$45:$D$99,$A40) -> 0 | G40: =SUMIFS('PNNL Office Measures'!$E$5:$E$69,'PNNL Office Measures'!$A$5:$A$69,$B40,'PNNL Office Measures'!$D$5:$D$69,"Hot & Humid") -> 104502 | H40: =SUMIFS('PNNL Office Measures'!$F$5:$F$69,'PNNL Office Measures'!$A$5:$A$69,$B40,'PNNL Office Measures'!$D$5:$D$69,"Hot & Humid") -> 207856 | I40: =SUMIFS('EPS Inputs'!$C$45:$C$99,'EPS Inputs'!$A$45:$A$99,"Hot & Dry",'EPS Inputs'!$D$45:$D$99,$A40) -> 1 | J40: =SUMIFS('PNNL Office Measures'!$E$5:$E$69,'PNNL Office Measures'!$A$5:$A$69,$B40,'PNNL Office Measures'!$D$5:$D$69,"Hot & Dry") -> 139044 | K40: =SUMIFS('PNNL Office Measures'!$F$5:$F$69,'PNNL Office Measures'!$A$5:$A$69,$B40,'PNNL Office Measures'!$D$5:$D$69,"Hot & Dry") -> 237533 | L40: =SUMIFS('EPS Inputs'!$C$45:$C$99,'EPS Inputs'!$A$45:$A$99,"Marine",'EPS Inputs'!$D$45:$D$99,$A40) -> 1 | M40: =SUMIFS('PNNL Office Measures'!$E$5:$E$69,'PNNL Office Measures'!$A$5:$A$69,$B40,'PNNL Office Measures'!$D$5:$D$69,"Marine") -> 144000 | N40: =SUMIFS('PNNL Office Measures'!$F$5:$F$69,'PNNL Office Measures'!$A$5:$A$69,$B40,'PNNL Office Measures'!$D$5:$D$69,"Marine") -> 246000 | O40: =SUMIFS('EPS Inputs'!$C$45:$C$99,'EPS Inputs'!$A$45:$A$99,"Cold",'EPS Inputs'!$D$45:$D$99,$A40) -> 1 | P40: =SUMIFS('PNNL Office Measures'!$E$5:$E$69,'PNNL Office Measures'!$A$5:$A$69,$B40,'PNNL Office Measures'!$D$5:$D$69,"Cold") -> 136291 | Q40: =SUMIFS('PNNL Office Measures'!$F$5:$F$69,'PNNL Office Measures'!$A$5:$A$69,$B40,'PNNL Office Measures'!$D$5:$D$69,"Cold") -> 232830 | R40: =SUMIFS('EPS Inputs'!$C$45:$C$99,'EPS Inputs'!$A$45:$A$99,"Very Cold",'EPS Inputs'!$D$45:$D$99,$A40) -> 1 | S40: =SUMIFS('PNNL Office Measures'!$E$5:$E$69,'PNNL Office Measures'!$A$5:$A$69,$B40,'PNNL Office Measures'!$D$5:$D$69,"Very Cold") -> 152707 | T40: =SUMIFS('PNNL Office Measures'!$F$5:$F$69,'PNNL Office Measures'!$A$5:$A$69,$B40,'PNNL Office Measures'!$D$5:$D$69,"Very Cold") -> 260168 | U40: =$D$32*F40*G40/$E$32+$D$33*I40*J40/$E$33+$D$34*L40*M40/$E$34+$D$35*O40*P40/$E$35+$D$36*R40*S40/$E$36 -> 0.10207593 | V40: =$D$32*F40*H40/$E$32+$D$33*I40*K40/$E$33+$D$34*L40*N40/$E$34+$D$35*O40*Q40/$E$35+$D$36*R40*T40/$E$36 -> 0.17434078 | W40: =VLOOKUP($D40,Calcs!$A$21:$J$27,8,FALSE) -> 1 | X40: =VLOOKUP($D40,Calcs!$A$21:$J$27,9,FALSE) -> 0 | Y40: =VLOOKUP($D40,Calcs!$A$21:$J$27,10,FALSE) -> 0 | Z40: =U40*W40 -> 0.10207593 | AA40: =U40*Y40 -> 0 | AB40: =U40*X40 -> 0
A41: HA13 | B41: HA13 | C41: DDC zone controls; occupancy sensors | D41: 334512 | E41: ISIC 26 | F41: =SUMIFS('EPS Inputs'!$C$45:$C$99,'EPS Inputs'!$A$45:$A$99,"Hot & Humid",'EPS Inputs'!$D$45:$D$99,$A41) -> 1 | G41: =SUMIFS('PNNL Office Measures'!$E$5:$E$69,'PNNL Office Measures'!$A$5:$A$69,$B41,'PNNL Office Measures'!$D$5:$D$69,"Hot & Humid") -> 66500 | H41: =SUMIFS('PNNL Office Measures'!$F$5:$F$69,'PNNL Office Measures'!$A$5:$A$69,$B41,'PNNL Office Measures'!$D$5:$D$69,"Hot & Humid") -> 147308 | I41: =SUMIFS('EPS Inputs'!$C$45:$C$99,'EPS Inputs'!$A$45:$A$99,"Hot & Dry",'EPS Inputs'!$D$45:$D$99,$A41) -> 1 | J41: =SUMIFS('PNNL Office Measures'!$E$5:$E$69,'PNNL Office Measures'!$A$5:$A$69,$B41,'PNNL Office Measures'!$D$5:$D$69,"Hot & Dry") -> 67098 | K41: =SUMIFS('PNNL Office Measures'!$F$5:$F$69,'PNNL Office Measures'!$A$5:$A$69,$B41,'PNNL Office Measures'!$D$5:$D$69,"Hot & Dry") -> 148632 | L41: =SUMIFS('EPS Inputs'!$C$45:$C$99,'EPS Inputs'!$A$45:$A$99,"Marine",'EPS Inputs'!$D$45:$D$99,$A41) -> 1 | M41: =SUMIFS('PNNL Office Measures'!$E$5:$E$69,'PNNL Office Measures'!$A$5:$A$69,$B41,'PNNL Office Measures'!$D$5:$D$69,"Marine") -> 69490 | N41: =SUMIFS('PNNL Office Measures'!$F$5:$F$69,'PNNL Office Measures'!$A$5:$A$69,$B41,'PNNL Office Measures'!$D$5:$D$69,"Marine") -> 153930 | O41: =SUMIFS('EPS Inputs'!$C$45:$C$99,'EPS Inputs'!$A$45:$A$99,"Cold",'EPS Inputs'!$D$45:$D$99,$A41) -> 1 | P41: =SUMIFS('PNNL Office Measures'!$E$5:$E$69,'PNNL Office Measures'!$A$5:$A$69,$B41,'PNNL Office Measures'!$D$5:$D$69,"Cold") -> 65769 | Q41: =SUMIFS('PNNL Office Measures'!$F$5:$F$69,'PNNL Office Measures'!$A$5:$A$69,$B41,'PNNL Office Measures'!$D$5:$D$69,"Cold") -> 145689 | R41: =SUMIFS('EPS Inputs'!$C$45:$C$99,'EPS Inputs'!$A$45:$A$99,"Very Cold",'EPS Inputs'!$D$45:$D$99,$A41) -> 1 | S41: =SUMIFS('PNNL Office Measures'!$E$5:$E$69,'PNNL Office Measures'!$A$5:$A$69,$B41,'PNNL Office Measures'!$D$5:$D$69,"Very Cold") -> 65504 | T41: =SUMIFS('PNNL Office Measures'!$F$5:$F$69,'PNNL Office Measures'!$A$5:$A$69,$B41,'PNNL Office Measures'!$D$5:$D$69,"Very Cold") -> 145100 | U41: =$D$32*F41*G41/$E$32+$D$33*I41*J41/$E$33+$D$34*L41*M41/$E$34+$D$35*O41*P41/$E$35+$D$36*R41*S41/$E$36 -> 0.080706421 | V41: =$D$32*F41*H41/$E$32+$D$33*I41*K41/$E$33+$D$34*L41*N41/$E$34+$D$35*O41*Q41/$E$35+$D$36*R41*T41/$E$36 -> 0.17877742 | W41: =VLOOKUP($D41,Calcs!$A$21:$J$27,8,FALSE) -> 0.81706549 | X41: =VLOOKUP($D41,Calcs!$A$21:$J$27,9,FALSE) -> 0.02361461 | Y41: =VLOOKUP($D41,Calcs!$A$21:$J$27,10,FALSE) -> 0.1593199 | Z41: =U41*W41 -> 0.065942431 | AA41: =U41*Y41 -> 0.012858139 | AB41: =U41*X41 -> 0.0019058506
A42: HA14 | B42: HA14 | C42: DDC zone controls | D42: 334512 | E42: ISIC 26 | F42: =SUMIFS('EPS Inputs'!$C$45:$C$99,'EPS Inputs'!$A$45:$A$99,"Hot & Humid",'EPS Inputs'!$D$45:$D$99,$A42) -> 1 | G42: =SUMIFS('PNNL Office Measures'!$E$5:$E$69,'PNNL Office Measures'!$A$5:$A$69,$B42,'PNNL Office Measures'!$D$5:$D$69,"Hot & Humid")-$F$32 -> 0 | H42: =SUMIFS('PNNL Office Measures'!$F$5:$F$69,'PNNL Office Measures'!$A$5:$A$69,$B42,'PNNL Office Measures'!$D$5:$D$69,"Hot & Humid")-$G$32 -> 36684 | I42: =SUMIFS('EPS Inputs'!$C$45:$C$99,'EPS Inputs'!$A$45:$A$99,"Hot & Dry",'EPS Inputs'!$D$45:$D$99,$A42) -> 1 | J42: =SUMIFS('PNNL Office Measures'!$E$5:$E$69,'PNNL Office Measures'!$A$5:$A$69,$B42,'PNNL Office Measures'!$D$5:$D$69,"Hot & Dry")-$F$33 -> 0 | K42: =SUMIFS('PNNL Office Measures'!$F$5:$F$69,'PNNL Office Measures'!$A$5:$A$69,$B42,'PNNL Office Measures'!$D$5:$D$69,"Hot & Dry")-$G$33 -> 37014 | L42: =SUMIFS('EPS Inputs'!$C$45:$C$99,'EPS Inputs'!$A$45:$A$99,"Marine",'EPS Inputs'!$D$45:$D$99,$A42) -> 1 | M42: =SUMIFS('PNNL Office Measures'!$E$5:$E$69,'PNNL Office Measures'!$A$5:$A$69,$B42,'PNNL Office Measures'!$D$5:$D$69,"Marine")-$F$34 -> 0 | N42: =SUMIFS('PNNL Office Measures'!$F$5:$F$69,'PNNL Office Measures'!$A$5:$A$69,$B42,'PNNL Office Measures'!$D$5:$D$69,"Marine")-$G$34 -> 38333 | O42: =SUMIFS('EPS Inputs'!$C$45:$C$99,'EPS Inputs'!$A$45:$A$99,"Cold",'EPS Inputs'!$D$45:$D$99,$A42) -> 1 | P42: =SUMIFS('PNNL Office Measures'!$E$5:$E$69,'PNNL Office Measures'!$A$5:$A$69,$B42,'PNNL Office Measures'!$D$5:$D$69,"Cold")-$F$35 -> 0 | Q42: =SUMIFS('PNNL Office Measures'!$F$5:$F$69,'PNNL Office Measures'!$A$5:$A$69,$B42,'PNNL Office Measures'!$D$5:$D$69,"Cold")-$G$35 -> 36281 | R42: =SUMIFS('EPS Inputs'!$C$45:$C$99,'EPS Inputs'!$A$45:$A$99,"Very Cold",'EPS Inputs'!$D$45:$D$99,$A42) -> 1 | S42: =SUMIFS('PNNL Office Measures'!$E$5:$E$69,'PNNL Office Measures'!$A$5:$A$69,$B42,'PNNL Office Measures'!$D$5:$D$69,"Very Cold")-$F$36 -> 0 | T42: =SUMIFS('PNNL Office Measures'!$F$5:$F$69,'PNNL Office Measures'!$A$5:$A$69,$B42,'PNNL Office Measures'!$D$5:$D$69,"Very Cold")-$G$36 -> 36134 | U42: =$D$32*F42*G42/$E$32+$D$33*I42*J42/$E$33+$D$34*L42*M42/$E$34+$D$35*O42*P42/$E$35+$D$36*R42*S42/$E$36 -> 0 | V42: =$D$32*F42*H42/$E$32+$D$33*I42*K42/$E$33+$D$34*L42*N42/$E$34+$D$35*O42*Q42/$E$35+$D$36*R42*T42/$E$36 -> 0.044520917 | W42: =VLOOKUP($D42,Calcs!$A$21:$J$27,8,FALSE) -> 0.81706549 | X42: =VLOOKUP($D42,Calcs!$A$21:$J$27,9,FALSE) -> 0.02361461 | Y42: =VLOOKUP($D42,Calcs!$A$21:$J$27,10,FALSE) -> 0.1593199 | Z42: =U42*W42 -> 0 | AA42: =U42*Y42 -> 0 | AB42: =U42*X42 -> 0
