Workbook

Sheet About
A1: VWSPbV Vehicle Weibull Shape Parameter by Vintage
A3: Sources: | B3: Fitted survival parameters (data-rich tier)
B4: Vehicle-vintaging pilot survival calibration
B5: prototype/v9_params.py (passenger LDVs: car/light-truck mixture per model year, fitted to NEMS AEO2026 survival and S&P age data; freight LDVs: NEMS truck curves 1-7) and prototype/truck_survival.py hdv (class 7-8: NEMS curves 8-11)
B6: 2026
B7: https://github.com/EIAgov/NEMS/tree/AEO2026-Public-Release/input/tdm
B8: per_vintage_params_v9.csv and freight_hdv.json pasted on tab 'Calibrated parameters' as values (fits cannot be Excel formulas). These are today's fits; an eps-calibrate survival step is to produce them for any region.
B10: Average vehicle lifetime (default tier)
B11: EPS input AVL (Avg Vehicle Lifetime)
B12: InputData/trans/AVL/AVL.csv
B13: 2026
B14: https://github.com/EnergyInnovation/eps-us
B15: Pasted on tab 'AVL (EPS input)'. For vehicle types without survival data the median life equals AVL.
B17: Default survival shapes
B18: U.S. Environmental Protection Agency
B19: Population and Activity of Onroad Vehicles in MOVES5, EPA-420-R-24-019, Table C-1 survival by age
B20: 2024
B21: https://www.epa.gov/moves/moves-onroad-technical-reports
B22: Weibull fits to MOVES5 Table C-1 (vintaging project data/survival-mileage/fits.csv): heavy-duty k = 2.094, motorcycle k = 1.062, used rounded (2.09, 1.06) on 'Assumptions'; other default-tier types use k = 2.
A25: Notes:
A26: What this is | B26: Weibull shape by model year (dimensionless): one of the three Weibull parameters that set each model year's survival curve, S(a) = exp(-(max(0, a - location) / scale)^shape).
A27: How each vehicle type is treated | B27: Passenger LDVs, freight LDVs (class 2b-6) and heavy trucks (class 7-8) have survival curves fitted to data; every other type uses a default curve whose median life is the lifetime in the AVL file and whose shape is set on 'Assumptions'. The type-by-type notes below say which and why.
A28: Passenger LDVs | B28: Fitted per model year as a mixture of car and light-truck curves, matched to NEMS's AEO 2026 survival rates and S&P registration ages. Cars and light trucks retire differently and their sales mix has shifted toward trucks, so one curve for all years would misplace the retirements of the vehicles already in the fleet.
A29: Freight LDVs (class 2b-6) and heavy trucks (class 7-8) | B29: NEMS's truck survival curves by size class, weighted by the registered stock. These are the only published U.S. truck survival curves by class; the model's class 2b-6 and 7-8 groups are built from them.
A30: Buses | B30: Default curve: median life 13 years (AVL) with the shape fitted to EPA MOVES5 heavy-duty survival (2.09). No bus-specific survival data exist; MOVES's heavy-duty shape is the closest published curve.
A31: Motorbikes | B31: Default curve: median life 22 years (AVL) with the shape fitted to MOVES5 motorcycle survival (1.06, close to a constant retirement rate), which is how motorcycles leave the fleet.
A32: Aircraft, rail, ships and boats | B32: Default curves: median life from the AVL file (24 years aircraft, 47 passenger rail, 34 freight rail, 38 recreational boats, 33 freight ships) with shape 2, a broad hump of retirements around the median. Nothing published describes the survival of these fleets year by year; the medians come from stock-flows and asset-life references documented in the AVL file.
A33: Companion workbooks | B33: VWSPbV (shape), VWSbV (scale) and VWLbV (location) hold the same calculation; each exports its own parameter.

Sheet Assumptions
A1: Assumptions
A2: Default-tier Weibull shapes by vehicle type (location 0; scale set by median = AVL).
A3: Vehicle type | B3: Shape (default tier) | C3: Why
A4: LDVs | B4: 2 | C4: Pilot default
A5: HDVs | B5: 2.09 | C5: MOVES5 Table C-1 heavy-duty fit, k = 2.094, rounded
A6: aircraft | B6: 2 | C6: Pilot default
A7: rail | B7: 2 | C7: Pilot default
A8: ships | B8: 2 | C8: Pilot default
A9: motorbikes | B9: 1.06 | C9: MOVES5 Table C-1 motorcycle fit, k = 1.062, rounded

Sheet AVL (EPS input)
A1: Vehicle Lifetime (years) | B1: Passenger | C1: Freight
A2: LDVs | B2: 17 | C2: 15
A3: HDVs | B3: 13 | C3: 20
A4: aircraft | B4: 24 | C4: 24
A5: rail | B5: 47 | C5: 34
A6: ships | B6: 38 | C6: 33
A7: motorbikes | B7: 22 | C7: 22

Sheet Calibrated parameters
A1: Fitted values (not formulas): per_vintage_params_v9.csv from the pilot's survival calibration, 2026-09-24.
A3: cargo_type | B3: vehicle_type | C3: model_year | D3: shape | E3: scale | F3: location | G3: fit_rmse
A4: passenger | B4: LDVs | C4: 1965 | D4: 1.6299001 | E4: 11.944716 | F4: 3.0544348 | G4: 0.0033677007
A5: passenger | B5: LDVs | C5: 1966 | D5: 1.6299001 | E5: 11.944717 | F5: 3.0544346 | G5: 0.0033677007
A6: passenger | B6: LDVs | C6: 1967 | D6: 1.6299002 | E6: 11.944717 | F6: 3.0544347 | G6: 0.0033677007
A7: passenger | B7: LDVs | C7: 1968 | D7: 1.6299002 | E7: 11.944718 | F7: 3.0544348 | G7: 0.0033677008
A8: passenger | B8: LDVs | C8: 1969 | D8: 1.6299002 | E8: 11.94472 | F8: 3.0544351 | G8: 0.003367701
A9: passenger | B9: LDVs | C9: 1970 | D9: 1.6299002 | E9: 11.944723 | F9: 3.0544356 | G9: 0.0033677013
A10: passenger | B10: LDVs | C10: 1971 | D10: 1.6299003 | E10: 11.94473 | F10: 3.0544367 | G10: 0.0033677019
A11: passenger | B11: LDVs | C11: 1972 | D11: 1.6299005 | E11: 11.944742 | F11: 3.0544387 | G11: 0.0033677032
A12: passenger | B12: LDVs | C12: 1973 | D12: 1.6299004 | E12: 11.944764 | F12: 3.0544452 | G12: 0.0033677056
A13: passenger | B13: LDVs | C13: 1974 | D13: 1.6299006 | E13: 11.94481 | F13: 3.0544553 | G13: 0.0033677103
A14: passenger | B14: LDVs | C14: 1975 | D14: 1.629901 | E14: 11.944899 | F14: 3.054475 | G14: 0.0033677195
A15: passenger | B15: LDVs | C15: 1976 | D15: 1.6179941 | E15: 11.918568 | F15: 3.1363957 | G15: 0.0036088162
... A175: freight | B175: LDVs | C175: 2050 | D175: 1.8724511 | E175: 29.182825 | F175: 6.2684781e-24 | G175: 0
A178: Freight HDVs (class 7-8), all model years: freight_hdv.json from truck_survival.py hdv
B179: shape | C179: scale | D179: location | E179: median
A180: freight HDVs | B180: 1.0594142 | C180: 26.25478 | D180: 2.8181259 | E180: 21.394489
A181: NEMS AEO2026 trnhdvx.xlsx SURV_D/SURV_ND curves 8-11 (class 7-8), weighted by 2024 stock of vintages 1-5

Sheet Calcs
A1: Weibull parameters by vehicle type, cargo type and model year
A2: Fitted tier reads the calibrated table; default tier: shape from Assumptions, scale = AVL / LN(2)^(1/shape), location 0.
A3: Weibull shape
A4: passenger | B4: 1965 | C4: 1966 | D4: 1967 | E4: 1968 | F4: 1969 | G4: 1970 | H4: 1971 | I4: 1972 | J4: 1973 | K4: 1974 | L4: 1975 | M4: 1976 | N4: 1977 | O4: 1978 | P4: 1979 | Q4: 1980 | R4: 1981 | S4: 1982 | T4: 1983 | U4: 1984 | V4: 1985 | W4: 1986 | X4: 1987 | Y4: 1988 | Z4: 1989 | AA4: 1990 | AB4: 1991 | AC4: 1992 | AD4: 1993 | AE4: 1994 | AF4: 1995 | AG4: 1996 | AH4: 1997 | AI4: 1998 | AJ4: 1999 | AK4: 2000 | AL4: 2001 | AM4: 2002 | AN4: 2003 | AO4: 2004 | AP4: 2005 | AQ4: 2006 | AR4: 2007 | AS4: 2008 | AT4: 2009 | AU4: 2010 | AV4: 2011 | AW4: 2012 | AX4: 2013 | AY4: 2014 | AZ4: 2015 | BA4: 2016 | BB4: 2017 | BC4: 2018 | BD4: 2019 | BE4: 2020 | BF4: 2021 | BG4: 2022 | BH4: 2023 | BI4: 2024 | BJ4: 2025 | BK4: 2026 | BL4: 2027 | BM4: 2028 | BN4: 2029 | BO4: 2030 | BP4: 2031 | BQ4: 2032 | BR4: 2033 | BS4: 2034 | BT4: 2035 | BU4: 2036 | BV4: 2037 | BW4: 2038 | BX4: 2039 | BY4: 2040 | BZ4: 2041 | CA4: 2042 | CB4: 2043 | CC4: 2044 | CD4: 2045 | CE4: 2046 | CF4: 2047 | CG4: 2048 | CH4: 2049 | CI4: 2050
A5: LDVs | B5: =SUMIFS('Calibrated parameters'!$D$4:$D$175,'Calibrated parameters'!$A$4:$A$175,$A$4,'Calibrated parameters'!$B$4:$B$175,$A5,'Calibrated parameters'!$C$4:$C$175,B$4) -> 1.6299001 | C5: =SUMIFS('Calibrated parameters'!$D$4:$D$175,'Calibrated parameters'!$A$4:$A$175,$A$4,'Calibrated parameters'!$B$4:$B$175,$A5,'Calibrated parameters'!$C$4:$C$175,C$4) -> 1.6299001 | D5: =SUMIFS('Calibrated parameters'!$D$4:$D$175,'Calibrated parameters'!$A$4:$A$175,$A$4,'Calibrated parameters'!$B$4:$B$175,$A5,'Calibrated parameters'!$C$4:$C$175,D$4) -> 1.6299002 | E5: =SUMIFS('Calibrated parameters'!$D$4:$D$175,'Calibrated parameters'!$A$4:$A$175,$A$4,'Calibrated parameters'!$B$4:$B$175,$A5,'Calibrated parameters'!$C$4:$C$175,E$4) -> 1.6299002 | F5: =SUMIFS('Calibrated parameters'!$D$4:$D$175,'Calibrated parameters'!$A$4:$A$175,$A$4,'Calibrated parameters'!$B$4:$B$175,$A5,'Calibrated parameters'!$C$4:$C$175,F$4) -> 1.6299002 | G5: =SUMIFS('Calibrated parameters'!$D$4:$D$175,'Calibrated parameters'!$A$4:$A$175,$A$4,'Calibrated parameters'!$B$4:$B$175,$A5,'Calibrated parameters'!$C$4:$C$175,G$4) -> 1.6299002 | H5: =SUMIFS('Calibrated parameters'!$D$4:$D$175,'Calibrated parameters'!$A$4:$A$175,$A$4,'Calibrated parameters'!$B$4:$B$175,$A5,'Calibrated parameters'!$C$4:$C$175,H$4) -> 1.6299003 | I5: =SUMIFS('Calibrated parameters'!$D$4:$D$175,'Calibrated parameters'!$A$4:$A$175,$A$4,'Calibrated parameters'!$B$4:$B$175,$A5,'Calibrated parameters'!$C$4:$C$175,I$4) -> 1.6299005 | ... CI5: =SUMIFS('Calibrated parameters'!$D$4:$D$175,'Calibrated parameters'!$A$4:$A$175,$A$4,'Calibrated parameters'!$B$4:$B$175,$A5,'Calibrated parameters'!$C$4:$C$175,CI$4) -> 1.2791622
A6: HDVs | B6: =Assumptions!$B$5 -> 2.09 | C6: =Assumptions!$B$5 -> 2.09 | D6: =Assumptions!$B$5 -> 2.09 | E6: =Assumptions!$B$5 -> 2.09 | F6: =Assumptions!$B$5 -> 2.09 | G6: =Assumptions!$B$5 -> 2.09 | H6: =Assumptions!$B$5 -> 2.09 | I6: =Assumptions!$B$5 -> 2.09 | ... CI6: =Assumptions!$B$5 -> 2.09
A7: aircraft | B7: =Assumptions!$B$6 -> 2 | C7: =Assumptions!$B$6 -> 2 | D7: =Assumptions!$B$6 -> 2 | E7: =Assumptions!$B$6 -> 2 | F7: =Assumptions!$B$6 -> 2 | G7: =Assumptions!$B$6 -> 2 | H7: =Assumptions!$B$6 -> 2 | I7: =Assumptions!$B$6 -> 2 | ... CI7: =Assumptions!$B$6 -> 2
A8: rail | B8: =Assumptions!$B$7 -> 2 | C8: =Assumptions!$B$7 -> 2 | D8: =Assumptions!$B$7 -> 2 | E8: =Assumptions!$B$7 -> 2 | F8: =Assumptions!$B$7 -> 2 | G8: =Assumptions!$B$7 -> 2 | H8: =Assumptions!$B$7 -> 2 | I8: =Assumptions!$B$7 -> 2 | ... CI8: =Assumptions!$B$7 -> 2
A9: ships | B9: =Assumptions!$B$8 -> 2 | C9: =Assumptions!$B$8 -> 2 | D9: =Assumptions!$B$8 -> 2 | E9: =Assumptions!$B$8 -> 2 | F9: =Assumptions!$B$8 -> 2 | G9: =Assumptions!$B$8 -> 2 | H9: =Assumptions!$B$8 -> 2 | I9: =Assumptions!$B$8 -> 2 | ... CI9: =Assumptions!$B$8 -> 2
A10: motorbikes | B10: =Assumptions!$B$9 -> 1.06 | C10: =Assumptions!$B$9 -> 1.06 | D10: =Assumptions!$B$9 -> 1.06 | E10: =Assumptions!$B$9 -> 1.06 | F10: =Assumptions!$B$9 -> 1.06 | G10: =Assumptions!$B$9 -> 1.06 | H10: =Assumptions!$B$9 -> 1.06 | I10: =Assumptions!$B$9 -> 1.06 | ... CI10: =Assumptions!$B$9 -> 1.06
A12: Weibull shape
A13: freight | B13: 1965 | C13: 1966 | D13: 1967 | E13: 1968 | F13: 1969 | G13: 1970 | H13: 1971 | I13: 1972 | J13: 1973 | K13: 1974 | L13: 1975 | M13: 1976 | N13: 1977 | O13: 1978 | P13: 1979 | Q13: 1980 | R13: 1981 | S13: 1982 | T13: 1983 | U13: 1984 | V13: 1985 | W13: 1986 | X13: 1987 | Y13: 1988 | Z13: 1989 | AA13: 1990 | AB13: 1991 | AC13: 1992 | AD13: 1993 | AE13: 1994 | AF13: 1995 | AG13: 1996 | AH13: 1997 | AI13: 1998 | AJ13: 1999 | AK13: 2000 | AL13: 2001 | AM13: 2002 | AN13: 2003 | AO13: 2004 | AP13: 2005 | AQ13: 2006 | AR13: 2007 | AS13: 2008 | AT13: 2009 | AU13: 2010 | AV13: 2011 | AW13: 2012 | AX13: 2013 | AY13: 2014 | AZ13: 2015 | BA13: 2016 | BB13: 2017 | BC13: 2018 | BD13: 2019 | BE13: 2020 | BF13: 2021 | BG13: 2022 | BH13: 2023 | BI13: 2024 | BJ13: 2025 | BK13: 2026 | BL13: 2027 | BM13: 2028 | BN13: 2029 | BO13: 2030 | BP13: 2031 | BQ13: 2032 | BR13: 2033 | BS13: 2034 | BT13: 2035 | BU13: 2036 | BV13: 2037 | BW13: 2038 | BX13: 2039 | BY13: 2040 | BZ13: 2041 | CA13: 2042 | CB13: 2043 | CC13: 2044 | CD13: 2045 | CE13: 2046 | CF13: 2047 | CG13: 2048 | CH13: 2049 | CI13: 2050
A14: LDVs | B14: =SUMIFS('Calibrated parameters'!$D$4:$D$175,'Calibrated parameters'!$A$4:$A$175,$A$13,'Calibrated parameters'!$B$4:$B$175,$A14,'Calibrated parameters'!$C$4:$C$175,B$13) -> 1.8724511 | C14: =SUMIFS('Calibrated parameters'!$D$4:$D$175,'Calibrated parameters'!$A$4:$A$175,$A$13,'Calibrated parameters'!$B$4:$B$175,$A14,'Calibrated parameters'!$C$4:$C$175,C$13) -> 1.8724511 | D14: =SUMIFS('Calibrated parameters'!$D$4:$D$175,'Calibrated parameters'!$A$4:$A$175,$A$13,'Calibrated parameters'!$B$4:$B$175,$A14,'Calibrated parameters'!$C$4:$C$175,D$13) -> 1.8724511 | E14: =SUMIFS('Calibrated parameters'!$D$4:$D$175,'Calibrated parameters'!$A$4:$A$175,$A$13,'Calibrated parameters'!$B$4:$B$175,$A14,'Calibrated parameters'!$C$4:$C$175,E$13) -> 1.8724511 | F14: =SUMIFS('Calibrated parameters'!$D$4:$D$175,'Calibrated parameters'!$A$4:$A$175,$A$13,'Calibrated parameters'!$B$4:$B$175,$A14,'Calibrated parameters'!$C$4:$C$175,F$13) -> 1.8724511 | G14: =SUMIFS('Calibrated parameters'!$D$4:$D$175,'Calibrated parameters'!$A$4:$A$175,$A$13,'Calibrated parameters'!$B$4:$B$175,$A14,'Calibrated parameters'!$C$4:$C$175,G$13) -> 1.8724511 | H14: =SUMIFS('Calibrated parameters'!$D$4:$D$175,'Calibrated parameters'!$A$4:$A$175,$A$13,'Calibrated parameters'!$B$4:$B$175,$A14,'Calibrated parameters'!$C$4:$C$175,H$13) -> 1.8724511 | I14: =SUMIFS('Calibrated parameters'!$D$4:$D$175,'Calibrated parameters'!$A$4:$A$175,$A$13,'Calibrated parameters'!$B$4:$B$175,$A14,'Calibrated parameters'!$C$4:$C$175,I$13) -> 1.8724511 | ... CI14: =SUMIFS('Calibrated parameters'!$D$4:$D$175,'Calibrated parameters'!$A$4:$A$175,$A$13,'Calibrated parameters'!$B$4:$B$175,$A14,'Calibrated parameters'!$C$4:$C$175,CI$13) -> 1.8724511
A15: HDVs | B15: ='Calibrated parameters'!$B$180 -> 1.0594142 | C15: ='Calibrated parameters'!$B$180 -> 1.0594142 | D15: ='Calibrated parameters'!$B$180 -> 1.0594142 | E15: ='Calibrated parameters'!$B$180 -> 1.0594142 | F15: ='Calibrated parameters'!$B$180 -> 1.0594142 | G15: ='Calibrated parameters'!$B$180 -> 1.0594142 | H15: ='Calibrated parameters'!$B$180 -> 1.0594142 | I15: ='Calibrated parameters'!$B$180 -> 1.0594142 | ... CI15: ='Calibrated parameters'!$B$180 -> 1.0594142
A16: aircraft | B16: =Assumptions!$B$6 -> 2 | C16: =Assumptions!$B$6 -> 2 | D16: =Assumptions!$B$6 -> 2 | E16: =Assumptions!$B$6 -> 2 | F16: =Assumptions!$B$6 -> 2 | G16: =Assumptions!$B$6 -> 2 | H16: =Assumptions!$B$6 -> 2 | I16: =Assumptions!$B$6 -> 2 | ... CI16: =Assumptions!$B$6 -> 2
A17: rail | B17: =Assumptions!$B$7 -> 2 | C17: =Assumptions!$B$7 -> 2 | D17: =Assumptions!$B$7 -> 2 | E17: =Assumptions!$B$7 -> 2 | F17: =Assumptions!$B$7 -> 2 | G17: =Assumptions!$B$7 -> 2 | H17: =Assumptions!$B$7 -> 2 | I17: =Assumptions!$B$7 -> 2 | ... CI17: =Assumptions!$B$7 -> 2
A18: ships | B18: =Assumptions!$B$8 -> 2 | C18: =Assumptions!$B$8 -> 2 | D18: =Assumptions!$B$8 -> 2 | E18: =Assumptions!$B$8 -> 2 | F18: =Assumptions!$B$8 -> 2 | G18: =Assumptions!$B$8 -> 2 | H18: =Assumptions!$B$8 -> 2 | I18: =Assumptions!$B$8 -> 2 | ... CI18: =Assumptions!$B$8 -> 2
A19: motorbikes | B19: =Assumptions!$B$9 -> 1.06 | C19: =Assumptions!$B$9 -> 1.06 | D19: =Assumptions!$B$9 -> 1.06 | E19: =Assumptions!$B$9 -> 1.06 | F19: =Assumptions!$B$9 -> 1.06 | G19: =Assumptions!$B$9 -> 1.06 | H19: =Assumptions!$B$9 -> 1.06 | I19: =Assumptions!$B$9 -> 1.06 | ... CI19: =Assumptions!$B$9 -> 1.06
A21: Weibull scale
A22: passenger | B22: 1965 | C22: 1966 | D22: 1967 | E22: 1968 | F22: 1969 | G22: 1970 | H22: 1971 | I22: 1972 | J22: 1973 | K22: 1974 | L22: 1975 | M22: 1976 | N22: 1977 | O22: 1978 | P22: 1979 | Q22: 1980 | R22: 1981 | S22: 1982 | T22: 1983 | U22: 1984 | V22: 1985 | W22: 1986 | X22: 1987 | Y22: 1988 | Z22: 1989 | AA22: 1990 | AB22: 1991 | AC22: 1992 | AD22: 1993 | AE22: 1994 | AF22: 1995 | AG22: 1996 | AH22: 1997 | AI22: 1998 | AJ22: 1999 | AK22: 2000 | AL22: 2001 | AM22: 2002 | AN22: 2003 | AO22: 2004 | AP22: 2005 | AQ22: 2006 | AR22: 2007 | AS22: 2008 | AT22: 2009 | AU22: 2010 | AV22: 2011 | AW22: 2012 | AX22: 2013 | AY22: 2014 | AZ22: 2015 | BA22: 2016 | BB22: 2017 | BC22: 2018 | BD22: 2019 | BE22: 2020 | BF22: 2021 | BG22: 2022 | BH22: 2023 | BI22: 2024 | BJ22: 2025 | BK22: 2026 | BL22: 2027 | BM22: 2028 | BN22: 2029 | BO22: 2030 | BP22: 2031 | BQ22: 2032 | BR22: 2033 | BS22: 2034 | BT22: 2035 | BU22: 2036 | BV22: 2037 | BW22: 2038 | BX22: 2039 | BY22: 2040 | BZ22: 2041 | CA22: 2042 | CB22: 2043 | CC22: 2044 | CD22: 2045 | CE22: 2046 | CF22: 2047 | CG22: 2048 | CH22: 2049 | CI22: 2050
A23: LDVs | B23: =SUMIFS('Calibrated parameters'!$E$4:$E$175,'Calibrated parameters'!$A$4:$A$175,$A$22,'Calibrated parameters'!$B$4:$B$175,$A23,'Calibrated parameters'!$C$4:$C$175,B$22) -> 11.944716 | C23: =SUMIFS('Calibrated parameters'!$E$4:$E$175,'Calibrated parameters'!$A$4:$A$175,$A$22,'Calibrated parameters'!$B$4:$B$175,$A23,'Calibrated parameters'!$C$4:$C$175,C$22) -> 11.944717 | D23: =SUMIFS('Calibrated parameters'!$E$4:$E$175,'Calibrated parameters'!$A$4:$A$175,$A$22,'Calibrated parameters'!$B$4:$B$175,$A23,'Calibrated parameters'!$C$4:$C$175,D$22) -> 11.944717 | E23: =SUMIFS('Calibrated parameters'!$E$4:$E$175,'Calibrated parameters'!$A$4:$A$175,$A$22,'Calibrated parameters'!$B$4:$B$175,$A23,'Calibrated parameters'!$C$4:$C$175,E$22) -> 11.944718 | F23: =SUMIFS('Calibrated parameters'!$E$4:$E$175,'Calibrated parameters'!$A$4:$A$175,$A$22,'Calibrated parameters'!$B$4:$B$175,$A23,'Calibrated parameters'!$C$4:$C$175,F$22) -> 11.94472 | G23: =SUMIFS('Calibrated parameters'!$E$4:$E$175,'Calibrated parameters'!$A$4:$A$175,$A$22,'Calibrated parameters'!$B$4:$B$175,$A23,'Calibrated parameters'!$C$4:$C$175,G$22) -> 11.944723 | H23: =SUMIFS('Calibrated parameters'!$E$4:$E$175,'Calibrated parameters'!$A$4:$A$175,$A$22,'Calibrated parameters'!$B$4:$B$175,$A23,'Calibrated parameters'!$C$4:$C$175,H$22) -> 11.94473 | I23: =SUMIFS('Calibrated parameters'!$E$4:$E$175,'Calibrated parameters'!$A$4:$A$175,$A$22,'Calibrated parameters'!$B$4:$B$175,$A23,'Calibrated parameters'!$C$4:$C$175,I$22) -> 11.944742 | ... CI23: =SUMIFS('Calibrated parameters'!$E$4:$E$175,'Calibrated parameters'!$A$4:$A$175,$A$22,'Calibrated parameters'!$B$4:$B$175,$A23,'Calibrated parameters'!$C$4:$C$175,CI$22) -> 14.557903
A24: HDVs | B24: ='AVL (EPS input)'!$B$3/LN(2)^(1/Assumptions!$B$5) -> 15.491855 | C24: ='AVL (EPS input)'!$B$3/LN(2)^(1/Assumptions!$B$5) -> 15.491855 | D24: ='AVL (EPS input)'!$B$3/LN(2)^(1/Assumptions!$B$5) -> 15.491855 | E24: ='AVL (EPS input)'!$B$3/LN(2)^(1/Assumptions!$B$5) -> 15.491855 | F24: ='AVL (EPS input)'!$B$3/LN(2)^(1/Assumptions!$B$5) -> 15.491855 | G24: ='AVL (EPS input)'!$B$3/LN(2)^(1/Assumptions!$B$5) -> 15.491855 | H24: ='AVL (EPS input)'!$B$3/LN(2)^(1/Assumptions!$B$5) -> 15.491855 | I24: ='AVL (EPS input)'!$B$3/LN(2)^(1/Assumptions!$B$5) -> 15.491855 | ... CI24: ='AVL (EPS input)'!$B$3/LN(2)^(1/Assumptions!$B$5) -> 15.491855
A25: aircraft | B25: ='AVL (EPS input)'!$B$4/LN(2)^(1/Assumptions!$B$6) -> 28.826938 | C25: ='AVL (EPS input)'!$B$4/LN(2)^(1/Assumptions!$B$6) -> 28.826938 | D25: ='AVL (EPS input)'!$B$4/LN(2)^(1/Assumptions!$B$6) -> 28.826938 | E25: ='AVL (EPS input)'!$B$4/LN(2)^(1/Assumptions!$B$6) -> 28.826938 | F25: ='AVL (EPS input)'!$B$4/LN(2)^(1/Assumptions!$B$6) -> 28.826938 | G25: ='AVL (EPS input)'!$B$4/LN(2)^(1/Assumptions!$B$6) -> 28.826938 | H25: ='AVL (EPS input)'!$B$4/LN(2)^(1/Assumptions!$B$6) -> 28.826938 | I25: ='AVL (EPS input)'!$B$4/LN(2)^(1/Assumptions!$B$6) -> 28.826938 | ... CI25: ='AVL (EPS input)'!$B$4/LN(2)^(1/Assumptions!$B$6) -> 28.826938
A26: rail | B26: ='AVL (EPS input)'!$B$5/LN(2)^(1/Assumptions!$B$7) -> 56.452753 | C26: ='AVL (EPS input)'!$B$5/LN(2)^(1/Assumptions!$B$7) -> 56.452753 | D26: ='AVL (EPS input)'!$B$5/LN(2)^(1/Assumptions!$B$7) -> 56.452753 | E26: ='AVL (EPS input)'!$B$5/LN(2)^(1/Assumptions!$B$7) -> 56.452753 | F26: ='AVL (EPS input)'!$B$5/LN(2)^(1/Assumptions!$B$7) -> 56.452753 | G26: ='AVL (EPS input)'!$B$5/LN(2)^(1/Assumptions!$B$7) -> 56.452753 | H26: ='AVL (EPS input)'!$B$5/LN(2)^(1/Assumptions!$B$7) -> 56.452753 | I26: ='AVL (EPS input)'!$B$5/LN(2)^(1/Assumptions!$B$7) -> 56.452753 | ... CI26: ='AVL (EPS input)'!$B$5/LN(2)^(1/Assumptions!$B$7) -> 56.452753
A27: ships | B27: ='AVL (EPS input)'!$B$6/LN(2)^(1/Assumptions!$B$8) -> 45.642652 | C27: ='AVL (EPS input)'!$B$6/LN(2)^(1/Assumptions!$B$8) -> 45.642652 | D27: ='AVL (EPS input)'!$B$6/LN(2)^(1/Assumptions!$B$8) -> 45.642652 | E27: ='AVL (EPS input)'!$B$6/LN(2)^(1/Assumptions!$B$8) -> 45.642652 | F27: ='AVL (EPS input)'!$B$6/LN(2)^(1/Assumptions!$B$8) -> 45.642652 | G27: ='AVL (EPS input)'!$B$6/LN(2)^(1/Assumptions!$B$8) -> 45.642652 | H27: ='AVL (EPS input)'!$B$6/LN(2)^(1/Assumptions!$B$8) -> 45.642652 | I27: ='AVL (EPS input)'!$B$6/LN(2)^(1/Assumptions!$B$8) -> 45.642652 | ... CI27: ='AVL (EPS input)'!$B$6/LN(2)^(1/Assumptions!$B$8) -> 45.642652
A28: motorbikes | B28: ='AVL (EPS input)'!$B$7/LN(2)^(1/Assumptions!$B$9) -> 31.08761 | C28: ='AVL (EPS input)'!$B$7/LN(2)^(1/Assumptions!$B$9) -> 31.08761 | D28: ='AVL (EPS input)'!$B$7/LN(2)^(1/Assumptions!$B$9) -> 31.08761 | E28: ='AVL (EPS input)'!$B$7/LN(2)^(1/Assumptions!$B$9) -> 31.08761 | F28: ='AVL (EPS input)'!$B$7/LN(2)^(1/Assumptions!$B$9) -> 31.08761 | G28: ='AVL (EPS input)'!$B$7/LN(2)^(1/Assumptions!$B$9) -> 31.08761 | H28: ='AVL (EPS input)'!$B$7/LN(2)^(1/Assumptions!$B$9) -> 31.08761 | I28: ='AVL (EPS input)'!$B$7/LN(2)^(1/Assumptions!$B$9) -> 31.08761 | ... CI28: ='AVL (EPS input)'!$B$7/LN(2)^(1/Assumptions!$B$9) -> 31.08761
A30: Weibull scale
A31: freight | B31: 1965 | C31: 1966 | D31: 1967 | E31: 1968 | F31: 1969 | G31: 1970 | H31: 1971 | I31: 1972 | J31: 1973 | K31: 1974 | L31: 1975 | M31: 1976 | N31: 1977 | O31: 1978 | P31: 1979 | Q31: 1980 | R31: 1981 | S31: 1982 | T31: 1983 | U31: 1984 | V31: 1985 | W31: 1986 | X31: 1987 | Y31: 1988 | Z31: 1989 | AA31: 1990 | AB31: 1991 | AC31: 1992 | AD31: 1993 | AE31: 1994 | AF31: 1995 | AG31: 1996 | AH31: 1997 | AI31: 1998 | AJ31: 1999 | AK31: 2000 | AL31: 2001 | AM31: 2002 | AN31: 2003 | AO31: 2004 | AP31: 2005 | AQ31: 2006 | AR31: 2007 | AS31: 2008 | AT31: 2009 | AU31: 2010 | AV31: 2011 | AW31: 2012 | AX31: 2013 | AY31: 2014 | AZ31: 2015 | BA31: 2016 | BB31: 2017 | BC31: 2018 | BD31: 2019 | BE31: 2020 | BF31: 2021 | BG31: 2022 | BH31: 2023 | BI31: 2024 | BJ31: 2025 | BK31: 2026 | BL31: 2027 | BM31: 2028 | BN31: 2029 | BO31: 2030 | BP31: 2031 | BQ31: 2032 | BR31: 2033 | BS31: 2034 | BT31: 2035 | BU31: 2036 | BV31: 2037 | BW31: 2038 | BX31: 2039 | BY31: 2040 | BZ31: 2041 | CA31: 2042 | CB31: 2043 | CC31: 2044 | CD31: 2045 | CE31: 2046 | CF31: 2047 | CG31: 2048 | CH31: 2049 | CI31: 2050
A32: LDVs | B32: =SUMIFS('Calibrated parameters'!$E$4:$E$175,'Calibrated parameters'!$A$4:$A$175,$A$31,'Calibrated parameters'!$B$4:$B$175,$A32,'Calibrated parameters'!$C$4:$C$175,B$31) -> 29.182825 | C32: =SUMIFS('Calibrated parameters'!$E$4:$E$175,'Calibrated parameters'!$A$4:$A$175,$A$31,'Calibrated parameters'!$B$4:$B$175,$A32,'Calibrated parameters'!$C$4:$C$175,C$31) -> 29.182825 | D32: =SUMIFS('Calibrated parameters'!$E$4:$E$175,'Calibrated parameters'!$A$4:$A$175,$A$31,'Calibrated parameters'!$B$4:$B$175,$A32,'Calibrated parameters'!$C$4:$C$175,D$31) -> 29.182825 | E32: =SUMIFS('Calibrated parameters'!$E$4:$E$175,'Calibrated parameters'!$A$4:$A$175,$A$31,'Calibrated parameters'!$B$4:$B$175,$A32,'Calibrated parameters'!$C$4:$C$175,E$31) -> 29.182825 | F32: =SUMIFS('Calibrated parameters'!$E$4:$E$175,'Calibrated parameters'!$A$4:$A$175,$A$31,'Calibrated parameters'!$B$4:$B$175,$A32,'Calibrated parameters'!$C$4:$C$175,F$31) -> 29.182825 | G32: =SUMIFS('Calibrated parameters'!$E$4:$E$175,'Calibrated parameters'!$A$4:$A$175,$A$31,'Calibrated parameters'!$B$4:$B$175,$A32,'Calibrated parameters'!$C$4:$C$175,G$31) -> 29.182825 | H32: =SUMIFS('Calibrated parameters'!$E$4:$E$175,'Calibrated parameters'!$A$4:$A$175,$A$31,'Calibrated parameters'!$B$4:$B$175,$A32,'Calibrated parameters'!$C$4:$C$175,H$31) -> 29.182825 | I32: =SUMIFS('Calibrated parameters'!$E$4:$E$175,'Calibrated parameters'!$A$4:$A$175,$A$31,'Calibrated parameters'!$B$4:$B$175,$A32,'Calibrated parameters'!$C$4:$C$175,I$31) -> 29.182825 | ... CI32: =SUMIFS('Calibrated parameters'!$E$4:$E$175,'Calibrated parameters'!$A$4:$A$175,$A$31,'Calibrated parameters'!$B$4:$B$175,$A32,'Calibrated parameters'!$C$4:$C$175,CI$31) -> 29.182825
A33: HDVs | B33: ='Calibrated parameters'!$C$180 -> 26.25478 | C33: ='Calibrated parameters'!$C$180 -> 26.25478 | D33: ='Calibrated parameters'!$C$180 -> 26.25478 | E33: ='Calibrated parameters'!$C$180 -> 26.25478 | F33: ='Calibrated parameters'!$C$180 -> 26.25478 | G33: ='Calibrated parameters'!$C$180 -> 26.25478 | H33: ='Calibrated parameters'!$C$180 -> 26.25478 | I33: ='Calibrated parameters'!$C$180 -> 26.25478 | ... CI33: ='Calibrated parameters'!$C$180 -> 26.25478
A34: aircraft | B34: ='AVL (EPS input)'!$C$4/LN(2)^(1/Assumptions!$B$6) -> 28.826938 | C34: ='AVL (EPS input)'!$C$4/LN(2)^(1/Assumptions!$B$6) -> 28.826938 | D34: ='AVL (EPS input)'!$C$4/LN(2)^(1/Assumptions!$B$6) -> 28.826938 | E34: ='AVL (EPS input)'!$C$4/LN(2)^(1/Assumptions!$B$6) -> 28.826938 | F34: ='AVL (EPS input)'!$C$4/LN(2)^(1/Assumptions!$B$6) -> 28.826938 | G34: ='AVL (EPS input)'!$C$4/LN(2)^(1/Assumptions!$B$6) -> 28.826938 | H34: ='AVL (EPS input)'!$C$4/LN(2)^(1/Assumptions!$B$6) -> 28.826938 | I34: ='AVL (EPS input)'!$C$4/LN(2)^(1/Assumptions!$B$6) -> 28.826938 | ... CI34: ='AVL (EPS input)'!$C$4/LN(2)^(1/Assumptions!$B$6) -> 28.826938
A35: rail | B35: ='AVL (EPS input)'!$C$5/LN(2)^(1/Assumptions!$B$7) -> 40.838162 | C35: ='AVL (EPS input)'!$C$5/LN(2)^(1/Assumptions!$B$7) -> 40.838162 | D35: ='AVL (EPS input)'!$C$5/LN(2)^(1/Assumptions!$B$7) -> 40.838162 | E35: ='AVL (EPS input)'!$C$5/LN(2)^(1/Assumptions!$B$7) -> 40.838162 | F35: ='AVL (EPS input)'!$C$5/LN(2)^(1/Assumptions!$B$7) -> 40.838162 | G35: ='AVL (EPS input)'!$C$5/LN(2)^(1/Assumptions!$B$7) -> 40.838162 | H35: ='AVL (EPS input)'!$C$5/LN(2)^(1/Assumptions!$B$7) -> 40.838162 | I35: ='AVL (EPS input)'!$C$5/LN(2)^(1/Assumptions!$B$7) -> 40.838162 | ... CI35: ='AVL (EPS input)'!$C$5/LN(2)^(1/Assumptions!$B$7) -> 40.838162
A36: ships | B36: ='AVL (EPS input)'!$C$6/LN(2)^(1/Assumptions!$B$8) -> 39.637039 | C36: ='AVL (EPS input)'!$C$6/LN(2)^(1/Assumptions!$B$8) -> 39.637039 | D36: ='AVL (EPS input)'!$C$6/LN(2)^(1/Assumptions!$B$8) -> 39.637039 | E36: ='AVL (EPS input)'!$C$6/LN(2)^(1/Assumptions!$B$8) -> 39.637039 | F36: ='AVL (EPS input)'!$C$6/LN(2)^(1/Assumptions!$B$8) -> 39.637039 | G36: ='AVL (EPS input)'!$C$6/LN(2)^(1/Assumptions!$B$8) -> 39.637039 | H36: ='AVL (EPS input)'!$C$6/LN(2)^(1/Assumptions!$B$8) -> 39.637039 | I36: ='AVL (EPS input)'!$C$6/LN(2)^(1/Assumptions!$B$8) -> 39.637039 | ... CI36: ='AVL (EPS input)'!$C$6/LN(2)^(1/Assumptions!$B$8) -> 39.637039
A37: motorbikes | B37: ='AVL (EPS input)'!$C$7/LN(2)^(1/Assumptions!$B$9) -> 31.08761 | C37: ='AVL (EPS input)'!$C$7/LN(2)^(1/Assumptions!$B$9) -> 31.08761 | D37: ='AVL (EPS input)'!$C$7/LN(2)^(1/Assumptions!$B$9) -> 31.08761 | E37: ='AVL (EPS input)'!$C$7/LN(2)^(1/Assumptions!$B$9) -> 31.08761 | F37: ='AVL (EPS input)'!$C$7/LN(2)^(1/Assumptions!$B$9) -> 31.08761 | G37: ='AVL (EPS input)'!$C$7/LN(2)^(1/Assumptions!$B$9) -> 31.08761 | H37: ='AVL (EPS input)'!$C$7/LN(2)^(1/Assumptions!$B$9) -> 31.08761 | I37: ='AVL (EPS input)'!$C$7/LN(2)^(1/Assumptions!$B$9) -> 31.08761 | ... CI37: ='AVL (EPS input)'!$C$7/LN(2)^(1/Assumptions!$B$9) -> 31.08761
A39: Weibull location
A40: passenger | B40: 1965 | C40: 1966 | D40: 1967 | E40: 1968 | F40: 1969 | G40: 1970 | H40: 1971 | I40: 1972 | J40: 1973 | K40: 1974 | L40: 1975 | M40: 1976 | N40: 1977 | O40: 1978 | P40: 1979 | Q40: 1980 | R40: 1981 | S40: 1982 | T40: 1983 | U40: 1984 | V40: 1985 | W40: 1986 | X40: 1987 | Y40: 1988 | Z40: 1989 | AA40: 1990 | AB40: 1991 | AC40: 1992 | AD40: 1993 | AE40: 1994 | AF40: 1995 | AG40: 1996 | AH40: 1997 | AI40: 1998 | AJ40: 1999 | AK40: 2000 | AL40: 2001 | AM40: 2002 | AN40: 2003 | AO40: 2004 | AP40: 2005 | AQ40: 2006 | AR40: 2007 | AS40: 2008 | AT40: 2009 | AU40: 2010 | AV40: 2011 | AW40: 2012 | AX40: 2013 | AY40: 2014 | AZ40: 2015 | BA40: 2016 | BB40: 2017 | BC40: 2018 | BD40: 2019 | BE40: 2020 | BF40: 2021 | BG40: 2022 | BH40: 2023 | BI40: 2024 | BJ40: 2025 | BK40: 2026 | BL40: 2027 | BM40: 2028 | BN40: 2029 | BO40: 2030 | BP40: 2031 | BQ40: 2032 | BR40: 2033 | BS40: 2034 | BT40: 2035 | BU40: 2036 | BV40: 2037 | BW40: 2038 | BX40: 2039 | BY40: 2040 | BZ40: 2041 | CA40: 2042 | CB40: 2043 | CC40: 2044 | CD40: 2045 | CE40: 2046 | CF40: 2047 | CG40: 2048 | CH40: 2049 | CI40: 2050
A41: LDVs | B41: =SUMIFS('Calibrated parameters'!$F$4:$F$175,'Calibrated parameters'!$A$4:$A$175,$A$40,'Calibrated parameters'!$B$4:$B$175,$A41,'Calibrated parameters'!$C$4:$C$175,B$40) -> 3.0544348 | C41: =SUMIFS('Calibrated parameters'!$F$4:$F$175,'Calibrated parameters'!$A$4:$A$175,$A$40,'Calibrated parameters'!$B$4:$B$175,$A41,'Calibrated parameters'!$C$4:$C$175,C$40) -> 3.0544346 | D41: =SUMIFS('Calibrated parameters'!$F$4:$F$175,'Calibrated parameters'!$A$4:$A$175,$A$40,'Calibrated parameters'!$B$4:$B$175,$A41,'Calibrated parameters'!$C$4:$C$175,D$40) -> 3.0544347 | E41: =SUMIFS('Calibrated parameters'!$F$4:$F$175,'Calibrated parameters'!$A$4:$A$175,$A$40,'Calibrated parameters'!$B$4:$B$175,$A41,'Calibrated parameters'!$C$4:$C$175,E$40) -> 3.0544348 | F41: =SUMIFS('Calibrated parameters'!$F$4:$F$175,'Calibrated parameters'!$A$4:$A$175,$A$40,'Calibrated parameters'!$B$4:$B$175,$A41,'Calibrated parameters'!$C$4:$C$175,F$40) -> 3.0544351 | G41: =SUMIFS('Calibrated parameters'!$F$4:$F$175,'Calibrated parameters'!$A$4:$A$175,$A$40,'Calibrated parameters'!$B$4:$B$175,$A41,'Calibrated parameters'!$C$4:$C$175,G$40) -> 3.0544356 | H41: =SUMIFS('Calibrated parameters'!$F$4:$F$175,'Calibrated parameters'!$A$4:$A$175,$A$40,'Calibrated parameters'!$B$4:$B$175,$A41,'Calibrated parameters'!$C$4:$C$175,H$40) -> 3.0544367 | I41: =SUMIFS('Calibrated parameters'!$F$4:$F$175,'Calibrated parameters'!$A$4:$A$175,$A$40,'Calibrated parameters'!$B$4:$B$175,$A41,'Calibrated parameters'!$C$4:$C$175,I$40) -> 3.0544387 | ... CI41: =SUMIFS('Calibrated parameters'!$F$4:$F$175,'Calibrated parameters'!$A$4:$A$175,$A$40,'Calibrated parameters'!$B$4:$B$175,$A41,'Calibrated parameters'!$C$4:$C$175,CI$40) -> 7.7327826
A42: HDVs | B42: =0 -> 0 | C42: =0 -> 0 | D42: =0 -> 0 | E42: =0 -> 0 | F42: =0 -> 0 | G42: =0 -> 0 | H42: =0 -> 0 | I42: =0 -> 0 | ... CI42: =0 -> 0
A43: aircraft | B43: =0 -> 0 | C43: =0 -> 0 | D43: =0 -> 0 | E43: =0 -> 0 | F43: =0 -> 0 | G43: =0 -> 0 | H43: =0 -> 0 | I43: =0 -> 0 | ... CI43: =0 -> 0
A44: rail | B44: =0 -> 0 | C44: =0 -> 0 | D44: =0 -> 0 | E44: =0 -> 0 | F44: =0 -> 0 | G44: =0 -> 0 | H44: =0 -> 0 | I44: =0 -> 0 | ... CI44: =0 -> 0
...

Sheet Checks
A1: Checks
A2: Is every calibrated model year present, and are all scales positive? 1 = problem.
A3: Check | B3: Value | C3: Expected | D3: CHECK: 1 = problem
A4: Calibrated rows for LDVs, both cargo types (expected: model years x 2) | B4: =COUNTIFS('Calibrated parameters'!$B$4:$B$175,Calcs!$A$5) -> 172 | C4: =COUNT(Calcs!B4:CI4)*2 -> 172 | D4: =IF(B4<>C4,1,0) -> 0
A5: Smallest scale anywhere (must be > 0) | B5: =MIN(Calcs!B23:CI37) -> 11.897379 | C5: 0 | D5: =IF(B5<=C5,1,0) -> 0

Sheet VWSPbV-psgr
A1: Weibull shape by model year (dimensionless) | B1: Vintage1965 | C1: Vintage1966 | D1: Vintage1967 | E1: Vintage1968 | F1: Vintage1969 | G1: Vintage1970 | H1: Vintage1971 | I1: Vintage1972 | J1: Vintage1973 | K1: Vintage1974 | L1: Vintage1975 | M1: Vintage1976 | N1: Vintage1977 | O1: Vintage1978 | P1: Vintage1979 | Q1: Vintage1980 | R1: Vintage1981 | S1: Vintage1982 | T1: Vintage1983 | U1: Vintage1984 | V1: Vintage1985 | W1: Vintage1986 | X1: Vintage1987 | Y1: Vintage1988 | Z1: Vintage1989 | AA1: Vintage1990 | AB1: Vintage1991 | AC1: Vintage1992 | AD1: Vintage1993 | AE1: Vintage1994 | AF1: Vintage1995 | AG1: Vintage1996 | AH1: Vintage1997 | AI1: Vintage1998 | AJ1: Vintage1999 | AK1: Vintage2000 | AL1: Vintage2001 | AM1: Vintage2002 | AN1: Vintage2003 | AO1: Vintage2004 | AP1: Vintage2005 | AQ1: Vintage2006 | AR1: Vintage2007 | AS1: Vintage2008 | AT1: Vintage2009 | AU1: Vintage2010 | AV1: Vintage2011 | AW1: Vintage2012 | AX1: Vintage2013 | AY1: Vintage2014 | AZ1: Vintage2015 | BA1: Vintage2016 | BB1: Vintage2017 | BC1: Vintage2018 | BD1: Vintage2019 | BE1: Vintage2020 | BF1: Vintage2021 | BG1: Vintage2022 | BH1: Vintage2023 | BI1: Vintage2024 | BJ1: Vintage2025 | BK1: Vintage2026 | BL1: Vintage2027 | BM1: Vintage2028 | BN1: Vintage2029 | BO1: Vintage2030 | BP1: Vintage2031 | BQ1: Vintage2032 | BR1: Vintage2033 | BS1: Vintage2034 | BT1: Vintage2035 | BU1: Vintage2036 | BV1: Vintage2037 | BW1: Vintage2038 | BX1: Vintage2039 | BY1: Vintage2040 | BZ1: Vintage2041 | CA1: Vintage2042 | CB1: Vintage2043 | CC1: Vintage2044 | CD1: Vintage2045 | CE1: Vintage2046 | CF1: Vintage2047 | CG1: Vintage2048 | CH1: Vintage2049 | CI1: Vintage2050
A2: LDVs | B2: =Calcs!B5 -> 1.6299001 | C2: =Calcs!C5 -> 1.6299001 | D2: =Calcs!D5 -> 1.6299002 | E2: =Calcs!E5 -> 1.6299002 | F2: =Calcs!F5 -> 1.6299002 | G2: =Calcs!G5 -> 1.6299002 | H2: =Calcs!H5 -> 1.6299003 | I2: =Calcs!I5 -> 1.6299005 | ... CI2: =Calcs!CI5 -> 1.2791622
A3: HDVs | B3: =Calcs!B6 -> 2.09 | C3: =Calcs!C6 -> 2.09 | D3: =Calcs!D6 -> 2.09 | E3: =Calcs!E6 -> 2.09 | F3: =Calcs!F6 -> 2.09 | G3: =Calcs!G6 -> 2.09 | H3: =Calcs!H6 -> 2.09 | I3: =Calcs!I6 -> 2.09 | ... CI3: =Calcs!CI6 -> 2.09
A4: aircraft | B4: =Calcs!B7 -> 2 | C4: =Calcs!C7 -> 2 | D4: =Calcs!D7 -> 2 | E4: =Calcs!E7 -> 2 | F4: =Calcs!F7 -> 2 | G4: =Calcs!G7 -> 2 | H4: =Calcs!H7 -> 2 | I4: =Calcs!I7 -> 2 | ... CI4: =Calcs!CI7 -> 2
A5: rail | B5: =Calcs!B8 -> 2 | C5: =Calcs!C8 -> 2 | D5: =Calcs!D8 -> 2 | E5: =Calcs!E8 -> 2 | F5: =Calcs!F8 -> 2 | G5: =Calcs!G8 -> 2 | H5: =Calcs!H8 -> 2 | I5: =Calcs!I8 -> 2 | ... CI5: =Calcs!CI8 -> 2
A6: ships | B6: =Calcs!B9 -> 2 | C6: =Calcs!C9 -> 2 | D6: =Calcs!D9 -> 2 | E6: =Calcs!E9 -> 2 | F6: =Calcs!F9 -> 2 | G6: =Calcs!G9 -> 2 | H6: =Calcs!H9 -> 2 | I6: =Calcs!I9 -> 2 | ... CI6: =Calcs!CI9 -> 2
A7: motorbikes | B7: =Calcs!B10 -> 1.06 | C7: =Calcs!C10 -> 1.06 | D7: =Calcs!D10 -> 1.06 | E7: =Calcs!E10 -> 1.06 | F7: =Calcs!F10 -> 1.06 | G7: =Calcs!G10 -> 1.06 | H7: =Calcs!H10 -> 1.06 | I7: =Calcs!I10 -> 1.06 | ... CI7: =Calcs!CI10 -> 1.06

Sheet VWSPbV-frgt
A1: Weibull shape by model year (dimensionless) | B1: Vintage1965 | C1: Vintage1966 | D1: Vintage1967 | E1: Vintage1968 | F1: Vintage1969 | G1: Vintage1970 | H1: Vintage1971 | I1: Vintage1972 | J1: Vintage1973 | K1: Vintage1974 | L1: Vintage1975 | M1: Vintage1976 | N1: Vintage1977 | O1: Vintage1978 | P1: Vintage1979 | Q1: Vintage1980 | R1: Vintage1981 | S1: Vintage1982 | T1: Vintage1983 | U1: Vintage1984 | V1: Vintage1985 | W1: Vintage1986 | X1: Vintage1987 | Y1: Vintage1988 | Z1: Vintage1989 | AA1: Vintage1990 | AB1: Vintage1991 | AC1: Vintage1992 | AD1: Vintage1993 | AE1: Vintage1994 | AF1: Vintage1995 | AG1: Vintage1996 | AH1: Vintage1997 | AI1: Vintage1998 | AJ1: Vintage1999 | AK1: Vintage2000 | AL1: Vintage2001 | AM1: Vintage2002 | AN1: Vintage2003 | AO1: Vintage2004 | AP1: Vintage2005 | AQ1: Vintage2006 | AR1: Vintage2007 | AS1: Vintage2008 | AT1: Vintage2009 | AU1: Vintage2010 | AV1: Vintage2011 | AW1: Vintage2012 | AX1: Vintage2013 | AY1: Vintage2014 | AZ1: Vintage2015 | BA1: Vintage2016 | BB1: Vintage2017 | BC1: Vintage2018 | BD1: Vintage2019 | BE1: Vintage2020 | BF1: Vintage2021 | BG1: Vintage2022 | BH1: Vintage2023 | BI1: Vintage2024 | BJ1: Vintage2025 | BK1: Vintage2026 | BL1: Vintage2027 | BM1: Vintage2028 | BN1: Vintage2029 | BO1: Vintage2030 | BP1: Vintage2031 | BQ1: Vintage2032 | BR1: Vintage2033 | BS1: Vintage2034 | BT1: Vintage2035 | BU1: Vintage2036 | BV1: Vintage2037 | BW1: Vintage2038 | BX1: Vintage2039 | BY1: Vintage2040 | BZ1: Vintage2041 | CA1: Vintage2042 | CB1: Vintage2043 | CC1: Vintage2044 | CD1: Vintage2045 | CE1: Vintage2046 | CF1: Vintage2047 | CG1: Vintage2048 | CH1: Vintage2049 | CI1: Vintage2050
A2: LDVs | B2: =Calcs!B14 -> 1.8724511 | C2: =Calcs!C14 -> 1.8724511 | D2: =Calcs!D14 -> 1.8724511 | E2: =Calcs!E14 -> 1.8724511 | F2: =Calcs!F14 -> 1.8724511 | G2: =Calcs!G14 -> 1.8724511 | H2: =Calcs!H14 -> 1.8724511 | I2: =Calcs!I14 -> 1.8724511 | ... CI2: =Calcs!CI14 -> 1.8724511
A3: HDVs | B3: =Calcs!B15 -> 1.0594142 | C3: =Calcs!C15 -> 1.0594142 | D3: =Calcs!D15 -> 1.0594142 | E3: =Calcs!E15 -> 1.0594142 | F3: =Calcs!F15 -> 1.0594142 | G3: =Calcs!G15 -> 1.0594142 | H3: =Calcs!H15 -> 1.0594142 | I3: =Calcs!I15 -> 1.0594142 | ... CI3: =Calcs!CI15 -> 1.0594142
A4: aircraft | B4: =Calcs!B16 -> 2 | C4: =Calcs!C16 -> 2 | D4: =Calcs!D16 -> 2 | E4: =Calcs!E16 -> 2 | F4: =Calcs!F16 -> 2 | G4: =Calcs!G16 -> 2 | H4: =Calcs!H16 -> 2 | I4: =Calcs!I16 -> 2 | ... CI4: =Calcs!CI16 -> 2
A5: rail | B5: =Calcs!B17 -> 2 | C5: =Calcs!C17 -> 2 | D5: =Calcs!D17 -> 2 | E5: =Calcs!E17 -> 2 | F5: =Calcs!F17 -> 2 | G5: =Calcs!G17 -> 2 | H5: =Calcs!H17 -> 2 | I5: =Calcs!I17 -> 2 | ... CI5: =Calcs!CI17 -> 2
A6: ships | B6: =Calcs!B18 -> 2 | C6: =Calcs!C18 -> 2 | D6: =Calcs!D18 -> 2 | E6: =Calcs!E18 -> 2 | F6: =Calcs!F18 -> 2 | G6: =Calcs!G18 -> 2 | H6: =Calcs!H18 -> 2 | I6: =Calcs!I18 -> 2 | ... CI6: =Calcs!CI18 -> 2
A7: motorbikes | B7: =Calcs!B19 -> 1.06 | C7: =Calcs!C19 -> 1.06 | D7: =Calcs!D19 -> 1.06 | E7: =Calcs!E19 -> 1.06 | F7: =Calcs!F19 -> 1.06 | G7: =Calcs!G19 -> 1.06 | H7: =Calcs!H19 -> 1.06 | I7: =Calcs!I19 -> 1.06 | ... CI7: =Calcs!CI19 -> 1.06
