Workbook

Sheet About
A1: CEIbPaF Cement Energy Intensity by Pathway and Fuel
A3: Sources: | B3: Dry pyroprocessing thermal energy intensity (basis for the 3.43 MMBtu/t clinker thermal total)
B4: US DOE, Advanced Manufacturing Office
B5: Bandwidth Study on Energy Use and Potential Energy Saving Opportunities in US Cement Manufacturing, Table 3-2 ("current typical" dry pyroprocessing energy)
B6: 2017
B7: https://www.energy.gov/eere/amo/articles/bandwidth-study-energy-use-and-potential-energy-savings-opportunities-us-1
B8: [PROXY] Table 3-2 reports "current typical" dry-kiln-with-precalciner pyroprocessing energy of 1,554 Btu/lb clinker. See the Calc tab for the conversion to BTU/metric ton (x 2,204.62 lb/metric ton = ~3.43 MMBtu/t) - a prior reviewer flagged a possible "discrepancy" using the 2,000 lb/short-ton conversion instead; 2,204.62 lb/metric ton is the correct factor and is used throughout. Nothing newer supersedes this figure; the GNR (Getting the Numbers Right) global database's ~3.3-3.5 MJ-basis range is directionally consistent.
B10: US fuel mix for cement kiln thermal energy (basis for the coal/petcoke/NG/alt-fuel split)
B11: Portland Cement Association (PCA)
B12: PCA 2023 Labor-Energy Input Survey, as reported in PCA press release
B13: 2023
B14: https://www.cement.org/newsroom
B15: [PROXY - accessed via PCA press release summarizing the survey, not the full survey report] Natural gas 31% (record share), alternative fuels 16%, coal + petroleum coke combined 53% of onsite thermal fuel. PCA does not separately break out coal vs. petroleum coke within the 53%.
B17: Cross-check for the coal-vs-petcoke split within PCA's combined 53%
B18: US Energy Information Administration (EIA)
B19: Manufacturing Energy Consumption Survey (MECS) 2018, Table 3.2, NAICS 3273 (cement)
B20: 2018
B21: https://www.eia.gov/consumption/manufacturing/data/2018/
B22: [SNIPPET] MECS 2018 shows onsite fuel roughly 41% coal : 24% petroleum coke (~63:37 ratio between the two). This workbook's chosen 33%/20% split of PCA's 53% (~62:38 ratio, see Parameters tab) is directionally consistent with MECS but is NOT a 2023 primary split - no such split has been published for 2023. Documented EI judgment, not a direct source figure.
B24: Cement-sector electricity intensity (basis for the electricity BTU/t clinker figure)
B25: Portland Cement Association (PCA)
B26: PCA plant energy survey (cited figure: 142 kWh per metric ton of cement)
B27: 2008
B28: https://www.cement.org/
B29: [PROXY - condensed/secondary citation of the PCA survey figure, primary survey report not directly accessed in this pass] 142 kWh/t CEMENT (not clinker). Converted to a per-t-clinker basis on the Calc tab by dividing by the BCtCR clinker-to-cement ratio (0.8214, sourced from the separate BCtCR input file) then multiplying by 3,412 BTU/kWh. MECS-2018-derived cross-checks put the plausible range at 132-142 kWh/t; this workbook uses the top of that range and flags re-derivation from MECS Table 3.2 + USGS for release-grade precision as a follow-up.
B31: CCS amine-capture energy penalty (natural gas and electricity adders on the CCS pathway)
B32: IEAGHG; Heidelberg Materials (Brevik)
B33: IEAGHG Technical Report 2018-TR03 (cement CCS energy penalty, with-heat-recovery case); Brevik CCS project reported energy penalty
B34: 2018
B35: https://ieaghg.org/publications/technical-reports/
B36: [PROXY - the adders themselves are an EI-derived DRAFT figure; the corroboration range is from these two secondary/tertiary citations] This workbook's +2.1 MMBtu/t natural gas (capture steam) at ~0.72 t CO2 captured per t clinker implies ~2.9 GJ/t CO2 captured, which falls inside IEAGHG 2018-TR03's with-heat-recovery band (3.1-3.3 GJ/t CO2) and is close to Brevik's reported 2.7-3.0 GJ/t CO2 - corroborating the DRAFT figure's order of magnitude without being independently re-derived from either primary report.
B38: Electric kiln and alternative-chemistry cement energy intensities
B39: EI internal engineering estimate
B40: (no company disclosure exists)
B41: 2026
B42: https://www.energyinnovation.org/
B43: [UNVERIFIED - EI judgment] Neither Coolbrook (electric kiln) nor Sublime Systems (alternative chemistry) has published an energy intensity figure. 4.0 MMBtu/t (electric kiln) and 2.5 MMBtu/t (alternative chemistry), both electricity-only, are internal engineering placeholders pending real disclosures.
A46: Notes:
A47: DRAFT status | B47: DRAFT - an input for staff review, not a finished or approved EI position. Verify every figure against primary sources before use in any work product; treat this workbook as a starting point open to further input and refinement.
A48: Apportionment method | B48: The Calc tab computes a single thermal-energy total (DOE Bandwidth 1,554 Btu/lb x 2,204.62 lb/metric ton = ~3.426 MMBtu/t clinker), then splits it across fuels using the PCA 2023 fuel-mix shares (coal 33% / petroleum coke 20% / natural gas 31% / alternative fuels 16% - the 33/20 split of PCA's combined 53% coal+petcoke figure is an EI judgment documented on the Parameters tab). Each fuel's share of the thermal total is rounded to the nearest 10,000 BTU (matching the shipped CSV's rounding convention) via ROUND(...,-4).
...

Sheet Source Data
A1: DOE Bandwidth Study 2017, Table 3-2
A2: Dry pyroprocessing current typical energy (Btu/lb clinker) | B2: 1554
A3: Conversion factor (lb/metric ton) | B3: 2204.62
A5: PCA 2023 Labor-Energy Input Survey fuel mix (share of onsite thermal fuel)
A6: Natural gas share | B6: 0.31
A7: Alternative fuels share | B7: 0.16
A8: Coal + petroleum coke combined share | B8: 0.53
A10: MECS 2018 cross-check (context only, not used numerically)
A11: Coal share of onsite fuel | B11: 0.41
A12: Petroleum coke share of onsite fuel | B12: 0.24
A13: Implied coal:petcoke ratio | B13: =B11/(B11+B12)
A15: Electricity intensity
A16: PCA electricity intensity (kWh/metric ton CEMENT) | B16: 142
A17: BAU Clinker to Cement Ratio, 2025 (from the BCtCR input file - cross-variable reference) | B17: 0.8214
A18: BTU per kWh | B18: 3412
A20: CCS amine-capture energy adders (DRAFT, corroborated - see About tab)
A21: Natural gas adder (BTU/t clinker) | B21: 2100000
A22: Electricity adder (BTU/t clinker) | B22: 150000

Sheet Parameters
A1: Judgment split of PCA's combined 53% coal+petcoke share
A2: Coal share of total thermal energy | B2: 0.33 | C2: EI judgment, within PCA 53%; ~62:38 coal:petcoke ratio, MECS-consistent (MECS implies ~63:37)
A3: Petroleum coke share of total thermal energy (rides "heavy or residual fuel oil if") | B3: 0.2 | C3: EI judgment, within PCA 53%; see coal row
A5: Electric kiln and alternative-chemistry literal energy intensities [UNVERIFIED]
A6: Electric kiln electricity intensity (BTU/t clinker) | B6: 4000000 | C6: EI internal engineering estimate; no company disclosure
A7: Alternative chemistry cement electricity intensity (BTU/t clinker) | B7: 2500000 | C7: EI internal engineering estimate; no company disclosure
A9: Petcoke split between EPS fuel elements, following BIFU: AEO cement block 2025 petroleum coke 24.6 TBtu (filed as petroleum diesel) vs other petroleum 35.4 TBtu (filed as residual-oil feedstock)
A10: Share of module petcoke on petroleum diesel | B10: 0.41
A11: Share on heavy or residual fuel oil | B11: =1-B10

Sheet Calc
A1: Thermal energy intensity conversion
A2: Thermal BTU/metric ton clinker, unrounded | B2: ='Source Data'!B2*'Source Data'!B3
A3: Thermal MMBtu/metric ton clinker (display) | B3: =B2/1000000
A5: Fuel splits (rounded to nearest 10,000 BTU)
A6: Fuel | B6: BTU/t clinker
A7: hard coal if | B7: =ROUND($B$2*Parameters!$B$2,-4)
A8: natural gas if | B8: =ROUND($B$2*'Source Data'!$B$6,-4)
A9: heavy or residual fuel oil if (petroleum coke, 59%) | B9: =ROUND($B$2*Parameters!$B$3*Parameters!$B$11,-3)
A10: biomass if (alternative fuels) | B10: =ROUND($B$2*'Source Data'!$B$7,-4)
A11: petroleum diesel if (petroleum coke, 41%) | B11: =ROUND($B$2*Parameters!$B$3*Parameters!$B$10,-3)
A12: Electricity
A13: kWh/t clinker, unrounded | B13: ='Source Data'!B16/'Source Data'!B17
A14: BTU/t clinker, unrounded | B14: =B13*'Source Data'!B18
A15: BTU/t clinker, rounded to nearest 10,000 | B15: =ROUND(B14,-4)
A17: CCS pathway: KILN ONLY since 2026-10-01 (capture energy comes from the CCS sector's CC Energy Use per Ton Industry CO2 Sequestered x captured tons); rows equal the dry kiln
A18: Electricity BTU/t | B18: =B15+'Source Data'!B22
A19: Natural gas BTU/t | B19: =B8+'Source Data'!B21

Sheet Checks
A1: Cross-check: export literal vs. Calc/Parameters-derived value (nonzero fuels only; plain ABS cells, no array formulas)
A3: Pathway | B3: Fuel | C3: Export literal | D3: Calc/Parameters value | E3: Abs diff
A4: dry kiln with precalciner | B4: electricity if | C4: =CEIbPaF!B2 | D4: =Calc!B15 | E4: =ABS(C4-D4)
A5: dry kiln with precalciner | B5: hard coal if | C5: =CEIbPaF!C2 | D5: =Calc!B7 | E5: =ABS(C5-D5)
A6: dry kiln with precalciner | B6: natural gas if | C6: =CEIbPaF!D2 | D6: =Calc!B8 | E6: =ABS(C6-D6)
A7: dry kiln with precalciner | B7: biomass if | C7: =CEIbPaF!E2 | D7: =Calc!B10 | E7: =ABS(C7-D7)
A8: dry kiln with precalciner | B8: heavy or residual fuel oil if | C8: =CEIbPaF!I2 | D8: =Calc!B9 | E8: =ABS(C8-D8)
A9: dry kiln with CCS | B9: electricity if | C9: =CEIbPaF!B3 | D9: =Calc!B15 | E9: =ABS(C9-D9)
A10: dry kiln with CCS | B10: hard coal if | C10: =CEIbPaF!C3 | D10: =Calc!B7 | E10: =ABS(C10-D10)
A11: dry kiln with CCS | B11: natural gas if | C11: =CEIbPaF!D3 | D11: =Calc!B8 | E11: =ABS(C11-D11)
A12: dry kiln with CCS | B12: biomass if | C12: =CEIbPaF!E3 | D12: =Calc!B10 | E12: =ABS(C12-D12)
A13: dry kiln with CCS | B13: heavy or residual fuel oil if | C13: =CEIbPaF!I3 | D13: =Calc!B9 | E13: =ABS(C13-D13)
A14: electric kiln | B14: electricity if | C14: =CEIbPaF!B4 | D14: =Parameters!B6 | E14: =ABS(C14-D14)
A15: alternative chemistry cement | B15: electricity if | C15: =CEIbPaF!B5 | D15: =Parameters!B7 | E15: =ABS(C15-D15)
A17: MAX abs diff | E17: =MAX(E4:E15)
A18: Overall | E18: =IF(E17<0.0000001,"PASS","FAIL")

Sheet CEIbPaF
A1: Unit: BTU/metric ton clinker (DOE Bandwidth 2017 thermal x PCA 2023 fuel mix; coal 33%/NG 31%/petcoke 20%/alt fuels 16% (as biomass); petcoke split 41% petroleum diesel + 59% residual oil to mirror BIFU's labelling of AEO petroleum coke and other petroleum (2026-10-01); CCS row is KILN ONLY - capture energy is booked by the CCS sector from captured tons; electric kiln/alt chem placeholders - verify before release) | B1: electricity if | C1: hard coal if | D1: natural gas if | E1: biomass if | F1: petroleum diesel if | G1: heat if | H1: crude oil if | I1: heavy or residual fuel oil if | J1: LPG propane or butane if | K1: hydrogen if | L1: green hydrogen if | M1: low carbon hydrogen if
A2: dry kiln with precalciner | B2: 590000 | C2: 1130000 | D2: 1060000 | E2: 550000 | F2: 283000 | G2: 0 | H2: 0 | I2: 407000 | J2: 0 | K2: 0 | L2: 0 | M2: 0
A3: dry kiln with CCS | B3: 590000 | C3: 1130000 | D3: 1060000 | E3: 550000 | F3: 283000 | G3: 0 | H3: 0 | I3: 407000 | J3: 0 | K3: 0 | L3: 0 | M3: 0
A4: electric kiln | B4: 4000000 | C4: 0 | D4: 0 | E4: 0 | F4: 0 | G4: 0 | H4: 0 | I4: 0 | J4: 0 | K4: 0 | L4: 0 | M4: 0
A5: alternative chemistry cement | B5: 2500000 | C5: 0 | D5: 0 | E5: 0 | F5: 0 | G5: 0 | H5: 0 | I5: 0 | J5: 0 | K5: 0 | L5: 0 | M5: 0
