Workbook
Name gal_per_barrel: [1]About!$A$63

Sheet About
A1: BFPIaE BAU Fuel Production
A2: BFPIaE BAU Fuel Imports
A3: BFPIaE BAU Fuel Exports
A5: Source: | B5: Petroleum-based fuels, biofuels
B6: U.S. Energy Information Administration
B7: 2025 (with annual data for 2024)
B8: Petroleum & Other Liquids: Supply and Disposition
B9: https://www.eia.gov/dnav/pet/pet_sum_snd_d_nus_mbbl_a_cur.htm
B10: Area: US, Period: Annual 2024
B12: Nuclear Fuel (Uranium) Production
B13: U.S. Energy Information Administration
B14: 2025
B15: Domestic Uranium Production Report - Annual
B16: https://www.eia.gov/uranium/production/annual/umine.php
B18: Nuclear Fuel (Uranium) Domestic Demand
B19: U.S. Energy Information Administration
B20: 2025
B21: Uranium Marketing Annual Report
B22: https://www.eia.gov/uranium/marketing/summarytable1a.php?
B24: Hard Coal, Lignite
B25: U.S. Energy Information Administration
B26: 2025
B27: Annual Coal Report and Browser Data
B28: https://www.eia.gov/coal/annual/pdf/tableES1.pdf
B29: https://www.eia.gov/coal/data/browser/
B30: https://www.eia.gov/coal/data/browser/#/topic/41?agg=0,2,1&rank=g&freq=A&start=2001&end=2024&ctype=map&ltype=pin&rtype=s&maptype=0&rse=0&pin=
B31: https://www.eia.gov/coal/data/browser/#/topic/39?agg=2,1,0&rank=ok&map=COAL.EXPORT_QTY.TOT-TOT-TOT.A&freq=A&start=2001&end=2024&ctype=map&ltype=pin&rtype=s&pin=&rse=0&maptype=0
B33: Biomass Production and Exports
B34: U.S. Energy Information Administration
B35: 2025
B36: Monthly Densified Biomass Fuel Report, December 2024
B37: https://www.eia.gov/biofuels/biomass/?year=2024&month=12#table_data
B38: Tables 2 and 8
B40: Natural Gas, Hydrogen, Time Series Scaling Factors
B41: U.S. Energy Information Administration
B42: 2026
B43: Annual Energy Outlook 2026
B44: https://www.eia.gov/outlooks/aeo/tables_ref.php
B45: Alternative Electricity and Transportation, Tables 1, 19
B47: Municipal Solid Waste
...

Sheet Petroleum and Biofuel Data
B1: Area: US | C1: Period: 2017 (Annual) | E1: Unit: Thousand Barrels
C2: Supply | I2: Disposition | M2: Ending Stocks
C3: Field Production | D3: Renewable Fuels & Oxygenate Plant Net Production | E3: Refinery & Blender Net Production | F3: Imports | G3: Net Receipts | H3: Adjust- ments | I3: Stock Change | J3: Refinery & Blender Net Inputs | K3: Exports | L3: Products Supplied
A4: =TRIM(B4) -> Crude Oil & Petroleum Products | B4: Crude Oil & Petroleum Products | C4: 4794078 | D4: 437131 | E4: 7408771 | F4: 3702640 | H4: 137262 | I4: -135002 | J4: 7003159 | K4: 2327156 | L4: 7284569 | M4: 1894570
A5: =TRIM(B5) -> Crude Oil | B5: Crude Oil | C5: 4083494 | D5: - - | E5: - - | F5: 2230000 | H5: 194916 | I5: -108241 | J5: 5529012 | K5: 1087638 | L5: 0 | M5: 1015102
A6: =TRIM(B6) -> Hydrocarbon Gas Liquids | B6: Hydrocarbon Gas Liquids | C6: 1970031 | D6: -7941 | E6: 225172 | F6: 63125 | H6: - - | I6: -40797 | J6: 198527 | K6: 848015 | L6: 1244642 | M6: 188360
A7: =TRIM(B7) -> Natural Gas Liquids | B7: Natural Gas Liquids | C7: 1970031 | D7: -7941 | E7: 120757 | F7: 57128 | H7: - - | I7: -40636 | J7: 198527 | K7: 848015 | L7: 1134069 | M7: 186272
A8: =TRIM(B8) -> Ethane | B8: Ethane | C8: 781560 | D8: - - | E8: 1505 | F8: - | H8: - - | I8: -9779 | K8: 147584 | L8: 645260 | M8: 59821
A9: =TRIM(B9) -> Propane | B9: Propane | C9: 632906 | D9: - - | E9: 101344 | F9: 41465 | H9: - - | I9: -8358 | K9: 477616 | L9: 306457 | M9: 62077
A10: =TRIM(B10) -> Normal Butane | B10: Normal Butane | C10: 180543 | D10: - | E10: 20998 | F10: 13237 | H10: - - | I10: -7626 | J10: 66056 | K10: 149693 | L10: 6655 | M10: 34017
A11: =TRIM(B11) -> Isobutane | B11: Isobutane | C11: 153863 | D11: - | E11: -3090 | F11: 2358 | H11: - - | I11: -2667 | J11: 71652 | K11: 1181 | L11: 82965 | M11: 9674
A12: =TRIM(B12) -> Natural Gasoline | B12: Natural Gasoline | C12: 221159 | D12: -7941 | F12: 68 | H12: - - | I12: -12206 | J12: 60819 | K12: 71941 | L12: 92732 | M12: 20683
A13: =TRIM(B13) -> Refinery Olefins | B13: Refinery Olefins | C13: - - | D13: - - | E13: 104415 | F13: 5997 | H13: - - | I13: -161 | J13: - - | K13: - - | L13: 110573 | M13: 2088
A14: =TRIM(B14) -> Ethylene | B14: Ethylene | C14: - - | D14: - - | E14: 277 | F14: - | H14: - - | I14: 0 | J14: - - | K14: - - | L14: 277 | M14: 0
A15: =TRIM(B15) -> Propylene | B15: Propylene | C15: - - | D15: - - | E15: 106126 | F15: 5243 | H15: - - | I15: -90 | J15: - - | K15: - - | L15: 111459 | M15: 1397
A16: =TRIM(B16) -> Normal Butylene | B16: Normal Butylene | C16: - - | D16: - - | E16: -2397 | F16: 2433 | H16: - - | I16: -1165 | J16: - - | K16: - - | L16: 1201 | M16: 1204
A17: =TRIM(B17) -> Isobutylene | B17: Isobutylene | C17: - - | D17: - - | E17: 286 | F17: - | H17: - - | I17: 6 | J17: - - | K17: - - | L17: 280 | M17: 30
A18: =TRIM(B18) -> Other Liquids | B18: Other Liquids | C18: - - | D18: 443737 | E18: - - | F18: 471784 | H18: 19117 | I18: 8685 | J18: 741289 | K18: 171592 | L18: 13072 | M18: 328230
A19: =TRIM(B19) -> Hydrogen/Oxygenates/Renewables/Other Hydrocarbons | B19: Hydrogen/Oxygenates/Renewables/Other Hydrocarbons | C19: - - | D19: 443788 | E19: - - | F19: 19778 | H19: 36824 | I19: 577 | J19: 439078 | K19: 60735 | L19: 0 | M19: 29585
A20: =TRIM(B20) -> Hydrogen | B20: Hydrogen | C20: - - | D20: - - | E20: - - | H20: 81091 | I20: - - | J20: 81091 | L20: 0 | M20: - -
A21: =TRIM(B21) -> Oxygenates (excl. Fuel Ethanol) | B21: Oxygenates (excl. Fuel Ethanol) | C21: - - | D21: 26360 | E21: - - | F21: 3835 | H21: -4811 | I21: -31 | J21: - | K21: 25415 | L21: 0 | M21: 1446
A22: =TRIM(B22) -> Renewable Fuels (incl. Fuel Ethanol) | B22: Renewable Fuels (incl. Fuel Ethanol) | C22: - - | D22: 417428 | E22: - - | F22: 15707 | H22: -39640 | I22: 578 | J22: 357597 | K22: 35320 | L22: 0 | M22: 28092
A23: =TRIM(B23) -> Fuel Ethanol | B23: Fuel Ethanol | C23: - - | D23: 379435 | E23: - - | F23: 1824 | H23: -9859 | I23: 3285 | J23: 335023 | K23: 33092 | L23: 0 | M23: 23043
A24: =TRIM(B24) -> Renewable Fuels Except Fuel Ethanol | B24: Renewable Fuels Except Fuel Ethanol | C24: - - | D24: 37993 | E24: - - | F24: 13883 | H24: -29781 | I24: -2707 | J24: 22574 | K24: 2228 | L24: 0 | M24: 5049
A25: =TRIM(B25) -> Other Hydrocarbons | B25: Other Hydrocarbons | C25: - - | D25: - - | E25: - - | F25: 236 | H25: 184 | I25: 30 | J25: 390 | L25: 0 | M25: 47
A26: =TRIM(B26) -> Unfinished Oils | B26: Unfinished Oils | C26: - - | D26: - - | E26: - - | F26: 231478 | H26: - - | I26: 6013 | J26: 129406 | K26: 82949 | L26: 13110 | M26: 86337
A27: =TRIM(B27) -> Motor Gasoline Blend. Comp. | B27: Motor Gasoline Blend. Comp. | C27: - - | D27: -51 | E27: - - | F27: 220528 | H27: -17707 | I27: 2089 | J27: 172773 | K27: 27908 | L27: 0 | M27: 212293
A28: =TRIM(B28) -> Reformulated | B28: Reformulated | C28: - - | D28: -3 | E28: - - | F28: 76948 | H28: 65150 | I28: 1299 | J28: 140697 | K28: 99 | L28: 0 | M28: 53447
A29: =TRIM(B29) -> Conventional | B29: Conventional | C29: - - | D29: -48 | E29: - - | F29: 143580 | H29: -82856 | I29: 790 | J29: 32076 | K29: 27810 | L29: 0 | M29: 158846
A30: =TRIM(B30) -> Aviation Gasoline Blend. Comp. | B30: Aviation Gasoline Blend. Comp. | C30: - - | D30: - - | E30: - - | F30: - | H30: - - | I30: 6 | J30: 32 | K30: - | L30: -38 | M30: 15
A31: =TRIM(B31) -> Finished Petroleum Products | B31: Finished Petroleum Products | C31: - - | D31: 1336 | E31: 7179380 | F31: 250759 | H31: 57659 | I31: -38269 | J31: - - | K31: 1220551 | L31: 6306852 | M31: 291859
A32: =TRIM(B32) -> Finished Motor Gasoline | B32: Finished Motor Gasoline | C32: - - | D32: 1336 | E32: 3633123 | F32: 11784 | H32: 27566 | I32: -3860 | J32: - - | K32: 273483 | L32: 3404186 | M32: 24523
A33: =TRIM(B33) -> Reformulated | B33: Reformulated | C33: - - | E33: 1187104 | F33: - | H33: -59342 | I33: -7 | J33: - - | K33: - | L33: 1127769 | M33: 40
A34: =TRIM(B34) -> Conventional | B34: Conventional | C34: - - | D34: 1336 | E34: 2446019 | F34: 11784 | H34: 86908 | I34: -3853 | J34: - - | K34: 273483 | L34: 2276417 | M34: 24483
A35: =TRIM(B35) -> Finished Aviation Gasoline | B35: Finished Aviation Gasoline | C35: - - | D35: - - | E35: 4032 | F35: 165 | H35: - - | I35: 47 | J35: - - | K35: - | L35: 4150 | M35: 1041
A36: =TRIM(B36) -> Kerosene-Type Jet Fuel | B36: Kerosene-Type Jet Fuel | C36: - - | D36: - - | E36: 621176 | F36: 58273 | H36: - - | I36: -1706 | J36: - - | K36: 67161 | L36: 613994 | M36: 41304
A37: =TRIM(B37) -> Kerosene | B37: Kerosene | C37: - - | D37: - - | E37: 2738 | F37: 1429 | H37: - - | I37: 10 | J37: - - | K37: 2267 | L37: 1890 | M37: 2138
A38: =TRIM(B38) -> Distillate Fuel Oil | B38: Distillate Fuel Oil | C38: - - | D38: - - | E38: 1833879 | F38: 54975 | H38: 30093 | I38: -20457 | J38: - - | K38: 504155 | L38: 1435249 | M38: 145638
A39: =TRIM(B39) -> 15 ppm Sulfur and Under | B39: 15 ppm Sulfur and Under | C39: - - | D39: - - | E39: 1713652 | F39: 37012 | H39: 30093 | I39: -16256 | J39: - - | K39: 423862 | L39: 1373151 | M39: 128016
A40: =TRIM(B40) -> Greater than 15 to 500 ppm Sulfur | B40: Greater than 15 to 500 ppm Sulfur | C40: - - | D40: - - | E40: 42167 | F40: 759 | H40: - | I40: -929 | J40: - - | K40: 41645 | L40: 2210 | M40: 7480
...

Sheet Petroleum and Biofuels 
A2: #VALUE!
A4: #VALUE! | C4: Field Production | D4: Transfers to Crude Oil Supply | E4: Biofuels Plant Net Production | F4: Refinery & Blender Net Production | G4: Imports | H4: Net Receipts | I4: Adjust- ments | J4: Stock Change | K4: Refinery & Blender Net Inputs | L4: Exports | M4: Products Supplied
B5: Crude Oil & Petroleum Products | C5: 7420896 | D5: 0 | E5: 504680 | F5: 7146373 | G5: 3088150 | I5: 64054 | J5: 23607 | K5: 6791496 | L5: 3919330 | M5: 7489722 | N5: 1629709
B6: Crude Oil | C6: 4843858 | D6: 223927 | E6: - - | F6: - - | G6: 2411095 | I6: -16532 | J6: 25773 | K6: 5938479 | L6: 1498096 | M6: 0 | N6: 806948
B7: Hydrocarbon Gas Liquids | C7: 2577038 | D7: -176427 | E7: -8484 | F7: 212322 | G7: 64641 | I7: - - | J7: 2412 | K7: 237103 | L7: 1060250 | M7: 1369325 | N7: 225710
B8: Natural Gas Liquids | C8: 2577038 | D8: -176427 | E8: -8484 | F8: 122497 | G8: 58699 | I8: - - | J8: 1772 | K8: 237103 | L8: 1060250 | M8: 1274198 | N8: 223701
B9: Ethane | C9: 1049589 | E9: - - | F9: 3305 | G9: - | I9: - - | J9: 5808 | L9: 178192 | M9: 868894 | N9: 71604
B10: Propane | C10: 798376 | D10: -269 | E10: - - | F10: 99800 | G10: 39610 | I10: - - | J10: 1009 | L10: 646618 | M10: 289890 | N10: 80649
B11: Normal Butane | C11: 246951 | D11: -5230 | E11: -- | F11: 25022 | G11: 15813 | I11: - - | J11: -2765 | K11: 62427 | L11: 179465 | M11: 43429 | N11: 36191
B12: Isobutane | C12: 170999 | D12: -1998 | E12: -- | F12: -5630 | G12: 3233 | I12: - - | J12: 1530 | K12: 91853 | L12: 1235 | M12: 71986 | N12: 12235
B13: Natural Gasoline | C13: 311123 | D13: -168930 | E13: -8484 | G13: 43 | I13: - - | J13: -3810 | K13: 82823 | L13: 54739 | M13: 0 | N13: 23022
B14: Condensate and Scrubber Oil | C14: 54857 | D14: -54860 | I14: - - | J14: -3 | M14: 0 | N14: 28
B15: Refinery Olefins | C15: - - | E15: - - | F15: 89825 | G15: 5942 | I15: - - | J15: 640 | K15: - - | L15: - - | M15: 95127 | N15: 2009
B16: Ethylene | C16: - - | E16: - - | F16: -6109 | G16: - | I16: - - | J16: 0 | K16: - - | L16: - - | M16: -6109 | N16: 0
B17: Propylene | C17: - - | E17: - - | F17: 96276 | G17: 5442 | I17: - - | J17: 466 | K17: - - | L17: - - | M17: 101252 | N17: 1375
B18: Normal Butylene | C18: - - | E18: - - | F18: -693 | G18: 500 | I18: - - | J18: 124 | K18: - - | L18: - - | M18: -317 | N18: 573
B19: Isobutylene | C19: - - | E19: - - | F19: 351 | G19: 7 | I19: - - | J19: 50 | K19: - - | L19: - - | M19: 301 | N19: 61
B20: Other Liquids | C20: - - | D20: -47500 | E20: 510454 | F20: - - | G20: 390451 | I20: 72862 | J20: -5840 | K20: 615914 | L20: 196936 | M20: 119257 | N20: 333975
B21: Hydrogen/Oxygenates/Renewables/Other Hydrocarbons | C21: - - | E21: 510459 | F21: - - | G21: 22625 | I21: 69549 | J21: 1891 | K21: 430753 | L21: 50526 | M21: 119462 | N21: 35008
B22: Hydrogen | C22: - - | E22: - - | F22: - - | I22: 80466 | J22: - - | K22: 80466 | M22: 0 | N22: - -
B23: Oxygenates (excl. Fuel Ethanol) | C23: - - | E23: -- | F23: - - | G23: -- | I23: -- | J23: -- | K23: -- | L23: -- | M23: - | N23: --
B24: Biofuels (incl. Fuel Ethanol) | C24: - - | E24: 510459 | F24: - - | G24: 22625 | I24: -11037 | J24: 1889 | K24: 350169 | L24: 50526 | M24: 119462 | N24: 34993
B25: Fuel Ethanol | C25: - - | E25: 386316 | F25: - - | G25: - | I25: -11037 | J25: 920 | K25: 328136 | L25: 46223 | M25: 0 | N25: 24418
B26: Biofuels (excl. Fuel Ethanol) | C26: - - | E26: 124142 | F26: - - | G26: 22625 | I26: -- | J26: 969 | K26: 22033 | L26: 4303 | M26: 119462 | N26: 10575
B27: Biodiesel | C27: - - | E27: 39795 | F27: - - | G27: 10231 | I27: - | J27: -258 | K27: 16089 | L27: 4303 | M27: 29893 | N27: 3555
B28: Renewable Diesel Fuel | C28: - - | E28: 76054 | F28: - - | G28: 12394 | I28: - | J28: 1053 | K28: 4037 | L28: NA | M28: 83358 | N28: 6531
B29: Other Biofuels | C29: - - | E29: 8293 | F29: - - | G29: - | I29: - | J29: 174 | K29: 1907 | L29: NA | M29: 6211 | N29: 489
B30: Other Hydrocarbons | C30: - - | E30: - - | F30: - - | G30: - | I30: 120 | J30: 2 | K30: 118 | M30: 0 | N30: 15
B31: Unfinished Oils | C31: - - | D31: -47500 | E31: - - | F31: - - | G31: 163638 | I31: - - | J31: -7656 | K31: 5556 | L31: 118238 | M31: 0 | N31: 76522
B32: Motor Gasoline Blend. Comp. | C32: - - | E32: -5 | F32: - - | G32: 204188 | I32: 3314 | J32: -85 | K32: 179410 | L32: 28172 | M32: 0 | N32: 222405
B33: Reformulated | C33: - - | E33: -1 | F33: - - | G33: 56108 | I33: 132745 | J33: 1456 | K33: 187319 | L33: 77 | M33: 0 | N33: 51987
B34: Conventional | C34: - - | E34: -5 | F34: - - | G34: 148080 | I34: -129431 | J34: -1541 | K34: -7909 | L34: 28095 | M34: 0 | N34: 170417
B35: Aviation Gasoline Blend. Comp. | C35: - - | E35: - - | F35: - - | G35: - | I35: - - | J35: 10 | K35: 195 | L35: - | M35: -205 | N35: 40
B36: Finished Petroleum Products | C36: - - | E36: 2711 | F36: 6934051 | G36: 221963 | I36: 7724 | J36: 1262 | K36: - - | L36: 1164048 | M36: 6001139 | N36: 263076
B37: Finished Motor Gasoline | C37: - - | E37: 2423 | F37: 3520823 | G37: 39911 | I37: 7724 | J37: -2415 | K37: - - | L37: 291546 | M37: 3281750 | N37: 15812
B38: Reformulated | C38: - - | F38: 1112341 | G38: - | I38: -99601 | J38: -1 | K38: - - | L38: - | M38: 1012741 | N38: 21
B39: Conventional | C39: - - | E39: 2423 | F39: 2408482 | G39: 39911 | I39: 107325 | J39: -2414 | K39: - - | L39: 291546 | M39: 2269009 | N39: 15791
B40: Finished Aviation Gasoline | C40: - - | E40: - - | F40: 4448 | G40: 322 | I40: - - | J40: 259 | K40: - - | L40: - | M40: 4511 | N40: 1460
B41: Kerosene-Type Jet Fuel | C41: - - | E41: 303 | F41: 660696 | G41: 38442 | I41: - - | J41: 3934 | K41: - - | L41: 76907 | M41: 618600 | N41: 43711
B42: Kerosene | C42: - - | E42: -- | F42: 4539 | G42: 15 | I42: - - | J42: -157 | K42: - - | L42: 1953 | M42: 2758 | N42: 1781
...

Sheet Biomass Data
A2: Table 8. Export sales and average price of densified biomass fuel, 2020
A3: Month | B3: Quantity (tons) | C3: Average Price (USD per ton)
A4: 1 | B4: 516492 | C4: 167.75
A5: 2 | B5: 749693 | C5: 163.39
A6: 3 | B6: 828225 | C6: 167.92
A7: 4 | B7: 714829 | C7: 164.43
A8: 5 | B8: 747809 | C8: 166.38
A9: 6 | B9: 734710 | C9: 159.44
A10: 7 | B10: 826189 | C10: 159.27
A11: 8 | B11: 739552 | C11: 169.81
A12: 9 | B12: 738479 | C12: 165.88
A13: 10 | B13: 757813 | C13: 166.42
A14: 11 | B14: 738409 | C14: 171.17
A15: 12 | B15: 779012 | C15: 172.44
A17: Total wood pellet production (Table 2)
A18: 13341865 | B18: tons
A20: Total wood pellet exports
A21: =SUM(B4:B15) -> 8871212 | B21: tons
A23: We don't have biomass import data from EIA. Imports are assumed to be negligible.
A25: Total wood pellet imports
A26: 0 | B26: tons

Sheet Uranium, Coal, MSW, Hydrogen
A1: Uranium
B2: Production | C2: Imports | D2: Exports | E2: Demand | F2: Unit
A3: 2024 | B3: =677/1000 -> 0.677 | C3: =E3-B3 -> 55.223 | D3: 0 | E3: 55.9 | F3: million pounds U3O8
A5: Hard Coal and Lignite
A6: 40.016958 | B6: million short tons of lignite produced in 2024 | F6: https://www.eia.gov/coal/annual/pdf/tableES1.pdf
A7: 512.54032 | B7: million short tons of coal produced (of all types) in 2024 | F7: https://www.eia.gov/coal/data/browser/
A8: 108.32638 | B8: million short tons of coal exported in 2024 | F8: https://www.eia.gov/coal/data/browser/#/topic/41?agg=0,2,1&rank=g&freq=A&start=2001&end=2024&ctype=map&ltype=pin&rtype=s&maptype=0&rse=0&pin=
A9: 1.997711 | B9: million short tons of coal imported in 2024 | F9: https://www.eia.gov/coal/data/browser/#/topic/39?agg=2,1,0&rank=ok&map=COAL.EXPORT_QTY.TOT-TOT-TOT.A&freq=A&start=2001&end=2024&ctype=map&ltype=pin&rtype=s&pin=&rse=0&maptype=0
A10: We assume that all imported and exported coal was hard coal, while all lignite produced was used domestically.
B12: Production | C12: Imports | D12: Exports | E12: Unit
A13: Hard Coal | B13: =A7*(1-A6/A7) -> 472.52337 | C13: =A9 -> 1.997711 | D13: =A8 -> 108.32638 | E13: million short tons
A14: Lignite | B14: =A6 -> 40.016958 | C14: 0 | D14: 0 | E14: million short tons
A16: Municipal Solid Waste
A17: MSW Tonnage Data for Year 2015
A18: 292 | B18: U.S. MSW generated (million tons)
A20: Although the U.S. exports waste to other countries,
A21: it is difficult to find statistics for waste exports other than plastic waste.
A22: (Plastic waste exports to other countries in 2018 were
A23: 1.07 million metric tons in 2018.) | D23: https://www.plasticpollutioncoalition.org/pft/2019/3/6/157000-shipping-containers-of-us-plastic-waste-exported-to-countries-with-poor-waste-management-in-2018
A26: In this model, we are only concerned about MSW that is burned as a
A27: fuel. We will assume that a negligible amount of exported waste
A28: is used as a fuel.
A30: Hydrogen
A31: =5.51+0.23 -> 5.74 | B31: million metric tons
A32: produced in 2024 (NOT including byproduct hydrogen)
A34: We assume none was imported or exported.

Sheet AEO Conversion Factors
B1: ref2023.d020623a | C1: 2022 | D1: 2023 | E1: 2024 | F1: 2025 | G1: 2026 | H1: 2027 | I1: 2028 | J1: 2029 | K1: 2030 | L1: 2031 | M1: 2032 | N1: 2033 | O1: 2034 | P1: 2035 | Q1: 2036 | R1: 2037 | S1: 2038 | T1: 2039 | U1: 2040 | V1: 2041 | W1: 2042 | X1: 2043 | Y1: 2044 | Z1: 2045 | AA1: 2046 | AB1: 2047 | AC1: 2048 | AD1: 2049 | AE1: 2050
C3: Report | D3: Annual Energy Outlook 2023
C4: Scenario | D4: ref2023 | G4: Reference
C5: Datekey | D5: d020623a
C6: Release Date | E6: March 2023
A10: CNV000:convert_cbob | B10: 68. Conversion Factors | AF10: Annual
A11: CNV000:convert_rbob | B11: (from physical units to million Btu) | AF11: Change
A12: CNV000:aa_PentanesPlus | AF12: 2022–2050
A13: CNV000:aa_OtherPetroleu | C13: 2022 | D13: 2023 | E13: 2024 | F13: 2025 | G13: 2026 | H13: 2027 | I13: 2028 | J13: 2029 | K13: 2030 | L13: 2031 | M13: 2032 | N13: 2033 | O13: 2034 | P13: 2035 | Q13: 2036 | R13: 2037 | S13: 2038 | T13: 2039 | U13: 2040 | V13: 2041 | W13: 2042 | X13: 2043 | Y13: 2044 | Z13: 2045 | AA13: 2046 | AB13: 2047 | AC13: 2048 | AD13: 2049 | AE13: 2050 | AF13: 2050
A14: CNV000:aa_PetrochemFeed | B14: Petroleum and Other Liquids
A15: CNV000:aa_PetroleumCoke | B15: (million Btu per barrel)
A16: CNV000:aa_ResidualFuel | B16: Asphalt and Road Oil | C16: 6.636 | D16: 6.636 | E16: 6.636 | F16: 6.636 | G16: 6.636 | H16: 6.636 | I16: 6.636 | J16: 6.636 | K16: 6.636 | L16: 6.636 | M16: 6.636 | N16: 6.636 | O16: 6.636 | P16: 6.636 | Q16: 6.636 | R16: 6.636 | S16: 6.636 | T16: 6.636 | U16: 6.636 | V16: 6.636 | W16: 6.636 | X16: 6.636 | Y16: 6.636 | Z16: 6.636 | AA16: 6.636 | AB16: 6.636 | AC16: 6.636 | AD16: 6.636 | AE16: 6.636 | AF16: 0
A17: CNV000:aa_StillGas | B17: Aviation Gasoline | C17: 5.048 | D17: 5.048 | E17: 5.048 | F17: 5.048 | G17: 5.048 | H17: 5.048 | I17: 5.048 | J17: 5.048 | K17: 5.048 | L17: 5.048 | M17: 5.048 | N17: 5.048 | O17: 5.048 | P17: 5.048 | Q17: 5.048 | R17: 5.048 | S17: 5.048 | T17: 5.048 | U17: 5.048 | V17: 5.048 | W17: 5.048 | X17: 5.048 | Y17: 5.048 | Z17: 5.048 | AA17: 5.048 | AB17: 5.048 | AC17: 5.048 | AD17: 5.048 | AE17: 5.048 | AF17: 0
A18: CNV000:aa_UnfinishOilIm | B18: Biodiesel | C18: 5.359 | D18: 5.359 | E18: 5.359 | F18: 5.359 | G18: 5.359 | H18: 5.359 | I18: 5.359 | J18: 5.359 | K18: 5.359 | L18: 5.359 | M18: 5.359 | N18: 5.359 | O18: 5.359 | P18: 5.359 | Q18: 5.359 | R18: 5.359 | S18: 5.359 | T18: 5.359 | U18: 5.359 | V18: 5.359 | W18: 5.359 | X18: 5.359 | Y18: 5.359 | Z18: 5.359 | AA18: 5.359 | AB18: 5.359 | AC18: 5.359 | AD18: 5.359 | AE18: 5.359 | AF18: 0
A19: CNV000:aa_TotalPetroleu | B19: Distillate Fuel Oil | C19: 5.825 | D19: 5.825 | E19: 5.825 | F19: 5.825 | G19: 5.825 | H19: 5.825 | I19: 5.825 | J19: 5.825 | K19: 5.825 | L19: 5.825 | M19: 5.825 | N19: 5.825 | O19: 5.825 | P19: 5.825 | Q19: 5.825 | R19: 5.825 | S19: 5.825 | T19: 5.825 | U19: 5.825 | V19: 5.825 | W19: 5.825 | X19: 5.825 | Y19: 5.825 | Z19: 5.825 | AA19: 5.825 | AB19: 5.825 | AC19: 5.825 | AD19: 5.825 | AE19: 5.825 | AF19: 0
A20: CNV000:aa_Imports | B20: Residential | C20: 5.775621 | D20: 5.775648 | E20: 5.776083 | F20: 5.776062 | G20: 5.776467 | H20: 5.777218 | I20: 5.776948 | J20: 5.776953 | K20: 5.776798 | L20: 5.776974 | M20: 5.776898 | N20: 5.77701 | O20: 5.776805 | P20: 5.776956 | Q20: 5.776839 | R20: 5.776862 | S20: 5.776748 | T20: 5.776711 | U20: 5.776654 | V20: 5.776614 | W20: 5.776632 | X20: 5.776631 | Y20: 5.776552 | Z20: 5.776594 | AA20: 5.776409 | AB20: 5.776283 | AC20: 5.77638 | AD20: 5.776386 | AE20: 5.776234 | AF20: 4e-06
A21: CNV000:aa_Exports | B21: Commercial | C21: 5.775621 | D21: 5.775648 | E21: 5.776083 | F21: 5.776062 | G21: 5.776467 | H21: 5.777218 | I21: 5.776948 | J21: 5.776953 | K21: 5.776798 | L21: 5.776974 | M21: 5.776898 | N21: 5.77701 | O21: 5.776805 | P21: 5.776956 | Q21: 5.776839 | R21: 5.776862 | S21: 5.776748 | T21: 5.776711 | U21: 5.776654 | V21: 5.776614 | W21: 5.776632 | X21: 5.776631 | Y21: 5.776552 | Z21: 5.776594 | AA21: 5.776409 | AB21: 5.776283 | AC21: 5.77638 | AD21: 5.776386 | AE21: 5.776234 | AF21: 4e-06
B22: Transportation | C22: 5.775621 | D22: 5.775648 | E22: 5.776083 | F22: 5.776062 | G22: 5.776467 | H22: 5.777218 | I22: 5.776948 | J22: 5.776953 | K22: 5.776798 | L22: 5.776974 | M22: 5.776898 | N22: 5.77701 | O22: 5.776805 | P22: 5.776956 | Q22: 5.776839 | R22: 5.776862 | S22: 5.776748 | T22: 5.776711 | U22: 5.776654 | V22: 5.776614 | W22: 5.776632 | X22: 5.776631 | Y22: 5.776552 | Z22: 5.776594 | AA22: 5.776409 | AB22: 5.776283 | AC22: 5.77638 | AD22: 5.776386 | AE22: 5.776234 | AF22: 4e-06
A23: CNV000:aa_CrudeOilProdu | B23: Industrial | C23: 5.775621 | D23: 5.775648 | E23: 5.776083 | F23: 5.776062 | G23: 5.776467 | H23: 5.777218 | I23: 5.776948 | J23: 5.776953 | K23: 5.776798 | L23: 5.776974 | M23: 5.776898 | N23: 5.77701 | O23: 5.776805 | P23: 5.776956 | Q23: 5.776839 | R23: 5.776862 | S23: 5.776748 | T23: 5.776711 | U23: 5.776654 | V23: 5.776614 | W23: 5.776632 | X23: 5.776631 | Y23: 5.776552 | Z23: 5.776594 | AA23: 5.776409 | AB23: 5.776283 | AC23: 5.77638 | AD23: 5.776386 | AE23: 5.776234 | AF23: 4e-06
A24: CNV000:aa_CrudeOilImpor | B24: Electric Power | C24: 5.775621 | D24: 5.775648 | E24: 5.776083 | F24: 5.776062 | G24: 5.776467 | H24: 5.777218 | I24: 5.776948 | J24: 5.776953 | K24: 5.776798 | L24: 5.776974 | M24: 5.776898 | N24: 5.77701 | O24: 5.776805 | P24: 5.776956 | Q24: 5.776839 | R24: 5.776862 | S24: 5.776748 | T24: 5.776711 | U24: 5.776654 | V24: 5.776614 | W24: 5.776632 | X24: 5.776631 | Y24: 5.776552 | Z24: 5.776594 | AA24: 5.776409 | AB24: 5.776283 | AC24: 5.77638 | AD24: 5.776386 | AE24: 5.776234 | AF24: 4e-06
A25: CNV000:aa_CrudeOilExpor | B25: Total Distillate | C25: 5.775621 | D25: 5.775648 | E25: 5.776083 | F25: 5.776062 | G25: 5.776467 | H25: 5.777218 | I25: 5.776948 | J25: 5.776953 | K25: 5.776799 | L25: 5.776974 | M25: 5.776899 | N25: 5.77701 | O25: 5.776805 | P25: 5.776956 | Q25: 5.776838 | R25: 5.776862 | S25: 5.776748 | T25: 5.776711 | U25: 5.776654 | V25: 5.776614 | W25: 5.776632 | X25: 5.776631 | Y25: 5.776552 | Z25: 5.776594 | AA25: 5.776409 | AB25: 5.776284 | AC25: 5.77638 | AD25: 5.776386 | AE25: 5.776234 | AF25: 4e-06
A26: CNV000:aa_NaturalGasPla | B26: Distillate Fuel Oil - Low Sulfur Diesel | C26: 5.817 | D26: 5.817 | E26: 5.817 | F26: 5.817 | G26: 5.817 | H26: 5.817 | I26: 5.817 | J26: 5.817 | K26: 5.817 | L26: 5.817 | M26: 5.817 | N26: 5.817 | O26: 5.817 | P26: 5.817 | Q26: 5.817 | R26: 5.817 | S26: 5.817 | T26: 5.817 | U26: 5.817 | V26: 5.817 | W26: 5.817 | X26: 5.817 | Y26: 5.817 | Z26: 5.817 | AA26: 5.817 | AB26: 5.817 | AC26: 5.817 | AD26: 5.817 | AE26: 5.817 | AF26: 0
B27: Distillate Fuel Oil - Ultra Low Sulfur Diesel | C27: 5.77 | D27: 5.77 | E27: 5.77 | F27: 5.77 | G27: 5.77 | H27: 5.77 | I27: 5.77 | J27: 5.77 | K27: 5.77 | L27: 5.77 | M27: 5.77 | N27: 5.77 | O27: 5.77 | P27: 5.77 | Q27: 5.77 | R27: 5.77 | S27: 5.77 | T27: 5.77 | U27: 5.77 | V27: 5.77 | W27: 5.77 | X27: 5.77 | Y27: 5.77 | Z27: 5.77 | AA27: 5.77 | AB27: 5.77 | AC27: 5.77 | AD27: 5.77 | AE27: 5.77 | AF27: 0
B28: Ethanol including denaturant | C28: 3.563 | D28: 3.563 | E28: 3.563 | F28: 3.563 | G28: 3.563 | H28: 3.563 | I28: 3.563 | J28: 3.563 | K28: 3.563 | L28: 3.563 | M28: 3.563 | N28: 3.563 | O28: 3.563 | P28: 3.563 | Q28: 3.563 | R28: 3.563 | S28: 3.563 | T28: 3.563 | U28: 3.563 | V28: 3.563 | W28: 3.563 | X28: 3.563 | Y28: 3.563 | Z28: 3.563 | AA28: 3.563 | AB28: 3.563 | AC28: 3.563 | AD28: 3.563 | AE28: 3.563 | AF28: 0
A29: CNV000:ba_Consumption | B29: E85 1/ | C29: 3.994413 | D29: 3.994413 | E29: 3.994413 | F29: 3.994413 | G29: 3.994413 | H29: 3.994413 | I29: 3.994413 | J29: 3.994413 | K29: 3.994413 | L29: 3.994413 | M29: 3.994413 | N29: 3.994413 | O29: 3.994413 | P29: 3.994413 | Q29: 3.994413 | R29: 3.994413 | S29: 3.994413 | T29: 3.994413 | U29: 3.994413 | V29: 3.994413 | W29: 3.994413 | X29: 3.994413 | Y29: 3.994413 | Z29: 3.994413 | AA29: 3.994413 | AB29: 3.994413 | AC29: 3.994413 | AD29: 3.994413 | AE29: 3.994413 | AF29: 0
A30: CNV000:ba_Utility | B30: Jet Fuel - Kerosene | C30: 5.67 | D30: 5.67 | E30: 5.67 | F30: 5.67 | G30: 5.67 | H30: 5.67 | I30: 5.67 | J30: 5.67 | K30: 5.67 | L30: 5.67 | M30: 5.67 | N30: 5.67 | O30: 5.67 | P30: 5.67 | Q30: 5.67 | R30: 5.67 | S30: 5.67 | T30: 5.67 | U30: 5.67 | V30: 5.67 | W30: 5.67 | X30: 5.67 | Y30: 5.67 | Z30: 5.67 | AA30: 5.67 | AB30: 5.67 | AC30: 5.67 | AD30: 5.67 | AE30: 5.67 | AF30: 0
A31: CNV000:ba_Nonutility | B31: Lubricants | C31: 6.065 | D31: 6.065 | E31: 6.065 | F31: 6.065 | G31: 6.065 | H31: 6.065 | I31: 6.065 | J31: 6.065 | K31: 6.065 | L31: 6.065 | M31: 6.065 | N31: 6.065 | O31: 6.065 | P31: 6.065 | Q31: 6.065 | R31: 6.065 | S31: 6.065 | T31: 6.065 | U31: 6.065 | V31: 6.065 | W31: 6.065 | X31: 6.065 | Y31: 6.065 | Z31: 6.065 | AA31: 6.065 | AB31: 6.065 | AC31: 6.065 | AD31: 6.065 | AE31: 6.065 | AF31: 0
A32: CNV000:ba_Production | B32: Motor Gasoline Average | C32: 5.051711 | D32: 5.050536 | E32: 5.049363 | F32: 5.048181 | G32: 5.046995 | H32: 5.045806 | I32: 5.044614 | J32: 5.043417 | K32: 5.042216 | L32: 5.041012 | M32: 5.039805 | N32: 5.038594 | O32: 5.037381 | P32: 5.036164 | Q32: 5.03513 | R32: 5.034097 | S32: 5.033101 | T32: 5.032113 | U32: 5.031125 | V32: 5.030226 | W32: 5.029317 | X32: 5.028415 | Y32: 5.02752 | Z32: 5.02663 | AA32: 5.025746 | AB32: 5.024862 | AC32: 5.023974 | AD32: 5.023084 | AE32: 5.0222 | AF32: -0.000209
A33: CNV000:ba_Imports | B33: Conventional Motor Gasoline | C33: 5.051239 | D33: 5.049952 | E33: 5.048665 | F33: 5.047375 | G33: 5.046085 | H33: 5.044794 | I33: 5.043502 | J33: 5.042209 | K33: 5.040914 | L33: 5.039618 | M33: 5.038322 | N33: 5.037026 | O33: 5.03573 | P33: 5.034434 | Q33: 5.033323 | R33: 5.032218 | S33: 5.03115 | T33: 5.030091 | U33: 5.029032 | V33: 5.028083 | W33: 5.027124 | X33: 5.026171 | Y33: 5.025226 | Z33: 5.024285 | AA33: 5.023351 | AB33: 5.022417 | AC33: 5.021479 | AD33: 5.020539 | AE33: 5.019606 | AF33: -0.000224
A34: CNV000:ba_Exports | B34: Reformulated Motor Gasoline | C34: 5.050956 | D34: 5.04961 | E34: 5.048264 | F34: 5.046918 | G34: 5.045574 | H34: 5.04423 | I34: 5.042888 | J34: 5.041545 | K34: 5.040203 | L34: 5.038862 | M34: 5.037521 | N34: 5.036182 | O34: 5.034844 | P34: 5.033506 | Q34: 5.032413 | R34: 5.031326 | S34: 5.030284 | T34: 5.029252 | U34: 5.028219 | V34: 5.027245 | W34: 5.026256 | X34: 5.025273 | Y34: 5.024298 | Z34: 5.023329 | AA34: 5.022367 | AB34: 5.021404 | AC34: 5.020434 | AD34: 5.019461 | AE34: 5.018494 | AF34: -0.00023
A35: CNV000:ba_CompressedNat | B35: Conventional before Blending | C35: 5.22228 | D35: 5.22228 | E35: 5.22228 | F35: 5.22228 | G35: 5.22228 | H35: 5.22228 | I35: 5.22228 | J35: 5.22228 | K35: 5.22228 | L35: 5.22228 | M35: 5.22228 | N35: 5.22228 | O35: 5.22228 | P35: 5.22228 | Q35: 5.22228 | R35: 5.22228 | S35: 5.22228 | T35: 5.22228 | U35: 5.22228 | V35: 5.22228 | W35: 5.22228 | X35: 5.22228 | Y35: 5.22228 | Z35: 5.22228 | AA35: 5.22228 | AB35: 5.22228 | AC35: 5.22228 | AD35: 5.22228 | AE35: 5.22228 | AF35: 0
B36: Reformulated before Blending | C36: 5.22228 | D36: 5.22228 | E36: 5.22228 | F36: 5.22228 | G36: 5.22228 | H36: 5.22228 | I36: 5.22228 | J36: 5.22228 | K36: 5.22228 | L36: 5.22228 | M36: 5.22228 | N36: 5.22228 | O36: 5.22228 | P36: 5.22228 | Q36: 5.22228 | R36: 5.22228 | S36: 5.22228 | T36: 5.22228 | U36: 5.22228 | V36: 5.22228 | W36: 5.22228 | X36: 5.22228 | Y36: 5.22228 | Z36: 5.22228 | AA36: 5.22228 | AB36: 5.22228 | AC36: 5.22228 | AD36: 5.22228 | AE36: 5.22228 | AF36: 0
B37: Natural Gasoline | C37: 4.638 | D37: 4.638 | E37: 4.638 | F37: 4.638 | G37: 4.638 | H37: 4.638 | I37: 4.638 | J37: 4.638 | K37: 4.638 | L37: 4.638 | M37: 4.638 | N37: 4.638 | O37: 4.638 | P37: 4.638 | Q37: 4.638 | R37: 4.638 | S37: 4.638 | T37: 4.638 | U37: 4.638 | V37: 4.638 | W37: 4.638 | X37: 4.638 | Y37: 4.638 | Z37: 4.638 | AA37: 4.638 | AB37: 4.638 | AC37: 4.638 | AD37: 4.638 | AE37: 4.638 | AF37: 0
A38: CNV000:ca_Production | B38: Other Petroleum | C38: 5.8 | D38: 5.8 | E38: 5.8 | F38: 5.8 | G38: 5.8 | H38: 5.8 | I38: 5.8 | J38: 5.8 | K38: 5.8 | L38: 5.8 | M38: 5.8 | N38: 5.8 | O38: 5.8 | P38: 5.8 | Q38: 5.8 | R38: 5.8 | S38: 5.8 | T38: 5.8 | U38: 5.8 | V38: 5.8 | W38: 5.8 | X38: 5.8 | Y38: 5.8 | Z38: 5.8 | AA38: 5.8 | AB38: 5.8 | AC38: 5.8 | AD38: 5.8 | AE38: 5.8 | AF38: 0
A39: CNV000:ca_EastoftheMiss | B39: Petrochemical Feedstocks | C39: 5.448283 | D39: 5.448283 | E39: 5.448283 | F39: 5.448283 | G39: 5.448283 | H39: 5.448283 | I39: 5.448283 | J39: 5.448283 | K39: 5.448283 | L39: 5.448283 | M39: 5.448283 | N39: 5.448283 | O39: 5.448283 | P39: 5.448283 | Q39: 5.448283 | R39: 5.448283 | S39: 5.448283 | T39: 5.448283 | U39: 5.448283 | V39: 5.448283 | W39: 5.448283 | X39: 5.448283 | Y39: 5.448283 | Z39: 5.448283 | AA39: 5.448283 | AB39: 5.448283 | AC39: 5.448283 | AD39: 5.448283 | AE39: 5.448283 | AF39: 0
A40: CNV000:ca_WestoftheMiss | B40: Petroleum Coke | C40: 6.287 | D40: 6.287 | E40: 6.287 | F40: 6.287 | G40: 6.287 | H40: 6.287 | I40: 6.287 | J40: 6.287 | K40: 6.287 | L40: 6.287 | M40: 6.287 | N40: 6.287 | O40: 6.287 | P40: 6.287 | Q40: 6.287 | R40: 6.287 | S40: 6.287 | T40: 6.287 | U40: 6.287 | V40: 6.287 | W40: 6.287 | X40: 6.287 | Y40: 6.287 | Z40: 6.287 | AA40: 6.287 | AB40: 6.287 | AC40: 6.287 | AD40: 6.287 | AE40: 6.287 | AF40: 0
A41: CNV000:ca_Consumption | B41: Residual Fuel | C41: 6.287 | D41: 6.287 | E41: 6.287 | F41: 6.287 | G41: 6.287 | H41: 6.287 | I41: 6.287 | J41: 6.287 | K41: 6.287 | L41: 6.287 | M41: 6.287 | N41: 6.287 | O41: 6.287 | P41: 6.287 | Q41: 6.287 | R41: 6.287 | S41: 6.287 | T41: 6.287 | U41: 6.287 | V41: 6.287 | W41: 6.287 | X41: 6.287 | Y41: 6.287 | Z41: 6.287 | AA41: 6.287 | AB41: 6.287 | AC41: 6.287 | AD41: 6.287 | AE41: 6.287 | AF41: 0
A42: CNV000:ca_Residentialan | B42: Still Gas | C42: 6.287 | D42: 6.287 | E42: 6.287 | F42: 6.287 | G42: 6.287 | H42: 6.287 | I42: 6.287 | J42: 6.287 | K42: 6.287 | L42: 6.287 | M42: 6.287 | N42: 6.287 | O42: 6.287 | P42: 6.287 | Q42: 6.287 | R42: 6.287 | S42: 6.287 | T42: 6.287 | U42: 6.287 | V42: 6.287 | W42: 6.287 | X42: 6.287 | Y42: 6.287 | Z42: 6.287 | AA42: 6.287 | AB42: 6.287 | AC42: 6.287 | AD42: 6.287 | AE42: 6.287 | AF42: 0
A43: CNV000:ca_Industrial | B43: Unfinished Oils | C43: 6.191736 | D43: 6.192239 | E43: 6.193067 | F43: 6.163516 | G43: 6.155307 | H43: 6.161367 | I43: 6.16242 | J43: 6.163478 | K43: 6.164545 | L43: 6.160776 | M43: 6.166696 | N43: 6.167782 | O43: 6.168875 | P43: 6.169975 | Q43: 6.171082 | R43: 6.172197 | S43: 6.173318 | T43: 6.174447 | U43: 6.175582 | V43: 6.176932 | W43: 6.178004 | X43: 6.179245 | Y43: 6.180129 | Z43: 6.181304 | AA43: 6.182486 | AB43: 6.183676 | AC43: 6.184874 | AD43: 6.18608 | AE43: 6.187586 | AF43: -2.4e-05
A44: CNV000:ca_Coking | B44: Total Petroleum Consumption | C44: 5.067464 | D44: 5.059147 | E44: 5.022825 | F44: 5.01719 | G44: 5.000348 | H44: 4.985026 | I44: 4.974782 | J44: 4.967464 | K44: 4.961115 | L44: 4.957813 | M44: 4.952669 | N44: 4.947966 | O44: 4.942125 | P44: 4.937525 | Q44: 4.932009 | R44: 4.929103 | S44: 4.927769 | T44: 4.92266 | U44: 4.920143 | V44: 4.916678 | W44: 4.910859 | X44: 4.90548 | Y44: 4.903147 | Z44: 4.901598 | AA44: 4.899264 | AB44: 4.896852 | AC44: 4.895994 | AD44: 4.893797 | AE44: 4.891023 | AF44: -0.001265
...

Sheet AEO 2026 Table 1
A1: Table 1. Total Energy Supply, Disposition, and Price Summary
A2: https://www.eia.gov/outlooks/aeo/data/browser/#/?id=1-AEO2026&region=0-0&cases=electrnp&start=2025&end=2050&f=A&sourcekey=0
A3: Thu Apr 23 2026 14:30:14 GMT-0700 (Pacific Daylight Time)
A4: Source: U.S. Energy Information Administration
B5: full name | C5: api key | D5: units | E5: 2025 | F5: 2026 | G5: 2027 | H5: 2028 | I5: 2029 | J5: 2030 | K5: 2031 | L5: 2032 | M5: 2033 | N5: 2034 | O5: 2035 | P5: 2036 | Q5: 2037 | R5: 2038 | S5: 2039 | T5: 2040 | U5: 2041 | V5: 2042 | W5: 2043 | X5: 2044 | Y5: 2045 | Z5: 2046 | AA5: 2047 | AB5: 2048 | AC5: 2049 | AD5: 2050 | AE5: Growth (2025-2050)
A6: Production
A7: Crude Oil and Lease Condensate | B7: Total Energy: Production: Crude Oil and Lease Condensate: Alternative Electricity and Transportation | C7: AEO.2026.ELECTRNP.SUP_PRD_TEN_NA_CLC_NA_USA_QBTU.A | D7: quads | E7: 28.09622 | F7: 27.83951 | G7: 27.93445 | H7: 27.987217 | I7: 27.814901 | J7: 28.041071 | K7: 28.029518 | L7: 27.882774 | M7: 27.414968 | N7: 27.162401 | O7: 26.851124 | P7: 26.72197 | Q7: 26.669319 | R7: 26.478785 | S7: 26.444294 | T7: 26.71266 | U7: 26.96909 | V7: 27.048578 | W7: 27.202837 | X7: 27.264698 | Y7: 27.201111 | Z7: 27.041689 | AA7: 26.884602 | AB7: 26.681749 | AC7: 26.394308 | AD7: 25.994829 | AE7: -0.003
A8: Natural Gas Plant Liquids | B8: Total Energy: Production: Natural Gas Plant Liquids: Alternative Electricity and Transportation | C8: AEO.2026.ELECTRNP.SUP_PRD_TEN_NA_NGP_NA_USA_QBTU.A | D8: quads | E8: 9.619033 | F8: 9.796805 | G8: 10.516297 | H8: 10.408414 | I8: 10.449044 | J8: 10.487188 | K8: 10.989504 | L8: 11.466014 | M8: 11.930082 | N8: 12.265282 | O8: 12.51648 | P8: 12.657268 | Q8: 12.87834 | R8: 13.124127 | S8: 13.329017 | T8: 13.664953 | U8: 13.958897 | V8: 14.123372 | W8: 14.198471 | X8: 14.139817 | Y8: 13.995239 | Z8: 13.875278 | AA8: 13.909235 | AB8: 14.003947 | AC8: 14.058703 | AD8: 14.029639 | AE8: 0.015
A9: Dry Natural Gas | B9: Total Energy: Production: Dry Natural Gas: Alternative Electricity and Transportation | C9: AEO.2026.ELECTRNP.SUP_PRD_TEN_NA_DNG_NA_USA_QBTU.A | D9: quads | E9: 40.570412 | F9: 40.294426 | G9: 39.723049 | H9: 40.499924 | I9: 40.887131 | J9: 42.027294 | K9: 43.181034 | L9: 44.25951 | M9: 45.101624 | N9: 46.168903 | O9: 46.66502 | P9: 47.017208 | Q9: 47.328976 | R9: 47.659122 | S9: 47.983776 | T9: 48.581455 | U9: 49.290066 | V9: 49.974457 | W9: 50.566368 | X9: 51.11755 | Y9: 51.666023 | Z9: 52.372948 | AA9: 52.807499 | AB9: 53.11705 | AC9: 53.229816 | AD9: 53.342106 | AE9: 0.011
A10: Coal | B10: Total Energy: Production: Coal: Alternative Electricity and Transportation | C10: AEO.2026.ELECTRNP.SUP_PRD_TEN_NA_CL_NA_USA_QBTU.A | D10: quads | E10: 10.763646 | F10: 10.497858 | G10: 10.141273 | H10: 9.522483 | I10: 9.294424 | J10: 9.39627 | K10: 8.459009 | L10: 8.232461 | M10: 8.093637 | N10: 7.82284 | O10: 7.805241 | P10: 7.667391 | Q10: 7.643977 | R10: 7.652178 | S10: 7.588447 | T10: 7.438392 | U10: 7.274271 | V10: 7.150982 | W10: 7.07684 | X10: 7.009675 | Y10: 6.930867 | Z10: 6.866632 | AA10: 6.879517 | AB10: 6.854223 | AC10: 6.756863 | AD10: 6.497005 | AE10: -0.02
A11: Nuclear / Uranium | B11: Total Energy: Production: Nuclear: Alternative Electricity and Transportation | C11: AEO.2026.ELECTRNP.SUP_PRD_TEN_NA_NUC_NA_USA_QBTU.A | D11: quads | E11: 8.187651 | F11: 8.372738 | G11: 8.321443 | H11: 8.357332 | I11: 8.366615 | J11: 8.373707 | K11: 8.373858 | L11: 8.373865 | M11: 8.373583 | N11: 8.373583 | O11: 8.373577 | P11: 8.373578 | Q11: 8.370988 | R11: 8.366815 | S11: 8.368925 | T11: 8.36346 | U11: 8.357713 | V11: 8.371456 | W11: 8.365458 | X11: 8.373578 | Y11: 8.373578 | Z11: 8.373578 | AA11: 8.373579 | AB11: 8.373578 | AC11: 8.373578 | AD11: 8.373294 | AE11: 0.001
A12: Conventional Hydroelectric Power | B12: Total Energy: Production: Hydropower: Alternative Electricity and Transportation | C12: AEO.2026.ELECTRNP.SUP_PRD_TEN_NA_HYD_CNV_USA_QBTU.A | D12: quads | E12: 0.833386 | F12: 0.893707 | G12: 0.914331 | H12: 0.933283 | I12: 0.938944 | J12: 0.939915 | K12: 0.940947 | L12: 0.940738 | M12: 0.941016 | N12: 0.941605 | O12: 0.941869 | P12: 0.941762 | Q12: 0.943859 | R12: 0.944092 | S12: 0.944029 | T12: 0.943578 | U12: 0.944099 | V12: 0.944191 | W12: 0.944182 | X12: 0.944196 | Y12: 0.94409 | Z12: 0.944285 | AA12: 0.944356 | AB12: 0.944565 | AC12: 0.944563 | AD12: 0.944374 | AE12: 0.005
A13: Biomass | B13: Total Energy: Production: Biomass: Alternative Electricity and Transportation | C13: AEO.2026.ELECTRNP.SUP_PRD_TEN_NA_BMS_NA_USA_QBTU.A | D13: quads | E13: 4.753613 | F13: 4.876166 | G13: 4.835322 | H13: 4.839541 | I13: 4.821688 | J13: 4.751903 | K13: 4.713766 | L13: 4.689816 | M13: 4.680038 | N13: 4.683924 | O13: 4.690135 | P13: 4.716203 | Q13: 4.726579 | R13: 4.744782 | S13: 4.771104 | T13: 4.799549 | U13: 4.804287 | V13: 4.839866 | W13: 4.852074 | X13: 4.868423 | Y13: 4.891001 | Z13: 4.910817 | AA13: 4.948695 | AB13: 4.997142 | AC13: 5.05494 | AD13: 5.273374 | AE13: 0.004
A14: Other Renewable Energy | B14: Total Energy: Production: Other Renewable Energy: Alternative Electricity and Transportation | C14: AEO.2026.ELECTRNP.SUP_PRD_TEN_NA_PRE_NA_USA_QBTU.A | D14: quads | E14: 2.880712 | F14: 3.166233 | G14: 3.747644 | H14: 4.126372 | I14: 4.342162 | J14: 4.504683 | K14: 4.661613 | L14: 4.761504 | M14: 4.886238 | N14: 5.063766 | O14: 5.264389 | P14: 5.470821 | Q14: 5.615872 | R14: 5.739579 | S14: 5.866665 | T14: 5.986307 | U14: 6.091763 | V14: 6.138132 | W14: 6.158761 | X14: 6.175585 | Y14: 6.190252 | Z14: 6.209311 | AA14: 6.233634 | AB14: 6.247483 | AC14: 6.276224 | AD14: 6.308211 | AE14: 0.032
A15: Other | B15: Total Energy: Production: Other: Alternative Electricity and Transportation | C15: AEO.2026.ELECTRNP.SUP_PRD_TEN_NA_OTH_NA_USA_QBTU.A | D15: quads | E15: 1.597606 | F15: 1.539008 | G15: 0.732086 | H15: 0.664054 | I15: 0.656211 | J15: 0.650822 | K15: 0.634452 | L15: 0.506509 | M15: 0.508553 | N15: 0.526544 | O15: 0.532123 | P15: 0.529193 | Q15: 0.542328 | R15: 0.546555 | S15: 0.548446 | T15: 0.543072 | U15: 0.542411 | V15: 0.539229 | W15: 0.542313 | X15: 0.558117 | Y15: 0.564131 | Z15: 0.563349 | AA15: 0.565125 | AB15: 0.56417 | AC15: 0.563789 | AD15: 0.56249 | AE15: -0.041
A16: Total | B16: Total Energy: Production: Total: Alternative Electricity and Transportation | C16: AEO.2026.ELECTRNP.SUP_PRD_TEN_NA_TOT_NA_USA_QBTU.A | D16: quads | E16: 107.30228 | F16: 107.27644 | G16: 106.86589 | H16: 107.33862 | I16: 107.57112 | J16: 109.17285 | K16: 109.9837 | L16: 111.11319 | M16: 111.92973 | N16: 113.00884 | O16: 113.63995 | P16: 114.09539 | Q16: 114.72024 | R16: 115.25603 | S16: 115.84471 | T16: 117.03342 | U16: 118.2326 | V16: 119.13027 | W16: 119.9073 | X16: 120.45164 | Y16: 120.7563 | Z16: 121.15789 | AA16: 121.54624 | AB16: 121.78391 | AC16: 121.65279 | AD16: 121.32533 | AE16: 0.005
A17: Imports
A18: Crude Oil | B18: Total Energy: Imports: Crude Oil: Alternative Electricity and Transportation | C18: AEO.2026.ELECTRNP.TRAD_IMP_TEN_NA_CR_NA_USA_QBTU.A | D18: quads | E18: 13.254901 | F18: 12.62451 | G18: 13.906896 | H18: 14.053762 | I18: 14.525437 | J18: 14.625464 | K18: 14.482899 | L18: 14.885132 | M18: 15.092349 | N18: 15.432104 | O18: 15.633177 | P18: 15.400255 | Q18: 15.42865 | R18: 15.850074 | S18: 15.792415 | T18: 15.533682 | U18: 15.173124 | V18: 14.999949 | W18: 14.883173 | X18: 14.798785 | Y18: 15.292476 | Z18: 15.863901 | AA18: 16.235161 | AB18: 16.110662 | AC18: 16.079632 | AD18: 16.61627 | AE18: 0.009
A19: Petroleum and Other Liquids | B19: Total Energy: Imports: Liquid Fuels: Alternative Electricity and Transportation | C19: AEO.2026.ELECTRNP.TRAD_IMP_TEN_NA_LFL_NA_USA_QBTU.A | D19: quads | E19: 3.506377 | F19: 3.419535 | G19: 3.574062 | H19: 3.492604 | I19: 3.409276 | J19: 3.386769 | K19: 3.340114 | L19: 3.288664 | M19: 3.248637 | N19: 3.199638 | O19: 3.165486 | P19: 3.146207 | Q19: 3.146906 | R19: 3.138245 | S19: 3.132051 | T19: 3.134073 | U19: 3.123925 | V19: 3.122812 | W19: 3.124113 | X19: 3.116613 | Y19: 3.142915 | Z19: 3.108672 | AA19: 3.098501 | AB19: 3.171854 | AC19: 3.170427 | AD19: 3.125792 | AE19: -0.005
A20: Natural Gas | B20: Total Energy: Imports: Natural Gas: Alternative Electricity and Transportation | C20: AEO.2026.ELECTRNP.TRAD_IMP_TEN_NA_NG_NA_USA_QBTU.A | D20: quads | E20: 3.256896 | F20: 3.391662 | G20: 3.244866 | H20: 2.953583 | I20: 2.832458 | J20: 2.97589 | K20: 2.959408 | L20: 2.754073 | M20: 2.516675 | N20: 2.360982 | O20: 2.385319 | P20: 2.451794 | Q20: 2.522372 | R20: 2.578678 | S20: 2.652019 | T20: 2.552771 | U20: 2.306502 | V20: 2.2828 | W20: 2.345492 | X20: 2.457237 | Y20: 2.509919 | Z20: 2.442209 | AA20: 2.537626 | AB20: 2.670558 | AC20: 2.810932 | AD20: 2.948299 | AE20: -0.004
A21: Other | B21: Total Energy: Imports: Other: Alternative Electricity and Transportation | C21: AEO.2026.ELECTRNP.TRAD_IMP_TEN_NA_OTH_NA_USA_QBTU.A | D21: quads | E21: 0.094426 | F21: 0.145997 | G21: 0.205067 | H21: 0.244731 | I21: 0.265442 | J21: 0.29067 | K21: 0.288673 | L21: 0.294341 | M21: 0.304539 | N21: 0.308912 | O21: 0.314078 | P21: 0.30591 | Q21: 0.304515 | R21: 0.303384 | S21: 0.30777 | T21: 0.303434 | U21: 0.303217 | V21: 0.290294 | W21: 0.279213 | X21: 0.274696 | Y21: 0.273568 | Z21: 0.264709 | AA21: 0.255194 | AB21: 0.24511 | AC21: 0.22992 | AD21: 0.220576 | AE21: 0.035
A22: Total | B22: Total Energy: Imports: Total: Alternative Electricity and Transportation | C22: AEO.2026.ELECTRNP.TRAD_IMP_TEN_NA_TOT_NA_USA_QBTU.A | D22: quads | E22: 20.112602 | F22: 19.581705 | G22: 20.930889 | H22: 20.74468 | I22: 21.032614 | J22: 21.278793 | K22: 21.071095 | L22: 21.22221 | M22: 21.162201 | N22: 21.301638 | O22: 21.49806 | P22: 21.304167 | Q22: 21.402443 | R22: 21.870382 | S22: 21.884254 | T22: 21.52396 | U22: 20.906769 | V22: 20.695856 | W22: 20.63199 | X22: 20.647331 | Y22: 21.218876 | Z22: 21.679491 | AA22: 22.126482 | AB22: 22.198185 | AC22: 22.290911 | AD22: 22.910936 | AE22: 0.005
A23: Exports
A24: Petroleum and Other Liquids | B24: Total Energy: Exports: Petroleum: Alternative Electricity and Transportation | C24: AEO.2026.ELECTRNP.TRAD_EXP_TEN_NA_PET_NA_USA_QBTU.A | D24: quads | E24: 20.076674 | F24: 19.914589 | G24: 21.616186 | H24: 21.639196 | I24: 22.136238 | J24: 22.429478 | K24: 23.03207 | L24: 23.705414 | M24: 24.135605 | N24: 24.560024 | O24: 24.835129 | P24: 24.702003 | Q24: 24.975132 | R24: 25.413769 | S24: 25.593113 | T24: 25.894386 | U24: 26.1339 | V24: 26.221857 | W24: 26.39142 | X24: 26.317417 | Y24: 26.584335 | Z24: 26.764486 | AA24: 26.981876 | AB24: 26.844584 | AC24: 26.65336 | AD24: 26.702797 | AE24: 0.011
A25: Natural Gas | B25: Total Energy: Exports: Natural Gas: Alternative Electricity and Transportation | C25: AEO.2026.ELECTRNP.TRAD_EXP_TEN_NA_NG_NA_USA_QBTU.A | D25: quads | E25: 8.975658 | F25: 9.088441 | G25: 9.822119 | H25: 10.434997 | I25: 10.937449 | J25: 12.260552 | K25: 12.868597 | L25: 13.509771 | M25: 13.987963 | N25: 14.747663 | O25: 15.282458 | P25: 15.722227 | Q25: 15.969494 | R25: 16.216171 | S25: 16.470881 | T25: 16.730671 | U25: 16.97636 | V25: 17.203733 | W25: 17.429588 | X25: 17.687986 | Y25: 17.89101 | Z25: 18.132946 | AA25: 18.363718 | AB25: 18.52001 | AC25: 18.519236 | AD25: 18.544718 | AE25: 0.029
A26: Coal | B26: Total Energy: Exports: Coal: Alternative Electricity and Transportation | C26: AEO.2026.ELECTRNP.TRAD_EXP_TEN_NA_CL_NA_USA_QBTU.A | D26: quads | E26: 2.463368 | F26: 2.559237 | G26: 2.735956 | H26: 2.849638 | I26: 2.751542 | J26: 2.886293 | K26: 2.907977 | L26: 3.081553 | M26: 3.111071 | N26: 3.103139 | O26: 3.1274 | P26: 3.06748 | Q26: 3.123805 | R26: 3.146678 | S26: 3.130178 | T26: 3.149433 | U26: 3.085596 | V26: 3.056049 | W26: 3.095218 | X26: 3.120324 | Y26: 3.108418 | Z26: 3.122652 | AA26: 3.11857 | AB26: 3.101774 | AC26: 3.112857 | AD26: 3.034203 | AE26: 0.008
A27: Total | B27: Total Energy: Exports: Total: Alternative Electricity and Transportation | C27: AEO.2026.ELECTRNP.TRAD_EXP_TEN_NA_TOT_NA_USA_QBTU.A | D27: quads | E27: 31.515699 | F27: 31.562267 | G27: 34.174259 | H27: 34.923828 | I27: 35.825226 | J27: 37.576321 | K27: 38.808643 | L27: 40.296738 | M27: 41.234638 | N27: 42.410824 | O27: 43.244987 | P27: 43.491711 | Q27: 44.068432 | R27: 44.776619 | S27: 45.194176 | T27: 45.77449 | U27: 46.195858 | V27: 46.48164 | W27: 46.916225 | X27: 47.125725 | Y27: 47.583763 | Z27: 48.020081 | AA27: 48.464165 | AB27: 48.466366 | AC27: 48.285454 | AD27: 48.281715 | AE27: 0.017
A28: Discrepancy | B28: Total Energy: Discrepancy: Alternative Electricity and Transportation | C28: AEO.2026.ELECTRNP.UNC_NA_TEN_NA_DESCR_NA_USA_QBTU.A | D28: quads | E28: 0.609568 | F28: -0.330133 | G28: -0.56411 | H28: -0.473511 | I28: -0.333321 | J28: 0.028347 | K28: -0.001419 | L28: -0.002094 | M28: -0.083462 | N28: -0.047085 | O28: -0.115166 | P28: -0.141689 | Q28: -0.128963 | R28: -0.042755 | S28: -0.078278 | T28: -0.053158 | U28: -0.099354 | V28: -0.012081 | W28: -0.081821 | X28: -0.072121 | Y28: -0.052273 | Z28: 0.023468 | AA28: -0.026619 | AB28: -0.023872 | AC28: -0.0513 | AD28: -0.034363 | AE28: - -
A29: Consumption
A30: Petroleum and Other Liquids | B30: Total Energy: Use: Liquid Fuels: Alternative Electricity and Transportation | C30: AEO.2026.ELECTRNP.CNSM_USE_TEN_NA_LFL_NA_USA_QBTU.A | D30: quads | E30: 37.415314 | F30: 37.39756 | G30: 37.429806 | H30: 37.393105 | I30: 37.092777 | J30: 36.903763 | K30: 36.673176 | L30: 36.545361 | M30: 36.386639 | N30: 36.327778 | O30: 36.269566 | P30: 36.183342 | Q30: 36.101166 | R30: 36.030628 | S30: 35.997036 | T30: 35.997505 | U30: 35.993946 | V30: 35.983074 | W30: 36.004101 | X30: 36.009083 | Y30: 36.05069 | Z30: 36.066441 | AA30: 36.141716 | AB30: 36.131622 | AC30: 36.106647 | AD30: 36.114407 | AE30: -0.001
A31: Natural Gas | B31: Total Energy: Use: Natural Gas: Alternative Electricity and Transportation | C31: AEO.2026.ELECTRNP.CNSM_USE_TEN_NA_NG_NA_USA_QBTU.A | D31: quads | E31: 34.309906 | F31: 34.343494 | G31: 32.823555 | H31: 32.58604 | I31: 32.265926 | J31: 32.059547 | K31: 32.53434 | L31: 32.775009 | M31: 32.883018 | N31: 33.030529 | O31: 32.972298 | P31: 32.965488 | Q31: 33.113277 | R31: 33.27256 | S31: 33.420219 | T31: 33.683891 | U31: 33.893101 | V31: 34.241695 | W31: 34.675434 | X31: 35.069263 | Y31: 35.454762 | Z31: 35.832901 | AA31: 36.141129 | AB31: 36.424366 | AC31: 36.691483 | AD31: 36.904549 | AE31: 0.003
A32: Coal | B32: Total Energy: Use: Coal: Alternative Electricity and Transportation | C32: AEO.2026.ELECTRNP.CNSM_USE_TEN_NA_CL_NA_USA_QBTU.A | D32: quads | E32: 8.312325 | F32: 7.978454 | G32: 7.41205 | H32: 6.680679 | I32: 6.548737 | J32: 6.516286 | K32: 5.549825 | L32: 5.152449 | M32: 4.980665 | N32: 4.715786 | O32: 4.682521 | P32: 4.603929 | Q32: 4.522728 | R32: 4.506305 | S32: 4.465453 | T32: 4.287592 | U32: 4.18628 | V32: 4.097344 | W32: 3.978774 | X32: 3.887891 | Y32: 3.823375 | Z32: 3.756142 | AA32: 3.769727 | AB32: 3.763525 | AC32: 3.644761 | AD32: 3.470035 | AE32: -0.034
A33: Nuclear / Uranium | B33: Total Energy: Use: Nuclear: Alternative Electricity and Transportation | C33: AEO.2026.ELECTRNP.CNSM_USE_TEN_NA_NUC_NA_USA_QBTU.A | D33: quads | E33: 8.187651 | F33: 8.372738 | G33: 8.321443 | H33: 8.357332 | I33: 8.366615 | J33: 8.373707 | K33: 8.373858 | L33: 8.373865 | M33: 8.373583 | N33: 8.373583 | O33: 8.373577 | P33: 8.373578 | Q33: 8.370988 | R33: 8.366815 | S33: 8.368925 | T33: 8.36346 | U33: 8.357713 | V33: 8.371456 | W33: 8.365458 | X33: 8.373578 | Y33: 8.373578 | Z33: 8.373578 | AA33: 8.373579 | AB33: 8.373578 | AC33: 8.373578 | AD33: 8.373294 | AE33: 0.001
A34: Conventional Hydroelectric Power | B34: Total Energy: Use: Hydropower: Alternative Electricity and Transportation | C34: AEO.2026.ELECTRNP.CNSM_USE_TEN_NA_HYD_CNV_USA_QBTU.A | D34: quads | E34: 0.833386 | F34: 0.893707 | G34: 0.914331 | H34: 0.933283 | I34: 0.938944 | J34: 0.939915 | K34: 0.940947 | L34: 0.940738 | M34: 0.941016 | N34: 0.941605 | O34: 0.941869 | P34: 0.941762 | Q34: 0.943859 | R34: 0.944092 | S34: 0.944029 | T34: 0.943578 | U34: 0.944099 | V34: 0.944191 | W34: 0.944182 | X34: 0.944196 | Y34: 0.94409 | Z34: 0.944285 | AA34: 0.944356 | AB34: 0.944565 | AC34: 0.944563 | AD34: 0.944374 | AE34: 0.005
A35: Biomass | B35: Total Energy: Use: Biomass: Alternative Electricity and Transportation | C35: AEO.2026.ELECTRNP.CNSM_USE_TEN_NA_BMS_NA_USA_QBTU.A | D35: quads | E35: 2.925746 | F35: 3.020187 | G35: 2.990986 | H35: 2.971073 | I35: 2.95593 | J35: 2.923736 | K35: 2.881742 | L35: 2.854099 | M35: 2.839809 | N35: 2.838316 | O35: 2.839848 | P35: 2.852271 | Q35: 2.857769 | R35: 2.873178 | S35: 2.891686 | T35: 2.908722 | U35: 2.907083 | V35: 2.920886 | W35: 2.925695 | X35: 2.93498 | Y35: 2.954176 | Z35: 2.969813 | AA35: 2.994902 | AB35: 3.023774 | AC35: 3.049063 | AD35: 3.256605 | AE35: 0.004
A36: Other Renewable Energy | B36: Total Energy: Use: Other Renewable Energy: Alternative Electricity and Transportation | C36: AEO.2026.ELECTRNP.CNSM_USE_TEN_NA_PRE_NA_USA_QBTU.A | D36: quads | E36: 2.880712 | F36: 3.166233 | G36: 3.747644 | H36: 4.126372 | I36: 4.342162 | J36: 4.504683 | K36: 4.661613 | L36: 4.761504 | M36: 4.886238 | N36: 5.063766 | O36: 5.264389 | P36: 5.470821 | Q36: 5.615872 | R36: 5.739579 | S36: 5.866665 | T36: 5.986307 | U36: 6.091763 | V36: 6.138132 | W36: 6.158761 | X36: 6.175585 | Y36: 6.190252 | Z36: 6.209311 | AA36: 6.233634 | AB36: 6.247483 | AC36: 6.276224 | AD36: 6.308211 | AE36: 0.032
A37: Other | B37: Total Energy: Use: Other: Alternative Electricity and Transportation | C37: AEO.2026.ELECTRNP.CNSM_USE_TEN_NA_OTH_NA_USA_QBTU.A | D37: quads | E37: 0.424569 | F37: 0.453636 | G37: 0.546819 | H37: 0.585096 | I37: 0.60074 | J37: 0.625341 | K37: 0.632063 | L37: 0.637733 | M37: 0.649799 | N37: 0.65537 | O37: 0.664124 | P37: 0.658336 | Q37: 0.657547 | R37: 0.659404 | S37: 0.659049 | T37: 0.664997 | U37: 0.668879 | V37: 0.659788 | W37: 0.652483 | X37: 0.650791 | Y37: 0.65276 | Z37: 0.641367 | AA37: 0.636121 | AB37: 0.630691 | AC37: 0.62323 | AD37: 0.617439 | AE37: 0.015
A38: Total | B38: Total Energy: Use: Total: Alternative Electricity and Transportation | C38: AEO.2026.ELECTRNP.CNSM_USE_TEN_NA_TOT_NA_USA_QBTU.A | D38: quads | E38: 95.289612 | F38: 95.626015 | G38: 94.18663 | H38: 93.63298 | I38: 93.111832 | J38: 92.846977 | K38: 92.247574 | L38: 92.040756 | M38: 91.940758 | N38: 91.946739 | O38: 92.008194 | P38: 92.049538 | Q38: 92.183212 | R38: 92.392555 | S38: 92.613068 | T38: 92.836052 | U38: 93.042862 | V38: 93.356567 | W38: 93.704887 | X38: 94.045372 | Y38: 94.443687 | Z38: 94.793831 | AA38: 95.235176 | AB38: 95.539604 | AC38: 95.709549 | AD38: 95.988907 | AE38: 0
A39: Prices (2025 dollars per unit)
A40: Brent Spot Price (dollars per barrel) | B40: Total Energy: Real Prices: Brent: Alternative Electricity and Transportation | C40: AEO.2026.ELECTRNP.PRCE_RLP_TEN_NA_BRN_NA_USA_Y13DLRPBBL.A | D40: 2025 $/b | E40: 68.758003 | F40: 53.451851 | G40: 58.008591 | H40: 62.476402 | I40: 65.409325 | J40: 65.158569 | K40: 68.833679 | L40: 69.83049 | M40: 71.635643 | N40: 73.592148 | O40: 74.762581 | P40: 76.158562 | Q40: 78.223351 | R40: 79.690277 | S40: 80.750778 | T40: 81.161491 | U40: 82.013199 | V40: 83.342216 | W40: 84.728607 | X40: 85.865303 | Y40: 87.667793 | Z40: 89.243423 | AA40: 90.481903 | AB40: 91.804817 | AC40: 92.957466 | AD40: 94.122032 | AE40: 0.013
...

Sheet AEO 2026 Table 19
A1: Table 19. Hydrogen Supply, Disposition, and Prices
A2: https://www.eia.gov/outlooks/aeo/data/browser/#/?id=23-AEO2026&cases=electrnp&sourcekey=0
A3: Thu Apr 23 2026 15:00:15 GMT-0700 (Pacific Daylight Time)
A4: Source: U.S. Energy Information Administration
B5: full name | C5: api key | D5: units | E5: 2025 | F5: 2026 | G5: 2027 | H5: 2028 | I5: 2029 | J5: 2030 | K5: 2031 | L5: 2032 | M5: 2033 | N5: 2034 | O5: 2035 | P5: 2036 | Q5: 2037 | R5: 2038 | S5: 2039 | T5: 2040 | U5: 2041 | V5: 2042 | W5: 2043 | X5: 2044 | Y5: 2045 | Z5: 2046 | AA5: 2047 | AB5: 2048 | AC5: 2049 | AD5: 2050 | AE5: Growth (2025-2050)
A6: Supply
A7: Production By Technology
A8: Steam Methane Reforming | B8: Hydrogen Market Projections: Production By Technology: Steam Methane Reforming: Alternative Electricity and Transportation | C8: AEO.2026.ELECTRNP.SUP_PRD_NA_NA_HDG_SMR_USA_MMMT.A | D8: MMmt | E8: 5.659547 | F8: 5.032887 | G8: 4.992723 | H8: 5.019737 | I8: 4.898739 | J8: 4.879333 | K8: 4.789099 | L8: 4.76969 | M8: 4.790712 | N8: 4.936659 | O8: 4.982401 | P8: 5.015864 | Q8: 5.455601 | R8: 5.675931 | S8: 5.713116 | T8: 5.70251 | U8: 5.952733 | V8: 5.961066 | W8: 6.009364 | X8: 6.154692 | Y8: 6.243866 | Z8: 6.274028 | AA8: 6.329513 | AB8: 6.35868 | AC8: 6.383008 | AD8: 6.407354 | AE8: 0.005
A9: Steam Methane Reforming with CCS | B9: Hydrogen Market Projections: Production By Technology: Steam Methane Reforming with CCS: Alternative Electricity and Transportation | C9: AEO.2026.ELECTRNP.SUP_PRD_NA_NA_HDG_SMRCCS_USA_MMMT.A | D9: MMmt | E9: 0.334852 | F9: 0.334852 | G9: 0.334852 | H9: 0.334852 | I9: 0.334852 | J9: 0.334852 | K9: 0.334852 | L9: 0.334852 | M9: 0.334852 | N9: 0.334852 | O9: 0.334852 | P9: 0.304762 | Q9: 0 | R9: 0 | S9: 0 | T9: 0 | U9: 0 | V9: 0 | W9: 0 | X9: 0 | Y9: 0 | Z9: 0 | AA9: 0 | AB9: 0 | AC9: 0 | AD9: 0 | AE9: -1
A10: Autothermal Reforming with CCS | B10: Hydrogen Market Projections: Production By Technology: Autothermal Reforming with CCS: Alternative Electricity and Transportation | C10: AEO.2026.ELECTRNP.SUP_PRD_NA_NA_HDG_ATRCCS_USA_MMMT.A | D10: MMmt | E10: 0 | F10: 0.170512 | G10: 0.170512 | H10: 0.170512 | I10: 0.401204 | J10: 0.401204 | K10: 0.401204 | L10: 0.401204 | M10: 0.401204 | N10: 0.401204 | O10: 0.401204 | P10: 0.401204 | Q10: 0.401204 | R10: 0.230692 | S10: 0.230692 | T10: 0.230692 | U10: 0 | V10: 0 | W10: 0 | X10: 0 | Y10: 0 | Z10: 0 | AA10: 0 | AB10: 0 | AC10: 0 | AD10: 0 | AE10: - -
A11: Electrolysis | B11: Hydrogen Market Projections: Production By Technology: Electrolysis: Alternative Electricity and Transportation | C11: AEO.2026.ELECTRNP.SUP_PRD_NA_NA_HDG_GRDELEC_USA_MMMT.A | D11: MMmt | E11: 4.2e-05 | F11: 0.01439 | G11: 0.016392 | H11: 0.009311 | I11: 0.0081 | J11: 0.010323 | K11: 0.004869 | L11: 0.001615 | M11: 0.00146 | N11: 0.001759 | O11: 0.002048 | P11: 0 | Q11: 0 | R11: 0 | S11: 0 | T11: 0 | U11: 0 | V11: 0 | W11: 0 | X11: 0 | Y11: 0 | Z11: 0 | AA11: 0 | AB11: 0 | AC11: 0 | AD11: 0 | AE11: -1
A12: Byproduct Hydrogen Supply to Market | B12: Hydrogen Market Projections: Byproduct hydrogen supply to market: Alternative Electricity and Transportation | C12: AEO.2026.ELECTRNP.SUP_PRD_NA_NA_HDG_BYPROD_USA_MMMT.A | D12: MMmt | E12: 2.02554 | F12: 2.063889 | G12: 2.087271 | H12: 2.077101 | I12: 2.043689 | J12: 2.044156 | K12: 2.0521 | L12: 2.054974 | M12: 2.070796 | N12: 2.080865 | O12: 2.10896 | P12: 2.128429 | Q12: 2.133964 | R12: 2.157028 | S12: 2.179477 | T12: 2.199941 | U12: 2.230414 | V12: 2.258515 | W12: 2.286566 | X12: 2.307555 | Y12: 2.330795 | Z12: 2.360232 | AA12: 2.391338 | AB12: 2.418861 | AC12: 2.438444 | AD12: 2.464948 | AE12: 0.008
A13: Total Hydrogen Supply | B13: Hydrogen Market Projections: Total Hydrogen Supply: Alternative Electricity and Transportation | C13: AEO.2026.ELECTRNP.SUP_NA_NA_NA_HDG_TOT_USA_MMMT.A | D13: MMmt | E13: 8.019981 | F13: 7.61653 | G13: 7.601751 | H13: 7.611512 | I13: 7.686584 | J13: 7.669868 | K13: 7.582125 | L13: 7.562335 | M13: 7.599025 | N13: 7.75534 | O13: 7.829465 | P13: 7.850259 | Q13: 7.990769 | R13: 8.063651 | S13: 8.123285 | T13: 8.133142 | U13: 8.183146 | V13: 8.219581 | W13: 8.295929 | X13: 8.462247 | Y13: 8.574661 | Z13: 8.63426 | AA13: 8.720851 | AB13: 8.777541 | AC13: 8.821452 | AD13: 8.872303 | AE13: 0.004
A14: Consumption | B14: Hydrogen Market Projections: Total Hydrogen Consumption: Alternative Electricity and Transportation | C14: AEO.2026.ELECTRNP.CNSM_NA_NA_NA_HDG_TOT_USA_MMMT.A | D14: MMmt | E14: 8.012987 | F14: 7.607544 | G14: 7.591349 | H14: 7.601383 | I14: 7.675807 | J14: 7.659146 | K14: 7.571351 | L14: 7.551171 | M14: 7.587768 | N14: 7.744197 | O14: 7.818182 | P14: 7.839029 | Q14: 7.979493 | R14: 8.052443 | S14: 8.111986 | T14: 8.121541 | U14: 8.17167 | V14: 8.208235 | W14: 8.284301 | X14: 8.450414 | Y14: 8.562716 | Z14: 8.622116 | AA14: 8.708749 | AB14: 8.765518 | AC14: 8.809484 | AD14: 8.860441 | AE14: 0.004
A15: Industrial feedstock | B15: Hydrogen Market Projections: Consumption: Industrial feedstocks: Alternative Electricity and Transportation | C15: AEO.2026.ELECTRNP.CNSM_NA_NA_NA_HDG_INDF_USA_MMMT.A | D15: MMmt | E15: 8.009887 | F15: 7.604562 | G15: 7.588504 | H15: 7.598682 | I15: 7.673244 | J15: 7.656733 | K15: 7.569081 | L15: 7.549054 | M15: 7.5858 | N15: 7.742378 | O15: 7.81651 | P15: 7.837502 | Q15: 7.978107 | R15: 8.051191 | S15: 8.110865 | T15: 8.120539 | U15: 8.17078 | V15: 8.207437 | W15: 8.283582 | X15: 8.449756 | Y15: 8.562127 | Z15: 8.621575 | AA15: 8.708242 | AB15: 8.765047 | AC15: 8.809 | AD15: 8.859974 | AE15: 0.004
A16: Bulk Chemicals | B16: Hydrogen Market Projections: Consumption: Industrial feedstocks: Bulk chemicals: Alternative Electricity and Transportation | C16: AEO.2026.ELECTRNP.CNSM_NA_NA_NA_HDG_BC_USA_MMMT.A | D16: MMmt | E16: 4.312861 | F16: 4.257381 | G16: 4.269811 | H16: 4.242913 | I16: 4.220734 | J16: 4.243922 | K16: 4.277688 | L16: 4.290828 | M16: 4.312197 | N16: 4.334578 | O16: 4.366941 | P16: 4.409552 | Q16: 4.452061 | R16: 4.493399 | S16: 4.538706 | T16: 4.588114 | U16: 4.642948 | V16: 4.702968 | W16: 4.755772 | X16: 4.803819 | Y16: 4.870983 | Z16: 4.935818 | AA16: 5.008786 | AB16: 5.07222 | AC16: 5.118502 | AD16: 5.178623 | AE16: 0.007
A17: Refinery | B17: Hydrogen Market Projections: Consumption: Industrial feedstocks: Refinery: Alternative Electricity and Transportation | C17: AEO.2026.ELECTRNP.CNSM_NA_NA_NA_HDG_REF_USA_MMMT.A | D17: MMmt | E17: 3.696665 | F17: 3.346764 | G17: 3.318238 | H17: 3.355242 | I17: 3.451893 | J17: 3.412094 | K17: 3.29056 | L17: 3.257257 | M17: 3.272487 | N17: 3.40652 | O17: 3.448085 | P17: 3.426255 | Q17: 3.524112 | R17: 3.5556 | S17: 3.56969 | T17: 3.529653 | U17: 3.524729 | V17: 3.501023 | W17: 3.523996 | X17: 3.641738 | Y17: 3.686538 | Z17: 3.680712 | AA17: 3.693948 | AB17: 3.686834 | AC17: 3.683995 | AD17: 3.674316 | AE17: 0
A18: Other Industrial | B18: Hydrogen Market Projections: Consumption: Industrial feedstocks: Other industrial: Alternative Electricity and Transportation | C18: AEO.2026.ELECTRNP.CNSM_NA_NA_NA_HDG_OTHIND_USA_MMMT.A | D18: MMmt | E18: 0.000361 | F18: 0.000417 | G18: 0.000455 | H18: 0.000528 | I18: 0.000617 | J18: 0.000717 | K18: 0.000833 | L18: 0.00097 | M18: 0.001116 | N18: 0.00128 | O18: 0.001483 | P18: 0.001695 | Q18: 0.001934 | R18: 0.002192 | S18: 0.002469 | T18: 0.002772 | U18: 0.003103 | V18: 0.003445 | W18: 0.003814 | X18: 0.004199 | Y18: 0.004606 | Z18: 0.005045 | AA18: 0.005508 | AB18: 0.005993 | AC18: 0.006503 | AD18: 0.007035 | AE18: 0.126
