Workbook

Sheet About
A1: SoBCaICbIC Share of Buildings Capital and Installation Costs by ISIC Code
A3: Sources: | B3: Building Sector Appliance and Equipment Costs and Efficiencies
B4: EIA
B5: 2018
B6: "Updated Buildings Sector Appliance and Equipment Costs and Efficiencies"
B7: https://www.eia.gov/analysis/studies/buildings/equipcosts/pdf/full.pdf
B10: Commercial Equipment Prevalence
B11: EIA
B12: 2016
B13: Table B39. Heating equipment, floorspace & Table42. Water-heating equipment, number of buildings and floorspace
B14: https://www.eia.gov/consumption/commercial/data/2012/#b38-b46
B17: Residential Equipment Prevelance
B18: U.S. Energy Information Administration
B19: 2026
B20: Annual Energy Outlook 2026
B21: Alternative electricity and transportation: Table 21
B22: https://www.eia.gov/outlooks/aeo/tables_side_xls.php
B25: ISIC Code Mapping
B26: United Nations
B27: 2008
B28: International Standard Industrial Classification of All Economic Activities Revision 4
B29: https://unstats.un.org/unsd/publication/seriesM/seriesm_4rev4e.pdf
B31: Markups on equipment (manufacturer, freight, wholesale and retail)
B32: U.S. Bureau of Economic Analysis
B33: 2017
B34: Margins, Before Redefinitions, Detail (input-output accounts), sheet "2017"
B35: https://apps.bea.gov/industry/release/xlsx/Margins_Before_Redefinitions_Detail.xlsx
B36: Rows for the nine equipment commodities used here are on the "BEA 2017 Margins" tab. Accessed October 2026.
A39: Notes:
A40: Note from "Updated Building Sector Appliance and Equipment Costs and Efficiencies."
A41: The Energy Independence and Security Act of 2007 prescribes standards for current 100 watt incandescent lamps
A42: as of January 1, 2012. Starting in 2012, 100-watt incandescent lamps will be replaced by halogen lamps.
A44: For commercial lighting - estimated cost averages based on selected commercial light fixtures assumed to be most common
A46: Cost averages from NEMS are across appliance type and years (2012-2050)
A48: Water heating, refrigeration, clothes washing/drying, cooking, and diswashing equipment are all assigned to appliances
A50: Other equipment includes primarily additional plug load equipment including computers and televisions
A52: 52-code expansion (2026-07-17):
A53: The output tabs produce the 52-code ISIC list. The derivation above is unchanged and live; output-tab formulas reference the derivation tabs
A54: directly, with the original header-label criteria written as literals (the derivation tabs still use the pre-split 42-code labels).
A56: Children of split parents multiply the parent's allocation by the factors on the 'Factors applied' tab (editable; defaults = BEA 2024 gross-
...

Sheet Factors applied
A1: Child factors applied inline in the output-tab formulas (editable). Defaults = BEA 2024 output shares; semantic overrides and fuel reroutes noted per row.
A2: File | B2: Row context | C2: Child | D2: Parent | E2: Factor | F2: Rationale | G2: BEA 2024 output share
A3: SoBCaICbIC-commercial.csv | B3: Appliances | C3: ISIC 01 | D3: ISIC 01T03 | E3: 0.94299868 | F3: BEA 2024 output share (default) | G3: 0.94299868
A4: SoBCaICbIC-commercial.csv | B4: Appliances | C4: ISIC 02 | D4: ISIC 01T03 | E4: 0.041765731 | F4: BEA 2024 output share (default) | G4: 0.041765731
A5: SoBCaICbIC-commercial.csv | B5: Appliances | C5: ISIC 03 | D5: ISIC 01T03 | E5: 0.015235586 | F5: BEA 2024 output share (default) | G5: 0.015235586
A6: SoBCaICbIC-commercial.csv | B6: Appliances | C6: ISIC 07 | D6: ISIC 07T08 | E6: 0.43273688 | F6: BEA 2024 output share (default) | G6: 0.43273688
A7: SoBCaICbIC-commercial.csv | B7: Appliances | C7: ISIC 08 | D7: ISIC 07T08 | E7: 0.56726312 | F7: BEA 2024 output share (default) | G7: 0.56726312
A8: SoBCaICbIC-commercial.csv | B8: Appliances | C8: ISIC 301 | D8: ISIC 30 | E8: 0.11713687 | F8: BEA 2024 output share (default) | G8: 0.11713687
A9: SoBCaICbIC-commercial.csv | B9: Appliances | C9: ISIC 302T309 | D9: ISIC 30 | E9: 0.88286313 | F9: BEA 2024 output share (default) | G9: 0.88286313
A10: SoBCaICbIC-commercial.csv | B10: Appliances | C10: ISIC 49 | D10: ISIC 49T53 | E10: 0.45630816 | F10: BEA 2024 output share (default) | G10: 0.45630816
A11: SoBCaICbIC-commercial.csv | B11: Appliances | C11: ISIC 50 | D11: ISIC 49T53 | E11: 0.044370048 | F11: BEA 2024 output share (default) | G11: 0.044370048
A12: SoBCaICbIC-commercial.csv | B12: Appliances | C12: ISIC 51 | D12: ISIC 49T53 | E12: 0.18837505 | F12: BEA 2024 output share (default) | G12: 0.18837505
A13: SoBCaICbIC-commercial.csv | B13: Appliances | C13: ISIC 52 | D13: ISIC 49T53 | E13: 0.22286512 | F13: BEA 2024 output share (default) | G13: 0.22286512
A14: SoBCaICbIC-commercial.csv | B14: Appliances | C14: ISIC 53 | D14: ISIC 49T53 | E14: 0.088081621 | F14: BEA 2024 output share (default) | G14: 0.088081621
... A290: SoBCaICbIC-urbanresidential.csv | B290: Other | C290: ISIC 94T96 | D290: ISIC 90T96 | E290: 0.57837505 | F290: BEA 2024 output share (default) | G290: 0.57837505

Sheet source data>

Sheet OECD Mapping
A1: OECD Code | B1: ISIC Code
A2: D01T03: Agriculture, forestry and fishing | B2: ISIC 01T03
A3: D05: Coal mining | B3: ISIC 05
A4: D06: Oil and gas extraction | B4: ISIC 06
A5: D07T08: Mining and quarrying of non-energy producing products | B5: ISIC 07T08
A6: D09: Mining support service activities | B6: ISIC 09
A7: D10T12: Food products, beverages and tobacco | B7: ISIC 10T12
A8: D13T15: Textiles, wearing apparel, leather and related products | B8: ISIC 13T15
A9: D16: Wood and products of wood and cork | B9: ISIC 16
A10: D17T18: Paper products and printing | B10: ISIC 17T18
A11: D19: Coke and refined petroleum products | B11: ISIC 19
A12: D20: Chemicals | B12: ISIC 20
... A43: D97T98: Private households with employed persons | B43: ISIC 97T98

Sheet ISIC Code Mapping
B1: Heating | C1: Cooling | D1: Envelope | E1: Lighting | F1: Appliances | G1: Other
A2: Equipment | B2: ='OECD Mapping'!B22 -> ISIC 28 | C2: ='OECD Mapping'!B22 -> ISIC 28 | D2: ='OECD Mapping'!B29 -> ISIC 41T43 | E2: ='OECD Mapping'!B21 -> ISIC 27 | F2: ='OECD Mapping'!B21 -> ISIC 27 | G2: ='OECD Mapping'!B21 -> ISIC 27
A3: Installation | B3: ='OECD Mapping'!B29 -> ISIC 41T43 | C3: ='OECD Mapping'!B29 -> ISIC 41T43 | D3: ='OECD Mapping'!B29 -> ISIC 41T43 | E3: ='OECD Mapping'!B29 -> ISIC 41T43 | F3: ='OECD Mapping'!B29 -> ISIC 41T43 | G3: ='OECD Mapping'!B29 -> ISIC 41T43

Sheet Cost Summary New
A1: Costs of Residential Equipment - Weighted Calculation
B3: Equipment Type - Name from RECS | C3: Percent Equipment Costs (Copied from NEMS spreadsheet) | D3: Percent of Total Appliances w/ Cost Data | E3: Weighted Percent Equipment Cost | F3: Weighted Percent Labor Cost | H3: Source | I3: Calculations
A4: Main Space Heaters | D4: =SUM(D5:D13) -> 1 | E4: =SUM(E5:E13) -> 0.55028127 | F4: =1-E4 -> 0.44971873 | H4: https://www.eia.gov/analysis/studies/buildings/equipcosts/pdf/full.pdf | I4: "NEMS cost data_new"
A5: Main Space Heaters | B5: Electric Heat Pumps | C5: 0.74328168 | D5: ='Summary_Res Appliances'!G6 -> 0.15713894 | E5: =D5*C5 -> 0.11679849 | H5: https://www.eia.gov/analysis/studies/buildings/equipcosts/pdf/full.pdf | I5: "NEMS cost data_new"
A6: Main Space Heaters | B6: Electric Other | C6: 0.59090909 | D6: ='Summary_Res Appliances'!G7 -> 0.24672282 | E6: =D6*C6 -> 0.14579076 | H6: https://www.eia.gov/analysis/studies/buildings/equipcosts/pdf/full.pdf | I6: "NEMS cost data_new"
A7: Main Space Heaters | B7: Natural Gas Heat Pumps | D7: ='Summary_Res Appliances'!G8 -> 0 | E7: =D7*C7 -> 0 | H7: https://www.eia.gov/analysis/studies/buildings/equipcosts/pdf/full.pdf | I7: "NEMS cost data_new"
A8: Main Space Heaters | B8: Natural Gas Other | C8: 0.48259279 | D8: ='Summary_Res Appliances'!G9 -> 0.59613825 | E8: =D8*C8 -> 0.28769202 | H8: https://www.eia.gov/analysis/studies/buildings/equipcosts/pdf/full.pdf | I8: "NEMS cost data_new"
A9: Main Space Heaters | B9: Distillate Fuel Oil | D9: ='Summary_Res Appliances'!G10 -> 0 | E9: =D9*C9 -> 0 | H9: https://www.eia.gov/analysis/studies/buildings/equipcosts/pdf/full.pdf | I9: "NEMS cost data_new"
A10: Main Space Heaters | B10: Propane | D10: ='Summary_Res Appliances'!G11 -> 0 | E10: =D10*C10 -> 0 | H10: https://www.eia.gov/analysis/studies/buildings/equipcosts/pdf/full.pdf | I10: "NEMS cost data_new"
A11: Main Space Heaters | B11: Kerosene | D11: ='Summary_Res Appliances'!G12 -> 0 | E11: =D11*C11 -> 0 | H11: https://www.eia.gov/analysis/studies/buildings/equipcosts/pdf/full.pdf | I11: "NEMS cost data_new"
A12: Main Space Heaters | B12: Wood Stoves | D12: ='Summary_Res Appliances'!G13 -> 0 | E12: =D12*C12 -> 0 | H12: https://www.eia.gov/analysis/studies/buildings/equipcosts/pdf/full.pdf | I12: "NEMS cost data_new"
A13: Main Space Heaters | B13: Geothermal Heat Pumps | D13: ='Summary_Res Appliances'!G14 -> 0 | E13: =D13*C13 -> 0 | H13: https://www.eia.gov/analysis/studies/buildings/equipcosts/pdf/full.pdf | I13: "NEMS cost data_new"
A14: Space Cooling | D14: =SUM(D15:D19) -> 1 | E14: =SUM(E15:E19) -> 0.73624569 | F14: =1-E14 -> 0.26375431 | H14: https://www.eia.gov/analysis/studies/buildings/equipcosts/pdf/full.pdf | I14: "NEMS cost data_new"
A15: Space Cooling | B15: Electric Heat Pumps | C15: 0.74328168 | D15: ='Summary_Res Appliances'!G17 -> 0.12261684 | E15: =D15*C15 -> 0.091138851 | H15: https://www.eia.gov/analysis/studies/buildings/equipcosts/pdf/full.pdf | I15: "NEMS cost data_new"
A16: Space Cooling | B16: Natural Gas Heat Pumps | D16: ='Summary_Res Appliances'!G18 -> 0 | E16: =D16*C16 -> 0 | H16: https://www.eia.gov/analysis/studies/buildings/equipcosts/pdf/full.pdf | I16: "NEMS cost data_new"
A17: Space Cooling | B17: Geothermal Heat Pumps | D17: ='Summary_Res Appliances'!G19 -> 0 | E17: =D17*C17 -> 0 | H17: https://www.eia.gov/analysis/studies/buildings/equipcosts/pdf/full.pdf | I17: "NEMS cost data_new"
A18: Space Cooling | B18: Central Air Conditioners | C18: 0.66273252 | D18: ='Summary_Res Appliances'!G20 -> 0.57118911 | E18: =D18*C18 -> 0.3785456 | H18: https://www.eia.gov/analysis/studies/buildings/equipcosts/pdf/full.pdf | I18: "NEMS cost data_new"
A19: Space Cooling | B19: Room Air Conditioners | C19: 0.87056309 | D19: ='Summary_Res Appliances'!G21 -> 0.30619405 | E19: =D19*C19 -> 0.26656124 | H19: https://www.eia.gov/analysis/studies/buildings/equipcosts/pdf/full.pdf | I19: "NEMS cost data_new"
A20: Water Heaters | E20: =SUM(E21:E25) -> 0.55741274 | F20: =1-E20 -> 0.44258726 | H20: https://www.eia.gov/analysis/studies/buildings/equipcosts/pdf/full.pdf | I20: "NEMS cost data_new"
A21: Water Heaters | B21: Electric | C21: 0.56212605 | D21: ='Summary_Res Appliances'!G24 -> 0.48965433 | E21: =D21*C21 -> 0.27524746 | H21: https://www.eia.gov/analysis/studies/buildings/equipcosts/pdf/full.pdf | I21: "NEMS cost data_new"
A22: Water Heaters | B22: Natural Gas | C22: 0.55289052 | D22: ='Summary_Res Appliances'!G25 -> 0.51034567 | E22: =D22*C22 -> 0.28216528 | H22: https://www.eia.gov/analysis/studies/buildings/equipcosts/pdf/full.pdf | I22: "NEMS cost data_new"
A23: Water Heaters | B23: Distillate Fuel Oil | D23: ='Summary_Res Appliances'!G26 -> 0 | E23: =D23*C23 -> 0 | H23: https://www.eia.gov/analysis/studies/buildings/equipcosts/pdf/full.pdf | I23: "NEMS cost data_new"
A24: Water Heaters | B24: Propane | D24: ='Summary_Res Appliances'!G27 -> 0 | E24: =D24*C24 -> 0 | H24: https://www.eia.gov/analysis/studies/buildings/equipcosts/pdf/full.pdf | I24: "NEMS cost data_new"
A25: Water Heaters | B25: Solar Thermal | D25: ='Summary_Res Appliances'!G28 -> 0 | E25: =D25*C25 -> 0 | H25: https://www.eia.gov/analysis/studies/buildings/equipcosts/pdf/full.pdf | I25: "NEMS cost data_new"
A26: Cooking Equipment | E26: =SUM(E27:E30) -> 0.83324329 | F26: =1-E26 -> 0.16675671 | H26: https://www.eia.gov/analysis/studies/buildings/equipcosts/pdf/full.pdf | I26: "NEMS cost data_new"
A27: Cooking Equipment | B27: Electric | D27: ='Summary_Res Appliances'!G31 -> 0 | E27: =D27*C27 -> 0 | H27: https://www.eia.gov/analysis/studies/buildings/equipcosts/pdf/full.pdf | I27: "NEMS cost data_new"
A28: Cooking Equipment | B28: Natural Gas | C28: 0.83324329 | D28: ='Summary_Res Appliances'!G32 -> 1 | E28: =D28*C28 -> 0.83324329 | H28: https://www.eia.gov/analysis/studies/buildings/equipcosts/pdf/full.pdf | I28: "NEMS cost data_new"
A29: Cooking Equipment | B29: Natural Gas | C29: 0.70132633 | D29: ='Summary_Res Appliances'!G33 -> 0 | E29: =D29*C29 -> 0 | H29: https://www.eia.gov/analysis/studies/buildings/equipcosts/pdf/full.pdf | I29: "NEMS cost data_new"
A30: Cooking Equipment | B30: Propane | D30: ='Summary_Res Appliances'!G34 -> 0 | E30: =D30*C30 -> 0 | H30: https://www.eia.gov/analysis/studies/buildings/equipcosts/pdf/full.pdf | I30: "NEMS cost data_new"
A31: Clothes Dryers | E31: =SUM(E32:E33) -> 0.8046221 | F31: =1-E31 -> 0.1953779 | H31: https://www.eia.gov/analysis/studies/buildings/equipcosts/pdf/full.pdf | I31: "NEMS cost data_new"
A32: Clothes Dryers | B32: Electric | C32: 0.81320282 | D32: ='Summary_Res Appliances'!G36 -> 0.82299211 | E32: =D32*C32 -> 0.6692595 | H32: https://www.eia.gov/analysis/studies/buildings/equipcosts/pdf/full.pdf | I32: "NEMS cost data_new"
A33: Clothes Dryers | B33: Natural Gas | C33: 0.76472644 | D33: ='Summary_Res Appliances'!G37 -> 0.17700787 | E33: =D33*C33 -> 0.1353626 | H33: https://www.eia.gov/analysis/studies/buildings/equipcosts/pdf/full.pdf | I33: "NEMS cost data_new"
A34: Other Appliances | E34: =AVERAGE(C35:C38) -> 0.82212755 | F34: =1-E34 -> 0.17787245
A35: Appliances | C35: 1 | H35: https://www.eia.gov/analysis/studies/buildings/equipcosts/pdf/full.pdf | I35: "NEMS cost data_new"
A36: Appliances | C36: 0.6516356 | H36: https://www.eia.gov/analysis/studies/buildings/equipcosts/pdf/full.pdf | I36: "NEMS cost data_new"
A37: Appliances | C37: 0.81848666 | H37: https://www.eia.gov/analysis/studies/buildings/equipcosts/pdf/full.pdf | I37: "NEMS cost data_new"
A38: Appliances | C38: 0.81838794 | H38: https://www.eia.gov/analysis/studies/buildings/equipcosts/pdf/full.pdf | I38: "NEMS cost data_new"
A39: Lighting | C39: 1 | E39: =C39 -> 1 | F39: =1-E39 -> 0 | H39: https://www.eia.gov/analysis/studies/buildings/equipcosts/pdf/full.pdf | I39: "NEMS cost data_new"
A41: Appliances - Average total | E41: =AVERAGE(E31,E34,E26,E20) -> 0.75435142 | F41: =1-E41 -> 0.24564858
A43: Costs of Commercial Equipment - Weighted Calculation
...

Sheet COM_NEMS Cost
A1: Hard Copied from: "Summary Commercial" tab on "NEMS cost data new.xlsx"
C3: Equipment Type | D3: Percent Equipment Costs
B4: Commercial Heating | C4: Commercial Gas Fired Furnaces | D4: 0.5405477
B5: Commercial Heating | C5: Commercial Oil-Fired Furnaces | D5: 0.71607519
B6: Commercial Heating | C6: Commercial Electric Resistance Heaters | D6: 0.82799025
B7: Commercial Heating | C7: Commercial Electric Boilers | D7: 0.80922582
B8: Commercial Heating | C8: Commercial Gas Fired Boilers | D8: 0.73560375
B9: Commercial Heating | C9: Commercial Oil-Fired Boilers | D9: 0.77352719
B10: Commercial Cooling | C10: Commercial Rooftop Air Conditioners | D10: 0.70929577
B11: Commercial Cooling | C11: Commercial Rooftop Heat Pumps | D11: 0.72239286
B12: Commercial Cooling | C12: Commercial Ground Source Heat Pumps | D12: 0.30780169
B13: Commercial Water Heating | C13: Commercial Gas-Fired Storage Water Heaters | D13: 0.74018277
B14: Commercial Water Heating | C14: Commercial Electric Resistance Storage Water Heaters | D14: 0.76129032
B15: Commercial Water Heating | C15: Commercial Heat Pump Water Heaters | D15: 0.92443572
... B19: Commercial Lighting | C19: Commercial Lighting - Halogen | D19: 0.26190847

Sheet calcs>

Sheet Summary_Com Appliances
A1: Commercial Appliance Prevalance
A2: Fuel | B2: Heating Equipment | C2: Total Floorspace (million square feet) | D2: Percent of Total Appliances | E2: Percent of Total Appliances w/ Cost Data | I2: Source
A3: Electricity | E3: =SUM(C4:C10)/E43 -> 0.34719121
A4: Electricity | B4: Heat pumps | C4: =IFERROR(INDEX(TableB39!$E$154:$K$159,MATCH('Summary_Com Appliances'!$A4,TableB39!$B$154:$B$159,0),MATCH('Summary_Com Appliances'!$B4,TableB39!$E$5:$K$5,0)),"") -> 7215 | D4: =IFERROR(C4/$D$43,"") -> 0.06080859 | I4: =About!$B$14 -> https://www.eia.gov/consumption/commercial/data/2012/#b38-b46
A5: Electricity | B5: Furnaces | C5: =IFERROR(INDEX(TableB39!$E$154:$K$159,MATCH('Summary_Com Appliances'!$A5,TableB39!$B$154:$B$159,0),MATCH('Summary_Com Appliances'!$B5,TableB39!$E$5:$K$5,0)),"") -> 2270 | D5: =IFERROR(C5/$D$43,"") -> 0.019131739 | I5: =About!$B$14 -> https://www.eia.gov/consumption/commercial/data/2012/#b38-b46
A6: Electricity | B6: Indiv- idual space heaters | C6: =IFERROR(INDEX(TableB39!$E$154:$K$159,MATCH('Summary_Com Appliances'!$A6,TableB39!$B$154:$B$159,0),MATCH('Summary_Com Appliances'!$B6,TableB39!$E$5:$K$5,0)),"") -> 6035 | D6: =IFERROR(C6/$D$43,"") -> 0.050863457 | I6: =About!$B$14 -> https://www.eia.gov/consumption/commercial/data/2012/#b38-b46
A7: Electricity | B7: District heat | C7: =IFERROR(INDEX(TableB39!$E$154:$K$159,MATCH('Summary_Com Appliances'!$A7,TableB39!$B$154:$B$159,0),MATCH('Summary_Com Appliances'!$B7,TableB39!$E$5:$K$5,0)),"") -> Q | D7: =IFERROR(C7/$D$43,"") | I7: =About!$B$14 -> https://www.eia.gov/consumption/commercial/data/2012/#b38-b46
A8: Electricity | B8: Boilers | C8: =IFERROR(INDEX(TableB39!$E$154:$K$159,MATCH('Summary_Com Appliances'!$A8,TableB39!$B$154:$B$159,0),MATCH('Summary_Com Appliances'!$B8,TableB39!$E$5:$K$5,0)),"") -> 2982 | D8: =IFERROR(C8/$D$43,"") -> 0.025132532 | I8: =About!$B$14 -> https://www.eia.gov/consumption/commercial/data/2012/#b38-b46
A9: Electricity | B9: Pack- aged heating units | C9: =IFERROR(INDEX(TableB39!$E$154:$K$159,MATCH('Summary_Com Appliances'!$A9,TableB39!$B$154:$B$159,0),MATCH('Summary_Com Appliances'!$B9,TableB39!$E$5:$K$5,0)),"") -> 18523 | D9: =IFERROR(C9/$D$43,"") -> 0.15611331 | I9: =About!$B$14 -> https://www.eia.gov/consumption/commercial/data/2012/#b38-b46
A10: Electricity | B10: Other | C10: =IFERROR(INDEX(TableB39!$E$154:$K$159,MATCH('Summary_Com Appliances'!$A10,TableB39!$B$154:$B$159,0),MATCH('Summary_Com Appliances'!$B10,TableB39!$E$5:$K$5,0)),"") -> 447 | D10: =IFERROR(C10/$D$43,"") -> 0.0037673513 | I10: =About!$B$14 -> https://www.eia.gov/consumption/commercial/data/2012/#b38-b46
A11: Natural gas | C11: =IFERROR(INDEX(TableB39!$E$154:$K$159,MATCH('Summary_Com Appliances'!$A11,TableB39!$B$154:$B$159,0),MATCH('Summary_Com Appliances'!$B11,TableB39!$E$5:$K$5,0)),"") | D11: =IFERROR(C11/$D$43,"") | E11: =SUM(C12:C18)/E43 -> 0.62252036 | I11: =About!$B$14 -> https://www.eia.gov/consumption/commercial/data/2012/#b38-b46
A12: Natural gas | B12: Heat pumps | C12: =IFERROR(INDEX(TableB39!$E$154:$K$159,MATCH('Summary_Com Appliances'!$A12,TableB39!$B$154:$B$159,0),MATCH('Summary_Com Appliances'!$B12,TableB39!$E$5:$K$5,0)),"") -> 3792 | D12: =IFERROR(C12/$D$43,"") -> 0.031959276 | I12: =About!$B$14 -> https://www.eia.gov/consumption/commercial/data/2012/#b38-b46
A13: Natural gas | B13: Furnaces | C13: =IFERROR(INDEX(TableB39!$E$154:$K$159,MATCH('Summary_Com Appliances'!$A13,TableB39!$B$154:$B$159,0),MATCH('Summary_Com Appliances'!$B13,TableB39!$E$5:$K$5,0)),"") -> 5778 | D13: =IFERROR(C13/$D$43,"") -> 0.04869744 | I13: =About!$B$14 -> https://www.eia.gov/consumption/commercial/data/2012/#b38-b46
A14: Natural gas | B14: Indiv- idual space heaters | C14: =IFERROR(INDEX(TableB39!$E$154:$K$159,MATCH('Summary_Com Appliances'!$A14,TableB39!$B$154:$B$159,0),MATCH('Summary_Com Appliances'!$B14,TableB39!$E$5:$K$5,0)),"") -> 11482 | D14: =IFERROR(C14/$D$43,"") -> 0.096771203 | I14: =About!$B$14 -> https://www.eia.gov/consumption/commercial/data/2012/#b38-b46
A15: Natural gas | B15: District heat | C15: =IFERROR(INDEX(TableB39!$E$154:$K$159,MATCH('Summary_Com Appliances'!$A15,TableB39!$B$154:$B$159,0),MATCH('Summary_Com Appliances'!$B15,TableB39!$E$5:$K$5,0)),"") -> Q | D15: =IFERROR(C15/$D$43,"") | I15: =About!$B$14 -> https://www.eia.gov/consumption/commercial/data/2012/#b38-b46
A16: Natural gas | B16: Boilers | C16: =IFERROR(INDEX(TableB39!$E$154:$K$159,MATCH('Summary_Com Appliances'!$A16,TableB39!$B$154:$B$159,0),MATCH('Summary_Com Appliances'!$B16,TableB39!$E$5:$K$5,0)),"") -> 17437 | D16: =IFERROR(C16/$D$43,"") -> 0.14696041 | I16: =About!$B$14 -> https://www.eia.gov/consumption/commercial/data/2012/#b38-b46
A17: Natural gas | B17: Pack- aged heating units | C17: =IFERROR(INDEX(TableB39!$E$154:$K$159,MATCH('Summary_Com Appliances'!$A17,TableB39!$B$154:$B$159,0),MATCH('Summary_Com Appliances'!$B17,TableB39!$E$5:$K$5,0)),"") -> 27826 | D17: =IFERROR(C17/$D$43,"") -> 0.23451973 | I17: =About!$B$14 -> https://www.eia.gov/consumption/commercial/data/2012/#b38-b46
A18: Natural gas | B18: Other | C18: =IFERROR(INDEX(TableB39!$E$154:$K$159,MATCH('Summary_Com Appliances'!$A18,TableB39!$B$154:$B$159,0),MATCH('Summary_Com Appliances'!$B18,TableB39!$E$5:$K$5,0)),"") -> 873 | D18: =IFERROR(C18/$D$43,"") -> 0.007357713 | I18: =About!$B$14 -> https://www.eia.gov/consumption/commercial/data/2012/#b38-b46
A19: Fuel oil | C19: =IFERROR(INDEX(TableB39!$E$154:$K$159,MATCH('Summary_Com Appliances'!$A19,TableB39!$B$154:$B$159,0),MATCH('Summary_Com Appliances'!$B19,TableB39!$E$5:$K$5,0)),"") | D19: =IFERROR(C19/$D$43,"") | E19: =SUM(C20:C26)/E43 -> 0.03028843 | I19: =About!$B$14 -> https://www.eia.gov/consumption/commercial/data/2012/#b38-b46
A20: Fuel oil | B20: Heat pumps | C20: =IFERROR(INDEX(TableB39!$E$154:$K$159,MATCH('Summary_Com Appliances'!$A20,TableB39!$B$154:$B$159,0),MATCH('Summary_Com Appliances'!$B20,TableB39!$E$5:$K$5,0)),"") -> Q | D20: =IFERROR(C20/$D$43,"") | I20: =About!$B$14 -> https://www.eia.gov/consumption/commercial/data/2012/#b38-b46
A21: Fuel oil | B21: Furnaces | C21: =IFERROR(INDEX(TableB39!$E$154:$K$159,MATCH('Summary_Com Appliances'!$A21,TableB39!$B$154:$B$159,0),MATCH('Summary_Com Appliances'!$B21,TableB39!$E$5:$K$5,0)),"") -> Q | D21: =IFERROR(C21/$D$43,"") | I21: =About!$B$14 -> https://www.eia.gov/consumption/commercial/data/2012/#b38-b46
A22: Fuel oil | B22: Indiv- idual space heaters | C22: =IFERROR(INDEX(TableB39!$E$154:$K$159,MATCH('Summary_Com Appliances'!$A22,TableB39!$B$154:$B$159,0),MATCH('Summary_Com Appliances'!$B22,TableB39!$E$5:$K$5,0)),"") -> 1008 | D22: =IFERROR(C22/$D$43,"") -> 0.0084955036 | I22: =About!$B$14 -> https://www.eia.gov/consumption/commercial/data/2012/#b38-b46
A23: Fuel oil | B23: District heat | C23: =IFERROR(INDEX(TableB39!$E$154:$K$159,MATCH('Summary_Com Appliances'!$A23,TableB39!$B$154:$B$159,0),MATCH('Summary_Com Appliances'!$B23,TableB39!$E$5:$K$5,0)),"") -> Q | D23: =IFERROR(C23/$D$43,"") | I23: =About!$B$14 -> https://www.eia.gov/consumption/commercial/data/2012/#b38-b46
A24: Fuel oil | B24: Boilers | C24: =IFERROR(INDEX(TableB39!$E$154:$K$159,MATCH('Summary_Com Appliances'!$A24,TableB39!$B$154:$B$159,0),MATCH('Summary_Com Appliances'!$B24,TableB39!$E$5:$K$5,0)),"") -> 1504 | D24: =IFERROR(C24/$D$43,"") -> 0.012675831 | I24: =About!$B$14 -> https://www.eia.gov/consumption/commercial/data/2012/#b38-b46
A25: Fuel oil | B25: Pack- aged heating units | C25: =IFERROR(INDEX(TableB39!$E$154:$K$159,MATCH('Summary_Com Appliances'!$A25,TableB39!$B$154:$B$159,0),MATCH('Summary_Com Appliances'!$B25,TableB39!$E$5:$K$5,0)),"") -> 757 | D25: =IFERROR(C25/$D$43,"") -> 0.0063800558 | I25: =About!$B$14 -> https://www.eia.gov/consumption/commercial/data/2012/#b38-b46
A26: Fuel oil | B26: Other | C26: =IFERROR(INDEX(TableB39!$E$154:$K$159,MATCH('Summary_Com Appliances'!$A26,TableB39!$B$154:$B$159,0),MATCH('Summary_Com Appliances'!$B26,TableB39!$E$5:$K$5,0)),"") -> Q | D26: =IFERROR(C26/$D$43,"") | I26: =About!$B$14 -> https://www.eia.gov/consumption/commercial/data/2012/#b38-b46
A27: District heat | C27: =IFERROR(INDEX(TableB39!$E$154:$K$159,MATCH('Summary_Com Appliances'!$A27,TableB39!$B$154:$B$159,0),MATCH('Summary_Com Appliances'!$B27,TableB39!$E$5:$K$5,0)),"") | D27: =IFERROR(C27/$D$43,"") | I27: =About!$B$14 -> https://www.eia.gov/consumption/commercial/data/2012/#b38-b46
A28: District heat | B28: Heat pumps | C28: =IFERROR(INDEX(TableB39!$E$154:$K$159,MATCH('Summary_Com Appliances'!$A28,TableB39!$B$154:$B$159,0),MATCH('Summary_Com Appliances'!$B28,TableB39!$E$5:$K$5,0)),"") -> 464 | D28: =IFERROR(C28/$D$43,"") -> 0.0039106287 | I28: =About!$B$14 -> https://www.eia.gov/consumption/commercial/data/2012/#b38-b46
A29: District heat | B29: Furnaces | C29: =IFERROR(INDEX(TableB39!$E$154:$K$159,MATCH('Summary_Com Appliances'!$A29,TableB39!$B$154:$B$159,0),MATCH('Summary_Com Appliances'!$B29,TableB39!$E$5:$K$5,0)),"") -> Q | D29: =IFERROR(C29/$D$43,"") | I29: =About!$B$14 -> https://www.eia.gov/consumption/commercial/data/2012/#b38-b46
A30: District heat | B30: Indiv- idual space heaters | C30: =IFERROR(INDEX(TableB39!$E$154:$K$159,MATCH('Summary_Com Appliances'!$A30,TableB39!$B$154:$B$159,0),MATCH('Summary_Com Appliances'!$B30,TableB39!$E$5:$K$5,0)),"") -> 1271 | D30: =IFERROR(C30/$D$43,"") -> 0.010712088 | I30: =About!$B$14 -> https://www.eia.gov/consumption/commercial/data/2012/#b38-b46
A31: District heat | B31: District heat | C31: =IFERROR(INDEX(TableB39!$E$154:$K$159,MATCH('Summary_Com Appliances'!$A31,TableB39!$B$154:$B$159,0),MATCH('Summary_Com Appliances'!$B31,TableB39!$E$5:$K$5,0)),"") -> 5797 | D31: =IFERROR(C31/$D$43,"") -> 0.048857574 | I31: =About!$B$14 -> https://www.eia.gov/consumption/commercial/data/2012/#b38-b46
A32: District heat | B32: Boilers | C32: =IFERROR(INDEX(TableB39!$E$154:$K$159,MATCH('Summary_Com Appliances'!$A32,TableB39!$B$154:$B$159,0),MATCH('Summary_Com Appliances'!$B32,TableB39!$E$5:$K$5,0)),"") -> Q | D32: =IFERROR(C32/$D$43,"") | I32: =About!$B$14 -> https://www.eia.gov/consumption/commercial/data/2012/#b38-b46
A33: District heat | B33: Pack- aged heating units | C33: =IFERROR(INDEX(TableB39!$E$154:$K$159,MATCH('Summary_Com Appliances'!$A33,TableB39!$B$154:$B$159,0),MATCH('Summary_Com Appliances'!$B33,TableB39!$E$5:$K$5,0)),"") -> 650 | D33: =IFERROR(C33/$D$43,"") -> 0.0054782513 | I33: =About!$B$14 -> https://www.eia.gov/consumption/commercial/data/2012/#b38-b46
A34: District heat | B34: Other | C34: =IFERROR(INDEX(TableB39!$E$154:$K$159,MATCH('Summary_Com Appliances'!$A34,TableB39!$B$154:$B$159,0),MATCH('Summary_Com Appliances'!$B34,TableB39!$E$5:$K$5,0)),"") -> Q | D34: =IFERROR(C34/$D$43,"") | I34: =About!$B$14 -> https://www.eia.gov/consumption/commercial/data/2012/#b38-b46
A35: Propane | C35: =IFERROR(INDEX(TableB39!$E$154:$K$159,MATCH('Summary_Com Appliances'!$A35,TableB39!$B$154:$B$159,0),MATCH('Summary_Com Appliances'!$B35,TableB39!$E$5:$K$5,0)),"") | D35: =IFERROR(C35/$D$43,"") | I35: =About!$B$14 -> https://www.eia.gov/consumption/commercial/data/2012/#b38-b46
A36: Propane | B36: Heat pumps | C36: =IFERROR(INDEX(TableB39!$E$154:$K$159,MATCH('Summary_Com Appliances'!$A36,TableB39!$B$154:$B$159,0),MATCH('Summary_Com Appliances'!$B36,TableB39!$E$5:$K$5,0)),"") -> Q | D36: =IFERROR(C36/$D$43,"") | I36: =About!$B$14 -> https://www.eia.gov/consumption/commercial/data/2012/#b38-b46
A37: Propane | B37: Furnaces | C37: =IFERROR(INDEX(TableB39!$E$154:$K$159,MATCH('Summary_Com Appliances'!$A37,TableB39!$B$154:$B$159,0),MATCH('Summary_Com Appliances'!$B37,TableB39!$E$5:$K$5,0)),"") -> 405 | D37: =IFERROR(C37/$D$43,"") -> 0.003413372 | I37: =About!$B$14 -> https://www.eia.gov/consumption/commercial/data/2012/#b38-b46
A38: Propane | B38: Indiv- idual space heaters | C38: =IFERROR(INDEX(TableB39!$E$154:$K$159,MATCH('Summary_Com Appliances'!$A38,TableB39!$B$154:$B$159,0),MATCH('Summary_Com Appliances'!$B38,TableB39!$E$5:$K$5,0)),"") -> 666 | D38: =IFERROR(C38/$D$43,"") -> 0.0056131006 | I38: =About!$B$14 -> https://www.eia.gov/consumption/commercial/data/2012/#b38-b46
A39: Propane | B39: District heat | C39: =IFERROR(INDEX(TableB39!$E$154:$K$159,MATCH('Summary_Com Appliances'!$A39,TableB39!$B$154:$B$159,0),MATCH('Summary_Com Appliances'!$B39,TableB39!$E$5:$K$5,0)),"") -> N | D39: =IFERROR(C39/$D$43,"") | I39: =About!$B$14 -> https://www.eia.gov/consumption/commercial/data/2012/#b38-b46
A40: Propane | B40: Boilers | C40: =IFERROR(INDEX(TableB39!$E$154:$K$159,MATCH('Summary_Com Appliances'!$A40,TableB39!$B$154:$B$159,0),MATCH('Summary_Com Appliances'!$B40,TableB39!$E$5:$K$5,0)),"") -> 276 | D40: =IFERROR(C40/$D$43,"") -> 0.0023261498 | I40: =About!$B$14 -> https://www.eia.gov/consumption/commercial/data/2012/#b38-b46
...

Sheet Summary_Res Appliances
A1: Residential Appliance Prevalance
F2: Calculation | G2: Calculation | I2: Source
B3: full name | C3: api key | D3: units | E3: 2025 | F3: Percent of Total Appliances | G3: Percent of Total Appliances w/ Cost Data
A4: Equipment Stock (million units) | I4: =About!$B$21 -> Alternative electricity and transportation: Table 21
A5: Main Space Heaters | I5: =About!$B$21 -> Alternative electricity and transportation: Table 21
A6: Electric Heat Pumps | B6: Residential Equipment: Equipment Stock: Main Space Heaters: Electric Heat Pumps: Alternative Electricity and Transportation | D6: millions | E6: =IFERROR(INDEX('AEO26 Table 21'!$E$6:$AD$92,MATCH($B6,'AEO26 Table 21'!$B$6:$B$92,0),MATCH($E$3,'AEO26 Table 21'!$E$5:$AD$5,0)),"") -> 17.311983 | F6: =E6/$E$15 -> 0.13854098 | G6: =E6/$G$15 -> 0.15713894 | I6: =About!$B$21 -> Alternative electricity and transportation: Table 21
A7: Electric Other | B7: Residential Equipment: Equipment Stock: Main Space Heaters: Electric Other: Alternative Electricity and Transportation | D7: millions | E7: =IFERROR(INDEX('AEO26 Table 21'!$E$6:$AD$92,MATCH($B7,'AEO26 Table 21'!$B$6:$B$92,0),MATCH($E$3,'AEO26 Table 21'!$E$5:$AD$5,0)),"") -> 27.181431 | F7: =E7/$E$15 -> 0.21752229 | G7: =E7/$G$15 -> 0.24672282 | I7: =About!$B$21 -> Alternative electricity and transportation: Table 21
A8: Natural Gas Heat Pumps | B8: Residential Equipment: Equipment Stock: Main Space Heaters: Natural Gas Heat Pumps: Alternative Electricity and Transportation | D8: millions | E8: =IFERROR(INDEX('AEO26 Table 21'!$E$6:$AD$92,MATCH($B8,'AEO26 Table 21'!$B$6:$B$92,0),MATCH($E$3,'AEO26 Table 21'!$E$5:$AD$5,0)),"") -> 1.353481 | F8: =E8/$E$15 -> 0.010831376 | I8: =About!$B$21 -> Alternative electricity and transportation: Table 21
A9: Natural Gas Other | B9: Residential Equipment: Equipment Stock: Main Space Heaters: Natural Gas Other: Alternative Electricity and Transportation | D9: millions | E9: =IFERROR(INDEX('AEO26 Table 21'!$E$6:$AD$92,MATCH($B9,'AEO26 Table 21'!$B$6:$B$92,0),MATCH($E$3,'AEO26 Table 21'!$E$5:$AD$5,0)),"") -> 65.676498 | F9: =E9/$E$15 -> 0.52558316 | G9: =E9/$G$15 -> 0.59613825 | I9: =About!$B$21 -> Alternative electricity and transportation: Table 21
A10: Distillate Fuel Oil | B10: Residential Equipment: Equipment Stock: Main Space Heaters: Distillate Fuel Oil: Alternative Electricity and Transportation | D10: millions | E10: =IFERROR(INDEX('AEO26 Table 21'!$E$6:$AD$92,MATCH($B10,'AEO26 Table 21'!$B$6:$B$92,0),MATCH($E$3,'AEO26 Table 21'!$E$5:$AD$5,0)),"") -> 4.673755 | F10: =E10/$E$15 -> 0.037402221 | I10: =About!$B$21 -> Alternative electricity and transportation: Table 21
A11: Propane | B11: Residential Equipment: Equipment Stock: Main Space Heaters: Propane: Alternative Electricity and Transportation | D11: millions | E11: =IFERROR(INDEX('AEO26 Table 21'!$E$6:$AD$92,MATCH($B11,'AEO26 Table 21'!$B$6:$B$92,0),MATCH($E$3,'AEO26 Table 21'!$E$5:$AD$5,0)),"") -> 5.239571 | F11: =E11/$E$15 -> 0.041930224 | I11: =About!$B$21 -> Alternative electricity and transportation: Table 21
A12: Kerosene | B12: Residential Equipment: Equipment Stock: Main Space Heaters: Kerosene: Alternative Electricity and Transportation | D12: millions | E12: =IFERROR(INDEX('AEO26 Table 21'!$E$6:$AD$92,MATCH($B12,'AEO26 Table 21'!$B$6:$B$92,0),MATCH($E$3,'AEO26 Table 21'!$E$5:$AD$5,0)),"") | F12: =E12/$E$15 -> #VALUE! | I12: =About!$B$21 -> Alternative electricity and transportation: Table 21
A13: Wood Stoves | B13: Residential Equipment: Equipment Stock: Main Space Heaters: Wood Stoves: Alternative Electricity and Transportation | D13: millions | E13: =IFERROR(INDEX('AEO26 Table 21'!$E$6:$AD$92,MATCH($B13,'AEO26 Table 21'!$B$6:$B$92,0),MATCH($E$3,'AEO26 Table 21'!$E$5:$AD$5,0)),"") -> 2.209099 | F13: =E13/$E$15 -> 0.01767855 | I13: =About!$B$21 -> Alternative electricity and transportation: Table 21
A14: Geothermal Heat Pumps | B14: Residential Equipment: Equipment Stock: Main Space Heaters: Geothermal Heat Pumps: Alternative Electricity and Transportation | D14: millions | E14: =IFERROR(INDEX('AEO26 Table 21'!$E$6:$AD$92,MATCH($B14,'AEO26 Table 21'!$B$6:$B$92,0),MATCH($E$3,'AEO26 Table 21'!$E$5:$AD$5,0)),"") -> 1.313477 | F14: =E14/$E$15 -> 0.010511239 | I14: =About!$B$21 -> Alternative electricity and transportation: Table 21
A15: Total | B15: Residential Equipment: Equipment Stock: Main Space Heaters: Total: Alternative Electricity and Transportation | D15: millions | E15: =IFERROR(INDEX('AEO26 Table 21'!$E$6:$AD$92,MATCH($B15,'AEO26 Table 21'!$B$6:$B$92,0),MATCH($E$3,'AEO26 Table 21'!$E$5:$AD$5,0)),"") -> 124.95929 | F15: =E15/$E$15 -> 1 | G15: =SUM(E6:E7,E9) -> 110.16991 | I15: =About!$B$21 -> Alternative electricity and transportation: Table 21
A16: Space Cooling (million units) | E16: =IFERROR(INDEX('AEO26 Table 21'!$E$6:$AD$92,MATCH($B16,'AEO26 Table 21'!$B$6:$B$92,0),MATCH($E$3,'AEO26 Table 21'!$E$5:$AD$5,0)),"") | I16: =About!$B$21 -> Alternative electricity and transportation: Table 21
A17: Electric Heat Pumps | B17: Residential Equipment: Equipment Stock: Space Cooling: Electric Heat Pumps: Alternative Electricity and Transportation | D17: millions | E17: =IFERROR(INDEX('AEO26 Table 21'!$E$6:$AD$92,MATCH($B17,'AEO26 Table 21'!$B$6:$B$92,0),MATCH($E$3,'AEO26 Table 21'!$E$5:$AD$5,0)),"") -> 17.311981 | F17: =E17/$E$22 -> 0.12034362 | G17: =E17/$G$22 -> 0.12261684 | I17: =About!$B$21 -> Alternative electricity and transportation: Table 21
A18: Natural Gas Heat Pumps | B18: Residential Equipment: Equipment Stock: Space Cooling: Natural Gas Heat Pumps: Alternative Electricity and Transportation | D18: millions | E18: =IFERROR(INDEX('AEO26 Table 21'!$E$6:$AD$92,MATCH($B18,'AEO26 Table 21'!$B$6:$B$92,0),MATCH($E$3,'AEO26 Table 21'!$E$5:$AD$5,0)),"") -> 1.353481 | F18: =E18/$E$22 -> 0.0094086748 | I18: =About!$B$21 -> Alternative electricity and transportation: Table 21
A19: Geothermal Heat Pumps | B19: Residential Equipment: Equipment Stock: Space Cooling: Geothermal Heat Pumps: Alternative Electricity and Transportation | D19: millions | E19: =IFERROR(INDEX('AEO26 Table 21'!$E$6:$AD$92,MATCH($B19,'AEO26 Table 21'!$B$6:$B$92,0),MATCH($E$3,'AEO26 Table 21'!$E$5:$AD$5,0)),"") -> 1.313476 | F19: =E19/$E$22 -> 0.0091305815 | I19: =About!$B$21 -> Alternative electricity and transportation: Table 21
A20: Central Air Conditioners | B20: Residential Equipment: Equipment Stock: Space Cooling: Central Air Conditioners: Alternative Electricity and Transportation | D20: millions | E20: =IFERROR(INDEX('AEO26 Table 21'!$E$6:$AD$92,MATCH($B20,'AEO26 Table 21'!$B$6:$B$92,0),MATCH($E$3,'AEO26 Table 21'!$E$5:$AD$5,0)),"") -> 80.644836 | F20: =E20/$E$22 -> 0.5605997 | G20: =E20/$G$22 -> 0.57118911 | I20: =About!$B$21 -> Alternative electricity and transportation: Table 21
A21: Room Air Conditioners | B21: Residential Equipment: Equipment Stock: Space Cooling: Room Air Conditioners: Alternative Electricity and Transportation | D21: millions | E21: =IFERROR(INDEX('AEO26 Table 21'!$E$6:$AD$92,MATCH($B21,'AEO26 Table 21'!$B$6:$B$92,0),MATCH($E$3,'AEO26 Table 21'!$E$5:$AD$5,0)),"") -> 43.230812 | F21: =E21/$E$22 -> 0.30051744 | G21: =E21/$G$22 -> 0.30619405 | I21: =About!$B$21 -> Alternative electricity and transportation: Table 21
A22: Total | B22: Residential Equipment: Equipment Stock: Space Cooling: Total: Alternative Electricity and Transportation | D22: millions | E22: =IFERROR(INDEX('AEO26 Table 21'!$E$6:$AD$92,MATCH($B22,'AEO26 Table 21'!$B$6:$B$92,0),MATCH($E$3,'AEO26 Table 21'!$E$5:$AD$5,0)),"") -> 143.85458 | F22: =E22/$E$22 -> 1 | G22: =SUM(E17,E20:E21) -> 141.18763 | I22: =About!$B$21 -> Alternative electricity and transportation: Table 21
A23: Water Heaters (million units) | E23: =IFERROR(INDEX('AEO26 Table 21'!$E$6:$AD$92,MATCH($B23,'AEO26 Table 21'!$B$6:$B$92,0),MATCH($E$3,'AEO26 Table 21'!$E$5:$AD$5,0)),"") | I23: =About!$B$21 -> Alternative electricity and transportation: Table 21
A24: Electric | B24: Residential Equipment: Equipment Stock: Water Heaters: Electric: Alternative Electricity and Transportation | D24: millions | E24: =IFERROR(INDEX('AEO26 Table 21'!$E$6:$AD$92,MATCH($B24,'AEO26 Table 21'!$B$6:$B$92,0),MATCH($E$3,'AEO26 Table 21'!$E$5:$AD$5,0)),"") -> 62.475159 | F24: =E24/$E$29 -> 0.45872439 | G24: =E24/$G$29 -> 0.48965433 | I24: =About!$B$21 -> Alternative electricity and transportation: Table 21
A25: Natural Gas | B25: Residential Equipment: Equipment Stock: Water Heaters: Natural Gas: Alternative Electricity and Transportation | D25: millions | E25: =IFERROR(INDEX('AEO26 Table 21'!$E$6:$AD$92,MATCH($B25,'AEO26 Table 21'!$B$6:$B$92,0),MATCH($E$3,'AEO26 Table 21'!$E$5:$AD$5,0)),"") -> 65.115173 | F25: =E25/$E$29 -> 0.47810871 | G25: =E25/$G$29 -> 0.51034567 | I25: =About!$B$21 -> Alternative electricity and transportation: Table 21
A26: Distillate Fuel Oil | B26: Residential Equipment: Equipment Stock: Water Heaters: Distillate Fuel Oil: Alternative Electricity and Transportation | D26: millions | E26: =IFERROR(INDEX('AEO26 Table 21'!$E$6:$AD$92,MATCH($B26,'AEO26 Table 21'!$B$6:$B$92,0),MATCH($E$3,'AEO26 Table 21'!$E$5:$AD$5,0)),"") -> 2.224999 | F26: =E26/$E$29 -> 0.016337074 | I26: =About!$B$21 -> Alternative electricity and transportation: Table 21
A27: Propane | B27: Residential Equipment: Equipment Stock: Water Heaters: Propane: Alternative Electricity and Transportation | D27: millions | E27: =IFERROR(INDEX('AEO26 Table 21'!$E$6:$AD$92,MATCH($B27,'AEO26 Table 21'!$B$6:$B$92,0),MATCH($E$3,'AEO26 Table 21'!$E$5:$AD$5,0)),"") -> 4.199949 | F27: =E27/$E$29 -> 0.030838161 | I27: =About!$B$21 -> Alternative electricity and transportation: Table 21
A28: Solar Thermal | B28: Residential Equipment: Equipment Stock: Water Heaters: Solar Thermal: Alternative Electricity and Transportation | D28: millions | E28: =IFERROR(INDEX('AEO26 Table 21'!$E$6:$AD$92,MATCH($B28,'AEO26 Table 21'!$B$6:$B$92,0),MATCH($E$3,'AEO26 Table 21'!$E$5:$AD$5,0)),"") -> 2.17795 | F28: =E28/$E$29 -> 0.015991616 | I28: =About!$B$21 -> Alternative electricity and transportation: Table 21
A29: Total | B29: Residential Equipment: Equipment Stock: Water Heaters: Total: Alternative Electricity and Transportation | D29: millions | E29: =IFERROR(INDEX('AEO26 Table 21'!$E$6:$AD$92,MATCH($B29,'AEO26 Table 21'!$B$6:$B$92,0),MATCH($E$3,'AEO26 Table 21'!$E$5:$AD$5,0)),"") -> 136.19324 | F29: =E29/$E$29 -> 1 | G29: =SUM(E24:E25) -> 127.59033 | I29: =About!$B$21 -> Alternative electricity and transportation: Table 21
A30: Cooking Equipment (million units) | E30: =IFERROR(INDEX('AEO26 Table 21'!$E$6:$AD$92,MATCH($B30,'AEO26 Table 21'!$B$6:$B$92,0),MATCH($E$3,'AEO26 Table 21'!$E$5:$AD$5,0)),"") | I30: =About!$B$21 -> Alternative electricity and transportation: Table 21
A31: Electric | B31: Residential Equipment: Equipment Stock: Cooking Equipment: Electric: Alternative Electricity and Transportation | D31: millions | E31: =IFERROR(INDEX('AEO26 Table 21'!$E$6:$AD$92,MATCH($B31,'AEO26 Table 21'!$B$6:$B$92,0),MATCH($E$3,'AEO26 Table 21'!$E$5:$AD$5,0)),"") -> 101.44487 | F31: =E31/$E$34 -> 0.62683938 | I31: =About!$B$21 -> Alternative electricity and transportation: Table 21
A32: Natural Gas | B32: Residential Equipment: Equipment Stock: Cooking Equipment: Natural Gas: Alternative Electricity and Transportation | D32: millions | E32: =IFERROR(INDEX('AEO26 Table 21'!$E$6:$AD$92,MATCH($B32,'AEO26 Table 21'!$B$6:$B$92,0),MATCH($E$3,'AEO26 Table 21'!$E$5:$AD$5,0)),"") -> 54.077557 | F32: =E32/$E$34 -> 0.33415137 | G32: 1 | I32: =About!$B$21 -> Alternative electricity and transportation: Table 21
A33: Propane | B33: Residential Equipment: Equipment Stock: Cooking Equipment: Propane: Alternative Electricity and Transportation | D33: millions | E33: =IFERROR(INDEX('AEO26 Table 21'!$E$6:$AD$92,MATCH($B33,'AEO26 Table 21'!$B$6:$B$92,0),MATCH($E$3,'AEO26 Table 21'!$E$5:$AD$5,0)),"") -> 6.313086 | F33: =E33/$E$34 -> 0.039009276 | I33: =About!$B$21 -> Alternative electricity and transportation: Table 21
A34: Total | B34: Residential Equipment: Equipment Stock: Cooking Equipment: Total: Alternative Electricity and Transportation | D34: millions | E34: =IFERROR(INDEX('AEO26 Table 21'!$E$6:$AD$92,MATCH($B34,'AEO26 Table 21'!$B$6:$B$92,0),MATCH($E$3,'AEO26 Table 21'!$E$5:$AD$5,0)),"") -> 161.83551 | F34: =E34/$E$34 -> 1 | I34: =About!$B$21 -> Alternative electricity and transportation: Table 21
A35: Clothes Dryers (million units) | E35: =IFERROR(INDEX('AEO26 Table 21'!$E$6:$AD$92,MATCH($B35,'AEO26 Table 21'!$B$6:$B$92,0),MATCH($E$3,'AEO26 Table 21'!$E$5:$AD$5,0)),"") | I35: =About!$B$21 -> Alternative electricity and transportation: Table 21
A36: Electric | B36: Residential Equipment: Equipment Stock: Clothes Dryers: Electric: Alternative Electricity and Transportation | D36: millions | E36: =IFERROR(INDEX('AEO26 Table 21'!$E$6:$AD$92,MATCH($B36,'AEO26 Table 21'!$B$6:$B$92,0),MATCH($E$3,'AEO26 Table 21'!$E$5:$AD$5,0)),"") -> 95.14431 | F36: =E36/$E$38 -> 0.82299211 | G36: =F36 -> 0.82299211 | I36: =About!$B$21 -> Alternative electricity and transportation: Table 21
A37: Natural Gas | B37: Residential Equipment: Equipment Stock: Clothes Dryers: Natural Gas: Alternative Electricity and Transportation | D37: millions | E37: =IFERROR(INDEX('AEO26 Table 21'!$E$6:$AD$92,MATCH($B37,'AEO26 Table 21'!$B$6:$B$92,0),MATCH($E$3,'AEO26 Table 21'!$E$5:$AD$5,0)),"") -> 20.463491 | F37: =E37/$E$38 -> 0.17700787 | G37: =F37 -> 0.17700787 | I37: =About!$B$21 -> Alternative electricity and transportation: Table 21
A38: Total | B38: Residential Equipment: Equipment Stock: Clothes Dryers: Total: Alternative Electricity and Transportation | D38: millions | E38: =IFERROR(INDEX('AEO26 Table 21'!$E$6:$AD$92,MATCH($B38,'AEO26 Table 21'!$B$6:$B$92,0),MATCH($E$3,'AEO26 Table 21'!$E$5:$AD$5,0)),"") -> 115.6078 | F38: =E38/$E$38 -> 1 | G38: =SUM(E36:E37) -> 115.6078 | I38: =About!$B$21 -> Alternative electricity and transportation: Table 21
A39: Other Appliances (million units) | E39: =IFERROR(INDEX('AEO26 Table 21'!$E$6:$AD$92,MATCH($B39,'AEO26 Table 21'!$B$6:$B$92,0),MATCH($E$3,'AEO26 Table 21'!$E$5:$AD$5,0)),"") | I39: =About!$B$21 -> Alternative electricity and transportation: Table 21
A40: Refrigerators | B40: Residential Equipment: Equipment Stock: Other Appliances: Refrigerators: Alternative Electricity and Transportation | D40: millions | E40: =IFERROR(INDEX('AEO26 Table 21'!$E$6:$AD$92,MATCH($B40,'AEO26 Table 21'!$B$6:$B$92,0),MATCH($E$3,'AEO26 Table 21'!$E$5:$AD$5,0)),"") -> 187.50732 | I40: =About!$B$21 -> Alternative electricity and transportation: Table 21
...

Sheet Cost Breakdowns
A1: Sector | C1: Percent of cost | F1: ISIC Mapping | G1: Notes
C2: Urban-Residential | D2: Rural-Residential | E2: Commercial
A3: Heating | B3: Equipment | C3: ='Cost Summary New'!E$4*'Margin Calcs'!$L$5 -> 0.25957515 | D3: ='Cost Summary New'!E$4*'Margin Calcs'!$L$5 -> 0.25957515 | E3: ='Cost Summary New'!E45*'Margin Calcs'!$L$6 -> 0.48014297 | F3: ='ISIC Code Mapping'!B2 -> ISIC 28 | H3: Equipment rows: the equipment part of the installed cost times the manufacturer's, markup or freight share on the Margin Calcs tab.
A4: Heating | B4: Equipment markup (wholesale and retail) | C4: ='Cost Summary New'!E$4*'Margin Calcs'!$N$5 -> 0.28309633 | D4: ='Cost Summary New'!E$4*'Margin Calcs'!$N$5 -> 0.28309633 | E4: ='Cost Summary New'!E45*'Margin Calcs'!$N$6 -> 0.21006812 | F4: ="ISIC 45T47" -> ISIC 45T47
A5: Heating | B5: Equipment freight | C5: ='Cost Summary New'!E$4*'Margin Calcs'!$M$5 -> 0.0076097929 | D5: ='Cost Summary New'!E$4*'Margin Calcs'!$M$5 -> 0.0076097929 | E5: ='Cost Summary New'!E45*'Margin Calcs'!$M$6 -> 0.013776419 | F5: ="ISIC 49" -> ISIC 49
A6: Heating | B6: Labor | C6: ='Cost Summary New'!F$4 -> 0.44971873 | D6: ='Cost Summary New'!F$4 -> 0.44971873 | E6: ='Cost Summary New'!F45 -> 0.2960125 | F6: ='ISIC Code Mapping'!B3 -> ISIC 41T43
A7: Cooling | B7: Equipment | C7: ='Cost Summary New'!$E$14*'Margin Calcs'!$L$7 -> 0.34719458 | D7: ='Cost Summary New'!$E$14*'Margin Calcs'!$L$7 -> 0.34719458 | E7: ='Cost Summary New'!E95*'Margin Calcs'!$L$8 -> 0.39823638 | F7: ='ISIC Code Mapping'!C2 -> ISIC 28
A8: Cooling | B8: Equipment markup (wholesale and retail) | C8: ='Cost Summary New'!$E$14*'Margin Calcs'!$N$7 -> 0.37896261 | D8: ='Cost Summary New'!$E$14*'Margin Calcs'!$N$7 -> 0.37896261 | E8: ='Cost Summary New'!E95*'Margin Calcs'!$N$8 -> 0.17019402 | F8: ="ISIC 45T47" -> ISIC 45T47
A9: Cooling | B9: Equipment freight | C9: ='Cost Summary New'!$E$14*'Margin Calcs'!$M$7 -> 0.010088498 | D9: ='Cost Summary New'!$E$14*'Margin Calcs'!$M$7 -> 0.010088498 | E9: ='Cost Summary New'!E95*'Margin Calcs'!$M$8 -> 0.011399713 | F9: ="ISIC 49" -> ISIC 49
A10: Cooling | B10: Labor | C10: ='Cost Summary New'!$F$14 -> 0.26375431 | D10: ='Cost Summary New'!$F$14 -> 0.26375431 | E10: ='Cost Summary New'!F95 -> 0.42016989 | F10: ='ISIC Code Mapping'!C3 -> ISIC 41T43
A11: Lighting | B11: Equipment | C11: ='Cost Summary New'!$E$39*'Margin Calcs'!$L$9 -> 0.39998511 | D11: ='Cost Summary New'!$E$39*'Margin Calcs'!$L$9 -> 0.39998511 | E11: ='Cost Summary New'!E100*'Margin Calcs'!$L$10 -> 0.28238604 | F11: ='ISIC Code Mapping'!E2 -> ISIC 27
A12: Lighting | B12: Equipment markup (wholesale and retail) | C12: ='Cost Summary New'!$E$39*'Margin Calcs'!$N$9 -> 0.55505099 | D12: ='Cost Summary New'!$E$39*'Margin Calcs'!$N$9 -> 0.55505099 | E12: ='Cost Summary New'!E100*'Margin Calcs'!$N$10 -> 0.091251813 | F12: ="ISIC 45T47" -> ISIC 45T47
A13: Lighting | B13: Equipment freight | C13: ='Cost Summary New'!$E$39*'Margin Calcs'!$M$9 -> 0.044963895 | D13: ='Cost Summary New'!$E$39*'Margin Calcs'!$M$9 -> 0.044963895 | E13: ='Cost Summary New'!E100*'Margin Calcs'!$M$10 -> 0.034031096 | F13: ="ISIC 49" -> ISIC 49
A14: Lighting | B14: Labor | C14: ='Cost Summary New'!$F$39 -> 0 | D14: ='Cost Summary New'!$F$39 -> 0 | E14: ='Cost Summary New'!F100 -> 0.59233105 | F14: ='ISIC Code Mapping'!E3 -> ISIC 41T43
A15: Appliances | B15: Equipment | C15: ='Cost Summary New'!$E$41*'Margin Calcs'!$L$11 -> 0.41594355 | D15: ='Cost Summary New'!$E$41*'Margin Calcs'!$L$11 -> 0.41594355 | E15: ='Cost Summary New'!E88*'Margin Calcs'!$L$12 -> 0.51313159 | F15: ='ISIC Code Mapping'!F2 -> ISIC 27
A16: Appliances | B16: Equipment markup (wholesale and retail) | C16: ='Cost Summary New'!$E$41*'Margin Calcs'!$N$11 -> 0.33246167 | D16: ='Cost Summary New'!$E$41*'Margin Calcs'!$N$11 -> 0.33246167 | E16: ='Cost Summary New'!E88*'Margin Calcs'!$N$12 -> 0.22708138 | F16: ="ISIC 45T47" -> ISIC 45T47
A17: Appliances | B17: Equipment freight | C17: ='Cost Summary New'!$E$41*'Margin Calcs'!$M$11 -> 0.0059461992 | D17: ='Cost Summary New'!$E$41*'Margin Calcs'!$M$11 -> 0.0059461992 | E17: ='Cost Summary New'!E88*'Margin Calcs'!$M$12 -> 0.0141859 | F17: ="ISIC 49" -> ISIC 49
A18: Appliances | B18: Labor | C18: ='Cost Summary New'!$F$41 -> 0.24564858 | D18: ='Cost Summary New'!$F$41 -> 0.24564858 | E18: ='Cost Summary New'!F88 -> 0.24560113 | F18: ='ISIC Code Mapping'!F3 -> ISIC 41T43
A19: Other | B19: Equipment | C19: ='Cost Summary New'!$E$41*'Margin Calcs'!$L$13 -> 0.39439857 | D19: ='Cost Summary New'!$E$41*'Margin Calcs'!$L$13 -> 0.39439857 | E19: ='Cost Summary New'!E88*'Margin Calcs'!$L$14 -> 0.51142569 | F19: ='ISIC Code Mapping'!G2 -> ISIC 27 | G19: Other uses the appliances cost breakdown
A20: Other | B20: Equipment markup (wholesale and retail) | C20: ='Cost Summary New'!$E$41*'Margin Calcs'!$N$13 -> 0.34557881 | D20: ='Cost Summary New'!$E$41*'Margin Calcs'!$N$13 -> 0.34557881 | E20: ='Cost Summary New'!E88*'Margin Calcs'!$N$14 -> 0.23490525 | F20: ="ISIC 45T47" -> ISIC 45T47
A21: Other | B21: Equipment freight | C21: ='Cost Summary New'!$E$41*'Margin Calcs'!$M$13 -> 0.014374046 | D21: ='Cost Summary New'!$E$41*'Margin Calcs'!$M$13 -> 0.014374046 | E21: ='Cost Summary New'!E88*'Margin Calcs'!$M$14 -> 0.0080679255 | F21: ="ISIC 49" -> ISIC 49
A22: Other | B22: Labor | C22: ='Cost Summary New'!$F$41 -> 0.24564858 | D22: ='Cost Summary New'!$F$41 -> 0.24564858 | E22: ='Cost Summary New'!F88 -> 0.24560113 | F22: ='ISIC Code Mapping'!G3 -> ISIC 41T43

Sheet TableB39
B1: Release date: April 2015 Revised date: May 2016
B2: Table B39. Heating equipment, floorspace, 2012
C3: Total floorspace (million square feet)
C4: All buildings | D4: Buildings with space heating | E4: Heating equipment (more than one may apply)
E5: Heat pumps | F5: Furnaces | G5: Indiv- idual space heaters | H5: District heat | I5: Boilers | J5: Pack- aged heating units | K5: Other
B6: All buildings | C6: 87093 | D6: 80078 | E6: 11846 | F6: 8654 | G6: 20766 | H6: 5925 | I6: 22443 | J6: 49188 | K6: 1574
B7: Building floorspace (square feet)
B8: 1,001 to 5,000 | C8: 8041 | D8: 6699 | E8: 868 | F8: 1091 | G8: 1747 | H8: Q | I8: 400 | J8: 3809 | K8: Q
B9: 5,001 to 10,000 | C9: 8900 | D9: 7590 | E9: 1038 | F9: 1416 | G9: 2025 | H9: Q | I9: 734 | J9: 4622 | K9: Q
B10: 10,001 to 25,000 | C10: 14105 | D10: 12744 | E10: 1477 | F10: 2233 | G10: 3115 | H10: Q | I10: 2008 | J10: 8246 | K10: Q
B11: 25,001 to 50,000 | C11: 11917 | D11: 10911 | E11: 1642 | F11: 1439 | G11: 3021 | H11: 213 | I11: 2707 | J11: 7237 | K11: Q
B12: 50,001 to 100,000 | C12: 13918 | D12: 13114 | E12: 2664 | F12: 1042 | G12: 2763 | H12: 704 | I12: 4938 | J12: 8489 | K12: 541
B13: 100,001 to 200,000 | C13: 12415 | D13: 11941 | E13: 1549 | F13: 683 | G13: 2915 | H13: 1313 | I13: 4258 | J13: 7569 | K13: Q
B14: 200,001 to 500,000 | C14: 10724 | D14: 10348 | E14: 1527 | F14: 466 | G14: 2970 | H14: 1553 | I14: 4970 | J14: 5991 | K14: Q
B15: Over 500,000 | C15: 7074 | D15: 6730 | E15: 1080 | F15: 284 | G15: 2211 | H15: 1974 | I15: 2430 | J15: 3225 | K15: Q
B16: Principal building activity
B17: Education | C17: 12239 | D17: 12099 | E17: 2209 | F17: 564 | G17: 1750 | H17: 1155 | I17: 6637 | J17: 6107 | K17: Q
B18: Food sales | C18: 1252 | D18: 1196 | E18: Q | F18: Q | G18: 336 | H18: N | I18: Q | J18: 944 | K18: Q
B19: Food service | C19: 1819 | D19: 1762 | E19: 146 | F19: 266 | G19: 256 | H19: Q | I19: 145 | J19: 1296 | K19: Q
B20: Health care | C20: 4155 | D20: 4109 | E20: 739 | F20: 258 | G20: 967 | H20: 671 | I20: 2285 | J20: 2085 | K20: Q
B21: Inpatient | C21: 2374 | D21: 2354 | E21: 506 | F21: 124 | G21: 501 | H21: 563 | I21: 1698 | J21: 1073 | K21: Q
B22: Outpatient | C22: 1781 | D22: 1754 | E22: 233 | F22: 133 | G22: 466 | H22: Q | I22: 588 | J22: 1012 | K22: N
B23: Lodging | C23: 5826 | D23: 5696 | E23: 1259 | F23: 638 | G23: 2168 | H23: 621 | I23: 2105 | J23: 2561 | K23: Q
B24: Mercantile | C24: 11330 | D24: 10794 | E24: 1419 | F24: 1423 | G24: 2568 | H24: Q | I24: 1138 | J24: 9434 | K24: 872
B25: Retail (other than mall) | C25: 5439 | D25: 5088 | E25: 441 | F25: 590 | G25: 1007 | H25: Q | I25: 312 | J25: 3964 | K25: Q
B26: Enclosed and strip malls | C26: 5890 | D26: 5706 | E26: 978 | F26: 832 | G26: 1561 | H26: Q | I26: 826 | J26: 5470 | K26: 860
B27: Office | C27: 15952 | D27: 15753 | E27: 2667 | F27: 1691 | G27: 3727 | H27: 1794 | I27: 4650 | J27: 8407 | K27: Q
B28: Public assembly | C28: 5559 | D28: 5323 | E28: 727 | F28: 582 | G28: 1560 | H28: 888 | I28: 1621 | J28: 3016 | K28: Q
B29: Public order and safety | C29: 1440 | D29: 1391 | E29: Q | F29: Q | G29: 253 | H29: Q | I29: 466 | J29: 601 | K29: Q
B30: Religious worship | C30: 4557 | D30: 4511 | E30: 581 | F30: 927 | G30: 859 | H30: N | I30: 1359 | J30: 2801 | K30: Q
B31: Service | C31: 4630 | D31: 4157 | E31: 356 | F31: 497 | G31: 1919 | H31: Q | I31: 433 | J31: 2498 | K31: Q
B32: Warehouse and storage | C32: 13077 | D32: 9987 | E32: 1138 | F32: 1294 | G32: 3480 | H32: Q | I32: 841 | J32: 7297 | K32: Q
B33: Other | C33: 2002 | D33: 1886 | E33: Q | F33: Q | G33: 737 | H33: Q | I33: 408 | J33: 1257 | K33: Q
B34: Vacant | C34: 3256 | D34: 1415 | E34: Q | F34: Q | G34: Q | H34: Q | I34: 296 | J34: 886 | K34: Q
B35: Year constructed
B36: Before 1920 | C36: 3983 | D36: 3583 | E36: 371 | F36: 524 | G36: 1442 | H36: 523 | I36: 1221 | J36: 1380 | K36: Q
B37: 1920 to 1945 | C37: 6025 | D37: 5527 | E37: 744 | F37: 393 | G37: 1717 | H37: 888 | I37: 2016 | J37: 2589 | K37: Q
B38: 1946 to 1959 | C38: 7381 | D38: 6895 | E38: 907 | F38: 685 | G38: 2277 | H38: 446 | I38: 2659 | J38: 3715 | K38: Q
B39: 1960 to 1969 | C39: 10362 | D39: 9730 | E39: 1295 | F39: 1168 | G39: 2586 | H39: 1002 | I39: 3506 | J39: 5670 | K39: Q
B40: 1970 to 1979 | C40: 10846 | D40: 10045 | E40: 1198 | F40: 1345 | G40: 2923 | H40: 930 | I40: 2763 | J40: 6156 | K40: Q
...

Sheet TableB44
A1: Release date: April 2015 Revised date: May 2016
A2: Table B44. Lighting equipment, floorspace, 2012
B3: Total floorspace (million square feet)
B4: All buildings | C4: Lit buildings | D4: Lighting equipment (more than one may apply)
D5: Incand- escent | E5: Standard fluor- escent | F5: Compact fluor- escent | G5: High-intensity dis- charge | H5: Halogen | I5: LED
A6: All buildings | B6: 87093 | C6: 83569 | D6: 38406 | E6: 80081 | F6: 53816 | G6: 23396 | H6: 28059 | I6: 22071
A7: Building floorspace (square feet)
A8: 1,001 to 5,000 | B8: 8041 | C8: 7130 | D8: 2453 | E8: 6466 | F8: 2815 | G8: 373 | H8: 944 | I8: 348
A9: 5,001 to 10,000 | B9: 8900 | C9: 8152 | D9: 2917 | E9: 7589 | F9: 3740 | G9: 736 | H9: 1487 | I9: 714
A10: 10,001 to 25,000 | B10: 14105 | C10: 13250 | D10: 4987 | E10: 12533 | F10: 6767 | G10: 2175 | H10: 2903 | I10: 1882
A11: 25,001 to 50,000 | B11: 11917 | C11: 11542 | D11: 4788 | E11: 11063 | F11: 6970 | G11: 2712 | H11: 3556 | I11: 2252
A12: 50,001 to 100,000 | B12: 13918 | C12: 13564 | D12: 6218 | E12: 13217 | F12: 9652 | G12: 3766 | H12: 4989 | I12: 3479
A13: 100,001 to 200,000 | B13: 12415 | C13: 12282 | D13: 6239 | E13: 11745 | F13: 9078 | G13: 4244 | H13: 4605 | I13: 3919
A14: 200,001 to 500,000 | B14: 10724 | C14: 10634 | D14: 6002 | E14: 10552 | F14: 8775 | G14: 4981 | H14: 5161 | I14: 4866
A15: Over 500,000 | B15: 7074 | C15: 7014 | D15: 4803 | E15: 6915 | F15: 6021 | G15: 4409 | H15: 4413 | I15: 4612
A16: Principal building activity
A17: Education | B17: 12239 | C17: 12239 | D17: 5004 | E17: 12180 | F17: 8559 | G17: 4376 | H17: 3069 | I17: 2135
A18: Food sales | B18: 1252 | C18: 1252 | D18: 443 | E18: 1232 | F18: 560 | G18: Q | H18: 271 | I18: 323
A19: Food service | B19: 1819 | C19: 1819 | D19: 924 | E19: 1671 | F19: 1177 | G19: 121 | H19: 496 | I19: 275
A20: Health care | B20: 4155 | C20: 4155 | D20: 2391 | E20: 4074 | F20: 3535 | G20: 1448 | H20: 1875 | I20: 2245
A21: Inpatient | B21: 2374 | C21: 2374 | D21: 1745 | E21: 2373 | F21: 2260 | G21: 1217 | H21: 1452 | I21: 1647
A22: Outpatient | B22: 1781 | C22: 1781 | D22: 646 | E22: 1701 | F22: 1275 | G22: 231 | H22: 423 | I22: 598
A23: Lodging | B23: 5826 | C23: 5817 | D23: 3585 | E23: 5409 | F23: 5258 | G23: 1848 | H23: 2696 | I23: 2024
A24: Mercantile | B24: 11330 | C24: 11320 | D24: 6646 | E24: 10714 | F24: 8053 | G24: 3959 | H24: 5925 | I24: 5118
A25: Retail (other than mall) | B25: 5439 | C25: 5430 | D25: 1671 | E25: 4864 | F25: 2712 | G25: 891 | H25: 1608 | I25: 1295
A26: Enclosed and strip malls | B26: 5890 | C26: 5890 | D26: 4975 | E26: 5850 | F26: 5341 | G26: 3069 | H26: 4317 | I26: 3824
A27: Office | B27: 15952 | C27: 15952 | D27: 7541 | E27: 15547 | F27: 11438 | G27: 3858 | H27: 5598 | I27: 5034
A28: Public assembly | B28: 5559 | C28: 5527 | D28: 3035 | E28: 5208 | F28: 4125 | G28: 1922 | H28: 2172 | I28: 1955
A29: Public order and safety | B29: 1440 | C29: 1414 | D29: 623 | E29: 1375 | F29: 1086 | G29: 404 | H29: 416 | I29: 360
A30: Religious worship | B30: 4557 | C30: 4557 | D30: 3015 | E30: 4293 | F30: 3187 | G30: 839 | H30: 1540 | I30: 902
A31: Service | B31: 4630 | C31: 4379 | D31: 1026 | E31: 4142 | F31: 1569 | G31: 980 | H31: 1024 | I31: Q
A32: Warehouse and storage | B32: 13077 | C32: 12079 | D32: 3094 | E32: 11280 | F32: 4040 | G32: 2934 | H32: 2438 | I32: 998
A33: Other | B33: 2002 | C33: 1930 | D33: 790 | E33: 1880 | F33: 783 | G33: 383 | H33: 344 | I33: 290
A34: Vacant | B34: 3256 | C34: 1128 | D34: 288 | E34: 1076 | F34: 445 | G34: Q | H34: Q | I34: Q
A35: Year constructed
A36: Before 1920 | B36: 3983 | C36: 3715 | D36: 2292 | E36: 3280 | F36: 2346 | G36: 763 | H36: 1208 | I36: 744
A37: 1920 to 1945 | B37: 6025 | C37: 5774 | D37: 2750 | E37: 5472 | F37: 3714 | G37: 1337 | H37: 1948 | I37: 1528
A38: 1946 to 1959 | B38: 7381 | C38: 7087 | D38: 3494 | E38: 6860 | F38: 4340 | G38: 1785 | H38: 2028 | I38: 1306
A39: 1960 to 1969 | B39: 10362 | C39: 10061 | D39: 4629 | E39: 9857 | F39: 6463 | G39: 2525 | H39: 2948 | I39: 2224
A40: 1970 to 1979 | B40: 10846 | C40: 10354 | D40: 5560 | E40: 9992 | F40: 6913 | G40: 3311 | H40: 3418 | I40: 2632
...

Sheet TableB42
A1: Release date: April 2015 Revised date: May 2016
A2: Table B42. Water-heating equipment, number of buildings and floorspace, 2012
B3: Number of buildings (thousand) | G3: Total floorspace (million square feet)
B4: All buildings | C4: Buildings with water heating | D4: Type of water-heating equipment | G4: All buildings | H4: Buildings with water heating | I4: Type of water-heating equipment
D5: Central- ized system | E5: Distrib- uted system | F5: Both central- ized and distrib- uted systems | I5: Central- ized system | J5: Distrib- uted system | K5: Both central- ized and distrib- uted systems
A6: All buildings | B6: 5557 | C6: 4423 | D6: 3348 | E6: 690 | F6: 385 | G6: 87093 | H6: 79015 | I6: 47534 | J6: 12688 | K6: 18793
A7: Building floorspace (square feet)
A8: 1,001 to 5,000 | B8: 2777 | C8: 2032 | D8: 1653 | E8: 322 | F8: 57 | G8: 8041 | H8: 6102 | I8: 4906 | J8: 1011 | K8: 185
A9: 5,001 to 10,000 | B9: 1229 | C9: 992 | D9: 789 | E9: 120 | F9: 82 | G9: 8900 | H9: 7236 | I9: 5731 | J9: 890 | K9: 615
A10: 10,001 to 25,000 | B10: 884 | C10: 775 | D10: 538 | E10: 143 | F10: 93 | G10: 14105 | H10: 12401 | I10: 8549 | J10: 2318 | K10: 1534
A11: 25,001 to 50,000 | B11: 332 | C11: 307 | D11: 198 | E11: 57 | F11: 51 | G11: 11917 | H11: 11007 | I11: 7125 | J11: 1983 | K11: 1899
A12: 50,001 to 100,000 | B12: 199 | C12: 186 | D12: 103 | E12: 28 | F12: 55 | G12: 13918 | H12: 13063 | I12: 7181 | J12: 1904 | K12: 3978
A13: 100,001 to 200,000 | B13: 90 | C13: 86 | D13: 45 | E13: 13 | F13: 29 | G13: 12415 | H13: 11903 | I13: 6120 | J13: 1846 | K13: 3937
A14: 200,001 to 500,000 | B14: 38 | C14: 36 | D14: 17 | E14: 5 | F14: 14 | G14: 10724 | H14: 10351 | I14: 4924 | J14: 1516 | K14: 3911
A15: Over 500,000 | B15: 8 | C15: 8 | D15: 4 | E15: 1 | F15: 3 | G15: 7074 | H15: 6951 | I15: 2998 | J15: 1220 | K15: 2734
A16: Principal building activity
A17: Education | B17: 389 | C17: 332 | D17: 244 | E17: 51 | F17: 38 | G17: 12239 | H17: 11905 | I17: 7580 | J17: 1269 | K17: 3057
A18: Food sales | B18: 177 | C18: 177 | D18: 155 | E18: Q | F18: Q | G18: 1252 | H18: 1252 | I18: 883 | J18: Q | K18: Q
A19: Food service | B19: 380 | C19: 379 | D19: 307 | E19: 33 | F19: 39 | G19: 1819 | H19: 1817 | I19: 1449 | J19: 130 | K19: 237
A20: Health care | B20: 157 | C20: 156 | D20: 124 | E20: 22 | F20: 10 | G20: 4155 | H20: 4153 | I20: 2630 | J20: 449 | K20: 1074
A21: Inpatient | B21: 10 | C21: 10 | D21: 6 | E21: Q | F21: 2 | G21: 2374 | H21: 2374 | I21: 1419 | J21: Q | K21: 860
A22: Outpatient | B22: 147 | C22: 146 | D22: 118 | E22: 21 | F22: Q | G22: 1781 | H22: 1779 | I22: 1211 | J22: 354 | K22: Q
A23: Lodging | B23: 158 | C23: 158 | D23: 132 | E23: 7 | F23: 19 | G23: 5826 | H23: 5821 | I23: 4418 | J23: 369 | K23: 1034
A24: Mercantile | B24: 602 | C24: 531 | D24: 342 | E24: 90 | F24: 99 | G24: 11330 | H24: 10960 | I24: 4705 | J24: 1492 | K24: 4763
A25: Retail (other than mall) | B25: 438 | C25: 367 | D25: 270 | E25: 80 | F25: 17 | G25: 5439 | H25: 5070 | I25: 2932 | J25: 1013 | K25: 1125
