Workbook

Sheet About
A1: BGDP BAU Gross Domestic Product
A3: Source: | B3: 2021 Data
B4: BEA
B5: 2025
B6: Industry File Download
B7: https://apps.bea.gov/iTable/?isuri=1&reqid=151&step=1
B8: Value Added by Industry
B10: Projections
B11: EIA
B12: 2026
B13: Annual Energy Outlook 2026
B14: https://www.eia.gov/outlooks/aeo/tables_ref.php
B15: Table 20
B16: Alternative Electricity and Transportation
A17: Notes
A18: We use historical data from BEA for 2021 and 2022, then scale by the growth in GDP in the AEO.
A20: 0.84730413 | B20: 2021 to 2012 USD
A21: 0.78452102 | B21: 2022 to 2012 USD
A22: 0.75350342 | B22: 2023 to 2012 USD
A23: 0.73191601 | B23: 2024 to 2012 USD

Sheet BEA Data
A1: 2025 Data: | B1: [Millions of dollars] | C1: (nominal)
A2: Line | C2: ISIC Code | D2: 2021 | E2: 2022 | F2: 2023 | G2: 2024
A3: 1 | B3: Gross domestic product | D3: 23725645 | E3: 26054614 | F3: 27811517 | G3: 29298013
C5: in 2012 USD: | D5: {=D3:G3*TRANSPOSE(About!A20:A23)} -> 20102837 | E5: 20440392 | F5: 20956073 | G5: 21443685

Sheet AEO 2025 Table 20
A1: Table 20. Macroeconomic Indicators
A2: https://www.eia.gov/outlooks/aeo/data/browser/#/?id=18-AEO2025&cases=highZTC&sourcekey=0
A3: Tue Dec 02 2025 13:21:36 GMT-0800 (Pacific Standard Time)
A4: Source: U.S. Energy Information Administration | H4: =G6/F6*'BEA Data'!G5 -> 21910371
B5: full name | C5: api key | D5: units | E5: 2023 | F5: 2024 | G5: 2025 | H5: 2026 | I5: 2027 | J5: 2028 | K5: 2029 | L5: 2030 | M5: 2031 | N5: 2032 | O5: 2033 | P5: 2034 | Q5: 2035 | R5: 2036 | S5: 2037 | T5: 2038 | U5: 2039 | V5: 2040 | W5: 2041 | X5: 2042 | Y5: 2043 | Z5: 2044 | AA5: 2045 | AB5: 2046 | AC5: 2047 | AD5: 2048 | AE5: 2049 | AF5: 2050 | AG5: Growth (2024-2050)
A6: Real Gross Domestic Product | B6: Macroeconomic Indicators: Real Gross Domestic Product: High Zero-Carbon Technology Cost | C6: AEO.2025.HIGHZTC.ECI_NA_NA_NA_GDP_REAL_NA_BLNY09DLR.A | D6: billion 2012 $ | F6: 21699.672 | G6: 22171.93 | H6: 22685.953 | I6: 23162.596 | J6: 23590.016 | K6: 24042.869 | L6: 24479.318 | M6: 24877.939 | N6: 25299.824 | O6: 25731.902 | P6: 26166.297 | Q6: 26621.836 | R6: 27077.875 | S6: 27546.342 | T6: 28018.711 | U6: 28503.035 | V6: 29003.939 | W6: 29486.92 | X6: 29991.914 | Y6: 30494.672 | Z6: 30998.293 | AA6: 31501.85 | AB6: 32021.367 | AC6: 32546.51 | AD6: 33074.625 | AE6: 33617.656 | AF6: 34162.723 | AG6: 0.018
A7: Components of Real Gross Domestic Product
A8: Real Consumption | B8: Macroeconomic Indicators: GDP Components: Real Consumption: High Zero-Carbon Technology Cost | C8: AEO.2025.HIGHZTC.ECI_NA_NA_NA_GDP_RCNSP_NA_BLNY09DLR.A | D8: billion 2012 $ | F8: 15151.049 | G8: 15524.572 | H8: 15926.875 | I8: 16368.39 | J8: 16790.758 | K8: 17202.305 | L8: 17601.26 | M8: 17987.453 | N8: 18384.164 | O8: 18798.506 | P8: 19221.488 | Q8: 19634.119 | R8: 20038.617 | S8: 20454.438 | T8: 20860.752 | U8: 21268.02 | V8: 21682.088 | W8: 22091.867 | X8: 22505.357 | Y8: 22920.322 | Z8: 23337.055 | AA8: 23747.721 | AB8: 24165.93 | AC8: 24601.738 | AD8: 25052.125 | AE8: 25519.373 | AF8: 25983.877 | AG8: 0.021
A9: Real Business Fixed Investment | B9: Macroeconomic Indicators: GDP Components: Real Business Fixed Investment: High Zero-Carbon Technology Cost | C9: AEO.2025.HIGHZTC.ECI_NA_NA_NA_GDP_RINV_NA_BLNY09DLR.A | D9: billion 2012 $ | F9: 3493.9402 | G9: 3594.2749 | H9: 3649.9651 | I9: 3702.7681 | J9: 3743.2593 | K9: 3788.8196 | L9: 3847.7334 | M9: 3920.041 | N9: 4008.1609 | O9: 4113.0161 | P9: 4230.084 | Q9: 4347.6567 | R9: 4442.9697 | S9: 4543.9966 | T9: 4646.4092 | U9: 4749.9126 | V9: 4858.6167 | W9: 4967.812 | X9: 5077.7266 | Y9: 5191.708 | Z9: 5302.5923 | AA9: 5413.7686 | AB9: 5525.9058 | AC9: 5645.5312 | AD9: 5763.8345 | AE9: 5887.2368 | AF9: 6010.665 | AG9: 0.021
A10: Real Government Spending | B10: Macroeconomic Indicators: GDP Components: Real Government Spending: High Zero-Carbon Technology Cost | C10: AEO.2025.HIGHZTC.ECI_NA_NA_NA_GDP_RGSP_NA_BLNY09DLR.A | D10: billion 2012 $ | F10: 3663.0996 | G10: 3692.6582 | H10: 3702.4294 | I10: 3705.2068 | J10: 3700.4521 | K10: 3692.9424 | L10: 3692.6365 | M10: 3683.7205 | N10: 3684.8179 | O10: 3687.0542 | P10: 3686.1519 | Q10: 3695.8171 | R10: 3716.4253 | S10: 3739.5742 | T10: 3763.7507 | U10: 3787.4893 | V10: 3815.9573 | W10: 3832.676 | X10: 3856.4805 | Y10: 3879.9495 | Z10: 3900.8938 | AA10: 3921.02 | AB10: 3941.8579 | AC10: 3959.2688 | AD10: 3977.9834 | AE10: 3997.874 | AF10: 4025.7573 | AG10: 0.004
A11: Real Exports | B11: Macroeconomic Indicators: GDP Components: Real Exports: High Zero-Carbon Technology Cost | C11: AEO.2025.HIGHZTC.ECI_NA_NA_NA_GDP_REXP_NA_BLNY09DLR.A | D11: billion 2012 $ | F11: 2721.9966 | G11: 2817.2947 | H11: 2907.7732 | I11: 3020.0054 | J11: 3130.0764 | K11: 3230.9099 | L11: 3328.4602 | M11: 3416.293 | N11: 3509.2991 | O11: 3589.1208 | P11: 3685.4812 | Q11: 3762.8726 | R11: 3821.4929 | S11: 3883.9851 | T11: 3946.6619 | U11: 4015.3748 | V11: 4087.001 | W11: 4157.4023 | X11: 4230.5415 | Y11: 4302.79 | Z11: 4378.002 | AA11: 4441.7432 | AB11: 4512.8193 | AC11: 4584.1948 | AD11: 4643.1548 | AE11: 4699.0835 | AF11: 4750.3662 | AG11: 0.022
A12: Real Imports | B12: Macroeconomic Indicators: GDP Components: Real Imports: High Zero-Carbon Technology Cost | C12: AEO.2025.HIGHZTC.ECI_NA_NA_NA_GDP_RIMP_NA_BLNY09DLR.A | D12: billion 2012 $ | F12: 4085.1304 | G12: 4233.8345 | H12: 4349.9331 | I12: 4482.4502 | J12: 4617.8198 | K12: 4748.7231 | L12: 4891.5942 | M12: 5038.96 | N12: 5209.8481 | O12: 5367.5698 | P12: 5568.1763 | Q12: 5712.3799 | R12: 5821.2363 | S12: 5943.6084 | T12: 6033.5254 | U12: 6125.2974 | V12: 6213.2671 | W12: 6286.7271 | X12: 6369.7358 | Y12: 6443.5234 | Z12: 6522.7334 | AA12: 6587.8569 | AB12: 6664.9497 | AC12: 6768.4185 | AD12: 6865.8984 | AE12: 6979.1406 | AF12: 7082.5068 | AG12: 0.021
A13: Energy Intensity
A14: (thousand Btu per 2012 dollar of GDP)
A15: Delivered Energy | B15: Macroeconomic Indicators: Energy Intensity: Delivered Energy: High Zero-Carbon Technology Cost | C15: AEO.2025.HIGHZTC.INY_NA_NA_NA_DELE_NA_NA_THBTUPDLRGDP.A | D15: thousand Btu/$ GDP | F15: 3.428446 | G15: 3.411206 | H15: 3.342017 | I15: 3.275083 | J15: 3.217942 | K15: 3.154305 | L15: 3.091216 | M15: 3.032044 | N15: 2.970481 | O15: 2.904588 | P15: 2.84617 | Q15: 2.788277 | R15: 2.734798 | S15: 2.68155 | T15: 2.632799 | U15: 2.587637 | V15: 2.546635 | W15: 2.505724 | X15: 2.464391 | Y15: 2.426893 | Z15: 2.392449 | AA15: 2.360774 | AB15: 2.328157 | AC15: 2.300343 | AD15: 2.269897 | AE15: 2.242767 | AF15: 2.216291 | AG15: -0.017
A16: Total Energy | B16: Macroeconomic Indicators: Energy Intensity: Total Energy: High Zero-Carbon Technology Cost | C16: AEO.2025.HIGHZTC.INY_NA_NA_NA_TEN_NA_NA_THBTUPDLRGDP.A | D16: thousand Btu/$ GDP | F16: 4.32228 | G16: 4.264395 | H16: 4.132428 | I16: 4.030019 | J16: 3.951152 | K16: 3.870462 | L16: 3.775505 | M16: 3.693105 | N16: 3.590498 | O16: 3.506058 | P16: 3.429272 | Q16: 3.349698 | R16: 3.276012 | S16: 3.197353 | T16: 3.133636 | U16: 3.060143 | V16: 3.011317 | W16: 2.969604 | X16: 2.926789 | Y16: 2.885433 | Z16: 2.847558 | AA16: 2.809716 | AB16: 2.77065 | AC16: 2.737859 | AD16: 2.703419 | AE16: 2.672775 | AF16: 2.639816 | AG16: -0.019
A17: Price Indices
A18: GDP Chain-type Price Index (2012=1.000) | B18: Macroeconomic Indicators: Price Indices: GDP Chain-type Price Index: High Zero-Carbon Technology Cost | C18: AEO.2025.HIGHZTC.ECI_INDX_NA_NA_GDP_NA_NA_Y09EQ1D3Z.A | D18: 2012=1.000 | F18: 1.343117 | G18: 1.37063 | H18: 1.393811 | I18: 1.417134 | J18: 1.443964 | K18: 1.469734 | L18: 1.497355 | M18: 1.528316 | N18: 1.560939 | O18: 1.59519 | P18: 1.630786 | Q18: 1.666277 | R18: 1.700817 | S18: 1.736221 | T18: 1.772393 | U18: 1.808899 | V18: 1.846825 | W18: 1.88623 | X18: 1.926926 | Y18: 1.969164 | Z18: 2.012674 | AA18: 2.057508 | AB18: 2.103435 | AC18: 2.151106 | AD18: 2.200072 | AE18: 2.250369 | AF18: 2.302053 | AG18: 0.021
A19: Consumer Price Index (1982-84=1.00)
A20: All-urban | B20: Macroeconomic Indicators: Consumer Price Index: All-Urban: High Zero-Carbon Technology Cost | C20: AEO.2025.HIGHZTC.ECI_INDX_NA_NA_CPI_URB_NA_IDX82TO84EQ1.A | D20: 1982-84=1.00 | F20: 3.133236 | G20: 3.18731 | H20: 3.243816 | I20: 3.29739 | J20: 3.358501 | K20: 3.419744 | L20: 3.48402 | M20: 3.553799 | N20: 3.626987 | O20: 3.70384 | P20: 3.783029 | Q20: 3.862728 | R20: 3.941548 | S20: 4.02279 | T20: 4.106466 | U20: 4.191313 | V20: 4.278983 | W20: 4.372421 | X20: 4.468499 | Y20: 4.569344 | Z20: 4.672993 | AA20: 4.780564 | AB20: 4.890984 | AC20: 5.0058 | AD20: 5.123957 | AE20: 5.246688 | AF20: 5.373349 | AG20: 0.021
A21: Energy Commodities and Services | B21: Macroeconomic Indicators: Consumer Price Index: Energy Commodities and Services: High Zero-Carbon Technology Cost | C21: AEO.2025.HIGHZTC.ECI_INDX_NA_NA_CPI_ENE_NA_IDX82TO84EQ1.A | D21: 1982-84=1.00 | F21: 2.792508 | G21: 2.691455 | H21: 2.687613 | I21: 2.652168 | J21: 2.694916 | K21: 2.754513 | L21: 2.822355 | M21: 2.904072 | N21: 2.985838 | O21: 3.074229 | P21: 3.154155 | Q21: 3.222357 | R21: 3.283375 | S21: 3.345484 | T21: 3.41182 | U21: 3.473768 | V21: 3.537099 | W21: 3.624193 | X21: 3.703975 | Y21: 3.798629 | Z21: 3.885333 | AA21: 3.978532 | AB21: 4.071112 | AC21: 4.17385 | AD21: 4.280673 | AE21: 4.404905 | AF21: 4.542088 | AG21: 0.019
A22: Wholesale Price Index (1982=1.00)
A23: All Commodities | B23: Macroeconomic Indicators: Wholesale Price Index: All Commodities: High Zero-Carbon Technology Cost | C23: AEO.2025.HIGHZTC.ECI_INDX_NA_NA_WHP_NA_NA_IDX82EQ1.A | D23: 1982=1.00 | F23: 2.544483 | G23: 2.536922 | H23: 2.52845 | I23: 2.525562 | J23: 2.550341 | K23: 2.579834 | L23: 2.619156 | M23: 2.668178 | N23: 2.726175 | O23: 2.789146 | P23: 2.847746 | Q23: 2.89746 | R23: 2.941257 | S23: 2.990532 | T23: 3.043014 | U23: 3.092615 | V23: 3.145597 | W23: 3.206867 | X23: 3.267742 | Y23: 3.331159 | Z23: 3.391821 | AA23: 3.45685 | AB23: 3.521263 | AC23: 3.589466 | AD23: 3.660784 | AE23: 3.739734 | AF23: 3.822432 | AG23: 0.016
A24: Fuel and Power | B24: Macroeconomic Indicators: Wholesale Price Index: Fuel and Power: High Zero-Carbon Technology Cost | C24: AEO.2025.HIGHZTC.ECI_INDX_NA_NA_WHP_FULP_NA_IDX82EQ1.A | D24: 1982=1.00 | F24: 2.310759 | G24: 2.320295 | H24: 2.303557 | I24: 2.275027 | J24: 2.318662 | K24: 2.382703 | L24: 2.459605 | M24: 2.541698 | N24: 2.647537 | O24: 2.771688 | P24: 2.876411 | Q24: 2.950422 | R24: 3.007536 | S24: 3.068552 | T24: 3.136262 | U24: 3.193604 | V24: 3.256008 | W24: 3.34528 | X24: 3.429423 | Y24: 3.523086 | Z24: 3.602231 | AA24: 3.695193 | AB24: 3.781319 | AC24: 3.872714 | AD24: 3.971825 | AE24: 4.096216 | AF24: 4.237024 | AG24: 0.024
A25: Metals and Metal Products | B25: Macroeconomic Indicators: Wholesale Price Index: Metals and Metal Products: High Zero-Carbon Technology Cost | C25: AEO.2025.HIGHZTC.ECI_INDX_NA_NA_WHP_MET_NA_IDX82EQ1.A | D25: 1982=1.00 | F25: 3.032147 | G25: 2.860675 | H25: 2.788216 | I25: 2.763405 | J25: 2.74133 | K25: 2.739916 | L25: 2.764125 | M25: 2.812309 | N25: 2.861876 | O25: 2.903126 | P25: 2.943663 | Q25: 2.968103 | R25: 2.997323 | S25: 3.04296 | T25: 3.089376 | U25: 3.133001 | V25: 3.182893 | W25: 3.233063 | X25: 3.282713 | Y25: 3.329767 | Z25: 3.375909 | AA25: 3.42059 | AB25: 3.467509 | AC25: 3.520473 | AD25: 3.57451 | AE25: 3.631343 | AF25: 3.683043 | AG25: 0.008
A26: Industrial Commodities excluding Energy | B26: Macroeconomic Indicators: Wholesale Price Index: Industrial Commodities Excluding Energy: High Zero-Carbon Technology Cost | C26: AEO.2025.HIGHZTC.ECI_INDX_NA_NA_WHP_INDCOM_NA_IDX82EQ1.A | D26: 1982=1.00 | F26: 2.584583 | G26: 2.578931 | H26: 2.570989 | I26: 2.575217 | J26: 2.591711 | K26: 2.608134 | L26: 2.636302 | M26: 2.675857 | N26: 2.721102 | O26: 2.768586 | P26: 2.817564 | Q26: 2.862855 | R26: 2.904735 | S26: 2.953261 | T26: 3.004182 | U26: 3.054205 | V26: 3.107413 | W26: 3.163722 | X26: 3.220893 | Y26: 3.278532 | Z26: 3.336572 | AA26: 3.396411 | AB26: 3.457436 | AC26: 3.522192 | AD26: 3.588874 | AE26: 3.658511 | AF26: 3.728199 | AG26: 0.014
A27: Interest Rates (percentage | B27: nominal)
A28: Federal Funds Rate | B28: Macroeconomic Indicators: Interest Rates: Federal Funds Rate: High Zero-Carbon Technology Cost | C28: AEO.2025.HIGHZTC.ECI_FFR_NA_NA_NA_NA_NA_PCNTN.A | D28: percent, nominal | F28: 5.145988 | G28: 3.788913 | H28: 2.638171 | I28: 2.623136 | J28: 2.623651 | K28: 2.624111 | L28: 2.623967 | M28: 2.623016 | N28: 2.623715 | O28: 2.625211 | P28: 2.62642 | Q28: 2.627128 | R28: 2.627128 | S28: 2.627128 | T28: 2.627128 | U28: 2.627128 | V28: 2.627128 | W28: 2.627128 | X28: 2.627128 | Y28: 2.627128 | Z28: 2.627128 | AA28: 2.627128 | AB28: 2.627128 | AC28: 2.627128 | AD28: 2.627128 | AE28: 2.627128 | AF28: 2.627128 | AG28: -0.026
A29: 10-Year Treasury Note | B29: Macroeconomic Indicators: Interest Rates: 10-Year Treasury Note: High Zero-Carbon Technology Cost | C29: AEO.2025.HIGHZTC.ECI_TNR10_NA_NA_NA_NA_NA_PCNTN.A | D29: percent, nominal | F29: 4.076191 | G29: 3.481254 | H29: 3.280257 | I29: 3.187414 | J29: 3.166135 | K29: 3.182389 | L29: 3.213074 | M29: 3.235777 | N29: 3.245176 | O29: 3.24564 | P29: 3.257311 | Q29: 3.271183 | R29: 3.280437 | S29: 3.281555 | T29: 3.27677 | U29: 3.274115 | V29: 3.266999 | W29: 3.26056 | X29: 3.260744 | Y29: 3.26487 | Z29: 3.273189 | AA29: 3.280186 | AB29: 3.290334 | AC29: 3.30423 | AD29: 3.309904 | AE29: 3.312296 | AF29: 3.317643 | AG29: -0.008
A30: AA Utility Bond Rate | B30: Macroeconomic Indicators: Interest Rates: AA Utility Bond Rate: High Zero-Carbon Technology Cost | C30: AEO.2025.HIGHZTC.ECI_AAUTR_NA_NA_NA_NA_NA_PCNTN.A | D30: percent, nominal | F30: 5.39535 | G30: 5.215527 | H30: 5.132888 | I30: 5.046895 | J30: 5.031319 | K30: 5.018938 | L30: 5.001282 | M30: 4.983429 | N30: 4.99271 | O30: 5.025341 | P30: 5.034194 | Q30: 5.057391 | R30: 5.061762 | S30: 5.038929 | T30: 5.03973 | U30: 5.029006 | V30: 4.991193 | W30: 4.98222 | X30: 4.979214 | Y30: 4.996862 | Z30: 4.991411 | AA30: 5.0238 | AB30: 5.033196 | AC30: 5.048281 | AD30: 5.03838 | AE30: 5.04697 | AF30: 5.087938 | AG30: -0.002
A31: Value of Shipments (billion 2012 dollars)
A32: Non-Industrial and Service Sectors | B32: Macroeconomic Indicators: Value of Shipments: Non-Industrial: High Zero-Carbon Technology Cost | C32: AEO.2025.HIGHZTC.ECI_VOS_NIND_NA_NA_NA_NA_BLNY09DLR.A | D32: billion 2012 $ | F32: 28226.229 | G32: 28832.504 | H32: 29531.828 | I32: 30358.59 | J32: 31193.047 | K32: 31916.195 | L32: 32552.965 | M32: 33193.348 | N32: 33870.484 | O32: 34561.387 | P32: 35260.016 | Q32: 35955.832 | R32: 36628.492 | S32: 37306.129 | T32: 37972.012 | U32: 38639.688 | V32: 39328.715 | W32: 40017.156 | X32: 40711.211 | Y32: 41405.953 | Z32: 42105.754 | AA32: 42813.266 | AB32: 43534.359 | AC32: 44293.555 | AD32: 45075.363 | AE32: 45888.055 | AF32: 46699.145 | AG32: 0.02
A33: Total Industrial | B33: Macroeconomic Indicators: Value of Shipments: Total Industrial: High Zero-Carbon Technology Cost | C33: AEO.2025.HIGHZTC.ECI_VOS_IDAL_NA_NA_NA_NA_BLNY09DLR.A | D33: billion 2012 $ | F33: 8693.2148 | G33: 8880.0215 | H33: 9023.8906 | I33: 9136.9658 | J33: 9250.2949 | K33: 9368.2051 | L33: 9471.4043 | M33: 9544.3271 | N33: 9631.375 | O33: 9680.8301 | P33: 9759.0693 | Q33: 9833.1797 | R33: 9910.9326 | S33: 9985.4941 | T33: 10063.266 | U33: 10146.551 | V33: 10240.19 | W33: 10320.27 | X33: 10409.383 | Y33: 10482.778 | Z33: 10564.852 | AA33: 10653.48 | AB33: 10756.962 | AC33: 10868.238 | AD33: 10969.667 | AE33: 11079.729 | AF33: 11173.776 | AG33: 0.01
A34: Agriculture | B34: Mining | C34: and Construction | D34: Macroeconomic Indicators: Value of Shipments: Agriculture, Mining, and Construction: High Zero-Carbon Technology Cost | E34: AEO.2025.HIGHZTC.ECI_VOS_NMFG_NA_NA_NA_NA_BLNY09DLR.A | F34: billion 2012 $ | H34: 2718.2505 | I34: 2777.918 | J34: 2803.5085 | K34: 2839.2778 | L34: 2891.1875 | M34: 2948.4795 | N34: 2992.1099 | O34: 3020.3398 | P34: 3053.4861 | Q34: 3066.2 | R34: 3074.7314 | S34: 3093.0898 | T34: 3117.248 | U34: 3128.8452 | V34: 3144.9646 | W34: 3159.1543 | X34: 3177.1714 | Y34: 3191.8076 | Z34: 3212.5195 | AA34: 3226.1709 | AB34: 3241.9814 | AC34: 3269.1504 | AD34: 3302.4121 | AE34: 3332.9824 | AF34: 3363.4294 | AG34: 3398.2007 | AH34: 3430.1721 | AI34: 0.009
A35: Manufacturing | B35: Macroeconomic Indicators: Value of Shipments: Manufacturing: High Zero-Carbon Technology Cost | C35: AEO.2025.HIGHZTC.ECI_VOS_MANF_NA_NA_NA_NA_BLNY09DLR.A | D35: billion 2012 $ | F35: 5974.9644 | G35: 6102.103 | H35: 6220.3818 | I35: 6297.6885 | J35: 6359.1064 | K35: 6419.7251 | L35: 6479.2939 | M35: 6523.9873 | N35: 6577.8887 | O35: 6614.6299 | P35: 6684.3379 | Q35: 6740.0898 | R35: 6793.6846 | S35: 6856.6494 | T35: 6918.3008 | U35: 6987.3965 | V35: 7063.019 | W35: 7128.4624 | X35: 7196.8633 | Y35: 7256.6074 | Z35: 7322.8701 | AA35: 7384.3301 | AB35: 7454.5503 | AC35: 7535.2554 | AD35: 7606.2373 | AE35: 7681.5273 | AF35: 7743.604 | AG35: 0.01
A36: Energy-Intensive | B36: Macroeconomic Indicators: Value of Shipments: Energy-Intensive: High Zero-Carbon Technology Cost | C36: AEO.2025.HIGHZTC.ECI_VOS_EINT_NA_NA_NA_NA_BLNY09DLR.A | D36: billion 2012 $ | F36: 2316.677 | G36: 2344.0679 | H36: 2344.7004 | I36: 2344.4561 | J36: 2339.9897 | K36: 2341.4043 | L36: 2345.9622 | M36: 2352.5459 | N36: 2357.4746 | O36: 2357.0366 | P36: 2364.6448 | Q36: 2371.5659 | R36: 2377.9558 | S36: 2386.4595 | T36: 2396.3582 | U36: 2410.375 | V36: 2428.2468 | W36: 2443.2141 | X36: 2458.0295 | Y36: 2472.5491 | Z36: 2488.7952 | AA36: 2501.2651 | AB36: 2515.979 | AC36: 2536.9199 | AD36: 2552.4993 | AE36: 2569.5615 | AF36: 2586.6147 | AG36: 0.004
A37: Non-Energy-Intensive | B37: Macroeconomic Indicators: Value of Shipments: Non-Energy-Intensive: High Zero-Carbon Technology Cost | C37: AEO.2025.HIGHZTC.ECI_VOS_NEINT_NA_NA_NA_NA_BLNY09DLR.A | D37: billion 2012 $ | F37: 3658.2871 | G37: 3758.0356 | H37: 3875.6812 | I37: 3953.2327 | J37: 4019.1172 | K37: 4078.3218 | L37: 4133.3311 | M37: 4171.4424 | N37: 4220.415 | O37: 4257.5938 | P37: 4319.6934 | Q37: 4368.5234 | R37: 4415.7285 | S37: 4470.1904 | T37: 4521.9424 | U37: 4577.021 | V37: 4634.7725 | W37: 4685.2485 | X37: 4738.834 | Y37: 4784.0586 | Z37: 4834.0747 | AA37: 4883.0659 | AB37: 4938.5713 | AC37: 4998.3364 | AD37: 5053.7378 | AE37: 5111.9658 | AF37: 5156.9897 | AG37: 0.013
A38: Total Shipments | B38: Macroeconomic Indicators: Value of Shipments: Total: High Zero-Carbon Technology Cost | C38: AEO.2025.HIGHZTC.ECI_VOS_NA_NA_NA_NA_NA_BLNY09DLR.A | D38: billion 2012 $ | F38: 36919.445 | G38: 37712.523 | H38: 38555.719 | I38: 39495.555 | J38: 40443.344 | K38: 41284.398 | L38: 42024.367 | M38: 42737.676 | N38: 43501.859 | O38: 44242.219 | P38: 45019.086 | Q38: 45789.012 | R38: 46539.426 | S38: 47291.625 | T38: 48035.277 | U38: 48786.238 | V38: 49568.906 | W38: 50337.426 | X38: 51120.594 | Y38: 51888.73 | Z38: 52670.605 | AA38: 53466.746 | AB38: 54291.32 | AC38: 55161.793 | AD38: 56045.031 | AE38: 56967.781 | AF38: 57872.922 | AG38: 0.017
A39: Population and Employment (millions)
A40: Population | B40: with Armed Forces Overseas | C40: Macroeconomic Indicators: Population, with Armed Forces Overseas: High Zero-Carbon Technology Cost | D40: AEO.2025.HIGHZTC.DMG_POP_PWAF_NA_NA_NA_NA_MILL.A | E40: millions | G40: 342.00198 | H40: 344.85077 | I40: 346.96423 | J40: 348.43741 | K40: 349.87805 | L40: 351.28119 | M40: 352.64179 | N40: 353.9574 | O40: 355.23047 | P40: 356.45853 | Q40: 357.63406 | R40: 358.73593 | S40: 359.77283 | T40: 360.75125 | U40: 361.67264 | V40: 362.53564 | W40: 363.34354 | X40: 364.09573 | Y40: 364.79132 | Z40: 365.43613 | AA40: 366.03445 | AB40: 366.59067 | AC40: 367.10648 | AD40: 367.58792 | AE40: 368.03946 | AF40: 368.46582 | AG40: 368.87057 | AH40: 0.003
...

Sheet AEO 2026 Table 20
A1: Table 20. Macroeconomic Indicators
A2: https://www.eia.gov/outlooks/aeo/data/browser/#/?id=18-AEO2026&cases=electrnp&sourcekey=0
A3: Thu Apr 23 2026 15:00:34 GMT-0700 (Pacific Daylight Time)
A4: Source: U.S. Energy Information Administration
B5: full name | C5: api key | D5: units | E5: 2025 | F5: 2026 | G5: 2027 | H5: 2028 | I5: 2029 | J5: 2030 | K5: 2031 | L5: 2032 | M5: 2033 | N5: 2034 | O5: 2035 | P5: 2036 | Q5: 2037 | R5: 2038 | S5: 2039 | T5: 2040 | U5: 2041 | V5: 2042 | W5: 2043 | X5: 2044 | Y5: 2045 | Z5: 2046 | AA5: 2047 | AB5: 2048 | AC5: 2049 | AD5: 2050 | AE5: Growth (2025-2050)
A6: Real Gross Domestic Product | B6: Macroeconomic Indicators: Real Gross Domestic Product: Alternative Electricity and Transportation | C6: AEO.2026.ELECTRNP.ECI_NA_NA_NA_GDP_REAL_NA_BLNY09DLR.A | D6: billion 2012 $ | E6: 22086.084 | F6: 22669.975 | G6: 23095.641 | H6: 23390.617 | I6: 23750.76 | J6: 24166.652 | K6: 24572.645 | L6: 25034.145 | M6: 25522.301 | N6: 26041.154 | O6: 26595.578 | P6: 27063.66 | Q6: 27531.34 | R6: 28000.277 | S6: 28461.051 | T6: 28925.545 | U6: 29375.912 | V6: 29841.965 | W6: 30321.672 | X6: 30806.215 | Y6: 31294.172 | Z6: 31769.938 | AA6: 32226.467 | AB6: 32681.023 | AC6: 33125.082 | AD6: 33582.949 | AE6: 0.017
A7: Components of Real Gross Domestic Product
A8: Real Consumption | B8: Macroeconomic Indicators: GDP Components: Real Consumption: Alternative Electricity and Transportation | C8: AEO.2026.ELECTRNP.ECI_NA_NA_NA_GDP_RCNSP_NA_BLNY09DLR.A | D8: billion 2012 $ | E8: 15470.457 | F8: 15745.258 | G8: 16077.065 | H8: 16443.414 | I8: 16808.172 | J8: 17210.961 | K8: 17613.143 | L8: 18045.73 | M8: 18508.07 | N8: 18995.17 | O8: 19504.887 | P8: 19969.223 | Q8: 20418.203 | R8: 20862.244 | S8: 21285.115 | T8: 21701.123 | U8: 22115.762 | V8: 22530.051 | W8: 22959.676 | X8: 23398.494 | Y8: 23833.768 | Z8: 24265.73 | AA8: 24688.705 | AB8: 25114.117 | AC8: 25538.404 | AD8: 25973.34 | AE8: 0.021
A9: Real Business Fixed Investment | B9: Macroeconomic Indicators: GDP Components: Real Business Fixed Investment: Alternative Electricity and Transportation | C9: AEO.2026.ELECTRNP.ECI_NA_NA_NA_GDP_RINV_NA_BLNY09DLR.A | D9: billion 2012 $ | E9: 3563.6355 | F9: 3578.6487 | G9: 3636.2075 | H9: 3675.7742 | I9: 3739.9631 | J9: 3828.8762 | K9: 3932.9365 | L9: 4064.687 | M9: 4220.5518 | N9: 4389.6118 | O9: 4577.1562 | P9: 4708.251 | Q9: 4803.7773 | R9: 4906.7871 | S9: 5008.8701 | T9: 5115.3516 | U9: 5224.2739 | V9: 5330.0991 | W9: 5439.5435 | X9: 5548.8521 | Y9: 5656.4873 | Z9: 5759.6855 | AA9: 5856.4038 | AB9: 5955.8071 | AC9: 6052.5615 | AD9: 6153.7349 | AE9: 0.022
A10: Real Government Spending | B10: Macroeconomic Indicators: GDP Components: Real Government Spending: Alternative Electricity and Transportation | C10: AEO.2026.ELECTRNP.ECI_NA_NA_NA_GDP_RGSP_NA_BLNY09DLR.A | D10: billion 2012 $ | E10: 3737.1343 | F10: 3772.5564 | G10: 3775.8491 | H10: 3765.7637 | I10: 3760.9731 | J10: 3758.6948 | K10: 3745.5552 | L10: 3742.2781 | M10: 3740.5403 | N10: 3740.7231 | O10: 3741.604 | P10: 3755.5669 | Q10: 3777.7124 | R10: 3798.313 | S10: 3816.7888 | T10: 3839.5361 | U10: 3850.3596 | V10: 3869.3965 | W10: 3887.5898 | X10: 3907.699 | Y10: 3928.4329 | Z10: 3946.7456 | AA10: 3963.8059 | AB10: 3979.4841 | AC10: 3992.6289 | AD10: 4010.4639 | AE10: 0.003
A11: Real Exports | B11: Macroeconomic Indicators: GDP Components: Real Exports: Alternative Electricity and Transportation | C11: AEO.2026.ELECTRNP.ECI_NA_NA_NA_GDP_REXP_NA_BLNY09DLR.A | D11: billion 2012 $ | E11: 2741.9917 | F11: 2835.4888 | G11: 2965.7207 | H11: 3053.7249 | I11: 3141.342 | J11: 3221.0476 | K11: 3296.947 | L11: 3370.6318 | M11: 3442.1299 | N11: 3516.7747 | O11: 3600.7878 | P11: 3663.314 | Q11: 3717.0537 | R11: 3773.1755 | S11: 3830.6138 | T11: 3891.9331 | U11: 3953.2131 | V11: 4015.3606 | W11: 4078.2385 | X11: 4136.7773 | Y11: 4201.0942 | Z11: 4263.4404 | AA11: 4324.4824 | AB11: 4377.5757 | AC11: 4423.9746 | AD11: 4471.9355 | AE11: 0.02
A12: Real Imports | B12: Macroeconomic Indicators: GDP Components: Real Imports: Alternative Electricity and Transportation | C12: AEO.2026.ELECTRNP.ECI_NA_NA_NA_GDP_RIMP_NA_BLNY09DLR.A | D12: billion 2012 $ | E12: 4186.7524 | F12: 4022.1733 | G12: 4147.2222 | H12: 4320.2764 | I12: 4507.0161 | J12: 4704.0293 | K12: 4907.7056 | L12: 5125.8799 | M12: 5352.9961 | N12: 5587.9282 | O12: 5844.6904 | P12: 6048.5542 | Q12: 6204.1309 | R12: 6358.2119 | S12: 6485.8809 | T12: 6615.105 | U12: 6735.519 | V12: 6867.3271 | W12: 6990.7378 | X12: 7119.168 | Y12: 7268.3828 | Z12: 7422.4976 | AA12: 7583.2998 | AB12: 7741.9419 | AC12: 7900.0137 | AD12: 8086.9849 | AE12: 0.027
A13: Energy Intensity
A14: (thousand Btu per 2012 dollar of GDP)
A15: Delivered Energy | B15: Macroeconomic Indicators: Energy Intensity: Delivered Energy: Alternative Electricity and Transportation | C15: AEO.2026.ELECTRNP.INY_NA_NA_NA_DELE_NA_NA_THBTUPDLRGDP.A | D15: thousand Btu/$ GDP | E15: 3.439244 | F15: 3.350909 | G15: 3.29415 | H15: 3.255929 | I15: 3.19607 | J15: 3.139376 | K15: 3.082243 | L15: 3.026489 | M15: 2.967935 | N15: 2.916056 | O15: 2.860977 | P15: 2.816053 | Q15: 2.772426 | R15: 2.731513 | S15: 2.694315 | T15: 2.65988 | U15: 2.627352 | V15: 2.595521 | W15: 2.564102 | X15: 2.532736 | Y15: 2.503596 | Z15: 2.474786 | AA15: 2.450853 | AB15: 2.423894 | AC15: 2.396323 | AD15: 2.370422 | AE15: -0.015
A16: Total Energy | B16: Macroeconomic Indicators: Energy Intensity: Total Energy: Alternative Electricity and Transportation | C16: AEO.2026.ELECTRNP.INY_NA_NA_NA_TEN_NA_NA_THBTUPDLRGDP.A | D16: thousand Btu/$ GDP | E16: 4.314489 | F16: 4.218206 | G16: 4.078142 | H16: 4.003045 | I16: 3.920406 | J16: 3.841981 | K16: 3.754112 | L16: 3.676647 | M16: 3.602411 | N16: 3.530866 | O16: 3.459574 | P16: 3.401268 | Q16: 3.348348 | R16: 3.299749 | S16: 3.254078 | T16: 3.209533 | U16: 3.167369 | V16: 3.128416 | W16: 3.090411 | X16: 3.052857 | Y16: 3.017984 | Z16: 2.983811 | AA16: 2.955237 | AB16: 2.923449 | AC16: 2.88939 | AD16: 2.858316 | AE16: -0.016
A17: Price Indices
A18: GDP Chain-type Price Index (2012=1.000) | B18: Macroeconomic Indicators: Price Indices: GDP Chain-type Price Index: Alternative Electricity and Transportation | C18: AEO.2026.ELECTRNP.ECI_INDX_NA_NA_GDP_NA_NA_Y09EQ1D3Z.A | D18: 2012=1.000 | E18: 1.383637 | F18: 1.421667 | G18: 1.448645 | H18: 1.478788 | I18: 1.509192 | J18: 1.540631 | K18: 1.572918 | L18: 1.605325 | M18: 1.639644 | N18: 1.673843 | O18: 1.709171 | P18: 1.744338 | Q18: 1.778532 | R18: 1.813455 | S18: 1.848656 | T18: 1.884722 | U18: 1.920868 | V18: 1.957016 | W18: 1.993336 | X18: 2.029829 | Y18: 2.066643 | Z18: 2.104074 | AA18: 2.142279 | AB18: 2.18149 | AC18: 2.2211 | AD18: 2.260831 | AE18: 0.02
A19: Consumer Price Index (1982-84=1.00)
A20: All-urban | B20: Macroeconomic Indicators: Consumer Price Index: All-Urban: Alternative Electricity and Transportation | C20: AEO.2026.ELECTRNP.ECI_INDX_NA_NA_CPI_URB_NA_IDX82TO84EQ1.A | D20: 1982-84=1.00 | E20: 3.224163 | F20: 3.299957 | G20: 3.363701 | H20: 3.431324 | I20: 3.501327 | J20: 3.575855 | K20: 3.651944 | L20: 3.728562 | M20: 3.810579 | N20: 3.889556 | O20: 3.972642 | P20: 4.055532 | Q20: 4.137613 | R20: 4.220924 | S20: 4.305421 | T20: 4.391723 | U20: 4.478698 | V20: 4.566073 | W20: 4.653815 | X20: 4.742461 | Y20: 4.834256 | Z20: 4.927659 | AA20: 5.023974 | AB20: 5.123249 | AC20: 5.224092 | AD20: 5.323658 | AE20: 0.02
A21: Energy Commodities and Services | B21: Macroeconomic Indicators: Consumer Price Index: Energy Commodities and Services: Alternative Electricity and Transportation | C21: AEO.2026.ELECTRNP.ECI_INDX_NA_NA_CPI_ENE_NA_IDX82TO84EQ1.A | D21: 1982-84=1.00 | E21: 2.773167 | F21: 2.699711 | G21: 2.694441 | H21: 2.730387 | I21: 2.795724 | J21: 2.888529 | K21: 2.986886 | L21: 3.073357 | M21: 3.189636 | N21: 3.256396 | O21: 3.349661 | P21: 3.438492 | Q21: 3.534943 | R21: 3.625857 | S21: 3.71479 | T21: 3.802111 | U21: 3.88752 | V21: 3.973053 | W21: 4.048632 | X21: 4.120994 | Y21: 4.213217 | Z21: 4.302158 | AA21: 4.403974 | AB21: 4.514734 | AC21: 4.621875 | AD21: 4.717258 | AE21: 0.021
A22: Wholesale Price Index (1982=1.00)
A23: All Commodities | B23: Macroeconomic Indicators: Wholesale Price Index: All Commodities: Alternative Electricity and Transportation | C23: AEO.2026.ELECTRNP.ECI_INDX_NA_NA_WHP_NA_NA_IDX82EQ1.A | D23: 1982=1.00 | E23: 2.591355 | F23: 2.597289 | G23: 2.626654 | H23: 2.655499 | I23: 2.693941 | J23: 2.746304 | K23: 2.80189 | L23: 2.853223 | M23: 2.910415 | N23: 2.959416 | O23: 3.016569 | P23: 3.073467 | Q23: 3.133204 | R23: 3.196835 | S23: 3.259201 | T23: 3.323803 | U23: 3.38692 | V23: 3.446613 | W23: 3.503907 | X23: 3.561005 | Y23: 3.62564 | Z23: 3.695196 | AA23: 3.768493 | AB23: 3.845382 | AC23: 3.921381 | AD23: 3.997225 | AE23: 0.017
A24: Fuel and Power | B24: Macroeconomic Indicators: Wholesale Price Index: Fuel and Power: Alternative Electricity and Transportation | C24: AEO.2026.ELECTRNP.ECI_INDX_NA_NA_WHP_FULP_NA_IDX82EQ1.A | D24: 1982=1.00 | E24: 2.242908 | F24: 2.199618 | G24: 2.225608 | H24: 2.267588 | I24: 2.342907 | J24: 2.446827 | K24: 2.552402 | L24: 2.628374 | M24: 2.727046 | N24: 2.797092 | O24: 2.883656 | P24: 2.963107 | Q24: 3.04702 | R24: 3.130187 | S24: 3.208749 | T24: 3.28886 | U24: 3.354087 | V24: 3.404894 | W24: 3.442159 | X24: 3.47821 | Y24: 3.536491 | Z24: 3.608317 | AA24: 3.69306 | AB24: 3.783067 | AC24: 3.865132 | AD24: 3.938273 | AE24: 0.023
A25: Metals and Metal Products | B25: Macroeconomic Indicators: Wholesale Price Index: Metals and Metal Products: Alternative Electricity and Transportation | C25: AEO.2026.ELECTRNP.ECI_INDX_NA_NA_WHP_MET_NA_IDX82EQ1.A | D25: 1982=1.00 | E25: 3.202144 | F25: 3.17322 | G25: 3.169432 | H25: 3.162961 | I25: 3.166607 | J25: 3.197945 | K25: 3.232062 | L25: 3.27933 | M25: 3.322896 | N25: 3.365797 | O25: 3.412253 | P25: 3.454753 | Q25: 3.505802 | R25: 3.567842 | S25: 3.624778 | T25: 3.687192 | U25: 3.752452 | V25: 3.814663 | W25: 3.879371 | X25: 3.941341 | Y25: 4.011244 | Z25: 4.086101 | AA25: 4.15933 | AB25: 4.238098 | AC25: 4.313878 | AD25: 4.397111 | AE25: 0.013
A26: Industrial Commodities excluding Energy | B26: Macroeconomic Indicators: Wholesale Price Index: Industrial Commodities Excluding Energy: Alternative Electricity and Transportation | C26: AEO.2026.ELECTRNP.ECI_INDX_NA_NA_WHP_INDCOM_NA_IDX82EQ1.A | D26: 1982=1.00 | E26: 2.662289 | F26: 2.704771 | G26: 2.73811 | H26: 2.759989 | I26: 2.784223 | J26: 2.821728 | K26: 2.863219 | L26: 2.908752 | M26: 2.95659 | N26: 3.003484 | O26: 3.056471 | P26: 3.11063 | Q26: 3.167595 | R26: 3.230385 | S26: 3.292784 | T26: 3.357944 | U26: 3.425665 | V26: 3.493071 | W26: 3.561416 | X26: 3.629889 | Y26: 3.702253 | Z26: 3.77741 | AA26: 3.853839 | AB26: 3.933667 | AC26: 4.014669 | AD26: 4.098438 | AE26: 0.017
A27: Interest Rates (percentage | B27: nominal)
A28: Federal Funds Rate | B28: Macroeconomic Indicators: Interest Rates: Federal Funds Rate: Alternative Electricity and Transportation | C28: AEO.2026.ELECTRNP.ECI_FFR_NA_NA_NA_NA_NA_PCNTN.A | D28: percent, nominal | E28: 4.328587 | F28: 3.471333 | G28: 2.875 | H28: 2.920516 | I28: 3.125 | J28: 3.125 | K28: 3.125 | L28: 3.125 | M28: 3.125 | N28: 3.125 | O28: 3.125 | P28: 3.125 | Q28: 3.125 | R28: 3.125 | S28: 3.125 | T28: 3.125 | U28: 3.125 | V28: 3.125 | W28: 3.125 | X28: 3.125 | Y28: 3.125 | Z28: 3.125 | AA28: 3.125 | AB28: 3.125 | AC28: 3.125 | AD28: 3.125 | AE28: -0.013
A29: 10-Year Treasury Note | B29: Macroeconomic Indicators: Interest Rates: 10-Year Treasury Note: Alternative Electricity and Transportation | C29: AEO.2026.ELECTRNP.ECI_TNR10_NA_NA_NA_NA_NA_PCNTN.A | D29: percent, nominal | E29: 4.359502 | F29: 4.021862 | G29: 3.892701 | H29: 3.930959 | I29: 3.989025 | J29: 4.000497 | K29: 3.975329 | L29: 3.949521 | M29: 3.932374 | N29: 3.902812 | O29: 3.887719 | P29: 3.889442 | Q29: 3.893909 | R29: 3.908684 | S29: 3.911668 | T29: 3.907815 | U29: 3.900185 | V29: 3.887692 | W29: 3.872872 | X29: 3.852367 | Y29: 3.839636 | Z29: 3.832254 | AA29: 3.831839 | AB29: 3.843084 | AC29: 3.859855 | AD29: 3.872646 | AE29: -0.005
A30: AA Utility Bond Rate | B30: Macroeconomic Indicators: Interest Rates: AA Utility Bond Rate: Alternative Electricity and Transportation | C30: AEO.2026.ELECTRNP.ECI_AAUTR_NA_NA_NA_NA_NA_PCNTN.A | D30: percent, nominal | E30: 5.777357 | F30: 5.770922 | G30: 5.738921 | H30: 5.72926 | I30: 5.729354 | J30: 5.699732 | K30: 5.665697 | L30: 5.628308 | M30: 5.606607 | N30: 5.600248 | O30: 5.55746 | P30: 5.582308 | Q30: 5.592952 | R30: 5.608163 | S30: 5.628979 | T30: 5.609316 | U30: 5.599217 | V30: 5.591004 | W30: 5.569545 | X30: 5.544533 | Y30: 5.521287 | Z30: 5.507062 | AA30: 5.514881 | AB30: 5.532126 | AC30: 5.568912 | AD30: 5.580168 | AE30: -0.001
A31: Value of Shipments (billion 2012 dollars)
A32: Non-Industrial and Service Sectors | B32: Macroeconomic Indicators: Value of Shipments: Non-Industrial: Alternative Electricity and Transportation | C32: AEO.2026.ELECTRNP.ECI_VOS_NIND_NA_NA_NA_NA_BLNY09DLR.A | D32: billion 2012 $ | E32: 29310.039 | F32: 30023.715 | G32: 30766.252 | H32: 31515.33 | I32: 32089.752 | J32: 32683.012 | K32: 33302.93 | L32: 33955.328 | M32: 34627.875 | N32: 35322.406 | O32: 36045.23 | P32: 36780.773 | Q32: 37524.594 | R32: 38263.555 | S32: 38972.633 | T32: 39668.195 | U32: 40357.141 | V32: 41045.812 | W32: 41749.961 | X32: 42474.762 | Y32: 43209.52 | Z32: 43937.121 | AA32: 44650.023 | AB32: 45374.547 | AC32: 46099.578 | AD32: 46845.535 | AE32: 0.019
A33: Total Industrial | B33: Macroeconomic Indicators: Value of Shipments: Total Industrial: Alternative Electricity and Transportation | C33: AEO.2026.ELECTRNP.ECI_VOS_IDAL_NA_NA_NA_NA_BLNY09DLR.A | D33: billion 2012 $ | E33: 8703.1973 | F33: 8752.5635 | G33: 8860.085 | H33: 8925.2109 | I33: 8996.9727 | J33: 9096.0137 | K33: 9180.3887 | L33: 9280.9082 | M33: 9357.7578 | N33: 9436.4336 | O33: 9520.166 | P33: 9604.2979 | Q33: 9697.3643 | R33: 9786.8828 | S33: 9878.123 | T33: 9974.8271 | U33: 10069.033 | V33: 10166.394 | W33: 10253.316 | X33: 10343.383 | Y33: 10450.387 | Z33: 10563.197 | AA33: 10674.792 | AB33: 10773.287 | AC33: 10876.104 | AD33: 10975.348 | AE33: 0.009
A34: Agriculture | B34: Mining | C34: and Construction | D34: Macroeconomic Indicators: Value of Shipments: Agriculture, Mining, and Construction: Alternative Electricity and Transportation | E34: AEO.2026.ELECTRNP.ECI_VOS_NMFG_NA_NA_NA_NA_BLNY09DLR.A | F34: billion 2012 $ | G34: 2803.3442 | H34: 2871.4666 | I34: 2881.314 | J34: 2905.5051 | K34: 2942.6826 | L34: 2994.1714 | M34: 3039.165 | N34: 3083.4395 | O34: 3117.4536 | P34: 3149.9683 | Q34: 3179.4119 | R34: 3207.2556 | S34: 3233.686 | T34: 3258.1426 | U34: 3282.6372 | V34: 3307.2117 | W34: 3331.6807 | X34: 3357.1152 | Y34: 3380.1191 | Z34: 3401.7805 | AA34: 3431.3511 | AB34: 3462.2949 | AC34: 3493.667 | AD34: 3521.9922 | AE34: 3550.4158 | AF34: 3579.9399 | AG34: 0.01
A35: Manufacturing | B35: Macroeconomic Indicators: Value of Shipments: Manufacturing: Alternative Electricity and Transportation | C35: AEO.2026.ELECTRNP.ECI_VOS_MANF_NA_NA_NA_NA_BLNY09DLR.A | D35: billion 2012 $ | E35: 5899.8525 | F35: 5881.0972 | G35: 5978.772 | H35: 6019.7056 | I35: 6054.2891 | J35: 6101.8418 | K35: 6141.2236 | L35: 6197.4688 | M35: 6240.3042 | N35: 6286.4653 | O35: 6340.7539 | P35: 6397.0425 | Q35: 6463.6777 | R35: 6528.7402 | S35: 6595.4858 | T35: 6667.6152 | U35: 6737.3516 | V35: 6809.2788 | W35: 6873.1973 | X35: 6941.6021 | Y35: 7019.0356 | Z35: 7100.9023 | AA35: 7181.1245 | AB35: 7251.2944 | AC35: 7325.687 | AD35: 7395.4077 | AE35: 0.009
A36: Energy-Intensive | B36: Macroeconomic Indicators: Value of Shipments: Energy-Intensive: Alternative Electricity and Transportation | C36: AEO.2026.ELECTRNP.ECI_VOS_EINT_NA_NA_NA_NA_BLNY09DLR.A | D36: billion 2012 $ | E36: 2268.0803 | F36: 2262.8013 | G36: 2273.1584 | H36: 2277.8271 | I36: 2273.0415 | J36: 2281.1123 | K36: 2292.3989 | L36: 2305.2056 | M36: 2320.0837 | N36: 2336.4343 | O36: 2354.8857 | P36: 2369.8201 | Q36: 2380.8423 | R36: 2392.5137 | S36: 2409.4175 | T36: 2428.3511 | U36: 2449.6045 | V36: 2469.7427 | W36: 2485.3384 | X36: 2500.5459 | Y36: 2517.7095 | Z36: 2539.0469 | AA36: 2562.5078 | AB36: 2580.4128 | AC36: 2597.0923 | AD36: 2616.8943 | AE36: 0.006
A37: Non-Energy-Intensive | B37: Macroeconomic Indicators: Value of Shipments: Non-Energy-Intensive: Alternative Electricity and Transportation | C37: AEO.2026.ELECTRNP.ECI_VOS_NEINT_NA_NA_NA_NA_BLNY09DLR.A | D37: billion 2012 $ | E37: 3631.772 | F37: 3618.2966 | G37: 3705.6135 | H37: 3741.8794 | I37: 3781.2473 | J37: 3820.7292 | K37: 3848.8247 | L37: 3892.2627 | M37: 3920.2212 | N37: 3950.0315 | O37: 3985.8687 | P37: 4027.2222 | Q37: 4082.8354 | R37: 4136.2271 | S37: 4186.0684 | T37: 4239.2642 | U37: 4287.7466 | V37: 4339.5361 | W37: 4387.8584 | X37: 4441.0562 | Y37: 4501.3262 | Z37: 4561.8555 | AA37: 4618.6162 | AB37: 4670.8818 | AC37: 4728.5952 | AD37: 4778.5137 | AE37: 0.011
A38: Total Shipments | B38: Macroeconomic Indicators: Value of Shipments: Total: Alternative Electricity and Transportation | C38: AEO.2026.ELECTRNP.ECI_VOS_NA_NA_NA_NA_NA_BLNY09DLR.A | D38: billion 2012 $ | E38: 38013.234 | F38: 38776.277 | G38: 39626.336 | H38: 40440.539 | I38: 41086.727 | J38: 41779.023 | K38: 42483.32 | L38: 43236.234 | M38: 43985.633 | N38: 44758.84 | O38: 45565.398 | P38: 46385.07 | Q38: 47221.957 | R38: 48050.438 | S38: 48850.758 | T38: 49643.023 | U38: 50426.172 | V38: 51212.207 | W38: 52003.277 | X38: 52818.145 | Y38: 53659.906 | Z38: 54500.32 | AA38: 55324.816 | AB38: 56147.836 | AC38: 56975.68 | AD38: 57820.883 | AE38: 0.017
A39: Population and Employment (millions)
A40: Population | B40: with Armed Forces Overseas | C40: Macroeconomic Indicators: Population, with Armed Forces Overseas: Alternative Electricity and Transportation | D40: AEO.2026.ELECTRNP.DMG_POP_PWAF_NA_NA_NA_NA_MILL.A | E40: millions | F40: 341.75317 | G40: 343.01141 | H40: 344.24216 | I40: 345.60837 | J40: 347.09195 | K40: 348.5 | L40: 349.84818 | M40: 351.13016 | N40: 352.35477 | O40: 353.52618 | P40: 354.64002 | Q40: 355.69449 | R40: 356.68884 | S40: 357.62469 | T40: 358.50104 | U40: 359.31769 | V40: 360.06976 | W40: 360.76502 | X40: 361.40601 | Y40: 361.99826 | Z40: 362.54215 | AA40: 363.04501 | AB40: 363.51031 | AC40: 363.94165 | AD40: 364.34549 | AE40: 364.72809 | AF40: 0.003
...

Sheet calcs
E2: 2024 | F2: 2025 | G2: 2026 | H2: 2027 | I2: 2028 | J2: 2029 | K2: 2030 | L2: 2031 | M2: 2032 | N2: 2033 | O2: 2034 | P2: 2035 | Q2: 2036 | R2: 2037 | S2: 2038 | T2: 2039 | U2: 2040 | V2: 2041 | W2: 2042 | X2: 2043 | Y2: 2044 | Z2: 2045 | AA2: 2046 | AB2: 2047 | AC2: 2048 | AD2: 2049 | AE2: 2050
A3: Real Gross Domestic Product | B3: Macroeconomic Indicators: Real Gross Domestic Product: High Zero-Carbon Technology Cost | C3: AEO.2025.HIGHZTC.ECI_NA_NA_NA_GDP_REAL_NA_BLNY09DLR.A | D3: billion 2012 $ | E3: ='AEO 2025 Table 20'!F6 -> 21699.672 | F3: ='AEO 2026 Table 20'!E6 -> 22086.084 | G3: ='AEO 2026 Table 20'!F6 -> 22669.975 | H3: ='AEO 2026 Table 20'!G6 -> 23095.641 | I3: ='AEO 2026 Table 20'!H6 -> 23390.617 | J3: ='AEO 2026 Table 20'!I6 -> 23750.76 | K3: ='AEO 2026 Table 20'!J6 -> 24166.652 | L3: ='AEO 2026 Table 20'!K6 -> 24572.645 | M3: ='AEO 2026 Table 20'!L6 -> 25034.145 | ... AE3: ='AEO 2026 Table 20'!AD6 -> 33582.949

Sheet BGDP
A1: Unit: 2012 USD | B1: GDP {2025+ recomputed: AEO 2026 ELECTRNP real-GDP growth, 2025 spliced vs AEO 2025 (consistent with the Table-23 industrial rates); <=2024 unchanged BEA-anchored history. Scheme-independent: 42-code BGDP == 52-code BGDP (no ISIC dimension).}
A2: 2024 | B2: ='BEA Data'!G5*10^6 -> 2.1443685e+13
A3: 2025 | B3: =B2*(1+(('AEO 2026 Table 20'!E6-'AEO 2025 Table 20'!F6)/'AEO 2025 Table 20'!F6)) -> 2.1825538e+13
A4: 2026 | B4: =B3*(1+('AEO 2026 Table 20'!F6/'AEO 2026 Table 20'!E6-1)) -> 2.2402541e+13
A5: 2027 | B5: =B4*(1+('AEO 2026 Table 20'!G6/'AEO 2026 Table 20'!F6-1)) -> 2.2823185e+13
A6: 2028 | B6: =B5*(1+('AEO 2026 Table 20'!H6/'AEO 2026 Table 20'!G6-1)) -> 2.3114682e+13
A7: 2029 | B7: =B6*(1+('AEO 2026 Table 20'!I6/'AEO 2026 Table 20'!H6-1)) -> 2.3470576e+13
A8: 2030 | B8: =B7*(1+('AEO 2026 Table 20'!J6/'AEO 2026 Table 20'!I6-1)) -> 2.3881563e+13
A9: 2031 | B9: =B8*(1+('AEO 2026 Table 20'!K6/'AEO 2026 Table 20'!J6-1)) -> 2.4282765e+13
A10: 2032 | B10: =B9*(1+('AEO 2026 Table 20'!L6/'AEO 2026 Table 20'!K6-1)) -> 2.4738821e+13
A11: 2033 | B11: =B10*(1+('AEO 2026 Table 20'!M6/'AEO 2026 Table 20'!L6-1)) -> 2.5221219e+13
A12: 2034 | B12: =B11*(1+('AEO 2026 Table 20'!N6/'AEO 2026 Table 20'!M6-1)) -> 2.5733951e+13
A13: 2035 | B13: =B12*(1+('AEO 2026 Table 20'!O6/'AEO 2026 Table 20'!N6-1)) -> 2.6281835e+13
A14: 2036 | B14: =B13*(1+('AEO 2026 Table 20'!P6/'AEO 2026 Table 20'!O6-1)) -> 2.6744395e+13
A15: 2037 | B15: =B14*(1+('AEO 2026 Table 20'!Q6/'AEO 2026 Table 20'!P6-1)) -> 2.7206557e+13
A16: 2038 | B16: =B15*(1+('AEO 2026 Table 20'!R6/'AEO 2026 Table 20'!Q6-1)) -> 2.7669963e+13
A17: 2039 | B17: =B16*(1+('AEO 2026 Table 20'!S6/'AEO 2026 Table 20'!R6-1)) -> 2.8125301e+13
A18: 2040 | B18: =B17*(1+('AEO 2026 Table 20'!T6/'AEO 2026 Table 20'!S6-1)) -> 2.8584315e+13
A19: 2041 | B19: =B18*(1+('AEO 2026 Table 20'!U6/'AEO 2026 Table 20'!T6-1)) -> 2.902937e+13
A20: 2042 | B20: =B19*(1+('AEO 2026 Table 20'!V6/'AEO 2026 Table 20'!U6-1)) -> 2.9489924e+13
A21: 2043 | B21: =B20*(1+('AEO 2026 Table 20'!W6/'AEO 2026 Table 20'!V6-1)) -> 2.9963972e+13
A22: 2044 | B22: =B21*(1+('AEO 2026 Table 20'!X6/'AEO 2026 Table 20'!W6-1)) -> 3.0442799e+13
A23: 2045 | B23: =B22*(1+('AEO 2026 Table 20'!Y6/'AEO 2026 Table 20'!X6-1)) -> 3.0925e+13
A24: 2046 | B24: =B23*(1+('AEO 2026 Table 20'!Z6/'AEO 2026 Table 20'!Y6-1)) -> 3.1395153e+13
A25: 2047 | B25: =B24*(1+('AEO 2026 Table 20'!AA6/'AEO 2026 Table 20'!Z6-1)) -> 3.1846297e+13
A26: 2048 | B26: =B25*(1+('AEO 2026 Table 20'!AB6/'AEO 2026 Table 20'!AA6-1)) -> 3.2295491e+13
A27: 2049 | B27: =B26*(1+('AEO 2026 Table 20'!AC6/'AEO 2026 Table 20'!AB6-1)) -> 3.2734311e+13
A28: 2050 | B28: =B27*(1+('AEO 2026 Table 20'!AD6/'AEO 2026 Table 20'!AC6-1)) -> 3.3186777e+13
