Workbook

Sheet About
A1: AVIC Annual Vehicle Insurance Cost
A3: Source: | B3: Passenger LDVs
B4: Insurify
B5: 2025
B6: EVs Cost 49% More to Insure Than Gas-Powered Cars, Data Reveals
B7: https://insurify.com/car-insurance/report/electric-vehicle-insurance-costs/
B9: Freight LDVs
B10: Car and Driver magazine
B11: 2021
B12: Commercial Auto Insurance Cost: Everything You Need to Know
B13: https://www.caranddriver.com/car-insurance/a36232977/commercial-auto-insurance-cost/
B15: Freight HDVs
B16: Progressive Commercial
B17: undated
B18: What does commercial truck insurance cost?
B19: https://www.progressivecommercial.com/commercial-auto-insurance/truck-insurance/commercial-truck-insurance-cost/
B21: Passenger HDVs (buses)
B22: Bus Insurance HQ
B23: undated
B24: https://www.businsurancehq.com/bus-insurance-cost/
B26: Passenger Motorbikes
B27: Matt Timmons
B28: 2021
B29: Average Cost of Motorcycle Insurance (2022)
B30: https://www.valuepenguin.com/average-cost-of-motorcycle-insurance
B32: BEV Markup for Freight LDVs/HDVs and Passenger HDVs
B33: CCJ
B34: 2025
B35: Why zero-emission trucks often cost 30-50% more to insure than diesel models
B36: https://www.ccjdigital.com/business/article/15753084/why-zeroemission-truck-insurance-costs-can-wipe-out-fuel-savings
A38: Notes
A39: Data on insurnace costs for LDVs, HDVs, and motorbikes is relatively available online, as these vehicles are often
A40: used by individuals or small owner-operator businesses (e.g. trucking firms, tourist buses, etc.) that need
A41: insurance quotes.
A43: Insurance costs for rail, commercial airlines, and freight shipping is harder to come by. It appears these firms
A44: often buy policies covering a broader share of company operations, not just individual vehicles. For instance,
A45: a railroad's insurance might cover up to $X million in damages/liability from covered causes across the railroad's
A46: entire system, and would include things like damage caused by spills, collisions, etc.
A47: It appears that per-vehicle insurance may not be the correct way to price insurance costs for commercial
A48: airlines, rail, or freight shipping, so we leave those values set to zero in this variable.
...

Sheet Data
A1: Passenger LDVs
A3: Data from Insurify:
A4: Passenger LDV, gasoline | B4: 2732 | C4: $/yr (2025 USD)
A5: Passenger LDV, battery electric | B5: 4058 | C5: $/yr (2025 USD)
A7: Freight LDVs
A9: Using data from Car and Driver magazine (2021):
B11: Low | C11: High | D11: Simple Avg
A12: standard car used for business purposes | B12: 600 | C12: 2400 | D12: =AVERAGE(B12:C12) -> 1500 | E12: $/yr (2021 USD)
A13: Limousine | B13: 4000 | C13: 10000 | D13: =AVERAGE(B13:C13) -> 7000 | E13: $/yr (2021 USD)
A14: Cargo or delivery van | B14: 3300 | C14: 6200 | D14: =AVERAGE(B14:C14) -> 4750 | E14: $/yr (2021 USD)
A15: Taxi | B15: 5000 | C15: 10000 | D15: =AVERAGE(B15:C15) -> 7500 | E15: $/yr (2021 USD)
A16: Semi-truck | B16: 8000 | C16: 12500 | D16: =AVERAGE(B16:C16) -> 10250 | E16: $/yr (2021 USD)
A18: For freight LDVs, the value for "cargo or delivery van" is most appropriate.
A20: Freight HDVs
A22: Avg. for specialty truckers | B22: 640 | C22: $/mth
A23: Avg. for transport truckers | B23: 982 | C23: $/mth
A24: Overall simple average | B24: =AVERAGE(B22:B23) -> 811 | C24: $/mth
A25: Annualized | B25: =B24*12 -> 9732 | C25: $/yr
A27: Likely includes primary liability insurance, physical damage insurance, occupational accident coverage, and general liability insurance.
A28: For more on these insurance types, see https://www.caranddriver.com/car-insurance/a36320549/truck-insurance-cost/
A30: Passenger HDVs (buses)
A32: 50-state average | B32: 9420 | C32: $/yr
A34: Passenger Motorbikes
A36: Timmons (2021):
A38: 50-state average | B38: 721 | C38: $/yr (2021 USD)

Sheet AVIC-passenger
A1: 2012 USD/year | B1: battery electric vehicle | C1: natural gas vehicle | D1: gasoline vehicle | E1: diesel vehicle | F1: plugin hybrid vehicle | G1: LPG vehicle | H1: hydrogen vehicle
A2: LDVs | B2: =Data!B5*About!A61 -> 2893.7963 | C2: =D2 -> 1948.2138 | D2: =Data!B4*About!A61 -> 1948.2138 | E2: =D2 -> 1948.2138 | F2: =AVERAGE(D2,B2) -> 2421.0051 | G2: =D2 -> 1948.2138 | H2: =B2 -> 2893.7963
A3: HDVs | B3: =D3*1.4 -> 11174.247 | C3: =D3 -> 7981.6049 | D3: =Data!B32*About!A60 -> 7981.6049 | E3: =D3 -> 7981.6049 | F3: =AVERAGE(D3,B3) -> 9577.9259 | G3: =D3 -> 7981.6049 | H3: =B3 -> 11174.247
A4: aircraft | B4: 0 | C4: =B4 -> 0 | D4: =C4 -> 0 | E4: =D4 -> 0 | F4: =E4 -> 0 | G4: =F4 -> 0 | H4: =G4 -> 0
A5: rail | B5: 0 | C5: =B5 -> 0 | D5: =C5 -> 0 | E5: =D5 -> 0 | F5: =E5 -> 0 | G5: =F5 -> 0 | H5: =G5 -> 0
A6: ships | B6: 0 | C6: =B6 -> 0 | D6: =C6 -> 0 | E6: =D6 -> 0 | F6: =E6 -> 0 | G6: =F6 -> 0 | H6: =G6 -> 0
A7: motorbikes | B7: =Data!B38*About!A60 -> 610.90628 | C7: =B7 -> 610.90628 | D7: =C7 -> 610.90628 | E7: =D7 -> 610.90628 | F7: =E7 -> 610.90628 | G7: =F7 -> 610.90628 | H7: =G7 -> 610.90628

Sheet AVIC-freight
A1: 2012 USD/year | B1: battery electric vehicle | C1: natural gas vehicle | D1: gasoline vehicle | E1: diesel vehicle | F1: plugin hybrid vehicle | G1: LPG vehicle | H1: hydrogen vehicle
A2: LDVs | B2: =E2*1.4 -> 5634.5725 | C2: =E2 -> 4024.6946 | D2: =E2 -> 4024.6946 | E2: =Data!D14*About!A60 -> 4024.6946 | F2: =AVERAGE(E2,B2) -> 4829.6335 | G2: =B2 -> 5634.5725 | H2: =B2 -> 5634.5725
A3: HDVs | B3: =E3*1.4 -> 11544.349 | C3: =E3 -> 8245.9638 | D3: =E3 -> 8245.9638 | E3: =Data!B25*About!A60 -> 8245.9638 | F3: =AVERAGE(E3,B3) -> 9895.1565 | G3: =B3 -> 11544.349 | H3: =B3 -> 11544.349
A4: aircraft | B4: =E4 -> 0 | C4: =E4 -> 0 | D4: =E4 -> 0 | E4: 0 | F4: =AVERAGE(E4,B4) -> 0 | G4: =B4 -> 0 | H4: =B4 -> 0
A5: rail | B5: =E5 -> 0 | C5: =E5 -> 0 | D5: =E5 -> 0 | E5: 0 | F5: =AVERAGE(E5,B5) -> 0 | G5: =B5 -> 0 | H5: =B5 -> 0
A6: ships | B6: =E6 -> 0 | C6: =E6 -> 0 | D6: =E6 -> 0 | E6: 0 | F6: =AVERAGE(E6,B6) -> 0 | G6: =B6 -> 0 | H6: =B6 -> 0
A7: motorbikes | B7: =E7 -> 0 | C7: =E7 -> 0 | D7: =E7 -> 0 | E7: 0 | F7: =AVERAGE(E7,B7) -> 0 | G7: =B7 -> 0 | H7: =B7 -> 0
