Workbook

Sheet About
A1: SoCEUtiNTY Share of Components Energy Use that is New This Year
A3: Sources: | B3: Share of commercial floorspace that is new
B4: U.S. Energy Information Administration
B5: 2025
B6: Annual Energy Outlook 2025
B7: Scenario: High zero-carbon technology cost
B8: Table 5
B9: https://www.eia.gov/outlooks/aeo/tables_side_xls.php
B11: Number of homes
B12: U.S. Energy Information Administration
B13: 2026
B14: Annual Energy Outlook 2026
B15: Alternative electricity and transportation: Table 4, Table 5
B16: https://www.eia.gov/outlooks/aeo/tables_side_xls.php
B19: Share of homes that are new
B20: EIA
B21: 2020
B22: Residential Demand Module of the National Energy Modeling System: Model Documentation
B23: https://www.eia.gov/outlooks/aeo/nems/documentation/residential/pdf/m067(2020).pdf
B24: Page 58, Existing housing evolution rate
B26: Replacement rate of components in surviving buildings
B27: See bldgs/CL variable
A29: About
A30: This variable is used to estimate the share of BAU component energy use
A31: that is new (i.e. from newly installed components) each year. This includes
A32: both components to serve new buildings (demand growth) and components
A33: to replace retiring components.
A35: The "envelope" value in this variable does not matter, because envelope
A36: does not itself use energy. To avoid confusion, envelope is assigned
A37: a value of zero.
A39: We separately estimate the share of buildings that are new (whose components
A40: are all new) and the share of components in surviving buildings that are
A41: replaced each year. We consider the share of surviving buildings and
A42: new buildings to properly calculate overall component replacement rates.
... A45: to new regions.
A47: Data centers | B47: Data centers use the commercial shares except for IT load ('other component'), which is one over the IT equipment lifetime on the 'Data Centers' tab.

Sheet source data>

Sheet Component Lifetimes
A1: Building Component | B1: Lifetime (yr)
A2: heating | B2: 19
A3: cooling and ventilation | B3: 15.833333
A4: envelope | B4: 51.818182
A5: lighting | B5: 9.1324201
A6: appliances | B6: 13.533333
A7: other component | B7: 15.4

Sheet AEO 2026 Table 4
A1: Table 4. Residential Sector Key Indicators and Consumption
A2: https://www.eia.gov/outlooks/aeo/data/browser/#/?id=4-AEO2026&cases=electrnp&sourcekey=0
A3: Thu Apr 23 2026 14:30:24 GMT-0700 (Pacific Daylight Time)
A4: Source: U.S. Energy Information Administration
B5: full name | C5: api key | D5: units | E5: 2025 | F5: 2026 | G5: 2027 | H5: 2028 | I5: 2029 | J5: 2030 | K5: 2031 | L5: 2032 | M5: 2033 | N5: 2034 | O5: 2035 | P5: 2036 | Q5: 2037 | R5: 2038 | S5: 2039 | T5: 2040 | U5: 2041 | V5: 2042 | W5: 2043 | X5: 2044 | Y5: 2045 | Z5: 2046 | AA5: 2047 | AB5: 2048 | AC5: 2049 | AD5: 2050 | AE5: Growth (2025-2050)
A6: Key Indicators
A7: Households (millions)
A8: Single-Family | B8: Residential: Key Indicators: Households: Single-Family: Alternative Electricity and Transportation | C8: AEO.2026.ELECTRNP.KEI_HHD_RESD_SFR_NA_NA_USA_MILL.A | D8: millions | E8: 89.551808 | F8: 90.49932 | G8: 91.445952 | H8: 92.375528 | I8: 93.308328 | J8: 94.24312 | K8: 95.158208 | L8: 96.071576 | M8: 96.973696 | N8: 97.85328 | O8: 98.71644 | P8: 99.555664 | Q8: 100.3796 | R8: 101.17977 | S8: 101.94854 | T8: 102.6897 | U8: 103.40026 | V8: 104.0939 | W8: 104.76102 | X8: 105.40485 | Y8: 106.04946 | Z8: 106.69842 | AA8: 107.34532 | AB8: 107.99104 | AC8: 108.63598 | AD8: 109.28382 | AE8: 0.8%
A9: Multifamily | B9: Residential: Key Indicators: Households: Multifamily: Alternative Electricity and Transportation | C9: AEO.2026.ELECTRNP.KEI_HHD_RESD_MFR_NA_NA_USA_MILL.A | D9: millions | E9: 34.432312 | F9: 34.836668 | G9: 35.242792 | H9: 35.639104 | I9: 36.037196 | J9: 36.453672 | K9: 36.90364 | L9: 37.355532 | M9: 37.797056 | N9: 38.222764 | O9: 38.636756 | P9: 39.039476 | Q9: 39.397844 | R9: 39.73052 | S9: 40.040472 | T9: 40.33182 | U9: 40.601424 | V9: 40.85396 | W9: 41.099856 | X9: 41.347656 | Y9: 41.597008 | Z9: 41.846876 | AA9: 42.095096 | AB9: 42.342736 | AC9: 42.590232 | AD9: 42.838628 | AE9: 0.9%
A10: Mobile Homes | B10: Residential: Key Indicators: Households: Mobile Homes: Alternative Electricity and Transportation | C10: AEO.2026.ELECTRNP.KEI_HHD_RESD_MBH_NA_NA_USA_MILL.A | D10: millions | E10: 6.745095 | F10: 6.759423 | G10: 6.806991 | H10: 6.858165 | I10: 6.903711 | J10: 6.913014 | K10: 6.915089 | L10: 6.918252 | M10: 6.921087 | N10: 6.923413 | O10: 6.926996 | P10: 6.931356 | Q10: 6.932999 | R10: 6.932745 | S10: 6.927611 | T10: 6.924169 | U10: 6.922683 | V10: 6.921756 | W10: 6.922089 | X10: 6.924877 | Y10: 6.929586 | Z10: 6.934404 | AA10: 6.93933 | AB10: 6.943018 | AC10: 6.946523 | AD10: 6.950291 | AE10: 0.1%
A11: Total | B11: Residential: Key Indicators: Households: Total: Alternative Electricity and Transportation | C11: AEO.2026.ELECTRNP.KEI_HHD_RESD_TEN_NA_NA_USA_MILL.A | D11: millions | E11: 130.72922 | F11: 132.09541 | G11: 133.49573 | H11: 134.8728 | I11: 136.24923 | J11: 137.60981 | K11: 138.97694 | L11: 140.34536 | M11: 141.69184 | N11: 142.99946 | O11: 144.28019 | P11: 145.5265 | Q11: 146.71044 | R11: 147.84303 | S11: 148.91662 | T11: 149.94569 | U11: 150.92436 | V11: 151.86962 | W11: 152.78297 | X11: 153.67738 | Y11: 154.57605 | Z11: 155.4797 | AA11: 156.37975 | AB11: 157.27679 | AC11: 158.17273 | AD11: 159.07273 | AE11: 0.8%
A12: Average House Square Footage | B12: Residential: Key Indicators: Average House Square Footage: Alternative Electricity and Transportation | C12: AEO.2026.ELECTRNP.KEI_HHD_RESD_NA_NA_NA_USA_SQFT.A | D12: sq ft | E12: 1648.5809 | F12: 1653.8009 | G12: 1658.7534 | H12: 1663.6196 | I12: 1668.3839 | J12: 1673.0569 | K12: 1677.3986 | L12: 1681.6154 | M12: 1685.7919 | N12: 1689.9557 | O12: 1694.0829 | P12: 1698.1729 | Q12: 1702.4686 | R12: 1706.8398 | S12: 1711.274 | T12: 1715.7278 | U12: 1720.2239 | V12: 1724.7522 | W12: 1729.2341 | X12: 1733.6156 | Y12: 1737.9188 | Z12: 1742.1624 | AA12: 1746.3572 | AB12: 1750.5023 | AC12: 1754.593 | AD12: 1758.624 | AE12: 0.3%
A13: Energy Intensity
A14: (MMBtu per household)
A15: Gross End-use Consumption | B15: Residential: Household Energy Intensity: Gross End-use Consumption: Alternative Electricity and Transportation | C15: AEO.2026.ELECTRNP.INY_HHD_RESD_DELE_NA_NA_USA_MILLBTUPHOSD.A | D15: MMBtu/household | E15: 89.060958 | F15: 86.654179 | G15: 85.803576 | H15: 85.129928 | I15: 84.070611 | J15: 82.772625 | K15: 81.43822 | L15: 80.199732 | M15: 79.037515 | N15: 78.012084 | O15: 77.086948 | P15: 76.247253 | Q15: 75.471804 | R15: 74.779412 | S15: 74.147297 | T15: 73.529513 | U15: 72.98766 | V15: 72.550301 | W15: 72.19137 | X15: 71.873314 | Y15: 71.554366 | Z15: 71.242594 | AA15: 70.912942 | AB15: 70.590441 | AC15: 70.298459 | AD15: 70.025753 | AE15: -1.0%
A16: Delivered Energy Consumption | B16: Residential: Household Energy Intensity: Delivered Energy Consumption: Alternative Electricity and Transportation | C16: AEO.2026.ELECTRNP.INY_HHD_RESD_TEN_NA_NA_USA_MILLBTUPHOSD.A | D16: MMBtu/household | E16: 87.644801 | F16: 85.169031 | G16: 84.24495 | H16: 83.496612 | I16: 82.368483 | J16: 80.999154 | K16: 79.589086 | L16: 78.275952 | M16: 77.036292 | N16: 75.928768 | O16: 74.916513 | P16: 73.985585 | Q16: 73.112308 | R16: 72.31741 | S16: 71.577848 | T16: 70.8491 | U16: 70.192104 | V16: 69.636396 | W16: 69.156582 | X16: 68.713555 | Y16: 68.267577 | Z16: 67.825555 | AA16: 67.362432 | AB16: 66.902169 | AC16: 66.470931 | AD16: 66.055663 | AE16: -1.1%
A17: (thousand Btu per square foot)
A18: Gross End-use Consumption | B18: Residential: Energy Intensity per Square Foot: Gross End-use Consumption: Alternative Electricity and Transportation | C18: AEO.2026.ELECTRNP.INY_HHD_RESD_DELE_NA_NA_USA_THBTUPSQFT.A | D18: thousand Btu/sq ft | E18: 54.0228 | F18: 52.396983 | G18: 51.727746 | H18: 51.17151 | I18: 50.390447 | J18: 49.473886 | K18: 48.55031 | L18: 47.692079 | M18: 46.884504 | N18: 46.162207 | O18: 45.503646 | P18: 44.899583 | Q18: 44.330805 | R18: 43.811616 | S18: 43.32871 | T18: 42.856165 | U18: 42.429164 | V18: 42.064188 | W18: 41.747597 | X18: 41.458622 | Y18: 41.172444 | Z18: 40.8932 | AA18: 40.606208 | AB18: 40.32582 | AC18: 40.065393 | AD18: 39.81849 | AE18: -1.2%
A19: Delivered Energy Consumption | B19: Residential: Energy Intensity per Square Foot: Delivered Energy Consumption: Alternative Electricity and Transportation | C19: AEO.2026.ELECTRNP.INY_HHD_RESD_TEN_NA_NA_USA_THBTUPSQFT.A | D19: thousand Btu/sq ft | E19: 53.163785 | F19: 51.498963 | G19: 50.788109 | H19: 50.189725 | I19: 49.370221 | J19: 48.413867 | K19: 47.447928 | L19: 46.548072 | M19: 45.697392 | N19: 44.929443 | O19: 44.22246 | P19: 43.567759 | Q19: 42.944878 | R19: 42.369183 | S19: 41.827227 | T19: 41.293905 | U19: 40.804052 | V19: 40.374725 | W19: 39.992608 | X19: 39.635981 | Y19: 39.281223 | Z19: 38.931822 | AA19: 38.573113 | AB19: 38.21884 | AC19: 37.88396 | AD19: 37.560992 | AE19: -1.4%
A20: Energy Consumption by Fuel
A21: Electricity
A22: Space Heating | B22: Residential: Electricity: Space Heating: Alternative Electricity and Transportation | C22: AEO.2026.ELECTRNP.CNSM_HHD_RESD_SPH_ELC_NA_USA_QBTU.A | D22: quads | E22: 0.594987 | F22: 0.565591 | G22: 0.56617 | H22: 0.56695 | I22: 0.565817 | J22: 0.562275 | K22: 0.557641 | L22: 0.553019 | M22: 0.548665 | N22: 0.544101 | O22: 0.539627 | P22: 0.535383 | Q22: 0.530849 | R22: 0.526527 | S22: 0.522045 | T22: 0.517517 | U22: 0.512782 | V22: 0.508507 | W22: 0.504388 | X22: 0.500026 | Y22: 0.495959 | Z22: 0.491539 | AA22: 0.48666 | AB22: 0.481831 | AC22: 0.477193 | AD22: 0.472459 | AE22: -0.9%
A23: Space Cooling | B23: Residential: Electricity: Space Cooling: Alternative Electricity and Transportation | C23: AEO.2026.ELECTRNP.CNSM_NA_RESD_SPC_ELC_NA_USA_QBTU.A | D23: quads | E23: 0.924574 | F23: 0.983886 | G23: 0.997782 | H23: 1.011565 | I23: 1.022745 | J23: 1.029994 | K23: 1.036595 | L23: 1.044131 | M23: 1.052389 | N23: 1.061989 | O23: 1.072572 | P23: 1.084402 | Q23: 1.097 | R23: 1.11012 | S23: 1.123595 | T23: 1.137956 | U23: 1.153139 | V23: 1.170164 | W23: 1.188274 | X23: 1.206452 | Y23: 1.225277 | Z23: 1.243111 | AA23: 1.260267 | AB23: 1.276902 | AC23: 1.294258 | AD23: 1.31138 | AE23: 1.4%
A24: Water Heating | B24: Residential: Electricity: Water Heating: Alternative Electricity and Transportation | C24: AEO.2026.ELECTRNP.CNSM_NA_RESD_WTHT_ELC_NA_USA_QBTU.A | D24: quads | E24: 0.452529 | F24: 0.444829 | G24: 0.439241 | H24: 0.434669 | I24: 0.417931 | J24: 0.396813 | K24: 0.37455 | L24: 0.353889 | M24: 0.334859 | N24: 0.31755 | O24: 0.301886 | P24: 0.288067 | Q24: 0.276008 | R24: 0.265726 | S24: 0.257168 | T24: 0.250335 | U24: 0.24518 | V24: 0.24183 | W24: 0.240263 | X24: 0.238624 | Y24: 0.236984 | Z24: 0.235242 | AA24: 0.233407 | AB24: 0.23158 | AC24: 0.229981 | AD24: 0.228558 | AE24: -2.7%
A25: Refrigeration | B25: Residential: Electricity: Refrigeration: Alternative Electricity and Transportation | C25: AEO.2026.ELECTRNP.CNSM_NA_RESD_REFR_ELC_NA_USA_QBTU.A | D25: quads | E25: 0.349563 | F25: 0.348527 | G25: 0.347433 | H25: 0.346209 | I25: 0.345259 | J25: 0.342024 | K25: 0.33903 | L25: 0.336304 | M25: 0.333799 | N25: 0.331468 | O25: 0.329366 | P25: 0.327653 | Q25: 0.326343 | R25: 0.325461 | S25: 0.32499 | T25: 0.324938 | U25: 0.325294 | V25: 0.326072 | W25: 0.327281 | X25: 0.328913 | Y25: 0.33105 | Z25: 0.333714 | AA25: 0.336865 | AB25: 0.340006 | AC25: 0.343129 | AD25: 0.346229 | AE25: -0.0%
A26: Cooking | B26: Residential: Electricity: Cooking: Alternative Electricity and Transportation | C26: AEO.2026.ELECTRNP.CNSM_NA_RESD_CGR_ELC_NA_USA_QBTU.A | D26: quads | E26: 0.068362 | F26: 0.069242 | G26: 0.07015 | H26: 0.071053 | I26: 0.07196 | J26: 0.07286 | K26: 0.07377 | L26: 0.074686 | M26: 0.075595 | N26: 0.076502 | O26: 0.077415 | P26: 0.078332 | Q26: 0.079236 | R26: 0.080074 | S26: 0.080823 | T26: 0.081486 | U26: 0.082052 | V26: 0.082525 | W26: 0.082965 | X26: 0.083381 | Y26: 0.083789 | Z26: 0.084191 | AA26: 0.084584 | AB26: 0.084967 | AC26: 0.085342 | AD26: 0.085709 | AE26: 0.9%
A27: Clothes Dryers | B27: Residential: Electricity: Clothes Dryers: Alternative Electricity and Transportation | C27: AEO.2026.ELECTRNP.CNSM_NA_RESD_CDR_ELC_NA_USA_QBTU.A | D27: quads | E27: 0.190333 | F27: 0.190841 | G27: 0.191803 | H27: 0.193076 | I27: 0.193741 | J27: 0.193361 | K27: 0.192361 | L27: 0.191029 | M27: 0.19012 | N27: 0.1896 | O27: 0.189483 | P27: 0.189817 | Q27: 0.190518 | R27: 0.191708 | S27: 0.19336 | T27: 0.195529 | U27: 0.198302 | V27: 0.20107 | W27: 0.20391 | X27: 0.206758 | Y27: 0.209611 | Z27: 0.212328 | AA27: 0.214859 | AB27: 0.217261 | AC27: 0.21971 | AD27: 0.222073 | AE27: 0.6%
A28: Freezers | B28: Residential: Electricity: Freezers: Alternative Electricity and Transportation | C28: AEO.2026.ELECTRNP.CNSM_NA_RESD_FRZ_ELC_NA_USA_QBTU.A | D28: quads | E28: 0.079278 | F28: 0.079241 | G28: 0.079217 | H28: 0.07916 | I28: 0.079073 | J28: 0.07857 | K28: 0.078007 | L28: 0.077404 | M28: 0.076823 | N28: 0.076257 | O28: 0.075716 | P28: 0.075195 | Q28: 0.074693 | R28: 0.074214 | S28: 0.073757 | T28: 0.073328 | U28: 0.072937 | V28: 0.072586 | W28: 0.072278 | X28: 0.072012 | Y28: 0.071802 | Z28: 0.07166 | AA28: 0.071579 | AB28: 0.071571 | AC28: 0.071643 | AD28: 0.0718 | AE28: -0.4%
A29: Lighting | B29: Residential: Electricity: Lighting: Alternative Electricity and Transportation | C29: AEO.2026.ELECTRNP.CNSM_NA_RESD_LGHTNG_ELC_NA_USA_QBTU.A | D29: quads | E29: 0.182847 | F29: 0.182216 | G29: 0.183569 | H29: 0.18564 | I29: 0.187439 | J29: 0.186994 | K29: 0.186424 | L29: 0.186261 | M29: 0.186404 | N29: 0.186742 | O29: 0.187215 | P29: 0.187754 | Q29: 0.188226 | R29: 0.188723 | S29: 0.1894 | T29: 0.187035 | U29: 0.185089 | V29: 0.183691 | W29: 0.182846 | X29: 0.182477 | Y29: 0.182384 | Z29: 0.18231 | AA29: 0.182202 | AB29: 0.182192 | AC29: 0.182375 | AD29: 0.182588 | AE29: -0.0%
A30: Clothes Washers | B30: Residential: Electricity: Clothes Washers: Alternative Electricity and Transportation | C30: AEO.2026.ELECTRNP.CNSM_NA_RESD_CLW_ELC_NA_USA_QBTU.A | D30: quads | E30: 0.040723 | F30: 0.039741 | G30: 0.03875 | H30: 0.037583 | I30: 0.036385 | J30: 0.034992 | K30: 0.03354 | L30: 0.032 | M30: 0.030665 | N30: 0.029534 | O30: 0.028609 | P30: 0.027904 | Q30: 0.027429 | R30: 0.02721 | S30: 0.027261 | T30: 0.027311 | U30: 0.027362 | V30: 0.02742 | W30: 0.027486 | X30: 0.027564 | Y30: 0.027658 | Z30: 0.027768 | AA30: 0.02789 | AB30: 0.028024 | AC30: 0.028167 | AD30: 0.028319 | AE30: -1.4%
A31: Dishwashers | B31: Residential: Electricity: Dishwashers: Alternative Electricity and Transportation | C31: AEO.2026.ELECTRNP.CNSM_NA_RESD_DSW_ELC_NA_USA_QBTU.A | D31: quads | E31: 0.037162 | F31: 0.038076 | G31: 0.03836 | H31: 0.038523 | I31: 0.038637 | J31: 0.038703 | K31: 0.03872 | L31: 0.038689 | M31: 0.038734 | N31: 0.038861 | O31: 0.039071 | P31: 0.039371 | Q31: 0.039764 | R31: 0.040262 | S31: 0.040872 | T31: 0.041477 | U31: 0.042076 | V31: 0.042674 | W31: 0.043273 | X31: 0.043876 | Y31: 0.044488 | Z31: 0.045111 | AA31: 0.045741 | AB31: 0.046379 | AC31: 0.047023 | AD31: 0.047676 | AE31: 1.0%
A32: Televisions and Related Equipment | B32: Residential: Electricity: Televisions: Alternative Electricity and Transportation | C32: AEO.2026.ELECTRNP.CNSM_NA_RESD_TVR_ELC_NA_USA_QBTU.A | D32: quads | E32: 0.124839 | F32: 0.122177 | G32: 0.119963 | H32: 0.118088 | I32: 0.116097 | J32: 0.113806 | K32: 0.111516 | L32: 0.109399 | M32: 0.107489 | N32: 0.105735 | O32: 0.104144 | P32: 0.102719 | Q32: 0.101411 | R32: 0.100273 | S32: 0.099267 | T32: 0.098398 | U32: 0.097694 | V32: 0.097154 | W32: 0.096815 | X32: 0.096643 | Y32: 0.096638 | Z32: 0.096759 | AA32: 0.096903 | AB32: 0.097108 | AC32: 0.097404 | AD32: 0.097758 | AE32: -1.0%
A33: Computers and Related Equipment | B33: Residential: Electricity: Computers: Alternative Electricity and Transportation | C33: AEO.2026.ELECTRNP.CNSM_NA_RESD_CMPR_ELC_NA_USA_QBTU.A | D33: quads | E33: 0.097012 | F33: 0.095324 | G33: 0.093865 | H33: 0.092524 | I33: 0.090934 | J33: 0.088982 | K33: 0.086906 | L33: 0.084865 | M33: 0.082885 | N33: 0.080946 | O33: 0.079062 | P33: 0.07725 | Q33: 0.075484 | R33: 0.073799 | S33: 0.072189 | T33: 0.070667 | U33: 0.069258 | V33: 0.06799 | W33: 0.066879 | X33: 0.065919 | Y33: 0.065114 | Z33: 0.064456 | AA33: 0.063893 | AB33: 0.063459 | AC33: 0.063206 | AD33: 0.063082 | AE33: -1.7%
... A39: Purchased Electricity at Residential Location | B39: Residential: Electricity: Purchased Electricity at Residential Location: Alternative Electricity and Transportation | C39: AEO.2026.ELECTRNP.CNSM_NA_RESD_PURCHELEC_ELC_NA_USA_QBTU.A | D39: quads | E39: 5.216623 | F39: 5.257673 | G39: 5.182968 | H39: 5.247639 | I39: 5.291314 | J39: 5.309832 | K39: 5.3177 | L39: 5.32703 | M39: 5.34066 | N39: 5.361271 | O39: 5.386619 | P39: 5.416244 | Q39: 5.448967 | R39: 5.485255 | S39: 5.522946 | T39: 5.555702 | U39: 5.592755 | V39: 5.63542 | W39: 5.683198 | X39: 5.73157 | Y39: 5.777129 | Z39: 5.824309 | AA39: 5.868561 | AB39: 5.911637 | AC39: 5.95669 | AD39: 6.00164 | AE39: 0.6%
A40: Natural Gas
A41: Space Heating | B41: Residential: Natural Gas: Space Heating: Alternative Electricity and Transportation | C41: AEO.2026.ELECTRNP.CNSM_NA_RESD_SPH_NG_NA_USA_QBTU.A | D41: quads | E41: 3.118029 | F41: 2.929732 | G41: 3.047068 | H41: 3.028339 | I41: 2.991961 | J41: 2.947513 | K41: 2.90039 | L41: 2.856502 | M41: 2.813128 | N41: 2.772394 | O41: 2.732819 | P41: 2.695713 | Q41: 2.658051 | R41: 2.62224 | S41: 2.587139 | T41: 2.553313 | U41: 2.519939 | V41: 2.490338 | W41: 2.462606 | X41: 2.436644 | Y41: 2.412093 | Z41: 2.386654 | AA41: 2.359964 | AB41: 2.333602 | AC41: 2.307677 | AD41: 2.28263 | AE41: -1.2%
A42: Space Cooling | B42: Residential: Natural Gas: Space Cooling: Alternative Electricity and Transportation | C42: AEO.2026.ELECTRNP.CNSM_NA_RESD_SPC_NG_NA_USA_QBTU.A | D42: quads | E42: 0.058598 | F42: 0.062155 | G42: 0.06259 | H42: 0.062752 | I42: 0.062711 | J42: 0.062576 | K42: 0.062453 | L42: 0.06243 | M42: 0.062446 | N42: 0.062545 | O42: 0.062667 | P42: 0.062853 | Q42: 0.06307 | R42: 0.063308 | S42: 0.063572 | T42: 0.063894 | U42: 0.064259 | V42: 0.064725 | W42: 0.065211 | X42: 0.065681 | Y42: 0.066162 | Z42: 0.066587 | AA42: 0.066993 | AB42: 0.067365 | AC42: 0.067759 | AD42: 0.068145 | AE42: 0.6%
A43: Water Heating | B43: Residential: Natural Gas: Water Heating: Alternative Electricity and Transportation | C43: AEO.2026.ELECTRNP.CNSM_NA_RESD_WTHT_NG_NA_USA_QBTU.A | D43: quads | E43: 1.024266 | F43: 1.035179 | G43: 1.045421 | H43: 1.055186 | I43: 1.053344 | J43: 1.049761 | K43: 1.0469 | L43: 1.0452 | M43: 1.042567 | N43: 1.041999 | O43: 1.043007 | P43: 1.043505 | Q43: 1.043021 | R43: 1.042215 | S43: 1.04091 | T43: 1.039289 | U43: 1.037016 | V43: 1.034723 | W43: 1.032111 | X43: 1.029129 | Y43: 1.025429 | Z43: 1.020672 | AA43: 1.015129 | AB43: 1.009384 | AC43: 1.003914 | AD43: 0.99913 | AE43: -0.1%
A44: Cooking | B44: Residential: Natural Gas: Cooking: Alternative Electricity and Transportation | C44: AEO.2026.ELECTRNP.CNSM_NA_RESD_CGR_NG_NA_USA_QBTU.A | D44: quads | E44: 0.077268 | F44: 0.077256 | G44: 0.077247 | H44: 0.077222 | I44: 0.077195 | J44: 0.077167 | K44: 0.077124 | L44: 0.077065 | M44: 0.077006 | N44: 0.07697 | O44: 0.076962 | P44: 0.076991 | Q44: 0.07706 | R44: 0.077217 | S44: 0.077432 | T44: 0.077712 | U44: 0.078045 | V44: 0.07843 | W44: 0.078816 | X44: 0.079203 | Y44: 0.079599 | Z44: 0.080006 | AA44: 0.080424 | AB44: 0.080855 | AC44: 0.081299 | AD44: 0.081761 | AE44: 0.2%
A45: Clothes Dryers | B45: Residential: Natural Gas: Clothes Dryers: Alternative Electricity and Transportation | C45: AEO.2026.ELECTRNP.CNSM_NA_RESD_CDR_NG_NA_USA_QBTU.A | D45: quads | E45: 0.039574 | F45: 0.040284 | G45: 0.04092 | H45: 0.041544 | I45: 0.042109 | J45: 0.042643 | K45: 0.043187 | L45: 0.043759 | M45: 0.044208 | N45: 0.044701 | O45: 0.045238 | P45: 0.045826 | Q45: 0.046396 | R45: 0.046978 | S45: 0.047561 | T45: 0.048146 | U45: 0.048724 | V45: 0.049352 | W45: 0.050015 | X45: 0.050707 | Y45: 0.051406 | Z45: 0.052088 | AA45: 0.052756 | AB45: 0.053424 | AC45: 0.0541 | AD45: 0.054789 | AE45: 1.3%
...

Sheet AEO 2026 Table 5
A1: Table 5. Commercial Sector Key Indicators and Consumption
A2: https://www.eia.gov/outlooks/aeo/data/browser/#/?id=5-AEO2026&cases=electrnp&sourcekey=0
A3: Thu Apr 23 2026 14:57:48 GMT-0700 (Pacific Daylight Time)
A4: Source: U.S. Energy Information Administration
B5: full name | C5: api key | D5: units | E5: 2025 | F5: 2026 | G5: 2027 | H5: 2028 | I5: 2029 | J5: 2030 | K5: 2031 | L5: 2032 | M5: 2033 | N5: 2034 | O5: 2035 | P5: 2036 | Q5: 2037 | R5: 2038 | S5: 2039 | T5: 2040 | U5: 2041 | V5: 2042 | W5: 2043 | X5: 2044 | Y5: 2045 | Z5: 2046 | AA5: 2047 | AB5: 2048 | AC5: 2049 | AD5: 2050 | AE5: Growth (2025-2050)
A6: Key Indicators
A7: Total Floorspace (billion square feet)
A8: Surviving | B8: Commercial: Total Floorspace: Surviving: Alternative Electricity and Transportation | C8: AEO.2026.ELECTRNP.KEI_NA_COMM_NA_TFP_SURV_USA_BLNSQFT.A | D8: billion sq ft | E8: 101.84551 | F8: 103.10442 | G8: 104.31425 | H8: 105.48232 | I8: 106.62843 | J8: 107.75984 | K8: 108.90231 | L8: 110.07059 | M8: 111.26775 | N8: 112.50001 | O8: 113.76868 | P8: 115.07391 | Q8: 116.41436 | R8: 117.78051 | S8: 119.11474 | T8: 120.4153 | U8: 121.68447 | V8: 122.89786 | W8: 124.06418 | X8: 125.19847 | Y8: 126.30771 | Z8: 127.40099 | AA8: 128.48196 | AB8: 129.55205 | AC8: 130.61298 | AD8: 131.66556 | AE8: 1.0%
A9: New Additions | B9: Commercial: Total Floorspace: New Additions: Alternative Electricity and Transportation | C9: AEO.2026.ELECTRNP.KEI_NA_COMM_NA_TFP_NADN_USA_BLNSQFT.A | D9: billion sq ft | E9: 2.798354 | F9: 2.763133 | G9: 2.73562 | H9: 2.728133 | I9: 2.728127 | J9: 2.754144 | K9: 2.795398 | L9: 2.840164 | M9: 2.891744 | N9: 2.945178 | O9: 2.999384 | P9: 3.052837 | Q9: 3.097313 | R9: 3.084287 | S9: 3.069424 | T9: 3.056657 | U9: 3.019132 | V9: 2.989726 | W9: 2.974996 | X9: 2.966822 | Y9: 2.967411 | Z9: 2.971346 | AA9: 2.976496 | AB9: 2.983037 | AC9: 2.990272 | AD9: 2.998542 | AE9: 0.3%
A10: Total | B10: Commercial: Total Floorspace: Total: Alternative Electricity and Transportation | C10: AEO.2026.ELECTRNP.KEI_NA_COMM_NA_TFP_TOT_USA_BLNSQFT.A | D10: billion sq ft | E10: 104.64386 | F10: 105.86755 | G10: 107.04987 | H10: 108.21046 | I10: 109.35656 | J10: 110.51399 | K10: 111.69771 | L10: 112.91075 | M10: 114.15949 | N10: 115.44518 | O10: 116.76806 | P10: 118.12675 | Q10: 119.51167 | R10: 120.8648 | S10: 122.18417 | T10: 123.47195 | U10: 124.70361 | V10: 125.88759 | W10: 127.03918 | X10: 128.1653 | Y10: 129.27512 | Z10: 130.37233 | AA10: 131.45847 | AB10: 132.53508 | AC10: 133.60324 | AD10: 134.66409 | AE10: 1.0%
A11: Energy Consumption Intensity
A12: (thousand Btu per square foot)
A13: Gross End-use Consumption | B13: Commercial: Energy Use Intensity: Gross End-use Consumption: Alternative Electricity and Transportation | C13: AEO.2026.ELECTRNP.INY_NA_COMM_NA_EUI_DLENCONS_USA_THBTUPSQFT.A | D13: thousand Btu/sq ft | E13: 94.608612 | F13: 95.200951 | G13: 94.894547 | H13: 94.391609 | I13: 93.678154 | J13: 92.73333 | K13: 91.840523 | L13: 91.140854 | M13: 90.533226 | N13: 90.025192 | O13: 89.527039 | P13: 89.104965 | Q13: 88.683937 | R13: 88.304733 | S13: 87.952103 | T13: 87.609711 | U13: 87.320465 | V13: 87.099518 | W13: 86.907028 | X13: 86.73526 | Y13: 86.553421 | Z13: 86.303925 | AA13: 85.985275 | AB13: 85.63308 | AC13: 85.264458 | AD13: 84.897255 | AE13: -0.4%
A14: Delivered Energy Consumption | B14: Commercial: Energy Use Intensity: Delivered Energy Consumption: Alternative Electricity and Transportation | C14: AEO.2026.ELECTRNP.INY_NA_COMM_NA_EUI_ERL_USA_THBTUPSQFT.A | D14: thousand Btu/sq ft | E14: 93.084305 | F14: 93.513206 | G14: 93.074776 | H14: 92.51963 | I14: 91.782715 | J14: 90.809181 | K14: 89.899635 | L14: 89.19178 | M14: 88.573189 | N14: 88.038452 | O14: 87.524017 | P14: 87.092613 | Q14: 86.638893 | R14: 86.228638 | S14: 85.833717 | T14: 85.458237 | U14: 85.160706 | V14: 84.916267 | W14: 84.720146 | X14: 84.541443 | Y14: 84.357269 | Z14: 84.093651 | AA14: 83.753242 | AB14: 83.378761 | AC14: 82.997833 | AD14: 82.609665 | AE14: -0.5%
A15: Energy Consumption by Fuel
A16: Electricity
A17: Space Heating | B17: Commercial: Purchased Electricity: Space Heating: Alternative Electricity and Transportation | C17: AEO.2026.ELECTRNP.CNSM_NA_COMM_NA_PRC_SPH_USA_QBTU.A | D17: quads | E17: 0.20086 | F17: 0.193991 | G17: 0.19233 | H17: 0.191237 | I17: 0.18969 | J17: 0.187902 | K17: 0.186031 | L17: 0.184106 | M17: 0.18223 | N17: 0.180242 | O17: 0.1782 | P17: 0.176227 | Q17: 0.174101 | R17: 0.171933 | S17: 0.169663 | T17: 0.167366 | U17: 0.165099 | V17: 0.162808 | W17: 0.160509 | X17: 0.158156 | Y17: 0.155824 | Z17: 0.153355 | AA17: 0.150715 | AB17: 0.148032 | AC17: 0.145385 | AD17: 0.142671 | AE17: -1.4%
A18: Space Cooling | B18: Commercial: Purchased Electricity: Space Cooling: Alternative Electricity and Transportation | C18: AEO.2026.ELECTRNP.CNSM_NA_COMM_NA_PRC_SPC_USA_QBTU.A | D18: quads | E18: 0.566839 | F18: 0.594472 | G18: 0.600861 | H18: 0.609032 | I18: 0.61581 | J18: 0.620066 | K18: 0.624956 | L18: 0.630446 | M18: 0.636408 | N18: 0.642945 | O18: 0.649799 | P18: 0.657449 | Q18: 0.665266 | R18: 0.673226 | S18: 0.681101 | T18: 0.689312 | U18: 0.697981 | V18: 0.707102 | W18: 0.716932 | X18: 0.727006 | Y18: 0.737548 | Z18: 0.747668 | AA18: 0.757338 | AB18: 0.766944 | AC18: 0.777089 | AD18: 0.787237 | AE18: 1.3%
A19: Water Heating | B19: Commercial: Purchased Electricity: Water Heating: Alternative Electricity and Transportation | C19: AEO.2026.ELECTRNP.CNSM_NA_COMM_NA_PRC_WTHT_USA_QBTU.A | D19: quads | E19: 0.073797 | F19: 0.072726 | G19: 0.072052 | H19: 0.07164 | I19: 0.071071 | J19: 0.070187 | K19: 0.069283 | L19: 0.068399 | M19: 0.067566 | N19: 0.066746 | O19: 0.065932 | P19: 0.065184 | Q19: 0.064425 | R19: 0.063673 | S19: 0.062916 | T19: 0.062153 | U19: 0.061431 | V19: 0.060716 | W19: 0.060034 | X19: 0.059364 | Y19: 0.058695 | Z19: 0.058002 | AA19: 0.057258 | AB19: 0.056503 | AC19: 0.055764 | AD19: 0.055011 | AE19: -1.2%
A20: Ventilation | B20: Commercial: Purchased Electricity: Ventilation: Alternative Electricity and Transportation | C20: AEO.2026.ELECTRNP.CNSM_NA_COMM_NA_PRC_VNTC_USA_QBTU.A | D20: quads | E20: 0.772579 | F20: 0.778081 | G20: 0.787216 | H20: 0.798948 | I20: 0.808617 | J20: 0.812848 | K20: 0.817403 | L20: 0.822489 | M20: 0.828422 | N20: 0.834734 | O20: 0.841408 | P20: 0.84894 | Q20: 0.856496 | R20: 0.864206 | S20: 0.871853 | T20: 0.879611 | U20: 0.887874 | V20: 0.896257 | W20: 0.905085 | X20: 0.914164 | Y20: 0.923373 | Z20: 0.932169 | AA20: 0.940261 | AB20: 0.948153 | AC20: 0.956425 | AD20: 0.964518 | AE20: 0.9%
A21: Cooking | B21: Commercial: Purchased Electricity: Cooking: Alternative Electricity and Transportation | C21: AEO.2026.ELECTRNP.CNSM_NA_COMM_NA_PRC_CGR_USA_QBTU.A | D21: quads | E21: 0.083991 | F21: 0.083245 | G21: 0.082882 | H21: 0.08275 | I21: 0.082396 | J21: 0.081708 | K21: 0.080997 | L21: 0.080317 | M21: 0.079704 | N21: 0.079116 | O21: 0.078533 | P21: 0.077998 | Q21: 0.077442 | R21: 0.076881 | S21: 0.076298 | T21: 0.075702 | U21: 0.075151 | V21: 0.074597 | W21: 0.074065 | X21: 0.073538 | Y21: 0.073002 | Z21: 0.072417 | AA21: 0.071763 | AB21: 0.071082 | AC21: 0.070415 | AD21: 0.069721 | AE21: -0.7%
A22: Lighting | B22: Commercial: Purchased Electricity: Lighting: Alternative Electricity and Transportation | C22: AEO.2026.ELECTRNP.CNSM_NA_COMM_NA_PRC_LGHTNG_USA_QBTU.A | D22: quads | E22: 0.564649 | F22: 0.553328 | G22: 0.547329 | H22: 0.54543 | I22: 0.543588 | J22: 0.532318 | K22: 0.522622 | L22: 0.5142 | M22: 0.506779 | N22: 0.499778 | O22: 0.492952 | P22: 0.487289 | Q22: 0.482486 | R22: 0.478498 | S22: 0.475119 | T22: 0.470122 | U22: 0.466407 | V22: 0.463482 | W22: 0.461297 | X22: 0.459643 | Y22: 0.458401 | Z22: 0.457258 | AA22: 0.455994 | AB22: 0.454706 | AC22: 0.453692 | AD22: 0.452695 | AE22: -0.9%
A23: Refrigeration | B23: Commercial: Purchased Electricity: Refrigeration: Alternative Electricity and Transportation | C23: AEO.2026.ELECTRNP.CNSM_NA_COMM_NA_PRC_REFR_USA_QBTU.A | D23: quads | E23: 0.366734 | F23: 0.365953 | G23: 0.366174 | H23: 0.367 | I23: 0.367563 | J23: 0.366644 | K23: 0.366206 | L23: 0.366109 | M23: 0.36639 | N23: 0.36695 | O23: 0.367756 | P23: 0.368848 | Q23: 0.370046 | R23: 0.371239 | S23: 0.372383 | T23: 0.373485 | U23: 0.374828 | V23: 0.376102 | W23: 0.37739 | X23: 0.378663 | Y23: 0.379901 | Z23: 0.381014 | AA23: 0.381955 | AB23: 0.382807 | AC23: 0.383654 | AD23: 0.384415 | AE23: 0.2%
A24: Data Center Servers | B24: Commercial: Purchased Electricity: Data Center Servers: Alternative Electricity and Transportation | C24: AEO.2026.ELECTRNP.CNSM_NA_COMM_NA_PRC_DATACTRSERV_USA_QBTU.A | D24: quads | E24: 0.357691 | F24: 0.403698 | G24: 0.452968 | H24: 0.503864 | I24: 0.555801 | J24: 0.608106 | K24: 0.660976 | L24: 0.714861 | M24: 0.769734 | N24: 0.825407 | O24: 0.881718 | P24: 0.938386 | Q24: 0.995149 | R24: 1.051305 | S24: 1.106359 | T24: 1.159801 | U24: 1.211428 | V24: 1.260422 | W24: 1.30683 | X24: 1.349851 | Y24: 1.389499 | Z24: 1.424823 | AA24: 1.455517 | AB24: 1.481245 | AC24: 1.501816 | AD24: 1.520085 | AE24: 6.0%
A25: Computers and office equipment | B25: Commercial: Purchased Electricity: Computers and Office Equipment: Alternative Electricity and Transportation | C25: AEO.2026.ELECTRNP.CNSM_NA_COMM_NA_PRC_OTHEQP_USA_QBTU.A | D25: quads | E25: 0.216953 | F25: 0.211745 | G25: 0.207122 | H25: 0.202684 | I25: 0.198262 | J25: 0.193913 | K25: 0.189829 | L25: 0.18572 | M25: 0.182465 | N25: 0.179709 | O25: 0.177067 | P25: 0.175041 | Q25: 0.173177 | R25: 0.171447 | S25: 0.170381 | T25: 0.169034 | U25: 0.167367 | V25: 0.16648 | W25: 0.164809 | X25: 0.163452 | Y25: 0.161864 | Z25: 0.16063 | AA25: 0.158545 | AB25: 0.15621 | AC25: 0.153638 | AD25: 0.150807 | AE25: -1.4%
A26: Other Uses | B26: Commercial: Purchased Electricity: Other Uses: Alternative Electricity and Transportation | C26: AEO.2026.ELECTRNP.CNSM_NA_COMM_NA_PRC_OTHU_USA_QBTU.A | D26: quads | E26: 1.949163 | F26: 2.133727 | G26: 2.139688 | H26: 2.13915 | I26: 2.138203 | J26: 2.13603 | K26: 2.134272 | L26: 2.133495 | M26: 2.134242 | N26: 2.136272 | O26: 2.139616 | P26: 2.144953 | Q26: 2.15116 | R26: 2.157878 | S26: 2.164868 | T26: 2.172189 | U26: 2.179389 | V26: 2.186837 | W26: 2.194853 | X26: 2.203038 | Y26: 2.212115 | Z26: 2.221061 | AA26: 2.230132 | AB26: 2.239662 | AC26: 2.249701 | AD26: 2.260383 | AE26: 0.6%
A27: Gross End-use Electricity Consumption | B27: Commercial: Energy Consumption by Fuel: Electricity Subtotal: Alternative Electricity and Transportation | C27: AEO.2026.ELECTRNP.CNSM_NA_COMM_NA_PRC_DELE_USA_QBTU.A | D27: quads | E27: 5.153255 | F27: 5.390966 | G27: 5.448623 | H27: 5.511735 | I27: 5.571003 | J27: 5.609722 | K27: 5.652576 | L27: 5.700143 | M27: 5.753941 | N27: 5.811899 | O27: 5.872981 | P27: 5.940315 | Q27: 6.009748 | R27: 6.080286 | S27: 6.150941 | T27: 6.218776 | U27: 6.286955 | V27: 6.354805 | W27: 6.421803 | X27: 6.486873 | Y27: 6.550223 | Z27: 6.608398 | AA27: 6.659479 | AB27: 6.705345 | AC27: 6.747578 | AD27: 6.787544 | AE27: 1.1%
A28: Purchased Electricity for Electric Vehicle Charging | B28: Commercial: Energy Consumption by Fuel: Purchased Electricity for EV Charging: Alternative Electricity and Transportation | C28: AEO.2026.ELECTRNP.GEN_NA_COMM_NA_PRC_EVCHA_USA_QBTU.A | D28: quads | E28: 0.031625 | F28: 0.041349 | G28: 0.053095 | H28: 0.066244 | I28: 0.079603 | J28: 0.092543 | K28: 0.104416 | L28: 0.115643 | M28: 0.126972 | N28: 0.138502 | O28: 0.150392 | P28: 0.162461 | Q28: 0.174804 | R28: 0.187239 | S28: 0.19959 | T28: 0.212288 | U28: 0.225364 | V28: 0.239243 | W28: 0.253973 | X28: 0.269944 | Y28: 0.287121 | Z28: 0.304738 | AA28: 0.322704 | AB28: 0.341035 | AC28: 0.359608 | AD28: 0.378263 | AE28: 10.4%
... A30: Purchased Electricity at Commercial Location | B30: Commercial: Energy Consumption by Fuel: Purchased Electricity: Alternative Electricity and Transportation | C30: AEO.2026.ELECTRNP.CNSM_NA_COMM_NA_DELE_ELC_USA_QBTU.A | D30: quads | E30: 5.025373 | F30: 5.253638 | G30: 5.306912 | H30: 5.375412 | I30: 5.443327 | J30: 5.48962 | K30: 5.540199 | L30: 5.595715 | M30: 5.657156 | N30: 5.72104 | O30: 5.789485 | P30: 5.865063 | Q30: 5.940146 | R30: 6.016598 | S30: 6.091698 | T30: 6.165417 | U30: 6.24299 | V30: 6.319204 | W30: 6.397956 | X30: 6.475646 | Y30: 6.553437 | Z30: 6.624979 | AA30: 6.688763 | AB30: 6.747605 | AC30: 6.804358 | AD30: 6.857751 | AE30: 1.3%
A31: Natural Gas
A32: Space Heating | B32: Commercial: Natural Gas: Space Heating: Alternative Electricity and Transportation | C32: AEO.2026.ELECTRNP.CNSM_NA_COMM_NA_NG_SPH_USA_QBTU.A | D32: quads | E32: 1.677395 | F32: 1.658977 | G32: 1.655333 | H32: 1.640213 | I32: 1.614623 | J32: 1.585396 | K32: 1.558153 | L32: 1.539679 | M32: 1.52558 | N32: 1.514998 | O32: 1.504151 | P32: 1.494749 | Q32: 1.484763 | R32: 1.474809 | S32: 1.464232 | T32: 1.453817 | U32: 1.443761 | V32: 1.435541 | W32: 1.427792 | X32: 1.420772 | Y32: 1.413245 | Z32: 1.403235 | AA32: 1.391638 | AB32: 1.379734 | AC32: 1.367849 | AD32: 1.356255 | AE32: -0.8%
A33: Space Cooling | B33: Commercial: Natural Gas: Space Cooling: Alternative Electricity and Transportation | C33: AEO.2026.ELECTRNP.CNSM_NA_COMM_NA_NG_SPC_USA_QBTU.A | D33: quads | E33: 0.015692 | F33: 0.017612 | G33: 0.017945 | H33: 0.018169 | I33: 0.018287 | J33: 0.018392 | K33: 0.018555 | L33: 0.018871 | M33: 0.01928 | N33: 0.019785 | O33: 0.020338 | P33: 0.020947 | Q33: 0.021603 | R33: 0.022292 | S33: 0.023007 | T33: 0.023771 | U33: 0.024568 | V33: 0.025421 | W33: 0.026326 | X33: 0.027285 | Y33: 0.028298 | Z33: 0.029311 | AA33: 0.030356 | AB33: 0.031435 | AC33: 0.03257 | AD33: 0.033763 | AE33: 3.1%
A34: Water Heating | B34: Commercial: Natural Gas: Water Heating: Alternative Electricity and Transportation | C34: AEO.2026.ELECTRNP.CNSM_NA_COMM_NA_NG_WTHT_USA_QBTU.A | D34: quads | E34: 0.27397 | F34: 0.280341 | G34: 0.283018 | H34: 0.283701 | I34: 0.282807 | J34: 0.281323 | K34: 0.280138 | L34: 0.280657 | M34: 0.281792 | N34: 0.283857 | O34: 0.2861 | P34: 0.288783 | Q34: 0.291449 | R34: 0.294131 | S34: 0.29673 | T34: 0.299366 | U34: 0.302164 | V34: 0.305317 | W34: 0.308628 | X34: 0.312135 | Y34: 0.315522 | Z34: 0.318429 | AA34: 0.321005 | AB34: 0.323466 | AC34: 0.325923 | AD34: 0.328429 | AE34: 0.7%
A35: Cooking | B35: Commercial: Natural Gas: Cooking: Alternative Electricity and Transportation | C35: AEO.2026.ELECTRNP.CNSM_NA_COMM_NA_NG_CGR_USA_QBTU.A | D35: quads | E35: 0.40539 | F35: 0.412698 | G35: 0.416201 | H35: 0.416769 | I35: 0.415153 | J35: 0.412603 | K35: 0.410522 | L35: 0.410815 | M35: 0.412028 | N35: 0.414518 | O35: 0.417203 | P35: 0.420466 | Q35: 0.423673 | R35: 0.426868 | S35: 0.429898 | T35: 0.432934 | U35: 0.436245 | V35: 0.440058 | W35: 0.444076 | X35: 0.448351 | Y35: 0.452416 | Z35: 0.455738 | AA35: 0.458542 | AB35: 0.461147 | AC35: 0.463721 | AD35: 0.466344 | AE35: 0.6%
A36: Other Uses | B36: Commercial: Natural Gas: Other Uses: Alternative Electricity and Transportation | C36: AEO.2026.ELECTRNP.CNSM_NA_COMM_NA_NG_OTHU_USA_QBTU.A | D36: quads | E36: 1.267356 | F36: 1.194333 | G36: 1.199043 | H36: 1.197086 | I36: 1.188333 | J36: 1.177144 | K36: 1.166085 | L36: 1.160668 | M36: 1.157207 | N36: 1.156334 | O36: 1.155312 | P36: 1.155334 | Q36: 1.155167 | R36: 1.155125 | S36: 1.154979 | T36: 1.155163 | U36: 1.155525 | V36: 1.157366 | W36: 1.159725 | X36: 1.162961 | Y36: 1.165869 | Z36: 1.167382 | AA36: 1.168018 | AB36: 1.16842 | AC36: 1.168869 | AD36: 1.169652 | AE36: -0.3%
A37: Delivered Energy | B37: Commercial: Natural Gas: Delivered Energy: Alternative Electricity and Transportation | C37: AEO.2026.ELECTRNP.CNSM_NA_COMM_NA_NG_DELE_USA_QBTU.A | D37: quads | E37: 3.639804 | F37: 3.563961 | G37: 3.57154 | H37: 3.555938 | I37: 3.519203 | J37: 3.474857 | K37: 3.433453 | L37: 3.41069 | M37: 3.395886 | N37: 3.389492 | O37: 3.383103 | P37: 3.380279 | Q37: 3.376655 | R37: 3.373224 | S37: 3.368847 | T37: 3.365051 | U37: 3.362263 | V37: 3.363703 | W37: 3.366547 | X37: 3.371504 | Y37: 3.37535 | Z37: 3.374094 | AA37: 3.369559 | AB37: 3.364201 | AC37: 3.358932 | AD37: 3.354442 | AE37: -0.3%
A38: Distillate Fuel Oil
A39: Space Heating | B39: Commercial: Distillate Fuel Oil: Space Heating: Alternative Electricity and Transportation | C39: AEO.2026.ELECTRNP.CNSM_NA_COMM_NA_DFO_SPH_USA_QBTU.A | D39: quads | E39: 0.074528 | F39: 0.072814 | G39: 0.072147 | H39: 0.071328 | I39: 0.07024 | J39: 0.06939 | K39: 0.068552 | L39: 0.067389 | M39: 0.065912 | N39: 0.064453 | O39: 0.063009 | P39: 0.06167 | Q39: 0.060346 | R39: 0.059039 | S39: 0.05778 | T39: 0.056542 | U39: 0.055331 | V39: 0.054154 | W39: 0.052975 | X39: 0.051814 | Y39: 0.050657 | Z39: 0.049516 | AA39: 0.048376 | AB39: 0.047276 | AC39: 0.046179 | AD39: 0.045136 | AE39: -2.0%
A40: Water Heating | B40: Commercial: Distillate Fuel Oil: Water Heating: Alternative Electricity and Transportation | C40: AEO.2026.ELECTRNP.CNSM_NA_COMM_NA_DFO_WTHT_USA_QBTU.A | D40: quads | E40: 0.003768 | F40: 0.003783 | G40: 0.003772 | H40: 0.003756 | I40: 0.003738 | J40: 0.003734 | K40: 0.00373 | L40: 0.00371 | M40: 0.003672 | N40: 0.003636 | O40: 0.003602 | P40: 0.003574 | Q40: 0.003547 | R40: 0.003521 | S40: 0.003496 | T40: 0.003472 | U40: 0.003448 | V40: 0.003424 | W40: 0.0034 | X40: 0.003376 | Y40: 0.00335 | Z40: 0.003324 | AA40: 0.003298 | AB40: 0.003273 | AC40: 0.003246 | AD40: 0.003222 | AE40: -0.6%
A41: Other Uses | B41: Commercial: Distillate Fuel Oil: Other Uses: Alternative Electricity and Transportation | C41: AEO.2026.ELECTRNP.CNSM_NA_COMM_NA_DFO_OTHU_USA_QBTU.A | D41: quads | E41: 0.237124 | F41: 0.242392 | G41: 0.250526 | H41: 0.25241 | I41: 0.253941 | J41: 0.256359 | K41: 0.258468 | L41: 0.259219 | M41: 0.258164 | N41: 0.257158 | O41: 0.256193 | P41: 0.255626 | Q41: 0.254962 | R41: 0.25428 | S41: 0.253748 | T41: 0.253289 | U41: 0.25278 | V41: 0.252306 | W41: 0.251799 | X41: 0.251265 | Y41: 0.25063 | Z41: 0.249962 | AA41: 0.249195 | AB41: 0.248498 | AC41: 0.247697 | AD41: 0.247076 | AE41: 0.2%
...

Sheet calcs>

Sheet Calculations
A1: Fraction of Commercial Floorspace that is New
B2: 2025 | C2: 2026 | D2: 2027 | E2: 2028 | F2: 2029 | G2: 2030 | H2: 2031 | I2: 2032 | J2: 2033 | K2: 2034 | L2: 2035 | M2: 2036 | N2: 2037 | O2: 2038 | P2: 2039 | Q2: 2040 | R2: 2041 | S2: 2042 | T2: 2043 | U2: 2044 | V2: 2045 | W2: 2046 | X2: 2047 | Y2: 2048 | Z2: 2049 | AA2: 2050
A3: Commercial floorspace | B3: ='AEO 2026 Table 5'!E9/'AEO 2026 Table 5'!E10 -> 0.026741693 | C3: ='AEO 2026 Table 5'!F9/'AEO 2026 Table 5'!F10 -> 0.026099904 | D3: ='AEO 2026 Table 5'!G9/'AEO 2026 Table 5'!G10 -> 0.025554633 | E3: ='AEO 2026 Table 5'!H9/'AEO 2026 Table 5'!H10 -> 0.025211362 | F3: ='AEO 2026 Table 5'!I9/'AEO 2026 Table 5'!I10 -> 0.024947081 | G3: ='AEO 2026 Table 5'!J9/'AEO 2026 Table 5'!J10 -> 0.024921226 | H3: ='AEO 2026 Table 5'!K9/'AEO 2026 Table 5'!K10 -> 0.025026458 | I3: ='AEO 2026 Table 5'!L9/'AEO 2026 Table 5'!L10 -> 0.025154062 | ... AA3: ='AEO 2026 Table 5'!AD9/'AEO 2026 Table 5'!AD10 -> 0.022266827
A5: Average | B5: =AVERAGE(B3:AA3) -> 0.024515798
A8: Fraction of Residential Homes that are New
A10: Housing evolution rates from EIA NEMS documentation:
B12: HDR value | C12: (Fraction of homes that survive each year)
A13: Single-family homes | B13: 0.997
A14: Multifamily homes | B14: 0.995
A15: Mobile homes | B15: 0.966
A17: Surviving homes
B18: 2025 | C18: 2026 | D18: 2027 | E18: 2028 | F18: 2029 | G18: 2030 | H18: 2031 | I18: 2032 | J18: 2033 | K18: 2034 | L18: 2035 | M18: 2036 | N18: 2037 | O18: 2038 | P18: 2039 | Q18: 2040 | R18: 2041 | S18: 2042 | T18: 2043 | U18: 2044 | V18: 2045 | W18: 2046 | X18: 2047 | Y18: 2048 | Z18: 2049 | AA18: 2050
A19: Single-family homes | B19: ='AEO 2026 Table 4'!E8*$B13 -> 89.283153 | C19: ='AEO 2026 Table 4'!F8*$B13 -> 90.227822 | D19: ='AEO 2026 Table 4'!G8*$B13 -> 91.171614 | E19: ='AEO 2026 Table 4'!H8*$B13 -> 92.098401 | F19: ='AEO 2026 Table 4'!I8*$B13 -> 93.028403 | G19: ='AEO 2026 Table 4'!J8*$B13 -> 93.960391 | H19: ='AEO 2026 Table 4'!K8*$B13 -> 94.872733 | I19: ='AEO 2026 Table 4'!L8*$B13 -> 95.783361 | ... AA19: ='AEO 2026 Table 4'!AD8*$B13 -> 108.95596
A20: Multifamily homes | B20: ='AEO 2026 Table 4'!E9*$B14 -> 34.26015 | C20: ='AEO 2026 Table 4'!F9*$B14 -> 34.662485 | D20: ='AEO 2026 Table 4'!G9*$B14 -> 35.066578 | E20: ='AEO 2026 Table 4'!H9*$B14 -> 35.460908 | F20: ='AEO 2026 Table 4'!I9*$B14 -> 35.85701 | G20: ='AEO 2026 Table 4'!J9*$B14 -> 36.271404 | H20: ='AEO 2026 Table 4'!K9*$B14 -> 36.719122 | I20: ='AEO 2026 Table 4'!L9*$B14 -> 37.168754 | ... AA20: ='AEO 2026 Table 4'!AD9*$B14 -> 42.624435
A21: Mobile homes | B21: ='AEO 2026 Table 4'!E10*$B15 -> 6.5157618 | C21: ='AEO 2026 Table 4'!F10*$B15 -> 6.5296026 | D21: ='AEO 2026 Table 4'!G10*$B15 -> 6.5755533 | E21: ='AEO 2026 Table 4'!H10*$B15 -> 6.6249874 | F21: ='AEO 2026 Table 4'!I10*$B15 -> 6.6689848 | G21: ='AEO 2026 Table 4'!J10*$B15 -> 6.6779715 | H21: ='AEO 2026 Table 4'!K10*$B15 -> 6.679976 | I21: ='AEO 2026 Table 4'!L10*$B15 -> 6.6830314 | ... AA21: ='AEO 2026 Table 4'!AD10*$B15 -> 6.7139811
A23: Newly built homes
B24: 2025 | C24: 2026 | D24: 2027 | E24: 2028 | F24: 2029 | G24: 2030 | H24: 2031 | I24: 2032 | J24: 2033 | K24: 2034 | L24: 2035 | M24: 2036 | N24: 2037 | O24: 2038 | P24: 2039 | Q24: 2040 | R24: 2041 | S24: 2042 | T24: 2043 | U24: 2044 | V24: 2045 | W24: 2046 | X24: 2047 | Y24: 2048 | Z24: 2049 | AA24: 2050
A25: Single-family homes | B25: ='AEO 2026 Table 4'!E8-B19 -> 0.26865542 | C25: ='AEO 2026 Table 4'!F8-C19 -> 0.27149796 | D25: ='AEO 2026 Table 4'!G8-D19 -> 0.27433786 | E25: ='AEO 2026 Table 4'!H8-E19 -> 0.27712658 | F25: ='AEO 2026 Table 4'!I8-F19 -> 0.27992498 | G25: ='AEO 2026 Table 4'!J8-G19 -> 0.28272936 | H25: ='AEO 2026 Table 4'!K8-H19 -> 0.28547462 | I25: ='AEO 2026 Table 4'!L8-I19 -> 0.28821473 | ... AA25: ='AEO 2026 Table 4'!AD8-AA19 -> 0.32785145
A26: Multifamily homes | B26: ='AEO 2026 Table 4'!E9-B20 -> 0.17216156 | C26: ='AEO 2026 Table 4'!F9-C20 -> 0.17418334 | D26: ='AEO 2026 Table 4'!G9-D20 -> 0.17621396 | E26: ='AEO 2026 Table 4'!H9-E20 -> 0.17819552 | F26: ='AEO 2026 Table 4'!I9-F20 -> 0.18018598 | G26: ='AEO 2026 Table 4'!J9-G20 -> 0.18226836 | H26: ='AEO 2026 Table 4'!K9-H20 -> 0.1845182 | I26: ='AEO 2026 Table 4'!L9-I20 -> 0.18677766 | ... AA26: ='AEO 2026 Table 4'!AD9-AA20 -> 0.21419314
A27: Mobile homes | B27: ='AEO 2026 Table 4'!E10-B21 -> 0.22933323 | C27: ='AEO 2026 Table 4'!F10-C21 -> 0.22982038 | D27: ='AEO 2026 Table 4'!G10-D21 -> 0.23143769 | E27: ='AEO 2026 Table 4'!H10-E21 -> 0.23317761 | F27: ='AEO 2026 Table 4'!I10-F21 -> 0.23472617 | G27: ='AEO 2026 Table 4'!J10-G21 -> 0.23504248 | H27: ='AEO 2026 Table 4'!K10-H21 -> 0.23511303 | I27: ='AEO 2026 Table 4'!L10-I21 -> 0.23522057 | ... AA27: ='AEO 2026 Table 4'!AD10-AA21 -> 0.23630989
A29: Fraction of homes that are new
B30: 2025 | C30: 2026 | D30: 2027 | E30: 2028 | F30: 2029 | G30: 2030 | H30: 2031 | I30: 2032 | J30: 2033 | K30: 2034 | L30: 2035 | M30: 2036 | N30: 2037 | O30: 2038 | P30: 2039 | Q30: 2040 | R30: 2041 | S30: 2042 | T30: 2043 | U30: 2044 | V30: 2045 | W30: 2046 | X30: 2047 | Y30: 2048 | Z30: 2049 | AA30: 2050
A31: Single-family homes | B31: =B25/B19 -> 0.0030090271 | C31: =C25/C19 -> 0.0030090271 | D31: =D25/D19 -> 0.0030090271 | E31: =E25/E19 -> 0.0030090271 | F31: =F25/F19 -> 0.0030090271 | G31: =G25/G19 -> 0.0030090271 | H31: =H25/H19 -> 0.0030090271 | I31: =I25/I19 -> 0.0030090271 | ... AA31: =AA25/AA19 -> 0.0030090271
A32: Multifamily homes | B32: =B26/B20 -> 0.0050251256 | C32: =C26/C20 -> 0.0050251256 | D32: =D26/D20 -> 0.0050251256 | E32: =E26/E20 -> 0.0050251256 | F32: =F26/F20 -> 0.0050251256 | G32: =G26/G20 -> 0.0050251256 | H32: =H26/H20 -> 0.0050251256 | I32: =I26/I20 -> 0.0050251256 | ... AA32: =AA26/AA20 -> 0.0050251256
A33: Mobile homes | B33: =B27/B21 -> 0.035196687 | C33: =C27/C21 -> 0.035196687 | D33: =D27/D21 -> 0.035196687 | E33: =E27/E21 -> 0.035196687 | F33: =F27/F21 -> 0.035196687 | G33: =G27/G21 -> 0.035196687 | H33: =H27/H21 -> 0.035196687 | I33: =I27/I21 -> 0.035196687 | ... AA33: =AA27/AA21 -> 0.035196687
A35: Average fraction of homes that are new by home type
A36: Single-family homes | B36: =AVERAGE(B31:AA31) -> 0.0030090271
A37: Multifamily homes | B37: =AVERAGE(B32:AA32) -> 0.0050251256
A38: Mobile homes | B38: =AVERAGE(B33:AA33) -> 0.035196687
A40: Weighted average fraction of homes that are new
A41: All homes | B41: =SUMPRODUCT(B36:B38,'AEO 2026 Table 4'!E8:E10)/SUM('AEO 2026 Table 4'!E8:E10) -> 0.0052007924
A44: Share of Components That is New This Year
A46: The share of new components is the share of old components that are replaced in surviving
A47: buildings, plus the share of components in new buildings (which equals the share of new
A48: buildings, because all components in new buildings are new components).
A50: Share of Buildings that are Surviving
A51: Commercial | B51: =1-B5 -> 0.9754842
A52: Residential | B52: =1-B41 -> 0.99479921
A54: Replacement rate of components in surviving buildings
A55: heating | B55: =1/'Component Lifetimes'!B2 -> 0.052631579
...

Sheet Pre-Calibration Calculated Vals
B1: urban residential | C1: rural residential | D1: commercial
A2: heating | B2: =Calculations!C63 -> 0.057558645 | C2: =B2 -> 0.057558645 | D2: =Calculations!B63 -> 0.075857072
A3: cooling and ventilation | B3: =Calculations!C64 -> 0.068030216 | C3: =B3 -> 0.068030216 | D3: =Calculations!B64 -> 0.086125327
A4: envelope | B4: 0 | C4: 0 | D4: 0
A5: lighting | B5: =Calculations!C65 -> 0.11413131 | C5: =B5 -> 0.11413131 | D5: =Calculations!B65 -> 0.13133132
A6: appliances | B6: =Calculations!C66 -> 0.078708123 | C6: =B6 -> 0.078708123 | D6: =Calculations!B66 -> 0.096595912
A7: other component | B7: =Calculations!C67 -> 0.069798144 | C7: =B7 -> 0.069798144 | D7: =Calculations!B67 -> 0.087858928

Sheet Data Centers
A1: Data center assumptions
A2: Data centers are a separate building type. They use the commercial shares, except for IT load ('other component'), where the share that is new each year comes from the IT equipment lifetime.
A4: Assumption | B4: Value | C4: Basis
A5: Lifetime of data-center IT equipment (years) | B5: 5 | C5: Same value as the IT equipment lifetime in the Component Lifetime (CL) workbook. The share of IT energy use that is new each year is one over this lifetime.

Sheet SoCEUtiNTY
A1: Share of New Components Energy Use (dimensionless) | B1: urban residential | C1: rural residential | D1: commercial | E1: data centers
A2: heating | B2: =1/'Component Lifetimes'!B2 -> 0.052631579 | C2: 0.053 | D2: =1/'Component Lifetimes'!B2 -> 0.052631579 | E2: =$D2 -> 0.052631579
A3: cooling and ventilation | B3: =1/'Component Lifetimes'!B3 -> 0.063157895 | C3: =B3 -> 0.063157895 | D3: =1/'Component Lifetimes'!B3 -> 0.063157895 | E3: =$D3 -> 0.063157895
A4: envelope | B4: 0 | C4: 0 | D4: 0 | E4: =$D4 -> 0
A5: lighting | B5: =1/'Component Lifetimes'!B5 -> 0.1095 | C5: =B5 -> 0.1095 | D5: =1/'Component Lifetimes'!B5 -> 0.1095 | E5: =$D5 -> 0.1095
A6: appliances | B6: 0.071 | C6: =B6 -> 0.071 | D6: =B6 -> 0.071 | E6: =$D6 -> 0.071
A7: other component | B7: 0.066 | C7: =B7 -> 0.066 | D7: 0.066 | E7: =1/'Data Centers'!$B$5 -> 0.2
