Workbook

Sheet About
A1: ELCCAfR Effective Load Carrying Capability Adjustment for Reliability - per (tech, slice, hour)
A3: Sources: | B3: Hourly VRE output at pinned peak days (regional statistic for solar PV, onshore wind and offshore wind; solar thermal national)
B4: NREL
B5: NREL Cambium Scenarios 2024
B6: 2024
B7: https://www.nrel.gov/analysis/cambium.html (downloads: https://scenarioviewer.nrel.gov)
B8: MidCase scenario, weather year 2012, hourly (timestamps in Eastern Time), 2025 model year. SOLAR PV and ONSHORE WIND (regional statistic, changed 2026-09-24): the 133 balancing-area files Cambium24_MidCase_hourly_p<NNN>_2025.csv (Cambium24_MidCase_hourly_balancingArea.zip), aggregated to the 18 Cambium 'gea' regions listed in each file's header (CAISO, ERCOT, FRCC, ISONE, MISO_Central/North/South, NYISO, NorthernGrid_East/South/West, PJM_East/West, SERTP, SPP_North/South, WestConnect_North/South), together with the national file for the denominator. Gate: the 133 balancing areas sum to the national file within 1 MWh at every pinned hour. Nameplate capacity cancels out of the ratio, so hourly generation (MWh) is used in place of capacity factors. The raw hourly files are not pasted into this workbook (see the No raw source tabs note). Vintage history: Cambium22 -> Cambium24 on 2026-08-26 (Megan); state models stay on Cambium22 and are not interchangeable with this national file (see Deployment).
B10: Exceptions - offshore wind (later model year) and solar thermal (Cambium 2022)
B11: NREL
B12: NREL Cambium Scenarios 2024 (offshore wind) / 2022 (solar thermal)
B13: 2024 / 2022
B14: https://www.nrel.gov/analysis/cambium.html (downloads: https://scenarioviewer.nrel.gov)
B15: OFFSHORE WIND: same file family and method as above, but the 2040 model year (Cambium24_MidCase_hourly_usa_2040.csv, ~50 GW national offshore fleet). A later model year is required because the near-term offshore fleet is too small for the statistic to describe resource behaviour rather than single-site weather: the Cambium24 2025 offshore fleet is 1.7 GW, versus 50.3 GW in 2040. Every Cambium model year shares the 2012 weather year, so the pinned peak days line up across model years and the method is otherwise unchanged. SOLAR THERMAL: computed from Cambium22_MidCase_hourly_usa_2024.csv, because Cambium24 has no usable CSP fleet in any model year or scenario - 59 MW in MidCase (zero generating hours in 2025), 163 MW in the most CSP-heavy Cambium24 scenario, and zero in Cambium23 - whereas Cambium22 carries 1,323 MW across CA (918), AZ (296) and NV (110), flat from 2024 through 2040. The statistic, pinned days and degenerate/cap rules are identical to the other techs; only the source vintage differs. Solar thermal is immaterial in the national model regardless: BHRaSYC-StartYearCapacities gives it zero capacity.
B17: Pinned peak-day identities (which days count as Summer Peak / Winter Peak)
... B31: ELCC Class Ratings for the 2026/2027 Base Residual Auction
B32: 2025
B33: https://www.pjm.com/-/media/DotCom/planning/res-adeq/elcc/2026-27-bra-elcc-class-ratings.pdf (accessed September 22, 2026)
B34: SUPERSEDED 2026-09-30 (kept as a record; see the Demand-altering ELCC revision note). Class ratings used: 4-hr Storage 50 percent, Demand Resource 69 percent, 10-hr Storage 72 percent (proxy for pumped hydro). Blended on the DAT-derivation tab into the flat 0.64 deployed on the demand-altering tab. PJM revises class ratings each auction - re-check before reuse. Supporting reference on storage ELCC declining with penetration: CPUC/Astrape battery ELCC analysis, 2019-20 IRP.
B36: US pumped hydro fleet capacity (pool-weight input to the demand-altering ELCC blend)
B37: EIA
B38: Preliminary Monthly Electric Generator Inventory (EIA-860M), July 2026 edition, Operating tab
B39: 2026
B40: https://www.eia.gov/electricity/data/eia860m/ (accessed September 22, 2026)
B41: 23.0 GW net summer pumped storage fleet (150 units; essentially unchanged since ~2000). Used with EPS BAU pool sizes (2028 grid battery fleet and demand response capacity) to weight the accreditation blend on the DAT-derivation tab.
A43: Notes:
A44: Concept | B44: Per-cell capacity-adequacy derate. Multiplied with SYSHECF in the reliability calculation, NOT in dispatch. Cells = 1.0 mean no derate (full SYSHECF contribution). Cells < 1.0 mean VRE output at that hour-of-day is uncertain across pinned peak days.
A45: Methodology | B45: SOLAR THERMAL only (national statistic): per (slice, hour) cell, ELCCAfR = 70%-exceedance output / mean output across the pinned peak days at that hour-of-day (70% exceedance = the 30th percentile of the pinned-day sample, linearly interpolated), both statistics at the same hour-of-day. SOLAR PV, ONSHORE WIND and OFFSHORE WIND (regional statistic, adopted 2026-09-24 - see the dedicated note below): at each hour-of-day, the 30th percentile across the pinned days is taken separately for each of the 18 Cambium GEA regions, those 18 regional values are ADDED, and the sum is divided by the NATIONAL mean output at that hour (which equals the sum of the regional means, since the balancing areas add up to the national file). In words: the national method takes the bad day of the national total; the regional method takes the sum of each region's own bad day. The second is always lower, and the gap is the inter-regional diversity benefit that only unlimited transmission could deliver. Day pool: identical for both methods - only the pinned Summer Peak (11) and Winter Peak (10) days; a region's 'bad day' is its 30th-percentile day WITHIN that pool, not its worst day of the year, and the pool itself is pinned on national net load. The 70% exceedance level (adopted 2026-08-26, replacing a minimum-CF numerator that is a ~96% exceedance standard no accreditation framework uses) follows the CPUC Slice-of-Day resource-adequacy framework (D.23-04-010, levels updated per D.24-06-004); verify the exact exceedance language against D.23-04-010 before any external use. Degenerate cells (negligible mean output, e.g. solar overnight) are 1.0. Cells are capped at 1.0: a percentile numerator can exceed the mean on a left-skewed sample and ELCCAfR is a derate, never a bonus. Model years: solar PV and onshore wind Cambium24 2025; offshore wind Cambium24 2040; solar thermal Cambium22 2024 (see Sources).
A46: Slice coverage | B46: Summer Peak and Winter Peak are computed per-hour from the pinned days. The four non-peak slices (Winter, Spring, Summer, Fall) are 1.0 across all hours: adequacy is not binding outside the peak slices, and non-peak ELCCAfR = 1.0 prevents incorrectly derating VRE for dispatch at midday.
A47: No raw source tabs | B47: Unlike most EPS input workbooks, the raw Cambium hourly files (8,760 rows x ~78 columns per model year; 133 files per model year at balancing-area resolution) are not pasted into source tabs here, and the VRE output tabs hold values rather than formulas. Solar thermal values are produced by recompute_elccafr_national.py; solar PV, onshore and offshore wind values by optionA_c24.py (both kept in the ELCC tooling folder and in eps-us _claude/scratch/elcc-geo). Both scripts read the pinned day-of-year to timeslice assignment from the pasted Cambium hourly source tab of the deployed SHELF workbook. Gates run on every execution: recompute_elccafr_national.py verifies that reading the Cambium24 2025 CSV reproduces that SHELF tab cell-for-cell (48/48 per tech); optionA_c24.py verifies (1) that the 133 balancing-area files sum to the national file within 1 MWh at every pinned hour and (2) that its own national-P30 recomputation reproduces the deployed solar PV CSV to 4 dp. The state-data-pipeline ELCCAfR builder does not reproduce these national values (the states remain on Cambium22 and a national min/mean statistic). The PREVIOUSLY deployed (pre-2026-08-26) national values could not be reproduced from any pinned-day set in this repo: they were computed on a 27-summer / 20-winter-peak-day clustering (commit 5243d9fe) while the deployed SHELF has carried 11 / 10 since commit 6fdfe6dd - stale against their own pinned days. The per-state workbooks carry pasted pinned-day source tabs and live MIN/AVERAGE formulas - see any state ELCCAfR workbook in state-eps-data-repository.
A48: Deployment | B48: CHANGED 2026-08-26: this national file is NO LONGER byte-identical to the state ELCCAfR files and must not be synced over them. National uses Cambium24 (except solar thermal, on Cambium22 for lack of a Cambium24 CSP fleet); state models stay on Cambium22, which retains the state disaggregation Cambium24 does not provide (Megan, 2026-08-26). Previously all 50 state ELCCAfR-offshore-wind.csv files inherited this file unchanged (state-eps-data-repository commit 08659643df). Any model-sync step that copies the national ELCCAfR folder into state input trees needs to be updated to exclude it, or states will silently pick up the Cambium24 national values. The state files also still carry the min/mean statistic; converting them to 70% exceedance on their Cambium22 basis is separate work.
A49: Demand-altering ELCC (2026-09-22, SUPERSEDED 2026-09-30) | B49: Method: the deployed value is set so that ELCC times the 0.9 demand-altering RAF equals a blend of market capacity accreditation across the credited flexible pool - PJM 2026/27 class ratings weighted by the approximate 2028 US BAU pool (57 percent grid batteries, 31 percent demand response incl. electrolyzer flexibility, 11 percent pumped hydro at binding-hour availability). All arithmetic is live formulas on the DAT-derivation tab; the ELCCAfR-demand-altering-techs output tab reads that result by formula. Caveats: PJM ratings reflect one RTO and are revised each auction; the blend uses static 2028 weights while the pool shifts toward batteries over time (implied value drifts toward ~0.55 by the 2040s).
A50: VRE regional statistic (2026-09-24) | B50: WHAT CHANGED: the Summer Peak and Winter Peak rows of ELCCAfR-solar-pv, ELCCAfR-onshore-wind and ELCCAfR-offshore-wind were recomputed with the regional statistic described under Methodology (one treatment for all VRE; Megan 2026-09-24); solar thermal (Cambium22 basis, zero BAU capacity) and all other tabs are unchanged. SOLAR PV is barely affected at the hours that matter: at Summer Peak Hour20 the regional value is 0.794 vs 0.791 national, because solar's inter-regional diversity is mostly time-zone structure (present every day) rather than weather, so each region's P30 sits near its own mean; the larger drops are at Hour21 (0.79 -> 0.50, where solar output is ~0) and in Winter Peak mornings (Hour7-8 0.92 -> 0.74), which do not bind. WHY: the EPS models the US as a single region with no transmission limits, and a national P30 credits wind for calm days in one region being offset by windy days in another - a diversity benefit the real grid cannot fully deliver (wind in the Plains cannot serve a calm evening in California). Summing each region's own P30 at the same hour removes that inter-regional smoothing while keeping every value at one hour on one clock (all Cambium24 timestamps are Eastern Time). DATA: Cambium24 MidCase hourly balancing-area files (Cambium24_MidCase_hourly_balancingArea.zip, downloaded 2026-09-23 from scenarioviewer.nrel.gov), aggregated by the 'gea' field in each file's header to the 18 GEA regions; 2025 model year for onshore, 2040 for offshore, as before. EFFECT: onshore wind Summer Peak Hour20 (the binding hour) 0.9335 -> 0.8029; Winter Peak Hour20 0.81 -> 0.68; offshore wind falls further but has ~6 GW of BAU capacity and is immaterial. Diversity ACROSS DAYS within a region is retained. In a US BAU test run (eps-us HEAD e147e53f basis, 2026-09-23) nothing changed before 2033 (capacity market not binding); afterwards the reliability channel buys more gas and batteries and less wind (2050 onshore wind 564 -> 449 GW, gas CC +56 GW, batteries +26 GW). NOT CAPTURED: regions peak at different hours (e.g. CAISO ~3 hours after the Eastern peak) and the pinned peak days are chosen on national net load; a regional peak-timing correction would require a regional reliability check in the model, not a data change. Balancing-area resolution (133 regions, no transmission even within an ISO) was computed as a lower bound (Hour20 0.75) and not adopted. STATE MODELS are single regions and keep their own Cambium22 national-style statistic; this change does not apply to them. Reviewed by: (pending) - Robbie's recorded view of 2026-09-22 was that the national P30 should stand; the argument here is not the percentile but the free-transmission assumption embedded in the national aggregate.
A52: Demand-altering ELCC (revised 2026-09-30) | B52: 0.82. This factor applies to the net-peak-hour demand reduction that EPS dispatches from grid batteries, demand response and pumped hydro. That reduction is already energy-limited (stored and shiftable energy is spread across the peak day's above-average hours), and battery availability is already derated by the 0.9 demand-altering RAF. The factor therefore represents only residual risks not captured in dispatch: demand-response delivery below enrolled capacity, depletion across consecutive peak days, and peak-timing uncertainty. PJM ELCC class ratings (the previous basis) are mainly duration discounts for PJM's winter-dominated risk and are not used, because applying them to an energy-limited dispatch would count duration twice. Summer-risk accreditation evidence (ERCOT summer-evening 4-hr storage about 55%, SPP summer storage 82-100% at low penetration, E3/SPP summer DR 83%, NREL national storage peaking-capacity analysis) places whole-resource credit at roughly 55-100% of nameplate. With this factor, the EPS pool is credited at about 37-45% of nameplate in the binding hour. Within the 0.8-0.95 range supported by these residual risks, 0.82 is the value at which the 2025 fleet meets the reliability requirement. A flat factor does not capture the decline in storage capacity value with penetration; a penetration-dependent factor is planned. Arithmetic on the DAT-derivation tab, rows 19-28. Wording drafted by Robbie; full citations for the ERCOT, SPP, E3 and NREL sources to be added.
A53: Firm/dispatchable ELCC (revised 2026-09-30) | B53: DRAFT for review. 0.98 for every firm/dispatchable source except hydro (fossil, nuclear, SMR, biomass, MSW, geothermal, CCS and hydrogen types); hydro stays at 0.90 because its derate reflects water limits, not forced outages. For MCF-path plants the reliability credit is MCF x RAF x ELCCAfR, so forced outages and regional availability are already derated by MCF (0.85-0.95) and RAF before this factor applies. At the previous 0.90, the combined credit for gas combined cycle and steam turbines was 0.77, below the NERC GADS 1-EFORd class averages of 0.89-0.95 (2020-2024), which counted outage risk twice. At 0.98 it is 0.84, still at or below those benchmarks, so ELCCAfR now covers only residual risks not captured in MCF or RAF, such as ambient-temperature derates at the summer peak and common-mode fuel-supply risk. Nuclear, SMR, biomass, MSW and geothermal are on the SYSHECF path, so their combined credit is SYSHECF-based; nuclear remains below its 0.975-0.984 benchmark. Arithmetic on the Thermal-derivation tab. Value from Robbie's sandbox setting (2026-09-30); rationale drafted from the NERC GADS benchmarks and pending Robbie's review.

Sheet DAT-derivation
A1: Derivation of the demand-altering technologies ELCC value (PJM blend deployed 2026-09-22; SUPERSEDED 2026-09-30, see row 19 onward)
A3: Step 1 - Market accreditation by resource class, weighted by the EPS credited pool
A4: Resource | B4: Market accreditation | C4: EPS credited pool (GW) | D4: Pool share used (rounded)
A5: 4-hour battery storage | B5: 0.5 | C5: 75.6 | D5: =ROUND(C5/$C$8,2) -> 0.57
A6: Demand response | B6: 0.69 | C6: 41.4 | D6: =ROUND(C6/$C$8,2) -> 0.31
A7: Pumped hydro (10-hr storage class rating) | B7: 0.72 | C7: 15 | D7: =ROUND(C7/$C$8,2) -> 0.11
A8: Total | C8: =SUM(C5:C7) -> 132
A10: Step 2 - Blended effective credit target (sum of rating x share) | B10: =SUMPRODUCT(B5:B7,D5:D7) -> 0.5781
A11: Step 3 - RAF for demand-altering technologies (already applied separately in the model; see InputData/elec/RAF/RAF-demand-altering-techs.csv) | B11: 0.9
A12: Step 4 - ELCC value so that ELCC x RAF = blended target | B12: =B10/B11 -> 0.64233333
A13: Previous deployed value (2026-09-22 to 2026-09-30, superseded) | B13: =ROUND(B12,2) -> 0.64
A16: Sources and methodology notes: About tab (Sources and Notes sections).
A17: Pool GW basis: 2028 US BAU post 2026-09-22 planned-build refresh (batteries = grid battery fleet; DR = DRC input + electrolyzers; pumped hydro = 23.0 GW x ~0.65 binding-hour availability).
A19: Revision 2026-09-30: residual-risk factor applied on top of energy-limited dispatch
A20: Binding-hour delivery of the credited pool before ELCC, share of nameplate (low) | B20: 0.45
A21: Binding-hour delivery of the credited pool before ELCC, share of nameplate (high) | B21: 0.55
A22: Range supported by residual risks not captured in dispatch (low) | B22: 0.8
A23: Range supported by residual risks not captured in dispatch (high) | B23: 0.95
A24: Deployed value: the value within B22:B23 at which the 2025 fleet meets the reliability requirement (base-year consistency check); feeds the ELCCAfR-demand-altering-techs tab | B24: 0.82
A25: Effective credit of the pool in the binding hour, low (= B20 x B24) | B25: =B20*B24 -> 0.369
A26: Effective credit of the pool in the binding hour, high (= B21 x B24) | B26: =B21*B24 -> 0.451
A27: Summer-risk whole-resource benchmarks (share of nameplate): ERCOT summer-evening 4-hr storage ~0.55; SPP summer storage 0.82-1.00 at low penetration; E3 study for SPP, limited-call DR 0.83 in summer; NREL, near-full peak credit for the first tens of GW of storage nationally. The effective credit in B25:B26 sits at or below the low end.
A28: Why the PJM class ratings (rows 3-13) are no longer used: they are mainly duration discounts driven by PJM's winter-dominated risk; applying them to an already energy-limited dispatch counts duration twice. Rows 3-13 are kept as a record.

Sheet Thermal-derivation
A1: Derivation of the firm/dispatchable (thermal) ELCC value (revised 2026-09-30)
A3: Deployed value (feeds every thermal ELCCAfR tab by formula; hydro excluded) | B3: 0.98
A4: Previous value (2026-08-19 to 2026-09-30) | B4: 0.9
A6: Combined reliability credit for MCF-path plants = MCF x RAF x ELCCAfR (2026 inputs)
A7: Plant type | B7: MCF (MCF.csv) | C7: RAF (RAF-generation.csv, deployed) | D7: Credit at previous ELCC | E7: Credit at deployed ELCC | F7: NERC GADS 1-EFORd, 2020-24 class average
A8: natural gas combined cycle | B8: 0.95 | C8: 0.9 | D8: =B8*C8*$B$4 -> 0.7695 | E8: =B8*C8*$B$3 -> 0.8379 | F8: 0.951
A9: natural gas steam turbine | B9: 0.95 | C9: 0.9 | D9: =B9*C9*$B$4 -> 0.7695 | E9: =B9*C9*$B$3 -> 0.8379 | F9: 0.887-0.902
A10: natural gas peaker | B10: 0.95 | C10: 0.9 | D10: =B10*C10*$B$4 -> 0.7695 | E10: =B10*C10*$B$3 -> 0.8379 | F10: 0.910 (GT 50+ MW)
A11: hard coal | B11: 0.85 | C11: 0.63 | D11: =B11*C11*$B$4 -> 0.48195 | E11: =B11*C11*$B$3 -> 0.52479 | F11: 0.860-0.910
A12: petroleum | B12: 0.95 | C12: 0.8 | D12: =B12*C12*$B$4 -> 0.684 | E12: =B12*C12*$B$3 -> 0.7448 | F12: 0.751-0.878
A14: Natural gas peaker RAF was 0.8 until 2026-09-30 (credit at the previous ELCC and RAF = 0.95 x 0.8 x 0.90 = 0.684).
A15: Nuclear, SMR, biomass, MSW and geothermal use the SYSHECF path (BDTPTUMCF = 0), so their combined credit is SYSHECF-based and is not shown here.
A16: Hydro stays at 0.90: its derate reflects water limits, not forced outages.
A17: Benchmark source: NERC GADS EFORd class averages, 5-year 2020-2024 (ISO-NE compilation, updated 2026-03-12). 1-EFORd is the UCAP convention used by PJM, MISO and ISO-NE.
A18: Sources and methodology notes: About tab (Firm/dispatchable ELCC note, 2026-09-30).

Sheet ELCCAfR-solar-pv
A1: solar pv | B1: Hour0 | C1: Hour1 | D1: Hour2 | E1: Hour3 | F1: Hour4 | G1: Hour5 | H1: Hour6 | I1: Hour7 | J1: Hour8 | K1: Hour9 | L1: Hour10 | M1: Hour11 | N1: Hour12 | O1: Hour13 | P1: Hour14 | Q1: Hour15 | R1: Hour16 | S1: Hour17 | T1: Hour18 | U1: Hour19 | V1: Hour20 | W1: Hour21 | X1: Hour22 | Y1: Hour23
A2: Representative Day 1 | B2: 1 | C2: 1 | D2: 1 | E2: 1 | F2: 1 | G2: 1 | H2: 1 | I2: 1 | J2: 1 | K2: 1 | L2: 1 | M2: 1 | N2: 1 | O2: 1 | P2: 1 | Q2: 1 | R2: 1 | S2: 1 | T2: 1 | U2: 1 | V2: 1 | W2: 1 | X2: 1 | Y2: 1
A3: Representative Day 2 | B3: 1 | C3: 1 | D3: 1 | E3: 1 | F3: 1 | G3: 1 | H3: 1 | I3: 1 | J3: 1 | K3: 1 | L3: 1 | M3: 1 | N3: 1 | O3: 1 | P3: 1 | Q3: 1 | R3: 1 | S3: 1 | T3: 1 | U3: 1 | V3: 1 | W3: 1 | X3: 1 | Y3: 1
A4: Representative Day 3 | B4: 1 | C4: 1 | D4: 1 | E4: 1 | F4: 1 | G4: 1 | H4: 1 | I4: 1 | J4: 1 | K4: 1 | L4: 1 | M4: 1 | N4: 1 | O4: 1 | P4: 1 | Q4: 1 | R4: 1 | S4: 1 | T4: 1 | U4: 1 | V4: 1 | W4: 1 | X4: 1 | Y4: 1
A5: Representative Day 4 | B5: 1 | C5: 1 | D5: 1 | E5: 1 | F5: 1 | G5: 1 | H5: 1 | I5: 1 | J5: 1 | K5: 1 | L5: 1 | M5: 1 | N5: 1 | O5: 1 | P5: 1 | Q5: 1 | R5: 1 | S5: 1 | T5: 1 | U5: 1 | V5: 1 | W5: 1 | X5: 1 | Y5: 1
A6: Net Peak Summer Day | B6: 1 | C6: 1 | D6: 1 | E6: 1 | F6: 0.233 | G6: 0.709 | H6: 0.8568 | I6: 0.8872 | J6: 0.9374 | K6: 0.9594 | L6: 0.9706 | M6: 0.9839 | N6: 0.9844 | O6: 0.9757 | P6: 0.9764 | Q6: 0.9526 | R6: 0.9416 | S6: 0.9197 | T6: 0.9012 | U6: 0.8342 | V6: 0.7944 | W6: 0.5027 | X6: 1 | Y6: 1
A7: Net Peak Winter Day | B7: 1 | C7: 1 | D7: 1 | E7: 1 | F7: 1 | G7: 1 | H7: 1 | I7: 0.7405 | J7: 0.7412 | K7: 0.7874 | L7: 0.8352 | M7: 0.8854 | N7: 0.8785 | O7: 0.8576 | P7: 0.8445 | Q7: 0.8319 | R7: 0.8491 | S7: 0.8341 | T7: 0.701 | U7: 0.02 | V7: 1 | W7: 1 | X7: 1 | Y7: 1

Sheet ELCCAfR-solar-thermal
A1: solar thermal | B1: Hour0 | C1: Hour1 | D1: Hour2 | E1: Hour3 | F1: Hour4 | G1: Hour5 | H1: Hour6 | I1: Hour7 | J1: Hour8 | K1: Hour9 | L1: Hour10 | M1: Hour11 | N1: Hour12 | O1: Hour13 | P1: Hour14 | Q1: Hour15 | R1: Hour16 | S1: Hour17 | T1: Hour18 | U1: Hour19 | V1: Hour20 | W1: Hour21 | X1: Hour22 | Y1: Hour23
A2: Representative Day 1 | B2: 1 | C2: 1 | D2: 1 | E2: 1 | F2: 1 | G2: 1 | H2: 1 | I2: 1 | J2: 1 | K2: 1 | L2: 1 | M2: 1 | N2: 1 | O2: 1 | P2: 1 | Q2: 1 | R2: 1 | S2: 1 | T2: 1 | U2: 1 | V2: 1 | W2: 1 | X2: 1 | Y2: 1
A3: Representative Day 2 | B3: 1 | C3: 1 | D3: 1 | E3: 1 | F3: 1 | G3: 1 | H3: 1 | I3: 1 | J3: 1 | K3: 1 | L3: 1 | M3: 1 | N3: 1 | O3: 1 | P3: 1 | Q3: 1 | R3: 1 | S3: 1 | T3: 1 | U3: 1 | V3: 1 | W3: 1 | X3: 1 | Y3: 1
A4: Representative Day 3 | B4: 1 | C4: 1 | D4: 1 | E4: 1 | F4: 1 | G4: 1 | H4: 1 | I4: 1 | J4: 1 | K4: 1 | L4: 1 | M4: 1 | N4: 1 | O4: 1 | P4: 1 | Q4: 1 | R4: 1 | S4: 1 | T4: 1 | U4: 1 | V4: 1 | W4: 1 | X4: 1 | Y4: 1
A5: Representative Day 4 | B5: 1 | C5: 1 | D5: 1 | E5: 1 | F5: 1 | G5: 1 | H5: 1 | I5: 1 | J5: 1 | K5: 1 | L5: 1 | M5: 1 | N5: 1 | O5: 1 | P5: 1 | Q5: 1 | R5: 1 | S5: 1 | T5: 1 | U5: 1 | V5: 1 | W5: 1 | X5: 1 | Y5: 1
A6: Net Peak Summer Day | B6: 1 | C6: 1 | D6: 1 | E6: 1 | F6: 1 | G6: 1 | H6: 1 | I6: 0 | J6: 0.8639 | K6: 1 | L6: 1 | M6: 0.9716 | N6: 0.9672 | O6: 1 | P6: 1 | Q6: 1 | R6: 1 | S6: 1 | T6: 1 | U6: 0.9313 | V6: 0.7022 | W6: 1 | X6: 1 | Y6: 1
A7: Net Peak Winter Day | B7: 1 | C7: 1 | D7: 1 | E7: 1 | F7: 1 | G7: 1 | H7: 1 | I7: 1 | J7: 1 | K7: 0.2419 | L7: 0.9532 | M7: 0.8804 | N7: 0.9782 | O7: 0.9895 | P7: 0.9927 | Q7: 1 | R7: 1 | S7: 1 | T7: 0.8902 | U7: 0 | V7: 1 | W7: 1 | X7: 1 | Y7: 1

Sheet ELCCAfR-onshore-wind
A1: onshore wind | B1: Hour0 | C1: Hour1 | D1: Hour2 | E1: Hour3 | F1: Hour4 | G1: Hour5 | H1: Hour6 | I1: Hour7 | J1: Hour8 | K1: Hour9 | L1: Hour10 | M1: Hour11 | N1: Hour12 | O1: Hour13 | P1: Hour14 | Q1: Hour15 | R1: Hour16 | S1: Hour17 | T1: Hour18 | U1: Hour19 | V1: Hour20 | W1: Hour21 | X1: Hour22 | Y1: Hour23
A2: Representative Day 1 | B2: 1 | C2: 1 | D2: 1 | E2: 1 | F2: 1 | G2: 1 | H2: 1 | I2: 1 | J2: 1 | K2: 1 | L2: 1 | M2: 1 | N2: 1 | O2: 1 | P2: 1 | Q2: 1 | R2: 1 | S2: 1 | T2: 1 | U2: 1 | V2: 1 | W2: 1 | X2: 1 | Y2: 1
A3: Representative Day 2 | B3: 1 | C3: 1 | D3: 1 | E3: 1 | F3: 1 | G3: 1 | H3: 1 | I3: 1 | J3: 1 | K3: 1 | L3: 1 | M3: 1 | N3: 1 | O3: 1 | P3: 1 | Q3: 1 | R3: 1 | S3: 1 | T3: 1 | U3: 1 | V3: 1 | W3: 1 | X3: 1 | Y3: 1
A4: Representative Day 3 | B4: 1 | C4: 1 | D4: 1 | E4: 1 | F4: 1 | G4: 1 | H4: 1 | I4: 1 | J4: 1 | K4: 1 | L4: 1 | M4: 1 | N4: 1 | O4: 1 | P4: 1 | Q4: 1 | R4: 1 | S4: 1 | T4: 1 | U4: 1 | V4: 1 | W4: 1 | X4: 1 | Y4: 1
A5: Representative Day 4 | B5: 1 | C5: 1 | D5: 1 | E5: 1 | F5: 1 | G5: 1 | H5: 1 | I5: 1 | J5: 1 | K5: 1 | L5: 1 | M5: 1 | N5: 1 | O5: 1 | P5: 1 | Q5: 1 | R5: 1 | S5: 1 | T5: 1 | U5: 1 | V5: 1 | W5: 1 | X5: 1 | Y5: 1
A6: Net Peak Summer Day | B6: 0.8087 | C6: 0.801 | D6: 0.7873 | E6: 0.7594 | F6: 0.746 | G6: 0.7381 | H6: 0.7303 | I6: 0.6455 | J6: 0.4884 | K6: 0.4448 | L6: 0.4695 | M6: 0.4994 | N6: 0.4593 | O6: 0.4743 | P6: 0.5139 | Q6: 0.5791 | R6: 0.6387 | S6: 0.716 | T6: 0.7641 | U6: 0.7687 | V6: 0.8029 | W6: 0.8225 | X6: 0.7908 | Y6: 0.7818
A7: Net Peak Winter Day | B7: 0.6936 | C7: 0.6744 | D7: 0.6634 | E7: 0.6747 | F7: 0.7006 | G7: 0.7177 | H7: 0.7161 | I7: 0.6676 | J7: 0.6678 | K7: 0.5934 | L7: 0.57 | M7: 0.5104 | N7: 0.4738 | O7: 0.4681 | P7: 0.4829 | Q7: 0.4884 | R7: 0.5145 | S7: 0.5589 | T7: 0.6036 | U7: 0.6518 | V7: 0.678 | W7: 0.6812 | X7: 0.6573 | Y7: 0.633

Sheet ELCCAfR-offshore-wind
A1: offshore wind | B1: Hour0 | C1: Hour1 | D1: Hour2 | E1: Hour3 | F1: Hour4 | G1: Hour5 | H1: Hour6 | I1: Hour7 | J1: Hour8 | K1: Hour9 | L1: Hour10 | M1: Hour11 | N1: Hour12 | O1: Hour13 | P1: Hour14 | Q1: Hour15 | R1: Hour16 | S1: Hour17 | T1: Hour18 | U1: Hour19 | V1: Hour20 | W1: Hour21 | X1: Hour22 | Y1: Hour23
A2: Representative Day 1 | B2: 1 | C2: 1 | D2: 1 | E2: 1 | F2: 1 | G2: 1 | H2: 1 | I2: 1 | J2: 1 | K2: 1 | L2: 1 | M2: 1 | N2: 1 | O2: 1 | P2: 1 | Q2: 1 | R2: 1 | S2: 1 | T2: 1 | U2: 1 | V2: 1 | W2: 1 | X2: 1 | Y2: 1
A3: Representative Day 2 | B3: 1 | C3: 1 | D3: 1 | E3: 1 | F3: 1 | G3: 1 | H3: 1 | I3: 1 | J3: 1 | K3: 1 | L3: 1 | M3: 1 | N3: 1 | O3: 1 | P3: 1 | Q3: 1 | R3: 1 | S3: 1 | T3: 1 | U3: 1 | V3: 1 | W3: 1 | X3: 1 | Y3: 1
A4: Representative Day 3 | B4: 1 | C4: 1 | D4: 1 | E4: 1 | F4: 1 | G4: 1 | H4: 1 | I4: 1 | J4: 1 | K4: 1 | L4: 1 | M4: 1 | N4: 1 | O4: 1 | P4: 1 | Q4: 1 | R4: 1 | S4: 1 | T4: 1 | U4: 1 | V4: 1 | W4: 1 | X4: 1 | Y4: 1
A5: Representative Day 4 | B5: 1 | C5: 1 | D5: 1 | E5: 1 | F5: 1 | G5: 1 | H5: 1 | I5: 1 | J5: 1 | K5: 1 | L5: 1 | M5: 1 | N5: 1 | O5: 1 | P5: 1 | Q5: 1 | R5: 1 | S5: 1 | T5: 1 | U5: 1 | V5: 1 | W5: 1 | X5: 1 | Y5: 1
A6: Net Peak Summer Day | B6: 0.3342 | C6: 0.3227 | D6: 0.3139 | E6: 0.3015 | F6: 0.2806 | G6: 0.3124 | H6: 0.3376 | I6: 0.336 | J6: 0.2908 | K6: 0.3335 | L6: 0.3762 | M6: 0.3539 | N6: 0.3468 | O6: 0.3099 | P6: 0.3416 | Q6: 0.3879 | R6: 0.4142 | S6: 0.4311 | T6: 0.4187 | U6: 0.4417 | V6: 0.4141 | W6: 0.4328 | X6: 0.4036 | Y6: 0.4314
A7: Net Peak Winter Day | B7: 0.8551 | C7: 0.8756 | D7: 0.8773 | E7: 0.8858 | F7: 0.9117 | G7: 0.9661 | H7: 0.9644 | I7: 0.8964 | J7: 0.8249 | K7: 0.7466 | L7: 0.6587 | M7: 0.5957 | N7: 0.6236 | O7: 0.5908 | P7: 0.5929 | Q7: 0.6201 | R7: 0.689 | S7: 0.7286 | T7: 0.7342 | U7: 0.7883 | V7: 0.8414 | W7: 0.8114 | X7: 0.8037 | Y7: 0.7322

Sheet ELCCAfR-MSW
A1: municipal solid waste | B1: Hour0 | C1: Hour1 | D1: Hour2 | E1: Hour3 | F1: Hour4 | G1: Hour5 | H1: Hour6 | I1: Hour7 | J1: Hour8 | K1: Hour9 | L1: Hour10 | M1: Hour11 | N1: Hour12 | O1: Hour13 | P1: Hour14 | Q1: Hour15 | R1: Hour16 | S1: Hour17 | T1: Hour18 | U1: Hour19 | V1: Hour20 | W1: Hour21 | X1: Hour22 | Y1: Hour23
A2: Representative Day 1 | B2: ='Thermal-derivation'!$B$3 -> 0.98 | C2: ='Thermal-derivation'!$B$3 -> 0.98 | D2: ='Thermal-derivation'!$B$3 -> 0.98 | E2: ='Thermal-derivation'!$B$3 -> 0.98 | F2: ='Thermal-derivation'!$B$3 -> 0.98 | G2: ='Thermal-derivation'!$B$3 -> 0.98 | H2: ='Thermal-derivation'!$B$3 -> 0.98 | I2: ='Thermal-derivation'!$B$3 -> 0.98 | ... Y2: ='Thermal-derivation'!$B$3 -> 0.98
A3: Representative Day 2 | B3: ='Thermal-derivation'!$B$3 -> 0.98 | C3: ='Thermal-derivation'!$B$3 -> 0.98 | D3: ='Thermal-derivation'!$B$3 -> 0.98 | E3: ='Thermal-derivation'!$B$3 -> 0.98 | F3: ='Thermal-derivation'!$B$3 -> 0.98 | G3: ='Thermal-derivation'!$B$3 -> 0.98 | H3: ='Thermal-derivation'!$B$3 -> 0.98 | I3: ='Thermal-derivation'!$B$3 -> 0.98 | ... Y3: ='Thermal-derivation'!$B$3 -> 0.98
A4: Representative Day 3 | B4: ='Thermal-derivation'!$B$3 -> 0.98 | C4: ='Thermal-derivation'!$B$3 -> 0.98 | D4: ='Thermal-derivation'!$B$3 -> 0.98 | E4: ='Thermal-derivation'!$B$3 -> 0.98 | F4: ='Thermal-derivation'!$B$3 -> 0.98 | G4: ='Thermal-derivation'!$B$3 -> 0.98 | H4: ='Thermal-derivation'!$B$3 -> 0.98 | I4: ='Thermal-derivation'!$B$3 -> 0.98 | ... Y4: ='Thermal-derivation'!$B$3 -> 0.98
A5: Representative Day 4 | B5: ='Thermal-derivation'!$B$3 -> 0.98 | C5: ='Thermal-derivation'!$B$3 -> 0.98 | D5: ='Thermal-derivation'!$B$3 -> 0.98 | E5: ='Thermal-derivation'!$B$3 -> 0.98 | F5: ='Thermal-derivation'!$B$3 -> 0.98 | G5: ='Thermal-derivation'!$B$3 -> 0.98 | H5: ='Thermal-derivation'!$B$3 -> 0.98 | I5: ='Thermal-derivation'!$B$3 -> 0.98 | ... Y5: ='Thermal-derivation'!$B$3 -> 0.98
A6: Net Peak Summer Day | B6: ='Thermal-derivation'!$B$3 -> 0.98 | C6: ='Thermal-derivation'!$B$3 -> 0.98 | D6: ='Thermal-derivation'!$B$3 -> 0.98 | E6: ='Thermal-derivation'!$B$3 -> 0.98 | F6: ='Thermal-derivation'!$B$3 -> 0.98 | G6: ='Thermal-derivation'!$B$3 -> 0.98 | H6: ='Thermal-derivation'!$B$3 -> 0.98 | I6: ='Thermal-derivation'!$B$3 -> 0.98 | ... Y6: ='Thermal-derivation'!$B$3 -> 0.98
A7: Net Peak Winter Day | B7: ='Thermal-derivation'!$B$3 -> 0.98 | C7: ='Thermal-derivation'!$B$3 -> 0.98 | D7: ='Thermal-derivation'!$B$3 -> 0.98 | E7: ='Thermal-derivation'!$B$3 -> 0.98 | F7: ='Thermal-derivation'!$B$3 -> 0.98 | G7: ='Thermal-derivation'!$B$3 -> 0.98 | H7: ='Thermal-derivation'!$B$3 -> 0.98 | I7: ='Thermal-derivation'!$B$3 -> 0.98 | ... Y7: ='Thermal-derivation'!$B$3 -> 0.98

Sheet ELCCAfR-SMR
A1: small modular reactor | B1: Hour0 | C1: Hour1 | D1: Hour2 | E1: Hour3 | F1: Hour4 | G1: Hour5 | H1: Hour6 | I1: Hour7 | J1: Hour8 | K1: Hour9 | L1: Hour10 | M1: Hour11 | N1: Hour12 | O1: Hour13 | P1: Hour14 | Q1: Hour15 | R1: Hour16 | S1: Hour17 | T1: Hour18 | U1: Hour19 | V1: Hour20 | W1: Hour21 | X1: Hour22 | Y1: Hour23
A2: Representative Day 1 | B2: ='Thermal-derivation'!$B$3 -> 0.98 | C2: ='Thermal-derivation'!$B$3 -> 0.98 | D2: ='Thermal-derivation'!$B$3 -> 0.98 | E2: ='Thermal-derivation'!$B$3 -> 0.98 | F2: ='Thermal-derivation'!$B$3 -> 0.98 | G2: ='Thermal-derivation'!$B$3 -> 0.98 | H2: ='Thermal-derivation'!$B$3 -> 0.98 | I2: ='Thermal-derivation'!$B$3 -> 0.98 | ... Y2: ='Thermal-derivation'!$B$3 -> 0.98
A3: Representative Day 2 | B3: ='Thermal-derivation'!$B$3 -> 0.98 | C3: ='Thermal-derivation'!$B$3 -> 0.98 | D3: ='Thermal-derivation'!$B$3 -> 0.98 | E3: ='Thermal-derivation'!$B$3 -> 0.98 | F3: ='Thermal-derivation'!$B$3 -> 0.98 | G3: ='Thermal-derivation'!$B$3 -> 0.98 | H3: ='Thermal-derivation'!$B$3 -> 0.98 | I3: ='Thermal-derivation'!$B$3 -> 0.98 | ... Y3: ='Thermal-derivation'!$B$3 -> 0.98
A4: Representative Day 3 | B4: ='Thermal-derivation'!$B$3 -> 0.98 | C4: ='Thermal-derivation'!$B$3 -> 0.98 | D4: ='Thermal-derivation'!$B$3 -> 0.98 | E4: ='Thermal-derivation'!$B$3 -> 0.98 | F4: ='Thermal-derivation'!$B$3 -> 0.98 | G4: ='Thermal-derivation'!$B$3 -> 0.98 | H4: ='Thermal-derivation'!$B$3 -> 0.98 | I4: ='Thermal-derivation'!$B$3 -> 0.98 | ... Y4: ='Thermal-derivation'!$B$3 -> 0.98
A5: Representative Day 4 | B5: ='Thermal-derivation'!$B$3 -> 0.98 | C5: ='Thermal-derivation'!$B$3 -> 0.98 | D5: ='Thermal-derivation'!$B$3 -> 0.98 | E5: ='Thermal-derivation'!$B$3 -> 0.98 | F5: ='Thermal-derivation'!$B$3 -> 0.98 | G5: ='Thermal-derivation'!$B$3 -> 0.98 | H5: ='Thermal-derivation'!$B$3 -> 0.98 | I5: ='Thermal-derivation'!$B$3 -> 0.98 | ... Y5: ='Thermal-derivation'!$B$3 -> 0.98
A6: Net Peak Summer Day | B6: ='Thermal-derivation'!$B$3 -> 0.98 | C6: ='Thermal-derivation'!$B$3 -> 0.98 | D6: ='Thermal-derivation'!$B$3 -> 0.98 | E6: ='Thermal-derivation'!$B$3 -> 0.98 | F6: ='Thermal-derivation'!$B$3 -> 0.98 | G6: ='Thermal-derivation'!$B$3 -> 0.98 | H6: ='Thermal-derivation'!$B$3 -> 0.98 | I6: ='Thermal-derivation'!$B$3 -> 0.98 | ... Y6: ='Thermal-derivation'!$B$3 -> 0.98
A7: Net Peak Winter Day | B7: ='Thermal-derivation'!$B$3 -> 0.98 | C7: ='Thermal-derivation'!$B$3 -> 0.98 | D7: ='Thermal-derivation'!$B$3 -> 0.98 | E7: ='Thermal-derivation'!$B$3 -> 0.98 | F7: ='Thermal-derivation'!$B$3 -> 0.98 | G7: ='Thermal-derivation'!$B$3 -> 0.98 | H7: ='Thermal-derivation'!$B$3 -> 0.98 | I7: ='Thermal-derivation'!$B$3 -> 0.98 | ... Y7: ='Thermal-derivation'!$B$3 -> 0.98

Sheet ELCCAfR-biomass-CCS
A1: biomass w CCS | B1: Hour0 | C1: Hour1 | D1: Hour2 | E1: Hour3 | F1: Hour4 | G1: Hour5 | H1: Hour6 | I1: Hour7 | J1: Hour8 | K1: Hour9 | L1: Hour10 | M1: Hour11 | N1: Hour12 | O1: Hour13 | P1: Hour14 | Q1: Hour15 | R1: Hour16 | S1: Hour17 | T1: Hour18 | U1: Hour19 | V1: Hour20 | W1: Hour21 | X1: Hour22 | Y1: Hour23
A2: Representative Day 1 | B2: ='Thermal-derivation'!$B$3 -> 0.98 | C2: ='Thermal-derivation'!$B$3 -> 0.98 | D2: ='Thermal-derivation'!$B$3 -> 0.98 | E2: ='Thermal-derivation'!$B$3 -> 0.98 | F2: ='Thermal-derivation'!$B$3 -> 0.98 | G2: ='Thermal-derivation'!$B$3 -> 0.98 | H2: ='Thermal-derivation'!$B$3 -> 0.98 | I2: ='Thermal-derivation'!$B$3 -> 0.98 | ... Y2: ='Thermal-derivation'!$B$3 -> 0.98
A3: Representative Day 2 | B3: ='Thermal-derivation'!$B$3 -> 0.98 | C3: ='Thermal-derivation'!$B$3 -> 0.98 | D3: ='Thermal-derivation'!$B$3 -> 0.98 | E3: ='Thermal-derivation'!$B$3 -> 0.98 | F3: ='Thermal-derivation'!$B$3 -> 0.98 | G3: ='Thermal-derivation'!$B$3 -> 0.98 | H3: ='Thermal-derivation'!$B$3 -> 0.98 | I3: ='Thermal-derivation'!$B$3 -> 0.98 | ... Y3: ='Thermal-derivation'!$B$3 -> 0.98
A4: Representative Day 3 | B4: ='Thermal-derivation'!$B$3 -> 0.98 | C4: ='Thermal-derivation'!$B$3 -> 0.98 | D4: ='Thermal-derivation'!$B$3 -> 0.98 | E4: ='Thermal-derivation'!$B$3 -> 0.98 | F4: ='Thermal-derivation'!$B$3 -> 0.98 | G4: ='Thermal-derivation'!$B$3 -> 0.98 | H4: ='Thermal-derivation'!$B$3 -> 0.98 | I4: ='Thermal-derivation'!$B$3 -> 0.98 | ... Y4: ='Thermal-derivation'!$B$3 -> 0.98
A5: Representative Day 4 | B5: ='Thermal-derivation'!$B$3 -> 0.98 | C5: ='Thermal-derivation'!$B$3 -> 0.98 | D5: ='Thermal-derivation'!$B$3 -> 0.98 | E5: ='Thermal-derivation'!$B$3 -> 0.98 | F5: ='Thermal-derivation'!$B$3 -> 0.98 | G5: ='Thermal-derivation'!$B$3 -> 0.98 | H5: ='Thermal-derivation'!$B$3 -> 0.98 | I5: ='Thermal-derivation'!$B$3 -> 0.98 | ... Y5: ='Thermal-derivation'!$B$3 -> 0.98
A6: Net Peak Summer Day | B6: ='Thermal-derivation'!$B$3 -> 0.98 | C6: ='Thermal-derivation'!$B$3 -> 0.98 | D6: ='Thermal-derivation'!$B$3 -> 0.98 | E6: ='Thermal-derivation'!$B$3 -> 0.98 | F6: ='Thermal-derivation'!$B$3 -> 0.98 | G6: ='Thermal-derivation'!$B$3 -> 0.98 | H6: ='Thermal-derivation'!$B$3 -> 0.98 | I6: ='Thermal-derivation'!$B$3 -> 0.98 | ... Y6: ='Thermal-derivation'!$B$3 -> 0.98
A7: Net Peak Winter Day | B7: ='Thermal-derivation'!$B$3 -> 0.98 | C7: ='Thermal-derivation'!$B$3 -> 0.98 | D7: ='Thermal-derivation'!$B$3 -> 0.98 | E7: ='Thermal-derivation'!$B$3 -> 0.98 | F7: ='Thermal-derivation'!$B$3 -> 0.98 | G7: ='Thermal-derivation'!$B$3 -> 0.98 | H7: ='Thermal-derivation'!$B$3 -> 0.98 | I7: ='Thermal-derivation'!$B$3 -> 0.98 | ... Y7: ='Thermal-derivation'!$B$3 -> 0.98

Sheet ELCCAfR-biomass
A1: biomass | B1: Hour0 | C1: Hour1 | D1: Hour2 | E1: Hour3 | F1: Hour4 | G1: Hour5 | H1: Hour6 | I1: Hour7 | J1: Hour8 | K1: Hour9 | L1: Hour10 | M1: Hour11 | N1: Hour12 | O1: Hour13 | P1: Hour14 | Q1: Hour15 | R1: Hour16 | S1: Hour17 | T1: Hour18 | U1: Hour19 | V1: Hour20 | W1: Hour21 | X1: Hour22 | Y1: Hour23
A2: Representative Day 1 | B2: ='Thermal-derivation'!$B$3 -> 0.98 | C2: ='Thermal-derivation'!$B$3 -> 0.98 | D2: ='Thermal-derivation'!$B$3 -> 0.98 | E2: ='Thermal-derivation'!$B$3 -> 0.98 | F2: ='Thermal-derivation'!$B$3 -> 0.98 | G2: ='Thermal-derivation'!$B$3 -> 0.98 | H2: ='Thermal-derivation'!$B$3 -> 0.98 | I2: ='Thermal-derivation'!$B$3 -> 0.98 | ... Y2: ='Thermal-derivation'!$B$3 -> 0.98
A3: Representative Day 2 | B3: ='Thermal-derivation'!$B$3 -> 0.98 | C3: ='Thermal-derivation'!$B$3 -> 0.98 | D3: ='Thermal-derivation'!$B$3 -> 0.98 | E3: ='Thermal-derivation'!$B$3 -> 0.98 | F3: ='Thermal-derivation'!$B$3 -> 0.98 | G3: ='Thermal-derivation'!$B$3 -> 0.98 | H3: ='Thermal-derivation'!$B$3 -> 0.98 | I3: ='Thermal-derivation'!$B$3 -> 0.98 | ... Y3: ='Thermal-derivation'!$B$3 -> 0.98
A4: Representative Day 3 | B4: ='Thermal-derivation'!$B$3 -> 0.98 | C4: ='Thermal-derivation'!$B$3 -> 0.98 | D4: ='Thermal-derivation'!$B$3 -> 0.98 | E4: ='Thermal-derivation'!$B$3 -> 0.98 | F4: ='Thermal-derivation'!$B$3 -> 0.98 | G4: ='Thermal-derivation'!$B$3 -> 0.98 | H4: ='Thermal-derivation'!$B$3 -> 0.98 | I4: ='Thermal-derivation'!$B$3 -> 0.98 | ... Y4: ='Thermal-derivation'!$B$3 -> 0.98
A5: Representative Day 4 | B5: ='Thermal-derivation'!$B$3 -> 0.98 | C5: ='Thermal-derivation'!$B$3 -> 0.98 | D5: ='Thermal-derivation'!$B$3 -> 0.98 | E5: ='Thermal-derivation'!$B$3 -> 0.98 | F5: ='Thermal-derivation'!$B$3 -> 0.98 | G5: ='Thermal-derivation'!$B$3 -> 0.98 | H5: ='Thermal-derivation'!$B$3 -> 0.98 | I5: ='Thermal-derivation'!$B$3 -> 0.98 | ... Y5: ='Thermal-derivation'!$B$3 -> 0.98
A6: Net Peak Summer Day | B6: ='Thermal-derivation'!$B$3 -> 0.98 | C6: ='Thermal-derivation'!$B$3 -> 0.98 | D6: ='Thermal-derivation'!$B$3 -> 0.98 | E6: ='Thermal-derivation'!$B$3 -> 0.98 | F6: ='Thermal-derivation'!$B$3 -> 0.98 | G6: ='Thermal-derivation'!$B$3 -> 0.98 | H6: ='Thermal-derivation'!$B$3 -> 0.98 | I6: ='Thermal-derivation'!$B$3 -> 0.98 | ... Y6: ='Thermal-derivation'!$B$3 -> 0.98
A7: Net Peak Winter Day | B7: ='Thermal-derivation'!$B$3 -> 0.98 | C7: ='Thermal-derivation'!$B$3 -> 0.98 | D7: ='Thermal-derivation'!$B$3 -> 0.98 | E7: ='Thermal-derivation'!$B$3 -> 0.98 | F7: ='Thermal-derivation'!$B$3 -> 0.98 | G7: ='Thermal-derivation'!$B$3 -> 0.98 | H7: ='Thermal-derivation'!$B$3 -> 0.98 | I7: ='Thermal-derivation'!$B$3 -> 0.98 | ... Y7: ='Thermal-derivation'!$B$3 -> 0.98

Sheet ELCCAfR-combined-cycle-CCS
A1: natural gas combined cycle w CCS | B1: Hour0 | C1: Hour1 | D1: Hour2 | E1: Hour3 | F1: Hour4 | G1: Hour5 | H1: Hour6 | I1: Hour7 | J1: Hour8 | K1: Hour9 | L1: Hour10 | M1: Hour11 | N1: Hour12 | O1: Hour13 | P1: Hour14 | Q1: Hour15 | R1: Hour16 | S1: Hour17 | T1: Hour18 | U1: Hour19 | V1: Hour20 | W1: Hour21 | X1: Hour22 | Y1: Hour23
A2: Representative Day 1 | B2: ='Thermal-derivation'!$B$3 -> 0.98 | C2: ='Thermal-derivation'!$B$3 -> 0.98 | D2: ='Thermal-derivation'!$B$3 -> 0.98 | E2: ='Thermal-derivation'!$B$3 -> 0.98 | F2: ='Thermal-derivation'!$B$3 -> 0.98 | G2: ='Thermal-derivation'!$B$3 -> 0.98 | H2: ='Thermal-derivation'!$B$3 -> 0.98 | I2: ='Thermal-derivation'!$B$3 -> 0.98 | ... Y2: ='Thermal-derivation'!$B$3 -> 0.98
A3: Representative Day 2 | B3: ='Thermal-derivation'!$B$3 -> 0.98 | C3: ='Thermal-derivation'!$B$3 -> 0.98 | D3: ='Thermal-derivation'!$B$3 -> 0.98 | E3: ='Thermal-derivation'!$B$3 -> 0.98 | F3: ='Thermal-derivation'!$B$3 -> 0.98 | G3: ='Thermal-derivation'!$B$3 -> 0.98 | H3: ='Thermal-derivation'!$B$3 -> 0.98 | I3: ='Thermal-derivation'!$B$3 -> 0.98 | ... Y3: ='Thermal-derivation'!$B$3 -> 0.98
A4: Representative Day 3 | B4: ='Thermal-derivation'!$B$3 -> 0.98 | C4: ='Thermal-derivation'!$B$3 -> 0.98 | D4: ='Thermal-derivation'!$B$3 -> 0.98 | E4: ='Thermal-derivation'!$B$3 -> 0.98 | F4: ='Thermal-derivation'!$B$3 -> 0.98 | G4: ='Thermal-derivation'!$B$3 -> 0.98 | H4: ='Thermal-derivation'!$B$3 -> 0.98 | I4: ='Thermal-derivation'!$B$3 -> 0.98 | ... Y4: ='Thermal-derivation'!$B$3 -> 0.98
A5: Representative Day 4 | B5: ='Thermal-derivation'!$B$3 -> 0.98 | C5: ='Thermal-derivation'!$B$3 -> 0.98 | D5: ='Thermal-derivation'!$B$3 -> 0.98 | E5: ='Thermal-derivation'!$B$3 -> 0.98 | F5: ='Thermal-derivation'!$B$3 -> 0.98 | G5: ='Thermal-derivation'!$B$3 -> 0.98 | H5: ='Thermal-derivation'!$B$3 -> 0.98 | I5: ='Thermal-derivation'!$B$3 -> 0.98 | ... Y5: ='Thermal-derivation'!$B$3 -> 0.98
A6: Net Peak Summer Day | B6: ='Thermal-derivation'!$B$3 -> 0.98 | C6: ='Thermal-derivation'!$B$3 -> 0.98 | D6: ='Thermal-derivation'!$B$3 -> 0.98 | E6: ='Thermal-derivation'!$B$3 -> 0.98 | F6: ='Thermal-derivation'!$B$3 -> 0.98 | G6: ='Thermal-derivation'!$B$3 -> 0.98 | H6: ='Thermal-derivation'!$B$3 -> 0.98 | I6: ='Thermal-derivation'!$B$3 -> 0.98 | ... Y6: ='Thermal-derivation'!$B$3 -> 0.98
A7: Net Peak Winter Day | B7: ='Thermal-derivation'!$B$3 -> 0.98 | C7: ='Thermal-derivation'!$B$3 -> 0.98 | D7: ='Thermal-derivation'!$B$3 -> 0.98 | E7: ='Thermal-derivation'!$B$3 -> 0.98 | F7: ='Thermal-derivation'!$B$3 -> 0.98 | G7: ='Thermal-derivation'!$B$3 -> 0.98 | H7: ='Thermal-derivation'!$B$3 -> 0.98 | I7: ='Thermal-derivation'!$B$3 -> 0.98 | ... Y7: ='Thermal-derivation'!$B$3 -> 0.98

Sheet ELCCAfR-combined-cycle
A1: natural gas combined cycle | B1: Hour0 | C1: Hour1 | D1: Hour2 | E1: Hour3 | F1: Hour4 | G1: Hour5 | H1: Hour6 | I1: Hour7 | J1: Hour8 | K1: Hour9 | L1: Hour10 | M1: Hour11 | N1: Hour12 | O1: Hour13 | P1: Hour14 | Q1: Hour15 | R1: Hour16 | S1: Hour17 | T1: Hour18 | U1: Hour19 | V1: Hour20 | W1: Hour21 | X1: Hour22 | Y1: Hour23
A2: Representative Day 1 | B2: ='Thermal-derivation'!$B$3 -> 0.98 | C2: ='Thermal-derivation'!$B$3 -> 0.98 | D2: ='Thermal-derivation'!$B$3 -> 0.98 | E2: ='Thermal-derivation'!$B$3 -> 0.98 | F2: ='Thermal-derivation'!$B$3 -> 0.98 | G2: ='Thermal-derivation'!$B$3 -> 0.98 | H2: ='Thermal-derivation'!$B$3 -> 0.98 | I2: ='Thermal-derivation'!$B$3 -> 0.98 | ... Y2: ='Thermal-derivation'!$B$3 -> 0.98
A3: Representative Day 2 | B3: ='Thermal-derivation'!$B$3 -> 0.98 | C3: ='Thermal-derivation'!$B$3 -> 0.98 | D3: ='Thermal-derivation'!$B$3 -> 0.98 | E3: ='Thermal-derivation'!$B$3 -> 0.98 | F3: ='Thermal-derivation'!$B$3 -> 0.98 | G3: ='Thermal-derivation'!$B$3 -> 0.98 | H3: ='Thermal-derivation'!$B$3 -> 0.98 | I3: ='Thermal-derivation'!$B$3 -> 0.98 | ... Y3: ='Thermal-derivation'!$B$3 -> 0.98
A4: Representative Day 3 | B4: ='Thermal-derivation'!$B$3 -> 0.98 | C4: ='Thermal-derivation'!$B$3 -> 0.98 | D4: ='Thermal-derivation'!$B$3 -> 0.98 | E4: ='Thermal-derivation'!$B$3 -> 0.98 | F4: ='Thermal-derivation'!$B$3 -> 0.98 | G4: ='Thermal-derivation'!$B$3 -> 0.98 | H4: ='Thermal-derivation'!$B$3 -> 0.98 | I4: ='Thermal-derivation'!$B$3 -> 0.98 | ... Y4: ='Thermal-derivation'!$B$3 -> 0.98
A5: Representative Day 4 | B5: ='Thermal-derivation'!$B$3 -> 0.98 | C5: ='Thermal-derivation'!$B$3 -> 0.98 | D5: ='Thermal-derivation'!$B$3 -> 0.98 | E5: ='Thermal-derivation'!$B$3 -> 0.98 | F5: ='Thermal-derivation'!$B$3 -> 0.98 | G5: ='Thermal-derivation'!$B$3 -> 0.98 | H5: ='Thermal-derivation'!$B$3 -> 0.98 | I5: ='Thermal-derivation'!$B$3 -> 0.98 | ... Y5: ='Thermal-derivation'!$B$3 -> 0.98
A6: Net Peak Summer Day | B6: ='Thermal-derivation'!$B$3 -> 0.98 | C6: ='Thermal-derivation'!$B$3 -> 0.98 | D6: ='Thermal-derivation'!$B$3 -> 0.98 | E6: ='Thermal-derivation'!$B$3 -> 0.98 | F6: ='Thermal-derivation'!$B$3 -> 0.98 | G6: ='Thermal-derivation'!$B$3 -> 0.98 | H6: ='Thermal-derivation'!$B$3 -> 0.98 | I6: ='Thermal-derivation'!$B$3 -> 0.98 | ... Y6: ='Thermal-derivation'!$B$3 -> 0.98
A7: Net Peak Winter Day | B7: ='Thermal-derivation'!$B$3 -> 0.98 | C7: ='Thermal-derivation'!$B$3 -> 0.98 | D7: ='Thermal-derivation'!$B$3 -> 0.98 | E7: ='Thermal-derivation'!$B$3 -> 0.98 | F7: ='Thermal-derivation'!$B$3 -> 0.98 | G7: ='Thermal-derivation'!$B$3 -> 0.98 | H7: ='Thermal-derivation'!$B$3 -> 0.98 | I7: ='Thermal-derivation'!$B$3 -> 0.98 | ... Y7: ='Thermal-derivation'!$B$3 -> 0.98

Sheet ELCCAfR-crude-oil
A1: crude oil | B1: Hour0 | C1: Hour1 | D1: Hour2 | E1: Hour3 | F1: Hour4 | G1: Hour5 | H1: Hour6 | I1: Hour7 | J1: Hour8 | K1: Hour9 | L1: Hour10 | M1: Hour11 | N1: Hour12 | O1: Hour13 | P1: Hour14 | Q1: Hour15 | R1: Hour16 | S1: Hour17 | T1: Hour18 | U1: Hour19 | V1: Hour20 | W1: Hour21 | X1: Hour22 | Y1: Hour23
A2: Representative Day 1 | B2: ='Thermal-derivation'!$B$3 -> 0.98 | C2: ='Thermal-derivation'!$B$3 -> 0.98 | D2: ='Thermal-derivation'!$B$3 -> 0.98 | E2: ='Thermal-derivation'!$B$3 -> 0.98 | F2: ='Thermal-derivation'!$B$3 -> 0.98 | G2: ='Thermal-derivation'!$B$3 -> 0.98 | H2: ='Thermal-derivation'!$B$3 -> 0.98 | I2: ='Thermal-derivation'!$B$3 -> 0.98 | ... Y2: ='Thermal-derivation'!$B$3 -> 0.98
A3: Representative Day 2 | B3: ='Thermal-derivation'!$B$3 -> 0.98 | C3: ='Thermal-derivation'!$B$3 -> 0.98 | D3: ='Thermal-derivation'!$B$3 -> 0.98 | E3: ='Thermal-derivation'!$B$3 -> 0.98 | F3: ='Thermal-derivation'!$B$3 -> 0.98 | G3: ='Thermal-derivation'!$B$3 -> 0.98 | H3: ='Thermal-derivation'!$B$3 -> 0.98 | I3: ='Thermal-derivation'!$B$3 -> 0.98 | ... Y3: ='Thermal-derivation'!$B$3 -> 0.98
A4: Representative Day 3 | B4: ='Thermal-derivation'!$B$3 -> 0.98 | C4: ='Thermal-derivation'!$B$3 -> 0.98 | D4: ='Thermal-derivation'!$B$3 -> 0.98 | E4: ='Thermal-derivation'!$B$3 -> 0.98 | F4: ='Thermal-derivation'!$B$3 -> 0.98 | G4: ='Thermal-derivation'!$B$3 -> 0.98 | H4: ='Thermal-derivation'!$B$3 -> 0.98 | I4: ='Thermal-derivation'!$B$3 -> 0.98 | ... Y4: ='Thermal-derivation'!$B$3 -> 0.98
A5: Representative Day 4 | B5: ='Thermal-derivation'!$B$3 -> 0.98 | C5: ='Thermal-derivation'!$B$3 -> 0.98 | D5: ='Thermal-derivation'!$B$3 -> 0.98 | E5: ='Thermal-derivation'!$B$3 -> 0.98 | F5: ='Thermal-derivation'!$B$3 -> 0.98 | G5: ='Thermal-derivation'!$B$3 -> 0.98 | H5: ='Thermal-derivation'!$B$3 -> 0.98 | I5: ='Thermal-derivation'!$B$3 -> 0.98 | ... Y5: ='Thermal-derivation'!$B$3 -> 0.98
A6: Net Peak Summer Day | B6: ='Thermal-derivation'!$B$3 -> 0.98 | C6: ='Thermal-derivation'!$B$3 -> 0.98 | D6: ='Thermal-derivation'!$B$3 -> 0.98 | E6: ='Thermal-derivation'!$B$3 -> 0.98 | F6: ='Thermal-derivation'!$B$3 -> 0.98 | G6: ='Thermal-derivation'!$B$3 -> 0.98 | H6: ='Thermal-derivation'!$B$3 -> 0.98 | I6: ='Thermal-derivation'!$B$3 -> 0.98 | ... Y6: ='Thermal-derivation'!$B$3 -> 0.98
A7: Net Peak Winter Day | B7: ='Thermal-derivation'!$B$3 -> 0.98 | C7: ='Thermal-derivation'!$B$3 -> 0.98 | D7: ='Thermal-derivation'!$B$3 -> 0.98 | E7: ='Thermal-derivation'!$B$3 -> 0.98 | F7: ='Thermal-derivation'!$B$3 -> 0.98 | G7: ='Thermal-derivation'!$B$3 -> 0.98 | H7: ='Thermal-derivation'!$B$3 -> 0.98 | I7: ='Thermal-derivation'!$B$3 -> 0.98 | ... Y7: ='Thermal-derivation'!$B$3 -> 0.98

Sheet ELCCAfR-demand-altering-techs
A1: Unit: dimensionless (ELCC fraction at hour) | B1: Hour0 | C1: Hour1 | D1: Hour2 | E1: Hour3 | F1: Hour4 | G1: Hour5 | H1: Hour6 | I1: Hour7 | J1: Hour8 | K1: Hour9 | L1: Hour10 | M1: Hour11 | N1: Hour12 | O1: Hour13 | P1: Hour14 | Q1: Hour15 | R1: Hour16 | S1: Hour17 | T1: Hour18 | U1: Hour19 | V1: Hour20 | W1: Hour21 | X1: Hour22 | Y1: Hour23
A2: Representative Day 1 | B2: ='DAT-derivation'!$B$24 -> 0.82 | C2: ='DAT-derivation'!$B$24 -> 0.82 | D2: ='DAT-derivation'!$B$24 -> 0.82 | E2: ='DAT-derivation'!$B$24 -> 0.82 | F2: ='DAT-derivation'!$B$24 -> 0.82 | G2: ='DAT-derivation'!$B$24 -> 0.82 | H2: ='DAT-derivation'!$B$24 -> 0.82 | I2: ='DAT-derivation'!$B$24 -> 0.82 | ... Y2: ='DAT-derivation'!$B$24 -> 0.82
A3: Representative Day 2 | B3: ='DAT-derivation'!$B$24 -> 0.82 | C3: ='DAT-derivation'!$B$24 -> 0.82 | D3: ='DAT-derivation'!$B$24 -> 0.82 | E3: ='DAT-derivation'!$B$24 -> 0.82 | F3: ='DAT-derivation'!$B$24 -> 0.82 | G3: ='DAT-derivation'!$B$24 -> 0.82 | H3: ='DAT-derivation'!$B$24 -> 0.82 | I3: ='DAT-derivation'!$B$24 -> 0.82 | ... Y3: ='DAT-derivation'!$B$24 -> 0.82
A4: Representative Day 3 | B4: ='DAT-derivation'!$B$24 -> 0.82 | C4: ='DAT-derivation'!$B$24 -> 0.82 | D4: ='DAT-derivation'!$B$24 -> 0.82 | E4: ='DAT-derivation'!$B$24 -> 0.82 | F4: ='DAT-derivation'!$B$24 -> 0.82 | G4: ='DAT-derivation'!$B$24 -> 0.82 | H4: ='DAT-derivation'!$B$24 -> 0.82 | I4: ='DAT-derivation'!$B$24 -> 0.82 | ... Y4: ='DAT-derivation'!$B$24 -> 0.82
A5: Representative Day 4 | B5: ='DAT-derivation'!$B$24 -> 0.82 | C5: ='DAT-derivation'!$B$24 -> 0.82 | D5: ='DAT-derivation'!$B$24 -> 0.82 | E5: ='DAT-derivation'!$B$24 -> 0.82 | F5: ='DAT-derivation'!$B$24 -> 0.82 | G5: ='DAT-derivation'!$B$24 -> 0.82 | H5: ='DAT-derivation'!$B$24 -> 0.82 | I5: ='DAT-derivation'!$B$24 -> 0.82 | ... Y5: ='DAT-derivation'!$B$24 -> 0.82
A6: Net Peak Summer Day | B6: ='DAT-derivation'!$B$24 -> 0.82 | C6: ='DAT-derivation'!$B$24 -> 0.82 | D6: ='DAT-derivation'!$B$24 -> 0.82 | E6: ='DAT-derivation'!$B$24 -> 0.82 | F6: ='DAT-derivation'!$B$24 -> 0.82 | G6: ='DAT-derivation'!$B$24 -> 0.82 | H6: ='DAT-derivation'!$B$24 -> 0.82 | I6: ='DAT-derivation'!$B$24 -> 0.82 | ... Y6: ='DAT-derivation'!$B$24 -> 0.82
A7: Net Peak Winter Day | B7: ='DAT-derivation'!$B$24 -> 0.82 | C7: ='DAT-derivation'!$B$24 -> 0.82 | D7: ='DAT-derivation'!$B$24 -> 0.82 | E7: ='DAT-derivation'!$B$24 -> 0.82 | F7: ='DAT-derivation'!$B$24 -> 0.82 | G7: ='DAT-derivation'!$B$24 -> 0.82 | H7: ='DAT-derivation'!$B$24 -> 0.82 | I7: ='DAT-derivation'!$B$24 -> 0.82 | ... Y7: ='DAT-derivation'!$B$24 -> 0.82

Sheet ELCCAfR-geothermal
A1: geothermal | B1: Hour0 | C1: Hour1 | D1: Hour2 | E1: Hour3 | F1: Hour4 | G1: Hour5 | H1: Hour6 | I1: Hour7 | J1: Hour8 | K1: Hour9 | L1: Hour10 | M1: Hour11 | N1: Hour12 | O1: Hour13 | P1: Hour14 | Q1: Hour15 | R1: Hour16 | S1: Hour17 | T1: Hour18 | U1: Hour19 | V1: Hour20 | W1: Hour21 | X1: Hour22 | Y1: Hour23
A2: Representative Day 1 | B2: ='Thermal-derivation'!$B$3 -> 0.98 | C2: ='Thermal-derivation'!$B$3 -> 0.98 | D2: ='Thermal-derivation'!$B$3 -> 0.98 | E2: ='Thermal-derivation'!$B$3 -> 0.98 | F2: ='Thermal-derivation'!$B$3 -> 0.98 | G2: ='Thermal-derivation'!$B$3 -> 0.98 | H2: ='Thermal-derivation'!$B$3 -> 0.98 | I2: ='Thermal-derivation'!$B$3 -> 0.98 | ... Y2: ='Thermal-derivation'!$B$3 -> 0.98
A3: Representative Day 2 | B3: ='Thermal-derivation'!$B$3 -> 0.98 | C3: ='Thermal-derivation'!$B$3 -> 0.98 | D3: ='Thermal-derivation'!$B$3 -> 0.98 | E3: ='Thermal-derivation'!$B$3 -> 0.98 | F3: ='Thermal-derivation'!$B$3 -> 0.98 | G3: ='Thermal-derivation'!$B$3 -> 0.98 | H3: ='Thermal-derivation'!$B$3 -> 0.98 | I3: ='Thermal-derivation'!$B$3 -> 0.98 | ... Y3: ='Thermal-derivation'!$B$3 -> 0.98
A4: Representative Day 3 | B4: ='Thermal-derivation'!$B$3 -> 0.98 | C4: ='Thermal-derivation'!$B$3 -> 0.98 | D4: ='Thermal-derivation'!$B$3 -> 0.98 | E4: ='Thermal-derivation'!$B$3 -> 0.98 | F4: ='Thermal-derivation'!$B$3 -> 0.98 | G4: ='Thermal-derivation'!$B$3 -> 0.98 | H4: ='Thermal-derivation'!$B$3 -> 0.98 | I4: ='Thermal-derivation'!$B$3 -> 0.98 | ... Y4: ='Thermal-derivation'!$B$3 -> 0.98
A5: Representative Day 4 | B5: ='Thermal-derivation'!$B$3 -> 0.98 | C5: ='Thermal-derivation'!$B$3 -> 0.98 | D5: ='Thermal-derivation'!$B$3 -> 0.98 | E5: ='Thermal-derivation'!$B$3 -> 0.98 | F5: ='Thermal-derivation'!$B$3 -> 0.98 | G5: ='Thermal-derivation'!$B$3 -> 0.98 | H5: ='Thermal-derivation'!$B$3 -> 0.98 | I5: ='Thermal-derivation'!$B$3 -> 0.98 | ... Y5: ='Thermal-derivation'!$B$3 -> 0.98
A6: Net Peak Summer Day | B6: ='Thermal-derivation'!$B$3 -> 0.98 | C6: ='Thermal-derivation'!$B$3 -> 0.98 | D6: ='Thermal-derivation'!$B$3 -> 0.98 | E6: ='Thermal-derivation'!$B$3 -> 0.98 | F6: ='Thermal-derivation'!$B$3 -> 0.98 | G6: ='Thermal-derivation'!$B$3 -> 0.98 | H6: ='Thermal-derivation'!$B$3 -> 0.98 | I6: ='Thermal-derivation'!$B$3 -> 0.98 | ... Y6: ='Thermal-derivation'!$B$3 -> 0.98
A7: Net Peak Winter Day | B7: ='Thermal-derivation'!$B$3 -> 0.98 | C7: ='Thermal-derivation'!$B$3 -> 0.98 | D7: ='Thermal-derivation'!$B$3 -> 0.98 | E7: ='Thermal-derivation'!$B$3 -> 0.98 | F7: ='Thermal-derivation'!$B$3 -> 0.98 | G7: ='Thermal-derivation'!$B$3 -> 0.98 | H7: ='Thermal-derivation'!$B$3 -> 0.98 | I7: ='Thermal-derivation'!$B$3 -> 0.98 | ... Y7: ='Thermal-derivation'!$B$3 -> 0.98

Sheet ELCCAfR-hard-coal-CCS
A1: hard coal w CCS | B1: Hour0 | C1: Hour1 | D1: Hour2 | E1: Hour3 | F1: Hour4 | G1: Hour5 | H1: Hour6 | I1: Hour7 | J1: Hour8 | K1: Hour9 | L1: Hour10 | M1: Hour11 | N1: Hour12 | O1: Hour13 | P1: Hour14 | Q1: Hour15 | R1: Hour16 | S1: Hour17 | T1: Hour18 | U1: Hour19 | V1: Hour20 | W1: Hour21 | X1: Hour22 | Y1: Hour23
A2: Representative Day 1 | B2: ='Thermal-derivation'!$B$3 -> 0.98 | C2: ='Thermal-derivation'!$B$3 -> 0.98 | D2: ='Thermal-derivation'!$B$3 -> 0.98 | E2: ='Thermal-derivation'!$B$3 -> 0.98 | F2: ='Thermal-derivation'!$B$3 -> 0.98 | G2: ='Thermal-derivation'!$B$3 -> 0.98 | H2: ='Thermal-derivation'!$B$3 -> 0.98 | I2: ='Thermal-derivation'!$B$3 -> 0.98 | ... Y2: ='Thermal-derivation'!$B$3 -> 0.98
A3: Representative Day 2 | B3: ='Thermal-derivation'!$B$3 -> 0.98 | C3: ='Thermal-derivation'!$B$3 -> 0.98 | D3: ='Thermal-derivation'!$B$3 -> 0.98 | E3: ='Thermal-derivation'!$B$3 -> 0.98 | F3: ='Thermal-derivation'!$B$3 -> 0.98 | G3: ='Thermal-derivation'!$B$3 -> 0.98 | H3: ='Thermal-derivation'!$B$3 -> 0.98 | I3: ='Thermal-derivation'!$B$3 -> 0.98 | ... Y3: ='Thermal-derivation'!$B$3 -> 0.98
A4: Representative Day 3 | B4: ='Thermal-derivation'!$B$3 -> 0.98 | C4: ='Thermal-derivation'!$B$3 -> 0.98 | D4: ='Thermal-derivation'!$B$3 -> 0.98 | E4: ='Thermal-derivation'!$B$3 -> 0.98 | F4: ='Thermal-derivation'!$B$3 -> 0.98 | G4: ='Thermal-derivation'!$B$3 -> 0.98 | H4: ='Thermal-derivation'!$B$3 -> 0.98 | I4: ='Thermal-derivation'!$B$3 -> 0.98 | ... Y4: ='Thermal-derivation'!$B$3 -> 0.98
A5: Representative Day 4 | B5: ='Thermal-derivation'!$B$3 -> 0.98 | C5: ='Thermal-derivation'!$B$3 -> 0.98 | D5: ='Thermal-derivation'!$B$3 -> 0.98 | E5: ='Thermal-derivation'!$B$3 -> 0.98 | F5: ='Thermal-derivation'!$B$3 -> 0.98 | G5: ='Thermal-derivation'!$B$3 -> 0.98 | H5: ='Thermal-derivation'!$B$3 -> 0.98 | I5: ='Thermal-derivation'!$B$3 -> 0.98 | ... Y5: ='Thermal-derivation'!$B$3 -> 0.98
A6: Net Peak Summer Day | B6: ='Thermal-derivation'!$B$3 -> 0.98 | C6: ='Thermal-derivation'!$B$3 -> 0.98 | D6: ='Thermal-derivation'!$B$3 -> 0.98 | E6: ='Thermal-derivation'!$B$3 -> 0.98 | F6: ='Thermal-derivation'!$B$3 -> 0.98 | G6: ='Thermal-derivation'!$B$3 -> 0.98 | H6: ='Thermal-derivation'!$B$3 -> 0.98 | I6: ='Thermal-derivation'!$B$3 -> 0.98 | ... Y6: ='Thermal-derivation'!$B$3 -> 0.98
A7: Net Peak Winter Day | B7: ='Thermal-derivation'!$B$3 -> 0.98 | C7: ='Thermal-derivation'!$B$3 -> 0.98 | D7: ='Thermal-derivation'!$B$3 -> 0.98 | E7: ='Thermal-derivation'!$B$3 -> 0.98 | F7: ='Thermal-derivation'!$B$3 -> 0.98 | G7: ='Thermal-derivation'!$B$3 -> 0.98 | H7: ='Thermal-derivation'!$B$3 -> 0.98 | I7: ='Thermal-derivation'!$B$3 -> 0.98 | ... Y7: ='Thermal-derivation'!$B$3 -> 0.98

Sheet ELCCAfR-hard-coal
A1: hard coal | B1: Hour0 | C1: Hour1 | D1: Hour2 | E1: Hour3 | F1: Hour4 | G1: Hour5 | H1: Hour6 | I1: Hour7 | J1: Hour8 | K1: Hour9 | L1: Hour10 | M1: Hour11 | N1: Hour12 | O1: Hour13 | P1: Hour14 | Q1: Hour15 | R1: Hour16 | S1: Hour17 | T1: Hour18 | U1: Hour19 | V1: Hour20 | W1: Hour21 | X1: Hour22 | Y1: Hour23
A2: Representative Day 1 | B2: ='Thermal-derivation'!$B$3 -> 0.98 | C2: ='Thermal-derivation'!$B$3 -> 0.98 | D2: ='Thermal-derivation'!$B$3 -> 0.98 | E2: ='Thermal-derivation'!$B$3 -> 0.98 | F2: ='Thermal-derivation'!$B$3 -> 0.98 | G2: ='Thermal-derivation'!$B$3 -> 0.98 | H2: ='Thermal-derivation'!$B$3 -> 0.98 | I2: ='Thermal-derivation'!$B$3 -> 0.98 | ... Y2: ='Thermal-derivation'!$B$3 -> 0.98
A3: Representative Day 2 | B3: ='Thermal-derivation'!$B$3 -> 0.98 | C3: ='Thermal-derivation'!$B$3 -> 0.98 | D3: ='Thermal-derivation'!$B$3 -> 0.98 | E3: ='Thermal-derivation'!$B$3 -> 0.98 | F3: ='Thermal-derivation'!$B$3 -> 0.98 | G3: ='Thermal-derivation'!$B$3 -> 0.98 | H3: ='Thermal-derivation'!$B$3 -> 0.98 | I3: ='Thermal-derivation'!$B$3 -> 0.98 | ... Y3: ='Thermal-derivation'!$B$3 -> 0.98
A4: Representative Day 3 | B4: ='Thermal-derivation'!$B$3 -> 0.98 | C4: ='Thermal-derivation'!$B$3 -> 0.98 | D4: ='Thermal-derivation'!$B$3 -> 0.98 | E4: ='Thermal-derivation'!$B$3 -> 0.98 | F4: ='Thermal-derivation'!$B$3 -> 0.98 | G4: ='Thermal-derivation'!$B$3 -> 0.98 | H4: ='Thermal-derivation'!$B$3 -> 0.98 | I4: ='Thermal-derivation'!$B$3 -> 0.98 | ... Y4: ='Thermal-derivation'!$B$3 -> 0.98
A5: Representative Day 4 | B5: ='Thermal-derivation'!$B$3 -> 0.98 | C5: ='Thermal-derivation'!$B$3 -> 0.98 | D5: ='Thermal-derivation'!$B$3 -> 0.98 | E5: ='Thermal-derivation'!$B$3 -> 0.98 | F5: ='Thermal-derivation'!$B$3 -> 0.98 | G5: ='Thermal-derivation'!$B$3 -> 0.98 | H5: ='Thermal-derivation'!$B$3 -> 0.98 | I5: ='Thermal-derivation'!$B$3 -> 0.98 | ... Y5: ='Thermal-derivation'!$B$3 -> 0.98
A6: Net Peak Summer Day | B6: ='Thermal-derivation'!$B$3 -> 0.98 | C6: ='Thermal-derivation'!$B$3 -> 0.98 | D6: ='Thermal-derivation'!$B$3 -> 0.98 | E6: ='Thermal-derivation'!$B$3 -> 0.98 | F6: ='Thermal-derivation'!$B$3 -> 0.98 | G6: ='Thermal-derivation'!$B$3 -> 0.98 | H6: ='Thermal-derivation'!$B$3 -> 0.98 | I6: ='Thermal-derivation'!$B$3 -> 0.98 | ... Y6: ='Thermal-derivation'!$B$3 -> 0.98
A7: Net Peak Winter Day | B7: ='Thermal-derivation'!$B$3 -> 0.98 | C7: ='Thermal-derivation'!$B$3 -> 0.98 | D7: ='Thermal-derivation'!$B$3 -> 0.98 | E7: ='Thermal-derivation'!$B$3 -> 0.98 | F7: ='Thermal-derivation'!$B$3 -> 0.98 | G7: ='Thermal-derivation'!$B$3 -> 0.98 | H7: ='Thermal-derivation'!$B$3 -> 0.98 | I7: ='Thermal-derivation'!$B$3 -> 0.98 | ... Y7: ='Thermal-derivation'!$B$3 -> 0.98

Sheet ELCCAfR-heavy-or-residual-oil
A1: heavy or residual fuel oil | B1: Hour0 | C1: Hour1 | D1: Hour2 | E1: Hour3 | F1: Hour4 | G1: Hour5 | H1: Hour6 | I1: Hour7 | J1: Hour8 | K1: Hour9 | L1: Hour10 | M1: Hour11 | N1: Hour12 | O1: Hour13 | P1: Hour14 | Q1: Hour15 | R1: Hour16 | S1: Hour17 | T1: Hour18 | U1: Hour19 | V1: Hour20 | W1: Hour21 | X1: Hour22 | Y1: Hour23
A2: Representative Day 1 | B2: ='Thermal-derivation'!$B$3 -> 0.98 | C2: ='Thermal-derivation'!$B$3 -> 0.98 | D2: ='Thermal-derivation'!$B$3 -> 0.98 | E2: ='Thermal-derivation'!$B$3 -> 0.98 | F2: ='Thermal-derivation'!$B$3 -> 0.98 | G2: ='Thermal-derivation'!$B$3 -> 0.98 | H2: ='Thermal-derivation'!$B$3 -> 0.98 | I2: ='Thermal-derivation'!$B$3 -> 0.98 | ... Y2: ='Thermal-derivation'!$B$3 -> 0.98
A3: Representative Day 2 | B3: ='Thermal-derivation'!$B$3 -> 0.98 | C3: ='Thermal-derivation'!$B$3 -> 0.98 | D3: ='Thermal-derivation'!$B$3 -> 0.98 | E3: ='Thermal-derivation'!$B$3 -> 0.98 | F3: ='Thermal-derivation'!$B$3 -> 0.98 | G3: ='Thermal-derivation'!$B$3 -> 0.98 | H3: ='Thermal-derivation'!$B$3 -> 0.98 | I3: ='Thermal-derivation'!$B$3 -> 0.98 | ... Y3: ='Thermal-derivation'!$B$3 -> 0.98
A4: Representative Day 3 | B4: ='Thermal-derivation'!$B$3 -> 0.98 | C4: ='Thermal-derivation'!$B$3 -> 0.98 | D4: ='Thermal-derivation'!$B$3 -> 0.98 | E4: ='Thermal-derivation'!$B$3 -> 0.98 | F4: ='Thermal-derivation'!$B$3 -> 0.98 | G4: ='Thermal-derivation'!$B$3 -> 0.98 | H4: ='Thermal-derivation'!$B$3 -> 0.98 | I4: ='Thermal-derivation'!$B$3 -> 0.98 | ... Y4: ='Thermal-derivation'!$B$3 -> 0.98
A5: Representative Day 4 | B5: ='Thermal-derivation'!$B$3 -> 0.98 | C5: ='Thermal-derivation'!$B$3 -> 0.98 | D5: ='Thermal-derivation'!$B$3 -> 0.98 | E5: ='Thermal-derivation'!$B$3 -> 0.98 | F5: ='Thermal-derivation'!$B$3 -> 0.98 | G5: ='Thermal-derivation'!$B$3 -> 0.98 | H5: ='Thermal-derivation'!$B$3 -> 0.98 | I5: ='Thermal-derivation'!$B$3 -> 0.98 | ... Y5: ='Thermal-derivation'!$B$3 -> 0.98
A6: Net Peak Summer Day | B6: ='Thermal-derivation'!$B$3 -> 0.98 | C6: ='Thermal-derivation'!$B$3 -> 0.98 | D6: ='Thermal-derivation'!$B$3 -> 0.98 | E6: ='Thermal-derivation'!$B$3 -> 0.98 | F6: ='Thermal-derivation'!$B$3 -> 0.98 | G6: ='Thermal-derivation'!$B$3 -> 0.98 | H6: ='Thermal-derivation'!$B$3 -> 0.98 | I6: ='Thermal-derivation'!$B$3 -> 0.98 | ... Y6: ='Thermal-derivation'!$B$3 -> 0.98
A7: Net Peak Winter Day | B7: ='Thermal-derivation'!$B$3 -> 0.98 | C7: ='Thermal-derivation'!$B$3 -> 0.98 | D7: ='Thermal-derivation'!$B$3 -> 0.98 | E7: ='Thermal-derivation'!$B$3 -> 0.98 | F7: ='Thermal-derivation'!$B$3 -> 0.98 | G7: ='Thermal-derivation'!$B$3 -> 0.98 | H7: ='Thermal-derivation'!$B$3 -> 0.98 | I7: ='Thermal-derivation'!$B$3 -> 0.98 | ... Y7: ='Thermal-derivation'!$B$3 -> 0.98

Sheet ELCCAfR-hydro
