Workbook
Name \P: #REF!
Name Adjusted: #REF!
Name CTFEBS: #REF!
Name FINAL: #REF!
Name PRINT: #REF!
Name SAVED: #REF!
Name SAVII: #REF!
Name SHEET1: #REF!
Name SHEET2: #REF!
Name STATES: #REF!
Name YEAR: #REF!
Name YEAR2: #REF!

Sheet About
A1: VSbS Vehicle Shares by Subregion
A3: Source: | B3: U.S. Federal Highway Administration
B4: 2026
B5: Highway Statistics 2024
B6: https://www.fhwa.dot.gov/policyinformation/statistics/2020/mv1.cfm
B7: Table MV-1 (State motor-vehicle registrations)
A9: Notes
A10: This variable is used for a share of sales by subregion, but you can use share of total number of registered
A11: vehicles in each subregion as a proxy for share of sales.
A13: U.S. Data Notes
A15: The categories the Federal Highway Administration uses are: automobiles, buses, trucks, and motorcycles.
A17: We use the "automobile" shares to represent all passenger LDVs in the EPS, even though passenger LDVs
A18: include passenger SUVs, which are technically light trucks. The state-by-state distribution of
A19: SUVs ought to be similar to the state-by-state distribution of automobiles.
A21: We use the "truck" shares to represent both freight LDVs and freight HDVs in the EPS.
A23: Adapting this Variable to Other EPS Regions
A24: If you are adapting the EPS to another country or region and don't want to use
A25: sub-regional ZEV mandates, simply put "1" in the first sub-region row for each type of road
A26: vehicle and put "0" in all other cells on the blue output tabs.

Sheet Table MV-1
A1: 2022 State Motor-Vehicle Registrations (1)
A3: January 2026 | P3: TABLE MV-1
B5: AUTOMOBILES | E5: BUSES | H5: TRUCKS | K5: MOTORCYCLES | N5: ALL MOTOR VEHICLES
A6: STATE | B6: PRIVATE AND
B7: COMMERCIAL | C7: PUBLICLY | E7: PRIVATE AND | F7: PUBLICLY | H7: PRIVATE AND | I7: PUBLICLY | K7: PRIVATE AND | L7: PUBLICLY | N7: PRIVATE AND | O7: PUBLICLY
B8: (INCLUDING | C8: OWNED | D8: TOTAL | E8: COMMERCIAL | F8: OWNED | G8: TOTAL | H8: COMMERCIAL | I8: OWNED | J8: TOTAL | K8: COMMERCIAL | L8: OWNED | M8: TOTAL | N8: COMMERCIAL | O8: OWNED | P8: TOTAL
B9: TAXICABS) | C9: -1 | F9: -1 | I9: -1 | L9: -1 | O9: -1
A10: Alabama (2) | B10: 1932886 | C10: 4444 | D10: 1937330 | E10: 3246 | F10: 123 | G10: 3369 | H10: 3572635 | I10: 12996 | J10: 3585631 | K10: 129014 | L10: — | M10: 129014 | N10: 5637781 | O10: 17563 | P10: 5655344
A11: Alaska | B11: 120421 | C11: 2257 | D11: 122678 | E11: 8488 | F11: 601 | G11: 9089 | H11: 514116 | I11: 11599 | J11: 525715 | K11: 25530 | L11: 10 | M11: 25540 | N11: 668555 | O11: 14467 | P11: 683022
A12: Arizona | B12: 2254643 | C12: 32888 | D12: 2287531 | E12: 5083 | F12: 17534 | G12: 22617 | H12: 4024184 | I12: 66285 | J12: 4090469 | K12: 290639 | L12: 1375 | M12: 292014 | N12: 6574549 | O12: 118082 | P12: 6692631
A13: Arkansas (2) | B13: 892704 | C13: 19065 | D13: 911769 | E13: 4657 | F13: 6148 | G13: 10805 | H13: 2292346 | I13: 51233 | J13: 2343579 | K13: 100497 | L13: — | M13: 100497 | N13: 3290204 | O13: 76446 | P13: 3366650
A14: California | B14: 12737763 | C14: 241759 | D14: 12979522 | E14: 28069 | F14: 68160 | G14: 96229 | H14: 16752902 | I14: 360861 | J14: 17113763 | K14: 737824 | L14: 13314 | M14: 751138 | N14: 30256558 | O14: 684094 | P14: 30940652
A15: Colorado | B15: 1341494 | C15: 15032 | D15: 1356526 | E15: 4797 | F15: 7805 | G15: 12602 | H15: 3684600 | I15: 46491 | J15: 3731091 | K15: 176484 | L15: — | M15: 176484 | N15: 5207375 | O15: 69328 | P15: 5276703
A16: Connecticut (2) | B16: 1028325 | C16: 474 | D16: 1028799 | E16: 9854 | F16: 35 | G16: 9889 | H16: 1684267 | I16: 4505 | J16: 1688772 | K16: 81996 | L16: — | M16: 81996 | N16: 2804442 | O16: 5014 | P16: 2809456
A17: Delaware | B17: 146701 | C17: 1792 | D17: 148493 | E17: 1904 | F17: 1579 | G17: 3483 | H17: 266034 | I17: 4390 | J17: 270424 | K17: 24607 | L17: 87 | M17: 24694 | N17: 439246 | O17: 7848 | P17: 447094
A18: Dist. of Col. | B18: 138559 | C18: 11917 | D18: 150476 | E18: 2453 | F18: 3034 | G18: 5487 | H18: 129193 | I18: 13869 | J18: 143062 | K18: 3267 | L18: 355 | M18: 3622 | N18: 273472 | O18: 29175 | P18: 302647
A19: Florida | B19: 7113843 | C19: 96271 | D19: 7210114 | E19: 22196 | F19: 35272 | G19: 57468 | H19: 11617475 | I19: 176659 | J19: 11794134 | K19: 631452 | L19: 2912 | M19: 634364 | N19: 19384966 | O19: 311114 | P19: 19696080
A20: Georgia | B20: 3154970 | C20: 51640 | D20: 3206610 | E20: 10816 | F20: 28565 | G20: 39381 | H20: 5738067 | I20: 104056 | J20: 5842123 | K20: 221253 | L20: 41 | M20: 221294 | N20: 9125106 | O20: 184302 | P20: 9309408
A21: Hawaii | B21: 415330 | C21: 6962 | D21: 422292 | E21: 1054 | F21: 741 | G21: 1795 | H21: 804155 | I21: 17356 | J21: 821511 | K21: 24181 | L21: 374 | M21: 24555 | N21: 1244720 | O21: 25433 | P21: 1270153
A22: Idaho (3) | B22: 504204 | C22: 6312 | D22: 510516 | E22: 1567 | F22: 2515 | G22: 4082 | H22: 1419807 | I22: 20749 | J22: 1440556 | K22: 74815 | L22: 100 | M22: 74915 | N22: 2000393 | O22: 29676 | P22: 2030069
A23: Illinois | B23: 3443638 | C23: 70600 | D23: 3514238 | E23: 35404 | F23: 3779 | G23: 39183 | H23: 6580751 | I23: 146582 | J23: 6727333 | K23: 264596 | L23: 677 | M23: 265273 | N23: 10324389 | O23: 221638 | P23: 10546027
A24: Indiana | B24: 1752726 | C24: 38382 | D24: 1791108 | E24: 10464 | F24: 21897 | G24: 32361 | H24: 3981452 | I24: 91939 | J24: 4073391 | K24: 203508 | L24: 363 | M24: 203871 | N24: 5948150 | O24: 152581 | P24: 6100731
A25: Iowa | B25: 998101 | C25: 8893 | D25: 1006994 | E25: 3843 | F25: 5324 | G25: 9167 | H25: 2621876 | I25: 25446 | J25: 2647322 | K25: 192834 | L25: 330 | M25: 193164 | N25: 3816654 | O25: 39993 | P25: 3856647
A26: Kansas | B26: 592793 | C26: 1993 | D26: 594786 | E26: 1272 | F26: 162 | G26: 1434 | H26: 1309881 | I26: 6989 | J26: 1316870 | K26: 94483 | L26: 13 | M26: 94496 | N26: 1998429 | O26: 9157 | P26: 2007586
A27: Kentucky | B27: 1431848 | C27: 26811 | D27: 1458659 | E27: 151 | F27: 15277 | G27: 15428 | H27: 2914155 | I27: 57410 | J27: 2971565 | K27: 115807 | L27: 80 | M27: 115887 | N27: 4461961 | O27: 99578 | P27: 4561539
A28: Louisiana | B28: 1337616 | C28: 32947 | D28: 1370563 | E28: 24228 | F28: 9401 | G28: 33629 | H28: 2969301 | I28: 77439 | J28: 3046740 | K28: 104991 | L28: 513 | M28: 105504 | N28: 4436136 | O28: 120300 | P28: 4556436
... A31: Massachusetts | B31: 1690199 | C31: 16515 | D31: 1706714 | E31: 10865 | F31: 3038 | G31: 13903 | H31: 3194932 | I31: 37430 | J31: 3232362 | K31: 140949 | L31: 761 | M31: 141710 | N31: 5036945 | O31: 57744 | P31: 5094689
A32: Michigan | B32: 2493266 | C32: 970 | D32: 2494236 | E32: 2182 | F32: 74 | G32: 2256 | H32: 6850142 | I32: 10702 | J32: 6860844 | K32: 249465 | L32: — | M32: 249465 | N32: 9595055 | O32: 11746 | P32: 9606801
A33: Minnesota (2) | B33: 1592071 | C33: 16971 | D33: 1609042 | E33: 14159 | F33: 26 | G33: 14185 | H33: 4040621 | I33: 47020 | J33: 4087641 | K33: 226544 | L33: — | M33: 226544 | N33: 5873395 | O33: 64017 | P33: 5937412
A34: Mississippi | B34: 754721 | C34: 2220 | D34: 756941 | E34: 2006 | F34: 6499 | G34: 8505 | H34: 1411201 | I34: 7181 | J34: 1418382 | K34: 30421 | L34: — | M34: 30421 | N34: 2198349 | O34: 15900 | P34: 2214249
A35: Missouri (2) | B35: 1644583 | C35: 1131 | D35: 1645714 | E35: 22786 | F35: 119 | G35: 22905 | H35: 3611893 | I35: 8106 | J35: 3619999 | K35: 133801 | L35: — | M35: 133801 | N35: 5413063 | O35: 9356 | P35: 5422419
A36: Montana | B36: 524624 | C36: 602 | D36: 525226 | E36: 5409 | F36: 220 | G36: 5629 | H36: 1490120 | I36: 4351 | J36: 1494471 | K36: 447935 | L36: 8 | M36: 447943 | N36: 2468088 | O36: 5181 | P36: 2473269
A37: Nebraska | B37: 551466 | C37: 9645 | D37: 561111 | E37: 3632 | F37: 5374 | G37: 9006 | H37: 1343041 | I37: 25261 | J37: 1368302 | K37: 50655 | L37: 98 | M37: 50753 | N37: 1948794 | O37: 40378 | P37: 1989172
A38: Nevada | B38: 832098 | C38: 11001 | D38: 843099 | E38: 1167 | F38: 6714 | G38: 7881 | H38: 1427942 | I38: 22292 | J38: 1450234 | K38: 85715 | L38: 1987 | M38: 87702 | N38: 2346922 | O38: 41994 | P38: 2388916
A39: New Hampshire | B39: 387846 | C39: 3218 | D39: 391064 | E39: 1729 | F39: 718 | G39: 2447 | H39: 902330 | I39: 8561 | J39: 910891 | K39: 86178 | L39: 30 | M39: 86208 | N39: 1378083 | O39: 12527 | P39: 1390610
A40: New Jersey | B40: 2251730 | C40: 23325 | D40: 2275055 | E40: 22486 | F40: 2731 | G40: 25217 | H40: 3762020 | I40: 47802 | J40: 3809822 | K40: 146003 | L40: — | M40: 146003 | N40: 6182239 | O40: 73858 | P40: 6256097
A41: New Mexico | B41: 571192 | C41: 18842 | D41: 590034 | E41: 2161 | F41: 4852 | G41: 7013 | H41: 1230750 | I41: 46059 | J41: 1276809 | K41: 56104 | L41: 393 | M41: 56497 | N41: 1860207 | O41: 70146 | P41: 1930353
A42: New York (3) | B42: 6452828 | C42: 21231 | D42: 6474059 | E42: 184779 | F42: 10896 | G42: 195675 | H42: 13469243 | I42: 57301 | J42: 13526544 | K42: 794796 | L42: 24 | M42: 794820 | N42: 20901646 | O42: 89452 | P42: 20991098
A43: North Carolina | B43: 2963141 | C43: 42508 | D43: 3005649 | E43: 9859 | F43: 22624 | G43: 32483 | H43: 5546131 | I43: 88423 | J43: 5634554 | K43: 189380 | L43: 354 | M43: 189734 | N43: 8708511 | O43: 153909 | P43: 8862420
A44: North Dakota | B44: 211559 | C44: 3730 | D44: 215289 | E44: 1142 | F44: 2466 | G44: 3608 | H44: 798031 | I44: 15596 | J44: 813627 | K44: 44145 | L44: 21 | M44: 44166 | N44: 1054877 | O44: 21813 | P44: 1076690
...

Sheet VSbS-passenger
A1: Unit: dimensionless (share of vehicles) | B1: LDVs | C1: HDVs | D1: aircraft | E1: rail | F1: ships | G1: motorbikes
A2: Alabama | B2: ='Table MV-1'!D10/'Table MV-1'!$D$61 -> 0.019887732 | C2: ='Table MV-1'!G10/'Table MV-1'!$G$61 -> 0.0030729658 | D2: ='Table MV-1'!$P10/'Table MV-1'!$P$61 -> 0.019007909 | E2: ='Table MV-1'!$P10/'Table MV-1'!$P$61 -> 0.019007909 | F2: ='Table MV-1'!$P10/'Table MV-1'!$P$61 -> 0.019007909 | G2: ='Table MV-1'!M10/'Table MV-1'!$M$61 -> 0.013930518
A3: Alaska | B3: ='Table MV-1'!D11/'Table MV-1'!$D$61 -> 0.0012593555 | C3: ='Table MV-1'!G11/'Table MV-1'!$G$61 -> 0.0082903492 | D3: ='Table MV-1'!$P11/'Table MV-1'!$P$61 -> 0.0022956729 | E3: ='Table MV-1'!$P11/'Table MV-1'!$P$61 -> 0.0022956729 | F3: ='Table MV-1'!$P11/'Table MV-1'!$P$61 -> 0.0022956729 | G3: ='Table MV-1'!M11/'Table MV-1'!$M$61 -> 0.0027577274
A4: Arizona | B4: ='Table MV-1'!D12/'Table MV-1'!$D$61 -> 0.023482733 | C4: ='Table MV-1'!G12/'Table MV-1'!$G$61 -> 0.020629643 | D4: ='Table MV-1'!$P12/'Table MV-1'!$P$61 -> 0.022494285 | E4: ='Table MV-1'!$P12/'Table MV-1'!$P$61 -> 0.022494285 | F4: ='Table MV-1'!$P12/'Table MV-1'!$P$61 -> 0.022494285 | G4: ='Table MV-1'!M12/'Table MV-1'!$M$61 -> 0.031530736
A5: Arkansas | B5: ='Table MV-1'!D13/'Table MV-1'!$D$61 -> 0.0093597979 | C5: ='Table MV-1'!G13/'Table MV-1'!$G$61 -> 0.0098555642 | D5: ='Table MV-1'!$P13/'Table MV-1'!$P$61 -> 0.011315488 | E5: ='Table MV-1'!$P13/'Table MV-1'!$P$61 -> 0.011315488 | F5: ='Table MV-1'!$P13/'Table MV-1'!$P$61 -> 0.011315488 | G5: ='Table MV-1'!M13/'Table MV-1'!$M$61 -> 0.010851344
A6: California | B6: ='Table MV-1'!D14/'Table MV-1'!$D$61 -> 0.13324176 | C6: ='Table MV-1'!G14/'Table MV-1'!$G$61 -> 0.087773354 | D6: ='Table MV-1'!$P14/'Table MV-1'!$P$61 -> 0.10399316 | E6: ='Table MV-1'!$P14/'Table MV-1'!$P$61 -> 0.10399316 | F6: ='Table MV-1'!$P14/'Table MV-1'!$P$61 -> 0.10399316 | G6: ='Table MV-1'!M14/'Table MV-1'!$M$61 -> 0.081105475
A7: Colorado | B7: ='Table MV-1'!D15/'Table MV-1'!$D$61 -> 0.013925467 | C7: ='Table MV-1'!G15/'Table MV-1'!$G$61 -> 0.011494662 | D7: ='Table MV-1'!$P15/'Table MV-1'!$P$61 -> 0.017735277 | E7: ='Table MV-1'!$P15/'Table MV-1'!$P$61 -> 0.017735277 | F7: ='Table MV-1'!$P15/'Table MV-1'!$P$61 -> 0.017735277 | G7: ='Table MV-1'!M15/'Table MV-1'!$M$61 -> 0.019056177
A8: Connecticut | B8: ='Table MV-1'!D16/'Table MV-1'!$D$61 -> 0.010561174 | C8: ='Table MV-1'!G16/'Table MV-1'!$G$61 -> 0.0090200532 | D8: ='Table MV-1'!$P16/'Table MV-1'!$P$61 -> 0.0094427295 | E8: ='Table MV-1'!$P16/'Table MV-1'!$P$61 -> 0.0094427295 | F8: ='Table MV-1'!$P16/'Table MV-1'!$P$61 -> 0.0094427295 | G8: ='Table MV-1'!M16/'Table MV-1'!$M$61 -> 0.0088536654
A9: Delaware | B9: ='Table MV-1'!D17/'Table MV-1'!$D$61 -> 0.0015243603 | C9: ='Table MV-1'!G17/'Table MV-1'!$G$61 -> 0.0031769487 | D9: ='Table MV-1'!$P17/'Table MV-1'!$P$61 -> 0.0015027065 | E9: ='Table MV-1'!$P17/'Table MV-1'!$P$61 -> 0.0015027065 | F9: ='Table MV-1'!$P17/'Table MV-1'!$P$61 -> 0.0015027065 | G9: ='Table MV-1'!M17/'Table MV-1'!$M$61 -> 0.002666379
A10: District of Columbia | B10: ='Table MV-1'!D18/'Table MV-1'!$D$61 -> 0.0015447169 | C10: ='Table MV-1'!G18/'Table MV-1'!$G$61 -> 0.0050048571 | D10: ='Table MV-1'!$P18/'Table MV-1'!$P$61 -> 0.0010172125 | E10: ='Table MV-1'!$P18/'Table MV-1'!$P$61 -> 0.0010172125 | F10: ='Table MV-1'!$P18/'Table MV-1'!$P$61 -> 0.0010172125 | G10: ='Table MV-1'!M18/'Table MV-1'!$M$61 -> 0.00039109196
A11: Florida | B11: ='Table MV-1'!D19/'Table MV-1'!$D$61 -> 0.074015688 | C11: ='Table MV-1'!G19/'Table MV-1'!$G$61 -> 0.052418285 | D11: ='Table MV-1'!$P19/'Table MV-1'!$P$61 -> 0.066199562 | E11: ='Table MV-1'!$P19/'Table MV-1'!$P$61 -> 0.066199562 | F11: ='Table MV-1'!$P19/'Table MV-1'!$P$61 -> 0.066199562 | G11: ='Table MV-1'!M19/'Table MV-1'!$M$61 -> 0.068496593
A12: Georgia | B12: ='Table MV-1'!D20/'Table MV-1'!$D$61 -> 0.032917572 | C12: ='Table MV-1'!G20/'Table MV-1'!$G$61 -> 0.03592059 | D12: ='Table MV-1'!$P20/'Table MV-1'!$P$61 -> 0.03128941 | E12: ='Table MV-1'!$P20/'Table MV-1'!$P$61 -> 0.03128941 | F12: ='Table MV-1'!$P20/'Table MV-1'!$P$61 -> 0.03128941 | G12: ='Table MV-1'!M20/'Table MV-1'!$M$61 -> 0.023894617
A13: Hawaii | B13: ='Table MV-1'!D21/'Table MV-1'!$D$61 -> 0.0043350539 | C13: ='Table MV-1'!G21/'Table MV-1'!$G$61 -> 0.0016372733 | D13: ='Table MV-1'!$P21/'Table MV-1'!$P$61 -> 0.0042690511 | E13: ='Table MV-1'!$P21/'Table MV-1'!$P$61 -> 0.0042690511 | F13: ='Table MV-1'!$P21/'Table MV-1'!$P$61 -> 0.0042690511 | G13: ='Table MV-1'!M21/'Table MV-1'!$M$61 -> 0.0026513702
... A52: Wyoming | B52: ='Table MV-1'!D60/'Table MV-1'!$D$61 -> 0.0017051775 | C52: ='Table MV-1'!G60/'Table MV-1'!$G$61 -> 0.0017813898 | D52: ='Table MV-1'!$P60/'Table MV-1'!$P$61 -> 0.0029481541 | E52: ='Table MV-1'!$P60/'Table MV-1'!$P$61 -> 0.0029481541 | F52: ='Table MV-1'!$P60/'Table MV-1'!$P$61 -> 0.0029481541 | G52: ='Table MV-1'!M60/'Table MV-1'!$M$61 -> 0.0030895401
A53: subregion52 | B53: 0 | C53: 0 | D53: 0 | E53: 0 | F53: 0 | G53: 0
A54: subregion53 | B54: 0 | C54: 0 | D54: 0 | E54: 0 | F54: 0 | G54: 0
A55: subregion54 | B55: 0 | C55: 0 | D55: 0 | E55: 0 | F55: 0 | G55: 0
A56: subregion55 | B56: 0 | C56: 0 | D56: 0 | E56: 0 | F56: 0 | G56: 0
A57: subregion56 | B57: 0 | C57: 0 | D57: 0 | E57: 0 | F57: 0 | G57: 0
A58: subregion57 | B58: 0 | C58: 0 | D58: 0 | E58: 0 | F58: 0 | G58: 0
A59: subregion58 | B59: 0 | C59: 0 | D59: 0 | E59: 0 | F59: 0 | G59: 0
A60: subregion59 | B60: 0 | C60: 0 | D60: 0 | E60: 0 | F60: 0 | G60: 0
A61: subregion60 | B61: 0 | C61: 0 | D61: 0 | E61: 0 | F61: 0 | G61: 0

Sheet VSbS-freight
A1: Unit: dimensionless (share of vehicles) | B1: LDVs | C1: HDVs | D1: aircraft | E1: rail | F1: ships | G1: motorbikes
A2: Alabama | B2: =C2 -> 0.018896115 | C2: ='Table MV-1'!J10/'Table MV-1'!$J$61 -> 0.018896115 | D2: ='Table MV-1'!$P10/'Table MV-1'!$P$61 -> 0.019007909 | E2: ='Table MV-1'!$P10/'Table MV-1'!$P$61 -> 0.019007909 | F2: ='Table MV-1'!$P10/'Table MV-1'!$P$61 -> 0.019007909 | G2: 0
A3: Alaska | B3: =C3 -> 0.0027704945 | C3: ='Table MV-1'!J11/'Table MV-1'!$J$61 -> 0.0027704945 | D3: ='Table MV-1'!$P11/'Table MV-1'!$P$61 -> 0.0022956729 | E3: ='Table MV-1'!$P11/'Table MV-1'!$P$61 -> 0.0022956729 | F3: ='Table MV-1'!$P11/'Table MV-1'!$P$61 -> 0.0022956729 | G3: 0
A4: Arizona | B4: =C4 -> 0.021556589 | C4: ='Table MV-1'!J12/'Table MV-1'!$J$61 -> 0.021556589 | D4: ='Table MV-1'!$P12/'Table MV-1'!$P$61 -> 0.022494285 | E4: ='Table MV-1'!$P12/'Table MV-1'!$P$61 -> 0.022494285 | F4: ='Table MV-1'!$P12/'Table MV-1'!$P$61 -> 0.022494285 | G4: 0
A5: Arkansas | B5: =C5 -> 0.012350557 | C5: ='Table MV-1'!J13/'Table MV-1'!$J$61 -> 0.012350557 | D5: ='Table MV-1'!$P13/'Table MV-1'!$P$61 -> 0.011315488 | E5: ='Table MV-1'!$P13/'Table MV-1'!$P$61 -> 0.011315488 | F5: ='Table MV-1'!$P13/'Table MV-1'!$P$61 -> 0.011315488 | G5: 0
A6: California | B6: =C6 -> 0.090188766 | C6: ='Table MV-1'!J14/'Table MV-1'!$J$61 -> 0.090188766 | D6: ='Table MV-1'!$P14/'Table MV-1'!$P$61 -> 0.10399316 | E6: ='Table MV-1'!$P14/'Table MV-1'!$P$61 -> 0.10399316 | F6: ='Table MV-1'!$P14/'Table MV-1'!$P$61 -> 0.10399316 | G6: 0
A7: Colorado | B7: =C7 -> 0.019662683 | C7: ='Table MV-1'!J15/'Table MV-1'!$J$61 -> 0.019662683 | D7: ='Table MV-1'!$P15/'Table MV-1'!$P$61 -> 0.017735277 | E7: ='Table MV-1'!$P15/'Table MV-1'!$P$61 -> 0.017735277 | F7: ='Table MV-1'!$P15/'Table MV-1'!$P$61 -> 0.017735277 | G7: 0
A8: Connecticut | B8: =C8 -> 0.0088997529 | C8: ='Table MV-1'!J16/'Table MV-1'!$J$61 -> 0.0088997529 | D8: ='Table MV-1'!$P16/'Table MV-1'!$P$61 -> 0.0094427295 | E8: ='Table MV-1'!$P16/'Table MV-1'!$P$61 -> 0.0094427295 | F8: ='Table MV-1'!$P16/'Table MV-1'!$P$61 -> 0.0094427295 | G8: 0
A9: Delaware | B9: =C9 -> 0.0014251224 | C9: ='Table MV-1'!J17/'Table MV-1'!$J$61 -> 0.0014251224 | D9: ='Table MV-1'!$P17/'Table MV-1'!$P$61 -> 0.0015027065 | E9: ='Table MV-1'!$P17/'Table MV-1'!$P$61 -> 0.0015027065 | F9: ='Table MV-1'!$P17/'Table MV-1'!$P$61 -> 0.0015027065 | G9: 0
A10: District of Columbia | B10: =C10 -> 0.00075393034 | C10: ='Table MV-1'!J18/'Table MV-1'!$J$61 -> 0.00075393034 | D10: ='Table MV-1'!$P18/'Table MV-1'!$P$61 -> 0.0010172125 | E10: ='Table MV-1'!$P18/'Table MV-1'!$P$61 -> 0.0010172125 | F10: ='Table MV-1'!$P18/'Table MV-1'!$P$61 -> 0.0010172125 | G10: 0
A11: Florida | B11: =C11 -> 0.062154559 | C11: ='Table MV-1'!J19/'Table MV-1'!$J$61 -> 0.062154559 | D11: ='Table MV-1'!$P19/'Table MV-1'!$P$61 -> 0.066199562 | E11: ='Table MV-1'!$P19/'Table MV-1'!$P$61 -> 0.066199562 | F11: ='Table MV-1'!$P19/'Table MV-1'!$P$61 -> 0.066199562 | G11: 0
A12: Georgia | B12: =C12 -> 0.030787727 | C12: ='Table MV-1'!J20/'Table MV-1'!$J$61 -> 0.030787727 | D12: ='Table MV-1'!$P20/'Table MV-1'!$P$61 -> 0.03128941 | E12: ='Table MV-1'!$P20/'Table MV-1'!$P$61 -> 0.03128941 | F12: ='Table MV-1'!$P20/'Table MV-1'!$P$61 -> 0.03128941 | G12: 0
A13: Hawaii | B13: =C13 -> 0.0043293262 | C13: ='Table MV-1'!J21/'Table MV-1'!$J$61 -> 0.0043293262 | D13: ='Table MV-1'!$P21/'Table MV-1'!$P$61 -> 0.0042690511 | E13: ='Table MV-1'!$P21/'Table MV-1'!$P$61 -> 0.0042690511 | F13: ='Table MV-1'!$P21/'Table MV-1'!$P$61 -> 0.0042690511 | G13: 0
... A52: Wyoming | B52: =C52 -> 0.0035860939 | C52: ='Table MV-1'!J60/'Table MV-1'!$J$61 -> 0.0035860939 | D52: ='Table MV-1'!$P60/'Table MV-1'!$P$61 -> 0.0029481541 | E52: ='Table MV-1'!$P60/'Table MV-1'!$P$61 -> 0.0029481541 | F52: ='Table MV-1'!$P60/'Table MV-1'!$P$61 -> 0.0029481541 | G52: 0
A53: subregion52 | B53: 0 | C53: 0 | D53: 0 | E53: 0 | F53: 0 | G53: 0
A54: subregion53 | B54: 0 | C54: 0 | D54: 0 | E54: 0 | F54: 0 | G54: 0
A55: subregion54 | B55: 0 | C55: 0 | D55: 0 | E55: 0 | F55: 0 | G55: 0
A56: subregion55 | B56: 0 | C56: 0 | D56: 0 | E56: 0 | F56: 0 | G56: 0
A57: subregion56 | B57: 0 | C57: 0 | D57: 0 | E57: 0 | F57: 0 | G57: 0
A58: subregion57 | B58: 0 | C58: 0 | D58: 0 | E58: 0 | F58: 0 | G58: 0
A59: subregion58 | B59: 0 | C59: 0 | D59: 0 | E59: 0 | F59: 0 | G59: 0
A60: subregion59 | B60: 0 | C60: 0 | D60: 0 | E60: 0 | F60: 0 | G60: 0
A61: subregion60 | B61: 0 | C61: 0 | D61: 0 | E61: 0 | F61: 0 | G61: 0
