Workbook

Sheet About
A1: AVLRaPTC Annual Vehicle Licensing Registration and Property Tax Costs
A3: Sources: | B3: Data
B4: American Automobile Association
B5: 2019
B6: Average Annual Cost of New Car Ownership Increases 5% to $9,282
B7: https://www.aaa.com/autorepair/articles/average-annual-cost-of-new-vehicle-ownership
B9: Explanation and Examples of U.S. State Vehicle Property Taxes
B10: Hendrickson, V. L.
B11: 2020
B12: Which U.S. States Charge Property Taxes for Cars?
B13: https://www.mansionglobal.com/articles/which-u-s-states-charge-property-taxes-for-cars-220298
B15: EV Taxes by State, 2025
B16: Tax Foundation
B17: 2025
B18: Electric Vehicle Taxes by State, 2025
B19: https://taxfoundation.org/data/all/state/electric-vehicle-ev-taxes/
A21: Notes
A22: The AAA document cited above lists the average U.S.-wide annual cost of licensing, registration, and taxes as:
A23: 753 | B23: 2019 USD/year
A25: This might seem high if one is familiar with annual license plate and car registration fees in some states,
A26: but it is likely reasonable when property tax is factored in. Property tax on vehicles varies greatly by state,
A27: with 23 states not charging it at all, versus the highest state charging an average of $1,011/year
A28: (according to Hendrickson, cited above). The AAA number appears to be a reasonable average accounting for
A29: high property taxes in some states and vehicle registration and license fees in essentially all states.
A31: The AAA number does not include sales tax on the car's initial purchase, which also varies by state, but
A32: generally is much higher than $753 (since the U.S. average sales tax is over 7%).
A34: We don't have data for vehicle types other than passenger LDVs, so we use the following assumptions:
A35: Value | B35: Registration fee and property tax multiplier for:
A36: 0.5 | B36: motorbikes
A37: 2 | B37: HDVs
A38: 1 | B38: freight LDVs
A40: Some states have higher EV registration fees to make up from lost revenue from gas taxes that don't affect
A41: BEVs and make less off PHEVs. We add an incremental EV registration fee weighted by U.S. state.
A43: Currency Conversion
A45: 0.898 | B45: 2019 to 2021 USD

Sheet EV Fees
A1: Electric Vehicles: EV Taxes by State, 2025 | Tax Foundation | E1: Sales Share
A2: State | B2: EV Purchase Tax Credit | C2: EV Annual Registration Fee | D2: Hybrid Annual Registration Fee | E2: psgr-LDV
A3: Alabama | B3: 0 | C3: 203 | D3: 103 | E3: {=INDEX('VSbS-passenger'!B$2:B$52,MATCH(TRIM('EV Fees'!$A3),TRIM('VSbS-passenger'!$A$2:$A$52),0))} -> 0.019359587
A4: Alaska | B4: 0 | C4: 0 | D4: 0 | E4: {=INDEX('VSbS-passenger'!B$2:B$52,MATCH(TRIM('EV Fees'!$A4),TRIM('VSbS-passenger'!$A$2:$A$52),0))} -> 0.001627845
A5: Arizona | B5: 0 | C5: 0 | D5: 0 | E5: {=INDEX('VSbS-passenger'!B$2:B$52,MATCH(TRIM('EV Fees'!$A5),TRIM('VSbS-passenger'!$A$2:$A$52),0))} -> 0.022923014
A6: Arkansas | B6: 0 | C6: 200 | D6: 100 | E6: {=INDEX('VSbS-passenger'!B$2:B$52,MATCH(TRIM('EV Fees'!$A6),TRIM('VSbS-passenger'!$A$2:$A$52),0))} -> 0.008298231
A7: California | B7: 0 (b) | C7: 118 | D7: 0 | E7: {=INDEX('VSbS-passenger'!B$2:B$52,MATCH(TRIM('EV Fees'!$A7),TRIM('VSbS-passenger'!$A$2:$A$52),0))} -> 0.13507737
A8: Colorado | B8: 3500 | C8: 60.05 | D8: 0 | E8: {=INDEX('VSbS-passenger'!B$2:B$52,MATCH(TRIM('EV Fees'!$A8),TRIM('VSbS-passenger'!$A$2:$A$52),0))} -> 0.015589702
A9: Connecticut | B9: 750-5,000 | C9: 0 | D9: 0 | E9: {=INDEX('VSbS-passenger'!B$2:B$52,MATCH(TRIM('EV Fees'!$A9),TRIM('VSbS-passenger'!$A$2:$A$52),0))} -> 0.011520117
A10: Delaware | B10: 1,000-2,500 (c) | C10: 0 | D10: 0 | E10: {=INDEX('VSbS-passenger'!B$2:B$52,MATCH(TRIM('EV Fees'!$A10),TRIM('VSbS-passenger'!$A$2:$A$52),0))} -> 0.003955998
A11: Florida | B11: 0 (d) | C11: 0 | D11: 0 | E11: {=INDEX('VSbS-passenger'!B$2:B$52,MATCH(TRIM('EV Fees'!$A11),TRIM('VSbS-passenger'!$A$2:$A$52),0))} -> 0.074585349
A12: Georgia | B12: 0 | C12: 234.97 | D12: 0 | E12: {=INDEX('VSbS-passenger'!B$2:B$52,MATCH(TRIM('EV Fees'!$A12),TRIM('VSbS-passenger'!$A$2:$A$52),0))} -> 0.033246883
A13: Hawaii | B13: 0 | C13: 50 | D13: 0 | E13: {=INDEX('VSbS-passenger'!B$2:B$52,MATCH(TRIM('EV Fees'!$A13),TRIM('VSbS-passenger'!$A$2:$A$52),0))} -> 0.004517788
A14: Idaho | B14: 0 | C14: 140 | D14: 75 | E14: {=INDEX('VSbS-passenger'!B$2:B$52,MATCH(TRIM('EV Fees'!$A14),TRIM('VSbS-passenger'!$A$2:$A$52),0))} -> 0.005596236
A15: Illinois | B15: 4,000 (e) | C15: 100 | D15: 0 | E15: {=INDEX('VSbS-passenger'!B$2:B$52,MATCH(TRIM('EV Fees'!$A15),TRIM('VSbS-passenger'!$A$2:$A$52),0))} -> 0.039583803
A16: Indiana | B16: 0 | C16: 230 | D16: 77 | E16: {=INDEX('VSbS-passenger'!B$2:B$52,MATCH(TRIM('EV Fees'!$A16),TRIM('VSbS-passenger'!$A$2:$A$52),0))} -> 0.020200142
A17: Iowa | B17: 0 | C17: 130 | D17: 65 | E17: {=INDEX('VSbS-passenger'!B$2:B$52,MATCH(TRIM('EV Fees'!$A17),TRIM('VSbS-passenger'!$A$2:$A$52),0))} -> 0.01106908
A18: Kansas | B18: Up to 4000 | C18: 165 | D18: 70 | E18: {=INDEX('VSbS-passenger'!B$2:B$52,MATCH(TRIM('EV Fees'!$A18),TRIM('VSbS-passenger'!$A$2:$A$52),0))} -> 0.00845656
A19: Kentucky | B19: 0 | C19: 120 | D19: 60 | E19: {=INDEX('VSbS-passenger'!B$2:B$52,MATCH(TRIM('EV Fees'!$A19),TRIM('VSbS-passenger'!$A$2:$A$52),0))} -> 0.015641721
A20: Louisiana | B20: 0 | C20: 110 | D20: 60 | E20: {=INDEX('VSbS-passenger'!B$2:B$52,MATCH(TRIM('EV Fees'!$A20),TRIM('VSbS-passenger'!$A$2:$A$52),0))} -> 0.012514265
A21: Maine | B21: Up to 7,500 (f) | C21: 0 | D21: 0 | E21: {=INDEX('VSbS-passenger'!B$2:B$52,MATCH(TRIM('EV Fees'!$A21),TRIM('VSbS-passenger'!$A$2:$A$52),0))} -> 0.003386864
A22: Maryland | B22: 3,000 (g) | C22: 125 | D22: 100 | E22: {=INDEX('VSbS-passenger'!B$2:B$52,MATCH(TRIM('EV Fees'!$A22),TRIM('VSbS-passenger'!$A$2:$A$52),0))} -> 0.017344821
A23: Massachusetts | B23: Up to 3,500 | C23: 0 | D23: 0 | E23: {=INDEX('VSbS-passenger'!B$2:B$52,MATCH(TRIM('EV Fees'!$A23),TRIM('VSbS-passenger'!$A$2:$A$52),0))} -> 0.019055189
A24: Michigan | B24: 0 | C24: 160 | D24: 60 | E24: {=INDEX('VSbS-passenger'!B$2:B$52,MATCH(TRIM('EV Fees'!$A24),TRIM('VSbS-passenger'!$A$2:$A$52),0))} -> 0.025602286
A25: Minnesota | B25: 0 | C25: 75 | D25: 0 | E25: {=INDEX('VSbS-passenger'!B$2:B$52,MATCH(TRIM('EV Fees'!$A25),TRIM('VSbS-passenger'!$A$2:$A$52),0))} -> 0.017517332
A26: Mississippi | B26: 0 (d) | C26: 150 | D26: 75 | E26: {=INDEX('VSbS-passenger'!B$2:B$52,MATCH(TRIM('EV Fees'!$A26),TRIM('VSbS-passenger'!$A$2:$A$52),0))} -> 0.007499146
A27: Missouri | B27: 0 | C27: 135 | D27: 67.5 | E27: {=INDEX('VSbS-passenger'!B$2:B$52,MATCH(TRIM('EV Fees'!$A27),TRIM('VSbS-passenger'!$A$2:$A$52),0))} -> 0.018941079
A28: Montana | B28: 0 | C28: =AVERAGE(130,190) -> 160 | D28: 85 | E28: {=INDEX('VSbS-passenger'!B$2:B$52,MATCH(TRIM('EV Fees'!$A28),TRIM('VSbS-passenger'!$A$2:$A$52),0))} -> 0.004366573
A29: Nebraska | B29: 0 | C29: 150 | D29: 75 | E29: {=INDEX('VSbS-passenger'!B$2:B$52,MATCH(TRIM('EV Fees'!$A29),TRIM('VSbS-passenger'!$A$2:$A$52),0))} -> 0.005943836
A30: Nevada | B30: 0 (d) | C30: 0 | D30: 0 | E30: {=INDEX('VSbS-passenger'!B$2:B$52,MATCH(TRIM('EV Fees'!$A30),TRIM('VSbS-passenger'!$A$2:$A$52),0))} -> 0.009773149
A31: New Hampshire | B31: 0 (d) | C31: 100 | D31: 50 | E31: {=INDEX('VSbS-passenger'!B$2:B$52,MATCH(TRIM('EV Fees'!$A31),TRIM('VSbS-passenger'!$A$2:$A$52),0))} -> 0.004383162
A32: New Jersey | B32: Up to 4,000 (b)(h) | C32: 260 | D32: 0 | E32: {=INDEX('VSbS-passenger'!B$2:B$52,MATCH(TRIM('EV Fees'!$A32),TRIM('VSbS-passenger'!$A$2:$A$52),0))} -> 0.024170046
A33: New Mexico | B33: Up to 3000 | C33: 0 | D33: 0 | E33: {=INDEX('VSbS-passenger'!B$2:B$52,MATCH(TRIM('EV Fees'!$A33),TRIM('VSbS-passenger'!$A$2:$A$52),0))} -> 0.005934781
A34: New York | B34: Up to 2,000 | C34: 0 | D34: 0 | E34: {=INDEX('VSbS-passenger'!B$2:B$52,MATCH(TRIM('EV Fees'!$A34),TRIM('VSbS-passenger'!$A$2:$A$52),0))} -> 0.040260008
A35: North Carolina | B35: 0 | C35: 214.5 | D35: 107.25 | E35: {=INDEX('VSbS-passenger'!B$2:B$52,MATCH(TRIM('EV Fees'!$A35),TRIM('VSbS-passenger'!$A$2:$A$52),0))} -> 0.032324728
A36: North Dakota | B36: 0 | C36: 120 | D36: 50 | E36: {=INDEX('VSbS-passenger'!B$2:B$52,MATCH(TRIM('EV Fees'!$A36),TRIM('VSbS-passenger'!$A$2:$A$52),0))} -> 0.002051204
A37: Ohio | B37: 0 | C37: 200 | D37: 150 | E37: {=INDEX('VSbS-passenger'!B$2:B$52,MATCH(TRIM('EV Fees'!$A37),TRIM('VSbS-passenger'!$A$2:$A$52),0))} -> 0.040403585
A38: Oklahoma | B38: Up to 5,500 | C38: 110 | D38: 82 | E38: {=INDEX('VSbS-passenger'!B$2:B$52,MATCH(TRIM('EV Fees'!$A38),TRIM('VSbS-passenger'!$A$2:$A$52),0))} -> 0.011640695
A39: Oregon | B39: Up to 7,500 (f) (h) | C39: 115 | D39: 35 | E39: {=INDEX('VSbS-passenger'!B$2:B$52,MATCH(TRIM('EV Fees'!$A39),TRIM('VSbS-passenger'!$A$2:$A$52),0))} -> 0.013704702
A40: Pennsylvania | B40: Up to 3,000 (f) (k) | C40: 200 | D40: 50 | E40: {=INDEX('VSbS-passenger'!B$2:B$52,MATCH(TRIM('EV Fees'!$A40),TRIM('VSbS-passenger'!$A$2:$A$52),0))} -> 0.03846201
...

Sheet VSbS-passenger
A1: Unit: dimensionless (share of vehicles) | B1: LDVs | C1: HDVs | D1: aircraft | E1: rail | F1: ships | G1: motorbikes
A2: Alabama | B2: 0.019359587 | C2: 0.005587852 | D2: 0.019282656 | E2: 0.019282656 | F2: 0.019282656 | G2: 0.013796718
A3: Alaska | B3: 0.001627845 | C3: 0.008564596 | D3: 0.002873461 | E3: 0.002873461 | F3: 0.002873461 | G3: 0.003215724
A4: Arizona | B4: 0.022923014 | C4: 0.008431457 | D4: 0.021940886 | E4: 0.021940886 | F4: 0.021940886 | G4: 0.01453794
A5: Arkansas | B5: 0.008298231 | C5: 0.011966588 | D5: 0.010559004 | E5: 0.010559004 | F5: 0.010559004 | G5: 0.020388346
A6: California | B6: 0.13507737 | C6: 0.10017994 | D6: 0.11017322 | E6: 0.11017322 | F6: 0.11017322 | G6: 0.094309654
A7: Colorado | B7: 0.015589702 | C7: 0.013631816 | D7: 0.019392719 | E7: 0.019392719 | F7: 0.019392719 | G7: 0.021503721
A8: Connecticut | B8: 0.011520117 | C8: 0.01169733 | D8: 0.010392956 | E8: 0.010392956 | F8: 0.010392956 | G8: 0.009719937
A9: Delaware | B9: 0.003955998 | C9: 0.003834197 | D9: 0.003646563 | E9: 0.003646563 | F9: 0.003646563 | G9: 0.000483061
A10: District of Columbia | B10: 0.002000251 | C10: 0.005100008 | D10: 0.001292207 | E10: 0.001292207 | F10: 0.001292207 | G10: 0.000428307
A11: Florida | B11: 0.074585349 | C11: 0.059786243 | D11: 0.066921421 | E11: 0.066921421 | F11: 0.066921421 | G11: 0.074455641
A12: Georgia | B12: 0.033246883 | C12: 0.036664815 | D12: 0.03200135 | E12: 0.03200135 | F12: 0.03200135 | G12: 0.024934379
A13: Hawaii | B13: 0.004517788 | C13: 0.002866457 | D13: 0.004512052 | E13: 0.004512052 | F13: 0.004512052 | G13: 0.004440367
... A61: subregion60 | B61: 0 | C61: 0 | D61: 0 | E61: 0 | F61: 0 | G61: 0

Sheet AVLRaPTC-psgr
A1: 2012 USD/year | B1: LDVs | C1: HDVs | D1: aircraft | E1: rail | F1: ships | G1: motorbikes
A2: battery electric vehicle | B2: =About!$A$23*About!$A$45+'EV Fees'!C53 -> 802.46413 | C2: =$B2*About!$A$37 -> 1604.9283 | D2: 0 | E2: 0 | F2: 0 | G2: =$B2*About!$A$36 -> 401.23206
A3: natural gas vehicle | B3: =About!$A$23*About!$A$45 -> 676.194 | C3: =$B3*About!$A$37 -> 1352.388 | D3: 0 | E3: 0 | F3: 0 | G3: =$B3*About!$A$36 -> 338.097
A4: gasoline vehicle | B4: =About!$A$23*About!$A$45 -> 676.194 | C4: =$B4*About!$A$37 -> 1352.388 | D4: 0 | E4: 0 | F4: 0 | G4: =$B4*About!$A$36 -> 338.097
A5: diesel vehicle | B5: =About!$A$23*About!$A$45 -> 676.194 | C5: =$B5*About!$A$37 -> 1352.388 | D5: 0 | E5: 0 | F5: 0 | G5: =$B5*About!$A$36 -> 338.097
A6: plugin hybrid vehicle | B6: =About!$A$23*About!$A$45+'EV Fees'!D53 -> 710.41339 | C6: =$B6*About!$A$37 -> 1420.8268 | D6: 0 | E6: 0 | F6: 0 | G6: =$B6*About!$A$36 -> 355.20669
A7: LPG vehicle | B7: =About!$A$23*About!$A$45 -> 676.194 | C7: =$B7*About!$A$37 -> 1352.388 | D7: 0 | E7: 0 | F7: 0 | G7: =$B7*About!$A$36 -> 338.097
A8: hydrogen vehicle | B8: =About!$A$23*About!$A$45 -> 676.194 | C8: =$B8*About!$A$37 -> 1352.388 | D8: 0 | E8: 0 | F8: 0 | G8: =$B8*About!$A$36 -> 338.097

Sheet AVLRaPTC-frgt
A1: 2012 USD/year | B1: LDVs | C1: HDVs | D1: aircraft | E1: rail | F1: ships | G1: motorbikes
A2: battery electric vehicle | B2: =About!$A$23*About!$A$45+'EV Fees'!C53 -> 802.46413 | C2: =$B2*About!$A$37 -> 1604.9283 | D2: 0 | E2: 0 | F2: 0 | G2: 0
A3: natural gas vehicle | B3: =About!$A$23*About!$A$45 -> 676.194 | C3: =$B3*About!$A$37 -> 1352.388 | D3: 0 | E3: 0 | F3: 0 | G3: 0
A4: gasoline vehicle | B4: =About!$A$23*About!$A$45 -> 676.194 | C4: =$B4*About!$A$37 -> 1352.388 | D4: 0 | E4: 0 | F4: 0 | G4: 0
A5: diesel vehicle | B5: =About!$A$23*About!$A$45+'EV Fees'!D53 -> 710.41339 | C5: =$B5*About!$A$37 -> 1420.8268 | D5: 0 | E5: 0 | F5: 0 | G5: 0
A6: plugin hybrid vehicle | B6: =About!$A$23*About!$A$45 -> 676.194 | C6: =$B6*About!$A$37 -> 1352.388 | D6: 0 | E6: 0 | F6: 0 | G6: 0
A7: LPG vehicle | B7: =About!$A$23*About!$A$45 -> 676.194 | C7: =$B7*About!$A$37 -> 1352.388 | D7: 0 | E7: 0 | F7: 0 | G7: 0
A8: hydrogen vehicle | B8: =About!$A$23*About!$A$45 -> 676.194 | C8: =$B8*About!$A$37 -> 1352.388 | D8: 0 | E8: 0 | F8: 0 | G8: 0
