Workbook

Sheet About
A1: RCDC Reliability Credit Derate Curve
A3: Sources: | B3: Parameter selection (shape a, scale b)
B4: Energy Innovation (internal)
B5: Reliability Credit Redesign design doc (Reliability-Credit-Redesign-2026-08-19.md) and parameter sweep, RCO
B6: 2026
B8: Parameters chosen from the redesign's parameter sweep (a in {8,15}, b in {0.8,0.9,1.0}), not calibrated to external evidence. a was raised 8 -> 15 in the 2026-08-20 refinement so the new-entrant credit stays >= 0.995 through 2027 and the derate bites only once the 5-year-foresight requirement passes ~76%. Recalibration once the design is ratified is an open item (see the design doc's Remaining Work).
A11: Notes:
A12: Role in the model | B12: This file sets the two constants of the Weibull-form reliability credit derate applied to NEW-ENTRANT capacity in the unified reliability capacity market: Reliability Credit Ratio for Non Qualifying Sources = EXP(-(F / b)^a), where F = Five Year Foresight Elec Portfolio Values for Reliability Check (the RPS/CES requirement five years ahead). It steers new reliability builds away from non-qualifying sources as the clean-electricity requirement approaches 100%. It is one part of the three-part split credit: the EXISTING fleet uses a separate physical energy-budget ratio (not this curve), and the endgame is handled by the rampdown + fossil backstop variables.
A13: How the model reads it | B13: GET DIRECT CONSTANTS from RCDC.csv: cell B2 = RCDCa Reliability Credit Derate Curve Shape Parameter, cell B3 = RCDCb Reliability Credit Derate Curve Scale Parameter. Both scenarios (policy and BAU) share the same constants. Export the RCDC tab of this workbook as RCDC.csv (CSV layout must stay: header row, then 'shape parameter a', then 'scale parameter b').
A14: Behavior at the chosen values (a=15, b=0.9) | B14: Credit ~1.00 below ~65% foresight requirement; ~0.98 at 76%; 0.105 at 95%; 0.008 at 100%. Higher a sharpens the transition; b positions it (credit = 1/e when F = b). The Curve tab computes the full curve from the Parameters tab and marks these landmarks; the Checks tab verifies monotonicity and the 95% landmark against the validated run evidence (REL_CA95: ratio 0.1054 from 2035).
A15: Provenance | B15: Introduced with the 2026-08 reliability credit redesign (eps-us develop_4.0.6; CSV committed 50643afc). Design history, the rejected single-factor variant, and the sweep evidence trail are in Reliability-Credit-Redesign-2026-08-19.md (Robbie Orvis / RCO).

Sheet Parameters
A1: Editable parameters (all Curve/Checks/RCDC cells recompute)
A2: RCDCa shape parameter a | B2: 15
A3: RCDCb scale parameter b | B3: 0.9
A5: Comparison curve (Curve tab column C, for reference only)
A6: comparison shape a | B6: 8
A7: comparison scale b | B7: 0.9

Sheet Curve
A1: Foresight requirement F | B1: Credit = EXP(-(F/b)^a) | C1: Comparison curve | D1: Landmark
A2: 0.5 | B2: =EXP(-((A2/Parameters!$B$3)^Parameters!$B$2)) -> 0.99985179 | C2: =EXP(-((A2/Parameters!$B$7)^Parameters!$B$6)) -> 0.99096661
A3: 0.51 | B3: =EXP(-((A3/Parameters!$B$3)^Parameters!$B$2)) -> 0.99980053 | C3: =EXP(-((A3/Parameters!$B$7)^Parameters!$B$6)) -> 0.98942417
A4: 0.52 | B4: =EXP(-((A4/Parameters!$B$3)^Parameters!$B$2)) -> 0.9997331 | C4: =EXP(-((A4/Parameters!$B$7)^Parameters!$B$6)) -> 0.9876578
A5: 0.53 | B5: =EXP(-((A5/Parameters!$B$3)^Parameters!$B$2)) -> 0.99964484 | C5: =EXP(-((A5/Parameters!$B$7)^Parameters!$B$6)) -> 0.98564081
A6: 0.54 | B6: =EXP(-((A6/Parameters!$B$3)^Parameters!$B$2)) -> 0.99952993 | C6: =EXP(-((A6/Parameters!$B$7)^Parameters!$B$6)) -> 0.98334411
A7: 0.55 | B7: =EXP(-((A7/Parameters!$B$3)^Parameters!$B$2)) -> 0.99938103 | C7: =EXP(-((A7/Parameters!$B$7)^Parameters!$B$6)) -> 0.98073609 | D7: credit ~1 at mid-range requirements
A8: 0.56 | B8: =EXP(-((A8/Parameters!$B$3)^Parameters!$B$2)) -> 0.99918903 | C8: =EXP(-((A8/Parameters!$B$7)^Parameters!$B$6)) -> 0.97778254
A9: 0.57 | B9: =EXP(-((A9/Parameters!$B$3)^Parameters!$B$2)) -> 0.99894256 | C9: =EXP(-((A9/Parameters!$B$7)^Parameters!$B$6)) -> 0.97444653
A10: 0.58 | B10: =EXP(-((A10/Parameters!$B$3)^Parameters!$B$2)) -> 0.99862759 | C10: =EXP(-((A10/Parameters!$B$7)^Parameters!$B$6)) -> 0.97068838
A11: 0.59 | B11: =EXP(-((A11/Parameters!$B$3)^Parameters!$B$2)) -> 0.9982268 | C11: =EXP(-((A11/Parameters!$B$7)^Parameters!$B$6)) -> 0.96646562
A12: 0.6 | B12: =EXP(-((A12/Parameters!$B$3)^Parameters!$B$2)) -> 0.99771895 | C12: =EXP(-((A12/Parameters!$B$7)^Parameters!$B$6)) -> 0.96173297
A13: 0.61 | B13: =EXP(-((A13/Parameters!$B$3)^Parameters!$B$2)) -> 0.99707804 | C13: =EXP(-((A13/Parameters!$B$7)^Parameters!$B$6)) -> 0.9564424
A14: 0.62 | B14: =EXP(-((A14/Parameters!$B$3)^Parameters!$B$2)) -> 0.99627242 | C14: =EXP(-((A14/Parameters!$B$7)^Parameters!$B$6)) -> 0.95054321
A15: 0.63 | B15: =EXP(-((A15/Parameters!$B$3)^Parameters!$B$2)) -> 0.99526369 | C15: =EXP(-((A15/Parameters!$B$7)^Parameters!$B$6)) -> 0.94398216
A16: 0.64 | B16: =EXP(-((A16/Parameters!$B$3)^Parameters!$B$2)) -> 0.99400544 | C16: =EXP(-((A16/Parameters!$B$7)^Parameters!$B$6)) -> 0.93670372
A17: 0.65 | B17: =EXP(-((A17/Parameters!$B$3)^Parameters!$B$2)) -> 0.99244184 | C17: =EXP(-((A17/Parameters!$B$7)^Parameters!$B$6)) -> 0.92865032
A18: 0.66 | B18: =EXP(-((A18/Parameters!$B$3)^Parameters!$B$2)) -> 0.99050595 | C18: =EXP(-((A18/Parameters!$B$7)^Parameters!$B$6)) -> 0.91976277
A19: 0.67 | B19: =EXP(-((A19/Parameters!$B$3)^Parameters!$B$2)) -> 0.98811795 | C19: =EXP(-((A19/Parameters!$B$7)^Parameters!$B$6)) -> 0.90998074
... A27: 0.75 | B27: =EXP(-((A27/Parameters!$B$3)^Parameters!$B$2)) -> 0.93715605 | C27: =EXP(-((A27/Parameters!$B$7)^Parameters!$B$6)) -> 0.79249583
A28: 0.76 | B28: =EXP(-((A28/Parameters!$B$3)^Parameters!$B$2)) -> 0.92388191 | C28: =EXP(-((A28/Parameters!$B$7)^Parameters!$B$6)) -> 0.77215933 | D28: derate begins to bite (design intent of a=15)
A29: 0.77 | B29: =EXP(-((A29/Parameters!$B$3)^Parameters!$B$2)) -> 0.90817199 | C29: =EXP(-((A29/Parameters!$B$7)^Parameters!$B$6)) -> 0.75046023
A30: 0.78 | B30: =EXP(-((A30/Parameters!$B$3)^Parameters!$B$2)) -> 0.88968209 | C30: =EXP(-((A30/Parameters!$B$7)^Parameters!$B$6)) -> 0.72739515
A31: 0.79 | B31: =EXP(-((A31/Parameters!$B$3)^Parameters!$B$2)) -> 0.8680517 | C31: =EXP(-((A31/Parameters!$B$7)^Parameters!$B$6)) -> 0.70297562
A32: 0.8 | B32: =EXP(-((A32/Parameters!$B$3)^Parameters!$B$2)) -> 0.84291578 | C32: =EXP(-((A32/Parameters!$B$7)^Parameters!$B$6)) -> 0.67722999
A33: 0.81 | B33: =EXP(-((A33/Parameters!$B$3)^Parameters!$B$2)) -> 0.81392168 | C33: =EXP(-((A33/Parameters!$B$7)^Parameters!$B$6)) -> 0.65020524
A34: 0.82 | B34: =EXP(-((A34/Parameters!$B$3)^Parameters!$B$2)) -> 0.78075247 | C34: =EXP(-((A34/Parameters!$B$7)^Parameters!$B$6)) -> 0.62196862
A35: 0.83 | B35: =EXP(-((A35/Parameters!$B$3)^Parameters!$B$2)) -> 0.74315716 | C35: =EXP(-((A35/Parameters!$B$7)^Parameters!$B$6)) -> 0.59260904
A36: 0.84 | B36: =EXP(-((A36/Parameters!$B$3)^Parameters!$B$2)) -> 0.7009881 | C36: =EXP(-((A36/Parameters!$B$7)^Parameters!$B$6)) -> 0.56223807
A37: 0.85 | B37: =EXP(-((A37/Parameters!$B$3)^Parameters!$B$2)) -> 0.65424471 | C37: =EXP(-((A37/Parameters!$B$7)^Parameters!$B$6)) -> 0.53099052
A38: 0.86 | B38: =EXP(-((A38/Parameters!$B$3)^Parameters!$B$2)) -> 0.60312107 | C38: =EXP(-((A38/Parameters!$B$7)^Parameters!$B$6)) -> 0.49902435
A39: 0.87 | B39: =EXP(-((A39/Parameters!$B$3)^Parameters!$B$2)) -> 0.54805315 | C39: =EXP(-((A39/Parameters!$B$7)^Parameters!$B$6)) -> 0.46651994
A40: 0.88 | B40: =EXP(-((A40/Parameters!$B$3)^Parameters!$B$2)) -> 0.48975865 | C40: =EXP(-((A40/Parameters!$B$7)^Parameters!$B$6)) -> 0.43367858
A41: 0.89 | B41: =EXP(-((A41/Parameters!$B$3)^Parameters!$B$2)) -> 0.42926001 | C41: =EXP(-((A41/Parameters!$B$7)^Parameters!$B$6)) -> 0.40072008
A42: 0.9 | B42: =EXP(-((A42/Parameters!$B$3)^Parameters!$B$2)) -> 0.36787944 | C42: =EXP(-((A42/Parameters!$B$7)^Parameters!$B$6)) -> 0.36787944 | D42: credit = 1/e when F = b
A43: 0.91 | B43: =EXP(-((A43/Parameters!$B$3)^Parameters!$B$2)) -> 0.30719422 | C43: =EXP(-((A43/Parameters!$B$7)^Parameters!$B$6)) -> 0.33540264
A44: 0.92 | B44: =EXP(-((A44/Parameters!$B$3)^Parameters!$B$2)) -> 0.2489438 | C44: =EXP(-((A44/Parameters!$B$7)^Parameters!$B$6)) -> 0.30354153
A45: 0.93 | B45: =EXP(-((A45/Parameters!$B$3)^Parameters!$B$2)) -> 0.19488718 | C45: =EXP(-((A45/Parameters!$B$7)^Parameters!$B$6)) -> 0.27254798
A46: 0.94 | B46: =EXP(-((A46/Parameters!$B$3)^Parameters!$B$2)) -> 0.14662062 | C46: =EXP(-((A46/Parameters!$B$7)^Parameters!$B$6)) -> 0.24266738
A47: 0.95 | B47: =EXP(-((A47/Parameters!$B$3)^Parameters!$B$2)) -> 0.1053807 | C47: =EXP(-((A47/Parameters!$B$7)^Parameters!$B$6)) -> 0.21413177 | D47: ClimateAmbition 95% CES plateau (run: 0.1054)
...

Sheet Checks
A1: Check | B1: Value | C1: Status
A2: Credit at F=0.50 (should be ~1, > 0.999) | B2: =Curve!B2 -> 0.99985179 | C2: =IF(B2>0.999,"PASS","FAIL") -> PASS
A3: Credit at F=0.95 (validated run landmark 0.1054, +/-0.02) | B3: =Curve!B47 -> 0.1053807 | C3: =IF(ABS(B3-0.1054)<0.02,"PASS","FAIL") -> PASS
A4: Credit at F=b equals 1/e (definition of scale parameter) | B4: =Curve!B42 -> 0.36787944 | C4: =IF(ABS(B4-EXP(-1))<0.0001,"PASS","FAIL") -> PASS
A5: Curve monotonically decreasing (count of rises, must be 0) | B5: =SUMPRODUCT(--(Curve!B3:B52>Curve!B2:B51)) -> 0 | C5: =IF(B5=0,"PASS","FAIL") -> PASS
A6: Output tab a matches Parameters | B6: =RCDC!B2 -> 15 | C6: =IF(B6=Parameters!B2,"PASS","FAIL") -> PASS
A7: Output tab b matches Parameters | B7: =RCDC!B3 -> 0.9 | C7: =IF(B7=Parameters!B3,"PASS","FAIL") -> PASS

Sheet RCDC
A1: Parameter | B1: Value
A2: shape parameter a | B2: =Parameters!B2 -> 15
A3: scale parameter b | B3: =Parameters!B3 -> 0.9
