Workbook
Name a: #REF!
Name AsphaltStore: [1]Control!$D$50
Name base.year: #REF!
Name BaseYear: 2018
Name BTV11_15: #REF!
Name BVT17_15: #REF!
Name CAAGR_tolerance: 200
Name CH4_to_CO2e: '[2]Cross-Page Data'!$C$12
Name CH4GWP: #REF!
Name CO2_T4_APS: #REF!
Name CO2_T4_NZE: #REF!
Name CO2_T4_STEPS: #REF!
Name CO2_T5_APS: #REF!
Name CO2_T5_CPS: #REF!
Name CO2_T5_NZE: #REF!
Name CO2_T5_STEPS: #REF!
Name coal.past: #REF!
Name COAL_PRODUCTION: #REF!
Name Coal_trade: #REF!
Name coaldemand: #REF!
Name CokeCoalStore: [1]Control!$D$63
Name Constants.Density.Diesel: #REF!
Name Constants.Density.Ethanol: #REF!
Name Constants.Density.JetFuel: #REF!
Name Constants.Density.MotorSpirit: #REF!
Name ConsumeBlock1: '[1]Default State Energy Data Table'!$A$6:$AM$67
Name Conversion.to.average.power: #REF!
Name Conversion.water.L: #REF!
Name Conversion.water.units: #REF!
Name Conversions.Area.m2: #REF!
Name Conversions.Area.Units: #REF!
Name Conversions.Energy.Joules: #REF!
Name Conversions.Energy.Units: #REF!
Name Conversions.Money.GBP: #REF!
Name Conversions.Money.Units: #REF!
Name Conversions.Power.Units: #REF!
Name Conversions.Power.Watts: #REF!
Name Cost.Capital.Scenario: #REF!
Name Cost.Finance.Scenario: #REF!
Name Cost.Fuel.Scenario: #REF!
Name Cost.Infrastructure.Scenario: #REF!
Name cpi_2010to2012: #REF!
Name cpi_2013to2012: #REF!
Name cpi_2014to2012: #REF!
Name cpi_2016to2012: #REF!
Name CreateRegions: #REF!
Name csp.capacity: #REF!
Name CSVfilepath: #REF!
Name D: #REF!
Name dd: #REF!
Name ddd: #REF!
Name ddddd: #REF!
Name dddddd: #REF!
Name deflator_year: "$2018"
Name DeflatorYear: "$2018"
Name discount_factors: #REF!
Name DistillStore: [1]Control!$D$51
Name DW_EDO_022WV: #REF!
Name DW_EDO_023WV: #REF!
Name DW_EDO_024WV: #REF!

Sheet About
A1: IEMUEF Industrial Equipment Minimum Unit Energy Factor
A3: Source: | B3: Energy Intensity Improvements
B4: Energy Information Administration
B5: 2025
B6: Assumptions to the Annual Energy Outlook 2025: Industrial Demand Module
B7: https://www.eia.gov/outlooks/aeo/assumptions/
B8: Table 3
B10: Industrial heat pump efficiency
B11: Arpagaus et al.
B12: 2018
B13: High temperature heat pumps: Market overview, state of the art, research status, refrigerants, and application potentials
B14: https://www.sciencedirect.com/science/article/pii/S0360544218305759
B15: Figure 8
B17: Combustion efficiency by temperature
B18: U.S. Department of Energy
B19: undated
B20: Check Burner Air-to-Fuel Ratios (Process Heating Tip Sheet)
B21: https://www.energy.gov/sites/prod/files/2014/05/f16/check_burner_air2.pdf
B22: Burner-integral (unit-level) waste heat recovery assumed universal (100% penetration, best case). With-recovery basis = ε = 0.6 recuperative-burner curve; ε = 0.8 regenerative where established (glass, steel stoves/reheat, >500 °C furnaces). ε = 0.4 (central HX / air preheat) = SYSTEM WHR, excluded. See Combustion Efficiency tab.
B24: Direct electric heating efficiency
B25: Assumption (this study)
B26: —
... B49: http://heattreatconsortium.com/metals-advisor/electric-arc-furnace/electric-arc-furnace-energy-consumption/#:~:text=Energy%20consumption%20varies%20from%20350-700%20kWh/ton%20of,burners%20reduces%20electric%20consumption%20to%20425%20kWh/ton.
A51: Notes
A52: This file should contain the minimum theoretical unit energy factors for industrial equipment
A53: subscripted by industrial process and fuel.
B55: Combustion efficiency — temperature/efficiency curves
B56: U.S. Department of Energy
B57: 2015 (Third Edition)
B58: Improving Process Heating System Performance: A Sourcebook for Industry (Third Edition)
B59: https://www.energy.gov/sites/prod/files/2016/04/f30/Improving%20Process%20Heating%20System%20Performance%20A%20Sourcebook%20for%20Industry%20Third%20Edition_0.pdf
B60: Temperature vs. efficiency curves; 10% excess-air basis
B62: Burner ε-curve definitions (recuperative/regenerative/central HX)
B63: Stephen R. Mickey (Thermal Processing)
B64: 2017
B65: Efficient Gas Heating of Industrial Furnaces
B66: https://thermalprocessing.com/efficient-gas-heating-of-industrial-furnaces/
B67: Defines ε=0.4 central heat exchanger, ε=0.6 recuperative burner, ε=0.8 regenerative burner efficiency curves (see 'Mickey data' tab)
B69: Industrial WHR technology / regenerative practice
B70: Kermeli et al.
...

Sheet BAU Efficiency Improvements
A1: indst/BIEEI
D18: UEC 2018 (trillion British thermal | E18: REI 2050 | F18: 2018 | G18: 2050 | K18: improvement
B19: End use | C19: Fuel | D19: units per billion 2012$ of shipments) | E19: existing | F19: new REI | G19: new REI | I19: 2021 | J19: 2050 | K19: over model run | M19: annual improvement
B20: Heat | C20: Natural gas | D20: 0.218 | E20: 0.844 | F20: 0.965 | G20: 0.812 | I20: {=TREND(F20:G20,$F$18:$G$18,$I$19)} -> 0.95065625 | J20: =G20 -> 0.812 | K20: =1-J20/I20 -> 0.14585319 | M20: =1-(1-K20)^(1/($J$19-$I$19)) -> 0.0054215328
B21: Heat | C21: Electricity | D21: 0.022 | E21: 0.919 | F21: 0.984 | G21: 0.931 | I21: {=TREND(F21:G21,$F$18:$G$18,$I$19)} -> 0.97903125 | J21: =G21 -> 0.931 | K21: =1-J21/I21 -> 0.049059976 | M21: =1-(1-K21)^(1/($J$19-$I$19)) -> 0.0017331269
B22: Heat | C22: Steam | D22: 0.204 | E22: 0.844 | F22: 0.965 | G22: 0.814 | I22: {=TREND(F22:G22,$F$18:$G$18,$I$19)} -> 0.95084375 | J22: =G22 -> 0.814 | K22: =1-J22/I22 -> 0.14391823 | M22: =1-(1-K22)^(1/($J$19-$I$19)) -> 0.0053439247
B23: Refrigeration | C23: Electricity | D23: 0.039 | E23: 0.914 | F23: 0.97 | G23: 0.89 | I23: {=TREND(F23:G23,$F$18:$G$18,$I$19)} -> 0.9625 | J23: =G23 -> 0.89 | K23: =1-J23/I23 -> 0.075324675 | M23: =1-(1-K23)^(1/($J$19-$I$19)) -> 0.0026967917
B24: Machine drive | C24: Natural gas | D24: 0.013 | E24: 0.962 | F24: 0.962 | G24: 0.812 | I24: {=TREND(F24:G24,$F$18:$G$18,$I$19)} -> 0.9479375 | J24: =G24 -> 0.812 | K24: =1-J24/I24 -> 0.14340344 | M24: =1-(1-K24)^(1/($J$19-$I$19)) -> 0.005323306
B25: Machine drive | C25: Electricity | D25: 0.199 | E25: 0.919 | F25: 0.984 | G25: 0.899 | I25: {=TREND(F25:G25,$F$18:$G$18,$I$19)} -> 0.97603125 | J25: =G25 -> 0.899 | K25: =1-J25/I25 -> 0.078922934 | M25: =1-(1-K25)^(1/($J$19-$I$19)) -> 0.0028308672
B26: Electrochemical | C26: Electricity | D26: 0.001 | E26: 0.909 | F26: 0.971 | G26: 0.837 | I26: {=TREND(F26:G26,$F$18:$G$18,$I$19)} -> 0.9584375 | J26: =G26 -> 0.837 | K26: =1-J26/I26 -> 0.12670362 | M26: =1-(1-K26)^(1/($J$19-$I$19)) -> 0.0046608383
B27: processes Other | C27: Natural gas | D27: 0.011 | E27: 0.872 | F27: 0.946 | G27: 0.82 | I27: {=TREND(F27:G27,$F$18:$G$18,$I$19)} -> 0.9341875 | J27: =G27 -> 0.82 | K27: =1-J27/I27 -> 0.12223189 | M27: =1-(1-K27)^(1/($J$19-$I$19)) -> 0.0044855246
B28: Other | C28: Electricity | D28: 0.007 | E28: 0.911 | F28: 0.972 | G28: 0.891 | I28: {=TREND(F28:G28,$F$18:$G$18,$I$19)} -> 0.96440625 | J28: =G28 -> 0.891 | K28: =1-J28/I28 -> 0.076115486 | M28: =1-(1-K28)^(1/($J$19-$I$19)) -> 0.002726215

Sheet Machine Drive
H2: Table 3: Energy efficiency of the installed base compared to the Premium Efficiency performance
H3: level by horsepower range. Premium Efficiency levels
I4: Motor Size Bin | J4: Average Efficiency of Industrial Installed Base (%) | K4: Average Efficiency of Commercial Installed Base (%) | L4: Premium Efficiency Performance Level (%) | N4: advanced motor % improvement at full load (permanent magnet)
L5: (%)
I6: [1.0, 6.0) | J6: 83 | K6: 82 | L6: 86.4—90.1 | M6: 90.1 | N6: 3.2 | O6: =SUM(M6:N6) -> 93.3
I7: [6.0, 21.0) | J7: 89 | K7: 89 | L7: 89.2_93.1 | M7: 93.1 | N7: 1.5 | O7: =SUM(M7:N7) -> 94.6
I8: [21.0. 51.0) | J8: 92 | K8: 91 | L8: 92_94.7 | M8: 94.7 | N8: 1 | O8: =SUM(M8:N8) -> 95.7
I9: [51.0, 101.0) | J9: 93 | K9: 92 | L9: 94.1-95.9 | M9: 95.9 | N9: 1 | O9: =SUM(M9:N9) -> 96.9
I10: [101.0, 201.0) | J10: 93 | K10: 93 | L10: 94.5_96.2 | M10: 96.2 | N10: 0.7 | O10: =SUM(M10:N10) -> 96.9
I11: [201.0. 501.0) | J11: 93 | K11: 94 | L11: 94.5-96.2 | M11: 96.2 | N11: 0.8 | O11: =SUM(M11:N11) -> 97
I12: [501.0, 1,001.0) | J12: 93 | K12: 94 | M12: =M11 -> 96.2 | O12: =SUM(M12:N12) -> 96.2
I13: [1,001.0, 2,001.0) | J13: 92 | K13: 95 | M13: =M12 -> 96.2 | O13: =SUM(M13:N13) -> 96.2
I14: [2,001.0, 5,001.0) | J14: 86 | K14: 95 | M14: =M13 -> 96.2 | O14: =SUM(M14:N14) -> 96.2
I15: [5,001.0, ino | J15: 91 | K15: N/A | M15: =M14 -> 96.2 | O15: =SUM(M15:N15) -> 96.2
J17: Annual Electricity Consumption (TWh/yr)
I18: [1.0, 6.0) | J18: 25.980398 | L18: Implementation of variable frequency drives on variably underloaded motor systems
I19: [6.0, 21.0) | J19: 67.647064 | L19: 0.08
I20: [21.0. 51.0) | J20: 86.928108 | L20: reduction in motor drive efficiency due to low load inefficiency
I21: [51.0, 101.0) | J21: 71.895428
I22: [101.0, 201.0) | J22: 64.379086
I23: [201.0. 501.0) | J23: 94.281049
I24: [501.0, 1,001.0) | J24: 62.908498
I25: [1,001.0, 2,001.0) | J25: 34.803927
I26: [2,001.0, 5,001.0) | J26: 17.647053
I27: [5,001.0, ino | J27: 17.156857
J29: Industry-wide Efficiency | K29: Potential
J30: =SUMPRODUCT(J6:J15,J18:J27)/SUM(J18:J27)/100-L19 -> 0.83510069 | K30: =SUMPRODUCT(O6:O15,J18:J27)/SUM(J18:J27)/100 -> 0.96096573
J31: =1/J30 -> 1.1974604 | K31: =1/K30 -> 1.0406198
J34: Diesel generator / NG combustion turbine max efficiency
J35: 0.4 | K35: start year assumption
J36: =1/J35*'BAU Efficiency Improvements'!J24/'BAU Efficiency Improvements'!I24 -> 2.1414914 | K36: energy intensity (MIN)

Sheet Heat pumps
B24: COP: | C24: 3 | D24: Based on Arpagaus et al. curve, assuming a temperature lift of around 55 C (e.g., industries using waste heat as the heat source, boosting 45 C to 100 C or similar) | H24: Direct electric heating efficiency (200-1000 °C, resistance/induction)
B25: Energy intensity | C25: =1/C24 -> 0.33333333 | H25: 0.99
B26: COP: | C26: 5
B27: Energy intensity | C27: =1/C26 -> 0.2 | D27: Assumption
B30: Best COP (100-200 °C): | C30: 3
B31: Energy intensity | C31: =IFERROR(1/C30,"") -> 0.33333333

Sheet 1.2 heat_cool hp 80 C 75 K 
A1: Technology | C1: Combined heating and cooling heat pump, up to 80 °C, Temp lift = 75 K
A2: year | C2: 2025 | D2: 2030 | E2: 2035 | F2: 2040 | G2: 2050 | H2: 2025 | I2: 2025 | J2: 2050 | K2: 2050 | L2: Note | M2: Ref
A3: est | C3: ctrl | D3: ctrl | E3: ctrl | F3: ctrl | G3: ctrl | H3: lower | I3: upper | J3: lower | K3: upper | L3: - | M3: -
A4: cat | B4: par
A5: Energy/technical data
B6: Heat generation capacity for one unit [MW] | C6: 3 | D6: 3 | E6: 3 | F6: 3 | G6: 3 | H6: 0.5 | I6: 5 | J6: 0.5 | K6: 5 | L6: A | M6: [1, 2]
B7: Total efficiency, net [%], nominel load | C7: 3.35 | D7: 3.43 | E7: 3.48 | F7: =D7*1.02 -> 3.4986 | G7: =F7*1.01 -> 3.533586 | H7: 3.33 | I7: =C7*1.05 -> 3.5175 | J7: =G7*0.97 -> 3.4275784 | K7: =G7*1.02 -> 3.6042577 | L7: B | M7: [1, 3]
B8: Total efficiency, net [%], annual average | C8: =C7-5% -> 3.3 | D8: =D7-5% -> 3.38 | E8: =E7-5% -> 3.43 | F8: =F7-5% -> 3.4486 | G8: =G7-5% -> 3.483586 | H8: =H7-5% -> 3.28 | I8: =I7-5% -> 3.4675 | J8: =J7-5% -> 3.3775784 | K8: =K7-5% -> 3.5542577 | L8: B,C
B9: Auxiliary electricity consumption [% of heat gen] | C9: 0.01 | D9: 0.01 | E9: 0.01 | F9: 0.01 | G9: 0.01 | H9: 0.01 | I9: 0.04 | J9: 0.01 | K9: 0.04 | M9: 2
B10: Forced outage [%] | C10: 0 | D10: 0 | E10: 0 | F10: 0 | G10: 0 | H10: 0 | I10: 0.01 | J10: 0 | K10: 0.01 | L10: D | M10: 2
B11: Planned outage [weeks per year] | C11: 1 | D11: 1 | E11: 1 | F11: 1 | G11: 1 | H11: 0.5 | I11: 2 | J11: 0.5 | K11: 2 | M11: 2
B12: Technical lifetime [years] | C12: 25 | D12: 25 | E12: 25 | F12: 25 | G12: 25 | H12: 15 | I12: 40 | J12: 15 | K12: 40 | M12: 2
B13: Construction time [years] | C13: 0.5 | D13: 0.5 | E13: 0.5 | F13: 0.5 | G13: 0.5 | H13: 0.3 | I13: 1 | J13: 0.3 | K13: 1 | M13: 2
A14: Regulation Ability
B15: Minimum load [% of full load] | C15: 0.25 | D15: 0.25 | E15: 0.25 | F15: 0.25 | G15: 0.25 | H15: 0.1 | I15: 0.5 | J15: 0.1 | K15: 0.5 | M15: 2
B16: Warm start-up time [hours] | C16: 0.1 | D16: 0.1 | E16: 0.1 | F16: 0.1 | G16: 0.1 | H16: 0.1 | I16: 0.2 | J16: 0.1 | K16: 0.2 | M16: 2
B17: Cold start-up time [hours] | C17: 1 | D17: 1 | E17: 1 | F17: 1 | G17: 1 | H17: 0.2 | I17: 1 | J17: 0.2 | K17: 1 | M17: 2
A18: Financial data
B19: Nominal investment [M€/MW] | C19: 0.95 | D19: 0.94 | E19: 0.91 | F19: 0.91 | G19: 0.89 | H19: 0.91 | I19: 0.95 | J19: 0.88 | K19: 0.95 | M19: 2
B20: - of which equipment [%] | C20: 0.4 | D20: 0.4 | E20: 0.4 | F20: 0.4 | G20: 0.4 | L20: E | M20: 2
B21: - of which installation and other costs [%] | C21: 0.6 | D21: 0.6 | E21: 0.6 | F21: 0.6 | G21: 0.6 | L21: F | M21: 2
B22: Fixed O&M [€/MJ/s/year] | C22: 2127 | D22: 2095 | E22: 2032 | F22: 2032 | G22: 2001 | H22: 2032 | I22: 2127 | J22: 1970 | K22: 2127 | M22: 2
B23: Variable O&M [€/MWh] | C23: 3.07 | D23: 3.02 | E23: 2.93 | F23: 2.93 | G23: 2.89 | H23: 2.93 | I23: 3.07 | J23: 2.84 | K23: 3.07 | M23: 2
A24: Technology-specific data
B25: Indirect investments cost [M€/MW] | C25: =C19*0.2 -> 0.19 | D25: =D19*0.2 -> 0.188 | E25: =E19*0.2 -> 0.182 | F25: =F19*0.2 -> 0.182 | G25: =G19*0.2 -> 0.178 | L25: H
B26: Non energy gains [M€/MW] | C26: - | D26: - | E26: - | F26: - | G26: -
B27: Startup cost [€/MW/startup] | C27: 10 | D27: 10 | E27: 10 | F27: 10 | G27: 10
B28: Temperature heat source supply [°C] | C28: 15 | D28: 15 | E28: 15 | F28: 15 | G28: 15 | L28: I
B29: Temperature heat source return [°C] | C29: 5 | D29: 5 | E29: 5 | F29: 5 | G29: 5 | L29: I
B30: Cooling generation capacity for one unit [MW] | C30: =C6-C6/(C7/100) -> -86.552239 | D30: =D6-D6/(D7/100) -> -84.463557 | E30: =E6-E6/(E7/100) -> -83.206897 | F30: =F6-F6/(F7/100) -> -82.748585 | G30: =G6-G6/(G7/100) -> -81.899589
A33: Notes:
A34: A | B34: 0,5-5 MW
A35: B | B35: Estimated based on cases presented in [3]
A36: C | B36: Based on lost produktion during startup/shutdown
A37: D | B37: May vary depending on heat source availability
A38: E | B38: Very individual, can vary ÷ 20 %
A39: F | B39: Very individual, can vary + 20 %
A40: G | B40: Based on the old technology catalogue on process heat from 2020.
A41: H | B41: Going from current implementation to potential
A42: I | B42: Uses waste heat
...

Sheet 2.b High temp. hp Up to 150
A1: Technology | C1: High-temperature heat pumps up to 150 °C
A2: year | C2: 2025 | D2: 2030 | E2: 2035 | F2: 2040 | G2: 2050 | H2: 2025 | I2: 2025 | J2: 2050 | K2: 2050 | L2: Note | M2: Ref
A3: est | C3: ctrl | D3: ctrl | E3: ctrl | F3: ctrl | G3: ctrl | H3: lower | I3: upper | J3: lower | K3: upper | L3: - | M3: -
A4: cat | B4: par
A5: Energy/technical data
B6: Heat generation capacity for one unit [MW] | C6: 2 | D6: 2 | E6: 3 | F6: 3 | G6: 3 | H6: 0.5 | I6: 80 | J6: 0.5 | K6: 100 | L6: B | M6: 4
B7: Total efficiency, net [%], nominel load. Based on a temperature lift of 65 K | C7: 2.75 | D7: 2.85 | E7: 2.9 | F7: 2.95 | G7: 3 | H7: 2.25 | I7: 4 | J7: 2.5 | K7: 4.5 | L7: C, H | M7: 1
B8: Total efficiency, net [%], annual average | C8: 2.7 | D8: 2.8 | E8: 2.85 | F8: 2.9 | G8: 2.95 | H8: 2.2 | I8: 3.95 | J8: 2.45 | K8: 4.45
B9: Auxiliary electricity consumption [% of heat gen] | C9: 0.02 | D9: 0.02 | E9: 0.02 | F9: 0.02 | G9: 0.02 | H9: 0.01 | I9: 0.07 | J9: 0.01 | K9: 0.07 | M9: 1
B10: Forced outage [days] | C10: 0 | D10: 0 | E10: 0 | F10: 0 | G10: 0 | H10: 0 | I10: 1 | J10: 0 | K10: 1 | M10: 4
B11: Planned outage [weeks per year] | C11: 0.5 | D11: 0.5 | E11: 0.5 | F11: 0.5 | G11: 0.5 | H11: 0 | I11: 1 | J11: 0 | K11: 1 | M11: 4
B12: Technical lifetime [years] | C12: 20 | D12: 20 | E12: 20 | F12: 20 | G12: 20 | H12: 15 | I12: 30 | J12: 15 | K12: 30 | L12: D | M12: 4
B13: Construction time [years] | C13: 0.6 | D13: 0.5 | E13: 0.4 | F13: 0.4 | G13: 0.4 | H13: 0.4 | I13: 0.8 | J13: 0.2 | K13: 0.8 | L13: E | M13: 4
B14: Space requirement [1000 m2/MW_e] | C14: 0.03 | D14: 0.03 | E14: 0.03 | F14: 0.03 | G14: 0.03 | H14: 0.02 | I14: 0.06 | J14: 0.01 | K14: 0.05
A15: Regulation ability
B16: Primary regulation (of full load, per 30 seconds) [] | C16: 0.05 | D16: 0.07 | E16: 0.08 | F16: 0.09 | G16: 0.1 | H16: 0.02 | I16: 0.1 | J16: 0.05 | K16: 0.2
B17: Secondary regulation (of full load, per minute) [] | C17: 0.1 | D17: 0.14 | E17: 0.16 | F17: 0.18 | G17: 0.2 | H17: 0.04 | I17: 0.2 | J17: 0.1 | K17: 0.4
B18: Minimum load (of full load) [] | C18: 0.25 | D18: 0.25 | E18: 0.25 | F18: 0.25 | G18: 0.25 | H18: 0.1 | I18: 0.5 | J18: 0.1 | K18: 0.5 | L18: F | M18: 4
B19: Warm start-up time [hours] | C19: 0.25 | D19: 0.25 | E19: 0.25 | F19: 0.25 | G19: 0.25 | H19: 0.1 | I19: 0.5 | J19: 0.1 | K19: 0.25 | M19: 4
B20: Cold start-up time [hours] | C20: 1 | D20: 1 | E20: 1 | F20: 1 | G20: 1 | H20: 0.5 | I20: 1.5 | J20: 0.5 | K20: 1.5 | M20: 4
A21: Financial data
B22: Nominal investment (*total) [MEUR/MW] | C22: 1.55 | D22: 1.5 | E22: 1.45 | F22: 1.4 | G22: 1.35 | H22: 1.25 | I22: 1.8 | J22: 1.1 | K22: 1.65 | L22: G
B23: - of which equipment [%] | C23: 0.4 | D23: 0.4 | E23: 0.4 | F23: 0.4 | G23: 0.4 | H23: 0.25 | I23: 0.6 | J23: 0.25 | K23: 0.7 | L23: A | M23: 1
B24: - of which installation [%] | C24: 0.6 | D24: 0.6 | E24: 0.6 | F24: 0.6 | G24: 0.6 | H24: 0.4 | I24: 0.75 | J24: 0.3 | K24: 0.75 | L24: A | M24: 3
B25: Fixed O&M [EUR/MW_y], from last update in 2019 | C25: 2494 | D25: 2456 | E25: 2382 | F25: 2382 | G25: 2345 | M25: 2
B26: Variable O&M [EUR/MWh], from last update in 2019 | C26: 3.6 | D26: 3.54 | E26: 3.43 | F26: 3.43 | G26: 3.39 | M26: 1
A27: Technology-specific data
B28: Technology dependent
B29: Indirect investment cost [M€/MW] | C29: 0.23 | D29: 0.23 | E29: 0.23 | F29: 0.23 | G29: 0.23 | L29: I
B30: - Steam generation decreases COP [%-point] | C30: -0.15 | D30: -0.1 | E30: -0.05 | F30: -0.05 | G30: -0.05 | H30: -0.05 | I30: -0.2 | J30: -0.05 | K30: -0.15 | M30: [1, 4]
B31: - Steam generation increases equipment cost by [MEUR/MW] | C31: 0.2 | D31: 0.15 | E31: 0.1 | F31: 0.1 | G31: 0.1 | H31: 0.05 | I31: 0.3 | J31: 0.05 | K31: 0.2 | M31: [1, 4]
B32: - Additional equipment cost for temperature lift above 75 K [MEUR/MW] | C32: =MROUND(C22*C23*0.3,0.05) -> 0.2 | D32: =MROUND(D22*D23*0.3,0.05) -> 0.2 | E32: =MROUND(E22*E23*0.3,0.05) -> 0.15 | F32: =MROUND(F22*F23*0.3,0.05) -> 0.15 | G32: =MROUND(G22*G23*0.3,0.05) -> 0.15 | H32: =MROUND(H22*H23*0.3,0.05) -> 0.1 | I32: =MROUND(I22*I23*0.3,0.05) -> 0.3 | J32: =MROUND(J22*J23*0.3,0.05) -> 0.1 | K32: =MROUND(K22*K23*0.3,0.05) -> 0.35 | M32: [1, 4]
B33: - Total efficiency, net [%], nominel load. Based on a temperature lift of 40 K | C33: 4.45 | D33: 4.65 | E33: 4.7 | F33: 4.8 | G33: 4.9 | H33: 3.65 | I33: 6.5 | J33: 4.05 | K33: 7.3 | M33: [1, 4]
B34: - Total efficiency, net [%], nominel load. Based on a temperature lift of 80 K | C34: 2.4 | D34: 2.45 | E34: 2.5 | F34: 2.55 | G34: 2.6 | H34: 2 | I34: 3.4 | J34: 2.2 | K34: 3.8 | M34: [1, 4]
B35: - Total efficiency, net [%], nominel load. Based on a temperature lift of 100 K | C35: 2.05 | D35: 2.1 | E35: 2.15 | F35: 2.2 | G35: 2.2 | H35: 1.7 | I35: 2.85 | J35: 1.9 | K35: 3.2 | M35: [1, 4]
A38: Notes:
A39: A | B39: Depends on production infrastructure. If HTHP replaces another HTHP, there will be lower investment in new installation
A40: B | B40: Unit sizes vary a lot and depends on production infrastructure. Lower capacities for specific production processes and higher capacities for central hot water supply
A41: C | B41: Efficiency depends on temperature lift of HTHP. High temperature lift reduces COP.
A42: D | B42: Both depends on lifetime of parts and new technology with higher efficiencies leading to replacement of existing systems
...

Sheet Cooling
B2: Chiller
J3: Avg COP | K3: Avg Energy Intensity
I4: 0.7 | J4: =I10 -> 1.38 | K4: =1/J4 -> 0.72463768
I5: 0.74
I6: 0.79
I7: 1.42
I8: 1.42
I9: 1.35
I10: 1.38
B18: https://www.energy.gov/sites/prod/files/2017/06/f35/CHP-Absorption%20Chiller-compliant.pdf
B19: Example w/ efficiency of 0.48-0.55 kW/ton
I21: COP = 3.516/(kW/ton)
J23: positive | K23: kW/t | L23: COP | M23: Max COP | N23: Min Intensity
J24: <75 t | K24: 0.79 | L24: =3.516/K24 -> 4.4506329 | M24: =L31*(1+B37) -> 7.3860417 | N24: =1/M24 -> 0.13539052
J25: 75-150 | K25: 0.79 | L25: =3.516/K25 -> 4.4506329
J26: 150-300 | K26: 0.717 | L26: =3.516/K26 -> 4.9037657
J27: >300 | K27: 0.639 | L27: =3.516/K27 -> 5.5023474
J28: centrifugal
J29: <150 | K29: 0.703 | L29: =3.516/K29 -> 5.0014225
J30: 150-300 | K30: 0.634 | L30: =3.516/K30 -> 5.5457413
J31: 300-600 | K31: 0.576 | L31: =3.516/K31 -> 6.1041667
J32: >600t | K32: 0.576 | L32: =3.516/K32 -> 6.1041667
B34: "For example, ASHRAE computer simulations run during the development of Addendum m
B35: showed a 21 percent efficiency improvement in a large Miami office building cooled by a single
B36: 600-ton water-cooled centrifugal chiller with a VFD, compared to a constant-speed chiller."
B37: =0.21 -> 0.21

Sheet High Temp
A2: Electric Arc Furnaces
B3: standard EAF energy intensity: | E3: Avg: | G3: EAF thermal efficiency = theoretical min ÷ actual (no scrap preheat)
A4: http://heattreatconsortium.com/metals-advisor/electric-arc-furnace/electric-arc-furnace-energy-consumption/#:~:text=Energy%20consumption%20varies%20from%20350-700%20kWh/ton%20of,burners%20reduces%20electric%20consumption%20to%20425%20kWh/ton. | B4: 425 | C4: kWh/ton | E4: =AVERAGE(B4:B6) -> 421.66667 | G4: =E8/B6 -> 0.8425
A5: https://www.advancedenergy.com/en-us/about/news/blog/improving-scrap-steel-efficiency-with-arc-furnace-optimization-techniques/ | B5: 440 | C5: kWh/ton
A6: https://www.chnzbtech.com/news/electric-arc-furnace-in-steel-making.html | B6: 400 | C6: kWh/ton
B7: theoretical minimum
A8: https://usea.org/sites/default/files/012012_CO2%20abatement%20in%20the%20iron%20and%20steel%20industry_ccc193.pdf | B8: 361 | C8: kWh/ton | E8: =AVERAGE(B8:B10) -> 337
A9: https://usea.org/sites/default/files/012012_CO2%20abatement%20in%20the%20iron%20and%20steel%20industry_ccc193.pdf | B9: 350 | C9: kWh/ton
A10: https://www.advancedenergy.com/en-us/about/news/blog/improving-scrap-steel-efficiency-with-arc-furnace-optimization-techniques/ | B10: 300 | C10: kWh/ton
A12: Coal cement kilns
B13: kiln energy intensity (w/o waste heat capture)
A14: https://www.sciencedirect.com/science/article/abs/pii/S0196890414007596 | B14: 0.504 | G14: energy intensity
B15: kiln energy intensity (incl waste heat capture) | G15: =1/B16 -> 1.814882
A16: https://www.sciencedirect.com/science/article/abs/pii/S0196890414007596 | B16: 0.551
A18: Natural gas glass-melting furnace
B19: current energy intensity | G19: "thermal efficiency"
B20: 1100 | C20: kWh/tonne | G20: =B22/B22 -> 1
B21: practical minimum energy intensity | G21: energy intensity
B22: 793 | C22: kWh/tonne | G22: =1/G20 -> 1
A24: EAF >1000°C electricity factor — definition & scrap-preheat treatment
A25: Factor = 1 / efficiency (same convention as condensing boiler 1/99%). Efficiency = theoretical min energy (useful) ÷ actual standard EAF intensity. See G4/G7 above.
A27: Inputs (kWh/ton), from rows above:
A28: Actual standard EAF intensity (avg of B4:B6) | B28: =E4 -> 421.66667 | C28: kWh/ton
A29: Theoretical minimum, no scrap preheat (USEA CCC193) — USED | B29: =B8 -> 361 | C29: kWh/ton
A30: Scrap-preheat-optimized minimum (Advanced Energy) — not standard | B30: =B10 -> 300 | C30: kWh/ton
A32: (a) BASELINE — no scrap preheat (standard practice; feeds the model)
A33: factor = actual ÷ no-preheat theoretical min = 421.7 / 361
A34: =B28/B29 -> 1.1680517 | B34: =B28/B29 -> 1.1680517 | C34: = 421.7 / 361 → factor (≡ G7, LIVE)
A37: (b) IF scrap preheat were credited (NOT standard — shown for comparison only)
A38: factor = actual ÷ preheat-optimized min = 421.7 / 300 | B38: =B28/B30 -> 1.4055556 | C38: = 421.7 / 300 → factor (higher: bigger gap vs aspirational floor)

Sheet Electrochemical
B2: alkaline water electrolyzer efficiency
A3: https://www.energy.gov/eere/fuelcells/technical-targets-liquid-alkaline-electrolysis | B3: 0.61
B4: long-term target efficiency
A5: https://www.energy.gov/eere/fuelcells/technical-targets-liquid-alkaline-electrolysis | B5: 0.7
B7: alkaline water electrolyzer efficiency
A8: https://www.energy.gov/eere/fuelcells/technical-targets-proton-exchange-membrane-electrolysis | B8: 0.61
B9: long-term target efficiency
A10: https://www.energy.gov/eere/fuelcells/technical-targets-proton-exchange-membrane-electrolysis | B10: 0.72
A12: long-term average | B12: =AVERAGE(B10,B5) -> 0.71
A13: intensity | B13: =1/B12 -> 1.4084507

Sheet Lighting
A2: https://www.mordorintelligence.com/industry-reports/industrial-lighting-market
A3: Industrial lighting market
A4: LED | B4: 0.652
A5: Fluorescent | B5: 0.1365
A6: HID fixtures | B6: 0.2005
A7: OLED | B7: 0.011
A9: https://www.gelighting.com/inform/guide-energy-efficient-light-bulbs
A10: Bulb efficiencies
A11: LED | B11: 0.9
A12: Fluoresecent | B12: 0.85
A13: Incandescent | B13: 0.1
A14: HID | B14: 0.7 | C14: (assumption)
A16: Avg effic | B16: =B11*B4+B12*B5+B6*B14+B11*B7 -> 0.853075
A18: Max effic | B18: 0.93 | C18: assumption for LEDs
A19: min intensity | B19: =1/B18 -> 1.0752688
A21: Lighting is powered by electricity. To use other fuels one can use a generator
A22: We assume a 35% generator efficiency to start. Assume a 5% improvement for best possible.
A23: 0.4
A25: Avg efficiency | B25: =B18*A23 -> 0.372
A26: Avg intensity | B26: =1/B25 -> 2.688172

Sheet Other
A1: Ag tractors (mobile equipment)
A2: Present day efficiencies
A3: Diesel
A4: Tractor | B4: η | C4: energy intensity | D4: nom P [kW] | E4: nom w [rpm] | F4: reference | H4: ref 19 // open circles are added via post processing and represent the weighted
A5: unkn. | B5: 0.303 | C5: =1/B5 -> 3.30033 | D5: 58.8 | E5: 2500 | F5: 19 | H5: average load & engine speeds from ref 20 scaled by nominal engine speeds
A6: 4WD / MFWD | B6: =AVERAGE(0.35,0.305,0.266) -> 0.307 | C6: =1/B6 -> 3.257329 | D6: 245/127 | E6: 2100 | F6: 20
A8: Electric
A9: Tractor | B9: η | C9: energy intensity
A10: PM Electric Motor | B10: =AVERAGE(0.836,0.885,0.905) -> 0.87533333 | C10: =1/B10 -> 1.1424219 | D10: 150 (overload) | E10: 2600 | F10: 21
A11: charging adjusted | B11: =B10*(1-AVERAGE(0.1,0.15)) -> 0.76591667 | C11: =1/B11 -> 1.3056251 | F11: 22,25
A12: Custom autonomous | B12: =1/C12 -> 0.64890827 | C12: =AVERAGE(C5:C6)*(1-AVERAGE(0.52,0.54)) -> 1.5410499 | D12: 50 | F12: 23
A13: Simulated autonomous | B13: =1/C13 -> 0.72615925 | C13: =AVERAGE(C5:C6)*(1-AVERAGE(0.58)) -> 1.3771084 | F13: 24
A15: Reduction in fuel use
A16: Average | B16: =(AVERAGE(C5:C6)-AVERAGE(C11:C13))/AVERAGE(C5:C6) -> 0.57060049
A18: Historical Change in Tractor Energy Intensity
A19: Diesel
A20: Tractor | B20: linear coef. | C20: # generations | D20: yr/generation | E20: change/yr | H20: ref 21 // open circles are added via post processing and represent the weighted
A21: - | B21: =-0.041 -> -0.041 | C21: 7 | D21: =(2021-1989)/C21 -> 4.5714286 | E21: =B21/D21 -> -0.00896875 | H21: average load & engine speeds from ref 20 scaled by nominal engine speeds
A22: Electric
E23: =E21*'BAU Efficiency Improvements'!M25/'BAU Efficiency Improvements'!M24 -> -0.0047694686
A24: Assume minimum E factor is if historical efficiency gains continue through the model run
A25: For electricity, scale this efficiency improvement by the ratio of electricity to combustion improvements
A26: in the AEO baseline.
A35: Ref 20 | D35: (from figure)
A36: Tables 2-5 | B36: weighted values | D36: max t at speed | E36: load (fig 16) | F36: speed on fig 2 | G36: speed on fig 14 | H36: torque on fig 2 | I36: torque on fig 14 | J36: % of total field time | M36: weighted average torque % | P36: weighted average engine speed | S36: weighted-average torque | T36: weighted-average engine speed
A37: Field operation | B37: t (%) | C37: w (s^-1) | J37: TS-I | K37: TS-II | L37: TS-III | M37: TS-I | N37: TS-II | O37: TS-III | P37: TS-I | Q37: TS-II | R37: TS-III
A38: NH3 application | B38: =AVERAGE(S38:S39) -> 41.68 | C38: =AVERAGE(T38:T39) -> 1840.755 | D38: 213 | E38: 0.38 | F38: =C38*$E$5/$E$6*2*PI()/60 -> 229.48025 | G38: =C38*$E$10/$E$6 -> 2279.03 | H38: =E38*D38 -> 80.94 | I38: =150*E38 -> 57 | J38: 8 | K38: 22 | L38: 70 | M38: 8 | N38: 23 | O38: 52 | P38: 884 | Q38: 1711 | R38: 2009 | S38: =SUMPRODUCT(J38:L38,M38:O38)/SUM(J38:L38) -> 42.1 | T38: =SUMPRODUCT(P38:R38,J38:L38)/SUM(J38:L38) -> 1853.44
J39: 8 | K39: 21 | L39: 71 | M39: 9 | N39: 24 | O39: 50 | P39: 955 | Q39: 1718 | R39: 1959 | S39: =SUMPRODUCT(J39:L39,M39:O39)/SUM(J39:L39) -> 41.26 | T39: =SUMPRODUCT(P39:R39,J39:L39)/SUM(J39:L39) -> 1828.07
A40: Field cultivation | B40: =AVERAGE(S40:S42) -> 55.79 | C40: =AVERAGE(T40:T41) -> 1791.89 | D40: 215 | E40: 0.48 | F40: =C40*$E$5/$E$6*2*PI()/60 -> 223.38843 | G40: =C40*$E$10/$E$6 -> 2218.5305 | H40: =E40*D40 -> 103.2 | I40: =150*E40 -> 72 | J40: 4 | K40: 25 | L40: 71 | M40: 13 | N40: 33 | O40: 66 | P40: 1455 | Q40: 1568 | R40: 1767 | S40: =SUMPRODUCT(J40:L40,M40:O40)/SUM(J40:L40) -> 55.63 | T40: =SUMPRODUCT(P40:R40,J40:L40)/SUM(J40:L40) -> 1704.77
J41: 3 | K41: 27 | L41: 70 | M41: 13 | N41: 35 | O41: 68 | P41: 1543 | Q41: 1696 | R41: 1964 | S41: =SUMPRODUCT(J41:L41,M41:O41)/SUM(J41:L41) -> 57.44 | T41: =SUMPRODUCT(P41:R41,J41:L41)/SUM(J41:L41) -> 1879.01
J42: 3 | K42: 24 | L42: 73 | M42: 13 | N42: 33 | O42: 63 | P42: 905 | Q42: 1541 | R42: 1827 | S42: =SUMPRODUCT(J42:L42,M42:O42)/SUM(J42:L42) -> 54.3 | T42: =SUMPRODUCT(P42:R42,J42:L42)/SUM(J42:L42) -> 1730.7
A43: Corn planting | B43: =AVERAGE(S43:S45) -> 73.423333 | C43: =AVERAGE(T43:T44) -> 1395.97 | D43: 220 | E43: 0.59 | F43: =C43*$E$5/$E$6*2*PI()/60 -> 174.03052 | G43: =C43*$E$10/$E$6 -> 1728.3438 | H43: =E43*D43 -> 129.8 | I43: =150*E43 -> 88.5 | J43: 41 | K43: 59 | M43: 37 | N43: 76 | P43: 904 | Q43: 1514 | S43: =SUMPRODUCT(J43:L43,M43:O43)/SUM(J43:L43) -> 60.01 | T43: =SUMPRODUCT(P43:R43,J43:L43)/SUM(J43:L43) -> 1263.9
J44: 4 | K44: 96 | M44: 36 | N44: 81 | P44: 1433 | Q44: 1532 | S44: =SUMPRODUCT(J44:L44,M44:O44)/SUM(J44:L44) -> 79.2 | T44: =SUMPRODUCT(P44:R44,J44:L44)/SUM(J44:L44) -> 1528.04
J45: 2 | K45: 98 | M45: 35 | N45: 82 | P45: 1492 | Q45: 1545 | S45: =SUMPRODUCT(J45:L45,M45:O45)/SUM(J45:L45) -> 81.06 | T45: =SUMPRODUCT(P45:R45,J45:L45)/SUM(J45:L45) -> 1543.94

Sheet References
A1: Reference Number | B1: Author | C1: Year | D1: Document | E1: URL | F1: Page or Table
A2: 19 | B2: D. Friso | C2: 2014 | D2: Brake Thermal Efficiency and BSFC of Diesel Engines: Mathematical Modeling and Comparison between Diesel Oil and Biodiesel Fueling | E2: https://www.m-hikari.com/ams/ams-2014/ams-129-132-2014/frisoAMS129-132-2014-1.pdf
A3: 20 | B3: S. Pitla, J.D. Luck, J. Werner, N. Line, S.A. Shearer | C3: 2016 | D3: In-field fuel use and load states of agricultural field machinery | E3: https://www.sciencedirect.com/science/article/pii/S0168169916000041
A4: 21 | B4: D. Troncon, L. Alberti | C4: 2020 | D4: Case of Study of the Electrification of a Tractor: Electric Motor Performance Requirements and Design | E4: https://www.mdpi.com/1996-1073/13/9/2197
A5: 22 | B5: Z. Shao, S. Anup | C5: 2022 | D5: Incentives for electrifying agricultural tractors in India | E5: https://theicct.org/publication/india-hvs-evs-incentives-elec-tractors-india-oct22/
A6: 23 | B6: O. Lagnelov et al. | C6: 2021 | D6: Cost analysis of autonomous battery electric field tractors in agriculture | E6: https://pub.epsilon.slu.se/id/document/20368600
A7: 24 | B7: J. Engstrom and O. Lagnelov | C7: 2018 | D7: An Autonomous Electric Powered Tractor—Simulation of All Operations on a Swedish Dairy Farm | E7: https://www.davidpublisher.com/Public/uploads/Contribute/5ba1b8c2036b0.pdf
A8: 25 | B8: U.S. Department of Energy | C8: 2015 | D8: Where the Energy Goes: Electric Cars | E8: https://www.fueleconomy.gov/feg/atv-ev.shtml
A9: 26 | B9: I. Herranz-Matey, L. Ruiz-Garcia | C9: 2025 | D9: Agricultural tractor efficiency development as a sustainable model and evaluating the implementation of its automation operations: a case study | E9: https://www.tandfonline.com/doi/pdf/10.1080/14735903.2025.2546703
A10: 27 | B10: J.F. Schifo, J.F. Radia (Keramida / U.S. DOE ITP) | C10: 2004 | D10: Theoretical/Best Practice Energy Use in Metalcasting Operations | E10: https://www.energy.gov/sites/prod/files/2013/11/f4/doebestpractice_052804.pdf | F10: Table 19 (electric wet reverberatory 59-76%, avg 67.5%; gas reverberatory 36%); induction 36-65% delivered, modern batch 65%, power utilisation 44%→70%
A11: 28 | B11: U.S. Department of Energy | C11: 2015 | D11: Quadrennial Technology Review 2015, Ch. 6 TA 6I: Process Heating | E11: https://www.energy.gov/sites/prod/files/2016/06/f32/QTR2015-6I-Process-Heating.pdf | F11: Table 6.I.1 (sector process-heating losses 18-72%, all-mfg ~35%); electricity = 5% (325 TBtu) of process heating energy
A12: 29 | B12: K. Thirumaran, S. Nimbalkar, A. Thekdi, J. Cresko (ORNL / E3M / U.S. DOE) | C12: 2019 | D12: Energy Implications of Electrotechnologies in Industrial Process Heating Systems (ACEEE Summer Study on Energy Efficiency in Industry) | E12: https://energyefficiency.ornl.gov/wp-content/uploads/2020/07/0313_0466_000057.pdf | F12: p. 4-87: fuel-fired systems 30-60% overall vs electrotechnologies 60-80%, from 500+ DOE plant assessments
A13: 30 | B13: M. Kirschen, K. Badr, H. Pfeifer | C13: 2009 | D13: Energy efficiency and the influence of gas burners to the energy related carbon dioxide emissions of electric arc furnaces in steel industry (Energy) | E13: https://www.sciencedirect.com/science/article/abs/pii/S0360544209001285 | F13: Steel + slag enthalpies = 50-70% of EAF output; water cooling 10-20%; off-gas 15-35%. Upper bound (70%) used as best-practice delivered EAF efficiency
A14: 31 | B14: U.S. Department of Energy, Advanced Manufacturing Office | C14: 2012 | D14: Steam Tip Sheet #15: Benchmark the Fuel Cost of Steam Generation | E14: https://www.energy.gov/sites/prod/files/2014/05/f16/steam15_benchmark.pdf | F14: Table 2, HHV boiler combustion efficiency: natural gas 85.7%, distillate/No.2 oil 88.7%, residual/No.6 oil 89.6%, coal 90.3% (economizer or air preheater, 3% O2)
A15: 32 | B15: C. McMillan, R. Boardman, M. McKellar, P. Sabharwall, M. Ruth, S. Bragg-Sitton (NREL / INL) | C15: 2016 | D15: Generation and Use of Thermal Energy in the U.S. Industrial Sector and Opportunities to Reduce its Carbon Emissions (NREL/TP-6A50-66743; INL/EXT-16-39680) | E15: https://www.osti.gov/servlets/purl/1389190/ | F15: Steam boilers + CHP ≈ 70% of heat loads across 14 energy-intensive industries; chemicals ~40% via steam loops; pulp & paper ~70% steam — basis for the 55% boiler-served share
A16: 33 | B16: I.C. Kemp (in Modern Drying Technology, Wiley-VCH) / Thermal Processing Magazine | C16: 2008; 2018 | D16: Fundamentals of Energy Analysis of Dryers; Efficient Gas Heating of Industrial Furnaces | E16: https://application.wiley-vch.de/books/sample/3527315594_c01.pdf ; https://thermalprocessing.com/efficient-gas-heating-of-industrial-furnaces/ | F16: Direct-fired convective dryers >40% and better than steam-heated equivalents; gas recuperative burners 60-65% and self-recuperative 70-75% at 1000 °C — support for the oven/furnace containment factor
A17: 34 | B17: CDP (technical guidance); Clarke Energy | C17: 2023 | D17: CDP Climate Change Question-level Guidance (heating-value conversion); Heating Value (HHV vs LHV) | E17: https://guidance.cdp.net/en/guidance?cid=C8.2c ; https://www.clarke-energy.com/gas-engines/heating-value/ | F17: LHV/HHV ≈ 0.95 for solid and liquid hydrocarbon fuels, 0.90 for gaseous; NG HHV/LHV ≈ 1.108. Basis for the HHV-consistent furnace fuel-adjustment ratios (Combustion Efficiency D3:D5, E3:F5)

Sheet Combustion Efficiency
A1: Combustion Efficiency Without Waste Heat Recovery
A2: Low-Temp Data | B2: Efficiency | C2: Source | D2: Ratio Relative to Natural Gas | E2: LHV/HHV ratio | F2: Furnace-duty deduction
A3: Coal-fired boiler or furnace (<500 °C) | D3: =(E3/$E$5)*(1-F3) -> 1.0238889 | E3: 0.95 | F3: 0.03
A4: Petroleum-fired boiler or furnace (<500 °C) | D4: =(E4/$E$5)*(1-F4) -> 1.045 | E4: 0.95 | F4: 0.01
A5: Natural gas-fired boiler or furnace (<500 °C) | D5: =(E5/$E$5)*(1-F5) -> 1 | E5: 0.9 | F5: 0
A7: DOE Temperature vs. Efficiency Curve
A8: https://www.energy.gov/sites/prod/files/2016/04/f30/Improving%20Process%20Heating%20System%20Performance%20A%20Sourcebook%20for%20Industry%20Third%20Edition_0.pdf
A10: Condensing boiler efficiency (NG, <200 °C best-case) | B10: 0.99 | C10: Condensing boiler (latent heat recovery); recuperative burners not applicable <200 °C
A11: Best-case petroleum/oil boiler efficiency (<200 °C) | B11: 0.92 | C11: Condensing oil boiler (limited by sulfur/lower H2O vapor)
A12: Best-case coal boiler efficiency (<200 °C, economizer) | B12: 0.88 | C12: Coal boiler + economizer (no deep condensing — acid dewpoint/ash)
A35: We select a reference temperature to represent each temperature band in this study. We pick temperatures that line up with one of the
A36: 200-F increment lines in the DOE figure above and that are close to the center of each temperature band. (The temperature bands are
A37: defined in Celsius.)
A39: Then we choose the value on the 10% excess air curve from the DOE figure above. We use the 10% curve because
A40: DOE indicates: "Most high temperature direct-fired furnaces, radiant tubes, and boilers operate with about 10% to 20% excess combustion air at high fire to prevent the formation of dangerous carbon monoxide and soot deposits on heat transfer surfaces and inside radiant tubes."
A42: Temperature band from this study | B42: Reference temp. (F) | C42: Reference temp (C) | D42: Efficiency from DOE Curve | E42: Note
A43: <100 C | B43: 200 | C43: 93 | D43: 0.85 | E43: Extrapolated from DOE efficiency curve, which does not go lower than 300 F
A44: 100-200 C | B44: 300 | C44: 149 | D44: 0.83
A45: 200-500 C | B45: 600 | C45: 315 | D45: 0.75
A46: 500-1000 C | B46: 1400 | C46: 760 | D46: 0.57
A47: 1000-1800 C | B47: 2600 | C47: 1426 | D47: 0.23
A49: Fuel Type Adjustments
A50: Temperature band from this study | B50: Coal efficiency | C50: Petroleum efficiency | D50: NG efficiency
A51: <100 °C | B51: =D43*$D$3 -> 0.87030556 | C51: =D43*$D$4 -> 0.88825 | D51: =D43 -> 0.85
A52: 100-200 °C | B52: =D44*$D$3 -> 0.84982778 | C52: =D44*$D$4 -> 0.86735 | D52: =D44 -> 0.83
A53: 200-500 °C | B53: =D45*$D$3 -> 0.76791667 | C53: =D45*$D$4 -> 0.78375 | D53: =D45 -> 0.75
A54: 500-1000 °C | B54: =D46*$D$3 -> 0.58361667 | C54: =D46*$D$4 -> 0.59565 | D54: =D46 -> 0.57
A55: 1000-1800 °C | B55: =D47*$D$3 -> 0.23549444 | C55: =D47*$D$4 -> 0.24035 | D55: =D47 -> 0.23
A57: Combustion Efficiency With Waste Heat Recovery
A58: Efficiency Curve for Equipment with Waste Heat Recovery
A59: https://www.chinesestandard.net/PDF.aspx/GB24500-2020
A80: The ε = 0 curve roughly corresponds to the 10% excess air curve on the DOE graph above. On these curves, ε is the fraction of available waste heat
A81: recovered. The Mickey/Thermal Processing burner-efficiency curves distinguish burner-integral (UNIT-level) recovery from system-level recovery:
A82: • ε = 0.6 = Recuperative burners (burner-integral WHR — this file's baseline with-recovery class)
A83: • ε = 0.8 = Regenerative burners (burner-integral WHR — established practice for glass furnaces, steel stoves/reheat, other >500 °C furnaces)
A84: • ε = 0.4 = Central heat exchangers / fired-heater air preheaters = SYSTEM WHR — EXCLUDED from this unit-equipment file.
A85: We take the with-recovery efficiency from the ε = 0.6 and ε = 0.8 burner curves at each band's reference temperature (rounded to nearest 10).
A88: Temperature band from this study | B88: Reference temp. (°C) | C88: Eff. from ε = 0.6 curve (recuperative) | D88: Eff. from ε = 0.8 curve (regenerative)
A89: <100 °C | B89: 90 | C89: =INDEX('Mickey data'!D:D,MATCH('Combustion Efficiency'!B89,'Mickey data'!A:A,0)) -> 0.9743 | D89: =INDEX('Mickey data'!E:E,MATCH('Combustion Efficiency'!B89,'Mickey data'!A:A,0)) -> 0.9855
A90: 100-200 °C | B90: 150 | C90: =INDEX('Mickey data'!D:D,MATCH('Combustion Efficiency'!B90,'Mickey data'!A:A,0)) -> 0.961 | D90: =INDEX('Mickey data'!E:E,MATCH('Combustion Efficiency'!B90,'Mickey data'!A:A,0)) -> 0.976
...

Sheet Mickey data
A1: Temperature (°C) | B1: No Waste Heat Recovery | C1: Plug-in or Central Heat Exchanger | D1: Recuperative Burner | E1: Regenerative Burner | F1: Theoretical Maximum Efficiency | H1: Source:
A2: 0 | B2: 0.9995 | C2: 0.9946 | D2: 0.9942 | E2: 0.9997 | F2: 0.9995 | H2: Stephen R. Mickey
A3: 10 | B3: 0.9955 | C3: 0.9918 | D3: 0.992 | E3: 0.9981 | F3: 0.9987 | H3: 2017
A4: 20 | B4: 0.9914 | C4: 0.989 | D4: 0.9898 | E4: 0.9966 | F4: 0.9978 | H4: Efficient Gas Heating of Industrial Furnaces
A5: 30 | B5: 0.9873 | C5: 0.9862 | D5: 0.9876 | E5: 0.995 | F5: 0.997 | H5: https://thermalprocessing.com/efficient-gas-heating-of-industrial-furnaces/
A6: 40 | B6: 0.9833 | C6: 0.9834 | D6: 0.9854 | E6: 0.9934 | F6: 0.9962
A7: 50 | B7: 0.9792 | C7: 0.9806 | D7: 0.9832 | E7: 0.9918 | F7: 0.9953
A8: 60 | B8: 0.9751 | C8: 0.9778 | D8: 0.981 | E8: 0.9903 | F8: 0.9945
A9: 70 | B9: 0.9709 | C9: 0.9749 | D9: 0.9788 | E9: 0.9887 | F9: 0.9937
A10: 80 | B10: 0.9668 | C10: 0.9721 | D10: 0.9766 | E10: 0.9871 | F10: 0.9928
A11: 90 | B11: 0.9626 | C11: 0.9693 | D11: 0.9743 | E11: 0.9855 | F11: 0.992
A12: 100 | B12: 0.9584 | C12: 0.9664 | D12: 0.9721 | E12: 0.9839 | F12: 0.9911
A13: 110 | B13: 0.9542 | C13: 0.9636 | D13: 0.9699 | E13: 0.9824 | F13: 0.9903
A14: 120 | B14: 0.95 | C14: 0.9607 | D14: 0.9677 | E14: 0.9808 | F14: 0.9895
A15: 130 | B15: 0.9458 | C15: 0.9578 | D15: 0.9654 | E15: 0.9792 | F15: 0.9886
A16: 140 | B16: 0.9415 | C16: 0.955 | D16: 0.9632 | E16: 0.9776 | F16: 0.9878
A17: 150 | B17: 0.9373 | C17: 0.9521 | D17: 0.961 | E17: 0.976 | F17: 0.9869
... A152: 1500 | B152: 0.2124 | C152: 0.5057 | D152: 0.6354 | E152: 0.752 | F152: 0.8663

Sheet IEMUEF
A1: Unit: dimensionless | B1: <100 °C | C1: 100-200 °C | D1: 200-500 °C | E1: 500-1000 °C | F1: >1000 °C | G1: Cooling | H1: Machine Drive | I1: Other process | J1: Facility HVAC | K1: Facility lighting | L1: Other nonprocess
A2: electricity if | B2: ='Heat pumps'!C27 -> 0.2 | C2: ='Heat pumps'!C31 -> 0.33333333 | D2: ='Electric Process Heat'!C55 -> 1.1034178 | E2: ='Electric Process Heat'!C56 -> 1.345895 | F2: ='Electric Process Heat'!C57 -> 1.4285714 | G2: =Cooling!N24 -> 0.13539052 | H2: ='Machine Drive'!K31 -> 1.0406198 | I2: =Electrochemical!B13 -> 1.4084507 | J2: =B2 -> 0.2 | K2: =Lighting!B19 -> 1.0752688 | L2: =AVERAGE(Other!C11:C13)*(1+Other!E23)^(2050-2021) -> 1.2256526
A3: hard coal if | B3: =1/'Combustion Efficiency'!B105 -> 1.1363636 | C3: =1/'Combustion Efficiency'!B106 -> 1.1363636 | D3: =1/'Combustion Efficiency'!B107 -> 1.1461997 | E3: =1/'Combustion Efficiency'!B108 -> 1.1507053 | F3: =1/'Combustion Efficiency'!B109 -> 1.4447579 | G3: =Cooling!$K$4 -> 0.72463768 | H3: ='Machine Drive'!$J$36 -> 2.1414914 | I3: =I2 -> 1.4084507 | J3: =B3 -> 1.1363636 | K3: =Lighting!$B$26 -> 2.688172 | L3: =AVERAGE(Other!C5:C6)*(1+Other!E21)^(2050-2021) -> 2.5249452
A4: natural gas if | B4: =1/'Combustion Efficiency'!D105 -> 1.010101 | C4: =1/'Combustion Efficiency'!D106 -> 1.010101 | D4: =1/'Combustion Efficiency'!D107 -> 1.1918013 | E4: =1/'Combustion Efficiency'!D108 -> 1.1781944 | F4: =1/'Combustion Efficiency'!D109 -> 1.4653799 | G4: =Cooling!$K$4 -> 0.72463768 | H4: ='Machine Drive'!$J$36 -> 2.1414914 | I4: =I3 -> 1.4084507 | J4: =B4 -> 1.010101 | K4: =Lighting!$B$26 -> 2.688172 | L4: =$L$3 -> 2.5249452
A5: biomass if | B5: =1/'Combustion Efficiency'!B105 -> 1.1363636 | C5: =1/'Combustion Efficiency'!B106 -> 1.1363636 | D5: =1/'Combustion Efficiency'!B107 -> 1.1461997 | E5: =1/'Combustion Efficiency'!B108 -> 1.1507053 | F5: =1/'Combustion Efficiency'!B109 -> 1.4447579 | G5: =Cooling!$K$4 -> 0.72463768 | H5: ='Machine Drive'!$J$36 -> 2.1414914 | I5: =I4 -> 1.4084507 | J5: =B5 -> 1.1363636 | K5: =Lighting!$B$26 -> 2.688172 | L5: =$L$3 -> 2.5249452
A6: petroleum diesel if | B6: =1/'Combustion Efficiency'!C105 -> 1.0869565 | C6: =1/'Combustion Efficiency'!C106 -> 1.0869565 | D6: =1/'Combustion Efficiency'!C107 -> 1.1429077 | E6: =1/'Combustion Efficiency'!C108 -> 1.1274587 | F6: =1/'Combustion Efficiency'!C109 -> 1.4270109 | G6: =Cooling!$K$4 -> 0.72463768 | H6: ='Machine Drive'!$J$36 -> 2.1414914 | I6: =I5 -> 1.4084507 | J6: =B6 -> 1.0869565 | K6: =Lighting!$B$26 -> 2.688172 | L6: =$L$3 -> 2.5249452
A7: heat if | B7: 1.05 | C7: =$B$7 -> 1.05 | D7: =$B$7 -> 1.05 | E7: =$B$7 -> 1.05 | F7: =$B$7 -> 1.05 | G7: =Cooling!$K$4 -> 0.72463768 | H7: ='Machine Drive'!$J$36 -> 2.1414914 | I7: =I6 -> 1.4084507 | J7: =B7 -> 1.05 | K7: =Lighting!$B$26 -> 2.688172 | L7: =$L$3 -> 2.5249452
A8: crude oil if | B8: =1/'Combustion Efficiency'!C105 -> 1.0869565 | C8: =1/'Combustion Efficiency'!C106 -> 1.0869565 | D8: =1/'Combustion Efficiency'!C107 -> 1.1429077 | E8: =1/'Combustion Efficiency'!C108 -> 1.1274587 | F8: =1/'Combustion Efficiency'!C109 -> 1.4270109 | G8: =Cooling!$K$4 -> 0.72463768 | H8: ='Machine Drive'!$J$36 -> 2.1414914 | I8: =I7 -> 1.4084507 | J8: =B8 -> 1.0869565 | K8: =Lighting!$B$26 -> 2.688172 | L8: =$L$3 -> 2.5249452
A9: heavy or residual fuel oil if | B9: =1/'Combustion Efficiency'!C105 -> 1.0869565 | C9: =1/'Combustion Efficiency'!C106 -> 1.0869565 | D9: =1/'Combustion Efficiency'!C107 -> 1.1429077 | E9: =1/'Combustion Efficiency'!C108 -> 1.1274587 | F9: =1/'Combustion Efficiency'!C109 -> 1.4270109 | G9: =Cooling!$K$4 -> 0.72463768 | H9: ='Machine Drive'!$J$36 -> 2.1414914 | I9: =I8 -> 1.4084507 | J9: =B9 -> 1.0869565 | K9: =Lighting!$B$26 -> 2.688172 | L9: =$L$3 -> 2.5249452
A10: LPG propane or butane if | B10: =1/'Combustion Efficiency'!D105 -> 1.010101 | C10: =1/'Combustion Efficiency'!D106 -> 1.010101 | D10: =1/'Combustion Efficiency'!D107 -> 1.1918013 | E10: =1/'Combustion Efficiency'!D108 -> 1.1781944 | F10: =1/'Combustion Efficiency'!D109 -> 1.4653799 | G10: =Cooling!$K$4 -> 0.72463768 | H10: ='Machine Drive'!$J$36 -> 2.1414914 | I10: =I9 -> 1.4084507 | J10: =B10 -> 1.010101 | K10: =Lighting!$B$26 -> 2.688172 | L10: =$L$3 -> 2.5249452
A11: hydrogen if | B11: =1/'Combustion Efficiency'!D105 -> 1.010101 | C11: =1/'Combustion Efficiency'!D106 -> 1.010101 | D11: =1/'Combustion Efficiency'!D107 -> 1.1918013 | E11: =1/'Combustion Efficiency'!D108 -> 1.1781944 | F11: =1/'Combustion Efficiency'!D109 -> 1.4653799 | G11: =Cooling!$K$4 -> 0.72463768 | H11: ='Machine Drive'!$J$36 -> 2.1414914 | I11: =I10 -> 1.4084507 | J11: =B11 -> 1.010101 | K11: =Lighting!$B$26 -> 2.688172 | L11: =$L$3 -> 2.5249452
A14: VALIDATION — minimum unit energy factor must not exceed the start-year factor (July 2026 revision)
A15: Start-year values entered statically (red font) to avoid external workbook links. Re-enter if the start-year file is revised. Source: 'Start Year Indst Eqpt Unit E Factor by Indst Proc and Fuel.xlsx', sheet SYIEUEFbIPaF row 2 (electricity) and row 4 (natural gas).
A16: Row | B16: =B1 -> <100 °C | C16: =C1 -> 100-200 °C | D16: =D1 -> 200-500 °C | E16: =E1 -> 500-1000 °C | F16: =F1 -> >1000 °C
A17: Electricity — this file (min) | B17: =B2 -> 0.2 | C17: =C2 -> 0.33333333 | D17: =D2 -> 1.1034178 | E17: =E2 -> 1.345895 | F17: =F2 -> 1.4285714
A18: Electricity — start-year file | B18: 0.27 | C18: 0.448 | D18: 1.247 | E18: 1.512 | F18: 1.754
A19: Check (min ≤ start year) | B19: =IF(B17<=B18,"PASS","FAIL") -> PASS | C19: =IF(C17<=C18,"PASS","FAIL") -> PASS | D19: =IF(D17<=D18,"PASS","FAIL") -> PASS | E19: =IF(E17<=E18,"PASS","FAIL") -> PASS | F19: =IF(F17<=F18,"PASS","FAIL") -> PASS
A20: Headroom (start year ÷ min − 1) | B20: =B18/B17-1 -> 0.35 | C20: =C18/C17-1 -> 0.344 | D20: =D18/D17-1 -> 0.13012493 | E20: =E18/E17-1 -> 0.123416 | F20: =F18/F17-1 -> 0.2278
A21: Natural gas — this file (min) | B21: =B4 -> 1.010101 | C21: =C4 -> 1.010101 | D21: =D4 -> 1.1918013 | E21: =E4 -> 1.1781944 | F21: =F4 -> 1.4653799
A22: Natural gas — start-year file | B22: 1.1764706 | C22: 1.2048193 | D22: 1.3769694 | E22: 1.7299036 | F22: 2.0438738
A23: Check (min ≤ start year) | B23: =IF(B21<=B22,"PASS","FAIL") -> PASS | C23: =IF(C21<=C22,"PASS","FAIL") -> PASS | D23: =IF(D21<=D22,"PASS","FAIL") -> PASS | E23: =IF(E21<=E22,"PASS","FAIL") -> PASS | F23: =IF(F21<=F22,"PASS","FAIL") -> PASS
A24: Headroom (start year ÷ min − 1) | B24: =B22/B21-1 -> 0.16470588 | C24: =C22/C21-1 -> 0.19277108 | D24: =D22/D21-1 -> 0.15536823 | E24: =E22/E21-1 -> 0.46826673 | F24: =F22/F21-1 -> 0.39477403

Sheet Electric Process Heat
A1: Start-Year Delivered Efficiency of Electric Process Heating, 200–1000°C (U.S.)
A2: Replaces the flat 99% "direct electric heating" assumption ('Heat pumps'!H25) for the 200-500°C and 500-1000°C bands. 99% is an electrical-to-thermal CONVERSION efficiency at the heating element; the fossil comparators on the 'Combustion Efficiency' tab are DELIVERED efficiencies (useful heat / fuel in) that include stack and containment losses. This tab puts the electric side on the same system boundary as the fossil side.
A4: SECTION 1. Delivered efficiency by electric heating technology
A5: Technology | B5: Delivered efficiency | C5: Low | D5: High | E5: Applicable band / basis | F5: Source
A6: Electric boiler / immersion resistance (fluid & steam heating) | B6: 0.97 | C6: 0.95 | D6: 0.99 | E6: 200-500°C only. Steam raising, fluid heating, distillation reboil. | F6: Judgment, anchored on DOE Sourcebook 3rd ed. (2016)
A7: Resistance oven / dryer, convection-dominated (<~675°C) | B7: 0.8 | C7: 0.7 | D7: 0.88 | E7: 200-500°C. Drying, curing, baking, low-temp heat treating. | F7: Judgment, bracketed by rows 6 and 8
A8: Resistance furnace, indirect / radiant (~700°C) | B8: 0.675 | C8: 0.59 | D8: 0.76 | E8: 500-1000°C. Heat treating, reheating, annealing, non-ferrous melting. | F8: DOE BestPractices, Metalcasting Energy Use (2004), Table 19
A9: Induction heating & melting (modern batch) | B9: 0.65 | C9: 0.36 | D9: 0.7 | E9: Mainly 500-1000°C; some 200-500°C surface/billet heating. | F9: DOE BestPractices, Metalcasting Energy Use (2004)
A10: Electric infrared (medium wavelength) | B10: 0.6 | C10: 0.5 | D10: 0.9 | E10: Both bands. Curing, drying, paper/coating, surface heating. | F10: DOE/AMO Process Heating Sourcebook 3rd ed. (2016), Table 3
A12: SECTION 2. Share of start-year electric heat sales by technology, within each band
A13: No U.S. survey splits electric process heat by electrotechnology (MECS reports only "Net electricity" for process heating). These shares are judgment, informed by which industries dominate each band on the 'indst heat consumption' tab. They are the largest uncertainty on this tab — vary them in Section 4.
A14: Temperature band | B14: Boiler / immersion | C14: Resistance oven | D14: Resistance furnace | E14: Induction | F14: Infrared | G14: Sum (check)
A15: 200-500°C | B15: ='Combustion Efficiency'!B134 -> 0.55 | C15: =1-B15-D15-E15-F15 -> 0.3 | D15: 0 | E15: 0.05 | F15: 0.1 | G15: =SUM(B15:F15) -> 1
A16: 500-1000°C | B16: 0 | C16: 0 | D16: 0.55 | E16: 0.4 | F16: 0.05 | G16: =SUM(B16:F16) -> 1
A18: SECTION 3. Blended start-year efficiency and unit energy factor
A19: Temperature band | B19: Blended efficiency | C19: Unit energy factor (1/eff) | D19: Prior assumption (99%) | E19: Change in electricity per unit heat | F19: Natural gas comparator | G19: Electric saving vs. gas
A20: 200-500°C | B20: 0.80198 | C20: =1/B20 -> 1.2469139 | D20: =1/'Heat pumps'!$H$25 -> 1.010101 | E20: =C20/D20-1 -> 0.23444475 | F20: 1.3769694 | G20: =1-C20/F20 -> 0.094450542
A21: 500-1000°C | B21: 0.66125 | C21: =1/B21 -> 1.5122873 | D21: =1/'Heat pumps'!$H$25 -> 1.010101 | E21: =C21/D21-1 -> 0.49716446 | F21: 1.7299036 | G21: =1-C21/F21 -> 0.12579675
A23: SECTION 4. Cross-checks and sensitivity
A24: Sensitivity: blended efficiency using the low and high ends of the DOE-reported technology ranges (mix held constant)
A25: Temperature band | B25: Low case | C25: Central | D25: High case | E25: Implied loss, central
A26: 200-500°C | B26: 0.7378 | C26: =B20 -> 0.80198 | D26: 0.86816 | E26: =1-B20 -> 0.19802
A27: 500-1000°C | B27: 0.4935 | C27: =B21 -> 0.66125 | D27: 0.743 | E27: =1-B21 -> 0.33875
A29: Cross-check 1 — plausibility of the implied losses
A30: The central cases imply 16.1% (200-500°C) and 33.9% (500-1000°C) of delivered electricity lost before it reaches the product. DOE QTR 2015 Table 6.I.1 reports process-heating energy losses within sector of 18% (petroleum refining) to 72% (forest products), ~35% across all U.S. manufacturing. Both central cases sit inside that observed range; the prior 99% assumption (1% loss) sits far outside it.
A31: Source: DOE Quadrennial Technology Review 2015, TA 6I Industrial Process Heating Systems, Table 6.I.1
A33: Cross-check 2 — RESOLVED (T6, see 'Combustion Efficiency' rows 142-149): is the fossil side too generous vs DOE field evidence (fuel-fired 30-60%, Ref 37; gas reverb 36% vs electric reverb 67.5%, Ref 35)?
A34: Finding: band-weighting QTR 2015 Table 6.I.1 sector losses (Ref 36) by this file's own band shares gives delivered-eff benchmarks of ~59.5% (200-500), ~70.7% (500-1000), ~56.5% (>1000). The 500-1000 and >1000 fossil blends (61.4%, 48.0%) sit BELOW their benchmarks — already conservative — because those bands are dominated by refinery/chemical fired heaters (QTR losses 18-23%) and WHR-heavy steel/cement, not the metals-niche furnaces behind the 30-60% field range. Only 200-500 got a trim: containment 0.97 on the direct-fired slice (NG 78.7% → 74.6%). The paired metalcasting comparison (1.9x) remains valid for foundry-type duty specifically — it is a minority share of every band.
A36: Cross-check 3 — RESOLVED (T3): the >1000 °C band previously used 'High Temp'!G4 (76.6%), a theoretical-minimum-to-actual ratio — not comparable to the delivered-energy basis used for 200-1000 °C, and it implied >1000 °C electric heat was MORE efficient than 500-1000 °C. Replaced by the delivered EAF efficiency in Section 6 below (rows 47-50); output cell SYIEUEFbIPaF!F2 repointed. 'High Temp'!G7 retained but superseded.
A37: High Temp'!G4 sets the >1000°C electric efficiency at 76.6%, computed as the ratio of theoretical-minimum to typical EAF intensity. That is a 'distance from best practice' metric, not a delivered-energy efficiency, so it is not on the same basis as this tab or as the combustion tab. Taken at face value it makes >1000°C electric heat more efficient than 500-1000°C electric heat, which is backwards. Recommend re-deriving the >1000°C value on a delivered-energy basis. Separately, the comment on 'Heat pumps'!H25 cites ~71% for EAF while 'High Temp'!G4 computes 76.6% — these should be reconciled.
A39: SECTION 5. Maximum-efficiency (end-state) case
A40: The original 99% belongs here, not in the start year. It is the electrical-to-thermal conversion ceiling: what a best-available, well-insulated, fully heat-recovered electric system approaches. Keeping it as the start-year value leaves zero improvement headroom, so equipment-efficiency policy in the EPS can only improve fossil equipment — which biases the model toward the fossil pathway.
A41: Max-efficiency conversion ceiling, 200-1000°C | B41: ='Heat pumps'!H25 -> 0.99 | C41: Feed this to the 'Efficiency Improvements' file as the end-state target, not the start year.
A42: Implied improvement headroom, 200-500°C | B42: =B41/B20-1 -> 0.23444475
A43: Implied improvement headroom, 500-1000°C | B43: =B41/B21-1 -> 0.49716446
A45: Housekeeping: 'Heat pumps'!H25 (99%) is retained only as the max-efficiency ceiling (Section 5). Sources for this tab are in References (refs 26, 35-41) and summarized on the About tab (2026 revision blocks). Remaining open item: cross-check 2 (A33) — fossil furnace efficiencies at top of DOE field-assessed range.
A47: Section 6 — >1000 °C: EAF delivered efficiency (T3; replaces the theoretical-minimum ratio method)
A48: EAF useful-heat efficiency (liquid-steel enthalpy ÷ total electrical + chemical input) | B48: 0.57 | C48: 0.5 | D48: 0.65
A49: Unit energy factor, >1000 °C (= 1 / B48) | B49: =1/B48 -> 1.754386
A50: Note: on this basis electric >1000 °C (57%) sits below 500-1000 °C (66%), as physics suggests — the old method had it backwards. Savings vs NG at >1000 °C become ~16% (1.754 vs 2.082) rather than ~37%. Headroom to the 99% ceiling: ~42%.
...

Sheet indst heat consumption
D2: Temperature mapping | I2: Share of all energy for heat at various temp bands
B3: Industry Category | C3: Share of all industry boiler/nonboiler heat | D3: < 100°C | E3: 100-200°C | F3: 200-500°C | G3: 500-1000°C | H3: > 1000°C | I3: < 100°C | J3: 100-200°C | K3: 200-500°C | L3: 500-1000°C | M3: > 1000°C | N3: QTR PH loss share (Ref 36)
B4: agriculture and forestry 01T03 | C4: 0.041094089 | D4: 1 | E4: 0 | F4: 0 | G4: 0 | H4: 0 | I4: =$C4*D4/SUMPRODUCT($C$4:$C$28,D$4:D$28) -> 0.18630249 | J4: =$C4*E4/SUMPRODUCT($C$4:$C$28,E$4:E$28) -> 0 | K4: =$C4*F4/SUMPRODUCT($C$4:$C$28,F$4:F$28) -> 0 | L4: =$C4*G4/SUMPRODUCT($C$4:$C$28,G$4:G$28) -> 0 | M4: =$C4*H4/SUMPRODUCT($C$4:$C$28,H$4:H$28) -> 0 | N4: 0.39
B5: coal mining 05 | C5: 0 | D5: 1 | E5: 0 | F5: 0 | G5: 0 | H5: 0 | I5: =$C5*D5/SUMPRODUCT($C$4:$C$28,D$4:D$28) -> 0 | J5: =$C5*E5/SUMPRODUCT($C$4:$C$28,E$4:E$28) -> 0 | K5: =$C5*F5/SUMPRODUCT($C$4:$C$28,F$4:F$28) -> 0 | L5: =$C5*G5/SUMPRODUCT($C$4:$C$28,G$4:G$28) -> 0 | M5: =$C5*H5/SUMPRODUCT($C$4:$C$28,H$4:H$28) -> 0 | N5: 0.39
B6: oil and gas extraction 06 | C6: 0.040805825 | D6: 0.076923077 | E6: 0.25213675 | F6: 0.53205128 | G6: 0.13888889 | H6: 0 | I6: =$C6*D6/SUMPRODUCT($C$4:$C$28,D$4:D$28) -> 0.014230433 | J6: =$C6*E6/SUMPRODUCT($C$4:$C$28,E$4:E$28) -> 0.054733821 | K6: =$C6*F6/SUMPRODUCT($C$4:$C$28,F$4:F$28) -> 0.05537122 | L6: =$C6*G6/SUMPRODUCT($C$4:$C$28,G$4:G$28) -> 0.07021543 | M6: =$C6*H6/SUMPRODUCT($C$4:$C$28,H$4:H$28) -> 0 | N6: 0.18
B7: other mining and quarrying 07T08 | C7: 0.023082653 | D7: 1 | E7: 0 | F7: 0 | G7: 0 | H7: 0 | I7: =$C7*D7/SUMPRODUCT($C$4:$C$28,D$4:D$28) -> 0.10464658 | J7: =$C7*E7/SUMPRODUCT($C$4:$C$28,E$4:E$28) -> 0 | K7: =$C7*F7/SUMPRODUCT($C$4:$C$28,F$4:F$28) -> 0 | L7: =$C7*G7/SUMPRODUCT($C$4:$C$28,G$4:G$28) -> 0 | M7: =$C7*H7/SUMPRODUCT($C$4:$C$28,H$4:H$28) -> 0 | N7: 0.39
B8: food beverage and tobacco 10T12 | C8: 0.097591785 | D8: 0.23333333 | E8: 0.25555556 | F8: 0.51111111 | G8: 0 | H8: 0 | I8: =$C8*D8/SUMPRODUCT($C$4:$C$28,D$4:D$28) -> 0.10323557 | J8: =$C8*E8/SUMPRODUCT($C$4:$C$28,E$4:E$28) -> 0.13267712 | K8: =$C8*F8/SUMPRODUCT($C$4:$C$28,F$4:F$28) -> 0.12721462 | L8: =$C8*G8/SUMPRODUCT($C$4:$C$28,G$4:G$28) -> 0 | M8: =$C8*H8/SUMPRODUCT($C$4:$C$28,H$4:H$28) -> 0 | N8: 0.56
B9: textiles apparel and leather 13T15 | C9: 0.0032056866 | D9: 0.47272727 | E9: 0.17575758 | F9: 0.35151515 | G9: 0 | H9: 0 | I9: =$C9*D9/SUMPRODUCT($C$4:$C$28,D$4:D$28) -> 0.0068702259 | J9: =$C9*E9/SUMPRODUCT($C$4:$C$28,E$4:E$28) -> 0.0029973162 | K9: =$C9*F9/SUMPRODUCT($C$4:$C$28,F$4:F$28) -> 0.0028739125 | L9: =$C9*G9/SUMPRODUCT($C$4:$C$28,G$4:G$28) -> 0 | M9: =$C9*H9/SUMPRODUCT($C$4:$C$28,H$4:H$28) -> 0 | N9: 0.56
B10: wood products 16 | C10: 0.05850378 | D10: 0.11764706 | E10: 0.29411765 | F10: 0.58823529 | G10: 0 | H10: 0 | I10: =$C10*D10/SUMPRODUCT($C$4:$C$28,D$4:D$28) -> 0.031203571 | J10: =$C10*E10/SUMPRODUCT($C$4:$C$28,E$4:E$28) -> 0.091538218 | K10: =$C10*F10/SUMPRODUCT($C$4:$C$28,F$4:F$28) -> 0.087769462 | L10: =$C10*G10/SUMPRODUCT($C$4:$C$28,G$4:G$28) -> 0 | M10: =$C10*H10/SUMPRODUCT($C$4:$C$28,H$4:H$28) -> 0 | N10: 0.72
B11: pulp paper and printing 17T18 | C11: 0.17093362 | D11: 0.34666667 | E11: 0.20444444 | F11: 0.41555556 | G11: 0.033333333 | H11: 0 | I11: =$C11*D11/SUMPRODUCT($C$4:$C$28,D$4:D$28) -> 0.26864507 | J11: =$C11*E11/SUMPRODUCT($C$4:$C$28,E$4:E$28) -> 0.18590893 | K11: =$C11*F11/SUMPRODUCT($C$4:$C$28,F$4:F$28) -> 0.18116113 | L11: =$C11*G11/SUMPRODUCT($C$4:$C$28,G$4:G$28) -> 0.070590966 | M11: =$C11*H11/SUMPRODUCT($C$4:$C$28,H$4:H$28) -> 0 | N11: 0.72
B12: refined petroleum and coke 19 | C12: 0.10696308 | D12: 0.076923077 | E12: 0.25213675 | F12: 0.53205128 | G12: 0.13888889 | H12: 0 | I12: =$C12*D12/SUMPRODUCT($C$4:$C$28,D$4:D$28) -> 0.037301803 | J12: =$C12*E12/SUMPRODUCT($C$4:$C$28,E$4:E$28) -> 0.14347211 | K12: =$C12*F12/SUMPRODUCT($C$4:$C$28,F$4:F$28) -> 0.1451429 | L12: =$C12*G12/SUMPRODUCT($C$4:$C$28,G$4:G$28) -> 0.18405358 | M12: =$C12*H12/SUMPRODUCT($C$4:$C$28,H$4:H$28) -> 0 | N12: 0.18
