Workbook
Name billion: About!$A$95
Name CH4GWP: #REF!
Name Eno_TM: '[1]1997 Table 1a Modified'!#REF!
Name Eno_TM: #REF!
Name Eno_TM: '[2]1997 Table 1a Modified'!#REF!
Name Eno_TM: '[2]1997 Table 1a Modified'!#REF!
Name Eno_TM: '[2]1997 Table 1a Modified'!#REF!
Name Eno_Tons: '[1]1997 Table 1a Modified'!#REF!
Name Eno_Tons: #REF!
Name Eno_Tons: '[2]1997 Table 1a Modified'!#REF!
Name Eno_Tons: '[2]1997 Table 1a Modified'!#REF!
Name Eno_Tons: '[2]1997 Table 1a Modified'!#REF!
Name EPS_data: #REF!
Name EPS_dates: #REF!
Name EPS_varnames: #REF!
Name GWPCH4: #REF!
Name GWPN2O: #REF!
Name N2OGWP: #REF!
Name NTS_YR: [3]About!$B$136
Name Sum_T2: '[1]1997 Table 1a Modified'!#REF!
Name Sum_T2: #REF!
Name Sum_T2: '[2]1997 Table 1a Modified'!#REF!
Name Sum_T2: '[2]1997 Table 1a Modified'!#REF!
Name Sum_T2: '[2]1997 Table 1a Modified'!#REF!
Name Sum_TTM: '[1]1997 Table 1a Modified'!#REF!
Name Sum_TTM: #REF!
Name Sum_TTM: '[2]1997 Table 1a Modified'!#REF!
Name Sum_TTM: '[2]1997 Table 1a Modified'!#REF!
Name Sum_TTM: '[2]1997 Table 1a Modified'!#REF!
Name ti_tbl_50: #REF!
Name ti_tbl_50: #REF!
Name ti_tbl_50: #REF!
Name ti_tbl_69: #REF!
Name ti_tbl_69: #REF!
Name ti_tbl_69: #REF!
Name TitleRegion1.f2.y3.5: #REF!
Name TitleRegion1.f3.n4.5: #REF!
Name TitleRegion2.e6.y15.5: #REF!
Name TitleRegion2.e8.n17.5: #REF!
Name TitleRegion3.c19.y51.5: #REF!
Name TitleRegion3.c24.n53.5: #REF!
Name TitleRegion4.e54.y63.5: #REF!
Name TitleRegion4.e57.n66.5: #REF!
Name TitleRegion5.d68.y124.5: #REF!
Name TitleRegion5.d73.n129.5: #REF!
Name trillion: About!$A$96

Sheet About
A1: SYFAFE Start Year Fleet Avg Fuel Economy
A3: Sources: | B3: See Notes section for which vehicle types use which sources
B4: EIA
B5: 2023, 2025, 2026
B6: Annual Energy Outlook 2023, 2025, 2026
B7: https://www.eia.gov/outlooks/aeo/tables_ref.cfm
B8: Tables 7, 25, 36, 37, 38, 40, 41, 43, 46, 47, 48, 49
B10: Bureau of Transportation Statistics
B11: 2018
B12: National Transportation Statistics
B13: https://www.bts.gov/content/us-passenger-miles
B14: Table 1-40
B16: U.S. Coast Guard
B17: 2013
B18: National Recreational Boating Survey 2012
B19: http://www.uscgboating.org/library/recreational-boating-servey/2012survey%20report.pdf
B20: Page 63, Table 40
B22: U.S. Department of Energy
B23: 2015
B24: Fuel Cells Fact Sheet
B25: https://www.energy.gov/sites/prod/files/2015/11/f27/fcto_fuel_cells_fact_sheet.pdf
B27: US EPA
B28: Inventory of U.S. Greenhouse Gas Emissions and Sinks: 1990-2021 and Annex
B29: 2023
B30: https://www.epa.gov/ghgemissions/inventory-us-greenhouse-gas-emissions-and-sinks-1990-2021
B32: Rail-passenger data
B33: National Transit Database Tables
B34: American Public Transportation Association
B35: 2020
B36: https://www.apta.com/research-technical-resources/transit-statistics/ntd-data-tables/
B40: Others as noted on "Calculations Etc" tab
A42: Notes
A43: This variable gives fleet-wide fuel economy in units of cargo distance per BTU.
A45: passenger LDVs, freight LDVs and HDVs
A46: Sources: AEO 37, 41, 43, 36, 49
A47: Vehicle distance traveled and energy consumption by vehicle technology is available for passenger LDVs, commercial light trucks and HDVs.
A48: We sum vehicle distance traveled by technology, divide by energy consumption of that technology, and multiply by the vehicle loading values used in the
A49: EPS to convert from miles/BTU to thing-miles/BTU. The AEO shows 0 energy consumption by battery electric and plug-in hybrid commercial freight
A50: trucks in 2019. Therefore, we use 2020 data for those two technologies.
A52: freight rail
...

Sheet source data>

Sheet EPA_Table 3-13
A1: Table 3-13: CO2 Emissions from Fossil Fuel Combustion in Transportation End-Use Sector (MMT CO2 Eq.)
A3: Fuel/Vehicle Type | B3: 2020 | C3: 2021
A4: Gasolinea | B4: 937 | C4: 1029
A5: Passenger Cars | B5: 328 | C5: 361
A6: Light-Duty Trucks | B6: 566 | C6: 620
A7: Medium- and Heavy-Duty Trucksb | B7: 24 | C7: 27
A8: Buses | B8: 3 | C8: 3
A9: Motorcycles | B9: 7 | C9: 7
A10: Recreational Boatsc | B10: 10 | C10: 11
A11: Distillate Fuel Oil (Diesel)a | B11: 455 | C11: 488
A12: Passenger Cars | B12: 3 | C12: 3
A13: Light-Duty Trucks | B13: 30 | C13: 33
A14: Medium- and Heavy-Duty Trucksb | B14: 353 | C14: 380
... A50: Biofuels-Biodieselh | B50: 17.7 | C50: 16.1
A51: + Does not exceed 0.05 MMT CO2 Eq.
A52: a On-road fuel consumption data from FHWA Table MF-21 and MF-27 were used to determine total on-road use of motor gasoline and diesel fuel (FHWA 1996 through 2023). Ratios developed from MOVES3 output are used to apportion FHWA fuel consumption data to vehicle type and fuel type (see Annex 3.2 for information about the MOVES model).
A53: b Includes medium- and heavy-duty trucks over 8,500 lbs.
A54: c In 2014, EPA incorporated the NONROAD2008 model into the MOVES model framework. The current Inventory uses the Nonroad component of MOVES3 for years 1999 through 2021. See Annex 3.2 for information about the MOVES model.
A55: d Note that large year over year fluctuations in emission estimates partially reflect nature of data collection for these sources.
A56: e Official estimates exclude emissions from the combustion of both aviation and marine international bunker fuels; however, estimates of international bunker fuel-related emissions are presented for informational purposes.
A57: f Commercial aircraft, as modeled in FAA’s Aviation Environmental Design Tool (AEDT), consists of passenger aircraft, cargo, and other chartered flights.
A58: g Pipelines reflect CO2 emissions from natural gas-powered pipelines transporting natural gas.
A59: h Ethanol and biodiesel estimates are presented for informational purposes only. See Section 3.10 of this chapter and the estimates in Land Use, Land-Use Change, and Forestry (see Chapter 6), in line with IPCC methodological guidance and UNFCCC reporting obligations, for more information on ethanol and biodiesel.
A60: i Transportation sector natural gas and LPG consumption are based on data from EIA (2021b). Prior to the 1990 to 2015 Inventory, data from DOE TEDB were used to estimate each vehicle class’s share of the total natural gas and LPG consumption. Since TEDB does not include estimates for natural gas use by medium and heavy-duty trucks or LPG use by passenger cars, EIA Alternative Fuel Vehicle Data (Browning 2017) is now used to determine each vehicle class’s share of the total natural gas and LPG consumption. These changes were first incorporated in the 1990 to 2016 Inventory and apply to the 1990 to 2021 time period.
A61: j Includes emissions from rail electricity.
A62: k Electricity consumption by passenger cars, light-duty trucks (SUVs), and buses is based on plug-in electric vehicle sales and engine efficiency data, as outlined in Browning (2018a). In prior Inventory years, CO2 emissions from electric vehicle charging were allocated to the residential and commercial sectors. They are now allocated to the transportation sector. These changes apply to the 2010 through 2021 time period.
A63: Notes: This table does not include emissions from non-transportation mobile sources, such as agricultural equipment and construction/mining equipment; it also does not include emissions associated with electricity consumption by pipelines or lubricants used in transportation. In addition, this table does not include CO2 emissions from U.S. Territories, since these are covered in a separate chapter of the Inventory. Totals may not sum due to independent rounding.

Sheet AVLo-passengers
A1: Vehicle Loading (passengers) | B1: 2015 | C1: 2016
A2: LDVs | B2: 1.67 | C2: 1.67
A3: HDVs | B3: 21.196137 | C3: 21.196137
A4: aircraft | B4: 111.39416 | C4: 111.39416
A5: rail | B5: 486.56732 | C5: 486.56732
A6: ships | B6: 1 | C6: 1
A7: motorbikes | B7: 1.2700757 | C7: 1.2700757

Sheet AVLo-freight
A1: Vehicle Loading (tons) | B1: 2016 | C1: 2017
A2: LDVs | B2: 1 | C2: 1
A3: HDVs | B3: 16 | C3: 16
A4: aircraft | B4: 41.989116 | C4: 41.989116
A5: rail | B5: 3512.3592 | C5: 3512.3592
A6: ships | B6: 1974.4736 | C6: 1974.4736
A7: motorbikes | B7: 0 | C7: 0

Sheet PEI-TFPEI-HDVs
A1: Pollutant Emissions Intensity (g pollutant/BTU) | B1: electricity | C1: natural gas | D1: petroleum gasoline | E1: petroleum diesel | F1: biofuel gasoline | G1: biofuel diesel | H1: jet fuel | I1: heavy or residual fuel oil | J1: LPG propane or butane | K1: hydrogen
A2: CO2 | B2: 0 | C2: 0.052751938 | D2: 0.072920704 | E2: 0.074215992 | F2: 0 | G2: 0 | H2: 0 | I2: 0 | J2: 0.067030065 | K2: 0
A3: VOC | B3: 0 | C3: 2.0116527e-05 | D3: 4.9544716e-05 | E3: 1.7127887e-05 | F3: 4.9544716e-05 | G3: 1.7127887e-05 | H3: 0 | I3: 0 | J3: 1.8676185e-05 | K3: 0
A4: CO | B4: 0 | C4: 0.0011140698 | D4: 0.0010281419 | E4: 7.8217123e-05 | F4: 0.0010281419 | G4: 7.8217123e-05 | H4: 0 | I4: 0 | J4: 3.2062705e-05 | K4: 0
A5: NOx | B5: 0 | C5: 6.3097541e-05 | D5: 0.00010277642 | E5: 0.00024072356 | F5: 0.00010277642 | G5: 0.00024072356 | H5: 0 | I5: 0 | J5: 0.000157038 | K5: 0
A6: PM10 | B6: 0 | C6: 5.6883776e-06 | D6: 6.1477987e-06 | E6: 1.5480764e-05 | F6: 6.1477987e-06 | G6: 1.5480764e-05 | H6: 0 | I6: 0 | J6: 5.2810902e-07 | K6: 0
A7: PM25 | B7: 0 | C7: 2.7736291e-06 | D7: 2.2736172e-06 | E7: 9.8509839e-06 | F7: 2.2736172e-06 | G7: 9.8509839e-06 | H7: 0 | I7: 0 | J7: 2.5750375e-07 | K7: 0
A8: SOx | B8: 0 | C8: 0 | D8: 7.7296864e-07 | E8: 6.6613125e-07 | F8: 7.7296864e-07 | G8: 6.6613125e-07 | H8: 0 | I8: 0 | J8: 0 | K8: 0
A9: BC | B9: 0 | C9: 2.2005086e-07 | D9: 3.5502594e-07 | E9: 4.9362701e-06 | F9: 3.5502594e-07 | G9: 4.9362701e-06 | H9: 0 | I9: 0 | J9: 2.0429523e-08 | K9: 0
A10: OC | B10: 0 | C10: 3.9999294e-07 | D10: 1.0010432e-06 | E10: 2.6892846e-06 | F10: 1.0010432e-06 | G10: 2.6892846e-06 | H10: 0 | I10: 0 | J10: 3.7135347e-08 | K10: 0
A11: CH4 | B11: 0 | C11: 1e-06 | D11: 3e-06 | E11: 3e-06 | F11: 0 | G11: 0 | H11: 0 | I11: 0 | J11: 3e-06 | K11: 0
A12: N2O | B12: 0 | C12: 1e-07 | D12: 6e-07 | E12: 6e-07 | F12: 0 | G12: 0 | H12: 0 | I12: 0 | J12: 6e-07 | K12: 0
A13: F gases | B13: 0 | C13: 0 | D13: 0 | E13: 0 | F13: 0 | G13: 0 | H13: 0 | I13: 0 | J13: 0 | K13: 0

Sheet AEO 2023 7
B1: ref2023.d020623a | C1: 2022 | D1: 2023 | E1: 2024 | F1: 2025 | G1: 2026 | H1: 2027 | I1: 2028 | J1: 2029 | K1: 2030 | L1: 2031 | M1: 2032 | N1: 2033 | O1: 2034 | P1: 2035 | Q1: 2036 | R1: 2037 | S1: 2038 | T1: 2039 | U1: 2040 | V1: 2041 | W1: 2042 | X1: 2043 | Y1: 2044 | Z1: 2045 | AA1: 2046 | AB1: 2047 | AC1: 2048 | AD1: 2049 | AE1: 2050
C3: Report | D3: Annual Energy Outlook 2023
C4: Scenario | D4: ref2023 | G4: Reference
C5: Datekey | D5: d020623a
C6: Release Date | E6: March 2023
A10: TKI000 | B10: 7. Transportation Sector Key Indicators and Delivered Energy Consumption | AF10: Average
AF11: Annual
AF12: Change
B13: Key Indicators and Consumption | C13: 2022 | D13: 2023 | E13: 2024 | F13: 2025 | G13: 2026 | H13: 2027 | I13: 2028 | J13: 2029 | K13: 2030 | L13: 2031 | M13: 2032 | N13: 2033 | O13: 2034 | P13: 2035 | Q13: 2036 | R13: 2037 | S13: 2038 | T13: 2039 | U13: 2040 | V13: 2041 | W13: 2042 | X13: 2043 | Y13: 2044 | Z13: 2045 | AA13: 2046 | AB13: 2047 | AC13: 2048 | AD13: 2049 | AE13: 2050 | AF13: 2022–2050
B15: Key Indicators
B16: Travel Indicators
B17: (billion vehicle miles traveled)
A18: TKI000:ba_Light-DutyVeh | B18: Light-Duty Vehicles less than 8,501 pounds | C18: 2843.2981 | D18: 2901.3589 | E18: 2922.5066 | F18: 2933.3601 | G18: 2954.238 | H18: 2981.9343 | I18: 3007.5581 | J18: 3027.573 | K18: 3042.8433 | L18: 3055.7747 | M18: 3066.6516 | N18: 3082.3594 | O18: 3102.4182 | P18: 3120.7375 | Q18: 3135.6208 | R18: 3152.9177 | S18: 3172.4355 | T18: 3192.1006 | U18: 3214.563 | V18: 3237.5806 | W18: 3261.5847 | X18: 3284.8975 | Y18: 3309.0391 | Z18: 3334.7034 | AA18: 3364.5225 | AB18: 3396.5352 | AC18: 3429.5627 | AD18: 3463.0249 | AE18: 3499.543 | AF18: 0.007444
A19: TKI000:ba_CommercialLig | B19: Commercial Light Trucks 1/ | C19: 102.21495 | D19: 103.34346 | E19: 103.55378 | F19: 104.36999 | G19: 105.65627 | H19: 107.00255 | I19: 108.20406 | J19: 109.32984 | K19: 110.21457 | L19: 111.0637 | M19: 112.17591 | N19: 113.26731 | O19: 114.36133 | P19: 115.53986 | Q19: 116.6934 | R19: 117.93478 | S19: 119.26325 | T19: 120.51714 | U19: 121.9657 | V19: 123.54321 | W19: 125.05544 | X19: 126.4902 | Y19: 127.8319 | Z19: 129.14803 | AA19: 130.64792 | AB19: 132.25534 | AC19: 133.71924 | AD19: 135.16911 | AE19: 137.06503 | AF19: 0.010533
A20: TKI000:ba_FreightTrucks | B20: Freight Trucks greater than 10,000 pounds | C20: 321.95499 | D20: 320.72061 | E20: 321.15665 | F20: 324.03918 | G20: 328.45148 | H20: 332.31928 | I20: 335.87875 | J20: 338.621 | K20: 341.15326 | L20: 344.16229 | M20: 348.16583 | N20: 351.54123 | O20: 354.83011 | P20: 358.3447 | Q20: 361.39355 | R20: 364.92679 | S20: 368.38065 | T20: 371.81143 | U20: 375.58807 | V20: 379.58752 | W20: 383.51465 | X20: 387.20883 | Y20: 390.63339 | Z20: 393.83795 | AA20: 397.54263 | AB20: 401.35467 | AC20: 404.65982 | AD20: 408.22446 | AE20: 413.08252 | AF20: 0.008941
B21: (billion passenger miles traveled)
A22: TKI000:buspassmiles | B22: Bus Transportation | C22: 175.47365 | D22: 186.88329 | E22: 193.3692 | F22: 197.39229 | G22: 200.32752 | H22: 202.52968 | I22: 204.21141 | J22: 205.46838 | K22: 206.39357 | L22: 207.0294 | M22: 207.54085 | N22: 207.99565 | O22: 208.43976 | P22: 208.79684 | Q22: 209.10339 | R22: 209.37013 | S22: 209.49379 | T22: 209.54416 | U22: 209.54358 | V22: 209.49118 | W22: 209.41185 | X22: 209.25844 | Y22: 209.10913 | Z22: 208.93102 | AA22: 208.81189 | AB22: 208.60612 | AC22: 208.41769 | AD22: 208.19235 | AE22: 207.99593 | AF22: 0.006091
A23: TKI000:railpassmiles | B23: Passenger Rail | C23: 30.144947 | D23: 32.030231 | E23: 33.06411 | F23: 33.706196 | G23: 34.620327 | H23: 35.443916 | I23: 36.137474 | J23: 36.650322 | K23: 37.00806 | L23: 37.264553 | M23: 37.633518 | N23: 38.06789 | O23: 38.564194 | P23: 38.985653 | Q23: 39.398945 | R23: 39.809189 | S23: 40.237045 | T23: 40.652229 | U23: 41.127975 | V23: 41.567631 | W23: 42.019573 | X23: 42.40731 | Y23: 42.842342 | Z23: 43.266335 | AA23: 43.867863 | AB23: 44.361511 | AC23: 44.905075 | AD23: 45.395485 | AE23: 46.002594 | AF23: 0.01521
B24: (billion seat miles available)
A25: TKI000:ba_Air | B25: Air | C25: 1173.0347 | D25: 1318.6946 | E25: 1361.6111 | F25: 1371.6552 | G25: 1402.928 | H25: 1433.8398 | I25: 1461.4722 | J25: 1484.8291 | K25: 1504.2688 | L25: 1524.7269 | M25: 1552.2568 | N25: 1583.9248 | O25: 1615.3802 | P25: 1647.3462 | Q25: 1682.5896 | R25: 1721.0469 | S25: 1761.139 | T25: 1801.941 | U25: 1848.072 | V25: 1894.2041 | W25: 1941.463 | X25: 1990.3643 | Y25: 2038.4374 | Z25: 2085.6875 | AA25: 2134.0049 | AB25: 2185.897 | AC25: 2238.8362 | AD25: 2292.3555 | AE25: 2350.269 | AF25: 0.02513
B26: (billion ton miles traveled)
A27: TKI000:ba_Rail | B27: Rail | C27: 1620.4949 | D27: 1600.1008 | E27: 1666.9198 | F27: 1628.4084 | G27: 1561.4207 | H27: 1509.6494 | I27: 1489.7312 | J27: 1507.5151 | K27: 1500.1649 | L27: 1506.9524 | M27: 1522.1982 | N27: 1534.7394 | O27: 1543.2374 | P27: 1554.5907 | Q27: 1557.5254 | R27: 1562.4816 | S27: 1568.9661 | T27: 1568.3395 | U27: 1571.7775 | V27: 1585.6112 | W27: 1597.307 | X27: 1600.1909 | Y27: 1601.8328 | Z27: 1602.9988 | AA27: 1608.1294 | AB27: 1618.0824 | AC27: 1630.808 | AD27: 1636.8905 | AE27: 1649.4695 | AF27: 0.000633
A28: TKI000:ba_DomesticShipp | B28: Domestic Shipping | C28: 444.89887 | D28: 450.42761 | E28: 448.61005 | F28: 446.74628 | G28: 445.22772 | H28: 442.84778 | I28: 440.43005 | J28: 437.0246 | K28: 434.03641 | L28: 431.39212 | M28: 429.99737 | N28: 428.16068 | O28: 426.27862 | P28: 424.17816 | Q28: 421.71698 | R28: 419.81464 | S28: 417.56705 | T28: 415.80768 | U28: 414.04514 | V28: 412.52209 | W28: 411.24774 | X28: 409.97736 | Y28: 408.52225 | Z28: 406.63034 | AA28: 405.35852 | AB28: 403.86591 | AC28: 401.97906 | AD28: 400.55664 | AE28: 400.09833 | AF28: -0.003783
B30: Energy Efficiency Indicators
B31: (miles per gallon)
A32: TKI000:ca_AvgCAFEStand | B32: New Light-Duty Vehicle CAFE Standard 2/ | C32: 35.855949 | D32: 36.277985 | E32: 39.337013 | F32: 42.578201 | G32: 47.262627 | H32: 47.227249 | I32: 47.18121 | J32: 47.168774 | K32: 47.163849 | L32: 47.152081 | M32: 47.159279 | N32: 47.152672 | O32: 47.146118 | P32: 47.131687 | Q32: 47.138325 | R32: 47.119869 | S32: 47.100937 | T32: 47.084251 | U32: 47.059879 | V32: 47.032314 | W32: 47.004074 | X32: 46.960155 | Y32: 46.939564 | Z32: 46.91069 | AA32: 46.948238 | AB32: 46.913113 | AC32: 46.90683 | AD32: 46.880138 | AE32: 46.870857 | AF32: 0.009613
A33: TKI000:ca_CarCAFEStand | B33: New Car 2/ | C33: 45.004654 | D33: 45.471119 | E33: 49.460312 | F33: 53.789036 | G33: 59.791531 | H33: 59.80352 | I33: 59.817413 | J33: 59.819332 | K33: 59.821598 | L33: 59.822445 | M33: 59.827473 | N33: 59.828793 | O33: 59.83078 | P33: 59.83112 | Q33: 59.842136 | R33: 59.842136 | S33: 59.842136 | T33: 59.843197 | U33: 59.843197 | V33: 59.843231 | W33: 59.845177 | X33: 59.845177 | Y33: 59.848228 | Z33: 59.848228 | AA33: 59.867775 | AB33: 59.867775 | AC33: 59.867775 | AD33: 59.867775 | AE33: 59.867775 | AF33: 0.010244
A34: TKI000:ca_TwukCAFEStand | B34: New Light Truck 2/ | C34: 32.047302 | D34: 32.608868 | E34: 35.403008 | F34: 38.46349 | G34: 42.755749 | H34: 42.75658 | I34: 42.76173 | J34: 42.76173 | K34: 42.761841 | L34: 42.762085 | M34: 42.762169 | N34: 42.76236 | O34: 42.76239 | P34: 42.76252 | Q34: 42.762554 | R34: 42.762699 | S34: 42.762756 | T34: 42.762825 | U34: 42.762897 | V34: 42.762962 | W34: 42.763016 | X34: 42.763103 | Y34: 42.763103 | Z34: 42.763184 | AA34: 42.763184 | AB34: 42.763294 | AC34: 42.763294 | AD34: 42.763393 | AE34: 42.763393 | AF34: 0.010356
A35: TKI000:ca_NewVehCred | B35: Compliance New Light-Duty Vehicle 3/ | C35: 41.802036 | D35: 43.2672 | E35: 44.448151 | F35: 47.052715 | G35: 48.571758 | H35: 49.79253 | I35: 52.281479 | J35: 53.248959 | K35: 53.962006 | L35: 54.332035 | M35: 54.872646 | N35: 55.329353 | O35: 55.771633 | P35: 56.242725 | Q35: 56.632603 | R35: 56.856194 | S35: 57.030457 | T35: 57.310715 | U35: 57.240421 | V35: 57.306023 | W35: 57.371868 | X35: 57.326744 | Y35: 57.237999 | Z35: 57.125122 | AA35: 57.475964 | AB35: 57.327747 | AC35: 57.273457 | AD35: 57.524818 | AE35: 57.479156 | AF35: 0.011439
A36: TKI000:ca_NewCarCred | B36: New Car 3/ | C36: 56.582645 | D36: 58.322227 | E36: 59.783314 | F36: 64.222374 | G36: 65.997482 | H36: 68.148636 | I36: 72.759445 | J36: 74.876167 | K36: 76.446304 | L36: 77.157303 | M36: 78.145363 | N36: 78.735664 | O36: 79.269257 | P36: 79.864815 | Q36: 80.311752 | R36: 80.510567 | S36: 80.643074 | T36: 81.042244 | U36: 80.790894 | V36: 80.999863 | W36: 81.213394 | X36: 81.251564 | Y36: 81.126785 | Z36: 80.963654 | AA36: 81.962257 | AB36: 81.685669 | AC36: 81.57402 | AD36: 82.338425 | AE36: 82.243484 | AF36: 0.013446
A37: TKI000:ca_NewTwukCred | B37: New Light Truck 3/ | C37: 36.263931 | D37: 37.832123 | E37: 39.014805 | F37: 41.375153 | G37: 42.876762 | H37: 43.911583 | I37: 45.953789 | J37: 46.678478 | K37: 47.207012 | L37: 47.518375 | M37: 47.939487 | N37: 48.362621 | O37: 48.779861 | P37: 49.233047 | Q37: 49.585567 | R37: 49.838345 | S37: 50.048077 | T37: 50.325745 | U37: 50.338009 | V37: 50.426777 | W37: 50.517311 | X37: 50.542614 | Y37: 50.50412 | Z37: 50.459385 | AA37: 50.61805 | AB37: 50.565735 | AC37: 50.535652 | AD37: 50.739391 | AE37: 50.721836 | AF37: 0.012055
A38: TKI000:ca_TestedNewVeh | B38: Tested New Light-Duty Vehicle 4/ | C38: 37.621078 | D38: 38.382416 | E38: 39.075672 | F38: 40.794502 | G38: 41.684994 | H38: 42.387779 | I38: 43.992405 | J38: 44.482399 | K38: 44.828846 | L38: 45.012852 | M38: 45.295109 | N38: 45.54966 | O38: 45.800465 | P38: 46.072914 | Q38: 46.308186 | R38: 46.454895 | S38: 46.573441 | T38: 46.763412 | U38: 46.743324 | V38: 46.781216 | W38: 46.812752 | X38: 46.781078 | Y38: 46.720787 | Z38: 46.649311 | AA38: 46.812588 | AB38: 46.721981 | AC38: 46.686661 | AD38: 46.844208 | AE38: 46.809135 | AF38: 0.007835
A39: TKI000:ca_TestedNewCar | B39: New Car 4/ | C39: 49.658657 | D39: 50.63982 | E39: 51.418789 | F39: 54.041267 | G39: 54.808311 | H39: 55.812794 | I39: 58.414131 | J39: 59.295654 | K39: 59.885937 | L39: 60.128426 | M39: 60.482559 | N39: 60.696911 | O39: 60.896141 | P39: 61.139969 | Q39: 61.34211 | R39: 61.456459 | S39: 61.54549 | T39: 61.791069 | U39: 61.720493 | V39: 61.820892 | W39: 61.909645 | X39: 61.923454 | Y39: 61.848679 | Z39: 61.762375 | AA39: 62.120819 | AB39: 61.989952 | AC39: 61.932671 | AD39: 62.331699 | AE39: 62.272804 | AF39: 0.008117
A40: TKI000:ca_TestedNewTwuk | B40: New Light Truck 4/ | C40: 32.951321 | D40: 33.82571 | E40: 34.570251 | F40: 36.235542 | G40: 37.203815 | H40: 37.859802 | I40: 39.251301 | J40: 39.65464 | K40: 39.942871 | L40: 40.123779 | M40: 40.372108 | N40: 40.635685 | O40: 40.898228 | P40: 41.187042 | Q40: 41.415565 | R40: 41.589336 | S40: 41.735809 | T40: 41.930031 | U40: 41.954327 | V40: 42.014381 | W40: 42.070942 | X40: 42.089371 | Y40: 42.062252 | Z40: 42.034523 | AA40: 42.106945 | AB40: 42.074627 | AC40: 42.053329 | AD40: 42.192116 | AE40: 42.17543 | AF40: 0.008853
A41: TKI000:ca_OnRoadNewVeh | B41: On-Road New Light-Duty Vehicle 5/ | C41: 30.687853 | D41: 31.308468 | E41: 31.873775 | F41: 33.275242 | G41: 34.001518 | H41: 34.574638 | I41: 35.883228 | J41: 36.28281 | K41: 36.56535 | L41: 36.715401 | M41: 36.945652 | N41: 37.153278 | O41: 37.357868 | P41: 37.580082 | Q41: 37.772026 | R41: 37.891651 | S41: 37.988308 | T41: 38.143211 | U41: 38.126759 | V41: 38.157574 | W41: 38.183201 | X41: 38.157219 | Y41: 38.107975 | Z41: 38.049587 | AA41: 38.182838 | AB41: 38.108822 | AC41: 38.080002 | AD41: 38.208389 | AE41: 38.179749 | AF41: 0.007832
A42: TKI000:ca_OnRoadNewCar | B42: New Car 5/ | C42: 40.552002 | D42: 41.353237 | E42: 41.989353 | F42: 44.130909 | G42: 44.75729 | H42: 45.577564 | I42: 47.701855 | J42: 48.421719 | K42: 48.903755 | L42: 49.101772 | M42: 49.390965 | N42: 49.566006 | O42: 49.728703 | P42: 49.927814 | Q42: 50.092888 | R42: 50.186264 | S42: 50.258968 | T42: 50.459515 | U42: 50.401878 | V42: 50.483868 | W42: 50.556343 | X42: 50.567619 | Y42: 50.506557 | Z42: 50.436081 | AA42: 50.72879 | AB42: 50.621925 | AC42: 50.575146 | AD42: 50.901001 | AE42: 50.852905 | AF42: 0.008117
A43: TKI000:ca_OnRoadNewTwuk | B43: New Light Truck 5/ | C43: 26.867123 | D43: 27.580063 | E43: 28.18713 | F43: 29.544939 | G43: 30.334429 | H43: 30.869291 | I43: 32.00386 | J43: 32.332729 | K43: 32.567738 | L43: 32.715244 | M43: 32.917721 | N43: 33.132629 | O43: 33.346695 | P43: 33.582184 | Q43: 33.768513 | R43: 33.910198 | S43: 34.029625 | T43: 34.187984 | U43: 34.207794 | V43: 34.25676 | W43: 34.302879 | X43: 34.317905 | Y43: 34.295792 | Z43: 34.273186 | AA43: 34.332233 | AB43: 34.305882 | AC43: 34.288517 | AD43: 34.40168 | AE43: 34.388073 | AF43: 0.008853
... A47: TKI000:ca_FreightTruck | B47: Freight Truck | C47: 7.472406 | D47: 7.578529 | E47: 7.705323 | F47: 7.84859 | G47: 8.002383 | H47: 8.163677 | I47: 8.321285 | J47: 8.479755 | K47: 8.638294 | L47: 8.79593 | M47: 8.948549 | N47: 9.090997 | O47: 9.222516 | P47: 9.343068 | Q47: 9.453315 | R47: 9.553063 | S47: 9.643444 | T47: 9.72671 | U47: 9.804593 | V47: 9.877275 | W47: 9.942431 | X47: 10.001567 | Y47: 10.055841 | Z47: 10.108454 | AA47: 10.161228 | AB47: 10.213311 | AC47: 10.263764 | AD47: 10.314513 | AE47: 10.365861 | AF47: 0.011758
B48: (seat miles per gallon)
A49: TKI000:ca_Aircraft | B49: Aircraft | C49: 72.717087 | D49: 73.091972 | E49: 73.492531 | F49: 74.018456 | G49: 74.683121 | H49: 75.131767 | I49: 75.59214 | J49: 76.024017 | K49: 76.492363 | L49: 77.014214 | M49: 77.60096 | N49: 78.266678 | O49: 78.981506 | P49: 79.730591 | Q49: 80.48922 | R49: 81.260979 | S49: 82.048454 | T49: 82.814575 | U49: 83.594772 | V49: 84.382309 | W49: 85.171204 | X49: 85.974022 | Y49: 86.764038 | Z49: 87.549927 | AA49: 88.321091 | AB49: 89.091156 | AC49: 89.849762 | AD49: 90.593376 | AE49: 91.328148 | AF49: 0.008172
...

Sheet AEO 2023 35
E1: 2021 | F1: 2022 | G1: 2023 | H1: 2024 | I1: 2025 | J1: 2026 | K1: 2027 | L1: 2028 | M1: 2029 | N1: 2030 | O1: 2031 | P1: 2032 | Q1: 2033 | R1: 2034 | S1: 2035 | T1: 2036 | U1: 2037 | V1: 2038 | W1: 2039 | X1: 2040 | Y1: 2041 | Z1: 2042 | AA1: 2043 | AB1: 2044 | AC1: 2045 | AD1: 2046 | AE1: 2047 | AF1: 2048 | AG1: 2049 | AH1: 2050 | AI1: Growth (2022-2050)
A10: Table 35. Transportation Sector Energy Use by Mode and Type
A11: https://www.eia.gov/outlooks/aeo/data/browser/#/?id=45-AEO2023&cases=ref2023&sourcekey=0
A12: Thu Dec 11 2025 13:26:03 GMT-0800 (Pacific Standard Time)
A13: Source: U.S. Energy Information Administration
B14: full name | C14: api key | D14: units | E14: 2021 | F14: 2022 | G14: 2023 | H14: 2024 | I14: 2025 | J14: 2026 | K14: 2027 | L14: 2028 | M14: 2029 | N14: 2030 | O14: 2031 | P14: 2032 | Q14: 2033 | R14: 2034 | S14: 2035 | T14: 2036 | U14: 2037 | V14: 2038 | W14: 2039 | X14: 2040 | Y14: 2041 | Z14: 2042 | AA14: 2043 | AB14: 2044 | AC14: 2045 | AD14: 2046 | AE14: 2047 | AF14: 2048 | AG14: 2049 | AH14: 2050 | AI14: Growth (2022-2050)
A15: Energy Use by Mode
A16: Highway
A17: Light-Duty Vehicles | B17: Transportation Energy Use: Highway: Light-Duty Vehicles: Reference case | C17: AEO.2023.REF2023.CNSM_NA_TRN_HWY_LDV_NA_NA_TRLBTU.A | D17: trillion Btu | F17: 14541.974 | G17: 14586.115 | H17: 14429.693 | I17: 14201.927 | J17: 14016.909 | K17: 13860.764 | L17: 13679.089 | M17: 13473.833 | N17: 13253.084 | O17: 13044.087 | P17: 12836.979 | Q17: 12674.041 | R17: 12534.656 | S17: 12394.664 | T17: 12251.55 | U17: 12130.824 | V17: 12028.419 | W17: 11933.924 | X17: 11864.004 | Y17: 11805.398 | Z17: 11762.744 | AA17: 11733.646 | AB17: 11725.389 | AC17: 11735.777 | AD17: 11770.766 | AE17: 11824.353 | AF17: 11889.718 | AG17: 11962.912 | AH17: 12054.456 | AI17: -0.007
A18: Automobiles | B18: Transportation Energy Use: Highway: Light-Duty Vehicles: Automobiles: Reference case | C18: AEO.2023.REF2023.CNSM_NA_TRN_HWY_LDV_AUTO_NA_TRLBTU.A | D18: trillion Btu | F18: 5654.1606 | G18: 5526.6772 | H18: 5311.813 | I18: 5067.3223 | J18: 4838.1689 | K18: 4619.4316 | L18: 4397.4468 | M18: 4169.8599 | N18: 3944.7561 | O18: 3731.1753 | P18: 3530.8748 | Q18: 3355.2742 | R18: 3201.8225 | S18: 3058.1055 | T18: 2927.6711 | U18: 2817.0913 | V18: 2726.7456 | W18: 2648.3855 | X18: 2585.8064 | Y18: 2534.5078 | Z18: 2494.8418 | AA18: 2463.2471 | AB18: 2438.6992 | AC18: 2420.9849 | AD18: 2411.0181 | AE18: 2405.7183 | AF18: 2403.655 | AG18: 2402.5029 | AH18: 2405.8833 | AI18: -0.03
A19: Light Trucks | B19: Transportation Energy Use: Highway: Light-Duty Vehicles: Light Trucks: Reference case | C19: AEO.2023.REF2023.CNSM_NA_TRN_HWY_LDV_LTRT_NA_TRLBTU.A | D19: trillion Btu | F19: 8871.5508 | G19: 9043.541 | H19: 9102.6006 | I19: 9120.0283 | J19: 9164.8242 | K19: 9228.0459 | L19: 9268.9941 | M19: 9291.9814 | N19: 9296.9863 | O19: 9302.1855 | P19: 9295.9561 | Q19: 9309.126 | R19: 9323.6357 | S19: 9327.7764 | T19: 9315.4736 | U19: 9305.6484 | V19: 9293.8496 | W19: 9277.9414 | X19: 9270.7812 | Y19: 9263.6221 | Z19: 9260.7471 | AA19: 9263.335 | AB19: 9279.6943 | AC19: 9307.8467 | AD19: 9352.8291 | AE19: 9411.7305 | AF19: 9479.1641 | AG19: 9553.5127 | AH19: 9641.666 | AI19: 0.003
A20: Motorcycles | B20: Transportation Energy Use: Highway: Light-Duty Vehicles: Motorcycles: Reference case | C20: AEO.2023.REF2023.CNSM_NA_TRN_HWY_LDV_MCYCL_NA_TRLBTU.A | D20: trillion Btu | F20: 16.262892 | G20: 15.896933 | H20: 15.278913 | I20: 14.5757 | J20: 13.916059 | K20: 13.285933 | L20: 12.647085 | M20: 11.991311 | N20: 11.342273 | O20: 10.726049 | P20: 10.148347 | Q20: 9.640781 | R20: 9.197762 | S20: 8.782386 | T20: 8.404802 | U20: 8.084402 | V20: 7.823192 | W20: 7.596957 | X20: 7.416474 | Y20: 7.268723 | Z20: 7.155083 | AA20: 7.064892 | AB20: 6.994964 | AC20: 6.945127 | AD20: 6.917612 | AE20: 6.903515 | AF20: 6.898674 | AG20: 6.896451 | AH20: 6.90719 | AI20: -0.03
A21: Commercial Light Trucks | B21: Transportation Energy Use: Highway: Commercial Light Trucks: Reference case | C21: AEO.2023.REF2023.CNSM_NA_TRN_HWY_CML_NA_NA_TRLBTU.A | D21: trillion Btu | F21: 951.50293 | G21: 942.55829 | H21: 925.34027 | I21: 912.45172 | J21: 903.11078 | K21: 894.80676 | L21: 888.38452 | M21: 882.99542 | N21: 877.03253 | O21: 872.79089 | P21: 871.79065 | Q21: 871.86749 | R21: 873.03369 | S21: 875.07349 | T21: 877.49945 | U21: 881.02332 | V21: 885.54089 | W21: 889.79602 | X21: 896.14636 | Y21: 903.92444 | Z21: 911.92096 | AA21: 918.6748 | AB21: 924.72058 | AC21: 931.8302 | AD21: 939.93994 | AE21: 949.95038 | AF21: 958.32001 | AG21: 967.2102 | AH21: 978.89801 | AI21: 0.001
A22: Buses | B22: Transportation Energy Use: Highway: Buses: Reference case | C22: AEO.2023.REF2023.CNSM_NA_TRN_HWY_BUS_NA_NA_TRLBTU.A | D22: trillion Btu | F22: 212.16301 | G22: 222.31247 | H22: 226.95673 | I22: 228.01268 | J22: 228.79755 | K22: 229.23793 | L22: 229.40265 | M22: 229.15626 | N22: 228.54794 | O22: 227.55568 | P22: 226.52992 | Q22: 226.00464 | R22: 225.33565 | S22: 224.47317 | T22: 223.49628 | U22: 221.94028 | V22: 220.57585 | W22: 219.0985 | X22: 217.49985 | Y22: 215.78369 | Z22: 214.03241 | AA22: 212.01721 | AB22: 210.15359 | AC22: 208.21464 | AD22: 206.53474 | AE22: 204.46298 | AF22: 202.45996 | AG22: 200.28244 | AH22: 198.18263 | AI22: -0.002
A23: Transit | B23: Transportation Energy Use: Highway: Buses: Transit: Reference case | C23: AEO.2023.REF2023.CNSM_NA_TRN_HWY_BUS_TNST_NA_TRLBTU.A | D23: trillion Btu | F23: 92.212234 | G23: 95.83783 | H23: 98.320953 | I23: 98.870079 | J23: 99.844643 | K23: 100.61442 | L23: 101.24708 | M23: 101.61662 | N23: 101.72417 | O23: 101.53801 | P23: 101.31126 | Q23: 100.9764 | R23: 100.75687 | S23: 100.29507 | T23: 99.678467 | U23: 98.421806 | V23: 97.683716 | W23: 96.918678 | X23: 96.071007 | Y23: 95.130722 | Z23: 94.233086 | AA23: 93.123825 | AB23: 92.2043 | AC23: 91.250328 | AD23: 90.65873 | AE23: 89.694473 | AF23: 88.826485 | AG23: 87.819649 | AH23: 86.904648 | AI23: -0.002
A24: Intercity | B24: Transportation Energy Use: Highway: Buses: Intercity: Reference case | C24: AEO.2023.REF2023.CNSM_NA_TRN_HWY_BUS_ICYT_NA_TRLBTU.A | D24: trillion Btu | F24: 26.118862 | G24: 28.024412 | H24: 29.477226 | I24: 30.571621 | J24: 31.3964 | K24: 32.010113 | L24: 32.464531 | M24: 32.799759 | N24: 33.046234 | O24: 33.226051 | P24: 33.352478 | Q24: 33.43018 | R24: 33.466476 | S24: 33.46925 | T24: 33.44516 | U24: 33.397396 | V24: 33.349758 | W24: 33.294384 | X24: 33.234276 | Y24: 33.167286 | Z24: 33.096901 | AA24: 33.025082 | AB24: 32.951077 | AC24: 32.875145 | AD24: 32.799278 | AE24: 32.723492 | AF24: 32.646706 | AG24: 32.56945 | AH24: 32.494362 | AI24: 0.008
A25: School | B25: Transportation Energy Use: Highway: Buses: School: Reference case | C25: AEO.2023.REF2023.CNSM_NA_TRN_HWY_BUS_SCBU_NA_TRLBTU.A | D25: trillion Btu | F25: 93.831894 | G25: 98.450195 | H25: 99.158546 | I25: 98.571014 | J25: 97.556511 | K25: 96.613396 | L25: 95.691032 | M25: 94.739861 | N25: 93.77755 | O25: 92.791618 | P25: 91.866196 | Q25: 91.598053 | R25: 91.112289 | S25: 90.70887 | T25: 90.37265 | U25: 90.12104 | V25: 89.542336 | W25: 88.885452 | X25: 88.194603 | Y25: 87.485649 | Z25: 86.702446 | AA25: 85.868294 | AB25: 84.99823 | AC25: 84.089134 | AD25: 83.076744 | AE25: 82.045021 | AF25: 80.986786 | AG25: 79.893326 | AH25: 78.783607 | AI25: -0.006
A26: Freight Trucks | B26: Transportation Energy Use: Highway: Freight Trucks: Reference case | C26: AEO.2023.REF2023.CNSM_NA_TRN_HWY_FGHT_NA_NA_TRLBTU.A | D26: trillion Btu | F26: 5922.792 | G26: 5816.707 | H26: 5728.0947 | I26: 5673.0977 | J26: 5638.8965 | K26: 5591.7075 | L26: 5543.7109 | M26: 5483.6704 | N26: 5422.3882 | O26: 5371.3022 | P26: 5340.1582 | Q26: 5306.5054 | R26: 5278.7798 | S26: 5261.2461 | T26: 5243 | U26: 5237.6978 | V26: 5236.3613 | W26: 5238.3042 | X26: 5247.9146 | Y26: 5263.2085 | Z26: 5281.4546 | AA26: 5299.6816 | AB26: 5316.7661 | AC26: 5331.6992 | AD26: 5353.2002 | AE26: 5376.3174 | AF26: 5393.3188 | AG26: 5413.416 | AH26: 5450.0127 | AI26: -0.003
A27: Light Medium | B27: Transportation Energy Use: Highway: Freight Trucks: Light Medium: Reference case | C27: AEO.2023.REF2023.CNSM_NA_TRN_HWY_FGHT_LITEMED_NA_TRLBTU.A | D27: trillion Btu | F27: 745.82806 | G27: 731.17401 | H27: 720.99341 | I27: 716.52246 | J27: 715.17627 | K27: 711.7099 | L27: 708.54388 | M27: 705.98785 | N27: 706.4599 | O27: 710.45679 | P27: 717.79156 | Q27: 724.37231 | R27: 731.39038 | S27: 739.17932 | T27: 746.30853 | U27: 754.65619 | V27: 763.13739 | W27: 772.1521 | X27: 782.66339 | Y27: 794.23718 | Z27: 805.87262 | AA27: 817.30426 | AB27: 829.03217 | AC27: 841.80096 | AD27: 857.07477 | AE27: 873.44006 | AF27: 889.11859 | AG27: 905.95618 | AH27: 926.21399 | AI27: 0.008
A28: Medium | B28: Transportation Energy Use: Highway: Freight Trucks: Medium: Reference case | C28: AEO.2023.REF2023.CNSM_NA_TRN_HWY_FGHT_MD10T26KLB_NA_TRLBTU.A | D28: trillion Btu | F28: 969.69183 | G28: 947.22809 | H28: 929.37402 | I28: 917.57544 | J28: 910.67749 | K28: 903.25037 | L28: 897.46631 | M28: 890.09558 | N28: 882.57385 | O28: 876.55035 | P28: 874.65271 | Q28: 871.91071 | R28: 869.98096 | S28: 869.72485 | T28: 869.34759 | U28: 871.61865 | V28: 873.72833 | W28: 877.64197 | X28: 882.78259 | Y28: 889.237 | Z28: 896.04053 | AA28: 903.72443 | AB28: 911.77496 | AC28: 919.3786 | AD28: 928.10925 | AE28: 937.41211 | AF28: 945.94012 | AG28: 955.21368 | AH28: 967.38184 | AI28: 0
A29: Large (more than 26000 pounds) | B29: Transportation Energy Use: Highway: Freight Trucks: Large: Reference case | C29: AEO.2023.REF2023.#N/A.A | D29: trillion Btu | F29: 4207.2715 | G29: 4138.3047 | H29: 4077.7268 | I29: 4039 | J29: 4013.0432 | K29: 3976.7476 | L29: 3937.7007 | M29: 3887.5867 | N29: 3833.355 | O29: 3784.2954 | P29: 3747.7139 | Q29: 3710.2224 | R29: 3677.4087 | S29: 3652.342 | T29: 3627.3435 | U29: 3611.4229 | V29: 3599.4961 | W29: 3588.51 | X29: 3582.4688 | Y29: 3579.7341 | Z29: 3579.5413 | AA29: 3578.6533 | AB29: 3575.9597 | AC29: 3570.5195 | AD29: 3568.0156 | AE29: 3565.4651 | AF29: 3558.26 | AG29: 3552.2463 | AH29: 3556.4165 | AI29: -0.006
A30: Non-Highway
A31: Air | B31: Transportation Energy Use: Non-Highway: Air: Reference case | C31: AEO.2023.REF2023.CNSM_NA_TRN_AIR_NA_NA_NA_TRLBTU.A | D31: trillion Btu | F31: 2802.8074 | G31: 3008.168 | H31: 3051.2026 | I31: 3057.1106 | J31: 3095.8982 | K31: 3134.2271 | L31: 3164.5515 | M31: 3187.1079 | N31: 3202.9382 | O31: 3218.7827 | P31: 3243.9365 | Q31: 3270.4482 | R31: 3294.4031 | S31: 3322.9241 | T31: 3359.825 | U31: 3403.8945 | V31: 3450.1719 | W31: 3498.4883 | X31: 3554.6438 | Y31: 3608.4036 | Z31: 3663.0974 | AA31: 3718.6248 | AB31: 3774.01 | AC31: 3827.9189 | AD31: 3880.4333 | AE31: 3936.7383 | AF31: 3993.604 | AG31: 4049.6506 | AH31: 4112.1577 | AI31: 0.014
A32: General Aviation | B32: Transportation Energy Use: Non-Highway: Air: General Aviation: Reference case | C32: AEO.2023.REF2023.CNSM_NA_TRN_AIR_GAV_NA_NA_TRLBTU.A | D32: trillion Btu | F32: 154.82079 | G32: 164.58934 | H32: 166.63007 | I32: 166.90428 | J32: 168.74524 | K32: 170.56552 | L32: 172.0056 | M32: 173.07629 | N32: 173.82729 | O32: 174.57951 | P32: 175.77553 | Q32: 177.03632 | R32: 178.17583 | S32: 179.53285 | T32: 181.289 | U32: 183.38686 | V32: 185.59007 | W32: 187.89032 | X32: 190.56396 | Y32: 193.12366 | Z32: 195.72784 | AA32: 198.37164 | AB32: 201.00888 | AC32: 203.57585 | AD32: 206.07645 | AE32: 208.75748 | AF32: 211.46515 | AG32: 214.13402 | AH32: 217.1105 | AI32: 0.012
A33: Domestic Passenger | B33: Transportation Energy Use: Non-Highway: Air: Domestic Passenger: Reference case | C33: AEO.2023.REF2023.CNSM_NA_TRN_AIR_DAC_NA_NA_TRLBTU.A | D33: trillion Btu | F33: 1525.3719 | G33: 1568.4963 | H33: 1545.2438 | I33: 1539.9454 | J33: 1560.0005 | K33: 1578.9973 | L33: 1593.6608 | M33: 1603.7645 | N33: 1608.9692 | O33: 1613.8066 | P33: 1624.1025 | Q33: 1638.2094 | R33: 1651.6223 | S33: 1665.2513 | T33: 1681.9424 | U33: 1701.5503 | V33: 1722.4525 | W33: 1743.975 | X33: 1770.0122 | Y33: 1794.5861 | Z33: 1819.5831 | AA33: 1845.8711 | AB33: 1871.9424 | AC33: 1896.6277 | AD33: 1920.9094 | AE33: 1947.4875 | AF33: 1974.0907 | AG33: 2000.766 | AH33: 2030.3903 | AI33: 0.01
A34: International Passenger | B34: Transportation Energy Use: Non-Highway: Air: International Passenger: Reference case | C34: AEO.2023.REF2023.CNSM_NA_TRN_AIR_IAC_NA_NA_TRLBTU.A | D34: trillion Btu | F34: 586.70477 | G34: 755.09033 | H34: 825.08246 | I34: 835.10657 | J34: 847.74762 | K34: 860.41785 | L34: 870.67084 | M34: 878.74676 | N34: 885.43268 | O34: 892.21881 | P34: 901.3352 | Q34: 909.30804 | R34: 916.19775 | S34: 925.32129 | T34: 937.39001 | U34: 951.84992 | V34: 966.82947 | W34: 982.55957 | X34: 1000.3361 | Y34: 1017.5378 | Z34: 1035.0142 | AA34: 1052.2997 | AB34: 1069.5682 | AC34: 1086.702 | AD34: 1103.2957 | AE34: 1120.8325 | AF34: 1138.662 | AG34: 1156.0013 | AH34: 1175.4172 | AI34: 0.025
A35: Dedicated Freight | B35: Transportation Energy Use: Non-Highway: Air: Dedicated Freight: Reference case | C35: AEO.2023.REF2023.CNSM_NA_TRN_AIR_DFT_NA_NA_TRLBTU.A | D35: trillion Btu | F35: 535.90997 | G35: 519.99194 | H35: 514.24634 | I35: 515.1543 | J35: 519.40478 | K35: 524.24622 | L35: 528.21435 | M35: 531.52032 | N35: 534.70904 | O35: 538.17767 | P35: 542.72302 | Q35: 545.89441 | R35: 548.40717 | S35: 552.81854 | T35: 559.20331 | U35: 567.1073 | V35: 575.29974 | W35: 584.06348 | X35: 593.73175 | Y35: 603.15594 | Z35: 612.77222 | AA35: 622.08221 | AB35: 631.49048 | AC35: 641.01318 | AD35: 650.15185 | AE35: 659.66058 | AF35: 669.38611 | AG35: 678.74933 | AH35: 689.23981 | AI35: 0.009
A36: Water | B36: Transportation Energy Use: Non-Highway: Water: Reference case | C36: AEO.2023.REF2023.CNSM_NA_TRN_WTR_NA_NA_NA_TRLBTU.A | D36: trillion Btu | F36: 1236.1034 | G36: 1179.9142 | H36: 1171.6475 | I36: 1169.6875 | J36: 1160.7493 | K36: 1156.1696 | L36: 1148.3876 | M36: 1142.2429 | N36: 1136.957 | O36: 1134.8431 | P36: 1133.3051 | Q36: 1132.2845 | R36: 1130.4717 | S36: 1129.385 | T36: 1127.3304 | U36: 1126.3339 | V36: 1125.2139 | W36: 1123.8895 | X36: 1123.0144 | Y36: 1122.3082 | Z36: 1122.0916 | AA36: 1121.3387 | AB36: 1120.708 | AC36: 1119.7297 | AD36: 1121.4393 | AE36: 1120.9009 | AF36: 1118.8984 | AG36: 1117.3406 | AH36: 1115.843 | AI36: -0.004
A37: Freight | B37: Transportation Energy Use: Non-Highway: Water: Freight: Reference case | C37: AEO.2023.REF2023.CNSM_NA_TRN_WTR_FGT_NA_NA_TRLBTU.A | D37: trillion Btu | F37: 1033.2667 | G37: 980.75116 | H37: 975.84198 | I37: 975.9502 | J37: 967.93616 | K37: 964.27222 | L37: 957.65405 | M37: 953.03247 | N37: 949.55359 | O37: 949.16626 | P37: 948.83813 | Q37: 948.67444 | R37: 947.69421 | S37: 947.38678 | T37: 945.88025 | U37: 945.22846 | V37: 944.46802 | W37: 943.50647 | X37: 942.71899 | Y37: 942.1471 | Z37: 942.10346 | AA37: 941.52521 | AB37: 941.15137 | AC37: 940.48584 | AD37: 942.48962 | AE37: 942.17328 | AF37: 940.40753 | AG37: 939.11212 | AH37: 937.68744 | AI37: -0.003
A38: Domestic Shipping | B38: Transportation Energy Use: Non-Highway: Water: Freight: Domestic Shipping: Reference case | C38: AEO.2023.REF2023.CNSM_NA_TRN_WTR_DMT_NA_NA_TRLBTU.A | D38: trillion Btu | F38: 98.239021 | G38: 98.920753 | H38: 98.114662 | I38: 97.346069 | J38: 96.685867 | K38: 95.823471 | L38: 94.964699 | M38: 93.890503 | N38: 92.919189 | O38: 92.029816 | P38: 91.401108 | Q38: 90.674225 | R38: 89.934029 | S38: 89.168869 | T38: 88.333008 | U38: 87.614967 | V38: 86.833351 | W38: 86.156693 | X38: 85.473595 | Y38: 84.846123 | Z38: 84.273766 | AA38: 83.705399 | AB38: 83.103455 | AC38: 82.418205 | AD38: 81.856209 | AE38: 81.249023 | AF38: 80.57312 | AG38: 79.990395 | AH38: 79.59285 | AI38: -0.007
A39: International Shipping | B39: Transportation Energy Use: Non-Highway: Water: Freight: International Shipping: Reference case | C39: AEO.2023.REF2023.CNSM_NA_TRN_WTR_INTS_NA_NA_TRLBTU.A | D39: trillion Btu | F39: 935.02771 | G39: 881.83038 | H39: 877.7273 | I39: 878.60413 | J39: 871.25031 | K39: 868.44873 | L39: 862.68933 | M39: 859.14197 | N39: 856.6344 | O39: 857.13648 | P39: 857.43701 | Q39: 858.00024 | R39: 857.76019 | S39: 858.2179 | T39: 857.54724 | U39: 857.61346 | V39: 857.63464 | W39: 857.34979 | X39: 857.24542 | Y39: 857.30096 | Z39: 857.82971 | AA39: 857.81982 | AB39: 858.04791 | AC39: 858.06763 | AD39: 860.63342 | AE39: 860.92426 | AF39: 859.83441 | AG39: 859.1217 | AH39: 858.0946 | AI39: -0.003
A40: Recreational Boats | B40: Transportation Energy Use: Non-Highway: Water: Recreational Boats: Reference case | C40: AEO.2023.REF2023.CNSM_NA_TRN_WTR_RBT_NA_NA_TRLBTU.A | D40: trillion Btu | F40: 202.83664 | G40: 199.16296 | H40: 195.80548 | I40: 193.73721 | J40: 192.81314 | K40: 191.8974 | L40: 190.73351 | M40: 189.21046 | N40: 187.40353 | O40: 185.67694 | P40: 184.46689 | Q40: 183.61003 | R40: 182.77757 | S40: 181.99818 | T40: 181.45029 | U40: 181.10551 | V40: 180.74588 | W40: 180.38298 | X40: 180.29542 | Y40: 180.16119 | Z40: 179.98802 | AA40: 179.81351 | AB40: 179.55652 | AC40: 179.24385 | AD40: 178.94971 | AE40: 178.72766 | AF40: 178.49087 | AG40: 178.22836 | AH40: 178.15555 | AI40: -0.005
A41: Rail | B41: Transportation Energy Use: Non-Highway: Rail: Reference case | C41: AEO.2023.REF2023.CNSM_NA_TRN_RAIL_RAIL_NA_NA_TRLBTU.A | D41: trillion Btu | F41: 525.29517 | G41: 520.38635 | H41: 540.67011 | I41: 529.40961 | J41: 509.78037 | K41: 494.66577 | L41: 488.8783 | M41: 494.23297 | N41: 492.04196 | O41: 494.02197 | P41: 498.57672 | Q41: 502.37463 | R41: 505.03482 | S41: 508.43884 | T41: 509.35068 | U41: 510.83496 | V41: 512.78436 | W41: 512.64246 | X41: 513.75494 | Y41: 517.85437 | Z41: 521.3421 | AA41: 522.19409 | AB41: 522.73846 | AC41: 523.13727 | AD41: 524.88281 | AE41: 527.90674 | AF41: 531.78455 | AG41: 533.67975 | AH41: 537.57678 | AI41: 0.001
A42: Freight | B42: Transportation Energy Use: Non-Highway: Rail: Freight: Reference case | C42: AEO.2023.REF2023.CNSM_NA_TRN_RAIL_FGT_NA_NA_TRLBTU.A | D42: trillion Btu | F42: 481.38171 | G42: 474.82239 | H42: 494.12915 | I42: 482.20422 | J42: 461.88034 | K42: 446.09524 | L42: 439.74536 | M42: 444.5257 | N42: 441.89194 | O42: 443.42331 | P42: 447.43723 | Q42: 450.64798 | R42: 452.66559 | S42: 455.51504 | T42: 455.89371 | U42: 456.86227 | V42: 458.27463 | W42: 457.60877 | X42: 458.12836 | Y42: 461.67325 | Z42: 464.58835 | AA42: 464.93649 | AB42: 464.92282 | AC42: 464.77069 | AD42: 465.76679 | AE42: 468.15533 | AF42: 471.33984 | AG42: 472.59906 | AH42: 475.72867 | AI42: 0
... A51: Jet Fuel and Aviation Gasoline | B51: Transportation Energy Use: Military Use: Aviation: Reference case | C51: AEO.2023.REF2023.CNSM_NA_TRN_MLU_AVI_NA_NA_TRLBTU.A | D51: trillion Btu | F51: 334.44891 | G51: 336.23386 | H51: 336.88306 | I51: 337.39594 | J51: 337.81006 | K51: 338.4198 | L51: 338.85339 | M51: 339.19925 | N51: 339.4949 | O51: 339.68457 | P51: 339.81464 | Q51: 339.87894 | R51: 339.90338 | S51: 339.91986 | T51: 340.01639 | U51: 340.17093 | V51: 340.33325 | W51: 340.50293 | X51: 340.67941 | Y51: 340.86197 | Z51: 341.05005 | AA51: 341.24316 | AB51: 341.44086 | AC51: 341.64276 | AD51: 341.84848 | AE51: 342.05759 | AF51: 342.26984 | AG51: 342.48502 | AH51: 342.70288 | AI51: 0.001
A52: Residual Fuel Oil | B52: Transportation Energy Use: Military Use: Residual Fuel Oil: Reference case | C52: AEO.2023.REF2023.CNSM_NA_TRN_MLU_RFO_NA_NA_TRLBTU.A | D52: trillion Btu | F52: 0 | G52: 0 | H52: 0 | I52: 0 | J52: 0 | K52: 0 | L52: 0 | M52: 0 | N52: 0 | O52: 0 | P52: 0 | Q52: 0 | R52: 0 | S52: 0 | T52: 0 | U52: 0 | V52: 0 | W52: 0 | X52: 0 | Y52: 0 | Z52: 0 | AA52: 0 | AB52: 0 | AC52: 0 | AD52: 0 | AE52: 0 | AF52: 0 | AG52: 0 | AH52: 0 | AI52: - -
A53: Distillates and Diesel | B53: Transportation Energy Use: Military Use: Distillate Fuel Oil: Reference case | C53: AEO.2023.REF2023.CNSM_NA_TRN_MLU_DFO_NA_NA_TRLBTU.A | D53: trillion Btu | F53: 96.382973 | G53: 96.897369 | H53: 97.084457 | I53: 97.232269 | J53: 97.351608 | K53: 97.527321 | L53: 97.652275 | M53: 97.751961 | N53: 97.837143 | O53: 97.891815 | P53: 97.929291 | Q53: 97.947815 | R53: 97.954857 | S53: 97.959595 | T53: 97.987419 | U53: 98.031967 | V53: 98.078743 | W53: 98.12764 | X53: 98.178513 | Y53: 98.231117 | Z53: 98.285309 | AA53: 98.340965 | AB53: 98.397942 | AC53: 98.456131 | AD53: 98.515411 | AE53: 98.575668 | AF53: 98.636826 | AG53: 98.698837 | AH53: 98.761627 | AI53: 0.001
A54: Total | B54: Transportation Energy Use: Total: Reference case | C54: AEO.2023.REF2023.CNSM_NA_TRN_NA_TOT_NA_NA_TRLBTU.A | D54: trillion Btu | F54: 27655.148 | G54: 27655.762 | H54: 27394.568 | I54: 27059.129 | J54: 26811.27 | K54: 26577.496 | L54: 26318.691 | M54: 26067.979 | N54: 25786.289 | O54: 25538.402 | P54: 25332.225 | Q54: 25172.969 | R54: 25035.588 | S54: 24912.785 | T54: 24789.316 | U54: 24709.041 | V54: 24660.725 | W54: 24616.969 | X54: 24627.309 | Y54: 24654.197 | Z54: 24700.111 | AA54: 24752.801 | AB54: 24825.584 | AC54: 24913.93 | AD54: 25038.584 | AE54: 25190.057 | AF54: 25345.311 | AG54: 25504.531 | AH54: 25712.529 | AI54: -0.003
A55: Energy Use by Type
A56: Motor Gasoline excluding E85 | B56: Transportation Energy Use: Petroleum: Motor Gasoline: Reference case | C56: AEO.2023.REF2023.CNSM_NA_TRN_NA_PET_MGS_NA_TRLBTU.A | D56: trillion Btu | F56: 15874.355 | G56: 15889.633 | H56: 15703.889 | I56: 15449.35 | J56: 15240.682 | K56: 15053.521 | L56: 14839.349 | M56: 14597.918 | N56: 14338.503 | O56: 14096.112 | P56: 13861.302 | Q56: 13670.039 | R56: 13502.24 | S56: 13335.431 | T56: 13166.213 | U56: 13022.09 | V56: 12897.387 | W56: 12783.024 | X56: 12697.221 | Y56: 12626.134 | Z56: 12573.058 | AA56: 12533.43 | AB56: 12516.672 | AC56: 12520.883 | AD56: 12551.513 | AE56: 12603.282 | AF56: 12665.79 | AG56: 12737.466 | AH56: 12832.444 | AI56: -0.008
...

Sheet AEO 2023 36
B1: Table 36. Transportation Sector Energy Use by Fuel Type Within a Mode
B2: https://www.eia.gov/outlooks/aeo/data/browser/#/?id=46-AEO2023&cases=ref2023&sourcekey=0
B3: Thu Dec 11 2025 13:27:15 GMT-0800 (Pacific Standard Time)
B4: Source: U.S. Energy Information Administration
C5: full name | D5: api key | E5: units | F5: 2021 | G5: 2022 | H5: 2023 | I5: 2024 | J5: 2025 | K5: 2026 | L5: 2027 | M5: 2028 | N5: 2029 | O5: 2030 | P5: 2031 | Q5: 2032 | R5: 2033 | S5: 2034 | T5: 2035 | U5: 2036 | V5: 2037 | W5: 2038 | X5: 2039 | Y5: 2040 | Z5: 2041 | AA5: 2042 | AB5: 2043 | AC5: 2044 | AD5: 2045 | AE5: 2046 | AF5: 2047 | AG5: 2048 | AH5: 2049 | AI5: 2050 | AJ5: Growth (2022-2050) | AK5: Growth (2020-2050)
B6: Light-Duty Vehicle | C6: Transportation Energy Use: Light-Duty Vehicle: Total: Reference case | D6: AEO.2023.REF2023.CNSM_NA_TRN_LDTY_NA_NA_NA_TRLBTU.A | E6: trillion Btu | G6: 14541.973 | H6: 14586.113 | I6: 14429.691 | J6: 14201.925 | K6: 14016.908 | L6: 13860.762 | M6: 13679.086 | N6: 13473.831 | O6: 13253.083 | P6: 13044.085 | Q6: 12836.978 | R6: 12674.038 | S6: 12534.655 | T6: 12394.663 | U6: 12251.547 | V6: 12130.821 | W6: 12028.415 | X6: 11933.922 | Y6: 11864.001 | Z6: 11805.396 | AA6: 11762.741 | AB6: 11733.644 | AC6: 11725.386 | AD6: 11735.774 | AE6: 11770.763 | AF6: 11824.349 | AG6: 11889.715 | AH6: 11962.909 | AI6: 12054.454 | AJ6: -0.007 | AK6: 0
B7: Motor Gasoline excluding E85 | C7: Transportation Energy Use: Light-Duty Vehicle: Motor Gasoline: Reference case | D7: AEO.2023.REF2023.CNSM_NA_TRN_LDTY_MGS_NA_NA_TRLBTU.A | E7: trillion Btu | G7: 14415.272 | H7: 14443.936 | I7: 14272.424 | J7: 14024.321 | K7: 13815.495 | L7: 13632.25 | M7: 13419.692 | N7: 13179.96 | O7: 12922.15 | P7: 12678.574 | Q7: 12437.037 | R7: 12238.959 | S7: 12063.409 | T7: 11887.983 | U7: 11710.702 | V7: 11556.08 | W7: 11421.213 | X7: 11295.929 | Y7: 11196.766 | Z7: 11110.767 | AA7: 11042.225 | AB7: 10988.435 | AC7: 10958.348 | AD7: 10949.109 | AE7: 10963.974 | AF7: 10998.307 | AG7: 11045.134 | AH7: 11100.26 | AI7: 11174.06 | AJ7: -0.009 | AK7: -0.001
B8: E85 | C8: Transportation Energy Use: Light-Duty Vehicle: Ethanol: Reference case | D8: AEO.2023.REF2023.CNSM_NA_TRN_LDTY_ETH_NA_NA_TRLBTU.A | E8: trillion Btu | G8: 31.110834 | H8: 31.64006 | I8: 29.552767 | J8: 29.441513 | K8: 28.728485 | L8: 27.952177 | M8: 27.018059 | N8: 25.972713 | O8: 24.873795 | P8: 23.80064 | Q8: 22.75461 | R8: 21.823027 | S8: 20.987984 | T8: 20.244169 | U8: 19.537762 | V8: 19.024712 | W8: 18.648621 | X8: 18.39851 | Y8: 18.275644 | Z8: 18.222813 | AA8: 18.236134 | AB8: 18.340065 | AC8: 18.452595 | AD8: 18.609615 | AE8: 18.756809 | AF8: 19.004078 | AG8: 19.229309 | AH8: 19.515997 | AI8: 19.788425 | AJ8: -0.016 | AK8: 0.004
B9: Distillate Fuel Oil (diesel) | C9: Transportation Energy Use: Light-Duty Vehicle: Distillate Fuel Oil: Reference case | D9: AEO.2023.REF2023.CNSM_NA_TRN_LDTY_DFO_NA_NA_TRLBTU.A | E9: trillion Btu | G9: 61.460403 | H9: 64.69902 | I9: 67.503647 | J9: 70.684074 | K9: 74.503555 | L9: 77.63253 | M9: 81.324982 | N9: 84.520767 | O9: 86.959732 | P9: 89.758049 | Q9: 91.490158 | R9: 93.247543 | S9: 95.158997 | T9: 96.641708 | U9: 98.053238 | V9: 99.8647 | W9: 101.3619 | X9: 102.78562 | Y9: 104.47522 | Z9: 105.74961 | AA9: 107.32461 | AB9: 109.77927 | AC9: 110.92001 | AD9: 111.97984 | AE9: 113.44128 | AF9: 115.03706 | AG9: 116.75106 | AH9: 118.59347 | AI9: 120.69574 | AJ9: 0.024 | AK9: 0.025
B10: Compressed/Liquefied Natural Gas | C10: Transportation Energy Use: Light-Duty Vehicle: Natural Gas: Reference case | D10: AEO.2023.REF2023.CNSM_NA_TRN_LDTY_NG_NA_NA_TRLBTU.A | E10: trillion Btu | G10: 0.712888 | H10: 0.677668 | I10: 0.537752 | J10: 0.515005 | K10: 0.507019 | L10: 0.492443 | M10: 0.481839 | N10: 0.470472 | O10: 0.445942 | P10: 0.443445 | Q10: 0.437883 | R10: 0.433434 | S10: 0.431733 | T10: 0.430499 | U10: 0.427096 | V10: 0.424631 | W10: 0.426227 | X10: 0.378024 | Y10: 0.335326 | Z10: 0.340053 | AA10: 0.343781 | AB10: 0.346656 | AC10: 0.349313 | AD10: 0.351864 | AE10: 0.356448 | AF10: 0.36171 | AG10: 0.367786 | AH10: 0.374043 | AI10: 0.381082 | AJ10: -0.022 | AK10: -0.001
B11: Propane | C11: Transportation Energy Use: Light-Duty Vehicle: Propane: Reference case | D11: AEO.2023.REF2023.CNSM_NA_TRN_LDTY_PROP_NA_NA_TRLBTU.A | E11: trillion Btu | G11: 0.797388 | H11: 0.735487 | I11: 0.547456 | J11: 0.540668 | K11: 0.544193 | L11: 0.561282 | M11: 0.312092 | N11: 0.33014 | O11: 0.384077 | P11: 0.437626 | Q11: 0.489719 | R11: 0.540254 | S11: 0.590177 | T11: 0.638076 | U11: 0.684164 | V11: 0.72876 | W11: 0.771586 | X11: 0.812987 | Y11: 0.85285 | Z11: 0.891809 | AA11: 0.930713 | AB11: 0.968622 | AC11: 1.007558 | AD11: 1.048031 | AE11: 1.096531 | AF11: 1.150243 | AG11: 1.209162 | AH11: 1.271896 | AI11: 1.341161 | AJ11: 0.019 | AK11: -0.007
B12: Electricity | C12: Transportation Energy Use: Light-Duty Vehicle: Electricity: Reference case | D12: AEO.2023.REF2023.CNSM_NA_TRN_LDTY_ELC_NA_NA_TRLBTU.A | E12: trillion Btu | G12: 32.193668 | H12: 43.907116 | I12: 58.529484 | J12: 75.757942 | K12: 96.391159 | L12: 121.06613 | M12: 149.37682 | N12: 181.62849 | O12: 217.24832 | P12: 249.97737 | Q12: 283.60272 | R12: 317.79742 | S12: 352.76804 | T12: 387.34479 | U12: 420.6944 | V12: 453.18622 | W12: 484.42331 | X12: 513.9956 | Y12: 541.63086 | Z12: 567.72461 | AA12: 591.9502 | AB12: 614.02081 | AC12: 634.53888 | AD12: 652.89734 | AE12: 671.34821 | AF12: 688.6897 | AG12: 705.21576 | AH12: 721.08112 | AI12: 736.37286 | AJ12: 0.118 | AK12: 0.101
B13: Hydrogen | C13: Transportation Energy Use: Light-Duty Vehicle: Hydrogen: Reference case | D13: AEO.2023.REF2023.CNSM_NA_TRN_LDTY_HDG_NA_NA_TRLBTU.A | E13: trillion Btu | G13: 0.426139 | H13: 0.518183 | I13: 0.595767 | J13: 0.665118 | K13: 0.737872 | L13: 0.80678 | M13: 0.879698 | N13: 0.948358 | O13: 1.020552 | P13: 1.093446 | Q13: 1.165657 | R13: 1.237105 | S13: 1.309695 | T13: 1.380918 | U13: 1.447488 | V13: 1.512508 | W13: 1.570883 | X13: 1.623062 | Y13: 1.665691 | Z13: 1.699897 | AA13: 1.731693 | AB13: 1.753623 | AC13: 1.769871 | AD13: 1.779117 | AE13: 1.789497 | AF13: 1.800149 | AG13: 1.807713 | AH13: 1.813287 | AI13: 1.816777 | AJ13: 0.053 | AK13: 0.038
B14: Commercial Light Trucks | C14: Transportation Energy Use: Commercial Light Trucks: Total: Reference case | D14: AEO.2023.REF2023.CNSM_NA_TRN_CLTR_NA_NA_NA_TRLBTU.A | E14: trillion Btu | G14: 951.50281 | H14: 942.55829 | I14: 925.34039 | J14: 912.45154 | K14: 903.11096 | L14: 894.80664 | M14: 888.38452 | N14: 882.9956 | O14: 877.03247 | P14: 872.79089 | Q14: 871.79065 | R14: 871.86755 | S14: 873.03363 | T14: 875.07349 | U14: 877.49945 | V14: 881.02332 | W14: 885.54096 | X14: 889.79608 | Y14: 896.14636 | Z14: 903.92438 | AA14: 911.92645 | AB14: 919.0462 | AC14: 925.474 | AD14: 932.77234 | AE14: 941.2807 | AF14: 951.49884 | AG14: 960.51416 | AH14: 969.5788 | AI14: 981.5957 | AJ14: 0.001 | AK14: 0.009
B15: Motor Gasoline excluding E85 | C15: Transportation Energy Use: Commercial Light Trucks: Motor Gasoline: Reference case | D15: AEO.2023.REF2023.CNSM_NA_TRN_CLTR_MGS_NA_NA_TRLBTU.A | E15: trillion Btu | G15: 657.76746 | H15: 651.25983 | I15: 640.80762 | J15: 634.44543 | K15: 630.82428 | L15: 624.78125 | M15: 620.94763 | N15: 618.08075 | O15: 615.03595 | P15: 613.48315 | Q15: 614.07129 | R15: 615.42194 | S15: 617.64148 | T15: 620.38318 | U15: 623.32221 | V15: 627.02631 | W15: 631.23346 | X15: 635.20404 | Y15: 640.80859 | Z15: 646.77948 | AA15: 653.38257 | AB15: 659.03369 | AC15: 663.90283 | AD15: 669.03552 | AE15: 675.10999 | AF15: 682.46606 | AG15: 688.97082 | AH15: 695.63995 | AI15: 704.23315 | AJ15: 0.002 | AK15: 0.008
B16: E85 | C16: Transportation Energy Use: Commercial Light Trucks: E85: Reference case | D16: AEO.2023.REF2023.CNSM_NA_TRN_CLTR_E85_NA_NA_TRLBTU.A | E16: trillion Btu | G16: 3.51367 | H16: 3.389497 | I16: 2.991625 | J16: 2.903706 | K16: 2.76768 | L16: 2.708098 | M16: 2.664845 | N16: 2.671002 | O16: 2.68058 | P16: 2.705457 | Q16: 2.745193 | R16: 2.803118 | S16: 2.875419 | T16: 2.972388 | U16: 3.075218 | V16: 3.206507 | W16: 3.350161 | X16: 3.50104 | Y16: 3.666781 | Z16: 3.843432 | AA16: 4.016943 | AB16: 4.194909 | AC16: 4.354052 | AD16: 4.515519 | AE16: 4.667729 | AF16: 4.835943 | AG16: 4.97936 | AH16: 5.131686 | AI16: 5.282454 | AJ16: 0.015 | AK16: 0.047
B17: Distillate Fuel Oil (diesel) | C17: Transportation Energy Use: Commercial Light Trucks: Distillate Fuel Oil: Reference case | D17: AEO.2023.REF2023.CNSM_NA_TRN_CLTR_DFO_NA_NA_TRLBTU.A | E17: trillion Btu | G17: 289.12039 | H17: 286.82144 | I17: 280.46921 | J17: 274.07837 | K17: 268.54092 | L17: 266.37576 | M17: 263.84299 | N17: 261.31543 | O17: 258.40118 | P17: 255.69388 | Q17: 254.05814 | R17: 252.70514 | S17: 251.54263 | T17: 250.69047 | U17: 250.00555 | V17: 249.60524 | W17: 249.66022 | X17: 249.65735 | Y17: 250.07077 | Z17: 251.50558 | AA17: 252.50731 | AB17: 253.54639 | AC17: 254.6667 | AD17: 256.36206 | AE17: 258.3045 | AF17: 260.63464 | AG17: 262.62152 | AH17: 264.4642 | AI17: 267.30786 | AJ17: -0.003 | AK17: 0.008
... B19: Compressed/Liquefied Natural Gas | C19: Transportation Energy Use: Commercial Light Trucks: Natural Gas: Reference case | D19: AEO.2023.REF2023.CNSM_NA_TRN_CLTR_NG_NA_NA_TRLBTU.A | E19: trillion Btu | G19: 1.100109 | H19: 1.028096 | I19: 0.954857 | J19: 0.851628 | K19: 0.748517 | L19: 0.657968 | M19: 0.592555 | N19: 0.535011 | O19: 0.478159 | P19: 0.423993 | Q19: 0.376664 | R19: 0.335485 | S19: 0.300891 | T19: 0.271073 | U19: 0.243198 | V19: 0.217586 | W19: 0.194927 | X19: 0.176079 | Y19: 0.160581 | Z19: 0.146182 | AA19: 0.133464 | AB19: 0.121475 | AC19: 0.110383 | AD19: 0.099974 | AE19: 0.087947 | AF19: 0.07232 | AG19: 0.057146 | AH19: 0.045076 | AI19: 0.03417 | AJ19: -0.117 | AK19: -0.013
B20: Electricity | C20: Transportation Energy Use: Commercial Light Trucks: Electricity: Reference case | D20: AEO.2023.REF2023.CNSM_NA_TRN_CLTR_ELC_NA_NA_TRLBTU.A | E20: trillion Btu | G20: 0 | H20: 0 | I20: 0 | J20: 0 | K20: 0 | L20: 0 | M20: 0 | N20: 0 | O20: 0 | P20: 0 | Q20: 0 | R20: 0 | S20: 0 | T20: 0 | U20: 0 | V20: 0 | W20: 0 | X20: 0 | Y20: 0 | Z20: 0 | AA20: 0 | AB20: 0 | AC20: 0 | AD20: 0 | AE20: 0 | AF20: 0 | AG20: 0 | AH20: 0 | AI20: 0 | AJ20: - - | AK20: 0.115
B21: Hydrogen | C21: Transportation Energy Use: Commercial Light Trucks: Hydrogen: Reference case | D21: AEO.2023.REF2023.CNSM_NA_TRN_CLTR_HDG_NA_NA_TRLBTU.A | E21: trillion Btu | G21: 0 | H21: 0 | I21: 0 | J21: 0 | K21: 0 | L21: 0 | M21: 0 | N21: 0 | O21: 0 | P21: 0 | Q21: 0 | R21: 0 | S21: 0 | T21: 0 | U21: 0 | V21: 0 | W21: 0 | X21: 0 | Y21: 0 | Z21: 0 | AA21: 0 | AB21: 0 | AC21: 0 | AD21: 0 | AE21: 0 | AF21: 0 | AG21: 0 | AH21: 0 | AI21: 0 | AJ21: - - | AK21: - -
B22: Freight Trucks | C22: Transportation Energy Use: Freight Trucks: Total: Reference case | D22: AEO.2023.REF2023.CNSM_NA_TRN_FRTT_NA_NA_NA_TRLBTU.A | E22: trillion Btu | G22: 5922.791 | H22: 5816.7056 | I22: 5728.0952 | J22: 5673.0986 | K22: 5638.8965 | L22: 5591.7085 | M22: 5543.7119 | N22: 5483.6694 | O22: 5422.3887 | P22: 5371.3027 | Q22: 5340.1582 | R22: 5306.5049 | S22: 5278.7798 | T22: 5261.2471 | U22: 5242.999 | V22: 5237.6973 | W22: 5236.3618 | X22: 5238.3042 | Y22: 5247.9146 | Z22: 5263.2085 | AA22: 5281.4541 | AB22: 5299.6816 | AC22: 5316.7681 | AD22: 5331.7002 | AE22: 5353.1992 | AF22: 5376.3164 | AG22: 5393.3179 | AH22: 5413.417 | AI22: 5450.0122 | AJ22: -0.003 | AK22: 0.005
B23: Motor Gasoline | C23: Transportation Energy Use: Freight Trucks: Motor Gasoline: Reference case | D23: AEO.2023.REF2023.CNSM_NA_TRN_FRTT_MGS_NA_NA_TRLBTU.A | E23: trillion Btu | G23: 616.2052 | H23: 611.60089 | I23: 610.37268 | J23: 612.19367 | K23: 616.9259 | L23: 620.02863 | M23: 623.43561 | N23: 626.1109 | O23: 629.31873 | P23: 633.79578 | Q23: 641.25617 | R23: 647.76111 | S23: 654.28461 | T23: 661.13013 | U23: 667.05139 | V23: 674.55737 | W23: 681.19171 | X23: 688.82941 | Y23: 697.0672 | Z23: 706.54358 | AA23: 715.97064 | AB23: 725.08044 | AC23: 734.18097 | AD23: 743.18781 | AE23: 753.50971 | AF23: 764.21655 | AG23: 774.0188 | AH23: 784.56543 | AI23: 797.65808 | AJ23: 0.009 | AK23: 0.017
B24: Distillate Fuel Oil (diesel) | C24: Transportation Energy Use: Freight Trucks: Distillate Fuel Oil: Reference case | D24: AEO.2023.REF2023.CNSM_NA_TRN_FRTT_DFO_NA_NA_TRLBTU.A | E24: trillion Btu | G24: 5252.3306 | H24: 5150.2441 | I24: 5062.3154 | J24: 5004.9751 | K24: 4965.6987 | L24: 4915.5693 | M24: 4864.6592 | N24: 4802.8213 | O24: 4739.4141 | P24: 4684.7788 | Q24: 4646.6831 | R24: 4606.6587 | S24: 4572.083 | T24: 4546.9648 | U24: 4521.8164 | V24: 4507.6465 | W24: 4498.0513 | X24: 4490.4604 | Y24: 4489.5615 | Z24: 4492.7368 | AA24: 4498.6597 | AB24: 4504.667 | AC24: 4509.3804 | AD24: 4511.9082 | AE24: 4519.4395 | AF24: 4527.9907 | AG24: 4531.3125 | AH24: 4536.8086 | AI24: 4555.8003 | AJ24: -0.005 | AK24: 0.003
B25: Compressed/Liquefied Natural Gas | C25: Transportation Energy Use: Freight Trucks: Natural Gas: Reference case | D25: AEO.2023.REF2023.CNSM_NA_TRN_FRTT_NG_NA_NA_TRLBTU.A | E25: trillion Btu | G25: 51.344929 | H25: 51.773193 | I25: 51.965775 | J25: 52.061794 | K25: 52.003609 | L25: 51.453991 | M25: 50.587242 | N25: 49.35791 | O25: 47.935226 | P25: 46.656029 | Q25: 45.774757 | R25: 45.265823 | S25: 45.213749 | T25: 45.570152 | U25: 46.181812 | V25: 47.148071 | W25: 48.373516 | X25: 49.850357 | Y25: 51.657871 | Z25: 53.785 | AA25: 56.128628 | AB25: 58.653038 | AC25: 61.32283 | AD25: 64.089226 | AE25: 67.060806 | AF25: 70.195709 | AG25: 73.347763 | AH25: 76.647514 | AI25: 80.336479 | AJ25: 0.016 | AK25: 0.022
B26: Propane | C26: Transportation Energy Use: Freight Trucks: Propane: Reference case | D26: AEO.2023.REF2023.CNSM_NA_TRN_FRTT_LPG_NA_NA_TRLBTU.A | E26: trillion Btu | G26: 1.245265 | H26: 1.386178 | I26: 1.524881 | J26: 1.656008 | K26: 1.786266 | L26: 1.903707 | M26: 2.010578 | N26: 2.099689 | O26: 2.180499 | P26: 2.260465 | Q26: 2.347809 | R26: 2.440473 | S26: 2.541221 | T26: 2.644983 | U26: 2.752405 | V26: 2.87385 | W26: 3.004591 | X26: 3.149585 | Y26: 3.313908 | Z26: 3.500602 | AA26: 3.702072 | AB26: 3.917007 | AC26: 4.141416 | AD26: 4.376885 | AE26: 4.632447 | AF26: 4.901746 | AG26: 5.174631 | AH26: 5.447477 | AI26: 5.745036 | AJ26: 0.056 | AK26: 0.045
