Workbook
Name lignite_multiplier: '[1]Hard Coal and Lig Multipliers'!$N$16
Name nonlignite_multiplier: '[1]Hard Coal and Lig Multipliers'!$N$17

Sheet About
A1: EIaE BAU Imported Electricity
A2: EIaE BAU Exported Electricity
A3: EIaE Imported Electricity Price
A4: EIaE BAU Exported Electricity Price
A6: Source: | B6: Quantity of Imports and Exports
B7: U.S. Energy Information Administration
B8: 2026
B9: Annual Energy Outlook 2026
B10: Alternative electricity and transportation: Table 10
B11: https://www.eia.gov/outlooks/aeo/tables_side_xls.php
B13: Canadian Electricity Generation by Type
B14: National Energy Board, Government of Canada
B15: 2021
B16: Canada's Energy Future 2021, Appendices
B17: https://apps.neb-one.gc.ca/ftrppndc/dflt.aspx?GoCTemplateCulture=en-CA
B18: Table "Electricity Generation," Reference Case, Canada
B20: Imported and Exported Electricity Prices
B21: U.S. Energy Information Administration
B22: 2026
B23: Annual Energy Outlook 2026
B24: Alternative electricity and transportation: Table 10
B25: https://www.eia.gov/outlooks/aeo/tables_side_xls.php
B27: Canada NG Generation by Turbine Type
B28: Statistics Canada
B29: 2022
B30: Electric power generation, monthly generation by type of electricity
B31: https://www150.statcan.gc.ca/t1/tbl1/en/tv.action?pid=2510001501&pickMembers%5B0%5D=1.1&pickMembers%5B1%5D=2.2&cubeTimeFrame.startMonth=01&cubeTimeFrame.startYear=2015&cubeTimeFrame.endMonth=12&cubeTimeFrame.endYear=2015&referencePeriods=20150101%2C20151201
B32: Data after 2015 does not break out turbine types, so we use data from 2015.
A34: Notes
A35: We need to know the mix of imported electricity types if we will be including
A36: pollutant emissions associated with imported electricity into the totals, which
A37: is managed by a control lever. If these emissions will not be included in the
A38: emissions totals, the breakdown is unimportant, and you may assign all
A39: imported electricity emissions to any one electricity source, if you prefer.
A41: Electricity exports are supplied by power plants in the modeled region and
A42: hence do not need their electricity source to be specified here.
A44: Since electricity imported to the U.S. comes overwhelmingly from Canada,
A45: we use Canada's electricity generation mix to approximate the mix
A46: of all imported electricity.
A48: All Canadian natural gas was assigned to the "natural gas nonpeaker" plant type
...

Sheet Source Data>

Sheet AEO Table 10 2025
A1: Table 10. Electricity Trade
A2: https://www.eia.gov/outlooks/aeo/data/browser/#/?id=10-AEO2025&cases=highZTC&sourcekey=0
A3: Tue Dec 02 2025 13:19:25 GMT-0800 (Pacific Standard Time)
A4: Source: U.S. Energy Information Administration
B5: full name | C5: api key | D5: units | E5: 2023 | F5: 2024 | G5: 2025 | H5: 2026 | I5: 2027 | J5: 2028 | K5: 2029 | L5: 2030 | M5: 2031 | N5: 2032 | O5: 2033 | P5: 2034 | Q5: 2035 | R5: 2036 | S5: 2037 | T5: 2038 | U5: 2039 | V5: 2040 | W5: 2041 | X5: 2042 | Y5: 2043 | Z5: 2044 | AA5: 2045 | AB5: 2046 | AC5: 2047 | AD5: 2048 | AE5: 2049 | AF5: 2050 | AG5: Growth (2024-2050)
A6: Interregional Electricity Trade
A7: Gross Domestic Sales
A8: Firm Power | B8: Electricity Trade: Gross Domestic Sales: Firm Power: High Zero-Carbon Technology Cost | C8: AEO.2025.HIGHZTC.TRAD_FPW_ELEP_GDSE_SAL_NA_USA_BLNKWH.A | D8: BkWh | F8: 45.122738 | G8: 43.267342 | H8: 43.046135 | I8: 42.817745 | J8: 42.559059 | K8: 42.293133 | L8: 42.024811 | M8: 41.620968 | N8: 41.217125 | O8: 40.813286 | P8: 40.156345 | Q8: 39.466721 | R8: 38.769127 | S8: 37.904129 | T8: 37.069424 | U8: 36.021156 | V8: 34.9147 | W8: 33.94376 | X8: 32.853245 | Y8: 31.762728 | Z8: 31.010212 | AA8: 30.418716 | AB8: 29.843166 | AC8: 29.442196 | AD8: 29.041224 | AE8: 28.861069 | AF8: 28.741493 | AG8: -0.017
A9: Economy | B9: Electricity Trade: Gross Domestic Sales: Economy: High Zero-Carbon Technology Cost | C9: AEO.2025.HIGHZTC.TRAD_ECN_ELEP_GDSE_SAL_NA_USA_BLNKWH.A | D9: BkWh | F9: 249.34067 | G9: 237.90076 | H9: 224.18767 | I9: 252.91287 | J9: 276.10901 | K9: 290.98074 | L9: 319.57144 | M9: 301.05426 | N9: 347.96228 | O9: 365.80243 | P9: 385.14499 | Q9: 402.39383 | R9: 398.53207 | S9: 421.89496 | T9: 440.45383 | U9: 465.01849 | V9: 502.0437 | W9: 519.92114 | X9: 527.19287 | Y9: 512.67108 | Z9: 508.11087 | AA9: 511.39545 | AB9: 502.66962 | AC9: 509.82706 | AD9: 502.75842 | AE9: 516.5943 | AF9: 523.46216 | AG9: 0.029
A10: Total Gross Domestic Sales | B10: Electricity Trade: Gross Domestic Sales: Total: High Zero-Carbon Technology Cost | C10: AEO.2025.HIGHZTC.TRAD_TOT_ELEP_GDSE_SAL_NA_USA_BLNKWH.A | D10: BkWh | F10: 294.46338 | G10: 281.16812 | H10: 267.23379 | I10: 295.73062 | J10: 318.66809 | K10: 333.27387 | L10: 361.59625 | M10: 342.67523 | N10: 389.17938 | O10: 406.61569 | P10: 425.30133 | Q10: 441.86057 | R10: 437.30121 | S10: 459.79907 | T10: 477.52328 | U10: 501.03964 | V10: 536.95837 | W10: 553.86493 | X10: 560.04614 | Y10: 544.43384 | Z10: 539.12109 | AA10: 541.81415 | AB10: 532.51276 | AC10: 539.26929 | AD10: 531.79962 | AE10: 545.45532 | AF10: 552.20367 | AG10: 0.024
A11: Gross Domestic Sales (million 2024 dollars)
A12: Firm Power | B12: Electricity Trade: Gross Domestic Sales: Firm Power: High Zero-Carbon Technology Cost | C12: AEO.2025.HIGHZTC.KEI_FPW_ELEP_GDSE_SAL_NA_USA_MILLY13DLR.A | D12: million 2024 $ | F12: 3718.7073 | G12: 3565.7986 | H12: 3547.5679 | I12: 3528.7461 | J12: 3507.427 | K12: 3485.5107 | L12: 3463.3979 | M12: 3430.1152 | N12: 3396.8337 | O12: 3363.5518 | P12: 3309.4119 | Q12: 3252.5774 | R12: 3195.0867 | S12: 3123.7993 | T12: 3055.0083 | U12: 2968.6177 | V12: 2877.4314 | W12: 2797.4126 | X12: 2707.5398 | Y12: 2617.667 | Z12: 2555.6499 | AA12: 2506.9031 | AB12: 2459.4697 | AC12: 2426.4246 | AD12: 2393.3794 | AE12: 2378.5317 | AF12: 2368.6775 | AG12: -0.017
A13: Economy | B13: Electricity Trade: Gross Domestic Sales: Economy: High Zero-Carbon Technology Cost | C13: AEO.2025.HIGHZTC.KEI_ECN_ELEP_GDSE_SAL_NA_USA_MILLY13DLR.A | D13: million 2024 $ | F13: 10351.312 | G13: 8023.959 | H13: 7793.375 | I13: 8403.7236 | J13: 9362.542 | K13: 10238.698 | L13: 11769.411 | M13: 11374.511 | N13: 15617.239 | O13: 16802.051 | P13: 17691.258 | Q13: 18451.445 | R13: 17562.094 | S13: 17828.92 | T13: 18883.072 | U13: 19100.727 | V13: 20427.402 | W13: 22106.875 | X13: 22795.535 | Y13: 22820.969 | Z13: 23120.818 | AA13: 23484.168 | AB13: 23698.35 | AC13: 24435.113 | AD13: 24780.49 | AE13: 27138.383 | AF13: 28180.879 | AG13: 0.039
A14: Total Gross Domestic Sales | B14: Electricity Trade: Gross Domestic Sales: Total: High Zero-Carbon Technology Cost | C14: AEO.2025.HIGHZTC.KEI_TOT_ELEP_GDSE_SAL_NA_USA_MILLY13DLR.A | D14: million 2024 $ | F14: 14070.019 | G14: 11589.758 | H14: 11340.943 | I14: 11932.47 | J14: 12869.969 | K14: 13724.209 | L14: 15232.809 | M14: 14804.626 | N14: 19014.072 | O14: 20165.602 | P14: 21000.67 | Q14: 21704.023 | R14: 20757.18 | S14: 20952.719 | T14: 21938.08 | U14: 22069.344 | V14: 23304.834 | W14: 24904.287 | X14: 25503.074 | Y14: 25438.637 | Z14: 25676.469 | AA14: 25991.07 | AB14: 26157.82 | AC14: 26861.537 | AD14: 27173.869 | AE14: 29516.914 | AF14: 30549.557 | AG14: 0.03
A15: International Electricity Trade
A16: Imports from Canada and Mexico
A17: Firm Power | B17: Electricity Trade: Imports from Canada and Mexico: Firm Power: High Zero-Carbon Technology Cost | C17: AEO.2025.HIGHZTC.TRAD_FPW_ELEP_ICME_IMP_CANMEX_USA_BLNKWH.A | D17: BkWh | F17: 16.437441 | G17: 25.2062 | H17: 25.2062 | I17: 36.334553 | J17: 36.334553 | K17: 36.270779 | L17: 36.207008 | M17: 36.143234 | N17: 36.079464 | O17: 36.01569 | P17: 35.951916 | Q17: 35.888142 | R17: 35.545364 | S17: 35.48159 | T17: 35.41782 | U17: 35.41782 | V17: 35.41782 | W17: 35.41782 | X17: 35.41782 | Y17: 26.649057 | Z17: 26.649057 | AA17: 26.649057 | AB17: 26.649057 | AC17: 26.649057 | AD17: 26.649057 | AE17: 26.649057 | AF17: 26.649057 | AG17: 0.019
A18: Economy | B18: Electricity Trade: Imports from Canada and Mexico: Economy: High Zero-Carbon Technology Cost | C18: AEO.2025.HIGHZTC.TRAD_ECN_ELEP_ICME_IMP_CANMEX_USA_BLNKWH.A | D18: BkWh | F18: 29.155848 | G18: 25.677845 | H18: 32.730957 | I18: 39.317871 | J18: 51.182159 | K18: 56.444569 | L18: 64.044449 | M18: 66.023598 | N18: 67.974152 | O18: 70.4571 | P18: 71.004646 | Q18: 72.311829 | R18: 70.41851 | S18: 69.43647 | T18: 69.029602 | U18: 66.713844 | V18: 68.071274 | W18: 68.488014 | X18: 67.780701 | Y18: 70.681862 | Z18: 70.270073 | AA18: 69.597511 | AB18: 64.902161 | AC18: 61.668133 | AD18: 59.742859 | AE18: 56.808781 | AF18: 54.116707 | AG18: 0.024
A19: Total Imports from Canada and Mexico | B19: Electricity Trade: Imports from Canada and Mexico: Total: High Zero-Carbon Technology Cost | C19: AEO.2025.HIGHZTC.TRAD_TOT_ELEP_ICME_IMP_CANMEX_USA_BLNKWH.A | D19: BkWh | F19: 45.593288 | G19: 50.884045 | H19: 57.93716 | I19: 75.652428 | J19: 87.516708 | K19: 92.715347 | L19: 100.25146 | M19: 102.16683 | N19: 104.05361 | O19: 106.47279 | P19: 106.95656 | Q19: 108.19997 | R19: 105.96388 | S19: 104.91807 | T19: 104.44743 | U19: 102.13166 | V19: 103.4891 | W19: 103.90583 | X19: 103.19852 | Y19: 97.330917 | Z19: 96.919128 | AA19: 96.246567 | AB19: 91.551224 | AC19: 88.317192 | AD19: 86.391914 | AE19: 83.45784 | AF19: 80.765762 | AG19: 0.022
A20: Exports to Canada and Mexico
A21: Firm Power | B21: Electricity Trade: Exports to Canada and Mexico: Firm Power: High Zero-Carbon Technology Cost | C21: AEO.2025.HIGHZTC.TRAD_FPW_ELEP_EXCM_IMP_CANMEX_USA_BLNKWH.A | D21: BkWh | F21: 1.19574 | G21: 1.19574 | H21: 1.19574 | I21: 1.19574 | J21: 1.19574 | K21: 1.19574 | L21: 1.19574 | M21: 1.076166 | N21: 0.956592 | O21: 0.837018 | P21: 0.717444 | Q21: 0.59787 | R21: 0.478296 | S21: 0.358722 | T21: 0.239148 | U21: 0.119574 | V21: 0 | W21: 0 | X21: 0 | Y21: 0 | Z21: 0 | AA21: 0 | AB21: 0 | AC21: 0 | AD21: 0 | AE21: 0 | AF21: 0 | AG21: -1
A22: Economy | B22: Electricity Trade: Exports to Canada and Mexico: Economy: High Zero-Carbon Technology Cost | C22: AEO.2025.HIGHZTC.TRAD_ECN_ELEP_EXCM_IMP_CANMEX_USA_BLNKWH.A | D22: BkWh | F22: 14.989228 | G22: 14.989228 | H22: 14.989228 | I22: 14.989228 | J22: 14.989228 | K22: 14.989228 | L22: 14.989228 | M22: 15.108803 | N22: 15.228375 | O22: 15.34795 | P22: 15.467525 | Q22: 15.587098 | R22: 15.706673 | S22: 15.826247 | T22: 15.945821 | U22: 16.065393 | V22: 16.184969 | W22: 16.184969 | X22: 16.184969 | Y22: 16.184969 | Z22: 16.184969 | AA22: 16.184969 | AB22: 16.184969 | AC22: 16.184969 | AD22: 16.184969 | AE22: 16.184969 | AF22: 16.184969 | AG22: 0.003
A23: Total Exports to Canada and Mexico | B23: Electricity Trade: Exports to Canada and Mexico: Total: High Zero-Carbon Technology Cost | C23: AEO.2025.HIGHZTC.TRAD_TOT_ELEP_EXCM_IMP_CANMEX_USA_BLNKWH.A | D23: BkWh | F23: 16.184969 | G23: 16.184969 | H23: 16.184969 | I23: 16.184969 | J23: 16.184969 | K23: 16.184969 | L23: 16.184969 | M23: 16.184969 | N23: 16.184967 | O23: 16.184967 | P23: 16.184969 | Q23: 16.184969 | R23: 16.184969 | S23: 16.184969 | T23: 16.184969 | U23: 16.184969 | V23: 16.184969 | W23: 16.184969 | X23: 16.184969 | Y23: 16.184969 | Z23: 16.184969 | AA23: 16.184969 | AB23: 16.184969 | AC23: 16.184969 | AD23: 16.184969 | AE23: 16.184969 | AF23: 16.184969 | AG23: 0

Sheet Canada Generation Projection
A1: Select Report Version: Canada’s Energy Future 2021
A2: Select Appendices: Electricity Generation
A3: Select Case: Evolving Policies
A4: Select Type: Primary Fuel
A7: Canada
A8: _ | B8: 2005 | C8: 2006 | D8: 2007 | E8: 2008 | F8: 2009 | G8: 2010 | H8: 2011 | I8: 2012 | J8: 2013 | K8: 2014 | L8: 2015 | M8: 2016 | N8: 2017 | O8: 2018 | P8: 2019 | Q8: 2020 | R8: 2021 | S8: 2022 | T8: 2023 | U8: 2024 | V8: 2025 | W8: 2026 | X8: 2027 | Y8: 2028 | Z8: 2029 | AA8: 2030 | AB8: 2031 | AC8: 2032 | AD8: 2033 | AE8: 2034 | AF8: 2035 | AG8: 2036 | AH8: 2037 | AI8: 2038 | AJ8: 2039 | AK8: 2040 | AL8: 2041 | AM8: 2042 | AN8: 2043 | AO8: 2044 | AP8: 2045 | AQ8: 2046 | AR8: 2047 | AS8: 2048 | AT8: 2049 | AU8: 2050
A9: Hydro / Wave / Tidal | B9: 358380.8 | C9: 349124.5 | D9: 363798.5 | E9: 373817.3 | F9: 365011.8 | G9: 347937.5 | H9: 371953.2 | I9: 375760.2 | J9: 387396.2 | K9: 378786.2 | L9: 378498.4 | M9: 381710.1 | N9: 390771.5 | O9: 382163.9 | P9: 375998.3 | Q9: 386156.5 | R9: 392952.2 | S9: 414009.7 | T9: 419884.8 | U9: 420564 | V9: 426253.5 | W9: 426438 | X9: 426601.5 | Y9: 426631.5 | Z9: 426216.6 | AA9: 434736.9 | AB9: 435601.5 | AC9: 435569.8 | AD9: 435924.3 | AE9: 437012.9 | AF9: 437761.2 | AG9: 439366.8 | AH9: 440272.5 | AI9: 440771.5 | AJ9: 441186.3 | AK9: 441464.6 | AL9: 442329.7 | AM9: 442987.3 | AN9: 443420.1 | AO9: 443696.5 | AP9: 444111.5 | AQ9: 444504.2 | AR9: 445041.1 | AS9: 445453.3 | AT9: 445232.7 | AU9: 446455.8
A10: Wind | B10: 1453.41 | C10: 2529.41 | D10: 3683.41 | E10: 4715.44 | F10: 7031.23 | G10: 8354.23 | H10: 11622.99 | I10: 13716.78 | J10: 17544.74 | K10: 21484.5 | L10: 26692.57 | M10: 30624 | N10: 31197 | O10: 32814.01 | P10: 32333 | Q10: 35393.52 | R10: 37205.53 | S10: 48919.51 | T10: 49031.61 | U10: 52057.91 | V10: 54360.89 | W10: 54962.97 | X10: 62089.04 | Y10: 65911.72 | Z10: 70643.33 | AA10: 79872.47 | AB10: 86951.15 | AC10: 93863.48 | AD10: 94757.65 | AE10: 96735.03 | AF10: 98444.02 | AG10: 101702.69 | AH10: 105080.85 | AI10: 112793.77 | AJ10: 116892.24 | AK10: 124088.41 | AL10: 129402.83 | AM10: 138717.12 | AN10: 144897.52 | AO10: 155135.9 | AP10: 159912.83 | AQ10: 169032.28 | AR10: 173414.12 | AS10: 180922.35 | AT10: 184784.68 | AU10: 188617.4
A11: Biomass / Geothermal | B11: 6997.43 | C11: 7143.38 | D11: 6971.02 | E11: 6319.81 | F11: 6057.39 | G11: 8266.52 | H11: 8716.9 | I11: 9038.92 | J11: 9208.18 | K11: 11997.93 | L11: 8462.34 | M11: 10240.42 | N11: 6300.36 | O11: 9260.97 | P11: 8892.72 | Q11: 7758.32 | R11: 7918.38 | S11: 8085.39 | T11: 8145.5 | U11: 8172.13 | V11: 8203.73 | W11: 8229 | X11: 8180.23 | Y11: 8103.16 | Z11: 8045.48 | AA11: 7905.92 | AB11: 7834.53 | AC11: 7690.12 | AD11: 7689.75 | AE11: 7650.3 | AF11: 7634.06 | AG11: 7693.85 | AH11: 7715.96 | AI11: 7725.27 | AJ11: 7761.59 | AK11: 7755.49 | AL11: 7782.51 | AM11: 7774.67 | AN11: 7744.41 | AO11: 7721.08 | AP11: 7695.88 | AQ11: 7712.57 | AR11: 7701.84 | AS11: 7680.33 | AT11: 7670.09 | AU11: 7658.64
A12: Solar | B12: 0 | C12: 0 | D12: 0 | E12: 0 | F12: 5 | G12: 123 | H12: 398 | I12: 842 | J12: 1173 | K12: 1757.71 | L12: 1426 | M12: 1779 | N12: 2001 | O12: 2191 | P12: 2194 | Q12: 2254.11 | R12: 2590.53 | S12: 3479.48 | T12: 3729.67 | U12: 4101.36 | V12: 4339.71 | W12: 4948.63 | X12: 5294.32 | Y12: 5402.63 | Z12: 6775.5 | AA12: 7795.56 | AB12: 8732.41 | AC12: 9823.47 | AD12: 11227.58 | AE12: 12784.3 | AF12: 16546.83 | AG12: 18243.05 | AH12: 20134.38 | AI12: 22116.59 | AJ12: 24421.73 | AK12: 28835.14 | AL12: 32492.45 | AM12: 36514.71 | AN12: 41164.5 | AO12: 45590.8 | AP12: 51145.22 | AQ12: 54488.5 | AR12: 56975.57 | AS12: 58937.9 | AT12: 60762.67 | AU12: 62179.97
A13: Uranium | B13: 86668.58 | C13: 92144.58 | D13: 88190.58 | E13: 90585.23 | F13: 84992.27 | G13: 85526.59 | H13: 88291.22 | I13: 89487.62 | J13: 97581.99 | K13: 101207.8 | L13: 96045.98 | M13: 95687.01 | N13: 95565 | O13: 95029.01 | P13: 95470 | Q13: 83454.6 | R13: 78636.44 | S13: 81051.16 | T13: 69916.27 | U13: 80287.2 | V13: 73386.14 | W13: 68045.74 | X13: 74340.98 | Y13: 80779.09 | Z13: 75834.09 | AA13: 82677.41 | AB13: 75980.73 | AC13: 82824.05 | AD13: 82864.78 | AE13: 89708.09 | AF13: 91531.05 | AG13: 91531.05 | AH13: 91572.66 | AI13: 91572.66 | AJ13: 91655.88 | AK13: 91822.32 | AL13: 87048.12 | AM13: 87214.55 | AN13: 87381 | AO13: 92942.27 | AP13: 93150.33 | AQ13: 93566.44 | AR13: 94398.65 | AS13: 95230.82 | AT13: 96063.03 | AU13: 96063.03
A14: Coal & Coke | B14: 97362.16 | C14: 92204.69 | D14: 97287.24 | E14: 91097.93 | F14: 76661.64 | G14: 71258.57 | H14: 65177.45 | I14: 63091.11 | J14: 64779.21 | K14: 64238.38 | L14: 57142.41 | M14: 57243.38 | N14: 55265.55 | O14: 46520.81 | P14: 44038.21 | Q14: 31125.9 | R14: 35373.81 | S14: 19471.19 | T14: 5484.64 | U14: 5565.84 | V14: 4949.22 | W14: 4771.36 | X14: 4351.34 | Y14: 3905.76 | Z14: 3916.5 | AA14: 3738.32 | AB14: 3737.32 | AC14: 2584.93 | AD14: 2627.06 | AE14: 2645 | AF14: 2456.07 | AG14: 2499.37 | AH14: 2532.17 | AI14: 2500.78 | AJ14: 2120.31 | AK14: 2074.75 | AL14: 104.48 | AM14: 99.27 | AN14: 99.59 | AO14: 94.46 | AP14: 94.46 | AQ14: 90.07 | AR14: 90.72 | AS14: 86.92 | AT14: 87.73 | AU14: 88.62
A15: Natural Gas | B15: 40015.8 | C15: 43057.99 | D15: 47278.59 | E15: 43912.88 | F15: 42619.74 | G15: 54093.18 | H15: 63514.07 | I15: 63899.03 | J15: 60403.56 | K15: 59038.3 | L15: 65743.65 | M15: 63421.96 | N15: 62934.24 | O15: 66979.59 | P15: 69561.62 | Q15: 74470.26 | R15: 76989.41 | S15: 83922.45 | T15: 101916.1 | U15: 96186.95 | V15: 99728.41 | W15: 105182.5 | X15: 96821.06 | Y15: 93319.9 | Z15: 95666.85 | AA15: 88717.43 | AB15: 92233 | AC15: 85495.38 | AD15: 85813.2 | AE15: 82220.93 | AF15: 81566.97 | AG15: 70336.41 | AH15: 70043.93 | AI15: 68278.8 | AJ15: 68627.71 | AK15: 67198.62 | AL15: 67266.27 | AM15: 67505.6 | AN15: 68650.61 | AO15: 67873.7 | AP15: 68202.07 | AQ15: 67896.58 | AR15: 68472.27 | AS15: 68041.43 | AT15: 68614.28 | AU15: 69154.7
A16: Oil | B16: 8193.96 | C16: 7877.58 | D16: 8776.76 | E16: 6929.51 | F16: 7336.52 | G16: 5187.67 | H16: 4561.87 | I16: 4271.87 | J16: 4071.33 | K16: 6616.76 | L16: 5266.72 | M16: 5087.45 | N16: 4150.07 | O16: 4189.29 | P16: 3719.72 | Q16: 3511.56 | R16: 3358.75 | S16: 3196.07 | T16: 3370.57 | U16: 2789.51 | V16: 3529.05 | W16: 6677.83 | X16: 4558.28 | Y16: 3428.4 | Z16: 5989.77 | AA16: 2608.05 | AB16: 7298.25 | AC16: 4931.98 | AD16: 5902.13 | AE16: 4773.99 | AF16: 4550.53 | AG16: 6077.36 | AH16: 5635.85 | AI16: 5525.19 | AJ16: 5859.8 | AK16: 5233.61 | AL16: 7917.99 | AM16: 5884.44 | AN16: 6604.3 | AO16: 4278.48 | AP16: 4863.56 | AQ16: 4581.3 | AR16: 4987.65 | AS16: 4371.99 | AT16: 4825.29 | AU16: 5720.7
A18: Newfoundland and Labrador
A19: _ | B19: 2005 | C19: 2006 | D19: 2007 | E19: 2008 | F19: 2009 | G19: 2010 | H19: 2011 | I19: 2012 | J19: 2013 | K19: 2014 | L19: 2015 | M19: 2016 | N19: 2017 | O19: 2018 | P19: 2019 | Q19: 2020 | R19: 2021 | S19: 2022 | T19: 2023 | U19: 2024 | V19: 2025 | W19: 2026 | X19: 2027 | Y19: 2028 | Z19: 2029 | AA19: 2030 | AB19: 2031 | AC19: 2032 | AD19: 2033 | AE19: 2034 | AF19: 2035 | AG19: 2036 | AH19: 2037 | AI19: 2038 | AJ19: 2039 | AK19: 2040 | AL19: 2041 | AM19: 2042 | AN19: 2043 | AO19: 2044 | AP19: 2045 | AQ19: 2046 | AR19: 2047 | AS19: 2048 | AT19: 2049 | AU19: 2050
A20: Hydro / Wave / Tidal | B20: 40741.37 | C20: 41953.37 | D20: 40291.38 | E20: 41897.25 | F20: 36728 | G20: 40286.8 | H20: 40033.37 | I20: 42202.52 | J20: 41441.68 | K20: 39047.83 | L20: 39686 | M20: 39482.99 | N20: 36548 | O20: 41831 | P20: 40798 | Q20: 44285.91 | R20: 50459.12 | S20: 51302.94 | T20: 51450.95 | U20: 51596.33 | V20: 51687.53 | W20: 51766.57 | X20: 51847.05 | Y20: 52209.73 | Z20: 52221 | AA20: 52233.74 | AB20: 52247.11 | AC20: 52260.72 | AD20: 52273.37 | AE20: 52285.32 | AF20: 52368.24 | AG20: 52433.39 | AH20: 52442.84 | AI20: 52449.65 | AJ20: 52447.73 | AK20: 52450.65 | AL20: 52451.59 | AM20: 52454.57 | AN20: 52458.66 | AO20: 52458.86 | AP20: 52458.86 | AQ20: 52458.83 | AR20: 52458.85 | AS20: 52458.8 | AT20: 52458.82 | AU20: 52458.85
A21: Wind | B21: 0 | C21: 0 | D21: 0 | E21: 0 | F21: 102 | G21: 183 | H21: 198 | I21: 195 | J21: 192 | K21: 176.96 | L21: 172 | M21: 190 | N21: 186 | O21: 206 | P21: 182 | Q21: 181.8 | R21: 181.83 | S21: 181.91 | T21: 181.92 | U21: 181.93 | V21: 181.94 | W21: 182 | X21: 182.01 | Y21: 182.09 | Z21: 182.15 | AA21: 183.78 | AB21: 185.55 | AC21: 187.48 | AD21: 189.59 | AE21: 192.37 | AF21: 215.04 | AG21: 228.5 | AH21: 244.79 | AI21: 261.79 | AJ21: 285.81 | AK21: 319.59 | AL21: 371.08 | AM21: 442.3 | AN21: 536.27 | AO21: 643.33 | AP21: 759.27 | AQ21: 860.06 | AR21: 917.13 | AS21: 945.68 | AT21: 967.35 | AU21: 982.55
A22: Biomass / Geothermal | B22: 0 | C22: 0 | D22: 0 | E22: 0 | F22: 0 | G22: 0 | H22: 0 | I22: 0 | J22: 0 | K22: 0 | L22: 0 | M22: 0 | N22: 0 | O22: 0 | P22: 0 | Q22: 0 | R22: 0 | S22: 0 | T22: 0 | U22: 0 | V22: 0 | W22: 0 | X22: 0 | Y22: 0 | Z22: 0 | AA22: 0 | AB22: 0 | AC22: 0 | AD22: 0 | AE22: 0 | AF22: 0 | AG22: 0 | AH22: 0 | AI22: 0 | AJ22: 0 | AK22: 0 | AL22: 0 | AM22: 0 | AN22: 0 | AO22: 0 | AP22: 0 | AQ22: 0 | AR22: 0 | AS22: 0 | AT22: 0 | AU22: 0
A23: Solar | B23: 0 | C23: 0 | D23: 0 | E23: 0 | F23: 0 | G23: 0 | H23: 0 | I23: 0 | J23: 0 | K23: 0 | L23: 0 | M23: 0 | N23: 0 | O23: 0 | P23: 0 | Q23: 0 | R23: 0 | S23: 0 | T23: 0 | U23: 0 | V23: 0 | W23: 0 | X23: 0 | Y23: 0 | Z23: 0 | AA23: 0 | AB23: 0 | AC23: 0 | AD23: 0 | AE23: 0 | AF23: 0 | AG23: 0 | AH23: 0 | AI23: 0 | AJ23: 0 | AK23: 0 | AL23: 0 | AM23: 0 | AN23: 0 | AO23: 0 | AP23: 0 | AQ23: 0 | AR23: 0 | AS23: 0 | AT23: 0 | AU23: 0
A24: Uranium | B24: 0 | C24: 0 | D24: 0 | E24: 0 | F24: 0 | G24: 0 | H24: 0 | I24: 0 | J24: 0 | K24: 0 | L24: 0 | M24: 0 | N24: 0 | O24: 0 | P24: 0 | Q24: 0 | R24: 0 | S24: 0 | T24: 0 | U24: 0 | V24: 0 | W24: 0 | X24: 0 | Y24: 0 | Z24: 0 | AA24: 0 | AB24: 0 | AC24: 0 | AD24: 0 | AE24: 0 | AF24: 0 | AG24: 0 | AH24: 0 | AI24: 0 | AJ24: 0 | AK24: 0 | AL24: 0 | AM24: 0 | AN24: 0 | AO24: 0 | AP24: 0 | AQ24: 0 | AR24: 0 | AS24: 0 | AT24: 0 | AU24: 0
A25: Coal & Coke | B25: 0 | C25: 0 | D25: 0 | E25: 0 | F25: 0 | G25: 0 | H25: 0 | I25: 0 | J25: 0 | K25: 0 | L25: 0 | M25: 0 | N25: 0 | O25: 0 | P25: 0 | Q25: 0 | R25: 0 | S25: 0 | T25: 0 | U25: 0 | V25: 0 | W25: 0 | X25: 0 | Y25: 0 | Z25: 0 | AA25: 0 | AB25: 0 | AC25: 0 | AD25: 0 | AE25: 0 | AF25: 0 | AG25: 0 | AH25: 0 | AI25: 0 | AJ25: 0 | AK25: 0 | AL25: 0 | AM25: 0 | AN25: 0 | AO25: 0 | AP25: 0 | AQ25: 0 | AR25: 0 | AS25: 0 | AT25: 0 | AU25: 0
A26: Natural Gas | B26: 267.07 | C26: 277.82 | D26: 236.77 | E26: 456.94 | F26: 447.62 | G26: 454.97 | H26: 449.29 | I26: 418.8 | J26: 444.36 | K26: 416.68 | L26: 225.22 | M26: 265.72 | N26: 391.17 | O26: 113.27 | P26: 263.31 | Q26: 398.28 | R26: 413.95 | S26: 452.33 | T26: 458.89 | U26: 516.14 | V26: 555.08 | W26: 595.08 | X26: 630.86 | Y26: 341.65 | Z26: 350.7 | AA26: 361.93 | AB26: 370.79 | AC26: 385.85 | AD26: 403.13 | AE26: 422.53 | AF26: 488.69 | AG26: 560.97 | AH26: 566.85 | AI26: 569.88 | AJ26: 566.48 | AK26: 579.49 | AL26: 610.58 | AM26: 657.46 | AN26: 748.67 | AO26: 858.39 | AP26: 1003.78 | AQ26: 1145.14 | AR26: 1243.72 | AS26: 1317.47 | AT26: 1380.75 | AU26: 1413.07
A27: Oil | B27: 1306.21 | C27: 823.06 | D27: 1305.52 | E27: 1139.06 | F27: 1121.59 | G27: 1017.23 | H27: 1039.36 | I27: 998.93 | J27: 1179.72 | K27: 1595.16 | L27: 1669.78 | M27: 1909.28 | N27: 1778.83 | O27: 1483.73 | P27: 1450.69 | Q27: 926.58 | R27: 884.98 | S27: 183.79 | T27: 182.88 | U27: 184.15 | V27: 184.94 | W27: 211.07 | X27: 188.64 | Y27: 190.04 | Z27: 215.06 | AA27: 189.72 | AB27: 240.78 | AC27: 221.96 | AD27: 268.66 | AE27: 227.23 | AF27: 340.15 | AG27: 191.32 | AH27: 219.22 | AI27: 191.44 | AJ27: 204.18 | AK27: 190.3 | AL27: 220.29 | AM27: 185.71 | AN27: 190.24 | AO27: 191.16 | AP27: 194.79 | AQ27: 191.76 | AR27: 191.16 | AS27: 190.61 | AT27: 190.04 | AU27: 189.45
A29: Prince Edward Island
A30: _ | B30: 2005 | C30: 2006 | D30: 2007 | E30: 2008 | F30: 2009 | G30: 2010 | H30: 2011 | I30: 2012 | J30: 2013 | K30: 2014 | L30: 2015 | M30: 2016 | N30: 2017 | O30: 2018 | P30: 2019 | Q30: 2020 | R30: 2021 | S30: 2022 | T30: 2023 | U30: 2024 | V30: 2025 | W30: 2026 | X30: 2027 | Y30: 2028 | Z30: 2029 | AA30: 2030 | AB30: 2031 | AC30: 2032 | AD30: 2033 | AE30: 2034 | AF30: 2035 | AG30: 2036 | AH30: 2037 | AI30: 2038 | AJ30: 2039 | AK30: 2040 | AL30: 2041 | AM30: 2042 | AN30: 2043 | AO30: 2044 | AP30: 2045 | AQ30: 2046 | AR30: 2047 | AS30: 2048 | AT30: 2049 | AU30: 2050
A31: Hydro / Wave / Tidal | B31: 0 | C31: 0 | D31: 0 | E31: 0 | F31: 0 | G31: 0 | H31: 0 | I31: 0 | J31: 0 | K31: 0 | L31: 0 | M31: 0 | N31: 0 | O31: 0 | P31: 0 | Q31: 0 | R31: 0 | S31: 0 | T31: 0 | U31: 0 | V31: 0 | W31: 0 | X31: 0 | Y31: 0 | Z31: 0 | AA31: 0 | AB31: 0 | AC31: 0 | AD31: 0 | AE31: 0 | AF31: 0 | AG31: 0 | AH31: 0 | AI31: 0 | AJ31: 0 | AK31: 0 | AL31: 0 | AM31: 0 | AN31: 0 | AO31: 0 | AP31: 0 | AQ31: 0 | AR31: 0 | AS31: 0 | AT31: 0 | AU31: 0
A32: Wind | B32: 40 | C32: 36 | D32: 40 | E32: 142 | F32: 347 | G32: 458 | H32: 488 | I32: 468 | J32: 499 | K32: 611.28 | L32: 606 | M32: 594 | N32: 604 | O32: 640 | P32: 645 | Q32: 677.27 | R32: 940.07 | S32: 940.02 | T32: 947.11 | U32: 955.04 | V32: 1226.21 | W32: 1234.87 | X32: 1243.91 | Y32: 1253.13 | Z32: 1262.74 | AA32: 1539.39 | AB32: 1553.64 | AC32: 1568.21 | AD32: 1583.18 | AE32: 1598.55 | AF32: 1614.34 | AG32: 1630.47 | AH32: 1646.86 | AI32: 1663.7 | AJ32: 1680.8 | AK32: 1698.19 | AL32: 1715.94 | AM32: 1733.89 | AN32: 1752.17 | AO32: 1770.74 | AP32: 1789.25 | AQ32: 1807.9 | AR32: 1826.81 | AS32: 1846.04 | AT32: 1865.54 | AU32: 1885.59
A33: Biomass / Geothermal | B33: 0 | C33: 0 | D33: 0 | E33: 5 | F33: 5 | G33: 5 | H33: 5 | I33: 5 | J33: 5 | K33: 2.5 | L33: 3 | M33: 3 | N33: 2 | O33: 2 | P33: 3 | Q33: 3 | R33: 3 | S33: 3 | T33: 3 | U33: 3.53 | V33: 3.53 | W33: 3.53 | X33: 3.53 | Y33: 3.53 | Z33: 3.53 | AA33: 3.53 | AB33: 3.53 | AC33: 3.53 | AD33: 3.53 | AE33: 3.53 | AF33: 3.53 | AG33: 3.53 | AH33: 3.53 | AI33: 3.53 | AJ33: 3.53 | AK33: 3.53 | AL33: 3.53 | AM33: 3.53 | AN33: 3.53 | AO33: 3.53 | AP33: 3.53 | AQ33: 4.49 | AR33: 4.49 | AS33: 4.49 | AT33: 4.49 | AU33: 4.49
A34: Solar | B34: 0 | C34: 0 | D34: 0 | E34: 0 | F34: 0 | G34: 0 | H34: 0 | I34: 0 | J34: 0 | K34: 0 | L34: 0 | M34: 0 | N34: 0 | O34: 0 | P34: 0 | Q34: 0 | R34: 0 | S34: 3.65 | T34: 3.65 | U34: 7.98 | V34: 12.49 | W34: 17.15 | X34: 21.95 | Y34: 26.92 | Z34: 32.03 | AA34: 37.27 | AB34: 42.65 | AC34: 48.13 | AD34: 53.76 | AE34: 59.49 | AF34: 65.34 | AG34: 71.28 | AH34: 77.32 | AI34: 83.44 | AJ34: 89.63 | AK34: 95.9 | AL34: 102.24 | AM34: 108.64 | AN34: 115.07 | AO34: 121.46 | AP34: 127.83 | AQ34: 134.23 | AR34: 140.73 | AS34: 147.25 | AT34: 153.86 | AU34: 160.61
A35: Uranium | B35: 0 | C35: 0 | D35: 0 | E35: 0 | F35: 0 | G35: 0 | H35: 0 | I35: 0 | J35: 0 | K35: 0 | L35: 0 | M35: 0 | N35: 0 | O35: 0 | P35: 0 | Q35: 0 | R35: 0 | S35: 0 | T35: 0 | U35: 0 | V35: 0 | W35: 0 | X35: 0 | Y35: 0 | Z35: 0 | AA35: 0 | AB35: 0 | AC35: 0 | AD35: 0 | AE35: 0 | AF35: 0 | AG35: 0 | AH35: 0 | AI35: 0 | AJ35: 0 | AK35: 0 | AL35: 0 | AM35: 0 | AN35: 0 | AO35: 0 | AP35: 0 | AQ35: 0 | AR35: 0 | AS35: 0 | AT35: 0 | AU35: 0
A36: Coal & Coke | B36: 0 | C36: 0 | D36: 0 | E36: 0 | F36: 0 | G36: 0 | H36: 0 | I36: 0 | J36: 0 | K36: 0 | L36: 0 | M36: 0 | N36: 0 | O36: 0 | P36: 0 | Q36: 0 | R36: 0 | S36: 0 | T36: 0 | U36: 0 | V36: 0 | W36: 0 | X36: 0 | Y36: 0 | Z36: 0 | AA36: 0 | AB36: 0 | AC36: 0 | AD36: 0 | AE36: 0 | AF36: 0 | AG36: 0 | AH36: 0 | AI36: 0 | AJ36: 0 | AK36: 0 | AL36: 0 | AM36: 0 | AN36: 0 | AO36: 0 | AP36: 0 | AQ36: 0 | AR36: 0 | AS36: 0 | AT36: 0 | AU36: 0
A37: Natural Gas | B37: 0 | C37: 0 | D37: 0 | E37: 0 | F37: 0 | G37: 0 | H37: 0 | I37: 0 | J37: 0 | K37: 0 | L37: 0 | M37: 0 | N37: 0 | O37: 0 | P37: 0 | Q37: 0 | R37: 0 | S37: 0 | T37: 0 | U37: 0 | V37: 0 | W37: 0 | X37: 0 | Y37: 0 | Z37: 0 | AA37: 0 | AB37: 0 | AC37: 0 | AD37: 0 | AE37: 0 | AF37: 0 | AG37: 0 | AH37: 0 | AI37: 0 | AJ37: 0 | AK37: 0 | AL37: 0 | AM37: 0 | AN37: 0 | AO37: 0 | AP37: 0 | AQ37: 0 | AR37: 0 | AS37: 0 | AT37: 0 | AU37: 0
A38: Oil | B38: 0.88 | C38: 0.88 | D38: 0.88 | E38: 0.48 | F38: 2.72 | G38: 0 | H38: 0 | I38: 8.16 | J38: 2.17 | K38: 5.8 | L38: 7 | M38: 7 | N38: 7 | O38: 6 | P38: 3 | Q38: 18.79 | R38: 18.79 | S38: 48.27 | T38: 27.62 | U38: 27.62 | V38: 18.95 | W38: 53.14 | X38: 18.79 | Y38: 17.81 | Z38: 17.83 | AA38: 9.78 | AB38: 45.33 | AC38: 45.33 | AD38: 39.78 | AE38: 9.95 | AF38: 28.75 | AG38: 1.1 | AH38: 1.1 | AI38: 1.1 | AJ38: 1.1 | AK38: 1.1 | AL38: 485.2 | AM38: 339.03 | AN38: 342 | AO38: 45.15 | AP38: 48.27 | AQ38: 48.27 | AR38: 48.27 | AS38: 48.27 | AT38: 48.27 | AU38: 48.27
A40: Nova Scotia
A41: _ | B41: 2005 | C41: 2006 | D41: 2007 | E41: 2008 | F41: 2009 | G41: 2010 | H41: 2011 | I41: 2012 | J41: 2013 | K41: 2014 | L41: 2015 | M41: 2016 | N41: 2017 | O41: 2018 | P41: 2019 | Q41: 2020 | R41: 2021 | S41: 2022 | T41: 2023 | U41: 2024 | V41: 2025 | W41: 2026 | X41: 2027 | Y41: 2028 | Z41: 2029 | AA41: 2030 | AB41: 2031 | AC41: 2032 | AD41: 2033 | AE41: 2034 | AF41: 2035 | AG41: 2036 | AH41: 2037 | AI41: 2038 | AJ41: 2039 | AK41: 2040 | AL41: 2041 | AM41: 2042 | AN41: 2043 | AO41: 2044 | AP41: 2045 | AQ41: 2046 | AR41: 2047 | AS41: 2048 | AT41: 2049 | AU41: 2050
A42: Hydro / Wave / Tidal | B42: 926.06 | C42: 926.06 | D42: 926.06 | E42: 1096.66 | F42: 1074.14 | G42: 1007.81 | H42: 1112.47 | I42: 851.5 | J42: 1005.76 | K42: 1128.69 | L42: 979.2 | M42: 779.28 | N42: 824.89 | O42: 910.29 | P42: 1001.52 | Q42: 1001.51 | R42: 1001.53 | S42: 1001.5 | T42: 1001.5 | U42: 1001.53 | V42: 1001.51 | W42: 1001.51 | X42: 1001.53 | Y42: 1001.53 | Z42: 1001.53 | AA42: 1001.52 | AB42: 1001.52 | AC42: 1001.5 | AD42: 1001.52 | AE42: 1001.51 | AF42: 1001.52 | AG42: 1001.51 | AH42: 1001.52 | AI42: 1001.52 | AJ42: 1001.51 | AK42: 1001.53 | AL42: 1001.52 | AM42: 1001.52 | AN42: 1001.52 | AO42: 1001.52 | AP42: 1001.52 | AQ42: 1054.08 | AR42: 1105.85 | AS42: 1157.18 | AT42: 1207.82 | AU42: 1207.82
A43: Wind | B43: 85 | C43: 110 | D43: 157 | E43: 149 | F43: 154 | G43: 387 | H43: 664.19 | I43: 800 | J43: 765 | K43: 748.68 | L43: 803.57 | M43: 999 | N43: 1309 | O43: 1153 | P43: 1057 | Q43: 1056.93 | R43: 1057.31 | S43: 1058.1 | T43: 1101.22 | U43: 1102.26 | V43: 1147.93 | W43: 1193.73 | X43: 1239.51 | Y43: 1285.7 | Z43: 1332.66 | AA43: 1418.81 | AB43: 1506.32 | AC43: 1595.13 | AD43: 1686.43 | AE43: 1779.67 | AF43: 1875.69 | AG43: 1925.17 | AH43: 1978.23 | AI43: 2084.07 | AJ43: 2200.23 | AK43: 2327.44 | AL43: 2459.51 | AM43: 2603.59 | AN43: 2754.38 | AO43: 2902.41 | AP43: 3041.06 | AQ43: 3233.53 | AR43: 3422.88 | AS43: 3615.59 | AT43: 3810.58 | AU43: 3954
A44: Biomass / Geothermal | B44: 318 | C44: 318 | D44: 318 | E44: 322 | F44: 245 | G44: 378 | H44: 363 | I44: 387 | J44: 331 | K44: 253.9 | L44: 427 | M44: 395 | N44: 288 | O44: 487 | P44: 314 | Q44: 233.04 | R44: 265.93 | S44: 269.06 | T44: 265.93 | U44: 265.93 | V44: 264.62 | W44: 265.39 | X44: 265.93 | Y44: 264.06 | Z44: 264.06 | AA44: 264.06 | AB44: 264.06 | AC44: 210.35 | AD44: 210.35 | AE44: 210.35 | AF44: 210.35 | AG44: 210.35 | AH44: 210.35 | AI44: 210.35 | AJ44: 210.35 | AK44: 210.35 | AL44: 241.52 | AM44: 229.88 | AN44: 212.53 | AO44: 212.53 | AP44: 203.34 | AQ44: 195.92 | AR44: 196.96 | AS44: 198.8 | AT44: 200.63 | AU44: 200.63
A45: Solar | B45: 0 | C45: 0 | D45: 0 | E45: 0 | F45: 0 | G45: 0 | H45: 0 | I45: 0 | J45: 0 | K45: 0 | L45: 0 | M45: 0 | N45: 0 | O45: 0 | P45: 0 | Q45: 0 | R45: 0.22 | S45: 0.61 | T45: 1.03 | U45: 1.36 | V45: 1.78 | W45: 2.22 | X45: 2.64 | Y45: 3.06 | Z45: 3.5 | AA45: 4 | AB45: 4.56 | AC45: 5.84 | AD45: 7.2 | AE45: 26.8 | AF45: 28.92 | AG45: 31.78 | AH45: 35.59 | AI45: 58.67 | AJ45: 84.44 | AK45: 112.89 | AL45: 155.86 | AM45: 199.26 | AN45: 243.6 | AO45: 286.18 | AP45: 325.41 | AQ45: 362.55 | AR45: 400.36 | AS45: 441.67 | AT45: 485.07 | AU45: 528.46
...

Sheet Canada NG Gen by Turbine Type
A1: Electric power generation, monthly generation by type of electricity 1 2
A2: Frequency: Monthly
A3: Table: 25-10-0015-01 (formerly CANSIM 127-0002)
A4: Release date: 2022-08-08
A5: Geography: Canada, Province or territory
A9: Geography | B9: Canada
A10: Class of electricity producer | B10: Electricity producers, electric utilities 3
A11: Type of electricity generation | B11: 42005 | C11: 42036 | D11: 42064 | E11: 42095 | F11: 42125 | G11: 42156 | H11: 42186 | I11: 42217 | J11: 42248 | K11: 42278 | L11: 42309 | M11: 42339 | N11: 2015 Total
B12: Megawatt hours
A13: Total all types of electricity generation | B13: 57211066 | C13: 51887549 | D13: 51928707 | E13: 44615918 | F13: 41273083 | G13: 40984150 | H13: 43038080 | I13: 42821817 | J13: 40051862 | K13: 41066197 | L13: 45130806 | M13: 50003722 | N13: =SUM(B13:M13) -> 550012957
A14: Hydraulic turbine 4 | B14: 37669235 | C14: 34013218 | D14: 33173669 | E14: 28699811 | F14: 25910082 | G14: 25327992 | H14: 25979724 | I14: 25478511 | J14: 25022584 | K14: 26123765 | L14: 27941235 | M14: 32045247 | N14: =SUM(B14:M14) -> 347385073
A15: Conventional steam turbine 5 | B15: 7190066 | C15: 6844655 | D15: 6613699 | E15: 5688669 | F15: 5082749 | G15: 5430405 | H15: 5991055 | I15: 6330435 | J15: 6041405 | K15: 6138156 | L15: 6294045 | M15: 6842938 | N15: =SUM(B15:M15) -> 74488277
A16: Nuclear steam turbine 6 | B16: 9180622 | C16: 8307371 | D16: 9230529 | E16: 7737381 | F16: 7985257 | G16: 8084872 | H16: 8900017 | I16: 8678391 | J16: 6965168 | K16: 6323797 | L16: 8448485 | M16: 8533084 | N16: =SUM(B16:M16) -> 98374974
A17: Internal combustion turbine 7 | B17: 92383 | C17: 85781 | D17: 84787 | E17: 74433 | F17: 66229 | G17: 63635 | H17: 66291 | I17: 69265 | J17: 65022 | K17: 73599 | L17: 74497 | M17: 84241 | N17: =SUM(B17:M17) -> 900163
A18: Combustion turbine 8 | B18: 2014274 | C18: 1874168 | D18: 1889483 | E18: 1556326 | F18: 1586397 | G18: 1577410 | H18: 1632967 | I18: 1756391 | J18: 1312213 | K18: 1476359 | L18: 1468138 | M18: 1615706 | N18: =SUM(B18:M18) -> 19759832
A19: Total electricity production from combustible fuels 9 | B19: .. | C19: .. | D19: .. | E19: .. | F19: .. | G19: .. | H19: .. | I19: .. | J19: .. | K19: .. | L19: .. | M19: .. | N19: ..
A20: Tidal power turbine 10 | B20: -124 | C20: -164 | D20: -13 | E20: 1538 | F20: 1615 | G20: 1951 | H20: 870 | I20: 22 | J20: 1791 | K20: 1524 | L20: 1979 | M20: 1831 | N20: =SUM(B20:M20) -> 12820
A21: Wind power turbine 11 | B21: 1053353 | C21: 748057 | D21: 924413 | E21: 832222 | F21: 611620 | G21: 469148 | H21: 435550 | I21: 477306 | J21: 616094 | K21: 907927 | L21: 885149 | M21: 872178 | N21: =SUM(B21:M21) -> 8833017
A22: Solar 12 | B22: 11257 | C22: 14463 | D22: 12140 | E22: 25538 | F22: 29134 | G22: 28737 | H22: 31620 | I22: 31496 | J22: 27584 | K22: 21070 | L22: 17278 | M22: 8498 | N22: =SUM(B22:M22) -> 258815
A23: Other types of electricity generation | B23: .. | C23: .. | D23: .. | E23: .. | F23: .. | G23: .. | H23: .. | I23: .. | J23: .. | K23: .. | L23: .. | M23: .. | N23: ..
A25: Symbol legend:
A26: .. | B26: not available for a specific reference period
A27: r | B27: revised
A32: Footnotes:
A33: 1 | B33: For monthly data prior to January 2008, please see table 25-10-0001-01 (terminated). For current monthly data on Electric power receipts and deliveries, see table 25-10-0016-01.
A34: 2 | B34: The target population for the Monthly Electricity Supply and Disposition Survey has been expanded to improve coverage of renewable energy in Canada, particularly wind and solar power. As a result of this change, users will have to use caution when comparing data for historical purposes. For wind power, significant changes occurred in British Columbia, Alberta, Ontario, Quebec and Prince Edward Island. For solar power, significant changes occurred in Ontario.
A35: 3 | B35: A utility is an organization that, as its prime purpose, generates, transmits and/or distributes electric energy for sale. It can be private or public (provincial or municipal).
A36: 4 | B36: Electric power generated from a plant in which the turbine generators are driven by flowing water. Prior to January 2008, hydro included wind and tidal generation. From January 2008 on, wind and tidal generation are reported separately.
A37: 5 | B37: A power plant in which the prime mover is a steam turbine. The steam used to drive the turbine is produced in a boiler where fossil fuels or other combustible materials are burned. From January 2016 on, this generation is reported as part of combustible fuel generation.
A38: 6 | B38: Electricity generated at an electric power plant whose turbines are driven by steam generated in a reactor by heat from the fission of nuclear fuel.
A39: 7 | B39: A power plant in which the prime mover is an internal combustion turbine. Electric power is generated by converting energy obtained by the rapid burning of a fuel-air mixture into mechanical energy. From January 2016 on, this generation is reported as part of combustible fuel generation.
A40: 8 | B40: A power plant in which the prime mover is a combustion turbine. Electric power is generated by converting energy obtained by burning fuel into mechanical energy. From January 2016 on, this generation is reported as part of combustible fuel generation.
A41: 9 | B41: Total combustible generation includes non-renewable combustible fuels (coal, natural gas, petroleum and other non-renewable combustible fuels) and biomass (wood, spent pulping liquor, methane, municipal waste, other waste and other types of biomass).
A42: 10 | B42: Electric power generated from a plant in which the turbine generators are driven by moving water from tidal flows.
A43: 11 | B43: A power plant in which the prime mover is a wind turbine. Electric power is generated by the conversion of wind power into mechanical energy.
A44: 12 | B44: Electricity created by converting solar radiation through photovoltaic processes or transforming solar radiation captured by concentrating thermal systems.
A48: How to cite: Statistics Canada. Table 25-10-0015-01 Electric power generation, monthly generation by type of electricity
A49: https://www150.statcan.gc.ca/t1/tbl1/en/tv.action?pid=2510001501
A52: NG Breakdown by EPS Plant Type
A53: natural gas steam turbine | B53: =N15/SUM(N15,N17:N18) -> 0.78286526
...

Sheet Canada Elec Mix
B1: 2020 | C1: 2021 | D1: 2022 | E1: 2023 | F1: 2024 | G1: 2025 | H1: 2026 | I1: 2027 | J1: 2028 | K1: 2029 | L1: 2030 | M1: 2031 | N1: 2032 | O1: 2033 | P1: 2034 | Q1: 2035 | R1: 2036 | S1: 2037 | T1: 2038 | U1: 2039 | V1: 2040 | W1: 2041 | X1: 2042 | Y1: 2043 | Z1: 2044 | AA1: 2045 | AB1: 2046 | AC1: 2047 | AD1: 2048 | AE1: 2049 | AF1: 2050
A2: hard coal | B2: ='Canada Generation Projection'!Q14/B20 -> 0.049871278 | C2: ='Canada Generation Projection'!R14/C20 -> 0.05570459 | D2: ='Canada Generation Projection'!S14/D20 -> 0.029406679 | E2: ='Canada Generation Projection'!T14/E20 -> 0.0082914781 | F2: ='Canada Generation Projection'!U14/F20 -> 0.0083106362 | G2: ='Canada Generation Projection'!V14/G20 -> 0.0073348873 | H2: ='Canada Generation Projection'!W14/H20 -> 0.0070243911 | I2: ='Canada Generation Projection'!X14/I20 -> 0.0063780498 | ... AF2: ='Canada Generation Projection'!AU14/AF20 -> 0.00010117144
A3: natural gas steam turbine | B3: ='Canada Generation Projection'!Q$15/B$20*'Canada NG Gen by Turbine Type'!$B$53 -> 0.093411097 | C3: ='Canada Generation Projection'!R$15/C$20*'Canada NG Gen by Turbine Type'!$B$53 -> 0.094913318 | D3: ='Canada Generation Projection'!S$15/D$20*'Canada NG Gen by Turbine Type'!$B$53 -> 0.099224442 | E3: ='Canada Generation Projection'!T$15/E$20*'Canada NG Gen by Turbine Type'!$B$53 -> 0.12061842 | F3: ='Canada Generation Projection'!U$15/F$20*'Canada NG Gen by Turbine Type'!$B$53 -> 0.11243635 | G3: ='Canada Generation Projection'!V$15/G$20*'Canada NG Gen by Turbine Type'!$B$53 -> 0.11570779 | H3: ='Canada Generation Projection'!W$15/H$20*'Canada NG Gen by Turbine Type'!$B$53 -> 0.12122634 | I3: ='Canada Generation Projection'!X$15/I$20*'Canada NG Gen by Turbine Type'!$B$53 -> 0.11110197 | ... AF3: ='Canada Generation Projection'!AU$15/AF$20*'Canada NG Gen by Turbine Type'!$B$53 -> 0.061806611
A4: natural gas combined cycle | B4: ='Canada Generation Projection'!Q$15/B$20*'Canada NG Gen by Turbine Type'!$B$54 -> 0 | C4: ='Canada Generation Projection'!R$15/C$20*'Canada NG Gen by Turbine Type'!$B$54 -> 0 | D4: ='Canada Generation Projection'!S$15/D$20*'Canada NG Gen by Turbine Type'!$B$54 -> 0 | E4: ='Canada Generation Projection'!T$15/E$20*'Canada NG Gen by Turbine Type'!$B$54 -> 0 | F4: ='Canada Generation Projection'!U$15/F$20*'Canada NG Gen by Turbine Type'!$B$54 -> 0 | G4: ='Canada Generation Projection'!V$15/G$20*'Canada NG Gen by Turbine Type'!$B$54 -> 0 | H4: ='Canada Generation Projection'!W$15/H$20*'Canada NG Gen by Turbine Type'!$B$54 -> 0 | I4: ='Canada Generation Projection'!X$15/I$20*'Canada NG Gen by Turbine Type'!$B$54 -> 0 | ... AF4: ='Canada Generation Projection'!AU$15/AF$20*'Canada NG Gen by Turbine Type'!$B$54 -> 0
A5: nuclear | B5: ='Canada Generation Projection'!Q13/B20 -> 0.13371461 | C5: ='Canada Generation Projection'!R13/C20 -> 0.12383203 | D5: ='Canada Generation Projection'!S13/D20 -> 0.12240882 | E5: ='Canada Generation Projection'!T13/E20 -> 0.10569686 | F5: ='Canada Generation Projection'!U13/F20 -> 0.11988086 | G5: ='Canada Generation Projection'!V13/G20 -> 0.10876038 | H5: ='Canada Generation Projection'!W13/H20 -> 0.10017687 | I5: ='Canada Generation Projection'!X13/I20 -> 0.10896654 | ... AF5: ='Canada Generation Projection'!AU13/AF20 -> 0.10966865
A6: hydro | B6: ='Canada Generation Projection'!Q9/B20 -> 0.61871683 | C6: ='Canada Generation Projection'!R9/C20 -> 0.61879795 | D6: ='Canada Generation Projection'!S9/D20 -> 0.62526483 | E6: ='Canada Generation Projection'!T9/E20 -> 0.63476648 | F6: ='Canada Generation Projection'!U9/F20 -> 0.6279653 | G6: ='Canada Generation Projection'!V9/G20 -> 0.63172003 | H6: ='Canada Generation Projection'!W9/H20 -> 0.62780157 | I6: ='Canada Generation Projection'!X9/I20 -> 0.62529833 | ... AF6: ='Canada Generation Projection'!AU9/AF20 -> 0.50968831
A7: onshore wind | B7: ='Canada Generation Projection'!Q10/B20 -> 0.056709046 | C7: ='Canada Generation Projection'!R10/C20 -> 0.058589075 | D7: ='Canada Generation Projection'!S10/D20 -> 0.07388148 | E7: ='Canada Generation Projection'!T10/E20 -> 0.074124195 | F7: ='Canada Generation Projection'!U10/F20 -> 0.077730289 | G7: ='Canada Generation Projection'!V10/G20 -> 0.080564413 | H7: ='Canada Generation Projection'!W10/H20 -> 0.080916426 | I7: ='Canada Generation Projection'!X10/I20 -> 0.091008055 | ... AF7: ='Canada Generation Projection'!AU10/AF20 -> 0.2153317
A8: solar PV | B8: ='Canada Generation Projection'!Q12/B20 -> 0.0036116336 | C8: ='Canada Generation Projection'!R12/C20 -> 0.0040794139 | D8: ='Canada Generation Projection'!S12/D20 -> 0.0052549409 | E8: ='Canada Generation Projection'!T12/E20 -> 0.0056383787 | F8: ='Canada Generation Projection'!U12/F20 -> 0.0061239473 | G8: ='Canada Generation Projection'!V12/G20 -> 0.0064315759 | H8: ='Canada Generation Projection'!W12/H20 -> 0.0072853678 | I8: ='Canada Generation Projection'!X12/I20 -> 0.0077602387 | ... AF8: ='Canada Generation Projection'!AU12/AF20 -> 0.070986655
A9: solar thermal | B9: 0 | C9: 0 | D9: 0 | E9: 0 | F9: 0 | G9: 0 | H9: 0 | I9: 0 | J9: 0 | K9: 0 | L9: 0 | M9: 0 | N9: 0 | O9: 0 | P9: 0 | Q9: 0 | R9: 0 | S9: 0 | T9: 0 | U9: 0 | V9: 0 | W9: 0 | X9: 0 | Y9: 0 | Z9: 0 | AA9: 0 | AB9: 0 | AC9: 0 | AD9: 0 | AE9: 0 | AF9: 0
A10: biomass | B10: ='Canada Generation Projection'!Q11/B20 -> 0.01243072 | C10: ='Canada Generation Projection'!R11/C20 -> 0.012469398 | D10: ='Canada Generation Projection'!S11/D20 -> 0.012211091 | E10: ='Canada Generation Projection'!T11/E20 -> 0.012314069 | F10: ='Canada Generation Projection'!U11/F20 -> 0.012202219 | G10: ='Canada Generation Projection'!V11/G20 -> 0.012158165 | H10: ='Canada Generation Projection'!W11/H20 -> 0.012114725 | I10: ='Canada Generation Projection'!X11/I20 -> 0.01199031 | ... AF10: ='Canada Generation Projection'!AU11/AF20 -> 0.00874335
A11: geothermal | B11: 0 | C11: 0 | D11: 0 | E11: 0 | F11: 0 | G11: 0 | H11: 0 | I11: 0 | J11: 0 | K11: 0 | L11: 0 | M11: 0 | N11: 0 | O11: 0 | P11: 0 | Q11: 0 | R11: 0 | S11: 0 | T11: 0 | U11: 0 | V11: 0 | W11: 0 | X11: 0 | Y11: 0 | Z11: 0 | AA11: 0 | AB11: 0 | AC11: 0 | AD11: 0 | AE11: 0 | AF11: 0
A12: petroleum | B12: ='Canada Generation Projection'!Q16/B20 -> 0.005626375 | C12: ='Canada Generation Projection'!R16/C20 -> 0.0052891614 | D12: ='Canada Generation Projection'!S16/D20 -> 0.0048269163 | E12: ='Canada Generation Projection'!T16/E20 -> 0.0050955044 | F12: ='Canada Generation Projection'!U16/F20 -> 0.004165158 | G12: ='Canada Generation Projection'!V16/G20 -> 0.0052301543 | H12: ='Canada Generation Projection'!W16/H20 -> 0.0098310942 | I12: ='Canada Generation Projection'!X16/I20 -> 0.0066813756 | ... AF12: ='Canada Generation Projection'!AU16/AF20 -> 0.0065309353
A13: natural gas peaker | B13: ='Canada Generation Projection'!Q$15/B$20*'Canada NG Gen by Turbine Type'!$B$55 -> 0.02590841 | C13: ='Canada Generation Projection'!R$15/C$20*'Canada NG Gen by Turbine Type'!$B$55 -> 0.026325064 | D13: ='Canada Generation Projection'!S$15/D$20*'Canada NG Gen by Turbine Type'!$B$55 -> 0.027520793 | E13: ='Canada Generation Projection'!T$15/E$20*'Canada NG Gen by Turbine Type'!$B$55 -> 0.033454607 | F13: ='Canada Generation Projection'!U$15/F$20*'Canada NG Gen by Turbine Type'!$B$55 -> 0.031185235 | G13: ='Canada Generation Projection'!V$15/G$20*'Canada NG Gen by Turbine Type'!$B$55 -> 0.032092599 | H13: ='Canada Generation Projection'!W$15/H$20*'Canada NG Gen by Turbine Type'!$B$55 -> 0.033623219 | I13: ='Canada Generation Projection'!X$15/I$20*'Canada NG Gen by Turbine Type'!$B$55 -> 0.030815132 | ... AF13: ='Canada Generation Projection'!AU$15/AF$20*'Canada NG Gen by Turbine Type'!$B$55 -> 0.017142621
A14: lignite | B14: 0 | C14: 0 | D14: 0 | E14: 0 | F14: 0 | G14: 0 | H14: 0 | I14: 0 | J14: 0 | K14: 0 | L14: 0 | M14: 0 | N14: 0 | O14: 0 | P14: 0 | Q14: 0 | R14: 0 | S14: 0 | T14: 0 | U14: 0 | V14: 0 | W14: 0 | X14: 0 | Y14: 0 | Z14: 0 | AA14: 0 | AB14: 0 | AC14: 0 | AD14: 0 | AE14: 0 | AF14: 0
A15: offshore wind | B15: 0 | C15: 0 | D15: 0 | E15: 0 | F15: 0 | G15: 0 | H15: 0 | I15: 0 | J15: 0 | K15: 0 | L15: 0 | M15: 0 | N15: 0 | O15: 0 | P15: 0 | Q15: 0 | R15: 0 | S15: 0 | T15: 0 | U15: 0 | V15: 0 | W15: 0 | X15: 0 | Y15: 0 | Z15: 0 | AA15: 0 | AB15: 0 | AC15: 0 | AD15: 0 | AE15: 0 | AF15: 0
A16: crude oil | B16: 0 | C16: 0 | D16: 0 | E16: 0 | F16: 0 | G16: 0 | H16: 0 | I16: 0 | J16: 0 | K16: 0 | L16: 0 | M16: 0 | N16: 0 | O16: 0 | P16: 0 | Q16: 0 | R16: 0 | S16: 0 | T16: 0 | U16: 0 | V16: 0 | W16: 0 | X16: 0 | Y16: 0 | Z16: 0 | AA16: 0 | AB16: 0 | AC16: 0 | AD16: 0 | AE16: 0 | AF16: 0
A17: heavy or residual fuel oil | B17: 0 | C17: 0 | D17: 0 | E17: 0 | F17: 0 | G17: 0 | H17: 0 | I17: 0 | J17: 0 | K17: 0 | L17: 0 | M17: 0 | N17: 0 | O17: 0 | P17: 0 | Q17: 0 | R17: 0 | S17: 0 | T17: 0 | U17: 0 | V17: 0 | W17: 0 | X17: 0 | Y17: 0 | Z17: 0 | AA17: 0 | AB17: 0 | AC17: 0 | AD17: 0 | AE17: 0 | AF17: 0
A18: municipal solid waste | B18: 0 | C18: 0 | D18: 0 | E18: 0 | F18: 0 | G18: 0 | H18: 0 | I18: 0 | J18: 0 | K18: 0 | L18: 0 | M18: 0 | N18: 0 | O18: 0 | P18: 0 | Q18: 0 | R18: 0 | S18: 0 | T18: 0 | U18: 0 | V18: 0 | W18: 0 | X18: 0 | Y18: 0 | Z18: 0 | AA18: 0 | AB18: 0 | AC18: 0 | AD18: 0 | AE18: 0 | AF18: 0
A20: Sum of Canada Generation | B20: =SUM(Table15[2020]) -> 624124.77 | C20: =SUM(Table15[2021]) -> 635025.05 | D20: =SUM(Table15[2022]) -> 662134.95 | E20: =SUM(Table15[2023]) -> 661479.16 | F20: =SUM(Table15[2024]) -> 669724.9 | G20: =SUM(Table15[2025]) -> 674750.65 | H20: =SUM(Table15[2026]) -> 679256.03 | I20: =SUM(Table15[2027]) -> 682236.75 | J20: =SUM(Table15[2028]) -> 687482.16 | K20: =SUM(Table15[2029]) -> 693088.12 | L20: =SUM(Table15[2030]) -> 708052.06 | M20: =SUM(Table15[2031]) -> 718368.89 | N20: =SUM(Table15[2032]) -> 722783.21 | O20: =SUM(Table15[2033]) -> 726806.45 | P20: =SUM(Table15[2034]) -> 733530.54 | Q20: =SUM(Table15[2035]) -> 740490.73 | R20: =SUM(Table15[2036]) -> 737450.58 | S20: =SUM(Table15[2037]) -> 742988.3 | T20: =SUM(Table15[2038]) -> 751284.56 | U20: =SUM(Table15[2039]) -> 758525.56 | V20: =SUM(Table15[2040]) -> 768472.94 | W20: =SUM(Table15[2041]) -> 774344.35 | X20: =SUM(Table15[2042]) -> 786697.66 | Y20: =SUM(Table15[2043]) -> 799962.03 | Z20: =SUM(Table15[2044]) -> 817333.19 | AA20: =SUM(Table15[2045]) -> 829175.85 | AB20: =SUM(Table15[2046]) -> 841871.94 | AC20: =SUM(Table15[2047]) -> 851081.92 | AD20: =SUM(Table15[2048]) -> 860725.04 | AE20: =SUM(Table15[2049]) -> 868040.47 | AF20: =SUM(Table15[2050]) -> 875938.86

Sheet AEO Table 3 2025
A1: Table 3. Energy Prices by Sector and Source
A2: https://www.eia.gov/outlooks/aeo/data/browser/#/?id=3-AEO2025&cases=highZTC&sourcekey=0
A3: Tue Dec 02 2025 13:12:56 GMT-0800 (Pacific Standard Time)
A4: Source: U.S. Energy Information Administration
B5: full name | C5: api key | D5: units | E5: 2023 | F5: 2024 | G5: 2025 | H5: 2026 | I5: 2027 | J5: 2028 | K5: 2029 | L5: 2030 | M5: 2031 | N5: 2032 | O5: 2033 | P5: 2034 | Q5: 2035 | R5: 2036 | S5: 2037 | T5: 2038 | U5: 2039 | V5: 2040 | W5: 2041 | X5: 2042 | Y5: 2043 | Z5: 2044 | AA5: 2045 | AB5: 2046 | AC5: 2047 | AD5: 2048 | AE5: 2049 | AF5: 2050 | AG5: Growth (2024-2050)
A6: Residential
A7: Propane | B7: Energy Prices: Residential: Propane: High Zero-Carbon Technology Cost | C7: AEO.2025.HIGHZTC.PRCE_REAL_RESD_NA_PROP_NA_NA_Y13DLRPMMBTU.A | D7: 2024 $/MMBtu | F7: 26.593981 | G7: 25.690693 | H7: 25.882023 | I7: 25.734011 | J7: 25.761881 | K7: 25.984186 | L7: 26.494528 | M7: 27.035074 | N7: 27.848438 | O7: 28.895929 | P7: 29.836832 | Q7: 30.497536 | R7: 30.975727 | S7: 31.295523 | T7: 31.443632 | U7: 31.521713 | V7: 31.634783 | W7: 31.863678 | X7: 32.095478 | Y7: 32.443432 | Z7: 32.908676 | AA7: 33.216011 | AB7: 33.459888 | AC7: 33.58733 | AD7: 33.707253 | AE7: 33.953312 | AF7: 34.455376 | AG7: 0.01
A8: Distillate Fuel Oil | B8: Energy Prices: Residential: Distillate Fuel Oil: High Zero-Carbon Technology Cost | C8: AEO.2025.HIGHZTC.PRCE_REAL_RESD_NA_DFO_NA_NA_Y13DLRPMMBTU.A | D8: 2024 $/MMBtu | F8: 26.158379 | G8: 24.617764 | H8: 24.643763 | I8: 25.310112 | J8: 26.17977 | K8: 27.100401 | L8: 28.068832 | M8: 28.11725 | N8: 28.0326 | O8: 28.357315 | P8: 28.466999 | Q8: 28.689667 | R8: 28.809559 | S8: 29.071898 | T8: 29.171333 | U8: 29.291199 | V8: 29.469152 | W8: 29.758438 | X8: 29.994083 | Y8: 30.294477 | Z8: 30.955036 | AA8: 30.868721 | AB8: 30.956972 | AC8: 30.914091 | AD8: 30.902479 | AE8: 30.934729 | AF8: 31.279491 | AG8: 0.007
A9: Natural Gas | B9: Energy Prices: Residential: Natural Gas: High Zero-Carbon Technology Cost | C9: AEO.2025.HIGHZTC.PRCE_REAL_RESD_NA_NG_NA_NA_Y13DLRPMMBTU.A | D9: 2024 $/MMBtu | F9: 13.932205 | G9: 12.694278 | H9: 12.476946 | I9: 12.0713 | J9: 11.825522 | K9: 11.708606 | L9: 11.628035 | M9: 11.829365 | N9: 12.259671 | O9: 12.641685 | P9: 12.901601 | Q9: 13.046376 | R9: 13.061166 | S9: 13.048336 | T9: 13.026576 | U9: 12.968637 | V9: 13.000326 | W9: 13.125381 | X9: 13.234643 | Y9: 13.327177 | Z9: 13.385166 | AA9: 13.471466 | AB9: 13.568365 | AC9: 13.612545 | AD9: 13.641063 | AE9: 13.722773 | AF9: 13.794634 | AG9: 0
A10: Electricity | B10: Energy Prices: Residential: Electricity: High Zero-Carbon Technology Cost | C10: AEO.2025.HIGHZTC.PRCE_REAL_RESD_NA_ELC_NA_NA_Y13DLRPMMBTU.A | D10: 2024 $/MMBtu | F10: 45.553139 | G10: 45.024025 | H10: 42.541679 | I10: 40.45982 | J10: 40.182793 | K10: 40.569782 | L10: 41.046375 | M10: 41.716888 | N10: 42.268425 | O10: 43.117485 | P10: 43.465755 | Q10: 43.342434 | R10: 43.037926 | S10: 42.73064 | T10: 42.891632 | U10: 42.628983 | V10: 42.525494 | W10: 42.545128 | X10: 42.731728 | Y10: 42.921192 | Z10: 43.168861 | AA10: 43.377872 | AB10: 43.621025 | AC10: 43.79406 | AD10: 44.126114 | AE10: 44.423275 | AF10: 44.787258 | AG10: -0.001
A11: Commercial
A12: Propane | B12: Energy Prices: Commercial: Propane: High Zero-Carbon Technology Cost | C12: AEO.2025.HIGHZTC.PRCE_REAL_COMM_NA_PROP_NA_NA_Y13DLRPMMBTU.A | D12: 2024 $/MMBtu | F12: 19.0868 | G12: 19.071598 | H12: 19.969246 | I12: 19.804914 | J12: 19.920181 | K12: 20.219919 | L12: 20.798326 | M12: 21.250935 | N12: 22.027008 | O12: 22.973885 | P12: 23.6208 | Q12: 23.91017 | R12: 24.102671 | S12: 24.204554 | T12: 24.180492 | U12: 24.168512 | V12: 24.257711 | W12: 24.494383 | X12: 24.6768 | Y12: 25.001261 | Z12: 25.422537 | AA12: 25.562656 | AB12: 25.683006 | AC12: 25.692684 | AD12: 25.758125 | AE12: 26.007099 | AF12: 26.538202 | AG12: 0.013
A13: Distillate Fuel Oil | B13: Energy Prices: Commercial: Distillate Fuel Oil: High Zero-Carbon Technology Cost | C13: AEO.2025.HIGHZTC.PRCE_REAL_COMM_NA_DFO_NA_NA_Y13DLRPMMBTU.A | D13: 2024 $/MMBtu | F13: 26.207932 | G13: 24.707527 | H13: 23.565269 | I13: 23.058794 | J13: 22.754671 | K13: 22.501291 | L13: 22.297827 | M13: 22.340889 | N13: 22.216309 | O13: 22.527172 | P13: 22.633039 | Q13: 22.83795 | R13: 22.942883 | S13: 23.194223 | T13: 23.297205 | U13: 23.403837 | V13: 23.570314 | W13: 23.852497 | X13: 24.078636 | Y13: 24.381926 | Z13: 25.030125 | AA13: 24.942905 | AB13: 25.028816 | AC13: 24.984297 | AD13: 24.964209 | AE13: 25.003876 | AF13: 25.3452 | AG13: -0.001
A14: Residual Fuel Oil | B14: Energy Prices: Commercial: Residual Fuel: High Zero-Carbon Technology Cost | C14: AEO.2025.HIGHZTC.PRCE_REAL_COMM_NA_RFL_NA_NA_Y13DLRPMMBTU.A | D14: 2024 $/MMBtu | F14: 6.746078 | G14: 7.471698 | H14: 7.841193 | I14: 8.831597 | J14: 9.914908 | K14: 11.015342 | L14: 12.183045 | M14: 12.244162 | N14: 12.208694 | O14: 12.446174 | P14: 12.544676 | Q14: 12.678741 | R14: 12.753716 | S14: 12.87225 | T14: 12.979047 | U14: 12.997785 | V14: 13.118733 | W14: 13.235469 | X14: 13.365701 | Y14: 13.416109 | Z14: 13.347304 | AA14: 13.387928 | AB14: 13.678938 | AC14: 13.632569 | AD14: 13.671235 | AE14: 13.775191 | AF14: 14.322314 | AG14: 0.029
A15: Natural Gas | B15: Energy Prices: Commercial: Natural Gas: High Zero-Carbon Technology Cost | C15: AEO.2025.HIGHZTC.PRCE_REAL_COMM_NA_NG_NA_NA_Y13DLRPMMBTU.A | D15: 2024 $/MMBtu | F15: 9.555858 | G15: 8.473628 | H15: 8.571372 | I15: 8.513054 | J15: 8.593106 | K15: 8.767466 | L15: 8.976199 | M15: 9.121284 | N15: 9.472503 | O15: 9.787833 | P15: 9.988475 | Q15: 10.085086 | R15: 10.067373 | S15: 10.026683 | T15: 9.977905 | U15: 9.894558 | V15: 9.894806 | W15: 9.981339 | X15: 10.052937 | Y15: 10.11166 | Z15: 10.137436 | AA15: 10.191541 | AB15: 10.258538 | AC15: 10.274831 | AD15: 10.279621 | AE15: 10.336456 | AF15: 10.384078 | AG15: 0.003
A16: Electricity | B16: Energy Prices: Commercial: Electricity: High Zero-Carbon Technology Cost | C16: AEO.2025.HIGHZTC.PRCE_REAL_COMM_NA_ELC_NA_NA_Y13DLRPMMBTU.A | D16: 2024 $/MMBtu | F16: 38.551605 | G16: 37.602798 | H16: 35.105431 | I16: 33.124508 | J16: 32.965439 | K16: 33.32024 | L16: 33.809681 | M16: 34.413387 | N16: 34.929173 | O16: 35.701324 | P16: 35.979614 | Q16: 35.811676 | R16: 35.482807 | S16: 35.191898 | T16: 35.411739 | U16: 35.115093 | V16: 34.986004 | W16: 34.99255 | X16: 35.154461 | Y16: 35.305714 | Z16: 35.501835 | AA16: 35.64677 | AB16: 35.79763 | AC16: 35.841282 | AD16: 36.080368 | AE16: 36.286304 | AF16: 36.524944 | AG16: -0.002
A17: Industrial
A18: Propane | B18: Energy Prices: Industrial: Propane: High Zero-Carbon Technology Cost | C18: AEO.2025.HIGHZTC.PRCE_REAL_IDAL_NA_PROP_NA_NA_Y13DLRPMMBTU.A | D18: 2024 $/MMBtu | F18: 12.66026 | G18: 12.605674 | H18: 13.465074 | I18: 13.314802 | J18: 13.427592 | K18: 13.72262 | L18: 14.298682 | M18: 14.759735 | N18: 15.554036 | O18: 16.543209 | P18: 17.23724 | Q18: 17.555822 | R18: 17.767212 | S18: 17.880009 | T18: 17.856604 | U18: 17.844084 | V18: 17.93939 | W18: 18.19438 | X18: 18.394274 | Y18: 18.748419 | Z18: 19.21232 | AA18: 19.372681 | AB18: 19.508192 | AC18: 19.52129 | AD18: 19.593958 | AE18: 19.869528 | AF18: 20.462763 | AG18: 0.019
A19: Distillate Fuel Oil | B19: Energy Prices: Industrial: Distillate Fuel Oil: High Zero-Carbon Technology Cost | C19: AEO.2025.HIGHZTC.PRCE_REAL_IDAL_NA_DFO_NA_NA_Y13DLRPMMBTU.A | D19: 2024 $/MMBtu | F19: 26.091763 | G19: 24.600626 | H19: 23.425852 | I19: 22.88941 | J19: 22.557371 | K19: 22.274755 | L19: 22.032902 | M19: 22.079994 | N19: 21.943752 | O19: 22.273958 | P19: 22.39349 | Q19: 22.623447 | R19: 22.746523 | S19: 23.008989 | T19: 23.10652 | U19: 23.218241 | V19: 23.399351 | W19: 23.679426 | X19: 23.916767 | Y19: 24.223963 | Z19: 24.880014 | AA19: 24.792429 | AB19: 24.880751 | AC19: 24.838329 | AD19: 24.82336 | AE19: 24.858402 | AF19: 25.202454 | AG19: -0.001
A20: Residual Fuel Oil | B20: Energy Prices: Industrial: Residual Fuel Oil: High Zero-Carbon Technology Cost | C20: AEO.2025.HIGHZTC.PRCE_REAL_IDAL_NA_RFO_NA_NA_Y13DLRPMMBTU.A | D20: 2024 $/MMBtu | F20: 7.83466 | G20: 8.848094 | H20: 9.435161 | I20: 10.629246 | J20: 11.88067 | K20: 13.214781 | L20: 14.622335 | M20: 14.725853 | N20: 14.700524 | O20: 14.992572 | P20: 15.113938 | Q20: 15.285793 | R20: 15.383565 | S20: 15.518867 | T20: 15.634306 | U20: 15.663942 | V20: 15.779115 | W20: 15.889836 | X20: 16.038828 | Y20: 16.101131 | Z20: 16.053886 | AA20: 16.051018 | AB20: 16.34535 | AC20: 16.306047 | AD20: 16.344069 | AE20: 16.451635 | AF20: 16.998318 | AG20: 0.03
A21: Natural Gas | B21: Energy Prices: Industrial: Natural Gas: High Zero-Carbon Technology Cost | C21: AEO.2025.HIGHZTC.PRCE_REAL_IDAL_NA_NG_NA_NA_Y13DLRPMMBTU.A | D21: 2024 $/MMBtu | F21: 3.33707 | G21: 4.010599 | H21: 3.911485 | I21: 3.791521 | J21: 3.869612 | K21: 4.020249 | L21: 4.230658 | M21: 4.390093 | N21: 4.830755 | O21: 5.179088 | P21: 5.412342 | Q21: 5.494054 | R21: 5.481412 | S21: 5.430798 | T21: 5.370685 | U21: 5.290253 | V21: 5.310672 | W21: 5.403639 | X21: 5.486475 | Y21: 5.561241 | Z21: 5.615677 | AA21: 5.665632 | AB21: 5.71713 | AC21: 5.72265 | AD21: 5.7369 | AE21: 5.797705 | AF21: 5.862935 | AG21: 0.022
A22: Metallurgical Coal | B22: Energy Prices: Industrial: Metallurgical Coal: High Zero-Carbon Technology Cost | C22: AEO.2025.HIGHZTC.PRCE_REAL_IDAL_NA_MTC_NA_NA_Y13DLRPMMBTU.A | D22: 2024 $/MMBtu | F22: 7.767755 | G22: 7.639748 | H22: 7.585148 | I22: 7.555212 | J22: 7.520931 | K22: 7.512826 | L22: 7.510444 | M22: 7.515949 | N22: 7.537591 | O22: 7.537167 | P22: 7.49989 | Q22: 7.518089 | R22: 7.517967 | S22: 7.515557 | T22: 7.51727 | U22: 7.498265 | V22: 7.496222 | W22: 7.466915 | X22: 7.461041 | Y22: 7.453232 | Z22: 7.458103 | AA22: 7.471511 | AB22: 7.467525 | AC22: 7.46251 | AD22: 7.461265 | AE22: 7.469367 | AF22: 7.466943 | AG22: -0.002
A23: Other Industrial Coal | B23: Energy Prices: Industrial: Other Industrial Coal: High Zero-Carbon Technology Cost | C23: AEO.2025.HIGHZTC.PRCE_REAL_IDAL_NA_OIC_NA_NA_Y13DLRPMMBTU.A | D23: 2024 $/MMBtu | F23: 3.572155 | G23: 3.624099 | H23: 3.618806 | I23: 3.601768 | J23: 3.571336 | K23: 3.55915 | L23: 3.533537 | M23: 3.497851 | N23: 3.464142 | O23: 3.459587 | P23: 3.441433 | Q23: 3.415449 | R23: 3.421638 | S23: 3.423545 | T23: 3.432421 | U23: 3.428609 | V23: 3.430913 | W23: 3.425192 | X23: 3.418891 | Y23: 3.422088 | Z23: 3.426063 | AA23: 3.434236 | AB23: 3.444175 | AC23: 3.448749 | AD23: 3.448136 | AE23: 3.449347 | AF23: 3.454516 | AG23: -0.001
A24: Hydrogen | B24: Energy Prices: Industrial: Hydrogen: High Zero-Carbon Technology Cost | C24: AEO.2025.HIGHZTC.PRCE_REAL_IDAL_NA_HDG_NA_NA_Y13DLRPMMBTU.A | D24: 2024 $/MMBtu | F24: 9.533875 | G24: 10.619709 | H24: 10.514131 | I24: 10.426125 | J24: 10.55792 | K24: 10.787679 | L24: 11.065716 | M24: 11.319676 | N24: 11.63994 | O24: 12.155972 | P24: 12.524699 | Q24: 12.666781 | R24: 12.616203 | S24: 12.533028 | T24: 12.742199 | U24: 12.81229 | V24: 12.800771 | W24: 12.675635 | X24: 12.587033 | Y24: 12.651853 | Z24: 12.824852 | AA24: 12.7927 | AB24: 12.813029 | AC24: 12.789708 | AD24: 12.823941 | AE24: 12.685263 | AF24: 12.783066 | AG24: 0.011
A25: Electricity | B25: Energy Prices: Industrial: Electricity: High Zero-Carbon Technology Cost | C25: AEO.2025.HIGHZTC.PRCE_REAL_IDAL_NA_ELC_NA_NA_Y13DLRPMMBTU.A | D25: 2024 $/MMBtu | F25: 26.507746 | G25: 25.922054 | H25: 23.537739 | I25: 22.156487 | J25: 22.004316 | K25: 22.322678 | L25: 22.749052 | M25: 23.346399 | N25: 23.998974 | O25: 24.751463 | P25: 24.95269 | Q25: 24.768763 | R25: 24.45256 | S25: 24.243956 | T25: 24.34145 | U25: 24.228069 | V25: 24.145441 | W25: 24.157953 | X25: 24.287434 | Y25: 24.39603 | Z25: 24.534168 | AA25: 24.641457 | AB25: 24.755726 | AC25: 24.854349 | AD25: 25.022724 | AE25: 25.199516 | AF25: 25.411121 | AG25: -0.002
A26: Transportation
