Workbook

Sheet About
A1: FoPTaFbIC Fractions of Products That are Fuels by ISIC Code
A3: Sources: | B3: U.S. Energy Information Administration
B4: U.S. Energy Information Administration
B5: 2026
B6: Annual Energy Outlook 2026
B7: Alternative electricity and transportation:Table 2, Table 3, Table 6, Table 17
B8: https://www.eia.gov/outlooks/aeo/tables_side_xls.php
B10: Table numbers specified on "Calculations" tab
B12: Also relies on data from io-model/BObIC and fuels/BFPaT
A14: Notes
A15: This variable expresses what share of the products of a particular ISIC code
A16: consist of fuels. For example, ISIC 19 (Coke and refined petroleum products)
A17: mostly consists of refined fuels, but refineries also produce some chemicals
A18: sold to the chemicals industry (such as BTX aromatics), which are not fuels.
A20: For most industries, the fraction in this variable should be zero, because most
A21: industries do not produce any fuels at all.
A23: Energy carriers such as electricity and heat are considered fuels in this variable.
A25: Fuel | B25: Producer ISIC Code | C25: ISIC Meaning
A26: electricity | B26: ISIC 351 | C26: Electricity generation and distribution
A27: hard coal | B27: ISIC 05 | C27: Coal mining
A28: natural gas | B28: ISIC 352T353 | C28: Energy pipelines and gas processing
A29: nuclear | B29: ISIC 07T08 | C29: Mining and quarrying of uranium and non-energy-producing products
A30: hydro | B30: ISIC 351 | C30: Electricity generation and distribution
A31: wind | B31: ISIC 351 | C31: Electricity generation and distribution
A32: solar | B32: ISIC 351 | C32: Electricity generation and distribution
A33: biomass | B33: ISIC 01T03 | C33: Agriculture, forestry and fishing
A34: petroleum gasoline | B34: ISIC 19 | C34: Refining
A35: petroleum diesel | B35: ISIC 19 | C35: Refining
A36: biofuel gasoline | B36: ISIC 19 | C36: Refining
... A46: hydrogen | B46: ISIC 352T353 | C46: Energy pipelines and gas processing
A48: 42-code sibling (build_sector_shares_42):
A49: This workbook is the 42-code (un-split) sibling of the 52-code expansion. The 42 scheme is the 52 scheme with the six OECD-native parents
A50: left merged (ISIC 01T03, 07T08, 30, 49T53, 69T82, 90T96); the BEA carves ISIC 231/239 and 351/352T353 are retained (present in both
A51: schemes).
A53: The output tabs are the stock derivation, unchanged and live: the stock workbook is natively 42-code (its output columns already are the
A54: 42-code ISIC list, in canonical order), so no child split is applied here. This is a RATE file (fraction of each code's products that are
A55: fuels), not an allocation, so its columns are NOT expected to sum to 1 across ISIC. It is emitted verbatim at 42 codes.

Sheet source data>

Sheet AEO 2025 Table 2
A1: Table 2. Energy Consumption by Sector and Source
A2: https://www.eia.gov/outlooks/aeo/data/browser/#/?id=2-AEO2025&cases=highZTC&sourcekey=0
A3: Tue Dec 02 2025 13:12:48 GMT-0800 (Pacific Standard Time)
A4: Source: U.S. Energy Information Administration
B5: full name | C5: api key | D5: units | E5: 2023 | F5: 2024 | G5: 2025 | H5: 2026 | I5: 2027 | J5: 2028 | K5: 2029 | L5: 2030 | M5: 2031 | N5: 2032 | O5: 2033 | P5: 2034 | Q5: 2035 | R5: 2036 | S5: 2037 | T5: 2038 | U5: 2039 | V5: 2040 | W5: 2041 | X5: 2042 | Y5: 2043 | Z5: 2044 | AA5: 2045 | AB5: 2046 | AC5: 2047 | AD5: 2048 | AE5: 2049 | AF5: 2050 | AG5: Growth (2024-2050)
A6: Residential
A7: Propane | B7: Energy Use: Residential: Propane: High Zero-Carbon Technology Cost | C7: AEO.2025.HIGHZTC.CNSM_ENU_RESD_NA_PROP_NA_NA_QBTU.A | D7: quads | F7: 0.445585 | G7: 0.480711 | H7: 0.477666 | I7: 0.473743 | J7: 0.469514 | K7: 0.464486 | L7: 0.458849 | M7: 0.453163 | N7: 0.447466 | O7: 0.442258 | P7: 0.437043 | Q7: 0.432687 | R7: 0.429065 | S7: 0.426084 | T7: 0.423529 | U7: 0.421347 | V7: 0.419476 | W7: 0.417701 | X7: 0.416029 | Y7: 0.414376 | Z7: 0.412896 | AA7: 0.411593 | AB7: 0.41062 | AC7: 0.409815 | AD7: 0.409114 | AE7: 0.408349 | AF7: 0.407288 | AG7: -0.003
A8: Distillate Fuel Oil | B8: Energy Use: Residential: Distillate Fuel Oil: High Zero-Carbon Technology Cost | C8: AEO.2025.HIGHZTC.CNSM_ENU_RESD_NA_DFO_NA_NA_QBTU.A | D8: quads | F8: 0.445877 | G8: 0.475235 | H8: 0.468476 | I8: 0.459419 | J8: 0.449316 | K8: 0.439104 | L8: 0.429291 | M8: 0.420822 | N8: 0.413547 | O8: 0.407175 | P8: 0.400771 | Q8: 0.394716 | R8: 0.388874 | S8: 0.383074 | T8: 0.377439 | U8: 0.371949 | V8: 0.366483 | W8: 0.361042 | X8: 0.355729 | Y8: 0.350562 | Z8: 0.345267 | AA8: 0.340544 | AB8: 0.335973 | AC8: 0.331592 | AD8: 0.327346 | AE8: 0.323188 | AF8: 0.318975 | AG8: -0.013
A9: Petroleum and Other Liquids Subtotal | B9: Energy Use: Residential: Liquid Fuels Subtotal: High Zero-Carbon Technology Cost | C9: AEO.2025.HIGHZTC.CNSM_ENU_RESD_NA_LFL_NA_NA_QBTU.A | D9: quads | F9: 0.891462 | G9: 0.955946 | H9: 0.946142 | I9: 0.933162 | J9: 0.918829 | K9: 0.90359 | L9: 0.88814 | M9: 0.873986 | N9: 0.861013 | O9: 0.849433 | P9: 0.837815 | Q9: 0.827403 | R9: 0.817938 | S9: 0.809158 | T9: 0.800968 | U9: 0.793296 | V9: 0.785959 | W9: 0.778743 | X9: 0.771758 | Y9: 0.764938 | Z9: 0.758162 | AA9: 0.752137 | AB9: 0.746593 | AC9: 0.741407 | AD9: 0.73646 | AE9: 0.731537 | AF9: 0.726263 | AG9: -0.008
A10: Natural Gas | B10: Energy Use: Residential: Natural Gas: High Zero-Carbon Technology Cost | C10: AEO.2025.HIGHZTC.CNSM_ENU_RESD_NA_NG_NA_NA_QBTU.A | D10: quads | F10: 4.60344 | G10: 4.966208 | H10: 4.999522 | I10: 5.019517 | J10: 5.029608 | K10: 5.016108 | L10: 4.994521 | M10: 4.960952 | N10: 4.913073 | O10: 4.871797 | P10: 4.830965 | Q10: 4.800086 | R10: 4.776269 | S10: 4.75662 | T10: 4.738029 | U10: 4.720499 | V10: 4.700645 | W10: 4.675209 | X10: 4.647515 | Y10: 4.6187 | Z10: 4.591101 | AA10: 4.565073 | AB10: 4.53873 | AC10: 4.513139 | AD10: 4.488929 | AE10: 4.465213 | AF10: 4.441305 | AG10: -0.001
A11: Renewable Energy | B11: Energy Use: Residential: Renewable Energy: High Zero-Carbon Technology Cost | C11: AEO.2025.HIGHZTC.CNSM_ENU_RESD_NA_REN_NA_NA_QBTU.A | D11: quads | F11: 0.357584 | G11: 0.365094 | H11: 0.352654 | I11: 0.347295 | J11: 0.345718 | K11: 0.345503 | L11: 0.34529 | M11: 0.342499 | N11: 0.337295 | O11: 0.332838 | P11: 0.328234 | Q11: 0.323965 | R11: 0.319381 | S11: 0.315221 | T11: 0.311018 | U11: 0.306564 | V11: 0.302182 | W11: 0.2981 | X11: 0.294377 | Y11: 0.29095 | Z11: 0.288536 | AA11: 0.284935 | AB11: 0.281377 | AC11: 0.277692 | AD11: 0.273872 | AE11: 0.270572 | AF11: 0.26805 | AG11: -0.011
A12: Purchased Electricity for Residential Use | B12: Energy Use: Residential: Electricity: High Zero-Carbon Technology Cost | C12: AEO.2025.HIGHZTC.CNSM_ENU_RESD_NA_ELC_NA_NA_QBTU.A | D12: quads | F12: 5.097395 | G12: 5.01535 | H12: 5.056309 | I12: 5.103827 | J12: 5.128921 | K12: 5.120373 | L12: 5.090785 | M12: 5.051124 | N12: 5.01591 | O12: 4.988002 | P12: 4.969066 | Q12: 4.970526 | R12: 4.986686 | S12: 5.011181 | T12: 5.033259 | U12: 5.06003 | V12: 5.086498 | W12: 5.113048 | X12: 5.141541 | Y12: 5.172765 | Z12: 5.203447 | AA12: 5.233101 | AB12: 5.262091 | AC12: 5.290592 | AD12: 5.318973 | AE12: 5.348809 | AF12: 5.378547 | AG12: 0.002
A13: Delivered Energy | B13: Energy Use: Residential: Delivered Energy: High Zero-Carbon Technology Cost | C13: AEO.2025.HIGHZTC.CNSM_ENU_RESD_NA_DELE_NA_NA_QBTU.A | D13: quads | F13: 10.949879 | G13: 11.302598 | H13: 11.354626 | I13: 11.403802 | J13: 11.423075 | K13: 11.385574 | L13: 11.318736 | M13: 11.22856 | N13: 11.127291 | O13: 11.04207 | P13: 10.96608 | Q13: 10.921979 | R13: 10.900274 | S13: 10.892181 | T13: 10.883274 | U13: 10.880389 | V13: 10.875284 | W13: 10.865099 | X13: 10.855191 | Y13: 10.847352 | Z13: 10.841247 | AA13: 10.835244 | AB13: 10.828792 | AC13: 10.82283 | AD13: 10.818233 | AE13: 10.81613 | AF13: 10.814168 | AG13: 0
A14: Electricity-Related Losses | B14: Energy Use: Residential: Electricity Related Losses: High Zero-Carbon Technology Cost | C14: AEO.2025.HIGHZTC.CNSM_ENU_RESD_NA_ERL_NA_NA_QBTU.A | D14: quads | F14: 7.245147 | G14: 6.912201 | H14: 6.553731 | I14: 6.362611 | J14: 6.252065 | K14: 6.13198 | L14: 5.851551 | M14: 5.620308 | N14: 5.220071 | O14: 5.0221 | P14: 4.822125 | Q14: 4.611793 | R14: 4.429836 | S14: 4.219049 | T14: 4.103611 | U14: 3.878483 | V14: 3.828674 | W14: 3.840003 | X14: 3.853276 | Y14: 3.849748 | Z14: 3.852274 | AA14: 3.831165 | AB14: 3.808954 | AC14: 3.799681 | AD14: 3.800865 | AE14: 3.810485 | AF14: 3.790734 | AG14: -0.025
A15: Total | B15: Energy Use: Residential: Total: High Zero-Carbon Technology Cost | C15: AEO.2025.HIGHZTC.CNSM_ENU_RESD_NA_TOT_NA_NA_QBTU.A | D15: quads | F15: 18.195026 | G15: 18.2148 | H15: 17.908356 | I15: 17.766413 | J15: 17.67514 | K15: 17.517555 | L15: 17.170286 | M15: 16.848869 | N15: 16.347363 | O15: 16.064171 | P15: 15.788204 | Q15: 15.533772 | R15: 15.330111 | S15: 15.111231 | T15: 14.986885 | U15: 14.758872 | V15: 14.703958 | W15: 14.705102 | X15: 14.708467 | Y15: 14.6971 | Z15: 14.693521 | AA15: 14.666409 | AB15: 14.637746 | AC15: 14.622511 | AD15: 14.619099 | AE15: 14.626616 | AF15: 14.604902 | AG15: -0.008
A16: Commercial
A17: Propane | B17: Energy Use: Commercial: Propane: High Zero-Carbon Technology Cost | C17: AEO.2025.HIGHZTC.CNSM_ENU_COMM_NA_PROP_NA_NA_QBTU.A | D17: quads | F17: 0.203527 | G17: 0.207036 | H17: 0.211189 | I17: 0.21576 | J17: 0.220555 | K17: 0.224618 | L17: 0.228576 | M17: 0.232463 | N17: 0.236365 | O17: 0.240305 | P17: 0.244263 | Q17: 0.248203 | R17: 0.252085 | S17: 0.255888 | T17: 0.25962 | U17: 0.263292 | V17: 0.266917 | W17: 0.270508 | X17: 0.274074 | Y17: 0.277623 | Z17: 0.281163 | AA17: 0.284705 | AB17: 0.288254 | AC17: 0.29182 | AD17: 0.295404 | AE17: 0.299009 | AF17: 0.302635 | AG17: 0.015
A18: Motor Gasoline | B18: Energy Use: Commercial: Motor Gasoline: High Zero-Carbon Technology Cost | C18: AEO.2025.HIGHZTC.CNSM_ENU_COMM_NA_MGS_NA_NA_QBTU.A | D18: quads | F18: 0.433115 | G18: 0.438858 | H18: 0.445824 | I18: 0.453659 | J18: 0.46196 | K18: 0.470477 | L18: 0.478778 | M18: 0.486934 | N18: 0.495121 | O18: 0.503391 | P18: 0.5117 | Q18: 0.519974 | R18: 0.52813 | S18: 0.536125 | T18: 0.543972 | U18: 0.551696 | V18: 0.559325 | W18: 0.566886 | X18: 0.574397 | Y18: 0.581873 | Z18: 0.589333 | AA18: 0.596798 | AB18: 0.604282 | AC18: 0.6118 | AD18: 0.619359 | AE18: 0.626964 | AF18: 0.634613 | AG18: 0.015
A19: Kerosene | B19: Energy Use: Commercial: Kerosene: High Zero-Carbon Technology Cost | C19: AEO.2025.HIGHZTC.CNSM_ENU_COMM_NA_KRS_NA_NA_QBTU.A | D19: quads | F19: 0.002101 | G19: 0.001663 | H19: 0.003083 | I19: 0.0031 | J19: 0.00296 | K19: 0.002497 | L19: 0.002105 | M19: 0.002033 | N19: 0.002065 | O19: 0.00189 | P19: 0.001818 | Q19: 0.001706 | R19: 0.001673 | S19: 0.001536 | T19: 0.00143 | U19: 0.001377 | V19: 0.001275 | W19: 0.001142 | X19: 0.001025 | Y19: 0.000888 | Z19: 0.000688 | AA19: 0.000707 | AB19: 0.000673 | AC19: 0.000662 | AD19: 0.00067 | AE19: 0.000649 | AF19: 0.00061 | AG19: -0.046
A20: Distillate Fuel Oil | B20: Energy Use: Commercial: Distillate Fuel Oil: High Zero-Carbon Technology Cost | C20: AEO.2025.HIGHZTC.CNSM_ENU_COMM_NA_DFO_NA_NA_QBTU.A | D20: quads | F20: 0.308284 | G20: 0.316531 | H20: 0.320091 | I20: 0.322023 | J20: 0.322813 | K20: 0.322871 | L20: 0.32285 | M20: 0.322282 | N20: 0.32166 | O20: 0.320479 | P20: 0.319178 | Q20: 0.317716 | R20: 0.316511 | S20: 0.315075 | T20: 0.313805 | U20: 0.312652 | V20: 0.311396 | W20: 0.310069 | X20: 0.30861 | Y20: 0.307126 | Z20: 0.305111 | AA20: 0.303931 | AB20: 0.302812 | AC20: 0.302144 | AD20: 0.301719 | AE20: 0.30106 | AF20: 0.30013 | AG20: -0.001
A21: Residual Fuel Oil | B21: Energy Use: Commercial: Residual Fuel Oil: High Zero-Carbon Technology Cost | C21: AEO.2025.HIGHZTC.CNSM_ENU_COMM_NA_RFO_NA_NA_QBTU.A | D21: quads | F21: 0.00255 | G21: 0.000986 | H21: 0.000986 | I21: 0.001056 | J21: 0.001132 | K21: 0.001157 | L21: 0.00118 | M21: 0.001204 | N21: 0.001227 | O21: 0.001251 | P21: 0.001274 | Q21: 0.001298 | R21: 0.001321 | S21: 0.001343 | T21: 0.001365 | U21: 0.001386 | V21: 0.001407 | W21: 0.001427 | X21: 0.001447 | Y21: 0.001467 | Z21: 0.001487 | AA21: 0.001507 | AB21: 0.001527 | AC21: 0.001546 | AD21: 0.001566 | AE21: 0.001586 | AF21: 0.001606 | AG21: -0.018
A22: Petroleum and Other Liquids Subtotal | B22: Energy Use: Commercial: Liquid Fuels Subtotal: High Zero-Carbon Technology Cost | C22: AEO.2025.HIGHZTC.CNSM_ENU_COMM_NA_LFL_NA_NA_QBTU.A | D22: quads | F22: 0.949578 | G22: 0.965074 | H22: 0.981173 | I22: 0.995598 | J22: 1.009419 | K22: 1.02162 | L22: 1.033489 | M22: 1.044916 | N22: 1.056438 | O22: 1.067316 | P22: 1.078234 | Q22: 1.088896 | R22: 1.099719 | S22: 1.109967 | T22: 1.120192 | U22: 1.130402 | V22: 1.140319 | W22: 1.150033 | X22: 1.159553 | Y22: 1.168977 | Z22: 1.177783 | AA22: 1.187648 | AB22: 1.197548 | AC22: 1.207972 | AD22: 1.218718 | AE22: 1.229268 | AF22: 1.239594 | AG22: 0.01
A23: Natural Gas | B23: Energy Use: Commercial: Natural Gas: High Zero-Carbon Technology Cost | C23: AEO.2025.HIGHZTC.CNSM_ENU_COMM_NA_NG_NA_NA_QBTU.A | D23: quads | F23: 3.426704 | G23: 3.611178 | H23: 3.645448 | I23: 3.652436 | J23: 3.643887 | K23: 3.643972 | L23: 3.636758 | M23: 3.632056 | N23: 3.618527 | O23: 3.602453 | P23: 3.590345 | Q23: 3.58766 | R23: 3.594494 | S23: 3.606606 | T23: 3.620292 | U23: 3.636338 | V23: 3.64947 | W23: 3.657411 | X23: 3.662507 | Y23: 3.666111 | Z23: 3.672477 | AA23: 3.67936 | AB23: 3.683807 | AC23: 3.690529 | AD23: 3.699193 | AE23: 3.706769 | AF23: 3.713181 | AG23: 0.003
A24: Coal | B24: Energy Use: Commercial: Coal: High Zero-Carbon Technology Cost | C24: AEO.2025.HIGHZTC.CNSM_ENU_COMM_NA_CL_NA_NA_QBTU.A | D24: quads | F24: 0.012118 | G24: 0.01267 | H24: 0.016739 | I24: 0.017261 | J24: 0.018487 | K24: 0.017758 | L24: 0.018493 | M24: 0.019202 | N24: 0.020131 | O24: 0.020423 | P24: 0.021234 | Q24: 0.021901 | R24: 0.022011 | S24: 0.022176 | T24: 0.021845 | U24: 0.022261 | V24: 0.022491 | W24: 0.022289 | X24: 0.022298 | Y24: 0.022141 | Z24: 0.021983 | AA24: 0.021868 | AB24: 0.021568 | AC24: 0.021554 | AD24: 0.021545 | AE24: 0.021557 | AF24: 0.021255 | AG24: 0.022
A25: Renewable Energy | B25: Energy Use: Commercial: Renewable Energy: High Zero-Carbon Technology Cost | C25: AEO.2025.HIGHZTC.CNSM_ENU_COMM_NA_REN_NA_NA_QBTU.A | D25: quads | F25: 0.158104 | G25: 0.158104 | H25: 0.158104 | I25: 0.158104 | J25: 0.158104 | K25: 0.158104 | L25: 0.158104 | M25: 0.158104 | N25: 0.158104 | O25: 0.158104 | P25: 0.158104 | Q25: 0.158104 | R25: 0.158104 | S25: 0.158104 | T25: 0.158104 | U25: 0.158104 | V25: 0.158104 | W25: 0.158104 | X25: 0.158104 | Y25: 0.158104 | Z25: 0.158104 | AA25: 0.158104 | AB25: 0.158104 | AC25: 0.158104 | AD25: 0.158104 | AE25: 0.158104 | AF25: 0.158104 | AG25: 0
A26: Purchased Electricity for Commercial Use | B26: Energy Use: Commercial: Electricity: High Zero-Carbon Technology Cost | C26: AEO.2025.HIGHZTC.CNSM_ENU_COMM_NA_ELC_NA_NA_QBTU.A | D26: quads | F26: 4.749338 | G26: 4.82175 | H26: 4.782341 | I26: 4.826618 | J26: 4.861098 | K26: 4.927334 | L26: 4.967134 | M26: 5.003686 | N26: 5.045472 | O26: 5.084223 | P26: 5.135777 | Q26: 5.202976 | R26: 5.281009 | S26: 5.36371 | T26: 5.440923 | U26: 5.525065 | V26: 5.609845 | W26: 5.695757 | X26: 5.78301 | Y26: 5.872692 | Z26: 5.964936 | AA26: 6.058793 | AB26: 6.155428 | AC26: 6.253218 | AD26: 6.354017 | AE26: 6.457747 | AF26: 6.564499 | AG26: 0.013
A27: Delivered Energy | B27: Energy Use: Commercial: Delivered Energy: High Zero-Carbon Technology Cost | C27: AEO.2025.HIGHZTC.CNSM_ENU_COMM_NA_DELE_NA_NA_QBTU.A | D27: quads | F27: 9.295842 | G27: 9.568778 | H27: 9.583804 | I27: 9.650017 | J27: 9.690993 | K27: 9.768787 | L27: 9.813977 | M27: 9.857964 | N27: 9.898672 | O27: 9.932518 | P27: 9.983692 | Q27: 10.059537 | R27: 10.155337 | S27: 10.260563 | T27: 10.361356 | U27: 10.472172 | V27: 10.58023 | W27: 10.683596 | X27: 10.785473 | Y27: 10.888024 | Z27: 10.995282 | AA27: 11.105772 | AB27: 11.216454 | AC27: 11.331375 | AD27: 11.451575 | AE27: 11.573444 | AF27: 11.696633 | AG27: 0.009
A28: Electricity-Related Losses | B28: Energy Use: Commercial: Electricity Related Losses: High Zero-Carbon Technology Cost | C28: AEO.2025.HIGHZTC.CNSM_ENU_COMM_NA_ERL_NA_NA_QBTU.A | D28: quads | F28: 6.750439 | G28: 6.64538 | H28: 6.198627 | I28: 6.017033 | J28: 5.925594 | K28: 5.900803 | L28: 5.709422 | M28: 5.567525 | N28: 5.250836 | O28: 5.118978 | P28: 4.983905 | Q28: 4.827467 | R28: 4.691292 | S28: 4.515852 | T28: 4.43598 | U28: 4.234931 | V28: 4.222603 | W28: 4.277629 | X28: 4.334019 | Y28: 4.370658 | Z28: 4.416029 | AA28: 4.435656 | AB28: 4.455595 | AC28: 4.491035 | AD28: 4.540494 | AE28: 4.600491 | AF28: 4.626578 | AG28: -0.014
A29: Total | B29: Energy Use: Commercial: Total: High Zero-Carbon Technology Cost | C29: AEO.2025.HIGHZTC.CNSM_ENU_COMM_NA_TOT_NA_NA_QBTU.A | D29: quads | F29: 16.046282 | G29: 16.214157 | H29: 15.782431 | I29: 15.667049 | J29: 15.616587 | K29: 15.66959 | L29: 15.523399 | M29: 15.425488 | N29: 15.149508 | O29: 15.051496 | P29: 14.967597 | Q29: 14.887005 | R29: 14.84663 | S29: 14.776415 | T29: 14.797336 | U29: 14.707102 | V29: 14.802834 | W29: 14.961225 | X29: 15.119492 | Y29: 15.258682 | Z29: 15.411311 | AA29: 15.541428 | AB29: 15.672049 | AC29: 15.82241 | AD29: 15.992069 | AE29: 16.173935 | AF29: 16.323212 | AG29: 0.001
A30: Industrial
A31: Hydrocarbon Gas Liquids | B31: Energy Use: Industrial: Hydrocarbon Gas Liquids: High Zero-Carbon Technology Cost | C31: AEO.2025.HIGHZTC.CNSM_ENU_IDAL_NA_LPG_NA_NA_QBTU.A | D31: quads | F31: 3.549334 | G31: 3.612091 | H31: 3.608268 | I31: 3.613257 | J31: 3.619893 | K31: 3.625968 | L31: 3.630452 | M31: 3.632591 | N31: 3.634803 | O31: 3.636342 | P31: 3.633108 | Q31: 3.629704 | R31: 3.62797 | S31: 3.623356 | T31: 3.653424 | U31: 3.722283 | V31: 3.797693 | W31: 3.858349 | X31: 3.921485 | Y31: 3.966205 | Z31: 3.93869 | AA31: 3.899894 | AB31: 3.9388 | AC31: 4.012206 | AD31: 4.06568 | AE31: 4.039013 | AF31: 4.011276 | AG31: 0.005
A32: Motor Gasoline | B32: Energy Use: Industrial: Motor Gasoline: High Zero-Carbon Technology Cost | C32: AEO.2025.HIGHZTC.CNSM_ENU_IDAL_NA_MGS_NA_NA_QBTU.A | D32: quads | F32: 0.281291 | G32: 0.285247 | H32: 0.288387 | I32: 0.292239 | J32: 0.297109 | K32: 0.302658 | L32: 0.307115 | M32: 0.310404 | N32: 0.313444 | O32: 0.31532 | P32: 0.316919 | Q32: 0.319351 | R32: 0.322235 | S32: 0.32399 | T32: 0.3259 | U32: 0.327691 | V32: 0.329586 | W32: 0.33104 | X32: 0.333046 | Y32: 0.334606 | Z32: 0.336343 | AA32: 0.339079 | AB32: 0.342198 | AC32: 0.345227 | AD32: 0.348264 | AE32: 0.351611 | AF32: 0.3547 | AG32: 0.009
A33: Distillate Fuel Oil | B33: Energy Use: Industrial: Distillate Fuel Oil: High Zero-Carbon Technology Cost | C33: AEO.2025.HIGHZTC.CNSM_ENU_IDAL_NA_DFO_NA_NA_QBTU.A | D33: quads | F33: 1.140013 | G33: 1.15177 | H33: 1.163439 | I33: 1.177088 | J33: 1.195205 | K33: 1.216104 | L33: 1.23274 | M33: 1.246904 | N33: 1.260956 | O33: 1.269289 | P33: 1.277959 | Q33: 1.288505 | R33: 1.299513 | S33: 1.308196 | T33: 1.317186 | U33: 1.324638 | V33: 1.332429 | W33: 1.337751 | X33: 1.344097 | Y33: 1.349923 | Z33: 1.356099 | AA33: 1.364485 | AB33: 1.374968 | AC33: 1.385294 | AD33: 1.394428 | AE33: 1.405687 | AF33: 1.41575 | AG33: 0.008
A34: Residual Fuel Oil | B34: Energy Use: Industrial: Residual Fuel Oil: High Zero-Carbon Technology Cost | C34: AEO.2025.HIGHZTC.CNSM_ENU_IDAL_NA_RFO_NA_NA_QBTU.A | D34: quads | F34: 0.041174 | G34: 0.04198 | H34: 0.041255 | I34: 0.040061 | J34: 0.038841 | K34: 0.037551 | L34: 0.036369 | M34: 0.035532 | N34: 0.035132 | O34: 0.03466 | P34: 0.034279 | Q34: 0.033786 | R34: 0.033265 | S34: 0.032701 | T34: 0.032198 | U34: 0.031759 | V34: 0.031438 | W34: 0.031172 | X34: 0.030896 | Y34: 0.030629 | Z34: 0.03044 | AA34: 0.03024 | AB34: 0.029949 | AC34: 0.029728 | AD34: 0.029473 | AE34: 0.029252 | AF34: 0.028857 | AG34: -0.014
A35: Petrochemical Feedstocks | B35: Energy Use: Industrial: Petrochemical Feedstocks: High Zero-Carbon Technology Cost | C35: AEO.2025.HIGHZTC.CNSM_ENU_IDAL_NA_PCF_NA_NA_QBTU.A | D35: quads | F35: 0.390525 | G35: 0.355 | H35: 0.55 | I35: 0.55 | J35: 0.55 | K35: 0.55 | L35: 0.55 | M35: 0.55 | N35: 0.55 | O35: 0.55 | P35: 0.55 | Q35: 0.55 | R35: 0.55 | S35: 0.55 | T35: 0.55 | U35: 0.55 | V35: 0.55 | W35: 0.55 | X35: 0.55 | Y35: 0.55 | Z35: 0.69558 | AA35: 0.84116 | AB35: 0.84116 | AC35: 0.84116 | AD35: 0.84116 | AE35: 0.964095 | AF35: 1.087029 | AG35: 0.04
A36: Other Petroleum | B36: Energy Use: Industrial: Other Petroleum: High Zero-Carbon Technology Cost | C36: AEO.2025.HIGHZTC.CNSM_ENU_IDAL_NA_ONP_NA_NA_QBTU.A | D36: quads | F36: 3.074002 | G36: 3.114025 | H36: 3.07424 | I36: 3.102287 | J36: 3.148089 | K36: 3.139748 | L36: 3.174176 | M36: 3.191782 | N36: 3.191282 | O36: 3.177934 | P36: 3.190891 | Q36: 3.189156 | R36: 3.203246 | S36: 3.207888 | T36: 3.208309 | U36: 3.218726 | V36: 3.236173 | W36: 3.244213 | X36: 3.23302 | Y36: 3.249378 | Z36: 3.249571 | AA36: 3.248773 | AB36: 3.261228 | AC36: 3.279748 | AD36: 3.279907 | AE36: 3.276667 | AF36: 3.263268 | AG36: 0.002
A37: Petroleum and Other Liquids Subtotal | B37: Energy Use: Industrial: Liquid Fuels Subtotal: High Zero-Carbon Technology Cost | C37: AEO.2025.HIGHZTC.CNSM_ENU_IDAL_NA_LFL_NA_NA_QBTU.A | D37: quads | F37: 8.476339 | G37: 8.560113 | H37: 8.72559 | I37: 8.774933 | J37: 8.849136 | K37: 8.872029 | L37: 8.930853 | M37: 8.967214 | N37: 8.985618 | O37: 8.983544 | P37: 9.003156 | Q37: 9.010503 | R37: 9.036229 | S37: 9.046131 | T37: 9.087018 | U37: 9.175098 | V37: 9.277319 | W37: 9.352525 | X37: 9.412545 | Y37: 9.480742 | Z37: 9.606723 | AA37: 9.723632 | AB37: 9.788304 | AC37: 9.893365 | AD37: 9.958912 | AE37: 10.066326 | AF37: 10.16088 | AG37: 0.007
A38: Natural Gas | B38: Energy Use: Industrial: Natural Gas: High Zero-Carbon Technology Cost | C38: AEO.2025.HIGHZTC.CNSM_ENU_IDAL_NA_NG_NA_NA_QBTU.A | D38: quads | F38: 7.80328 | G38: 7.915454 | H38: 7.686133 | I38: 7.688715 | J38: 7.692211 | K38: 7.711431 | L38: 7.726192 | M38: 7.761615 | N38: 7.771588 | O38: 7.73987 | P38: 7.705995 | Q38: 7.678161 | R38: 7.665715 | S38: 7.666882 | T38: 7.698881 | U38: 7.741982 | V38: 7.785161 | W38: 7.798125 | X38: 7.81503 | Y38: 7.852369 | Z38: 7.872563 | AA38: 7.894576 | AB38: 7.920349 | AC38: 7.972322 | AD38: 8.010198 | AE38: 8.04101 | AF38: 8.062402 | AG38: 0.001
A39: Lease and Plant Fuel | B39: Energy Use: Industrial: Lease and Plant Fuel: High Zero-Carbon Technology Cost | C39: AEO.2025.HIGHZTC.CNSM_ENU_IDAL_NA_LSAPFL_NA_NA_QBTU.A | D39: quads | F39: 2.045295 | G39: 2.052198 | H39: 2.151558 | I39: 2.160423 | J39: 2.206005 | K39: 2.226782 | L39: 2.238047 | M39: 2.23259 | N39: 2.285561 | O39: 2.298938 | P39: 2.313583 | Q39: 2.305008 | R39: 2.296317 | S39: 2.271652 | T39: 2.265647 | U39: 2.24652 | V39: 2.25015 | W39: 2.26053 | X39: 2.271182 | Y39: 2.275658 | Z39: 2.278661 | AA39: 2.28227 | AB39: 2.29152 | AC39: 2.301058 | AD39: 2.305694 | AE39: 2.311272 | AF39: 2.318181 | AG39: 0.005
A40: Natural Gas Subtotal | B40: Energy Use: Industrial: Natural Gas Subtotal: High Zero-Carbon Technology Cost | C40: AEO.2025.HIGHZTC.CNSM_ENU_IDAL_NA_NGS_NA_NA_QBTU.A | D40: quads | F40: 9.848575 | G40: 9.967653 | H40: 9.837691 | I40: 9.849138 | J40: 9.898215 | K40: 9.938212 | L40: 9.964239 | M40: 9.994205 | N40: 10.057149 | O40: 10.038807 | P40: 10.019579 | Q40: 9.983169 | R40: 9.962032 | S40: 9.938534 | T40: 9.964528 | U40: 9.988503 | V40: 10.035312 | W40: 10.058655 | X40: 10.086212 | Y40: 10.128028 | Z40: 10.151224 | AA40: 10.176846 | AB40: 10.211869 | AC40: 10.273379 | AD40: 10.315892 | AE40: 10.352282 | AF40: 10.380583 | AG40: 0.002
...

Sheet AEO 2025 Table 3
A1: Table 3. Energy Prices by Sector and Source
A2: https://www.eia.gov/outlooks/aeo/data/browser/#/?id=3-AEO2025&cases=highZTC&sourcekey=0
A3: Tue Dec 02 2025 13:12:56 GMT-0800 (Pacific Standard Time)
A4: Source: U.S. Energy Information Administration
B5: full name | C5: api key | D5: units | E5: 2023 | F5: 2024 | G5: 2025 | H5: 2026 | I5: 2027 | J5: 2028 | K5: 2029 | L5: 2030 | M5: 2031 | N5: 2032 | O5: 2033 | P5: 2034 | Q5: 2035 | R5: 2036 | S5: 2037 | T5: 2038 | U5: 2039 | V5: 2040 | W5: 2041 | X5: 2042 | Y5: 2043 | Z5: 2044 | AA5: 2045 | AB5: 2046 | AC5: 2047 | AD5: 2048 | AE5: 2049 | AF5: 2050 | AG5: Growth (2024-2050)
A6: Residential
A7: Propane | B7: Energy Prices: Residential: Propane: High Zero-Carbon Technology Cost | C7: AEO.2025.HIGHZTC.PRCE_REAL_RESD_NA_PROP_NA_NA_Y13DLRPMMBTU.A | D7: 2024 $/MMBtu | F7: 26.593981 | G7: 25.690693 | H7: 25.882023 | I7: 25.734011 | J7: 25.761881 | K7: 25.984186 | L7: 26.494528 | M7: 27.035074 | N7: 27.848438 | O7: 28.895929 | P7: 29.836832 | Q7: 30.497536 | R7: 30.975727 | S7: 31.295523 | T7: 31.443632 | U7: 31.521713 | V7: 31.634783 | W7: 31.863678 | X7: 32.095478 | Y7: 32.443432 | Z7: 32.908676 | AA7: 33.216011 | AB7: 33.459888 | AC7: 33.58733 | AD7: 33.707253 | AE7: 33.953312 | AF7: 34.455376 | AG7: 0.01
A8: Distillate Fuel Oil | B8: Energy Prices: Residential: Distillate Fuel Oil: High Zero-Carbon Technology Cost | C8: AEO.2025.HIGHZTC.PRCE_REAL_RESD_NA_DFO_NA_NA_Y13DLRPMMBTU.A | D8: 2024 $/MMBtu | F8: 26.158379 | G8: 24.617764 | H8: 24.643763 | I8: 25.310112 | J8: 26.17977 | K8: 27.100401 | L8: 28.068832 | M8: 28.11725 | N8: 28.0326 | O8: 28.357315 | P8: 28.466999 | Q8: 28.689667 | R8: 28.809559 | S8: 29.071898 | T8: 29.171333 | U8: 29.291199 | V8: 29.469152 | W8: 29.758438 | X8: 29.994083 | Y8: 30.294477 | Z8: 30.955036 | AA8: 30.868721 | AB8: 30.956972 | AC8: 30.914091 | AD8: 30.902479 | AE8: 30.934729 | AF8: 31.279491 | AG8: 0.007
A9: Natural Gas | B9: Energy Prices: Residential: Natural Gas: High Zero-Carbon Technology Cost | C9: AEO.2025.HIGHZTC.PRCE_REAL_RESD_NA_NG_NA_NA_Y13DLRPMMBTU.A | D9: 2024 $/MMBtu | F9: 13.932205 | G9: 12.694278 | H9: 12.476946 | I9: 12.0713 | J9: 11.825522 | K9: 11.708606 | L9: 11.628035 | M9: 11.829365 | N9: 12.259671 | O9: 12.641685 | P9: 12.901601 | Q9: 13.046376 | R9: 13.061166 | S9: 13.048336 | T9: 13.026576 | U9: 12.968637 | V9: 13.000326 | W9: 13.125381 | X9: 13.234643 | Y9: 13.327177 | Z9: 13.385166 | AA9: 13.471466 | AB9: 13.568365 | AC9: 13.612545 | AD9: 13.641063 | AE9: 13.722773 | AF9: 13.794634 | AG9: 0
A10: Electricity | B10: Energy Prices: Residential: Electricity: High Zero-Carbon Technology Cost | C10: AEO.2025.HIGHZTC.PRCE_REAL_RESD_NA_ELC_NA_NA_Y13DLRPMMBTU.A | D10: 2024 $/MMBtu | F10: 45.553139 | G10: 45.024025 | H10: 42.541679 | I10: 40.45982 | J10: 40.182793 | K10: 40.569782 | L10: 41.046375 | M10: 41.716888 | N10: 42.268425 | O10: 43.117485 | P10: 43.465755 | Q10: 43.342434 | R10: 43.037926 | S10: 42.73064 | T10: 42.891632 | U10: 42.628983 | V10: 42.525494 | W10: 42.545128 | X10: 42.731728 | Y10: 42.921192 | Z10: 43.168861 | AA10: 43.377872 | AB10: 43.621025 | AC10: 43.79406 | AD10: 44.126114 | AE10: 44.423275 | AF10: 44.787258 | AG10: -0.001
A11: Commercial
A12: Propane | B12: Energy Prices: Commercial: Propane: High Zero-Carbon Technology Cost | C12: AEO.2025.HIGHZTC.PRCE_REAL_COMM_NA_PROP_NA_NA_Y13DLRPMMBTU.A | D12: 2024 $/MMBtu | F12: 19.0868 | G12: 19.071598 | H12: 19.969246 | I12: 19.804914 | J12: 19.920181 | K12: 20.219919 | L12: 20.798326 | M12: 21.250935 | N12: 22.027008 | O12: 22.973885 | P12: 23.6208 | Q12: 23.91017 | R12: 24.102671 | S12: 24.204554 | T12: 24.180492 | U12: 24.168512 | V12: 24.257711 | W12: 24.494383 | X12: 24.6768 | Y12: 25.001261 | Z12: 25.422537 | AA12: 25.562656 | AB12: 25.683006 | AC12: 25.692684 | AD12: 25.758125 | AE12: 26.007099 | AF12: 26.538202 | AG12: 0.013
A13: Distillate Fuel Oil | B13: Energy Prices: Commercial: Distillate Fuel Oil: High Zero-Carbon Technology Cost | C13: AEO.2025.HIGHZTC.PRCE_REAL_COMM_NA_DFO_NA_NA_Y13DLRPMMBTU.A | D13: 2024 $/MMBtu | F13: 26.207932 | G13: 24.707527 | H13: 23.565269 | I13: 23.058794 | J13: 22.754671 | K13: 22.501291 | L13: 22.297827 | M13: 22.340889 | N13: 22.216309 | O13: 22.527172 | P13: 22.633039 | Q13: 22.83795 | R13: 22.942883 | S13: 23.194223 | T13: 23.297205 | U13: 23.403837 | V13: 23.570314 | W13: 23.852497 | X13: 24.078636 | Y13: 24.381926 | Z13: 25.030125 | AA13: 24.942905 | AB13: 25.028816 | AC13: 24.984297 | AD13: 24.964209 | AE13: 25.003876 | AF13: 25.3452 | AG13: -0.001
A14: Residual Fuel Oil | B14: Energy Prices: Commercial: Residual Fuel: High Zero-Carbon Technology Cost | C14: AEO.2025.HIGHZTC.PRCE_REAL_COMM_NA_RFL_NA_NA_Y13DLRPMMBTU.A | D14: 2024 $/MMBtu | F14: 6.746078 | G14: 7.471698 | H14: 7.841193 | I14: 8.831597 | J14: 9.914908 | K14: 11.015342 | L14: 12.183045 | M14: 12.244162 | N14: 12.208694 | O14: 12.446174 | P14: 12.544676 | Q14: 12.678741 | R14: 12.753716 | S14: 12.87225 | T14: 12.979047 | U14: 12.997785 | V14: 13.118733 | W14: 13.235469 | X14: 13.365701 | Y14: 13.416109 | Z14: 13.347304 | AA14: 13.387928 | AB14: 13.678938 | AC14: 13.632569 | AD14: 13.671235 | AE14: 13.775191 | AF14: 14.322314 | AG14: 0.029
A15: Natural Gas | B15: Energy Prices: Commercial: Natural Gas: High Zero-Carbon Technology Cost | C15: AEO.2025.HIGHZTC.PRCE_REAL_COMM_NA_NG_NA_NA_Y13DLRPMMBTU.A | D15: 2024 $/MMBtu | F15: 9.555858 | G15: 8.473628 | H15: 8.571372 | I15: 8.513054 | J15: 8.593106 | K15: 8.767466 | L15: 8.976199 | M15: 9.121284 | N15: 9.472503 | O15: 9.787833 | P15: 9.988475 | Q15: 10.085086 | R15: 10.067373 | S15: 10.026683 | T15: 9.977905 | U15: 9.894558 | V15: 9.894806 | W15: 9.981339 | X15: 10.052937 | Y15: 10.11166 | Z15: 10.137436 | AA15: 10.191541 | AB15: 10.258538 | AC15: 10.274831 | AD15: 10.279621 | AE15: 10.336456 | AF15: 10.384078 | AG15: 0.003
A16: Electricity | B16: Energy Prices: Commercial: Electricity: High Zero-Carbon Technology Cost | C16: AEO.2025.HIGHZTC.PRCE_REAL_COMM_NA_ELC_NA_NA_Y13DLRPMMBTU.A | D16: 2024 $/MMBtu | F16: 38.551605 | G16: 37.602798 | H16: 35.105431 | I16: 33.124508 | J16: 32.965439 | K16: 33.32024 | L16: 33.809681 | M16: 34.413387 | N16: 34.929173 | O16: 35.701324 | P16: 35.979614 | Q16: 35.811676 | R16: 35.482807 | S16: 35.191898 | T16: 35.411739 | U16: 35.115093 | V16: 34.986004 | W16: 34.99255 | X16: 35.154461 | Y16: 35.305714 | Z16: 35.501835 | AA16: 35.64677 | AB16: 35.79763 | AC16: 35.841282 | AD16: 36.080368 | AE16: 36.286304 | AF16: 36.524944 | AG16: -0.002
A17: Industrial
A18: Propane | B18: Energy Prices: Industrial: Propane: High Zero-Carbon Technology Cost | C18: AEO.2025.HIGHZTC.PRCE_REAL_IDAL_NA_PROP_NA_NA_Y13DLRPMMBTU.A | D18: 2024 $/MMBtu | F18: 12.66026 | G18: 12.605674 | H18: 13.465074 | I18: 13.314802 | J18: 13.427592 | K18: 13.72262 | L18: 14.298682 | M18: 14.759735 | N18: 15.554036 | O18: 16.543209 | P18: 17.23724 | Q18: 17.555822 | R18: 17.767212 | S18: 17.880009 | T18: 17.856604 | U18: 17.844084 | V18: 17.93939 | W18: 18.19438 | X18: 18.394274 | Y18: 18.748419 | Z18: 19.21232 | AA18: 19.372681 | AB18: 19.508192 | AC18: 19.52129 | AD18: 19.593958 | AE18: 19.869528 | AF18: 20.462763 | AG18: 0.019
A19: Distillate Fuel Oil | B19: Energy Prices: Industrial: Distillate Fuel Oil: High Zero-Carbon Technology Cost | C19: AEO.2025.HIGHZTC.PRCE_REAL_IDAL_NA_DFO_NA_NA_Y13DLRPMMBTU.A | D19: 2024 $/MMBtu | F19: 26.091763 | G19: 24.600626 | H19: 23.425852 | I19: 22.88941 | J19: 22.557371 | K19: 22.274755 | L19: 22.032902 | M19: 22.079994 | N19: 21.943752 | O19: 22.273958 | P19: 22.39349 | Q19: 22.623447 | R19: 22.746523 | S19: 23.008989 | T19: 23.10652 | U19: 23.218241 | V19: 23.399351 | W19: 23.679426 | X19: 23.916767 | Y19: 24.223963 | Z19: 24.880014 | AA19: 24.792429 | AB19: 24.880751 | AC19: 24.838329 | AD19: 24.82336 | AE19: 24.858402 | AF19: 25.202454 | AG19: -0.001
A20: Residual Fuel Oil | B20: Energy Prices: Industrial: Residual Fuel Oil: High Zero-Carbon Technology Cost | C20: AEO.2025.HIGHZTC.PRCE_REAL_IDAL_NA_RFO_NA_NA_Y13DLRPMMBTU.A | D20: 2024 $/MMBtu | F20: 7.83466 | G20: 8.848094 | H20: 9.435161 | I20: 10.629246 | J20: 11.88067 | K20: 13.214781 | L20: 14.622335 | M20: 14.725853 | N20: 14.700524 | O20: 14.992572 | P20: 15.113938 | Q20: 15.285793 | R20: 15.383565 | S20: 15.518867 | T20: 15.634306 | U20: 15.663942 | V20: 15.779115 | W20: 15.889836 | X20: 16.038828 | Y20: 16.101131 | Z20: 16.053886 | AA20: 16.051018 | AB20: 16.34535 | AC20: 16.306047 | AD20: 16.344069 | AE20: 16.451635 | AF20: 16.998318 | AG20: 0.03
A21: Natural Gas | B21: Energy Prices: Industrial: Natural Gas: High Zero-Carbon Technology Cost | C21: AEO.2025.HIGHZTC.PRCE_REAL_IDAL_NA_NG_NA_NA_Y13DLRPMMBTU.A | D21: 2024 $/MMBtu | F21: 3.33707 | G21: 4.010599 | H21: 3.911485 | I21: 3.791521 | J21: 3.869612 | K21: 4.020249 | L21: 4.230658 | M21: 4.390093 | N21: 4.830755 | O21: 5.179088 | P21: 5.412342 | Q21: 5.494054 | R21: 5.481412 | S21: 5.430798 | T21: 5.370685 | U21: 5.290253 | V21: 5.310672 | W21: 5.403639 | X21: 5.486475 | Y21: 5.561241 | Z21: 5.615677 | AA21: 5.665632 | AB21: 5.71713 | AC21: 5.72265 | AD21: 5.7369 | AE21: 5.797705 | AF21: 5.862935 | AG21: 0.022
A22: Metallurgical Coal | B22: Energy Prices: Industrial: Metallurgical Coal: High Zero-Carbon Technology Cost | C22: AEO.2025.HIGHZTC.PRCE_REAL_IDAL_NA_MTC_NA_NA_Y13DLRPMMBTU.A | D22: 2024 $/MMBtu | F22: 7.767755 | G22: 7.639748 | H22: 7.585148 | I22: 7.555212 | J22: 7.520931 | K22: 7.512826 | L22: 7.510444 | M22: 7.515949 | N22: 7.537591 | O22: 7.537167 | P22: 7.49989 | Q22: 7.518089 | R22: 7.517967 | S22: 7.515557 | T22: 7.51727 | U22: 7.498265 | V22: 7.496222 | W22: 7.466915 | X22: 7.461041 | Y22: 7.453232 | Z22: 7.458103 | AA22: 7.471511 | AB22: 7.467525 | AC22: 7.46251 | AD22: 7.461265 | AE22: 7.469367 | AF22: 7.466943 | AG22: -0.002
A23: Other Industrial Coal | B23: Energy Prices: Industrial: Other Industrial Coal: High Zero-Carbon Technology Cost | C23: AEO.2025.HIGHZTC.PRCE_REAL_IDAL_NA_OIC_NA_NA_Y13DLRPMMBTU.A | D23: 2024 $/MMBtu | F23: 3.572155 | G23: 3.624099 | H23: 3.618806 | I23: 3.601768 | J23: 3.571336 | K23: 3.55915 | L23: 3.533537 | M23: 3.497851 | N23: 3.464142 | O23: 3.459587 | P23: 3.441433 | Q23: 3.415449 | R23: 3.421638 | S23: 3.423545 | T23: 3.432421 | U23: 3.428609 | V23: 3.430913 | W23: 3.425192 | X23: 3.418891 | Y23: 3.422088 | Z23: 3.426063 | AA23: 3.434236 | AB23: 3.444175 | AC23: 3.448749 | AD23: 3.448136 | AE23: 3.449347 | AF23: 3.454516 | AG23: -0.001
A24: Hydrogen | B24: Energy Prices: Industrial: Hydrogen: High Zero-Carbon Technology Cost | C24: AEO.2025.HIGHZTC.PRCE_REAL_IDAL_NA_HDG_NA_NA_Y13DLRPMMBTU.A | D24: 2024 $/MMBtu | F24: 9.533875 | G24: 10.619709 | H24: 10.514131 | I24: 10.426125 | J24: 10.55792 | K24: 10.787679 | L24: 11.065716 | M24: 11.319676 | N24: 11.63994 | O24: 12.155972 | P24: 12.524699 | Q24: 12.666781 | R24: 12.616203 | S24: 12.533028 | T24: 12.742199 | U24: 12.81229 | V24: 12.800771 | W24: 12.675635 | X24: 12.587033 | Y24: 12.651853 | Z24: 12.824852 | AA24: 12.7927 | AB24: 12.813029 | AC24: 12.789708 | AD24: 12.823941 | AE24: 12.685263 | AF24: 12.783066 | AG24: 0.011
A25: Electricity | B25: Energy Prices: Industrial: Electricity: High Zero-Carbon Technology Cost | C25: AEO.2025.HIGHZTC.PRCE_REAL_IDAL_NA_ELC_NA_NA_Y13DLRPMMBTU.A | D25: 2024 $/MMBtu | F25: 26.507746 | G25: 25.922054 | H25: 23.537739 | I25: 22.156487 | J25: 22.004316 | K25: 22.322678 | L25: 22.749052 | M25: 23.346399 | N25: 23.998974 | O25: 24.751463 | P25: 24.95269 | Q25: 24.768763 | R25: 24.45256 | S25: 24.243956 | T25: 24.34145 | U25: 24.228069 | V25: 24.145441 | W25: 24.157953 | X25: 24.287434 | Y25: 24.39603 | Z25: 24.534168 | AA25: 24.641457 | AB25: 24.755726 | AC25: 24.854349 | AD25: 25.022724 | AE25: 25.199516 | AF25: 25.411121 | AG25: -0.002
A26: Transportation
A27: Propane | B27: Energy Prices: Transportation: Propane: High Zero-Carbon Technology Cost | C27: AEO.2025.HIGHZTC.PRCE_REAL_TRN_NA_PROP_NA_NA_Y13DLRPMMBTU.A | D27: 2024 $/MMBtu | F27: 17.589245 | G27: 17.749908 | H27: 18.586613 | I27: 18.389212 | J27: 18.496126 | K27: 18.760077 | L27: 19.2631 | M27: 19.634487 | N27: 20.300226 | O27: 21.098251 | P27: 21.613922 | Q27: 21.826738 | R27: 21.975828 | S27: 22.052736 | T27: 22.024448 | U27: 22.014761 | V27: 22.09473 | W27: 22.299959 | X27: 22.448139 | Y27: 22.723597 | Z27: 23.076363 | AA27: 23.174244 | AB27: 23.269659 | AC27: 23.270405 | AD27: 23.326803 | AE27: 23.542395 | AF27: 23.995331 | AG27: 0.012
A28: E85 | B28: Energy Prices: Transportation: E85: High Zero-Carbon Technology Cost | C28: AEO.2025.HIGHZTC.PRCE_REAL_TRN_NA_E85_NA_NA_Y13DLRPMMBTU.A | D28: 2024 $/MMBtu | F28: 28.823729 | G28: 28.93619 | H28: 30.221819 | I28: 29.874352 | J28: 29.356659 | K28: 28.412943 | L28: 28.414833 | M28: 28.528875 | N28: 28.297775 | O28: 28.022879 | P28: 27.970562 | Q28: 27.737436 | R28: 27.879841 | S28: 27.706806 | T28: 27.335274 | U28: 27.221582 | V28: 26.936087 | W28: 26.624407 | X28: 26.243464 | Y28: 26.249161 | Z28: 24.929926 | AA28: 24.592495 | AB28: 24.79623 | AC28: 24.925064 | AD28: 24.988291 | AE28: 25.141323 | AF28: 25.433138 | AG28: -0.005
A29: Motor Gasoline | B29: Energy Prices: Transportation: Motor Gasoline: High Zero-Carbon Technology Cost | C29: AEO.2025.HIGHZTC.PRCE_REAL_TRN_NA_MGS_NA_NA_Y13DLRPMMBTU.A | D29: 2024 $/MMBtu | F29: 28.679842 | G29: 27.094545 | H29: 25.485424 | I29: 24.986969 | J29: 24.719851 | K29: 24.436867 | L29: 24.474363 | M29: 24.48147 | N29: 24.300167 | O29: 24.154732 | P29: 24.09795 | Q29: 23.894083 | R29: 24.019566 | S29: 23.870735 | T29: 23.556276 | U29: 23.430714 | V29: 23.173237 | W29: 22.909204 | X29: 22.57633 | Y29: 22.596951 | Z29: 21.468903 | AA29: 21.182211 | AB29: 21.356647 | AC29: 21.464962 | AD29: 21.509295 | AE29: 21.631233 | AF29: 21.869665 | AG29: -0.01
A30: Jet Fuel | B30: Energy Prices: Transportation: Jet Fuel: High Zero-Carbon Technology Cost | C30: AEO.2025.HIGHZTC.PRCE_REAL_TRN_NA_JFL_NA_NA_Y13DLRPMMBTU.A | D30: 2024 $/MMBtu | F30: 17.638924 | G30: 16.395 | H30: 16.197346 | I30: 16.576864 | J30: 17.167725 | K30: 17.774681 | L30: 18.432444 | M30: 18.550699 | N30: 18.432102 | O30: 18.750156 | P30: 18.878136 | Q30: 19.088032 | R30: 19.162302 | S30: 19.413189 | T30: 19.636925 | U30: 19.743242 | V30: 19.910463 | W30: 20.238554 | X30: 20.505775 | Y30: 20.876812 | Z30: 21.614872 | AA30: 21.580616 | AB30: 21.698483 | AC30: 21.705061 | AD30: 21.706541 | AE30: 21.788584 | AF30: 22.195864 | AG30: 0.009
A31: Diesel Fuel (distillate fuel oil) | B31: Energy Prices: Transportation: Diesel Fuel: High Zero-Carbon Technology Cost | C31: AEO.2025.HIGHZTC.PRCE_REAL_TRN_NA_DFU_NA_NA_Y13DLRPMMBTU.A | D31: 2024 $/MMBtu | F31: 27.283649 | G31: 25.591213 | H31: 25.016569 | I31: 25.029736 | J31: 25.250086 | K31: 25.481937 | L31: 25.837044 | M31: 25.879503 | N31: 25.733622 | O31: 26.102192 | P31: 26.219612 | Q31: 26.457941 | R31: 26.618042 | S31: 26.882929 | T31: 26.978115 | U31: 27.113096 | V31: 27.266804 | W31: 27.578503 | X31: 27.813025 | Y31: 28.145802 | Z31: 28.854143 | AA31: 28.858868 | AB31: 28.825182 | AC31: 28.706501 | AD31: 28.759977 | AE31: 28.70521 | AF31: 29.126087 | AG31: 0.003
A32: Residual Fuel Oil | B32: Energy Prices: Transportation: Residual Fuel Oil: High Zero-Carbon Technology Cost | C32: AEO.2025.HIGHZTC.PRCE_REAL_TRN_NA_RFO_NA_NA_Y13DLRPMMBTU.A | D32: 2024 $/MMBtu | F32: 13.401297 | G32: 11.843807 | H32: 12.665238 | I32: 12.576532 | J32: 12.510175 | K32: 12.503057 | L32: 12.525302 | M32: 12.597067 | N32: 12.550599 | O32: 12.745926 | P32: 12.831242 | Q32: 12.954171 | R32: 13.008114 | S32: 13.096881 | T32: 13.191089 | U32: 13.218472 | V32: 13.301097 | W32: 13.406687 | X32: 13.509968 | Y32: 13.614932 | Z32: 13.650314 | AA32: 13.473039 | AB32: 13.708124 | AC32: 13.688977 | AD32: 13.7072 | AE32: 13.794828 | AF32: 14.231298 | AG32: 0.002
A33: Natural Gas | B33: Energy Prices: Transportation: Natural Gas: High Zero-Carbon Technology Cost | C33: AEO.2025.HIGHZTC.PRCE_REAL_TRN_NA_NG_NA_NA_Y13DLRPMMBTU.A | D33: 2024 $/MMBtu | F33: 14.514303 | G33: 15.045484 | H33: 14.977668 | I33: 14.858115 | J33: 14.908598 | K33: 15.040533 | L33: 15.186421 | M33: 15.299401 | N33: 15.666859 | O33: 15.903211 | P33: 16.017698 | Q33: 16.016142 | R33: 15.907859 | S33: 15.77169 | T33: 15.650945 | U33: 15.47576 | V33: 15.403385 | W33: 15.417639 | X33: 15.41606 | Y33: 15.414666 | Z33: 15.384685 | AA33: 15.361653 | AB33: 15.353804 | AC33: 15.281762 | AD33: 15.215751 | AE33: 15.207031 | AF33: 15.19101 | AG33: 0.002
A34: Hydrogen | B34: Energy Prices: Transportation: Hydrogen: High Zero-Carbon Technology Cost | C34: AEO.2025.HIGHZTC.PRCE_REAL_TRN_NA_HDG_NA_NA_Y13DLRPMMBTU.A | D34: 2024 $/MMBtu | F34: 60.468231 | G34: 60.745255 | H34: 60.549759 | I34: 60.44437 | J34: 60.531708 | K34: 60.737736 | L34: 60.991833 | M34: 61.818279 | N34: 62.04599 | O34: 62.676136 | P34: 63.049198 | Q34: 63.198536 | R34: 63.044495 | S34: 62.949413 | T34: 63.204426 | U34: 63.33548 | V34: 63.306995 | W34: 63.132828 | X34: 62.969875 | Y34: 63.022812 | Z34: 63.25135 | AA34: 63.215389 | AB34: 63.382431 | AC34: 63.355698 | AD34: 63.409069 | AE34: 63.016552 | AF34: 63.101322 | AG34: 0.002
A35: Electricity | B35: Energy Prices: Transportation: Electricity: High Zero-Carbon Technology Cost | C35: AEO.2025.HIGHZTC.PRCE_REAL_TRN_NA_ELC_NA_NA_Y13DLRPMMBTU.A | D35: 2024 $/MMBtu | F35: 42.609589 | G35: 42.26667 | H35: 39.670399 | I35: 36.717178 | J35: 36.535248 | K35: 36.81496 | L35: 37.285934 | M35: 38.057724 | N35: 38.70388 | O35: 39.740459 | P35: 40.09803 | Q35: 40.153744 | R35: 40.057587 | S35: 39.782898 | T35: 40.15593 | U35: 39.589664 | V35: 39.300087 | W35: 39.269657 | X35: 39.614471 | Y35: 39.822304 | Z35: 40.184521 | AA35: 40.37289 | AB35: 40.537704 | AC35: 40.4916 | AD35: 41.027618 | AE35: 41.285618 | AF35: 41.592472 | AG35: -0.001
A36: Electric Power
A37: Distillate Fuel Oil | B37: Energy Prices: Electric Power: Distillate Fuel Oil: High Zero-Carbon Technology Cost | C37: AEO.2025.HIGHZTC.PRCE_REAL_ELEP_NA_DFO_NA_NA_Y13DLRPMMBTU.A | D37: 2024 $/MMBtu | F37: 26.137505 | G37: 24.653458 | H37: 23.463963 | I37: 22.977613 | J37: 22.593882 | K37: 22.342915 | L37: 22.213257 | M37: 22.156206 | N37: 22.726322 | O37: 23.003592 | P37: 23.077461 | Q37: 23.249807 | R37: 23.28072 | S37: 23.52141 | T37: 23.668085 | U37: 23.751266 | V37: 23.886726 | W37: 24.176956 | X37: 24.404095 | Y37: 24.709991 | Z37: 25.257483 | AA37: 25.158951 | AB37: 25.341908 | AC37: 25.316826 | AD37: 25.294249 | AE37: 25.372868 | AF37: 25.729799 | AG37: -0.001
A38: Residual Fuel Oil | B38: Energy Prices: Electric Power: Residual Fuel Oil: High Zero-Carbon Technology Cost | C38: AEO.2025.HIGHZTC.PRCE_REAL_ELEP_NA_RFO_NA_NA_Y13DLRPMMBTU.A | D38: 2024 $/MMBtu | F38: 17.394409 | G38: 13.672506 | H38: 13.615168 | I38: 14.296899 | J38: 15.031581 | K38: 15.753065 | L38: 16.474405 | M38: 16.627272 | N38: 16.536289 | O38: 16.771885 | P38: 16.909727 | Q38: 17.088612 | R38: 17.157686 | S38: 17.269447 | T38: 17.398418 | U38: 17.408293 | V38: 17.490879 | W38: 17.551632 | X38: 17.536398 | Y38: 17.589537 | Z38: 17.510019 | AA38: 16.884666 | AB38: 17.201757 | AC38: 17.213936 | AD38: 17.253027 | AE38: 17.380194 | AF38: 17.916069 | AG38: 0.001
A39: Natural Gas | B39: Energy Prices: Electric Power: Natural Gas: High Zero-Carbon Technology Cost | C39: AEO.2025.HIGHZTC.PRCE_REAL_ELEP_NA_NG_NA_NA_Y13DLRPMMBTU.A | D39: 2024 $/MMBtu | F39: 2.719399 | G39: 3.131506 | H39: 3.068464 | I39: 2.996603 | J39: 3.12604 | K39: 3.327426 | L39: 3.603756 | M39: 3.695694 | N39: 4.197338 | O39: 4.507975 | P39: 4.717876 | Q39: 4.789361 | R39: 4.78448 | S39: 4.749629 | T39: 4.715602 | U39: 4.659969 | V39: 4.690855 | W39: 4.769531 | X39: 4.842232 | Y39: 4.929382 | Z39: 5.014789 | AA39: 5.059572 | AB39: 5.116513 | AC39: 5.124822 | AD39: 5.147723 | AE39: 5.21766 | AF39: 5.297616 | AG39: 0.026
A40: Steam Coal | B40: Energy Prices: Electric Power: Steam Coal: High Zero-Carbon Technology Cost | C40: AEO.2025.HIGHZTC.PRCE_REAL_ELEP_NA_STC_NA_NA_Y13DLRPMMBTU.A | D40: 2024 $/MMBtu | F40: 2.489397 | G40: 2.427415 | H40: 2.375483 | I40: 2.326139 | J40: 2.226495 | K40: 2.226722 | L40: 2.247866 | M40: 2.217924 | N40: 2.149103 | O40: 2.152961 | P40: 2.139093 | Q40: 2.125588 | R40: 2.125613 | S40: 2.15652 | T40: 2.152304 | U40: 2.213794 | V40: 2.210829 | W40: 2.208087 | X40: 2.206623 | Y40: 2.207428 | Z40: 2.207163 | AA40: 2.196095 | AB40: 1.887973 | AC40: 2.178344 | AD40: 2.178153 | AE40: 2.195496 | AF40: 2.192112 | AG40: -0.005
...

Sheet AEO 2025 Table 6
A1: Table 6. Industrial Sector Key Indicators and Consumption
A2: https://www.eia.gov/outlooks/aeo/data/browser/#/?id=6-AEO2025&cases=highZTC&sourcekey=0
A3: Tue Dec 02 2025 13:18:59 GMT-0800 (Pacific Standard Time)
A4: Source: U.S. Energy Information Administration
B5: full name | C5: api key | D5: units | E5: 2023 | F5: 2024 | G5: 2025 | H5: 2026 | I5: 2027 | J5: 2028 | K5: 2029 | L5: 2030 | M5: 2031 | N5: 2032 | O5: 2033 | P5: 2034 | Q5: 2035 | R5: 2036 | S5: 2037 | T5: 2038 | U5: 2039 | V5: 2040 | W5: 2041 | X5: 2042 | Y5: 2043 | Z5: 2044 | AA5: 2045 | AB5: 2046 | AC5: 2047 | AD5: 2048 | AE5: 2049 | AF5: 2050 | AG5: Growth (2024-2050)
A6: Value of Shipments
A7: (billion 2012 dollars)
A8: Manufacturing | B8: Industrial: Value of Shipments: Manufacturing: High Zero-Carbon Technology Cost | C8: AEO.2025.HIGHZTC.ECI_NA_IDAL_MANF_VOS_NA_USA_BLNY09DLR.A | D8: billion 2012 $ | F8: 5974.9639 | G8: 6102.1035 | H8: 6220.3818 | I8: 6297.689 | J8: 6359.1074 | K8: 6419.7266 | L8: 6479.293 | M8: 6523.9873 | N8: 6577.8892 | O8: 6614.6309 | P8: 6684.3379 | Q8: 6740.0898 | R8: 6793.6846 | S8: 6856.6504 | T8: 6918.3003 | U8: 6987.396 | V8: 7063.019 | W8: 7128.4629 | X8: 7196.8643 | Y8: 7256.6079 | Z8: 7322.8701 | AA8: 7384.3311 | AB8: 7454.5503 | AC8: 7535.2563 | AD8: 7606.2373 | AE8: 7681.5273 | AF8: 7743.6045 | AG8: 0.01
A9: Agriculture | B9: Mining | C9: and Construction | D9: Industrial: Value of Shipments: Agriculture, Mining, and Construction: High Zero-Carbon Technology Cost | E9: AEO.2025.HIGHZTC.ECI_NA_IDAL_NMFG_VOS_NA_USA_BLNY09DLR.A | F9: billion 2012 $ | H9: 2718.2505 | I9: 2777.918 | J9: 2803.5085 | K9: 2839.2778 | L9: 2891.1875 | M9: 2948.4795 | N9: 2992.1099 | O9: 3020.3398 | P9: 3053.4861 | Q9: 3066.2 | R9: 3074.7314 | S9: 3093.0898 | T9: 3117.248 | U9: 3128.8452 | V9: 3144.9646 | W9: 3159.1543 | X9: 3177.1714 | Y9: 3191.8076 | Z9: 3212.5195 | AA9: 3226.1709 | AB9: 3241.9814 | AC9: 3269.1504 | AD9: 3302.4121 | AE9: 3332.9824 | AF9: 3363.4294 | AG9: 3398.2007 | AH9: 3430.1721 | AI9: 0.009
A10: Total | B10: Industrial: Value of Shipments: Total: High Zero-Carbon Technology Cost | C10: AEO.2025.HIGHZTC.ECI_NA_IDAL_NA_VOS_NA_USA_BLNY09DLR.A | D10: billion 2012 $ | F10: 8693.2148 | G10: 8880.0215 | H10: 9023.8906 | I10: 9136.9668 | J10: 9250.2949 | K10: 9368.2061 | L10: 9471.4023 | M10: 9544.3271 | N10: 9631.375 | O10: 9680.8311 | P10: 9759.0693 | Q10: 9833.1797 | R10: 9910.9326 | S10: 9985.4961 | T10: 10063.265 | U10: 10146.551 | V10: 10240.19 | W10: 10320.271 | X10: 10409.384 | Y10: 10482.779 | Z10: 10564.852 | AA10: 10653.481 | AB10: 10756.963 | AC10: 10868.238 | AD10: 10969.667 | AE10: 11079.729 | AF10: 11173.776 | AG10: 0.01
A11: Energy Prices
A12: (2024 dollars per MMBtu)
A13: Propane | B13: Industrial: Energy Prices: Propane: High Zero-Carbon Technology Cost | C13: AEO.2025.HIGHZTC.PRCE_NA_IDAL_HAP_PROP_NA_USA_Y13DLRPMMBTU.A | D13: 2024 $/MMBtu | F13: 12.66026 | G13: 12.605674 | H13: 13.465074 | I13: 13.314802 | J13: 13.427592 | K13: 13.72262 | L13: 14.298682 | M13: 14.759735 | N13: 15.554036 | O13: 16.543209 | P13: 17.23724 | Q13: 17.555822 | R13: 17.767212 | S13: 17.880009 | T13: 17.856604 | U13: 17.844084 | V13: 17.93939 | W13: 18.19438 | X13: 18.394274 | Y13: 18.748419 | Z13: 19.21232 | AA13: 19.372681 | AB13: 19.508192 | AC13: 19.52129 | AD13: 19.593958 | AE13: 19.869528 | AF13: 20.462763 | AG13: 0.019
A14: Motor Gasoline | B14: Industrial: Energy Prices: Motor Gasoline: High Zero-Carbon Technology Cost | C14: AEO.2025.HIGHZTC.PRCE_NA_IDAL_NA_MGS_NA_USA_Y13DLRPMMBTU.A | D14: 2024 $/MMBtu | F14: 28.673464 | G14: 27.674664 | H14: 26.287764 | I14: 25.797014 | J14: 25.399086 | K14: 24.899 | L14: 24.675621 | M14: 24.706846 | N14: 24.538458 | O14: 24.413212 | P14: 24.381813 | Q14: 24.200912 | R14: 24.348745 | S14: 24.217527 | T14: 23.927593 | U14: 23.785702 | V14: 23.517384 | W14: 23.278688 | X14: 22.960827 | Y14: 23.000324 | Z14: 21.883543 | AA14: 21.605103 | AB14: 21.787703 | AC14: 21.908485 | AD14: 21.966629 | AE14: 22.09486 | AF14: 22.340118 | AG14: -0.01
A15: Distillate Fuel Oil | B15: Industrial: Energy Prices: Distillate Fuel Oil: High Zero-Carbon Technology Cost | C15: AEO.2025.HIGHZTC.PRCE_NA_IDAL_NA_DFO_NA_USA_Y13DLRPMMBTU.A | D15: 2024 $/MMBtu | F15: 26.091763 | G15: 24.600626 | H15: 23.425852 | I15: 22.88941 | J15: 22.557371 | K15: 22.274755 | L15: 22.032902 | M15: 22.079994 | N15: 21.943752 | O15: 22.273958 | P15: 22.39349 | Q15: 22.623447 | R15: 22.746523 | S15: 23.008989 | T15: 23.10652 | U15: 23.218241 | V15: 23.399351 | W15: 23.679426 | X15: 23.916767 | Y15: 24.223963 | Z15: 24.880014 | AA15: 24.792429 | AB15: 24.880751 | AC15: 24.838329 | AD15: 24.82336 | AE15: 24.858402 | AF15: 25.202454 | AG15: -0.001
A16: Residual Fuel Oil | B16: Industrial: Energy Prices: Residual Fuel Oil: High Zero-Carbon Technology Cost | C16: AEO.2025.HIGHZTC.PRCE_NA_IDAL_NA_RFO_NA_USA_Y13DLRPMMBTU.A | D16: 2024 $/MMBtu | F16: 7.83466 | G16: 8.848094 | H16: 9.435161 | I16: 10.629246 | J16: 11.88067 | K16: 13.214781 | L16: 14.622335 | M16: 14.725853 | N16: 14.700524 | O16: 14.992572 | P16: 15.113938 | Q16: 15.285793 | R16: 15.383565 | S16: 15.518867 | T16: 15.634306 | U16: 15.663942 | V16: 15.779115 | W16: 15.889836 | X16: 16.038828 | Y16: 16.101131 | Z16: 16.053886 | AA16: 16.051018 | AB16: 16.34535 | AC16: 16.306047 | AD16: 16.344069 | AE16: 16.451635 | AF16: 16.998318 | AG16: 0.03
A17: Asphalt and Road Oil | B17: Industrial: Energy Prices: Asphalt and Road Oil: High Zero-Carbon Technology Cost | C17: AEO.2025.HIGHZTC.PRCE_NA_IDAL_NA_ARO_NA_USA_Y13DLRPMMBTU.A | D17: 2024 $/MMBtu | F17: 7.535996 | G17: 8.807061 | H17: 8.571714 | I17: 8.758927 | J17: 8.982862 | K17: 9.272329 | L17: 9.597788 | M17: 9.626869 | N17: 9.576499 | O17: 9.736337 | P17: 9.803224 | Q17: 9.889682 | R17: 9.94466 | S17: 10.012337 | T17: 10.073389 | U17: 10.068779 | V17: 10.152576 | W17: 10.247764 | X17: 10.325734 | Y17: 10.296822 | Z17: 10.155124 | AA17: 10.215075 | AB17: 10.342485 | AC17: 10.290125 | AD17: 10.252983 | AE17: 10.41711 | AF17: 10.703161 | AG17: 0.014
A18: Natural Gas | B18: Industrial: Energy Prices: Natural Gas: High Zero-Carbon Technology Cost | C18: AEO.2025.HIGHZTC.PRCE_NA_IDAL_NA_NG_NA_USA_Y13DLRPMMBTU.A | D18: 2024 $/MMBtu | F18: 3.36092 | G18: 4.039081 | H18: 3.947378 | I18: 3.823099 | J18: 3.901809 | K18: 4.050515 | L18: 4.267354 | M18: 4.432152 | N18: 4.875979 | O18: 5.225038 | P18: 5.456037 | Q18: 5.537374 | R18: 5.522622 | S18: 5.471223 | T18: 5.405282 | U18: 5.327897 | V18: 5.350899 | W18: 5.447668 | X18: 5.53614 | Y18: 5.607039 | Z18: 5.661417 | AA18: 5.721578 | AB18: 5.771735 | AC18: 5.777755 | AD18: 5.79364 | AE18: 5.855846 | AF18: 5.927567 | AG18: 0.022
A19: Hydrogen | B19: Industrial: Energy Prices: Hydrogen: High Zero-Carbon Technology Cost | C19: AEO.2025.HIGHZTC.PRCE_NA_IDAL_NA_HDG_NA_USA_Y13DLRPMMBTU.A | D19: 2024 $/MMBtu | F19: 9.533875 | G19: 10.619709 | H19: 10.514131 | I19: 10.426125 | J19: 10.55792 | K19: 10.787679 | L19: 11.065716 | M19: 11.319676 | N19: 11.63994 | O19: 12.155972 | P19: 12.524699 | Q19: 12.666781 | R19: 12.616203 | S19: 12.533028 | T19: 12.742199 | U19: 12.81229 | V19: 12.800771 | W19: 12.675635 | X19: 12.587033 | Y19: 12.651853 | Z19: 12.824852 | AA19: 12.7927 | AB19: 12.813029 | AC19: 12.789708 | AD19: 12.823941 | AE19: 12.685263 | AF19: 12.783066 | AG19: 0.011
A20: Metallurgical Coal | B20: Industrial: Energy Prices: Metallurgical Coal: High Zero-Carbon Technology Cost | C20: AEO.2025.HIGHZTC.PRCE_NA_IDAL_NA_MTC_NA_USA_Y13DLRPMMBTU.A | D20: 2024 $/MMBtu | F20: 7.767755 | G20: 7.639748 | H20: 7.585148 | I20: 7.555212 | J20: 7.520931 | K20: 7.512826 | L20: 7.510444 | M20: 7.515949 | N20: 7.537591 | O20: 7.537167 | P20: 7.49989 | Q20: 7.518089 | R20: 7.517967 | S20: 7.515557 | T20: 7.51727 | U20: 7.498265 | V20: 7.496222 | W20: 7.466915 | X20: 7.461041 | Y20: 7.453232 | Z20: 7.458103 | AA20: 7.471511 | AB20: 7.467525 | AC20: 7.46251 | AD20: 7.461265 | AE20: 7.469367 | AF20: 7.466943 | AG20: -0.002
A21: Steam Coal | B21: Industrial: Energy Prices: Other Industrial Coal: High Zero-Carbon Technology Cost | C21: AEO.2025.HIGHZTC.PRCE_NA_IDAL_NA_STC_NA_USA_Y13DLRPMMBTU.A | D21: 2024 $/MMBtu | F21: 3.572155 | G21: 3.624099 | H21: 3.618806 | I21: 3.601768 | J21: 3.571336 | K21: 3.55915 | L21: 3.533537 | M21: 3.497851 | N21: 3.464142 | O21: 3.459587 | P21: 3.441433 | Q21: 3.415449 | R21: 3.421638 | S21: 3.423545 | T21: 3.432421 | U21: 3.428609 | V21: 3.430913 | W21: 3.425192 | X21: 3.418891 | Y21: 3.422088 | Z21: 3.426063 | AA21: 3.434236 | AB21: 3.444175 | AC21: 3.448749 | AD21: 3.448136 | AE21: 3.449347 | AF21: 3.454516 | AG21: -0.001
A22: Electricity | B22: Industrial: Energy Prices: Electricity: High Zero-Carbon Technology Cost | C22: AEO.2025.HIGHZTC.PRCE_NA_IDAL_NA_ELC_NA_USA_Y13DLRPMMBTU.A | D22: 2024 $/MMBtu | F22: 26.507746 | G22: 25.922054 | H22: 23.537739 | I22: 22.156487 | J22: 22.004316 | K22: 22.322678 | L22: 22.749052 | M22: 23.346399 | N22: 23.998974 | O22: 24.751463 | P22: 24.95269 | Q22: 24.768763 | R22: 24.45256 | S22: 24.243956 | T22: 24.34145 | U22: 24.228069 | V22: 24.145441 | W22: 24.157953 | X22: 24.287434 | Y22: 24.39603 | Z22: 24.534168 | AA22: 24.641457 | AB22: 24.755726 | AC22: 24.854349 | AD22: 25.022724 | AE22: 25.199516 | AF22: 25.411121 | AG22: -0.002
A23: (nominal dollars per MMBtu)
A24: Propane | B24: Industrial: Energy Prices: Nominal: Propane: High Zero-Carbon Technology Cost | C24: AEO.2025.HIGHZTC.PRCE_NA_IDAL_HAP_PROP_NA_USA_NDLRPMBTU.A | D24: nom $/MMBtu | F24: 12.66026 | G24: 12.863893 | H24: 13.973295 | I24: 14.048564 | J24: 14.43579 | K24: 15.016267 | L24: 15.940687 | M24: 16.79492 | N24: 18.076534 | O24: 19.648006 | P24: 20.92911 | Q24: 21.779829 | R24: 22.498993 | S24: 23.113136 | T24: 23.563791 | U24: 24.032267 | V24: 24.667187 | W24: 25.551607 | X24: 26.38966 | Y24: 27.487337 | Z24: 28.789852 | AA24: 29.676821 | AB24: 30.551477 | AC24: 31.264862 | AD24: 32.095585 | AE24: 33.291042 | AF24: 35.07243 | AG24: 0.04
A25: Motor Gasoline | B25: Industrial: Energy Prices: Nominal: Motor Gasoline: High Zero-Carbon Technology Cost | C25: AEO.2025.HIGHZTC.PRCE_NA_IDAL_NA_MGS_NA_USA_NDLRPMBTU.A | D25: nom $/MMBtu | F25: 28.673464 | G25: 28.241562 | H25: 27.279961 | I25: 27.218655 | J25: 27.306154 | K25: 27.246258 | L25: 27.509274 | M25: 28.113613 | N25: 28.518017 | O25: 28.995035 | P25: 29.603909 | Q25: 30.023756 | R25: 30.833324 | S25: 31.305521 | T25: 31.575144 | U25: 32.034389 | V25: 32.337093 | W25: 32.691845 | X25: 32.941139 | Y25: 33.721119 | Z25: 32.792706 | AA25: 33.096645 | AB25: 34.121384 | AC25: 35.088142 | AD25: 35.982105 | AE25: 37.01955 | AF25: 38.29015 | AG25: 0.011
A26: Distillate Fuel Oil | B26: Industrial: Energy Prices: Nominal: Distillate Fuel Oil: High Zero-Carbon Technology Cost | C26: AEO.2025.HIGHZTC.PRCE_NA_IDAL_NA_DFO_NA_USA_NDLRPMBTU.A | D26: nom $/MMBtu | F26: 26.091763 | G26: 25.104553 | H26: 24.31003 | I26: 24.150816 | J26: 24.251072 | K26: 24.374624 | L26: 24.563076 | M26: 25.124552 | N26: 25.502512 | O26: 26.454292 | P26: 27.189726 | Q26: 28.066748 | R26: 28.804398 | S26: 29.743267 | T26: 30.491646 | U26: 31.270138 | V26: 32.174793 | W26: 33.254627 | X26: 34.312599 | Y26: 35.515114 | Z26: 37.282944 | AA26: 37.979282 | AB26: 38.965359 | AC26: 39.780514 | AD26: 40.66153 | AE26: 41.649815 | AF26: 43.196087 | AG26: 0.02
A27: Residual Fuel Oil | B27: Industrial: Energy Prices: Nominal: Residual Fuel Oil: High Zero-Carbon Technology Cost | C27: AEO.2025.HIGHZTC.PRCE_NA_IDAL_NA_RFO_NA_USA_NDLRPMBTU.A | D27: nom $/MMBtu | F27: 7.83466 | G27: 9.029342 | H27: 9.791279 | I27: 11.21501 | J27: 12.772719 | K27: 14.460553 | L27: 16.301508 | M27: 16.756365 | N27: 17.084602 | O27: 17.806349 | P27: 18.351042 | Q27: 18.963621 | R27: 19.48053 | S27: 20.060932 | T27: 20.631222 | U27: 21.096069 | V27: 21.696745 | W27: 22.315178 | X27: 23.010378 | Y27: 23.606112 | Z27: 24.056906 | AA27: 24.588398 | AB27: 25.5982 | AC27: 26.115402 | AD27: 26.772156 | AE27: 27.564425 | AF27: 29.134497 | AG27: 0.052
A28: Asphalt and Road Oil | B28: Industrial: Energy Prices: Nominal: Asphalt and Road Oil: High Zero-Carbon Technology Cost | C28: AEO.2025.HIGHZTC.PRCE_NA_IDAL_NA_ARO_NA_USA_NDLRPMBTU.A | D28: nom $/MMBtu | F28: 7.535996 | G28: 8.987468 | H28: 8.895243 | I28: 9.241621 | J28: 9.657331 | K28: 10.146442 | L28: 10.699961 | M28: 10.954295 | N28: 11.12958 | O28: 11.563634 | P28: 11.902878 | Q28: 12.269182 | R28: 12.593131 | S28: 12.942751 | T28: 13.292968 | U28: 13.56055 | V28: 13.96009 | W28: 14.391631 | X28: 14.813991 | Y28: 15.096324 | Z28: 15.217553 | AA28: 15.648374 | AB28: 16.197206 | AC28: 16.480434 | AD28: 16.794744 | AE28: 17.453684 | AF28: 18.344828 | AG28: 0.035
A29: Natural Gas | B29: Industrial: Energy Prices: Nominal: Natural Gas Heat: High Zero-Carbon Technology Cost | C29: AEO.2025.HIGHZTC.PRCE_NA_IDAL_NA_NG_NA_USA_NDLRPMBTU.A | D29: nom $/MMBtu | F29: 3.36092 | G29: 4.121819 | H29: 4.096367 | I29: 4.033785 | J29: 4.194773 | K29: 4.432362 | L29: 4.7574 | M29: 5.043291 | N29: 5.666748 | O29: 6.205663 | P29: 6.62461 | Q29: 6.86969 | R29: 6.993411 | S29: 7.072542 | T29: 7.132877 | U29: 7.175567 | V29: 7.357642 | W29: 7.65053 | X29: 7.942518 | Y29: 8.220565 | Z29: 8.483688 | AA29: 8.76483 | AB29: 9.039025 | AC29: 9.253523 | AD29: 9.490184 | AE29: 9.811368 | AF29: 10.159634 | AG29: 0.043
A30: Hydrogen | B30: Industrial: Energy Prices: Nominal: Hydrogen: High Zero-Carbon Technology Cost | C30: AEO.2025.HIGHZTC.PRCE_NA_IDAL_NA_HDG_NA_USA_NDLRPMBTU.A | D30: nom $/MMBtu | F30: 9.533875 | G30: 10.837247 | H30: 10.910973 | I30: 11.000694 | J30: 11.350653 | K30: 11.804646 | L30: 12.33646 | M30: 12.88052 | N30: 13.527663 | O30: 14.437382 | P30: 15.207238 | Q30: 15.714464 | R30: 15.976162 | S30: 16.201199 | T30: 16.814762 | U30: 17.255487 | V30: 17.601435 | W30: 17.801258 | X30: 18.058201 | Y30: 18.54907 | Z30: 19.218168 | AA30: 19.597013 | AB30: 20.066286 | AC30: 20.483709 | AD30: 21.006063 | AE30: 21.253933 | AF30: 21.909708 | AG30: 0.033
A31: Metallurgical Coal | B31: Industrial: Energy Prices: Nominal: Metallurgical Coal: High Zero-Carbon Technology Cost | C31: AEO.2025.HIGHZTC.PRCE_NA_IDAL_NA_MTC_NA_USA_NDLRPMBTU.A | D31: nom $/MMBtu | F31: 7.767755 | G31: 7.796243 | H31: 7.871439 | I31: 7.97157 | J31: 8.085632 | K31: 8.221068 | L31: 8.372914 | M31: 8.552305 | N31: 8.76001 | O31: 8.951728 | P31: 9.106216 | Q31: 9.326975 | R31: 9.520159 | S31: 9.715213 | T31: 9.919882 | U31: 10.098601 | V31: 10.307525 | W31: 10.486297 | X31: 10.70411 | Y31: 10.927295 | Z31: 11.176041 | AA31: 11.445536 | AB31: 11.694777 | AC31: 11.95179 | AD31: 12.221812 | AE31: 12.514791 | AF31: 12.798068 | AG31: 0.019
A32: Steam Coal | B32: Industrial: Energy Prices: Nominal: Other Industrial Coal: High Zero-Carbon Technology Cost | C32: AEO.2025.HIGHZTC.PRCE_NA_IDAL_NA_STC_NA_USA_NDLRPMBTU.A | D32: nom $/MMBtu | F32: 3.572155 | G32: 3.698336 | H32: 3.755393 | I32: 3.800257 | J32: 3.839487 | K32: 3.894675 | L32: 3.939315 | M32: 3.980161 | N32: 4.025944 | O32: 4.108876 | P32: 4.178519 | Q32: 4.237221 | R32: 4.332891 | S32: 4.425549 | T32: 4.529464 | U32: 4.617622 | V32: 4.717606 | W32: 4.81023 | X32: 4.90497 | Y32: 5.017175 | Z32: 5.133989 | AA32: 5.260872 | AB32: 5.393869 | AC32: 5.523439 | AD32: 5.648167 | AE32: 5.779319 | AF32: 5.920915 | AG32: 0.02
A33: Electricity | B33: Industrial: Energy Prices: Nominal: Electricity: High Zero-Carbon Technology Cost | C33: AEO.2025.HIGHZTC.PRCE_NA_IDAL_NA_ELC_NA_USA_NDLRPMBTU.A | D33: nom $/MMBtu | F33: 26.507746 | G33: 26.453053 | H33: 24.42614 | I33: 23.377502 | J33: 23.65649 | K33: 24.427061 | L33: 25.361465 | M33: 26.565578 | N33: 27.891041 | O33: 29.39677 | P33: 30.297054 | Q33: 30.728235 | R33: 30.964788 | S33: 31.339684 | T33: 32.121273 | U33: 32.630165 | V33: 33.200687 | W33: 33.926659 | X33: 34.844383 | Y33: 35.767387 | Z33: 36.76469 | AA33: 37.748009 | AB33: 38.769558 | AC33: 39.806171 | AD33: 40.988098 | AE33: 42.221344 | AF33: 43.553734 | AG33: 0.019
A34: Energy Consumption (quadrillion Btu)
A35: Industrial End-Use Consumption Excluding Refining and Hydrogen Production
