Workbook

Sheet About
A1: BECbIC BAU Employee Compensation by ISIC Code
A3: Source: | B3: Most Industries
B4: OECD
B5: 2018
B6: Input-Output Tables 2018 Edition (ISIC Rev. 4)
B7: https://stats.oecd.org/Index.aspx?DataSetCode=IOTSI4_2018
B8: Variable: VAL
B10: ISIC Code Splits
B11: U.S. Bureau of Labor Statistics
B12: 2021
B13: Current Employment Statistics
B14: https://www.bls.gov/ces/data/employment-and-earnings/2021/table1a_202112.htm
B15: Table B-1a
B17: BEA
B18: 2021
B19: Industry File Download
B20: https://apps.bea.gov/iTable/?isuri=1&reqid=151&step=1
B21: Gross Output by Industry
B22: Underlying Detail: Gross Output by Industry
B23: Components of Value Added
A25: Notes
A26: In the OECD dataset, employee compensation includes not just salary and bonuses
A27: but also employer-paid benefits and employer-paid retirement plan contributions.
A29: We divide up various ISIC codes that need to be disaggregated in the EPS using data
A30: from BLS and BEA publications for the U.S. Data for various other countries that can
A31: help with some of these splits, such as chemicals (ISIC 20) and pharmaceuticals (ISIC 21),
A32: can be found in the OECD's "STAN Database for Structural Analysis," variable EMPN, at:
A33: https://stats.oecd.org/Index.aspx?DataSetCode=STANI4_2020
A35: We convert 2024 USD to 2012 USD with the following conversion factor:
A36: 0.73191601 | B36: 2012 USD per 2024 USD

Sheet OECD VAL
A1: =DotStatQuery(B1) -> #NAME? | B1: Sorry, the query is too large to fit into the Excel cell. You will not be able to update your table with the .Stat Populator.
A2: Dataset: Input-Output Tables 2018 edition
A3: Variable | C3: VAL: Value added
A4: Country | C4: USA: United States
A5: Time | C5: 2015
A6: Unit | C6: US Dollar, Millions
A7: To: (sector in column) | C7: D01T03: Agriculture, forestry and fishing | D7: D05T06: Mining and extraction of energy producing products | E7: D07T08: Mining and quarrying of non-energy producing products | F7: D09: Mining support service activities | G7: D10T12: Food products, beverages and tobacco | H7: D13T15: Textiles, wearing apparel, leather and related products | I7: D16: Wood and products of wood and cork | J7: D17T18: Paper products and printing | K7: D19: Coke and refined petroleum products | L7: D20T21: Chemicals and pharmaceutical products | M7: D22: Rubber and plastic products | N7: D23: Other non-metallic mineral products | O7: D24: Basic metals | P7: D25: Fabricated metal products | Q7: D26: Computer, electronic and optical products | R7: D27: Electrical equipment | S7: D28: Machinery and equipment, nec | T7: D29: Motor vehicles, trailers and semi-trailers | U7: D30: Other transport equipment | V7: D31T33: Other manufacturing; repair and installation of machinery and equipment | W7: D35T39: Electricity, gas, water supply, sewerage, waste and remediation services | X7: D41T43: Construction | Y7: D45T47: Wholesale and retail trade; repair of motor vehicles | Z7: D49T53: Transportation and storage | AA7: D55T56: Accomodation and food services | AB7: D58T60: Publishing, audiovisual and broadcasting activities | AC7: D61: Telecommunications | AD7: D62T63: IT and other information services | AE7: D64T66: Financial and insurance activities | AF7: D68: Real estate activities | AG7: D69T82: Other business sector services | AH7: D84: Public admin. and defence; compulsory social security | AI7: D85: Education | AJ7: D86T88: Human health and social work | AK7: D90T96: Arts, entertainment, recreation and other service activities | AL7: D97T98: Private households with employed persons
A8: From: (sector in row)
A9: LABR: Compensation of employees | C9: 55762.914 | D9: 43448.685 | E9: 13619.199 | F9: 32724.689 | G9: 107945.85 | H9: 19871.939 | I9: 19701.956 | J9: 55695.152 | K9: 18474.415 | L9: 101057.93 | M9: 49588.167 | N9: 28867.79 | O9: 31522.32 | P9: 96161.3 | Q9: 138134.1 | R9: 34122.231 | S9: 90491.687 | T9: 68236.228 | U9: 79237.049 | V9: 73046.581 | W9: 102871.54 | X9: 457892.09 | Y9: 1128201 | Z9: 370328.18 | AA9: 340904.28 | AB9: 204032.85 | AC9: 85985.094 | AD9: 295720.28 | AE9: 750363.11 | AF9: 102329.8 | AG9: 1362903.4 | AH9: 1221115 | AI9: 865699.73 | AJ9: 1075470 | AK9: 319976.05 | AL9: 21351.7
A10: OTXS: Other taxes less subsidies on production | C10: 11926.959 | D10: 22236.446 | E10: 2311.311 | F10: 2083.967 | G10: 8024.6 | H10: 879.298 | I10: 685.696 | J10: 2510.323 | K10: 3395.362 | L10: 13100.214 | M10: 1731.286 | N10: 1464.045 | O10: 2420.814 | P10: 2833.919 | Q10: 7170.704 | R10: 1134.489 | S10: 3331.678 | T10: 2995.89 | U10: 2412.781 | V10: 2228.652 | W10: 40723.43 | X10: 8240.802 | Y10: 54949.026 | Z10: 14802.978 | AA10: 23748.665 | AB10: 8516.97 | AC10: 8862.189 | AD10: 3501.547 | AE10: 41900.949 | AF10: 238841.58 | AG10: 30684.765 | AH10: 11907.354 | AI10: 35650.364 | AJ10: 25367.348 | AK10: 13906.24 | AL10: 0
A11: GOPS: Gross operating surplus and mixed income | C11: 126190.23 | D11: 158772.67 | E11: 25249.19 | F11: 17093.544 | G11: 132476.85 | H11: 6881.463 | I11: 8716.348 | J11: 38432.625 | K11: 136601.02 | L11: 261826.25 | M11: 28535.547 | N11: 21073.465 | O11: 21699.766 | P11: 47785.78 | Q11: 133207.19 | R11: 21061.68 | S11: 53386.635 | T11: 89287.181 | U11: 52498.97 | V11: 37863.368 | W11: 162146.13 | X11: 273780.8 | Y11: 661673.91 | Z11: 192958.04 | AA11: 120207.05 | AB11: 222554.88 | AC11: 186381.42 | AD11: 74944.076 | AE11: 538286.24 | AF11: 1835216.9 | AG11: 643188.55 | AH11: 317682.31 | AI11: 66144.604 | AJ11: 183358.17 | AK11: 133749.91 | AL11: 0
A12: Data extracted on 03 Jun 2020 20:52 UTC (GMT) from OECD.Stat

Sheet U.S. Data for ISIC Splits
A1: Data for Year 2024
A2: Calculated values are italicized. Non-italicized values come directly from source documents. | M2: ISIC 241
A3: Metric | B3: Source URL | C3: Source table | D3: Coal Mining | E3: Oil and gas extraction | F3: All Mining other than Oil and Gas (inc. Coal) | G3: Chemicals | H3: Pharmaceuticals | I3: Chemicals and Pharmaceuticals | J3: Glass | K3: Cement and Other Nometallic Minerals | L3: All Nonmetallic Minerals | M3: Iron and steel | N3: Other metals | O3: All primary metals | P3: Electricity generation and distribution | Q3: Energy pipelines and gas processing | R3: Water and waste | S3: All Utilities | T3: Petroleum Products | U3: Other petroleum and coal products manufacturing | V3: All refined petroleum products
A4: NAICS Code | D4: 2121 | E4: 211 | F4: 212 | G4: 3251-3253, 3255-3259 | H4: 3254 | I4: 325 | J4: 3272 | K4: 327 excl. 3272
A5: ISIC Code | D5: 05 | E5: 06 | F5: 05 + 07T08 | G5: 20 | H5: 21 | I5: 20T21 | J5: 231 | K5: 239 | L5: 23 | M5: 241 | N5: 242 | O5: 24 | P5: 351 | Q5: 352T353 | R5: 36T39 | S5: 35T39 | T5: 19 | U5: 241
A6: Employment (EEs) | B6: https://www.bls.gov/ces/data/employment-and-earnings/2021/table1a_202112.htm | C6: B-1a | D6: 42400 | E6: 142700 | G6: =863800-327800 -> 536000 | H6: 327800 | J6: 79200 | K6: =401000-79200 -> 321800 | M6: =82400+51500+57200 -> 191100 | N6: =60400+57900+49300 -> 167600 | P6: 375900 | Q6: 106300 | R6: 54300 | T6: =82400+51500+57200 -> 191100 | U6: =60400+57900+49300 -> 167600
A7: Gross Output (detail level) | B7: https://apps.bea.gov/iTable/?isuri=1&reqid=151&step=1 | C7: U.Gross Output by Industry - Detail Level | D7: =D35*10^6 -> 46019000000 | E7: =D34*10^6 -> 455994000000 | F7: =SUM(D35,D36:D39)*10^6 -> 139852000000 | G7: =SUM(D269:D275,D280:D287)*10^6 -> 662432000000 | H7: =SUM(D276:D279)*10^6 -> 333392000000 | I7: =SUM(G7:H7) -> 995824000000 | J7: =D71*10^6 -> 33702000000 | K7: =SUM(D70,D72:D81)*10^6 -> 141586000000 | L7: =SUM(J7:K7) -> 175288000000 | M7: =SUMIFS(D:D,E:E,M2)*10^6 -> 213917000000 | N7: =SUM(D84:D89,D91)*10^6 -> 112877000000 | O7: =SUM(M7:N7) -> 326794000000 | P7: =SUM(D42:D51)*10^6 -> 502911000000 | Q7: =D52*10^6 -> 118202000000 | R7: =SUM(D53)*10^6 -> 22159000000 | S7: =SUM(P7:R7) -> 643272000000 | T7: =SUM(D265:D267) -> 625936 | U7: =D268 -> 24695 | V7: =SUM(T7:U7) -> 650631
A8: Gross Output | B8: https://apps.bea.gov/iTable/?isuri=1&reqid=151&step=1 | C8: Gross Output by Industry | I8: 847284000000 | L8: 146318000000 | O8: 262538000000 | S8: 643958000000 | V8: 262538000000
A9: Value Added | B9: https://apps.bea.gov/iTable/?isuri=1&reqid=151&step=1 | C9: =A9 -> Value Added | D9: =$F9*($D$7/$F$7) -> 2.6587315e+10 | E9: =K27*10^6 -> 252608000000 | F9: =K28*10^6 -> 80799000000 | G9: =$I9*(G$7/$I$7) -> 3.6854026e+11 | H9: =$I9*(H$7/$I$7) -> 1.8548074e+11 | I9: =K52*10^6 -> 554021000000 | J9: =$L9*(J$7/$L$7) -> 1.4903725e+10 | K9: =$L9*(K$7/$L$7) -> 6.2612275e+10 | L9: =K35*10^6 -> 77516000000 | M9: =$O9*(M$7/$O$7) -> 5.0086823e+10 | N9: =$O9*(N$7/$O$7) -> 2.6429177e+10 | O9: =K36*10^6 -> 76516000000 | P9: =$S9*(P$7/$S$7) -> 3.5521697e+11 | Q9: =$S9*(Q$7/$S$7) -> 8.3488643e+10 | R9: =$S9*(R$7/$S$7) -> 1.5651383e+10 | S9: =K30*10^6 -> 454357000000 | T9: =$V9*(T$7/$V$7) -> 1.8828366e+11 | U9: =$V9*(U$7/$V$7) -> 7.4283393e+09 | V9: {=TRANSPOSE(K51:N51)*10^6} -> 195712000000
A10: Compensation of employees | C10: =A10 -> Compensation of employees | D10: =$F10*($D$7/$F$7) -> 7.7847832e+09 | E10: =L27*10^6 -> 31824000000 | F10: =L28*10^6 -> 23658000000 | G10: =$I10*(G$7/$I$7) -> 9.1116463e+10 | H10: =$I10*(H$7/$I$7) -> 4.5857537e+10 | I10: =L52*10^6 -> 136974000000 | J10: =$L10*(J$7/$L$7) -> 7.4872398e+09 | K10: =$L10*(K$7/$L$8) -> 3.7682596e+10 | L10: =L35*10^6 -> 38942000000 | M10: =$O10*(M$7/$O$7) -> 2.7019627e+10 | N10: =$O10*(N$7/$O$7) -> 1.4257373e+10 | O10: =L36*10^6 -> 41277000000 | P10: =$S10*(P$7/$S$7) -> 8.0862509e+10 | Q10: =$S10*(Q$7/$S$7) -> 1.900557e+10 | R10: =$S10*(R$7/$S$7) -> 3.5629213e+09 | S10: =L30*10^6 -> 103431000000 | T10: =$V10*(T$7/$V$7) -> 2.1826866e+10 | U10: =$V10*(U$7/$V$7) -> 8.6113352e+08 | V10: 22688000000
A11: Taxes on production and imports, less subsidies | C11: =A11 -> Taxes on production and imports, less subsidies | D11: =$F11*($D$7/$F$7) -> 2.6248717e+09 | E11: =M27*10^6 -> 49110000000 | F11: =M28*10^6 -> 7977000000 | G11: =$I11*(G$7/$I$7) -> 1.6418046e+10 | H11: =$I11*(H$7/$I$7) -> 8.262954e+09 | I11: =M52*10^6 -> 24681000000 | J11: =$L11*(J$7/$L$7) -> 4.2471657e+08 | K11: =$L11*(K$7/$L$8) -> 2.1375598e+09 | L11: =M35*10^6 -> 2209000000 | M11: =$O11*(M$7/$O$7) -> 2.3257682e+09 | N11: =$O11*(N$7/$O$7) -> 1.2272318e+09 | O11: =M36*10^6 -> 3553000000 | P11: =$S11*(P$7/$S$7) -> 6.6626686e+10 | Q11: =$S11*(Q$7/$S$7) -> 1.5659645e+10 | R11: =$S11*(R$7/$S$7) -> 2.93567e+09 | S11: =M30*10^6 -> 85222000000 | T11: =$V11*(T$7/$V$7) -> 6.0358674e+09 | U11: =$V11*(U$7/$V$7) -> 2.3813257e+08 | V11: 6274000000
A12: Gross operating surplus | C12: =A12 -> Gross operating surplus | D12: =$F12*($D$7/$F$7) -> 1.6177989e+10 | E12: =N27*10^6 -> 171675000000 | F12: =N28*10^6 -> 49165000000 | G12: =$I12*(G$7/$I$7) -> 2.6100575e+11 | H12: =$I12*(H$7/$I$7) -> 1.3136025e+11 | I12: =N52*10^6 -> 392366000000 | J12: =$L12*(J$7/$L$7) -> 6.9917691e+09 | K12: =$L12*(K$7/$L$8) -> 3.5188937e+10 | L12: =N35*10^6 -> 36365000000 | M12: =$O12*(M$7/$O$7) -> 2.0741428e+10 | N12: =$O12*(N$7/$O$7) -> 1.0944572e+10 | O12: =N36*10^6 -> 31686000000 | P12: =$S12*(P$7/$S$7) -> 2.0772856e+11 | Q12: =$S12*(Q$7/$S$7) -> 4.8823612e+10 | R12: =$S12*(R$7/$S$7) -> 9.1528266e+09 | S12: =N30*10^6 -> 265705000000 | T12: =$V12*(T$7/$V$7) -> 1.6042093e+11 | U12: =$V12*(U$7/$V$7) -> 6.3290732e+09 | V12: 166750000000
T13: *NEMS IDM includes NAICS 324199 under iron & steel
B16: U.Real Gross Output by Industry - Detail Level
B17: Last Revised on: September 25, 2025
B18: Suggested citation: U.S. Bureau of Economic Analysis, "U.Gross Output by Industry - Detail Level" (accessed Wednesday, January 7, 2026).
H19: 2024 Data: | I19: [Millions of dollars]
B20: Line | D20: 2024 | E20: ISIC Code | F20: EPS Industry Category | H20: Line | J20: ISIC Code | K20: Value Added | L20: Compensation of EEs | M20: Taxes on production and imports, less subsidies | N20: Gross operating surplus
B21: 1 | C21: Oilseed farming | D21: 50014 | E21: ISIC 01T03 | H21: 1 | I21: Gross domestic product | K21: =INDEX('BEA Data'!C:C,MATCH(TRIM('U.S. Data for ISIC Splits'!I21),'BEA Data'!E:E,0)) -> 29298013 | L21: {=INDEX('BEA Data'!C:C,MATCH(TRIM('U.S. Data for ISIC Splits'!I21),'BEA Data'!E:E,0)+1)} -> 15049121 | M21: {=INDEX('BEA Data'!C:C,MATCH(TRIM('U.S. Data for ISIC Splits'!I21),'BEA Data'!E:E,0)+2)} -> 1860444 | N21: {=INDEX('BEA Data'!C:C,MATCH(TRIM('U.S. Data for ISIC Splits'!I21),'BEA Data'!E:E,0)+3)} -> 12388448
B22: 2 | C22: Grain farming | D22: 82647 | E22: ISIC 01T03 | H22: 2 | I22: Private industries | K22: =INDEX('BEA Data'!C:C,MATCH(TRIM('U.S. Data for ISIC Splits'!I22),'BEA Data'!E:E,0)) -> 26001672 | L22: {=INDEX('BEA Data'!C:C,MATCH(TRIM('U.S. Data for ISIC Splits'!I22),'BEA Data'!E:E,0)+1)} -> 12463662 | M22: {=INDEX('BEA Data'!C:C,MATCH(TRIM('U.S. Data for ISIC Splits'!I22),'BEA Data'!E:E,0)+2)} -> 1905894 | N22: {=INDEX('BEA Data'!C:C,MATCH(TRIM('U.S. Data for ISIC Splits'!I22),'BEA Data'!E:E,0)+3)} -> 11632115
B23: 3 | C23: Vegetable and melon farming | D23: 26862 | E23: ISIC 01T03 | H23: 3 | I23: Agriculture, forestry, fishing, and hunting | J23: ISIC 01T03 | K23: =INDEX('BEA Data'!C:C,MATCH(TRIM('U.S. Data for ISIC Splits'!I23),'BEA Data'!E:E,0)) -> 269686 | L23: {=INDEX('BEA Data'!C:C,MATCH(TRIM('U.S. Data for ISIC Splits'!I23),'BEA Data'!E:E,0)+1)} -> 80082 | M23: {=INDEX('BEA Data'!C:C,MATCH(TRIM('U.S. Data for ISIC Splits'!I23),'BEA Data'!E:E,0)+2)} -> 8148 | N23: {=INDEX('BEA Data'!C:C,MATCH(TRIM('U.S. Data for ISIC Splits'!I23),'BEA Data'!E:E,0)+3)} -> 181456
B24: 4 | C24: Fruit and tree nut farming | D24: 30307 | E24: ISIC 01T03 | H24: 4 | I24: Farms | K24: =INDEX('BEA Data'!C:C,MATCH(TRIM('U.S. Data for ISIC Splits'!I24),'BEA Data'!E:E,0)) -> 215830 | L24: {=INDEX('BEA Data'!C:C,MATCH(TRIM('U.S. Data for ISIC Splits'!I24),'BEA Data'!E:E,0)+1)} -> 44527 | M24: {=INDEX('BEA Data'!C:C,MATCH(TRIM('U.S. Data for ISIC Splits'!I24),'BEA Data'!E:E,0)+2)} -> 5548 | N24: {=INDEX('BEA Data'!C:C,MATCH(TRIM('U.S. Data for ISIC Splits'!I24),'BEA Data'!E:E,0)+3)} -> 165755
B25: 5 | C25: Greenhouse, nursery, and floriculture production | D25: 31895 | E25: ISIC 01T03 | H25: 5 | I25: Forestry, fishing, and related activities | K25: =INDEX('BEA Data'!C:C,MATCH(TRIM('U.S. Data for ISIC Splits'!I25),'BEA Data'!E:E,0)) -> 53856 | L25: {=INDEX('BEA Data'!C:C,MATCH(TRIM('U.S. Data for ISIC Splits'!I25),'BEA Data'!E:E,0)+1)} -> 35555 | M25: {=INDEX('BEA Data'!C:C,MATCH(TRIM('U.S. Data for ISIC Splits'!I25),'BEA Data'!E:E,0)+2)} -> 2600 | N25: {=INDEX('BEA Data'!C:C,MATCH(TRIM('U.S. Data for ISIC Splits'!I25),'BEA Data'!E:E,0)+3)} -> 15701
B26: 6 | C26: Other crop farming | D26: 29353 | E26: ISIC 01T03 | H26: 6 | I26: Mining | K26: =INDEX('BEA Data'!C:C,MATCH(TRIM('U.S. Data for ISIC Splits'!I26),'BEA Data'!E:E,0)) -> 404248 | L26: {=INDEX('BEA Data'!C:C,MATCH(TRIM('U.S. Data for ISIC Splits'!I26),'BEA Data'!E:E,0)+1)} -> 92465 | M26: {=INDEX('BEA Data'!C:C,MATCH(TRIM('U.S. Data for ISIC Splits'!I26),'BEA Data'!E:E,0)+2)} -> 60004 | N26: {=INDEX('BEA Data'!C:C,MATCH(TRIM('U.S. Data for ISIC Splits'!I26),'BEA Data'!E:E,0)+3)} -> 251778
B27: 7 | C27: Dairy cattle and milk production | D27: 52126 | E27: ISIC 01T03 | H27: 7 | I27: Oil and gas extraction | J27: ISIC 06 | K27: =INDEX('BEA Data'!C:C,MATCH(TRIM('U.S. Data for ISIC Splits'!I27),'BEA Data'!E:E,0)) -> 252608 | L27: {=INDEX('BEA Data'!C:C,MATCH(TRIM('U.S. Data for ISIC Splits'!I27),'BEA Data'!E:E,0)+1)} -> 31824 | M27: {=INDEX('BEA Data'!C:C,MATCH(TRIM('U.S. Data for ISIC Splits'!I27),'BEA Data'!E:E,0)+2)} -> 49110 | N27: {=INDEX('BEA Data'!C:C,MATCH(TRIM('U.S. Data for ISIC Splits'!I27),'BEA Data'!E:E,0)+3)} -> 171675
B28: 8 | C28: Beef cattle ranching and farming, including feedlots and dual-purpose ranching and farming | D28: 141304 | E28: ISIC 01T03 | H28: 8 | I28: Mining, except oil and gas | J28: ISIC 05, ISIC 07T08 | K28: =INDEX('BEA Data'!C:C,MATCH(TRIM('U.S. Data for ISIC Splits'!I28),'BEA Data'!E:E,0)) -> 80799 | L28: {=INDEX('BEA Data'!C:C,MATCH(TRIM('U.S. Data for ISIC Splits'!I28),'BEA Data'!E:E,0)+1)} -> 23658 | M28: {=INDEX('BEA Data'!C:C,MATCH(TRIM('U.S. Data for ISIC Splits'!I28),'BEA Data'!E:E,0)+2)} -> 7977 | N28: {=INDEX('BEA Data'!C:C,MATCH(TRIM('U.S. Data for ISIC Splits'!I28),'BEA Data'!E:E,0)+3)} -> 49165
B29: 9 | C29: Poultry and egg production | D29: 75391 | E29: ISIC 01T03 | H29: 9 | I29: Support activities for mining | J29: ISIC 09 | K29: =INDEX('BEA Data'!C:C,MATCH(TRIM('U.S. Data for ISIC Splits'!I29),'BEA Data'!E:E,0)) -> 70840 | L29: {=INDEX('BEA Data'!C:C,MATCH(TRIM('U.S. Data for ISIC Splits'!I29),'BEA Data'!E:E,0)+1)} -> 36984 | M29: {=INDEX('BEA Data'!C:C,MATCH(TRIM('U.S. Data for ISIC Splits'!I29),'BEA Data'!E:E,0)+2)} -> 2917 | N29: {=INDEX('BEA Data'!C:C,MATCH(TRIM('U.S. Data for ISIC Splits'!I29),'BEA Data'!E:E,0)+3)} -> 30939
B30: 10 | C30: Animal production, except cattle and poultry and eggs | D30: 45807 | E30: ISIC 01T03 | H30: 10 | I30: Utilities | J30: ISIC 351; ISIC 352T353; ISIC 36T39 | K30: =INDEX('BEA Data'!C:C,MATCH(TRIM('U.S. Data for ISIC Splits'!I30),'BEA Data'!E:E,0)) -> 454357 | L30: {=INDEX('BEA Data'!C:C,MATCH(TRIM('U.S. Data for ISIC Splits'!I30),'BEA Data'!E:E,0)+1)} -> 103431 | M30: {=INDEX('BEA Data'!C:C,MATCH(TRIM('U.S. Data for ISIC Splits'!I30),'BEA Data'!E:E,0)+2)} -> 85222 | N30: {=INDEX('BEA Data'!C:C,MATCH(TRIM('U.S. Data for ISIC Splits'!I30),'BEA Data'!E:E,0)+3)} -> 265705
B31: 11 | C31: Forestry and logging | D31: 26473 | E31: ISIC 01T03 | H31: 11 | I31: Construction | J31: ISIC 41T43 | K31: =INDEX('BEA Data'!C:C,MATCH(TRIM('U.S. Data for ISIC Splits'!I31),'BEA Data'!E:E,0)) -> 1305402 | L31: {=INDEX('BEA Data'!C:C,MATCH(TRIM('U.S. Data for ISIC Splits'!I31),'BEA Data'!E:E,0)+1)} -> 799308 | M31: {=INDEX('BEA Data'!C:C,MATCH(TRIM('U.S. Data for ISIC Splits'!I31),'BEA Data'!E:E,0)+2)} -> 14907 | N31: {=INDEX('BEA Data'!C:C,MATCH(TRIM('U.S. Data for ISIC Splits'!I31),'BEA Data'!E:E,0)+3)} -> 491187
B32: 12 | C32: Fishing, hunting and trapping | D32: 9657 | E32: ISIC 01T03 | H32: 12 | I32: Manufacturing | K32: =INDEX('BEA Data'!C:C,MATCH(TRIM('U.S. Data for ISIC Splits'!I32),'BEA Data'!E:E,0)) -> 2880724 | L32: {=INDEX('BEA Data'!C:C,MATCH(TRIM('U.S. Data for ISIC Splits'!I32),'BEA Data'!E:E,0)+1)} -> 1359135 | M32: {=INDEX('BEA Data'!C:C,MATCH(TRIM('U.S. Data for ISIC Splits'!I32),'BEA Data'!E:E,0)+2)} -> 106009 | N32: {=INDEX('BEA Data'!C:C,MATCH(TRIM('U.S. Data for ISIC Splits'!I32),'BEA Data'!E:E,0)+3)} -> 1415581
B33: 13 | C33: Support activities for agriculture and forestry | D33: 32009 | E33: ISIC 01T03 | H33: 13 | I33: Durable goods | K33: =INDEX('BEA Data'!C:C,MATCH(TRIM('U.S. Data for ISIC Splits'!I33),'BEA Data'!E:E,0)) -> 1524841 | L33: {=INDEX('BEA Data'!C:C,MATCH(TRIM('U.S. Data for ISIC Splits'!I33),'BEA Data'!E:E,0)+1)} -> 893038 | M33: {=INDEX('BEA Data'!C:C,MATCH(TRIM('U.S. Data for ISIC Splits'!I33),'BEA Data'!E:E,0)+2)} -> 43401 | N33: {=INDEX('BEA Data'!C:C,MATCH(TRIM('U.S. Data for ISIC Splits'!I33),'BEA Data'!E:E,0)+3)} -> 588402
B34: 14 | C34: Oil and gas extraction | D34: 455994 | E34: ISIC 06 | F34: oil and gas extraction | H34: 14 | I34: Wood products | J34: ISIC 16 | K34: =INDEX('BEA Data'!C:C,MATCH(TRIM('U.S. Data for ISIC Splits'!I34),'BEA Data'!E:E,0)) -> 60171 | L34: {=INDEX('BEA Data'!C:C,MATCH(TRIM('U.S. Data for ISIC Splits'!I34),'BEA Data'!E:E,0)+1)} -> 32297 | M34: {=INDEX('BEA Data'!C:C,MATCH(TRIM('U.S. Data for ISIC Splits'!I34),'BEA Data'!E:E,0)+2)} -> 1132 | N34: {=INDEX('BEA Data'!C:C,MATCH(TRIM('U.S. Data for ISIC Splits'!I34),'BEA Data'!E:E,0)+3)} -> 26742
B35: 15 | C35: Coal mining | D35: 46019 | E35: ISIC 05 | F35: coal mining | H35: 15 | I35: Nonmetallic mineral products | J35: ISIC 239; ISIC 231 | K35: =INDEX('BEA Data'!C:C,MATCH(TRIM('U.S. Data for ISIC Splits'!I35),'BEA Data'!E:E,0)) -> 77516 | L35: {=INDEX('BEA Data'!C:C,MATCH(TRIM('U.S. Data for ISIC Splits'!I35),'BEA Data'!E:E,0)+1)} -> 38942 | M35: {=INDEX('BEA Data'!C:C,MATCH(TRIM('U.S. Data for ISIC Splits'!I35),'BEA Data'!E:E,0)+2)} -> 2209 | N35: {=INDEX('BEA Data'!C:C,MATCH(TRIM('U.S. Data for ISIC Splits'!I35),'BEA Data'!E:E,0)+3)} -> 36365
B36: 16 | C36: Copper, nickel, lead, and zinc mining | D36: 17136 | E36: ISIC 07T08 | H36: 16 | I36: Primary metals | J36: ISIC 241; ISIC 242 | K36: =INDEX('BEA Data'!C:C,MATCH(TRIM('U.S. Data for ISIC Splits'!I36),'BEA Data'!E:E,0)) -> 76516 | L36: {=INDEX('BEA Data'!C:C,MATCH(TRIM('U.S. Data for ISIC Splits'!I36),'BEA Data'!E:E,0)+1)} -> 41277 | M36: {=INDEX('BEA Data'!C:C,MATCH(TRIM('U.S. Data for ISIC Splits'!I36),'BEA Data'!E:E,0)+2)} -> 3553 | N36: {=INDEX('BEA Data'!C:C,MATCH(TRIM('U.S. Data for ISIC Splits'!I36),'BEA Data'!E:E,0)+3)} -> 31686
B37: 17 | C37: Iron, gold, silver, and other metal ore mining | D37: 23469 | E37: ISIC 07T08 | H37: 17 | I37: Fabricated metal products | J37: ISIC 25 | K37: =INDEX('BEA Data'!C:C,MATCH(TRIM('U.S. Data for ISIC Splits'!I37),'BEA Data'!E:E,0)) -> 190535 | L37: {=INDEX('BEA Data'!C:C,MATCH(TRIM('U.S. Data for ISIC Splits'!I37),'BEA Data'!E:E,0)+1)} -> 128099 | M37: {=INDEX('BEA Data'!C:C,MATCH(TRIM('U.S. Data for ISIC Splits'!I37),'BEA Data'!E:E,0)+2)} -> 5721 | N37: {=INDEX('BEA Data'!C:C,MATCH(TRIM('U.S. Data for ISIC Splits'!I37),'BEA Data'!E:E,0)+3)} -> 56715
B38: 18 | C38: Stone mining and quarrying | D38: 27727 | E38: ISIC 07T08 | H38: 18 | I38: Machinery | J38: ISIC 28 | K38: =INDEX('BEA Data'!C:C,MATCH(TRIM('U.S. Data for ISIC Splits'!I38),'BEA Data'!E:E,0)) -> 208621 | L38: {=INDEX('BEA Data'!C:C,MATCH(TRIM('U.S. Data for ISIC Splits'!I38),'BEA Data'!E:E,0)+1)} -> 120012 | M38: {=INDEX('BEA Data'!C:C,MATCH(TRIM('U.S. Data for ISIC Splits'!I38),'BEA Data'!E:E,0)+2)} -> 5159 | N38: {=INDEX('BEA Data'!C:C,MATCH(TRIM('U.S. Data for ISIC Splits'!I38),'BEA Data'!E:E,0)+3)} -> 83450
B39: 19 | C39: Other nonmetallic mineral mining and quarrying | D39: 25501 | E39: ISIC 07T08 | H39: 19 | I39: Computer and electronic products | J39: ISIC 26 | K39: =INDEX('BEA Data'!C:C,MATCH(TRIM('U.S. Data for ISIC Splits'!I39),'BEA Data'!E:E,0)) -> 299783 | L39: {=INDEX('BEA Data'!C:C,MATCH(TRIM('U.S. Data for ISIC Splits'!I39),'BEA Data'!E:E,0)+1)} -> 187376 | M39: {=INDEX('BEA Data'!C:C,MATCH(TRIM('U.S. Data for ISIC Splits'!I39),'BEA Data'!E:E,0)+2)} -> 11837 | N39: {=INDEX('BEA Data'!C:C,MATCH(TRIM('U.S. Data for ISIC Splits'!I39),'BEA Data'!E:E,0)+3)} -> 100569
B40: 20 | C40: Drilling oil and gas wells | D40: 18933 | E40: ISIC 09 | H40: 20 | I40: Electrical equipment, appliances, and components | J40: ISIC 27 | K40: =INDEX('BEA Data'!C:C,MATCH(TRIM('U.S. Data for ISIC Splits'!I40),'BEA Data'!E:E,0)) -> 80171 | L40: {=INDEX('BEA Data'!C:C,MATCH(TRIM('U.S. Data for ISIC Splits'!I40),'BEA Data'!E:E,0)+1)} -> 47290 | M40: {=INDEX('BEA Data'!C:C,MATCH(TRIM('U.S. Data for ISIC Splits'!I40),'BEA Data'!E:E,0)+2)} -> 1139 | N40: {=INDEX('BEA Data'!C:C,MATCH(TRIM('U.S. Data for ISIC Splits'!I40),'BEA Data'!E:E,0)+3)} -> 31742
B41: 21 | C41: Other support activities for mining | D41: 91628 | E41: ISIC 09 | H41: 21 | I41: Motor vehicles, bodies and trailers, and parts | J41: ISIC 29 | K41: =INDEX('BEA Data'!C:C,MATCH(TRIM('U.S. Data for ISIC Splits'!I41),'BEA Data'!E:E,0)) -> 185854 | L41: {=INDEX('BEA Data'!C:C,MATCH(TRIM('U.S. Data for ISIC Splits'!I41),'BEA Data'!E:E,0)+1)} -> 96593 | M41: {=INDEX('BEA Data'!C:C,MATCH(TRIM('U.S. Data for ISIC Splits'!I41),'BEA Data'!E:E,0)+2)} -> 5277 | N41: {=INDEX('BEA Data'!C:C,MATCH(TRIM('U.S. Data for ISIC Splits'!I41),'BEA Data'!E:E,0)+3)} -> 83984
B42: 22 | C42: Hydroelectric power generation | D42: 4372 | E42: ISIC 351 | F42: electricity generation and distribution | H42: 22 | I42: Other transportation equipment | J42: ISIC 30 | K42: =INDEX('BEA Data'!C:C,MATCH(TRIM('U.S. Data for ISIC Splits'!I42),'BEA Data'!E:E,0)) -> 197330 | L42: {=INDEX('BEA Data'!C:C,MATCH(TRIM('U.S. Data for ISIC Splits'!I42),'BEA Data'!E:E,0)+1)} -> 106326 | M42: {=INDEX('BEA Data'!C:C,MATCH(TRIM('U.S. Data for ISIC Splits'!I42),'BEA Data'!E:E,0)+2)} -> 4107 | N42: {=INDEX('BEA Data'!C:C,MATCH(TRIM('U.S. Data for ISIC Splits'!I42),'BEA Data'!E:E,0)+3)} -> 86897
...

Sheet BEA Data
A1: Components of Value Added by Industry
A2: [Millions of dollars]
A3: Bureau of Economic Analysis
A4: Last Revised on: September 25, 2025
A6: Line | C6: 2024
A8: 1 | B8: Gross domestic product | C8: 29298013 | E8: =TRIM(B8) -> Gross domestic product
A9: 2 | B9: Compensation of employees | C9: 15049121 | E9: =TRIM(B9) -> Compensation of employees
A10: 3 | B10: Taxes on production and imports less subsidies | C10: 1860444 | E10: =TRIM(B10) -> Taxes on production and imports less subsidies
A11: 4 | B11: Gross operating surplus | C11: 12388448 | E11: =TRIM(B11) -> Gross operating surplus
A12: 5 | B12: Private industries | C12: 26001672 | E12: =TRIM(B12) -> Private industries
A13: 6 | B13: Compensation of employees | C13: 12463662 | E13: =TRIM(B13) -> Compensation of employees
A14: 7 | B14: Taxes on production and imports less subsidies | C14: 1905894 | E14: =TRIM(B14) -> Taxes on production and imports less subsidies
A15: 8 | B15: Gross operating surplus | C15: 11632115 | E15: =TRIM(B15) -> Gross operating surplus
A16: 9 | B16: Agriculture, forestry, fishing, and hunting | C16: 269686 | E16: =TRIM(B16) -> Agriculture, forestry, fishing, and hunting
A17: 10 | B17: Compensation of employees | C17: 80082 | E17: =TRIM(B17) -> Compensation of employees
A18: 11 | B18: Taxes on production and imports less subsidies | C18: 8148 | E18: =TRIM(B18) -> Taxes on production and imports less subsidies
A19: 12 | B19: Gross operating surplus | C19: 181456 | E19: =TRIM(B19) -> Gross operating surplus
... A369: 362 | B369: Compensation of employees | C369: 607449 | E369: =TRIM(B369) -> Compensation of employees
A370: 363 | B370: Taxes on production and imports less subsidies | C370: --- | E370: =TRIM(B370) -> Taxes on production and imports less subsidies
A371: 364 | B371: Gross operating surplus | C371: 379329 | E371: =TRIM(B371) -> Gross operating surplus
A372: 365 | B372: National defense | C372: 549405 | E372: =TRIM(B372) -> National defense
A373: 366 | B373: Compensation of employees | C373: 339732 | E373: =TRIM(B373) -> Compensation of employees
A374: 367 | B374: Taxes on production and imports less subsidies | C374: --- | E374: =TRIM(B374) -> Taxes on production and imports less subsidies
A375: 368 | B375: Gross operating surplus | C375: 209673 | E375: =TRIM(B375) -> Gross operating surplus
A376: 369 | B376: Nondefense | C376: 437373 | E376: =TRIM(B376) -> Nondefense
A377: 370 | B377: Compensation of employees | C377: 267716 | E377: =TRIM(B377) -> Compensation of employees
A378: 371 | B378: Taxes on production and imports less subsidies | C378: --- | E378: =TRIM(B378) -> Taxes on production and imports less subsidies
A379: 372 | B379: Gross operating surplus | C379: 169656 | E379: =TRIM(B379) -> Gross operating surplus
A380: 373 | B380: Government enterprises | C380: 78079 | E380: =TRIM(B380) -> Government enterprises
A381: 374 | B381: Compensation of employees | C381: 72723 | E381: =TRIM(B381) -> Compensation of employees
A382: 375 | B382: Taxes on production and imports less subsidies | C382: -6847 | E382: =TRIM(B382) -> Taxes on production and imports less subsidies
A383: 376 | B383: Gross operating surplus | C383: 12204 | E383: =TRIM(B383) -> Gross operating surplus
A384: 377 | B384: State and local | C384: 2231485 | E384: =TRIM(B384) -> State and local
A385: 378 | B385: Compensation of employees | C385: 1905288 | E385: =TRIM(B385) -> Compensation of employees
A386: 379 | B386: Taxes on production and imports less subsidies | C386: -38603 | E386: =TRIM(B386) -> Taxes on production and imports less subsidies
A387: 380 | B387: Gross operating surplus | C387: 364800 | E387: =TRIM(B387) -> Gross operating surplus
A388: 381 | B388: General government | C388: 2073333 | E388: =TRIM(B388) -> General government
A389: 382 | B389: Compensation of employees | C389: 1760774 | E389: =TRIM(B389) -> Compensation of employees
A390: 383 | B390: Taxes on production and imports less subsidies | C390: --- | E390: =TRIM(B390) -> Taxes on production and imports less subsidies
A391: 384 | B391: Gross operating surplus | C391: 312559 | E391: =TRIM(B391) -> Gross operating surplus
...

Sheet BECbIC
A1: Unit: $ | B1: ISIC 01T03 | C1: ISIC 05 | D1: ISIC 06 | E1: ISIC 07T08 | F1: ISIC 09 | G1: ISIC 10T12 | H1: ISIC 13T15 | I1: ISIC 16 | J1: ISIC 17T18 | K1: ISIC 19 | L1: ISIC 20 | M1: ISIC 21 | N1: ISIC 22 | O1: ISIC 231 | P1: ISIC 239 | Q1: ISIC 241 | R1: ISIC 242 | S1: ISIC 25 | T1: ISIC 26 | U1: ISIC 27 | V1: ISIC 28 | W1: ISIC 29 | X1: ISIC 30 | Y1: ISIC 31T33 | Z1: ISIC 351 | AA1: ISIC 352T353 | AB1: ISIC 36T39 | AC1: ISIC 41T43 | AD1: ISIC 45T47 | AE1: ISIC 49T53 | AF1: ISIC 55T56 | AG1: ISIC 58T60 | AH1: ISIC 61 | AI1: ISIC 62T63 | AJ1: ISIC 64T66 | AK1: ISIC 68 | AL1: ISIC 69T82 | AM1: ISIC 84 | AN1: ISIC 85 | AO1: ISIC 86T88 | AP1: ISIC 90T96 | AQ1: ISIC 97T98
A2: Employee Compensation | B2: ='U.S. Data for ISIC Splits'!L23*10^6*About!$A$36 -> 5.8613298e+10 | C2: ='U.S. Data for ISIC Splits'!D10*About!$A$36 -> 5.6978074e+09 | D2: ='U.S. Data for ISIC Splits'!L27*10^6*About!$A$36 -> 2.3292495e+10 | E2: =('U.S. Data for ISIC Splits'!F10-'U.S. Data for ISIC Splits'!D10)*About!$A$36 -> 1.1617861e+10 | F2: ='U.S. Data for ISIC Splits'!L29*10^6*About!$A$36 -> 2.7069182e+10 | G2: ='U.S. Data for ISIC Splits'!L46*10^6*About!$A$36 -> 1.1736712e+11 | H2: =SUM('U.S. Data for ISIC Splits'!L47:L48)*10^6*About!$A$36 -> 1.491718e+10 | I2: ='U.S. Data for ISIC Splits'!L34*10^6*About!$A$36 -> 2.3638691e+10 | J2: =SUM('U.S. Data for ISIC Splits'!L49:L50)*10^6*About!$A$36 -> 4.6374198e+10 | K2: ='U.S. Data for ISIC Splits'!T10*About!$A$36 -> 1.5975433e+10 | L2: ='U.S. Data for ISIC Splits'!G10*About!$A$36 -> 6.6689598e+10 | M2: ='U.S. Data for ISIC Splits'!H10*About!$A$36 -> 3.3563865e+10 | N2: ='U.S. Data for ISIC Splits'!L53*10^6*About!$A$36 -> 4.562618e+10 | O2: ='U.S. Data for ISIC Splits'!J10*About!$A$36 -> 5.4800306e+09 | P2: =('U.S. Data for ISIC Splits'!L10-'U.S. Data for ISIC Splits'!$J$10)*About!$A$36 -> 2.3022242e+10 | Q2: =('U.S. Data for ISIC Splits'!U10+'U.S. Data for ISIC Splits'!M10)*About!$A$36 -> 2.0406375e+10 | R2: ='U.S. Data for ISIC Splits'!N10*About!$A$36 -> 1.0435199e+10 | S2: ='U.S. Data for ISIC Splits'!L37*10^6*About!$A$36 -> 9.3757708e+10 | T2: ='U.S. Data for ISIC Splits'!L39*10^6*About!$A$36 -> 1.3714349e+11 | U2: ='U.S. Data for ISIC Splits'!L40*10^6*About!$A$36 -> 3.4612308e+10 | V2: ='U.S. Data for ISIC Splits'!L38*10^6*About!$A$36 -> 8.7838704e+10 | W2: ='U.S. Data for ISIC Splits'!L41*10^6*About!$A$36 -> 7.0697963e+10 | X2: ='U.S. Data for ISIC Splits'!L42*10^6*About!$A$36 -> 7.7821701e+10 | Y2: =(SUM('U.S. Data for ISIC Splits'!L43:L44)+('U.S. Data for ISIC Splits'!L108*(SUM('U.S. Data for ISIC Splits'!D414)/SUM('U.S. Data for ISIC Splits'!D412:D423))))*10^6*About!$A$36 -> 8.7591009e+10 | Z2: ='U.S. Data for ISIC Splits'!P10*About!$A$36 -> 5.9184564e+10 | AA2: ='U.S. Data for ISIC Splits'!Q10*About!$A$36 -> 1.3910481e+10 | AB2: =('U.S. Data for ISIC Splits'!R10+('U.S. Data for ISIC Splits'!L93*10^6))*About!$A$36 -> 3.8827355e+10 | AC2: ='U.S. Data for ISIC Splits'!L31*10^6*About!$A$36 -> 5.8502632e+11 | AD2: =(SUM('U.S. Data for ISIC Splits'!L54:L55)+('U.S. Data for ISIC Splits'!L108*(SUM('U.S. Data for ISIC Splits'!D412)/SUM('U.S. Data for ISIC Splits'!D412:D423))))*10^6*About!$A$36 -> 1.2209546e+12 | AE2: =SUM('U.S. Data for ISIC Splits'!L61:L68)*10^6*About!$A$36 -> 4.224912e+11 | AF2: ='U.S. Data for ISIC Splits'!L105*10^6*About!$A$36 -> 4.149305e+11 | AG2: =(SUM('U.S. Data for ISIC Splits'!L70:L71)+('U.S. Data for ISIC Splits'!L72*(SUM('U.S. Data for ISIC Splits'!D337:D338)/SUM('U.S. Data for ISIC Splits'!D337:D341))))*10^6*About!$A$36 -> 1.8944516e+11 | AH2: =('U.S. Data for ISIC Splits'!L72*(SUM('U.S. Data for ISIC Splits'!D339:D341)/SUM('U.S. Data for ISIC Splits'!D337:D341)))*10^6*About!$A$36 -> 7.158683e+10 | AI2: =('U.S. Data for ISIC Splits'!L88+'U.S. Data for ISIC Splits'!L73)*10^6*About!$A$36 -> 4.9894055e+11 | AJ2: ='U.S. Data for ISIC Splits'!L75*10^6*About!$A$36 -> 8.1635862e+11 | AK2: ='U.S. Data for ISIC Splits'!L80*10^6*About!$A$36 -> 1.6364251e+11 | AL2: =SUM('U.S. Data for ISIC Splits'!L87,'U.S. Data for ISIC Splits'!L89:L90,'U.S. Data for ISIC Splits'!L92)*10^6*About!$A$36 -> 1.6335728e+12 | AM2: ='U.S. Data for ISIC Splits'!L109*10^6*About!$A$36 -> 1.8923388e+12 | AN2: ='U.S. Data for ISIC Splits'!L95*10^6*About!$A$36 -> 1.9615495e+11 | AO2: ='U.S. Data for ISIC Splits'!L96*10^6*About!$A$36 -> 1.2965438e+12 | AP2: =('U.S. Data for ISIC Splits'!L102+('U.S. Data for ISIC Splits'!L108*(SUM('U.S. Data for ISIC Splits'!D413,'U.S. Data for ISIC Splits'!D415:D422)/SUM('U.S. Data for ISIC Splits'!D412:D423))))*10^6*About!$A$36 -> 3.5352683e+11 | AQ2: =('U.S. Data for ISIC Splits'!L108*('U.S. Data for ISIC Splits'!D423/SUM('U.S. Data for ISIC Splits'!D412:D423)))*10^6*About!$A$36 -> 8.006921e+09
