Workbook

Sheet About
A1: AVL Avg Vehicle Lifetime
A3: Sources: | B3: LDV Lifetimes | D3: Bus fleet and sales (bus lifetime)
B4: Calibrated | D4: U.S. Federal Highway Administration; School Bus Fleet; Bureau of Transportation Statistics; BloombergNEF
D5: FHWA Highway Statistics MV-1 (via BTS NTS 1-11); School Bus Fleet OEM sales survey; BTS NTS 1-12 transit bus deliveries; BNEF transit bus sales and fleet 2021
B6: LDVs: Market Shares of Cars and Light Trucks | D6: 2026
B7: Bureau of Transportation Statistics | D7: https://www.bts.gov/content/number-us-aircraft-vehicles-vessels-and-other-conveyances
B8: 2016 | D8: On tab 'Freight and Buses'. School and transit buses are the only bus segments with published sales, so the selected life is their turnover; registered-bus totals include private buses with no sales series.
B9: National Transportation Statistics 2015
B10: http://www.rita.dot.gov/bts/sites/rita.dot.gov.bts/files/publications/national_transportation_statistics/index.html | D10: Motorcycle fleet and sales (motorbike lifetime)
B11: Table 1-20 | D11: U.S. Federal Highway Administration; Motorcycle Industry Council
D12: FHWA Highway Statistics MV-1 registered motorcycles 2015-2024; MIC on-highway, dual-sport and scooter retail sales
B13: Freight HDVs | D13: 2026
B14: Oak Ridge National Laboratory | D14: https://www.fhwa.dot.gov/policyinformation/statistics.cfm
B15: 2015 | D15: On tab 'Calculations' (motorbike block). On-road sales only; the BTS motorcycle sales series includes off-highway bikes and would overstate turnover.
B16: Transportation Energy Data Book Ed. 34
B17: http://cta.ornl.gov/data/tedb34/Spreadsheets/Table3_14.xls | D17: Registered boats and boat sales (recreational boat lifetime)
B18: Table 3-14, Row 43 | D18: U.S. Coast Guard; National Marine Manufacturers Association
D19: USCG Recreational Boating Statistics, registered vessels 2015-2024 (via BTS NTS 1-11); NMMA new powerboat retail units 2016-2021 (BTS NTS 1-12) and 2024-2025 (NMMA releases)
B20: Passenger HDVs (Buses) | D20: 2026
B21: ThoughtCo | D21: https://www.uscgboating.org/statistics/
B22: 2019 | D22: On tab 'Calculations' (boat block). NMMA's powerboat count includes personal watercraft and excludes sailboats, which matches the registered fleet well enough for a turnover rate.
B23: How Long Do Buses and Other Transit Vehicles Last?
B24: https://www.thoughtco.com/buses-and-other-transit-lifetime-2798844 | D24: Rail vehicles and years built (passenger rail lifetime)
D25: Federal Transit Administration, National Transit Database; Bureau of Transportation Statistics
B26: aircraft | D26: NTD Vehicles - Age Distribution, 2024 report year (rail vehicles by year built); BTS NTS Table 1-11 transit rail vehicles 2014 and 2024
B27: Jiang, Helen. Boeing. | D27: 2026
B28: 2013 | D28: https://data.transportation.gov/Public-Transit/2022-2025-NTD-Annual-Data-Vehicles-Age-Distribution-/6abt-uhgq
B29: Key Findings on Airplane Economic Life | D29: On tab 'Calculations' (passenger rail block). Vehicles built 2012-19 that are still in the fleet stand in for deliveries; later years are under-reported as agencies catch up, so they are not used.
B30: http://www.boeing.com/assets/pdf/commercial/aircraft_economic_life_whitepaper.pdf
B31: Exhibits 1-3
B33: rail and ships
B34: California State Controller's Office
B35: 1992 (but still current)
B36: Audit Guidelines and Uniform Accounting Systems: Special Districts
B37: http://www.sco.ca.gov/ard_local_rep_uas_special_dist.html
B38: Appendix A: Suggested Useful Lives of Fixed Assets
B40: motorbikes
B41: Bureau of Transportation Statistics
B42: 2009
B43: Motorcycle Trends in the United States
...

Sheet source data>

Sheet NTS 1-20
A1: Table 1-20: Productions, Production Shares, and Production-Weighted Fuel Economies of New Domestic and Imported Automobiles (Thousands of vehicles)
B2: 1980 | C2: 1985 | D2: 1990 | E2: 1991 | F2: 1992 | G2: 1993 | H2: 1994 | I2: 1995 | J2: 1996 | K2: 1997 | L2: 1998 | M2: 1999 | N2: 2000 | O2: 2001 | P2: 2002 | Q2: 2003 | R2: 2004 | S2: 2005 | T2: 2006 | U2: 2007 | V2: 2008 | W2: 2009 | X2: 2010 | Y2: 2011 | Z2: 2012 | AA2: 2013 | AB2: 2014
A3: TOTAL productions | B3: 11306 | C3: 14460 | D3: 12615 | E3: 12573 | F3: 12172 | G3: 13211 | H3: 14125 | I3: 15145 | J3: 13144 | K3: 14458 | L3: 14456 | M3: 15215 | N3: 16571 | O3: 15605 | P3: 16115 | Q3: 15773 | R3: 15709 | S3: 15892 | T3: 15104 | U3: 15276 | V3: 13898 | W3: 9316 | X3: 11110 | Y3: 12003 | Z3: 13438 | AA3: 14846 | AB3: N
A4: Car | B4: 9443 | C4: 10791 | D4: 8810 | E4: 8524 | F4: 8108 | G4: 8456 | H4: 8415 | I4: 9396 | J4: 7890 | K4: 8334 | L4: 7971 | M4: 8376 | N4: 9125 | O4: 8405 | P4: 8301 | Q4: 7921 | R4: 7537 | S4: 8027 | T4: 7993 | U4: 8082 | V4: 7319 | W4: 5636 | X4: 6055 | Y4: 5728 | Z4: 7379 | AA4: 7907 | AB4: N
A5: Car SUV | B5: 0 | C5: 88 | D5: 65 | E5: 224 | F5: 243 | G5: 473 | H5: 332 | I5: 220 | J5: 287 | K5: 361 | L5: 454 | M5: 488 | N5: 617 | O5: 743 | P5: 603 | Q5: 575 | R5: 639 | S5: 813 | T5: 751 | U5: 919 | V5: 924 | W5: 608 | X5: 915 | Y5: 1207 | Z5: 1269 | AA5: 1470 | AB5: N
A6: Pickup | B6: 1437 | C6: 2078 | D6: 1835 | E6: 1920 | F6: 1840 | G6: 2002 | H6: 2669 | I6: 2271 | J6: 1955 | K6: 2408 | L6: 2415 | M6: 2544 | N6: 2612 | O6: 2519 | P6: 2380 | Q6: 2474 | R6: 2505 | S6: 2300 | T6: 2188 | U6: 2113 | V6: 1794 | W6: 989 | X6: 1276 | Y6: 1479 | Z6: 1357 | AA6: 1577 | AB6: N
A7: Van | B7: 242 | C7: 855 | D7: 1262 | E7: 1034 | F7: 1221 | G7: 1441 | H7: 1418 | I7: 1662 | J7: 1409 | K7: 1265 | L7: 1489 | M7: 1463 | N7: 1691 | O7: 1232 | P7: 1243 | Q7: 1232 | R7: 953 | S7: 1481 | T7: 1166 | U7: 847 | V7: 790 | W7: 368 | X7: 559 | Y7: 521 | Z7: 661 | AA7: 571 | AB7: N
A8: Truck SUV | B8: 184 | C8: 648 | D8: 643 | E8: 871 | F8: 761 | G8: 838 | H8: 1291 | I8: 1596 | J8: 1603 | K8: 2089 | L8: 2127 | M8: 2342 | N8: 2526 | O8: 2707 | P8: 3588 | Q8: 3571 | R8: 4075 | S8: 3272 | T8: 3006 | U8: 3314 | V8: 3072 | W8: 1713 | X8: 2305 | Y8: 3069 | Z8: 2773 | AA8: 3321 | AB8: N
A9: Market share, percent
A10: Car | B10: =B4/B$3*100 -> 83.522024 | C10: =C4/C$3*100 -> 74.626556 | D10: 69.8 | E10: 67.8 | F10: 66.6 | G10: 64 | H10: 59.6 | I10: 62 | J10: 60 | K10: 57.6 | L10: 55.1 | M10: 55.1 | N10: 55.1 | O10: 53.9 | P10: 51.5 | Q10: 50.2 | R10: 48 | S10: 50.5 | T10: 52.9 | U10: 52.9 | V10: 52.7 | W10: 60.5 | X10: 54.5 | Y10: 47.7 | Z10: 54.9 | AA10: 53.3 | AB10: 51.3
A11: Car SUV | B11: 0 | C11: 0.6 | D11: 0.5 | E11: 1.8 | F11: 2 | G11: 3.6 | H11: 2.3 | I11: 1.5 | J11: 2.2 | K11: 2.5 | L11: 3.1 | M11: 3.2 | N11: 3.7 | O11: 4.8 | P11: 3.7 | Q11: 3.6 | R11: 4.1 | S11: 5.1 | T11: 5 | U11: 6 | V11: 6.6 | W11: 6.5 | X11: 8.2 | Y11: 10.1 | Z11: 9.4 | AA11: 9.9 | AB11: 10
A12: Pickup | B12: 12.7 | C12: 14.4 | D12: 14.5 | E12: 15.3 | F12: 15.1 | G12: 15.2 | H12: 18.9 | I12: 15 | J12: 14.9 | K12: 16.7 | L12: 16.7 | M12: 16.7 | N12: 15.8 | O12: 16.1 | P12: 14.8 | Q12: 15.7 | R12: 15.9 | S12: 14.5 | T12: 14.5 | U12: 13.8 | V12: 12.9 | W12: 10.6 | X12: 11.5 | Y12: 12.3 | Z12: 10.1 | AA12: 10.6 | AB12: 11.5
A13: Van | B13: 2.1 | C13: 5.9 | D13: 10 | E13: 8.2 | F13: 10 | G13: 10.9 | H13: 10 | I13: 11 | J13: 10.7 | K13: 8.8 | L13: 10.3 | M13: 9.6 | N13: 10.2 | O13: 7.9 | P13: 7.7 | Q13: 7.8 | R13: 6.1 | S13: 9.3 | T13: 7.7 | U13: 5.5 | V13: 5.7 | W13: 4 | X13: 5 | Y13: 4.3 | Z13: 4.9 | AA13: 3.8 | AB13: 3.9
A14: Truck SUV | B14: 1.6 | C14: 4.5 | D14: 5.1 | E14: 6.9 | F14: 6.2 | G14: 6.3 | H14: 9.1 | I14: 10.5 | J14: 12.2 | K14: 14.5 | L14: 14.7 | M14: 15.4 | N14: 15.2 | O14: 17.3 | P14: 22.3 | Q14: 22.6 | R14: 25.9 | S14: 20.6 | T14: 19.9 | U14: 21.7 | V14: 22.1 | W14: 18.4 | X14: 20.8 | Y14: 25.6 | Z14: 20.6 | AA14: 22.4 | AB14: 23.3
A15: Fuel economy, mpg
A16: Car | B16: 20 | C16: 23 | D16: 23.3 | E16: 23.4 | F16: 23.1 | G16: 23.5 | H16: 23.3 | I16: 23.4 | J16: 23.3 | K16: 23.4 | L16: 23.4 | M16: 23 | N16: 22.9 | O16: 23 | P16: 23.1 | Q16: 23.3 | R16: 23.1 | S16: 23.5 | T16: 23.3 | U16: 24.1 | V16: 24.3 | W16: 25.3 | X16: 26.2 | Y16: 26 | Z16: 27.8 | AA16: 28.3 | AB16: 28.7
A17: Car SUV | B17: 14.6 | C17: 20.1 | D17: 18.8 | E17: 18.2 | F17: 17.8 | G17: 17 | H17: 18 | I17: 17.8 | J17: 18.4 | K17: 19.2 | L17: 18.2 | M17: 18.5 | N17: 17.9 | O17: 18.8 | P17: 19.3 | Q17: 19.9 | R17: 20 | S17: 20.2 | T17: 20.5 | U17: 20.6 | V17: 21.2 | W17: 22 | X17: 23 | Y17: 23.6 | Z17: 23.4 | AA17: 24.5 | AB17: 24.3
A18: Pickup | B18: 16.5 | C18: 18.2 | D18: 17.4 | E18: 18.2 | F18: 17.5 | G18: 17.6 | H18: 17.4 | I18: 16.9 | J18: 17.1 | K18: 16.8 | L18: 17 | M18: 16.3 | N18: 16.7 | O18: 16 | P18: 15.8 | Q18: 16.1 | R18: 15.7 | S18: 15.8 | T18: 16.1 | U18: 16.2 | V18: 16.5 | W18: 16.9 | X18: 16.9 | Y18: 17.2 | Z18: 17.2 | AA18: 17.4 | AB18: 18
A19: Van | B19: 14.1 | C19: 16.5 | D19: 17.8 | E19: 17.9 | F19: 17.9 | G19: 18.2 | H19: 17.8 | I19: 18.1 | J19: 18.3 | K19: 18.2 | L19: 18.7 | M19: 18.3 | N19: 18.6 | O19: 18 | P19: 18.7 | Q19: 19 | R19: 19.2 | S19: 19.3 | T19: 19.5 | U19: 19.5 | V19: 19.8 | W19: 20.1 | X19: 20.1 | Y19: 21 | Z19: 21.4 | AA19: 21.1 | AB19: 21.2
A20: Truck SUV | B20: 13.2 | C20: 16.5 | D20: 16.4 | E20: 16.7 | F20: 16.2 | G20: 16.3 | H20: 16 | I20: 16 | J20: 16.2 | K20: 16.1 | L20: 16.2 | M20: 16.1 | N20: 16 | O20: 16.4 | P20: 16.3 | Q20: 16.4 | R20: 16.5 | S20: 16.7 | T20: 17.2 | U20: 17.7 | V20: 18.2 | W20: 19.3 | X20: 19.7 | Y20: 19.8 | Z20: 20 | AA20: 20.9 | AB20: 21.2
A21: KEY: mpg = miles per gallon; N = data are not available; R = revised; SUV = sport utility vehicle.
A23: NOTES
A24: Numbers may not add to totals due to rounding.
A25: This table is not comparable to previous publication's tables due to changes in the source data.
A26: The Environmental Protection Agency changed the vehicle classifications, combining wagons with the rest of the cars and dropping the small, medium, large categories of cars, pickups, sport-utilities, and vans. The fuel economy displayed in those tables has been adjusted to provide the best estimate of real-world performance.
A28: SOURCE
A29: U.S. Department of Energy, Office of Energy Efficiency and Renewable Energy, Transportation Energy Data Book, Edition 33, tables 4.7, table 4.9 and table 4.11 (Oak Ridge, TN), available at http://cta.ornl.gov/data/index.shtml as of Dec. 8, 2015.

Sheet AEO 2026 Table 45
A1: Table 45. Transportation Fleet Car and Truck Stock by Type and Technology
A2: https://www.eia.gov/outlooks/aeo/data/browser/#/?id=55-AEO2026&cases=electrnp&sourcekey=0
A3: Thu Apr 23 2026 15:04:58 GMT-0700 (Pacific Daylight Time)
A4: Source: U.S. Energy Information Administration
B5: full name | C5: api key | D5: units | E5: 2025 | F5: 2026 | G5: 2027 | H5: 2028 | I5: 2029 | J5: 2030 | K5: 2031 | L5: 2032 | M5: 2033 | N5: 2034 | O5: 2035 | P5: 2036 | Q5: 2037 | R5: 2038 | S5: 2039 | T5: 2040 | U5: 2041 | V5: 2042 | W5: 2043 | X5: 2044 | Y5: 2045 | Z5: 2046 | AA5: 2047 | AB5: 2048 | AC5: 2049 | AD5: 2050 | AE5: Growth (2025-2050)
A6: Car Stock
A7: Conventional Cars
A8: Gasoline ICE Vehicles | B8: Fleet Vehicle Stock: Conventional Cars: Gasoline: Alternative Electricity and Transportation | C8: AEO.2026.ELECTRNP.ECI_STK_CNV_FLC_GSL_NA_NA_TH.A | D8: thousands | E8: 5200.4526 | F8: 4904.3384 | G8: 4575.9521 | H8: 4294.0498 | I8: 4068.2461 | J8: 3891.0559 | K8: 3732.8235 | L8: 3585.3479 | M8: 3451.0632 | N8: 3324.0464 | O8: 3205.0349 | P8: 3085.6714 | Q8: 2977.6858 | R8: 2880.26 | S8: 2790.3772 | T8: 2705.311 | U8: 2623.4365 | V8: 2544.8809 | W8: 2468.8469 | X8: 2396.1611 | Y8: 2328.1196 | Z8: 2262.8105 | AA8: 2201.9463 | AB8: 2142.689 | AC8: 2084.9839 | AD8: 2026.223 | AE8: -0.037
A9: TDI Diesel ICE | B9: Fleet Vehicle Stock: Conventional Cars: TDI Diesel: Alternative Electricity and Transportation | C9: AEO.2026.ELECTRNP.ECI_STK_CNV_FLC_TDS_NA_NA_TH.A | D9: thousands | E9: 15.814128 | F9: 13.938295 | G9: 12.193138 | H9: 10.563546 | I9: 9.060416 | J9: 7.707277 | K9: 6.508159 | L9: 5.461804 | M9: 4.575233 | N9: 3.841874 | O9: 3.24966 | P9: 2.781465 | Q9: 2.41583 | R9: 2.134801 | S9: 1.917431 | T9: 1.736284 | U9: 1.57695 | V9: 1.436198 | W9: 1.310303 | X9: 1.196242 | Y9: 1.09238 | Z9: 0.997788 | AA9: 0.911623 | AB9: 0.833118 | AC9: 0.761579 | AD9: 0.696374 | AE9: -0.117
A10: Total Conventional Cars | B10: Fleet Vehicle Stock: Conventional Cars: Total: Alternative Electricity and Transportation | C10: AEO.2026.ELECTRNP.ECI_STK_CNV_FLC_NA_NA_NA_TH.A | D10: thousands | E10: 5216.2666 | F10: 4918.2769 | G10: 4588.1455 | H10: 4304.6133 | I10: 4077.3064 | J10: 3898.7632 | K10: 3739.3315 | L10: 3590.8098 | M10: 3455.6384 | N10: 3327.8882 | O10: 3208.2847 | P10: 3088.4529 | Q10: 2980.1016 | R10: 2882.3948 | S10: 2792.2947 | T10: 2707.0474 | U10: 2625.0134 | V10: 2546.3171 | W10: 2470.1572 | X10: 2397.3574 | Y10: 2329.2119 | Z10: 2263.8083 | AA10: 2202.8579 | AB10: 2143.522 | AC10: 2085.7454 | AD10: 2026.9194 | AE10: -0.037
A11: Alternative-Fuel Cars
A12: Ethanol-Flex Fuel ICE | B12: Fleet Vehicle Stock: Alternative-Fuel Cars: Ethanol-Flex Fuel ICE: Alternative Electricity and Transportation | C12: AEO.2026.ELECTRNP.ECI_STK_ALF1_FLC_EFFI_NA_NA_TH.A | D12: thousands | E12: 193.21745 | F12: 159.50981 | G12: 136.48273 | H12: 116.07923 | I12: 97.928757 | J12: 81.966225 | K12: 68.266495 | L12: 56.709991 | M12: 47.370358 | N12: 39.852268 | O12: 33.936234 | P12: 29.400446 | Q12: 25.805008 | R12: 22.915279 | S12: 20.616272 | T12: 18.729715 | U12: 17.147816 | V12: 15.794521 | W12: 14.636535 | X12: 13.635636 | Y12: 12.752481 | Z12: 11.956233 | AA12: 11.247208 | AB12: 10.631876 | AC12: 10.063699 | AD12: 9.538871 | AE12: -0.113
A13: 100-Mile Electric Vehicle | B13: Fleet Vehicle Stock: Alternative-Fuel Cars: 100-Mile Electric Vehicle: Alternative Electricity and Transportation | C13: AEO.2026.ELECTRNP.ECI_STK_ALF1_FLC_100MIEV_NA_NA_TH.A | D13: thousands | E13: 12.823667 | F13: 12.981208 | G13: 12.843882 | H13: 12.388824 | I13: 12.017113 | J13: 11.894691 | K13: 11.852228 | L13: 11.957543 | M13: 12.171066 | N13: 12.487912 | O13: 12.924793 | P13: 13.402992 | Q13: 13.933009 | R13: 14.512439 | S13: 15.111438 | T13: 15.709825 | U13: 16.255154 | V13: 16.760593 | W13: 17.227583 | X13: 17.645254 | Y13: 18.057564 | Z13: 18.413551 | AA13: 18.755608 | AB13: 19.067127 | AC13: 19.337585 | AD13: 19.542181 | AE13: 0.017
A14: 200-Mile Electric Vehicle | B14: Fleet Vehicle Stock: Alternative-Fuel Cars: 200-Mile Electric Vehicle: Alternative Electricity and Transportation | C14: AEO.2026.ELECTRNP.ECI_STK_ALF1_FLC_200MIEV_NA_NA_TH.A | D14: thousands | E14: 49.358566 | F14: 58.074745 | G14: 76.353798 | H14: 89.212097 | I14: 96.488159 | J14: 97.371002 | K14: 99.096672 | L14: 101.12775 | M14: 105.95017 | N14: 112.0268 | O14: 119.13989 | P14: 125.43132 | Q14: 131.71814 | R14: 137.8517 | S14: 143.6964 | T14: 148.72258 | U14: 153.47376 | V14: 157.99193 | W14: 162.17264 | X14: 165.96719 | Y14: 169.20833 | Z14: 172.41849 | AA14: 175.7299 | AB14: 178.67452 | AC14: 181.32904 | AD14: 183.35115 | AE14: 0.054
A15: 300-Mile Electric Vehicle | B15: Fleet Vehicle Stock: Alternative-Fuel Cars: 300-Mile Electric Vehicle: Alternative Electricity and Transportation | C15: AEO.2026.ELECTRNP.ECI_STK_ALF1_FLC_300MIEV_NA_NA_TH.A | D15: thousands | E15: 263.59168 | F15: 300.86673 | G15: 348.64984 | H15: 384.50433 | I15: 434.91431 | J15: 488.20209 | K15: 545.43536 | L15: 600.52863 | M15: 657.31561 | N15: 711.00708 | O15: 764.95624 | P15: 812.79352 | Q15: 858.64795 | R15: 902.62231 | S15: 944.09613 | T15: 981.4776 | U15: 1014.7573 | V15: 1044.864 | W15: 1071.6549 | X15: 1095.3257 | Y15: 1117.1243 | Z15: 1136.2902 | AA15: 1154.9224 | AB15: 1171.0825 | AC15: 1184.9039 | AD15: 1194.4635 | AE15: 0.062
A16: Plug-in 20 Gasoline Hybrid | B16: Fleet Vehicle Stock: Alternative-Fuel Cars: Plug-in 20 Gasoline Hybrid: Alternative Electricity and Transportation | C16: AEO.2026.ELECTRNP.ECI_STK_ALF1_FLC_PI20GH_NA_NA_TH.A | D16: thousands | E16: 34.596752 | F16: 30.608488 | G16: 27.326748 | H16: 26.614899 | I16: 25.900885 | J16: 25.315302 | K16: 24.233877 | L16: 23.190699 | M16: 22.490473 | N16: 21.979679 | O16: 21.573814 | P16: 21.04114 | Q16: 20.545706 | R16: 20.059357 | S16: 19.597324 | T16: 19.087015 | U16: 18.624937 | V16: 18.216772 | W16: 17.840681 | X16: 17.466496 | Y16: 17.061407 | Z16: 16.704313 | AA16: 16.385477 | AB16: 16.069012 | AC16: 15.745203 | AD16: 15.398971 | AE16: -0.032
A17: Plug-in 50 Gasoline Hybrid | B17: Fleet Vehicle Stock: Alternative-Fuel Cars: Plug-in 50 Gasoline Hybrid: Alternative Electricity and Transportation | C17: AEO.2026.ELECTRNP.ECI_STK_ALF1_FLC_PI50GH_NA_NA_TH.A | D17: thousands | E17: 19.589474 | F17: 24.650236 | G17: 32.934143 | H17: 39.004486 | I17: 37.118404 | J17: 33.069084 | K17: 29.835768 | L17: 27.469379 | M17: 26.31011 | N17: 25.836098 | O17: 25.82777 | P17: 25.819584 | Q17: 25.847315 | R17: 25.905813 | S17: 26.000364 | T17: 26.069088 | U17: 26.039118 | V17: 25.966375 | W17: 25.866949 | X17: 25.739273 | Y17: 25.665237 | Z17: 25.554262 | AA17: 25.507757 | AB17: 25.466749 | AC17: 25.447727 | AD17: 25.379066 | AE17: 0.01
A18: Electric-Gasoline Hybrid | B18: Fleet Vehicle Stock: Alternative-Fuel Cars: Electric-Gasoline Hybrid: Alternative Electricity and Transportation | C18: AEO.2026.ELECTRNP.ECI_STK_ALF1_FLC_EGH_NA_NA_TH.A | D18: thousands | E18: 287.18549 | F18: 318.71747 | G18: 342.02924 | H18: 352.97415 | I18: 359.95718 | J18: 369.39511 | K18: 381.5592 | L18: 393.66666 | M18: 407.05731 | N18: 419.79788 | O18: 432.14249 | P18: 441.82434 | Q18: 451.03738 | R18: 459.88 | S18: 468.02075 | T18: 475.0647 | U18: 480.99243 | V18: 485.98746 | W18: 489.92267 | X18: 493.09201 | Y18: 496.01276 | Z18: 498.5032 | AA18: 501.18487 | AB18: 503.39868 | AC18: 505.07394 | AD18: 505.58981 | AE18: 0.023
A19: Fuel Cell Hydrogen | B19: Fleet Vehicle Stock: Alternative-Fuel Cars: Fuel Cell Hydrogen: Alternative Electricity and Transportation | C19: AEO.2026.ELECTRNP.ECI_STK_ALF1_FLC_FCH_NA_NA_TH.A | D19: thousands | E19: 0.949052 | F19: 0.864998 | G19: 0.796722 | H19: 0.735669 | I19: 0.676834 | J19: 0.619557 | K19: 0.561393 | L19: 0.502012 | M19: 0.443478 | N19: 0.385677 | O19: 0.330998 | P19: 0.279892 | Q19: 0.233957 | R19: 0.193587 | S19: 0.159393 | T19: 0.13141 | U19: 0.109955 | V19: 0.093902 | W19: 0.081649 | X19: 0.072316 | Y19: 0.065349 | Z19: 0.060264 | AA19: 0.056443 | AB19: 0.053208 | AC19: 0.050313 | AD19: 0.047672 | AE19: -0.113
A20: Total Alternative Cars | B20: Fleet Vehicle Stock: Alternative-Fuel Cars: Total: Alternative Electricity and Transportation | C20: AEO.2026.ELECTRNP.ECI_STK_ALF1_FLC_NA_NA_NA_TH.A | D20: thousands | E20: 874.46881 | F20: 918.14514 | G20: 988.16138 | H20: 1031.1885 | I20: 1073.6791 | J20: 1115.6639 | K20: 1167.8727 | L20: 1221.469 | M20: 1284.7955 | N20: 1348.5228 | O20: 1415.5183 | P20: 1474.2825 | Q20: 1531.7611 | R20: 1587.6694 | S20: 1640.7957 | T20: 1688.2784 | U20: 1730.4884 | V20: 1768.5769 | W20: 1802.1298 | X20: 1831.5054 | Y20: 1858.3541 | Z20: 1882.1621 | AA20: 1905.9146 | AB20: 1926.4403 | AC20: 1943.8274 | AD20: 1955.074 | AE20: 0.033
A21: Total Car Stock | B21: Fleet Vehicle Stock: Cars: Total: Alternative Electricity and Transportation | C21: AEO.2026.ELECTRNP.ECI_STK_NA_FLC_NA_NA_NA_TH.A | D21: thousands | E21: 6090.7354 | F21: 5836.4219 | G21: 5576.3066 | H21: 5335.8018 | I21: 5150.9854 | J21: 5014.4272 | K21: 4907.2041 | L21: 4812.2788 | M21: 4740.4341 | N21: 4676.4111 | O21: 4623.8027 | P21: 4562.7354 | Q21: 4511.8628 | R21: 4470.0645 | S21: 4433.0903 | T21: 4395.3257 | U21: 4355.502 | V21: 4314.894 | W21: 4272.2871 | X21: 4228.8628 | Y21: 4187.5659 | Z21: 4145.9707 | AA21: 4108.7725 | AB21: 4069.9624 | AC21: 4029.5728 | AD21: 3981.9934 | AE21: -0.017
A22: Light Truck Stock
A23: Conventional Light Trucks
A24: Gasoline ICE Vehicles | B24: Fleet Vehicle Stock: Conventional Light Trucks: Gasoline: Alternative Electricity and Transportation | C24: AEO.2026.ELECTRNP.ECI_STK_CNV_FLTR_GSL_NA_NA_TH.A | D24: thousands | E24: 9500.2549 | F24: 9485.5742 | G24: 9426.8271 | H24: 9374.4473 | I24: 9420.6514 | J24: 9537.374 | K24: 9692.0547 | L24: 9842.9268 | M24: 9938.6143 | N24: 9986.3018 | O24: 9994.792 | P24: 9961.7373 | Q24: 9912.3682 | R24: 9851.3711 | S24: 9766.0889 | T24: 9673.0342 | U24: 9571.8486 | V24: 9462.0811 | W24: 9347.7188 | X24: 9230.7568 | Y24: 9111.1758 | Z24: 8989.4072 | AA24: 8862.6318 | AB24: 8731.4199 | AC24: 8593.6182 | AD24: 8447.0303 | AE24: -0.005
A25: TDI Diesel ICE | B25: Fleet Vehicle Stock: Conventional Light Trucks: TDI Diesel: Alternative Electricity and Transportation | C25: AEO.2026.ELECTRNP.ECI_STK_CNV_FLTR_TDS_NA_NA_TH.A | D25: thousands | E25: 110.0193 | F25: 122.5195 | G25: 132.05486 | H25: 139.49692 | I25: 146.40074 | J25: 153.45625 | K25: 160.04947 | L25: 166.03966 | M25: 171.30579 | N25: 176.15753 | O25: 180.27542 | P25: 183.36118 | Q25: 185.92255 | R25: 188.11433 | S25: 189.85066 | T25: 191.04047 | U25: 191.84402 | V25: 192.33519 | W25: 192.52586 | X25: 192.42023 | Y25: 191.95677 | Z25: 191.46834 | AA25: 190.80849 | AB25: 190.02399 | AC25: 188.93823 | AD25: 187.62779 | AE25: 0.022
A26: Total Conventional Light Trucks | B26: Fleet Vehicle Stock: Conventional Light Trucks: Total: Alternative Electricity and Transportation | C26: AEO.2026.ELECTRNP.ECI_STK_CNV_FLTR_NA_NA_NA_TH.A | D26: thousands | E26: 9610.2744 | F26: 9608.0938 | G26: 9558.8818 | H26: 9513.9443 | I26: 9567.0518 | J26: 9690.8301 | K26: 9852.1045 | L26: 10008.967 | M26: 10109.92 | N26: 10162.459 | O26: 10175.067 | P26: 10145.099 | Q26: 10098.291 | R26: 10039.485 | S26: 9955.9395 | T26: 9864.0742 | U26: 9763.6924 | V26: 9654.416 | W26: 9540.2441 | X26: 9423.1768 | Y26: 9303.1328 | Z26: 9180.876 | AA26: 9053.4404 | AB26: 8921.4443 | AC26: 8782.5566 | AD26: 8634.6582 | AE26: -0.004
A27: Alternative-Fuel Light Trucks
A28: Ethanol-Flex Fuel ICE | B28: Fleet Vehicle Stock: Alternative-Fuel Light Trucks: Ethanol-Flex Fuel ICE: Alternative Electricity and Transportation | C28: AEO.2026.ELECTRNP.ECI_STK_ALF1_FLTR_EFFI_NA_NA_TH.A | D28: thousands | E28: 1007.2556 | F28: 870.78906 | G28: 771.02258 | H28: 680.4483 | I28: 596.8443 | J28: 520.00269 | K28: 450.6156 | L28: 388.65585 | M28: 333.94754 | N28: 286.29788 | O28: 245.38309 | P28: 210.63995 | Q28: 181.58752 | R28: 157.65451 | S28: 137.72523 | T28: 120.98581 | U28: 107.05018 | V28: 95.466614 | W28: 85.941582 | X28: 78.031693 | Y28: 71.333115 | Z28: 65.642509 | AA28: 60.793465 | AB28: 56.536846 | AC28: 52.695965 | AD28: 49.226734 | AE28: -0.114
A29: 100-Mile Electric Vehicle | B29: Fleet Vehicle Stock: Alternative-Fuel Light Trucks: 100-Mile Electric Vehicle: Alternative Electricity and Transportation | C29: AEO.2026.ELECTRNP.ECI_STK_ALF1_FLTR_100MIEV_NA_NA_TH.A | D29: thousands | E29: 0.998046 | F29: 1.224324 | G29: 1.434016 | H29: 1.612743 | I29: 1.81001 | J29: 2.057015 | K29: 2.332481 | L29: 2.638899 | M29: 2.970936 | N29: 3.312224 | O29: 3.669823 | P29: 4.024693 | Q29: 4.383288 | R29: 4.745573 | S29: 5.111744 | T29: 5.478789 | U29: 5.831968 | V29: 6.173477 | W29: 6.504694 | X29: 6.826125 | Y29: 7.145949 | Z29: 7.445385 | AA29: 7.733372 | AB29: 8.003904 | AC29: 8.257642 | AD29: 8.483736 | AE29: 0.089
A30: 200-Mile Electric Vehicle | B30: Fleet Vehicle Stock: Alternative-Fuel Light Trucks: 200-Mile Electric Vehicle: Alternative Electricity and Transportation | C30: AEO.2026.ELECTRNP.ECI_STK_ALF1_FLTR_200MIEV_NA_NA_TH.A | D30: thousands | E30: 31.350508 | F30: 74.368172 | G30: 136.70589 | H30: 204.58423 | I30: 264.52899 | J30: 302.96585 | K30: 327.23053 | L30: 339.48434 | M30: 359.05701 | N30: 385 | O30: 416.31107 | P30: 447.93219 | Q30: 480.79114 | R30: 514.51483 | S30: 547.89514 | T30: 581.35474 | U30: 613.88788 | V30: 645.62732 | W30: 676.58795 | X30: 706.87476 | Y30: 736.98785 | Z30: 765.62231 | AA30: 793.84613 | AB30: 820.5882 | AC30: 846.39441 | AD30: 869.89203 | AE30: 0.142
A31: 300-Mile Electric Vehicle | B31: Fleet Vehicle Stock: Alternative-Fuel Light Trucks: 300-Mile Electric Vehicle: Alternative Electricity and Transportation | C31: AEO.2026.ELECTRNP.ECI_STK_ALF1_FLTR_300MIEV_NA_NA_TH.A | D31: thousands | E31: 131.8945 | F31: 218.22766 | G31: 319.21445 | H31: 427.61621 | I31: 519.14703 | J31: 598.8775 | K31: 652.34125 | L31: 703.94128 | M31: 767.26276 | N31: 840.14691 | O31: 920.04553 | P31: 998.25732 | Q31: 1077.3264 | R31: 1156.8517 | S31: 1235.5844 | T31: 1313.3093 | U31: 1387.3439 | V31: 1458.1968 | W31: 1526.0869 | X31: 1591.3063 | Y31: 1655.2568 | Z31: 1714.7753 | AA31: 1772.1117 | AB31: 1825.3832 | AC31: 1875.2927 | AD31: 1919.2892 | AE31: 0.113
A32: Plug-in 20 Gasoline Hybrid | B32: Fleet Vehicle Stock: Alternative-Fuel Light Trucks: Plug-in 20 Gasoline Hybrid: Alternative Electricity and Transportation | C32: AEO.2026.ELECTRNP.ECI_STK_ALF1_FLTR_PI20GH_NA_NA_TH.A | D32: thousands | E32: 122.12784 | F32: 109.80188 | G32: 105.26385 | H32: 112.53404 | I32: 120.32596 | J32: 128.97658 | K32: 138.9632 | L32: 149.43585 | M32: 160.94911 | N32: 173.17796 | O32: 186.35577 | P32: 198.1078 | Q32: 209.28947 | R32: 220.11481 | S32: 230.61597 | T32: 240.00815 | U32: 248.14912 | V32: 255.41205 | W32: 262.11166 | X32: 268.10059 | Y32: 273.49014 | Z32: 278.10757 | AA32: 282.30191 | AB32: 285.72101 | AC32: 288.57199 | AD32: 290.41791 | AE32: 0.035
A33: Plug-in 50 Gasoline Hybrid | B33: Fleet Vehicle Stock: Alternative-Fuel Light Trucks: Plug-in 50 Gasoline Hybrid: Alternative Electricity and Transportation | C33: AEO.2026.ELECTRNP.ECI_STK_ALF1_FLTR_PI50GH_NA_NA_TH.A | D33: thousands | E33: 21.128172 | F33: 63.923275 | G33: 127.46903 | H33: 198.09959 | I33: 204.47481 | J33: 194.68616 | K33: 177.24062 | L33: 158.29658 | M33: 146.7289 | N33: 141.22395 | O33: 138.79694 | P33: 136.70372 | Q33: 134.75311 | R33: 132.77786 | S33: 130.82497 | T33: 128.74747 | U33: 126.18153 | V33: 123.2283 | W33: 120.0466 | X33: 116.77601 | Y33: 113.73335 | Z33: 110.68338 | AA33: 107.94883 | AB33: 105.44351 | AC33: 103.29976 | AD33: 101.36417 | AE33: 0.065
A34: Electric-Gasoline Hybrid | B34: Fleet Vehicle Stock: Alternative-Fuel Light Trucks: Electric-Gasoline Hybrid: Alternative Electricity and Transportation | C34: AEO.2026.ELECTRNP.ECI_STK_ALF1_FLTR_EGH_NA_NA_TH.A | D34: thousands | E34: 532.14844 | F34: 776.49652 | G34: 993.47315 | H34: 1195.9524 | I34: 1387.8796 | J34: 1573.0736 | K34: 1745.166 | L34: 1900.5806 | M34: 2044.6385 | N34: 2176.8999 | O34: 2298.969 | P34: 2405.2585 | Q34: 2503.7341 | R34: 2594.5647 | S34: 2690.9143 | T34: 2777.6707 | U34: 2850.6106 | V34: 2910.7866 | W34: 2963.3218 | X34: 3010.3772 | Y34: 3053.2241 | Z34: 3091.2175 | AA34: 3124.9641 | AB34: 3153.6448 | AC34: 3178.0256 | AD34: 3196.3552 | AE34: 0.074
A35: Fuel Cell Hydrogen | B35: Fleet Vehicle Stock: Alternative-Fuel Light Trucks: Fuel Cell Hydrogen: Alternative Electricity and Transportation | C35: AEO.2026.ELECTRNP.ECI_STK_ALF1_FLTR_FCH_NA_NA_TH.A | D35: thousands | E35: 0 | F35: 0 | G35: 0 | H35: 0 | I35: 0 | J35: 0 | K35: 0 | L35: 0 | M35: 0 | N35: 0 | O35: 0 | P35: 0 | Q35: 0 | R35: 0 | S35: 0 | T35: 0 | U35: 0 | V35: 0 | W35: 0 | X35: 0 | Y35: 0 | Z35: 0 | AA35: 0 | AB35: 0 | AC35: 0 | AD35: 0 | AE35: - -
A36: Total Alternative Light Trucks | B36: Fleet Vehicle Stock: Alternative-Fuel Light Trucks: Total: Alternative Electricity and Transportation | C36: AEO.2026.ELECTRNP.ECI_STK_ALF1_FLTR_NA_NA_NA_TH.A | D36: thousands | E36: 1858.9742 | F36: 2126.1035 | G36: 2465.1501 | H36: 2830.7666 | I36: 3104.3303 | J36: 3329.3943 | K36: 3502.1111 | L36: 3650.751 | M36: 3822.7976 | N36: 4012.8557 | O36: 4215.9092 | P36: 4406.9121 | Q36: 4597.4941 | R36: 4786.5161 | S36: 4983.6494 | T36: 5172.2368 | U36: 5343.459 | V36: 5499.0332 | W36: 5644.4971 | X36: 5781.9575 | Y36: 5914.6187 | Z36: 6036.7368 | AA36: 6152.7495 | AB36: 6258.1904 | AC36: 6355.2363 | AD36: 6437.5669 | AE36: 0.051
A37: Total Light Truck Stock | B37: Fleet Vehicle Stock: Light Trucks: Total: Alternative Electricity and Transportation | C37: AEO.2026.ELECTRNP.ECI_STK_NA_FLTR_NA_NA_NA_TH.A | D37: thousands | E37: 11469.249 | F37: 11734.197 | G37: 12024.032 | H37: 12344.711 | I37: 12671.382 | J37: 13020.225 | K37: 13354.216 | L37: 13659.718 | M37: 13932.718 | N37: 14175.314 | O37: 14390.977 | P37: 14552.011 | Q37: 14695.785 | R37: 14826.002 | S37: 14939.589 | T37: 15036.311 | U37: 15107.151 | V37: 15153.449 | W37: 15184.741 | X37: 15205.135 | Y37: 15217.752 | Z37: 15217.613 | AA37: 15206.189 | AB37: 15179.635 | AC37: 15137.793 | AD37: 15072.225 | AE37: 0.011
A38: Total Fleet Vehicles | B38: Fleet Stock: Total Fleet Vehicles: Alternative Electricity and Transportation | C38: AEO.2026.ELECTRNP.ECI_STK_NA_NA_NA_NA_NA_TH.A | D38: thousands | E38: 17559.984 | F38: 17570.619 | G38: 17600.34 | H38: 17680.512 | I38: 17822.367 | J38: 18034.652 | K38: 18261.42 | L38: 18471.996 | M38: 18673.152 | N38: 18851.727 | O38: 19014.779 | P38: 19114.746 | Q38: 19207.648 | R38: 19296.066 | S38: 19372.68 | T38: 19431.637 | U38: 19462.652 | V38: 19468.344 | W38: 19457.027 | X38: 19433.998 | Y38: 19405.318 | Z38: 19363.584 | AA38: 19314.961 | AB38: 19249.598 | AC38: 19167.365 | AD38: 19054.219 | AE38: 0.003
A39: Motor Gasoline | B39: Fleet Stock: Commercial Light Trucks: Gasoline: Alternative Electricity and Transportation | C39: AEO.2026.ELECTRNP.ECI_STK_NA_CLTR_GSL_NA_NA_TH.A | D39: thousands | E39: 7882.2637 | F39: 7718.1157 | G39: 7629.0815 | H39: 7589.3721 | I39: 7590.8135 | J39: 7633.5 | K39: 7698.8799 | L39: 7782.9263 | M39: 7859.0767 | N39: 7919.3301 | O39: 7952.2817 | P39: 7956.8364 | Q39: 7931.2661 | R39: 7882.021 | S39: 7812.3657 | T39: 7721.0332 | U39: 7608.1904 | V39: 7477.1328 | W39: 7346.2534 | X39: 7216.3901 | Y39: 7075.6992 | Z39: 6920.3643 | AA39: 6762.7627 | AB39: 6594.4473 | AC39: 6411.7974 | AD39: 6213.7129 | AE39: -0.009
A40: Diesel | B40: Fleet Stock: Commercial Light Trucks: TDI Diesel: Alternative Electricity and Transportation | C40: AEO.2026.ELECTRNP.ECI_STK_NA_CLTR_TDS_NA_NA_TH.A | D40: thousands | E40: 5002.978 | F40: 4920.6372 | G40: 4838.4229 | H40: 4754.917 | I40: 4667.8301 | J40: 4577.2856 | K40: 4477.2271 | L40: 4384.5674 | M40: 4277.0864 | N40: 4162.5894 | O40: 4032.8044 | P40: 3892.822 | Q40: 3743.9099 | R40: 3586.1233 | S40: 3426.6826 | T40: 3261.0994 | U40: 3103.415 | V40: 2952.2263 | W40: 2821.3669 | X40: 2704.1667 | Y40: 2587.6079 | Z40: 2472.3601 | AA40: 2362.5249 | AB40: 2255.0486 | AC40: 2139.4744 | AD40: 2021.7506 | AE40: -0.036
...

Sheet AEO 2026 Table 44
A1: Table 44. Transportation Fleet Car and Truck Sales by Type and Technology
A2: https://www.eia.gov/outlooks/aeo/data/browser/#/?id=54-AEO2026&cases=electrnp&sourcekey=0
A3: Thu Apr 23 2026 15:04:49 GMT-0700 (Pacific Daylight Time)
A4: Source: U.S. Energy Information Administration
B5: full name | C5: api key | D5: units | E5: 2025 | F5: 2026 | G5: 2027 | H5: 2028 | I5: 2029 | J5: 2030 | K5: 2031 | L5: 2032 | M5: 2033 | N5: 2034 | O5: 2035 | P5: 2036 | Q5: 2037 | R5: 2038 | S5: 2039 | T5: 2040 | U5: 2041 | V5: 2042 | W5: 2043 | X5: 2044 | Y5: 2045 | Z5: 2046 | AA5: 2047 | AB5: 2048 | AC5: 2049 | AD5: 2050 | AE5: Growth (2025-2050)
A6: New Car Sales
A7: Conventional Cars | D7: thousands
A8: Gasoline ICE Vehicles | B8: Fleet Vehicle Sales: Conventional Cars: Gasoline: Alternative Electricity and Transportation | C8: AEO.2026.ELECTRNP.ECI_SAL_CNV_FLC_GSL_NA_NA_TH.A | D8: thousands | E8: 714.64008 | F8: 635.59387 | G8: 589.33008 | H8: 570.05371 | I8: 565.56348 | J8: 572.2243 | K8: 565.49054 | L8: 559.52759 | M8: 556.60181 | N8: 545.70154 | O8: 535.82147 | P8: 516.50177 | Q8: 506.77213 | R8: 495.89575 | S8: 483.99036 | T8: 472.22794 | U8: 459.40717 | V8: 447.20297 | W8: 434.76849 | X8: 423.66336 | Y8: 414.56082 | Z8: 404.51852 | AA8: 397.13562 | AB8: 387.71933 | AC8: 378.78668 | AD8: 367.43161 | AE8: -0.026
A9: TDI Diesel ICE | B9: Fleet Vehicle Sales: Conventional Cars: TDI Diesel: Alternative Electricity and Transportation | C9: AEO.2026.ELECTRNP.ECI_SAL_CNV_FLC_TDS_NA_NA_TH.A | D9: thousands | E9: 0 | F9: 0 | G9: 0 | H9: 0 | I9: 0 | J9: 0 | K9: 0 | L9: 0 | M9: 0 | N9: 0 | O9: 0 | P9: 0 | Q9: 0 | R9: 0 | S9: 0 | T9: 0 | U9: 0 | V9: 0 | W9: 0 | X9: 0 | Y9: 0 | Z9: 0 | AA9: 0 | AB9: 0 | AC9: 0 | AD9: 0 | AE9: - -
A10: Total Conventional Cars | B10: Fleet Vehicle Sales: Conventional Cars: Total: Alternative Electricity and Transportation | C10: AEO.2026.ELECTRNP.ECI_SAL_CNV_FLC_NA_NA_NA_TH.A | D10: thousands | E10: 714.64008 | F10: 635.59387 | G10: 589.33008 | H10: 570.05371 | I10: 565.56348 | J10: 572.2243 | K10: 565.49054 | L10: 559.52759 | M10: 556.60181 | N10: 545.70154 | O10: 535.82147 | P10: 516.50177 | Q10: 506.77213 | R10: 495.89575 | S10: 483.99036 | T10: 472.22794 | U10: 459.40717 | V10: 447.20297 | W10: 434.76849 | X10: 423.66336 | Y10: 414.56082 | Z10: 404.51852 | AA10: 397.13562 | AB10: 387.71933 | AC10: 378.78668 | AD10: 367.43161 | AE10: -0.026
A11: Alternative-Fuel Cars
A12: Ethanol-Flex Fuel ICE | B12: Fleet Vehicle Sales: Alternative-Fuel Cars: Ethanol-Flex Fuel ICE: Alternative Electricity and Transportation | C12: AEO.2026.ELECTRNP.ECI_SAL_ALF1_FLC_EFFI_NA_NA_TH.A | D12: thousands | E12: 0 | F12: 0 | G12: 0 | H12: 0 | I12: 0 | J12: 0 | K12: 0 | L12: 0 | M12: 0 | N12: 0 | O12: 0 | P12: 0 | Q12: 0 | R12: 0 | S12: 0 | T12: 0 | U12: 0 | V12: 0 | W12: 0 | X12: 0 | Y12: 0 | Z12: 0 | AA12: 0 | AB12: 0 | AC12: 0 | AD12: 0 | AE12: - -
A13: 100-Mile Electric Vehicle | B13: Fleet Vehicle Sales: Alternative-Fuel Cars: 100-Mile Electric Vehicle: Alternative Electricity and Transportation | C13: AEO.2026.ELECTRNP.ECI_SAL_ALF1_FLC_100MIEV_NA_NA_TH.A | D13: thousands | E13: 2.206993 | F13: 1.606914 | G13: 1.736317 | H13: 1.700917 | I13: 1.723562 | J13: 1.962003 | K13: 2.042335 | L13: 2.218868 | M13: 2.376864 | N13: 2.52936 | O13: 2.693957 | P13: 2.791865 | Q13: 2.91197 | R13: 3.033377 | S13: 3.137336 | T13: 3.230299 | U13: 3.278135 | V13: 3.333602 | W13: 3.382076 | X13: 3.413587 | Y13: 3.481877 | Z13: 3.49565 | AA13: 3.547434 | AB13: 3.578463 | AC13: 3.593718 | AD13: 3.582147 | AE13: 0.02
A14: 200-Mile Electric Vehicle | B14: Fleet Vehicle Sales: Alternative-Fuel Cars: 200-Mile Electric Vehicle: Alternative Electricity and Transportation | C14: AEO.2026.ELECTRNP.ECI_SAL_ALF1_FLC_200MIEV_NA_NA_TH.A | D14: thousands | E14: 11.116908 | F14: 18.056486 | G14: 27.353477 | H14: 27.236639 | I14: 26.829969 | J14: 23.219538 | K14: 23.897659 | L14: 23.307835 | M14: 25.566116 | N14: 27.35363 | O14: 29.537977 | P14: 30.553305 | Q14: 32.302368 | R14: 33.748753 | S14: 34.955544 | T14: 35.629601 | U14: 36.613506 | V14: 37.451954 | W14: 38.109138 | X14: 38.691471 | Y14: 38.999683 | Z14: 39.68388 | AA14: 40.41082 | AB14: 40.720421 | AC14: 41.141041 | AD14: 41.111855 | AE14: 0.054
A15: 300-Mile Electric Vehicle | B15: Fleet Vehicle Sales: Alternative-Fuel Cars: 300-Mile Electric Vehicle: Alternative Electricity and Transportation | C15: AEO.2026.ELECTRNP.ECI_SAL_ALF1_FLC_300MIEV_NA_NA_TH.A | D15: thousands | E15: 96.054329 | F15: 90.126595 | G15: 102.83265 | H15: 100.90676 | I15: 121.4275 | J15: 132.38582 | K15: 146.47841 | L15: 156.11507 | M15: 168.88031 | N15: 177.80548 | O15: 189.09126 | P15: 194.10586 | Q15: 202.39836 | R15: 209.87733 | S15: 216.15157 | T15: 220.77983 | U15: 224.53557 | V15: 228.19815 | W15: 230.88274 | X15: 233.22369 | Y15: 236.1741 | Z15: 237.93591 | AA15: 241.45105 | AB15: 242.95039 | AC15: 244.44386 | AD15: 243.58099 | AE15: 0.038
A16: Plug-in 20 Gasoline Hybrid | B16: Fleet Vehicle Sales: Alternative-Fuel Cars: Plug-in 20 Gasoline Hybrid: Alternative Electricity and Transportation | C16: AEO.2026.ELECTRNP.ECI_SAL_ALF1_FLC_PI20GH_NA_NA_TH.A | D16: thousands | E16: 4.26343 | F16: 3.861525 | G16: 4.148829 | H16: 4.075779 | I16: 4.029793 | J16: 4.182173 | K16: 3.705255 | L16: 3.725301 | M16: 3.934903 | N16: 4.017191 | O16: 4.162245 | P16: 4.076983 | Q16: 4.104201 | R16: 4.05821 | S16: 3.996465 | T16: 3.856699 | U16: 3.781538 | V16: 3.694863 | W16: 3.602088 | X16: 3.496382 | Y16: 3.362428 | Z16: 3.30533 | AA16: 3.241091 | AB16: 3.160586 | AC16: 3.085132 | AD16: 2.995053 | AE16: -0.014
A17: Plug-in 50 Gasoline Hybrid | B17: Fleet Vehicle Sales: Alternative-Fuel Cars: Plug-in 50 Gasoline Hybrid: Alternative Electricity and Transportation | C17: AEO.2026.ELECTRNP.ECI_SAL_ALF1_FLC_PI50GH_NA_NA_TH.A | D17: thousands | E17: 3.723038 | F17: 7.36446 | G17: 12.089196 | H17: 12.113542 | I17: 6.245296 | J17: 4.512235 | K17: 3.883534 | L17: 3.104065 | M17: 3.453829 | N17: 3.696776 | O17: 4.049677 | P17: 4.183536 | Q17: 4.384931 | R17: 4.566596 | S17: 4.73197 | T17: 4.846192 | U17: 4.873715 | V17: 4.918883 | W17: 4.940303 | X17: 4.931192 | Y17: 4.980022 | Z17: 4.92065 | AA17: 4.949115 | AB17: 4.916635 | AC17: 4.904805 | AD17: 4.832694 | AE17: 0.01
A18: Electric-Gasoline Hybrid | B18: Fleet Vehicle Sales: Alternative-Fuel Cars: Electric-Gasoline Hybrid: Alternative Electricity and Transportation | C18: AEO.2026.ELECTRNP.ECI_SAL_ALF1_FLC_EGH_NA_NA_TH.A | D18: thousands | E18: 66.824852 | F18: 75.54911 | G18: 82.896721 | H18: 83.659462 | I18: 83.83902 | J18: 88.014381 | K18: 91.698105 | L18: 93.357445 | M18: 97.07724 | N18: 98.67495 | O18: 100.41347 | P18: 99.80909 | Q18: 100.74165 | R18: 101.40453 | S18: 101.69147 | T18: 101.77615 | U18: 101.70591 | V18: 101.65527 | W18: 101.35596 | X18: 101.22368 | Y18: 101.48513 | Z18: 101.54466 | AA18: 102.25279 | AB18: 102.36383 | AC18: 102.40939 | AD18: 101.73265 | AE18: 0.017
A19: Natural Gas ICE | B19: Fleet Vehicle Sales: Alternative-Fuel Cars: Natural Gas ICE: Alternative Electricity and Transportation | C19: AEO.2026.ELECTRNP.ECI_SAL_ALF1_FLC_NGI_NA_NA_TH.A | D19: thousands | E19: 0 | F19: 0 | G19: 0 | H19: 0 | I19: 0 | J19: 0 | K19: 0 | L19: 0 | M19: 0 | N19: 0 | O19: 0 | P19: 0 | Q19: 0 | R19: 0 | S19: 0 | T19: 0 | U19: 0 | V19: 0 | W19: 0 | X19: 0 | Y19: 0 | Z19: 0 | AA19: 0 | AB19: 0 | AC19: 0 | AD19: 0 | AE19: - -
A20: Natural Gas Bi-fuel | B20: Fleet Vehicle Sales: Alternative-Fuel Cars: Natural Gas Bi-fuel: Alternative Electricity and Transportation | C20: AEO.2026.ELECTRNP.ECI_SAL_ALF1_FLC_NBF_NA_NA_TH.A | D20: thousands | E20: 0 | F20: 0 | G20: 0 | H20: 0 | I20: 0 | J20: 0 | K20: 0 | L20: 0 | M20: 0 | N20: 0 | O20: 0 | P20: 0 | Q20: 0 | R20: 0 | S20: 0 | T20: 0 | U20: 0 | V20: 0 | W20: 0 | X20: 0 | Y20: 0 | Z20: 0 | AA20: 0 | AB20: 0 | AC20: 0 | AD20: 0 | AE20: - -
A21: Propane ICE | B21: Fleet Vehicle Sales: Alternative-Fuel Cars: Propane ICE: Alternative Electricity and Transportation | C21: AEO.2026.ELECTRNP.ECI_SAL_ALF1_FLC_PROP_NA_NA_TH.A | D21: thousands | E21: 0 | F21: 0 | G21: 0 | H21: 0 | I21: 0 | J21: 0 | K21: 0 | L21: 0 | M21: 0 | N21: 0 | O21: 0 | P21: 0 | Q21: 0 | R21: 0 | S21: 0 | T21: 0 | U21: 0 | V21: 0 | W21: 0 | X21: 0 | Y21: 0 | Z21: 0 | AA21: 0 | AB21: 0 | AC21: 0 | AD21: 0 | AE21: - -
A22: Propane Bi-fuel | B22: Fleet Vehicle Sales: Alternative-Fuel Cars: Propane Bi-fuel: Alternative Electricity and Transportation | C22: AEO.2026.ELECTRNP.ECI_SAL_ALF1_FLC_PBF_NA_NA_TH.A | D22: thousands | E22: 0 | F22: 0 | G22: 0 | H22: 0 | I22: 0 | J22: 0 | K22: 0 | L22: 0 | M22: 0 | N22: 0 | O22: 0 | P22: 0 | Q22: 0 | R22: 0 | S22: 0 | T22: 0 | U22: 0 | V22: 0 | W22: 0 | X22: 0 | Y22: 0 | Z22: 0 | AA22: 0 | AB22: 0 | AC22: 0 | AD22: 0 | AE22: - -
A23: Fuel Cell Hydrogen | B23: Fleet Vehicle Sales: Alternative-Fuel cars: Fuel Cell Hydrogen: Alternative Electricity and Transportation | C23: AEO.2026.ELECTRNP.ECI_SAL_ALF1_FLC_FCH_NA_NA_TH.A | D23: thousands | E23: 0.037471 | F23: 0.013645 | G23: 0.013157 | H23: 0.009 | I23: 0.006575 | J23: 0.007138 | K23: 0.006808 | L23: 0.006451 | M23: 0.006877 | N23: 0.006139 | O23: 0.006198 | P23: 0.005658 | Q23: 0.005438 | R23: 0.005134 | S23: 0.004983 | T23: 0.004842 | U23: 0.004685 | V23: 0.004541 | W23: 0.004401 | X23: 0.004281 | Y23: 0.00419 | Z23: 0.004053 | AA23: 0.003988 | AB23: 0.003867 | AC23: 0.003787 | AD23: 0.003661 | AE23: -0.089
A24: Total Alternative Cars | B24: Fleet Vehicle Sales: Alternative-Fuel Cars: Total: Alternative Electricity and Transportation | C24: AEO.2026.ELECTRNP.ECI_SAL_ALF1_FLC_NA_NA_NA_TH.A | D24: thousands | E24: 184.22702 | F24: 196.57873 | G24: 231.07034 | H24: 229.70212 | I24: 244.10173 | J24: 254.2833 | K24: 271.7121 | L24: 281.83502 | M24: 301.29611 | N24: 314.08353 | O24: 329.9548 | P24: 335.52628 | Q24: 346.84891 | R24: 356.69391 | S24: 364.66934 | T24: 370.12363 | U24: 374.79309 | V24: 379.25726 | W24: 382.2767 | X24: 384.98428 | Y24: 388.48743 | Z24: 390.89014 | AA24: 395.85629 | AB24: 397.69418 | AC24: 399.58173 | AD24: 397.83905 | AE24: 0.031
A25: Percentage Alternative Car Sales | B25: Fleet Vehicle Sales: Percentage Alternative Car: Alternative Electricity and Transportation | C25: AEO.2026.ELECTRNP.ECI_SAL_ALF1_FLC_NA_NA_NA_PCT.A | D25: percent | E25: 20.495468 | F25: 23.622351 | G25: 28.165558 | H25: 28.721529 | I25: 30.148476 | J25: 30.765999 | K25: 32.454758 | L25: 33.497448 | M25: 35.120277 | N25: 36.530472 | O25: 38.110863 | P25: 39.379723 | Q25: 40.632656 | R25: 41.836529 | S25: 42.970036 | T25: 43.939327 | U25: 44.928432 | V25: 45.889359 | W25: 46.787708 | X25: 47.60841 | Y25: 48.376598 | Z25: 49.143307 | AA25: 49.919334 | AB25: 50.635002 | AC25: 51.335812 | AD25: 51.986713 | AE25: 0.038
A26: Total New Car Sales | B26: Fleet Vehicle Sales: Total New Car: Alternative Electricity and Transportation | C26: AEO.2026.ELECTRNP.ECI_SAL_NA_FLC_NA_NA_NA_TH.A | D26: thousands | E26: 898.86707 | F26: 832.17261 | G26: 820.40039 | H26: 799.75586 | I26: 809.66522 | J26: 826.50757 | K26: 837.20264 | L26: 841.36261 | M26: 857.89795 | N26: 859.78503 | O26: 865.77625 | P26: 852.02808 | Q26: 853.62103 | R26: 852.58966 | S26: 848.65967 | T26: 842.35156 | U26: 834.20026 | V26: 826.4602 | W26: 817.04517 | X26: 808.64764 | Y26: 803.04822 | Z26: 795.40869 | AA26: 792.99194 | AB26: 785.41351 | AC26: 778.36841 | AD26: 765.27063 | AE26: -0.006
A27: New Light Truck Sales
A28: Conventional Light Trucks
A29: Gasoline ICE Vehicles | B29: Fleet Vehicle Sales: Conventional Light Trucks: Gasoline: Alternative Electricity and Transportation | C29: AEO.2026.ELECTRNP.ECI_SAL_CNV_FLTR_GSL_NA_NA_TH.A | D29: thousands | E29: 1437.173 | F29: 1280.6257 | G29: 1267.8079 | H29: 1227.0704 | I29: 1292.2639 | J29: 1355.6544 | K29: 1409.1293 | L29: 1440.6362 | M29: 1422.0645 | N29: 1402.7307 | O29: 1376.9635 | P29: 1336.5696 | Q29: 1314.984 | R29: 1293.8232 | S29: 1258.4368 | T29: 1238.3679 | U29: 1214.6133 | V29: 1189.9836 | W29: 1170.0724 | X29: 1151.5096 | Y29: 1133.5857 | Z29: 1116.7258 | AA29: 1097.0377 | AB29: 1077.1228 | AC29: 1054.2616 | AD29: 1028.1942 | AE29: -0.013
A30: TDI Diesel ICE | B30: Fleet Vehicle Sales: Conventional Light Trucks: TDI Diesel: Alternative Electricity and Transportation | C30: AEO.2026.ELECTRNP.ECI_SAL_CNV_FLTR_TDS_NA_NA_TH.A | D30: thousands | E30: 21.510231 | F30: 22.414324 | G30: 22.295994 | H30: 22.462799 | I30: 22.7118 | J30: 23.527294 | K30: 23.790461 | L30: 24.008343 | M30: 24.06229 | N30: 24.345695 | O30: 24.239101 | P30: 23.786434 | Q30: 23.735018 | R30: 23.701374 | S30: 23.534876 | T30: 23.222321 | U30: 23.034515 | V30: 22.8575 | W30: 22.660404 | X30: 22.448957 | Y30: 22.106741 | Z30: 22.052914 | AA30: 21.828384 | AB30: 21.665068 | AC30: 21.316776 | AD30: 20.988546 | AE30: -0.001
A31: Total Conventional Light Trucks | B31: Fleet Vehicle Sales: Conventional Light Trucks: Total: Alternative Electricity and Transportation | C31: AEO.2026.ELECTRNP.ECI_SAL_CNV_FLTR_NA_NA_NA_TH.A | D31: thousands | E31: 1458.6832 | F31: 1303.04 | G31: 1290.1039 | H31: 1249.5332 | I31: 1314.9757 | J31: 1379.1818 | K31: 1432.9197 | L31: 1464.6445 | M31: 1446.1267 | N31: 1427.0764 | O31: 1401.2026 | P31: 1360.356 | Q31: 1338.719 | R31: 1317.5247 | S31: 1281.9717 | T31: 1261.5902 | U31: 1237.6478 | V31: 1212.8412 | W31: 1192.7328 | X31: 1173.9586 | Y31: 1155.6924 | Z31: 1138.7787 | AA31: 1118.8661 | AB31: 1098.7878 | AC31: 1075.5784 | AD31: 1049.1827 | AE31: -0.013
A32: Alternative-Fuel Light Trucks
A33: Ethanol-Flex Fuel ICE | B33: Fleet Vehicle Sales: Alternative-Fuel Light Trucks: Ethanol-Flex Fuel ICE: Alternative Electricity and Transportation | C33: AEO.2026.ELECTRNP.ECI_SAL_ALF1_FLTR_EFFI_NA_NA_TH.A | D33: thousands | E33: 0.372822 | F33: 0.372309 | G33: 0.391655 | H33: 0.395681 | I33: 0.408074 | J33: 0.423958 | K33: 0.43165 | L33: 0.437611 | M33: 0.438934 | N33: 0.442066 | O33: 0.441668 | P33: 0.437692 | Q33: 0.436797 | R33: 0.43691 | S33: 0.43595 | T33: 0.434601 | U33: 0.431886 | V33: 0.428321 | W33: 0.426536 | X33: 0.424182 | Y33: 0.421887 | Z33: 0.420009 | AA33: 0.415897 | AB33: 0.412711 | AC33: 0.406969 | AD33: 0.400532 | AE33: 0.003
A34: 100-Mile Electric Vehicle | B34: Fleet Vehicle Sales: Alternative-Fuel Light Trucks: 100-Mile Electric Vehicle: Alternative Electricity and Transportation | C34: AEO.2026.ELECTRNP.ECI_SAL_ALF1_FLTR_100MIEV_NA_NA_TH.A | D34: thousands | E34: 0.438531 | F34: 0.307967 | G34: 0.356011 | H34: 0.376499 | I34: 0.402728 | J34: 0.470826 | K34: 0.526172 | L34: 0.589313 | M34: 0.651888 | N34: 0.70149 | O34: 0.759006 | P34: 0.798581 | Q34: 0.845509 | R34: 0.892578 | S34: 0.940033 | T34: 0.985847 | U34: 1.017161 | V34: 1.049405 | W34: 1.0807 | X34: 1.110321 | Y34: 1.147108 | Z34: 1.165064 | AA34: 1.191065 | AB34: 1.208701 | AC34: 1.224608 | AD34: 1.228536 | AE34: 0.042
A35: 200-Mile Electric Vehicle | B35: Fleet Vehicle Sales: Alternative-Fuel Light Trucks: 200-Mile Electric Vehicle: Alternative Electricity and Transportation | C35: AEO.2026.ELECTRNP.ECI_SAL_ALF1_FLTR_200MIEV_NA_NA_TH.A | D35: thousands | E35: 14.50286 | F35: 46.362995 | G35: 71.392891 | H35: 86.57637 | I35: 89.548294 | J35: 78.577286 | K35: 71.332283 | L35: 61.137123 | M35: 67.188408 | N35: 72.739761 | O35: 79.61319 | P35: 83.990189 | Q35: 89.878098 | R35: 95.494774 | S35: 99.948608 | T35: 104.95778 | U35: 108.87504 | V35: 112.86192 | W35: 116.73233 | X35: 120.47168 | Y35: 124.54692 | Z35: 127.16966 | AA35: 130.62906 | AB35: 132.75278 | AC35: 135.19066 | AD35: 136.03778 | AE35: 0.094
A36: 300-Mile Electric Vehicle | B36: Fleet Vehicle Sales: Alternative-Fuel Light Trucks: 300-Mile Electric Vehicle: Alternative Electricity and Transportation | C36: AEO.2026.ELECTRNP.ECI_SAL_ALF1_FLTR_300MIEV_NA_NA_TH.A | D36: thousands | E36: 69.390381 | F36: 98.883827 | G36: 128.46678 | H36: 153.13013 | I36: 151.60406 | J36: 154.36659 | K36: 140.18541 | L36: 144.5824 | M36: 158.72485 | N36: 170.94873 | O36: 185.01433 | P36: 193.63051 | Q36: 205.1306 | R36: 216.07722 | S36: 225.78798 | T36: 235.52168 | U36: 242.4572 | V36: 249.53416 | W36: 256.2612 | X36: 262.66656 | Y36: 270.07767 | Z36: 274.06888 | AA36: 279.84992 | AB36: 283.20371 | AC36: 286.69702 | AD36: 287.20252 | AE36: 0.058
A37: Plug-in 20 Gasoline Hybrid | B37: Fleet Vehicle Sales: Alternative-Fuel Light Trucks: Plug-in 20 Gasoline Hybrid: Alternative Electricity and Transportation | C37: AEO.2026.ELECTRNP.ECI_SAL_ALF1_FLTR_PI20GH_NA_NA_TH.A | D37: thousands | E37: 37.805 | F37: 26.940199 | G37: 29.180897 | H37: 29.918764 | I37: 29.766842 | J37: 31.682257 | K37: 34.03854 | L37: 36.009048 | M37: 39.023567 | N37: 41.944893 | O37: 45.362904 | P37: 46.736874 | Q37: 48.87421 | R37: 50.853432 | S37: 52.637215 | T37: 53.667587 | U37: 54.320786 | V37: 54.984226 | W37: 55.655186 | X37: 56.045773 | Y37: 56.453976 | Z37: 56.572586 | AA37: 56.907936 | AB37: 56.807114 | AC37: 56.826561 | AD37: 56.319984 | AE37: 0.016
A38: Plug-in 50 Gasoline Hybrid | B38: Fleet Vehicle Sales: Alternative-Fuel Light Trucks: Plug-in 50 Gasoline Hybrid: Alternative Electricity and Transportation | C38: AEO.2026.ELECTRNP.ECI_SAL_ALF1_FLTR_PI50GH_NA_NA_TH.A | D38: thousands | E38: 10.351457 | F38: 45.225361 | G38: 71.672699 | H38: 92.527695 | I38: 45.882923 | J38: 36.908356 | K38: 22.379274 | L38: 9.34068 | M38: 10.058076 | N38: 10.48983 | O38: 11.277993 | P38: 11.468544 | Q38: 11.854759 | R38: 12.145212 | S38: 12.498743 | T38: 12.771282 | U38: 12.710954 | V38: 12.699977 | W38: 12.69642 | X38: 12.664415 | Y38: 12.771111 | Z38: 12.526513 | AA38: 12.483051 | AB38: 12.270146 | AC38: 12.171361 | AD38: 11.912324 | AE38: 0.006
A39: Electric-Gasoline Hybrid | B39: Fleet Vehicle Sales: Alternative-Fuel Light Trucks: Electric-Gasoline Hybrid: Alternative Electricity and Transportation | C39: AEO.2026.ELECTRNP.ECI_SAL_ALF1_FLTR_EGH_NA_NA_TH.A | D39: thousands | E39: 231.93541 | F39: 300.65042 | G39: 321.92755 | H39: 358.1427 | I39: 381.94684 | J39: 403.00726 | K39: 416.13809 | L39: 421.31039 | M39: 429.03586 | N39: 433.79871 | O39: 438.41574 | P39: 436.38498 | Q39: 440.9809 | R39: 444.8045 | S39: 461.72449 | T39: 465.76788 | U39: 467.22736 | V39: 468.23367 | W39: 470.55792 | X39: 473.60718 | Y39: 477.20618 | Z39: 479.81244 | AA39: 482.48285 | AB39: 483.47772 | AC39: 484.22485 | AD39: 482.24207 | AE39: 0.03
A40: Natural Gas ICE | B40: Fleet Vehicle Sales: Alternative-Fuel Light Trucks: Natural Gas ICE: Alternative Electricity and Transportation | C40: AEO.2026.ELECTRNP.ECI_SAL_ALF1_FLTR_NGI_NA_NA_TH.A | D40: thousands | E40: 0 | F40: 0 | G40: 0 | H40: 0 | I40: 0 | J40: 0 | K40: 0 | L40: 0 | M40: 0 | N40: 0 | O40: 0 | P40: 0 | Q40: 0 | R40: 0 | S40: 0 | T40: 0 | U40: 0 | V40: 0 | W40: 0 | X40: 0 | Y40: 0 | Z40: 0 | AA40: 0 | AB40: 0 | AC40: 0 | AD40: 0 | AE40: - -
...

Sheet AEO 2026 Table 49
A1: Table 49. Freight Transportation Energy Use
A2: https://www.eia.gov/outlooks/aeo/data/browser/#/?id=58-AEO2026&cases=electrnp&sourcekey=0
A3: Thu Apr 23 2026 15:05:43 GMT-0700 (Pacific Daylight Time)
A4: Source: U.S. Energy Information Administration
B5: full name | C5: api key | D5: units | E5: 2025 | F5: 2026 | G5: 2027 | H5: 2028 | I5: 2029 | J5: 2030 | K5: 2031 | L5: 2032 | M5: 2033 | N5: 2034 | O5: 2035 | P5: 2036 | Q5: 2037 | R5: 2038 | S5: 2039 | T5: 2040 | U5: 2041 | V5: 2042 | W5: 2043 | X5: 2044 | Y5: 2045 | Z5: 2046 | AA5: 2047 | AB5: 2048 | AC5: 2049 | AD5: 2050 | AE5: Growth (2025-2050)
A6: Freight Truck Stock by Size Class
A7: Vehicle Miles Traveled (billion miles)
A8: Light Medium
A9: Diesel | B9: Freight: Truck Stock: Vehicle Miles Traveled: Light Medium: Diesel: Alternative Electricity and Transportation | C9: AEO.2026.ELECTRNP.ECI_VMT_FGHT_LITEMEDS_DSL_NA_NA_BLNMLS.A | D9: billion miles | E9: 58.413017 | F9: 57.420311 | G9: 56.362801 | H9: 55.456158 | I9: 54.686531 | J9: 54.216652 | K9: 53.628971 | L9: 53.071381 | M9: 52.386211 | N9: 51.729412 | O9: 50.979725 | P9: 50.103706 | Q9: 49.202808 | R9: 48.319229 | S9: 47.434059 | T9: 46.587254 | U9: 45.608746 | V9: 44.484791 | W9: 43.169189 | X9: 41.718536 | Y9: 40.212212 | Z9: 38.761288 | AA9: 37.372833 | AB9: 35.951756 | AC9: 34.608257 | AD9: 33.299496 | AE9: -0.022
A10: Motor Gasoline | B10: Freight: Truck Stock: Vehicle Miles Traveled: Light Medium: Motor Gasoline: Alternative Electricity and Transportation | C10: AEO.2026.ELECTRNP.ECI_VMT_FGHT_LITEMEDS_MGS_NA_NA_BLNMLS.A | D10: billion miles | E10: 27.328077 | F10: 28.272638 | G10: 29.206049 | H10: 30.198536 | I10: 31.257954 | J10: 32.472885 | K10: 33.565792 | L10: 34.62991 | M10: 35.530155 | N10: 36.361717 | O10: 37.028927 | P10: 37.488136 | Q10: 37.843647 | R10: 38.147228 | S10: 38.407978 | T10: 38.634766 | U10: 38.685001 | V10: 38.508476 | W10: 38.076015 | X10: 37.432987 | Y10: 36.696804 | Z10: 35.933998 | AA10: 35.163811 | AB10: 34.305832 | AC10: 33.493919 | AD10: 32.678135 | AE10: 0.007
A11: Propane | B11: Freight: Truck Stock: Vehicle Miles Traveled: Light Medium: Propane: Alternative Electricity and Transportation | C11: AEO.2026.ELECTRNP.ECI_VMT_FGHT_LITEMEDS_PROP_NA_NA_BLNMLS.A | D11: billion miles | E11: 0.000624 | F11: 0.000625 | G11: 0.000632 | H11: 0.000652 | I11: 0.000673 | J11: 0.000696 | K11: 0.000721 | L11: 0.000747 | M11: 0.000747 | N11: 0.00074 | O11: 0.000747 | P11: 0.000764 | Q11: 0.000788 | R11: 0.000817 | S11: 0.000849 | T11: 0.000884 | U11: 0.000918 | V11: 0.000951 | W11: 0.000982 | X11: 0.001012 | Y11: 0.001043 | Z11: 0.001075 | AA11: 0.001107 | AB11: 0.001138 | AC11: 0.001168 | AD11: 0.001194 | AE11: 0.026
A12: Compressed/Liquefied Natural Gas | B12: Freight: Truck Stock: Vehicle Miles Traveled: Light Medium: Natural Gas: Alternative Electricity and Transportation | C12: AEO.2026.ELECTRNP.ECI_VMT_FGHT_LITEMEDS_NG_NA_NA_BLNMLS.A | D12: billion miles | E12: 0.1018 | F12: 0.14121 | G12: 0.143647 | H12: 0.138923 | I12: 0.134816 | J12: 0.132154 | K12: 0.130291 | L12: 0.130465 | M12: 0.131806 | N12: 0.134191 | O12: 0.138595 | P12: 0.14476 | Q12: 0.157973 | R12: 0.173051 | S12: 0.190677 | T12: 0.217789 | U12: 0.252384 | V12: 0.300604 | W12: 0.35725 | X12: 0.422417 | Y12: 0.500916 | Z12: 0.582305 | AA12: 0.680468 | AB12: 0.791074 | AC12: 0.906443 | AD12: 1.041519 | AE12: 0.097
A13: Ethanol-Flex Fuel | B13: Freight: Truck Stock: Vehicle Miles Traveled: Light Medium: Ethanol-Flex Fuel: Alternative Electricity and Transportation | C13: AEO.2026.ELECTRNP.ECI_VMT_FGHT_LITEMEDS_EFFI_NA_NA_BLNMLS.A | D13: billion miles | E13: 2.734304 | F13: 2.478483 | G13: 2.234351 | H13: 2.013251 | I13: 1.81403 | J13: 1.636645 | K13: 1.472175 | L13: 1.323703 | M13: 1.187042 | N13: 1.067449 | O13: 0.958435 | P13: 0.85986 | Q13: 0.76879 | R13: 0.688141 | S13: 0.613102 | T13: 0.547159 | U13: 0.490353 | V13: 0.43976 | W13: 0.395778 | X13: 0.353755 | Y13: 0.311554 | Z13: 0.272084 | AA13: 0.236563 | AB13: 0.199415 | AC13: 0.163905 | AD13: 0.130143 | AE13: -0.115
A14: Electric | B14: Freight: Truck Stock: Vehicle Miles Traveled: Light Medium: Electric: Alternative Electricity and Transportation | C14: AEO.2026.ELECTRNP.ECI_VMT_FGHT_LITEMEDS_ELE_NA_NA_BLNMLS.A | D14: billion miles | E14: 0.201876 | F14: 0.235023 | G14: 0.265451 | H14: 0.293527 | I14: 0.321031 | J14: 0.349323 | K14: 0.375645 | L14: 0.401731 | M14: 0.426124 | N14: 0.450529 | O14: 0.473888 | P14: 0.496025 | Q14: 0.517966 | R14: 0.540045 | S14: 0.561847 | T14: 0.659889 | U14: 0.976502 | V14: 1.636871 | W14: 2.631784 | X14: 4.008795 | Y14: 5.728106 | Z14: 7.605267 | AA14: 9.642061 | AB14: 11.816639 | AC14: 14.05707 | AD14: 16.278847 | AE14: 0.192
A15: Plug-in Diesel Hybrid | B15: Freight: Truck Stock: Vehicle Miles Traveled: Light Medium: Plug-in Diesel Hybrid: Alternative Electricity and Transportation | C15: AEO.2026.ELECTRNP.ECI_VMT_FGHT_LITEMEDS_EDH_NA_NA_BLNMLS.A | D15: billion miles | E15: 0 | F15: 0 | G15: 0 | H15: 0 | I15: 0 | J15: 0 | K15: 0 | L15: 0 | M15: 0 | N15: 0 | O15: 0 | P15: 0 | Q15: 0 | R15: 0 | S15: 0 | T15: 0 | U15: 0 | V15: 0 | W15: 0 | X15: 0 | Y15: 0 | Z15: 0 | AA15: 0 | AB15: 0 | AC15: 0 | AD15: 0 | AE15: - -
A16: Plug-in Gasoline Hybrid | B16: Freight: Truck Stock: Vehicle Miles Traveled: Light Medium: Plug-in Gasoline Hybrid: Alternative Electricity and Transportation | C16: AEO.2026.ELECTRNP.ECI_VMT_FGHT_LITEMEDS_EGH_NA_NA_BLNMLS.A | D16: billion miles | E16: 0 | F16: 0 | G16: 0 | H16: 0 | I16: 0 | J16: 0 | K16: 0 | L16: 0 | M16: 0 | N16: 0 | O16: 0 | P16: 0 | Q16: 0 | R16: 0 | S16: 0 | T16: 0 | U16: 0 | V16: 0 | W16: 0 | X16: 0 | Y16: 0 | Z16: 0 | AA16: 0 | AB16: 0 | AC16: 0 | AD16: 0 | AE16: - -
A17: Fuel Cell | B17: Freight: Truck Stock: Vehicle Miles Traveled: Light Medium: Fuel Cell: Alternative Electricity and Transportation | C17: AEO.2026.ELECTRNP.ECI_VMT_FGHT_LITEMEDS_FUC_NA_NA_BLNMLS.A | D17: billion miles | E17: 0 | F17: 0 | G17: 0 | H17: 0 | I17: 0 | J17: 0 | K17: 0 | L17: 0 | M17: 0 | N17: 0 | O17: 0 | P17: 0 | Q17: 0 | R17: 0 | S17: 0 | T17: 0 | U17: 0 | V17: 0 | W17: 0 | X17: 0 | Y17: 0 | Z17: 0 | AA17: 0 | AB17: 0 | AC17: 0 | AD17: 0 | AE17: - -
A18: Fuel Cell Battery Dominant | B18: Freight: Truck Stock: Vehicle Miles Traveled: Light Medium: Fuel Cell Battery Dominant: Alternative Electricity and Transportation | C18: AEO.2026.ELECTRNP.ECI_VMT_FGHT_LITEMEDS_FEUCELBATDOM_NA_NA_BLNMLS.A | D18: billion miles | E18: 0 | F18: 0 | G18: 0 | H18: 0 | I18: 0 | J18: 0 | K18: 0 | L18: 0 | M18: 0 | N18: 0 | O18: 0 | P18: 0 | Q18: 0 | R18: 0 | S18: 0 | T18: 0 | U18: 0 | V18: 0 | W18: 0 | X18: 0 | Y18: 0 | Z18: 0 | AA18: 0 | AB18: 0 | AC18: 0 | AD18: 0 | AE18: - -
A19: Gasoline Hybrid | B19: Freight: Truck Stock: Vehicle Miles Traveled: Light Medium: Gasoline Hybrid: Alternative Electricity and Transportation | C19: AEO.2026.ELECTRNP.ECI_VMT_FGHT_LITEMEDS_GASHEV_NA_NA_BLNMLS.A | D19: billion miles | E19: 0.097703 | F19: 0.263975 | G19: 0.48311 | H19: 0.75416 | I19: 1.100802 | J19: 1.58399 | K19: 2.203856 | L19: 2.995292 | M19: 4.011751 | N19: 5.298637 | O19: 6.892163 | P19: 8.837455 | Q19: 11.058461 | R19: 13.483864 | S19: 16.040926 | T19: 18.654707 | U19: 21.234295 | V19: 23.733828 | W19: 26.101175 | X19: 28.37425 | Y19: 30.614744 | Z19: 32.802284 | AA19: 34.960983 | AB19: 37.017426 | AC19: 38.97467 | AD19: 40.763081 | AE19: 0.273
A20: Hydrogen ICE | B20: Freight: Truck Stock: Vehicle Miles Traveled: Light Medium: Hydrogen ICE: Alternative Electricity and Transportation | C20: AEO.2026.ELECTRNP.ECI_VMT_FGHT_LITEMEDS_HYDICE_NA_NA_BLNMLS.A | D20: billion miles | E20: 0 | F20: 0 | G20: 0 | H20: 0 | I20: 0 | J20: 0 | K20: 0 | L20: 0 | M20: 0 | N20: 0 | O20: 0 | P20: 0 | Q20: 0 | R20: 0 | S20: 0 | T20: 0 | U20: 0 | V20: 0 | W20: 0 | X20: 0 | Y20: 0 | Z20: 0 | AA20: 0 | AB20: 0 | AC20: 0 | AD20: 0 | AE20: - -
A21: Light Medium Subtotal | B21: Freight: Truck Stock: Vehicle Miles Traveled: Light Medium: Alternative Electricity and Transportation | C21: AEO.2026.ELECTRNP.ECI_VMT_FGHT_LITEMEDS_NA_NA_NA_BLNMLS.A | D21: billion miles | E21: 88.87738 | F21: 88.81218 | G21: 88.69593 | H21: 88.855186 | I21: 89.315735 | J21: 90.392151 | K21: 91.377357 | L21: 92.553032 | M21: 93.673729 | N21: 95.042549 | O21: 96.472305 | P21: 97.930557 | Q21: 99.550018 | R21: 101.35216 | S21: 103.24905 | T21: 105.30214 | U21: 107.24771 | V21: 109.10486 | W21: 110.73187 | X21: 112.31132 | Y21: 114.06494 | Z21: 115.95789 | AA21: 118.0573 | AB21: 120.08257 | AC21: 122.2047 | AD21: 124.19183 | AE21: 0.013
A22: Medium
A23: Diesel | B23: Freight: Truck Stock: Vehicle Miles Traveled: Medium: Diesel: Alternative Electricity and Transportation | C23: AEO.2026.ELECTRNP.ECI_VMT_FGHT_SOSOS_DSL_NA_NA_BLNMLS.A | D23: billion miles | E23: 35.473877 | F23: 34.636177 | G23: 33.951637 | H23: 33.342804 | I23: 32.749153 | J23: 32.298199 | K23: 31.77066 | L23: 31.311335 | M23: 30.799314 | N23: 30.333715 | O23: 29.880741 | P23: 29.443609 | Q23: 29.022797 | R23: 28.609694 | S23: 28.222281 | T23: 27.871525 | U23: 27.527695 | V23: 27.212862 | W23: 26.924488 | X23: 26.683699 | Y23: 26.514278 | Z23: 26.380215 | AA23: 26.283073 | AB23: 26.17104 | AC23: 26.08226 | AD23: 25.990124 | AE23: -0.012
A24: Motor Gasoline | B24: Freight: Truck Stock: Vehicle Miles Traveled: Medium: Motor Gasoline: Alternative Electricity and Transportation | C24: AEO.2026.ELECTRNP.ECI_VMT_FGHT_SOSOS_MGS_NA_NA_BLNMLS.A | D24: billion miles | E24: 22.472101 | F24: 22.273155 | G24: 22.199646 | H24: 22.199471 | I24: 22.203886 | J24: 22.291555 | K24: 22.325485 | L24: 22.409365 | M24: 22.439425 | N24: 22.504622 | O24: 22.556879 | P24: 22.584263 | Q24: 22.614752 | R24: 22.633869 | S24: 22.65753 | T24: 22.692263 | U24: 22.726048 | V24: 22.763575 | W24: 22.784922 | X24: 22.818722 | Y24: 22.893072 | Z24: 22.978222 | AA24: 23.073374 | AB24: 23.140879 | AC24: 23.219425 | AD24: 23.281679 | AE24: 0.001
A25: Propane | B25: Freight: Truck Stock: Vehicle Miles Traveled: Medium: Propane: Alternative Electricity and Transportation | C25: AEO.2026.ELECTRNP.ECI_VMT_FGHT_SOSOS_PROP_NA_NA_BLNMLS.A | D25: billion miles | E25: 0.021876 | F25: 0.019477 | G25: 0.017259 | H25: 0.015325 | I25: 0.012689 | J25: 0.011285 | K25: 0.009969 | L25: 0.008869 | M25: 0.007902 | N25: 0.006905 | O25: 0.006157 | P25: 0.005567 | Q25: 0.005097 | R25: 0.004691 | S25: 0.004345 | T25: 0.004065 | U25: 0.003807 | V25: 0.003581 | W25: 0.003376 | X25: 0.003178 | Y25: 0.003057 | Z25: 0.002919 | AA25: 0.002794 | AB25: 0.002472 | AC25: 0.00196 | AD25: 0.001558 | AE25: -0.1
