Workbook

Sheet About
A1: RZSPbS BAU Required ZEV Sales Percentage by Subregion
A3: Sources: | B3: State Passenger LDV Requirements
B4: California Air Resources Board
B5: 2022
B6: Final Regulation Order, Section 1962.4, Title 13, California Code of Regulations
B7: https://ww2.arb.ca.gov/sites/default/files/barcu/regact/2022/accii/acciifro1962.4.pdf
B8: Page 4
B10: Which States Follow ACC I Standards?
B11: California Air Resources Board + state regs
B12: 2019-2022
B13: 177 States
B14: https://ww2.arb.ca.gov/sites/default/files/2019-03/177-states.pdf
B15: https://ecology.wa.gov/Regulations-Permits/Laws-rules-rulemaking/Rulemaking/WAC-173-423-400
B16: https://ndep.nv.gov/uploads/air-ccn-docs/clean_cars_nv_reg.pdf
B17: https://cloud.env.nm.gov/air/resources/_translator.php/NoP4Wd1EyorPC~sl~BWz~sl~H2+PXdCQEKefUZ7Ou8Vgq~sl~x2ZYzqa1zexRjaNVbxGMCgU8AVirLkjjLdev8vysjOadSflGgbBfGQtLEpGCtN+kDVh1YPy2q5u9L4gGZ4Ls+vKK.pdf
B18: https://lis.virginia.gov/cgi-bin/legp604.exe?212+ful+HB1965ER
A20: Notes
A21: This variable expresses the percentage of vehicles sold in each subregion that must be
A22: ZEVs in each year (i.e., due to a mandate or binding target implemented in legislation).
A23: It should not cover any requirements outside the subregional geography (for the whole model region).
A24: I.e. the US national model should not cover federal requirements here, only state requirements.
A25: The model will allow more ZEVs than this to be sold if economic factors would favor
A26: a higher level of ZEV deployment. This variable should only contain the legislative
A27: required ZEV shares, not projected or expected ZEV shares based on economics,
A28: ZEV subsidies, or other such factors.
A30: Although manufacturers often begin selling new models before the calendar year begins, the
A31: EPS can't impose a ZEV standard for part of a year. Therefore, we assume sales year = model year.
A33: U.S. Data
A34: This variable implements ACCI for states that have formally adopted these rules.

Sheet CA Standards and Followers
B1: 2020 | C1: 2021 | D1: 2022 | E1: 2023 | F1: 2024 | G1: 2025 | H1: 2026 | I1: 2027 | J1: 2028 | K1: 2029 | L1: 2030 | M1: 2031 | N1: 2032 | O1: 2033 | P1: 2034 | Q1: 2035 | R1: 2036 | S1: 2037 | T1: 2038 | U1: 2039 | V1: 2040 | W1: 2041 | X1: 2042 | Y1: 2043 | Z1: 2044 | AA1: 2045 | AB1: 2046 | AC1: 2047 | AD1: 2048 | AE1: 2049 | AF1: 2050
A2: passenger LDVs ACC I | B2: 0 | C2: 0 | D2: 0 | E2: 0 | F2: 0.08 | G2: 0.08 | H2: 0 | I2: 0 | J2: 0 | K2: 0 | L2: 0 | M2: 0 | N2: 0 | O2: 0 | P2: 0 | Q2: 0 | R2: 0 | S2: 0 | T2: 0 | U2: 0 | V2: 0 | W2: 0 | X2: 0 | Y2: 0 | Z2: 0 | AA2: 0 | AB2: 0 | AC2: 0 | AD2: 0 | AE2: 0 | AF2: 0
C4: gray = no longer used
A5: use '1' to indicate that the state follows the rule | B5: Calibration Values for EPA LDV Stds Applied? | C5: Calibration Values for EPA HDV Stds Applied? | D5: Does this state follow: | G5: What model year does this state begin regulating:
D6: ACC I | E6: ACC II | F6: ACT | G6: ACC I Cars | H6: ACC II Cars | I6: Trucks
A7: Alabama | B7: =IF(E7>0,0,1) -> 1 | C7: =IF(F7=0,1) -> 1 | D7: 0 | E7: 0 | F7: 0
A8: Alaska | B8: =IF(E8>0,0,1) -> 1 | C8: =IF(F8=0,1) -> 1 | D8: 0 | E8: 0 | F8: 0
A9: Arizona | B9: =IF(E9>0,0,1) -> 1 | C9: =IF(F9=0,1) -> 1 | D9: 0 | E9: 0 | F9: 0
A10: Arkansas | B10: =IF(E10>0,0,1) -> 1 | C10: =IF(F10=0,1) -> 1 | D10: 0 | E10: 0 | F10: 0
A11: California | B11: =IF(E11>0,0,1) -> 1 | C11: =IF(F11=0,1) -> 1 | D11: 1 | E11: 0 | F11: 0 | G11: 1990 | H11: 2026 | I11: 2024
A12: Colorado | B12: =IF(E12>0,0,1) -> 1 | C12: =IF(F12=0,1) -> 1 | D12: 1 | E12: 0 | F12: 0 | G12: 2023 | H12: 2026 | I12: 2027
A13: Connecticut | B13: =IF(E13>0,0,1) -> 1 | C13: =IF(F13=0,1) -> 1 | D13: 1 | E13: 0 | F13: 0 | G13: 2008
A14: Delaware | B14: =IF(E14>0,0,1) -> 1 | C14: =IF(F14=0,1) -> 1 | D14: 0 | E14: 0 | F14: 0 | H14: 2026
A15: District of Columbia | B15: =IF(E15>0,0,1) -> 1 | C15: =IF(F15=0,1) -> 1 | D15: 0 | E15: 0 | F15: 0 | H15: 2026
A16: Florida | B16: =IF(E16>0,0,1) -> 1 | C16: =IF(F16=0,1) -> 1 | D16: 0 | E16: 0 | F16: 0
A17: Georgia | B17: =IF(E17>0,0,1) -> 1 | C17: =IF(F17=0,1) -> 1 | D17: 0 | E17: 0 | F17: 0
A18: Hawaii | B18: =IF(E18>0,0,1) -> 1 | C18: =IF(F18=0,1) -> 1 | D18: 0 | E18: 0 | F18: 0
A19: Idaho | B19: =IF(E19>0,0,1) -> 1 | C19: =IF(F19=0,1) -> 1 | D19: 0 | E19: 0 | F19: 0
A20: Illinois | B20: =IF(E20>0,0,1) -> 1 | C20: =IF(F20=0,1) -> 1 | D20: 0 | E20: 0 | F20: 0
A21: Indiana | B21: =IF(E21>0,0,1) -> 1 | C21: =IF(F21=0,1) -> 1 | D21: 0 | E21: 0 | F21: 0
A22: Iowa | B22: =IF(E22>0,0,1) -> 1 | C22: =IF(F22=0,1) -> 1 | D22: 0 | E22: 0 | F22: 0
A23: Kansas | B23: =IF(E23>0,0,1) -> 1 | C23: =IF(F23=0,1) -> 1 | D23: 0 | E23: 0 | F23: 0
A24: Kentucky | B24: =IF(E24>0,0,1) -> 1 | C24: =IF(F24=0,1) -> 1 | D24: 0 | E24: 0 | F24: 0
A25: Louisiana | B25: =IF(E25>0,0,1) -> 1 | C25: =IF(F25=0,1) -> 1 | D25: 0 | E25: 0 | F25: 0
A26: Maine | B26: =IF(E26>0,0,1) -> 1 | C26: =IF(F26=0,1) -> 1 | D26: 1 | E26: 0 | F26: 0 | G26: 2001
A27: Maryland | B27: =IF(E27>0,0,1) -> 1 | C27: =IF(F27=0,1) -> 1 | D27: 1 | E27: 0 | F27: 0 | G27: 2011 | H27: 2026 | I27: 2027
A28: Massachusetts | B28: =IF(E28>0,0,1) -> 1 | C28: =IF(F28=0,1) -> 1 | D28: 1 | E28: 0 | F28: 0 | G28: 1995 | H28: 2026 | I28: 2025
A29: Michigan | B29: =IF(E29>0,0,1) -> 1 | C29: =IF(F29=0,1) -> 1 | D29: 0 | E29: 0 | F29: 0
A30: Minnesota | B30: =IF(E30>0,0,1) -> 1 | C30: =IF(F30=0,1) -> 1 | D30: 1 | E30: 0 | F30: 0 | G30: 2025
A31: Mississippi | B31: =IF(E31>0,0,1) -> 1 | C31: =IF(F31=0,1) -> 1 | D31: 0 | E31: 0 | F31: 0
A32: Missouri | B32: =IF(E32>0,0,1) -> 1 | C32: =IF(F32=0,1) -> 1 | D32: 0 | E32: 0 | F32: 0
A33: Montana | B33: =IF(E33>0,0,1) -> 1 | C33: =IF(F33=0,1) -> 1 | D33: 0 | E33: 0 | F33: 0
A34: Nebraska | B34: =IF(E34>0,0,1) -> 1 | C34: =IF(F34=0,1) -> 1 | D34: 0 | E34: 0 | F34: 0
A35: Nevada | B35: =IF(E35>0,0,1) -> 1 | C35: =IF(F35=0,1) -> 1 | D35: 1 | E35: 0 | F35: 0 | G35: 2025
A36: New Hampshire | B36: =IF(E36>0,0,1) -> 1 | C36: =IF(F36=0,1) -> 1 | D36: 0 | E36: 0 | F36: 0
A37: New Jersey | B37: =IF(E37>0,0,1) -> 1 | C37: =IF(F37=0,1) -> 1 | D37: 1 | E37: 0 | F37: 0 | G37: 2009 | H37: 2026 | I37: 2025
A38: New Mexico | B38: =IF(E38>0,0,1) -> 1 | C38: =IF(F38=0,1) -> 1 | D38: 1 | E38: 0 | F38: 0 | G38: 2026 | H38: 2026 | I38: 2027
A39: New York | B39: =IF(E39>0,0,1) -> 1 | C39: =IF(F39=0,1) -> 1 | D39: 1 | E39: 0 | F39: 0 | G39: 1993 | H39: 2026 | I39: 2025
A40: North Carolina | B40: =IF(E40>0,0,1) -> 1 | C40: =IF(F40=0,1) -> 1 | D40: 0 | E40: 0 | F40: 0
A41: North Dakota | B41: =IF(E41>0,0,1) -> 1 | C41: =IF(F41=0,1) -> 1 | D41: 0 | E41: 0 | F41: 0
...

Sheet Schedules
B2: logic in chart | C2: Passenger LDVs (% ZEV Share)
C3: 2025 | D3: 2026 | E3: 2027 | F3: 2028 | G3: 2029 | H3: 2030 | I3: 2031 | J3: 2032 | K3: 2033 | L3: 2034 | M3: 2035 | N3: 2036 | O3: 2037 | P3: 2038 | Q3: 2039 | R3: 2040 | S3: 2041 | T3: 2042 | U3: 2043 | V3: 2044 | W3: 2045 | X3: 2046 | Y3: 2047 | Z3: 2048 | AA3: 2049 | AB3: 2050
C4: 0.15 | D4: 0.1 | E4: 0.125 | F4: 0.15 | G4: 0.2 | H4: 0.25 | I4: 0.3 | J4: 0.38 | K4: 0.46 | L4: 0.514 | M4: 0.568 | N4: 0.622 | O4: 0.676 | P4: 0.73 | Q4: 0.784 | R4: 0.838 | S4: 0.892 | T4: 0.946 | U4: 1 | V4: 1 | W4: 1 | X4: 1 | Y4: 1 | Z4: 1 | AA4: 1 | AB4: 1
B5: mimic the pathway for passenger LDVs | C5: Passenger HDVs (% ZEV Share)
C6: 2025 | D6: 2026 | E6: 2027 | F6: 2028 | G6: 2029 | H6: 2030 | I6: 2031 | J6: 2032 | K6: 2033 | L6: 2034 | M6: 2035 | N6: 2036 | O6: 2037 | P6: 2038 | Q6: 2039 | R6: 2040 | S6: 2041 | T6: 2042 | U6: 2043 | V6: 2044 | W6: 2045 | X6: 2046 | Y6: 2047 | Z6: 2048 | AA6: 2049 | AB6: 2050
C7: 0.15 | D7: 0.1 | E7: 0.125 | F7: 0.15 | G7: 0.2 | H7: 0.25 | I7: 0.3 | J7: 0.38 | K7: 0.46 | L7: 0.514 | M7: 0.568 | N7: 0.622 | O7: 0.676 | P7: 0.73 | Q7: 0.784 | R7: 0.838 | S7: 0.892 | T7: 0.946 | U7: 1 | V7: 1 | W7: 1 | X7: 1 | Y7: 1 | Z7: 1 | AA7: 1 | AB7: 1
B8: 1.5% annual growth; waiver + 10 yr to 80% (5% higher than ACT; start from 10% higher) | C8: Freight LDVs (% ZEV Share)
C9: 2025 | D9: 2026 | E9: 2027 | F9: 2028 | G9: 2029 | H9: 2030 | I9: 2031 | J9: 2032 | K9: 2033 | L9: 2034 | M9: 2035 | N9: 2036 | O9: 2037 | P9: 2038 | Q9: 2039 | R9: 2040 | S9: 2041 | T9: 2042 | U9: 2043 | V9: 2044 | W9: 2045 | X9: 2046 | Y9: 2047 | Z9: 2048 | AA9: 2049 | AB9: 2050
C10: 0.075 | D10: 0.095 | E10: 0.115 | F10: 0.135 | G10: 0.155 | H10: 0.175 | I10: 0.195 | J10: 0.255 | K10: 0.315 | L10: 0.375 | M10: 0.435 | N10: 0.495 | O10: 0.555 | P10: 0.615 | Q10: 0.675 | R10: 0.735 | S10: 0.795 | T10: 0.85 | U10: 0.88 | V10: 0.91 | W10: 0.94 | X10: 0.97 | Y10: 1 | Z10: 1 | AA10: 1 | AB10: 1
C11: Freight HDVs (% ZEV Share)
C12: 2025 | D12: 2026 | E12: 2027 | F12: 2028 | G12: 2029 | H12: 2030 | I12: 2031 | J12: 2032 | K12: 2033 | L12: 2034 | M12: 2035 | N12: 2036 | O12: 2037 | P12: 2038 | Q12: 2039 | R12: 2040 | S12: 2041 | T12: 2042 | U12: 2043 | V12: 2044 | W12: 2045 | X12: 2046 | Y12: 2047 | Z12: 2048 | AA12: 2049 | AB12: 2050
B13: minimal growth to 2031; new ACT schedule | C13: 0.01 | D13: 0.014 | E13: 0.018 | F13: 0.022 | G13: 0.026 | H13: 0.03 | I13: 0.034 | J13: 0.05 | K13: 0.07 | L13: 0.1 | M13: 0.15 | N13: 0.2 | O13: 0.25 | P13: 0.3 | Q13: 0.35 | R13: 0.4 | S13: 0.4 | T13: 0.4 | U13: 0.4 | V13: 0.457 | W13: 0.514 | X13: 0.571 | Y13: 0.628 | Z13: 0.685 | AA13: 0.742 | AB13: 0.8

Sheet State Map
A2: Alabama | B2: AL | C2: Reference | E2: Max Ambition
A3: Arkansas | B3: AR | C3: Reference | E3: Moderate Ambition
A4: Arizona | B4: AZ | C4: Moderate Ambition | E4: Reference
A5: California | B5: CA | C5: Max Ambition
A6: Colorado | B6: CO | C6: Max Ambition
A7: Connecticut | B7: CT | C7: Moderate Ambition
A8: Delaware | B8: DE | C8: Max Ambition
A9: Florida | B9: FL | C9: Reference
A10: Georgia | B10: GA | C10: Electricity Only
A11: Iowa | B11: IA | C11: Electricity Only
A12: Idaho | B12: ID | C12: Reference
A13: Illinois | B13: IL | C13: Max Ambition
A14: Indiana | B14: IN | C14: Reference
A15: Kansas | B15: KS | C15: Reference
A16: Kentucky | B16: KY | C16: Reference
... A49: Wyoming | B49: WY | C49: Reference

Sheet RZSPbS-psgr-ldv
A1: Unit: % (share of vehicles that must be ZEVs) | B1: 2020 | C1: 2021 | D1: 2022 | E1: 2023 | F1: 2024 | G1: 2025 | H1: 2026 | I1: 2027 | J1: 2028 | K1: 2029 | L1: 2030 | M1: 2031 | N1: 2032 | O1: 2033 | P1: 2034 | Q1: 2035 | R1: 2036 | S1: 2037 | T1: 2038 | U1: 2039 | V1: 2040 | W1: 2041 | X1: 2042 | Y1: 2043 | Z1: 2044 | AA1: 2045 | AB1: 2046 | AC1: 2047 | AD1: 2048 | AE1: 2049 | AF1: 2050
A2: Alabama | B2: =IF(AND(INDEX('CA Standards and Followers'!$E$7:$E$66,MATCH($A2,'CA Standards and Followers'!$A$7:$A$66,0))=1,INDEX('CA Standards and Followers'!$H$7:$H$66,MATCH($A2,'CA Standards and Followers'!$A$7:$A$66,0))<=B$1),INDEX('CA Standards and Followers'!#REF!,MATCH(B$1,'CA Standards and Followers'!$1:$1,0)),IF(AND(INDEX('CA Standards and Followers'!$D$7:$D$66,MATCH($A2,'CA Standards and Followers'!$A$7:$A$66,0))=1,INDEX('CA Standards and Followers'!$G$7:$G$66,MATCH($A2,'CA Standards and Followers'!$A$7:$A$66,0))<=B$1),INDEX('CA Standards and Followers'!$2:$2,MATCH(B$1,'CA Standards and Followers'!$1:$1,0)),0)) -> 0 | C2: =IF(AND(INDEX('CA Standards and Followers'!$E$7:$E$66,MATCH($A2,'CA Standards and Followers'!$A$7:$A$66,0))=1,INDEX('CA Standards and Followers'!$H$7:$H$66,MATCH($A2,'CA Standards and Followers'!$A$7:$A$66,0))<=C$1),INDEX('CA Standards and Followers'!#REF!,MATCH(C$1,'CA Standards and Followers'!$1:$1,0)),IF(AND(INDEX('CA Standards and Followers'!$D$7:$D$66,MATCH($A2,'CA Standards and Followers'!$A$7:$A$66,0))=1,INDEX('CA Standards and Followers'!$G$7:$G$66,MATCH($A2,'CA Standards and Followers'!$A$7:$A$66,0))<=C$1),INDEX('CA Standards and Followers'!$2:$2,MATCH(C$1,'CA Standards and Followers'!$1:$1,0)),0)) -> 0 | D2: =IF(AND(INDEX('CA Standards and Followers'!$E$7:$E$66,MATCH($A2,'CA Standards and Followers'!$A$7:$A$66,0))=1,INDEX('CA Standards and Followers'!$H$7:$H$66,MATCH($A2,'CA Standards and Followers'!$A$7:$A$66,0))<=D$1),INDEX('CA Standards and Followers'!#REF!,MATCH(D$1,'CA Standards and Followers'!$1:$1,0)),IF(AND(INDEX('CA Standards and Followers'!$D$7:$D$66,MATCH($A2,'CA Standards and Followers'!$A$7:$A$66,0))=1,INDEX('CA Standards and Followers'!$G$7:$G$66,MATCH($A2,'CA Standards and Followers'!$A$7:$A$66,0))<=D$1),INDEX('CA Standards and Followers'!$2:$2,MATCH(D$1,'CA Standards and Followers'!$1:$1,0)),0)) -> 0 | E2: =IF(AND(INDEX('CA Standards and Followers'!$E$7:$E$66,MATCH($A2,'CA Standards and Followers'!$A$7:$A$66,0))=1,INDEX('CA Standards and Followers'!$H$7:$H$66,MATCH($A2,'CA Standards and Followers'!$A$7:$A$66,0))<=E$1),INDEX('CA Standards and Followers'!#REF!,MATCH(E$1,'CA Standards and Followers'!$1:$1,0)),IF(AND(INDEX('CA Standards and Followers'!$D$7:$D$66,MATCH($A2,'CA Standards and Followers'!$A$7:$A$66,0))=1,INDEX('CA Standards and Followers'!$G$7:$G$66,MATCH($A2,'CA Standards and Followers'!$A$7:$A$66,0))<=E$1),INDEX('CA Standards and Followers'!$2:$2,MATCH(E$1,'CA Standards and Followers'!$1:$1,0)),0)) -> 0 | F2: =IF(AND(INDEX('CA Standards and Followers'!$E$7:$E$66,MATCH($A2,'CA Standards and Followers'!$A$7:$A$66,0))=1,INDEX('CA Standards and Followers'!$H$7:$H$66,MATCH($A2,'CA Standards and Followers'!$A$7:$A$66,0))<=F$1),INDEX('CA Standards and Followers'!#REF!,MATCH(F$1,'CA Standards and Followers'!$1:$1,0)),IF(AND(INDEX('CA Standards and Followers'!$D$7:$D$66,MATCH($A2,'CA Standards and Followers'!$A$7:$A$66,0))=1,INDEX('CA Standards and Followers'!$G$7:$G$66,MATCH($A2,'CA Standards and Followers'!$A$7:$A$66,0))<=F$1),INDEX('CA Standards and Followers'!$2:$2,MATCH(F$1,'CA Standards and Followers'!$1:$1,0)),0)) -> 0 | G2: =IF(AND(INDEX('CA Standards and Followers'!$E$7:$E$66,MATCH($A2,'CA Standards and Followers'!$A$7:$A$66,0))=1,INDEX('CA Standards and Followers'!$H$7:$H$66,MATCH($A2,'CA Standards and Followers'!$A$7:$A$66,0))<=G$1),INDEX('CA Standards and Followers'!#REF!,MATCH(G$1,'CA Standards and Followers'!$1:$1,0)),IF(AND(INDEX('CA Standards and Followers'!$D$7:$D$66,MATCH($A2,'CA Standards and Followers'!$A$7:$A$66,0))=1,INDEX('CA Standards and Followers'!$G$7:$G$66,MATCH($A2,'CA Standards and Followers'!$A$7:$A$66,0))<=G$1),INDEX('CA Standards and Followers'!$2:$2,MATCH(G$1,'CA Standards and Followers'!$1:$1,0)),0)) -> 0 | H2: =IF(AND(INDEX('CA Standards and Followers'!$E$7:$E$66,MATCH($A2,'CA Standards and Followers'!$A$7:$A$66,0))=1,INDEX('CA Standards and Followers'!$H$7:$H$66,MATCH($A2,'CA Standards and Followers'!$A$7:$A$66,0))<=H$1),INDEX('CA Standards and Followers'!#REF!,MATCH(H$1,'CA Standards and Followers'!$1:$1,0)),IF(AND(INDEX('CA Standards and Followers'!$D$7:$D$66,MATCH($A2,'CA Standards and Followers'!$A$7:$A$66,0))=1,INDEX('CA Standards and Followers'!$G$7:$G$66,MATCH($A2,'CA Standards and Followers'!$A$7:$A$66,0))<=H$1),INDEX('CA Standards and Followers'!$2:$2,MATCH(H$1,'CA Standards and Followers'!$1:$1,0)),0)) -> 0 | I2: =IF(AND(INDEX('CA Standards and Followers'!$E$7:$E$66,MATCH($A2,'CA Standards and Followers'!$A$7:$A$66,0))=1,INDEX('CA Standards and Followers'!$H$7:$H$66,MATCH($A2,'CA Standards and Followers'!$A$7:$A$66,0))<=I$1),INDEX('CA Standards and Followers'!#REF!,MATCH(I$1,'CA Standards and Followers'!$1:$1,0)),IF(AND(INDEX('CA Standards and Followers'!$D$7:$D$66,MATCH($A2,'CA Standards and Followers'!$A$7:$A$66,0))=1,INDEX('CA Standards and Followers'!$G$7:$G$66,MATCH($A2,'CA Standards and Followers'!$A$7:$A$66,0))<=I$1),INDEX('CA Standards and Followers'!$2:$2,MATCH(I$1,'CA Standards and Followers'!$1:$1,0)),0)) -> 0 | J2: =IF(AND(INDEX('CA Standards and Followers'!$E$7:$E$66,MATCH($A2,'CA Standards and Followers'!$A$7:$A$66,0))=1,INDEX('CA Standards and Followers'!$H$7:$H$66,MATCH($A2,'CA Standards and Followers'!$A$7:$A$66,0))<=J$1),INDEX('CA Standards and Followers'!#REF!,MATCH(J$1,'CA Standards and Followers'!$1:$1,0)),IF(AND(INDEX('CA Standards and Followers'!$D$7:$D$66,MATCH($A2,'CA Standards and Followers'!$A$7:$A$66,0))=1,INDEX('CA Standards and Followers'!$G$7:$G$66,MATCH($A2,'CA Standards and Followers'!$A$7:$A$66,0))<=J$1),INDEX('CA Standards and Followers'!$2:$2,MATCH(J$1,'CA Standards and Followers'!$1:$1,0)),0)) -> 0 | K2: =MAX(IFERROR(IF(INDEX('State Map'!$C:$C,MATCH(TRIM('RZSPbS-psgr-ldv'!$A2),'State Map'!$A:$A,0))="Max Ambition",Schedules!G$4,J2),J2),J2) -> 0 | L2: =MAX(IFERROR(IF(INDEX('State Map'!$C:$C,MATCH(TRIM('RZSPbS-psgr-ldv'!$A2),'State Map'!$A:$A,0))="Max Ambition",Schedules!H$4,K2),K2),K2) -> 0 | M2: =MAX(IFERROR(IF(INDEX('State Map'!$C:$C,MATCH(TRIM('RZSPbS-psgr-ldv'!$A2),'State Map'!$A:$A,0))="Max Ambition",Schedules!I$4,L2),L2),L2) -> 0 | N2: =MAX(IFERROR(IF(INDEX('State Map'!$C:$C,MATCH(TRIM('RZSPbS-psgr-ldv'!$A2),'State Map'!$A:$A,0))="Max Ambition",Schedules!J$4,M2),M2),M2) -> 0 | O2: =MAX(IFERROR(IF(INDEX('State Map'!$C:$C,MATCH(TRIM('RZSPbS-psgr-ldv'!$A2),'State Map'!$A:$A,0))="Max Ambition",Schedules!K$4,N2),N2),N2) -> 0 | P2: =MAX(IFERROR(IF(INDEX('State Map'!$C:$C,MATCH(TRIM('RZSPbS-psgr-ldv'!$A2),'State Map'!$A:$A,0))="Max Ambition",Schedules!L$4,O2),O2),O2) -> 0 | Q2: =MAX(IFERROR(IF(INDEX('State Map'!$C:$C,MATCH(TRIM('RZSPbS-psgr-ldv'!$A2),'State Map'!$A:$A,0))="Max Ambition",Schedules!M$4,P2),P2),P2) -> 0 | R2: =MAX(IFERROR(IF(INDEX('State Map'!$C:$C,MATCH(TRIM('RZSPbS-psgr-ldv'!$A2),'State Map'!$A:$A,0))="Max Ambition",Schedules!N$4,Q2),Q2),Q2) -> 0 | ... AF2: =MAX(IFERROR(IF(INDEX('State Map'!$C:$C,MATCH(TRIM('RZSPbS-psgr-ldv'!$A2),'State Map'!$A:$A,0))="Max Ambition",Schedules!AB$4,AE2),AE2),AE2) -> 0
A3: Alaska | B3: =IF(AND(INDEX('CA Standards and Followers'!$E$7:$E$66,MATCH($A3,'CA Standards and Followers'!$A$7:$A$66,0))=1,INDEX('CA Standards and Followers'!$H$7:$H$66,MATCH($A3,'CA Standards and Followers'!$A$7:$A$66,0))<=B$1),INDEX('CA Standards and Followers'!#REF!,MATCH(B$1,'CA Standards and Followers'!$1:$1,0)),IF(AND(INDEX('CA Standards and Followers'!$D$7:$D$66,MATCH($A3,'CA Standards and Followers'!$A$7:$A$66,0))=1,INDEX('CA Standards and Followers'!$G$7:$G$66,MATCH($A3,'CA Standards and Followers'!$A$7:$A$66,0))<=B$1),INDEX('CA Standards and Followers'!$2:$2,MATCH(B$1,'CA Standards and Followers'!$1:$1,0)),0)) -> 0 | C3: =IF(AND(INDEX('CA Standards and Followers'!$E$7:$E$66,MATCH($A3,'CA Standards and Followers'!$A$7:$A$66,0))=1,INDEX('CA Standards and Followers'!$H$7:$H$66,MATCH($A3,'CA Standards and Followers'!$A$7:$A$66,0))<=C$1),INDEX('CA Standards and Followers'!#REF!,MATCH(C$1,'CA Standards and Followers'!$1:$1,0)),IF(AND(INDEX('CA Standards and Followers'!$D$7:$D$66,MATCH($A3,'CA Standards and Followers'!$A$7:$A$66,0))=1,INDEX('CA Standards and Followers'!$G$7:$G$66,MATCH($A3,'CA Standards and Followers'!$A$7:$A$66,0))<=C$1),INDEX('CA Standards and Followers'!$2:$2,MATCH(C$1,'CA Standards and Followers'!$1:$1,0)),0)) -> 0 | D3: =IF(AND(INDEX('CA Standards and Followers'!$E$7:$E$66,MATCH($A3,'CA Standards and Followers'!$A$7:$A$66,0))=1,INDEX('CA Standards and Followers'!$H$7:$H$66,MATCH($A3,'CA Standards and Followers'!$A$7:$A$66,0))<=D$1),INDEX('CA Standards and Followers'!#REF!,MATCH(D$1,'CA Standards and Followers'!$1:$1,0)),IF(AND(INDEX('CA Standards and Followers'!$D$7:$D$66,MATCH($A3,'CA Standards and Followers'!$A$7:$A$66,0))=1,INDEX('CA Standards and Followers'!$G$7:$G$66,MATCH($A3,'CA Standards and Followers'!$A$7:$A$66,0))<=D$1),INDEX('CA Standards and Followers'!$2:$2,MATCH(D$1,'CA Standards and Followers'!$1:$1,0)),0)) -> 0 | E3: =IF(AND(INDEX('CA Standards and Followers'!$E$7:$E$66,MATCH($A3,'CA Standards and Followers'!$A$7:$A$66,0))=1,INDEX('CA Standards and Followers'!$H$7:$H$66,MATCH($A3,'CA Standards and Followers'!$A$7:$A$66,0))<=E$1),INDEX('CA Standards and Followers'!#REF!,MATCH(E$1,'CA Standards and Followers'!$1:$1,0)),IF(AND(INDEX('CA Standards and Followers'!$D$7:$D$66,MATCH($A3,'CA Standards and Followers'!$A$7:$A$66,0))=1,INDEX('CA Standards and Followers'!$G$7:$G$66,MATCH($A3,'CA Standards and Followers'!$A$7:$A$66,0))<=E$1),INDEX('CA Standards and Followers'!$2:$2,MATCH(E$1,'CA Standards and Followers'!$1:$1,0)),0)) -> 0 | F3: =IF(AND(INDEX('CA Standards and Followers'!$E$7:$E$66,MATCH($A3,'CA Standards and Followers'!$A$7:$A$66,0))=1,INDEX('CA Standards and Followers'!$H$7:$H$66,MATCH($A3,'CA Standards and Followers'!$A$7:$A$66,0))<=F$1),INDEX('CA Standards and Followers'!#REF!,MATCH(F$1,'CA Standards and Followers'!$1:$1,0)),IF(AND(INDEX('CA Standards and Followers'!$D$7:$D$66,MATCH($A3,'CA Standards and Followers'!$A$7:$A$66,0))=1,INDEX('CA Standards and Followers'!$G$7:$G$66,MATCH($A3,'CA Standards and Followers'!$A$7:$A$66,0))<=F$1),INDEX('CA Standards and Followers'!$2:$2,MATCH(F$1,'CA Standards and Followers'!$1:$1,0)),0)) -> 0 | G3: =IF(AND(INDEX('CA Standards and Followers'!$E$7:$E$66,MATCH($A3,'CA Standards and Followers'!$A$7:$A$66,0))=1,INDEX('CA Standards and Followers'!$H$7:$H$66,MATCH($A3,'CA Standards and Followers'!$A$7:$A$66,0))<=G$1),INDEX('CA Standards and Followers'!#REF!,MATCH(G$1,'CA Standards and Followers'!$1:$1,0)),IF(AND(INDEX('CA Standards and Followers'!$D$7:$D$66,MATCH($A3,'CA Standards and Followers'!$A$7:$A$66,0))=1,INDEX('CA Standards and Followers'!$G$7:$G$66,MATCH($A3,'CA Standards and Followers'!$A$7:$A$66,0))<=G$1),INDEX('CA Standards and Followers'!$2:$2,MATCH(G$1,'CA Standards and Followers'!$1:$1,0)),0)) -> 0 | H3: =IF(AND(INDEX('CA Standards and Followers'!$E$7:$E$66,MATCH($A3,'CA Standards and Followers'!$A$7:$A$66,0))=1,INDEX('CA Standards and Followers'!$H$7:$H$66,MATCH($A3,'CA Standards and Followers'!$A$7:$A$66,0))<=H$1),INDEX('CA Standards and Followers'!#REF!,MATCH(H$1,'CA Standards and Followers'!$1:$1,0)),IF(AND(INDEX('CA Standards and Followers'!$D$7:$D$66,MATCH($A3,'CA Standards and Followers'!$A$7:$A$66,0))=1,INDEX('CA Standards and Followers'!$G$7:$G$66,MATCH($A3,'CA Standards and Followers'!$A$7:$A$66,0))<=H$1),INDEX('CA Standards and Followers'!$2:$2,MATCH(H$1,'CA Standards and Followers'!$1:$1,0)),0)) -> 0 | I3: =IF(AND(INDEX('CA Standards and Followers'!$E$7:$E$66,MATCH($A3,'CA Standards and Followers'!$A$7:$A$66,0))=1,INDEX('CA Standards and Followers'!$H$7:$H$66,MATCH($A3,'CA Standards and Followers'!$A$7:$A$66,0))<=I$1),INDEX('CA Standards and Followers'!#REF!,MATCH(I$1,'CA Standards and Followers'!$1:$1,0)),IF(AND(INDEX('CA Standards and Followers'!$D$7:$D$66,MATCH($A3,'CA Standards and Followers'!$A$7:$A$66,0))=1,INDEX('CA Standards and Followers'!$G$7:$G$66,MATCH($A3,'CA Standards and Followers'!$A$7:$A$66,0))<=I$1),INDEX('CA Standards and Followers'!$2:$2,MATCH(I$1,'CA Standards and Followers'!$1:$1,0)),0)) -> 0 | J3: =IF(AND(INDEX('CA Standards and Followers'!$E$7:$E$66,MATCH($A3,'CA Standards and Followers'!$A$7:$A$66,0))=1,INDEX('CA Standards and Followers'!$H$7:$H$66,MATCH($A3,'CA Standards and Followers'!$A$7:$A$66,0))<=J$1),INDEX('CA Standards and Followers'!#REF!,MATCH(J$1,'CA Standards and Followers'!$1:$1,0)),IF(AND(INDEX('CA Standards and Followers'!$D$7:$D$66,MATCH($A3,'CA Standards and Followers'!$A$7:$A$66,0))=1,INDEX('CA Standards and Followers'!$G$7:$G$66,MATCH($A3,'CA Standards and Followers'!$A$7:$A$66,0))<=J$1),INDEX('CA Standards and Followers'!$2:$2,MATCH(J$1,'CA Standards and Followers'!$1:$1,0)),0)) -> 0 | K3: =MAX(IFERROR(IF(INDEX('State Map'!$C:$C,MATCH(TRIM('RZSPbS-psgr-ldv'!$A3),'State Map'!$A:$A,0))="Max Ambition",Schedules!G$4,J3),J3),J3) -> 0 | L3: =MAX(IFERROR(IF(INDEX('State Map'!$C:$C,MATCH(TRIM('RZSPbS-psgr-ldv'!$A3),'State Map'!$A:$A,0))="Max Ambition",Schedules!H$4,K3),K3),K3) -> 0 | M3: =MAX(IFERROR(IF(INDEX('State Map'!$C:$C,MATCH(TRIM('RZSPbS-psgr-ldv'!$A3),'State Map'!$A:$A,0))="Max Ambition",Schedules!I$4,L3),L3),L3) -> 0 | N3: =MAX(IFERROR(IF(INDEX('State Map'!$C:$C,MATCH(TRIM('RZSPbS-psgr-ldv'!$A3),'State Map'!$A:$A,0))="Max Ambition",Schedules!J$4,M3),M3),M3) -> 0 | O3: =MAX(IFERROR(IF(INDEX('State Map'!$C:$C,MATCH(TRIM('RZSPbS-psgr-ldv'!$A3),'State Map'!$A:$A,0))="Max Ambition",Schedules!K$4,N3),N3),N3) -> 0 | P3: =MAX(IFERROR(IF(INDEX('State Map'!$C:$C,MATCH(TRIM('RZSPbS-psgr-ldv'!$A3),'State Map'!$A:$A,0))="Max Ambition",Schedules!L$4,O3),O3),O3) -> 0 | Q3: =MAX(IFERROR(IF(INDEX('State Map'!$C:$C,MATCH(TRIM('RZSPbS-psgr-ldv'!$A3),'State Map'!$A:$A,0))="Max Ambition",Schedules!M$4,P3),P3),P3) -> 0 | R3: =MAX(IFERROR(IF(INDEX('State Map'!$C:$C,MATCH(TRIM('RZSPbS-psgr-ldv'!$A3),'State Map'!$A:$A,0))="Max Ambition",Schedules!N$4,Q3),Q3),Q3) -> 0 | ... AF3: =MAX(IFERROR(IF(INDEX('State Map'!$C:$C,MATCH(TRIM('RZSPbS-psgr-ldv'!$A3),'State Map'!$A:$A,0))="Max Ambition",Schedules!AB$4,AE3),AE3),AE3) -> 0
A4: Arizona | B4: =IF(AND(INDEX('CA Standards and Followers'!$E$7:$E$66,MATCH($A4,'CA Standards and Followers'!$A$7:$A$66,0))=1,INDEX('CA Standards and Followers'!$H$7:$H$66,MATCH($A4,'CA Standards and Followers'!$A$7:$A$66,0))<=B$1),INDEX('CA Standards and Followers'!#REF!,MATCH(B$1,'CA Standards and Followers'!$1:$1,0)),IF(AND(INDEX('CA Standards and Followers'!$D$7:$D$66,MATCH($A4,'CA Standards and Followers'!$A$7:$A$66,0))=1,INDEX('CA Standards and Followers'!$G$7:$G$66,MATCH($A4,'CA Standards and Followers'!$A$7:$A$66,0))<=B$1),INDEX('CA Standards and Followers'!$2:$2,MATCH(B$1,'CA Standards and Followers'!$1:$1,0)),0)) -> 0 | C4: =IF(AND(INDEX('CA Standards and Followers'!$E$7:$E$66,MATCH($A4,'CA Standards and Followers'!$A$7:$A$66,0))=1,INDEX('CA Standards and Followers'!$H$7:$H$66,MATCH($A4,'CA Standards and Followers'!$A$7:$A$66,0))<=C$1),INDEX('CA Standards and Followers'!#REF!,MATCH(C$1,'CA Standards and Followers'!$1:$1,0)),IF(AND(INDEX('CA Standards and Followers'!$D$7:$D$66,MATCH($A4,'CA Standards and Followers'!$A$7:$A$66,0))=1,INDEX('CA Standards and Followers'!$G$7:$G$66,MATCH($A4,'CA Standards and Followers'!$A$7:$A$66,0))<=C$1),INDEX('CA Standards and Followers'!$2:$2,MATCH(C$1,'CA Standards and Followers'!$1:$1,0)),0)) -> 0 | D4: =IF(AND(INDEX('CA Standards and Followers'!$E$7:$E$66,MATCH($A4,'CA Standards and Followers'!$A$7:$A$66,0))=1,INDEX('CA Standards and Followers'!$H$7:$H$66,MATCH($A4,'CA Standards and Followers'!$A$7:$A$66,0))<=D$1),INDEX('CA Standards and Followers'!#REF!,MATCH(D$1,'CA Standards and Followers'!$1:$1,0)),IF(AND(INDEX('CA Standards and Followers'!$D$7:$D$66,MATCH($A4,'CA Standards and Followers'!$A$7:$A$66,0))=1,INDEX('CA Standards and Followers'!$G$7:$G$66,MATCH($A4,'CA Standards and Followers'!$A$7:$A$66,0))<=D$1),INDEX('CA Standards and Followers'!$2:$2,MATCH(D$1,'CA Standards and Followers'!$1:$1,0)),0)) -> 0 | E4: =IF(AND(INDEX('CA Standards and Followers'!$E$7:$E$66,MATCH($A4,'CA Standards and Followers'!$A$7:$A$66,0))=1,INDEX('CA Standards and Followers'!$H$7:$H$66,MATCH($A4,'CA Standards and Followers'!$A$7:$A$66,0))<=E$1),INDEX('CA Standards and Followers'!#REF!,MATCH(E$1,'CA Standards and Followers'!$1:$1,0)),IF(AND(INDEX('CA Standards and Followers'!$D$7:$D$66,MATCH($A4,'CA Standards and Followers'!$A$7:$A$66,0))=1,INDEX('CA Standards and Followers'!$G$7:$G$66,MATCH($A4,'CA Standards and Followers'!$A$7:$A$66,0))<=E$1),INDEX('CA Standards and Followers'!$2:$2,MATCH(E$1,'CA Standards and Followers'!$1:$1,0)),0)) -> 0 | F4: =IF(AND(INDEX('CA Standards and Followers'!$E$7:$E$66,MATCH($A4,'CA Standards and Followers'!$A$7:$A$66,0))=1,INDEX('CA Standards and Followers'!$H$7:$H$66,MATCH($A4,'CA Standards and Followers'!$A$7:$A$66,0))<=F$1),INDEX('CA Standards and Followers'!#REF!,MATCH(F$1,'CA Standards and Followers'!$1:$1,0)),IF(AND(INDEX('CA Standards and Followers'!$D$7:$D$66,MATCH($A4,'CA Standards and Followers'!$A$7:$A$66,0))=1,INDEX('CA Standards and Followers'!$G$7:$G$66,MATCH($A4,'CA Standards and Followers'!$A$7:$A$66,0))<=F$1),INDEX('CA Standards and Followers'!$2:$2,MATCH(F$1,'CA Standards and Followers'!$1:$1,0)),0)) -> 0 | G4: =IF(AND(INDEX('CA Standards and Followers'!$E$7:$E$66,MATCH($A4,'CA Standards and Followers'!$A$7:$A$66,0))=1,INDEX('CA Standards and Followers'!$H$7:$H$66,MATCH($A4,'CA Standards and Followers'!$A$7:$A$66,0))<=G$1),INDEX('CA Standards and Followers'!#REF!,MATCH(G$1,'CA Standards and Followers'!$1:$1,0)),IF(AND(INDEX('CA Standards and Followers'!$D$7:$D$66,MATCH($A4,'CA Standards and Followers'!$A$7:$A$66,0))=1,INDEX('CA Standards and Followers'!$G$7:$G$66,MATCH($A4,'CA Standards and Followers'!$A$7:$A$66,0))<=G$1),INDEX('CA Standards and Followers'!$2:$2,MATCH(G$1,'CA Standards and Followers'!$1:$1,0)),0)) -> 0 | H4: =IF(AND(INDEX('CA Standards and Followers'!$E$7:$E$66,MATCH($A4,'CA Standards and Followers'!$A$7:$A$66,0))=1,INDEX('CA Standards and Followers'!$H$7:$H$66,MATCH($A4,'CA Standards and Followers'!$A$7:$A$66,0))<=H$1),INDEX('CA Standards and Followers'!#REF!,MATCH(H$1,'CA Standards and Followers'!$1:$1,0)),IF(AND(INDEX('CA Standards and Followers'!$D$7:$D$66,MATCH($A4,'CA Standards and Followers'!$A$7:$A$66,0))=1,INDEX('CA Standards and Followers'!$G$7:$G$66,MATCH($A4,'CA Standards and Followers'!$A$7:$A$66,0))<=H$1),INDEX('CA Standards and Followers'!$2:$2,MATCH(H$1,'CA Standards and Followers'!$1:$1,0)),0)) -> 0 | I4: =IF(AND(INDEX('CA Standards and Followers'!$E$7:$E$66,MATCH($A4,'CA Standards and Followers'!$A$7:$A$66,0))=1,INDEX('CA Standards and Followers'!$H$7:$H$66,MATCH($A4,'CA Standards and Followers'!$A$7:$A$66,0))<=I$1),INDEX('CA Standards and Followers'!#REF!,MATCH(I$1,'CA Standards and Followers'!$1:$1,0)),IF(AND(INDEX('CA Standards and Followers'!$D$7:$D$66,MATCH($A4,'CA Standards and Followers'!$A$7:$A$66,0))=1,INDEX('CA Standards and Followers'!$G$7:$G$66,MATCH($A4,'CA Standards and Followers'!$A$7:$A$66,0))<=I$1),INDEX('CA Standards and Followers'!$2:$2,MATCH(I$1,'CA Standards and Followers'!$1:$1,0)),0)) -> 0 | J4: =IF(AND(INDEX('CA Standards and Followers'!$E$7:$E$66,MATCH($A4,'CA Standards and Followers'!$A$7:$A$66,0))=1,INDEX('CA Standards and Followers'!$H$7:$H$66,MATCH($A4,'CA Standards and Followers'!$A$7:$A$66,0))<=J$1),INDEX('CA Standards and Followers'!#REF!,MATCH(J$1,'CA Standards and Followers'!$1:$1,0)),IF(AND(INDEX('CA Standards and Followers'!$D$7:$D$66,MATCH($A4,'CA Standards and Followers'!$A$7:$A$66,0))=1,INDEX('CA Standards and Followers'!$G$7:$G$66,MATCH($A4,'CA Standards and Followers'!$A$7:$A$66,0))<=J$1),INDEX('CA Standards and Followers'!$2:$2,MATCH(J$1,'CA Standards and Followers'!$1:$1,0)),0)) -> 0 | K4: =MAX(IFERROR(IF(INDEX('State Map'!$C:$C,MATCH(TRIM('RZSPbS-psgr-ldv'!$A4),'State Map'!$A:$A,0))="Max Ambition",Schedules!G$4,J4),J4),J4) -> 0 | L4: =MAX(IFERROR(IF(INDEX('State Map'!$C:$C,MATCH(TRIM('RZSPbS-psgr-ldv'!$A4),'State Map'!$A:$A,0))="Max Ambition",Schedules!H$4,K4),K4),K4) -> 0 | M4: =MAX(IFERROR(IF(INDEX('State Map'!$C:$C,MATCH(TRIM('RZSPbS-psgr-ldv'!$A4),'State Map'!$A:$A,0))="Max Ambition",Schedules!I$4,L4),L4),L4) -> 0 | N4: =MAX(IFERROR(IF(INDEX('State Map'!$C:$C,MATCH(TRIM('RZSPbS-psgr-ldv'!$A4),'State Map'!$A:$A,0))="Max Ambition",Schedules!J$4,M4),M4),M4) -> 0 | O4: =MAX(IFERROR(IF(INDEX('State Map'!$C:$C,MATCH(TRIM('RZSPbS-psgr-ldv'!$A4),'State Map'!$A:$A,0))="Max Ambition",Schedules!K$4,N4),N4),N4) -> 0 | P4: =MAX(IFERROR(IF(INDEX('State Map'!$C:$C,MATCH(TRIM('RZSPbS-psgr-ldv'!$A4),'State Map'!$A:$A,0))="Max Ambition",Schedules!L$4,O4),O4),O4) -> 0 | Q4: =MAX(IFERROR(IF(INDEX('State Map'!$C:$C,MATCH(TRIM('RZSPbS-psgr-ldv'!$A4),'State Map'!$A:$A,0))="Max Ambition",Schedules!M$4,P4),P4),P4) -> 0 | R4: =MAX(IFERROR(IF(INDEX('State Map'!$C:$C,MATCH(TRIM('RZSPbS-psgr-ldv'!$A4),'State Map'!$A:$A,0))="Max Ambition",Schedules!N$4,Q4),Q4),Q4) -> 0 | ... AF4: =MAX(IFERROR(IF(INDEX('State Map'!$C:$C,MATCH(TRIM('RZSPbS-psgr-ldv'!$A4),'State Map'!$A:$A,0))="Max Ambition",Schedules!AB$4,AE4),AE4),AE4) -> 0
A5: Arkansas | B5: =IF(AND(INDEX('CA Standards and Followers'!$E$7:$E$66,MATCH($A5,'CA Standards and Followers'!$A$7:$A$66,0))=1,INDEX('CA Standards and Followers'!$H$7:$H$66,MATCH($A5,'CA Standards and Followers'!$A$7:$A$66,0))<=B$1),INDEX('CA Standards and Followers'!#REF!,MATCH(B$1,'CA Standards and Followers'!$1:$1,0)),IF(AND(INDEX('CA Standards and Followers'!$D$7:$D$66,MATCH($A5,'CA Standards and Followers'!$A$7:$A$66,0))=1,INDEX('CA Standards and Followers'!$G$7:$G$66,MATCH($A5,'CA Standards and Followers'!$A$7:$A$66,0))<=B$1),INDEX('CA Standards and Followers'!$2:$2,MATCH(B$1,'CA Standards and Followers'!$1:$1,0)),0)) -> 0 | C5: =IF(AND(INDEX('CA Standards and Followers'!$E$7:$E$66,MATCH($A5,'CA Standards and Followers'!$A$7:$A$66,0))=1,INDEX('CA Standards and Followers'!$H$7:$H$66,MATCH($A5,'CA Standards and Followers'!$A$7:$A$66,0))<=C$1),INDEX('CA Standards and Followers'!#REF!,MATCH(C$1,'CA Standards and Followers'!$1:$1,0)),IF(AND(INDEX('CA Standards and Followers'!$D$7:$D$66,MATCH($A5,'CA Standards and Followers'!$A$7:$A$66,0))=1,INDEX('CA Standards and Followers'!$G$7:$G$66,MATCH($A5,'CA Standards and Followers'!$A$7:$A$66,0))<=C$1),INDEX('CA Standards and Followers'!$2:$2,MATCH(C$1,'CA Standards and Followers'!$1:$1,0)),0)) -> 0 | D5: =IF(AND(INDEX('CA Standards and Followers'!$E$7:$E$66,MATCH($A5,'CA Standards and Followers'!$A$7:$A$66,0))=1,INDEX('CA Standards and Followers'!$H$7:$H$66,MATCH($A5,'CA Standards and Followers'!$A$7:$A$66,0))<=D$1),INDEX('CA Standards and Followers'!#REF!,MATCH(D$1,'CA Standards and Followers'!$1:$1,0)),IF(AND(INDEX('CA Standards and Followers'!$D$7:$D$66,MATCH($A5,'CA Standards and Followers'!$A$7:$A$66,0))=1,INDEX('CA Standards and Followers'!$G$7:$G$66,MATCH($A5,'CA Standards and Followers'!$A$7:$A$66,0))<=D$1),INDEX('CA Standards and Followers'!$2:$2,MATCH(D$1,'CA Standards and Followers'!$1:$1,0)),0)) -> 0 | E5: =IF(AND(INDEX('CA Standards and Followers'!$E$7:$E$66,MATCH($A5,'CA Standards and Followers'!$A$7:$A$66,0))=1,INDEX('CA Standards and Followers'!$H$7:$H$66,MATCH($A5,'CA Standards and Followers'!$A$7:$A$66,0))<=E$1),INDEX('CA Standards and Followers'!#REF!,MATCH(E$1,'CA Standards and Followers'!$1:$1,0)),IF(AND(INDEX('CA Standards and Followers'!$D$7:$D$66,MATCH($A5,'CA Standards and Followers'!$A$7:$A$66,0))=1,INDEX('CA Standards and Followers'!$G$7:$G$66,MATCH($A5,'CA Standards and Followers'!$A$7:$A$66,0))<=E$1),INDEX('CA Standards and Followers'!$2:$2,MATCH(E$1,'CA Standards and Followers'!$1:$1,0)),0)) -> 0 | F5: =IF(AND(INDEX('CA Standards and Followers'!$E$7:$E$66,MATCH($A5,'CA Standards and Followers'!$A$7:$A$66,0))=1,INDEX('CA Standards and Followers'!$H$7:$H$66,MATCH($A5,'CA Standards and Followers'!$A$7:$A$66,0))<=F$1),INDEX('CA Standards and Followers'!#REF!,MATCH(F$1,'CA Standards and Followers'!$1:$1,0)),IF(AND(INDEX('CA Standards and Followers'!$D$7:$D$66,MATCH($A5,'CA Standards and Followers'!$A$7:$A$66,0))=1,INDEX('CA Standards and Followers'!$G$7:$G$66,MATCH($A5,'CA Standards and Followers'!$A$7:$A$66,0))<=F$1),INDEX('CA Standards and Followers'!$2:$2,MATCH(F$1,'CA Standards and Followers'!$1:$1,0)),0)) -> 0 | G5: =IF(AND(INDEX('CA Standards and Followers'!$E$7:$E$66,MATCH($A5,'CA Standards and Followers'!$A$7:$A$66,0))=1,INDEX('CA Standards and Followers'!$H$7:$H$66,MATCH($A5,'CA Standards and Followers'!$A$7:$A$66,0))<=G$1),INDEX('CA Standards and Followers'!#REF!,MATCH(G$1,'CA Standards and Followers'!$1:$1,0)),IF(AND(INDEX('CA Standards and Followers'!$D$7:$D$66,MATCH($A5,'CA Standards and Followers'!$A$7:$A$66,0))=1,INDEX('CA Standards and Followers'!$G$7:$G$66,MATCH($A5,'CA Standards and Followers'!$A$7:$A$66,0))<=G$1),INDEX('CA Standards and Followers'!$2:$2,MATCH(G$1,'CA Standards and Followers'!$1:$1,0)),0)) -> 0 | H5: =IF(AND(INDEX('CA Standards and Followers'!$E$7:$E$66,MATCH($A5,'CA Standards and Followers'!$A$7:$A$66,0))=1,INDEX('CA Standards and Followers'!$H$7:$H$66,MATCH($A5,'CA Standards and Followers'!$A$7:$A$66,0))<=H$1),INDEX('CA Standards and Followers'!#REF!,MATCH(H$1,'CA Standards and Followers'!$1:$1,0)),IF(AND(INDEX('CA Standards and Followers'!$D$7:$D$66,MATCH($A5,'CA Standards and Followers'!$A$7:$A$66,0))=1,INDEX('CA Standards and Followers'!$G$7:$G$66,MATCH($A5,'CA Standards and Followers'!$A$7:$A$66,0))<=H$1),INDEX('CA Standards and Followers'!$2:$2,MATCH(H$1,'CA Standards and Followers'!$1:$1,0)),0)) -> 0 | I5: =IF(AND(INDEX('CA Standards and Followers'!$E$7:$E$66,MATCH($A5,'CA Standards and Followers'!$A$7:$A$66,0))=1,INDEX('CA Standards and Followers'!$H$7:$H$66,MATCH($A5,'CA Standards and Followers'!$A$7:$A$66,0))<=I$1),INDEX('CA Standards and Followers'!#REF!,MATCH(I$1,'CA Standards and Followers'!$1:$1,0)),IF(AND(INDEX('CA Standards and Followers'!$D$7:$D$66,MATCH($A5,'CA Standards and Followers'!$A$7:$A$66,0))=1,INDEX('CA Standards and Followers'!$G$7:$G$66,MATCH($A5,'CA Standards and Followers'!$A$7:$A$66,0))<=I$1),INDEX('CA Standards and Followers'!$2:$2,MATCH(I$1,'CA Standards and Followers'!$1:$1,0)),0)) -> 0 | J5: =IF(AND(INDEX('CA Standards and Followers'!$E$7:$E$66,MATCH($A5,'CA Standards and Followers'!$A$7:$A$66,0))=1,INDEX('CA Standards and Followers'!$H$7:$H$66,MATCH($A5,'CA Standards and Followers'!$A$7:$A$66,0))<=J$1),INDEX('CA Standards and Followers'!#REF!,MATCH(J$1,'CA Standards and Followers'!$1:$1,0)),IF(AND(INDEX('CA Standards and Followers'!$D$7:$D$66,MATCH($A5,'CA Standards and Followers'!$A$7:$A$66,0))=1,INDEX('CA Standards and Followers'!$G$7:$G$66,MATCH($A5,'CA Standards and Followers'!$A$7:$A$66,0))<=J$1),INDEX('CA Standards and Followers'!$2:$2,MATCH(J$1,'CA Standards and Followers'!$1:$1,0)),0)) -> 0 | K5: =MAX(IFERROR(IF(INDEX('State Map'!$C:$C,MATCH(TRIM('RZSPbS-psgr-ldv'!$A5),'State Map'!$A:$A,0))="Max Ambition",Schedules!G$4,J5),J5),J5) -> 0 | L5: =MAX(IFERROR(IF(INDEX('State Map'!$C:$C,MATCH(TRIM('RZSPbS-psgr-ldv'!$A5),'State Map'!$A:$A,0))="Max Ambition",Schedules!H$4,K5),K5),K5) -> 0 | M5: =MAX(IFERROR(IF(INDEX('State Map'!$C:$C,MATCH(TRIM('RZSPbS-psgr-ldv'!$A5),'State Map'!$A:$A,0))="Max Ambition",Schedules!I$4,L5),L5),L5) -> 0 | N5: =MAX(IFERROR(IF(INDEX('State Map'!$C:$C,MATCH(TRIM('RZSPbS-psgr-ldv'!$A5),'State Map'!$A:$A,0))="Max Ambition",Schedules!J$4,M5),M5),M5) -> 0 | O5: =MAX(IFERROR(IF(INDEX('State Map'!$C:$C,MATCH(TRIM('RZSPbS-psgr-ldv'!$A5),'State Map'!$A:$A,0))="Max Ambition",Schedules!K$4,N5),N5),N5) -> 0 | P5: =MAX(IFERROR(IF(INDEX('State Map'!$C:$C,MATCH(TRIM('RZSPbS-psgr-ldv'!$A5),'State Map'!$A:$A,0))="Max Ambition",Schedules!L$4,O5),O5),O5) -> 0 | Q5: =MAX(IFERROR(IF(INDEX('State Map'!$C:$C,MATCH(TRIM('RZSPbS-psgr-ldv'!$A5),'State Map'!$A:$A,0))="Max Ambition",Schedules!M$4,P5),P5),P5) -> 0 | R5: =MAX(IFERROR(IF(INDEX('State Map'!$C:$C,MATCH(TRIM('RZSPbS-psgr-ldv'!$A5),'State Map'!$A:$A,0))="Max Ambition",Schedules!N$4,Q5),Q5),Q5) -> 0 | ... AF5: =MAX(IFERROR(IF(INDEX('State Map'!$C:$C,MATCH(TRIM('RZSPbS-psgr-ldv'!$A5),'State Map'!$A:$A,0))="Max Ambition",Schedules!AB$4,AE5),AE5),AE5) -> 0
A6: California | B6: =IF(AND(INDEX('CA Standards and Followers'!$E$7:$E$66,MATCH($A6,'CA Standards and Followers'!$A$7:$A$66,0))=1,INDEX('CA Standards and Followers'!$H$7:$H$66,MATCH($A6,'CA Standards and Followers'!$A$7:$A$66,0))<=B$1),INDEX('CA Standards and Followers'!#REF!,MATCH(B$1,'CA Standards and Followers'!$1:$1,0)),IF(AND(INDEX('CA Standards and Followers'!$D$7:$D$66,MATCH($A6,'CA Standards and Followers'!$A$7:$A$66,0))=1,INDEX('CA Standards and Followers'!$G$7:$G$66,MATCH($A6,'CA Standards and Followers'!$A$7:$A$66,0))<=B$1),INDEX('CA Standards and Followers'!$2:$2,MATCH(B$1,'CA Standards and Followers'!$1:$1,0)),0)) -> 0 | C6: =IF(AND(INDEX('CA Standards and Followers'!$E$7:$E$66,MATCH($A6,'CA Standards and Followers'!$A$7:$A$66,0))=1,INDEX('CA Standards and Followers'!$H$7:$H$66,MATCH($A6,'CA Standards and Followers'!$A$7:$A$66,0))<=C$1),INDEX('CA Standards and Followers'!#REF!,MATCH(C$1,'CA Standards and Followers'!$1:$1,0)),IF(AND(INDEX('CA Standards and Followers'!$D$7:$D$66,MATCH($A6,'CA Standards and Followers'!$A$7:$A$66,0))=1,INDEX('CA Standards and Followers'!$G$7:$G$66,MATCH($A6,'CA Standards and Followers'!$A$7:$A$66,0))<=C$1),INDEX('CA Standards and Followers'!$2:$2,MATCH(C$1,'CA Standards and Followers'!$1:$1,0)),0)) -> 0 | D6: =IF(AND(INDEX('CA Standards and Followers'!$E$7:$E$66,MATCH($A6,'CA Standards and Followers'!$A$7:$A$66,0))=1,INDEX('CA Standards and Followers'!$H$7:$H$66,MATCH($A6,'CA Standards and Followers'!$A$7:$A$66,0))<=D$1),INDEX('CA Standards and Followers'!#REF!,MATCH(D$1,'CA Standards and Followers'!$1:$1,0)),IF(AND(INDEX('CA Standards and Followers'!$D$7:$D$66,MATCH($A6,'CA Standards and Followers'!$A$7:$A$66,0))=1,INDEX('CA Standards and Followers'!$G$7:$G$66,MATCH($A6,'CA Standards and Followers'!$A$7:$A$66,0))<=D$1),INDEX('CA Standards and Followers'!$2:$2,MATCH(D$1,'CA Standards and Followers'!$1:$1,0)),0)) -> 0 | E6: =IF(AND(INDEX('CA Standards and Followers'!$E$7:$E$66,MATCH($A6,'CA Standards and Followers'!$A$7:$A$66,0))=1,INDEX('CA Standards and Followers'!$H$7:$H$66,MATCH($A6,'CA Standards and Followers'!$A$7:$A$66,0))<=E$1),INDEX('CA Standards and Followers'!#REF!,MATCH(E$1,'CA Standards and Followers'!$1:$1,0)),IF(AND(INDEX('CA Standards and Followers'!$D$7:$D$66,MATCH($A6,'CA Standards and Followers'!$A$7:$A$66,0))=1,INDEX('CA Standards and Followers'!$G$7:$G$66,MATCH($A6,'CA Standards and Followers'!$A$7:$A$66,0))<=E$1),INDEX('CA Standards and Followers'!$2:$2,MATCH(E$1,'CA Standards and Followers'!$1:$1,0)),0)) -> 0 | F6: =IF(AND(INDEX('CA Standards and Followers'!$E$7:$E$66,MATCH($A6,'CA Standards and Followers'!$A$7:$A$66,0))=1,INDEX('CA Standards and Followers'!$H$7:$H$66,MATCH($A6,'CA Standards and Followers'!$A$7:$A$66,0))<=F$1),INDEX('CA Standards and Followers'!#REF!,MATCH(F$1,'CA Standards and Followers'!$1:$1,0)),IF(AND(INDEX('CA Standards and Followers'!$D$7:$D$66,MATCH($A6,'CA Standards and Followers'!$A$7:$A$66,0))=1,INDEX('CA Standards and Followers'!$G$7:$G$66,MATCH($A6,'CA Standards and Followers'!$A$7:$A$66,0))<=F$1),INDEX('CA Standards and Followers'!$2:$2,MATCH(F$1,'CA Standards and Followers'!$1:$1,0)),0)) -> 0.08 | G6: =IF(AND(INDEX('CA Standards and Followers'!$E$7:$E$66,MATCH($A6,'CA Standards and Followers'!$A$7:$A$66,0))=1,INDEX('CA Standards and Followers'!$H$7:$H$66,MATCH($A6,'CA Standards and Followers'!$A$7:$A$66,0))<=G$1),INDEX('CA Standards and Followers'!#REF!,MATCH(G$1,'CA Standards and Followers'!$1:$1,0)),IF(AND(INDEX('CA Standards and Followers'!$D$7:$D$66,MATCH($A6,'CA Standards and Followers'!$A$7:$A$66,0))=1,INDEX('CA Standards and Followers'!$G$7:$G$66,MATCH($A6,'CA Standards and Followers'!$A$7:$A$66,0))<=G$1),INDEX('CA Standards and Followers'!$2:$2,MATCH(G$1,'CA Standards and Followers'!$1:$1,0)),0)) -> 0.08 | H6: =IF(AND(INDEX('CA Standards and Followers'!$E$7:$E$66,MATCH($A6,'CA Standards and Followers'!$A$7:$A$66,0))=1,INDEX('CA Standards and Followers'!$H$7:$H$66,MATCH($A6,'CA Standards and Followers'!$A$7:$A$66,0))<=H$1),INDEX('CA Standards and Followers'!#REF!,MATCH(H$1,'CA Standards and Followers'!$1:$1,0)),IF(AND(INDEX('CA Standards and Followers'!$D$7:$D$66,MATCH($A6,'CA Standards and Followers'!$A$7:$A$66,0))=1,INDEX('CA Standards and Followers'!$G$7:$G$66,MATCH($A6,'CA Standards and Followers'!$A$7:$A$66,0))<=H$1),INDEX('CA Standards and Followers'!$2:$2,MATCH(H$1,'CA Standards and Followers'!$1:$1,0)),0)) -> 0 | I6: =IF(AND(INDEX('CA Standards and Followers'!$E$7:$E$66,MATCH($A6,'CA Standards and Followers'!$A$7:$A$66,0))=1,INDEX('CA Standards and Followers'!$H$7:$H$66,MATCH($A6,'CA Standards and Followers'!$A$7:$A$66,0))<=I$1),INDEX('CA Standards and Followers'!#REF!,MATCH(I$1,'CA Standards and Followers'!$1:$1,0)),IF(AND(INDEX('CA Standards and Followers'!$D$7:$D$66,MATCH($A6,'CA Standards and Followers'!$A$7:$A$66,0))=1,INDEX('CA Standards and Followers'!$G$7:$G$66,MATCH($A6,'CA Standards and Followers'!$A$7:$A$66,0))<=I$1),INDEX('CA Standards and Followers'!$2:$2,MATCH(I$1,'CA Standards and Followers'!$1:$1,0)),0)) -> 0 | J6: =IF(AND(INDEX('CA Standards and Followers'!$E$7:$E$66,MATCH($A6,'CA Standards and Followers'!$A$7:$A$66,0))=1,INDEX('CA Standards and Followers'!$H$7:$H$66,MATCH($A6,'CA Standards and Followers'!$A$7:$A$66,0))<=J$1),INDEX('CA Standards and Followers'!#REF!,MATCH(J$1,'CA Standards and Followers'!$1:$1,0)),IF(AND(INDEX('CA Standards and Followers'!$D$7:$D$66,MATCH($A6,'CA Standards and Followers'!$A$7:$A$66,0))=1,INDEX('CA Standards and Followers'!$G$7:$G$66,MATCH($A6,'CA Standards and Followers'!$A$7:$A$66,0))<=J$1),INDEX('CA Standards and Followers'!$2:$2,MATCH(J$1,'CA Standards and Followers'!$1:$1,0)),0)) -> 0 | K6: =MAX(IFERROR(IF(INDEX('State Map'!$C:$C,MATCH(TRIM('RZSPbS-psgr-ldv'!$A6),'State Map'!$A:$A,0))="Max Ambition",Schedules!G$4,J6),J6),J6) -> 0.2 | L6: =MAX(IFERROR(IF(INDEX('State Map'!$C:$C,MATCH(TRIM('RZSPbS-psgr-ldv'!$A6),'State Map'!$A:$A,0))="Max Ambition",Schedules!H$4,K6),K6),K6) -> 0.25 | M6: =MAX(IFERROR(IF(INDEX('State Map'!$C:$C,MATCH(TRIM('RZSPbS-psgr-ldv'!$A6),'State Map'!$A:$A,0))="Max Ambition",Schedules!I$4,L6),L6),L6) -> 0.3 | N6: =MAX(IFERROR(IF(INDEX('State Map'!$C:$C,MATCH(TRIM('RZSPbS-psgr-ldv'!$A6),'State Map'!$A:$A,0))="Max Ambition",Schedules!J$4,M6),M6),M6) -> 0.38 | O6: =MAX(IFERROR(IF(INDEX('State Map'!$C:$C,MATCH(TRIM('RZSPbS-psgr-ldv'!$A6),'State Map'!$A:$A,0))="Max Ambition",Schedules!K$4,N6),N6),N6) -> 0.46 | P6: =MAX(IFERROR(IF(INDEX('State Map'!$C:$C,MATCH(TRIM('RZSPbS-psgr-ldv'!$A6),'State Map'!$A:$A,0))="Max Ambition",Schedules!L$4,O6),O6),O6) -> 0.514 | Q6: =MAX(IFERROR(IF(INDEX('State Map'!$C:$C,MATCH(TRIM('RZSPbS-psgr-ldv'!$A6),'State Map'!$A:$A,0))="Max Ambition",Schedules!M$4,P6),P6),P6) -> 0.568 | R6: =MAX(IFERROR(IF(INDEX('State Map'!$C:$C,MATCH(TRIM('RZSPbS-psgr-ldv'!$A6),'State Map'!$A:$A,0))="Max Ambition",Schedules!N$4,Q6),Q6),Q6) -> 0.622 | ... AF6: =MAX(IFERROR(IF(INDEX('State Map'!$C:$C,MATCH(TRIM('RZSPbS-psgr-ldv'!$A6),'State Map'!$A:$A,0))="Max Ambition",Schedules!AB$4,AE6),AE6),AE6) -> 1
A7: Colorado | B7: =IF(AND(INDEX('CA Standards and Followers'!$E$7:$E$66,MATCH($A7,'CA Standards and Followers'!$A$7:$A$66,0))=1,INDEX('CA Standards and Followers'!$H$7:$H$66,MATCH($A7,'CA Standards and Followers'!$A$7:$A$66,0))<=B$1),INDEX('CA Standards and Followers'!#REF!,MATCH(B$1,'CA Standards and Followers'!$1:$1,0)),IF(AND(INDEX('CA Standards and Followers'!$D$7:$D$66,MATCH($A7,'CA Standards and Followers'!$A$7:$A$66,0))=1,INDEX('CA Standards and Followers'!$G$7:$G$66,MATCH($A7,'CA Standards and Followers'!$A$7:$A$66,0))<=B$1),INDEX('CA Standards and Followers'!$2:$2,MATCH(B$1,'CA Standards and Followers'!$1:$1,0)),0)) -> 0 | C7: =IF(AND(INDEX('CA Standards and Followers'!$E$7:$E$66,MATCH($A7,'CA Standards and Followers'!$A$7:$A$66,0))=1,INDEX('CA Standards and Followers'!$H$7:$H$66,MATCH($A7,'CA Standards and Followers'!$A$7:$A$66,0))<=C$1),INDEX('CA Standards and Followers'!#REF!,MATCH(C$1,'CA Standards and Followers'!$1:$1,0)),IF(AND(INDEX('CA Standards and Followers'!$D$7:$D$66,MATCH($A7,'CA Standards and Followers'!$A$7:$A$66,0))=1,INDEX('CA Standards and Followers'!$G$7:$G$66,MATCH($A7,'CA Standards and Followers'!$A$7:$A$66,0))<=C$1),INDEX('CA Standards and Followers'!$2:$2,MATCH(C$1,'CA Standards and Followers'!$1:$1,0)),0)) -> 0 | D7: =IF(AND(INDEX('CA Standards and Followers'!$E$7:$E$66,MATCH($A7,'CA Standards and Followers'!$A$7:$A$66,0))=1,INDEX('CA Standards and Followers'!$H$7:$H$66,MATCH($A7,'CA Standards and Followers'!$A$7:$A$66,0))<=D$1),INDEX('CA Standards and Followers'!#REF!,MATCH(D$1,'CA Standards and Followers'!$1:$1,0)),IF(AND(INDEX('CA Standards and Followers'!$D$7:$D$66,MATCH($A7,'CA Standards and Followers'!$A$7:$A$66,0))=1,INDEX('CA Standards and Followers'!$G$7:$G$66,MATCH($A7,'CA Standards and Followers'!$A$7:$A$66,0))<=D$1),INDEX('CA Standards and Followers'!$2:$2,MATCH(D$1,'CA Standards and Followers'!$1:$1,0)),0)) -> 0 | E7: =IF(AND(INDEX('CA Standards and Followers'!$E$7:$E$66,MATCH($A7,'CA Standards and Followers'!$A$7:$A$66,0))=1,INDEX('CA Standards and Followers'!$H$7:$H$66,MATCH($A7,'CA Standards and Followers'!$A$7:$A$66,0))<=E$1),INDEX('CA Standards and Followers'!#REF!,MATCH(E$1,'CA Standards and Followers'!$1:$1,0)),IF(AND(INDEX('CA Standards and Followers'!$D$7:$D$66,MATCH($A7,'CA Standards and Followers'!$A$7:$A$66,0))=1,INDEX('CA Standards and Followers'!$G$7:$G$66,MATCH($A7,'CA Standards and Followers'!$A$7:$A$66,0))<=E$1),INDEX('CA Standards and Followers'!$2:$2,MATCH(E$1,'CA Standards and Followers'!$1:$1,0)),0)) -> 0 | F7: =IF(AND(INDEX('CA Standards and Followers'!$E$7:$E$66,MATCH($A7,'CA Standards and Followers'!$A$7:$A$66,0))=1,INDEX('CA Standards and Followers'!$H$7:$H$66,MATCH($A7,'CA Standards and Followers'!$A$7:$A$66,0))<=F$1),INDEX('CA Standards and Followers'!#REF!,MATCH(F$1,'CA Standards and Followers'!$1:$1,0)),IF(AND(INDEX('CA Standards and Followers'!$D$7:$D$66,MATCH($A7,'CA Standards and Followers'!$A$7:$A$66,0))=1,INDEX('CA Standards and Followers'!$G$7:$G$66,MATCH($A7,'CA Standards and Followers'!$A$7:$A$66,0))<=F$1),INDEX('CA Standards and Followers'!$2:$2,MATCH(F$1,'CA Standards and Followers'!$1:$1,0)),0)) -> 0.08 | G7: =IF(AND(INDEX('CA Standards and Followers'!$E$7:$E$66,MATCH($A7,'CA Standards and Followers'!$A$7:$A$66,0))=1,INDEX('CA Standards and Followers'!$H$7:$H$66,MATCH($A7,'CA Standards and Followers'!$A$7:$A$66,0))<=G$1),INDEX('CA Standards and Followers'!#REF!,MATCH(G$1,'CA Standards and Followers'!$1:$1,0)),IF(AND(INDEX('CA Standards and Followers'!$D$7:$D$66,MATCH($A7,'CA Standards and Followers'!$A$7:$A$66,0))=1,INDEX('CA Standards and Followers'!$G$7:$G$66,MATCH($A7,'CA Standards and Followers'!$A$7:$A$66,0))<=G$1),INDEX('CA Standards and Followers'!$2:$2,MATCH(G$1,'CA Standards and Followers'!$1:$1,0)),0)) -> 0.08 | H7: =IF(AND(INDEX('CA Standards and Followers'!$E$7:$E$66,MATCH($A7,'CA Standards and Followers'!$A$7:$A$66,0))=1,INDEX('CA Standards and Followers'!$H$7:$H$66,MATCH($A7,'CA Standards and Followers'!$A$7:$A$66,0))<=H$1),INDEX('CA Standards and Followers'!#REF!,MATCH(H$1,'CA Standards and Followers'!$1:$1,0)),IF(AND(INDEX('CA Standards and Followers'!$D$7:$D$66,MATCH($A7,'CA Standards and Followers'!$A$7:$A$66,0))=1,INDEX('CA Standards and Followers'!$G$7:$G$66,MATCH($A7,'CA Standards and Followers'!$A$7:$A$66,0))<=H$1),INDEX('CA Standards and Followers'!$2:$2,MATCH(H$1,'CA Standards and Followers'!$1:$1,0)),0)) -> 0 | I7: =IF(AND(INDEX('CA Standards and Followers'!$E$7:$E$66,MATCH($A7,'CA Standards and Followers'!$A$7:$A$66,0))=1,INDEX('CA Standards and Followers'!$H$7:$H$66,MATCH($A7,'CA Standards and Followers'!$A$7:$A$66,0))<=I$1),INDEX('CA Standards and Followers'!#REF!,MATCH(I$1,'CA Standards and Followers'!$1:$1,0)),IF(AND(INDEX('CA Standards and Followers'!$D$7:$D$66,MATCH($A7,'CA Standards and Followers'!$A$7:$A$66,0))=1,INDEX('CA Standards and Followers'!$G$7:$G$66,MATCH($A7,'CA Standards and Followers'!$A$7:$A$66,0))<=I$1),INDEX('CA Standards and Followers'!$2:$2,MATCH(I$1,'CA Standards and Followers'!$1:$1,0)),0)) -> 0 | J7: =IF(AND(INDEX('CA Standards and Followers'!$E$7:$E$66,MATCH($A7,'CA Standards and Followers'!$A$7:$A$66,0))=1,INDEX('CA Standards and Followers'!$H$7:$H$66,MATCH($A7,'CA Standards and Followers'!$A$7:$A$66,0))<=J$1),INDEX('CA Standards and Followers'!#REF!,MATCH(J$1,'CA Standards and Followers'!$1:$1,0)),IF(AND(INDEX('CA Standards and Followers'!$D$7:$D$66,MATCH($A7,'CA Standards and Followers'!$A$7:$A$66,0))=1,INDEX('CA Standards and Followers'!$G$7:$G$66,MATCH($A7,'CA Standards and Followers'!$A$7:$A$66,0))<=J$1),INDEX('CA Standards and Followers'!$2:$2,MATCH(J$1,'CA Standards and Followers'!$1:$1,0)),0)) -> 0 | K7: =MAX(IFERROR(IF(INDEX('State Map'!$C:$C,MATCH(TRIM('RZSPbS-psgr-ldv'!$A7),'State Map'!$A:$A,0))="Max Ambition",Schedules!G$4,J7),J7),J7) -> 0.2 | L7: =MAX(IFERROR(IF(INDEX('State Map'!$C:$C,MATCH(TRIM('RZSPbS-psgr-ldv'!$A7),'State Map'!$A:$A,0))="Max Ambition",Schedules!H$4,K7),K7),K7) -> 0.25 | M7: =MAX(IFERROR(IF(INDEX('State Map'!$C:$C,MATCH(TRIM('RZSPbS-psgr-ldv'!$A7),'State Map'!$A:$A,0))="Max Ambition",Schedules!I$4,L7),L7),L7) -> 0.3 | N7: =MAX(IFERROR(IF(INDEX('State Map'!$C:$C,MATCH(TRIM('RZSPbS-psgr-ldv'!$A7),'State Map'!$A:$A,0))="Max Ambition",Schedules!J$4,M7),M7),M7) -> 0.38 | O7: =MAX(IFERROR(IF(INDEX('State Map'!$C:$C,MATCH(TRIM('RZSPbS-psgr-ldv'!$A7),'State Map'!$A:$A,0))="Max Ambition",Schedules!K$4,N7),N7),N7) -> 0.46 | P7: =MAX(IFERROR(IF(INDEX('State Map'!$C:$C,MATCH(TRIM('RZSPbS-psgr-ldv'!$A7),'State Map'!$A:$A,0))="Max Ambition",Schedules!L$4,O7),O7),O7) -> 0.514 | Q7: =MAX(IFERROR(IF(INDEX('State Map'!$C:$C,MATCH(TRIM('RZSPbS-psgr-ldv'!$A7),'State Map'!$A:$A,0))="Max Ambition",Schedules!M$4,P7),P7),P7) -> 0.568 | R7: =MAX(IFERROR(IF(INDEX('State Map'!$C:$C,MATCH(TRIM('RZSPbS-psgr-ldv'!$A7),'State Map'!$A:$A,0))="Max Ambition",Schedules!N$4,Q7),Q7),Q7) -> 0.622 | ... AF7: =MAX(IFERROR(IF(INDEX('State Map'!$C:$C,MATCH(TRIM('RZSPbS-psgr-ldv'!$A7),'State Map'!$A:$A,0))="Max Ambition",Schedules!AB$4,AE7),AE7),AE7) -> 1
A8: Connecticut | B8: =IF(AND(INDEX('CA Standards and Followers'!$E$7:$E$66,MATCH($A8,'CA Standards and Followers'!$A$7:$A$66,0))=1,INDEX('CA Standards and Followers'!$H$7:$H$66,MATCH($A8,'CA Standards and Followers'!$A$7:$A$66,0))<=B$1),INDEX('CA Standards and Followers'!#REF!,MATCH(B$1,'CA Standards and Followers'!$1:$1,0)),IF(AND(INDEX('CA Standards and Followers'!$D$7:$D$66,MATCH($A8,'CA Standards and Followers'!$A$7:$A$66,0))=1,INDEX('CA Standards and Followers'!$G$7:$G$66,MATCH($A8,'CA Standards and Followers'!$A$7:$A$66,0))<=B$1),INDEX('CA Standards and Followers'!$2:$2,MATCH(B$1,'CA Standards and Followers'!$1:$1,0)),0)) -> 0 | C8: =IF(AND(INDEX('CA Standards and Followers'!$E$7:$E$66,MATCH($A8,'CA Standards and Followers'!$A$7:$A$66,0))=1,INDEX('CA Standards and Followers'!$H$7:$H$66,MATCH($A8,'CA Standards and Followers'!$A$7:$A$66,0))<=C$1),INDEX('CA Standards and Followers'!#REF!,MATCH(C$1,'CA Standards and Followers'!$1:$1,0)),IF(AND(INDEX('CA Standards and Followers'!$D$7:$D$66,MATCH($A8,'CA Standards and Followers'!$A$7:$A$66,0))=1,INDEX('CA Standards and Followers'!$G$7:$G$66,MATCH($A8,'CA Standards and Followers'!$A$7:$A$66,0))<=C$1),INDEX('CA Standards and Followers'!$2:$2,MATCH(C$1,'CA Standards and Followers'!$1:$1,0)),0)) -> 0 | D8: =IF(AND(INDEX('CA Standards and Followers'!$E$7:$E$66,MATCH($A8,'CA Standards and Followers'!$A$7:$A$66,0))=1,INDEX('CA Standards and Followers'!$H$7:$H$66,MATCH($A8,'CA Standards and Followers'!$A$7:$A$66,0))<=D$1),INDEX('CA Standards and Followers'!#REF!,MATCH(D$1,'CA Standards and Followers'!$1:$1,0)),IF(AND(INDEX('CA Standards and Followers'!$D$7:$D$66,MATCH($A8,'CA Standards and Followers'!$A$7:$A$66,0))=1,INDEX('CA Standards and Followers'!$G$7:$G$66,MATCH($A8,'CA Standards and Followers'!$A$7:$A$66,0))<=D$1),INDEX('CA Standards and Followers'!$2:$2,MATCH(D$1,'CA Standards and Followers'!$1:$1,0)),0)) -> 0 | E8: =IF(AND(INDEX('CA Standards and Followers'!$E$7:$E$66,MATCH($A8,'CA Standards and Followers'!$A$7:$A$66,0))=1,INDEX('CA Standards and Followers'!$H$7:$H$66,MATCH($A8,'CA Standards and Followers'!$A$7:$A$66,0))<=E$1),INDEX('CA Standards and Followers'!#REF!,MATCH(E$1,'CA Standards and Followers'!$1:$1,0)),IF(AND(INDEX('CA Standards and Followers'!$D$7:$D$66,MATCH($A8,'CA Standards and Followers'!$A$7:$A$66,0))=1,INDEX('CA Standards and Followers'!$G$7:$G$66,MATCH($A8,'CA Standards and Followers'!$A$7:$A$66,0))<=E$1),INDEX('CA Standards and Followers'!$2:$2,MATCH(E$1,'CA Standards and Followers'!$1:$1,0)),0)) -> 0 | F8: =IF(AND(INDEX('CA Standards and Followers'!$E$7:$E$66,MATCH($A8,'CA Standards and Followers'!$A$7:$A$66,0))=1,INDEX('CA Standards and Followers'!$H$7:$H$66,MATCH($A8,'CA Standards and Followers'!$A$7:$A$66,0))<=F$1),INDEX('CA Standards and Followers'!#REF!,MATCH(F$1,'CA Standards and Followers'!$1:$1,0)),IF(AND(INDEX('CA Standards and Followers'!$D$7:$D$66,MATCH($A8,'CA Standards and Followers'!$A$7:$A$66,0))=1,INDEX('CA Standards and Followers'!$G$7:$G$66,MATCH($A8,'CA Standards and Followers'!$A$7:$A$66,0))<=F$1),INDEX('CA Standards and Followers'!$2:$2,MATCH(F$1,'CA Standards and Followers'!$1:$1,0)),0)) -> 0.08 | G8: =IF(AND(INDEX('CA Standards and Followers'!$E$7:$E$66,MATCH($A8,'CA Standards and Followers'!$A$7:$A$66,0))=1,INDEX('CA Standards and Followers'!$H$7:$H$66,MATCH($A8,'CA Standards and Followers'!$A$7:$A$66,0))<=G$1),INDEX('CA Standards and Followers'!#REF!,MATCH(G$1,'CA Standards and Followers'!$1:$1,0)),IF(AND(INDEX('CA Standards and Followers'!$D$7:$D$66,MATCH($A8,'CA Standards and Followers'!$A$7:$A$66,0))=1,INDEX('CA Standards and Followers'!$G$7:$G$66,MATCH($A8,'CA Standards and Followers'!$A$7:$A$66,0))<=G$1),INDEX('CA Standards and Followers'!$2:$2,MATCH(G$1,'CA Standards and Followers'!$1:$1,0)),0)) -> 0.08 | H8: =IF(AND(INDEX('CA Standards and Followers'!$E$7:$E$66,MATCH($A8,'CA Standards and Followers'!$A$7:$A$66,0))=1,INDEX('CA Standards and Followers'!$H$7:$H$66,MATCH($A8,'CA Standards and Followers'!$A$7:$A$66,0))<=H$1),INDEX('CA Standards and Followers'!#REF!,MATCH(H$1,'CA Standards and Followers'!$1:$1,0)),IF(AND(INDEX('CA Standards and Followers'!$D$7:$D$66,MATCH($A8,'CA Standards and Followers'!$A$7:$A$66,0))=1,INDEX('CA Standards and Followers'!$G$7:$G$66,MATCH($A8,'CA Standards and Followers'!$A$7:$A$66,0))<=H$1),INDEX('CA Standards and Followers'!$2:$2,MATCH(H$1,'CA Standards and Followers'!$1:$1,0)),0)) -> 0 | I8: =IF(AND(INDEX('CA Standards and Followers'!$E$7:$E$66,MATCH($A8,'CA Standards and Followers'!$A$7:$A$66,0))=1,INDEX('CA Standards and Followers'!$H$7:$H$66,MATCH($A8,'CA Standards and Followers'!$A$7:$A$66,0))<=I$1),INDEX('CA Standards and Followers'!#REF!,MATCH(I$1,'CA Standards and Followers'!$1:$1,0)),IF(AND(INDEX('CA Standards and Followers'!$D$7:$D$66,MATCH($A8,'CA Standards and Followers'!$A$7:$A$66,0))=1,INDEX('CA Standards and Followers'!$G$7:$G$66,MATCH($A8,'CA Standards and Followers'!$A$7:$A$66,0))<=I$1),INDEX('CA Standards and Followers'!$2:$2,MATCH(I$1,'CA Standards and Followers'!$1:$1,0)),0)) -> 0 | J8: =IF(AND(INDEX('CA Standards and Followers'!$E$7:$E$66,MATCH($A8,'CA Standards and Followers'!$A$7:$A$66,0))=1,INDEX('CA Standards and Followers'!$H$7:$H$66,MATCH($A8,'CA Standards and Followers'!$A$7:$A$66,0))<=J$1),INDEX('CA Standards and Followers'!#REF!,MATCH(J$1,'CA Standards and Followers'!$1:$1,0)),IF(AND(INDEX('CA Standards and Followers'!$D$7:$D$66,MATCH($A8,'CA Standards and Followers'!$A$7:$A$66,0))=1,INDEX('CA Standards and Followers'!$G$7:$G$66,MATCH($A8,'CA Standards and Followers'!$A$7:$A$66,0))<=J$1),INDEX('CA Standards and Followers'!$2:$2,MATCH(J$1,'CA Standards and Followers'!$1:$1,0)),0)) -> 0 | K8: =MAX(IFERROR(IF(INDEX('State Map'!$C:$C,MATCH(TRIM('RZSPbS-psgr-ldv'!$A8),'State Map'!$A:$A,0))="Max Ambition",Schedules!G$4,J8),J8),J8) -> 0 | L8: =MAX(IFERROR(IF(INDEX('State Map'!$C:$C,MATCH(TRIM('RZSPbS-psgr-ldv'!$A8),'State Map'!$A:$A,0))="Max Ambition",Schedules!H$4,K8),K8),K8) -> 0 | M8: =MAX(IFERROR(IF(INDEX('State Map'!$C:$C,MATCH(TRIM('RZSPbS-psgr-ldv'!$A8),'State Map'!$A:$A,0))="Max Ambition",Schedules!I$4,L8),L8),L8) -> 0 | N8: =MAX(IFERROR(IF(INDEX('State Map'!$C:$C,MATCH(TRIM('RZSPbS-psgr-ldv'!$A8),'State Map'!$A:$A,0))="Max Ambition",Schedules!J$4,M8),M8),M8) -> 0 | O8: =MAX(IFERROR(IF(INDEX('State Map'!$C:$C,MATCH(TRIM('RZSPbS-psgr-ldv'!$A8),'State Map'!$A:$A,0))="Max Ambition",Schedules!K$4,N8),N8),N8) -> 0 | P8: =MAX(IFERROR(IF(INDEX('State Map'!$C:$C,MATCH(TRIM('RZSPbS-psgr-ldv'!$A8),'State Map'!$A:$A,0))="Max Ambition",Schedules!L$4,O8),O8),O8) -> 0 | Q8: =MAX(IFERROR(IF(INDEX('State Map'!$C:$C,MATCH(TRIM('RZSPbS-psgr-ldv'!$A8),'State Map'!$A:$A,0))="Max Ambition",Schedules!M$4,P8),P8),P8) -> 0 | R8: =MAX(IFERROR(IF(INDEX('State Map'!$C:$C,MATCH(TRIM('RZSPbS-psgr-ldv'!$A8),'State Map'!$A:$A,0))="Max Ambition",Schedules!N$4,Q8),Q8),Q8) -> 0 | ... AF8: =MAX(IFERROR(IF(INDEX('State Map'!$C:$C,MATCH(TRIM('RZSPbS-psgr-ldv'!$A8),'State Map'!$A:$A,0))="Max Ambition",Schedules!AB$4,AE8),AE8),AE8) -> 0
