Workbook

Sheet About
A1: BRZSPbS BAU Required ZEV Sales Percentage by Subregion
A3: Sources: | B3: State Passenger LDV Requirements
B4: California Air Resources Board
B5: 2022
B6: Final Regulation Order, Section 1962.4, Title 13, California Code of Regulations
B7: https://ww2.arb.ca.gov/sites/default/files/barcu/regact/2022/accii/acciifro1962.4.pdf
B8: Page 4
B10: Which States Follow ACC I Standards?
B11: California Air Resources Board + state regs
B12: 2019-2022
B13: 177 States
B14: https://ww2.arb.ca.gov/sites/default/files/2019-03/177-states.pdf
B15: https://ecology.wa.gov/Regulations-Permits/Laws-rules-rulemaking/Rulemaking/WAC-173-423-400
B16: https://ndep.nv.gov/uploads/air-ccn-docs/clean_cars_nv_reg.pdf
B17: https://cloud.env.nm.gov/air/resources/_translator.php/NoP4Wd1EyorPC~sl~BWz~sl~H2+PXdCQEKefUZ7Ou8Vgq~sl~x2ZYzqa1zexRjaNVbxGMCgU8AVirLkjjLdev8vysjOadSflGgbBfGQtLEpGCtN+kDVh1YPy2q5u9L4gGZ4Ls+vKK.pdf
B18: https://lis.virginia.gov/cgi-bin/legp604.exe?212+ful+HB1965ER
A20: Notes
A21: This variable expresses the percentage of vehicles sold in each subregion that must be
A22: ZEVs in each year (i.e., due to a mandate or binding target implemented in legislation).
A23: It should not cover any requirements outside the subregional geography (for the whole model region).
A24: I.e. the US national model should not cover federal requirements here, only state requirements.
A25: The model will allow more ZEVs than this to be sold if economic factors would favor
A26: a higher level of ZEV deployment. This variable should only contain the legislative
A27: required ZEV shares, not projected or expected ZEV shares based on economics,
A28: ZEV subsidies, or other such factors.
A30: Although manufacturers often begin selling new models before the calendar year begins, the
A31: EPS can't impose a ZEV standard for part of a year. Therefore, we assume sales year = model year.
A33: U.S. Data
... A35: ACCI eforcement runs through 2025

Sheet CA Standards and Followers
B1: 2020 | C1: 2021 | D1: 2022 | E1: 2023 | F1: 2024 | G1: 2025 | H1: 2026 | I1: 2027 | J1: 2028 | K1: 2029 | L1: 2030 | M1: 2031 | N1: 2032 | O1: 2033 | P1: 2034 | Q1: 2035 | R1: 2036 | S1: 2037 | T1: 2038 | U1: 2039 | V1: 2040 | W1: 2041 | X1: 2042 | Y1: 2043 | Z1: 2044 | AA1: 2045 | AB1: 2046 | AC1: 2047 | AD1: 2048 | AE1: 2049 | AF1: 2050
A2: passenger LDVs ACC I | B2: 0 | C2: 0 | D2: 0 | E2: 0 | F2: =8% -> 0.08 | G2: =8% -> 0.08 | H2: 0 | I2: 0 | J2: 0 | K2: 0 | L2: 0 | M2: 0 | N2: 0 | O2: 0 | P2: 0 | Q2: 0 | R2: 0 | S2: 0 | T2: 0 | U2: 0 | V2: 0 | W2: 0 | X2: 0 | Y2: 0 | Z2: 0 | AA2: 0 | AB2: 0 | AC2: 0 | AD2: 0 | AE2: 0 | AF2: 0
C5: gray = no longer used
A6: use '1' to indicate that the state follows the rule | B6: Calibration Values for EPA LDV Stds Applied? | C6: Calibration Values for EPA HDV Stds Applied? | D6: Does this state follow: | G6: What model year does this state begin regulating:
D7: ACC I | E7: ACC II | F7: ACT | G7: ACC I Cars | H7: ACC II Cars | I7: Trucks
A8: Alabama | B8: =IF(E8>0,0,1) -> 1 | C8: =IF(F8=0,1) -> 1 | D8: 0 | E8: 0 | F8: 0
A9: Alaska | B9: =IF(E9>0,0,1) -> 1 | C9: =IF(F9=0,1) -> 1 | D9: 0 | E9: 0 | F9: 0
A10: Arizona | B10: =IF(E10>0,0,1) -> 1 | C10: =IF(F10=0,1) -> 1 | D10: 0 | E10: 0 | F10: 0
A11: Arkansas | B11: =IF(E11>0,0,1) -> 1 | C11: =IF(F11=0,1) -> 1 | D11: 0 | E11: 0 | F11: 0
A12: California | B12: =IF(E12>0,0,1) -> 1 | C12: =IF(F12=0,1) -> 1 | D12: 1 | E12: 0 | F12: 0 | G12: 1990 | H12: 2026 | I12: 2024
A13: Colorado | B13: =IF(E13>0,0,1) -> 1 | C13: =IF(F13=0,1) -> 1 | D13: 1 | E13: 0 | F13: 0 | G13: 2023 | H13: 2026 | I13: 2027
A14: Connecticut | B14: =IF(E14>0,0,1) -> 1 | C14: =IF(F14=0,1) -> 1 | D14: 1 | E14: 0 | F14: 0 | G14: 2008
A15: Delaware | B15: =IF(E15>0,0,1) -> 1 | C15: =IF(F15=0,1) -> 1 | D15: 0 | E15: 0 | F15: 0 | H15: 2026
A16: District of Columbia | B16: =IF(E16>0,0,1) -> 1 | C16: =IF(F16=0,1) -> 1 | D16: 0 | E16: 0 | F16: 0 | H16: 2026
A17: Florida | B17: =IF(E17>0,0,1) -> 1 | C17: =IF(F17=0,1) -> 1 | D17: 0 | E17: 0 | F17: 0
A18: Georgia | B18: =IF(E18>0,0,1) -> 1 | C18: =IF(F18=0,1) -> 1 | D18: 0 | E18: 0 | F18: 0
A19: Hawaii | B19: =IF(E19>0,0,1) -> 1 | C19: =IF(F19=0,1) -> 1 | D19: 0 | E19: 0 | F19: 0
A20: Idaho | B20: =IF(E20>0,0,1) -> 1 | C20: =IF(F20=0,1) -> 1 | D20: 0 | E20: 0 | F20: 0
A21: Illinois | B21: =IF(E21>0,0,1) -> 1 | C21: =IF(F21=0,1) -> 1 | D21: 0 | E21: 0 | F21: 0
A22: Indiana | B22: =IF(E22>0,0,1) -> 1 | C22: =IF(F22=0,1) -> 1 | D22: 0 | E22: 0 | F22: 0
A23: Iowa | B23: =IF(E23>0,0,1) -> 1 | C23: =IF(F23=0,1) -> 1 | D23: 0 | E23: 0 | F23: 0
A24: Kansas | B24: =IF(E24>0,0,1) -> 1 | C24: =IF(F24=0,1) -> 1 | D24: 0 | E24: 0 | F24: 0
A25: Kentucky | B25: =IF(E25>0,0,1) -> 1 | C25: =IF(F25=0,1) -> 1 | D25: 0 | E25: 0 | F25: 0
A26: Louisiana | B26: =IF(E26>0,0,1) -> 1 | C26: =IF(F26=0,1) -> 1 | D26: 0 | E26: 0 | F26: 0
A27: Maine | B27: =IF(E27>0,0,1) -> 1 | C27: =IF(F27=0,1) -> 1 | D27: 1 | E27: 0 | F27: 0 | G27: 2001
A28: Maryland | B28: =IF(E28>0,0,1) -> 1 | C28: =IF(F28=0,1) -> 1 | D28: 1 | E28: 0 | F28: 0 | G28: 2011 | H28: 2026 | I28: 2027
A29: Massachusetts | B29: =IF(E29>0,0,1) -> 1 | C29: =IF(F29=0,1) -> 1 | D29: 1 | E29: 0 | F29: 0 | G29: 1995 | H29: 2026 | I29: 2025
A30: Michigan | B30: =IF(E30>0,0,1) -> 1 | C30: =IF(F30=0,1) -> 1 | D30: 0 | E30: 0 | F30: 0
A31: Minnesota | B31: =IF(E31>0,0,1) -> 1 | C31: =IF(F31=0,1) -> 1 | D31: 1 | E31: 0 | F31: 0 | G31: 2025
A32: Mississippi | B32: =IF(E32>0,0,1) -> 1 | C32: =IF(F32=0,1) -> 1 | D32: 0 | E32: 0 | F32: 0
A33: Missouri | B33: =IF(E33>0,0,1) -> 1 | C33: =IF(F33=0,1) -> 1 | D33: 0 | E33: 0 | F33: 0
A34: Montana | B34: =IF(E34>0,0,1) -> 1 | C34: =IF(F34=0,1) -> 1 | D34: 0 | E34: 0 | F34: 0
A35: Nebraska | B35: =IF(E35>0,0,1) -> 1 | C35: =IF(F35=0,1) -> 1 | D35: 0 | E35: 0 | F35: 0
A36: Nevada | B36: =IF(E36>0,0,1) -> 1 | C36: =IF(F36=0,1) -> 1 | D36: 1 | E36: 0 | F36: 0 | G36: 2025
A37: New Hampshire | B37: =IF(E37>0,0,1) -> 1 | C37: =IF(F37=0,1) -> 1 | D37: 0 | E37: 0 | F37: 0
A38: New Jersey | B38: =IF(E38>0,0,1) -> 1 | C38: =IF(F38=0,1) -> 1 | D38: 1 | E38: 0 | F38: 0 | G38: 2009 | H38: 2026 | I38: 2025
A39: New Mexico | B39: =IF(E39>0,0,1) -> 1 | C39: =IF(F39=0,1) -> 1 | D39: 1 | E39: 0 | F39: 0 | G39: 2026 | H39: 2026 | I39: 2027
A40: New York | B40: =IF(E40>0,0,1) -> 1 | C40: =IF(F40=0,1) -> 1 | D40: 1 | E40: 0 | F40: 0 | G40: 1993 | H40: 2026 | I40: 2025
A41: North Carolina | B41: =IF(E41>0,0,1) -> 1 | C41: =IF(F41=0,1) -> 1 | D41: 0 | E41: 0 | F41: 0
A42: North Dakota | B42: =IF(E42>0,0,1) -> 1 | C42: =IF(F42=0,1) -> 1 | D42: 0 | E42: 0 | F42: 0
...

Sheet BRZSPbS-psgr-ldv
A1: Unit: % (share of vehicles that must be ZEVs) | B1: 2020 | C1: 2021 | D1: 2022 | E1: 2023 | F1: 2024 | G1: 2025 | H1: 2026 | I1: 2027 | J1: 2028 | K1: 2029 | L1: 2030 | M1: 2031 | N1: 2032 | O1: 2033 | P1: 2034 | Q1: 2035 | R1: 2036 | S1: 2037 | T1: 2038 | U1: 2039 | V1: 2040 | W1: 2041 | X1: 2042 | Y1: 2043 | Z1: 2044 | AA1: 2045 | AB1: 2046 | AC1: 2047 | AD1: 2048 | AE1: 2049 | AF1: 2050
A2: Alabama | B2: =IF(AND(INDEX('CA Standards and Followers'!$E$8:$E$67,MATCH($A2,'CA Standards and Followers'!$A$8:$A$67,0))=1,INDEX('CA Standards and Followers'!$H$8:$H$67,MATCH($A2,'CA Standards and Followers'!$A$8:$A$67,0))<=B$1),INDEX('CA Standards and Followers'!#REF!,MATCH(B$1,'CA Standards and Followers'!$1:$1,0)),IF(AND(INDEX('CA Standards and Followers'!$D$8:$D$67,MATCH($A2,'CA Standards and Followers'!$A$8:$A$67,0))=1,INDEX('CA Standards and Followers'!$G$8:$G$67,MATCH($A2,'CA Standards and Followers'!$A$8:$A$67,0))<=B$1),INDEX('CA Standards and Followers'!$2:$2,MATCH(B$1,'CA Standards and Followers'!$1:$1,0)),0)) -> 0 | C2: =IF(AND(INDEX('CA Standards and Followers'!$E$8:$E$67,MATCH($A2,'CA Standards and Followers'!$A$8:$A$67,0))=1,INDEX('CA Standards and Followers'!$H$8:$H$67,MATCH($A2,'CA Standards and Followers'!$A$8:$A$67,0))<=C$1),INDEX('CA Standards and Followers'!#REF!,MATCH(C$1,'CA Standards and Followers'!$1:$1,0)),IF(AND(INDEX('CA Standards and Followers'!$D$8:$D$67,MATCH($A2,'CA Standards and Followers'!$A$8:$A$67,0))=1,INDEX('CA Standards and Followers'!$G$8:$G$67,MATCH($A2,'CA Standards and Followers'!$A$8:$A$67,0))<=C$1),INDEX('CA Standards and Followers'!$2:$2,MATCH(C$1,'CA Standards and Followers'!$1:$1,0)),0)) -> 0 | D2: =IF(AND(INDEX('CA Standards and Followers'!$E$8:$E$67,MATCH($A2,'CA Standards and Followers'!$A$8:$A$67,0))=1,INDEX('CA Standards and Followers'!$H$8:$H$67,MATCH($A2,'CA Standards and Followers'!$A$8:$A$67,0))<=D$1),INDEX('CA Standards and Followers'!#REF!,MATCH(D$1,'CA Standards and Followers'!$1:$1,0)),IF(AND(INDEX('CA Standards and Followers'!$D$8:$D$67,MATCH($A2,'CA Standards and Followers'!$A$8:$A$67,0))=1,INDEX('CA Standards and Followers'!$G$8:$G$67,MATCH($A2,'CA Standards and Followers'!$A$8:$A$67,0))<=D$1),INDEX('CA Standards and Followers'!$2:$2,MATCH(D$1,'CA Standards and Followers'!$1:$1,0)),0)) -> 0 | E2: =IF(AND(INDEX('CA Standards and Followers'!$E$8:$E$67,MATCH($A2,'CA Standards and Followers'!$A$8:$A$67,0))=1,INDEX('CA Standards and Followers'!$H$8:$H$67,MATCH($A2,'CA Standards and Followers'!$A$8:$A$67,0))<=E$1),INDEX('CA Standards and Followers'!#REF!,MATCH(E$1,'CA Standards and Followers'!$1:$1,0)),IF(AND(INDEX('CA Standards and Followers'!$D$8:$D$67,MATCH($A2,'CA Standards and Followers'!$A$8:$A$67,0))=1,INDEX('CA Standards and Followers'!$G$8:$G$67,MATCH($A2,'CA Standards and Followers'!$A$8:$A$67,0))<=E$1),INDEX('CA Standards and Followers'!$2:$2,MATCH(E$1,'CA Standards and Followers'!$1:$1,0)),0)) -> 0 | F2: =IF(AND(INDEX('CA Standards and Followers'!$E$8:$E$67,MATCH($A2,'CA Standards and Followers'!$A$8:$A$67,0))=1,INDEX('CA Standards and Followers'!$H$8:$H$67,MATCH($A2,'CA Standards and Followers'!$A$8:$A$67,0))<=F$1),INDEX('CA Standards and Followers'!#REF!,MATCH(F$1,'CA Standards and Followers'!$1:$1,0)),IF(AND(INDEX('CA Standards and Followers'!$D$8:$D$67,MATCH($A2,'CA Standards and Followers'!$A$8:$A$67,0))=1,INDEX('CA Standards and Followers'!$G$8:$G$67,MATCH($A2,'CA Standards and Followers'!$A$8:$A$67,0))<=F$1),INDEX('CA Standards and Followers'!$2:$2,MATCH(F$1,'CA Standards and Followers'!$1:$1,0)),0)) -> 0 | G2: =IF(AND(INDEX('CA Standards and Followers'!$E$8:$E$67,MATCH($A2,'CA Standards and Followers'!$A$8:$A$67,0))=1,INDEX('CA Standards and Followers'!$H$8:$H$67,MATCH($A2,'CA Standards and Followers'!$A$8:$A$67,0))<=G$1),INDEX('CA Standards and Followers'!#REF!,MATCH(G$1,'CA Standards and Followers'!$1:$1,0)),IF(AND(INDEX('CA Standards and Followers'!$D$8:$D$67,MATCH($A2,'CA Standards and Followers'!$A$8:$A$67,0))=1,INDEX('CA Standards and Followers'!$G$8:$G$67,MATCH($A2,'CA Standards and Followers'!$A$8:$A$67,0))<=G$1),INDEX('CA Standards and Followers'!$2:$2,MATCH(G$1,'CA Standards and Followers'!$1:$1,0)),0)) -> 0 | H2: =IF(AND(INDEX('CA Standards and Followers'!$E$8:$E$67,MATCH($A2,'CA Standards and Followers'!$A$8:$A$67,0))=1,INDEX('CA Standards and Followers'!$H$8:$H$67,MATCH($A2,'CA Standards and Followers'!$A$8:$A$67,0))<=H$1),INDEX('CA Standards and Followers'!#REF!,MATCH(H$1,'CA Standards and Followers'!$1:$1,0)),IF(AND(INDEX('CA Standards and Followers'!$D$8:$D$67,MATCH($A2,'CA Standards and Followers'!$A$8:$A$67,0))=1,INDEX('CA Standards and Followers'!$G$8:$G$67,MATCH($A2,'CA Standards and Followers'!$A$8:$A$67,0))<=H$1),INDEX('CA Standards and Followers'!$2:$2,MATCH(H$1,'CA Standards and Followers'!$1:$1,0)),0)) -> 0 | I2: =IF(AND(INDEX('CA Standards and Followers'!$E$8:$E$67,MATCH($A2,'CA Standards and Followers'!$A$8:$A$67,0))=1,INDEX('CA Standards and Followers'!$H$8:$H$67,MATCH($A2,'CA Standards and Followers'!$A$8:$A$67,0))<=I$1),INDEX('CA Standards and Followers'!#REF!,MATCH(I$1,'CA Standards and Followers'!$1:$1,0)),IF(AND(INDEX('CA Standards and Followers'!$D$8:$D$67,MATCH($A2,'CA Standards and Followers'!$A$8:$A$67,0))=1,INDEX('CA Standards and Followers'!$G$8:$G$67,MATCH($A2,'CA Standards and Followers'!$A$8:$A$67,0))<=I$1),INDEX('CA Standards and Followers'!$2:$2,MATCH(I$1,'CA Standards and Followers'!$1:$1,0)),0)) -> 0 | ... AF2: =IF(AND(INDEX('CA Standards and Followers'!$E$8:$E$67,MATCH($A2,'CA Standards and Followers'!$A$8:$A$67,0))=1,INDEX('CA Standards and Followers'!$H$8:$H$67,MATCH($A2,'CA Standards and Followers'!$A$8:$A$67,0))<=AF$1),INDEX('CA Standards and Followers'!#REF!,MATCH(AF$1,'CA Standards and Followers'!$1:$1,0)),IF(AND(INDEX('CA Standards and Followers'!$D$8:$D$67,MATCH($A2,'CA Standards and Followers'!$A$8:$A$67,0))=1,INDEX('CA Standards and Followers'!$G$8:$G$67,MATCH($A2,'CA Standards and Followers'!$A$8:$A$67,0))<=AF$1),INDEX('CA Standards and Followers'!$2:$2,MATCH(AF$1,'CA Standards and Followers'!$1:$1,0)),0)) -> 0
A3: Alaska | B3: =IF(AND(INDEX('CA Standards and Followers'!$E$8:$E$67,MATCH($A3,'CA Standards and Followers'!$A$8:$A$67,0))=1,INDEX('CA Standards and Followers'!$H$8:$H$67,MATCH($A3,'CA Standards and Followers'!$A$8:$A$67,0))<=B$1),INDEX('CA Standards and Followers'!#REF!,MATCH(B$1,'CA Standards and Followers'!$1:$1,0)),IF(AND(INDEX('CA Standards and Followers'!$D$8:$D$67,MATCH($A3,'CA Standards and Followers'!$A$8:$A$67,0))=1,INDEX('CA Standards and Followers'!$G$8:$G$67,MATCH($A3,'CA Standards and Followers'!$A$8:$A$67,0))<=B$1),INDEX('CA Standards and Followers'!$2:$2,MATCH(B$1,'CA Standards and Followers'!$1:$1,0)),0)) -> 0 | C3: =IF(AND(INDEX('CA Standards and Followers'!$E$8:$E$67,MATCH($A3,'CA Standards and Followers'!$A$8:$A$67,0))=1,INDEX('CA Standards and Followers'!$H$8:$H$67,MATCH($A3,'CA Standards and Followers'!$A$8:$A$67,0))<=C$1),INDEX('CA Standards and Followers'!#REF!,MATCH(C$1,'CA Standards and Followers'!$1:$1,0)),IF(AND(INDEX('CA Standards and Followers'!$D$8:$D$67,MATCH($A3,'CA Standards and Followers'!$A$8:$A$67,0))=1,INDEX('CA Standards and Followers'!$G$8:$G$67,MATCH($A3,'CA Standards and Followers'!$A$8:$A$67,0))<=C$1),INDEX('CA Standards and Followers'!$2:$2,MATCH(C$1,'CA Standards and Followers'!$1:$1,0)),0)) -> 0 | D3: =IF(AND(INDEX('CA Standards and Followers'!$E$8:$E$67,MATCH($A3,'CA Standards and Followers'!$A$8:$A$67,0))=1,INDEX('CA Standards and Followers'!$H$8:$H$67,MATCH($A3,'CA Standards and Followers'!$A$8:$A$67,0))<=D$1),INDEX('CA Standards and Followers'!#REF!,MATCH(D$1,'CA Standards and Followers'!$1:$1,0)),IF(AND(INDEX('CA Standards and Followers'!$D$8:$D$67,MATCH($A3,'CA Standards and Followers'!$A$8:$A$67,0))=1,INDEX('CA Standards and Followers'!$G$8:$G$67,MATCH($A3,'CA Standards and Followers'!$A$8:$A$67,0))<=D$1),INDEX('CA Standards and Followers'!$2:$2,MATCH(D$1,'CA Standards and Followers'!$1:$1,0)),0)) -> 0 | E3: =IF(AND(INDEX('CA Standards and Followers'!$E$8:$E$67,MATCH($A3,'CA Standards and Followers'!$A$8:$A$67,0))=1,INDEX('CA Standards and Followers'!$H$8:$H$67,MATCH($A3,'CA Standards and Followers'!$A$8:$A$67,0))<=E$1),INDEX('CA Standards and Followers'!#REF!,MATCH(E$1,'CA Standards and Followers'!$1:$1,0)),IF(AND(INDEX('CA Standards and Followers'!$D$8:$D$67,MATCH($A3,'CA Standards and Followers'!$A$8:$A$67,0))=1,INDEX('CA Standards and Followers'!$G$8:$G$67,MATCH($A3,'CA Standards and Followers'!$A$8:$A$67,0))<=E$1),INDEX('CA Standards and Followers'!$2:$2,MATCH(E$1,'CA Standards and Followers'!$1:$1,0)),0)) -> 0 | F3: =IF(AND(INDEX('CA Standards and Followers'!$E$8:$E$67,MATCH($A3,'CA Standards and Followers'!$A$8:$A$67,0))=1,INDEX('CA Standards and Followers'!$H$8:$H$67,MATCH($A3,'CA Standards and Followers'!$A$8:$A$67,0))<=F$1),INDEX('CA Standards and Followers'!#REF!,MATCH(F$1,'CA Standards and Followers'!$1:$1,0)),IF(AND(INDEX('CA Standards and Followers'!$D$8:$D$67,MATCH($A3,'CA Standards and Followers'!$A$8:$A$67,0))=1,INDEX('CA Standards and Followers'!$G$8:$G$67,MATCH($A3,'CA Standards and Followers'!$A$8:$A$67,0))<=F$1),INDEX('CA Standards and Followers'!$2:$2,MATCH(F$1,'CA Standards and Followers'!$1:$1,0)),0)) -> 0 | G3: =IF(AND(INDEX('CA Standards and Followers'!$E$8:$E$67,MATCH($A3,'CA Standards and Followers'!$A$8:$A$67,0))=1,INDEX('CA Standards and Followers'!$H$8:$H$67,MATCH($A3,'CA Standards and Followers'!$A$8:$A$67,0))<=G$1),INDEX('CA Standards and Followers'!#REF!,MATCH(G$1,'CA Standards and Followers'!$1:$1,0)),IF(AND(INDEX('CA Standards and Followers'!$D$8:$D$67,MATCH($A3,'CA Standards and Followers'!$A$8:$A$67,0))=1,INDEX('CA Standards and Followers'!$G$8:$G$67,MATCH($A3,'CA Standards and Followers'!$A$8:$A$67,0))<=G$1),INDEX('CA Standards and Followers'!$2:$2,MATCH(G$1,'CA Standards and Followers'!$1:$1,0)),0)) -> 0 | H3: =IF(AND(INDEX('CA Standards and Followers'!$E$8:$E$67,MATCH($A3,'CA Standards and Followers'!$A$8:$A$67,0))=1,INDEX('CA Standards and Followers'!$H$8:$H$67,MATCH($A3,'CA Standards and Followers'!$A$8:$A$67,0))<=H$1),INDEX('CA Standards and Followers'!#REF!,MATCH(H$1,'CA Standards and Followers'!$1:$1,0)),IF(AND(INDEX('CA Standards and Followers'!$D$8:$D$67,MATCH($A3,'CA Standards and Followers'!$A$8:$A$67,0))=1,INDEX('CA Standards and Followers'!$G$8:$G$67,MATCH($A3,'CA Standards and Followers'!$A$8:$A$67,0))<=H$1),INDEX('CA Standards and Followers'!$2:$2,MATCH(H$1,'CA Standards and Followers'!$1:$1,0)),0)) -> 0 | I3: =IF(AND(INDEX('CA Standards and Followers'!$E$8:$E$67,MATCH($A3,'CA Standards and Followers'!$A$8:$A$67,0))=1,INDEX('CA Standards and Followers'!$H$8:$H$67,MATCH($A3,'CA Standards and Followers'!$A$8:$A$67,0))<=I$1),INDEX('CA Standards and Followers'!#REF!,MATCH(I$1,'CA Standards and Followers'!$1:$1,0)),IF(AND(INDEX('CA Standards and Followers'!$D$8:$D$67,MATCH($A3,'CA Standards and Followers'!$A$8:$A$67,0))=1,INDEX('CA Standards and Followers'!$G$8:$G$67,MATCH($A3,'CA Standards and Followers'!$A$8:$A$67,0))<=I$1),INDEX('CA Standards and Followers'!$2:$2,MATCH(I$1,'CA Standards and Followers'!$1:$1,0)),0)) -> 0 | ... AF3: =IF(AND(INDEX('CA Standards and Followers'!$E$8:$E$67,MATCH($A3,'CA Standards and Followers'!$A$8:$A$67,0))=1,INDEX('CA Standards and Followers'!$H$8:$H$67,MATCH($A3,'CA Standards and Followers'!$A$8:$A$67,0))<=AF$1),INDEX('CA Standards and Followers'!#REF!,MATCH(AF$1,'CA Standards and Followers'!$1:$1,0)),IF(AND(INDEX('CA Standards and Followers'!$D$8:$D$67,MATCH($A3,'CA Standards and Followers'!$A$8:$A$67,0))=1,INDEX('CA Standards and Followers'!$G$8:$G$67,MATCH($A3,'CA Standards and Followers'!$A$8:$A$67,0))<=AF$1),INDEX('CA Standards and Followers'!$2:$2,MATCH(AF$1,'CA Standards and Followers'!$1:$1,0)),0)) -> 0
A4: Arizona | B4: =IF(AND(INDEX('CA Standards and Followers'!$E$8:$E$67,MATCH($A4,'CA Standards and Followers'!$A$8:$A$67,0))=1,INDEX('CA Standards and Followers'!$H$8:$H$67,MATCH($A4,'CA Standards and Followers'!$A$8:$A$67,0))<=B$1),INDEX('CA Standards and Followers'!#REF!,MATCH(B$1,'CA Standards and Followers'!$1:$1,0)),IF(AND(INDEX('CA Standards and Followers'!$D$8:$D$67,MATCH($A4,'CA Standards and Followers'!$A$8:$A$67,0))=1,INDEX('CA Standards and Followers'!$G$8:$G$67,MATCH($A4,'CA Standards and Followers'!$A$8:$A$67,0))<=B$1),INDEX('CA Standards and Followers'!$2:$2,MATCH(B$1,'CA Standards and Followers'!$1:$1,0)),0)) -> 0 | C4: =IF(AND(INDEX('CA Standards and Followers'!$E$8:$E$67,MATCH($A4,'CA Standards and Followers'!$A$8:$A$67,0))=1,INDEX('CA Standards and Followers'!$H$8:$H$67,MATCH($A4,'CA Standards and Followers'!$A$8:$A$67,0))<=C$1),INDEX('CA Standards and Followers'!#REF!,MATCH(C$1,'CA Standards and Followers'!$1:$1,0)),IF(AND(INDEX('CA Standards and Followers'!$D$8:$D$67,MATCH($A4,'CA Standards and Followers'!$A$8:$A$67,0))=1,INDEX('CA Standards and Followers'!$G$8:$G$67,MATCH($A4,'CA Standards and Followers'!$A$8:$A$67,0))<=C$1),INDEX('CA Standards and Followers'!$2:$2,MATCH(C$1,'CA Standards and Followers'!$1:$1,0)),0)) -> 0 | D4: =IF(AND(INDEX('CA Standards and Followers'!$E$8:$E$67,MATCH($A4,'CA Standards and Followers'!$A$8:$A$67,0))=1,INDEX('CA Standards and Followers'!$H$8:$H$67,MATCH($A4,'CA Standards and Followers'!$A$8:$A$67,0))<=D$1),INDEX('CA Standards and Followers'!#REF!,MATCH(D$1,'CA Standards and Followers'!$1:$1,0)),IF(AND(INDEX('CA Standards and Followers'!$D$8:$D$67,MATCH($A4,'CA Standards and Followers'!$A$8:$A$67,0))=1,INDEX('CA Standards and Followers'!$G$8:$G$67,MATCH($A4,'CA Standards and Followers'!$A$8:$A$67,0))<=D$1),INDEX('CA Standards and Followers'!$2:$2,MATCH(D$1,'CA Standards and Followers'!$1:$1,0)),0)) -> 0 | E4: =IF(AND(INDEX('CA Standards and Followers'!$E$8:$E$67,MATCH($A4,'CA Standards and Followers'!$A$8:$A$67,0))=1,INDEX('CA Standards and Followers'!$H$8:$H$67,MATCH($A4,'CA Standards and Followers'!$A$8:$A$67,0))<=E$1),INDEX('CA Standards and Followers'!#REF!,MATCH(E$1,'CA Standards and Followers'!$1:$1,0)),IF(AND(INDEX('CA Standards and Followers'!$D$8:$D$67,MATCH($A4,'CA Standards and Followers'!$A$8:$A$67,0))=1,INDEX('CA Standards and Followers'!$G$8:$G$67,MATCH($A4,'CA Standards and Followers'!$A$8:$A$67,0))<=E$1),INDEX('CA Standards and Followers'!$2:$2,MATCH(E$1,'CA Standards and Followers'!$1:$1,0)),0)) -> 0 | F4: =IF(AND(INDEX('CA Standards and Followers'!$E$8:$E$67,MATCH($A4,'CA Standards and Followers'!$A$8:$A$67,0))=1,INDEX('CA Standards and Followers'!$H$8:$H$67,MATCH($A4,'CA Standards and Followers'!$A$8:$A$67,0))<=F$1),INDEX('CA Standards and Followers'!#REF!,MATCH(F$1,'CA Standards and Followers'!$1:$1,0)),IF(AND(INDEX('CA Standards and Followers'!$D$8:$D$67,MATCH($A4,'CA Standards and Followers'!$A$8:$A$67,0))=1,INDEX('CA Standards and Followers'!$G$8:$G$67,MATCH($A4,'CA Standards and Followers'!$A$8:$A$67,0))<=F$1),INDEX('CA Standards and Followers'!$2:$2,MATCH(F$1,'CA Standards and Followers'!$1:$1,0)),0)) -> 0 | G4: =IF(AND(INDEX('CA Standards and Followers'!$E$8:$E$67,MATCH($A4,'CA Standards and Followers'!$A$8:$A$67,0))=1,INDEX('CA Standards and Followers'!$H$8:$H$67,MATCH($A4,'CA Standards and Followers'!$A$8:$A$67,0))<=G$1),INDEX('CA Standards and Followers'!#REF!,MATCH(G$1,'CA Standards and Followers'!$1:$1,0)),IF(AND(INDEX('CA Standards and Followers'!$D$8:$D$67,MATCH($A4,'CA Standards and Followers'!$A$8:$A$67,0))=1,INDEX('CA Standards and Followers'!$G$8:$G$67,MATCH($A4,'CA Standards and Followers'!$A$8:$A$67,0))<=G$1),INDEX('CA Standards and Followers'!$2:$2,MATCH(G$1,'CA Standards and Followers'!$1:$1,0)),0)) -> 0 | H4: =IF(AND(INDEX('CA Standards and Followers'!$E$8:$E$67,MATCH($A4,'CA Standards and Followers'!$A$8:$A$67,0))=1,INDEX('CA Standards and Followers'!$H$8:$H$67,MATCH($A4,'CA Standards and Followers'!$A$8:$A$67,0))<=H$1),INDEX('CA Standards and Followers'!#REF!,MATCH(H$1,'CA Standards and Followers'!$1:$1,0)),IF(AND(INDEX('CA Standards and Followers'!$D$8:$D$67,MATCH($A4,'CA Standards and Followers'!$A$8:$A$67,0))=1,INDEX('CA Standards and Followers'!$G$8:$G$67,MATCH($A4,'CA Standards and Followers'!$A$8:$A$67,0))<=H$1),INDEX('CA Standards and Followers'!$2:$2,MATCH(H$1,'CA Standards and Followers'!$1:$1,0)),0)) -> 0 | I4: =IF(AND(INDEX('CA Standards and Followers'!$E$8:$E$67,MATCH($A4,'CA Standards and Followers'!$A$8:$A$67,0))=1,INDEX('CA Standards and Followers'!$H$8:$H$67,MATCH($A4,'CA Standards and Followers'!$A$8:$A$67,0))<=I$1),INDEX('CA Standards and Followers'!#REF!,MATCH(I$1,'CA Standards and Followers'!$1:$1,0)),IF(AND(INDEX('CA Standards and Followers'!$D$8:$D$67,MATCH($A4,'CA Standards and Followers'!$A$8:$A$67,0))=1,INDEX('CA Standards and Followers'!$G$8:$G$67,MATCH($A4,'CA Standards and Followers'!$A$8:$A$67,0))<=I$1),INDEX('CA Standards and Followers'!$2:$2,MATCH(I$1,'CA Standards and Followers'!$1:$1,0)),0)) -> 0 | ... AF4: =IF(AND(INDEX('CA Standards and Followers'!$E$8:$E$67,MATCH($A4,'CA Standards and Followers'!$A$8:$A$67,0))=1,INDEX('CA Standards and Followers'!$H$8:$H$67,MATCH($A4,'CA Standards and Followers'!$A$8:$A$67,0))<=AF$1),INDEX('CA Standards and Followers'!#REF!,MATCH(AF$1,'CA Standards and Followers'!$1:$1,0)),IF(AND(INDEX('CA Standards and Followers'!$D$8:$D$67,MATCH($A4,'CA Standards and Followers'!$A$8:$A$67,0))=1,INDEX('CA Standards and Followers'!$G$8:$G$67,MATCH($A4,'CA Standards and Followers'!$A$8:$A$67,0))<=AF$1),INDEX('CA Standards and Followers'!$2:$2,MATCH(AF$1,'CA Standards and Followers'!$1:$1,0)),0)) -> 0
A5: Arkansas | B5: =IF(AND(INDEX('CA Standards and Followers'!$E$8:$E$67,MATCH($A5,'CA Standards and Followers'!$A$8:$A$67,0))=1,INDEX('CA Standards and Followers'!$H$8:$H$67,MATCH($A5,'CA Standards and Followers'!$A$8:$A$67,0))<=B$1),INDEX('CA Standards and Followers'!#REF!,MATCH(B$1,'CA Standards and Followers'!$1:$1,0)),IF(AND(INDEX('CA Standards and Followers'!$D$8:$D$67,MATCH($A5,'CA Standards and Followers'!$A$8:$A$67,0))=1,INDEX('CA Standards and Followers'!$G$8:$G$67,MATCH($A5,'CA Standards and Followers'!$A$8:$A$67,0))<=B$1),INDEX('CA Standards and Followers'!$2:$2,MATCH(B$1,'CA Standards and Followers'!$1:$1,0)),0)) -> 0 | C5: =IF(AND(INDEX('CA Standards and Followers'!$E$8:$E$67,MATCH($A5,'CA Standards and Followers'!$A$8:$A$67,0))=1,INDEX('CA Standards and Followers'!$H$8:$H$67,MATCH($A5,'CA Standards and Followers'!$A$8:$A$67,0))<=C$1),INDEX('CA Standards and Followers'!#REF!,MATCH(C$1,'CA Standards and Followers'!$1:$1,0)),IF(AND(INDEX('CA Standards and Followers'!$D$8:$D$67,MATCH($A5,'CA Standards and Followers'!$A$8:$A$67,0))=1,INDEX('CA Standards and Followers'!$G$8:$G$67,MATCH($A5,'CA Standards and Followers'!$A$8:$A$67,0))<=C$1),INDEX('CA Standards and Followers'!$2:$2,MATCH(C$1,'CA Standards and Followers'!$1:$1,0)),0)) -> 0 | D5: =IF(AND(INDEX('CA Standards and Followers'!$E$8:$E$67,MATCH($A5,'CA Standards and Followers'!$A$8:$A$67,0))=1,INDEX('CA Standards and Followers'!$H$8:$H$67,MATCH($A5,'CA Standards and Followers'!$A$8:$A$67,0))<=D$1),INDEX('CA Standards and Followers'!#REF!,MATCH(D$1,'CA Standards and Followers'!$1:$1,0)),IF(AND(INDEX('CA Standards and Followers'!$D$8:$D$67,MATCH($A5,'CA Standards and Followers'!$A$8:$A$67,0))=1,INDEX('CA Standards and Followers'!$G$8:$G$67,MATCH($A5,'CA Standards and Followers'!$A$8:$A$67,0))<=D$1),INDEX('CA Standards and Followers'!$2:$2,MATCH(D$1,'CA Standards and Followers'!$1:$1,0)),0)) -> 0 | E5: =IF(AND(INDEX('CA Standards and Followers'!$E$8:$E$67,MATCH($A5,'CA Standards and Followers'!$A$8:$A$67,0))=1,INDEX('CA Standards and Followers'!$H$8:$H$67,MATCH($A5,'CA Standards and Followers'!$A$8:$A$67,0))<=E$1),INDEX('CA Standards and Followers'!#REF!,MATCH(E$1,'CA Standards and Followers'!$1:$1,0)),IF(AND(INDEX('CA Standards and Followers'!$D$8:$D$67,MATCH($A5,'CA Standards and Followers'!$A$8:$A$67,0))=1,INDEX('CA Standards and Followers'!$G$8:$G$67,MATCH($A5,'CA Standards and Followers'!$A$8:$A$67,0))<=E$1),INDEX('CA Standards and Followers'!$2:$2,MATCH(E$1,'CA Standards and Followers'!$1:$1,0)),0)) -> 0 | F5: =IF(AND(INDEX('CA Standards and Followers'!$E$8:$E$67,MATCH($A5,'CA Standards and Followers'!$A$8:$A$67,0))=1,INDEX('CA Standards and Followers'!$H$8:$H$67,MATCH($A5,'CA Standards and Followers'!$A$8:$A$67,0))<=F$1),INDEX('CA Standards and Followers'!#REF!,MATCH(F$1,'CA Standards and Followers'!$1:$1,0)),IF(AND(INDEX('CA Standards and Followers'!$D$8:$D$67,MATCH($A5,'CA Standards and Followers'!$A$8:$A$67,0))=1,INDEX('CA Standards and Followers'!$G$8:$G$67,MATCH($A5,'CA Standards and Followers'!$A$8:$A$67,0))<=F$1),INDEX('CA Standards and Followers'!$2:$2,MATCH(F$1,'CA Standards and Followers'!$1:$1,0)),0)) -> 0 | G5: =IF(AND(INDEX('CA Standards and Followers'!$E$8:$E$67,MATCH($A5,'CA Standards and Followers'!$A$8:$A$67,0))=1,INDEX('CA Standards and Followers'!$H$8:$H$67,MATCH($A5,'CA Standards and Followers'!$A$8:$A$67,0))<=G$1),INDEX('CA Standards and Followers'!#REF!,MATCH(G$1,'CA Standards and Followers'!$1:$1,0)),IF(AND(INDEX('CA Standards and Followers'!$D$8:$D$67,MATCH($A5,'CA Standards and Followers'!$A$8:$A$67,0))=1,INDEX('CA Standards and Followers'!$G$8:$G$67,MATCH($A5,'CA Standards and Followers'!$A$8:$A$67,0))<=G$1),INDEX('CA Standards and Followers'!$2:$2,MATCH(G$1,'CA Standards and Followers'!$1:$1,0)),0)) -> 0 | H5: =IF(AND(INDEX('CA Standards and Followers'!$E$8:$E$67,MATCH($A5,'CA Standards and Followers'!$A$8:$A$67,0))=1,INDEX('CA Standards and Followers'!$H$8:$H$67,MATCH($A5,'CA Standards and Followers'!$A$8:$A$67,0))<=H$1),INDEX('CA Standards and Followers'!#REF!,MATCH(H$1,'CA Standards and Followers'!$1:$1,0)),IF(AND(INDEX('CA Standards and Followers'!$D$8:$D$67,MATCH($A5,'CA Standards and Followers'!$A$8:$A$67,0))=1,INDEX('CA Standards and Followers'!$G$8:$G$67,MATCH($A5,'CA Standards and Followers'!$A$8:$A$67,0))<=H$1),INDEX('CA Standards and Followers'!$2:$2,MATCH(H$1,'CA Standards and Followers'!$1:$1,0)),0)) -> 0 | I5: =IF(AND(INDEX('CA Standards and Followers'!$E$8:$E$67,MATCH($A5,'CA Standards and Followers'!$A$8:$A$67,0))=1,INDEX('CA Standards and Followers'!$H$8:$H$67,MATCH($A5,'CA Standards and Followers'!$A$8:$A$67,0))<=I$1),INDEX('CA Standards and Followers'!#REF!,MATCH(I$1,'CA Standards and Followers'!$1:$1,0)),IF(AND(INDEX('CA Standards and Followers'!$D$8:$D$67,MATCH($A5,'CA Standards and Followers'!$A$8:$A$67,0))=1,INDEX('CA Standards and Followers'!$G$8:$G$67,MATCH($A5,'CA Standards and Followers'!$A$8:$A$67,0))<=I$1),INDEX('CA Standards and Followers'!$2:$2,MATCH(I$1,'CA Standards and Followers'!$1:$1,0)),0)) -> 0 | ... AF5: =IF(AND(INDEX('CA Standards and Followers'!$E$8:$E$67,MATCH($A5,'CA Standards and Followers'!$A$8:$A$67,0))=1,INDEX('CA Standards and Followers'!$H$8:$H$67,MATCH($A5,'CA Standards and Followers'!$A$8:$A$67,0))<=AF$1),INDEX('CA Standards and Followers'!#REF!,MATCH(AF$1,'CA Standards and Followers'!$1:$1,0)),IF(AND(INDEX('CA Standards and Followers'!$D$8:$D$67,MATCH($A5,'CA Standards and Followers'!$A$8:$A$67,0))=1,INDEX('CA Standards and Followers'!$G$8:$G$67,MATCH($A5,'CA Standards and Followers'!$A$8:$A$67,0))<=AF$1),INDEX('CA Standards and Followers'!$2:$2,MATCH(AF$1,'CA Standards and Followers'!$1:$1,0)),0)) -> 0
A6: California | B6: =IF(AND(INDEX('CA Standards and Followers'!$E$8:$E$67,MATCH($A6,'CA Standards and Followers'!$A$8:$A$67,0))=1,INDEX('CA Standards and Followers'!$H$8:$H$67,MATCH($A6,'CA Standards and Followers'!$A$8:$A$67,0))<=B$1),INDEX('CA Standards and Followers'!#REF!,MATCH(B$1,'CA Standards and Followers'!$1:$1,0)),IF(AND(INDEX('CA Standards and Followers'!$D$8:$D$67,MATCH($A6,'CA Standards and Followers'!$A$8:$A$67,0))=1,INDEX('CA Standards and Followers'!$G$8:$G$67,MATCH($A6,'CA Standards and Followers'!$A$8:$A$67,0))<=B$1),INDEX('CA Standards and Followers'!$2:$2,MATCH(B$1,'CA Standards and Followers'!$1:$1,0)),0)) -> 0 | C6: =IF(AND(INDEX('CA Standards and Followers'!$E$8:$E$67,MATCH($A6,'CA Standards and Followers'!$A$8:$A$67,0))=1,INDEX('CA Standards and Followers'!$H$8:$H$67,MATCH($A6,'CA Standards and Followers'!$A$8:$A$67,0))<=C$1),INDEX('CA Standards and Followers'!#REF!,MATCH(C$1,'CA Standards and Followers'!$1:$1,0)),IF(AND(INDEX('CA Standards and Followers'!$D$8:$D$67,MATCH($A6,'CA Standards and Followers'!$A$8:$A$67,0))=1,INDEX('CA Standards and Followers'!$G$8:$G$67,MATCH($A6,'CA Standards and Followers'!$A$8:$A$67,0))<=C$1),INDEX('CA Standards and Followers'!$2:$2,MATCH(C$1,'CA Standards and Followers'!$1:$1,0)),0)) -> 0 | D6: =IF(AND(INDEX('CA Standards and Followers'!$E$8:$E$67,MATCH($A6,'CA Standards and Followers'!$A$8:$A$67,0))=1,INDEX('CA Standards and Followers'!$H$8:$H$67,MATCH($A6,'CA Standards and Followers'!$A$8:$A$67,0))<=D$1),INDEX('CA Standards and Followers'!#REF!,MATCH(D$1,'CA Standards and Followers'!$1:$1,0)),IF(AND(INDEX('CA Standards and Followers'!$D$8:$D$67,MATCH($A6,'CA Standards and Followers'!$A$8:$A$67,0))=1,INDEX('CA Standards and Followers'!$G$8:$G$67,MATCH($A6,'CA Standards and Followers'!$A$8:$A$67,0))<=D$1),INDEX('CA Standards and Followers'!$2:$2,MATCH(D$1,'CA Standards and Followers'!$1:$1,0)),0)) -> 0 | E6: =IF(AND(INDEX('CA Standards and Followers'!$E$8:$E$67,MATCH($A6,'CA Standards and Followers'!$A$8:$A$67,0))=1,INDEX('CA Standards and Followers'!$H$8:$H$67,MATCH($A6,'CA Standards and Followers'!$A$8:$A$67,0))<=E$1),INDEX('CA Standards and Followers'!#REF!,MATCH(E$1,'CA Standards and Followers'!$1:$1,0)),IF(AND(INDEX('CA Standards and Followers'!$D$8:$D$67,MATCH($A6,'CA Standards and Followers'!$A$8:$A$67,0))=1,INDEX('CA Standards and Followers'!$G$8:$G$67,MATCH($A6,'CA Standards and Followers'!$A$8:$A$67,0))<=E$1),INDEX('CA Standards and Followers'!$2:$2,MATCH(E$1,'CA Standards and Followers'!$1:$1,0)),0)) -> 0 | F6: =IF(AND(INDEX('CA Standards and Followers'!$E$8:$E$67,MATCH($A6,'CA Standards and Followers'!$A$8:$A$67,0))=1,INDEX('CA Standards and Followers'!$H$8:$H$67,MATCH($A6,'CA Standards and Followers'!$A$8:$A$67,0))<=F$1),INDEX('CA Standards and Followers'!#REF!,MATCH(F$1,'CA Standards and Followers'!$1:$1,0)),IF(AND(INDEX('CA Standards and Followers'!$D$8:$D$67,MATCH($A6,'CA Standards and Followers'!$A$8:$A$67,0))=1,INDEX('CA Standards and Followers'!$G$8:$G$67,MATCH($A6,'CA Standards and Followers'!$A$8:$A$67,0))<=F$1),INDEX('CA Standards and Followers'!$2:$2,MATCH(F$1,'CA Standards and Followers'!$1:$1,0)),0)) -> 0.08 | G6: =IF(AND(INDEX('CA Standards and Followers'!$E$8:$E$67,MATCH($A6,'CA Standards and Followers'!$A$8:$A$67,0))=1,INDEX('CA Standards and Followers'!$H$8:$H$67,MATCH($A6,'CA Standards and Followers'!$A$8:$A$67,0))<=G$1),INDEX('CA Standards and Followers'!#REF!,MATCH(G$1,'CA Standards and Followers'!$1:$1,0)),IF(AND(INDEX('CA Standards and Followers'!$D$8:$D$67,MATCH($A6,'CA Standards and Followers'!$A$8:$A$67,0))=1,INDEX('CA Standards and Followers'!$G$8:$G$67,MATCH($A6,'CA Standards and Followers'!$A$8:$A$67,0))<=G$1),INDEX('CA Standards and Followers'!$2:$2,MATCH(G$1,'CA Standards and Followers'!$1:$1,0)),0)) -> 0.08 | H6: =IF(AND(INDEX('CA Standards and Followers'!$E$8:$E$67,MATCH($A6,'CA Standards and Followers'!$A$8:$A$67,0))=1,INDEX('CA Standards and Followers'!$H$8:$H$67,MATCH($A6,'CA Standards and Followers'!$A$8:$A$67,0))<=H$1),INDEX('CA Standards and Followers'!#REF!,MATCH(H$1,'CA Standards and Followers'!$1:$1,0)),IF(AND(INDEX('CA Standards and Followers'!$D$8:$D$67,MATCH($A6,'CA Standards and Followers'!$A$8:$A$67,0))=1,INDEX('CA Standards and Followers'!$G$8:$G$67,MATCH($A6,'CA Standards and Followers'!$A$8:$A$67,0))<=H$1),INDEX('CA Standards and Followers'!$2:$2,MATCH(H$1,'CA Standards and Followers'!$1:$1,0)),0)) -> 0 | I6: =IF(AND(INDEX('CA Standards and Followers'!$E$8:$E$67,MATCH($A6,'CA Standards and Followers'!$A$8:$A$67,0))=1,INDEX('CA Standards and Followers'!$H$8:$H$67,MATCH($A6,'CA Standards and Followers'!$A$8:$A$67,0))<=I$1),INDEX('CA Standards and Followers'!#REF!,MATCH(I$1,'CA Standards and Followers'!$1:$1,0)),IF(AND(INDEX('CA Standards and Followers'!$D$8:$D$67,MATCH($A6,'CA Standards and Followers'!$A$8:$A$67,0))=1,INDEX('CA Standards and Followers'!$G$8:$G$67,MATCH($A6,'CA Standards and Followers'!$A$8:$A$67,0))<=I$1),INDEX('CA Standards and Followers'!$2:$2,MATCH(I$1,'CA Standards and Followers'!$1:$1,0)),0)) -> 0 | ... AF6: =IF(AND(INDEX('CA Standards and Followers'!$E$8:$E$67,MATCH($A6,'CA Standards and Followers'!$A$8:$A$67,0))=1,INDEX('CA Standards and Followers'!$H$8:$H$67,MATCH($A6,'CA Standards and Followers'!$A$8:$A$67,0))<=AF$1),INDEX('CA Standards and Followers'!#REF!,MATCH(AF$1,'CA Standards and Followers'!$1:$1,0)),IF(AND(INDEX('CA Standards and Followers'!$D$8:$D$67,MATCH($A6,'CA Standards and Followers'!$A$8:$A$67,0))=1,INDEX('CA Standards and Followers'!$G$8:$G$67,MATCH($A6,'CA Standards and Followers'!$A$8:$A$67,0))<=AF$1),INDEX('CA Standards and Followers'!$2:$2,MATCH(AF$1,'CA Standards and Followers'!$1:$1,0)),0)) -> 0
A7: Colorado | B7: =IF(AND(INDEX('CA Standards and Followers'!$E$8:$E$67,MATCH($A7,'CA Standards and Followers'!$A$8:$A$67,0))=1,INDEX('CA Standards and Followers'!$H$8:$H$67,MATCH($A7,'CA Standards and Followers'!$A$8:$A$67,0))<=B$1),INDEX('CA Standards and Followers'!#REF!,MATCH(B$1,'CA Standards and Followers'!$1:$1,0)),IF(AND(INDEX('CA Standards and Followers'!$D$8:$D$67,MATCH($A7,'CA Standards and Followers'!$A$8:$A$67,0))=1,INDEX('CA Standards and Followers'!$G$8:$G$67,MATCH($A7,'CA Standards and Followers'!$A$8:$A$67,0))<=B$1),INDEX('CA Standards and Followers'!$2:$2,MATCH(B$1,'CA Standards and Followers'!$1:$1,0)),0)) -> 0 | C7: =IF(AND(INDEX('CA Standards and Followers'!$E$8:$E$67,MATCH($A7,'CA Standards and Followers'!$A$8:$A$67,0))=1,INDEX('CA Standards and Followers'!$H$8:$H$67,MATCH($A7,'CA Standards and Followers'!$A$8:$A$67,0))<=C$1),INDEX('CA Standards and Followers'!#REF!,MATCH(C$1,'CA Standards and Followers'!$1:$1,0)),IF(AND(INDEX('CA Standards and Followers'!$D$8:$D$67,MATCH($A7,'CA Standards and Followers'!$A$8:$A$67,0))=1,INDEX('CA Standards and Followers'!$G$8:$G$67,MATCH($A7,'CA Standards and Followers'!$A$8:$A$67,0))<=C$1),INDEX('CA Standards and Followers'!$2:$2,MATCH(C$1,'CA Standards and Followers'!$1:$1,0)),0)) -> 0 | D7: =IF(AND(INDEX('CA Standards and Followers'!$E$8:$E$67,MATCH($A7,'CA Standards and Followers'!$A$8:$A$67,0))=1,INDEX('CA Standards and Followers'!$H$8:$H$67,MATCH($A7,'CA Standards and Followers'!$A$8:$A$67,0))<=D$1),INDEX('CA Standards and Followers'!#REF!,MATCH(D$1,'CA Standards and Followers'!$1:$1,0)),IF(AND(INDEX('CA Standards and Followers'!$D$8:$D$67,MATCH($A7,'CA Standards and Followers'!$A$8:$A$67,0))=1,INDEX('CA Standards and Followers'!$G$8:$G$67,MATCH($A7,'CA Standards and Followers'!$A$8:$A$67,0))<=D$1),INDEX('CA Standards and Followers'!$2:$2,MATCH(D$1,'CA Standards and Followers'!$1:$1,0)),0)) -> 0 | E7: =IF(AND(INDEX('CA Standards and Followers'!$E$8:$E$67,MATCH($A7,'CA Standards and Followers'!$A$8:$A$67,0))=1,INDEX('CA Standards and Followers'!$H$8:$H$67,MATCH($A7,'CA Standards and Followers'!$A$8:$A$67,0))<=E$1),INDEX('CA Standards and Followers'!#REF!,MATCH(E$1,'CA Standards and Followers'!$1:$1,0)),IF(AND(INDEX('CA Standards and Followers'!$D$8:$D$67,MATCH($A7,'CA Standards and Followers'!$A$8:$A$67,0))=1,INDEX('CA Standards and Followers'!$G$8:$G$67,MATCH($A7,'CA Standards and Followers'!$A$8:$A$67,0))<=E$1),INDEX('CA Standards and Followers'!$2:$2,MATCH(E$1,'CA Standards and Followers'!$1:$1,0)),0)) -> 0 | F7: =IF(AND(INDEX('CA Standards and Followers'!$E$8:$E$67,MATCH($A7,'CA Standards and Followers'!$A$8:$A$67,0))=1,INDEX('CA Standards and Followers'!$H$8:$H$67,MATCH($A7,'CA Standards and Followers'!$A$8:$A$67,0))<=F$1),INDEX('CA Standards and Followers'!#REF!,MATCH(F$1,'CA Standards and Followers'!$1:$1,0)),IF(AND(INDEX('CA Standards and Followers'!$D$8:$D$67,MATCH($A7,'CA Standards and Followers'!$A$8:$A$67,0))=1,INDEX('CA Standards and Followers'!$G$8:$G$67,MATCH($A7,'CA Standards and Followers'!$A$8:$A$67,0))<=F$1),INDEX('CA Standards and Followers'!$2:$2,MATCH(F$1,'CA Standards and Followers'!$1:$1,0)),0)) -> 0.08 | G7: =IF(AND(INDEX('CA Standards and Followers'!$E$8:$E$67,MATCH($A7,'CA Standards and Followers'!$A$8:$A$67,0))=1,INDEX('CA Standards and Followers'!$H$8:$H$67,MATCH($A7,'CA Standards and Followers'!$A$8:$A$67,0))<=G$1),INDEX('CA Standards and Followers'!#REF!,MATCH(G$1,'CA Standards and Followers'!$1:$1,0)),IF(AND(INDEX('CA Standards and Followers'!$D$8:$D$67,MATCH($A7,'CA Standards and Followers'!$A$8:$A$67,0))=1,INDEX('CA Standards and Followers'!$G$8:$G$67,MATCH($A7,'CA Standards and Followers'!$A$8:$A$67,0))<=G$1),INDEX('CA Standards and Followers'!$2:$2,MATCH(G$1,'CA Standards and Followers'!$1:$1,0)),0)) -> 0.08 | H7: =IF(AND(INDEX('CA Standards and Followers'!$E$8:$E$67,MATCH($A7,'CA Standards and Followers'!$A$8:$A$67,0))=1,INDEX('CA Standards and Followers'!$H$8:$H$67,MATCH($A7,'CA Standards and Followers'!$A$8:$A$67,0))<=H$1),INDEX('CA Standards and Followers'!#REF!,MATCH(H$1,'CA Standards and Followers'!$1:$1,0)),IF(AND(INDEX('CA Standards and Followers'!$D$8:$D$67,MATCH($A7,'CA Standards and Followers'!$A$8:$A$67,0))=1,INDEX('CA Standards and Followers'!$G$8:$G$67,MATCH($A7,'CA Standards and Followers'!$A$8:$A$67,0))<=H$1),INDEX('CA Standards and Followers'!$2:$2,MATCH(H$1,'CA Standards and Followers'!$1:$1,0)),0)) -> 0 | I7: =IF(AND(INDEX('CA Standards and Followers'!$E$8:$E$67,MATCH($A7,'CA Standards and Followers'!$A$8:$A$67,0))=1,INDEX('CA Standards and Followers'!$H$8:$H$67,MATCH($A7,'CA Standards and Followers'!$A$8:$A$67,0))<=I$1),INDEX('CA Standards and Followers'!#REF!,MATCH(I$1,'CA Standards and Followers'!$1:$1,0)),IF(AND(INDEX('CA Standards and Followers'!$D$8:$D$67,MATCH($A7,'CA Standards and Followers'!$A$8:$A$67,0))=1,INDEX('CA Standards and Followers'!$G$8:$G$67,MATCH($A7,'CA Standards and Followers'!$A$8:$A$67,0))<=I$1),INDEX('CA Standards and Followers'!$2:$2,MATCH(I$1,'CA Standards and Followers'!$1:$1,0)),0)) -> 0 | ... AF7: =IF(AND(INDEX('CA Standards and Followers'!$E$8:$E$67,MATCH($A7,'CA Standards and Followers'!$A$8:$A$67,0))=1,INDEX('CA Standards and Followers'!$H$8:$H$67,MATCH($A7,'CA Standards and Followers'!$A$8:$A$67,0))<=AF$1),INDEX('CA Standards and Followers'!#REF!,MATCH(AF$1,'CA Standards and Followers'!$1:$1,0)),IF(AND(INDEX('CA Standards and Followers'!$D$8:$D$67,MATCH($A7,'CA Standards and Followers'!$A$8:$A$67,0))=1,INDEX('CA Standards and Followers'!$G$8:$G$67,MATCH($A7,'CA Standards and Followers'!$A$8:$A$67,0))<=AF$1),INDEX('CA Standards and Followers'!$2:$2,MATCH(AF$1,'CA Standards and Followers'!$1:$1,0)),0)) -> 0
A8: Connecticut | B8: =IF(AND(INDEX('CA Standards and Followers'!$E$8:$E$67,MATCH($A8,'CA Standards and Followers'!$A$8:$A$67,0))=1,INDEX('CA Standards and Followers'!$H$8:$H$67,MATCH($A8,'CA Standards and Followers'!$A$8:$A$67,0))<=B$1),INDEX('CA Standards and Followers'!#REF!,MATCH(B$1,'CA Standards and Followers'!$1:$1,0)),IF(AND(INDEX('CA Standards and Followers'!$D$8:$D$67,MATCH($A8,'CA Standards and Followers'!$A$8:$A$67,0))=1,INDEX('CA Standards and Followers'!$G$8:$G$67,MATCH($A8,'CA Standards and Followers'!$A$8:$A$67,0))<=B$1),INDEX('CA Standards and Followers'!$2:$2,MATCH(B$1,'CA Standards and Followers'!$1:$1,0)),0)) -> 0 | C8: =IF(AND(INDEX('CA Standards and Followers'!$E$8:$E$67,MATCH($A8,'CA Standards and Followers'!$A$8:$A$67,0))=1,INDEX('CA Standards and Followers'!$H$8:$H$67,MATCH($A8,'CA Standards and Followers'!$A$8:$A$67,0))<=C$1),INDEX('CA Standards and Followers'!#REF!,MATCH(C$1,'CA Standards and Followers'!$1:$1,0)),IF(AND(INDEX('CA Standards and Followers'!$D$8:$D$67,MATCH($A8,'CA Standards and Followers'!$A$8:$A$67,0))=1,INDEX('CA Standards and Followers'!$G$8:$G$67,MATCH($A8,'CA Standards and Followers'!$A$8:$A$67,0))<=C$1),INDEX('CA Standards and Followers'!$2:$2,MATCH(C$1,'CA Standards and Followers'!$1:$1,0)),0)) -> 0 | D8: =IF(AND(INDEX('CA Standards and Followers'!$E$8:$E$67,MATCH($A8,'CA Standards and Followers'!$A$8:$A$67,0))=1,INDEX('CA Standards and Followers'!$H$8:$H$67,MATCH($A8,'CA Standards and Followers'!$A$8:$A$67,0))<=D$1),INDEX('CA Standards and Followers'!#REF!,MATCH(D$1,'CA Standards and Followers'!$1:$1,0)),IF(AND(INDEX('CA Standards and Followers'!$D$8:$D$67,MATCH($A8,'CA Standards and Followers'!$A$8:$A$67,0))=1,INDEX('CA Standards and Followers'!$G$8:$G$67,MATCH($A8,'CA Standards and Followers'!$A$8:$A$67,0))<=D$1),INDEX('CA Standards and Followers'!$2:$2,MATCH(D$1,'CA Standards and Followers'!$1:$1,0)),0)) -> 0 | E8: =IF(AND(INDEX('CA Standards and Followers'!$E$8:$E$67,MATCH($A8,'CA Standards and Followers'!$A$8:$A$67,0))=1,INDEX('CA Standards and Followers'!$H$8:$H$67,MATCH($A8,'CA Standards and Followers'!$A$8:$A$67,0))<=E$1),INDEX('CA Standards and Followers'!#REF!,MATCH(E$1,'CA Standards and Followers'!$1:$1,0)),IF(AND(INDEX('CA Standards and Followers'!$D$8:$D$67,MATCH($A8,'CA Standards and Followers'!$A$8:$A$67,0))=1,INDEX('CA Standards and Followers'!$G$8:$G$67,MATCH($A8,'CA Standards and Followers'!$A$8:$A$67,0))<=E$1),INDEX('CA Standards and Followers'!$2:$2,MATCH(E$1,'CA Standards and Followers'!$1:$1,0)),0)) -> 0 | F8: =IF(AND(INDEX('CA Standards and Followers'!$E$8:$E$67,MATCH($A8,'CA Standards and Followers'!$A$8:$A$67,0))=1,INDEX('CA Standards and Followers'!$H$8:$H$67,MATCH($A8,'CA Standards and Followers'!$A$8:$A$67,0))<=F$1),INDEX('CA Standards and Followers'!#REF!,MATCH(F$1,'CA Standards and Followers'!$1:$1,0)),IF(AND(INDEX('CA Standards and Followers'!$D$8:$D$67,MATCH($A8,'CA Standards and Followers'!$A$8:$A$67,0))=1,INDEX('CA Standards and Followers'!$G$8:$G$67,MATCH($A8,'CA Standards and Followers'!$A$8:$A$67,0))<=F$1),INDEX('CA Standards and Followers'!$2:$2,MATCH(F$1,'CA Standards and Followers'!$1:$1,0)),0)) -> 0.08 | G8: =IF(AND(INDEX('CA Standards and Followers'!$E$8:$E$67,MATCH($A8,'CA Standards and Followers'!$A$8:$A$67,0))=1,INDEX('CA Standards and Followers'!$H$8:$H$67,MATCH($A8,'CA Standards and Followers'!$A$8:$A$67,0))<=G$1),INDEX('CA Standards and Followers'!#REF!,MATCH(G$1,'CA Standards and Followers'!$1:$1,0)),IF(AND(INDEX('CA Standards and Followers'!$D$8:$D$67,MATCH($A8,'CA Standards and Followers'!$A$8:$A$67,0))=1,INDEX('CA Standards and Followers'!$G$8:$G$67,MATCH($A8,'CA Standards and Followers'!$A$8:$A$67,0))<=G$1),INDEX('CA Standards and Followers'!$2:$2,MATCH(G$1,'CA Standards and Followers'!$1:$1,0)),0)) -> 0.08 | H8: =IF(AND(INDEX('CA Standards and Followers'!$E$8:$E$67,MATCH($A8,'CA Standards and Followers'!$A$8:$A$67,0))=1,INDEX('CA Standards and Followers'!$H$8:$H$67,MATCH($A8,'CA Standards and Followers'!$A$8:$A$67,0))<=H$1),INDEX('CA Standards and Followers'!#REF!,MATCH(H$1,'CA Standards and Followers'!$1:$1,0)),IF(AND(INDEX('CA Standards and Followers'!$D$8:$D$67,MATCH($A8,'CA Standards and Followers'!$A$8:$A$67,0))=1,INDEX('CA Standards and Followers'!$G$8:$G$67,MATCH($A8,'CA Standards and Followers'!$A$8:$A$67,0))<=H$1),INDEX('CA Standards and Followers'!$2:$2,MATCH(H$1,'CA Standards and Followers'!$1:$1,0)),0)) -> 0 | I8: =IF(AND(INDEX('CA Standards and Followers'!$E$8:$E$67,MATCH($A8,'CA Standards and Followers'!$A$8:$A$67,0))=1,INDEX('CA Standards and Followers'!$H$8:$H$67,MATCH($A8,'CA Standards and Followers'!$A$8:$A$67,0))<=I$1),INDEX('CA Standards and Followers'!#REF!,MATCH(I$1,'CA Standards and Followers'!$1:$1,0)),IF(AND(INDEX('CA Standards and Followers'!$D$8:$D$67,MATCH($A8,'CA Standards and Followers'!$A$8:$A$67,0))=1,INDEX('CA Standards and Followers'!$G$8:$G$67,MATCH($A8,'CA Standards and Followers'!$A$8:$A$67,0))<=I$1),INDEX('CA Standards and Followers'!$2:$2,MATCH(I$1,'CA Standards and Followers'!$1:$1,0)),0)) -> 0 | ... AF8: =IF(AND(INDEX('CA Standards and Followers'!$E$8:$E$67,MATCH($A8,'CA Standards and Followers'!$A$8:$A$67,0))=1,INDEX('CA Standards and Followers'!$H$8:$H$67,MATCH($A8,'CA Standards and Followers'!$A$8:$A$67,0))<=AF$1),INDEX('CA Standards and Followers'!#REF!,MATCH(AF$1,'CA Standards and Followers'!$1:$1,0)),IF(AND(INDEX('CA Standards and Followers'!$D$8:$D$67,MATCH($A8,'CA Standards and Followers'!$A$8:$A$67,0))=1,INDEX('CA Standards and Followers'!$G$8:$G$67,MATCH($A8,'CA Standards and Followers'!$A$8:$A$67,0))<=AF$1),INDEX('CA Standards and Followers'!$2:$2,MATCH(AF$1,'CA Standards and Followers'!$1:$1,0)),0)) -> 0
A9: Delaware | B9: =IF(AND(INDEX('CA Standards and Followers'!$E$8:$E$67,MATCH($A9,'CA Standards and Followers'!$A$8:$A$67,0))=1,INDEX('CA Standards and Followers'!$H$8:$H$67,MATCH($A9,'CA Standards and Followers'!$A$8:$A$67,0))<=B$1),INDEX('CA Standards and Followers'!#REF!,MATCH(B$1,'CA Standards and Followers'!$1:$1,0)),IF(AND(INDEX('CA Standards and Followers'!$D$8:$D$67,MATCH($A9,'CA Standards and Followers'!$A$8:$A$67,0))=1,INDEX('CA Standards and Followers'!$G$8:$G$67,MATCH($A9,'CA Standards and Followers'!$A$8:$A$67,0))<=B$1),INDEX('CA Standards and Followers'!$2:$2,MATCH(B$1,'CA Standards and Followers'!$1:$1,0)),0)) -> 0 | C9: =IF(AND(INDEX('CA Standards and Followers'!$E$8:$E$67,MATCH($A9,'CA Standards and Followers'!$A$8:$A$67,0))=1,INDEX('CA Standards and Followers'!$H$8:$H$67,MATCH($A9,'CA Standards and Followers'!$A$8:$A$67,0))<=C$1),INDEX('CA Standards and Followers'!#REF!,MATCH(C$1,'CA Standards and Followers'!$1:$1,0)),IF(AND(INDEX('CA Standards and Followers'!$D$8:$D$67,MATCH($A9,'CA Standards and Followers'!$A$8:$A$67,0))=1,INDEX('CA Standards and Followers'!$G$8:$G$67,MATCH($A9,'CA Standards and Followers'!$A$8:$A$67,0))<=C$1),INDEX('CA Standards and Followers'!$2:$2,MATCH(C$1,'CA Standards and Followers'!$1:$1,0)),0)) -> 0 | D9: =IF(AND(INDEX('CA Standards and Followers'!$E$8:$E$67,MATCH($A9,'CA Standards and Followers'!$A$8:$A$67,0))=1,INDEX('CA Standards and Followers'!$H$8:$H$67,MATCH($A9,'CA Standards and Followers'!$A$8:$A$67,0))<=D$1),INDEX('CA Standards and Followers'!#REF!,MATCH(D$1,'CA Standards and Followers'!$1:$1,0)),IF(AND(INDEX('CA Standards and Followers'!$D$8:$D$67,MATCH($A9,'CA Standards and Followers'!$A$8:$A$67,0))=1,INDEX('CA Standards and Followers'!$G$8:$G$67,MATCH($A9,'CA Standards and Followers'!$A$8:$A$67,0))<=D$1),INDEX('CA Standards and Followers'!$2:$2,MATCH(D$1,'CA Standards and Followers'!$1:$1,0)),0)) -> 0 | E9: =IF(AND(INDEX('CA Standards and Followers'!$E$8:$E$67,MATCH($A9,'CA Standards and Followers'!$A$8:$A$67,0))=1,INDEX('CA Standards and Followers'!$H$8:$H$67,MATCH($A9,'CA Standards and Followers'!$A$8:$A$67,0))<=E$1),INDEX('CA Standards and Followers'!#REF!,MATCH(E$1,'CA Standards and Followers'!$1:$1,0)),IF(AND(INDEX('CA Standards and Followers'!$D$8:$D$67,MATCH($A9,'CA Standards and Followers'!$A$8:$A$67,0))=1,INDEX('CA Standards and Followers'!$G$8:$G$67,MATCH($A9,'CA Standards and Followers'!$A$8:$A$67,0))<=E$1),INDEX('CA Standards and Followers'!$2:$2,MATCH(E$1,'CA Standards and Followers'!$1:$1,0)),0)) -> 0 | F9: =IF(AND(INDEX('CA Standards and Followers'!$E$8:$E$67,MATCH($A9,'CA Standards and Followers'!$A$8:$A$67,0))=1,INDEX('CA Standards and Followers'!$H$8:$H$67,MATCH($A9,'CA Standards and Followers'!$A$8:$A$67,0))<=F$1),INDEX('CA Standards and Followers'!#REF!,MATCH(F$1,'CA Standards and Followers'!$1:$1,0)),IF(AND(INDEX('CA Standards and Followers'!$D$8:$D$67,MATCH($A9,'CA Standards and Followers'!$A$8:$A$67,0))=1,INDEX('CA Standards and Followers'!$G$8:$G$67,MATCH($A9,'CA Standards and Followers'!$A$8:$A$67,0))<=F$1),INDEX('CA Standards and Followers'!$2:$2,MATCH(F$1,'CA Standards and Followers'!$1:$1,0)),0)) -> 0 | G9: =IF(AND(INDEX('CA Standards and Followers'!$E$8:$E$67,MATCH($A9,'CA Standards and Followers'!$A$8:$A$67,0))=1,INDEX('CA Standards and Followers'!$H$8:$H$67,MATCH($A9,'CA Standards and Followers'!$A$8:$A$67,0))<=G$1),INDEX('CA Standards and Followers'!#REF!,MATCH(G$1,'CA Standards and Followers'!$1:$1,0)),IF(AND(INDEX('CA Standards and Followers'!$D$8:$D$67,MATCH($A9,'CA Standards and Followers'!$A$8:$A$67,0))=1,INDEX('CA Standards and Followers'!$G$8:$G$67,MATCH($A9,'CA Standards and Followers'!$A$8:$A$67,0))<=G$1),INDEX('CA Standards and Followers'!$2:$2,MATCH(G$1,'CA Standards and Followers'!$1:$1,0)),0)) -> 0 | H9: =IF(AND(INDEX('CA Standards and Followers'!$E$8:$E$67,MATCH($A9,'CA Standards and Followers'!$A$8:$A$67,0))=1,INDEX('CA Standards and Followers'!$H$8:$H$67,MATCH($A9,'CA Standards and Followers'!$A$8:$A$67,0))<=H$1),INDEX('CA Standards and Followers'!#REF!,MATCH(H$1,'CA Standards and Followers'!$1:$1,0)),IF(AND(INDEX('CA Standards and Followers'!$D$8:$D$67,MATCH($A9,'CA Standards and Followers'!$A$8:$A$67,0))=1,INDEX('CA Standards and Followers'!$G$8:$G$67,MATCH($A9,'CA Standards and Followers'!$A$8:$A$67,0))<=H$1),INDEX('CA Standards and Followers'!$2:$2,MATCH(H$1,'CA Standards and Followers'!$1:$1,0)),0)) -> 0 | I9: =IF(AND(INDEX('CA Standards and Followers'!$E$8:$E$67,MATCH($A9,'CA Standards and Followers'!$A$8:$A$67,0))=1,INDEX('CA Standards and Followers'!$H$8:$H$67,MATCH($A9,'CA Standards and Followers'!$A$8:$A$67,0))<=I$1),INDEX('CA Standards and Followers'!#REF!,MATCH(I$1,'CA Standards and Followers'!$1:$1,0)),IF(AND(INDEX('CA Standards and Followers'!$D$8:$D$67,MATCH($A9,'CA Standards and Followers'!$A$8:$A$67,0))=1,INDEX('CA Standards and Followers'!$G$8:$G$67,MATCH($A9,'CA Standards and Followers'!$A$8:$A$67,0))<=I$1),INDEX('CA Standards and Followers'!$2:$2,MATCH(I$1,'CA Standards and Followers'!$1:$1,0)),0)) -> 0 | ... AF9: =IF(AND(INDEX('CA Standards and Followers'!$E$8:$E$67,MATCH($A9,'CA Standards and Followers'!$A$8:$A$67,0))=1,INDEX('CA Standards and Followers'!$H$8:$H$67,MATCH($A9,'CA Standards and Followers'!$A$8:$A$67,0))<=AF$1),INDEX('CA Standards and Followers'!#REF!,MATCH(AF$1,'CA Standards and Followers'!$1:$1,0)),IF(AND(INDEX('CA Standards and Followers'!$D$8:$D$67,MATCH($A9,'CA Standards and Followers'!$A$8:$A$67,0))=1,INDEX('CA Standards and Followers'!$G$8:$G$67,MATCH($A9,'CA Standards and Followers'!$A$8:$A$67,0))<=AF$1),INDEX('CA Standards and Followers'!$2:$2,MATCH(AF$1,'CA Standards and Followers'!$1:$1,0)),0)) -> 0
A10: District of Columbia | B10: =IF(AND(INDEX('CA Standards and Followers'!$E$8:$E$67,MATCH($A10,'CA Standards and Followers'!$A$8:$A$67,0))=1,INDEX('CA Standards and Followers'!$H$8:$H$67,MATCH($A10,'CA Standards and Followers'!$A$8:$A$67,0))<=B$1),INDEX('CA Standards and Followers'!#REF!,MATCH(B$1,'CA Standards and Followers'!$1:$1,0)),IF(AND(INDEX('CA Standards and Followers'!$D$8:$D$67,MATCH($A10,'CA Standards and Followers'!$A$8:$A$67,0))=1,INDEX('CA Standards and Followers'!$G$8:$G$67,MATCH($A10,'CA Standards and Followers'!$A$8:$A$67,0))<=B$1),INDEX('CA Standards and Followers'!$2:$2,MATCH(B$1,'CA Standards and Followers'!$1:$1,0)),0)) -> 0 | C10: =IF(AND(INDEX('CA Standards and Followers'!$E$8:$E$67,MATCH($A10,'CA Standards and Followers'!$A$8:$A$67,0))=1,INDEX('CA Standards and Followers'!$H$8:$H$67,MATCH($A10,'CA Standards and Followers'!$A$8:$A$67,0))<=C$1),INDEX('CA Standards and Followers'!#REF!,MATCH(C$1,'CA Standards and Followers'!$1:$1,0)),IF(AND(INDEX('CA Standards and Followers'!$D$8:$D$67,MATCH($A10,'CA Standards and Followers'!$A$8:$A$67,0))=1,INDEX('CA Standards and Followers'!$G$8:$G$67,MATCH($A10,'CA Standards and Followers'!$A$8:$A$67,0))<=C$1),INDEX('CA Standards and Followers'!$2:$2,MATCH(C$1,'CA Standards and Followers'!$1:$1,0)),0)) -> 0 | D10: =IF(AND(INDEX('CA Standards and Followers'!$E$8:$E$67,MATCH($A10,'CA Standards and Followers'!$A$8:$A$67,0))=1,INDEX('CA Standards and Followers'!$H$8:$H$67,MATCH($A10,'CA Standards and Followers'!$A$8:$A$67,0))<=D$1),INDEX('CA Standards and Followers'!#REF!,MATCH(D$1,'CA Standards and Followers'!$1:$1,0)),IF(AND(INDEX('CA Standards and Followers'!$D$8:$D$67,MATCH($A10,'CA Standards and Followers'!$A$8:$A$67,0))=1,INDEX('CA Standards and Followers'!$G$8:$G$67,MATCH($A10,'CA Standards and Followers'!$A$8:$A$67,0))<=D$1),INDEX('CA Standards and Followers'!$2:$2,MATCH(D$1,'CA Standards and Followers'!$1:$1,0)),0)) -> 0 | E10: =IF(AND(INDEX('CA Standards and Followers'!$E$8:$E$67,MATCH($A10,'CA Standards and Followers'!$A$8:$A$67,0))=1,INDEX('CA Standards and Followers'!$H$8:$H$67,MATCH($A10,'CA Standards and Followers'!$A$8:$A$67,0))<=E$1),INDEX('CA Standards and Followers'!#REF!,MATCH(E$1,'CA Standards and Followers'!$1:$1,0)),IF(AND(INDEX('CA Standards and Followers'!$D$8:$D$67,MATCH($A10,'CA Standards and Followers'!$A$8:$A$67,0))=1,INDEX('CA Standards and Followers'!$G$8:$G$67,MATCH($A10,'CA Standards and Followers'!$A$8:$A$67,0))<=E$1),INDEX('CA Standards and Followers'!$2:$2,MATCH(E$1,'CA Standards and Followers'!$1:$1,0)),0)) -> 0 | F10: =IF(AND(INDEX('CA Standards and Followers'!$E$8:$E$67,MATCH($A10,'CA Standards and Followers'!$A$8:$A$67,0))=1,INDEX('CA Standards and Followers'!$H$8:$H$67,MATCH($A10,'CA Standards and Followers'!$A$8:$A$67,0))<=F$1),INDEX('CA Standards and Followers'!#REF!,MATCH(F$1,'CA Standards and Followers'!$1:$1,0)),IF(AND(INDEX('CA Standards and Followers'!$D$8:$D$67,MATCH($A10,'CA Standards and Followers'!$A$8:$A$67,0))=1,INDEX('CA Standards and Followers'!$G$8:$G$67,MATCH($A10,'CA Standards and Followers'!$A$8:$A$67,0))<=F$1),INDEX('CA Standards and Followers'!$2:$2,MATCH(F$1,'CA Standards and Followers'!$1:$1,0)),0)) -> 0 | G10: =IF(AND(INDEX('CA Standards and Followers'!$E$8:$E$67,MATCH($A10,'CA Standards and Followers'!$A$8:$A$67,0))=1,INDEX('CA Standards and Followers'!$H$8:$H$67,MATCH($A10,'CA Standards and Followers'!$A$8:$A$67,0))<=G$1),INDEX('CA Standards and Followers'!#REF!,MATCH(G$1,'CA Standards and Followers'!$1:$1,0)),IF(AND(INDEX('CA Standards and Followers'!$D$8:$D$67,MATCH($A10,'CA Standards and Followers'!$A$8:$A$67,0))=1,INDEX('CA Standards and Followers'!$G$8:$G$67,MATCH($A10,'CA Standards and Followers'!$A$8:$A$67,0))<=G$1),INDEX('CA Standards and Followers'!$2:$2,MATCH(G$1,'CA Standards and Followers'!$1:$1,0)),0)) -> 0 | H10: =IF(AND(INDEX('CA Standards and Followers'!$E$8:$E$67,MATCH($A10,'CA Standards and Followers'!$A$8:$A$67,0))=1,INDEX('CA Standards and Followers'!$H$8:$H$67,MATCH($A10,'CA Standards and Followers'!$A$8:$A$67,0))<=H$1),INDEX('CA Standards and Followers'!#REF!,MATCH(H$1,'CA Standards and Followers'!$1:$1,0)),IF(AND(INDEX('CA Standards and Followers'!$D$8:$D$67,MATCH($A10,'CA Standards and Followers'!$A$8:$A$67,0))=1,INDEX('CA Standards and Followers'!$G$8:$G$67,MATCH($A10,'CA Standards and Followers'!$A$8:$A$67,0))<=H$1),INDEX('CA Standards and Followers'!$2:$2,MATCH(H$1,'CA Standards and Followers'!$1:$1,0)),0)) -> 0 | I10: =IF(AND(INDEX('CA Standards and Followers'!$E$8:$E$67,MATCH($A10,'CA Standards and Followers'!$A$8:$A$67,0))=1,INDEX('CA Standards and Followers'!$H$8:$H$67,MATCH($A10,'CA Standards and Followers'!$A$8:$A$67,0))<=I$1),INDEX('CA Standards and Followers'!#REF!,MATCH(I$1,'CA Standards and Followers'!$1:$1,0)),IF(AND(INDEX('CA Standards and Followers'!$D$8:$D$67,MATCH($A10,'CA Standards and Followers'!$A$8:$A$67,0))=1,INDEX('CA Standards and Followers'!$G$8:$G$67,MATCH($A10,'CA Standards and Followers'!$A$8:$A$67,0))<=I$1),INDEX('CA Standards and Followers'!$2:$2,MATCH(I$1,'CA Standards and Followers'!$1:$1,0)),0)) -> 0 | ... AF10: =IF(AND(INDEX('CA Standards and Followers'!$E$8:$E$67,MATCH($A10,'CA Standards and Followers'!$A$8:$A$67,0))=1,INDEX('CA Standards and Followers'!$H$8:$H$67,MATCH($A10,'CA Standards and Followers'!$A$8:$A$67,0))<=AF$1),INDEX('CA Standards and Followers'!#REF!,MATCH(AF$1,'CA Standards and Followers'!$1:$1,0)),IF(AND(INDEX('CA Standards and Followers'!$D$8:$D$67,MATCH($A10,'CA Standards and Followers'!$A$8:$A$67,0))=1,INDEX('CA Standards and Followers'!$G$8:$G$67,MATCH($A10,'CA Standards and Followers'!$A$8:$A$67,0))<=AF$1),INDEX('CA Standards and Followers'!$2:$2,MATCH(AF$1,'CA Standards and Followers'!$1:$1,0)),0)) -> 0
