Workbook
Name a: #REF!
Name AsphaltStore: [1]Control!$D$50
Name base.year: #REF!
Name BaseYear: 2018
Name BTV11_15: #REF!
Name BVT17_15: #REF!
Name CAAGR_tolerance: 200
Name CH4_to_CO2e: '[2]Cross-Page Data'!$C$12
Name CH4GWP: #REF!
Name CO2_T4_APS: #REF!
Name CO2_T4_NZE: #REF!
Name CO2_T4_STEPS: #REF!
Name CO2_T5_APS: #REF!
Name CO2_T5_CPS: #REF!
Name CO2_T5_NZE: #REF!
Name CO2_T5_STEPS: #REF!
Name coal.past: #REF!
Name COAL_PRODUCTION: #REF!
Name Coal_trade: #REF!
Name coaldemand: #REF!
Name CokeCoalStore: [1]Control!$D$63
Name Constants.Density.Diesel: #REF!
Name Constants.Density.Ethanol: #REF!
Name Constants.Density.JetFuel: #REF!
Name Constants.Density.MotorSpirit: #REF!
Name ConsumeBlock1: '[1]Default State Energy Data Table'!$A$6:$AM$67
Name Conversion.to.average.power: #REF!
Name Conversion.water.L: #REF!
Name Conversion.water.units: #REF!
Name Conversions.Area.m2: #REF!
Name Conversions.Area.Units: #REF!
Name Conversions.Energy.Joules: #REF!
Name Conversions.Energy.Units: #REF!
Name Conversions.Money.GBP: #REF!
Name Conversions.Money.Units: #REF!
Name Conversions.Power.Units: #REF!
Name Conversions.Power.Watts: #REF!
Name Cost.Capital.Scenario: #REF!
Name Cost.Finance.Scenario: #REF!
Name Cost.Fuel.Scenario: #REF!
Name Cost.Infrastructure.Scenario: #REF!
Name cpi_2010to2012: #REF!
Name cpi_2013to2012: #REF!
Name cpi_2014to2012: #REF!
Name cpi_2016to2012: #REF!
Name CreateRegions: #REF!
Name csp.capacity: #REF!
Name CSVfilepath: #REF!
Name D: #REF!
Name dd: #REF!
Name ddd: #REF!
Name ddddd: #REF!
Name dddddd: #REF!
Name deflator_year: "$2018"
Name DeflatorYear: "$2018"
Name discount_factors: #REF!
Name DistillStore: [1]Control!$D$51
Name DW_EDO_022WV: #REF!
Name DW_EDO_023WV: #REF!
Name DW_EDO_024WV: #REF!

Sheet About
A1: BIEEI BAU Industrial Equipment Efficiency Improvement
A4: Sources: | B4: Annual Energy Outlook
B5: Energy Information Administration
B6: 2025
B7: Assumptions to the Annual Energy Outlook 2025: Industrial Demand Module
B8: https://www.eia.gov/outlooks/aeo/assumptions/
B9: Table 3
A11: Notes:
A12: This variable should contain the BAU annual efficiency improvement of industrial equipment
A13: subscripted by industrial process.
A15: Methodology update:
A16: All efficiency-improvement rates are sourced from AEO 2025 IDM Assumptions Table 3 (base year 2022), via the MECS tab.
A17: Table 3 inputs were refreshed from the prior 2018-base vintage to the current 2022-base release.
A18: New-equipment REI is interpolated to 2021 (TREND), and the 2021-2050 improvement is annualized at a constant rate.
A19: The 'DEA rates' tab (Danish Energy Agency technology data) is retained for reference but is not linked to the BIEEI outputs.
A21: Combustion heat-band update (Worklog T3.1–T3.3):
A22: The five combustion heat bands in BIEEI-other (rows 2–6) are no longer a uniform MECS rate. They now carry year-specific
A23: BAU improvement rates from the 'Combustion BAU Trajectory' tab, driven by growing burner-integral waste-heat-recovery (WHR) penetration.
A24: Penetration pen(t) starts at the completed start-year installed mix (0% / 0% / 5% / 17.4% / 58.7% by band) and trends linearly to a
... A40: Kermeli 2050 implementation rates are BAT-mitigation-scenario values, not BAU; only a 30% gap-closure share (blue input, 'Combustion BAU Trajectory'!G13) is assumed autonomous in the U.S. BAU, preserving the remaining potential for the price-responsive cost-curve file.
A41: Additional source: | B41: Energy efficiency potentials in the EU industry: impacts of deep decarbonization technologies
B42: Kermeli, K., Edelenbosch, O.Y., Crijns-Graus, W., van Ruijven, B.J., van Vuuren, D.P., Worrell, E.
B44: Energy Efficiency 15, 55 (2022)
B45: https://link.springer.com/article/10.1007/s12053-022-10071-8
B46: Supplementary material: energy savings & cost of measures by industry (2015 diffusion, 2030/2050 implementation)
A48: Band 2050 adoption targets use full-coverage industry weighting: every industry's band-heat share ('indst heat consumption') × its mapped burner-adoption level ('Combustion BAU Trajectory' rows 56–80). Targets = start-year penetration + mapping-implied 2015→2050 delta, computed on a consistent basis so industries with no additional adoption contribute zero change.
A49: Refining, chemicals, and all unmapped industries are held at the Kermeli 'Other' level (10% diffusion, no additional adoption): fired-heater WHR in these sectors is achieved via convection sections and central air preheat — system WHR (ε=0.4 scope), whose savings are priced in the separate cost-curve file. Refs: DOE, Waste Heat Recovery: Technology and Opportunities in U.S. Industry (BCS Inc., 2008); ACEEE Summer Study 2007 (<5% of U.S. manufacturing facilities use waste-heat recovery).
A50: Data caveat: Kermeli et al. (2022) assume identical 2015 diffusion rates across all countries due to lack of data, and no U.S.-specific burner-penetration statistics were found in DOE/ORNL/ACEEE literature. Band heat composition, not adoption statistics, is what drives the band targets here.
A51: Bands <200 °C: burner-integral regen/recup technology not applicable, so these bands carry no WHR-driven improvement; their BAU improvement comes solely from the residual equipment-native rate (see below).
A52: KEY ASSUMPTION — RESIDUAL EQUIPMENT-NATIVE IMPROVEMENT: all five heat bands carry an additional 0.2%/yr efficiency drift ('Combustion BAU Trajectory'!G14, blue/yellow input) on top of the burner-WHR sweep, compounded and capped at the tech-matched ceiling. It represents non-WHR, non-price-driven improvement only: combustion control/O2 trim becoming standard practice, refractory & insulation upgrades at rebuild, furnace pressure control, and vintage design improvement at stock turnover. Basis: EIA NEMS Industrial Demand Module 'technology possibility curves' (trend-based improvement of new + existing equipment; https://www.eia.gov/outlooks/aeo/nems/overview/industrial.html); prior all-mechanism MECS/AEO rate was 0.535%/yr. It EXCLUDES all WHR and all price-responsive measures — those savings live in the system-WHR scope and the separate cost-curve file respectively, so none are double-counted here.

Sheet MECS
D2: UEC 2022 (trillion British thermal | E2: REI 2050 | F2: 2022 | G2: 2050 | K2: improvement
B3: End use | C3: Fuel | D3: units per billion 2012$ of shipments) | E3: existing | F3: new REI | G3: new REI | I3: 2021 | J3: 2050 | K3: over model run | M3: annual improvement
B4: Heat | C4: Natural gas | D4: 0.243 | E4: 0.862 | F4: 0.965 | G4: 0.83 | I4: {=TREND(F4:G4,$F$2:$G$2,$I$3)} -> 0.96982143 | J4: =G4 -> 0.83 | K4: =1-J4/I4 -> 0.14417234 | M4: =1-(1-K4)^(1/($J$3-$I$3)) -> 0.0053541071
B5: Heat | C5: Electricity | D5: 0.023 | E5: 0.929 | F5: 0.983 | G5: 0.938 | I5: {=TREND(F5:G5,$F$2:$G$2,$I$3)} -> 0.98460714 | J5: =G5 -> 0.938 | K5: =1-J5/I5 -> 0.047335776 | M5: =1-(1-K5)^(1/($J$3-$I$3)) -> 0.0016707673
B6: Heat | C6: Steam | D6: 0.375 | E6: 0.862 | F6: 0.965 | G6: 0.829 | I6: {=TREND(F6:G6,$F$2:$G$2,$I$3)} -> 0.96985714 | J6: =G6 -> 0.829 | K6: =1-J6/I6 -> 0.14523494 | M6: =1-(1-K6)^(1/($J$3-$I$3)) -> 0.0053967172
B7: Refrigeration | C7: Electricity | D7: 0.043 | E7: 0.923 | F7: 0.966 | G7: 0.9 | I7: {=TREND(F7:G7,$F$2:$G$2,$I$3)} -> 0.96835714 | J7: =G7 -> 0.9 | K7: =1-J7/I7 -> 0.070590839 | M7: =1-(1-K7)^(1/($J$3-$I$3)) -> 0.0025211684
B8: Machine drive | C8: Natural gas | D8: 0.029 | E8: 0.882 | F8: 0.97 | G8: 0.829 | I8: {=TREND(F8:G8,$F$2:$G$2,$I$3)} -> 0.97503571 | J8: =G8 -> 0.829 | K8: =1-J8/I8 -> 0.14977473 | M8: =1-(1-K8)^(1/($J$3-$I$3)) -> 0.005579341
B9: Machine drive | C9: Electricity | D9: 0.225 | E9: 0.929 | F9: 0.983 | G9: 0.909 | I9: {=TREND(F9:G9,$F$2:$G$2,$I$3)} -> 0.98564286 | J9: =G9 -> 0.909 | K9: =1-J9/I9 -> 0.077759258 | M9: =1-(1-K9)^(1/($J$3-$I$3)) -> 0.002787452
B10: Electrochemical | C10: Electricity | D10: 0.009 | E10: 0.919 | F10: 0.947 | G10: 0.642 | I10: {=TREND(F10:G10,$F$2:$G$2,$I$3)} -> 0.95789286 | J10: =G10 -> 0.642 | K10: =1-J10/I10 -> 0.3297789 | M10: =1-(1-K10)^(1/($J$3-$I$3)) -> 0.013703435
B11: processes Other | C11: Natural gas | D11: 0.019 | E11: 0.893 | F11: 0.969 | G11: 0.845 | I11: {=TREND(F11:G11,$F$2:$G$2,$I$3)} -> 0.97342857 | J11: =G11 -> 0.845 | K11: =1-J11/I11 -> 0.13193425 | M11: =1-(1-K11)^(1/($J$3-$I$3)) -> 0.004867008
B12: Other | C12: Electricity | D12: 0.009 | E12: 0.922 | F12: 0.983 | G12: 0.903 | I12: {=TREND(F12:G12,$F$2:$G$2,$I$3)} -> 0.98585714 | J12: =G12 -> 0.903 | K12: =1-J12/I12 -> 0.08404579 | M12: =1-(1-K12)^(1/($J$3-$I$3)) -> 0.0030226263

Sheet lighting
B5: 2024 | C5: 0.853075 | D5: =1/C5 -> 1.1722299 | E5: start year lighting efficiency from SYIEUEFbIPaF
B6: 2050 | C6: 0.9 | D6: =1/C6 -> 1.1111111 | E6: assumed efficiency 2050 (all LEDs)
D8: =1-D6/D5 -> 0.052138889
F9: =D8/25 -> 0.0020855556
D14: =1-(1-D8)^(1/($B$6-$B$5)) -> 0.002057392

Sheet Other data ->
A1: https://ens.dk/en/analyses-and-statistics/technology-data-industrial-process-heat
A2: Technology Data for Industrial Process Heat

Sheet 1.1 Traditional heat pump
A1: Technology | C1: Heat pump, up to 60 °C, Temp lift = 40 K
A2: year | C2: 2025 | D2: 2030 | E2: 2035 | F2: 2040 | G2: 2050 | H2: 2025 | I2: 2025 | J2: 2050 | K2: 2050 | L2: Note | M2: Ref
A3: est | C3: ctrl | D3: ctrl | E3: ctrl | F3: ctrl | G3: ctrl | H3: lower | I3: upper | J3: lower | K3: upper | L3: - | M3: -
A4: cat | B4: par
A5: Energy/technical data
B6: Heat generation capacity for one unit [MW] | C6: 3 | D6: 3 | E6: 3 | F6: 3 | G6: 3 | H6: 0.5 | I6: 5 | J6: 0.5 | K6: 5 | L6: A | M6: [1, 2]
B7: Total efficiency, net [%], nominel load | C7: 5.33 | D7: =C7*1.03 -> 5.4899 | E7: 5.55 | F7: =D7*1.02 -> 5.599698 | G7: =F7*1.01 -> 5.655695 | H7: =C7 -> 5.33 | I7: =C7*1.05 -> 5.5965 | J7: =G7*0.97 -> 5.4860241 | K7: =G7*1.02 -> 5.7688089 | L7: B | M7: [1, 3]
B8: Total efficiency, net [%], annual average | C8: =C7-5% -> 5.28 | D8: =D7-5% -> 5.4399 | E8: =E7-5% -> 5.5 | F8: =F7-5% -> 5.549698 | G8: =G7-5% -> 5.605695 | H8: =H7-5% -> 5.28 | I8: =I7-5% -> 5.5465 | J8: =J7-5% -> 5.4360241 | K8: =K7-5% -> 5.7188089 | L8: B,C
B9: Auxiliary electricity consumption [% of heat gen] | C9: 0.01 | D9: 0.01 | E9: 0.01 | F9: 0.01 | G9: 0.01 | H9: 0.01 | I9: 0.04 | J9: 0.01 | K9: 0.04 | M9: 2
B10: Forced outage [%] | C10: 0 | D10: 0 | E10: 0 | F10: 0 | G10: 0 | H10: 0 | I10: 0.01 | J10: 0 | K10: 0.01 | L10: D | M10: 2
B11: Planned outage [weeks per year] | C11: 1 | D11: 1 | E11: 1 | F11: 1 | G11: 1 | H11: 0.5 | I11: 2 | J11: 0.5 | K11: 2 | M11: 2
B12: Technical lifetime [years] | C12: 25 | D12: 25 | E12: 25 | F12: 25 | G12: 25 | H12: 15 | I12: 40 | J12: 15 | K12: 40 | M12: 2
B13: Construction time [years] | C13: 0.5 | D13: 0.5 | E13: 0.5 | F13: 0.5 | G13: 0.5 | H13: 0.3 | I13: 1 | J13: 0.3 | K13: 1 | M13: 2
A14: Regulation Ability
B15: Minimum load [% of full load] | C15: 0.25 | D15: 0.25 | E15: 0.25 | F15: 0.25 | G15: 0.25 | H15: 0.1 | I15: 0.5 | J15: 0.1 | K15: 0.5 | M15: 2
B16: Warm start-up time [hours] | C16: 0.1 | D16: 0.1 | E16: 0.1 | F16: 0.1 | G16: 0.1 | H16: 0.1 | I16: 0.2 | J16: 0.1 | K16: 0.2 | M16: 2
B17: Cold start-up time [hours] | C17: 1 | D17: 1 | E17: 1 | F17: 1 | G17: 1 | H17: 0.2 | I17: 1 | J17: 0.2 | K17: 1 | M17: 2
A18: Financial data
B19: Nominal investment [M€/MW] | C19: 0.95 | D19: 0.94 | E19: 0.91 | F19: 0.91 | G19: 0.89 | H19: 0.91 | I19: 0.95 | J19: 0.88 | K19: 0.95 | M19: 2
B20: - of which equipment [%] | C20: 0.4 | D20: 0.4 | E20: 0.4 | F20: 0.4 | G20: 0.4 | L20: E | M20: 2
B21: - of which installation and other costs [%] | C21: 0.6 | D21: 0.6 | E21: 0.6 | F21: 0.6 | G21: 0.6 | L21: F | M21: 2
B22: Fixed O&M [€/MJ/s/year] | C22: 2127 | D22: 2095 | E22: 2032 | F22: 2032 | G22: 2001 | H22: 2032 | I22: 2127 | J22: 1970 | K22: 2127 | M22: 2
B23: Variable O&M [€/MWh] | C23: 3.07 | D23: 3.02 | E23: 2.93 | F23: 2.93 | G23: 2.89 | H23: 2.93 | I23: 3.07 | J23: 2.84 | K23: 3.07 | M23: 2
A24: Technology-specific data
B25: Indirect investments cost [M€/MW] | C25: =C19*0.2 -> 0.19 | D25: =D19*0.2 -> 0.188 | E25: =E19*0.2 -> 0.182 | F25: =F19*0.2 -> 0.182 | G25: =G19*0.2 -> 0.178 | L25: H
B26: Non energy gains [M€/MW] | C26: - | D26: - | E26: - | F26: - | G26: -
B27: Startup cost [€/MW/startup] | C27: 10 | D27: 10 | E27: 10 | F27: 10 | G27: 10
B28: Temperature heat source supply [°C] | C28: 30 | D28: 30 | E28: 30 | F28: 30 | G28: 30 | L28: I
B29: Temperature heat source return [°C] | C29: 20 | D29: 20 | E29: 20 | F29: 20 | G29: 20 | L29: I
B30: - Total efficiency, net [%], nominel load. Based on a temperature lift of 50 K, 70°C max | C30: 4.52 | D30: 4.6 | E30: 4.65 | F30: 4.7 | G30: 4.74 | H30: 4.47 | I30: 4.69 | J30: 4.6 | K30: 4.84 | L30: G
B31: - Total efficiency, net [%], nominel load. Based on a temperature lift of 60 K, 80°C max | C31: 3.95 | D31: 4 | E31: 4.04 | F31: 4.08 | G31: 4.12 | H31: 3.88 | I31: 4.07 | J31: 3.99 | K31: 4.2 | L31: G
B32: Cooling generation capacity for one unit [MW] | C32: - | D32: - | E32: - | F32: - | G32: -
A35: Notes:
A36: A | B36: 0,5-5 MW
A37: B | B37: Estimated based on cases presented in [3]
A38: C | B38: Based on lost produktion during startup/shutdown
A39: D | B39: May vary depending on heat source availability
A40: E | B40: Very individual, can vary ÷ 20 %
A41: F | B41: Very individual, can vary + 20 %
A42: G | B42: Based on the old technology catalogue on process heat from 2020.
...

Sheet 1.2 heat_cool hp 80 C 75 K 
A1: Technology | C1: Combined heating and cooling heat pump, up to 80 °C, Temp lift = 75 K
A2: year | C2: 2025 | D2: 2030 | E2: 2035 | F2: 2040 | G2: 2050 | H2: 2025 | I2: 2025 | J2: 2050 | K2: 2050 | L2: Note | M2: Ref
A3: est | C3: ctrl | D3: ctrl | E3: ctrl | F3: ctrl | G3: ctrl | H3: lower | I3: upper | J3: lower | K3: upper | L3: - | M3: -
A4: cat | B4: par
A5: Energy/technical data
B6: Heat generation capacity for one unit [MW] | C6: 3 | D6: 3 | E6: 3 | F6: 3 | G6: 3 | H6: 0.5 | I6: 5 | J6: 0.5 | K6: 5 | L6: A | M6: [1, 2]
B7: Total efficiency, net [%], nominel load | C7: 3.35 | D7: 3.43 | E7: 3.48 | F7: =D7*1.02 -> 3.4986 | G7: =F7*1.01 -> 3.533586 | H7: 3.33 | I7: =C7*1.05 -> 3.5175 | J7: =G7*0.97 -> 3.4275784 | K7: =G7*1.02 -> 3.6042577 | L7: B | M7: [1, 3]
B8: Total efficiency, net [%], annual average | C8: =C7-5% -> 3.3 | D8: =D7-5% -> 3.38 | E8: =E7-5% -> 3.43 | F8: =F7-5% -> 3.4486 | G8: =G7-5% -> 3.483586 | H8: =H7-5% -> 3.28 | I8: =I7-5% -> 3.4675 | J8: =J7-5% -> 3.3775784 | K8: =K7-5% -> 3.5542577 | L8: B,C
B9: Auxiliary electricity consumption [% of heat gen] | C9: 0.01 | D9: 0.01 | E9: 0.01 | F9: 0.01 | G9: 0.01 | H9: 0.01 | I9: 0.04 | J9: 0.01 | K9: 0.04 | M9: 2
B10: Forced outage [%] | C10: 0 | D10: 0 | E10: 0 | F10: 0 | G10: 0 | H10: 0 | I10: 0.01 | J10: 0 | K10: 0.01 | L10: D | M10: 2
B11: Planned outage [weeks per year] | C11: 1 | D11: 1 | E11: 1 | F11: 1 | G11: 1 | H11: 0.5 | I11: 2 | J11: 0.5 | K11: 2 | M11: 2
B12: Technical lifetime [years] | C12: 25 | D12: 25 | E12: 25 | F12: 25 | G12: 25 | H12: 15 | I12: 40 | J12: 15 | K12: 40 | M12: 2
B13: Construction time [years] | C13: 0.5 | D13: 0.5 | E13: 0.5 | F13: 0.5 | G13: 0.5 | H13: 0.3 | I13: 1 | J13: 0.3 | K13: 1 | M13: 2
A14: Regulation Ability
B15: Minimum load [% of full load] | C15: 0.25 | D15: 0.25 | E15: 0.25 | F15: 0.25 | G15: 0.25 | H15: 0.1 | I15: 0.5 | J15: 0.1 | K15: 0.5 | M15: 2
B16: Warm start-up time [hours] | C16: 0.1 | D16: 0.1 | E16: 0.1 | F16: 0.1 | G16: 0.1 | H16: 0.1 | I16: 0.2 | J16: 0.1 | K16: 0.2 | M16: 2
B17: Cold start-up time [hours] | C17: 1 | D17: 1 | E17: 1 | F17: 1 | G17: 1 | H17: 0.2 | I17: 1 | J17: 0.2 | K17: 1 | M17: 2
A18: Financial data
B19: Nominal investment [M€/MW] | C19: 0.95 | D19: 0.94 | E19: 0.91 | F19: 0.91 | G19: 0.89 | H19: 0.91 | I19: 0.95 | J19: 0.88 | K19: 0.95 | M19: 2
B20: - of which equipment [%] | C20: 0.4 | D20: 0.4 | E20: 0.4 | F20: 0.4 | G20: 0.4 | L20: E | M20: 2
B21: - of which installation and other costs [%] | C21: 0.6 | D21: 0.6 | E21: 0.6 | F21: 0.6 | G21: 0.6 | L21: F | M21: 2
B22: Fixed O&M [€/MJ/s/year] | C22: 2127 | D22: 2095 | E22: 2032 | F22: 2032 | G22: 2001 | H22: 2032 | I22: 2127 | J22: 1970 | K22: 2127 | M22: 2
B23: Variable O&M [€/MWh] | C23: 3.07 | D23: 3.02 | E23: 2.93 | F23: 2.93 | G23: 2.89 | H23: 2.93 | I23: 3.07 | J23: 2.84 | K23: 3.07 | M23: 2
A24: Technology-specific data
B25: Indirect investments cost [M€/MW] | C25: =C19*0.2 -> 0.19 | D25: =D19*0.2 -> 0.188 | E25: =E19*0.2 -> 0.182 | F25: =F19*0.2 -> 0.182 | G25: =G19*0.2 -> 0.178 | L25: H
B26: Non energy gains [M€/MW] | C26: - | D26: - | E26: - | F26: - | G26: -
B27: Startup cost [€/MW/startup] | C27: 10 | D27: 10 | E27: 10 | F27: 10 | G27: 10
B28: Temperature heat source supply [°C] | C28: 15 | D28: 15 | E28: 15 | F28: 15 | G28: 15 | L28: I
B29: Temperature heat source return [°C] | C29: 5 | D29: 5 | E29: 5 | F29: 5 | G29: 5 | L29: I
B30: Cooling generation capacity for one unit [MW] | C30: =C6-C6/(C7/100) -> -86.552239 | D30: =D6-D6/(D7/100) -> -84.463557 | E30: =E6-E6/(E7/100) -> -83.206897 | F30: =F6-F6/(F7/100) -> -82.748585 | G30: =G6-G6/(G7/100) -> -81.899589
A33: Notes:
A34: A | B34: 0,5-5 MW
A35: B | B35: Estimated based on cases presented in [3]
A36: C | B36: Based on lost produktion during startup/shutdown
A37: D | B37: May vary depending on heat source availability
A38: E | B38: Very individual, can vary ÷ 20 %
A39: F | B39: Very individual, can vary + 20 %
A40: G | B40: Based on the old technology catalogue on process heat from 2020.
A41: H | B41: Going from current implementation to potential
A42: I | B42: Uses waste heat
...

Sheet 2.a High temp. hp Up to 125C
A1: Technology | C1: High-temperature heat pumps up to 125 °C
A2: year | C2: 2025 | D2: 2030 | E2: 2035 | F2: 2040 | G2: 2050 | H2: 2025 | I2: 2025 | J2: 2050 | K2: 2050 | L2: Note | M2: Ref
A3: est | C3: ctrl | D3: ctrl | E3: ctrl | F3: ctrl | G3: ctrl | H3: lower | I3: upper | J3: lower | K3: upper | L3: - | M3: -
A4: cat | B4: par
A5: Energy/technical data
B6: Heat generation capacity for one unit [MW] | C6: 2 | D6: 2 | E6: 3 | F6: 3 | G6: 3 | H6: 0.3 | I6: 25 | J6: 0.2 | K6: 50 | L6: B | M6: 4
B7: Total efficiency, net [%], nominel load. Based on a temperature lift of 65 K | C7: 2.75 | D7: 2.85 | E7: 2.9 | F7: 2.95 | G7: 3 | H7: 2.25 | I7: 4 | J7: 2.5 | K7: 4.5 | L7: C, H | M7: 1
B8: Total efficiency, net [%], annual average | C8: 2.7 | D8: 2.8 | E8: 2.85 | F8: 2.9 | G8: 2.95 | H8: 2.2 | I8: 3.95 | J8: 2.45 | K8: 4.45
B9: Auxiliary electricity consumption [% of heat gen] | C9: 0.02 | D9: 0.02 | E9: 0.02 | F9: 0.02 | G9: 0.02 | H9: 0.01 | I9: 0.07 | J9: 0.01 | K9: 0.07 | M9: 1
B10: Forced outage [days] | C10: 0 | D10: 0 | E10: 0 | F10: 0 | G10: 0 | H10: 0 | I10: 1 | J10: 0 | K10: 1 | M10: 4
B11: Planned outage [weeks per year] | C11: 0.5 | D11: 0.5 | E11: 0.5 | F11: 0.5 | G11: 0.5 | H11: 0 | I11: 1 | J11: 0 | K11: 1 | M11: 4
B12: Technical lifetime [years] | C12: 20 | D12: 20 | E12: 20 | F12: 20 | G12: 20 | H12: 15 | I12: 30 | J12: 15 | K12: 30 | L12: D | M12: 4
B13: Construction time [years] | C13: 0.6 | D13: 0.5 | E13: 0.4 | F13: 0.4 | G13: 0.4 | H13: 0.4 | I13: 0.8 | J13: 0.2 | K13: 0.8 | L13: E | M13: 4
B14: Space requirement [1000 m2/MW_e] | C14: 0.02 | D14: 0.02 | E14: 0.02 | F14: 0.02 | G14: 0.02 | H14: 0.01 | I14: 0.04 | J14: 0.01 | K14: 0.04
A15: Regulation ability
B16: Primary regulation (of full load, per 30 seconds) [] | C16: 0.05 | D16: 0.07 | E16: 0.08 | F16: 0.09 | G16: 0.1 | H16: 0.02 | I16: 0.1 | J16: 0.05 | K16: 0.2
B17: Secondary regulation (of full load, per minute) [] | C17: 0.1 | D17: 0.14 | E17: 0.16 | F17: 0.18 | G17: 0.2 | H17: 0.04 | I17: 0.2 | J17: 0.1 | K17: 0.4
B18: Minimum load (of full load) [] | C18: 0.25 | D18: 0.25 | E18: 0.25 | F18: 0.25 | G18: 0.25 | H18: 0.1 | I18: 0.5 | J18: 0.1 | K18: 0.5 | L18: F | M18: 4
B19: Warm start-up time [hours] | C19: 0.25 | D19: 0.25 | E19: 0.25 | F19: 0.25 | G19: 0.25 | H19: 0.1 | I19: 0.5 | J19: 0.1 | K19: 0.25 | M19: 4
B20: Cold start-up time [hours] | C20: 1 | D20: 1 | E20: 1 | F20: 1 | G20: 1 | H20: 0.5 | I20: 1.5 | J20: 0.5 | K20: 1.5 | M20: 4
A21: Financial data
B22: Nominal investment (*total) [MEUR/MW] | C22: 1.2 | D22: 1.15 | E22: 1.1 | F22: 1.05 | G22: 1 | H22: 0.9 | I22: 1.5 | J22: 0.7 | K22: 1.3 | L22: G | M22: [1, 4]
B23: - of which equipment [%] | C23: 0.4 | D23: 0.4 | E23: 0.4 | F23: 0.4 | G23: 0.4 | H23: 0.25 | I23: 0.6 | J23: 0.25 | K23: 0.7 | L23: A | M23: 1
B24: - of which installation [%] | C24: 0.6 | D24: 0.6 | E24: 0.6 | F24: 0.6 | G24: 0.6 | H24: 0.4 | I24: 0.75 | J24: 0.3 | K24: 0.75 | L24: A | M24: 3
B25: Fixed O&M [EUR/MW_y] | C25: 2494 | D25: 2456 | E25: 2382 | F25: 2382 | G25: 2345 | M25: 2
B26: Variable O&M [EUR/MWh] | C26: 3.6 | D26: 3.54 | E26: 3.43 | F26: 3.43 | G26: 3.39 | M26: 2
A27: Technology-specific data
B28: Technology dependent
B29: Indirect investment cost [M€/MW] | C29: 0.23 | D29: 0.23 | E29: 0.23 | F29: 0.23 | G29: 0.23 | L29: I
B30: - Steam generation decreases COP [%-point] | C30: -0.15 | D30: -0.1 | E30: -0.05 | F30: -0.05 | G30: -0.05 | H30: -0.05 | I30: -0.2 | J30: -0.05 | K30: -0.15 | M30: [1, 4]
B31: - Steam generation increases equipment cost by [MEUR/MW] | C31: 0.2 | D31: 0.15 | E31: 0.1 | F31: 0.1 | G31: 0.1 | H31: 0.05 | I31: 0.3 | J31: 0.05 | K31: 0.2 | M31: [1, 4]
B32: - Additional equipment cost for temperature lift above 75 K [MEUR/MW] | C32: =MROUND(C22*C23*0.3,0.05) -> 0.15 | D32: =MROUND(D22*D23*0.3,0.05) -> 0.15 | E32: =MROUND(E22*E23*0.3,0.05) -> 0.15 | F32: =MROUND(F22*F23*0.3,0.05) -> 0.15 | G32: =MROUND(G22*G23*0.3,0.05) -> 0.1 | H32: =MROUND(H22*H23*0.3,0.05) -> 0.05 | I32: =MROUND(I22*I23*0.3,0.05) -> 0.25 | J32: =MROUND(J22*J23*0.3,0.05) -> 0.05 | K32: =MROUND(K22*K23*0.3,0.05) -> 0.25 | M32: [1, 4]
B33: - Total efficiency, net [%], nominel load. Based on a temperature lift of 40 K | C33: 4.45 | D33: 4.65 | E33: 4.7 | F33: 4.8 | G33: 4.9 | H33: 3.65 | I33: 6.5 | J33: 4.05 | K33: 7.3 | M33: [1, 4]
B34: - Total efficiency, net [%], nominel load. Based on a temperature lift of 80 K | C34: 2.4 | D34: 2.45 | E34: 2.5 | F34: 2.55 | G34: 2.6 | H34: 2 | I34: 3.4 | J34: 2.2 | K34: 3.8 | M34: [1, 4]
B35: - Total efficiency, net [%], nominel load. Based on a temperature lift of 100 K | C35: 2.05 | D35: 2.1 | E35: 2.15 | F35: 2.2 | G35: 2.2 | H35: 1.7 | I35: 2.85 | J35: 1.9 | K35: 3.2 | M35: [1, 4]
A38: Notes:
A39: A | B39: Depends on production infrastructure. If HTHP replaces another HTHP, there will be lower investment in new installation
A40: B | B40: Unit sizes vary a lot and depends on production infrastructure. Lower capacities for specific production processes and higher capacities for central hot water supply
A41: C | B41: Efficiency depends on temperature lift of HTHP. High temperature lift reduces COP.
A42: D | B42: Both depends on lifetime of parts and new technology with higher efficiencies leading to replacement of existing systems
...

Sheet 2.b High temp. hp Up to 150
A1: Technology | C1: High-temperature heat pumps up to 150 °C
A2: year | C2: 2025 | D2: 2030 | E2: 2035 | F2: 2040 | G2: 2050 | H2: 2025 | I2: 2025 | J2: 2050 | K2: 2050 | L2: Note | M2: Ref
A3: est | C3: ctrl | D3: ctrl | E3: ctrl | F3: ctrl | G3: ctrl | H3: lower | I3: upper | J3: lower | K3: upper | L3: - | M3: -
A4: cat | B4: par
A5: Energy/technical data
B6: Heat generation capacity for one unit [MW] | C6: 2 | D6: 2 | E6: 3 | F6: 3 | G6: 3 | H6: 0.5 | I6: 80 | J6: 0.5 | K6: 100 | L6: B | M6: 4
B7: Total efficiency, net [%], nominel load. Based on a temperature lift of 65 K | C7: 2.75 | D7: 2.85 | E7: 2.9 | F7: 2.95 | G7: 3 | H7: 2.25 | I7: 4 | J7: 2.5 | K7: 4.5 | L7: C, H | M7: 1
B8: Total efficiency, net [%], annual average | C8: 2.7 | D8: 2.8 | E8: 2.85 | F8: 2.9 | G8: 2.95 | H8: 2.2 | I8: 3.95 | J8: 2.45 | K8: 4.45
B9: Auxiliary electricity consumption [% of heat gen] | C9: 0.02 | D9: 0.02 | E9: 0.02 | F9: 0.02 | G9: 0.02 | H9: 0.01 | I9: 0.07 | J9: 0.01 | K9: 0.07 | M9: 1
B10: Forced outage [days] | C10: 0 | D10: 0 | E10: 0 | F10: 0 | G10: 0 | H10: 0 | I10: 1 | J10: 0 | K10: 1 | M10: 4
B11: Planned outage [weeks per year] | C11: 0.5 | D11: 0.5 | E11: 0.5 | F11: 0.5 | G11: 0.5 | H11: 0 | I11: 1 | J11: 0 | K11: 1 | M11: 4
B12: Technical lifetime [years] | C12: 20 | D12: 20 | E12: 20 | F12: 20 | G12: 20 | H12: 15 | I12: 30 | J12: 15 | K12: 30 | L12: D | M12: 4
B13: Construction time [years] | C13: 0.6 | D13: 0.5 | E13: 0.4 | F13: 0.4 | G13: 0.4 | H13: 0.4 | I13: 0.8 | J13: 0.2 | K13: 0.8 | L13: E | M13: 4
B14: Space requirement [1000 m2/MW_e] | C14: 0.03 | D14: 0.03 | E14: 0.03 | F14: 0.03 | G14: 0.03 | H14: 0.02 | I14: 0.06 | J14: 0.01 | K14: 0.05
A15: Regulation ability
B16: Primary regulation (of full load, per 30 seconds) [] | C16: 0.05 | D16: 0.07 | E16: 0.08 | F16: 0.09 | G16: 0.1 | H16: 0.02 | I16: 0.1 | J16: 0.05 | K16: 0.2
B17: Secondary regulation (of full load, per minute) [] | C17: 0.1 | D17: 0.14 | E17: 0.16 | F17: 0.18 | G17: 0.2 | H17: 0.04 | I17: 0.2 | J17: 0.1 | K17: 0.4
B18: Minimum load (of full load) [] | C18: 0.25 | D18: 0.25 | E18: 0.25 | F18: 0.25 | G18: 0.25 | H18: 0.1 | I18: 0.5 | J18: 0.1 | K18: 0.5 | L18: F | M18: 4
B19: Warm start-up time [hours] | C19: 0.25 | D19: 0.25 | E19: 0.25 | F19: 0.25 | G19: 0.25 | H19: 0.1 | I19: 0.5 | J19: 0.1 | K19: 0.25 | M19: 4
B20: Cold start-up time [hours] | C20: 1 | D20: 1 | E20: 1 | F20: 1 | G20: 1 | H20: 0.5 | I20: 1.5 | J20: 0.5 | K20: 1.5 | M20: 4
A21: Financial data
B22: Nominal investment (*total) [MEUR/MW] | C22: 1.55 | D22: 1.5 | E22: 1.45 | F22: 1.4 | G22: 1.35 | H22: 1.25 | I22: 1.8 | J22: 1.1 | K22: 1.65 | L22: G
B23: - of which equipment [%] | C23: 0.4 | D23: 0.4 | E23: 0.4 | F23: 0.4 | G23: 0.4 | H23: 0.25 | I23: 0.6 | J23: 0.25 | K23: 0.7 | L23: A | M23: 1
B24: - of which installation [%] | C24: 0.6 | D24: 0.6 | E24: 0.6 | F24: 0.6 | G24: 0.6 | H24: 0.4 | I24: 0.75 | J24: 0.3 | K24: 0.75 | L24: A | M24: 3
B25: Fixed O&M [EUR/MW_y], from last update in 2019 | C25: 2494 | D25: 2456 | E25: 2382 | F25: 2382 | G25: 2345 | M25: 2
B26: Variable O&M [EUR/MWh], from last update in 2019 | C26: 3.6 | D26: 3.54 | E26: 3.43 | F26: 3.43 | G26: 3.39 | M26: 1
A27: Technology-specific data
B28: Technology dependent
B29: Indirect investment cost [M€/MW] | C29: 0.23 | D29: 0.23 | E29: 0.23 | F29: 0.23 | G29: 0.23 | L29: I
B30: - Steam generation decreases COP [%-point] | C30: -0.15 | D30: -0.1 | E30: -0.05 | F30: -0.05 | G30: -0.05 | H30: -0.05 | I30: -0.2 | J30: -0.05 | K30: -0.15 | M30: [1, 4]
B31: - Steam generation increases equipment cost by [MEUR/MW] | C31: 0.2 | D31: 0.15 | E31: 0.1 | F31: 0.1 | G31: 0.1 | H31: 0.05 | I31: 0.3 | J31: 0.05 | K31: 0.2 | M31: [1, 4]
B32: - Additional equipment cost for temperature lift above 75 K [MEUR/MW] | C32: =MROUND(C22*C23*0.3,0.05) -> 0.2 | D32: =MROUND(D22*D23*0.3,0.05) -> 0.2 | E32: =MROUND(E22*E23*0.3,0.05) -> 0.15 | F32: =MROUND(F22*F23*0.3,0.05) -> 0.15 | G32: =MROUND(G22*G23*0.3,0.05) -> 0.15 | H32: =MROUND(H22*H23*0.3,0.05) -> 0.1 | I32: =MROUND(I22*I23*0.3,0.05) -> 0.3 | J32: =MROUND(J22*J23*0.3,0.05) -> 0.1 | K32: =MROUND(K22*K23*0.3,0.05) -> 0.35 | M32: [1, 4]
B33: - Total efficiency, net [%], nominel load. Based on a temperature lift of 40 K | C33: 4.45 | D33: 4.65 | E33: 4.7 | F33: 4.8 | G33: 4.9 | H33: 3.65 | I33: 6.5 | J33: 4.05 | K33: 7.3 | M33: [1, 4]
B34: - Total efficiency, net [%], nominel load. Based on a temperature lift of 80 K | C34: 2.4 | D34: 2.45 | E34: 2.5 | F34: 2.55 | G34: 2.6 | H34: 2 | I34: 3.4 | J34: 2.2 | K34: 3.8 | M34: [1, 4]
B35: - Total efficiency, net [%], nominel load. Based on a temperature lift of 100 K | C35: 2.05 | D35: 2.1 | E35: 2.15 | F35: 2.2 | G35: 2.2 | H35: 1.7 | I35: 2.85 | J35: 1.9 | K35: 3.2 | M35: [1, 4]
A38: Notes:
A39: A | B39: Depends on production infrastructure. If HTHP replaces another HTHP, there will be lower investment in new installation
A40: B | B40: Unit sizes vary a lot and depends on production infrastructure. Lower capacities for specific production processes and higher capacities for central hot water supply
A41: C | B41: Efficiency depends on temperature lift of HTHP. High temperature lift reduces COP.
A42: D | B42: Both depends on lifetime of parts and new technology with higher efficiencies leading to replacement of existing systems
...

Sheet 4 MVR 5 K
A1: Technology | C1: Mechanical vapor recompression
A2: year | C2: 2025 | D2: 2030 | E2: 2035 | F2: 2040 | G2: 2050 | H2: 2025 | I2: 2025 | J2: 2050 | K2: 2050 | L2: Note | M2: Ref
A3: est | C3: ctrl | D3: ctrl | E3: ctrl | F3: ctrl | G3: ctrl | H3: lower | I3: upper | J3: lower | K3: upper | L3: - | M3: -
A4: cat | B4: par
A5: Energy/technical data
B6: Heat generation capacity for one unit [MW] | C6: 20 | D6: 20 | E6: 20 | F6: 20 | G6: 20 | H6: 5 | I6: 50 | J6: 5 | K6: 50 | L6: A | M6: 1
B7: Total efficiency, net [%], nominel load | C7: 12.6 | D7: 13.2 | E7: 13.5 | F7: 13.8 | G7: 14.3 | H7: 10 | I7: 15.12 | J7: 10.56 | K7: 17.16 | L7: B | M7: 1
B8: Total efficiency, net [%], annual average | C8: =C7-50% -> 12.1 | D8: =D7-50% -> 12.7 | E8: =E7-50% -> 13 | F8: =F7-50% -> 13.3 | G8: =G7-50% -> 13.8 | H8: =H7-50% -> 9.5 | I8: =I7-50% -> 14.62 | J8: =J7-50% -> 10.06 | K8: =K7-50% -> 16.66
B9: Auxiliary electricity consumption [% of heat gen] | C9: 0.01 | D9: 0.01 | E9: 0.01 | F9: 0.01 | G9: 0.01 | H9: 0 | I9: 0.02 | J9: 0 | K9: 0.02 | M9: 3
B10: Forced outage [%] | C10: 0 | D10: 0 | E10: 0 | F10: 0 | G10: 0 | H10: 0 | I10: 0.01 | J10: 0 | K10: 0.01 | M10: 2
B11: Planned outage [weeks per year] | C11: 0.5 | D11: 0.5 | E11: 0.5 | F11: 0.5 | G11: 0.5 | H11: 0 | I11: 1 | J11: 0 | K11: 1 | M11: 2
B12: Technical lifetime [years] | C12: 25 | D12: 25 | E12: 25 | F12: 25 | G12: 25 | H12: 15 | I12: 35 | J12: 15 | K12: 35 | M12: [1, 2]
B13: Construction time [years] | C13: 0.1 | D13: 0.1 | E13: 0.1 | F13: 0.1 | G13: 0.1 | H13: 0.05 | I13: 0.2 | J13: 0.05 | K13: 0.2 | M13: [1, 3]
A14: Regulation Ability
B15: Minimum load [% of full load] | C15: 0.15 | D15: 0.15 | E15: 0.15 | F15: 0.15 | G15: 0.15 | M15: 4
B16: Warm start-up time [hours] | C16: 0.5 | D16: 0.5 | E16: 0.5 | F16: 0.5 | G16: 0.5 | M16: 3
B17: Cold start-up time [hours] | C17: 1 | D17: 1 | E17: 1 | F17: 1 | G17: 1 | M17: 3
A18: Financial data
B19: Nominal investment [M€/MW] | C19: 0.41 | D19: 0.39 | E19: 0.39 | F19: 0.38 | G19: 0.36 | M19: [1, 5]
B20: - of which equipment [%] | C20: 0.6 | D20: 0.6 | E20: 0.6 | F20: 0.6 | G20: 0.6 | M20: [1, 5]
B21: - of which installation [%] | C21: 0.4 | D21: 0.4 | E21: 0.4 | F21: 0.4 | G21: 0.4 | M21: [1, 5]
B22: Fixed O&M [€/MJ/s/year] | C22: 2345 | D22: 2345 | E22: 2345 | F22: 2345 | G22: 2345 | M22: 2
B23: Variable O&M [€/MWh] | C23: 2.1 | D23: 2 | E23: 2 | F23: 2 | G23: 1.9 | M23: 2
A26: Notes:
A27: A | B27: 5-50 MW
A28: B | B28: Assumed temperature lift of 5 K (saturation temperatur)
A30: References:
A31: 1 | B31: Viegand Maagøe, MVR, 2018
A32: 2 | B32: Technological data for energi plants (Compressions Heat Pumps for DH), Energistyrelsen, 2017
A33: 3 | B33: Viegand Maagøe, 2019
A34: 4 | B34: EPCON, EVAPORATION TECHNOLOGY, 2019
A35: 5 | B35: EPCON investment cost offer, 2017.

Sheet 5.1a Electric boiler steam
A1: Technology | C1: Electric boiler, 0,4-0,69 kV, steam, 1-12 bar
A2: year | C2: 2025 | D2: 2030 | E2: 2035 | F2: 2040 | G2: 2050 | H2: 2025 | I2: 2025 | J2: 2050 | K2: 2050 | L2: Note | M2: Ref
A3: est | C3: ctrl | D3: ctrl | E3: ctrl | F3: ctrl | G3: ctrl | H3: lower | I3: upper | J3: lower | K3: upper | L3: - | M3: -
A4: cat | B4: par
A5: Energy/technical data
B6: Heat generation capacity for one unit [MW] | C6: 2 | D6: 2 | E6: 2 | F6: 2 | G6: 2 | H6: 1 | I6: 5 | J6: 1 | K6: 5 | L6: A
B7: Total efficiency, net [%], nominel load | C7: 0.99 | D7: 0.99 | E7: 0.99 | F7: 0.99 | G7: 0.99 | H7: 0.98 | I7: 1 | J7: 0.98 | K7: 1 | M7: [1, 2]
B8: Total efficiency, net [%], annual average | C8: 0.99 | D8: 0.99 | E8: 0.99 | F8: 0.99 | G8: 0.99 | H8: 0.98 | I8: 0.99 | J8: 0.98 | K8: 0.99 | M8: [1, 2]
B9: Auxiliary electricity consumption [% of heat gen] | C9: 0.005 | D9: 0.005 | E9: 0.005 | F9: 0.005 | G9: 0.005 | H9: 0.001 | I9: 0.005 | J9: 0.001 | K9: 0.005 | M9: [1, 2]
B10: Forced outage [%] | C10: 0.01 | D10: 0.01 | E10: 0.01 | F10: 0.01 | G10: 0.01 | H10: 0.005 | I10: 0.01 | J10: 0.005 | K10: 0.01 | M10: [1, 2]
B11: Planned outage [weeks per year] | C11: 0.2 | D11: 0.2 | E11: 0.2 | F11: 0.2 | G11: 0.2 | H11: 0.2 | I11: 0.2 | J11: 0.2 | K11: 0.2 | M11: 2
B12: Technical lifetime [years] | C12: 25 | D12: 25 | E12: 25 | F12: 25 | G12: 25 | H12: 20 | I12: 25 | J12: 20 | K12: 25 | M12: 2
B13: Construction time [years] | C13: 0.5 | D13: 0.5 | E13: 0.5 | F13: 0.5 | G13: 0.5 | H13: 0.5 | I13: 1 | J13: 0.5 | K13: 1 | M13: 1
A14: Regulation Ability
B15: Minimum load [% of full load] | C15: 0.02 | D15: 0.02 | E15: 0.02 | F15: 0.02 | G15: 0.02 | M15: 2
B16: Warm start-up time [hours] | C16: 0.03 | D16: 0.03 | E16: 0.03 | F16: 0.03 | G16: 0.03 | M16: 2
B17: Cold start-up time [hours] | C17: 0.17 | D17: 0.17 | E17: 0.17 | F17: 0.17 | G17: 0.17 | M17: 2
A18: Financial data
B19: Nominal investment [M€/MW] | C19: 0.25 | D19: 0.22 | E19: 0.22 | F19: 0.22 | G19: 0.22 | L19: B,C | M19: [1, 2, 4]
B20: - of which equipment [%] | C20: 0.75 | D20: 0.75 | E20: 0.75 | F20: 0.75 | G20: 0.75 | M20: [2, 4]
B21: - of which installation [%] | C21: 0.25 | D21: 0.25 | E21: 0.25 | F21: 0.25 | G21: 0.25 | M21: [2, 4]
B22: Fixed O&M [€/MJ/s/year] | C22: 1442 | D22: 1375 | E22: 1341 | F22: 1307 | G22: 1240 | M22: [2, 3, 4]
B23: Variable O&M [€/MWh] | C23: 0.674 | D23: 0.642 | E23: 0.627 | F23: 0.611 | G23: 0.578 | M23: [2, 3, 4]
A24: Technology-specific data
B25: Additional investments cost for 12-16 bar boilers [M€/MW] | C25: 0.064 | D25: 0.057 | E25: 0.057 | F25: 0.057 | G25: 0.057
A28: Notes:
A29: A | B29: 1-5 MW
A30: B | B30: Electrode boilers at low voltage typically needs a transformer from distribution grid. Costs for the transformer are included in the equipment costs.
A31: C | B31: Investment cost is slightly higher than for a hot water boiler.
A33: References:
A34: 1 | B34: Danish Enegy Agency, Technology Data - Energy Plants for Electricity and District heating generation, 2022
A35: 2 | B35: AS:scan, Personal communication, 2022
A36: 3 | B36: Tjæreborg Industri, Personal communication, 2022
A37: 4 | B37: Nordheat, Personal communication, 2022

Sheet 5.1b Electric boiler steam
A1: Technology | C1: Electric boiler, 10 kV, steam, 1-12 bar
A2: year | C2: 2025 | D2: 2030 | E2: 2035 | F2: 2040 | G2: 2050 | H2: 2025 | I2: 2025 | J2: 2050 | K2: 2050 | L2: Note | M2: Ref
A3: est | C3: ctrl | D3: ctrl | E3: ctrl | F3: ctrl | G3: ctrl | H3: lower | I3: upper | J3: lower | K3: upper | L3: - | M3: -
A4: cat | B4: par
A5: Energy/technical data
B6: Heat generation capacity for one unit [MW] | C6: 15 | D6: 15 | E6: 15 | F6: 15 | G6: 15 | H6: 5 | I6: 60 | J6: 5 | K6: 60 | L6: A
B7: Total efficiency, net [%], nominel load | C7: 0.99 | D7: 0.99 | E7: 0.99 | F7: 0.99 | G7: 0.99 | H7: 0.98 | I7: 1 | J7: 0.98 | K7: 1 | M7: [1, 2]
B8: Total efficiency, net [%], annual average | C8: 0.99 | D8: 0.99 | E8: 0.99 | F8: 0.99 | G8: 0.99 | H8: 0.98 | I8: 0.99 | J8: 0.98 | K8: 0.99 | M8: [1, 2]
B9: Auxiliary electricity consumption [% of heat gen] | C9: 0.005 | D9: 0.005 | E9: 0.005 | F9: 0.005 | G9: 0.005 | H9: 0.001 | I9: 0.005 | J9: 0.001 | K9: 0.005 | M9: [1, 2]
B10: Forced outage [%] | C10: 0.01 | D10: 0.01 | E10: 0.01 | F10: 0.01 | G10: 0.01 | H10: 0.005 | I10: 0.01 | J10: 0.005 | K10: 0.01 | M10: [1, 2]
B11: Planned outage [weeks per year] | C11: 0.2 | D11: 0.2 | E11: 0.2 | F11: 0.2 | G11: 0.2 | H11: 0.2 | I11: 0.2 | J11: 0.2 | K11: 0.2 | M11: 2
B12: Technical lifetime [years] | C12: 25 | D12: 25 | E12: 25 | F12: 25 | G12: 25 | H12: 20 | I12: 25 | J12: 20 | K12: 25 | M12: 2
B13: Construction time [years] | C13: 0.5 | D13: 0.5 | E13: 0.5 | F13: 0.5 | G13: 0.5 | H13: 0.5 | I13: 1 | J13: 0.5 | K13: 1 | M13: 1
A14: Regulation Ability
B15: Minimum load [% of full load] | C15: 0.02 | D15: 0.02 | E15: 0.02 | F15: 0.02 | G15: 0.02 | M15: 2
B16: Warm start-up time [hours] | C16: 0.03 | D16: 0.03 | E16: 0.03 | F16: 0.03 | G16: 0.03 | M16: 2
B17: Cold start-up time [hours] | C17: 0.17 | D17: 0.17 | E17: 0.17 | F17: 0.17 | G17: 0.17 | M17: 2
A18: Financial data
B19: Nominal investment [M€/MW] | C19: 0.11 | D19: 0.1 | E19: 0.1 | F19: 0.1 | G19: 0.1 | L19: B,C | M19: [1, 2, 4]
B20: - of which equipment [%] | C20: 0.85 | D20: 0.85 | E20: 0.85 | F20: 0.85 | G20: 0.85 | M20: 2
B21: - of which installation [%] | C21: 0.15 | D21: 0.15 | E21: 0.15 | F21: 0.15 | G21: 0.15 | M21: 2
B22: Fixed O&M [€/MJ/s/year] | C22: 1298 | D22: 1237 | E22: 1208 | F22: 1177 | G22: 1116 | M22: [2, 3, 4]
B23: Variable O&M [€/MWh] | C23: 0.61 | D23: 0.58 | E23: 0.56 | F23: 0.55 | G23: 0.52 | M23: [2, 3, 4]
A24: Technology-specific data
B25: Additional investments cost for 12-16 bar boilers [M€/MW] | C25: 0.021 | D25: 0.018 | E25: 0.018 | F25: 0.018 | G25: 0.018
A28: Notes:
A29: A | B29: 5-60 MW
A30: B | B30: Electrode boilers at medium-high voltage are directly connected to the distribution grid. Costs for the distribution board are included in the equipment costs.
A31: C | B31: Investment cost is slightly higher than for a hot water boiler.
A33: References:
A34: 1 | B34: Danish Enegy Agency, Technology Data - Energy Plants for Electricity and District heating generation, 2022
A35: 2 | B35: AS:scan, Personal communication, 2022
A36: 3 | B36: Tjæreborg Industri, Personal communication, 2022
A37: 4 | B37: Nordheat, Personal communication, 2022

Sheet 5.2a Electric boiler hot wate
A1: Technology | C1: Electric boiler, 0,4-0,69 kV, hot water, 1-12 bar
A2: year | C2: 2025 | D2: 2030 | E2: 2035 | F2: 2040 | G2: 2050 | H2: 2025 | I2: 2025 | J2: 2050 | K2: 2050 | L2: Note | M2: Ref
A3: est | C3: ctrl | D3: ctrl | E3: ctrl | F3: ctrl | G3: ctrl | H3: lower | I3: upper | J3: lower | K3: upper | L3: - | M3: -
A4: cat | B4: par
A5: Energy/technical data
B6: Heat generation capacity for one unit [MW] | C6: 2 | D6: 2 | E6: 2 | F6: 2 | G6: 2 | H6: 1 | I6: 5 | J6: 1 | K6: 5 | L6: A
B7: Total efficiency, net [%], nominel load | C7: 0.99 | D7: 0.99 | E7: 0.99 | F7: 0.99 | G7: 0.99 | H7: 0.98 | I7: 1 | J7: 0.98 | K7: 1 | M7: [1, 2]
B8: Total efficiency, net [%], annual average | C8: 0.99 | D8: 0.99 | E8: 0.99 | F8: 0.99 | G8: 0.99 | H8: 0.98 | I8: 0.99 | J8: 0.98 | K8: 0.99 | M8: [1, 2]
B9: Auxiliary electricity consumption [% of heat gen] | C9: 0.005 | D9: 0.005 | E9: 0.005 | F9: 0.005 | G9: 0.005 | H9: 0.001 | I9: 0.005 | J9: 0.001 | K9: 0.005 | M9: [1, 2]
B10: Forced outage [%] | C10: 0.01 | D10: 0.01 | E10: 0.01 | F10: 0.01 | G10: 0.01 | H10: 0.005 | I10: 0.01 | J10: 0.005 | K10: 0.01 | M10: [1, 2]
B11: Planned outage [weeks per year] | C11: 0.2 | D11: 0.2 | E11: 0.2 | F11: 0.2 | G11: 0.2 | H11: 0.2 | I11: 0.2 | J11: 0.2 | K11: 0.2 | M11: 1
B12: Technical lifetime [years] | C12: 25 | D12: 25 | E12: 25 | F12: 25 | G12: 25 | H12: 20 | I12: 25 | J12: 20 | K12: 25 | M12: 2
B13: Construction time [years] | C13: 0.5 | D13: 0.5 | E13: 0.5 | F13: 0.5 | G13: 0.5 | H13: 0.5 | I13: 1 | J13: 0.5 | K13: 1 | M13: 1
A14: Regulation Ability
B15: Minimum load [% of full load] | C15: 0.05 | D15: 0.05 | E15: 0.05 | F15: 0.05 | G15: 0.05 | M15: 1
B16: Warm start-up time [hours] | C16: 0.008 | D16: 0.008 | E16: 0.008 | F16: 0.008 | G16: 0.008 | M16: 1
B17: Cold start-up time [hours] | C17: 0.08 | D17: 0.08 | E17: 0.08 | F17: 0.08 | G17: 0.08 | M17: 1
A18: Financial data
B19: Nominal investment [M€/MW] | C19: 0.202 | D19: 0.187 | E19: 0.187 | F19: 0.187 | G19: 0.187 | L19: B,C | M19: [1, 2, 4]
B20: - of which equipment [%] | C20: 0.75 | D20: 0.75 | E20: 0.75 | F20: 0.75 | G20: 0.75 | M20: 2
B21: - of which installation [%] | C21: 0.25 | D21: 0.25 | E21: 0.25 | F21: 0.25 | G21: 0.25 | M21: 2
B22: Fixed O&M [€/MJ/s/year] | C22: 1254 | D22: 1196 | E22: 1166 | F22: 1137 | G22: 1079 | M22: 1
B23: Variable O&M [€/MWh] | C23: 0.59 | D23: 0.56 | E23: 0.54 | F23: 0.53 | G23: 0.5 | M23: [2, 3, 4]
A24: Technology-specific data
B25: Indirect investments cost [M€/MW] | C25: =C19*0.5 -> 0.101 | D25: =D19*0.5 -> 0.0935 | E25: =E19*0.5 -> 0.0935 | F25: =F19*0.5 -> 0.0935 | G25: =G19*0.5 -> 0.0935 | L25: D
B26: Additional investments cost for 12-16 bar boilers [M€/MW] | C26: 0.057 | D26: 0.049 | E26: 0.049 | F26: 0.049 | G26: 0.049
A29: Notes:
A30: A | B30: 1-5 MW
A31: B | B31: Electrode boilers at low voltage typically needs a transformer from distribution grid. Costs for the transformer are included in the equipment costs.
A32: C | B32: Investment cost is slightly lower than for a steam boiler.
A33: D | B33: Going from current implementation to potential
A35: References:
A36: 1 | B36: Danish Enegy Agency, Technology Data - Energy Plants for Electricity and District heating generation, 2022
A37: 2 | B37: AS:scan, Personal communication, 2022
A38: 3 | B38: Tjæreborg Industri, Personal communication, 2019
A39: 4 | B39: Nordheat, Personal communication, 2022

Sheet 5.2b Electric boiler hot wate
A1: Technology | C1: Electric boiler,10 kV, hot water, 1-12 bar
A2: year | C2: 2025 | D2: 2030 | E2: 2035 | F2: 2040 | G2: 2050 | H2: 2025 | I2: 2025 | J2: 2050 | K2: 2050 | L2: Note | M2: Ref
A3: est | C3: ctrl | D3: ctrl | E3: ctrl | F3: ctrl | G3: ctrl | H3: lower | I3: upper | J3: lower | K3: upper | L3: - | M3: -
A4: cat | B4: par
A5: Energy/technical data
B6: Heat generation capacity for one unit [MW] | C6: 15 | D6: 15 | E6: 15 | F6: 15 | G6: 15 | H6: 5 | I6: 60 | J6: 5 | K6: 60 | L6: A
B7: Total efficiency, net [%], nominel load | C7: 0.99 | D7: 0.99 | E7: 0.99 | F7: 0.99 | G7: 0.99 | H7: 0.98 | I7: 1 | J7: 0.98 | K7: 1 | M7: [1, 2]
B8: Total efficiency, net [%], annual average | C8: 0.99 | D8: 0.99 | E8: 0.99 | F8: 0.99 | G8: 0.99 | H8: 0.98 | I8: 0.99 | J8: 0.98 | K8: 0.99 | M8: [1, 2]
B9: Auxiliary electricity consumption [% of heat gen] | C9: 0.005 | D9: 0.005 | E9: 0.005 | F9: 0.005 | G9: 0.005 | H9: 0.001 | I9: 0.005 | J9: 0.001 | K9: 0.005 | M9: [1, 2]
B10: Forced outage [%] | C10: 0.01 | D10: 0.01 | E10: 0.01 | F10: 0.01 | G10: 0.01 | H10: 0.005 | I10: 0.01 | J10: 0.005 | K10: 0.01 | M10: [1, 2]
B11: Planned outage [weeks per year] | C11: 0.2 | D11: 0.2 | E11: 0.2 | F11: 0.2 | G11: 0.2 | H11: 0.2 | I11: 0.2 | J11: 0.2 | K11: 0.2 | M11: 1
B12: Technical lifetime [years] | C12: 25 | D12: 25 | E12: 25 | F12: 25 | G12: 25 | H12: 20 | I12: 25 | J12: 20 | K12: 25 | M12: 2
B13: Construction time [years] | C13: 0.5 | D13: 0.5 | E13: 0.5 | F13: 0.5 | G13: 0.5 | H13: 0.5 | I13: 1 | J13: 0.5 | K13: 1 | M13: 1
A14: Regulation Ability
B15: Minimum load [% of full load] | C15: 0.05 | D15: 0.05 | E15: 0.05 | F15: 0.05 | G15: 0.05 | M15: 1
B16: Warm start-up time [hours] | C16: 0.008 | D16: 0.008 | E16: 0.008 | F16: 0.008 | G16: 0.008 | M16: 1
B17: Cold start-up time [hours] | C17: 0.08 | D17: 0.08 | E17: 0.08 | F17: 0.08 | G17: 0.08 | M17: 1
A18: Financial data
B19: Nominal investment [M€/MW] | C19: 0.089 | D19: 0.084 | E19: 0.084 | F19: 0.084 | G19: 0.084 | L19: B,C | M19: [1, 2, 4]
B20: - of which equipment [%] | C20: 0.85 | D20: 0.85 | E20: 0.85 | F20: 0.85 | G20: 0.85 | M20: 2
B21: - of which installation [%] | C21: 0.15 | D21: 0.15 | E21: 0.15 | F21: 0.15 | G21: 0.15 | M21: 2
B22: Fixed O&M [€/MJ/s/year] | C22: 1103 | D22: 1076 | E22: 1050 | F22: 1023 | G22: 971 | M22: [1, 2, 4]
B23: Variable O&M [€/MWh] | C23: 0.53 | D23: 0.5 | E23: 0.49 | F23: 0.48 | G23: 0.45 | M23: [2, 3, 4]
A24: Technology-specific data
B25: Indirect investments cost [M€/MW] | C25: =C19/2 -> 0.0445 | D25: =D19/2 -> 0.042 | E25: =E19/2 -> 0.042 | F25: =F19/2 -> 0.042 | G25: =G19/2 -> 0.042 | L25: D
B26: Additional investments cost for 12-16 bar boilers [M€/MW] | C26: 0.018 | D26: 0.016 | E26: 0.016 | F26: 0.016 | G26: 0.016
A29: Notes:
A30: A | B30: 5-60 MW
A31: B | B31: Electrode boilers at medium-high voltage are directly connected to the distribution grid. Costs for the distribution board are included in the equipment costs.
A32: C | B32: Investment cost is slightly lower than for a steam boiler.
A33: D | B33: Going from current implementation to potential
A35: References:
A36: 1 | B36: Danish Enegy Agency, Technology Data - Energy Plants for Electricity and District heating generation, 2022
A37: 2 | B37: AS:scan, Personal communication, 2022
A38: 3 | B38: Tjæreborg Industri, Personal communication, 2022
A39: 4 | B39: Nordheat, Personal communication, 2022

Sheet 6.1 Boiler, gas and oil
A1: Technology | C1: Boiler, gas and oil
A2: year | C2: 2025 | D2: 2030 | E2: 2035 | F2: 2040 | G2: 2050 | H2: 2025 | I2: 2025 | J2: 2050 | K2: 2050 | L2: Note | M2: Ref
A3: est | C3: ctrl | D3: ctrl | E3: ctrl | F3: ctrl | G3: ctrl | H3: lower | I3: upper | J3: lower | K3: upper | L3: - | M3: -
A4: cat | B4: par
A5: Energy/technical data
B6: Heat generation capacity for one unit [MW] | C6: 5 | D6: 5 | E6: 5 | F6: 5 | G6: 5 | H6: 0.5 | I6: 50 | J6: 0.5 | K6: 50 | M6: [1, 2, 3, 6]
B7: Total efficiency, net [%], nominel load | C7: 0.94 | D7: 0.94 | E7: 0.94 | F7: 0.94 | G7: 0.94 | H7: 0.92 | I7: 0.95 | J7: 0.92 | K7: 0.95 | L7: A, B, E | M7: [1, 4, 6]
B8: Total efficiency, net [%], annual average | C8: 0.939 | D8: 0.939 | E8: 0.939 | F8: 0.939 | G8: 0.939 | H8: 0.919 | I8: 0.949 | J8: 0.919 | K8: 0.949 | L8: A, B, D | M8: [1, 4]
B9: Auxiliary electricity consumption [% of heat gen] | C9: 0.0015 | D9: 0.0015 | E9: 0.0015 | F9: 0.0015 | G9: 0.0015 | H9: 0 | I9: 0.0015 | J9: 0 | K9: 0.0015 | M9: [1, 2]
B10: Forced outage [%] | C10: 0.01 | D10: 0.01 | E10: 0.01 | F10: 0.01 | G10: 0.01 | H10: 0 | I10: 0.02 | J10: 0 | K10: 0.02 | M10: 1
B11: Planned outage [weeks per year] | C11: 0.5 | D11: 0.5 | E11: 0.5 | F11: 0.5 | G11: 0.5 | H11: 0.3 | I11: 0.6 | J11: 0.3 | K11: 0.6 | M11: [1, 2]
B12: Technical lifetime [years] | C12: 25 | D12: 25 | E12: 25 | F12: 25 | G12: 25 | H12: 25 | J12: 25 | M12: 1
B13: Construction time [years] | C13: 0.2 | D13: 0.2 | E13: 0.2 | F13: 0.2 | G13: 0.2 | H13: 0.02 | I13: 0.7 | J13: 0.02 | K13: 0.7 | M13: [1, 2]
B14: Space requirement [1000 m2/MW_e] | C14: 0.008 | D14: 0.008 | E14: 0.008 | F14: 0.008 | G14: 0.008 | H14: 0.007 | I14: 0.01 | J14: 0.007 | K14: 0.01 | M14: [2, 3]
A15: Regulation ability
B16: Primary regulation (of full load, per 30 seconds) [%] | C16: 0.15 | D16: 0.15 | E16: 0.15 | F16: 0.15 | G16: 0.15 | H16: 0.035 | I16: 0.3 | L16: H | M16: [1, 2, 6]
B17: Secondary regulation (of full load, per minute) [%] | C17: 0.3 | D17: 0.3 | E17: 0.3 | F17: 0.3 | G17: 0.3 | H17: 0.07 | I17: 0.6 | L17: H | M17: [1, 2, 6]
B18: Minimum load (of full load) [%] | C18: 0.15 | D18: 0.15 | E18: 0.15 | F18: 0.15 | G18: 0.15 | H18: 0.1 | I18: 0.2 | M18: [1, 2, 6]
B19: Warm start-up time [hours] | C19: 0.06 | D19: 0.06 | E19: 0.06 | F19: 0.06 | G19: 0.06 | H19: 0.025 | I19: 0.2 | M19: [1, 2, 6]
B20: Cold start-up time [hours] | C20: 0.5 | D20: 0.5 | E20: 0.5 | F20: 0.5 | G20: 0.5 | H20: 0.3 | I20: 1 | M20: [1, 2, 6]
A21: Financial data
B22: Nominal investment (*total) [MEUR/MW] | C22: 0.09 | D22: 0.09 | E22: 0.09 | F22: 0.09 | G22: 0.09 | L22: C, B | M22: [1, 2, 6]
B23: - of which equipment [%] | C23: 0.66 | D23: 0.66 | E23: 0.66 | F23: 0.66 | G23: 0.66 | M23: [1, 2]
B24: - of which installation [%] | C24: 0.34 | D24: 0.34 | E24: 0.34 | F24: 0.34 | G24: 0.34 | M24: [1, 2]
B25: Fixed O&M [EUR/MW_y] | C25: 2000 | D25: 2000 | E25: 2000 | F25: 2000 | G25: 2000 | M25: [1, 2]
B26: Variable O&M [EUR/MWh] | C26: 1.23 | D26: 1.23 | E26: 1.23 | F26: 1.23 | G26: 1.23 | M26: 1
A27: Technology-specific data
B28: Indirect investment cost [M€/MW] | C28: 0.23 | D28: 0.23 | E28: 0.23 | F28: 0.23 | G28: 0.23 | L28: J | M28: 2
B29: Technology dependent
B30: - Adding flue gas condenser (after economiser) increases efficiency by [%-point] (gas only) | C30: 0.06 | D30: 0.06 | E30: 0.06 | F30: 0.06 | G30: 0.06 | L30: I, E | M30: [1, 2, 5]
B31: - Adding flue gas condenser (after economiser) increases nominal investment by [%] (gas only) | C31: 0.1 | D31: 0.1 | E31: 0.1 | F31: 0.1 | G31: 0.1 | L31: I | M31: 2
B32: - Hot water boiler instead of steam boiler increases efficiency by [%-point] | C32: 0.01 | D32: 0.01 | E32: 0.01 | F32: 0.01 | G32: 0.01 | L32: F
B33: - Hot water boiler instead of steam boiler reduces nominal investment by [%] | C33: 0.3 | D33: 0.3 | E33: 0.3 | F33: 0.3 | G33: 0.3 | L33: G | M33: [2, 3]
A36: Notes:
A37: A | B37: Effeciency for unit with economiser (but not flue gas condenser) installed.
A38: B | B38: Values for steam boiler (see technology-specific data for differences with hot water boiler)
A39: C | B39: Prices include boiler, firing equipment, pumps, economiser, water-treatment system, chimney and installation.
A40: D | B40: Assuming 10 starts a year.
A41: E | B41: For condensing boilers, efficiencies above 100% are possible, since the standard efficiency calculation using the lower heating value (LHV) as denominator.
A42: F | B42: 1 %-point higher for hot water boiler, due to assumed lower flue gas temperature. If no flue gas condenser and economiser is used, the increase will be higher.
...

Sheet 6.2 Boiler, biomass
A1: Technology | C1: Boiler, biomass
A2: year | C2: 2025 | D2: 2030 | E2: 2035 | F2: 2040 | G2: 2050 | H2: 2025 | I2: 2025 | J2: 2050 | K2: 2050 | L2: Note | M2: Ref
A3: est | C3: ctrl | D3: ctrl | E3: ctrl | F3: ctrl | G3: ctrl | H3: lower | I3: upper | J3: lower | K3: upper | L3: - | M3: -
A4: cat | B4: par
A5: Energy/technical data
B6: Heat generation capacity for one unit [MW] | C6: 6.5 | D6: 6.5 | E6: 6.5 | F6: 6.5 | G6: 6.5 | H6: 0.3 | I6: 50 | J6: 0.3 | K6: 50 | M6: [1, 4, 5]
B7: Total efficiency, net [%], nominel load | C7: 0.89 | D7: 0.89 | E7: 0.89 | F7: 0.89 | G7: 0.89 | H7: 0.87 | I7: 0.91 | J7: 0.87 | K7: 0.91 | L7: A, B | M7: 2
B8: Total efficiency, net [%], annual average | C8: 0.889 | D8: 0.889 | E8: 0.889 | F8: 0.889 | G8: 0.889 | H8: 0.869 | I8: 0.909 | J8: 0.869 | K8: 0.909 | L8: A, B, D | M8: 2
B9: Auxiliary electricity consumption [% of heat gen] | C9: 0.02 | D9: 0.02 | E9: 0.02 | F9: 0.02 | G9: 0.02 | H9: 0.02 | I9: 0.02 | J9: 0.02 | K9: 0.02 | M9: 1
B10: Forced outage [%] | C10: 0.03 | D10: 0.03 | E10: 0.03 | F10: 0.03 | G10: 0.03 | H10: 0.03 | I10: 0.03 | J10: 0.03 | K10: 0.03 | M10: 1
B11: Planned outage [weeks per year] | C11: 2 | D11: 2 | E11: 2 | F11: 2 | G11: 2 | H11: 1.7 | I11: 2.3 | J11: 1.5 | K11: 2.5 | M11: 1
B12: Technical lifetime [years] | C12: 25 | D12: 25 | E12: 25 | F12: 25 | G12: 25 | H12: 20 | I12: 35 | J12: 20 | K12: 35 | M12: 1
B13: Construction time [years] | C13: 1 | D13: 1 | E13: 1 | F13: 1 | G13: 1 | H13: 0.5 | I13: 1.5 | J13: 0.5 | K13: 1.5 | M13: 1
B14: Space requirement [1000 m2/MW_e] | C14: 0.2 | D14: 0.2 | E14: 0.2 | F14: 0.2 | G14: 0.2 | H14: 0.14 | I14: 0.25 | J14: 0.12 | K14: 0.27 | M14: 1
A15: Regulation ability
B16: Primary regulation (of full load, per 30 seconds) [%]
B17: Secondary regulation (of full load, per minute) [%] | C17: 0.1 | D17: 0.1 | E17: 0.1 | F17: 0.1 | G17: 0.1 | M17: 1
B18: Minimum load (of full load) [%] | C18: 0.2 | D18: 0.2 | E18: 0.2 | F18: 0.2 | G18: 0.2 | M18: 1
B19: Warm start-up time [hours] | C19: 0.25 | D19: 0.25 | E19: 0.25 | F19: 0.25 | G19: 0.25 | M19: 1
B20: Cold start-up time [hours] | C20: 0.5 | D20: 0.5 | E20: 0.5 | F20: 0.5 | G20: 0.5 | M20: 1
A21: Financial data
B22: Nominal investment (*total) [MEUR/MW] | C22: 0.87840721 | D22: 0.82891948 | E22: 0.8072686 | F22: 0.78561772 | G22: 0.74231596 | M22: 1
B23: - of which equipment [%] | C23: 0.6 | D23: 0.6 | E23: 0.6 | F23: 0.6 | G23: 0.6 | M23: 1
B24: - of which installation [%] | C24: 0.4 | D24: 0.4 | E24: 0.4 | F24: 0.4 | G24: 0.4 | M24: 1
B25: Fixed O&M [EUR/MW_y] | C25: 39500 | D25: 38700 | E25: 37900 | F25: 37100 | G25: 35600 | M25: 1
B26: Variable O&M [EUR/MWh] | C26: 1.45 | D26: 1.45 | E26: 1.45 | F26: 1.45 | G26: 1.45 | L26: C, H | M26: 1
A27: Technology-specific data
B28: Indirect investment cost [M€/MW] | C28: 0.23 | D28: 0.23 | E28: 0.23 | F28: 0.23 | G28: 0.23 | L28: K, J
B29: Technology dependent
B30: - Using wood chips, and adding flue gas condenser (after economiser) increases efficiency by [%-point] | C30: 0.25 | D30: 0.25 | E30: 0.25 | F30: 0.25 | G30: 0.25 | L30: F, E | M30: [1, 3]
B31: - Using wood pellets, and adding flue gas condenser (after economiser) increases efficiency by [%-point] | C31: 0.12 | D31: 0.12 | E31: 0.12 | F31: 0.12 | G31: 0.12 | L31: E, I | M31: [1, 3]
B32: - Hot water boiler instead of steam boiler increases efficiency by [%-point] | C32: 0.01 | D32: 0.01 | E32: 0.01 | F32: 0.01 | G32: 0.01 | L32: G
B33: - Wood pellets (instead of wood chips) reduces Variable O&M by [%] | C33: 0.5 | D33: 0.5 | E33: 0.5 | F33: 0.5 | G33: 0.5 | M33: 1
A36: Notes:
A37: A | B37: Effeciency for unit with economiser (but not flue gas condenser) installed.
A38: B | B38: Values for steam boiler (see technology-specific data for differences with hot water boiler)
A39: C | B39: Values for wood chips (see technology-specific data for differences with wood pellets)
A40: D | B40: Assuming 10 starts a year.
A41: E | B41: For condensing boilers, efficiencies above 100% are possible, since the standard efficiency calculation using the lower heating value (LHV) as denominator.
A42: F | B42: Large increase in efficiency using flue gas condensen because of large water content in wood chips.
...

Sheet 6.3 Boiler, coal
A1: Technology | C1: Boiler, coal
A2: year | C2: 2025 | D2: 2030 | E2: 2035 | F2: 2040 | G2: 2050 | H2: 2025 | I2: 2025 | J2: 2050 | K2: 2050 | L2: Note | M2: Ref
A3: est | C3: ctrl | D3: ctrl | E3: ctrl | F3: ctrl | G3: ctrl | H3: lower | I3: upper | J3: lower | K3: upper | L3: - | M3: -
A4: cat | B4: par
A5: Energy/technical data
B6: Heat generation capacity for one unit [MW] | C6: 5 | D6: 5 | E6: 5 | F6: 5 | G6: 5 | H6: 1.6 | I6: 50 | J6: 1.6 | K6: 50 | M6: [3, 4]
B7: Total efficiency, net [%], nominel load | C7: 0.9 | D7: 0.9 | E7: 0.9 | F7: 0.9 | G7: 0.9 | H7: 0.88 | I7: 0.92 | J7: 0.88 | K7: 0.92 | L7: A, B, C | M7: 2
B8: Total efficiency, net [%], annual average | C8: 0.899 | D8: 0.899 | E8: 0.899 | F8: 0.899 | G8: 0.899 | H8: 0.879 | I8: 0.919 | J8: 0.879 | K8: 0.919 | L8: A, B, C, D | M8: 2
B9: Auxiliary electricity consumption [% of heat gen] | C9: 0.02 | D9: 0.02 | E9: 0.02 | F9: 0.02 | G9: 0.02 | H9: 0.02 | I9: 0.02 | J9: 0.02 | K9: 0.02 | L9: F | M9: 1
B10: Forced outage [%] | C10: 0.03 | D10: 0.03 | E10: 0.03 | F10: 0.03 | G10: 0.03 | H10: 0.03 | I10: 0.03 | J10: 0.03 | K10: 0.03 | L10: F | M10: 1
B11: Planned outage [weeks per year] | C11: 2 | D11: 2 | E11: 2 | F11: 2 | G11: 2 | H11: 1.7 | I11: 2.3 | J11: 1.5 | K11: 2.5 | L11: F | M11: 1
B12: Technical lifetime [years] | C12: 25 | D12: 25 | E12: 25 | F12: 25 | G12: 25 | H12: 20 | I12: 35 | J12: 20 | K12: 35 | L12: E, F | M12: 1
B13: Construction time [years] | C13: 1 | D13: 1 | E13: 1 | F13: 1 | G13: 1 | H13: 0.5 | I13: 1.5 | J13: 0.5 | K13: 1.5 | L13: F | M13: 1
B14: Space requirement [1000 m2/MW_e] | C14: 0.2 | D14: 0.2 | E14: 0.2 | F14: 0.2 | G14: 0.2 | H14: 0.14 | I14: 0.25 | J14: 0.12 | K14: 0.27 | L14: F | M14: 1
A15: Regulation ability
B16: Primary regulation (of full load, per 30 seconds) [%]
B17: Secondary regulation (of full load, per minute) [%] | C17: 0.1 | D17: 0.1 | E17: 0.1 | F17: 0.1 | G17: 0.1 | L17: F | M17: 1
B18: Minimum load (of full load) [%] | C18: 0.15 | D18: 0.15 | E18: 0.15 | F18: 0.15 | G18: 0.15 | L18: E | M18: 1
B19: Warm start-up time [hours] | C19: 0.25 | D19: 0.25 | E19: 0.25 | F19: 0.25 | G19: 0.25 | L19: F | M19: 1
B20: Cold start-up time [hours] | C20: 0.5 | D20: 0.5 | E20: 0.5 | F20: 0.5 | G20: 0.5 | L20: F | M20: 1
A21: Financial data
B22: Nominal investment (*total) [MEUR/MW] | C22: 0.565 | D22: 0.545 | E22: 0.533 | F22: 0.521 | G22: 0.515 | L22: F, H | M22: 1
B23: - of which equipment [%] | C23: 0.6 | D23: 0.6 | E23: 0.6 | F23: 0.6 | G23: 0.6 | M23: 1
B24: - of which installation [%] | C24: 0.4 | D24: 0.4 | E24: 0.4 | F24: 0.4 | G24: 0.4 | M24: 1
B25: Fixed O&M [EUR/MW_y] | C25: 40000 | D25: 39500 | E25: 39000 | F25: 38500 | G25: 37500 | L25: E, F | M25: 1
B26: Variable O&M [EUR/MWh] | C26: 1.45 | D26: 1.45 | E26: 1.45 | F26: 1.45 | G26: 1.45 | L26: F | M26: 1
A27: Technology-specific data
B28: Indirect investment cost [M€/MW] | C28: 0.23 | D28: 0.23 | E28: 0.23 | F28: 0.23 | G28: 0.23 | L28: I, J
B29: Technology dependent
B30: - Hot water boiler instead of steam boiler increases efficiency by [%-point] | C30: 0.01 | D30: 0.01 | E30: 0.01 | F30: 0.01 | G30: 0.01 | L30: G
A33: Notes:
A34: A | B34: Effeciency for unit with economiser (but not flue gas condenser) installed.
A35: B | B35: Values for steam boiler (see technology-specific data for differences with hot water boiler)
A36: C | B36: Flue gas condenser not possible for coal boiler, since no water vapor is present in flue gas.
A37: D | B37: Assuming 10 starts a year.
A38: E | B38: Values estimated based on "01 Coal CHP" from ref. 1.
A39: F | B39: Values estimated based on "09b Wood Pellets HOP"/"09a Wood Chips HOP, small" from ref. 1 (since they are solid fuels, and often the same boiler can used either biomass or coal)
A40: G | B40: 1 %-point higher for hot water boiler, due to assumed lower flue gas temperature
A41: H | B41: Viegand Maagøe A/S experience
A42: I | B42: Relevant for hot water boiler when needing to install new hot water piping instead of existing steam piping.
...

Sheet 7.1 Direct firing Natural Gas
A1: Technology | C1: Direct firing, Natural gas
A2: year | C2: 2025 | D2: 2030 | E2: 2035 | F2: 2040 | G2: 2050 | H2: 2025 | I2: 2025 | J2: 2050 | K2: 2050 | L2: Note | M2: Ref
A3: est | C3: ctrl | D3: ctrl | E3: ctrl | F3: ctrl | G3: ctrl | H3: lower | I3: upper | J3: lower | K3: upper | L3: - | M3: -
A4: cat | B4: par
A5: Energy/technical data
B6: Heat generation capacity for one unit [MW] | C6: 2.5 | D6: 2.5 | E6: 2.5 | F6: 2.5 | G6: 2.5 | H6: 1 | I6: 10 | J6: 1 | K6: 10 | M6: 2
B7: Total efficiency, net [%], nominel load | C7: 1 | D7: 1 | E7: 1 | F7: 1 | G7: 1 | H7: 1 | I7: 1 | J7: 1 | K7: 1 | L7: A | M7: 2
B8: Total efficiency, net [%], annual average | C8: 1 | D8: 1 | E8: 1 | F8: 1 | G8: 1 | H8: 1 | I8: 1 | J8: 1 | K8: 1 | L8: A | M8: 2
B9: Auxiliary electricity consumption [% of heat gen] | C9: 0.0025 | D9: 0.0025 | E9: 0.0025 | F9: 0.0025 | G9: 0.0025 | H9: 0.001 | I9: 0.01 | J9: 0.001 | K9: 0.01 | M9: [8, 9]
B10: Forced outage [%] | C10: 0.0025 | D10: 0.0025 | E10: 0.0025 | F10: 0.0025 | G10: 0.0025 | H10: 0 | I10: 0.005 | J10: 0 | K10: 0.005 | M10: 2
B11: Planned outage [weeks per year] | C11: 0.5 | D11: 0.5 | E11: 0.5 | F11: 0.5 | G11: 0.5 | H11: 0 | I11: 1 | J11: 0 | K11: 1 | M11: 2
B12: Technical lifetime [years] | C12: 15 | D12: 15 | E12: 15 | F12: 15 | G12: 15 | H12: 10 | I12: 20 | J12: 10 | K12: 20 | M12: 4
B13: Construction time [years] | C13: 0.01 | D13: 0.01 | E13: 0.01 | F13: 0.01 | G13: 0.01 | H13: 0.01 | I13: 0.04 | J13: 0.01 | K13: 0.04 | M13: 2
A14: Regulation Ability
B15: Minimum load [% of full load] | C15: 0.1 | D15: 0.1 | E15: 0.1 | F15: 0.1 | G15: 0.1 | M15: 6
B16: Warm start-up time [hours] | C16: 0.01 | D16: 0.01 | E16: 0.01 | F16: 0.01 | G16: 0.01 | M16: 2
B17: Cold start-up time [hours] | C17: 0.01 | D17: 0.01 | E17: 0.01 | F17: 0.01 | G17: 0.01 | M17: 2
A18: Environment
B19: SO2 [g per GJ fuel] | C19: 0.3 | D19: 0.3 | E19: 0.3 | F19: 0.3 | G19: 0.3 | M19: 1
B20: PM2.5 [g per GJ fuel] | C20: 0.1 | D20: 0.1 | E20: 0.1 | F20: 0.1 | G20: 0.1 | M20: 1
B21: NOX [g per GJ fuel] | C21: 9 | D21: 7 | E21: 7 | F21: 6 | G21: 6 | M21: 1
B22: CH4 [g per GJ fuel] | C22: 3 | D22: 2 | E22: 2 | F22: 2 | G22: 2 | M22: 1
B23: N2O [g per GJ fuel] | C23: 1 | D23: 1 | E23: 1 | F23: 1 | G23: 1 | M23: 1
A24: Financial data
B25: Nominal investment [M€/MW] | C25: 0.0176 | D25: 0.0176 | E25: 0.0176 | F25: 0.0176 | G25: 0.0176 | L25: B | M25: [4, 7]
B26: - of which equipment [%] | C26: 0.66666667 | D26: 0.66666667 | E26: 0.66666667 | F26: 0.66666667 | G26: 0.66666667 | M26: 7
B27: - of which installation [%] | C27: 0.33333333 | D27: 0.33333333 | E27: 0.33333333 | F27: 0.33333333 | G27: 0.33333333 | M27: 7
B28: Fixed O&M [€/MJ/s/year] | C28: 213 | D28: 208 | E28: 205 | F28: 202 | G28: 181 | L28: C | M28: [2, 1]
