Workbook

Sheet About
A1: CSMI Cement Substitute Material Inputs
A3: Sources: | B3: Raw clay price and calcined clay costs, North America
B4: RMI
B5: The Business Case for LC3 (December 2024), page 24 and Exhibits 8-9
B6: 2024
B7: https://rmi.org/wp-content/uploads/dlm_uploads/2024/12/the_business_case_for_LC3_report.pdf
B8: Raw clay $15-25 per tonne in North America; calcined clay about $44 per tonne at its North American plant (including energy), $21-25 at its Latin American plants. Built with the LC3 project's cost tool.
B10: US clay, crushed stone, slag and pumice prices
B11: U.S. Geological Survey
B12: Mineral Commodity Summaries 2026: Clays; Stone (Crushed); Iron and Steel Slag; Pumice and Pumicite
B13: 2026
B14: https://pubs.usgs.gov/periodicals/mcs2026/mcs2026-stone-crushed.pdf
B15: Average unit values for 2025 (estimates): common clay $21 per tonne; crushed stone $18.50 (about 70% limestone and dolomite, 17% used for cement); all slag $40 FOB plant, with ground granulated slag under 30% of tonnage but about 80% of value and some "about $140 or more"; pumice and pumicite $44 FOB mine or mill. The slag chapter also expects slag imports to fall as foreign blast furnaces close. Other chapters: mcs2026-clays.pdf, mcs2026-iron-steel-slag.pdf, mcs2026-pumice.pdf at the same address.
B17: US cost assumptions for limestone, clay, fly ash, slag and calcined clay operation, and a 2030s US cement mix
B18: U.S. Department of Energy
B19: Pathways to Commercial Liftoff: Low-Carbon Cement (updated February 2025), page 26 and Appendix A.2
B20: 2025
B21: https://liftoff.energy.gov/wp-content/uploads/2023/12/LIFTOFF_Cement_Updated-2.6.25.pdf
B22: Limestone about $7 per tonne (crushed stone less transport and margin), raw clay assumed the same, fly ash $45 (industry expert input), slag $55 (market research); calcined clay maintenance $5 and labor $12 per tonne. Representative early-2030s US cement: 65% clinker, 15% limestone, 9% calcined clay, 5% gypsum, 3% fly ash, 2% natural pozzolan, under 1% slag.
B24: Imported granulated slag prices
B25: United Nations
B26: UN Comtrade, US imports of HS 261800 (granulated slag), 2022-2024
B27: 2025
B28: https://comtradeapi.un.org/public/v1/preview/C/A/HS?reporterCode=842&period=2024&cmdCode=261800&flowCode=M&partnerCode=0
B29: Value over quantity: $113 per tonne FOB and $140 CIF in 2024 (1.92 million tonnes), up from $71 and $88 in 2022. Mostly unground granules.
B31: US fly ash price (old survey)
B32: American Road and Transportation Builders Association, Transportation Development Foundation
B33: The Economic Impacts of Prohibiting Coal Fly Ash Use in Transportation Infrastructure Construction
B34: 2011
B35: https://acaa-usa.org/wp-content/uploads/2021/05/2011FlyAshStudy_lowres-FINAL.pdf
B36: Average fly ash price of $40 per short ton FOB ($44 per tonne) in 2010, from a survey of fly ash suppliers. Industry-funded; the only survey-based US price found.
B38: Non-fuel costs of making clinker at a reference plant
B39: CEMCAP project (SINTEF and partners); IEAGHG
B40: CEMCAP D4.6, Comparative techno-economic analysis of CO2 capture in cement plants (rev. 1, 2019); IEAGHG 2013/19, Deployment of CCS in the Cement Industry
B41: 2019
B42: https://zenodo.org/records/2597091
B43: Raw meal EUR 5 per tonne of clinker (Europe; IEAGHG uses EUR 1.5 for China and the Middle East), other variable costs EUR 1.1 plus EUR 0.7 ammonia; fixed costs (labor EUR 8.7, insurance and taxes EUR 4.2, maintenance EUR 5.3) are not credited here.
B45: Cross-check on US raw material costs
B46: U.S. Census Bureau
B47: 2022 Economic Census, Materials Consumed by Kind (NAICS 327310 cement manufacturing)
...

Sheet Price Index
A1: U.S. CPI-U annual averages (BLS), used to convert prices to 2012 dollars
A3: Year | B3: CPI-U
A4: 2012 | B4: 229.594
A5: 2024 | B5: 313.689
A6: 2025 | B6: 321.943

Sheet Materials
A1: Substitute materials: heat to make them and their non-energy cost (edit the blue-header inputs)
A3: Material | B3: Heat to make (GJ per metric ton) | C3: Non-energy cost (USD per metric ton, price year below) | D3: Price year | E3: Non-energy cost (2012 USD per metric ton) | F3: Low (price-year USD) | G3: High (price-year USD) | H3: What the cost covers and where it comes from
A4: Calcined clay | B4: 2.3 | C4: 30 | D4: 2025 | E4: =C4*VLOOKUP(2012,'Price Index'!$A$4:$B$6,2,FALSE)/VLOOKUP(D4,'Price Index'!$A$4:$B$6,2,FALSE) -> 21.394533 | F4: 12 | G4: 50 | H4: Everything except the calcining heat and the calciner capital (both charged separately in the model): about 1.2 t of raw clay per t of calcined clay at $15/t ($18; RMI gives $15-25 for North America, USGS common clay $21 ex-works), plant operation and maintenance about $9 (DOE Liftoff labor and maintenance; LC3 project studies $3-4 in emerging markets), grinding and drying electricity about $2. Heat: 2.3 GJ per t (RILEM range 2.2-3.0 for real calciners).
A5: Limestone | B5: 0 | C5: 10 | D5: 2025 | E5: =C5*VLOOKUP(2012,'Price Index'!$A$4:$B$6,2,FALSE)/VLOOKUP(D5,'Price Index'!$A$4:$B$6,2,FALSE) -> 7.1315109 | F5: 5 | G5: 20 | H5: Ground limestone from the plant's own or a nearby quarry: DOE Liftoff's $7/t production-cost proxy (USGS crushed stone less transport and margin) and USGS crushed stone $18.50/t FOB (2025, all crushed stone, about 70% limestone and dolomite). No heat.
A6: Fly ash (about 75% harvested from ponds and landfills) | B6: 0.675 | C6: 85 | D6: 2025 | E6: =C6*VLOOKUP(2012,'Price Index'!$A$4:$B$6,2,FALSE)/VLOOKUP(D6,'Price Index'!$A$4:$B$6,2,FALSE) -> 60.617842 | F6: 45 | G6: 125 | H6: No primary US price series exists. Anchors: ARTBA survey of fly ash suppliers $44/t (2010), DOE Liftoff $45 ('industry expert input'), IMARC $123 (Q2 2025, basis unknown); harvested ash costs more than fresh. Heat: drying harvested ash about 0.9 GJ/t, times its 75% share. The delivered price may already include some of that drying, a double count of well under $1 per t of substitution.
A7: Ground granulated blast-furnace slag | B7: 0.3 | C7: 125 | D7: 2025 | E7: =C7*VLOOKUP(2012,'Price Index'!$A$4:$B$6,2,FALSE)/VLOOKUP(D7,'Price Index'!$A$4:$B$6,2,FALSE) -> 89.143886 | F7: 100 | G7: 160 | H7: USGS: ground slag is under 30% of US slag tonnage but about 80% of its value, which implies at least about $103/t, with some "about $140 or more". UN Comtrade US imports of granulated slag (mostly unground) $113/t FOB, $140/t CIF in 2024. Heat: drying, about 0.3 GJ/t.
A8: Natural pozzolan | B8: 0.3 | C8: 60 | D8: 2025 | E8: =C8*VLOOKUP(2012,'Price Index'!$A$4:$B$6,2,FALSE)/VLOOKUP(D8,'Price Index'!$A$4:$B$6,2,FALSE) -> 42.789065 | F8: 30 | G8: 100 | H8: No price for cement-grade natural pozzolan was found. USGS pumice and pumicite $44/t FOB mine or mill (2025, all uses, mostly unground); dried and ground product costs more. Heat: drying, about 0.3 GJ/t.

Sheet Avoided Clinker Cost
A1: Non-fuel variable cost of making a ton of clinker, avoided when clinker is replaced
A3: Item | B3: USD per metric ton clinker (price year) | C3: Price year | D3: 2012 USD per metric ton clinker | E3: Low | F3: High | G3: Basis
A4: Raw materials (quarrying, crushing, purchased correctives) | B4: 11.217819 | C4: 2025 | D4: =B4*VLOOKUP(2012,'Price Index'!$A$4:$B$6,2,FALSE)/VLOOKUP(C4,'Price Index'!$A$4:$B$6,2,FALSE) -> 8 | E4: 7.0111371 | F4: 15.424502 | G4: About 1.55 t of raw material per t of clinker at DOE Liftoff's $7/t limestone proxy gives $8.5 (2012$). European reference plants (CEMCAP, IEAGHG) use EUR 5/t clinker ($6.4); US Census 2022 purchased nonmetallic minerals for cement plants come to $7.4 (2012$) per t clinker. Central $8 (2012$), range $5-11.
A5: Other variable costs (consumables, NOx reagent, water, refractories) | B5: 3.5055685 | C5: 2025 | D5: =B5*VLOOKUP(2012,'Price Index'!$A$4:$B$6,2,FALSE)/VLOOKUP(C5,'Price Index'!$A$4:$B$6,2,FALSE) -> 2.5 | E5: 2.1033411 | F5: 5.6089096 | G5: CEMCAP reference plant EUR 1.1/t clinker other variable costs plus EUR 0.7 ammonia ($2.3, 2012$); IEAGHG EUR 0.8/t cement. Central $2.5 (2012$), range $1.5-4. Labor, insurance and maintenance are fixed costs that scale with kiln capacity, which the model already treats as kiln capital, so they are not credited. Electricity is not credited here because the model already lowers cement electricity use with clinker output.
A6: TOTAL AVOIDED (2012 USD per metric ton clinker) | D6: =SUM(D4:D5) -> 10.5

Sheet Mix
A1: Marginal substitute mix (share of each metric ton of clinker replaced); edit the anchor-year columns
A2: Shares are held flat before the first anchor year and after the last, and move in a straight line between anchors.
A3: Material | B3: 2026 | C3: 2050
A4: Calcined clay | B4: 0.5 | C4: 0.75
A5: Limestone | B5: 0.15 | C5: 0.1
A6: Fly ash (about 75% harvested from ponds and landfills) | B6: 0.15 | C6: 0.07
A7: Ground granulated blast-furnace slag | B7: 0.15 | C7: 0.05
A8: Natural pozzolan | B8: 0.05 | C8: 0.03
A9: Total (must be 1) | B9: =SUM(B4:B8) -> 1 | C9: =SUM(C4:C8) -> 1

Sheet Derivation
A1: Mix by year and the three exported values
A3: Row | B3: 2021 | C3: 2022 | D3: 2023 | E3: 2024 | F3: 2025 | G3: 2026 | H3: 2027 | I3: 2028 | J3: 2029 | K3: 2030 | L3: 2031 | M3: 2032 | N3: 2033 | O3: 2034 | P3: 2035 | Q3: 2036 | R3: 2037 | S3: 2038 | T3: 2039 | U3: 2040 | V3: 2041 | W3: 2042 | X3: 2043 | Y3: 2044 | Z3: 2045 | AA3: 2046 | AB3: 2047 | AC3: 2048 | AD3: 2049 | AE3: 2050
A4: Year | B4: 2021 | C4: 2022 | D4: 2023 | E4: 2024 | F4: 2025 | G4: 2026 | H4: 2027 | I4: 2028 | J4: 2029 | K4: 2030 | L4: 2031 | M4: 2032 | N4: 2033 | O4: 2034 | P4: 2035 | Q4: 2036 | R4: 2037 | S4: 2038 | T4: 2039 | U4: 2040 | V4: 2041 | W4: 2042 | X4: 2043 | Y4: 2044 | Z4: 2045 | AA4: 2046 | AB4: 2047 | AC4: 2048 | AD4: 2049 | AE4: 2050
A5: Share: Calcined clay | B5: =IF(B$4<=2026,Mix!$B$4,IF(B$4<=2050,Mix!$B$4+(Mix!$C$4-Mix!$B$4)*(B$4-2026)/(2050-2026),Mix!$C$4)) -> 0.5 | C5: =IF(C$4<=2026,Mix!$B$4,IF(C$4<=2050,Mix!$B$4+(Mix!$C$4-Mix!$B$4)*(C$4-2026)/(2050-2026),Mix!$C$4)) -> 0.5 | D5: =IF(D$4<=2026,Mix!$B$4,IF(D$4<=2050,Mix!$B$4+(Mix!$C$4-Mix!$B$4)*(D$4-2026)/(2050-2026),Mix!$C$4)) -> 0.5 | E5: =IF(E$4<=2026,Mix!$B$4,IF(E$4<=2050,Mix!$B$4+(Mix!$C$4-Mix!$B$4)*(E$4-2026)/(2050-2026),Mix!$C$4)) -> 0.5 | F5: =IF(F$4<=2026,Mix!$B$4,IF(F$4<=2050,Mix!$B$4+(Mix!$C$4-Mix!$B$4)*(F$4-2026)/(2050-2026),Mix!$C$4)) -> 0.5 | G5: =IF(G$4<=2026,Mix!$B$4,IF(G$4<=2050,Mix!$B$4+(Mix!$C$4-Mix!$B$4)*(G$4-2026)/(2050-2026),Mix!$C$4)) -> 0.5 | H5: =IF(H$4<=2026,Mix!$B$4,IF(H$4<=2050,Mix!$B$4+(Mix!$C$4-Mix!$B$4)*(H$4-2026)/(2050-2026),Mix!$C$4)) -> 0.51041667 | I5: =IF(I$4<=2026,Mix!$B$4,IF(I$4<=2050,Mix!$B$4+(Mix!$C$4-Mix!$B$4)*(I$4-2026)/(2050-2026),Mix!$C$4)) -> 0.52083333 | ... AE5: =IF(AE$4<=2026,Mix!$B$4,IF(AE$4<=2050,Mix!$B$4+(Mix!$C$4-Mix!$B$4)*(AE$4-2026)/(2050-2026),Mix!$C$4)) -> 0.75
A6: Share: Limestone | B6: =IF(B$4<=2026,Mix!$B$5,IF(B$4<=2050,Mix!$B$5+(Mix!$C$5-Mix!$B$5)*(B$4-2026)/(2050-2026),Mix!$C$5)) -> 0.15 | C6: =IF(C$4<=2026,Mix!$B$5,IF(C$4<=2050,Mix!$B$5+(Mix!$C$5-Mix!$B$5)*(C$4-2026)/(2050-2026),Mix!$C$5)) -> 0.15 | D6: =IF(D$4<=2026,Mix!$B$5,IF(D$4<=2050,Mix!$B$5+(Mix!$C$5-Mix!$B$5)*(D$4-2026)/(2050-2026),Mix!$C$5)) -> 0.15 | E6: =IF(E$4<=2026,Mix!$B$5,IF(E$4<=2050,Mix!$B$5+(Mix!$C$5-Mix!$B$5)*(E$4-2026)/(2050-2026),Mix!$C$5)) -> 0.15 | F6: =IF(F$4<=2026,Mix!$B$5,IF(F$4<=2050,Mix!$B$5+(Mix!$C$5-Mix!$B$5)*(F$4-2026)/(2050-2026),Mix!$C$5)) -> 0.15 | G6: =IF(G$4<=2026,Mix!$B$5,IF(G$4<=2050,Mix!$B$5+(Mix!$C$5-Mix!$B$5)*(G$4-2026)/(2050-2026),Mix!$C$5)) -> 0.15 | H6: =IF(H$4<=2026,Mix!$B$5,IF(H$4<=2050,Mix!$B$5+(Mix!$C$5-Mix!$B$5)*(H$4-2026)/(2050-2026),Mix!$C$5)) -> 0.14791667 | I6: =IF(I$4<=2026,Mix!$B$5,IF(I$4<=2050,Mix!$B$5+(Mix!$C$5-Mix!$B$5)*(I$4-2026)/(2050-2026),Mix!$C$5)) -> 0.14583333 | ... AE6: =IF(AE$4<=2026,Mix!$B$5,IF(AE$4<=2050,Mix!$B$5+(Mix!$C$5-Mix!$B$5)*(AE$4-2026)/(2050-2026),Mix!$C$5)) -> 0.1
A7: Share: Fly ash (about 75% harvested from ponds and landfills) | B7: =IF(B$4<=2026,Mix!$B$6,IF(B$4<=2050,Mix!$B$6+(Mix!$C$6-Mix!$B$6)*(B$4-2026)/(2050-2026),Mix!$C$6)) -> 0.15 | C7: =IF(C$4<=2026,Mix!$B$6,IF(C$4<=2050,Mix!$B$6+(Mix!$C$6-Mix!$B$6)*(C$4-2026)/(2050-2026),Mix!$C$6)) -> 0.15 | D7: =IF(D$4<=2026,Mix!$B$6,IF(D$4<=2050,Mix!$B$6+(Mix!$C$6-Mix!$B$6)*(D$4-2026)/(2050-2026),Mix!$C$6)) -> 0.15 | E7: =IF(E$4<=2026,Mix!$B$6,IF(E$4<=2050,Mix!$B$6+(Mix!$C$6-Mix!$B$6)*(E$4-2026)/(2050-2026),Mix!$C$6)) -> 0.15 | F7: =IF(F$4<=2026,Mix!$B$6,IF(F$4<=2050,Mix!$B$6+(Mix!$C$6-Mix!$B$6)*(F$4-2026)/(2050-2026),Mix!$C$6)) -> 0.15 | G7: =IF(G$4<=2026,Mix!$B$6,IF(G$4<=2050,Mix!$B$6+(Mix!$C$6-Mix!$B$6)*(G$4-2026)/(2050-2026),Mix!$C$6)) -> 0.15 | H7: =IF(H$4<=2026,Mix!$B$6,IF(H$4<=2050,Mix!$B$6+(Mix!$C$6-Mix!$B$6)*(H$4-2026)/(2050-2026),Mix!$C$6)) -> 0.14666667 | I7: =IF(I$4<=2026,Mix!$B$6,IF(I$4<=2050,Mix!$B$6+(Mix!$C$6-Mix!$B$6)*(I$4-2026)/(2050-2026),Mix!$C$6)) -> 0.14333333 | ... AE7: =IF(AE$4<=2026,Mix!$B$6,IF(AE$4<=2050,Mix!$B$6+(Mix!$C$6-Mix!$B$6)*(AE$4-2026)/(2050-2026),Mix!$C$6)) -> 0.07
A8: Share: Ground granulated blast-furnace slag | B8: =IF(B$4<=2026,Mix!$B$7,IF(B$4<=2050,Mix!$B$7+(Mix!$C$7-Mix!$B$7)*(B$4-2026)/(2050-2026),Mix!$C$7)) -> 0.15 | C8: =IF(C$4<=2026,Mix!$B$7,IF(C$4<=2050,Mix!$B$7+(Mix!$C$7-Mix!$B$7)*(C$4-2026)/(2050-2026),Mix!$C$7)) -> 0.15 | D8: =IF(D$4<=2026,Mix!$B$7,IF(D$4<=2050,Mix!$B$7+(Mix!$C$7-Mix!$B$7)*(D$4-2026)/(2050-2026),Mix!$C$7)) -> 0.15 | E8: =IF(E$4<=2026,Mix!$B$7,IF(E$4<=2050,Mix!$B$7+(Mix!$C$7-Mix!$B$7)*(E$4-2026)/(2050-2026),Mix!$C$7)) -> 0.15 | F8: =IF(F$4<=2026,Mix!$B$7,IF(F$4<=2050,Mix!$B$7+(Mix!$C$7-Mix!$B$7)*(F$4-2026)/(2050-2026),Mix!$C$7)) -> 0.15 | G8: =IF(G$4<=2026,Mix!$B$7,IF(G$4<=2050,Mix!$B$7+(Mix!$C$7-Mix!$B$7)*(G$4-2026)/(2050-2026),Mix!$C$7)) -> 0.15 | H8: =IF(H$4<=2026,Mix!$B$7,IF(H$4<=2050,Mix!$B$7+(Mix!$C$7-Mix!$B$7)*(H$4-2026)/(2050-2026),Mix!$C$7)) -> 0.14583333 | I8: =IF(I$4<=2026,Mix!$B$7,IF(I$4<=2050,Mix!$B$7+(Mix!$C$7-Mix!$B$7)*(I$4-2026)/(2050-2026),Mix!$C$7)) -> 0.14166667 | ... AE8: =IF(AE$4<=2026,Mix!$B$7,IF(AE$4<=2050,Mix!$B$7+(Mix!$C$7-Mix!$B$7)*(AE$4-2026)/(2050-2026),Mix!$C$7)) -> 0.05
A9: Share: Natural pozzolan | B9: =IF(B$4<=2026,Mix!$B$8,IF(B$4<=2050,Mix!$B$8+(Mix!$C$8-Mix!$B$8)*(B$4-2026)/(2050-2026),Mix!$C$8)) -> 0.05 | C9: =IF(C$4<=2026,Mix!$B$8,IF(C$4<=2050,Mix!$B$8+(Mix!$C$8-Mix!$B$8)*(C$4-2026)/(2050-2026),Mix!$C$8)) -> 0.05 | D9: =IF(D$4<=2026,Mix!$B$8,IF(D$4<=2050,Mix!$B$8+(Mix!$C$8-Mix!$B$8)*(D$4-2026)/(2050-2026),Mix!$C$8)) -> 0.05 | E9: =IF(E$4<=2026,Mix!$B$8,IF(E$4<=2050,Mix!$B$8+(Mix!$C$8-Mix!$B$8)*(E$4-2026)/(2050-2026),Mix!$C$8)) -> 0.05 | F9: =IF(F$4<=2026,Mix!$B$8,IF(F$4<=2050,Mix!$B$8+(Mix!$C$8-Mix!$B$8)*(F$4-2026)/(2050-2026),Mix!$C$8)) -> 0.05 | G9: =IF(G$4<=2026,Mix!$B$8,IF(G$4<=2050,Mix!$B$8+(Mix!$C$8-Mix!$B$8)*(G$4-2026)/(2050-2026),Mix!$C$8)) -> 0.05 | H9: =IF(H$4<=2026,Mix!$B$8,IF(H$4<=2050,Mix!$B$8+(Mix!$C$8-Mix!$B$8)*(H$4-2026)/(2050-2026),Mix!$C$8)) -> 0.049166667 | I9: =IF(I$4<=2026,Mix!$B$8,IF(I$4<=2050,Mix!$B$8+(Mix!$C$8-Mix!$B$8)*(I$4-2026)/(2050-2026),Mix!$C$8)) -> 0.048333333 | ... AE9: =IF(AE$4<=2026,Mix!$B$8,IF(AE$4<=2050,Mix!$B$8+(Mix!$C$8-Mix!$B$8)*(AE$4-2026)/(2050-2026),Mix!$C$8)) -> 0.03
A11: Heat per ton of substitution (GJ per metric ton) | B11: =SUMPRODUCT(B5:B9,Materials!$B$4:$B$8) -> 1.31125 | C11: =SUMPRODUCT(C5:C9,Materials!$B$4:$B$8) -> 1.31125 | D11: =SUMPRODUCT(D5:D9,Materials!$B$4:$B$8) -> 1.31125 | E11: =SUMPRODUCT(E5:E9,Materials!$B$4:$B$8) -> 1.31125 | F11: =SUMPRODUCT(F5:F9,Materials!$B$4:$B$8) -> 1.31125 | G11: =SUMPRODUCT(G5:G9,Materials!$B$4:$B$8) -> 1.31125 | H11: =SUMPRODUCT(H5:H9,Materials!$B$4:$B$8) -> 1.3314583 | I11: =SUMPRODUCT(I5:I9,Materials!$B$4:$B$8) -> 1.3516667 | ... AE11: =SUMPRODUCT(AE5:AE9,Materials!$B$4:$B$8) -> 1.79625
A12: Calcined clay share of substitution | B12: =B5 -> 0.5 | C12: =C5 -> 0.5 | D12: =D5 -> 0.5 | E12: =E5 -> 0.5 | F12: =F5 -> 0.5 | G12: =G5 -> 0.5 | H12: =H5 -> 0.51041667 | I12: =I5 -> 0.52083333 | ... AE12: =AE5 -> 0.75
A13: Material non-energy cost (2012 USD per metric ton of substitution) | B13: =SUMPRODUCT(B5:B9,Materials!$E$4:$E$8) -> 36.370705 | C13: =SUMPRODUCT(C5:C9,Materials!$E$4:$E$8) -> 36.370705 | D13: =SUMPRODUCT(D5:D9,Materials!$E$4:$E$8) -> 36.370705 | E13: =SUMPRODUCT(E5:E9,Materials!$E$4:$E$8) -> 36.370705 | F13: =SUMPRODUCT(F5:F9,Materials!$E$4:$E$8) -> 36.370705 | G13: =SUMPRODUCT(G5:G9,Materials!$E$4:$E$8) -> 36.370705 | H13: =SUMPRODUCT(H5:H9,Materials!$E$4:$E$8) -> 35.969558 | I13: =SUMPRODUCT(I5:I9,Materials!$E$4:$E$8) -> 35.56841 | ... AE13: =SUMPRODUCT(AE5:AE9,Materials!$E$4:$E$8) -> 26.743166
A14: Avoided clinker non-fuel cost (2012 USD per metric ton) | B14: ='Avoided Clinker Cost'!$D$6 -> 10.5 | C14: ='Avoided Clinker Cost'!$D$6 -> 10.5 | D14: ='Avoided Clinker Cost'!$D$6 -> 10.5 | E14: ='Avoided Clinker Cost'!$D$6 -> 10.5 | F14: ='Avoided Clinker Cost'!$D$6 -> 10.5 | G14: ='Avoided Clinker Cost'!$D$6 -> 10.5 | H14: ='Avoided Clinker Cost'!$D$6 -> 10.5 | I14: ='Avoided Clinker Cost'!$D$6 -> 10.5 | ... AE14: ='Avoided Clinker Cost'!$D$6 -> 10.5
A15: NET MATERIAL COST (2012 USD per metric ton of substitution) | B15: =B13-B14 -> 25.870705 | C15: =C13-C14 -> 25.870705 | D15: =D13-D14 -> 25.870705 | E15: =E13-E14 -> 25.870705 | F15: =F13-F14 -> 25.870705 | G15: =G13-G14 -> 25.870705 | H15: =H13-H14 -> 25.469558 | I15: =I13-I14 -> 25.06841 | ... AE15: =AE13-AE14 -> 16.243166

Sheet Regions
A1: Other regions: availability and price notes for adapting this file (not read by the model)
A3: Region | B3: Fly ash | C3: Slag | D3: Calcined clay / clay | E3: Limestone and others | F3: Suggested mix direction | G3: Quality
A4: China | B4: About $22-23/t (trade listing) | C4: S95 slag powder about $47/t (trade listing) | D4: Scale US calcined clay operating costs by about 0.3 | E4: IEAGHG raw materials EUR 1.5/t clinker (vs EUR 5 Europe) | F4: Fly ash and slag stay the marginal materials longer | G4: Low (prices unverified)
A5: India | B5: Trader listings about $15-24/t; power plants must supply ash, transport-cost rules changed in 2021 (unresolved) | C5: No price found | D5: LC3 beats fly-ash cement only where ash is dear or far (IIT Delhi/TARA 2016) | F5: Fly-ash cement (PPC) dominates; calcined clay grows slowly | G5: Low
A6: EU | B6: Shrinking with coal phase-out; legacy-ash harvesting starting | C6: No price found | D6: US-like | E6: Raw meal EUR 5/t clinker; other variable EUR 1.1-1.8 | F6: Shift to calcined clay as in the US | G6: Medium (costs); low (prices)
A7: Brazil | B7: Little | C7: Some | D7: Calcined clay $21-25/t total (RMI, promoter); about $12-15/t non-heat | F7: Calcined clay and natural pozzolans already common | G7: Low
A8: Mexico | B8: No price found | C8: No price found | D8: Use Latin America values | G8: None
A9: Indonesia | B9: No price found | C9: No price found | D9: Tropical kaolinitic clays generally plentiful (not verified) | F9: Calcined clay | G9: None
A10: South Africa | B10: Large coal-ash supply while the coal fleet runs | C10: No price found | D10: Emerging-market values | F10: Fly ash first | G10: None
A11: Canada | B11: Use US values | C11: Use US values | D11: RMI North America plant applies | F11: As US | G11: Low

Sheet Checks
A1: Live checks
A2: Check | B2: Value | C2: Result
A3: Mix shares sum to 1 in every anchor year (count failing) | B3: =SUMPRODUCT(--(ABS(Mix!B9:C9-1)>0.0001)) -> 0 | C3: =IF(B3=0,"PASS","FAIL") -> PASS
A4: Heat between 0 and 3,000,000 BTU per ton in every year (count failing) | B4: =COUNTIF('CSMI-heat'!B2:AE2,"<0")+COUNTIF('CSMI-heat'!B2:AE2,">3000000") -> 0 | C4: =IF(B4=0,"PASS","FAIL") -> PASS
A5: Calcined clay share between 0 and 1 (count failing) | B5: =COUNTIF('CSMI-clay-share'!B2:AE2,"<0")+COUNTIF('CSMI-clay-share'!B2:AE2,">1") -> 0 | C5: =IF(B5=0,"PASS","FAIL") -> PASS
A6: Net cost between -100 and 100 2012-$ per ton (count failing) | B6: =COUNTIF('CSMI-net-cost'!B2:AE2,"<-100")+COUNTIF('CSMI-net-cost'!B2:AE2,">100") -> 0 | C6: =IF(B6=0,"PASS","FAIL") -> PASS

Sheet CSMI-heat
A1: Unit: BTU/metric ton | B1: 2021 | C1: 2022 | D1: 2023 | E1: 2024 | F1: 2025 | G1: 2026 | H1: 2027 | I1: 2028 | J1: 2029 | K1: 2030 | L1: 2031 | M1: 2032 | N1: 2033 | O1: 2034 | P1: 2035 | Q1: 2036 | R1: 2037 | S1: 2038 | T1: 2039 | U1: 2040 | V1: 2041 | W1: 2042 | X1: 2043 | Y1: 2044 | Z1: 2045 | AA1: 2046 | AB1: 2047 | AC1: 2048 | AD1: 2049 | AE1: 2050
A2: Substitute Material Heat per Ton of Substitution | B2: =Derivation!B11*947817 -> 1242825 | C2: =Derivation!C11*947817 -> 1242825 | D2: =Derivation!D11*947817 -> 1242825 | E2: =Derivation!E11*947817 -> 1242825 | F2: =Derivation!F11*947817 -> 1242825 | G2: =Derivation!G11*947817 -> 1242825 | H2: =Derivation!H11*947817 -> 1261978.8 | I2: =Derivation!I11*947817 -> 1281132.6 | ... AE2: =Derivation!AE11*947817 -> 1702516.3

Sheet CSMI-clay-share
A1: Unit: dimensionless | B1: 2021 | C1: 2022 | D1: 2023 | E1: 2024 | F1: 2025 | G1: 2026 | H1: 2027 | I1: 2028 | J1: 2029 | K1: 2030 | L1: 2031 | M1: 2032 | N1: 2033 | O1: 2034 | P1: 2035 | Q1: 2036 | R1: 2037 | S1: 2038 | T1: 2039 | U1: 2040 | V1: 2041 | W1: 2042 | X1: 2043 | Y1: 2044 | Z1: 2045 | AA1: 2046 | AB1: 2047 | AC1: 2048 | AD1: 2049 | AE1: 2050
A2: Calcined Clay Share of Substitution | B2: =Derivation!B12 -> 0.5 | C2: =Derivation!C12 -> 0.5 | D2: =Derivation!D12 -> 0.5 | E2: =Derivation!E12 -> 0.5 | F2: =Derivation!F12 -> 0.5 | G2: =Derivation!G12 -> 0.5 | H2: =Derivation!H12 -> 0.51041667 | I2: =Derivation!I12 -> 0.52083333 | ... AE2: =Derivation!AE12 -> 0.75

Sheet CSMI-net-cost
A1: Unit: 2012 USD/metric ton | B1: 2021 | C1: 2022 | D1: 2023 | E1: 2024 | F1: 2025 | G1: 2026 | H1: 2027 | I1: 2028 | J1: 2029 | K1: 2030 | L1: 2031 | M1: 2032 | N1: 2033 | O1: 2034 | P1: 2035 | Q1: 2036 | R1: 2037 | S1: 2038 | T1: 2039 | U1: 2040 | V1: 2041 | W1: 2042 | X1: 2043 | Y1: 2044 | Z1: 2045 | AA1: 2046 | AB1: 2047 | AC1: 2048 | AD1: 2049 | AE1: 2050
A2: Net Substitute Material Cost per Ton of Substitution | B2: =Derivation!B15 -> 25.870705 | C2: =Derivation!C15 -> 25.870705 | D2: =Derivation!D15 -> 25.870705 | E2: =Derivation!E15 -> 25.870705 | F2: =Derivation!F15 -> 25.870705 | G2: =Derivation!G15 -> 25.870705 | H2: =Derivation!H15 -> 25.469558 | I2: =Derivation!I15 -> 25.06841 | ... AE2: =Derivation!AE15 -> 16.243166
