Workbook

Sheet About
A1: BIISRP BAU Individual Industrial Site Retirement Profiles
A2: BIISRP Boolean Use Individual Industrial Site Retirement Profiles
A4: Source: | B4: Iron & steelmaking plants
B5: Global Energy Monitor
B6: 2025
B7: Global Iron and Steel Tracker (September 2025 release)
B8: https://globalenergymonitor.org/projects/global-iron-and-steel-tracker/dashboard/
B9: Multiple tables
A12: Notes
A13: This file allows the user to define explicit retirement profiles for specific industries.
A14: In small regions, there may be a limited number of facilities of a certain type -- for
A15: example, one integrated steelmaking plant. Therefore, using a smooth retirement curve
A16: as defined in indst/IESD might not reflect the quantized retirement that would be expected.
A18: Instead, you can use this file to define an explicit retirement profile. Maybe that one
A19: integrated plant will phase down from 2028 to 2030. You can use this file to define that
A20: retirement curve.

Sheet Steel ->

Sheet Plant data
A1: Plant ID | B1: Plant name (English) | C1: Owner GEM ID | D1: Municipality | E1: Subnational unit (province/state) | F1: Country/Area | G1: Region | H1: GEM wiki page | I1: Plant age (years) | J1: Announced date | K1: Construction date | L1: Start date | M1: Pre-retirement announcement date | N1: Idled date | O1: Retired date | P1: Main production equipment | Q1: Power source | R1: Most Recent Relining
A2: P100000120004 | B2: Kurum International Elbasan steel plant | C2: E100000130992 | D2: Bradashesh | E2: Elbasan | F2: Albania | G2: Europe | H2: https://www.gem.wiki/Kurum_International_Elbasan_steel_plant | I2: 27 | J2: unknown | K2: unknown | L2: 1998 | M2: unknown | N2: unknown | O2: unknown | P2: EAF | Q2: Hydraulic, integrated plants; Four hydropower plants used as captive power plants | R2: =INDEX('Blast furnaces'!$R:$R,MATCH(A2,'Blast furnaces'!$A:$A,0)) -> #N/A
A3: P100000120439 | B3: Algerian Qatari Steel Jijel plant | C3: E100001000957 | D3: El-Milia | E3: Jijel | F3: Algeria | G3: Africa | H3: https://www.gem.wiki/Algerian_Qatari_Steel_Jijel_plant | I3: 8 | J3: 2013 | K3: 2015 | L3: 2017 | M3: unknown | N3: unknown | O3: unknown | P3: EAF; DRI | Q3: unknown | R3: =INDEX('Blast furnaces'!$R:$R,MATCH(A3,'Blast furnaces'!$A:$A,0)) -> #N/A
A4: P100000120442 | B4: ETRHB Annaba steel plant | C4: E100001010275 | D4: Berrahal | E4: Annaba | F4: Algeria | G4: Africa | H4: https://www.gem.wiki/ETRHB_Annaba_steel_plant | I4: unknown | J4: 2017 | K4: 2018 | L4: unknown | M4: unknown | N4: unknown | O4: 44958 | P4: EAF | Q4: unknown | R4: =INDEX('Blast furnaces'!$R:$R,MATCH(A4,'Blast furnaces'!$A:$A,0)) -> #N/A
A5: P100000121198 | B5: Ozmert Algeria steel plant | C5: E100001012196 | D5: Tebessa | E5: Tebessa | F5: Algeria | G5: Africa | H5: https://www.gem.wiki/Ozmert_Algeria_Steel_Plant | I5: unknown | J5: unknown | K5: unknown | L5: unknown | M5: unknown | N5: unknown | O5: unknown | P5: EAF; DRI | Q5: unknown | R5: =INDEX('Blast furnaces'!$R:$R,MATCH(A5,'Blast furnaces'!$A:$A,0)) -> #N/A
A6: P100000120440 | B6: Sider El Hadjar Annaba steel plant | C6: E100001000960 | D6: Sidi Amar | E6: Annaba | F6: Algeria | G6: Africa | H6: https://www.gem.wiki/Sider_El_Hadjar_Annaba_steel_plant | I6: 56 | J6: 1964 | K6: unknown | L6: 1969 | M6: unknown | N6: unknown | O6: unknown | P6: BF; BOF; EAF; DRI | Q6: unknown | R6: =INDEX('Blast furnaces'!$R:$R,MATCH(A6,'Blast furnaces'!$A:$A,0)) -> 0
A7: P100000120441 | B7: Tosyali Algerie Oran steel plant | C7: E100000131071 | D7: Bethiqua | E7: Oran | F7: Algeria | G7: Africa | H7: https://www.gem.wiki/Tosyali_Algerie_Oran_steel_plant | I7: 12 | J7: unknown | K7: unknown | L7: 2013 | M7: unknown | N7: unknown | O7: unknown | P7: EAF; DRI | Q7: unknown | R7: =INDEX('Blast furnaces'!$R:$R,MATCH(A7,'Blast furnaces'!$A:$A,0)) -> #N/A
A8: P100000120005 | B8: Aceria Angola Bengo steel plant | C8: E100000131097 | D8: Barra de Dande | E8: Bengo | F8: Angola | G8: Africa | H8: https://www.gem.wiki/Aceria_Angola_Bengo_steel_plant | I8: 10 | J8: unknown | K8: 2013 | L8: 2015 | M8: unknown | N8: unknown | O8: unknown | P8: Steel other/unspecified | Q8: 50 km transmission line (220kV electricity) | R8: =INDEX('Blast furnaces'!$R:$R,MATCH(A8,'Blast furnaces'!$A:$A,0)) -> #N/A
A9: P100000121215 | B9: Companhia Siderurgica do Cuchi pig iron plant | C9: E100001012404 | D9: Cuchi | E9: Cuando Cubango | F9: Angola | G9: Africa | H9: https://www.gem.wiki/Companhia_Siderurgica_do_Cuchi_pig_iron_plant | I9: 2.03 | J9: unknown | K9: unknown | L9: 45170 | M9: unknown | N9: unknown | O9: unknown | P9: BF | Q9: 15 MW captive thermoelectric plant | R9: =INDEX('Blast furnaces'!$R:$R,MATCH(A9,'Blast furnaces'!$A:$A,0)) -> 0
A10: P100001042927 | B10: Tosyali Sonangol Kassinga Iron and Steel Plant | C10: E100002003752; E100000000004 | D10: Kassinga | E10: Huíla | F10: Angola | G10: Africa | H10: https://www.gem.wiki/Tosyali_Sonangol_Kassinga_Iron_and_Steel_Plant | J10: 2019 | K10: unknown | L10: 2027 | M10: unknown | N10: unknown | O10: unknown | P10: EAF; DRI | Q10: unknown | R10: =INDEX('Blast furnaces'!$R:$R,MATCH(A10,'Blast furnaces'!$A:$A,0)) -> #N/A
A11: P100000120006 | B11: ArcelorMittal Acindar Villa Constitución steel plant | C11: E100001010109 | D11: Villa Constitución | E11: Santa Fe | F11: Argentina | G11: Central & South America | H11: https://www.gem.wiki/ArcelorMittal_Acindar_Villa_Constitución_steel_plant | I11: 79 | J11: unknown | K11: unknown | L11: 1946 | M11: unknown | N11: unknown | O11: unknown | P11: EAF; DRI | Q11: Signed agreement with Petroquimica Comodoro Rivadavia (PCR) to invest $140 million in a renewable energy project in the San Luis Norte wind farm. | R11: =INDEX('Blast furnaces'!$R:$R,MATCH(A11,'Blast furnaces'!$A:$A,0)) -> #N/A
A12: P100000120009 | B12: Gerdau Sipar Pérez steel plant | C12: E100001010274 | D12: Pérez | E12: Santa Fe | F12: Argentina | G12: Central & South America | H12: https://www.gem.wiki/Gerdau_Sipar_Pérez_steel_plant | I12: 8 | J12: unknown | K12: unknown | L12: 2017 | M12: unknown | N12: unknown | O12: unknown | P12: EAF | Q12: unknown | R12: =INDEX('Blast furnaces'!$R:$R,MATCH(A12,'Blast furnaces'!$A:$A,0)) -> #N/A
A13: P100000120007 | B13: TenarisSiderca Campana steel plant | C13: E100000001765 | D13: Campana | E13: Buenos Aires | F13: Argentina | G13: Central & South America | H13: https://www.gem.wiki/TenarisSiderca_Campana_steel_plant | I13: 65.13 | J13: unknown | K13: unknown | L13: 22122 | M13: unknown | N13: unknown | O13: unknown | P13: EAF; DRI | Q13: Since Oct 2023, The Buena Ventura wind farm now supplies 100 MW of power, through the interconnected grid, to our industrial facilities in Campana, meeting close to 50% of its total electric power requirements and contributing to a lower energy costs. | R13: =INDEX('Blast furnaces'!$R:$R,MATCH(A13,'Blast furnaces'!$A:$A,0)) -> #N/A
A14: P100000120008 | B14: Ternium Siderar San Nicolás steel plant | C14: E100000130688 | D14: San Nicolás de los Arroyos | E14: Buenos Aires | F14: Argentina | G14: Central & South America | H14: https://www.gem.wiki/Ternium_Siderar_San_Nicolás_steel_plant | I14: 65 | J14: unknown | K14: unknown | L14: 1960 | M14: unknown | N14: unknown | O14: unknown | P14: BF; BOF | Q14: Thermoelectric, integrated | R14: =INDEX('Blast furnaces'!$R:$R,MATCH(A14,'Blast furnaces'!$A:$A,0)) -> 39448
A15: P100000120012 | B15: BlueScope Port Kembla steel plant | C15: E100000130689 | D15: Port Kembla | E15: New South Wales | F15: Australia | G15: Asia Pacific | H15: https://www.gem.wiki/BlueScope_Port_Kembla_steel_plant | I15: 97 | J15: unknown | K15: 1926 | L15: 1928 | M15: unknown | N15: unknown | O15: unknown | P15: BF; BOF | Q15: unknown | R15: =INDEX('Blast furnaces'!$R:$R,MATCH(A15,'Blast furnaces'!$A:$A,0)) -> 40026
A16: P100001043035 | B16: Fortescue Christmas Creek Green Metal Project | C16: E100001011127 | D16: Christmas Creek | E16: Western Australia | F16: Australia | G16: Asia Pacific | H16: https://www.gem.wiki/Fortescue_Christmas_Creek_Green_Metal_Project | I16: 0 | J16: unknown | K16: 45505 | L16: 2025 | M16: unknown | N16: unknown | O16: unknown | P16: Iron other/unspecified | Q16: Solar Power | R16: =INDEX('Blast furnaces'!$R:$R,MATCH(A16,'Blast furnaces'!$A:$A,0)) -> #N/A
A17: P100000120014 | B17: GFG Liberty Laverton Steel Mill | C17: E100001010334 | D17: Laverton | E17: Victoria | F17: Australia | G17: Asia Pacific | H17: https://www.gem.wiki/GFG_Liberty_Laverton_Steel_Mill | I17: 33 | J17: unknown | K17: unknown | L17: 1992 | M17: unknown | N17: unknown | O17: unknown | P17: EAF | Q17: 128 MW Numurkah Solar Farm | R17: =INDEX('Blast furnaces'!$R:$R,MATCH(A17,'Blast furnaces'!$A:$A,0)) -> #N/A
A18: P100000120013 | B18: GFG Liberty Steel Australia Whyalla steel plant | C18: E100001000556 | D18: Whyalla | E18: South Australia | F18: Australia | G18: Asia Pacific | H18: https://www.gem.wiki/GFG_Liberty_Steel_Australia_Whyalla_steel_plant | I18: 84 | J18: unknown | K18: unknown | L18: 1941 | M18: unknown | N18: unknown | O18: unknown | P18: BF; BOF; EAF; DRI | Q18: 66.5 MW Captive Power Plant; South Australian Grid, Santos (gas supplier) | R18: =INDEX('Blast furnaces'!$R:$R,MATCH(A18,'Blast furnaces'!$A:$A,0)) -> 40695
A19: P100000120015 | B19: GFG Liberty Sydney Steel Mill | C19: E100001010334 | D19: Rooty Hill | E19: New South Wales | F19: Australia | G19: Asia Pacific | H19: https://www.gem.wiki/GFG_Liberty_Sydney_Steel_Mill | I19: 43 | J19: unknown | K19: unknown | L19: 1982 | M19: unknown | N19: unknown | O19: unknown | P19: EAF | Q19: unknown | R19: =INDEX('Blast furnaces'!$R:$R,MATCH(A19,'Blast furnaces'!$A:$A,0)) -> #N/A
A20: P100000121147 | B20: Green Steel of WA Collie Steel plant | C20: E100001012187 | D20: Collie | E20: Western Australia | F20: Australia | G20: Asia Pacific | H20: https://www.gem.wiki/Green_Steel_of_WA_Collie_Steel_plant | J20: 2022 | K20: 2024 | L20: 2026 | M20: unknown | N20: unknown | O20: unknown | P20: EAF | Q20: renewable electricity | R20: =INDEX('Blast furnaces'!$R:$R,MATCH(A20,'Blast furnaces'!$A:$A,0)) -> #N/A
A21: P100000121163 | B21: Green Steel of WA Geraldton Steel plant | C21: E100001012187 | D21: Geraldton | E21: Mid-West Australia | F21: Australia | G21: Asia Pacific | H21: https://www.gem.wiki/Green_Steel_of_WA_Geraldton_Steel_plant | J21: 45039 | K21: unknown | L21: 2027 | M21: unknown | N21: unknown | O21: unknown | P21: DRI | Q21: Renewable energy | R21: =INDEX('Blast furnaces'!$R:$R,MATCH(A21,'Blast furnaces'!$A:$A,0)) -> #N/A
A22: P100001026026 | B22: GreenSteel Australia New South Wales Steel Plant | C22: E100000131094 | D22: Wollongong | E22: New South Wales | F22: Australia | G22: Asia Pacific | H22: https://www.gem.wiki/GreenSteel_Australia_New_South_Wales_Steel_Plant | J22: unknown | K22: 2025 | L22: 2026 | M22: unknown | N22: unknown | O22: unknown | P22: EAF; DRI | Q22: Renewable energy | R22: =INDEX('Blast furnaces'!$R:$R,MATCH(A22,'Blast furnaces'!$A:$A,0)) -> #N/A
A23: P100000121161 | B23: POSCO Port Hedland Iron Project | C23: E100002009156 | D23: Boodarie Strategic Industrial Area | E23: Western Australia | F23: Australia | G23: Asia Pacific | H23: https://www.gem.wiki/POSCO_Port_Hedland_Steel_Plant | J23: 44682 | K23: 2025 | L23: 2028 | M23: unknown | N23: unknown | O23: unknown | P23: DRI | Q23: renewable energy project in Pilbara with Engie | R23: =INDEX('Blast furnaces'!$R:$R,MATCH(A23,'Blast furnaces'!$A:$A,0)) -> #N/A
A24: P100000120011 | B24: Voestalpine Stahl Donawitz steel plant | C24: E100000130917 | D24: Leoben | E24: Styria | F24: Austria | G24: Europe | H24: https://www.gem.wiki/Voestalpine_Stahl_Donawitz_steel_plant | I24: 147 | J24: unknown | K24: unknown | L24: 1878 | M24: unknown | N24: unknown | O24: unknown | P24: BF; BOF; EAF; DRI | Q24: Captive power plant | R24: =INDEX('Blast furnaces'!$R:$R,MATCH(A24,'Blast furnaces'!$A:$A,0)) -> 43368
A25: P100000120010 | B25: Voestalpine Stahl Linz steel plant | C25: E100000130978 | D25: Linz | E25: Upper Austria | F25: Austria | G25: Europe | H25: https://www.gem.wiki/Voestalpine_Stahl_Linz_steel_plant | I25: 85 | J25: unknown | K25: unknown | L25: 1940 | M25: unknown | N25: unknown | O25: unknown | P25: BF; BOF; EAF | Q25: unknown | R25: =INDEX('Blast furnaces'!$R:$R,MATCH(A25,'Blast furnaces'!$A:$A,0)) -> 43344
A26: P100000121043 | B26: Azerbaijan Integrated Steel Mill Complex | C26: E100000131069 | D26: Ganja | E26: Ganja-Dashkasan | F26: Azerbaijan | G26: Eurasia | H26: https://www.gem.wiki/Azerbaijan_Integrated_Steel_Mill_Complex | I26: unknown | J26: 2018 | K26: unknown | L26: unknown | M26: unknown | N26: unknown | O26: unknown | P26: EAF; DRI | Q26: unknown | R26: =INDEX('Blast furnaces'!$R:$R,MATCH(A26,'Blast furnaces'!$A:$A,0)) -> #N/A
A27: P100000120016 | B27: Baku Steel Company steel plant | C27: E100000131003 | D27: Baku | E27: Narimanov | F27: Azerbaijan | G27: Eurasia | H27: https://www.gem.wiki/Baku_Steel_Company_steel_plant | I27: 24 | J27: unknown | K27: unknown | L27: 2001 | M27: unknown | N27: unknown | O27: unknown | P27: EAF | Q27: unknown | R27: =INDEX('Blast furnaces'!$R:$R,MATCH(A27,'Blast furnaces'!$A:$A,0)) -> #N/A
A28: P100000120032 | B28: Sulb Bahrain Al Hidd steel plant | C28: E100000131139 | D28: Al Hidd | E28: Muharraq | F28: Bahrain | G28: Middle East | H28: https://www.gem.wiki/Sulb_Bahrain_Al_Hidd_steel_plant | I28: 13 | J28: 2009 | K28: unknown | L28: 2012 | M28: unknown | N28: unknown | O28: unknown | P28: EAF; DRI | Q28: unknown | R28: =INDEX('Blast furnaces'!$R:$R,MATCH(A28,'Blast furnaces'!$A:$A,0)) -> #N/A
A29: P100000120020 | B29: Abul Khair Steel Sitakunda plant | C29: E100000131068 | D29: Sitakunda | E29: Chittagong | F29: Bangladesh | G29: Asia Pacific | H29: https://www.gem.wiki/Abul_Khair_Steel_Sitakunda_plant | I29: 10 | J29: unknown | K29: unknown | L29: 2015 | M29: unknown | N29: unknown | O29: unknown | P29: EAF | Q29: unknown | R29: =INDEX('Blast furnaces'!$R:$R,MATCH(A29,'Blast furnaces'!$A:$A,0)) -> #N/A
A30: P100000120019 | B30: Bashundhara Steel Mirsarai plant | C30: E100002006720 | D30: Mirsarai | E30: Chittagong | F30: Bangladesh | G30: Asia Pacific | H30: https://www.gem.wiki/Bashundhara_Steel_Mirsarai_plant | J30: 2020 | K30: 44805 | L30: 2026 | M30: unknown | N30: unknown | O30: unknown | P30: EAF; DRI | Q30: unknown | R30: =INDEX('Blast furnaces'!$R:$R,MATCH(A30,'Blast furnaces'!$A:$A,0)) -> #N/A
A31: P100000120022 | B31: BSRM Ltd Mirsarai plant | C31: E100000120118 | D31: Mirsarai | E31: Chattogram | F31: Bangladesh | G31: Asia Pacific | H31: https://www.gem.wiki/BSRM_Ltd_Mirsarai_plant | I31: 9.28 | J31: unknown | K31: unknown | L31: 42522 | M31: unknown | N31: unknown | O31: unknown | P31: Steel other/unspecified | Q31: unknown | R31: =INDEX('Blast furnaces'!$R:$R,MATCH(A31,'Blast furnaces'!$A:$A,0)) -> #N/A
A32: P100000120021 | B32: BSRM Steels Mirsarai plant | C32: E100000130854 | D32: Mirsarai | E32: Chattogram | F32: Bangladesh | G32: Asia Pacific | H32: https://www.gem.wiki/BSRM_Steels_Mirsarai_plant | I32: 6 | J32: 2016 | K32: unknown | L32: 2019 | M32: unknown | N32: unknown | O32: unknown | P32: Steel other/unspecified | Q32: unknown | R32: =INDEX('Blast furnaces'!$R:$R,MATCH(A32,'Blast furnaces'!$A:$A,0)) -> #N/A
A33: P100000120018 | B33: GPH Steel Sitakunda plant | C33: E100000130987 | D33: Kumira | E33: Chittagong | F33: Bangladesh | G33: Asia Pacific | H33: https://www.gem.wiki/GPH_Steel_Sitakunda_plant | I33: 17.05 | J33: unknown | K33: unknown | L33: 39681 | M33: unknown | N33: unknown | O33: unknown | P33: EAF; Steel other/unspecified | Q33: Captive power plant | R33: =INDEX('Blast furnaces'!$R:$R,MATCH(A33,'Blast furnaces'!$A:$A,0)) -> #N/A
A34: P100000120024 | B34: KSRM Sitakunda steel plant | C34: E100000131041 | D34: Sitakunda | E34: Chittagong | F34: Bangladesh | G34: Asia Pacific | H34: https://www.gem.wiki/KSRM_Sitakunda_steel_plant | I34: 41 | J34: unknown | K34: unknown | L34: 1984 | M34: unknown | N34: unknown | O34: unknown | P34: EAF | Q34: 56MW gas-based Captive Power plant | R34: =INDEX('Blast furnaces'!$R:$R,MATCH(A34,'Blast furnaces'!$A:$A,0)) -> #N/A
A35: P100001042845 | B35: Megnha Re-rolling and Steel Mills steel plant | C35: E100002005771 | D35: Meghna | E35: Chittagong | F35: Bangladesh | G35: Asia Pacific | H35: https://www.gem.wiki/Megnha_Re-rolling_and_Steel_Mills_steel_plant | I35: unknown | J35: 45525 | K35: unknown | L35: unknown | M35: unknown | N35: unknown | O35: unknown | P35: EAF | Q35: unknown | R35: =INDEX('Blast furnaces'!$R:$R,MATCH(A35,'Blast furnaces'!$A:$A,0)) -> #N/A
A36: P100000120025 | B36: Star Consortium steel plant | C36: E100000131025 | D36: Mirsarai | E36: Chittagong | F36: Bangladesh | G36: Asia Pacific | H36: https://www.gem.wiki/Star_Consortium_steel_plant | I36: 2 | J36: 42856 | K36: unknown | L36: 2023 | M36: unknown | N36: unknown | O36: unknown | P36: BF; BOF | Q36: 167 MW coal-fired power plant | R36: =INDEX('Blast furnaces'!$R:$R,MATCH(A36,'Blast furnaces'!$A:$A,0)) -> 0
A37: P100001042855 | B37: Unitex Steel Mills Feni steel plant | C37: E100002005773 | D37: Muhuriganj | E37: Chittagong | F37: Bangladesh | G37: Asia Pacific | H37: https://www.gem.wiki/Unitex_Steel_Mills_Feni_steel_plant | I37: unknown | J37: 2020-19-18 | K37: 45231 | L37: unknown | M37: unknown | N37: unknown | O37: unknown | P37: EAF | Q37: Korerhat 400/230/132/33 kV Substation of PGCB | R37: =INDEX('Blast furnaces'!$R:$R,MATCH(A37,'Blast furnaces'!$A:$A,0)) -> #N/A
A38: P100000120056 | B38: Byelorussian Steel Works | C38: E100000130960 | D38: Zhlobin | E38: Gomel Region | F38: Belarus | G38: Europe | H38: https://www.gem.wiki/Byelorussian_Steel_Works | I38: 41 | J38: unknown | K38: unknown | L38: 1984 | M38: unknown | N38: unknown | O38: unknown | P38: EAF | Q38: Lukoml GRES power station | R38: =INDEX('Blast furnaces'!$R:$R,MATCH(A38,'Blast furnaces'!$A:$A,0)) -> #N/A
A39: P100000120029 | B39: Aperam Stainless Belgium Châtelet steel plant | C39: E100000130918 | D39: Châtelet | E39: Wallonie | F39: Belgium | G39: Europe | H39: https://www.gem.wiki/Aperam_Stainless_Belgium_Châtelet_steel_plant | I39: 49 | J39: unknown | K39: unknown | L39: 1976 | M39: unknown | N39: unknown | O39: unknown | P39: EAF | Q39: unknown | R39: =INDEX('Blast furnaces'!$R:$R,MATCH(A39,'Blast furnaces'!$A:$A,0)) -> #N/A
A40: P100000120028 | B40: Aperam Stainless Belgium Genk steel plant | C40: E100000130918 | D40: Genk | E40: Limburg | F40: Belgium | G40: Europe | H40: https://www.gem.wiki/Aperam_Stainless_Belgium_Genk_steel_plant | I40: 55 | J40: unknown | K40: unknown | L40: 1970 | M40: unknown | N40: unknown | O40: unknown | P40: EAF | Q40: unknown | R40: =INDEX('Blast furnaces'!$R:$R,MATCH(A40,'Blast furnaces'!$A:$A,0)) -> #N/A
...

Sheet Blast furnaces
A1: GEM Plant ID | B1: Municipality | C1: Subnational unit (province/state) | D1: Country/Area | E1: GEM Unit ID | F1: Unit Name | G1: GEM Wiki Page | H1: Unit Status | I1: Announced Date | J1: Construction Date | K1: Start Date | L1: Unit Age | M1: Pre-retirement Announcement Date | N1: Idled Date | O1: Retired Date | P1: Current Capacity (ttpa) | Q1: Current Size (m3) | R1: Most Recent Relining | S1: Relining (Date Format) | T1: Next Relining | U1: Next Relining Year | V1: Share of Capacity
A2: P100000120008 | B2: =INDEX('Plant data'!D:D,MATCH('Blast furnaces'!$A2,'Plant data'!$A:$A,0)) -> San Nicolás de los Arroyos | C2: =INDEX('Plant data'!E:E,MATCH('Blast furnaces'!$A2,'Plant data'!$A:$A,0)) -> Buenos Aires | D2: =INDEX('Plant data'!F:F,MATCH('Blast furnaces'!$A2,'Plant data'!$A:$A,0)) -> Argentina | E2: U100000140001 | F2: BF 2 | G2: https://www.gem.wiki/Ternium_Siderar_San_Nicolás_steel_plant | H2: operating | I2: unknown | J2: unknown | K2: 1974 | L2: 51 | M2: unknown | N2: unknown | O2: unknown | P2: 2628 | Q2: 2340 | R2: 39448 | S2: =_xlfn.LET( _xlpm.x, R2, _xlpm.t, TEXT(R2,"@"), IF(R2="","", IF(ISNUMBER(_xlpm.x), IF(_xlpm.x>=30000, _xlpm.x, DATE(_xlpm.x,1,1)), DATE( LEFT(_xlpm.t,4), IF(LEN(_xlpm.t)>=7, MID(_xlpm.t,6,2), 1), IF(LEN(_xlpm.t)>=10, RIGHT(_xlpm.t,2), 1) ) ) ) ) -> 39448 | T2: =IF(R2="","",EDATE(S2,240)) -> 46753
A3: P100000120008 | B3: =INDEX('Plant data'!D:D,MATCH('Blast furnaces'!$A3,'Plant data'!$A:$A,0)) -> San Nicolás de los Arroyos | C3: =INDEX('Plant data'!E:E,MATCH('Blast furnaces'!$A3,'Plant data'!$A:$A,0)) -> Buenos Aires | D3: =INDEX('Plant data'!F:F,MATCH('Blast furnaces'!$A3,'Plant data'!$A:$A,0)) -> Argentina | E3: U100000140002 | F3: BF 1 | G3: https://www.gem.wiki/Ternium_Siderar_San_Nicolás_steel_plant | H3: operating | I3: unknown | J3: unknown | K3: 1960 | L3: 65 | M3: unknown | N3: unknown | O3: unknown | P3: 1387 | Q3: 1548 | R3: 39845 | S3: =_xlfn.LET( _xlpm.x, R3, _xlpm.t, TEXT(R3,"@"), IF(R3="","", IF(ISNUMBER(_xlpm.x), IF(_xlpm.x>=30000, _xlpm.x, DATE(_xlpm.x,1,1)), DATE( LEFT(_xlpm.t,4), IF(LEN(_xlpm.t)>=7, MID(_xlpm.t,6,2), 1), IF(LEN(_xlpm.t)>=10, RIGHT(_xlpm.t,2), 1) ) ) ) ) -> 39845 | T3: =IF(R3="","",EDATE(S3,240)) -> 47150
A4: P100000120010 | B4: =INDEX('Plant data'!D:D,MATCH('Blast furnaces'!$A4,'Plant data'!$A:$A,0)) -> Linz | C4: =INDEX('Plant data'!E:E,MATCH('Blast furnaces'!$A4,'Plant data'!$A:$A,0)) -> Upper Austria | D4: =INDEX('Plant data'!F:F,MATCH('Blast furnaces'!$A4,'Plant data'!$A:$A,0)) -> Austria | E4: U100000140003 | F4: BF A | G4: https://www.gem.wiki/Voestalpine_Stahl_Linz_steel_plant | H4: operating | I4: unknown | J4: unknown | K4: 1977 | L4: 48 | M4: unknown | N4: unknown | O4: unknown | P4: 3300 | Q4: unknown | R4: 43344 | S4: =_xlfn.LET( _xlpm.x, R4, _xlpm.t, TEXT(R4,"@"), IF(R4="","", IF(ISNUMBER(_xlpm.x), IF(_xlpm.x>=30000, _xlpm.x, DATE(_xlpm.x,1,1)), DATE( LEFT(_xlpm.t,4), IF(LEN(_xlpm.t)>=7, MID(_xlpm.t,6,2), 1), IF(LEN(_xlpm.t)>=10, RIGHT(_xlpm.t,2), 1) ) ) ) ) -> 43344 | T4: =IF(R4="","",EDATE(S4,240)) -> 50649
A5: P100000120010 | B5: =INDEX('Plant data'!D:D,MATCH('Blast furnaces'!$A5,'Plant data'!$A:$A,0)) -> Linz | C5: =INDEX('Plant data'!E:E,MATCH('Blast furnaces'!$A5,'Plant data'!$A:$A,0)) -> Upper Austria | D5: =INDEX('Plant data'!F:F,MATCH('Blast furnaces'!$A5,'Plant data'!$A:$A,0)) -> Austria | E5: U100000140004 | F5: BF 5 | G5: https://www.gem.wiki/Voestalpine_Stahl_Linz_steel_plant | H5: operating pre-retirement | I5: unknown | J5: unknown | K5: 1941 | L5: 86 | M5: 2023 | N5: unknown | O5: 2027 | P5: 850 | Q5: unknown | R5: 45222 | S5: =_xlfn.LET( _xlpm.x, R5, _xlpm.t, TEXT(R5,"@"), IF(R5="","", IF(ISNUMBER(_xlpm.x), IF(_xlpm.x>=30000, _xlpm.x, DATE(_xlpm.x,1,1)), DATE( LEFT(_xlpm.t,4), IF(LEN(_xlpm.t)>=7, MID(_xlpm.t,6,2), 1), IF(LEN(_xlpm.t)>=10, RIGHT(_xlpm.t,2), 1) ) ) ) ) -> 45222 | T5: =IF(R5="","",EDATE(S5,240)) -> 52527
A6: P100000120010 | B6: =INDEX('Plant data'!D:D,MATCH('Blast furnaces'!$A6,'Plant data'!$A:$A,0)) -> Linz | C6: =INDEX('Plant data'!E:E,MATCH('Blast furnaces'!$A6,'Plant data'!$A:$A,0)) -> Upper Austria | D6: =INDEX('Plant data'!F:F,MATCH('Blast furnaces'!$A6,'Plant data'!$A:$A,0)) -> Austria | E6: U100000140005 | F6: BF 6 | G6: https://www.gem.wiki/Voestalpine_Stahl_Linz_steel_plant | H6: operating pre-retirement | I6: unknown | J6: unknown | K6: 1941 | L6: 89 | M6: 2023 | N6: unknown | O6: 2030 | P6: 850 | Q6: 1200 | R6: 45566 | S6: =_xlfn.LET( _xlpm.x, R6, _xlpm.t, TEXT(R6,"@"), IF(R6="","", IF(ISNUMBER(_xlpm.x), IF(_xlpm.x>=30000, _xlpm.x, DATE(_xlpm.x,1,1)), DATE( LEFT(_xlpm.t,4), IF(LEN(_xlpm.t)>=7, MID(_xlpm.t,6,2), 1), IF(LEN(_xlpm.t)>=10, RIGHT(_xlpm.t,2), 1) ) ) ) ) -> 45566 | T6: =IF(R6="","",EDATE(S6,240)) -> 52871
A7: P100000120011 | B7: =INDEX('Plant data'!D:D,MATCH('Blast furnaces'!$A7,'Plant data'!$A:$A,0)) -> Leoben | C7: =INDEX('Plant data'!E:E,MATCH('Blast furnaces'!$A7,'Plant data'!$A:$A,0)) -> Styria | D7: =INDEX('Plant data'!F:F,MATCH('Blast furnaces'!$A7,'Plant data'!$A:$A,0)) -> Austria | E7: U100000140006 | F7: BF 1 | G7: https://www.gem.wiki/Voestalpine_Stahl_Donawitz_steel_plant | H7: operating | I7: unknown | J7: unknown | K7: unknown | L7: unknown | M7: unknown | N7: unknown | O7: unknown | P7: 825 | Q7: 1205 | R7: 43368 | S7: =_xlfn.LET( _xlpm.x, R7, _xlpm.t, TEXT(R7,"@"), IF(R7="","", IF(ISNUMBER(_xlpm.x), IF(_xlpm.x>=30000, _xlpm.x, DATE(_xlpm.x,1,1)), DATE( LEFT(_xlpm.t,4), IF(LEN(_xlpm.t)>=7, MID(_xlpm.t,6,2), 1), IF(LEN(_xlpm.t)>=10, RIGHT(_xlpm.t,2), 1) ) ) ) ) -> 43368 | T7: =IF(R7="","",EDATE(S7,240)) -> 50673
A8: P100000120011 | B8: =INDEX('Plant data'!D:D,MATCH('Blast furnaces'!$A8,'Plant data'!$A:$A,0)) -> Leoben | C8: =INDEX('Plant data'!E:E,MATCH('Blast furnaces'!$A8,'Plant data'!$A:$A,0)) -> Styria | D8: =INDEX('Plant data'!F:F,MATCH('Blast furnaces'!$A8,'Plant data'!$A:$A,0)) -> Austria | E8: U100000140007 | F8: BF 4 | G8: https://www.gem.wiki/Voestalpine_Stahl_Donawitz_steel_plant | H8: operating pre-retirement | I8: unknown | J8: unknown | K8: 1941 | L8: 86 | M8: 2023 | N8: unknown | O8: 2027 | P8: 825 | Q8: 1343 | R8: 2016 | S8: =_xlfn.LET( _xlpm.x, R8, _xlpm.t, TEXT(R8,"@"), IF(R8="","", IF(ISNUMBER(_xlpm.x), IF(_xlpm.x>=30000, _xlpm.x, DATE(_xlpm.x,1,1)), DATE( LEFT(_xlpm.t,4), IF(LEN(_xlpm.t)>=7, MID(_xlpm.t,6,2), 1), IF(LEN(_xlpm.t)>=10, RIGHT(_xlpm.t,2), 1) ) ) ) ) -> 42370 | T8: =IF(R8="","",EDATE(S8,240)) -> 49675
A9: P100000120012 | B9: =INDEX('Plant data'!D:D,MATCH('Blast furnaces'!$A9,'Plant data'!$A:$A,0)) -> Port Kembla | C9: =INDEX('Plant data'!E:E,MATCH('Blast furnaces'!$A9,'Plant data'!$A:$A,0)) -> New South Wales | D9: =INDEX('Plant data'!F:F,MATCH('Blast furnaces'!$A9,'Plant data'!$A:$A,0)) -> Australia | E9: U100000140008 | F9: BF 5 | G9: https://www.gem.wiki/BlueScope_Port_Kembla_steel_plant | H9: operating pre-retirement | I9: unknown | J9: unknown | K9: 1972 | L9: 58 | M9: unknown | N9: unknown | O9: 2030 | P9: 3000 | Q9: 3427 | R9: 40026 | S9: =_xlfn.LET( _xlpm.x, R9, _xlpm.t, TEXT(R9,"@"), IF(R9="","", IF(ISNUMBER(_xlpm.x), IF(_xlpm.x>=30000, _xlpm.x, DATE(_xlpm.x,1,1)), DATE( LEFT(_xlpm.t,4), IF(LEN(_xlpm.t)>=7, MID(_xlpm.t,6,2), 1), IF(LEN(_xlpm.t)>=10, RIGHT(_xlpm.t,2), 1) ) ) ) ) -> 40026 | T9: =IF(R9="","",EDATE(S9,240)) -> 47331
A10: P100000120012 | B10: =INDEX('Plant data'!D:D,MATCH('Blast furnaces'!$A10,'Plant data'!$A:$A,0)) -> Port Kembla | C10: =INDEX('Plant data'!E:E,MATCH('Blast furnaces'!$A10,'Plant data'!$A:$A,0)) -> New South Wales | D10: =INDEX('Plant data'!F:F,MATCH('Blast furnaces'!$A10,'Plant data'!$A:$A,0)) -> Australia | E10: U100000140009 | F10: BF 6 | G10: https://www.gem.wiki/BlueScope_Port_Kembla_steel_plant | H10: mothballed | I10: unknown | J10: unknown | K10: 1996 | L10: 29 | M10: unknown | N10: 2011 | O10: unknown | P10: 3000 | Q10: 3208 | S10: =_xlfn.LET( _xlpm.x, R10, _xlpm.t, TEXT(R10,"@"), IF(R10="","", IF(ISNUMBER(_xlpm.x), IF(_xlpm.x>=30000, _xlpm.x, DATE(_xlpm.x,1,1)), DATE( LEFT(_xlpm.t,4), IF(LEN(_xlpm.t)>=7, MID(_xlpm.t,6,2), 1), IF(LEN(_xlpm.t)>=10, RIGHT(_xlpm.t,2), 1) ) ) ) )
A11: P100000120013 | B11: =INDEX('Plant data'!D:D,MATCH('Blast furnaces'!$A11,'Plant data'!$A:$A,0)) -> Whyalla | C11: =INDEX('Plant data'!E:E,MATCH('Blast furnaces'!$A11,'Plant data'!$A:$A,0)) -> South Australia | D11: =INDEX('Plant data'!F:F,MATCH('Blast furnaces'!$A11,'Plant data'!$A:$A,0)) -> Australia | E11: U100000140010 | F11: BF 2 | G11: https://www.gem.wiki/GFG_Liberty_Steel_Australia_Whyalla_steel_plant | H11: operating pre-retirement | I11: unknown | J11: 1965 | K11: 1965 | L11: 60 | M11: unknown | N11: unknown | O11: unknown | P11: 1200 | Q11: 1884 | R11: 40695 | S11: =_xlfn.LET( _xlpm.x, R11, _xlpm.t, TEXT(R11,"@"), IF(R11="","", IF(ISNUMBER(_xlpm.x), IF(_xlpm.x>=30000, _xlpm.x, DATE(_xlpm.x,1,1)), DATE( LEFT(_xlpm.t,4), IF(LEN(_xlpm.t)>=7, MID(_xlpm.t,6,2), 1), IF(LEN(_xlpm.t)>=10, RIGHT(_xlpm.t,2), 1) ) ) ) ) -> 40695 | T11: =IF(R11="","",EDATE(S11,240)) -> 48000
A12: P100000120017 | B12: =INDEX('Plant data'!D:D,MATCH('Blast furnaces'!$A12,'Plant data'!$A:$A,0)) -> Zenica | C12: =INDEX('Plant data'!E:E,MATCH('Blast furnaces'!$A12,'Plant data'!$A:$A,0)) -> Zenica-Doboj | D12: =INDEX('Plant data'!F:F,MATCH('Blast furnaces'!$A12,'Plant data'!$A:$A,0)) -> Bosnia and Herzegovina | E12: U100000140011 | F12: BF 4 | G12: https://www.gem.wiki/ArcelorMittal_Zenica_steel_plant | H12: operating | I12: unknown | J12: unknown | K12: 2004 | L12: 21 | M12: unknown | N12: unknown | O12: unknown | P12: 1100 | Q12: 2024 | R12: 43252 | S12: =_xlfn.LET( _xlpm.x, R12, _xlpm.t, TEXT(R12,"@"), IF(R12="","", IF(ISNUMBER(_xlpm.x), IF(_xlpm.x>=30000, _xlpm.x, DATE(_xlpm.x,1,1)), DATE( LEFT(_xlpm.t,4), IF(LEN(_xlpm.t)>=7, MID(_xlpm.t,6,2), 1), IF(LEN(_xlpm.t)>=10, RIGHT(_xlpm.t,2), 1) ) ) ) ) -> 43252 | T12: =IF(R12="","",EDATE(S12,240)) -> 50557
A13: P100000120025 | B13: =INDEX('Plant data'!D:D,MATCH('Blast furnaces'!$A13,'Plant data'!$A:$A,0)) -> Mirsarai | C13: =INDEX('Plant data'!E:E,MATCH('Blast furnaces'!$A13,'Plant data'!$A:$A,0)) -> Chittagong | D13: =INDEX('Plant data'!F:F,MATCH('Blast furnaces'!$A13,'Plant data'!$A:$A,0)) -> Bangladesh | E13: U100000140012 | F13: unknown BF (1) | G13: https://www.gem.wiki/Star_Consortium_steel_plant | H13: cancelled | I13: 42856 | J13: unknown | K13: 2023 | L13: 2 | M13: unknown | N13: unknown | O13: unknown | P13: 2000 | Q13: unknown | S13: =_xlfn.LET( _xlpm.x, R13, _xlpm.t, TEXT(R13,"@"), IF(R13="","", IF(ISNUMBER(_xlpm.x), IF(_xlpm.x>=30000, _xlpm.x, DATE(_xlpm.x,1,1)), DATE( LEFT(_xlpm.t,4), IF(LEN(_xlpm.t)>=7, MID(_xlpm.t,6,2), 1), IF(LEN(_xlpm.t)>=10, RIGHT(_xlpm.t,2), 1) ) ) ) )
A14: P100000120027 | B14: =INDEX('Plant data'!D:D,MATCH('Blast furnaces'!$A14,'Plant data'!$A:$A,0)) -> Gent | C14: =INDEX('Plant data'!E:E,MATCH('Blast furnaces'!$A14,'Plant data'!$A:$A,0)) -> Vlaanderen | D14: =INDEX('Plant data'!F:F,MATCH('Blast furnaces'!$A14,'Plant data'!$A:$A,0)) -> Belgium | E14: U100000140013 | F14: BF B | G14: https://www.gem.wiki/ArcelorMittal_Gent_steel_plant | H14: operating | I14: unknown | J14: unknown | K14: 1967 | L14: 58 | M14: unknown | N14: unknown | O14: unknown | P14: 2300 | Q14: 2347 | R14: 44256 | S14: =_xlfn.LET( _xlpm.x, R14, _xlpm.t, TEXT(R14,"@"), IF(R14="","", IF(ISNUMBER(_xlpm.x), IF(_xlpm.x>=30000, _xlpm.x, DATE(_xlpm.x,1,1)), DATE( LEFT(_xlpm.t,4), IF(LEN(_xlpm.t)>=7, MID(_xlpm.t,6,2), 1), IF(LEN(_xlpm.t)>=10, RIGHT(_xlpm.t,2), 1) ) ) ) ) -> 44256 | T14: =IF(R14="","",EDATE(S14,240)) -> 51561
A15: P100000120027 | B15: =INDEX('Plant data'!D:D,MATCH('Blast furnaces'!$A15,'Plant data'!$A:$A,0)) -> Gent | C15: =INDEX('Plant data'!E:E,MATCH('Blast furnaces'!$A15,'Plant data'!$A:$A,0)) -> Vlaanderen | D15: =INDEX('Plant data'!F:F,MATCH('Blast furnaces'!$A15,'Plant data'!$A:$A,0)) -> Belgium | E15: U100000140014 | F15: BF A | G15: https://www.gem.wiki/ArcelorMittal_Gent_steel_plant | H15: operating pre-retirement | I15: unknown | J15: unknown | K15: 1966 | L15: 64 | M15: 44440 | N15: unknown | O15: 2030 | P15: 2700 | Q15: 2550 | R15: 45270 | S15: =_xlfn.LET( _xlpm.x, R15, _xlpm.t, TEXT(R15,"@"), IF(R15="","", IF(ISNUMBER(_xlpm.x), IF(_xlpm.x>=30000, _xlpm.x, DATE(_xlpm.x,1,1)), DATE( LEFT(_xlpm.t,4), IF(LEN(_xlpm.t)>=7, MID(_xlpm.t,6,2), 1), IF(LEN(_xlpm.t)>=10, RIGHT(_xlpm.t,2), 1) ) ) ) ) -> 45270 | T15: =IF(R15="","",EDATE(S15,240)) -> 52575
A16: P100000120033 | B16: =INDEX('Plant data'!D:D,MATCH('Blast furnaces'!$A16,'Plant data'!$A:$A,0)) -> Ouro Branco | C16: =INDEX('Plant data'!E:E,MATCH('Blast furnaces'!$A16,'Plant data'!$A:$A,0)) -> Minas Gerais | D16: =INDEX('Plant data'!F:F,MATCH('Blast furnaces'!$A16,'Plant data'!$A:$A,0)) -> Brazil | E16: U100000140015 | F16: BF 1 | G16: https://www.gem.wiki/Gerdau_Açominas_Ouro_Branco_steel_plant | H16: operating | I16: unknown | J16: unknown | K16: 1986 | L16: 39 | M16: unknown | N16: unknown | O16: unknown | P16: 2815 | Q16: 2652 | R16: 37043 | S16: =_xlfn.LET( _xlpm.x, R16, _xlpm.t, TEXT(R16,"@"), IF(R16="","", IF(ISNUMBER(_xlpm.x), IF(_xlpm.x>=30000, _xlpm.x, DATE(_xlpm.x,1,1)), DATE( LEFT(_xlpm.t,4), IF(LEN(_xlpm.t)>=7, MID(_xlpm.t,6,2), 1), IF(LEN(_xlpm.t)>=10, RIGHT(_xlpm.t,2), 1) ) ) ) ) -> 37043 | T16: =IF(R16="","",EDATE(S16,240)) -> 44348
A17: P100000120033 | B17: =INDEX('Plant data'!D:D,MATCH('Blast furnaces'!$A17,'Plant data'!$A:$A,0)) -> Ouro Branco | C17: =INDEX('Plant data'!E:E,MATCH('Blast furnaces'!$A17,'Plant data'!$A:$A,0)) -> Minas Gerais | D17: =INDEX('Plant data'!F:F,MATCH('Blast furnaces'!$A17,'Plant data'!$A:$A,0)) -> Brazil | E17: U100000140016 | F17: BF 2 | G17: https://www.gem.wiki/Gerdau_Açominas_Ouro_Branco_steel_plant | H17: operating | I17: unknown | J17: 38657 | K17: 2007 | L17: 18 | M17: unknown | N17: unknown | O17: unknown | P17: 1533 | Q17: 1420 | S17: =_xlfn.LET( _xlpm.x, R17, _xlpm.t, TEXT(R17,"@"), IF(R17="","", IF(ISNUMBER(_xlpm.x), IF(_xlpm.x>=30000, _xlpm.x, DATE(_xlpm.x,1,1)), DATE( LEFT(_xlpm.t,4), IF(LEN(_xlpm.t)>=7, MID(_xlpm.t,6,2), 1), IF(LEN(_xlpm.t)>=10, RIGHT(_xlpm.t,2), 1) ) ) ) ) | T17: =IF(R17="","",EDATE(S17,240))
A18: P100000120034 | B18: =INDEX('Plant data'!D:D,MATCH('Blast furnaces'!$A18,'Plant data'!$A:$A,0)) -> Tubarão, Serra | C18: =INDEX('Plant data'!E:E,MATCH('Blast furnaces'!$A18,'Plant data'!$A:$A,0)) -> Espírito Santo | D18: =INDEX('Plant data'!F:F,MATCH('Blast furnaces'!$A18,'Plant data'!$A:$A,0)) -> Brazil | E18: U100000140017 | F18: BF 1 | G18: https://www.gem.wiki/ArcelorMittal_Tubarão_steel_plant | H18: operating | I18: unknown | J18: unknown | K18: 1983 | L18: 42 | M18: unknown | N18: unknown | O18: unknown | P18: 3280 | Q18: 320 | R18: 41091 | S18: =_xlfn.LET( _xlpm.x, R18, _xlpm.t, TEXT(R18,"@"), IF(R18="","", IF(ISNUMBER(_xlpm.x), IF(_xlpm.x>=30000, _xlpm.x, DATE(_xlpm.x,1,1)), DATE( LEFT(_xlpm.t,4), IF(LEN(_xlpm.t)>=7, MID(_xlpm.t,6,2), 1), IF(LEN(_xlpm.t)>=10, RIGHT(_xlpm.t,2), 1) ) ) ) ) -> 41091 | T18: =IF(R18="","",EDATE(S18,240)) -> 48396
A19: P100000120034 | B19: =INDEX('Plant data'!D:D,MATCH('Blast furnaces'!$A19,'Plant data'!$A:$A,0)) -> Tubarão, Serra | C19: =INDEX('Plant data'!E:E,MATCH('Blast furnaces'!$A19,'Plant data'!$A:$A,0)) -> Espírito Santo | D19: =INDEX('Plant data'!F:F,MATCH('Blast furnaces'!$A19,'Plant data'!$A:$A,0)) -> Brazil | E19: U100000140018 | F19: BF 2 | G19: https://www.gem.wiki/ArcelorMittal_Tubarão_steel_plant | H19: operating | I19: unknown | J19: unknown | K19: 1998 | L19: 27 | M19: unknown | N19: unknown | O19: unknown | P19: 1200 | Q19: 1374 | R19: 43800 | S19: =_xlfn.LET( _xlpm.x, R19, _xlpm.t, TEXT(R19,"@"), IF(R19="","", IF(ISNUMBER(_xlpm.x), IF(_xlpm.x>=30000, _xlpm.x, DATE(_xlpm.x,1,1)), DATE( LEFT(_xlpm.t,4), IF(LEN(_xlpm.t)>=7, MID(_xlpm.t,6,2), 1), IF(LEN(_xlpm.t)>=10, RIGHT(_xlpm.t,2), 1) ) ) ) ) -> 43800 | T19: =IF(R19="","",EDATE(S19,240)) -> 51105
A20: P100000120034 | B20: =INDEX('Plant data'!D:D,MATCH('Blast furnaces'!$A20,'Plant data'!$A:$A,0)) -> Tubarão, Serra | C20: =INDEX('Plant data'!E:E,MATCH('Blast furnaces'!$A20,'Plant data'!$A:$A,0)) -> Espírito Santo | D20: =INDEX('Plant data'!F:F,MATCH('Blast furnaces'!$A20,'Plant data'!$A:$A,0)) -> Brazil | E20: U100000140019 | F20: BF 3 | G20: https://www.gem.wiki/ArcelorMittal_Tubarão_steel_plant | H20: operating | I20: unknown | J20: unknown | K20: 2007 | L20: 18 | M20: unknown | N20: unknown | O20: unknown | P20: 2800 | Q20: 3126 | S20: =_xlfn.LET( _xlpm.x, R20, _xlpm.t, TEXT(R20,"@"), IF(R20="","", IF(ISNUMBER(_xlpm.x), IF(_xlpm.x>=30000, _xlpm.x, DATE(_xlpm.x,1,1)), DATE( LEFT(_xlpm.t,4), IF(LEN(_xlpm.t)>=7, MID(_xlpm.t,6,2), 1), IF(LEN(_xlpm.t)>=10, RIGHT(_xlpm.t,2), 1) ) ) ) ) | T20: =IF(R20="","",EDATE(S20,240))
A21: P100000120035 | B21: =INDEX('Plant data'!D:D,MATCH('Blast furnaces'!$A21,'Plant data'!$A:$A,0)) -> João Monlevade | C21: =INDEX('Plant data'!E:E,MATCH('Blast furnaces'!$A21,'Plant data'!$A:$A,0)) -> Minas Gerais | D21: =INDEX('Plant data'!F:F,MATCH('Blast furnaces'!$A21,'Plant data'!$A:$A,0)) -> Brazil | E21: U100000140020 | F21: BF A | G21: https://www.gem.wiki/ArcelorMittal_Monlevade_steel_plant | H21: operating | I21: unknown | J21: unknown | K21: 1999 | L21: 26 | M21: unknown | N21: unknown | O21: unknown | P21: 1040 | Q21: 1357 | R21: 42948 | S21: =_xlfn.LET( _xlpm.x, R21, _xlpm.t, TEXT(R21,"@"), IF(R21="","", IF(ISNUMBER(_xlpm.x), IF(_xlpm.x>=30000, _xlpm.x, DATE(_xlpm.x,1,1)), DATE( LEFT(_xlpm.t,4), IF(LEN(_xlpm.t)>=7, MID(_xlpm.t,6,2), 1), IF(LEN(_xlpm.t)>=10, RIGHT(_xlpm.t,2), 1) ) ) ) ) -> 42948 | T21: =IF(R21="","",EDATE(S21,240)) -> 50253
A22: P100000120035 | B22: =INDEX('Plant data'!D:D,MATCH('Blast furnaces'!$A22,'Plant data'!$A:$A,0)) -> João Monlevade | C22: =INDEX('Plant data'!E:E,MATCH('Blast furnaces'!$A22,'Plant data'!$A:$A,0)) -> Minas Gerais | D22: =INDEX('Plant data'!F:F,MATCH('Blast furnaces'!$A22,'Plant data'!$A:$A,0)) -> Brazil | E22: U100000140021 | F22: BF B | G22: https://www.gem.wiki/ArcelorMittal_Monlevade_steel_plant | H22: cancelled | I22: 40391 | J22: 2021 | K22: 2026 | M22: unknown | N22: unknown | O22: unknown | P22: 1200 | Q22: 1524 | S22: =_xlfn.LET( _xlpm.x, R22, _xlpm.t, TEXT(R22,"@"), IF(R22="","", IF(ISNUMBER(_xlpm.x), IF(_xlpm.x>=30000, _xlpm.x, DATE(_xlpm.x,1,1)), DATE( LEFT(_xlpm.t,4), IF(LEN(_xlpm.t)>=7, MID(_xlpm.t,6,2), 1), IF(LEN(_xlpm.t)>=10, RIGHT(_xlpm.t,2), 1) ) ) ) )
A23: P100000120037 | B23: =INDEX('Plant data'!D:D,MATCH('Blast furnaces'!$A23,'Plant data'!$A:$A,0)) -> Cubatão | C23: =INDEX('Plant data'!E:E,MATCH('Blast furnaces'!$A23,'Plant data'!$A:$A,0)) -> São Paulo | D23: =INDEX('Plant data'!F:F,MATCH('Blast furnaces'!$A23,'Plant data'!$A:$A,0)) -> Brazil | E23: U100000140022 | F23: BF 1 | G23: https://www.gem.wiki/Usiminas_Cubatão_steel_plant | H23: mothballed | I23: unknown | J23: unknown | K23: 1965 | L23: 60 | M23: unknown | N23: 42125 | O23: unknown | P23: 1600 | Q23: 1820 | R23: 36892 | S23: =_xlfn.LET( _xlpm.x, R23, _xlpm.t, TEXT(R23,"@"), IF(R23="","", IF(ISNUMBER(_xlpm.x), IF(_xlpm.x>=30000, _xlpm.x, DATE(_xlpm.x,1,1)), DATE( LEFT(_xlpm.t,4), IF(LEN(_xlpm.t)>=7, MID(_xlpm.t,6,2), 1), IF(LEN(_xlpm.t)>=10, RIGHT(_xlpm.t,2), 1) ) ) ) ) -> 36892
A24: P100000120037 | B24: =INDEX('Plant data'!D:D,MATCH('Blast furnaces'!$A24,'Plant data'!$A:$A,0)) -> Cubatão | C24: =INDEX('Plant data'!E:E,MATCH('Blast furnaces'!$A24,'Plant data'!$A:$A,0)) -> São Paulo | D24: =INDEX('Plant data'!F:F,MATCH('Blast furnaces'!$A24,'Plant data'!$A:$A,0)) -> Brazil | E24: U100000140023 | F24: BF 2 | G24: https://www.gem.wiki/Usiminas_Cubatão_steel_plant | H24: mothballed | I24: unknown | J24: unknown | K24: 1976 | L24: 49 | M24: unknown | N24: 2016 | O24: unknown | P24: 2900 | Q24: 3365 | R24: 37165 | S24: =_xlfn.LET( _xlpm.x, R24, _xlpm.t, TEXT(R24,"@"), IF(R24="","", IF(ISNUMBER(_xlpm.x), IF(_xlpm.x>=30000, _xlpm.x, DATE(_xlpm.x,1,1)), DATE( LEFT(_xlpm.t,4), IF(LEN(_xlpm.t)>=7, MID(_xlpm.t,6,2), 1), IF(LEN(_xlpm.t)>=10, RIGHT(_xlpm.t,2), 1) ) ) ) ) -> 37165
A25: P100000120038 | B25: =INDEX('Plant data'!D:D,MATCH('Blast furnaces'!$A25,'Plant data'!$A:$A,0)) -> Santa Cruz | C25: =INDEX('Plant data'!E:E,MATCH('Blast furnaces'!$A25,'Plant data'!$A:$A,0)) -> Rio de Janeiro | D25: =INDEX('Plant data'!F:F,MATCH('Blast furnaces'!$A25,'Plant data'!$A:$A,0)) -> Brazil | E25: U100000140024 | F25: BF 1 | G25: https://www.gem.wiki/Ternium_Brasil_Santa_Cruz_steel_plant | H25: operating | I25: unknown | J25: unknown | K25: 2010 | L25: 15 | M25: unknown | N25: unknown | O25: unknown | P25: 2650 | Q25: 3300 | S25: =_xlfn.LET( _xlpm.x, R25, _xlpm.t, TEXT(R25,"@"), IF(R25="","", IF(ISNUMBER(_xlpm.x), IF(_xlpm.x>=30000, _xlpm.x, DATE(_xlpm.x,1,1)), DATE( LEFT(_xlpm.t,4), IF(LEN(_xlpm.t)>=7, MID(_xlpm.t,6,2), 1), IF(LEN(_xlpm.t)>=10, RIGHT(_xlpm.t,2), 1) ) ) ) ) | T25: =IF(R25="","",EDATE(S25,240))
A26: P100000120038 | B26: =INDEX('Plant data'!D:D,MATCH('Blast furnaces'!$A26,'Plant data'!$A:$A,0)) -> Santa Cruz | C26: =INDEX('Plant data'!E:E,MATCH('Blast furnaces'!$A26,'Plant data'!$A:$A,0)) -> Rio de Janeiro | D26: =INDEX('Plant data'!F:F,MATCH('Blast furnaces'!$A26,'Plant data'!$A:$A,0)) -> Brazil | E26: U100000140025 | F26: BF 2 | G26: https://www.gem.wiki/Ternium_Brasil_Santa_Cruz_steel_plant | H26: operating | I26: unknown | J26: unknown | K26: 2010 | L26: 15 | M26: unknown | N26: unknown | O26: unknown | P26: 2650 | Q26: 3300 | S26: =_xlfn.LET( _xlpm.x, R26, _xlpm.t, TEXT(R26,"@"), IF(R26="","", IF(ISNUMBER(_xlpm.x), IF(_xlpm.x>=30000, _xlpm.x, DATE(_xlpm.x,1,1)), DATE( LEFT(_xlpm.t,4), IF(LEN(_xlpm.t)>=7, MID(_xlpm.t,6,2), 1), IF(LEN(_xlpm.t)>=10, RIGHT(_xlpm.t,2), 1) ) ) ) ) | T26: =IF(R26="","",EDATE(S26,240))
A27: P100000120039 | B27: =INDEX('Plant data'!D:D,MATCH('Blast furnaces'!$A27,'Plant data'!$A:$A,0)) -> Volta Redonda | C27: =INDEX('Plant data'!E:E,MATCH('Blast furnaces'!$A27,'Plant data'!$A:$A,0)) -> Rio de Janeiro | D27: =INDEX('Plant data'!F:F,MATCH('Blast furnaces'!$A27,'Plant data'!$A:$A,0)) -> Brazil | E27: U100000140026 | F27: BF 3 | G27: https://www.gem.wiki/CSN_Volta_Redonda_steel_plant | H27: operating | I27: unknown | J27: unknown | K27: 1976 | L27: 49 | M27: unknown | N27: unknown | O27: unknown | P27: 3900 | Q27: 4247 | R27: 43705 | S27: =_xlfn.LET( _xlpm.x, R27, _xlpm.t, TEXT(R27,"@"), IF(R27="","", IF(ISNUMBER(_xlpm.x), IF(_xlpm.x>=30000, _xlpm.x, DATE(_xlpm.x,1,1)), DATE( LEFT(_xlpm.t,4), IF(LEN(_xlpm.t)>=7, MID(_xlpm.t,6,2), 1), IF(LEN(_xlpm.t)>=10, RIGHT(_xlpm.t,2), 1) ) ) ) ) -> 43705 | T27: =IF(R27="","",EDATE(S27,240)) -> 51010
A28: P100000120039 | B28: =INDEX('Plant data'!D:D,MATCH('Blast furnaces'!$A28,'Plant data'!$A:$A,0)) -> Volta Redonda | C28: =INDEX('Plant data'!E:E,MATCH('Blast furnaces'!$A28,'Plant data'!$A:$A,0)) -> Rio de Janeiro | D28: =INDEX('Plant data'!F:F,MATCH('Blast furnaces'!$A28,'Plant data'!$A:$A,0)) -> Brazil | E28: U100000140027 | F28: BF 2 | G28: https://www.gem.wiki/CSN_Volta_Redonda_steel_plant | H28: operating | I28: unknown | J28: unknown | K28: 1954 | L28: 71 | M28: unknown | N28: unknown | O28: unknown | P28: 1680 | Q28: 1653 | R28: 42644 | S28: =_xlfn.LET( _xlpm.x, R28, _xlpm.t, TEXT(R28,"@"), IF(R28="","", IF(ISNUMBER(_xlpm.x), IF(_xlpm.x>=30000, _xlpm.x, DATE(_xlpm.x,1,1)), DATE( LEFT(_xlpm.t,4), IF(LEN(_xlpm.t)>=7, MID(_xlpm.t,6,2), 1), IF(LEN(_xlpm.t)>=10, RIGHT(_xlpm.t,2), 1) ) ) ) ) -> 42644 | T28: =IF(R28="","",EDATE(S28,240)) -> 49949
A29: P100000120040 | B29: =INDEX('Plant data'!D:D,MATCH('Blast furnaces'!$A29,'Plant data'!$A:$A,0)) -> São Gonçalo do Amarante | C29: =INDEX('Plant data'!E:E,MATCH('Blast furnaces'!$A29,'Plant data'!$A:$A,0)) -> Ceará | D29: =INDEX('Plant data'!F:F,MATCH('Blast furnaces'!$A29,'Plant data'!$A:$A,0)) -> Brazil | E29: U100000140028 | F29: BF 1 | G29: https://www.gem.wiki/ArcelorMittal_Pecém_steel_plant | H29: operating | I29: unknown | J29: 44743 | K29: 2016 | L29: 9 | M29: unknown | N29: unknown | O29: unknown | P29: 3192 | Q29: 3800 | S29: =_xlfn.LET( _xlpm.x, R29, _xlpm.t, TEXT(R29,"@"), IF(R29="","", IF(ISNUMBER(_xlpm.x), IF(_xlpm.x>=30000, _xlpm.x, DATE(_xlpm.x,1,1)), DATE( LEFT(_xlpm.t,4), IF(LEN(_xlpm.t)>=7, MID(_xlpm.t,6,2), 1), IF(LEN(_xlpm.t)>=10, RIGHT(_xlpm.t,2), 1) ) ) ) ) | T29: =IF(R29="","",EDATE(S29,240))
A30: P100000120043 | B30: =INDEX('Plant data'!D:D,MATCH('Blast furnaces'!$A30,'Plant data'!$A:$A,0)) -> Ipatinga | C30: =INDEX('Plant data'!E:E,MATCH('Blast furnaces'!$A30,'Plant data'!$A:$A,0)) -> Minas Gerais | D30: =INDEX('Plant data'!F:F,MATCH('Blast furnaces'!$A30,'Plant data'!$A:$A,0)) -> Brazil | E30: U100000140029 | F30: BF 1 | G30: https://www.gem.wiki/Usiminas_Ipatinga_steel_plant | H30: mothballed | I30: unknown | J30: unknown | K30: 1962 | L30: 63 | M30: unknown | N30: unknown | O30: unknown | P30: 660 | Q30: 777 | R30: 43191 | S30: =_xlfn.LET( _xlpm.x, R30, _xlpm.t, TEXT(R30,"@"), IF(R30="","", IF(ISNUMBER(_xlpm.x), IF(_xlpm.x>=30000, _xlpm.x, DATE(_xlpm.x,1,1)), DATE( LEFT(_xlpm.t,4), IF(LEN(_xlpm.t)>=7, MID(_xlpm.t,6,2), 1), IF(LEN(_xlpm.t)>=10, RIGHT(_xlpm.t,2), 1) ) ) ) ) -> 43191
A31: P100000120043 | B31: =INDEX('Plant data'!D:D,MATCH('Blast furnaces'!$A31,'Plant data'!$A:$A,0)) -> Ipatinga | C31: =INDEX('Plant data'!E:E,MATCH('Blast furnaces'!$A31,'Plant data'!$A:$A,0)) -> Minas Gerais | D31: =INDEX('Plant data'!F:F,MATCH('Blast furnaces'!$A31,'Plant data'!$A:$A,0)) -> Brazil | E31: U100000140030 | F31: BF 2 | G31: https://www.gem.wiki/Usiminas_Ipatinga_steel_plant | H31: operating | I31: unknown | J31: unknown | K31: 1965 | L31: 60 | M31: unknown | N31: unknown | O31: unknown | P31: 660 | Q31: 777 | R31: 44348 | S31: =_xlfn.LET( _xlpm.x, R31, _xlpm.t, TEXT(R31,"@"), IF(R31="","", IF(ISNUMBER(_xlpm.x), IF(_xlpm.x>=30000, _xlpm.x, DATE(_xlpm.x,1,1)), DATE( LEFT(_xlpm.t,4), IF(LEN(_xlpm.t)>=7, MID(_xlpm.t,6,2), 1), IF(LEN(_xlpm.t)>=10, RIGHT(_xlpm.t,2), 1) ) ) ) ) -> 44348 | T31: =IF(R31="","",EDATE(S31,240)) -> 51653
A32: P100000120043 | B32: =INDEX('Plant data'!D:D,MATCH('Blast furnaces'!$A32,'Plant data'!$A:$A,0)) -> Ipatinga | C32: =INDEX('Plant data'!E:E,MATCH('Blast furnaces'!$A32,'Plant data'!$A:$A,0)) -> Minas Gerais | D32: =INDEX('Plant data'!F:F,MATCH('Blast furnaces'!$A32,'Plant data'!$A:$A,0)) -> Brazil | E32: U100000140031 | F32: BF 3 | G32: https://www.gem.wiki/Usiminas_Ipatinga_steel_plant | H32: operating | I32: unknown | J32: unknown | K32: 1974 | L32: 51 | M32: unknown | N32: unknown | O32: unknown | P32: 3000 | Q32: 2722 | R32: 45231 | S32: =_xlfn.LET( _xlpm.x, R32, _xlpm.t, TEXT(R32,"@"), IF(R32="","", IF(ISNUMBER(_xlpm.x), IF(_xlpm.x>=30000, _xlpm.x, DATE(_xlpm.x,1,1)), DATE( LEFT(_xlpm.t,4), IF(LEN(_xlpm.t)>=7, MID(_xlpm.t,6,2), 1), IF(LEN(_xlpm.t)>=10, RIGHT(_xlpm.t,2), 1) ) ) ) ) -> 45231 | T32: =IF(R32="","",EDATE(S32,240)) -> 52536
A33: P100000120044 | B33: =INDEX('Plant data'!D:D,MATCH('Blast furnaces'!$A33,'Plant data'!$A:$A,0)) -> Jeceaba | C33: =INDEX('Plant data'!E:E,MATCH('Blast furnaces'!$A33,'Plant data'!$A:$A,0)) -> Minas Gerais | D33: =INDEX('Plant data'!F:F,MATCH('Blast furnaces'!$A33,'Plant data'!$A:$A,0)) -> Brazil | E33: U100000140032 | F33: BF 2 | G33: https://www.gem.wiki/Vallourec_Jeceaba_steel_plant | H33: operating | I33: unknown | J33: unknown | K33: 2014 | L33: 11 | M33: unknown | N33: unknown | O33: unknown | P33: 350 | Q33: 350 | S33: =_xlfn.LET( _xlpm.x, R33, _xlpm.t, TEXT(R33,"@"), IF(R33="","", IF(ISNUMBER(_xlpm.x), IF(_xlpm.x>=30000, _xlpm.x, DATE(_xlpm.x,1,1)), DATE( LEFT(_xlpm.t,4), IF(LEN(_xlpm.t)>=7, MID(_xlpm.t,6,2), 1), IF(LEN(_xlpm.t)>=10, RIGHT(_xlpm.t,2), 1) ) ) ) ) | T33: =IF(R33="","",EDATE(S33,240))
A34: P100000120044 | B34: =INDEX('Plant data'!D:D,MATCH('Blast furnaces'!$A34,'Plant data'!$A:$A,0)) -> Jeceaba | C34: =INDEX('Plant data'!E:E,MATCH('Blast furnaces'!$A34,'Plant data'!$A:$A,0)) -> Minas Gerais | D34: =INDEX('Plant data'!F:F,MATCH('Blast furnaces'!$A34,'Plant data'!$A:$A,0)) -> Brazil | E34: U100000140033 | F34: BF 1 | G34: https://www.gem.wiki/Vallourec_Jeceaba_steel_plant | H34: cancelled | I34: unknown | J34: unknown | K34: unknown | L34: unknown | M34: unknown | N34: unknown | O34: unknown | P34: 500 | Q34: 350 | S34: =_xlfn.LET( _xlpm.x, R34, _xlpm.t, TEXT(R34,"@"), IF(R34="","", IF(ISNUMBER(_xlpm.x), IF(_xlpm.x>=30000, _xlpm.x, DATE(_xlpm.x,1,1)), DATE( LEFT(_xlpm.t,4), IF(LEN(_xlpm.t)>=7, MID(_xlpm.t,6,2), 1), IF(LEN(_xlpm.t)>=10, RIGHT(_xlpm.t,2), 1) ) ) ) )
A35: P100000120045 | B35: =INDEX('Plant data'!D:D,MATCH('Blast furnaces'!$A35,'Plant data'!$A:$A,0)) -> Juiz de Fora | C35: =INDEX('Plant data'!E:E,MATCH('Blast furnaces'!$A35,'Plant data'!$A:$A,0)) -> Minas Gerais | D35: =INDEX('Plant data'!F:F,MATCH('Blast furnaces'!$A35,'Plant data'!$A:$A,0)) -> Brazil | E35: U100000140034 | F35: BF 1 | G35: https://www.gem.wiki/ArcelorMittal_Juiz_de_Fora_steel_plant | H35: operating | I35: unknown | J35: unknown | K35: 2007 | L35: 18 | M35: unknown | N35: unknown | O35: unknown | P35: 180 | Q35: 250 | R35: 44166 | S35: =_xlfn.LET( _xlpm.x, R35, _xlpm.t, TEXT(R35,"@"), IF(R35="","", IF(ISNUMBER(_xlpm.x), IF(_xlpm.x>=30000, _xlpm.x, DATE(_xlpm.x,1,1)), DATE( LEFT(_xlpm.t,4), IF(LEN(_xlpm.t)>=7, MID(_xlpm.t,6,2), 1), IF(LEN(_xlpm.t)>=10, RIGHT(_xlpm.t,2), 1) ) ) ) ) -> 44166 | T35: =IF(R35="","",EDATE(S35,240)) -> 51471
A36: P100000120045 | B36: =INDEX('Plant data'!D:D,MATCH('Blast furnaces'!$A36,'Plant data'!$A:$A,0)) -> Juiz de Fora | C36: =INDEX('Plant data'!E:E,MATCH('Blast furnaces'!$A36,'Plant data'!$A:$A,0)) -> Minas Gerais | D36: =INDEX('Plant data'!F:F,MATCH('Blast furnaces'!$A36,'Plant data'!$A:$A,0)) -> Brazil | E36: U100000140035 | F36: BF 2 | G36: https://www.gem.wiki/ArcelorMittal_Juiz_de_Fora_steel_plant | H36: operating | I36: unknown | J36: unknown | K36: 2007 | L36: 18 | M36: unknown | N36: unknown | O36: unknown | P36: 180 | Q36: 250 | R36: 44440 | S36: =_xlfn.LET( _xlpm.x, R36, _xlpm.t, TEXT(R36,"@"), IF(R36="","", IF(ISNUMBER(_xlpm.x), IF(_xlpm.x>=30000, _xlpm.x, DATE(_xlpm.x,1,1)), DATE( LEFT(_xlpm.t,4), IF(LEN(_xlpm.t)>=7, MID(_xlpm.t,6,2), 1), IF(LEN(_xlpm.t)>=10, RIGHT(_xlpm.t,2), 1) ) ) ) ) -> 44440 | T36: =IF(R36="","",EDATE(S36,240)) -> 51745
A37: P100000120046 | B37: =INDEX('Plant data'!D:D,MATCH('Blast furnaces'!$A37,'Plant data'!$A:$A,0)) -> Açailândia | C37: =INDEX('Plant data'!E:E,MATCH('Blast furnaces'!$A37,'Plant data'!$A:$A,0)) -> Maranhão | D37: =INDEX('Plant data'!F:F,MATCH('Blast furnaces'!$A37,'Plant data'!$A:$A,0)) -> Brazil | E37: U100000140036 | F37: BF 1; "Roberta" | G37: https://www.gem.wiki/AVB_Açailândia_steel_plant | H37: operating | I37: unknown | J37: unknown | K37: 2018 | L37: 7 | M37: unknown | N37: unknown | O37: unknown | P37: 360 | Q37: 352 | S37: =_xlfn.LET( _xlpm.x, R37, _xlpm.t, TEXT(R37,"@"), IF(R37="","", IF(ISNUMBER(_xlpm.x), IF(_xlpm.x>=30000, _xlpm.x, DATE(_xlpm.x,1,1)), DATE( LEFT(_xlpm.t,4), IF(LEN(_xlpm.t)>=7, MID(_xlpm.t,6,2), 1), IF(LEN(_xlpm.t)>=10, RIGHT(_xlpm.t,2), 1) ) ) ) ) | T37: =IF(R37="","",EDATE(S37,240))
A38: P100000120046 | B38: =INDEX('Plant data'!D:D,MATCH('Blast furnaces'!$A38,'Plant data'!$A:$A,0)) -> Açailândia | C38: =INDEX('Plant data'!E:E,MATCH('Blast furnaces'!$A38,'Plant data'!$A:$A,0)) -> Maranhão | D38: =INDEX('Plant data'!F:F,MATCH('Blast furnaces'!$A38,'Plant data'!$A:$A,0)) -> Brazil | E38: U100000140037 | F38: BF 2; "Regina" | G38: https://www.gem.wiki/AVB_Açailândia_steel_plant | H38: operating | I38: unknown | J38: unknown | K38: 2021 | L38: 4 | M38: unknown | N38: unknown | O38: unknown | P38: 360 | Q38: 352 | S38: =_xlfn.LET( _xlpm.x, R38, _xlpm.t, TEXT(R38,"@"), IF(R38="","", IF(ISNUMBER(_xlpm.x), IF(_xlpm.x>=30000, _xlpm.x, DATE(_xlpm.x,1,1)), DATE( LEFT(_xlpm.t,4), IF(LEN(_xlpm.t)>=7, MID(_xlpm.t,6,2), 1), IF(LEN(_xlpm.t)>=10, RIGHT(_xlpm.t,2), 1) ) ) ) ) | T38: =IF(R38="","",EDATE(S38,240))
A39: P100000120047 | B39: =INDEX('Plant data'!D:D,MATCH('Blast furnaces'!$A39,'Plant data'!$A:$A,0)) -> Divinópolis | C39: =INDEX('Plant data'!E:E,MATCH('Blast furnaces'!$A39,'Plant data'!$A:$A,0)) -> Minas Gerais | D39: =INDEX('Plant data'!F:F,MATCH('Blast furnaces'!$A39,'Plant data'!$A:$A,0)) -> Brazil | E39: U100000140038 | F39: BF 1 | G39: https://www.gem.wiki/Gerdau_Divinópolis_steel_plant | H39: operating | I39: unknown | J39: unknown | K39: 1957 | L39: 68 | M39: unknown | N39: unknown | O39: unknown | P39: 112 | Q39: 110 | R39: 44713 | S39: =_xlfn.LET( _xlpm.x, R39, _xlpm.t, TEXT(R39,"@"), IF(R39="","", IF(ISNUMBER(_xlpm.x), IF(_xlpm.x>=30000, _xlpm.x, DATE(_xlpm.x,1,1)), DATE( LEFT(_xlpm.t,4), IF(LEN(_xlpm.t)>=7, MID(_xlpm.t,6,2), 1), IF(LEN(_xlpm.t)>=10, RIGHT(_xlpm.t,2), 1) ) ) ) ) -> 44713 | T39: =IF(R39="","",EDATE(S39,240)) -> 52018
A40: P100000120047 | B40: =INDEX('Plant data'!D:D,MATCH('Blast furnaces'!$A40,'Plant data'!$A:$A,0)) -> Divinópolis | C40: =INDEX('Plant data'!E:E,MATCH('Blast furnaces'!$A40,'Plant data'!$A:$A,0)) -> Minas Gerais | D40: =INDEX('Plant data'!F:F,MATCH('Blast furnaces'!$A40,'Plant data'!$A:$A,0)) -> Brazil | E40: U100000140039 | F40: BF 3 | G40: https://www.gem.wiki/Gerdau_Divinópolis_steel_plant | H40: operating | I40: unknown | J40: unknown | K40: unknown | L40: unknown | M40: unknown | N40: unknown | O40: unknown | P40: 128 | Q40: 125 | R40: 44713 | S40: =_xlfn.LET( _xlpm.x, R40, _xlpm.t, TEXT(R40,"@"), IF(R40="","", IF(ISNUMBER(_xlpm.x), IF(_xlpm.x>=30000, _xlpm.x, DATE(_xlpm.x,1,1)), DATE( LEFT(_xlpm.t,4), IF(LEN(_xlpm.t)>=7, MID(_xlpm.t,6,2), 1), IF(LEN(_xlpm.t)>=10, RIGHT(_xlpm.t,2), 1) ) ) ) ) -> 44713 | T40: =IF(R40="","",EDATE(S40,240)) -> 52018
...

Sheet DRI furnaces
A1: GEM Plant ID | B1: Municipality | C1: Subnational unit (province/state) | D1: Country/Area | E1: GEM Unit ID | F1: Unit Name | G1: GEM Wiki Page | H1: Unit Status | I1: Announced Date | J1: Construction Date | K1: Start Date | L1: Unit Age | M1: Pre-retirement Announcement Date | N1: Idled Date | O1: Retired Date | P1: Furnace Manufacturer | Q1: Furnace Model | R1: Furnace Type | S1: Current Capacity (ttpa) | T1: CCS/CCUS | U1: Reductant | V1: Retirement Date
A2: P100000120001 | B2: =INDEX('Plant data'!D:D,MATCH($A2,'Plant data'!$A:$A,0)) -> Abu Dhabi Industrial City | C2: =INDEX('Plant data'!E:E,MATCH($A2,'Plant data'!$A:$A,0)) -> Abu Dhabi | D2: =INDEX('Plant data'!F:F,MATCH($A2,'Plant data'!$A:$A,0)) -> United Arab Emirates | E2: U100000143280 | F2: DRI 1 | G2: https://www.gem.wiki/Emsteel_Abu_Dhabi_plant | H2: operating | I2: unknown | J2: unknown | K2: 2009 | L2: 16 | M2: unknown | N2: unknown | O2: unknown | P2: Tenova HYL and Danieli & C | Q2: Energiron | R2: shaft furnace | S2: 2000 | T2: No | U2: hydrogen | V2: =IFERROR(K2+40,"") -> 2049
A3: P100000120001 | B3: =INDEX('Plant data'!D:D,MATCH($A3,'Plant data'!$A:$A,0)) -> Abu Dhabi Industrial City | C3: =INDEX('Plant data'!E:E,MATCH($A3,'Plant data'!$A:$A,0)) -> Abu Dhabi | D3: =INDEX('Plant data'!F:F,MATCH($A3,'Plant data'!$A:$A,0)) -> United Arab Emirates | E3: U100000143281 | F3: DRI 2 | G3: https://www.gem.wiki/Emsteel_Abu_Dhabi_plant | H3: operating | I3: unknown | J3: unknown | K3: 2011 | L3: 14 | M3: unknown | N3: unknown | O3: unknown | P3: Tenova HYL and Danieli & C | Q3: Energiron | R3: shaft furnace | S3: 2000 | T3: No | U3: methane | V3: =IFERROR(K3+40,"") -> 2051
A4: P100000120001 | B4: =INDEX('Plant data'!D:D,MATCH($A4,'Plant data'!$A:$A,0)) -> Abu Dhabi Industrial City | C4: =INDEX('Plant data'!E:E,MATCH($A4,'Plant data'!$A:$A,0)) -> Abu Dhabi | D4: =INDEX('Plant data'!F:F,MATCH($A4,'Plant data'!$A:$A,0)) -> United Arab Emirates | E4: U100001030327 | F4: DRI 3 | G4: https://www.gem.wiki/Emsteel_Abu_Dhabi_plant | H4: operating | I4: unknown | J4: unknown | K4: unknown | L4: unknown | M4: unknown | N4: unknown | O4: unknown | P4: unknown | Q4: unknown | R4: unknown | S4: 200 | T4: No | U4: unknown | V4: =IFERROR(K4+40,"")
A5: P100000120006 | B5: =INDEX('Plant data'!D:D,MATCH($A5,'Plant data'!$A:$A,0)) -> Villa Constitución | C5: =INDEX('Plant data'!E:E,MATCH($A5,'Plant data'!$A:$A,0)) -> Santa Fe | D5: =INDEX('Plant data'!F:F,MATCH($A5,'Plant data'!$A:$A,0)) -> Argentina | E5: U100000143284 | F5: unknown DRI (1) | G5: https://www.gem.wiki/ArcelorMittal_Acindar_Villa_Constitución_steel_plant | H5: operating | I5: unknown | J5: unknown | K5: 1978 | L5: 47 | M5: unknown | N5: unknown | O5: unknown | P5: unknown | Q5: Midrex | R5: shaft furnace | S5: 600 | T5: No | U5: unknown | V5: =IFERROR(K5+40,"") -> 2018
A6: P100000120007 | B6: =INDEX('Plant data'!D:D,MATCH($A6,'Plant data'!$A:$A,0)) -> Campana | C6: =INDEX('Plant data'!E:E,MATCH($A6,'Plant data'!$A:$A,0)) -> Buenos Aires | D6: =INDEX('Plant data'!F:F,MATCH($A6,'Plant data'!$A:$A,0)) -> Argentina | E6: U100000143285 | F6: unknown DRI (1) | G6: https://www.gem.wiki/TenarisSiderca_Campana_steel_plant | H6: operating | I6: unknown | J6: unknown | K6: 1976 | L6: 49 | M6: unknown | N6: unknown | O6: unknown | P6: unknown | Q6: Midrex | R6: shaft furnace | S6: 960 | T6: No | U6: unknown | V6: =IFERROR(K6+40,"") -> 2016
A7: P100000120011 | B7: =INDEX('Plant data'!D:D,MATCH($A7,'Plant data'!$A:$A,0)) -> Leoben | C7: =INDEX('Plant data'!E:E,MATCH($A7,'Plant data'!$A:$A,0)) -> Styria | D7: =INDEX('Plant data'!F:F,MATCH($A7,'Plant data'!$A:$A,0)) -> Austria | E7: U100001048461 | F7: DRI Hyfor | G7: https://www.gem.wiki/Voestalpine_Stahl_Donawitz_steel_plant | H7: operating | I7: unknown | J7: unknown | K7: 2024 | L7: 1 | M7: unknown | N7: unknown | O7: unknown | P7: Primetals | Q7: unknown | R7: shaft furnace | S7: 1 | T7: No | U7: hydrogen | V7: =IFERROR(K7+40,"") -> 2064
A8: P100000120013 | B8: =INDEX(#REF!,MATCH($A8,#REF!,0)) -> #REF! | C8: =INDEX(#REF!,MATCH($A8,#REF!,0)) -> #REF! | D8: =INDEX(#REF!,MATCH($A8,#REF!,0)) -> #REF! | E8: U100000143286 | F8: unknown DRI (1) | G8: https://www.gem.wiki/GFG_Liberty_Steel_Australia_Whyalla_steel_plant | H8: announced | I8: unknown | J8: unknown | K8: 2027 | M8: unknown | N8: unknown | O8: unknown | P8: unknown | Q8: unknown | R8: unknown | S8: 1800 | T8: No | U8: unknown | V8: =IFERROR(K8+40,"") -> 2067
A9: P100000120019 | B9: =INDEX(#REF!,MATCH($A9,#REF!,0)) -> #REF! | C9: =INDEX(#REF!,MATCH($A9,#REF!,0)) -> #REF! | D9: =INDEX(#REF!,MATCH($A9,#REF!,0)) -> #REF! | E9: U100000144885 | F9: unknown DRI (1) | G9: https://www.gem.wiki/Bashundhara_Steel_Mirsarai_plant | H9: announced | I9: 2022 | J9: unknown | K9: 2026 | M9: unknown | N9: unknown | O9: unknown | P9: unknown | Q9: unknown | R9: unknown | S9: 2200 | T9: No | U9: unknown | V9: =IFERROR(K9+40,"") -> 2066
A10: P100000120027 | B10: =INDEX(#REF!,MATCH($A10,#REF!,0)) -> #REF! | C10: =INDEX(#REF!,MATCH($A10,#REF!,0)) -> #REF! | D10: =INDEX(#REF!,MATCH($A10,#REF!,0)) -> #REF! | E10: U100000143287 | F10: unknown DRI (1) | G10: https://www.gem.wiki/ArcelorMittal_Gent_steel_plant | H10: announced | I10: unknown | J10: unknown | K10: unknown | L10: unknown | M10: unknown | N10: unknown | O10: unknown | P10: unknown | Q10: unknown | R10: unknown | S10: 2500 | T10: No | U10: unknown | V10: =IFERROR(K10+40,"")
A11: P100000120032 | B11: =INDEX('Plant data'!D:D,MATCH($A11,'Plant data'!$A:$A,0)) -> Al Hidd | C11: =INDEX('Plant data'!E:E,MATCH($A11,'Plant data'!$A:$A,0)) -> Muharraq | D11: =INDEX('Plant data'!F:F,MATCH($A11,'Plant data'!$A:$A,0)) -> Bahrain | E11: U100000143288 | F11: unknown DRI (1) | G11: https://www.gem.wiki/Sulb_Bahrain_Al_Hidd_steel_plant | H11: operating | I11: unknown | J11: unknown | K11: 2013 | L11: 12 | M11: unknown | N11: unknown | O11: unknown | P11: Midrex | Q11: unknown | R11: shaft furnace | S11: 1619 | T11: No | U11: methane | V11: =IFERROR(K11+40,"") -> 2053
A12: P100000120057 | B12: =INDEX('Plant data'!D:D,MATCH($A12,'Plant data'!$A:$A,0)) -> Contrecœur | C12: =INDEX('Plant data'!E:E,MATCH($A12,'Plant data'!$A:$A,0)) -> Quebec | D12: =INDEX('Plant data'!F:F,MATCH($A12,'Plant data'!$A:$A,0)) -> Canada | E12: U100000143289 | F12: DRI 1 | G12: https://www.gem.wiki/ArcelorMittal_Montreal_steel_plant | H12: operating | I12: unknown | J12: unknown | K12: unknown | L12: unknown | M12: unknown | N12: unknown | O12: unknown | P12: unknown | Q12: unknown | R12: shaft furnace | S12: 650 | T12: No | U12: methane | V12: =IFERROR(K12+40,"")
A13: P100000120057 | B13: =INDEX('Plant data'!D:D,MATCH($A13,'Plant data'!$A:$A,0)) -> Contrecœur | C13: =INDEX('Plant data'!E:E,MATCH($A13,'Plant data'!$A:$A,0)) -> Quebec | D13: =INDEX('Plant data'!F:F,MATCH($A13,'Plant data'!$A:$A,0)) -> Canada | E13: U100000143290 | F13: DRI 2 | G13: https://www.gem.wiki/ArcelorMittal_Montreal_steel_plant | H13: operating | I13: unknown | J13: unknown | K13: unknown | L13: unknown | M13: unknown | N13: unknown | O13: unknown | P13: unknown | Q13: unknown | R13: shaft furnace | S13: 1000 | T13: No | U13: methane | V13: =IFERROR(K13+40,"")
A14: P100000120058 | B14: =INDEX(#REF!,MATCH($A14,#REF!,0)) -> #REF! | C14: =INDEX(#REF!,MATCH($A14,#REF!,0)) -> #REF! | D14: =INDEX(#REF!,MATCH($A14,#REF!,0)) -> #REF! | E14: U100000143291 | F14: unknown DRI (1) | G14: https://www.gem.wiki/ArcelorMittal_Dofasco_steel_plant | H14: announced | I14: unknown | J14: unknown | K14: 2028 | M14: unknown | N14: unknown | O14: unknown | P14: unknown | Q14: unknown | R14: shaft furnace | S14: 2500 | T14: No | U14: methane | V14: =IFERROR(K14+40,"") -> 2068
