Workbook

Sheet About
A1: HRPfIEP Hurdle Rate Premium for Industrial Equipment Purchases
A3: Sources: | B3: Commercial time-preference premium distribution (KPREM)
B4: U.S. Energy Information Administration
B5: NEMS Commercial Demand Module input file KPREM (contact listed in-file: Meera Fickling; EIA; file dated Sept 19; 2019)
B6: 2019
B7: https://www.eia.gov/outlooks/aeo/nems/documentation/commercial/pdf/CDM_AEO2025.pdf
B8: Premiums added to the 10-yr Treasury rate; 7 segments {1000%; 100%; 45%; 25%; 15%; 6.5%; 0%}. Steady-state (2016+) space-heating weights pasted in the KPREM source tab. Population-mean 10-yr annuity factor = 1.78 yr = single-rate equivalent of approx. 55%. Commercial operators face landlord-tenant split incentives; treated as an upper bound for industrial purchase decisions.
B10: Industrial payback acceptance curve (AcceptFrac; CHP adoption)
B11: U.S. Energy Information Administration
B12: NEMS Industrial Demand Module input workbook indcogenx.xlsx (in-file provenance: EIA internal payback acceptance.xlsx; AEO2018 vintage)
B13: 2018
B14: https://github.com/EIAgov/NEMS
B15: Fraction of industrial market accepting a project with simple payback of N years; identical for smaller and large plants. Mean acceptable payback approx. 4.7 yr = single-rate equivalent approx. 17% on a 10-yr life. Adopt-vs-defer decision type; no published derivation of the underlying numbers.
B17: Empirical implicit discount rates; industrial retrofit adoption
B18: Anderson & Newell
B19: Information programs for technology adoption: the case of energy-efficiency audits; Resource and Energy Economics 26(1):27-50
B20: 2004
B21: https://doi.org/10.1016/j.reseneeco.2003.07.001
B22: DOE IAC audit data; ~9;000 small/medium manufacturing plants 1981-2000. Median payback threshold approx. 15 months; implied hurdle rates 50-100% (real; PPI-deflated) at 10-yr project life. Deferrable-retrofit decision type; this evidence family anchors the separate PAC Payback Acceptance Curve input; not this parameter.
B24: Empirical implicit discount rates; industrial retrofit adoption (updated sample)
B25: Qiu; Wang & Wang
B26: Implied discount rate and payback threshold of energy efficiency investment in the industrial sector; Applied Economics 47(21):2218-2233
B27: 2015
B28: https://doi.org/10.1080/00036846.2015.1005829
B29: IAC database 2002-2011; >30;000 recommendations. Implied discount rates 40-45%; average payback threshold approx. 9 months.
B31: Industrial hurdle-rate quantification with process/non-process split
B32: Warfel
B33: Quantifying the Hurdle Rates United States Industry Places on Energy Efficiency Opportunities; ACEEE Summer Study on Energy Efficiency in Industry
B34: 1998
B35: https://www.aceee.org/proceedings
B36: Corporate cost-of-capital baseline cited at 22-28%; energy-project investment tails off at approx. 2-yr payback. Process-affecting measures held to stricter thresholds than building-and-grounds measures.
B38: Model practice; industrial technology-choice discount rates
B39: European Commission JRC / E3Modelling
B40: JRC-EU-TIMES and PRIMES sectoral discount-rate assumptions (12% energy-intensive industry; 14% other industry)
B41: 2016
B42: https://doi.org/10.1016/j.enpol.2016.10.019
B43: UNVERIFIED against primary text (access blocked at time of compilation); verify before external citation. NEMS Residential Demand Module uses 20% for new-construction heating-system choice (RDM documentation; July 2026).
B45: Internal evidence digest and derivation record
B46: Energy Innovation (internal)
B47: Industry_HurdleRate_Premium_Research.md (EPS US repo root)
...

Sheet Parameters
A1: Parameter | B1: Value
A2: Target total decision hurdle rate (real) | B2: 0.2
A3: Equipment lifetime for annuity math (years) | B3: 10
A4: Reference risk-free rate for NEMS segment math (nominal; approx. 10-yr Treasury) | B4: 0.04

Sheet KPREM source
A1: FILE NAME: | B1: KPREM
A2: DATE MODIFIED: | B2: September 19, 2019
B3: 2010-2011 Fed; State; local govt. flsp; new+replace demand at T-bill to reflect ARRA funding; just new for 2012; 2013 except for lighting
A4: CONTACT: | B4: Meera Fickling; NEMS Buildings Analyst; Meera.fickling@eia.gov; (202)586-0765
A5: USED BY: | B5: Technology Choice subroutine of the National Energy Modeling System (NEMS) Commercial Demand Module (CDM)
A6: DEFINITION: | B6: Consumer time preference category proportions and premiums for each year from 1990 through 2050 inclusive. Represents the distribution of consumers and their associated time preference premia to be added to the risk-free interest rate to obtain the consumer discount rate for each segment.
A7: UNITS: | B7: unitless
A8: DIMENSION: | B8: End-use service; year
A10: Excerpt: 2016+ steady-state Space Heating block; the full file repeats near-identical blocks by end use and year through 2050.
A11: Proportion (P_p) | B11: Premium
A12: 0.266 | B12: 10
A13: 0.235 | B13: 1
A14: 0.196 | B14: 0.45
A15: 0.187 | B15: 0.25
A16: 0.098 | B16: 0.15
A17: 0.016 | B17: 0.065
A18: 0.002 | B18: 0

Sheet AcceptFrac source
A1: Excerpt: NEMS Industrial Demand Module CHP input workbook indcogenx.xlsx; sheet 'icogen'; rows 161-196; columns A-C; pasted verbatim.
A2: Market Penetration Assumptions | B2: Industrial | C2: IPP Version | D2: source: | E2: L:\mid\Industrial_Team\US\AEO\AEO2018\CHP\indcogen\payback acceptance.xlsx
A3: Payback Acceptance Fraction | B3: (smaller plants) | C3: (large plants)
A4: Payback Years | B4: Fraction with a given payback need
A5: 0 | B5: 0 | C5: 0
A6: 1 | B6: 0.13796482 | C6: 0.13796482
A7: 2 | B7: 0.13338675 | C7: 0.13338675
A8: 3 | B8: 0.12773564 | C8: 0.12773564
A9: 4 | B9: 0.11995636 | C9: 0.11995636
A10: 5 | B10: 0.1101785 | C10: 0.1101785
A11: 6 | B11: 0.098564968 | C11: 0.098564968
A12: 7 | B12: 0.085309265 | C12: 0.085309265
A13: 8 | B13: 0.070632237 | C13: 0.070632237
A14: 9 | B14: 0.054778417 | C14: 0.054778417
A15: 10 | B15: 0.038011942 | C15: 0.038011942
A16: 11 | B16: 0.020612156 | C16: 0.020612156
A17: 12 | B17: 0.0028689546 | C17: 0.0028689546
A18: leave blank==> | B18: 0 | C18: 0
A19: Check: Should add to 100% ==> | B19: =SUM(B5:B17) | C19: =SUM(C5:C17)
B20: Fraction with this payback or longer
A21: 0 | B21: 1 | C21: 1
A22: 1 | B22: 1 | C22: 1
A23: 2 | B23: 0.86203518 | C23: 0.86203518
A24: 3 | B24: 0.72864844 | C24: 0.72864844
A25: 4 | B25: 0.60091279 | C25: 0.60091279
A26: 5 | B26: 0.48095644 | C26: 0.48095644
A27: 6 | B27: 0.37077794 | C27: 0.37077794
A28: 7 | B28: 0.27221297 | C28: 0.27221297
A29: 8 | B29: 0.18690371 | C29: 0.18690371
A30: 9 | B30: 0.11627147 | C30: 0.11627147
A31: 10 | B31: 0.061493054 | C31: 0.061493054
A32: 11 | B32: 0.023481111 | C32: 0.023481111
A33: 12 | B33: 0.0028689546 | C33: 0.0028689546
A34: leave blank==> | B34: 0 | C34: 0

Sheet BCoISC source
A1: Unit: dimensionless (% of project cost) | B1: Weighted Average Cost of Capital
A2: agriculture and forestry 01T03 | B2: 0.04656
A3: coal mining 05 | B3: 0.05765
A4: oil and gas extraction 06 | B4: 0.03656
A5: other mining and quarrying 07T08 | B5: 0.05558
A6: food beverage and tobacco 10T12 | B6: 0.03824
A7: textiles apparel and leather 13T15 | B7: 0.04521
A8: wood products 16 | B8: 0.04321
A9: pulp paper and printing 17T18 | B9: 0.03842
A10: refined petroleum and coke 19 | B10: 0.02511
A11: chemicals 20 | B11: 0.03642
A12: rubber and plastic products 22 | B12: 0.01931
A13: glass and glass products 231 | B13: 0.05223
... A26: construction 41T43 | B26: 0.06035

Sheet Calculation
A1: Block A: KPREM single-rate equivalent
A2: Segment | B2: Premium | C2: Segment Rate | D2: Annuity Factor | E2: Weight | F2: Weighted AF
A3: Segment 1 | B3: ='KPREM source'!B12 | C3: =B3+Parameters!$B$4 | D3: =(1-(1+C3)^-Parameters!$B$3)/C3 | E3: ='KPREM source'!A12 | F3: =E3*D3
A4: Segment 2 | B4: ='KPREM source'!B13 | C4: =B4+Parameters!$B$4 | D4: =(1-(1+C4)^-Parameters!$B$3)/C4 | E4: ='KPREM source'!A13 | F4: =E4*D4
A5: Segment 3 | B5: ='KPREM source'!B14 | C5: =B5+Parameters!$B$4 | D5: =(1-(1+C5)^-Parameters!$B$3)/C5 | E5: ='KPREM source'!A14 | F5: =E5*D5
A6: Segment 4 | B6: ='KPREM source'!B15 | C6: =B6+Parameters!$B$4 | D6: =(1-(1+C6)^-Parameters!$B$3)/C6 | E6: ='KPREM source'!A15 | F6: =E6*D6
A7: Segment 5 | B7: ='KPREM source'!B16 | C7: =B7+Parameters!$B$4 | D7: =(1-(1+C7)^-Parameters!$B$3)/C7 | E7: ='KPREM source'!A16 | F7: =E7*D7
A8: Segment 6 | B8: ='KPREM source'!B17 | C8: =B8+Parameters!$B$4 | D8: =(1-(1+C8)^-Parameters!$B$3)/C8 | E8: ='KPREM source'!A17 | F8: =E8*D8
A9: Segment 7 | B9: ='KPREM source'!B18 | C9: =B9+Parameters!$B$4 | D9: =(1-(1+C9)^-Parameters!$B$3)/C9 | E9: ='KPREM source'!A18 | F9: =E9*D9
A11: Mean AF (weighted) | B11: =SUM(F3:F9)
A12: Implied KPREM single rate | B12: =RATE(Parameters!$B$3,-1,B11)
A14: Block B: AcceptFrac single-rate equivalent
A15: Payback Year | B15: Density (smaller plants) | C15: Year x Density
A16: ='AcceptFrac source'!A5 | B16: ='AcceptFrac source'!B5 | C16: =A16*B16
A17: ='AcceptFrac source'!A6 | B17: ='AcceptFrac source'!B6 | C17: =A17*B17
A18: ='AcceptFrac source'!A7 | B18: ='AcceptFrac source'!B7 | C18: =A18*B18
A19: ='AcceptFrac source'!A8 | B19: ='AcceptFrac source'!B8 | C19: =A19*B19
A20: ='AcceptFrac source'!A9 | B20: ='AcceptFrac source'!B9 | C20: =A20*B20
A21: ='AcceptFrac source'!A10 | B21: ='AcceptFrac source'!B10 | C21: =A21*B21
A22: ='AcceptFrac source'!A11 | B22: ='AcceptFrac source'!B11 | C22: =A22*B22
A23: ='AcceptFrac source'!A12 | B23: ='AcceptFrac source'!B12 | C23: =A23*B23
A24: ='AcceptFrac source'!A13 | B24: ='AcceptFrac source'!B13 | C24: =A24*B24
A25: ='AcceptFrac source'!A14 | B25: ='AcceptFrac source'!B14 | C25: =A25*B25
A26: ='AcceptFrac source'!A15 | B26: ='AcceptFrac source'!B15 | C26: =A26*B26
A27: ='AcceptFrac source'!A16 | B27: ='AcceptFrac source'!B16 | C27: =A27*B27
A28: ='AcceptFrac source'!A17 | B28: ='AcceptFrac source'!B17 | C28: =A28*B28
A30: Mean acceptable payback (years) | B30: =SUM(C16:C28)
A31: Implied AcceptFrac single rate | B31: =RATE(Parameters!$B$3,-1,B30)
A33: Block C: Evidence summary (literature figures; secondhand values flagged)
A34: AcceptFrac equivalent (NEMS industrial CHP payback curve) | B34: =B31 | C34: NEMS Industrial Demand Module indcogenx.xlsx
A35: Warfel (1998) corporate cost-of-capital baseline | B35: 0.22-0.28 (text range; literature figure) | C35: ACEEE Summer Study on Energy Efficiency in Industry 1998
A36: NEMS Residential Demand Module (RDM) new-construction heating choice | B36: 0.2 | C36: EIA RDM documentation; July 2026
A37: EU-TIMES / PRIMES industrial discount rate | B37: 0.12-0.14 (UNVERIFIED) | C37: JRC-EU-TIMES and PRIMES sectoral assumptions; Enepol 2016
A38: KPREM commercial time-preference equivalent (upper bound; split-incentive inflated) | B38: =B12 | C38: EIA NEMS Commercial Demand Module KPREM
A39: IAC retrofit-adoption implied rates (Anderson & Newell; Qiu Wang Wang) | B39: 0.40-1.00 (retrofit family - parameterizes PAC; not this input) | C39: Anderson & Newell 2004; Qiu Wang Wang 2015
A41: Block D: Derivation of exported value
A42: Mean WACC across 25 modeled industries | B42: =AVERAGE('BCoISC source'!B2:B26)
A43: Target total decision hurdle rate (Parameters) | B43: =Parameters!$B$2
A44: Exported premium (Target - Mean WACC) | B44: =MAX(0,B43-B42)
A46: Sensitivity ladder
...

Sheet Checks
A1: Check | B1: Value | C1: Result
A2: KPREM weights sum to 1 (within 0.005) | B2: =SUM('KPREM source'!A12:A18) | C2: =IF(ABS(B2-1)<=0.005,"PASS","FAIL")
A3: AcceptFrac density sums to 1 (within 0.001) | B3: =SUM('AcceptFrac source'!B5:B17) | C3: =IF(ABS(B3-1)<=0.001,"PASS","FAIL")
A4: Exported premium between 0 and 1 | B4: =Calculation!B44 | C4: =IF(AND(B4>=0,B4<=1),"PASS","FAIL")
A5: Premium + mean WACC equals Parameters target (within 1e-9) | B5: =Calculation!B44+Calculation!B42-Calculation!B43 | C5: =IF(ABS(B5)<=0.000000001,"PASS","FAIL")

Sheet HRPfIEP
A1: Unit: fraction (real; added to BCoISC WACC) | B1: Hurdle Rate Premium
A2: Industrial Equipment Purchases | B2: =ROUND(Calculation!B44,4)
