Workbook

Sheet About
A1: HCCbV Historical Clinker Consumed by Vintage
A3: Sources: | B3: U.S. cement apparent consumption and production, 1950-2021
B4: U.S. Geological Survey
B5: Cement Statistics, Historical Statistics for Mineral and Material Commodities in the United States (Data Series 140)
B6: 2023
B7: https://www.usgs.gov/media/files/cement-historical-statistics-data-series-140
B8: The 'Cement' sheet of ds140-cement-2021.xlsx (last modified May 3, 2023) is pasted verbatim on the 'USGS DS140' tab. We use the Apparent consumption column (production plus imports minus exports, adjusted for stocks) and the Production column. Values cover portland and masonry cement. USGS notes that the figures are calculated, estimated or reported; the series is a national total and cannot be split by end use or by state.
B10: U.S. cement apparent consumption, production and clinker production, 2021-2024
B11: U.S. Geological Survey
B12: Mineral Commodity Summaries 2026: Cement
B13: 2026
B14: https://pubs.usgs.gov/periodicals/mcs2026/mcs2026-cement.pdf
B15: Salient statistics pasted on the 'USGS MCS 2026' tab. We use apparent consumption for 2022-2024 (DS140 ends in 2021), and clinker and cement production for 2021-2024 to compute the clinker ratio. USGS rounds apparent consumption to the nearest million tons.
B17: U.S. clinker production, 1990, 2005 and 2018-2020
B18: U.S. Environmental Protection Agency
B19: Inventory of U.S. Greenhouse Gas Emissions and Sinks: 1990-2022, Chapter 4 (Industrial Processes and Product Use), Table 4-5
B20: 2024
B21: https://www.epa.gov/system/files/documents/2024-02/us-ghg-inventory-2024-chapter-4-industrial-processes-and-product-use.pdf
B22: Table 4-5 (Clinker Production, kt) is typed on the 'EPA GHGI clinker' tab. It includes Puerto Rico, which the USGS production figures also include in recent years; the small mismatch in earlier years is well inside the uncertainty of the clinker ratio. The inventory publishes only these anchor years, so the clinker ratio between them is interpolated.
A25: Notes:
A26: Purpose | B26: This file gives the EPS the clinker contained in the cement used in the United States in each year before the model starts, by year of use (the 'vintage'). The EPS uses it to work out how much CO2 the concrete and mortar already in place will take back up from the air through carbonation during the model run. Cement used during the model run comes from the model's own cement demand, so every vintage from the model's start year on is zero here.
A27: Layout | B27: The 'Parameters' tab holds the model start year. The 'Calculation' tab lines up consumption and the clinker ratio year by year and multiplies them. The dark blue 'HCCbV' tab is the exported file, one row per vintage from 1950 to 2050.
A28: Clinker ratio | B28: Clinker per ton of cement is clinker production divided by cement production in the years where both are published (EPA for 1990, 2005 and 2018-2020; USGS for 2021-2024), with straight lines between those years. Before 1990 we hold the 1990 ratio. The ratio counts clinker made in the United States against cement made here; imported cement is assumed to contain clinker in the same proportion. Cement from imported clinker makes the domestic ratio slightly low (by about 1-2 percent in recent years).
A29: Why 1950 | B29: The EPS tracks vintages from 1950. Cement used before then matters little: concrete takes up most of its CO2 within its service life (about 65 years in the U.S.), so cement used before 1950 had finished its in-use uptake before the model starts.

Sheet Parameters
A1: Model start year (first year the model computes cement use itself) | B1: 2025

Sheet USGS DS140
A1: CEMENT STATISTICS1
A2: U.S. GEOLOGICAL SURVEY
A3: [All values in metric tons (t) gross weight unless otherwise noted]
A4: Last modification: May 3, 2023
A5: Year | B5: Production | C5: Imports | D5: Exports | E5: Stocks | F5: Apparent consumption | G5: Unit value ($/t) | H5: Unit value (98$/t) | I5: World production
A6: 1900 | B6: 2680400 | C6: 411440 | D6: 17200 | E6: NA | F6: 3074600 | G6: 4 | H6: 78 | I6: NA
A7: 1901 | B7: 3202400 | C7: 161850 | D7: 64500 | E7: NA | F7: 3299800 | G7: 4.5 | H7: 88 | I7: NA
A8: 1902 | B8: 4147600 | C8: 338350 | D8: 58800 | E8: NA | F8: 4427100 | G8: 5.34 | H8: 100 | I8: NA
A9: 1903 | B9: 4898000 | C9: 388170 | D9: 49100 | E9: NA | F9: 5237100 | G9: 5.88 | H9: 110 | I9: NA
A10: 1904 | B10: 5282700 | C10: 166850 | D10: 134000 | E10: NA | F10: 5315900 | G10: 4.79 | H10: 87 | I10: NA
A11: 1905 | B11: 6750300 | C11: 154610 | D11: 155000 | E11: NA | F11: 6750100 | G11: 5.26 | H11: 95 | I11: NA
A12: 1906 | B12: 8643600 | C12: 391790 | D12: 100000 | E12: NA | F12: 8934900 | G12: 6.16 | H12: 110 | I12: NA
A13: 1907 | B13: 8897800 | C13: 350420 | D13: 155000 | E13: NA | F13: 9092900 | G13: 6.14 | H13: 110 | I13: NA
A14: 1908 | B14: 9059000 | C14: 145130 | D14: 146000 | E14: NA | F14: 9058200 | G14: 4.93 | H14: 89 | I14: NA
A15: 1909 | B15: 11437000 | C15: 76530 | D15: 182000 | E15: NA | F15: 11332000 | G15: 4.76 | H15: 86 | I15: NA
A16: 1910 | B16: 13366000 | C16: 52916 | D16: 427000 | E16: NA | F16: 12992000 | G16: 5.33 | H16: 93 | I16: NA
A17: 1911 | B17: 13678000 | C17: 28440 | D17: 540000 | E17: 1791000 | F17: 13166000 | G17: 5.32 | H17: 93 | I17: NA
A18: 1912 | B18: 14337000 | C18: 11893 | D18: 727000 | E18: 1347000 | F18: 13623000 | G18: 4.99 | H18: 84 | I18: NA
A19: 1913 | B19: 15994000 | C19: 14651 | D19: 511000 | E19: 1935000 | F19: 15498000 | G19: 6.06 | H19: 99.8 | I19: NA
A20: 1914 | B20: 15322000 | C20: 20856 | D20: 369000 | E20: 2202000 | F20: 14974000 | G20: 5.54 | H20: 90.3 | I20: NA
A21: 1915 | B21: 14919000 | C21: 7239 | D21: 442000 | E21: 1976000 | F21: 14484000 | G21: 5.18 | H21: 83.6 | I21: NA
A22: 1916 | B22: 15890000 | C22: 345 | D22: 442000 | E22: 1441000 | F22: 15448000 | G22: 6.61 | H22: 98.8 | I22: NA
A23: 1917 | B23: 16085000 | C23: 345 | D23: 446000 | E23: 1785000 | F23: 15639000 | G23: 8.14 | H23: 104 | I23: NA
A24: 1918 | B24: 12311000 | C24: 52 | D24: 388000 | E24: 1802000 | F24: 11923000 | G24: 9.65 | H24: 104 | I24: NA
A25: 1919 | B25: 13995000 | C25: 1551 | D25: 425000 | E25: 906000 | F25: 13572000 | G25: 10.3 | H25: 97.2 | I25: NA
A26: 1920 | B26: 17163000 | C26: 90492 | D26: 509000 | E26: 1507000 | F26: 16744000 | G26: 12.1 | H26: 98.8 | I26: NA
A27: 1921 | B27: 16950000 | C27: 20813 | D27: 201000 | E27: 2080000 | F27: 16769000 | G27: 11.2 | H27: 102 | I27: NA
A28: 1922 | B28: 19729000 | C28: 60734 | D28: 192000 | E28: 1595000 | F28: 19597000 | G28: 10.4 | H28: 101 | I28: NA
... A31: 1925 | B31: 27866000 | C31: 625590 | D31: 174000 | E31: 3153000 | F31: 28318000 | G31: 10.2 | H31: 95 | I31: NA
A32: 1926 | B32: 28420000 | C32: 553430 | D32: 166000 | E32: 3569000 | F32: 28807000 | G32: 9.89 | H32: 91.1 | I32: 62400000
A33: 1927 | B33: 29903000 | C33: 349730 | D33: 139000 | E33: 3856000 | F33: 29540000 | G33: 9.43 | H33: 88.3 | I33: 67800000
A34: 1928 | B34: 30445000 | C34: 392720 | D34: 141000 | E34: 3906000 | F34: 30231000 | G34: 9.11 | H34: 86.8 | I34: 72200000
A35: 1929 | B35: 29481000 | C35: 297700 | D35: 151000 | E35: 4076000 | F35: 29202000 | G35: 8.66 | H35: 82.5 | I35: 74900000
A36: 1930 | B36: 27798000 | C36: 167990 | D36: 129000 | E36: 4437000 | F36: 27227000 | G36: 8.42 | H36: 82.2 | I36: 72300000
A37: 1931 | B37: 21604000 | C37: 80159 | D37: 73300 | E37: 4191000 | F37: 21745000 | G37: 6.51 | H37: 69.8 | I37: 62100000
A38: 1932 | B38: 13166000 | C38: 79818 | D38: 64000 | E38: 3453000 | F38: 13729000 | G38: 5.95 | H38: 70.8 | I38: 49300000
A39: 1933 | B39: 10913000 | C39: 81353 | D39: 116000 | E39: 3334000 | F39: 10860000 | G39: 7.83 | H39: 98.2 | I39: 48200000
A40: 1934 | B40: 13375000 | C40: 45367 | D40: 96500 | E40: 3658000 | F40: 12877000 | G40: 9.06 | H40: 110 | I40: 58300000
A41: 1935 | B41: 13260000 | C41: 105570 | D41: 70900 | E41: 3935000 | F41: 12745000 | G41: 8.81 | H41: 105 | I41: 65400000
A42: 1936 | B42: 19523000 | C42: 282940 | D42: 57100 | E42: 3850000 | F42: 19129000 | G42: 8.61 | H42: 101 | I42: 62800000
...

Sheet USGS MCS 2026
A1: USGS Mineral Commodity Summaries 2026 - Cement. Salient Statistics - United States, pasted from the PDF ('e' = estimated). Thousand metric tons.
A2: Item | B2: 2021 | C2: 2022 | D2: 2023 | E2: 2024 | F2: 2025e
A3: Production: Portland, blended, and masonry cement (includes cement made from imported clinker) | B3: 91000 | C3: 91200 | D3: 89700 | E3: 85000 | F3: 84000
A4: Production: Clinker | B4: 79616 | C4: 79489 | D4: 76789 | E4: 72000 | F4: 69000
A5: Shipments to final customers, includes exports | B5: 108969 | C5: 111092 | D5: 110290 | E5: 100000 | F5: 100000
A6: Imports for consumption: Hydraulic cement | B6: 19937 | C6: 24985 | D6: 24986 | E6: 23675 | F6: 23000
A7: Imports for consumption: Clinker | B7: 1563 | C7: 1021 | D7: 921 | E7: 685 | F7: 660
A8: Exports, hydraulic cement and clinker | B8: 939 | C8: 904 | D8: 889 | E8: 932 | F8: 1000
A9: Consumption, apparent | B9: 111000 | C9: 114000 | D9: 113000 | E9: 110000 | F9: 110000

Sheet EPA GHGI clinker
A1: EPA GHG Inventory 1990-2022, Table 4-5: Clinker Production (kt). Includes Puerto Rico.
A2: Year | B2: Clinker (kt)
A3: 1990 | B3: 64355
A4: 2005 | B4: 88783
A5: 2018 | B5: 74900
A6: 2019 | B6: 78600
A7: 2020 | B7: 78200
A8: 2021 | B8: 79400
A9: 2022 | B9: 80500

Sheet Calculation
A1: How much clinker was in the cement used each year? Consumption x clinker ratio. Column G is what the output file reads.
A3: Year | B3: Cement used apparent consumption, t | C3: Cement produced t | D3: Clinker produced t (anchor years only) | E3: Clinker ratio in anchor years clinker / cement produced | F3: Clinker ratio used anchors, straight lines between, 1990 held before | G3: CLINKER IN CEMENT USED t (USED IN THE OUTPUT FILE)
A4: 1950 | B4: ='USGS DS140'!F56 -> 40891000 | C4: ='USGS DS140'!B56 -> 38724000 | F4: =$E$44 -> 0.91996169 | G4: =B4*F4 -> 37618153
A5: 1951 | B5: ='USGS DS140'!F57 -> 42695000 | C5: ='USGS DS140'!B57 -> 41825000 | F5: =$E$44 -> 0.91996169 | G5: =B5*F5 -> 39277764
A6: 1952 | B6: ='USGS DS140'!F58 -> 44335000 | C6: ='USGS DS140'!B58 -> 42394000 | F6: =$E$44 -> 0.91996169 | G6: =B6*F6 -> 40786501
A7: 1953 | B7: ='USGS DS140'!F59 -> 46047000 | C7: ='USGS DS140'!B59 -> 45021000 | F7: =$E$44 -> 0.91996169 | G7: =B7*F7 -> 42361476
A8: 1954 | B8: ='USGS DS140'!F60 -> 48897000 | C8: ='USGS DS140'!B60 -> 46434000 | F8: =$E$44 -> 0.91996169 | G8: =B8*F8 -> 44983367
A9: 1955 | B9: ='USGS DS140'!F61 -> 53589000 | C9: ='USGS DS140'!B61 -> 52994000 | F9: =$E$44 -> 0.91996169 | G9: =B9*F9 -> 49299827
A10: 1956 | B10: ='USGS DS140'!F62 -> 55225000 | C10: ='USGS DS140'!B62 -> 56153000 | F10: =$E$44 -> 0.91996169 | G10: =B10*F10 -> 50804884
A11: 1957 | B11: ='USGS DS140'!F63 -> 51638000 | C11: ='USGS DS140'!B63 -> 52574000 | F11: =$E$44 -> 0.91996169 | G11: =B11*F11 -> 47504982
A12: 1958 | B12: ='USGS DS140'!F64 -> 54542000 | C12: ='USGS DS140'!B64 -> 54831000 | F12: =$E$44 -> 0.91996169 | G12: =B12*F12 -> 50176550
A13: 1959 | B13: ='USGS DS140'!F65 -> 59899000 | C13: ='USGS DS140'!B65 -> 59764000 | F13: =$E$44 -> 0.91996169 | G13: =B13*F13 -> 55104785
A14: 1960 | B14: ='USGS DS140'!F66 -> 55526000 | C14: ='USGS DS140'!B66 -> 56063000 | F14: =$E$44 -> 0.91996169 | G14: =B14*F14 -> 51081793
A15: 1961 | B15: ='USGS DS140'!F67 -> 56826000 | C15: ='USGS DS140'!B67 -> 56718000 | F15: =$E$44 -> 0.91996169 | G15: =B15*F15 -> 52277743
... A43: 1989 | B43: ='USGS DS140'!F95 -> 82414000 | C43: ='USGS DS140'!B95 -> 70025000 | F43: =$E$44 -> 0.91996169 | G43: =B43*F43 -> 75817723
A44: 1990 | B44: ='USGS DS140'!F96 -> 80964000 | C44: ='USGS DS140'!B96 -> 69954000 | D44: ='EPA GHGI clinker'!B3*1000 -> 64355000 | E44: =D44/C44 -> 0.91996169 | F44: =E44 -> 0.91996169 | G44: =B44*F44 -> 74483778
A45: 1991 | B45: ='USGS DS140'!F97 -> 71800000 | C45: ='USGS DS140'!B97 -> 66755000 | F45: =E44+(E59-E44)*(A45-A44)/(A59-A44) -> 0.91822542 | G45: =B45*F45 -> 65928585
A46: 1992 | B46: ='USGS DS140'!F98 -> 76169000 | C46: ='USGS DS140'!B98 -> 69585000 | F46: =E44+(E59-E44)*(A46-A44)/(A59-A44) -> 0.91648914 | G46: =B46*F46 -> 69808061
A47: 1993 | B47: ='USGS DS140'!F99 -> 79701000 | C47: ='USGS DS140'!B99 -> 73807000 | F47: =E44+(E59-E44)*(A47-A44)/(A59-A44) -> 0.91475287 | G47: =B47*F47 -> 72906718
A48: 1994 | B48: ='USGS DS140'!F100 -> 86476000 | C48: ='USGS DS140'!B100 -> 77948000 | F48: =E44+(E59-E44)*(A48-A44)/(A59-A44) -> 0.91301659 | G48: =B48*F48 -> 78954023
A49: 1995 | B49: ='USGS DS140'!F101 -> 86003000 | C49: ='USGS DS140'!B101 -> 76906000 | F49: =E44+(E59-E44)*(A49-A44)/(A59-A44) -> 0.91128032 | G49: =B49*F49 -> 78372841
A50: 1996 | B50: ='USGS DS140'!F102 -> 90355000 | C50: ='USGS DS140'!B102 -> 79266000 | F50: =E44+(E59-E44)*(A50-A44)/(A59-A44) -> 0.90954404 | G50: =B50*F50 -> 82181852
A51: 1997 | B51: ='USGS DS140'!F103 -> 96018000 | C51: ='USGS DS140'!B103 -> 82582000 | F51: =E44+(E59-E44)*(A51-A44)/(A59-A44) -> 0.90780777 | G51: =B51*F51 -> 87165887
A52: 1998 | B52: ='USGS DS140'!F104 -> 103457000 | C52: ='USGS DS140'!B104 -> 83931000 | F52: =E44+(E59-E44)*(A52-A44)/(A59-A44) -> 0.9060715 | G52: =B52*F52 -> 93739439
A53: 1999 | B53: ='USGS DS140'!F105 -> 108862000 | C53: ='USGS DS140'!B105 -> 85952000 | F53: =E44+(E59-E44)*(A53-A44)/(A59-A44) -> 0.90433522 | G53: =B53*F53 -> 98447741
A54: 2000 | B54: ='USGS DS140'!F106 -> 110470000 | C54: ='USGS DS140'!B106 -> 87846000 | F54: =E44+(E59-E44)*(A54-A44)/(A59-A44) -> 0.90259895 | G54: =B54*F54 -> 99710106
A55: 2001 | B55: ='USGS DS140'!F107 -> 112800000 | C55: ='USGS DS140'!B107 -> 88900000 | F55: =E44+(E59-E44)*(A55-A44)/(A59-A44) -> 0.90086267 | G55: =B55*F55 -> 1.0161731e+08
A56: 2002 | B56: ='USGS DS140'!F108 -> 110020000 | C56: ='USGS DS140'!B108 -> 89732000 | F56: =E44+(E59-E44)*(A56-A44)/(A59-A44) -> 0.8991264 | G56: =B56*F56 -> 98921887
A57: 2003 | B57: ='USGS DS140'!F109 -> 114090000 | C57: ='USGS DS140'!B109 -> 92843000 | F57: =E44+(E59-E44)*(A57-A44)/(A59-A44) -> 0.89739013 | G57: =B57*F57 -> 1.0238324e+08
A58: 2004 | B58: ='USGS DS140'!F110 -> 121980000 | C58: ='USGS DS140'!B110 -> 97434000 | F58: =E44+(E59-E44)*(A58-A44)/(A59-A44) -> 0.89565385 | G58: =B58*F58 -> 1.0925186e+08
A59: 2005 | B59: ='USGS DS140'!F111 -> 128250000 | C59: ='USGS DS140'!B111 -> 99319000 | D59: ='EPA GHGI clinker'!B4*1000 -> 88783000 | E59: =D59/C59 -> 0.89391758 | F59: =E59 -> 0.89391758 | G59: =B59*F59 -> 1.1464493e+08
A60: 2006 | B60: ='USGS DS140'!F112 -> 127660000 | C60: ='USGS DS140'!B112 -> 98167000 | F60: =E59+(E72-E59)*(A60-A59)/(A72-A59) -> 0.89183916 | G60: =B60*F60 -> 1.1385219e+08
A61: 2007 | B61: ='USGS DS140'!F113 -> 116550000 | C61: ='USGS DS140'!B113 -> 95464000 | F61: =E59+(E72-E59)*(A61-A59)/(A72-A59) -> 0.88976074 | G61: =B61*F61 -> 1.0370161e+08
A62: 2008 | B62: ='USGS DS140'!F114 -> 96760000 | C62: ='USGS DS140'!B114 -> 86310000 | F62: =E59+(E72-E59)*(A62-A59)/(A72-A59) -> 0.88768233 | G62: =B62*F62 -> 85892142
A63: 2009 | B63: ='USGS DS140'!F115 -> 71540000 | C63: ='USGS DS140'!B115 -> 63929000 | F63: =E59+(E72-E59)*(A63-A59)/(A72-A59) -> 0.88560391 | G63: =B63*F63 -> 63356104
A64: 2010 | B64: ='USGS DS140'!F116 -> 71180000 | C64: ='USGS DS140'!B116 -> 66447000 | F64: =E59+(E72-E59)*(A64-A59)/(A72-A59) -> 0.88352549 | G64: =B64*F64 -> 62889344
A65: 2011 | B65: ='USGS DS140'!F117 -> 72200000 | C65: ='USGS DS140'!B117 -> 67895000 | F65: =E59+(E72-E59)*(A65-A59)/(A72-A59) -> 0.88144707 | G65: =B65*F65 -> 63640479
A66: 2012 | B66: ='USGS DS140'!F118 -> 77880000 | C66: ='USGS DS140'!B118 -> 74151000 | F66: =E59+(E72-E59)*(A66-A59)/(A72-A59) -> 0.87936865 | G66: =B66*F66 -> 68485231
A67: 2013 | B67: ='USGS DS140'!F119 -> 81750000 | C67: ='USGS DS140'!B119 -> 76804000 | F67: =E59+(E72-E59)*(A67-A59)/(A72-A59) -> 0.87729024 | G67: =B67*F67 -> 71718477
A68: 2014 | B68: ='USGS DS140'!F120 -> 89220000 | C68: ='USGS DS140'!B120 -> 82535000 | F68: =E59+(E72-E59)*(A68-A59)/(A72-A59) -> 0.87521182 | G68: =B68*F68 -> 78086398
...

Sheet Checks
A1: CHECK: is every clinker ratio between 0.75 and 1? (1 = problem) | B1: =IF(OR(MIN(Calculation!F4:F78)<0.75,MAX(Calculation!F4:F78)>1),1,0) -> 0
A2: CHECK: does every year before the start year have consumption? (1 = problem) | B2: =IF(COUNT(Calculation!B4:B78)<75,1,0) -> 0

Sheet HCCbV
A1: Unit: metric tons clinker | B1: Clinker in Cement Used
A2: ModeledVintage1950 | B2: =IF(1950<Parameters!$B$1,Calculation!G4,0) -> 37618153
A3: ModeledVintage1951 | B3: =IF(1951<Parameters!$B$1,Calculation!G5,0) -> 39277764
A4: ModeledVintage1952 | B4: =IF(1952<Parameters!$B$1,Calculation!G6,0) -> 40786501
A5: ModeledVintage1953 | B5: =IF(1953<Parameters!$B$1,Calculation!G7,0) -> 42361476
A6: ModeledVintage1954 | B6: =IF(1954<Parameters!$B$1,Calculation!G8,0) -> 44983367
A7: ModeledVintage1955 | B7: =IF(1955<Parameters!$B$1,Calculation!G9,0) -> 49299827
A8: ModeledVintage1956 | B8: =IF(1956<Parameters!$B$1,Calculation!G10,0) -> 50804884
A9: ModeledVintage1957 | B9: =IF(1957<Parameters!$B$1,Calculation!G11,0) -> 47504982
A10: ModeledVintage1958 | B10: =IF(1958<Parameters!$B$1,Calculation!G12,0) -> 50176550
A11: ModeledVintage1959 | B11: =IF(1959<Parameters!$B$1,Calculation!G13,0) -> 55104785
A12: ModeledVintage1960 | B12: =IF(1960<Parameters!$B$1,Calculation!G14,0) -> 51081793
A13: ModeledVintage1961 | B13: =IF(1961<Parameters!$B$1,Calculation!G15,0) -> 52277743
A14: ModeledVintage1962 | B14: =IF(1962<Parameters!$B$1,Calculation!G16,0) -> 54262100
A15: ModeledVintage1963 | B15: =IF(1963<Parameters!$B$1,Calculation!G17,0) -> 58553722
A16: ModeledVintage1964 | B16: =IF(1964<Parameters!$B$1,Calculation!G18,0) -> 60854546
A17: ModeledVintage1965 | B17: =IF(1965<Parameters!$B$1,Calculation!G19,0) -> 62179291
A18: ModeledVintage1966 | B18: =IF(1966<Parameters!$B$1,Calculation!G20,0) -> 63008176
A19: ModeledVintage1967 | B19: =IF(1967<Parameters!$B$1,Calculation!G21,0) -> 62059696
A20: ModeledVintage1968 | B20: =IF(1968<Parameters!$B$1,Calculation!G22,0) -> 65519671
A21: ModeledVintage1969 | B21: =IF(1969<Parameters!$B$1,Calculation!G23,0) -> 65410196
A22: ModeledVintage1970 | B22: =IF(1970<Parameters!$B$1,Calculation!G24,0) -> 62075335
A23: ModeledVintage1971 | B23: =IF(1971<Parameters!$B$1,Calculation!G25,0) -> 67011849
A24: ModeledVintage1972 | B24: =IF(1972<Parameters!$B$1,Calculation!G26,0) -> 70623619
A25: ModeledVintage1973 | B25: =IF(1973<Parameters!$B$1,Calculation!G27,0) -> 75382581
A26: ModeledVintage1974 | B26: =IF(1974<Parameters!$B$1,Calculation!G28,0) -> 68853613
A27: ModeledVintage1975 | B27: =IF(1975<Parameters!$B$1,Calculation!G29,0) -> 58516923
A28: ModeledVintage1976 | B28: =IF(1976<Parameters!$B$1,Calculation!G30,0) -> 62105694
A29: ModeledVintage1977 | B29: =IF(1977<Parameters!$B$1,Calculation!G31,0) -> 67550027
A30: ModeledVintage1978 | B30: =IF(1978<Parameters!$B$1,Calculation!G32,0) -> 72941922
A31: ModeledVintage1979 | B31: =IF(1979<Parameters!$B$1,Calculation!G33,0) -> 72643855
A32: ModeledVintage1980 | B32: =IF(1980<Parameters!$B$1,Calculation!G34,0) -> 64556472
A33: ModeledVintage1981 | B33: =IF(1981<Parameters!$B$1,Calculation!G35,0) -> 60802108
A34: ModeledVintage1982 | B34: =IF(1982<Parameters!$B$1,Calculation!G36,0) -> 54803958
A35: ModeledVintage1983 | B35: =IF(1983<Parameters!$B$1,Calculation!G37,0) -> 60568438
A36: ModeledVintage1984 | B36: =IF(1984<Parameters!$B$1,Calculation!G38,0) -> 70088201
A37: ModeledVintage1985 | B37: =IF(1985<Parameters!$B$1,Calculation!G39,0) -> 72526100
A38: ModeledVintage1986 | B38: =IF(1986<Parameters!$B$1,Calculation!G40,0) -> 76206866
A39: ModeledVintage1987 | B39: =IF(1987<Parameters!$B$1,Calculation!G41,0) -> 77464454
A40: ModeledVintage1988 | B40: =IF(1988<Parameters!$B$1,Calculation!G42,0) -> 77139708
...
