Workbook
Name dollars_2018_to_2012: #REF!
Name dollars_2020_2012: About!$A$85
Name dollars_2021_2012: #REF!
Name dollars_2022_2012: #REF!
Name lignite_multiplier: #REF!
Name nonlignite_multiplier: #REF!

Sheet About
A1: BS BAU Subsidy for Thermal Fuels per Energy Unit Produced
A2: BS BAU Subsidy per Unit Electricity Output
A3: BS BAU Subsidy per Unit Electricity Output for Exisiting Plants
A4: BS BAU Subsidy per Unit Electricity Capacity Built
A5: BS Duration of Subsidies per Unit Electricity Output
A7: Source: | B7: Tax Expenditures
B8: Joint Committee on Taxation, 113th Congress, 2nd Session
B9: 2014
B10: Estimates of Federal Tax Expenditures for Fiscal Years 2014-2018
B11: https://www.jct.gov/publications.html?func=download&id=4663&chk=4663&no_html=1
B12: Pages 22-34, Table 1
B14: Investment Tax Credit
B15: Database of State Incentives for Renewables & Efficiency (DSIRE)
B16: 2015
B17: Business Energy Investment Tax Credit
B18: http://programs.dsireusa.org/system/program/detail/658
B20: Production Tax Credit
B21: Congressional Research Service
B22: 2020
B23: The Renewable Electricity Production Tax Credit: In Brief
B24: https://fas.org/sgp/crs/misc/R43453.pdf
B26: Tax Credit for Qualifying Advanced Coal Projects
B27: Legal Information Institute, Cornell University Law School
B28: 2015
B29: 26 U.S. Code § 48A - Qualifying advanced coal project credit
B30: https://www.law.cornell.edu/uscode/text/26/48A
B32: Capital Gains Treatment for Royalties of Coal; Inclusion of Coal in Expensing of Exploration and Development Costs for Hard Mineral Fuels; Deductions for Tertiary Injections
B33: U.S. Treasury
B34: 2015
B35: Progress Report on Fossil Fuel Subsidies
B36: http://www.treasury.gov/open/Documents/USA%20FFSR%20progress%20report%20to%20G20%202014%20Final.pdf
B37: p.5
B39: Energy Production
B40: Energy Information Administration
B41: 2021, 2022, 2025, 2026
B42: Annual Energy Outlook 2021, Annual Energy Outlook 2022, Annual Energy Outlook 2025 (AEO 2025 High Zero-Carbon Technology Cost), Annual Energy Outlook 2026 (Alternative Electricity and Transportation)
B43: https://www.eia.gov/outlooks/aeo/tables_side.php
B44: Table 1, Table 8, Table 11
B46: 2020 Tax Credit Expansions
B47: Jeff St. John
...

Sheet 45Y48E Credits
A1: Methodology:
A2: First, we calculate the percentage of new plants that will qualify for a) the prevailing wage and apprenticeship requirements and b) the domestic content requirements. For part a, we only calculate the share of plants that would meet the apprenticeship requirement and assume all these plants would also meet the prevailing wage requirement (varying assumptions on the share of qualifying plants across scenarios based on data for the construction industry from the ACP Labor Supply Report). For part a, we assume this requirement can be met in every year (which would represent union representation grows by roughly 20% by 2025. For part b, we calculate the domestic content share for each power plant type. For onshore and offshore wind, we assume 100% of plants qualify for the bonus credit, based on a Net Zero America analysis, which lists domestic content shares for various wind components at well over the 55% domestic content requirement. For solar, we use the cited domestic content values for cells, modules, and inverters to calculate a weighted domestic content share, given the percentage of solar capital costs by component from the JEDI model. We assume the domestic content share can increase to meet half the difference between current levels and the 55% requirement by 2026. Next, we add in the energy community bonus, assuming that 50% of capacity additions qualify. We then calculate what the total credit value would be for each technology in each year for both the ITC and the PTC. Here, we assume credits start in 2023 and run at their full value through 2032. For the PTC values, we also adjust the calculated credit by the present value over 10 years divided by the present value over the plant lifetime, because the PTC is only available for the first 10 years of a plant's lifetime. Finally, we apply a transferability multiplier of 7.5%. This value reduces the credit value available to developers to account for the fact tax credits are transferable. We limit our analysis to onshore and offshore wind, solar PV, solar thermal, geothermal, municipal solid waste, and battery storage. We do not model credits for qualifying hydro or biogas plants. For solar PV, we calculate a LCOE for both the ITC and PTC settings to determine whether that resource elects the ITC or the PTC in each year (the result is that solar PV opts for the PTC in every year of IRA tax credits).
A4: Phase-Out:
A5: The IRA tax credits will begin to phase out the later of either when electricity sector emissions fall 75% below 2022 values or after 2032.
A6: According to the EPA Greenhouse Gas Inventory, electricity sector CO2 emissions were 1554.4 MMT in 2022.
A7: Therefore, we evaluate when EPS electricity sector emissions fall below:
A8: =1554.4*0.25 -> 388.6 | B8: MMT
A9: Latest calibration year target passed: 2036
A10: https://www.nrel.gov/docs/fy25osti/92256.pdf
A12: First year after applicable year | B12: Second year following applicable year | C12: Third year following applicable year | D12: All years thereafter
A13: 1 | B13: 0.75 | C13: 0.5 | D13: 0
P14: threshold reached | Q14: first year | R14: second year | S14: third year
A15: Phaseout Timeline (without commenced construction provisions, covered below)
B16: 2019 | C16: 2020 | D16: 2021 | E16: 2022 | F16: 2023 | G16: 2024 | H16: 2025 | I16: 2026 | J16: 2027 | K16: 2028 | L16: 2029 | M16: 2030 | N16: 2031 | O16: 2032 | P16: 2033 | Q16: 2034 | R16: 2035 | S16: 2036 | T16: 2037 | U16: 2038 | V16: 2039 | W16: 2040 | X16: 2041 | Y16: 2042 | Z16: 2043 | AA16: 2044 | AB16: 2045 | AC16: 2046 | AD16: 2047 | AE16: 2048 | AF16: 2049 | AG16: 2050
A17: geothermal/nuclear/other | B17: 1 | C17: 1 | D17: 1 | E17: 1 | F17: 1 | G17: 1 | H17: 1 | I17: 1 | J17: 1 | K17: 1 | L17: 1 | M17: 1 | N17: 1 | O17: 1 | P17: =A13 -> 1 | Q17: =B13 -> 0.75 | R17: =C13 -> 0.5 | S17: =D13 -> 0 | T17: =E13 -> 0 | U17: =F13 -> 0 | V17: =G13 -> 0 | W17: =H13 -> 0 | ... AG17: =R13 -> 0
A18: wind/solar* | B18: 1 | C18: 1 | D18: 1 | E18: 1 | F18: 1 | G18: 1 | H18: 0.667 | I18: 0.333 | J18: 0 | K18: 0 | L18: 0 | M18: 0 | N18: 0 | O18: 0 | P18: 0 | Q18: 0 | R18: 0 | S18: 0 | T18: 0 | U18: 0 | V18: 0 | W18: 0 | X18: 0 | Y18: 0 | Z18: 0 | AA18: 0 | AB18: 0 | AC18: 0 | AD18: 0 | AE18: 0 | AF18: 0 | AG18: 0
A19: *the safe harbor deadline to qualify for the more relaxed safe harbor restrictions is July 4, 2026. We use reduced values here to represent lower qualifying shares of deployment
A20: in 2029 and 2030 as the stock of safe-harbored power plants is depleted and new, unsubsidized power plants take over.
A21: Calculations:
A22: Union Representation Calculations:
A23: Union membership
A24: https://cleanpower.org/wp-content/uploads/2021/06/ACP-Labor-Supply-Report.pdf
A43: Used union membership value for the construction industry to approximate. The apprenticeship provision applies to
A44: "each contractor and subcontractor who employs 4 or more individuals to perform construction, alteration,
A45: or repair work."
A46: We assume that the rate of union membership can increase by 20% by 2025 in response to the tax credit incentives.
A47: Current Value | B47: 0.127
A48: Value if Increased by 20% | B48: =B47*1.2 -> 0.1524
B50: 2022 | C50: 2023 | D50: 2024 | E50: 2025 | F50: 2026 | G50: 2027 | H50: 2028 | I50: 2029 | J50: 2030 | K50: 2031 | L50: 2032 | M50: 2033 | N50: 2034 | O50: 2035 | P50: 2036 | Q50: 2037 | R50: 2038 | S50: 2039 | T50: 2040 | U50: 2041 | V50: 2042 | W50: 2043 | X50: 2044 | Y50: 2045 | Z50: 2046 | AA50: 2047 | AB50: 2048 | AC50: 2049 | AD50: 2050
A51: Percentage of total labor hours that must be from qualified apprentices | B51: 0 | C51: 0.05 | D51: 0.1 | E51: 0.15 | F51: 0.15 | G51: 0.15 | H51: 0.15 | I51: 0.15 | J51: 0.15 | K51: 0.15 | L51: 0.15 | M51: 0.15 | N51: 0.15 | O51: 0.15 | P51: 0.15 | Q51: 0.15 | R51: 0.15 | S51: 0.15 | T51: 0.15 | U51: 0.15 | V51: 0.15 | W51: 0.15 | X51: 0.15 | Y51: 0.15 | Z51: 0.15 | AA51: 0.15 | AB51: 0.15 | AC51: 0.15 | AD51: 0.15
A52: Percent multiplier for bonus credit | B52: =B51 -> 0 | C52: 1 | D52: 1 | E52: 1 | F52: 1 | G52: 1 | H52: 1 | I52: 1 | J52: 1 | K52: 1 | L52: 1 | M52: 1 | N52: 1 | O52: 1 | P52: 1 | Q52: 1 | R52: 1 | S52: 1 | T52: 1 | U52: 1 | V52: 1 | W52: 1 | X52: 1 | Y52: 1 | Z52: 1 | AA52: 1 | AB52: 1 | AC52: 1 | AD52: 1
A54: Domestic Content Calculations
A55: Assumed that wind fully qualifies for domestic content credit, because weighted domestic content share is ~70%
A56: Source: https://netzeroamerica.princeton.edu/img/Working_Paper-High_Road_Labor_and_Renewable_Energy-PUBLIC_RELEASE-4-13-21.pdf
A58: Solar PV Capital Costs | B58: Percent | D58: Net Zero America: Domestic Content Share
A59: Construction Costs | B59: of Cost
A60: Module | B60: 0.412 | D60: 0.11
A61: Inverter | B61: 0.132 | D61: 0.37
A62: Electrical BOS | B62: 0.114 | D62: 0.15
A63: Structural BOS | B63: 0.07
...

Sheet Tax Credits
A1: LEGACY REFERENCE: IRA-era NREL ATB tax credit assumptions. Nothing in this workbook reads this tab; the CSVs follow the 45Y48E Credits tab (see About).
C2: 2021 | D2: 2022 | E2: 2023 | F2: 2024 | G2: 2025 | H2: 2026 | I2: 2027 | J2: 2028 | K2: 2029 | L2: 2030 | M2: 2031 | N2: 2032 | O2: 2033 | P2: 2034 | Q2: 2035 | R2: 2036 | S2: 2037 | T2: 2038 | U2: 2039 | V2: 2040 | W2: 2041 | X2: 2042 | Y2: 2043 | Z2: 2044 | AA2: 2045 | AB2: 2046 | AC2: 2047 | AD2: 2048 | AE2: 2049 | AF2: 2050
A3: R&D ITC (%) | B3: R&D Scenario | C3: 0 | D3: 0 | E3: 0 | F3: 0 | G3: 0 | H3: 0 | I3: 0 | J3: 0 | K3: 0 | L3: 0 | M3: 0 | N3: 0 | O3: 0 | P3: 0 | Q3: 0 | R3: 0 | S3: 0 | T3: 0 | U3: 0 | V3: 0 | W3: 0 | X3: 0 | Y3: 0 | Z3: 0 | AA3: 0 | AB3: 0 | AC3: 0 | AD3: 0 | AE3: 0 | AF3: 0
A4: R&D PTC ($/MWh) | C4: 0 | D4: 0 | E4: 0 | F4: 0 | G4: 0 | H4: 0 | I4: 0 | J4: 0 | K4: 0 | L4: 0 | M4: 0 | N4: 0 | O4: 0 | P4: 0 | Q4: 0 | R4: 0 | S4: 0 | T4: 0 | U4: 0 | V4: 0 | W4: 0 | X4: 0 | Y4: 0 | Z4: 0 | AA4: 0 | AB4: 0 | AC4: 0 | AD4: 0 | AE4: 0 | AF4: 0
B6: Market and Policies Scenario
C7: Note that changing tax credit assumptions has implications for project financing. If you change numbers here, we strongly recommend changing debt fractions on the WACC Calc sheet as well.
A9: ITC (%) | B9: Offshore Wind | C9: 0.30000001 | D9: 0.30000001 | E9: 0.30000001 | F9: 0.30000001 | G9: 0.30000001 | H9: 0.30000001 | I9: 0.30000001 | J9: 0.30000001 | K9: 0.30000001 | L9: 0.30000001 | M9: 0.30000001 | N9: 0.30000001 | O9: 0.30000001 | P9: 0.30000001 | Q9: 0.30000001 | R9: 0.30000001 | S9: 0.30000001 | T9: 0.30000001 | U9: 0.30000001 | V9: 0.30000001 | W9: 0.30000001 | X9: 0.30000001 | Y9: 0.30000001 | Z9: 0.30000001 | AA9: 0.30000001 | AB9: 0.30000001 | AC9: 0.30000001 | AD9: 0.30000001 | AE9: 0.30000001 | AF9: 0.22500001 | AH9: 10 Year Safe Harbor
B10: Land-Based Wind | C10: 0 | D10: 0 | E10: 0 | F10: 0 | G10: 0 | H10: 0 | I10: 0 | J10: 0 | K10: 0 | L10: 0 | M10: 0 | N10: 0 | O10: 0 | P10: 0 | Q10: 0 | R10: 0 | S10: 0 | T10: 0 | U10: 0 | V10: 0 | W10: 0 | X10: 0 | Y10: 0 | Z10: 0 | AA10: 0 | AB10: 0 | AC10: 0 | AD10: 0 | AE10: 0 | AF10: 0
B11: Distributed Wind | C11: 0 | D11: 0 | E11: 0.30000001 | F11: 0.30000001 | G11: 0.30000001 | H11: 0.30000001 | I11: 0.30000001 | J11: 0.30000001 | K11: 0.30000001 | L11: 0.30000001 | M11: 0.30000001 | N11: 0.30000001 | O11: 0.30000001 | P11: 0.30000001 | Q11: 0.30000001 | R11: 0.30000001 | S11: 0.30000001 | T11: 0.30000001 | U11: 0.30000001 | V11: 0.30000001 | W11: 0.30000001 | X11: 0.30000001 | Y11: 0.30000001 | Z11: 0.22500001 | AA11: 0.15000001 | AB11: 0 | AC11: 0 | AD11: 0 | AE11: 0 | AF11: 0 | AH11: 4 Year Safe Harbor
B12: Solar - Utility PV | C12: 0.30000001 | D12: 0.30000001 | E12: 0 | F12: 0 | G12: 0 | H12: 0 | I12: 0 | J12: 0 | K12: 0 | L12: 0 | M12: 0 | N12: 0 | O12: 0 | P12: 0 | Q12: 0 | R12: 0 | S12: 0 | T12: 0 | U12: 0 | V12: 0 | W12: 0 | X12: 0 | Y12: 0 | Z12: 0 | AA12: 0 | AB12: 0 | AC12: 0 | AD12: 0 | AE12: 0 | AF12: 0
B13: Solar - PV Dist. Comm | C13: 0.30000001 | D13: 0.30000001 | E13: 0.30000001 | F13: 0.30000001 | G13: 0.30000001 | H13: 0.30000001 | I13: 0.30000001 | J13: 0.30000001 | K13: 0.30000001 | L13: 0.30000001 | M13: 0.30000001 | N13: 0.30000001 | O13: 0.30000001 | P13: 0.30000001 | Q13: 0.30000001 | R13: 0.30000001 | S13: 0.30000001 | T13: 0.30000001 | U13: 0.30000001 | V13: 0.30000001 | W13: 0.30000001 | X13: 0.30000001 | Y13: 0.30000001 | Z13: 0.22500001 | AA13: 0.15000001 | AB13: 0 | AC13: 0 | AD13: 0 | AE13: 0 | AF13: 0 | AH13: 4 Year Safe Harbor
B14: Solar - PV Dist. Res | C14: 0.30000001 | D14: 0.30000001 | E14: 0.30000001 | F14: 0.30000001 | G14: 0.30000001 | H14: 0.30000001 | I14: 0.30000001 | J14: 0.30000001 | K14: 0.30000001 | L14: 0.30000001 | M14: 0.30000001 | N14: 0.30000001 | O14: 0.26 | P14: 0.22 | Q14: 0 | R14: 0 | S14: 0 | T14: 0 | U14: 0 | V14: 0 | W14: 0 | X14: 0 | Y14: 0 | Z14: 0 | AA14: 0 | AB14: 0 | AC14: 0 | AD14: 0 | AE14: 0 | AF14: 0
B15: Solar - CSP | C15: 0.30000001 | D15: 0.30000001 | E15: 0.30000001 | F15: 0.30000001 | G15: 0.30000001 | H15: 0.30000001 | I15: 0.30000001 | J15: 0.30000001 | K15: 0.30000001 | L15: 0.30000001 | M15: 0.30000001 | N15: 0.30000001 | O15: 0.30000001 | P15: 0.30000001 | Q15: 0.30000001 | R15: 0.30000001 | S15: 0.30000001 | T15: 0.30000001 | U15: 0.30000001 | V15: 0.30000001 | W15: 0.30000001 | X15: 0.30000001 | Y15: 0.30000001 | Z15: 0.22500001 | AA15: 0.15000001 | AB15: 0 | AC15: 0 | AD15: 0 | AE15: 0 | AF15: 0 | AH15: 25D specifies credit by date, not CO2 emissions
B16: Geothermal | C16: 0 | D16: 0 | E16: 0.30000001 | F16: 0.30000001 | G16: 0.30000001 | H16: 0.30000001 | I16: 0.30000001 | J16: 0.30000001 | K16: 0.30000001 | L16: 0.30000001 | M16: 0.30000001 | N16: 0.30000001 | O16: 0.30000001 | P16: 0.30000001 | Q16: 0.30000001 | R16: 0.30000001 | S16: 0.30000001 | T16: 0.30000001 | U16: 0.30000001 | V16: 0.30000001 | W16: 0.30000001 | X16: 0.30000001 | Y16: 0.30000001 | Z16: 0.22500001 | AA16: 0.15000001 | AB16: 0 | AC16: 0 | AD16: 0 | AE16: 0 | AF16: 0 | AH16: 4 Year Safe Harbor
B17: Hydropower | C17: 0 | D17: 0 | E17: 0.30000001 | F17: 0.30000001 | G17: 0.30000001 | H17: 0.30000001 | I17: 0.30000001 | J17: 0.30000001 | K17: 0.30000001 | L17: 0.30000001 | M17: 0.30000001 | N17: 0.30000001 | O17: 0.30000001 | P17: 0.30000001 | Q17: 0.30000001 | R17: 0.30000001 | S17: 0.30000001 | T17: 0.30000001 | U17: 0.30000001 | V17: 0.30000001 | W17: 0.30000001 | X17: 0.30000001 | Y17: 0.30000001 | Z17: 0.22500001 | AA17: 0.15000001 | AB17: 0 | AC17: 0 | AD17: 0 | AE17: 0 | AF17: 0 | AH17: 4 Year Safe Harbor
B18: Nuclear | C18: 0 | D18: 0 | E18: 0 | F18: 0 | G18: 0.30000001 | H18: 0.30000001 | I18: 0.30000001 | J18: 0.30000001 | K18: 0.30000001 | L18: 0.30000001 | M18: 0.30000001 | N18: 0.30000001 | O18: 0.30000001 | P18: 0.30000001 | Q18: 0.30000001 | R18: 0.30000001 | S18: 0.30000001 | T18: 0.30000001 | U18: 0.30000001 | V18: 0.30000001 | W18: 0.30000001 | X18: 0.30000001 | Y18: 0.30000001 | Z18: 0.22500001 | AA18: 0.15000001 | AB18: 0 | AC18: 0 | AD18: 0 | AE18: 0 | AF18: 0 | AH18: 4 Year Safe Harbor
B19: Biopower | C19: 0 | D19: 0 | E19: 0 | F19: 0 | G19: 0 | H19: 0 | I19: 0 | J19: 0 | K19: 0 | L19: 0 | M19: 0 | N19: 0 | O19: 0 | P19: 0 | Q19: 0 | R19: 0 | S19: 0 | T19: 0 | U19: 0 | V19: 0 | W19: 0 | X19: 0 | Y19: 0 | Z19: 0 | AA19: 0 | AB19: 0 | AC19: 0 | AD19: 0 | AE19: 0 | AF19: 0
B20: Utility-Scale PV-Plus-Battery | C20: 0.30000001 | D20: 0.30000001 | E20: 0.30000001 | F20: 0.30000001 | G20: 0.30000001 | H20: 0.30000001 | I20: 0.30000001 | J20: 0.30000001 | K20: 0.30000001 | L20: 0.30000001 | M20: 0.30000001 | N20: 0.30000001 | O20: 0.30000001 | P20: 0.30000001 | Q20: 0.30000001 | R20: 0.30000001 | S20: 0.30000001 | T20: 0.30000001 | U20: 0.30000001 | V20: 0.30000001 | W20: 0.30000001 | X20: 0.30000001 | Y20: 0.30000001 | Z20: 0.22500001 | AA20: 0.15000001 | AB20: 0 | AC20: 0 | AD20: 0 | AE20: 0 | AF20: 0 | AH20: 4 Year Safe Harbor
B21: Utility-Scale Battery Storage | C21: 0.30000001 | D21: 0.30000001 | E21: 0.30000001 | F21: 0.30000001 | G21: 0.30000001 | H21: 0.30000001 | I21: 0.30000001 | J21: 0.30000001 | K21: 0.30000001 | L21: 0.30000001 | M21: 0.30000001 | N21: 0.30000001 | O21: 0.30000001 | P21: 0.30000001 | Q21: 0.30000001 | R21: 0.30000001 | S21: 0.30000001 | T21: 0.30000001 | U21: 0.30000001 | V21: 0.30000001 | W21: 0.30000001 | X21: 0.30000001 | Y21: 0.30000001 | Z21: 0.22500001 | AA21: 0.15000001 | AB21: 0 | AC21: 0 | AD21: 0 | AE21: 0 | AF21: 0 | AH21: 4 Year Safe Harbor
B22: Commercial Battery Storage | C22: 0.30000001 | D22: 0.30000001 | E22: 0.30000001 | F22: 0.30000001 | G22: 0.30000001 | H22: 0.30000001 | I22: 0.30000001 | J22: 0.30000001 | K22: 0.30000001 | L22: 0.30000001 | M22: 0.30000001 | N22: 0.30000001 | O22: 0.30000001 | P22: 0.30000001 | Q22: 0.30000001 | R22: 0.30000001 | S22: 0.30000001 | T22: 0.30000001 | U22: 0.30000001 | V22: 0.30000001 | W22: 0.30000001 | X22: 0.30000001 | Y22: 0.30000001 | Z22: 0.22500001 | AA22: 0.15000001 | AB22: 0 | AC22: 0 | AD22: 0 | AE22: 0 | AF22: 0 | AH22: 4 Year Safe Harbor
B23: Residential Battery Storage | C23: 0.30000001 | D23: 0.30000001 | E23: 0.30000001 | F23: 0.30000001 | G23: 0.30000001 | H23: 0.30000001 | I23: 0.30000001 | J23: 0.30000001 | K23: 0.30000001 | L23: 0.30000001 | M23: 0.30000001 | N23: 0.30000001 | O23: 0.26 | P23: 0.22 | Q23: 0 | R23: 0 | S23: 0 | T23: 0 | U23: 0 | V23: 0 | W23: 0 | X23: 0 | Y23: 0 | Z23: 0 | AA23: 0 | AB23: 0 | AC23: 0 | AD23: 0 | AE23: 0 | AF23: 0 | AH23: 25D specifies credit by date, not CO2 emissions
B24: Pumped Storage Hydropower | C24: 0.30000001 | D24: 0.30000001 | E24: 0.30000001 | F24: 0.30000001 | G24: 0.30000001 | H24: 0.30000001 | I24: 0.30000001 | J24: 0.30000001 | K24: 0.30000001 | L24: 0.30000001 | M24: 0.30000001 | N24: 0.30000001 | O24: 0.30000001 | P24: 0.30000001 | Q24: 0.30000001 | R24: 0.30000001 | S24: 0.30000001 | T24: 0.30000001 | U24: 0.30000001 | V24: 0.30000001 | W24: 0.30000001 | X24: 0.30000001 | Y24: 0.30000001 | Z24: 0.22500001 | AA24: 0.15000001 | AB24: 0 | AC24: 0 | AD24: 0 | AE24: 0 | AF24: 0 | AH24: 4 Year Safe Harbor
A26: PTC ($/MWh) | B26: Offshore Wind | C26: 0 | D26: 0 | E26: 0 | F26: 0 | G26: 0 | H26: 0 | I26: 0 | J26: 0 | K26: 0 | L26: 0 | M26: 0 | N26: 0 | O26: 0 | P26: 0 | Q26: 0 | R26: 0 | S26: 0 | T26: 0 | U26: 0 | V26: 0 | W26: 0 | X26: 0 | Y26: 0 | Z26: 0 | AA26: 0 | AB26: 0 | AC26: 0 | AD26: 0 | AE26: 0 | AF26: 0
B27: Land-Based Wind | C27: 19.2 | D27: 25.46 | E27: 25.46 | F27: 25.46 | G27: 25.46 | H27: 25.46 | I27: 25.46 | J27: 25.46 | K27: 25.46 | L27: 25.46 | M27: 25.46 | N27: 25.46 | O27: 25.46 | P27: 25.46 | Q27: 25.46 | R27: 25.46 | S27: 25.46 | T27: 25.46 | U27: 25.46 | V27: 25.46 | W27: 25.46 | X27: 25.46 | Y27: 25.46 | Z27: 19.095 | AA27: 12.73 | AB27: 0 | AC27: 0 | AD27: 0 | AE27: 0 | AF27: 0 | AH27: 4 Year Safe Harbor
B28: Distributed Wind | C28: 19.2 | D28: 25.46 | E28: 0 | F28: 0 | G28: 0 | H28: 0 | I28: 0 | J28: 0 | K28: 0 | L28: 0 | M28: 0 | N28: 0 | O28: 0 | P28: 0 | Q28: 0 | R28: 0 | S28: 0 | T28: 0 | U28: 0 | V28: 0 | W28: 0 | X28: 0 | Y28: 0 | Z28: 0 | AA28: 0 | AB28: 0 | AC28: 0 | AD28: 0 | AE28: 0 | AF28: 0
B29: Solar - Utility PV | C29: 0 | D29: 0 | E29: 25.46 | F29: 25.46 | G29: 25.46 | H29: 25.46 | I29: 25.46 | J29: 25.46 | K29: 25.46 | L29: 25.46 | M29: 25.46 | N29: 25.46 | O29: 25.46 | P29: 25.46 | Q29: 25.46 | R29: 25.46 | S29: 25.46 | T29: 25.46 | U29: 25.46 | V29: 25.46 | W29: 25.46 | X29: 25.46 | Y29: 25.46 | Z29: 19.095 | AA29: 12.73 | AB29: 0 | AC29: 0 | AD29: 0 | AE29: 0 | AF29: 0 | AH29: 4 Year Safe Harbor
B30: Solar - PV Dist. Comm | C30: 0 | D30: 0 | E30: 0 | F30: 0 | G30: 0 | H30: 0 | I30: 0 | J30: 0 | K30: 0 | L30: 0 | M30: 0 | N30: 0 | O30: 0 | P30: 0 | Q30: 0 | R30: 0 | S30: 0 | T30: 0 | U30: 0 | V30: 0 | W30: 0 | X30: 0 | Y30: 0 | Z30: 0 | AA30: 0 | AB30: 0 | AC30: 0 | AD30: 0 | AE30: 0 | AF30: 0
B31: Solar - PV Dist. Res | C31: 0 | D31: 0 | E31: 0 | F31: 0 | G31: 0 | H31: 0 | I31: 0 | J31: 0 | K31: 0 | L31: 0 | M31: 0 | N31: 0 | O31: 0 | P31: 0 | Q31: 0 | R31: 0 | S31: 0 | T31: 0 | U31: 0 | V31: 0 | W31: 0 | X31: 0 | Y31: 0 | Z31: 0 | AA31: 0 | AB31: 0 | AC31: 0 | AD31: 0 | AE31: 0 | AF31: 0
B32: Solar - CSP | C32: 0 | D32: 0 | E32: 0 | F32: 0 | G32: 0 | H32: 0 | I32: 0 | J32: 0 | K32: 0 | L32: 0 | M32: 0 | N32: 0 | O32: 0 | P32: 0 | Q32: 0 | R32: 0 | S32: 0 | T32: 0 | U32: 0 | V32: 0 | W32: 0 | X32: 0 | Y32: 0 | Z32: 0 | AA32: 0 | AB32: 0 | AC32: 0 | AD32: 0 | AE32: 0 | AF32: 0
B33: Geothermal | C33: 24 | D33: 24 | E33: 0 | F33: 0 | G33: 0 | H33: 0 | I33: 0 | J33: 0 | K33: 0 | L33: 0 | M33: 0 | N33: 0 | O33: 0 | P33: 0 | Q33: 0 | R33: 0 | S33: 0 | T33: 0 | U33: 0 | V33: 0 | W33: 0 | X33: 0 | Y33: 0 | Z33: 0 | AA33: 0 | AB33: 0 | AC33: 0 | AD33: 0 | AE33: 0 | AF33: 0
B34: Hydropower | C34: 6 | D34: 6 | E34: 0 | F34: 0 | G34: 0 | H34: 0 | I34: 0 | J34: 0 | K34: 0 | L34: 0 | M34: 0 | N34: 0 | O34: 0 | P34: 0 | Q34: 0 | R34: 0 | S34: 0 | T34: 0 | U34: 0 | V34: 0 | W34: 0 | X34: 0 | Y34: 0 | Z34: 0 | AA34: 0 | AB34: 0 | AC34: 0 | AD34: 0 | AE34: 0 | AF34: 0
B35: Nuclear | C35: 0 | D35: 0 | E35: 0 | F35: 0 | G35: 0 | H35: 0 | I35: 0 | J35: 0 | K35: 0 | L35: 0 | M35: 0 | N35: 0 | O35: 0 | P35: 0 | Q35: 0 | R35: 0 | S35: 0 | T35: 0 | U35: 0 | V35: 0 | W35: 0 | X35: 0 | Y35: 0 | Z35: 0 | AA35: 0 | AB35: 0 | AC35: 0 | AD35: 0 | AE35: 0 | AF35: 0
B36: Biopower | C36: 0 | D36: 0 | E36: 25.46 | F36: 25.46 | G36: 25.46 | H36: 25.46 | I36: 25.46 | J36: 25.46 | K36: 25.46 | L36: 25.46 | M36: 25.46 | N36: 25.46 | O36: 25.46 | P36: 25.46 | Q36: 25.46 | R36: 25.46 | S36: 25.46 | T36: 25.46 | U36: 25.46 | V36: 25.46 | W36: 25.46 | X36: 25.46 | Y36: 25.46 | Z36: 19.095 | AA36: 12.73 | AB36: 0 | AC36: 0 | AD36: 0 | AE36: 0 | AF36: 0 | AH36: 4 Year Safe Harbor
B37: Utility-Scale PV-Plus-Battery | C37: 0 | D37: 0 | E37: 0 | F37: 0 | G37: 0 | H37: 0 | I37: 0 | J37: 0 | K37: 0 | L37: 0 | M37: 0 | N37: 0 | O37: 0 | P37: 0 | Q37: 0 | R37: 0 | S37: 0 | T37: 0 | U37: 0 | V37: 0 | W37: 0 | X37: 0 | Y37: 0 | Z37: 0 | AA37: 0 | AB37: 0 | AC37: 0 | AD37: 0 | AE37: 0 | AF37: 0
B38: Utility-Scale Battery Storage | C38: 0 | D38: 0 | E38: 0 | F38: 0 | G38: 0 | H38: 0 | I38: 0 | J38: 0 | K38: 0 | L38: 0 | M38: 0 | N38: 0 | O38: 0 | P38: 0 | Q38: 0 | R38: 0 | S38: 0 | T38: 0 | U38: 0 | V38: 0 | W38: 0 | X38: 0 | Y38: 0 | Z38: 0 | AA38: 0 | AB38: 0 | AC38: 0 | AD38: 0 | AE38: 0 | AF38: 0
B39: Commercial Battery Storage | C39: 0 | D39: 0 | E39: 0 | F39: 0 | G39: 0 | H39: 0 | I39: 0 | J39: 0 | K39: 0 | L39: 0 | M39: 0 | N39: 0 | O39: 0 | P39: 0 | Q39: 0 | R39: 0 | S39: 0 | T39: 0 | U39: 0 | V39: 0 | W39: 0 | X39: 0 | Y39: 0 | Z39: 0 | AA39: 0 | AB39: 0 | AC39: 0 | AD39: 0 | AE39: 0 | AF39: 0
B40: Residential Battery Storage | C40: 0 | D40: 0 | E40: 0 | F40: 0 | G40: 0 | H40: 0 | I40: 0 | J40: 0 | K40: 0 | L40: 0 | M40: 0 | N40: 0 | O40: 0 | P40: 0 | Q40: 0 | R40: 0 | S40: 0 | T40: 0 | U40: 0 | V40: 0 | W40: 0 | X40: 0 | Y40: 0 | Z40: 0 | AA40: 0 | AB40: 0 | AC40: 0 | AD40: 0 | AE40: 0 | AF40: 0
B41: Pumped Storage Hydropower | C41: 0 | D41: 0 | E41: 0 | F41: 0 | G41: 0 | H41: 0 | I41: 0 | J41: 0 | K41: 0 | L41: 0 | M41: 0 | N41: 0 | O41: 0 | P41: 0 | Q41: 0 | R41: 0 | S41: 0 | T41: 0 | U41: 0 | V41: 0 | W41: 0 | X41: 0 | Y41: 0 | Z41: 0 | AA41: 0 | AB41: 0 | AC41: 0 | AD41: 0 | AE41: 0 | AF41: 0
A43: Notes and References | B43: PTC Amounts from https://www.irs.gov/pub/irs-drop/a-22-23.pdf, deflated to 2021 dollars
B44: Tax credits for storage technologies are included here for reference, but do not affect project costs since the ATB does not calculate LCOS
...

Sheet Solar - Utility PV
A1: Solar Utility PV | M1: https://atb.nrel.gov/electricity/2023/utility-scale_pv
U2: Inputs
U3: Calculated
U4: Input from other tab
B7: X | G7: Assumptions
H9: Technology | J9: Base Year: | M9: 2021
J10: All values are given in 2021 U.S. dollars, see references at the bottom of this worksheet for dollar year conversions where source dollar years don't match 2021.
J11: Utility Scale Solar Photovoltaic
J12: Representative plant is single-axis tracking with capacity of 100 MW DC
J13: Overnight Capital Cost, Capacity Factor, Fixed O&M, and Variable O&M costs represent
J14: $/kW AC, unlike the commercial and residential PV cases which are represented in $/kW DC.
J15: Capacity factors chosen here to reflect range across the continental U.S. in ReEDS.
J16: Available Capacity (GW)
J19: 118918
M20: ATB values reflect annual average capacity factor over life of plant including estimated degradation, starting at 0.7% per year, reducing to 0.2%, 0.5%, and 0.5% annual degradation by 2050 for the advanced, moderate, and conservative scenarios, respectively. Capacity factors also assume an energy yield gain of 20%, 10%, and 0% for advanced, moderate, and conservatives scenarios in 2035.
J26: Technology Classification | K26: Name | L26: Tech | M26: Resource | N26: Scale | O26: Maturity
K27: Utility PV - Class 1 | L27: Tracking PV | M27: Class1 | N27: Utility | O27: Y
K28: Utility PV - Class 2 | L28: Tracking PV | M28: Class2 | N28: Utility | O28: Y
K29: Utility PV - Class 3 | L29: Tracking PV | M29: Class3 | N29: Utility | O29: Y
K30: Utility PV - Class 4 | L30: Tracking PV | M30: Class4 | N30: Utility | O30: Y
K31: Utility PV - Class 5 | L31: Tracking PV | M31: Class5 | N31: Utility | O31: Y
K32: Utility PV - Class 6 | L32: Tracking PV | M32: Class6 | N32: Utility | O32: Y
K33: Utility PV - Class 7 | L33: Tracking PV | M33: Class7 | N33: Utility | O33: Y
K34: Utility PV - Class 8 | L34: Tracking PV | M34: Class8 | N34: Utility | O34: Y
K35: Utility PV - Class 9 | L35: Tracking PV | M35: Class9 | N35: Utility | O35: Y
K36: Utility PV - Class 10 | L36: Tracking PV | M36: Class10 | N36: Utility | O36: Y
H38: Finance | J38: Financial Assumptions:
J39: Capital Recovery Period (Years) | O39: 20 | Q39: Financial Case | S39: Market
J40: Depreciation Period | O40: 5 | Q40: Capital Recovery Period | S40: 20
J41: Equity Premium During Construction | O41: 0.02
J42: Construction Duration yrs | O42: 1
J43: Year | K43: Capital | L43: Percent of Leverage During Construction | M43: Percent of Equity During Construction
J44: Index | K44: Fraction
J47: 0 | K47: 1 | L47: 0.8 | M47: 0.2
J48: 1 | K48: 0 | L48: 0.8 | M48: 0.2
J49: 2 | K49: 0 | L49: 0.8 | M49: 0.2
M51: 2021 | N51: 2022 | O51: 2023 | P51: 2024 | Q51: 2025 | R51: 2026 | S51: 2027 | T51: 2028 | U51: 2029 | V51: 2030 | W51: 2031 | X51: 2032 | Y51: 2033 | Z51: 2034 | AA51: 2035 | AB51: 2036 | AC51: 2037 | AD51: 2038 | AE51: 2039 | AF51: 2040 | AG51: 2041 | AH51: 2042 | AI51: 2043 | AJ51: 2044 | AK51: 2045 | AL51: 2046 | AM51: 2047 | AN51: 2048 | AO51: 2049 | AP51: 2050
J52: Assumptions | K52: Inflation Rate | L52: * | M52: 0.0279 | N52: 0.0272 | O52: 0.0253 | P52: 0.025 | Q52: 0.025 | R52: 0.025 | S52: 0.025 | T52: 0.025 | U52: 0.025 | V52: 0.025 | W52: 0.025 | X52: 0.025 | Y52: 0.025 | Z52: 0.025 | AA52: 0.025 | AB52: 0.025 | AC52: 0.025 | AD52: 0.025 | AE52: 0.025 | AF52: 0.025 | AG52: 0.025 | AH52: 0.025 | AI52: 0.025 | AJ52: 0.025 | AK52: 0.025 | AL52: 0.025 | AM52: 0.025 | AN52: 0.025 | AO52: 0.025 | AP52: 0.025
K53: Interest Rate Nominal | L53: Advanced | M53: 0.07 | N53: 0.07 | O53: 0.07 | P53: 0.07 | Q53: 0.07 | R53: 0.07 | S53: 0.07 | T53: 0.07 | U53: 0.07 | V53: 0.07 | W53: 0.07 | X53: 0.07 | Y53: 0.07 | Z53: 0.07 | AA53: 0.07 | AB53: 0.07 | AC53: 0.07 | AD53: 0.07 | AE53: 0.07 | AF53: 0.07 | AG53: 0.07 | AH53: 0.07 | AI53: 0.07 | AJ53: 0.07 | AK53: 0.07 | AL53: 0.07 | AM53: 0.07 | AN53: 0.07 | AO53: 0.07 | AP53: 0.07
K54: Interest Rate Nominal | L54: Moderate | M54: 0.07 | N54: 0.07 | O54: 0.07 | P54: 0.07 | Q54: 0.07 | R54: 0.07 | S54: 0.07 | T54: 0.07 | U54: 0.07 | V54: 0.07 | W54: 0.07 | X54: 0.07 | Y54: 0.07 | Z54: 0.07 | AA54: 0.07 | AB54: 0.07 | AC54: 0.07 | AD54: 0.07 | AE54: 0.07 | AF54: 0.07 | AG54: 0.07 | AH54: 0.07 | AI54: 0.07 | AJ54: 0.07 | AK54: 0.07 | AL54: 0.07 | AM54: 0.07 | AN54: 0.07 | AO54: 0.07 | AP54: 0.07
...

Sheet Land-Based Wind
A1: Land-Based Wind | M1: https://atb.nrel.gov/electricity/2023/land-based_wind
U2: Inputs
U3: Calculated
U4: Input from other tab
B7: X | G7: Assumptions
H9: Technology | J9: Base Year: | M9: 2021
J10: All values are given in 2021 U.S. dollars, see references at the bottom of this worksheet for dollar year conversions where source dollar years don't match 2021.
J11: Land-Based Wind Classes
J13: Technology Classification | K13: Name | L13: Tech | M13: Resource | N13: Scale | O13: Maturity | P13: Wind Classes | Q13: Wind Speed Range (m/s) | R13: Weighted Average Wind Speed (m/s)
K14: Land-Based Wind - Class 1 - Technology 1 | L14: Wind Turbine Technology 1 | M14: Class1 | N14: Utility | O14: Y | P14: Class1 | Q14: > 9.0 | R14: 9.5
K15: Land-Based Wind - Class 2 - Technology 1 | L15: Wind Turbine Technology 1 | M15: Class2 | N15: Utility | O15: Y | P15: Class2 | Q15: 8.8 - 9.0 | R15: 8.9
K16: Land-Based Wind - Class 3 - Technology 1 | L16: Wind Turbine Technology 1 | M16: Class3 | N16: Utility | O16: Y | P16: Class3 | Q16: 8.6 - 8.8 | R16: 8.7
K17: Land-Based Wind - Class 4 - Technology 1 | L17: Wind Turbine Technology 1 | M17: Class4 | N17: Utility | O17: Y | P17: Class4 | Q17: 8.4 - 8.6 | R17: 8.5
K18: Land-Based Wind - Class 5 - Technology 1 | L18: Wind Turbine Technology 1 | M18: Class5 | N18: Utility | O18: Y | P18: Class5 | Q18: 8.1 - 8.4 | R18: 8.2
K19: Land-Based Wind - Class 6 - Technology 1 | L19: Wind Turbine Technology 1 | M19: Class6 | N19: Utility | O19: Y | P19: Class6 | Q19: 7.6 - 8.1 | R19: 7.8
K20: Land-Based Wind - Class 7 - Technology 1 | L20: Wind Turbine Technology 1 | M20: Class7 | N20: Utility | O20: Y | P20: Class7 | Q20: 7.1 - 7.6 | R20: 7.4
K21: Land-Based Wind - Class 8 - Technology 2 | L21: Wind Turbine Technology 2 | M21: Class8 | N21: Utility | O21: Y | P21: Class8 | Q21: 6.5 - 7.1 | R21: 6.8
K22: Land-Based Wind - Class 9 - Technology 3 | L22: Wind Turbine Technology 3 | M22: Class9 | N22: Utility | O22: Y | P22: Class9 | Q22: 5.9 - 6.5 | R22: 6.2
K23: Land-Based Wind - Class 10 - Technology 4 | L23: Wind Turbine Technology 4 | M23: Class10 | N23: Utility | O23: Y | P23: Class10 | Q23: 1.7 - 5.9 | R23: 5.2
P25: Wind speeds presented in table are assumed to be 110 meters above the surface
Q27: Financial Case | S27: Market
H28: Finance | J28: Financial Assumptions: | Q28: Capital Recovery Period | S28: 20
J29: Capital Recovery Period (Years) | O29: 20
J30: Depreciation Period | O30: 5
J31: Equity Premium During Construction | O31: 0.02
J32: Construction Duration yrs | O32: 3
J33: Year | K33: Capital | L33: Percent of Leverage During Construction | M33: Percent of Equity During Construction
J34: Index | K34: Fraction
J35: 0 | K35: 0.8 | L35: 0.8 | M35: 0.2
J36: 1 | K36: 0.1 | L36: 0.8 | M36: 0.2
J37: 2 | K37: 0.1 | L37: 0.8 | M37: 0.2
M40: 2021 | N40: 2022 | O40: 2023 | P40: 2024 | Q40: 2025 | R40: 2026 | S40: 2027 | T40: 2028 | U40: 2029 | V40: 2030 | W40: 2031 | X40: 2032 | Y40: 2033 | Z40: 2034 | AA40: 2035 | AB40: 2036 | AC40: 2037 | AD40: 2038 | AE40: 2039 | AF40: 2040 | AG40: 2041 | AH40: 2042 | AI40: 2043 | AJ40: 2044 | AK40: 2045 | AL40: 2046 | AM40: 2047 | AN40: 2048 | AO40: 2049 | AP40: 2050
J41: Assumptions | K41: Inflation Rate | L41: * | M41: 0.0279 | N41: 0.0272 | O41: 0.0253 | P41: 0.025 | Q41: 0.025 | R41: 0.025 | S41: 0.025 | T41: 0.025 | U41: 0.025 | V41: 0.025 | W41: 0.025 | X41: 0.025 | Y41: 0.025 | Z41: 0.025 | AA41: 0.025 | AB41: 0.025 | AC41: 0.025 | AD41: 0.025 | AE41: 0.025 | AF41: 0.025 | AG41: 0.025 | AH41: 0.025 | AI41: 0.025 | AJ41: 0.025 | AK41: 0.025 | AL41: 0.025 | AM41: 0.025 | AN41: 0.025 | AO41: 0.025 | AP41: 0.025
K42: Interest Rate Nominal | L42: Advanced | M42: 0.07 | N42: 0.07 | O42: 0.07 | P42: 0.07 | Q42: 0.07 | R42: 0.07 | S42: 0.07 | T42: 0.07 | U42: 0.07 | V42: 0.07 | W42: 0.07 | X42: 0.07 | Y42: 0.07 | Z42: 0.07 | AA42: 0.07 | AB42: 0.07 | AC42: 0.07 | AD42: 0.07 | AE42: 0.07 | AF42: 0.07 | AG42: 0.07 | AH42: 0.07 | AI42: 0.07 | AJ42: 0.07 | AK42: 0.07 | AL42: 0.07 | AM42: 0.07 | AN42: 0.07 | AO42: 0.07 | AP42: 0.07
K43: Interest Rate Nominal | L43: Moderate | M43: 0.07 | N43: 0.07 | O43: 0.07 | P43: 0.07 | Q43: 0.07 | R43: 0.07 | S43: 0.07 | T43: 0.07 | U43: 0.07 | V43: 0.07 | W43: 0.07 | X43: 0.07 | Y43: 0.07 | Z43: 0.07 | AA43: 0.07 | AB43: 0.07 | AC43: 0.07 | AD43: 0.07 | AE43: 0.07 | AF43: 0.07 | AG43: 0.07 | AH43: 0.07 | AI43: 0.07 | AJ43: 0.07 | AK43: 0.07 | AL43: 0.07 | AM43: 0.07 | AN43: 0.07 | AO43: 0.07 | AP43: 0.07
K44: Interest Rate Nominal | L44: Conservative | M44: 0.07 | N44: 0.07 | O44: 0.07 | P44: 0.07 | Q44: 0.07 | R44: 0.07 | S44: 0.07 | T44: 0.07 | U44: 0.07 | V44: 0.07 | W44: 0.07 | X44: 0.07 | Y44: 0.07 | Z44: 0.07 | AA44: 0.07 | AB44: 0.07 | AC44: 0.07 | AD44: 0.07 | AE44: 0.07 | AF44: 0.07 | AG44: 0.07 | AH44: 0.07 | AI44: 0.07 | AJ44: 0.07 | AK44: 0.07 | AL44: 0.07 | AM44: 0.07 | AN44: 0.07 | AO44: 0.07 | AP44: 0.07
K45: Calculated Interest Rate Real | L45: Advanced | M45: 0.040957292 | N45: 0.041666667 | O45: 0.043596996 | P45: 0.043902439 | Q45: 0.043902439 | R45: 0.043902439 | S45: 0.043902439 | T45: 0.043902439 | U45: 0.043902439 | V45: 0.043902439 | W45: 0.043902439 | X45: 0.043902439 | Y45: 0.043902439 | Z45: 0.043902439 | AA45: 0.043902439 | AB45: 0.043902439 | AC45: 0.043902439 | AD45: 0.043902439 | AE45: 0.043902439 | AF45: 0.043902439 | AG45: 0.043902439 | AH45: 0.043902439 | AI45: 0.043902439 | AJ45: 0.043902439 | AK45: 0.043902439 | AL45: 0.043902439 | AM45: 0.043902439 | AN45: 0.043902439 | AO45: 0.043902439 | AP45: 0.043902439
K46: Calculated Interest Rate Real | L46: Moderate | M46: 0.040957292 | N46: 0.041666667 | O46: 0.043596996 | P46: 0.043902439 | Q46: 0.043902439 | R46: 0.043902439 | S46: 0.043902439 | T46: 0.043902439 | U46: 0.043902439 | V46: 0.043902439 | W46: 0.043902439 | X46: 0.043902439 | Y46: 0.043902439 | Z46: 0.043902439 | AA46: 0.043902439 | AB46: 0.043902439 | AC46: 0.043902439 | AD46: 0.043902439 | AE46: 0.043902439 | AF46: 0.043902439 | AG46: 0.043902439 | AH46: 0.043902439 | AI46: 0.043902439 | AJ46: 0.043902439 | AK46: 0.043902439 | AL46: 0.043902439 | AM46: 0.043902439 | AN46: 0.043902439 | AO46: 0.043902439 | AP46: 0.043902439
K47: Calculated Interest Rate Real | L47: Conservative | M47: 0.040957292 | N47: 0.041666667 | O47: 0.043596996 | P47: 0.043902439 | Q47: 0.043902439 | R47: 0.043902439 | S47: 0.043902439 | T47: 0.043902439 | U47: 0.043902439 | V47: 0.043902439 | W47: 0.043902439 | X47: 0.043902439 | Y47: 0.043902439 | Z47: 0.043902439 | AA47: 0.043902439 | AB47: 0.043902439 | AC47: 0.043902439 | AD47: 0.043902439 | AE47: 0.043902439 | AF47: 0.043902439 | AG47: 0.043902439 | AH47: 0.043902439 | AI47: 0.043902439 | AJ47: 0.043902439 | AK47: 0.043902439 | AL47: 0.043902439 | AM47: 0.043902439 | AN47: 0.043902439 | AO47: 0.043902439 | AP47: 0.043902439
K48: Interest During Construction - Nominal | L48: * | M48: 0.065 | N48: 0.065 | O48: 0.065 | P48: 0.065 | Q48: 0.065 | R48: 0.065 | S48: 0.065 | T48: 0.065 | U48: 0.065 | V48: 0.065 | W48: 0.065 | X48: 0.065 | Y48: 0.065 | Z48: 0.065 | AA48: 0.065 | AB48: 0.065 | AC48: 0.065 | AD48: 0.065 | AE48: 0.065 | AF48: 0.065 | AG48: 0.065 | AH48: 0.065 | AI48: 0.065 | AJ48: 0.065 | AK48: 0.065 | AL48: 0.065 | AM48: 0.065 | AN48: 0.065 | AO48: 0.065 | AP48: 0.065
...

Sheet Subsidies Paid
A1: Model Energy Source | B1: Subsidy Name | C1: Source | D1: Fuel/Electricity | E1: Unit | F1: 2013 | G1: 2014 | H1: 2015 | I1: 2016 | J1: 2017 | K1: 2018 | L1: 2019 | M1: 2020 | N1: 2021 | O1: 2022 | P1: 2023 | Q1: 2024 | R1: 2025 | S1: 2026 | T1: 2027 | U1: 2028 | V1: 2029 | W1: 2030
A2: biomass | B2: Section 45: PTC | C2: http://programs.dsireusa.org/system/program/detail/734 | D2: Electricity | E2: $/kWh (2014) | F2: 0.011 | G2: 0.012 | H2: 0.012 | I2: 0.012 | J2: 0 | K2: 0 | L2: 0 | M2: 0 | N2: 0 | O2: 0 | P2: 0 | Q2: 0 | R2: 0 | S2: 0 | T2: 0 | U2: 0 | V2: 0 | W2: 0 | X2: <expires in 2016
A3: coal | B3: IRC Section 48A Tax Credit for IGCC and ACBGT | C3: https://www.law.cornell.edu/uscode/text/26/48A | D3: Electricity | E3: % of investments costs | F3: 0 | G3: 0 | H3: 0 | I3: 0 | J3: 0 | K3: 0 | L3: 0 | M3: 0 | N3: 0 | O3: 0 | P3: 0 | Q3: 0 | R3: 0 | S3: 0 | T3: 0 | U3: 0 | V3: 0 | W3: 0 | X3: <We assign this zero because no unit in our model can meet the heat rate requirements to be elgible and we assume no new IGCC units
A4: coal | B4: Amortization of air pollution control facilities | C4: https://www.jct.gov/publications.html?func=download&id=4663&chk=4663&no_html=1 | D4: Electricity | E4: Billion $ | F4: n/a | G4: 0.4 | H4: 0.4 | I4: 0.4 | J4: 0.3 | K4: 0.3 | L4: n/a | M4: n/a | N4: n/a | O4: n/a | P4: n/a | Q4: n/a | R4: n/a | S4: n/a | T4: n/a | U4: n/a | V4: n/a | W4: n/a | X4: <use same methodology as before
A5: hydro | B5: Section 45: PTC | C5: http://programs.dsireusa.org/system/program/detail/734 | D5: Electricity | E5: $/kWh (2014) | F5: 0.011 | G5: 0.012 | H5: 0.012 | I5: 0.012 | J5: 0 | K5: 0 | L5: 0 | M5: 0 | N5: 0 | O5: 0 | P5: 0 | Q5: 0 | R5: 0 | S5: 0 | T5: 0 | U5: 0 | V5: 0 | W5: 0 | X5: <expires in 2016
A6: nuclear | B6: Special rules for nuclear decommissioning costs | C6: https://www.jct.gov/publications.html?func=download&id=4663&chk=4663&no_html=1 | D6: Electricity | E6: Billion $ | F6: 0 | G6: 0.2 | H6: 0.2 | I6: 0.2 | J6: 0.3 | K6: 0.3 | L6: 0 | M6: 0 | N6: 0 | O6: 0 | P6: 0 | Q6: 0 | R6: 0 | S6: 0 | T6: 0 | U6: 0 | V6: 0 | W6: 0 | X6: <use same methodology as before
A7: nuclear | B7: Civil Nuclear Credit Program | C7: https://www.energy.gov/ne/civil-nuclear-credit-program | D7: Electricity | E7: Billion $ | F7: 0 | G7: 0 | H7: 0 | I7: 0 | J7: 0 | K7: 0 | L7: 0 | M7: 0 | N7: 0 | O7: =6/5 -> 1.2 | P7: =6/5 -> 1.2 | Q7: =6/5 -> 1.2 | R7: =6/5 -> 1.2 | S7: =6/5 -> 1.2 | T7: 0 | U7: 0 | V7: 0 | W7: 0 | X7: <we use the assumption in the 2022 AEO, which is that funds are used between 2022-2026
A8: solar pv, solar thermal | B8: Section 48: ITC | C8: https://www.greentechmedia.com/articles/read/solar-and-wind-tax-credit-extensions-energy-rd-package-in-spending-bill-before-congress#:~:text=According%20to%20a%20summary%20shared,would%20have%20under%20existing%20law. | D8: Electricity | E8: % of investment costs | F8: 0.3 | G8: 0.3 | H8: 0.3 | I8: 0.3 | J8: 0.3 | K8: 0.3 | L8: 0.3 | M8: 0.26 | N8: 0.26 | O8: 0.26 | P8: 0.22 | Q8: 0.1 | R8: 0.1 | S8: 0.1 | T8: 0.1 | U8: 0.1 | V8: 0.1 | W8: 0.1 | X8: <extended with ramp down and no phase out
A9: offshore wind | B9: Section 48: ITC | C9: https://www.greentechmedia.com/articles/read/solar-and-wind-tax-credit-extensions-energy-rd-package-in-spending-bill-before-congress#:~:text=According%20to%20a%20summary%20shared,would%20have%20under%20existing%20law. | D9: Electricity | E9: % of investment costs | F9: 0 | G9: 0 | H9: 0 | I9: 0 | J9: 0 | K9: 0 | L9: 0 | M9: 0 | N9: 0.3 | O9: 0.3 | P9: 0.3 | Q9: 0.3 | R9: 0.3 | S9: 0 | T9: 0 | U9: 0 | V9: 0 | W9: 0 | X9: <assumed offshore wind will use the ITC starting in 2021 based on a lower calculated LCOE
A10: onshore wind | B10: Section 45: PTC | C10: https://fas.org/sgp/crs/misc/R43453.pdf; https://www.greentechmedia.com/articles/read/solar-and-wind-tax-credit-extensions-energy-rd-package-in-spending-bill-before-congress#:~:text=According%20to%20a%20summary%20shared,would%20have%20under%20existing%20law. | D10: Electricity | E10: $/kWh (2019) | F10: 0.023 | G10: 0.023 | H10: 0.023 | I10: 0.023 | J10: =I10*0.8 -> 0.0184 | K10: =I10*0.6 -> 0.0138 | L10: =0.025*0.4 -> 0.01 | M10: =0.025*0.6 -> 0.015 | N10: =0.025*0.6 -> 0.015 | O10: 0 | P10: 0 | Q10: 0 | R10: 0 | S10: 0 | T10: 0 | U10: 0 | V10: 0 | W10: 0 | X10: <extending with ramp down, expiring in 2021
A11: offshore wind | B11: Section 45: PTC | C11: https://fas.org/sgp/crs/misc/R43453.pdf; https://www.greentechmedia.com/articles/read/solar-and-wind-tax-credit-extensions-energy-rd-package-in-spending-bill-before-congress#:~:text=According%20to%20a%20summary%20shared,would%20have%20under%20existing%20law. | D11: Electricity | E11: $/kWh (2019) | F11: =F10 -> 0.023 | G11: =G10 -> 0.023 | H11: =H10 -> 0.023 | I11: =I10 -> 0.023 | J11: =J10 -> 0.0184 | K11: =K10 -> 0.0138 | L11: =L10 -> 0.01 | M11: =M10 -> 0.015 | N11: 0 | O11: 0 | P11: 0 | Q11: 0 | R11: 0 | S11: 0 | T11: 0 | U11: 0 | V11: 0 | W11: 0 | X11: <extended through 2020, but assumes offshore wind will use the ITC starting in 2021 based on a lower calculated LCOE
A12: geothermal | B12: Section 45: PTC | C12: http://programs.dsireusa.org/system/program/detail/734 | D12: Electricity | E12: $/kWh (2019) | F12: =0.023 -> 0.023 | G12: =0.023 -> 0.023 | H12: =0.023 -> 0.023 | I12: =0.023 -> 0.023 | J12: 0 | K12: 0 | L12: 0 | M12: 0 | N12: 0 | O12: 0 | P12: 0 | Q12: 0 | R12: 0 | S12: 0 | T12: 0 | U12: 0 | V12: 0 | W12: 0 | X12: <expires in 2016
A13: geothermal | B13: Section 48: ITC | C13: http://programs.dsireusa.org/system/program/detail/658 | D13: Electricity | E13: % of investment costs | F13: 0.1 | G13: 0.1 | H13: 0.1 | I13: 0.1 | J13: 0.1 | K13: 0.1 | L13: 0.1 | M13: 0.1 | N13: 0.1 | O13: 0.1 | P13: 0.1 | Q13: 0.1 | R13: 0.1 | S13: 0.1 | T13: 0.1 | U13: 0.1 | V13: 0.1 | W13: 0.1 | X13: <no expiration; can be taken in lieu of PTC
A14: coal | B14: Capital gains treatment for royalties of coal | C14: http://www.treasury.gov/open/Documents/USA%20FFSR%20progress%20report%20to%20G20%202014%20Final.pdf | D14: Fuel | E14: $ | F14: n/a | G14: n/a | H14: 53000000 | I14: n/a | J14: n/a | K14: n/a | L14: n/a | M14: n/a | N14: n/a | O14: n/a | P14: n/a | Q14: n/a | R14: n/a | S14: n/a | T14: n/a | U14: n/a | V14: n/a | W14: n/a | X14: <need to estimate based on this
A15: coal | B15: Expensing of exploration and development costs for hard mineral fuels | C15: http://www.treasury.gov/open/Documents/USA%20FFSR%20progress%20report%20to%20G20%202014%20Final.pdf; https://www.jct.gov/publications.html?func=download&id=4663&chk=4663&no_html=1 | D15: Fuel | E15: Billion $ | F15: n/a | G15: 0.1 | H15: 0.1 | I15: 0.1 | J15: 0.1 | K15: 0.1 | L15: n/a | M15: n/a | N15: n/a | O15: n/a | P15: n/a | Q15: n/a | R15: n/a | S15: n/a | T15: n/a | U15: n/a | V15: n/a | W15: n/a
A16: petroleum gasoline, petroleum diesel, jet fuel | B16: Expensing of exploration and development costs for hard mineral fuels | C16: http://www.treasury.gov/open/Documents/USA%20FFSR%20progress%20report%20to%20G20%202014%20Final.pdf; https://www.jct.gov/publications.html?func=download&id=4663&chk=4663&no_html=1 | D16: Fuel | E16: Billion $ | F16: n/a | G16: 1.1 | H16: 1.1 | I16: 1.2 | J16: 1.3 | K16: 1.3 | L16: n/a | M16: n/a | N16: n/a | O16: n/a | P16: n/a | Q16: n/a | R16: n/a | S16: n/a | T16: n/a | U16: n/a | V16: n/a | W16: n/a | X16: <use same methodology as before
A17: natural gas, petroleum gasoline, petroleum diesel, jet fuel | B17: Excess of percentage over cost depletion, fuels: Oil and gas | C17: http://www.treasury.gov/open/Documents/USA%20FFSR%20progress%20report%20to%20G20%202014%20Final.pdf | D17: Fuel | E17: Billion $ | F17: n/a | G17: 1.02 | H17: 1.52 | I17: 1.62 | J17: 1.62 | K17: 1.62 | L17: n/a | M17: n/a | N17: n/a | O17: n/a | P17: n/a | Q17: n/a | R17: n/a | S17: n/a | T17: n/a | U17: n/a | V17: n/a | W17: n/a | X17: <use same methodology as before
A18: natural gas, petroleum gasoline, petroleum diesel, jet fuel | B18: Amortization of geological and geophysical expenditures associated with oil and gas exploration | C18: http://www.treasury.gov/open/Documents/USA%20FFSR%20progress%20report%20to%20G20%202014%20Final.pdf | D18: Fuel | E18: Billion $ | F18: n/a | G18: 0.14 | H18: 0.14 | I18: 0.14 | J18: 0.14 | K18: 0.14 | L18: n/a | M18: n/a | N18: n/a | O18: n/a | P18: n/a | Q18: n/a | R18: n/a | S18: n/a | T18: n/a | U18: n/a | V18: n/a | W18: n/a | X18: <use same methodology as before
A19: natural gas, petroleum gasoline, petroleum diesel, jet fuel | B19: Exceptions for publicly traded partnership with qualified income derived from certain energy-related activities | C19: https://www.fas.org/sgp/crs/misc/R41769.pdf | D19: Fuel | E19: Billion $ | F19: n/a | G19: 1.1 | H19: 1.1 | I19: 1.2 | J19: 1.2 | K19: 1.2 | L19: n/a | M19: n/a | N19: n/a | O19: n/a | P19: n/a | Q19: n/a | R19: n/a | S19: n/a | T19: n/a | U19: n/a | V19: n/a | W19: n/a | X19: <use same methodology as before
A20: petroleum gasoline, petroleum diesel, jet fuel | B20: Deduction for tertiary injectants | C20: http://www.treasury.gov/open/Documents/USA%20FFSR%20progress%20report%20to%20G20%202014%20Final.pdf | D20: Fuel | E20: $ | F20: n/a | G20: n/a | H20: 10000000 | I20: n/a | J20: n/a | K20: n/a | L20: n/a | M20: n/a | N20: n/a | O20: n/a | P20: n/a | Q20: n/a | R20: n/a | S20: n/a | T20: n/a | U20: n/a | V20: n/a | W20: n/a | X20: <need to estimate based on this

Sheet AEO 2022 Table 1
B1: ref2022.d011222a | C1: 2021 | D1: 2022 | E1: 2023 | F1: 2024 | G1: 2025 | H1: 2026 | I1: 2027 | J1: 2028 | K1: 2029 | L1: 2030 | M1: 2031 | N1: 2032 | O1: 2033 | P1: 2034 | Q1: 2035 | R1: 2036 | S1: 2037 | T1: 2038 | U1: 2039 | V1: 2040 | W1: 2041 | X1: 2042 | Y1: 2043 | Z1: 2044 | AA1: 2045 | AB1: 2046 | AC1: 2047 | AD1: 2048 | AE1: 2049 | AF1: 2050
C3: Report | D3: Annual Energy Outlook 2022
C4: Scenario | D4: ref2022 | G4: Reference
C5: Datekey | D5: d011222a
C6: Release Date | E6: March 2022
A10: SUP000 | B10: 1. Total Energy Supply, Disposition, and Price Summary | AG10: Average
B11: (quadrillion Btu, unless otherwise noted) | AG11: Annual
AG12: Change
B13: Supply, Disposition, and Prices | C13: 2021 | D13: 2022 | E13: 2023 | F13: 2024 | G13: 2025 | H13: 2026 | I13: 2027 | J13: 2028 | K13: 2029 | L13: 2030 | M13: 2031 | N13: 2032 | O13: 2033 | P13: 2034 | Q13: 2035 | R13: 2036 | S13: 2037 | T13: 2038 | U13: 2039 | V13: 2040 | W13: 2041 | X13: 2042 | Y13: 2043 | Z13: 2044 | AA13: 2045 | AB13: 2046 | AC13: 2047 | AD13: 2048 | AE13: 2049 | AF13: 2050 | AG13: 2021–2050
B15: Production
A16: SUP000:ba_CrudeOilLease | B16: Crude Oil and Lease Condensate | C16: 23.173487 | D16: 24.717472 | E16: 25.494104 | F16: 26.154642 | G16: 27.054277 | H16: 27.435596 | I16: 27.342155 | J16: 27.686852 | K16: 27.633852 | L16: 27.555265 | M16: 27.280258 | N16: 27.009712 | O16: 27.003248 | P16: 26.646475 | Q16: 26.47743 | R16: 26.305445 | S16: 26.016472 | T16: 25.819599 | U16: 25.821352 | V16: 25.902487 | W16: 25.722721 | X16: 25.635948 | Y16: 25.63641 | Z16: 25.47831 | AA16: 25.779816 | AB16: 25.951448 | AC16: 25.981897 | AD16: 25.859144 | AE16: 25.553583 | AF16: 26.234585 | AG16: 0.004287
A17: SUP000:ba_NaturalGasPla | B17: Natural Gas Plant Liquids | C17: 7.006215 | D17: 7.552815 | E17: 7.883783 | F17: 8.023396 | G17: 8.163991 | H17: 8.108202 | I17: 8.041482 | J17: 8.029618 | K17: 8.082181 | L17: 8.155948 | M17: 8.184832 | N17: 8.259987 | O17: 8.235239 | P17: 8.250072 | Q17: 8.27844 | R17: 8.210117 | S17: 8.17472 | T17: 8.172275 | U17: 8.222511 | V17: 8.267702 | W17: 8.281703 | X17: 8.384741 | Y17: 8.490253 | Z17: 8.476263 | AA17: 8.579662 | AB17: 8.612893 | AC17: 8.634458 | AD17: 8.644827 | AE17: 8.650251 | AF17: 8.701235 | AG17: 0.007499
A18: SUP000:ba_DryNaturalGas | B18: Dry Natural Gas | C18: 35.682777 | D18: 36.629646 | E18: 36.922058 | F18: 37.131554 | G18: 37.233967 | H18: 37.210548 | I18: 37.134987 | J18: 37.74691 | K18: 38.012238 | L18: 38.079895 | M18: 38.334229 | N18: 38.609394 | O18: 38.861305 | P18: 38.688675 | Q18: 38.547447 | R18: 38.495739 | S18: 38.611137 | T18: 38.832619 | U18: 39.095234 | V18: 39.377579 | W18: 39.502232 | X18: 39.69487 | Y18: 40.037334 | Z18: 40.361305 | AA18: 40.596077 | AB18: 40.848938 | AC18: 41.134644 | AD18: 41.335979 | AE18: 41.513866 | AF18: 41.894924 | AG18: 0.00555
A19: SUP000:ba_Coal | B19: Coal 1/ | C19: 13.089978 | D19: 12.741252 | E19: 12.812081 | F19: 11.346849 | G19: 10.919338 | H19: 10.890395 | I19: 10.594276 | J19: 10.517385 | K19: 10.477952 | L19: 10.320335 | M19: 10.278054 | N19: 10.186623 | O19: 10.161192 | P19: 9.840708 | Q19: 9.568752 | R19: 9.414873 | S19: 9.287329 | T19: 9.301336 | U19: 9.227633 | V19: 9.145965 | W19: 9.122682 | X19: 9.086012 | Y19: 8.961373 | Z19: 8.89466 | AA19: 8.785145 | AB19: 8.720604 | AC19: 8.623024 | AD19: 8.544412 | AE19: 8.507181 | AF19: 8.572097 | AG19: -0.014492
A20: SUP000:ba_NuclearPower | B20: Nuclear / Uranium 2/ | C20: 8.12115 | D20: 8.183111 | E20: 8.202579 | F20: 8.239058 | G20: 8.163899 | H20: 8.075755 | I20: 7.930267 | J20: 7.368946 | K20: 7.299504 | L20: 7.307006 | M20: 7.318423 | N20: 7.326343 | O20: 6.808416 | P20: 6.815667 | Q20: 6.747447 | R20: 6.758354 | S20: 6.760554 | T20: 6.762659 | U20: 6.762759 | V20: 6.766273 | W20: 6.77936 | X20: 6.788805 | Y20: 6.797936 | Z20: 6.805902 | AA20: 6.814445 | AB20: 6.818903 | AC20: 6.823349 | AD20: 6.826119 | AE20: 6.829472 | AF20: 6.834313 | AG20: -0.005931
A21: SUP000:ba_Hydropower | B21: Conventional Hydroelectric Power | C21: 2.288529 | D21: 2.39653 | E21: 2.520376 | F21: 2.607582 | G21: 2.562303 | H21: 2.533515 | I21: 2.5148 | J21: 2.494481 | K21: 2.48263 | L21: 2.471396 | M21: 2.456771 | N21: 2.450083 | O21: 2.436512 | P21: 2.4271 | Q21: 2.410605 | R21: 2.397023 | S21: 2.392663 | T21: 2.381657 | U21: 2.376802 | V21: 2.37014 | W21: 2.362096 | X21: 2.354189 | Y21: 2.3427 | Z21: 2.33699 | AA21: 2.32513 | AB21: 2.318443 | AC21: 2.309026 | AD21: 2.304834 | AE21: 2.295233 | AF21: 2.274688 | AG21: -0.000209
A22: SUP000:ba_Biomass | B22: Biomass 3/ | C22: 4.70119 | D22: 4.833665 | E22: 4.736951 | F22: 4.731843 | G22: 4.751482 | H22: 4.740038 | I22: 4.728146 | J22: 4.706775 | K22: 4.708263 | L22: 4.6997 | M22: 4.688527 | N22: 4.681827 | O22: 4.666749 | P22: 4.654086 | Q22: 4.648972 | R22: 4.641438 | S22: 4.63418 | T22: 4.638316 | U22: 4.647457 | V22: 4.683486 | W22: 4.705445 | X22: 4.722157 | Y22: 4.748343 | Z22: 4.791994 | AA22: 4.814004 | AB22: 4.843565 | AC22: 4.876688 | AD22: 4.909999 | AE22: 4.942437 | AF22: 4.984637 | AG22: 0.002021
A23: SUP000:ba_RenewableEner | B23: Other Renewable Energy 4/ | C23: 4.839005 | D23: 5.544484 | E23: 6.085557 | F23: 6.989227 | G23: 7.561359 | H23: 7.846316 | I23: 8.347466 | J23: 8.5777 | K23: 8.787159 | L23: 9.155986 | M23: 9.41178 | N23: 9.649215 | O23: 9.910384 | P23: 10.464489 | Q23: 11.17978 | R23: 11.560812 | S23: 11.709242 | T23: 11.735645 | U23: 11.787336 | V23: 11.864063 | W23: 11.965893 | X23: 12.084974 | Y23: 12.202391 | Z23: 12.369851 | AA23: 12.586577 | AB23: 12.70438 | AC23: 12.871214 | AD23: 13.03612 | AE23: 13.182046 | AF23: 13.273847 | AG23: 0.035408
A24: SUP000:ba_Other | B24: Other 5/ | C24: 2.133576 | D24: 1.012973 | E24: 0.879855 | F24: 0.894946 | G24: 0.774271 | H24: 0.88321 | I24: 0.8699 | J24: 0.796129 | K24: 0.770551 | L24: 0.770231 | M24: 0.768565 | N24: 0.632673 | O24: 0.631935 | P24: 0.640565 | Q24: 0.637551 | R24: 0.647367 | S24: 0.651814 | T24: 0.653633 | U24: 0.651491 | V24: 0.642037 | W24: 0.639621 | X24: 0.634056 | Y24: 0.627797 | Z24: 0.632698 | AA24: 0.626717 | AB24: 0.618566 | AC24: 0.61455 | AD24: 0.621078 | AE24: 0.628376 | AF24: 0.623335 | AG24: -0.041542
A25: SUP000:ba_Total | B25: Total | C25: 101.0359 | D25: 103.61195 | E25: 105.53733 | F25: 106.1191 | G25: 107.18489 | H25: 107.72357 | I25: 107.50348 | J25: 107.9248 | K25: 108.25434 | L25: 108.51576 | M25: 108.72144 | N25: 108.80585 | O25: 108.71499 | P25: 108.42783 | Q25: 108.49642 | R25: 108.43117 | S25: 108.23811 | T25: 108.29774 | U25: 108.59257 | V25: 109.01973 | W25: 109.08175 | X25: 109.38576 | Y25: 109.84454 | Z25: 110.14797 | AA25: 110.90757 | AB25: 111.43774 | AC25: 111.86885 | AD25: 112.08251 | AE25: 112.10244 | AF25: 113.39367 | AG25: 0.003987
B27: Imports
A28: SUP000:ca_CrudeOil | B28: Crude Oil | C28: 13.849983 | D28: 16.37085 | E28: 16.629141 | F28: 15.971055 | G28: 15.230758 | H28: 14.679036 | I28: 14.643375 | J28: 14.357627 | K28: 14.264916 | L28: 14.200821 | M28: 14.399286 | N28: 14.778255 | O28: 14.611301 | P28: 14.955673 | Q28: 15.036996 | R28: 15.363056 | S28: 15.527345 | T28: 15.740888 | U28: 15.813135 | V28: 15.458242 | W28: 15.443821 | X28: 15.243117 | Y28: 14.882616 | Z28: 15.204732 | AA28: 14.507174 | AB28: 14.091373 | AC28: 13.903984 | AD28: 14.131474 | AE28: 14.48548 | AF28: 13.759513 | AG28: -0.000226
A29: SUP000:ca_PetroleumProd | B29: Petroleum and Other Liquids 6/ | C29: 4.715964 | D29: 4.470991 | E29: 3.845002 | F29: 3.923882 | G29: 4.01288 | H29: 3.965475 | I29: 3.914824 | J29: 3.83206 | K29: 3.720322 | L29: 3.693734 | M29: 3.634232 | N29: 3.635437 | O29: 3.59495 | P29: 3.562899 | Q29: 3.543973 | R29: 3.497625 | S29: 3.494834 | T29: 3.505317 | U29: 3.501205 | V29: 3.483078 | W29: 3.503401 | X29: 3.506699 | Y29: 3.514882 | Z29: 3.52966 | AA29: 3.55301 | AB29: 3.566257 | AC29: 3.599412 | AD29: 3.686488 | AE29: 3.677653 | AF29: 3.64243 | AG29: -0.008867
A30: SUP000:ca_NaturalGas | B30: Natural Gas | C30: 2.798295 | D30: 2.540921 | E30: 2.459869 | F30: 2.356853 | G30: 2.282891 | H30: 2.256741 | I30: 2.221225 | J30: 2.170627 | K30: 2.036805 | L30: 1.983411 | M30: 1.890747 | N30: 1.878801 | O30: 1.924771 | P30: 1.886512 | Q30: 1.844462 | R30: 1.839028 | S30: 1.873339 | T30: 1.870136 | U30: 1.839986 | V30: 1.805083 | W30: 1.780095 | X30: 1.772161 | Y30: 1.710783 | Z30: 1.587325 | AA30: 1.509457 | AB30: 1.489166 | AC30: 1.460802 | AD30: 1.464388 | AE30: 1.431648 | AF30: 1.387205 | AG30: -0.023907
A31: SUP000:ca_OtherImports | B31: Other 7/ | C31: 0.290388 | D31: 0.22012 | E31: 0.1165 | F31: 0.120814 | G31: 0.110212 | H31: 0.115351 | I31: 0.128298 | J31: 0.136961 | K31: 0.138309 | L31: 0.145788 | M31: 0.137366 | N31: 0.141914 | O31: 0.134995 | P31: 0.140072 | Q31: 0.137182 | R31: 0.136788 | S31: 0.131592 | T31: 0.13375 | U31: 0.134478 | V31: 0.136204 | W31: 0.131303 | X31: 0.131657 | Y31: 0.139108 | Z31: 0.138671 | AA31: 0.134569 | AB31: 0.134666 | AC31: 0.134403 | AD31: 0.13461 | AE31: 0.13483 | AF31: 0.135472 | AG31: -0.025949
A32: SUP000:ca_Total | B32: Total | C32: 21.654629 | D32: 23.602882 | E32: 23.05051 | F32: 22.372604 | G32: 21.63674 | H32: 21.016602 | I32: 20.907722 | J32: 20.497274 | K32: 20.160353 | L32: 20.023756 | M32: 20.06163 | N32: 20.434408 | O32: 20.266016 | P32: 20.545156 | Q32: 20.562613 | R32: 20.836498 | S32: 21.027109 | T32: 21.250092 | U32: 21.288803 | V32: 20.882607 | W32: 20.85862 | X32: 20.653633 | Y32: 20.247391 | Z32: 20.460388 | AA32: 19.70421 | AB32: 19.281464 | AC32: 19.098602 | AD32: 19.41696 | AE32: 19.729612 | AF32: 18.92462 | AG32: -0.004636
B34: Exports
A35: SUP000:da_Petroleum | B35: Petroleum and Other Liquids 8/ | C35: 16.73385 | D35: 18.356298 | E35: 19.182388 | F35: 19.602926 | G35: 19.941938 | H35: 19.903315 | I35: 19.849981 | J35: 19.863663 | K35: 19.811287 | L35: 19.834377 | M35: 19.808157 | N35: 19.842936 | O35: 19.662491 | P35: 19.775711 | Q35: 19.81488 | R35: 19.950239 | S35: 19.816631 | T35: 19.884661 | U35: 19.983006 | V35: 19.83169 | W35: 19.682125 | X35: 19.486174 | Y35: 19.221823 | Z35: 19.413261 | AA35: 19.138691 | AB35: 18.841377 | AC35: 18.655954 | AD35: 18.810968 | AE35: 18.771133 | AF35: 18.527115 | AG35: 0.003517
A36: SUP000:da_NaturalGas | B36: Natural Gas | C36: 6.809672 | D36: 7.579476 | E36: 7.788739 | F36: 7.875538 | G36: 8.095082 | H36: 8.109738 | I36: 8.24765 | J36: 8.540207 | K36: 8.791788 | L36: 9.023255 | M36: 9.300149 | N36: 9.552501 | O36: 9.670875 | P36: 9.714972 | Q36: 9.777483 | R36: 9.799871 | S36: 9.798469 | T36: 9.820782 | U36: 9.84569 | V36: 9.881186 | W36: 9.868215 | X36: 9.885421 | Y36: 9.895191 | Z36: 9.93121 | AA36: 9.928005 | AB36: 9.911631 | AC36: 9.899729 | AD36: 9.904961 | AE36: 9.876596 | AF36: 9.8705 | AG36: 0.012882
A37: SUP000:da_Coal | B37: Coal | C37: 2.253399 | D37: 2.300418 | E37: 2.924233 | F37: 2.806449 | G37: 2.745555 | H37: 2.878079 | I37: 2.822221 | J37: 2.814723 | K37: 2.789355 | L37: 2.781176 | M37: 2.809537 | N37: 2.864769 | O37: 2.790718 | P37: 2.767172 | Q37: 2.793478 | R37: 2.759903 | S37: 2.751223 | T37: 2.785581 | U37: 2.726024 | V37: 2.735147 | W37: 2.71931 | X37: 2.734332 | Y37: 2.698877 | Z37: 2.698676 | AA37: 2.712163 | AB37: 2.696237 | AC37: 2.690248 | AD37: 2.71199 | AE37: 2.722844 | AF37: 2.737185 | AG37: 0.006729
A38: SUP000:da_Total | B38: Total | C38: 25.796921 | D38: 28.236191 | E38: 29.895359 | F38: 30.284914 | G38: 30.782578 | H38: 30.891132 | I38: 30.919853 | J38: 31.218594 | K38: 31.392429 | L38: 31.638807 | M38: 31.917843 | N38: 32.260204 | O38: 32.124084 | P38: 32.257858 | Q38: 32.385841 | R38: 32.510014 | S38: 32.366325 | T38: 32.491024 | U38: 32.554718 | V38: 32.448021 | W38: 32.26965 | X38: 32.105927 | Y38: 31.815891 | Z38: 32.043148 | AA38: 31.778858 | AB38: 31.449245 | AC38: 31.245932 | AD38: 31.427919 | AE38: 31.370575 | AF38: 31.1348 | AG38: 0.006506
A40: SUP000:ea_Discrepancy | B40: Discrepancy 9/ | C40: -0.09956 | D40: 1.014343 | E40: 0.351906 | F40: 0.371489 | G40: 0.341177 | H40: 0.382046 | I40: 0.381279 | J40: 0.35734 | K40: 0.386271 | L40: 0.381487 | M40: 0.400639 | N40: 0.433743 | O40: 0.415009 | P40: 0.413139 | Q40: 0.417732 | R40: 0.407967 | S40: 0.411499 | T40: 0.408596 | U40: 0.402512 | V40: 0.377655 | W40: 0.373608 | X40: 0.358025 | Y40: 0.344402 | Z40: 0.348759 | AA40: 0.320744 | AB40: 0.279781 | AC40: 0.300562 | AD40: 0.304501 | AE40: 0.307432 | AF40: 0.309587 | AG40: --
B42: Consumption
A43: SUP000:fa_PetroleumProd | B43: Petroleum and Other Liquids 10/ | C43: 36.03891 | D43: 36.753876 | E43: 37.164867 | F43: 37.008743 | G43: 36.993271 | H43: 36.890812 | I43: 36.698307 | J43: 36.579685 | K43: 36.420643 | L43: 36.309967 | M43: 36.218292 | N43: 36.215271 | O43: 36.163837 | P43: 36.030983 | Q43: 35.914291 | R43: 35.832382 | S43: 35.810936 | T43: 35.784924 | U43: 35.813648 | V43: 35.779423 | W43: 35.801689 | X43: 35.841454 | Y43: 35.887527 | Z43: 35.903362 | AA43: 35.944035 | AB43: 36.088379 | AC43: 36.201035 | AD43: 36.273766 | AE43: 36.392872 | AF43: 36.628178 | AG43: 0.000559
A44: SUP000:fa_NaturalGas | B44: Natural Gas | C44: 31.361422 | D44: 31.199945 | E44: 31.177605 | F44: 31.16921 | G44: 30.965534 | H44: 30.880772 | I44: 30.613737 | J44: 30.871202 | K44: 30.754141 | L44: 30.537725 | M44: 30.416206 | N44: 30.414434 | O44: 30.607912 | P44: 30.353966 | Q44: 30.106274 | R44: 30.03334 | S44: 30.184532 | T44: 30.381096 | U44: 30.592625 | V44: 30.803253 | W44: 30.909266 | X44: 31.077223 | Y44: 31.346886 | Z44: 31.509253 | AA44: 31.678867 | AB44: 31.934574 | AC44: 32.173542 | AD44: 32.373512 | AE44: 32.546021 | AF44: 32.886066 | AG44: 0.001638
A45: SUP000:fa_Coal | B45: Coal 11/ | C45: 10.883375 | D45: 10.484755 | E45: 9.873912 | F45: 8.510278 | G45: 8.140191 | H45: 7.937951 | I45: 7.705096 | J45: 7.669232 | K45: 7.61521 | L45: 7.464706 | M45: 7.393437 | N45: 7.246166 | O45: 7.293676 | P45: 6.99925 | Q45: 6.700851 | R45: 6.583507 | S45: 6.461794 | T45: 6.44173 | U45: 6.426641 | V45: 6.337152 | W45: 6.326757 | X45: 6.277361 | Y45: 6.194617 | Z45: 6.127982 | AA45: 6.00381 | AB45: 5.957881 | AC45: 5.866497 | AD45: 5.765072 | AE45: 5.717658 | AF45: 5.766378 | AG45: -0.021665
A46: SUP000:fa_NuclearPower | B46: Nuclear / Uranium 2/ | C46: 8.12115 | D46: 8.183111 | E46: 8.202579 | F46: 8.239058 | G46: 8.163899 | H46: 8.075755 | I46: 7.930267 | J46: 7.368946 | K46: 7.299504 | L46: 7.307006 | M46: 7.318423 | N46: 7.326343 | O46: 6.808416 | P46: 6.815667 | Q46: 6.747447 | R46: 6.758354 | S46: 6.760554 | T46: 6.762659 | U46: 6.762759 | V46: 6.766273 | W46: 6.77936 | X46: 6.788805 | Y46: 6.797936 | Z46: 6.805902 | AA46: 6.814445 | AB46: 6.818903 | AC46: 6.823349 | AD46: 6.826119 | AE46: 6.829472 | AF46: 6.834313 | AG46: -0.005931
A47: SUP000:fa_Hydropower | B47: Conventional Hydroelectric Power | C47: 2.288529 | D47: 2.39653 | E47: 2.520376 | F47: 2.607582 | G47: 2.562303 | H47: 2.533515 | I47: 2.5148 | J47: 2.494481 | K47: 2.48263 | L47: 2.471396 | M47: 2.456771 | N47: 2.450083 | O47: 2.436512 | P47: 2.4271 | Q47: 2.410605 | R47: 2.397023 | S47: 2.392663 | T47: 2.381657 | U47: 2.376802 | V47: 2.37014 | W47: 2.362096 | X47: 2.354189 | Y47: 2.3427 | Z47: 2.33699 | AA47: 2.32513 | AB47: 2.318443 | AC47: 2.309026 | AD47: 2.304834 | AE47: 2.295233 | AF47: 2.274688 | AG47: -0.000209
