Workbook
Name a: #REF!
Name AsphaltStore: [1]Control!$D$50
Name base.year: #REF!
Name BaseYear: 2018
Name BTV11_15: #REF!
Name BVT17_15: #REF!
Name CAAGR_tolerance: 200
Name CH4_to_CO2e: '[2]Cross-Page Data'!$C$12
Name CH4GWP: #REF!
Name CO2_T4_APS: #REF!
Name CO2_T4_NZE: #REF!
Name CO2_T4_STEPS: #REF!
Name CO2_T5_APS: #REF!
Name CO2_T5_CPS: #REF!
Name CO2_T5_NZE: #REF!
Name CO2_T5_STEPS: #REF!
Name coal.past: #REF!
Name COAL_PRODUCTION: #REF!
Name Coal_trade: #REF!
Name coaldemand: #REF!
Name CokeCoalStore: [1]Control!$D$63
Name Constants.Density.Diesel: #REF!
Name Constants.Density.Ethanol: #REF!
Name Constants.Density.JetFuel: #REF!
Name Constants.Density.MotorSpirit: #REF!
Name ConsumeBlock1: '[1]Default State Energy Data Table'!$A$6:$AM$67
Name Conversion.to.average.power: #REF!
Name Conversion.water.L: #REF!
Name Conversion.water.units: #REF!
Name Conversions.Area.m2: #REF!
Name Conversions.Area.Units: #REF!
Name Conversions.Energy.Joules: #REF!
Name Conversions.Energy.Units: #REF!
Name Conversions.Money.GBP: #REF!
Name Conversions.Money.Units: #REF!
Name Conversions.Power.Units: #REF!
Name Conversions.Power.Watts: #REF!
Name Cost.Capital.Scenario: #REF!
Name Cost.Finance.Scenario: #REF!
Name Cost.Fuel.Scenario: #REF!
Name Cost.Infrastructure.Scenario: #REF!
Name cpi_2010to2012: #REF!
Name cpi_2013to2012: #REF!
Name cpi_2014to2012: #REF!
Name cpi_2016to2012: #REF!
Name CreateRegions: #REF!
Name csp.capacity: #REF!
Name CSVfilepath: #REF!
Name D: #REF!
Name dd: #REF!
Name ddd: #REF!
Name ddddd: #REF!
Name dddddd: #REF!
Name deflator_year: "$2018"
Name DeflatorYear: "$2018"
Name discount_factors: #REF!
Name DistillStore: [1]Control!$D$51
Name DW_EDO_022WV: #REF!
Name DW_EDO_023WV: #REF!
Name DW_EDO_024WV: #REF!

Sheet About
A1: PEaWHRP Process Efficiency and Waste Heat Recovery Parameters
A4: Sources: | B4: Recovery Costs | D4: Waste Heat Recovery Equipment Costs
B5: Kermeli et al. | D5: U.S. DOE Advanced Manufacturing Office / BCS Inc.; EPRI; Case Studies in Thermal Engineering
B6: 2022 | D6: 2008-2025
B7: Energy efficiency potentials in the EU industry: impacts of deep decarbonization technologies | D7: Steam Tip Sheets #3 and #26A; Waste Heat Recovery: Technology and Opportunities in U.S. Industry; EPRI report 1020134; industrial ORC capex survey
B8: https://link.springer.com/article/10.1007/s12053-022-10071-8#Sec15 | D8: https://www.energy.gov/sites/prod/files/2014/05/f16/steam26a_condensing.pdf ; https://www.epri.com/research/products/1020134
B9: Supplementary Information | D9: Basis for gap-fill technology assumptions (blue inputs); evidence table on tab 'summary'
B11: Specific Energy Consumption | D11: Fuel Carbon Intensity
B12: Fleiter et al. (via Kermeli et al. Table 1) | D12: U.S. Environmental Protection Agency
B13: 2017 | D13: 2022-2024
B14: Baseline scenario of the heating and cooling demand in buildings and industry in the 14 MSs until 2050 | D14: GHG Emission Factors Hub (stationary combustion); eGRID (US average grid intensity)
B15: https://link.springer.com/article/10.1007/s12053-022-10071-8/tables/1 | D15: https://www.epa.gov/climateleadership/ghg-emission-factors-hub
B16: Pasted to tab 'Kermeli SEC' | D16: Used for the $/MMBtu -> $/tCO2 equivalence table on tab 'summary'
B18: US Production Tonnages | D18: Industry Cost of Capital
B19: USGS; AISI / worldsteel; U.S. EIA; FAO; American Foundry Society | D19: EPS input data folder: indst / BCoISC
B20: 2018-2025 | D20: as of 2026-07-29
B21: Mineral Commodity Summaries (aluminum, soda ash, ammonia, cement, clinker); crude steel by route; coke; paper & pulp; aluminum castings | D21: Real weighted average cost of capital by EPS industry (no hurdle premium included)
B22: https://pubs.usgs.gov/periodicals/mcs2025/ ; https://www.eia.gov/todayinenergy/detail.php?id=67385 | D22: Tab 'BCoISC-WACCbI'
B23: Eight products ESTIMATED (no official source found) - see 'product map' cols I/J | D23: Real WACC by EPS industry from the EPS input-data folder (indst / BCoISC), as of 2026-07-29.
B25: Industry Energy Base | D25: Waste Heat Potential & Temperature Splits
B26: U.S. Energy Information Administration, Manufacturing Energy Consumption Survey (MECS) | D26: Imported from 'Waste Heat Recovery Potl by Indst' file (Bianchi-derived)
B27: 2018 | D27: -
B28: Table 3.1 Fuel Consumption, by NAICS code | D28: Industry waste-heat potential (dimensionless) and low / medium / high temperature shares
B29: https://www.eia.gov/consumption/manufacturing/data/2018/pdf/Table3_1.pdf | D29: External links now broken; cached values retained
B30: Mapped to EPS industries on tab 'energy base (MECS)' | D30: Tabs: 'WHRPbI', 'EU Data', 'heat share (src)'. The source file's 'BPFUbIP-Summed Data by Industry' tab is no longer in this workbook; its values are cached where used.
B32: Industry Heat Temperature Bands | D32: Zero-Savings & Zero-Cost Corrections (rounding recovery)
B33: Derived from the industry / BPFUbIP source file | D33: Worrell, Kermeli & Galitsky (2013) ENERGY STAR Cement Guide; Fleiter et al. (2012) Energy 40(1); Worrell et al. (2010) LBNL-4779E; Zhang et al. (2021) J. Cleaner Production
B34: - | D34: 2010-2021
B35: Share of each industry's boiler and non-boiler heat falling in five temperature bands (<100C, 100-200C, 200-500C, 500-1000C, >1000C) | D35: Kermeli's published tables round savings to 0.1 GJ/t and costs to whole euros, zeroing 12 small measures and 5 costs. True values recovered from the primary sources and wired into 'Kermeli Data' (green cells) via tab 'src review'.
B36: - | D36: https://www.energystar.gov/sites/default/files/buildings/tools/ENERGY%20STAR%20Guide%20for%20the%20Cement%20Industry%2028_08_2013%20Final.pdf ; https://www.osti.gov/servlets/purl/1026806 ; doi 10.1016/j.energy.2012.02.025 ; Zhang et al. (2021) via https://pure.iiasa.ac.at/id/eprint/16625 (Elsevier PII S0959652620333801)
B37: Tab 'indst heat consumption'; used to deduct already-credited burner-integral recovery band by band | D37: Clinker-to-cement ratio 76% (GNR 2019, via Kermeli et al. 2022) used for basis conversions; full audit trail, verdicts and open items on tab 'src review'.
A40: Notes:
A41: Purpose | B41: Converts the single-average WHR capital cost into measure-level cost data and cost-binned energy-savings supply curves for EPS. (The LEGACY Calcs and WHRCC tabs that held the original single-average calculation were validated against the new outputs and removed 2026-07-29.)
A42: Outputs | B42: PEaWHRP-WMD / PEaWHRP-PMD = measure-level data (25 EPS industries x 7 waste-heat / 17 efficiency measure slots; savings as % of industry fuel or electricity, capital and operating intensities per unit of annual savings capacity, lifetime). PEaWHRP-WM / PEaWHRP-PM = subscript element lists. Efficiency slots reduced 18 -> 17 on 2026-07-29 by re-packing the chemicals list after an equipment-replacement exclusion.
A43: Master table | B43: Kermeli Data' - extended with added columns (classification, EPS industry, carrier shares, temperature band); source values never retyped.
A44: Classification | B44: Three buckets: (1) unit WHR = burner-integral recovery, excluded (handled in the unit-efficiency files); (2) system WHR = process-level recovery -> waste-heat outputs; (3) other process efficiency -> efficiency outputs.
A45: Classification rulings (G0.1) | B45: Scrap preheat = system WHR; ammonia air preheat = system WHR; glass low-NOx burners = unit (excluded); optimized burning = process; CHP and cogeneration = excluded; top-gas recovery turbine = system WHR; top-gas recycling = process; clinker substitution = excluded; the fuel-switching and electrification block = excluded. Row-by-row map on tab 'reconciliation'.
A46: Do-not-double-count | B46: Recovery already credited in unit-efficiency files is never re-credited: glass regenerative furnaces; blast-furnace hot-blast stoves and coke-oven regenerators; cement preheater/precalciner; recuperative/regenerative burners generally.
A47: Burner-integral credits | B47: Start-year penetrations already credited by temperature band: <100C 0%; 100-200C 0%; 200-500C 5%; 500-1000C 17.4%; >1000C 58.7%. Deducted when sizing gap-fill.
A48: Energy base (G0.6) | B48: Fuel savings are expressed as a percentage of industry TOTAL COMBUSTION FUEL (MECS total less electricity); electricity savings as a percentage of total net electricity. Kermeli Table 1 reports a heating share of 1.0 for fuels in every product, so fuel savings draw on total fuel. The heat-share column on 'energy base (MECS)' is retained for reference only.
...

Sheet hand-maintained inputs
A1: Hand-maintained model input CSVs (not produced by ExportPEaWHRP.py)
A2: Documented 2026-07-31. These four CSVs live beside this workbook and are read directly by EPS.mdl. Edit them in a text editor; keep this tab in sync.
A4: File | B4: Contents & units | C4: Methodology & sources
A5: PEaWHRP-PAC.csv | B5: Payback acceptance curve: share of firms accepting a simple payback of N years (survivor curve), rows = Measure Set (waste heat / process efficiency, currently identical), cols = payback grid 0-10 yr. Read as Vensim lookups (PAC Payback Acceptance Curve). | C5: Anchored on revealed adoption in DOE IAC audit data: Anderson & Newell (2004), RFF/Resources for the Future - implicit threshold 1.25-1.5 yr payback (65-80% hurdle rate), ~half of recommendations rejected; Muthulingam, Corbett, Benartzi & Oppenheim (2013), M&SOM 15(4) - 89,299 recommendations, mean payback 1.06 yr, adoption 50.16%. Shape ~lognormal(median 1 yr, sigma 0.9); S(0)=0.85 reflects incomplete adoption even at instant payback. Same construct as EIA NEMS IDM 'AcceptFrac' payback acceptance curve (kept as optimistic sensitivity bound, NOT adopted - it is a CHP engineering assumption, 100% acceptance at 1 yr). Full derivation: PEaWHRP_PaybackAcceptance_Plan.md at repo root.
A6: PEaWHRP-MCL-mult.csv | B6: Measure Cost Level multipliers scaling levelized cost / payback across 5 cost variants per measure. Decision-only: cash flows use unadjusted input costs. | C6: Equal-probability quintile midpoints of Normal(mean 1, sigma 0.30): 0.62/0.84/1.00/1.16/1.38. The +/-30% sigma spread was specified in the project brief (Dan O'Brien); discretization documented in WHR_EfficiencyMeasures_Restructure_Plan.md sec 4.5. Note: for measures with negative O&M cost the multiplier amplifies the benefit at high cost levels - flagged for review.
A7: PEaWHRP-MCL-share.csv | B7: Share of each measure's potential assigned to each cost level; must sum to 1. | C7: Equal 20% shares by construction (quintile discretization, same source as multipliers).
A8: PEaWHRP-SoCEMDSiaY.csv | B8: Share of each cost-effective tranche's remaining potential that begins deployment per year (0.2). | C8: Mirrors the industrial CCS convention SoCECRCSiaY (InputData/ccs/SoCECRCSiaY/SoCECRCSiaY.csv = 0.2/yr), adopted for consistency across EPS endogenous-deployment structures.
A10: Retired: | B10: PEaWHRP-MHRP.csv (hurdle premium; superseded by the PAC curve 2026-07-31), PEaWHRP-PSUS.csv (price-signal unlock sensitivity; superseded by the PAC curve 2026-07-31). Kept as .retired files for history.

Sheet Data
A1: Historical Consumer Price Index for All Urban Consumers (CPI-U): U.S. city average, all items, index
A2: averages — Continued
A3: [1982-84=100, unless otherwise noted]
A5: Source: | B5: U.S. Bureau of Labor Statistics
B6: 2024
B7: Historical CPI-U
B8: https://data.bls.gov/pdq/SurveyOutputServlet
A10: Year | B10: Semiannual averages | D10: Annual avg. | E10: Percent change from previous | G10: Multiply by to get 2012 Dollars
B11: 1st half | C11: 2nd half | E11: Dec. | F11: Annual avg.
A12: 1968............................................................................. . | B12: – | C12: – | D12: 34.8 | E12: 4.7 | F12: 4.2
A13: 1969............................................................................. . | B13: – | C13: – | D13: 36.7 | E13: 6.2 | F13: 5.5
A14: 1970............................................................................. . | B14: – | C14: – | D14: 38.8 | E14: 5.6 | F14: 5.7
A15: 1971............................................................................. . | B15: – | C15: – | D15: 40.5 | E15: 3.3 | F15: 4.4
A16: 1972............................................................................. . | B16: – | C16: – | D16: 41.8 | E16: 3.4 | F16: 3.2
A17: 1973............................................................................. . | B17: – | C17: – | D17: 44.4 | E17: 8.7 | F17: 6.2
A18: 1974............................................................................. . | B18: – | C18: – | D18: 49.3 | E18: 12.3 | F18: 11
A19: 1975............................................................................. . | B19: – | C19: – | D19: 53.8 | E19: 6.9 | F19: 9.1
A20: 1976............................................................................. . | B20: – | C20: – | D20: 56.9 | E20: 4.9 | F20: 5.8
A21: 1977............................................................................. . | B21: – | C21: – | D21: 60.6 | E21: 6.7 | F21: 6.5
A22: 1978............................................................................. . | B22: – | C22: – | D22: 65.2 | E22: 9 | F22: 7.6
A23: 1979............................................................................. . | B23: – | C23: – | D23: 72.6 | E23: 13.3 | F23: 11.3
... A27: 1983............................................................................. . | B27: – | C27: – | D27: 99.6 | E27: 3.8 | F27: 3.2
A28: 1984............................................................................. . | B28: 102.9 | C28: 104.9 | D28: 103.9 | E28: 3.9 | F28: 4.3
A29: 1985............................................................................. . | B29: 106.6 | C29: 108.5 | D29: 107.6 | E29: 3.8 | F29: 3.6
A30: 1986............................................................................. . | B30: 109.1 | C30: 110.1 | D30: 109.6 | E30: 1.1 | F30: 1.9
A31: 1987............................................................................. . | B31: 112.4 | C31: 114.9 | D31: 113.6 | E31: 4.4 | F31: 3.6
A32: 1988............................................................................. . | B32: 116.8 | C32: 119.7 | D32: 118.3 | E32: 4.4 | F32: 4.1
A33: 1989............................................................................. . | B33: 122.7 | C33: 125.3 | D33: 124 | E33: 4.6 | F33: 4.8
A34: 1990............................................................................. . | B34: 128.7 | C34: 132.6 | D34: 130.7 | E34: 6.1 | F34: 5.4 | G34: =$D$56/D34
A35: 1991............................................................................. . | B35: 135.2 | C35: 137.2 | D35: 136.2 | E35: 3.1 | F35: 4.2 | G35: =$D$56/D35
A36: 1992............................................................................. . | B36: 139.2 | C36: 141.4 | D36: 140.3 | E36: 2.9 | F36: 3 | G36: =$D$56/D36
A37: 1993............................................................................. . | B37: 143.7 | C37: 145.3 | D37: 144.5 | E37: 2.7 | F37: 3 | G37: =$D$56/D37
A38: 1994............................................................................. . | B38: 147.2 | C38: 149.3 | D38: 148.2 | E38: 2.7 | F38: 2.6 | G38: =$D$56/D38
A39: 1995............................................................................. . | B39: 151.5 | C39: 153.2 | D39: 152.4 | E39: 2.5 | F39: 2.8 | G39: =$D$56/D39
A40: 1996............................................................................. . | B40: 155.8 | C40: 157.9 | D40: 156.9 | E40: 3.3 | F40: 3 | G40: =$D$56/D40
A41: 1997............................................................................. . | B41: 159.9 | C41: 161.2 | D41: 160.5 | E41: 1.7 | F41: 2.3 | G41: =$D$56/D41
A42: 1998............................................................................. . | B42: 162.3 | C42: 163.7 | D42: 163 | E42: 1.6 | F42: 1.6 | G42: =$D$56/D42
A43: 1999............................................................................. . | B43: 165.4 | C43: 167.8 | D43: 166.6 | E43: 2.7 | F43: 2.2 | G43: =$D$56/D43
A44: 2000............................................................................. . | B44: 170.8 | C44: 173.6 | D44: 172.2 | E44: 3.4 | F44: 3.4 | G44: =$D$56/D44
A45: 2001............................................................................. . | B45: 176.6 | C45: 177.5 | D45: 177.1 | E45: 1.6 | F45: 2.8 | G45: =$D$56/D45
...

Sheet cpi
A1: CPI-U deflators & unit conversions
A2: US CPI-U, all items, U.S. city average, not seasonally adjusted, annual average (1982-84=100). Source: BLS series CUUR0000SA0. Values now pulled live from the 'Data' sheet, which holds the full 1968-2025 series.
A3: Used to deflate Kermeli 2021-EUR costs to 2012 USD (the model's reporting-year basis, matching LEGACY Calcs).
A5: Year | B5: CPI-U (annual avg) | C5: Deflator to 2012$
A6: 2012 | B6: =Data!D56 | C6: =$B$6/B6
A7: 2015 | B7: =Data!D59 | C7: =$B$6/B7
A8: 2021 | B8: =Data!D65 | C8: =$B$6/B8
A10: Key deflator (2021 -> 2012 USD) | B10: =C8 | C10: = CPI2012 / CPI2021. LEGACY About!A18 uses 0.847 (hardcoded); this cell recomputes it live = 0.8473.
A12: EUR->USD (2021 average) | B12: 1.1827 | C12: USD per EUR. LEGACY About!A17 stores the inverse 0.8458 (EUR per USD) and divides.
A13: GJ -> BTU | B13: 947817 | C13: BTU per GJ. Matches LEGACY About!A19.
A15: 2012$/MMBtu conversion helper | B15: =B13/1000000 | C15: BTU per GJ / 1e6 = MMBtu per GJ (0.947817).

Sheet summary
A1: Summary — supply curves, gap-fill assumptions, review flags
A2: Curves = cumulative % reduction of industry carrier energy vs CCE (2012$/MMBtu, @10% real). Covered industries from Kermeli measures; 19 uncovered industries carry the Bianchi fill (fuel-whr only, assumed cost $4.95/MMBtu).
A4: Proposed gap-fill technology assumptions (generic heat recovery, covered sectors) — before applying to curves
A5: Technology | B5: Temp band | C5: Capex $/kW | D5: Life (yr) | E5: O&M %capex/yr | F5: Load (h/yr) | G5: CCE @10% ($/MMBtu)
A6: Plug-in recuperator / fired-heater APH (gas-gas, eps~0.4) | B6: 200-1000C | C6: 300 | D6: 20 | E6: 0.02 | F6: 8000 | G6: 1.5107667
A7: Economizer (boiler feedwater, <200C) | B7: 100-200C | C7: 250 | D7: 20 | E7: 0.02 | F7: 8000 | G7: 1.2589722
A8: Condensing HX (deep <100C latent recovery) | B8: <100C | C8: 300 | D8: 20 | E8: 0.025 | F8: 8000 | G8: 1.5657198
A9: Waste-heat ORC (heat-to-power, $/kWe) | B9: 200-500C | C9: 2500 | D9: 20 | E9: 0.02 | F9: 8000 | G9: 12.589722
A10: Generic Bianchi-fill recovery (uncovered industries) | B10: mixed | C10: 275 | D10: 20 | E10: 0.02 | F10: 8000 | G10: 1.3848695
A11: Sizing rule (double-count-safe): gap-fill applies to COVERED industries only, sized to the RESIDUAL = Bianchi potential − existing curve capture − burner-integral credit already taken in unit files (by temp band: 200-500C 5%, 500-1000C 17.4%, >1000C 58.7%). Recuperator/APH fill only the un-credited band share; economizer/condensing HX fill <500C where unit files credit 0-5% (this file's declared scope); NO ORC fill in cement (clinker ORC measure already in curve). Uncovered industries already carry the full Bianchi fill — no gap-fill there.
A12: Do-not-double-count guard: glass regenerative furnaces, BF hot-blast stoves/coke regenerators, cement preheater/precalciner are inside the >1000C burner-integral credit — the 58.7% deduction above prevents re-crediting them.
A13: Review flags
A14: 1. GUESSED TONNAGES: glass, pulp grades, methanol, carbon black are industry ballparks (tagged); Al foundries has none (contributes 0); ethylene is 2019. Curves scale 1:1 with these.
A15: 2. GAP-FILL PRICES ARE PROPOSALS: the 4 blue rows above are DOE/EPRI-anchored picks, not data; not yet in curves. subject to review, then inject per the sizing rule (A11).
A16: 3. RESOLVED — bottom-up vs MECS check complete (validation F13:I19); ratios 0.12-0.89, all < 1, shortfalls explainable.
A17: 4. CURVES UNDERSHOOT LITERATURE POTENTIAL (e.g. steel ~2% found vs ~14% recoverable) because Kermeli omits generic bolt-on HX — closing flag 2 closes this.
A18: 5. DISCOUNT RATE = industry WACC (BCoISC-WACCbI tab) + hurdle premium (economics!AE4, blue, = +7pp per G0.1 ruling) => covered industries ~10.6-12.6%. Rationale: owners don't invest at break-even (legacy Calcs: 'hurdle = WACC + risk premium'). Flat-15% sensitivity retained (economics col Y). Tune AE4 to change every CCE at once.
A19: 6. JUDGMENT CALLS: ammonia reactor cooling + clinker grate cooler counted as system WHR; arguable overlap with unit-file high-temp credit. If reversed, cement/ammonia whr shrink modestly.
A20: 7. BAKED-IN BASES (documented in-cell, swappable): MECS 2018; heat-share fractions from imported potential file; ammonia N->NH3 conversion; pig iron = BOF-route proxy.
A22: Cost curves — rows 11-18 of each output tab (pulp&paper, refining, chemicals, rubber&plastic, glass, cement, iron&steel, other metals)
A60: CCE $/MMBtu -> $/tCO2 (carbon-price equivalence by displaced fuel)
A61: Fuel displaced | B61: kg CO2 / MMBtu | C61: $/tCO2 per $1/MMBtu | D61: Bulk curve $1/MMBtu -> | E61: $4/MMBtu ->
A62: Natural gas | B62: 53.06 | C62: 18.846589 | D62: 18.846589 | E62: 75.386355
A63: Distillate fuel oil (No.2) | B63: 73.96 | C63: 13.520822 | D63: 13.520822 | E63: 54.083288
A64: Bituminous coal | B64: 93.28 | C64: 10.720412 | D64: 10.720412 | E64: 42.881647
A65: Coal coke | B65: 113.67 | C65: 8.797396 | D65: 8.797396 | E65: 35.189584
A66: Grid electricity (US avg) | B66: 109.4 | C66: 9.1407678 | D66: 9.1407678 | E66: 36.563071
A68: Gap-fill techs vs NG carbon price ($/tCO2): | B68: 28.472798 | C68: 23.727332 | D68: 29.508477 | E68: 115.07973 | F68: (recuperator / economizer / condensing HX / ORC-vs-grid)
A70: Published cost evidence behind the gap-fill assumptions
A71: Source | B71: Technology | C71: Published figure | D71: Implied $/kW | E71: Our assumption
A72: Case Studies in Thermal Engineering (Dec 2023, peer-reviewed) | B72: Fired-heater air preheater (gas-gas HX) | C72: $71,631 capex for 286 kW_th recovered; 0.77-yr payback | D72: $250/kW_th | E72: $300/kW_th (recuperator/APH, +20% conservative)
A73: U.S. DOE research range (WHR systems, all classes) | B73: Industrial WHR generally | C73: $500-$4,500 per kW of waste heat recovered | D73: brackets all four rows | E73: economizer $200 / condensing $250 sit at-to-below the floor: flag as weakest two
A74: EPRI report 1020134 (2010) | B74: Waste-heat-driven CHP (heat-to-power) | C74: $2,000-2,500/kW (>5 MW); $3,500-4,500/kW (<400 kW) | D74: $2,000-4,500/kWe | E74: $2,500/kWe (ORC, large-system end)
A75: ORC market survey (2024-25) | B75: Industrial ORC 1-10 MWe | C75: $1.8M-$3.2M per MWe installed | D75: $1,800-3,200/kWe | E75: $2,500/kWe (midpoint)
A76: U.S. DOE / BCS Inc. (2008), Waste Heat Recovery: Technology and Opportunities | B76: Recuperators, economizers (canonical study) | C76: Canonical DOE cost study underpinning the economizer and recuperator classes | D76: - | E76: backstops recuperator/economizer rows
A77: DOE AMO Steam Tip Sheets #3 / #26A / #26B | B77: Feedwater + condensing economizers | C77: payback < 2 years' at $8/MMBtu fuel; worked examples 4.6-7.55 MMBtu/hr recovered | D77: implied ~$200-550/kW_th | E77: economizer raised to $250; condensing to $300 (mid-range)
A78: Weakest links: economizer ($200) and condensing HX ($250) rest on the DOE range floor, not a specific study.
A80: Capital cost of equipment at full 2050 potential (2012$ millions) — for EPS investment accounting
A81: Industry | B81: whr measures $M | C81: gap-fill HX $M | D81: process measures $M | E81: TOTAL $M
A82: pulp paper and printing 17T18 | B82: 314.52017 | C82: 889.28203 | D82: 625.47585 | E82: 1829.2781
...

Sheet Kermeli Data
A1: Calculations | W1: Exclusion note
A2: Data from Kermeli et al. (SM) | B2: https://link.springer.com/article/10.1007/s12053-022-10071-8#Sec10
A3: NPV =CF0 + CF1/(1+r)1 + CF2/(1+r)2 + … + CFn/(1+r)n
A4: r = hurdle rate = WACC + risk premium
A5: https://capitalgains.thediff.co/p/hurdle-rates
A7: Energy Savings & Cost of Measures from Kermeli et al.
A8: Product / Process | B8: Technology / Measure | C8: 2015 Diffusion | D8: 2030 Implementation | E8: 2050 Implementation | F8: Fuel Savings (GJ/t) | G8: Elec. Savings (GJ/t) | H8: H2 Savings (GJ/t) | I8: Investment (€/t) | J8: Technical lifetime (years) | K8: Annual O&M Costs (€/t) | L8: Temp band | M8: Burner-integral penetration | N8: EPS/heat-share industry | O8: Heat share | P8: Bucket | Q8: Bucket justification / tag | R8: Fuel save share | S8: Elec save share | T8: H2 save share | U8: 2015+2050 sum | V8: Diffusion flag
A9: Primary aluminum | B9: PFPBa | C9: 0.9 | D9: 0.1 | E9: 0.1 | F9: 0 | G9: 2.8 | H9: 0 | I9: 2340 | J9: 20 | K9: 0 | L9: >1000C | M9: 0.587 | N9: Other metals (242) | O9: 0.6089 | P9: 3 proc | Q9: Smelter electrical efficiency (point-feed prebake). Not recovery. | R9: 0 | S9: 1 | T9: 0 | U9: 1
A10: Primary aluminum | B10: Optimization electrolysis controlc | C10: 0.55 | D10: 0.35 | E10: 0.45 | F10: 0 | G10: 3.6 | H10: 0 | I10: 188 | J10: 5 | K10: -65 | L10: >1000C | M10: 0.587 | N10: Other metals (242) | O10: 0.6089 | P10: 3 proc | Q10: Electrolysis control optimization. Not recovery. | R10: 0 | S10: 1 | T10: 0 | U10: 1
A11: Primary aluminum | B11: Optimization cell designc | C11: 0.55 | D11: 0.35 | E11: 0.45 | F11: 0 | G11: 2.5 | H11: 0 | I11: 236 | J11: 6 | K11: 0 | L11: >1000C | M11: 0.587 | N11: Other metals (242) | O11: 0.6089 | P11: 3 proc | Q11: Cell design optimization. Not recovery. | R11: 0 | S11: 1 | T11: 0 | U11: 1
A12: Secondary aluminum | B12: Regenerative or recuperative burnerd | C12: 0.3 | D12: 0.25 | E12: 0.5 | F12: 2 | G12: 0 | H12: 0 | I12: 14 | J12: 20 | K12: 0.4 | L12: 500-1000C | M12: 0.174 | N12: Other metals (242) | O12: 0.6089 | P12: 1 unit | Q12: unit WHR — handled in unit-efficiency files (recup/regen burner; do-not-double-count). | R12: 1 | S12: 0 | T12: 0 | U12: 0.8
A13: Secondary aluminum | B13: New decoating equipmentd | C13: 0 | D13: 0.15 | E13: 0.6 | F13: 0.4 | G13: 0 | H13: 0 | I13: 40 | J13: 10 | K13: 40 | L13: 500-1000C | M13: 0.174 | N13: Other metals (242) | O13: 0.6089 | P13: X equip-replace | Q13: Decoating/delacquering process improvement. | R13: 1 | S13: 0 | T13: 0 | U13: 0.6 | W13: Excluded 2026-07-28: discrete furnace replacement - VFM 'in place of a gas reverberatory furnace' (DOE Aluminum Report 2016). Carried by stock turnover / standards channel.
A14: Aluminum foundries | B14: Improved process schedulinge | C14: 0.6 | D14: 0.39 | E14: 0.4 | F14: 1.8 | G14: 0 | H14: 0 | I14: 25 | J14: 20 | K14: 0 | L14: 500-1000C | M14: 0.174 | N14: Other metals (242) | O14: 0.6089 | P14: 3 proc | Q14: Process scheduling. Not recovery. | R14: 1 | S14: 0 | T14: 0 | U14: 1
A15: Aluminum foundries | B15: Regenerative or recuperative burnere | C15: 0.5 | D15: 0.05 | E15: 0.3 | F15: 4.8 | G15: 0 | H15: 0 | I15: 10 | J15: 20 | K15: 0.7 | L15: 500-1000C | M15: 0.174 | N15: Other metals (242) | O15: 0.6089 | P15: 1 unit | Q15: unit WHR — handled in unit-efficiency files (recup/regen burner; do-not-double-count). | R15: 1 | S15: 0 | T15: 0 | U15: 0.8
A16: Aluminum foundries | B16: Liquid metal as feedstocke | C16: 0.05 | D16: 0.2 | E16: 0.45 | F16: 8.7 | G16: 0 | H16: 0 | I16: 25 | J16: 20 | K16: 0 | L16: 500-1000C | M16: 0.174 | N16: Other metals (242) | O16: 0.6089 | P16: 3 proc | Q16: Liquid-metal feedstock avoids remelt. Process/material. | R16: 1 | S16: 0 | T16: 0 | U16: 0.5
A17: Coke oven | B17: Programmed heatinga | C17: 0.3 | D17: 0.5 | E17: 0.7 | F17: 0.2 | G17: 0 | H17: 0 | I17: 0.2 | J17: 10 | K17: 0 | L17: >1000C | M17: 0.587 | N17: Iron & steel (241) | O17: 0.6516 | P17: 3 proc | Q17: Programmed heating (control). Not recovery. | R17: 1 | S17: 0 | T17: 0 | U17: 1
A18: Coke oven | B18: Variable speed drive on compressorsa | C18: 0.3 | D18: 0.5 | E18: 0.7 | F18: ='src review'!H97 | G18: ='src review'!I97 | H18: 0 | I18: 0.3 | J18: 15 | K18: 0 | L18: >1000C | M18: 0.587 | N18: Iron & steel (241) | O18: 0.6516 | P18: 3 proc | Q18: VSD on compressors (motor efficiency). | R18: 0 | S18: 0 | T18: 0 | U18: 1
A19: Coke oven | B19: Coal moisture controla | C19: 0.3 | D19: 0.5 | E19: 0.7 | F19: 0.3 | G19: 0 | H19: 0 | I19: 6.5 | J19: 10 | K19: 0 | L19: >1000C | M19: 0.587 | N19: Iron & steel (241) | O19: 0.6516 | P19: 3 proc | Q19: Coal moisture control (charge prep). | R19: 1 | S19: 0 | T19: 0 | U19: 1
A20: Pig iron | B20: Waste heat recovery blast furnace slagb | C20: 0 | D20: 0.43 | E20: 0.8 | F20: 0.4 | G20: 0 | H20: 0 | I20: 54.5 | J20: 20 | K20: 0 | L20: >1000C | M20: 0.587 | N20: Iron & steel (241) | O20: 0.6516 | P20: 2 whr | Q20: System WHR: blast-furnace slag sensible-heat recovery. Not on do-not-double-count list. | R20: 1 | S20: 0 | T20: 0 | U20: 0.8
A21: Pig iron | B21: Top gas recovery turbineb | C21: 0.7 | D21: 0.21 | E21: 0.29 | F21: 0 | G21: 0.1 | H21: 0 | I21: 3.3 | J21: 15 | K21: 0.5 | L21: >1000C | M21: 0.587 | N21: Iron & steel (241) | O21: 0.6516 | P21: 2 whr | Q21: System WHR: top-gas recovery turbine (pressure/sensible heat). G0.1 ruling; no overlap with hot-blast-stove credit. | R21: 0 | S21: 1 | T21: 0 | U21: 0.99
A22: Pig iron | B22: Moisture Removing Blowing Technique in Blast Furnacec | C22: 0.05 | D22: 0.65 | E22: 0.75 | F22: 0.2 | G22: 0 | H22: 0 | I22: 2 | J22: 15 | K22: 0 | L22: >1000C | M22: 0.587 | N22: Iron & steel (241) | O22: 0.6516 | P22: 3 proc | Q22: Blast dehumidification (process). | R22: 1 | S22: 0 | T22: 0 | U22: 0.8
A23: Pig iron | B23: Injection of pulverized coal in BFc | C23: 0.05 | D23: 0.45 | E23: 0.95 | F23: 0.6 | G23: 0 | H23: 0 | I23: 5.4 | J23: 20 | K23: 1.6 | L23: >1000C | M23: 0.587 | N23: Iron & steel (241) | O23: 0.6516 | P23: 3 proc | Q23: Pulverized-coal injection (reductant substitution). | R23: 1 | S23: 0 | T23: 0 | U23: 1
A24: Pig iron | B24: Cogeneration (for the use of untapped coke oven gas, blast furnace gas, and basic oxygen furnace-gas in integrated steel mills)c | C24: 0.05 | D24: 0.2 | E24: 0.5 | F24: 0.2 | G24: 0 | H24: 0 | I24: 2.8 | J24: 20 | K24: 0 | L24: >1000C | M24: 0.587 | N24: Iron & steel (241) | O24: 0.6516 | P24: X CHP | Q24: CHP/cogen — excluded per G0.1 ruling. | R24: 1 | S24: 0 | T24: 0 | U24: 0.55
A25: Pig iron | B25: Recovery of blast furnace gas | C25: 0.05 | D25: 0.03 | E25: 0.05 | F25: 0.1 | G25: 0 | H25: 0 | I25: 1.3 | J25: 15 | K25: 0 | L25: >1000C | M25: 0.587 | N25: Iron & steel (241) | O25: 0.6516 | P25: 3 proc | Q25: Off-gas recovery (BF gas capture). Bucket 3 per G0.1 ruling: gas/feedstock recovery, not waste heat. | R25: 1 | S25: 0 | T25: 0 | U25: 0.1
A26: Pig iron | B26: Improved hot blast stove controlc | C26: 0.25 | D26: 0.3 | E26: 0.45 | F26: 0.3 | G26: 0 | H26: 0 | I26: 0.3 | J26: 5 | K26: 0 | L26: >1000C | M26: 0.587 | N26: Iron & steel (241) | O26: 0.6516 | P26: 3 proc | Q26: Hot-blast-stove CONTROL efficiency (not recovery; stove recovery itself is do-not-double-count). | R26: 1 | S26: 0 | T26: 0 | U26: 0.7
A27: Pig iron | B27: Improved blast furnace controlc | C27: 0.5 | D27: 0.25 | E27: 0.5 | F27: 0.3 | G27: 0 | H27: 0 | I27: 0.6 | J27: 5 | K27: 0 | L27: >1000C | M27: 0.587 | N27: Iron & steel (241) | O27: 0.6516 | P27: 3 proc | Q27: Blast furnace control. Not recovery. | R27: 1 | S27: 0 | T27: 0 | U27: 1
A28: BF/BOF steel | B28: Recovery of BOF and sensible heatc | C28: 0.7 | D28: 0.1 | E28: 0.2 | F28: 0.6 | G28: 0 | H28: 0 | I28: 25.6 | J28: 10 | K28: 0 | L28: >1000C | M28: 0.587 | N28: Iron & steel (241) | O28: 0.6516 | P28: 2 whr | Q28: System WHR: BOF gas + sensible heat recovery. | R28: 1 | S28: 0 | T28: 0 | U28: 0.9
A29: BF/BOF steel | B29: Scrap preheatingc | C29: 0.3 | D29: 0.25 | E29: 0.7 | F29: 0.2 | G29: 0.4 | H29: 0 | I29: 17.4 | J29: 30 | K29: 0 | L29: >1000C | M29: 0.587 | N29: Iron & steel (241) | O29: 0.6516 | P29: 2 whr | Q29: System WHR: scrap preheating. G0.1 ruling (EAF floor at no-preheat value; no double count). | R29: 0.33333333 | S29: 0.66666667 | T29: 0 | U29: 1
A30: BF/BOF steel | B30: Variable speed drives for flue gas control, pumps, fans in integrated steel millsc | C30: 0.85 | D30: 0.15 | E30: 0.15 | F30: 0 | G30: 0.03 | H30: 0 | I30: 1.5 | J30: 10 | K30: 0 | L30: >1000C | M30: 0.587 | N30: Iron & steel (241) | O30: 0.6516 | P30: 3 proc | Q30: VSD flue-gas/pumps/fans (motor efficiency). | R30: 0 | S30: 1 | T30: 0 | U30: 1
... A34: Rolled steel | B34: Recuperative or regenerative burnerc | C34: 0.4 | D34: 0.5 | E34: 0.6 | F34: 0.6 | G34: 0 | H34: 0 | I34: 2.9 | J34: 10 | K34: 0 | L34: 500-1000C | M34: 0.174 | N34: Iron & steel (241) | O34: 0.6516 | P34: 1 unit | Q34: unit WHR — handled in unit-efficiency files (recup/regen burner; do-not-double-count). | R34: 1 | S34: 0 | T34: 0 | U34: 1
A35: Rolled steel | B35: Endless Hot Rolling of Steel Sheetsc | C35: 0.01 | D35: 0.14 | E35: 0.19 | F35: 0.4 | G35: 0 | H35: 0 | I35: 7.3 | J35: 20 | K35: 0 | L35: 500-1000C | M35: 0.174 | N35: Iron & steel (241) | O35: 0.6516 | P35: X equip-replace | Q35: Endless hot rolling (process). | R35: 1 | S35: 0 | T35: 0 | U35: 0.2 | W35: Excluded 2026-07-28: new-build casting-rolling line - 'construction of an ESP plant' (Worrell et al. 2010, LBNL-4779E). Enters via new equipment stock, not retrofit.
A36: Rolled steel | B36: Process control in hot rollingc | C36: 0.3 | D36: 0.5 | E36: 0.7 | F36: 0.3 | G36: 0 | H36: 0 | I36: 0.8 | J36: 10 | K36: 0 | L36: 500-1000C | M36: 0.174 | N36: Iron & steel (241) | O36: 0.6516 | P36: 3 proc | Q36: Hot-rolling process control. | R36: 1 | S36: 0 | T36: 0 | U36: 1
A37: Container glass | B37: Batch/cullet preheatinga | C37: 0.4 | D37: 0.2 | E37: 0.38 | F37: 0.7 | G37: 0 | H37: 0 | I37: 20 | J37: 20 | K37: 0 | L37: >1000C | M37: 0.587 | N37: Glass (231) | O37: 0.7514 | P37: 2 whr | Q37: System WHR: flue-gas heat to preheat batch/cullet (bolt-on downstream of regenerator; not double-counted). | R37: 1 | S37: 0 | T37: 0 | U37: 0.78
A38: Container glass | B38: Increase of culletsb | C38: 0.55 | D38: 0.27 | E38: 0.3 | F38: 1.2 | G38: 0 | H38: 0 | I38: 28 | J38: 20 | K38: 0.8 | L38: >1000C | M38: 0.587 | N38: Glass (231) | O38: 0.7514 | P38: 3 proc | Q38: Increased cullet (raw-material substitution). | R38: 1 | S38: 0 | T38: 0 | U38: 0.85
A39: Container glass | B39: Low NOx burnersa | C39: 0.25 | D39: 0.21 | E39: 0.37 | F39: 0.3 | G39: 0 | H39: 0 | I39: 3 | J39: 20 | K39: 0 | L39: >1000C | M39: 0.587 | N39: Glass (231) | O39: 0.7514 | P39: 1 unit | Q39: unit WHR — handled in unit-efficiency files (low-NOx burner). G0.1 ruling. | R39: 1 | S39: 0 | T39: 0 | U39: 0.62
A40: Container glass | B40: Optimized burningc | C40: 0.3 | D40: 0.39 | E40: 0.65 | F40: 0.5 | G40: 0 | H40: 0 | I40: 10 | J40: 20 | K40: 0 | L40: >1000C | M40: 0.587 | N40: Glass (231) | O40: 0.7514 | P40: 3 proc | Q40: Optimized burning (process efficiency). G0.1 ruling. | R40: 1 | S40: 0 | T40: 0 | U40: 0.95
A41: Container glass | B41: Process Control-Software and Image based controla | C41: 0.5 | D41: 0.3 | E41: 0.5 | F41: 0.2 | G41: 0 | H41: 0 | I41: 3 | J41: 10 | K41: 0 | L41: >1000C | M41: 0.587 | N41: Glass (231) | O41: 0.7514 | P41: 3 proc | Q41: Process control / image-based control. | R41: 1 | S41: 0 | T41: 0 | U41: 1
A42: Flat glass | B42: Waste heat recoveryd | C42: 0.7 | D42: 0.05 | E42: 0.25 | F42: 0 | G42: 0.3 | H42: 0 | I42: 10 | J42: 20 | K42: 0 | L42: >1000C | M42: 0.587 | N42: Glass (231) | O42: 0.7514 | P42: 2 whr | Q42: System WHR: flat-glass waste heat recovery (offsets electricity). | R42: 0 | S42: 1 | T42: 0 | U42: 0.95
A43: Flat glass | B43: Batch/cullet preheatinge | C43: 0 | D43: 0.2 | E43: 0.5 | F43: 1.1 | G43: 0 | H43: 0 | I43: 20 | J43: 20 | K43: 0 | L43: >1000C | M43: 0.587 | N43: Glass (231) | O43: 0.7514 | P43: 2 whr | Q43: System WHR: flue-gas heat to preheat batch/cullet. | R43: 1 | S43: 0 | T43: 0 | U43: 0.5
A44: Flat glass | B44: Low NOx burnersa | C44: 0.25 | D44: 0.21 | E44: 0.37 | F44: 0.4 | G44: 0 | H44: 0 | I44: 3 | J44: 20 | K44: 0 | L44: >1000C | M44: 0.587 | N44: Glass (231) | O44: 0.7514 | P44: 1 unit | Q44: unit WHR — handled in unit-efficiency files (low-NOx burner). G0.1 ruling. | R44: 1 | S44: 0 | T44: 0 | U44: 0.62
...

Sheet Kermeli SEC
B3: Products | C3: Specific energy consumption (SEC) | E3: Share for heating | G3: Share for cooling
C5: (in GJ/t product)
C6: Fuels | D6: Electricity | E6: Fuels | F6: Electricity | G6: Fuels | H6: Electricity
B7: Chemicals
B8: Carbon black | C8: 52.7a | D8: 1.8 | E8: 1 | F8: 0 | G8: 0 | H8: 0.06
B9: Ethylene | C9: 31.8a | D9: 0 | E9: 1 | F9: 0 | G9: 0 | H9: 0
B10: Methanol | C10: 15 | D10: 0.5 | E10: 1 | F10: 0 | G10: 0 | H10: 0.04
B11: Ammonia | C11: 11.3 | D11: 0.5 | E11: 1 | F11: 0 | G11: 0 | H11: 0.06
B12: Soda ash | C12: 11.3 | D12: 0.3 | E12: 1 | F12: 0 | G12: 0 | H12: 0
B13: All rest chemicals | E13: 1 | F13: 0 | G13: 0 | H13: 0.03
B14: Iron and steel
B15: Blast furnace | C15: 11.6 | D15: 0.6 | E15: 1 | F15: 0 | G15: 0 | H15: 0
B16: Rolled steel | C16: 1.8b | D16: 0.4b | E16: 1 | F16: 0.1 | G16: 0 | H16: 0
B17: Electric arc furnace | C17: 1 | D17: 2.3 | E17: 1 | F17: 0.95 | G17: 0 | H17: 0
B18: Coke oven | C18: 3.2 | D18: 0.1 | E18: 1 | F18: 0 | G18: 0 | H18: 0
B19: All rest iron and steel | E19: 1 | F19: 0 | G19: 0 | H19: 0
B20: Non-ferrous metals
B21: Primary aluminium | C21: 0 | D21: 55.8 | E21: 1 | F21: 0.05 | G21: 0 | H21: 0
B22: All rest non-ferrous metals | E22: 1 | F22: 0.05 | G22: 0 | H22: 0
B23: Non-metallic minerals
B24: Cement | C24: 3.7c | D24: 0.5c | E24: 1 | F24: 0 | G24: 0 | H24: 0
B25: Flat glass | C25: 10.9 | D25: 3.3 | E25: 1 | F25: 0 | G25: 0 | H25: 0.06
B26: Container glass | C26: 5.8 | D26: 1.4 | E26: 1 | F26: 0.04 | G26: 0 | H26: 0.06
B27: All rest non-metallic minerals | E27: 1 | F27: 0 | G27: 0 | H27: 0.02
B28: Pulp and paper
B29: Paper | C29: 5.5 | D29: 1.9 | E29: 1 | F29: 0.01 | G29: 0 | H29: 0.01
B30: Chemical pulp | C30: 12.7 | D30: 2.3 | E30: 1 | F30: 0.01 | G30: 0 | H30: 0
B31: All rest pulp and paper | E31: 1 | F31: 0.01 | G31: 0 | H31: 0.005
B32: Others
B33: All rest others | E33: 1 | F33: 0.05 | G33: 0 | H33: 0.15

Sheet product map
A1: Product map & source data
A2: Per-product attributes referenced by Kermeli Data (XLOOKUP). Temp band & burner-integral penetration per G0.1 ruling-approved mapping. Heat-share links to 'heat share (src)'. US tonnages added in T4.2.
A4: Band -> burner-integral penetration (start-year, already credited in unit files)
A5: Band | B5: Penetration
A6: <100C | B6: 0
A7: 100-200C | B7: 0
A8: 200-500C | B8: 0.05
A9: 500-1000C | B9: 0.174
A10: >1000C | B10: 0.587
A13: Product | B13: EPS / heat-share industry | C13: Heat-share code | D13: Heat share (link) | E13: Temp band (dominant) | F13: Burner-integral penetration | G13: US production (Mt/yr) | H13: Basis year | I13: Source (primary) | J13: Split method / notes | K13: SEC total (GJ/t) — Kermeli Table 1 | L13: Steel split inputs | N13: SEC x prod (TBtu)
A14: Primary aluminum | B14: Other metals (242) | C14: 242 | D14: 0.6089 | E14: >1000C | F14: 0.587 | G14: 0.67 | H14: 2024e | I14: USGS MCS 2025 Aluminum | K14: 55.8 | L14: US crude steel total (Mt) | M14: 79.5 | N14: 35.435086
A15: Secondary aluminum | B15: Other metals (242) | C15: 242 | D15: 0.6089 | E15: 500-1000C | F15: 0.174 | G15: 1.6 | H15: 2024e | I15: USGS MCS 2025 Aluminum (old scrap) | K15: pending | L15: EAF share | M15: 0.718 | N15: 0
A16: Aluminum foundries | B16: Other metals (242) | C16: 242 | D16: 0.6089 | E16: 500-1000C | F16: 0.174 | G16: 2.4 | H16: ~2023 est | I16: ESTIMATED (AFS census basis) | J16: estimated split | K16: pending | L16: Note | M16: EAF/BOF split = total x EAF share; rolled ≈ total crude steel; pig iron proxy ≈ BOF-route crude steel. | N16: 0
A17: Coke oven | B17: Iron & steel (241) | C17: 241 | D17: 0.6516 | E17: >1000C | F17: 0.587 | G17: 9.07 | H17: 2025 | I17: EIA Today in Energy / Quarterly Coal Report | K17: 3.3 | L17: US paper total (Mt, 2023 FAO) | M17: 60.7 | N17: 28.369111
A18: Pig iron | B18: Iron & steel (241) | C18: 241 | D18: 0.6516 | E18: >1000C | F18: 0.587 | G18: 22.419 | H18: 2024 (proxy) | I18: Proxy from crude-steel split (see L13:M16) | K18: 12.2 | N18: 259.23913
A19: BF/BOF steel | B19: Iron & steel (241) | C19: 241 | D19: 0.6516 | E19: >1000C | F19: 0.587 | G19: 22.419 | H19: 2024 | I19: worldsteel/AISI x (1 - EAF share) | K19: pending | N19: 0
A20: EAF steel | B20: Iron & steel (241) | C20: 241 | D20: 0.6516 | E20: >1000C | F20: 0.587 | G20: 57.081 | H20: 2024 | I20: worldsteel/AISI x EAF share | K20: 3.3 | N20: 178.53773
A21: Rolled steel | B21: Iron & steel (241) | C21: 241 | D21: 0.6516 | E21: 500-1000C | F21: 0.174 | G21: 79.5 | H21: 2024 | I21: ≈ total crude steel (worldsteel/AISI) | K21: 2.2 | N21: 165.77319
A22: Container glass | B22: Glass (231) | C22: 231 | D22: 0.7514 | E22: >1000C | F22: 0.587 | G22: 10 | H22: ~2024 est | I22: ESTIMATED (market research) | J22: estimated split | K22: 7.2 | N22: 68.242824
A23: Flat glass | B23: Glass (231) | C23: 231 | D23: 0.7514 | E23: >1000C | F23: 0.587 | G23: 5 | H23: ~2024 est | I23: ESTIMATED (market research) | J23: estimated split | K23: 14.2 | N23: 67.295007
A24: Mechanical pulp | B24: Pulp & paper (17T18) | C24: 17T18 | D24: 0.8551 | E24: 100-200C | F24: 0 | G24: 1.5 | H24: ~2023 est | I24: ESTIMATED (FAO-anchored) | J24: estimated split | K24: pending | N24: 0
A25: Recovered fibre pulp | B25: Pulp & paper (17T18) | C25: 17T18 | D25: 0.8551 | E25: 100-200C | F25: 0 | G25: 20 | H25: ~2023 est | I25: ESTIMATED (FAO-anchored) | J25: estimated split | K25: pending | N25: 0
A26: Chemical pulp | B26: Pulp & paper (17T18) | C26: 17T18 | D26: 0.8551 | E26: 100-200C | F26: 0 | G26: 40 | H26: ~2023 est | I26: ESTIMATED (FAO-anchored) | J26: estimated split | K26: 15 | N26: 568.6902
A27: Tissue paper | B27: Pulp & paper (17T18) | C27: 17T18 | D27: 0.8551 | E27: 100-200C | F27: 0 | G27: 7.1 | H27: 2023 | I27: FAOSTAT (household & sanitary) | J27: direct | K27: 7.4 | N27: 49.798305
A28: Graphic paper | B28: Pulp & paper (17T18) | C28: 17T18 | D28: 0.8551 | E28: 100-200C | F28: 0 | G28: 7.37 | H28: 2023 | I28: FAOSTAT residual (total - tissue - packaging) | J28: estimated split (residual) | K28: 7.4 | N28: 51.692044
A29: Board and packaging paper | B29: Pulp & paper (17T18) | C29: 17T18 | D29: 0.8551 | E29: 100-200C | F29: 0 | G29: 46.23 | H29: 2023 | I29: FAOSTAT (packaging paper & board) | J29: direct | K29: 7.4 | N29: 324.25009
A30: Ethylene | B30: Chemicals (20) | C30: 20 | D30: 0.7161 | E30: 500-1000C | F30: 0.174 | G30: 31.4 | H30: 2019 | I30: US DOE Ethane Report (2019; refine to recent yr) | J30: direct (dated) | K30: 31.8 | N30: 946.41423
A31: Soda ash | B31: Chemicals (20) | C31: 20 | D31: 0.7161 | E31: 200-500C | F31: 0.05 | G31: 12 | H31: 2024e | I31: USGS MCS 2025 Soda Ash | K31: 11.6 | N31: 131.93613
A32: Carbon black | B32: Chemicals (20) | C32: 20 | D32: 0.7161 | E32: >1000C | F32: 0.587 | G32: 1.3 | H32: ~2023 est | I32: ESTIMATED | J32: estimated split | K32: 54.5 | N32: 67.152834
A33: Methanol | B33: Chemicals (20) | C33: 20 | D33: 0.7161 | E33: 500-1000C | F33: 0.174 | G33: 9 | H33: ~2023 est | I33: ESTIMATED (ACC-anchored) | J33: estimated split | K33: 15.5 | N33: 132.22047
A34: Ammonia | B34: Chemicals (20) | C34: 20 | D34: 0.7161 | E34: 500-1000C | F34: 0.174 | G34: 16.5 | H34: 2024 | I34: USGS MCS 2026 Nitrogen (N content /0.8235 -> NH3) | K34: 11.8 | N34: 184.53997
A35: Clinker | B35: Cement (239) | C35: 239 | D35: 0.8492 | E35: >1000C | F35: 0.587 | G35: 72 | H35: 2024e | I35: USGS MCS 2026 Cement (clinker line) | K35: pending | N35: 0
A36: Cement | B36: Cement (239) | C36: 239 | D36: 0.8492 | E36: >1000C | F36: 0.587 | G36: 85 | H36: 2024e | I36: USGS MCS 2026 Cement | K36: 4.2 | N36: 338.37067

Sheet energy base (MECS)
A1: Industry energy base — EIA MECS 2018 Table 3.1 (denominator for % reduction curves)
A2: Fuel-curve base = combustion fuel x heat share (G0.6 Option B). Elec-curve base = net electricity. Elec TBtu = MkWh x 0.003412 (3,412 Btu/kWh). Only the 6 covered manufacturing industries need this; uncovered industries take the Bianchi fraction directly.
A3: EPS industry | B3: NAICS | C3: Total fuel (TBtu) | D3: Net elec (MkWh) | E3: Elec (TBtu) | F3: Combustion fuel (TBtu) | G3: Heat share | H3: Fuel-for-heat base (TBtu) | I3: Elec base (TBtu) | K3: code
A4: pulp paper and printing 17T18 | B4: 322+323 | C4: 2098 | D4: 61038 | E4: =D4*0.003412 | F4: =C4-E4 | G4: ='heat share (src)'!C10 | H4: =F4*G4 | I4: =E4 | K4: 17T18
A5: chemicals 20 | B5: 325 | C5: 3813 | D5: 146846 | E5: =D5*0.003412 | F5: =C5-E5 | G5: ='heat share (src)'!C12 | H5: =F5*G5 | I5: =E5 | K5: 20
A6: glass and glass products 231 | B6: 3272 | C6: 153 | D6: 10676 | E6: =D6*0.003412 | F6: =C6-E6 | G6: ='heat share (src)'!C14 | H6: =F6*G6 | I6: =E6 | K6: 231
A7: cement and other nonmetallic 239 | B7: 327 less 3272 | C7: 668 | D7: 27277 | E7: =D7*0.003412 | F7: =C7-E7 | G7: ='heat share (src)'!C15 | H7: =F7*G7 | I7: =E7 | K7: 239
A8: iron and steel 241 | B8: 331110 | C8: 1141 | D8: 55633 | E8: =D8*0.003412 | F8: =C8-E8 | G8: ='heat share (src)'!C16 | H8: =F8*G8 | I8: =E8 | K8: 241
A9: other metals 242 | B9: 3313+3314 | C9: 302 | D9: 39534 | E9: =D9*0.003412 | F9: =C9-E9 | G9: ='heat share (src)'!C17 | H9: =F9*G9 | I9: =E9 | K9: 242
A11: Bianchi assumed cost mu (savings-wtd avg CCE of covered whr, $/MMBtu) | F11: {=SUMPRODUCT((economics!$D$2:$D$167="whr")*economics!$AK$2:$AK$167*economics!$AH$2:$AH$167)/SUMPRODUCT((economics!$D$2:$D$167="whr")*economics!$AH$2:$AH$167)}

Sheet EU Data
B22: Indst | C22: Potential (TWh) | D22: Potential (%) | E22: LT | F22: MT | G22: HT | H22: EPS ISIC 1 | I22: EPS ISIC 2 | J22: EPS ISIC 3
B23: NS | C23: 19.9 | D23: 0.033 | E23: 35.4 | F23: 17.9 | G23: 46.7 | H23: other manufacturing 31T33 | I23: metal products except machinery and vehicles 25 | J23: rubber and plastic products 22
B24: C | C24: 9.6 | D24: 0.016 | E24: 15.2 | F24: 33.2 | G24: 51.6 | H24: construction 41T43
B25: W&WP | C25: 4.8 | D25: 0.008 | E25: 73.9 | F25: 4 | G25: 22.1 | H25: wood products 16
B26: M | C26: 19.6 | D26: 0.033 | E26: 36.8 | F26: 6.2 | G26: 57 | H26: other machinery 28 | I26: computers and electronics 26 | J26: appliances and electrical equipment 27
B27: TE | C27: 7.9 | D27: 0.013 | E27: 40.7 | F27: 5.8 | G27: 53.5 | H27: road vehicles 29 | I27: nonroad vehicles 30
B28: PPP | C28: 27 | D28: 0.045 | E28: 43.8 | F28: 6.8 | G28: 49.4 | H28: pulp paper and printing 17T18
B29: T&L | C29: 5.5 | D29: 0.009 | E29: 26.2 | F29: 5.9 | G29: 67.9 | H29: textiles apparel and leather 13T15
B30: F&T | C30: 35.1 | D30: 0.059 | E30: 25.1 | F30: 9.1 | G30: 65.8 | H30: food beverage and tobacco 10T12
B31: M&Q | C31: 3.3 | D31: 0.005 | E31: 27 | F31: 20.6 | G31: 52.4 | H31: other mining and quarrying 07T08
B32: NMM | C32: 43.8 | D32: 0.074 | E32: 0.6 | F32: 15 | G32: 84.4 | H32: cement and other nonmetallic minerals 239 | I32: glass and glass products 231
B33: C&P | C33: 33.9 | D33: 0.057 | E33: 37.1 | F33: 62.9 | G33: 0 | H33: chemicals 20
B34: NFM | C34: 14.1 | D34: 0.024 | E34: 1.8 | F34: 4.5 | G34: 93.7 | H34: other metals 242
B35: I&S | C35: 54.3 | D35: 0.091 | E35: 11.1 | F35: 29.8 | G35: 59.1 | H35: iron and steel 241

Sheet economics
A1: Product | B1: Measure | C1: Bucket | D1: Curve | E1: 2050 add'l diffusion | F1: Fuel GJ/t | G1: Elec GJ/t | H1: Invest EUR/t | I1: Life (yr) | J1: O&M EUR/t | K1: US tonnage (Mt) | L1: Invest 2012$/t | M1: O&M 2012$/t | N1: CRF@10% | O1: Ann cost 2012$/t | P1: Tot pos GJ/t | Q1: Fuel share | R1: Elec share | S1: CCE@10% $/GJ | T1: CCE@10% $/MMBtu | U1: CCE fuel@10% | V1: CCE elec@10% | W1: CRF@15% | X1: Ann cost@15% $/t | Y1: CCE@15% $/MMBtu | Z1: Ann fuel saved GJ/yr | AA1: Ann elec saved GJ/yr | AB1: Flags | AD1: Real discount rate | AE1: 0.1 | AG1: Industry code | AH1: Fuel %pot | AI1: Elec %pot | AJ1: sigma | AK1: mu | AL1: WACC (industry) | AM1: Cap intensity 2012$/MMBtu-yr | AN1: Total capex 2012$
A2: ='Kermeli Data'!A9 | B2: ='Kermeli Data'!B9 | C2: ='Kermeli Data'!P9 | D2: =IF(C2="2 whr","whr",IF(C2="3 proc","process","EXCLUDED")) | E2: ='Kermeli Data'!E9 | F2: ='Kermeli Data'!F9 | G2: ='Kermeli Data'!G9 | H2: ='Kermeli Data'!I9 | I2: ='Kermeli Data'!J9 | J2: ='Kermeli Data'!K9 | K2: =IFERROR(_xlfn.XLOOKUP(A2,'product map'!$A$14:$A$36,'product map'!$G$14:$G$36),"pending") | L2: =H2*cpi!$B$12*cpi!$B$10 | M2: =J2*cpi!$B$12*cpi!$B$10 | N2: =IF(I2>0,AL2/(1-(1+AL2)^-I2),"") | O2: =L2*N2+M2 | P2: =MAX(F2,0)+MAX(G2,0) | Q2: =IF(P2>0,MAX(F2,0)/P2,0) | R2: =IF(P2>0,MAX(G2,0)/P2,0) | S2: =IF(P2>0,O2/P2,"") | T2: =IF(P2>0,S2/$AE$3,"") | U2: =IF(AND(P2>0,Q2>0),T2,"") | V2: =IF(AND(P2>0,R2>0),T2,"") | W2: =IF(I2>0,$AE$2/(1-(1+$AE$2)^-I2),"") | X2: =L2*W2+M2 | Y2: =IF(P2>0,(X2/P2)/$AE$3,"") | Z2: =IF(AND(ISNUMBER(K2),Q2>0),MAX(F2,0)*K2*1000000*E2,"pending") | AA2: =IF(AND(ISNUMBER(K2),R2>0),MAX(G2,0)*K2*1000000*E2,"pending") | AB2: =IF(AND(ISNUMBER(S2),S2<0),"NEG-CCE","")&IF(NOT(ISNUMBER(K2)),"|pending tonnage","") | AD2: Hurdle rate (sensitivity) | AE2: 0.15 | AG2: =IFERROR(_xlfn.XLOOKUP(A2,'product map'!$A$14:$A$36,'product map'!$C$14:$C$36),"?") | AH2: =IFERROR((Z2*0.000000947817)/_xlfn.XLOOKUP(AG2,'energy base (MECS)'!$K$4:$K$9,'energy base (MECS)'!$F$4:$F$9),0) | AI2: =IFERROR((AA2*0.000000947817)/_xlfn.XLOOKUP(AG2,'energy base (MECS)'!$K$4:$K$9,'energy base (MECS)'!$I$4:$I$9),0) | AJ2: =MAX(0.3*ABS(AK2),0.000001) | AK2: =IF(ISNUMBER(T2),T2,0) | AL2: =IFERROR(_xlfn.XLOOKUP(AG2,'BCoISC-WACCbI'!$C$2:$C$26,'BCoISC-WACCbI'!$B$2:$B$26)+$AE$4,0.1) | AM2: =IF(P2>0,L2/P2/0.947817,0) | AN2: =IF(AND(P2>0,ISNUMBER(K2)),L2*K2*1000000*E2,0)
A3: ='Kermeli Data'!A10 | B3: ='Kermeli Data'!B10 | C3: ='Kermeli Data'!P10 | D3: =IF(C3="2 whr","whr",IF(C3="3 proc","process","EXCLUDED")) | E3: ='Kermeli Data'!E10 | F3: ='Kermeli Data'!F10 | G3: ='Kermeli Data'!G10 | H3: ='Kermeli Data'!I10 | I3: ='Kermeli Data'!J10 | J3: ='Kermeli Data'!K10 | K3: =IFERROR(_xlfn.XLOOKUP(A3,'product map'!$A$14:$A$36,'product map'!$G$14:$G$36),"pending") | L3: =H3*cpi!$B$12*cpi!$B$10 | M3: =J3*cpi!$B$12*cpi!$B$10 | N3: =IF(I3>0,AL3/(1-(1+AL3)^-I3),"") | O3: =L3*N3+M3 | P3: =MAX(F3,0)+MAX(G3,0) | Q3: =IF(P3>0,MAX(F3,0)/P3,0) | R3: =IF(P3>0,MAX(G3,0)/P3,0) | S3: =IF(P3>0,O3/P3,"") | T3: =IF(P3>0,S3/$AE$3,"") | U3: =IF(AND(P3>0,Q3>0),T3,"") | V3: =IF(AND(P3>0,R3>0),T3,"") | W3: =IF(I3>0,$AE$2/(1-(1+$AE$2)^-I3),"") | X3: =L3*W3+M3 | Y3: =IF(P3>0,(X3/P3)/$AE$3,"") | Z3: =IF(AND(ISNUMBER(K3),Q3>0),MAX(F3,0)*K3*1000000*E3,"pending") | AA3: =IF(AND(ISNUMBER(K3),R3>0),MAX(G3,0)*K3*1000000*E3,"pending") | AB3: =IF(AND(ISNUMBER(S3),S3<0),"NEG-CCE","")&IF(NOT(ISNUMBER(K3)),"|pending tonnage","") | AD3: MMBtu per GJ (from cpi!B15) | AE3: =cpi!B15 | AG3: =IFERROR(_xlfn.XLOOKUP(A3,'product map'!$A$14:$A$36,'product map'!$C$14:$C$36),"?") | AH3: =IFERROR((Z3*0.000000947817)/_xlfn.XLOOKUP(AG3,'energy base (MECS)'!$K$4:$K$9,'energy base (MECS)'!$F$4:$F$9),0) | AI3: =IFERROR((AA3*0.000000947817)/_xlfn.XLOOKUP(AG3,'energy base (MECS)'!$K$4:$K$9,'energy base (MECS)'!$I$4:$I$9),0) | AJ3: =MAX(0.3*ABS(AK3),0.000001) | AK3: =IF(ISNUMBER(T3),T3,0) | AL3: =IFERROR(_xlfn.XLOOKUP(AG3,'BCoISC-WACCbI'!$C$2:$C$26,'BCoISC-WACCbI'!$B$2:$B$26)+$AE$4,0.1) | AM3: =IF(P3>0,L3/P3/0.947817,0) | AN3: =IF(AND(P3>0,ISNUMBER(K3)),L3*K3*1000000*E3,0)
A4: ='Kermeli Data'!A11 | B4: ='Kermeli Data'!B11 | C4: ='Kermeli Data'!P11 | D4: =IF(C4="2 whr","whr",IF(C4="3 proc","process","EXCLUDED")) | E4: ='Kermeli Data'!E11 | F4: ='Kermeli Data'!F11 | G4: ='Kermeli Data'!G11 | H4: ='Kermeli Data'!I11 | I4: ='Kermeli Data'!J11 | J4: ='Kermeli Data'!K11 | K4: =IFERROR(_xlfn.XLOOKUP(A4,'product map'!$A$14:$A$36,'product map'!$G$14:$G$36),"pending") | L4: =H4*cpi!$B$12*cpi!$B$10 | M4: =J4*cpi!$B$12*cpi!$B$10 | N4: =IF(I4>0,AL4/(1-(1+AL4)^-I4),"") | O4: =L4*N4+M4 | P4: =MAX(F4,0)+MAX(G4,0) | Q4: =IF(P4>0,MAX(F4,0)/P4,0) | R4: =IF(P4>0,MAX(G4,0)/P4,0) | S4: =IF(P4>0,O4/P4,"") | T4: =IF(P4>0,S4/$AE$3,"") | U4: =IF(AND(P4>0,Q4>0),T4,"") | V4: =IF(AND(P4>0,R4>0),T4,"") | W4: =IF(I4>0,$AE$2/(1-(1+$AE$2)^-I4),"") | X4: =L4*W4+M4 | Y4: =IF(P4>0,(X4/P4)/$AE$3,"") | Z4: =IF(AND(ISNUMBER(K4),Q4>0),MAX(F4,0)*K4*1000000*E4,"pending") | AA4: =IF(AND(ISNUMBER(K4),R4>0),MAX(G4,0)*K4*1000000*E4,"pending") | AB4: =IF(AND(ISNUMBER(S4),S4<0),"NEG-CCE","")&IF(NOT(ISNUMBER(K4)),"|pending tonnage","") | AD4: Hurdle premium (added to industry WACC) | AE4: 0.07 | AG4: =IFERROR(_xlfn.XLOOKUP(A4,'product map'!$A$14:$A$36,'product map'!$C$14:$C$36),"?") | AH4: =IFERROR((Z4*0.000000947817)/_xlfn.XLOOKUP(AG4,'energy base (MECS)'!$K$4:$K$9,'energy base (MECS)'!$F$4:$F$9),0) | AI4: =IFERROR((AA4*0.000000947817)/_xlfn.XLOOKUP(AG4,'energy base (MECS)'!$K$4:$K$9,'energy base (MECS)'!$I$4:$I$9),0) | AJ4: =MAX(0.3*ABS(AK4),0.000001) | AK4: =IF(ISNUMBER(T4),T4,0) | AL4: =IFERROR(_xlfn.XLOOKUP(AG4,'BCoISC-WACCbI'!$C$2:$C$26,'BCoISC-WACCbI'!$B$2:$B$26)+$AE$4,0.1) | AM4: =IF(P4>0,L4/P4/0.947817,0) | AN4: =IF(AND(P4>0,ISNUMBER(K4)),L4*K4*1000000*E4,0)
A5: ='Kermeli Data'!A12 | B5: ='Kermeli Data'!B12 | C5: ='Kermeli Data'!P12 | D5: =IF(C5="2 whr","whr",IF(C5="3 proc","process","EXCLUDED")) | E5: ='Kermeli Data'!E12 | F5: ='Kermeli Data'!F12 | G5: ='Kermeli Data'!G12 | H5: ='Kermeli Data'!I12 | I5: ='Kermeli Data'!J12 | J5: ='Kermeli Data'!K12 | K5: =IFERROR(_xlfn.XLOOKUP(A5,'product map'!$A$14:$A$36,'product map'!$G$14:$G$36),"pending") | L5: =H5*cpi!$B$12*cpi!$B$10 | M5: =J5*cpi!$B$12*cpi!$B$10 | N5: =IF(I5>0,AL5/(1-(1+AL5)^-I5),"") | O5: =L5*N5+M5 | P5: =MAX(F5,0)+MAX(G5,0) | Q5: =IF(P5>0,MAX(F5,0)/P5,0) | R5: =IF(P5>0,MAX(G5,0)/P5,0) | S5: =IF(P5>0,O5/P5,"") | T5: =IF(P5>0,S5/$AE$3,"") | U5: =IF(AND(P5>0,Q5>0),T5,"") | V5: =IF(AND(P5>0,R5>0),T5,"") | W5: =IF(I5>0,$AE$2/(1-(1+$AE$2)^-I5),"") | X5: =L5*W5+M5 | Y5: =IF(P5>0,(X5/P5)/$AE$3,"") | Z5: =IF(AND(ISNUMBER(K5),Q5>0),MAX(F5,0)*K5*1000000*E5,"pending") | AA5: =IF(AND(ISNUMBER(K5),R5>0),MAX(G5,0)*K5*1000000*E5,"pending") | AB5: =IF(AND(ISNUMBER(S5),S5<0),"NEG-CCE","")&IF(NOT(ISNUMBER(K5)),"|pending tonnage","") | AG5: =IFERROR(_xlfn.XLOOKUP(A5,'product map'!$A$14:$A$36,'product map'!$C$14:$C$36),"?") | AH5: =IFERROR((Z5*0.000000947817)/_xlfn.XLOOKUP(AG5,'energy base (MECS)'!$K$4:$K$9,'energy base (MECS)'!$F$4:$F$9),0) | AI5: =IFERROR((AA5*0.000000947817)/_xlfn.XLOOKUP(AG5,'energy base (MECS)'!$K$4:$K$9,'energy base (MECS)'!$I$4:$I$9),0) | AJ5: =MAX(0.3*ABS(AK5),0.000001) | AK5: =IF(ISNUMBER(T5),T5,0) | AL5: =IFERROR(_xlfn.XLOOKUP(AG5,'BCoISC-WACCbI'!$C$2:$C$26,'BCoISC-WACCbI'!$B$2:$B$26)+$AE$4,0.1) | AM5: =IF(P5>0,L5/P5/0.947817,0) | AN5: =IF(AND(P5>0,ISNUMBER(K5)),L5*K5*1000000*E5,0)
A6: ='Kermeli Data'!A13 | B6: ='Kermeli Data'!B13 | C6: ='Kermeli Data'!P13 | D6: =IF(C6="2 whr","whr",IF(C6="3 proc","process","EXCLUDED")) | E6: ='Kermeli Data'!E13 | F6: ='Kermeli Data'!F13 | G6: ='Kermeli Data'!G13 | H6: ='Kermeli Data'!I13 | I6: ='Kermeli Data'!J13 | J6: ='Kermeli Data'!K13 | K6: =IFERROR(_xlfn.XLOOKUP(A6,'product map'!$A$14:$A$36,'product map'!$G$14:$G$36),"pending") | L6: =H6*cpi!$B$12*cpi!$B$10 | M6: =J6*cpi!$B$12*cpi!$B$10 | N6: =IF(I6>0,AL6/(1-(1+AL6)^-I6),"") | O6: =L6*N6+M6 | P6: =MAX(F6,0)+MAX(G6,0) | Q6: =IF(P6>0,MAX(F6,0)/P6,0) | R6: =IF(P6>0,MAX(G6,0)/P6,0) | S6: =IF(P6>0,O6/P6,"") | T6: =IF(P6>0,S6/$AE$3,"") | U6: =IF(AND(P6>0,Q6>0),T6,"") | V6: =IF(AND(P6>0,R6>0),T6,"") | W6: =IF(I6>0,$AE$2/(1-(1+$AE$2)^-I6),"") | X6: =L6*W6+M6 | Y6: =IF(P6>0,(X6/P6)/$AE$3,"") | Z6: =IF(AND(ISNUMBER(K6),Q6>0),MAX(F6,0)*K6*1000000*E6,"pending") | AA6: =IF(AND(ISNUMBER(K6),R6>0),MAX(G6,0)*K6*1000000*E6,"pending") | AB6: =IF(AND(ISNUMBER(S6),S6<0),"NEG-CCE","")&IF(NOT(ISNUMBER(K6)),"|pending tonnage","") | AG6: =IFERROR(_xlfn.XLOOKUP(A6,'product map'!$A$14:$A$36,'product map'!$C$14:$C$36),"?") | AH6: =IFERROR((Z6*0.000000947817)/_xlfn.XLOOKUP(AG6,'energy base (MECS)'!$K$4:$K$9,'energy base (MECS)'!$F$4:$F$9),0) | AI6: =IFERROR((AA6*0.000000947817)/_xlfn.XLOOKUP(AG6,'energy base (MECS)'!$K$4:$K$9,'energy base (MECS)'!$I$4:$I$9),0) | AJ6: =MAX(0.3*ABS(AK6),0.000001) | AK6: =IF(ISNUMBER(T6),T6,0) | AL6: =IFERROR(_xlfn.XLOOKUP(AG6,'BCoISC-WACCbI'!$C$2:$C$26,'BCoISC-WACCbI'!$B$2:$B$26)+$AE$4,0.1) | AM6: =IF(P6>0,L6/P6/0.947817,0) | AN6: =IF(AND(P6>0,ISNUMBER(K6)),L6*K6*1000000*E6,0)
A7: ='Kermeli Data'!A14 | B7: ='Kermeli Data'!B14 | C7: ='Kermeli Data'!P14 | D7: =IF(C7="2 whr","whr",IF(C7="3 proc","process","EXCLUDED")) | E7: ='Kermeli Data'!E14 | F7: ='Kermeli Data'!F14 | G7: ='Kermeli Data'!G14 | H7: ='Kermeli Data'!I14 | I7: ='Kermeli Data'!J14 | J7: ='Kermeli Data'!K14 | K7: =IFERROR(_xlfn.XLOOKUP(A7,'product map'!$A$14:$A$36,'product map'!$G$14:$G$36),"pending") | L7: =H7*cpi!$B$12*cpi!$B$10 | M7: =J7*cpi!$B$12*cpi!$B$10 | N7: =IF(I7>0,AL7/(1-(1+AL7)^-I7),"") | O7: =L7*N7+M7 | P7: =MAX(F7,0)+MAX(G7,0) | Q7: =IF(P7>0,MAX(F7,0)/P7,0) | R7: =IF(P7>0,MAX(G7,0)/P7,0) | S7: =IF(P7>0,O7/P7,"") | T7: =IF(P7>0,S7/$AE$3,"") | U7: =IF(AND(P7>0,Q7>0),T7,"") | V7: =IF(AND(P7>0,R7>0),T7,"") | W7: =IF(I7>0,$AE$2/(1-(1+$AE$2)^-I7),"") | X7: =L7*W7+M7 | Y7: =IF(P7>0,(X7/P7)/$AE$3,"") | Z7: =IF(AND(ISNUMBER(K7),Q7>0),MAX(F7,0)*K7*1000000*E7,"pending") | AA7: =IF(AND(ISNUMBER(K7),R7>0),MAX(G7,0)*K7*1000000*E7,"pending") | AB7: =IF(AND(ISNUMBER(S7),S7<0),"NEG-CCE","")&IF(NOT(ISNUMBER(K7)),"|pending tonnage","") | AG7: =IFERROR(_xlfn.XLOOKUP(A7,'product map'!$A$14:$A$36,'product map'!$C$14:$C$36),"?") | AH7: =IFERROR((Z7*0.000000947817)/_xlfn.XLOOKUP(AG7,'energy base (MECS)'!$K$4:$K$9,'energy base (MECS)'!$F$4:$F$9),0) | AI7: =IFERROR((AA7*0.000000947817)/_xlfn.XLOOKUP(AG7,'energy base (MECS)'!$K$4:$K$9,'energy base (MECS)'!$I$4:$I$9),0) | AJ7: =MAX(0.3*ABS(AK7),0.000001) | AK7: =IF(ISNUMBER(T7),T7,0) | AL7: =IFERROR(_xlfn.XLOOKUP(AG7,'BCoISC-WACCbI'!$C$2:$C$26,'BCoISC-WACCbI'!$B$2:$B$26)+$AE$4,0.1) | AM7: =IF(P7>0,L7/P7/0.947817,0) | AN7: =IF(AND(P7>0,ISNUMBER(K7)),L7*K7*1000000*E7,0)
A8: ='Kermeli Data'!A15 | B8: ='Kermeli Data'!B15 | C8: ='Kermeli Data'!P15 | D8: =IF(C8="2 whr","whr",IF(C8="3 proc","process","EXCLUDED")) | E8: ='Kermeli Data'!E15 | F8: ='Kermeli Data'!F15 | G8: ='Kermeli Data'!G15 | H8: ='Kermeli Data'!I15 | I8: ='Kermeli Data'!J15 | J8: ='Kermeli Data'!K15 | K8: =IFERROR(_xlfn.XLOOKUP(A8,'product map'!$A$14:$A$36,'product map'!$G$14:$G$36),"pending") | L8: =H8*cpi!$B$12*cpi!$B$10 | M8: =J8*cpi!$B$12*cpi!$B$10 | N8: =IF(I8>0,AL8/(1-(1+AL8)^-I8),"") | O8: =L8*N8+M8 | P8: =MAX(F8,0)+MAX(G8,0) | Q8: =IF(P8>0,MAX(F8,0)/P8,0) | R8: =IF(P8>0,MAX(G8,0)/P8,0) | S8: =IF(P8>0,O8/P8,"") | T8: =IF(P8>0,S8/$AE$3,"") | U8: =IF(AND(P8>0,Q8>0),T8,"") | V8: =IF(AND(P8>0,R8>0),T8,"") | W8: =IF(I8>0,$AE$2/(1-(1+$AE$2)^-I8),"") | X8: =L8*W8+M8 | Y8: =IF(P8>0,(X8/P8)/$AE$3,"") | Z8: =IF(AND(ISNUMBER(K8),Q8>0),MAX(F8,0)*K8*1000000*E8,"pending") | AA8: =IF(AND(ISNUMBER(K8),R8>0),MAX(G8,0)*K8*1000000*E8,"pending") | AB8: =IF(AND(ISNUMBER(S8),S8<0),"NEG-CCE","")&IF(NOT(ISNUMBER(K8)),"|pending tonnage","") | AG8: =IFERROR(_xlfn.XLOOKUP(A8,'product map'!$A$14:$A$36,'product map'!$C$14:$C$36),"?") | AH8: =IFERROR((Z8*0.000000947817)/_xlfn.XLOOKUP(AG8,'energy base (MECS)'!$K$4:$K$9,'energy base (MECS)'!$F$4:$F$9),0) | AI8: =IFERROR((AA8*0.000000947817)/_xlfn.XLOOKUP(AG8,'energy base (MECS)'!$K$4:$K$9,'energy base (MECS)'!$I$4:$I$9),0) | AJ8: =MAX(0.3*ABS(AK8),0.000001) | AK8: =IF(ISNUMBER(T8),T8,0) | AL8: =IFERROR(_xlfn.XLOOKUP(AG8,'BCoISC-WACCbI'!$C$2:$C$26,'BCoISC-WACCbI'!$B$2:$B$26)+$AE$4,0.1) | AM8: =IF(P8>0,L8/P8/0.947817,0) | AN8: =IF(AND(P8>0,ISNUMBER(K8)),L8*K8*1000000*E8,0)
