Workbook
Name gal_per_barrel: [1]About!$A$63

Sheet About
A1: BIFUbC BAU Industrial Fuel Use before CCS
A3: Sources: | B3: All Subscripts Except Waste Management | D3: Properties of Hydrogen Fuel
B4: Energy Information Administration | D4: Pacific Northwest National Laboratory
B5: 2025 | D5: Accessed 2022
B6: Annual Energy Outlook 2025 (the High Zero-Carbon Technology Cost scenario for most industries and the Alternate Transportation scenario for refined petroleum and coke and chemicals) | D6: Hydrogen Analysis Resource Center
B7: https://www.eia.gov/outlooks/aeo/ | D7: https://h2tools.org/hyarc/hydrogen-data/lower-and-higher-heating-values-hydrogen-and-other-fuels
B8: See below for listing of which tables are used for which data | D8: Lower and Higher Heating Values.xlsx
B10: Waste Management
B11: Energy Information Administration
B12: 2021
B13: Miscellaneous Electric Load Consumption Characterization 2021 Update
B14: https://www.eia.gov/analysis/studies/demand/miscelectric/pdf/miscelectric.pdf
B16: Reallocating Portions of "Balance of Manufacturing" to Specific Industry Categories
B17: U.S. Bureau of Economic Analysis
B18: 2025 (with data for 2017)
B19: https://apps.bea.gov/iTable/?reqid=1602&step=2&Categories=AR&isURI=1&_gl=1*1mimqnw*_ga*MTQwODg4MjA3OC4xNzY2NDQ0MTUw*_ga_J4698JNNFT*czE3NjY0NDQxNDkkbzEkZzEkdDE3NjY0NDU2MDIkajU4JGwwJGgw#eyJhcHBpZCI6MTYwMiwic3RlcHMiOlsxLDIsM10sImRhdGEiOltbImNhdGVnb3JpZXMiLCJBUiJdLFsiVGFibGVfTGlzdCIsIlVzZUFSUHJvIl1dfQ==
B20: "Use of Commodities by Industry" table, 405-industry breakdown
A22: Note:
A23: The words "before CCS" in this variable name indicate that this is the fuel use by industry, excluding
A24: any fuel used to power the energy-intensive process of carbon capture and sequestration. If any CCS
A25: is performed by Industry in the BAU case, this is handled in CCS sector input variables, not here.
A27: EIA Data Source and Adjustments
A28: EIA provided a detailed industrial energy consumption file from the AEO that they run on request (titled indusa),
A29: which contains several more industry categories than available online. We use this file directly for most
A30: energy consumption. However, there are a few places where we supplement with the published AEO
A31: tables where they contain data not shown in the detailed table (e.g. some refining energy consumption).
A33: The following table provides a key to the AEO data sources available for each EPS Industry Category.
A34: The places where the indusa is supplemented by the main AEO tables is also noted by red color coding
A35: in the output tabs.
... A44: Note the special handling for the hydrogen output tab, discussed below.
B46: EPS Industry Category | C46: AEO Data Source
B47: agriculture and forestry 01T03 | C47: indusa
B48: coal mining 05 | C48: indusa
B49: oil and gas extraction 06 | C49: indusa, adds Lease and Plant Fuel from Table 34 into the natural gas category (this is mapped to production instead of the "energy pipelines and gas processing" category because of how changes in energy consumption and emissions in the EPS Industry sector are calculated, as processing enegy use/emissions are more correlated with the amount of domestic production rather than the amount of domestic demand)
B50: other mining and quarrying 07T08 | C50: indusa
B51: food beverage and tobacco 10T12 | C51: indusa
B52: textiles apparel and leather 13T15 | C52: indusa
B53: wood products 16 | C53: indusa
B54: pulp paper and printing 17T18 | C54: indusa
B55: refined petroleum and coke 19 | C55: indusa (Alt Trans case), plus several tabs include line items from Table 24 that are not included in the indusa file; crude oil inputs are calculated based on Tables 24 and 11
...

Sheet AEO 2025 Table 11 Alt Trans
B1: alttrnp.d032125a | AE1: 2048 | AF1: 2049 | AG1: 2050
C3: Report | D3: Annual Energy Outlook 2025
C4: Scenario | D4: alttrnp | F4: Alternative Transportation
C5: Datekey | D5: d032125a
C6: Release Date | E6: April 2025
B7: 11. Petroleum and Other Liquids Supply and Disposition | AH7: Average
B8: (million barrels per day, unless otherwise noted) | AH8: Annual
AD9: Avg Annual Change | AH9: Change
B10: Supply and Disposition | C10: 2024 | D10: 2025 | E10: 2026 | F10: 2027 | G10: 2028 | H10: 2029 | I10: 2030 | J10: 2031 | K10: 2032 | L10: 2033 | M10: 2034 | N10: 2035 | O10: 2036 | P10: 2037 | Q10: 2038 | R10: 2039 | S10: 2040 | T10: 2041 | U10: 2042 | V10: 2043 | W10: 2044 | X10: 2045 | Y10: 2046 | Z10: 2047 | AA10: 2048 | AB10: 2049 | AC10: 2050 | AD10: 2024-2050 | AE10: 2048 | AF10: 2049 | AG10: 2050 | AH10: 2022–2050
B12: Crude Oil
A13: PSD000:ba_DomesticCrude | B13: Domestic Crude Production 1/ | C13: 13.266058 | D13: 13.693652 | E13: 13.839074 | F13: 14.038465 | G13: 14.011215 | H13: 14.015731 | I13: 13.940209 | J13: 13.756026 | K13: 13.561993 | L13: 13.430722 | M13: 13.346446 | N13: 13.136957 | O13: 12.949175 | P13: 12.84719 | Q13: 12.758718 | R13: 12.588844 | S13: 12.433366 | T13: 12.430215 | U13: 12.487457 | V13: 12.401797 | W13: 12.272331 | X13: 12.159727 | Y13: 12.08534 | Z13: 12.215338 | AA13: 12.170947 | AB13: 12.05266 | AC13: 11.838856 | AD13: -0.0043681915 | AE13: 13.064216 | AF13: 13.201051 | AG13: 13.238148 | AH13: 0.00403
A14: PSD000:ba_Alaska | B14: Alaska | C14: 0.41062087 | D14: 0.39963207 | E14: 0.40487066 | F14: 0.46422005 | G14: 0.56030095 | H14: 0.60315979 | I14: 0.60611278 | J14: 0.62792921 | K14: 0.66175401 | L14: 0.71722645 | M14: 0.71032172 | N14: 0.68120486 | O14: 0.64413589 | P14: 0.61198485 | Q14: 0.57338315 | R14: 0.53106153 | S14: 0.48933902 | T14: 0.45479003 | U14: 0.42676017 | V14: 0.4074499 | W14: 0.38954821 | X14: 0.37030914 | Y14: 0.35324398 | Z14: 0.338072 | AA14: 0.32455087 | AB14: 0.31247112 | AC14: 0.28727165 | AD14: -0.013646115 | AE14: 0.764543 | AF14: 0.759241 | AG14: 0.728145 | AH14: 0.018448
A15: PSD000:ba_Lower48States | B15: Lower 48 States | C15: 12.855437 | D15: 13.29402 | E15: 13.434203 | F15: 13.574244 | G15: 13.450914 | H15: 13.412571 | I15: 13.334097 | J15: 13.128097 | K15: 12.900238 | L15: 12.713495 | M15: 12.636125 | N15: 12.455752 | O15: 12.305039 | P15: 12.235205 | Q15: 12.185335 | R15: 12.057782 | S15: 11.944027 | T15: 11.975426 | U15: 12.060698 | V15: 11.994348 | W15: 11.882784 | X15: 11.789417 | Y15: 11.732097 | Z15: 11.877266 | AA15: 11.846396 | AB15: 11.740189 | AC15: 11.551584 | AD15: -0.0041047932 | AE15: 12.299672 | AF15: 12.441811 | AG15: 12.510002 | AH15: 0.003349
A16: PSD000:ba_NetImports | B16: Net Imports | C16: 2.4549999 | D16: 1.8920002 | E16: 2.1775162 | F16: 1.9933624 | G16: 2.1656954 | H16: 2.313693 | I16: 2.4252987 | J16: 2.7585728 | K16: 3.0392106 | L16: 3.0914676 | M16: 3.2355583 | N16: 3.3848877 | O16: 3.5184855 | P16: 3.5493448 | Q16: 3.6603484 | R16: 3.9512239 | S16: 4.0562949 | T16: 4.0106273 | U16: 3.7918098 | V16: 3.9335723 | W16: 4.0717936 | X16: 4.2653069 | Y16: 4.2957578 | Z16: 4.1539917 | AA16: 4.2179379 | AB16: 4.3336339 | AC16: 4.6391878 | AD16: 0.024779438 | AE16: 3.920272 | AF16: 3.804193 | AG16: 3.70923 | AH16: 0.009909
A17: PSD000:ba_GrossImports | B17: Gross Imports | C17: 6.585 | D17: 6.0910001 | E17: 6.3381681 | F17: 6.0013413 | G17: 6.2358308 | H17: 6.3450432 | I17: 6.356637 | J17: 6.5245132 | K17: 6.8713169 | L17: 6.8747983 | M17: 7.0884843 | N17: 7.1651192 | O17: 7.2640347 | P17: 7.1343379 | Q17: 7.1455827 | R17: 7.3101044 | S17: 7.3866124 | T17: 7.3212247 | U17: 7.1790562 | V17: 7.2514606 | W17: 7.3556213 | X17: 7.4329057 | Y17: 7.2070584 | Z17: 7.0455523 | AA17: 7.037344 | AB17: 7.2015338 | AC17: 7.427247 | AD17: 0.0046399982 | AE17: 6.913453 | AF17: 6.763233 | AG17: 6.649956 | AH17: 0.002081
A18: PSD000:ba_Exports | B18: Exports | C18: 4.1300001 | D18: 4.1989999 | E18: 4.1606517 | F18: 4.0079789 | G18: 4.0701356 | H18: 4.0313501 | I18: 3.9313383 | J18: 3.7659404 | K18: 3.8321061 | L18: 3.7833304 | M18: 3.852926 | N18: 3.7802315 | O18: 3.745549 | P18: 3.5849934 | Q18: 3.4852343 | R18: 3.3588803 | S18: 3.3303175 | T18: 3.3105974 | U18: 3.3872464 | V18: 3.3178883 | W18: 3.2838275 | X18: 3.167599 | Y18: 2.9113004 | Z18: 2.8915603 | AA18: 2.8194063 | AB18: 2.8678997 | AC18: 2.7880592 | AD18: -0.014999133 | AE18: 2.993181 | AF18: 2.95904 | AG18: 2.940725 | AH18: -0.005787
A19: PSD000:ba_OtherCrudeSup | B19: Other Crude Supply 2/ | C19: 0.53499997 | D19: 0.57100004 | E19: 0.10617 | F19: 0.10548 | G19: 0.070079997 | H19: 0.059999999 | I19: 0.059999999 | J19: 0.059999999 | K19: 0 | L19: 0 | M19: 0 | N19: 0 | O19: 0 | P19: 0 | Q19: 0 | R19: 0 | S19: 0 | T19: 0 | U19: 0 | V19: 0 | W19: 0 | X19: 0 | Y19: 0 | Z19: 0 | AA19: 0 | AB19: 0 | AC19: 0 | AD19: -- | AE19: 0 | AF19: 0 | AG19: 0 | AH19: --
A20: PSD000:ba_TotalCrudeSup | B20: Total Crude Supply | C20: 16.256058 | D20: 16.156652 | E20: 16.122761 | F20: 16.137306 | G20: 16.24699 | H20: 16.389423 | I20: 16.425508 | J20: 16.574598 | K20: 16.601204 | L20: 16.52219 | M20: 16.582005 | N20: 16.521845 | O20: 16.467661 | P20: 16.396534 | Q20: 16.419067 | R20: 16.540068 | S20: 16.48966 | T20: 16.440842 | U20: 16.279266 | V20: 16.335369 | W20: 16.344124 | X20: 16.425034 | Y20: 16.381098 | Z20: 16.369329 | AA20: 16.388885 | AB20: 16.386293 | AC20: 16.478043 | AD20: 0.00052179455 | AE20: 16.984488 | AF20: 17.005243 | AG20: 16.947378 | AH20: 0.003854
A22: PSD000:ca_NetProductImp | B22: Net Product Imports | C22: -4.7969999 | D22: -4.4340005 | E22: -5.3931117 | F22: -5.6637378 | G22: -5.8147402 | H22: -6.0862393 | I22: -6.3148069 | J22: -6.4986482 | K22: -6.7580967 | L22: -6.8829226 | M22: -7.1004648 | N22: -7.2989154 | O22: -7.3504176 | P22: -7.3862834 | Q22: -7.55582 | R22: -7.7120018 | S22: -7.6603565 | T22: -7.6474137 | U22: -7.5461054 | V22: -7.6730962 | W22: -7.7635083 | X22: -7.9331498 | Y22: -8.0228386 | Z22: -8.0455475 | AA22: -8.0462437 | AB22: -7.9991622 | AC22: -8.0336752 | AD22: 0.020030722 | AE22: -6.658555 | AF22: -6.624732 | AG22: -6.431421 | AH22: 0.017224
A23: PSD000:ca_GrossRefinedP | B23: Gross Refined Product Imports 3/ | C23: 0.66500002 | D23: 0.65899998 | E23: 0.74173576 | F23: 0.74009639 | G23: 0.73737037 | H23: 0.73435467 | I23: 0.74169171 | J23: 0.75268632 | K23: 0.75330985 | L23: 0.75508237 | M23: 0.75996852 | N23: 0.76140255 | O23: 0.76254404 | P23: 0.76617682 | Q23: 0.76701474 | R23: 0.76568347 | S23: 0.76656389 | T23: 0.77134937 | U23: 0.77358657 | V23: 0.77358884 | W23: 0.77418184 | X23: 0.78442264 | Y23: 0.7686832 | Z23: 0.76776731 | AA23: 0.79498076 | AB23: 0.79559314 | AC23: 0.77234918 | AD23: 0.0057723531 | AE23: 0.805134 | AF23: 0.810104 | AG23: 0.773733 | AH23: -0.009681
A24: PSD000:ca_UnfinishedOil | B24: Unfinished Oil Imports | C24: 0.59200001 | D24: 0.58200002 | E24: 0.59942865 | F24: 0.59710908 | G24: 0.59515744 | H24: 0.59320581 | I24: 0.58276296 | J24: 0.58930254 | K24: 0.5790931 | L24: 0.57725811 | M24: 0.57542318 | N24: 0.57395619 | O24: 0.57212126 | P24: 0.57028633 | Q24: 0.5684514 | R24: 0.55160463 | S24: 0.5497697 | T24: 0.54756814 | U24: 0.56073201 | V24: 0.55889708 | W24: 0.55706209 | X24: 0.54001164 | Y24: 0.55302429 | Z24: 0.55285913 | AA24: 0.55238223 | AB24: 0.5475902 | AC24: 0.53426778 | AD24: -0.0039387407 | AE24: 0.549354 | AF24: 0.54752 | AG24: 0.545493 | AH24: -0.009369
A25: PSD000:ca_BlendingCompo | B25: Blending Component Imports | C25: 0.60500002 | D25: 0.60500002 | E25: 0.53568333 | F25: 0.48372349 | G25: 0.4439463 | H25: 0.41017503 | I25: 0.37991047 | J25: 0.35651109 | K25: 0.33064896 | L25: 0.31053254 | M25: 0.29528698 | N25: 0.27803043 | O25: 0.27208009 | P25: 0.26686966 | Q25: 0.26301065 | R25: 0.26084292 | S25: 0.25915292 | T25: 0.25786659 | U25: 0.25322995 | V25: 0.25596577 | W25: 0.2564913 | X25: 0.25691581 | Y25: 0.25923806 | Z25: 0.261724 | AA25: 0.26749563 | AB25: 0.27378368 | AC25: 0.27946764 | AD25: -0.02926859 | AE25: 0.380901 | AF25: 0.387239 | AG25: 0.393548 | AH25: -0.004218
A26: PSD000:ca_Exports | B26: Exports | C26: 6.6589999 | D26: 6.2800002 | E26: 7.2699594 | F26: 7.4846668 | G26: 7.5912142 | H26: 7.8239746 | I26: 8.0191717 | J26: 8.1971483 | K26: 8.4211483 | L26: 8.5257959 | M26: 8.731144 | N26: 8.9123039 | O26: 8.9571629 | P26: 8.9896164 | Q26: 9.1542969 | R26: 9.2901335 | S26: 9.2358427 | T26: 9.2241983 | U26: 9.1336536 | V26: 9.261548 | W26: 9.351244 | X26: 9.5144997 | Y26: 9.6037836 | Z26: 9.6278982 | AA26: 9.6611023 | AB26: 9.6161289 | AC26: 9.6197605 | AD26: 0.014248637 | AE26: 8.393944 | AF26: 8.369595 | AG26: 8.144195 | AH26: 0.010046
A27: PSD000:ca_RefineryProce | B27: Refinery Processing Gain 4/ | C27: 0.98000002 | D27: 1.016 | E27: 0.90159047 | F27: 0.87853771 | G27: 0.91380489 | H27: 0.93051493 | I27: 0.93910778 | J27: 0.93981522 | K27: 0.9594422 | L27: 0.95770127 | M27: 0.96941692 | N27: 0.96152616 | O27: 0.97701991 | P27: 0.97750109 | Q27: 0.97359896 | R27: 0.98396575 | S27: 0.98303294 | T27: 0.98112708 | U27: 0.97470093 | V27: 0.97656184 | W27: 0.97273654 | X27: 0.97380805 | Y27: 0.96531028 | Z27: 0.96246451 | AA27: 0.96213937 | AB27: 0.95689845 | AC27: 0.96412009 | AD27: -0.00062813839 | AE27: 0.973956 | AF27: 0.974545 | AG27: 0.965124 | AH27: -0.001622
A28: PSD000:ProductStockDraw | B28: Product Stock Withdrawal | C28: 0.048 | D28: -0.011 | E28: 0 | F28: 0 | G28: 0 | H28: 0 | I28: 0 | J28: 0 | K28: 0 | L28: 0 | M28: 0 | N28: 0 | O28: 0 | P28: 0 | Q28: 0 | R28: 0 | S28: 0 | T28: 0 | U28: 0 | V28: 0 | W28: 0 | X28: 0 | Y28: 0 | Z28: 0 | AA28: 0 | AB28: 0 | AC28: 0 | AD28: -- | AE28: 0 | AF28: 0 | AG28: 0 | AH28: --
A29: PSD000:ca_NaturalGasPla | B29: Natural Gas Plant Liquids | C29: 6.8487673 | D29: 6.9222689 | E29: 7.4246435 | F29: 7.6437483 | G29: 7.6547918 | H29: 7.6884294 | I29: 7.7403307 | J29: 7.6810575 | K29: 7.7766018 | L29: 7.8726325 | M29: 7.9454503 | N29: 8.1236935 | O29: 8.1454334 | P29: 8.2023191 | Q29: 8.2853785 | R29: 8.2694407 | S29: 8.2659359 | T29: 8.2955713 | U29: 8.3512173 | V29: 8.4079313 | W29: 8.4561825 | X29: 8.518302 | Y29: 8.6038322 | Z29: 8.6799364 | AA29: 8.7107763 | AB29: 8.7141981 | AC29: 8.6905966 | AD29: 0.0092025823 | AE29: 7.166816 | AF29: 7.201195 | AG29: 7.223709 | AH29: 0.006831
A30: PSD000:ca_Hydrogeb | B30: Hydrogen 5/ | C30: 8.3062735 | D30: 8.3583136 | E30: 8.9121571 | F30: 9.1428165 | G30: 9.0858173 | H30: 9.1176319 | I30: 9.1689453 | J30: 9.1082878 | K30: 9.2017498 | L30: 9.2964916 | M30: 9.3937244 | N30: 9.5747032 | O30: 9.5822945 | P30: 9.6281366 | Q30: 9.7292938 | R30: 9.7108603 | S30: 9.7017021 | T30: 9.7291346 | U30: 9.7831783 | V30: 9.838479 | W30: 9.8863745 | X30: 9.9508924 | Y30: 10.044309 | Z30: 10.134096 | AA30: 10.167455 | AB30: 10.181632 | AC30: 10.171256 | AD30: 0.0078209885
A31: PSD000:from_Renewables | B31: Biofuels | C31: 1.2375062 | D31: 1.2160439 | E31: 1.2622174 | F31: 1.2737726 | G31: 1.2059509 | H31: 1.205182 | I31: 1.2033191 | J31: 1.2019346 | K31: 1.1998516 | L31: 1.1985633 | M31: 1.2229778 | N31: 1.2257136 | O31: 1.2115651 | P31: 1.2005217 | Q31: 1.2186189 | R31: 1.2161235 | S31: 1.2104707 | T31: 1.2082673 | U31: 1.2066653 | V31: 1.2052517 | W31: 1.204896 | X31: 1.2072945 | Y31: 1.2151804 | Z31: 1.2288632 | AA31: 1.2313821 | AB31: 1.2421379 | AC31: 1.2553636 | AD31: 0.00055119233 | AE31: 1.163749 | AF31: 1.181888 | AG31: 1.196141 | AH31: 0.001356
A32: PSD000:cb_TotalEthanol | B32: Ethanol (undenatured) | C32: 0.89962983 | D32: 0.90398222 | E32: 0.92223638 | F32: 0.9248206 | G32: 0.92163283 | H32: 0.91708481 | I32: 0.91132659 | J32: 0.90740526 | K32: 0.90213406 | L32: 0.898054 | M32: 0.89526153 | N32: 0.89227635 | O32: 0.88661826 | P32: 0.88121343 | Q32: 0.87751985 | R32: 0.87381512 | S32: 0.87144601 | T32: 0.86933738 | U32: 0.86621034 | V32: 0.86530417 | W32: 0.86331224 | X32: 0.86287463 | Y32: 0.86172152 | Z32: 0.86258709 | AA32: 0.86133522 | AB32: 0.86205858 | AC32: 0.8650347 | AD32: -0.0015070847 | AE32: 0.858167 | AF32: 0.86727 | AG32: 0.878013 | AH32: -0.000415
A33: PSD000:ca_DomesticEthan | B33: Domestic Production | C33: 1.0228798 | D33: 1.0248302 | E33: 1.0403882 | F33: 1.0419692 | G33: 1.0420033 | H33: 1.0426598 | I33: 1.0419941 | J33: 1.041517 | K33: 1.0413069 | L33: 1.0418068 | M33: 1.0419081 | N33: 1.0411739 | O33: 1.0428159 | P33: 1.0448785 | Q33: 1.0452884 | R33: 1.0493288 | S33: 1.055146 | T33: 1.0576329 | U33: 1.0592115 | V33: 1.0711412 | W33: 1.0752956 | X33: 1.0801607 | Y33: 1.0844382 | Z33: 1.0908749 | AA33: 1.0953219 | AB33: 1.1018975 | AC33: 1.1049199 | AD33: 0.0029717466 | AE33: 1.102327 | AF33: 1.113072 | AG33: 1.121086 | AH33: 0.004852
A34: PSD000:ca_EthanolImport | B34: Net Imports | C34: -0.12325 | D34: -0.120848 | E34: -0.11815185 | F34: -0.11714857 | G34: -0.12037047 | H34: -0.12557498 | I34: -0.13066749 | J34: -0.13411175 | K34: -0.13917278 | L34: -0.14375283 | M34: -0.14664665 | N34: -0.14889759 | O34: -0.15619764 | P34: -0.16366504 | Q34: -0.16776858 | R34: -0.1755137 | S34: -0.1837 | T34: -0.18829556 | U34: -0.19300112 | V34: -0.20583709 | W34: -0.21198334 | X34: -0.21728612 | Y34: -0.22271666 | Z34: -0.22828779 | AA34: -0.23398666 | AB34: -0.23983888 | AC34: -0.23988521 | AD34: 0.025944135 | AE34: -0.24416 | AF34: -0.245802 | AG34: -0.243073 | AH34: 0.035821
A35: PSD000:cb_TotalBiodiesl | B35: Biodiesel | C35: 0.12139644 | D35: 0.10103945 | E35: 0.10270155 | F35: 0.096831784 | G35: 0.059198756 | H35: 0.069466762 | I35: 0.07241486 | J35: 0.073744856 | K35: 0.074368209 | L35: 0.077496417 | M35: 0.084545314 | N35: 0.089571968 | O35: 0.088854894 | P35: 0.093317956 | Q35: 0.092993245 | R35: 0.091702439 | S35: 0.090348974 | T35: 0.088931568 | U35: 0.087448962 | V35: 0.085899837 | W35: 0.084543794 | X35: 0.082857601 | Y35: 0.081100821 | Z35: 0.079272017 | AA35: 0.077369772 | AB35: 0.075392589 | AC35: 0.073338971 | AD35: -0.019196788 | AE35: 0.060377 | AF35: 0.057682 | AG35: 0.054987 | AH35: --
A36: PSD000:cb_DomesticBiodi | B36: Domestic Production | C36: 0.108 | D36: 0.10557124 | E36: 0.094603211 | F36: 0.088692948 | G36: 0.051019225 | H36: 0.061246332 | I36: 0.064153329 | J36: 0.065442018 | K36: 0.066023856 | L36: 0.069110341 | M36: 0.076117307 | N36: 0.081101827 | O36: 0.080342397 | P36: 0.084762901 | Q36: 0.084395416 | R36: 0.083061621 | S36: 0.08166495 | T36: 0.080204122 | U36: 0.078677878 | V36: 0.077084899 | W36: 0.075684778 | X36: 0.073954292 | Y36: 0.072152995 | Z36: 0.070279457 | AA36: 0.068332247 | AB36: 0.066309877 | AC36: 0.064210847 | AD36: -0.019799782 | AE36: 0.051339 | AF36: 0.048599 | AG36: 0.045859 | AH36: -0.029806
A37: PSD000:cb_BiodieselImpo | B37: Net Imports | C37: 0.013396445 | D37: -0.0045317831 | E37: 0.0080983434 | F37: 0.0081388364 | G37: 0.0081795305 | H37: 0.0082204277 | I37: 0.0082615297 | J37: 0.0083028376 | K37: 0.0083443513 | L37: 0.0083860727 | M37: 0.0084280036 | N37: 0.0084701432 | O37: 0.0085124942 | P37: 0.0085550565 | Q37: 0.0085978322 | R37: 0.0086408211 | S37: 0.0086840251 | T37: 0.0087274453 | U37: 0.0087710833 | V37: 0.0088149374 | W37: 0.0088590123 | X37: 0.0089033078 | Y37: 0.0089478241 | Z37: 0.008992563 | AA37: 0.0090375263 | AB37: 0.0090827141 | AC37: 0.0091281272 | AD37: -0.014646633 | AE37: 0.009038 | AF37: 0.009083 | AG37: 0.009128 | AH37: --
A38: PSD000:cb_TotalRenewableBiodiesl | B38: Renewable Diesel | C38: 0.21056423 | D38: 0.20132892 | E38: 0.22745721 | F38: 0.22205755 | G38: 0.19547884 | H38: 0.18923268 | I38: 0.19006601 | J38: 0.19125785 | K38: 0.19378066 | L38: 0.19346045 | M38: 0.21322477 | N38: 0.21391486 | O38: 0.2063068 | P38: 0.19575992 | Q38: 0.21744311 | R38: 0.21990336 | S38: 0.21802208 | T38: 0.21932875 | U38: 0.22228675 | V38: 0.22331826 | W38: 0.22626144 | X38: 0.23070426 | Y38: 0.2412954 | Z38: 0.25565976 | AA38: 0.26123065 | AB38: 0.27301162 | AC38: 0.28508034 | AD38: 0.011721251 | AE38: 0.240211 | AF38: 0.251702 | AG38: 0.257954 | AH38: 0.017899
A39: PSD000:cb_DomesticBiodi | B39: Domestic Production | C39: 0.17383203 | D39: 0.17999749 | E39: 0.1864015 | F39: 0.18048865 | G39: 0.15926315 | H39: 0.15256429 | I39: 0.15293926 | J39: 0.15366702 | K39: 0.15571994 | L39: 0.15492398 | M39: 0.17420658 | N39: 0.17440894 | O39: 0.16630706 | P39: 0.15526019 | Q39: 0.17643712 | R39: 0.17838481 | S39: 0.17598455 | T39: 0.17676574 | U39: 0.17919171 | V39: 0.17968453 | W39: 0.18208228 | X39: 0.18597287 | Y39: 0.19600487 | Z39: 0.20980309 | AA39: 0.21480079 | AB39: 0.22600137 | AC39: 0.23748246 | AD39: 0.012072455 | AE39: 0.193781 | AF39: 0.204692 | AG39: 0.210356 | AH39: 0.015761
A40: PSD000:cb_BiodieselImpo | B40: Net Imports | C40: 0.036732204 | D40: 0.021331433 | E40: 0.041055705 | F40: 0.041568901 | G40: 0.036215696 | H40: 0.036668394 | I40: 0.037126746 | J40: 0.037590832 | K40: 0.038060717 | L40: 0.038536478 | M40: 0.03901818 | N40: 0.03950591 | O40: 0.039999735 | P40: 0.040499728 | Q40: 0.041005976 | R40: 0.04151855 | S40: 0.042037532 | T40: 0.042563003 | U40: 0.043095041 | V40: 0.043633729 | W40: 0.044179149 | X40: 0.04473139 | Y40: 0.04529053 | Z40: 0.045856662 | AA40: 0.046429869 | AB40: 0.047010247 | AC40: 0.047597874 | AD40: 0.010016534 | AE40: 0.04643 | AF40: 0.04701 | AG40: 0.047598 | AH40: 0.029306
A41: PSD000:Other_BM-derived | B41: Other Biomass-derived Liquids 6/ | C41: 0.0059156041 | D41: 0.0096933525 | E41: 0.0098222801 | F41: 0.030062634 | G41: 0.029640473 | H41: 0.02939764 | I41: 0.029511649 | J41: 0.029526625 | K41: 0.029568642 | L41: 0.029552519 | M41: 0.029946186 | N41: 0.029950442 | O41: 0.029785194 | P41: 0.03023036 | Q41: 0.030662647 | R41: 0.030702494 | S41: 0.030653605 | T41: 0.030669641 | U41: 0.030719234 | V41: 0.030729385 | W41: 0.030778408 | X41: 0.0308579 | Y41: 0.03106273 | Z41: 0.031344425 | AA41: 0.031446498 | AB41: 0.031675179 | AC41: 0.031909589 | AD41: 0.066966663 | AE41: 0.004994 | AF41: 0.005235 | AG41: 0.005188 | AH41: 0.016102
A42: PSD000:Other_BM_Dome | B42: Domestic Production | C42: 0.0059156041 | D42: 0.0096933525 | E42: 0.0098222801 | F42: 0.030062634 | G42: 0.029640473 | H42: 0.02939764 | I42: 0.029511649 | J42: 0.029526625 | K42: 0.029568642 | L42: 0.029552519 | M42: 0.029946186 | N42: 0.029950442 | O42: 0.029785194 | P42: 0.03023036 | Q42: 0.030662647 | R42: 0.030702494 | S42: 0.030653605 | T42: 0.030669641 | U42: 0.030719234 | V42: 0.030729385 | W42: 0.030778408 | X42: 0.0308579 | Y42: 0.03106273 | Z42: 0.031344425 | AA42: 0.031446498 | AB42: 0.031675179 | AC42: 0.031909589 | AD42: 0.066966663 | AE42: 0.004994 | AF42: 0.005235 | AG42: 0.005188 | AH42: 0.016102
A43: PSD000:Other_BM_NetImp | B43: Net Imports | C43: 0 | D43: 0 | E43: 0 | F43: 0 | G43: 0 | H43: 0 | I43: 0 | J43: 0 | K43: 0 | L43: 0 | M43: 0 | N43: 0 | O43: 0 | P43: 0 | Q43: 0 | R43: 0 | S43: 0 | T43: 0 | U43: 0 | V43: 0 | W43: 0 | X43: 0 | Y43: 0 | Z43: 0 | AA43: 0 | AB43: 0 | AC43: 0 | AD43: -- | AE43: 0 | AF43: 0 | AG43: 0 | AH43: --
...

Sheet AEO 2025 Table 19 Alt Trans
B1: alttrnp.d032125a
C3: Report | D3: Annual Energy Outlook 2025
C4: Scenario | D4: alttrnp | F4: Alternative Transportation
C5: Datekey | D5: d032125a
C6: Release Date | E6: April 2025
B7: 19. Hydrogen Supply, Disposition, and Prices
B8: (million metric tons unless otherwise noted)
AD9: Avg Annual Change
C10: 2024 | D10: 2025 | E10: 2026 | F10: 2027 | G10: 2028 | H10: 2029 | I10: 2030 | J10: 2031 | K10: 2032 | L10: 2033 | M10: 2034 | N10: 2035 | O10: 2036 | P10: 2037 | Q10: 2038 | R10: 2039 | S10: 2040 | T10: 2041 | U10: 2042 | V10: 2043 | W10: 2044 | X10: 2045 | Y10: 2046 | Z10: 2047 | AA10: 2048 | AB10: 2049 | AC10: 2050 | AD10: 2024-2050
B12: Supply 1/
B13: Production By Technology
A14: HMM000:ba_smr | B14: Steam Methane Reforming 2/ | C14: 5.5051384 | D14: 5.5889602 | E14: 5.5451565 | F14: 5.5703378 | G14: 5.5628238 | H14: 5.5745244 | I14: 5.6207018 | J14: 5.6625314 | K14: 5.707273 | L14: 5.7308187 | M14: 5.749361 | N14: 5.7707858 | O14: 5.8204174 | P14: 6.0551076 | Q14: 6.2393594 | R14: 6.2594314 | S14: 6.2611084 | T14: 6.2733102 | U14: 6.2780075 | V14: 6.3645296 | W14: 6.3972588 | X14: 6.432919 | Y14: 6.4609509 | Z14: 6.4699512 | AA14: 6.4801841 | AB14: 6.4801397 | AC14: 6.5980368 | AD14: 0.0069893211
A15: HMM000:ba_smrccs | B15: Steam Methane Reforming with CCS 2/ | C15: 0.2306924 | D15: 0.230692 | E15: 0.39994362 | F15: 0.41354027 | G15: 0.41889471 | H15: 0.4279497 | I15: 0.43944368 | J15: 0.45007727 | K15: 0.46119824 | L15: 0.47170499 | M15: 0.48237947 | N15: 0.48959753 | O15: 0.4892351 | P15: 0.28911802 | Q15: 0.14359674 | R15: 0.15727676 | S15: 0.1627091 | T15: 0.16618843 | U15: 0.17135538 | V15: 0.11807384 | W15: 0.11751097 | X15: 0.11735085 | Y15: 0.11717795 | Z15: 0.11653521 | AA15: 0.11577284 | AB15: 0.11521158 | AC15: 0 | AD15: --
A16: HMM000:ba_electrolysis | B16: Electrolysis | C16: 6.3908135e-07 | D16: 6.1730128e-07 | E16: 3.8930702e-07 | F16: 3.628117e-07 | G16: 3.327601e-07 | H16: 2.985829e-07 | I16: 2.6217054e-07 | J16: 0.00012001424 | K16: 0.00092720776 | L16: 0.00067770947 | M16: 0.0024563787 | N16: 0.004181481 | O16: 0.0060350928 | P16: 0.0060992041 | Q16: 0.0060373452 | R16: 0.005953365 | S16: 0.005953365 | T16: 0.0056725019 | U16: 0.004532469 | V16: 0.0036667839 | W16: 0.0026680494 | X16: 0.0012990754 | Y16: 6.6363667e-05 | Z16: 0.00011060611 | AA16: 0.00010507581 | AB16: 7.189397e-05 | AC16: 6.6363667e-05 | AD16: 0.19550901
A17: HMM000:ba_byproduct | B17: Byproduct Hydrogen Supply to Market 3/ | C17: 2.0956628 | D17: 2.1142423 | E17: 2.1277764 | F17: 2.1292381 | G17: 2.1321261 | H17: 2.1337104 | I17: 2.1338773 | J17: 2.1338718 | K17: 2.1376319 | L17: 2.148906 | M17: 2.1672626 | N17: 2.1772437 | O17: 2.1832345 | P17: 2.1968148 | Q17: 2.2088783 | R17: 2.2192264 | S17: 2.2451625 | T17: 2.2696211 | U17: 2.2976239 | V17: 2.3018119 | W17: 2.3032181 | X17: 2.3003263 | Y17: 2.2891886 | Z17: 2.3190982 | AA17: 2.3579726 | AB17: 2.392503 | AC17: 2.4160314 | AD17: 0.0054863943
A18: HMM000:ba_tothydrogen | B18: Total Hydrogen Supply | C18: 7.8314943 | D18: 7.9338951 | E18: 8.0728769 | F18: 8.1131172 | G18: 8.1138449 | H18: 8.1361847 | I18: 8.1940231 | J18: 8.2466002 | K18: 8.3070297 | L18: 8.352107 | M18: 8.4014587 | N18: 8.4418087 | O18: 8.4989223 | P18: 8.5471392 | Q18: 8.5978718 | R18: 8.6418877 | S18: 8.6749334 | T18: 8.7147923 | U18: 8.7515192 | V18: 8.7880821 | W18: 8.8206558 | X18: 8.8518953 | Y18: 8.867384 | Z18: 8.905695 | AA18: 8.9540348 | AB18: 8.9879265 | AC18: 9.0141344 | AD18: 0.0054239063
A20: HMM000:ca_totconsumption | B20: Consumption | C20: 7.7855921 | D20: 7.892333 | E20: 8.0292177 | F20: 8.084693 | G20: 8.0735922 | H20: 8.0833263 | I20: 8.1592484 | J20: 8.210845 | K20: 8.2659883 | L20: 8.3113127 | M20: 8.3615227 | N20: 8.4006357 | O20: 8.4577017 | P20: 8.5056267 | Q20: 8.5566587 | R20: 8.5998325 | S20: 8.6340618 | T20: 8.6736765 | U20: 8.7099237 | V20: 8.7465868 | W20: 8.7804031 | X20: 8.8126745 | Y20: 8.8281441 | Z20: 8.8652754 | AA20: 8.9119902 | AB20: 8.9451675 | AC20: 8.9719315 | AD20: 0.0054697556
A21: HMM000:ca_industrial | B21: Industrial feedstock 4/ | C21: 7.7823462 | D21: 7.8888826 | E21: 8.0256901 | F21: 8.0811338 | G21: 8.0700436 | H21: 8.079875 | I21: 8.1558905 | J21: 8.2075968 | K21: 8.2623367 | L21: 8.3077421 | M21: 8.358736 | N21: 8.3978758 | O21: 8.4545679 | P21: 8.5026684 | Q21: 8.553874 | R21: 8.5972147 | S21: 8.6316042 | T21: 8.6713753 | U21: 8.7077494 | V21: 8.744525 | W21: 8.7784281 | X21: 8.8107958 | Y21: 8.8263378 | Z21: 8.8635216 | AA21: 8.9102688 | AB21: 8.9434757 | AC21: 8.9702616 | AD21: 0.005478683
A22: HMM000:ca_bulkchemical | B22: Bulk Chemicals 5/ | C22: 3.9304557 | D22: 4.0369473 | E22: 4.1736989 | F22: 4.2290726 | G22: 4.2216926 | H22: 4.2494364 | I22: 4.3035359 | J22: 4.3551092 | K22: 4.4096913 | L22: 4.4549131 | M22: 4.5057025 | N22: 4.5446177 | O22: 4.6010561 | P22: 4.6488757 | Q22: 4.6998014 | R22: 4.7428293 | S22: 4.776876 | T22: 4.8162756 | U22: 4.852252 | V22: 4.8885646 | W22: 4.9219723 | X22: 4.9538069 | Y22: 4.96878 | Z22: 5.0053468 | AA22: 5.0514383 | AB22: 5.08394 | AC22: 5.1098895 | AD22: 0.010144278
A23: HMM000:ca_refinery | B23: Refinery 6/ | C23: 3.8516364 | D23: 3.8516364 | E23: 3.8516364 | F23: 3.8516364 | G23: 3.8478487 | H23: 3.8298378 | I23: 3.8516364 | J23: 3.8516364 | K23: 3.8516364 | L23: 3.8516364 | M23: 3.8516364 | N23: 3.8516364 | O23: 3.8516364 | P23: 3.8516364 | Q23: 3.8516364 | R23: 3.8516364 | S23: 3.8516364 | T23: 3.8516364 | U23: 3.8516364 | V23: 3.8516364 | W23: 3.8516364 | X23: 3.8516364 | Y23: 3.8516364 | Z23: 3.8516364 | AA23: 3.8516364 | AB23: 3.8516364 | AC23: 3.8516364 | AD23: 0
A24: HMM000:ca_othercons | B24: Other Industrial 7/ | C24: 0.00025415421 | D24: 0.0002989769 | E24: 0.00035476685 | F24: 0.00042486191 | G24: 0.00050234795 | H24: 0.00060081482 | I24: 0.00071811676 | J24: 0.00085115433 | K24: 0.0010089874 | L24: 0.0011925697 | M24: 0.0013971329 | N24: 0.0016217232 | O24: 0.0018754005 | P24: 0.0021562576 | Q24: 0.002436161 | R24: 0.0027489662 | S24: 0.0030918121 | T24: 0.0034632683 | U24: 0.0038609505 | V24: 0.0043239594 | W24: 0.0048193932 | X24: 0.0053524971 | Y24: 0.0059213638 | Z24: 0.0065383911 | AA24: 0.0071940422 | AB24: 0.0078992844 | AC24: 0.0087356567 | AD24: 0.14573597
A25: HMM000:ca_transportation | B25: Transportation | C25: 0.0032457646 | D25: 0.0034504062 | E25: 0.0035280678 | F25: 0.0035593058 | G25: 0.0035486633 | H25: 0.003451298 | I25: 0.0033582149 | J25: 0.0032481444 | K25: 0.0031163597 | L25: 0.0029525768 | M25: 0.0027863262 | N25: 0.0026168041 | O25: 0.0024430808 | P25: 0.0022680461 | Q25: 0.0020939324 | R25: 0.0019270121 | S25: 0.0017670685 | T25: 0.0016111071 | U25: 0.0014840551 | V25: 0.0013711945 | W25: 0.0012841554 | X25: 0.0011884088 | Y25: 0.0011161857 | Z25: 0.0010638197 | AA25: 0.0010311647 | AB25: 0.0010016119 | AC25: 0.00097954215 | AD25: -0.04503227
A26: HMM000:ca_transportationldv | B26: Light-Duty Vehicles | C26: 0.003000132 | D26: 0.0031928055 | E26: 0.0032669876 | F26: 0.0032981676 | G26: 0.0032883768 | H26: 0.0031925521 | I26: 0.00310094 | J26: 0.0029922982 | K26: 0.0028639704 | L26: 0.0027039882 | M26: 0.002540295 | N26: 0.0023743205 | O26: 0.0022043486 | P26: 0.0020332623 | Q26: 0.0018629252 | R26: 0.0016997308 | S26: 0.0015439068 | T26: 0.0013922079 | U26: 0.0012697311 | V26: 0.0011609823 | W26: 0.0010781866 | X26: 0.00098615105 | Y26: 0.0009180202 | Z26: 0.00087024301 | AA26: 0.00084183092 | AB26: 0.0008162384 | AC26: 0.00079701416 | AD26: -0.049704485
A27: HMM000:ca_transportationclt | B27: Commercial Light Trucks | C27: 0 | D27: 0 | E27: 0 | F27: 0 | G27: 0 | H27: 0 | I27: 0 | J27: 0 | K27: 0 | L27: 0 | M27: 0 | N27: 0 | O27: 0 | P27: 0 | Q27: 0 | R27: 0 | S27: 0 | T27: 0 | U27: 0 | V27: 0 | W27: 0 | X27: 0 | Y27: 0 | Z27: 0 | AA27: 0 | AB27: 0 | AC27: 0 | AD27: --
A28: HMM000:ca_transportationft | B28: Freight Trucks | C28: 0 | D28: 0 | E28: 0 | F28: 0 | G28: 0 | H28: 0 | I28: 0 | J28: 0 | K28: 0 | L28: 0 | M28: 0 | N28: 0 | O28: 0 | P28: 0 | Q28: 0 | R28: 0 | S28: 0 | T28: 0 | U28: 0 | V28: 0 | W28: 0 | X28: 0 | Y28: 0 | Z28: 0 | AA28: 0 | AB28: 0 | AC28: 0 | AD28: --
A29: HMM000:ca_transportationbt | B29: Bus Transportation | C29: 0.00024563243 | D29: 0.00025760106 | E29: 0.0002610801 | F29: 0.0002611379 | G29: 0.00026028638 | H29: 0.00025874595 | I29: 0.00025727504 | J29: 0.00025584645 | K29: 0.00025238932 | L29: 0.000248589 | M29: 0.00024603124 | N29: 0.00024248399 | O29: 0.00023873204 | P29: 0.00023478399 | Q29: 0.00023100717 | R29: 0.00022728153 | S29: 0.00022316181 | T29: 0.00021889906 | U29: 0.00021432411 | V29: 0.00021021221 | W29: 0.0002059689 | X29: 0.00020225787 | Y29: 0.00019816554 | Z29: 0.00019357671 | AA29: 0.0001893336 | AB29: 0.00018537347 | AC29: 0.00018252793 | AD29: -0.011355534
A30: HMM000:ca_electric | B30: Electric Power | C30: 0 | D30: 0 | E30: 0 | F30: 0 | G30: 0 | H30: 0 | I30: 0 | J30: 0 | K30: 0.00053505629 | L30: 0.00061796914 | M30: 0 | N30: 0.0001431947 | O30: 0.00069062994 | P30: 0.00069062994 | Q30: 0.00069062994 | R30: 0.00069062994 | S30: 0.00069062994 | T30: 0.00069062994 | U30: 0.00069062994 | V30: 0.00069062994 | W30: 0.00069062994 | X30: 0.00069062994 | Y30: 0.00069062994 | Z30: 0.00069062994 | AA30: 0.00069062994 | AB30: 0.00069062994 | AC30: 0.00069062994 | AD30: --
A32: HMM000:da_disc | B32: Discrepancy 8/ | C32: 0.045902252 | D32: 0.04156208 | E32: 0.04365921 | F32: 0.028424263 | G32: 0.040252686 | H32: 0.052858353 | I32: 0.03477478 | J32: 0.035755157 | K32: 0.041041374 | L32: 0.040794373 | M32: 0.039936066 | N32: 0.041172981 | O32: 0.041220665 | P32: 0.041512489 | Q32: 0.041213036 | R32: 0.04205513 | S32: 0.04087162 | T32: 0.041115761 | U32: 0.041595459 | V32: 0.041495323 | W32: 0.040252686 | X32: 0.03922081 | Y32: 0.039239883 | Z32: 0.040419579 | AA32: 0.04204464 | AB32: 0.042758942 | AC32: 0.04220295 | AD32: -0.0032264787
B34: Prices ($/MMBtu)
A35: HMM000:ea_spotprice | B35: Hydrogen average market spot price 9/ | C35: 7.0623779 | D35: 8.1772223 | E35: 8.0545816 | F35: 7.9175053 | G35: 8.0400534 | H35: 8.1602316 | I35: 8.3440771 | J35: 8.5184183 | K35: 8.94697 | L35: 9.3011131 | M35: 9.5776072 | N35: 9.6891594 | O35: 9.6014671 | P35: 9.5438509 | Q35: 9.6702099 | R35: 9.5780802 | S35: 9.621891 | T35: 9.7619715 | U35: 9.9076681 | V35: 9.856391 | W35: 9.917922 | X35: 9.9243517 | Y35: 9.9192829 | Z35: 9.8394737 | AA35: 9.8236074 | AB35: 9.8260241 | AC35: 9.6644516 | AD35: 0.012137397
B37: Delivered End-Use Prices ($/MMBtu)
A38: HMM000:fa_indprice | B38: Industrial 10/ | C38: 9.5251846 | D38: 10.640075 | E38: 10.517506 | F38: 10.380456 | G38: 10.503005 | H38: 10.623157 | I38: 10.806981 | J38: 10.981338 | K38: 11.409804 | L38: 11.764016 | M38: 12.040632 | N38: 12.152257 | O38: 12.064539 | P38: 12.006973 | Q38: 12.133413 | R38: 12.041291 | S38: 12.085117 | T38: 12.225208 | U38: 12.370907 | V38: 12.319608 | W38: 12.38115 | X38: 12.38759 | Y38: 12.382531 | Z38: 12.302726 | AA38: 12.286866 | AB38: 12.289292 | AC38: 12.127695 | AD38: 0.0093337667
A39: HMM000:fa_transprice | B39: Transportation 11/ | C39: 61.324638 | D39: 62.25843 | E39: 61.971077 | F39: 61.767258 | G39: 61.892784 | H39: 62.113873 | I39: 62.39904 | J39: 62.600948 | K39: 63.057625 | L39: 63.294518 | M39: 63.625202 | N39: 63.53323 | O39: 63.365929 | P39: 63.24189 | Q39: 63.203316 | R39: 63.148933 | S39: 63.206013 | T39: 63.394558 | U39: 63.590591 | V39: 63.686977 | W39: 63.750324 | X39: 63.777321 | Y39: 63.778011 | Z39: 63.728878 | AA39: 63.706928 | AB39: 63.682514 | AC39: 63.668934 | AD39: 0.0014439282
A40: HMM000:fa_epprice | B40: Electric Power 10/ | C40: 9.5251846 | D40: 10.640075 | E40: 10.517506 | F40: 10.380456 | G40: 10.503005 | H40: 10.623157 | I40: 10.806981 | J40: 10.981338 | K40: 12.995852 | L40: 13.232461 | M40: 12.040632 | N40: 13.472548 | O40: 13.305155 | P40: 13.177244 | Q40: 13.113541 | R40: 13.064906 | S40: 13.120963 | T40: 13.31252 | U40: 13.512442 | V40: 13.66419 | W40: 13.733344 | X40: 13.768576 | Y40: 13.772696 | Z40: 13.729864 | AA40: 13.708858 | AB40: 13.6861 | AC40: 13.695667 | AD40: 0.014064925
B42: Data source: 2024: U.S. Energy Information Administration (EIA), Short-Term Energy Outlook, December 2024 and EIA,
B43: AEO2025 National Energy Modeling System run alttrnp.d032125a. Projections: EIA, AEO2025 National Energy Modeling System run alttrnp.d032125a.
B44: 1/ Supply is defined as hydrogen production from an industrial process that converts an energy feedstock of water
B45: into hydrogen gas as its primary output, plus byproduct hydrogen delivered to an end user (that is, not self-consumed for heat
B46: and power onsite).
B47: 2/ Includes volumes produced for delivery to end users in the market as well as production at facilities that may be adjacent
...

Sheet AEO 2025 Table 24 Alt Trans
A1: Table 24. Refining Industry Energy Consumption
A2: https://www.eia.gov/outlooks/aeo/data/browser/#/?id=35-AEO2025&cases=alttrnp&sourcekey=0
A3: Mon Dec 22 2025 12:10:08 GMT-0800 (Pacific Standard Time)
A4: Source: U.S. Energy Information Administration
B5: full name | C5: api key | D5: units | E5: 2023 | F5: 2024 | G5: 2025 | H5: 2026 | I5: 2027 | J5: 2028 | K5: 2029 | L5: 2030 | M5: 2031 | N5: 2032 | O5: 2033 | P5: 2034 | Q5: 2035 | R5: 2036 | S5: 2037 | T5: 2038 | U5: 2039 | V5: 2040 | W5: 2041 | X5: 2042 | Y5: 2043 | Z5: 2044 | AA5: 2045 | AB5: 2046 | AC5: 2047 | AD5: 2048 | AE5: 2049 | AF5: 2050 | AG5: Growth (2024-2050)
A6: Value of Shipments (billion 2012 dollars) | B6: Refining Industry: Value of Shipments: Alternative Transportation | C6: AEO.2025.ALTTRNP.ECI_VOS_IDAL_REF_NA_NA_NA_BLNY09DLR.A | D6: billion 2012 $ | F6: 773.8219 | G6: 786.61841 | H6: 783.81787 | I6: 782.10388 | J6: 779.7373 | K6: 776.40668 | L6: 771.18811 | M6: 766.94324 | N6: 762.13257 | O6: 758.32636 | P6: 755.69568 | Q6: 752.53565 | R6: 749.16858 | S6: 746.45282 | T6: 744.5329 | U6: 742.69019 | V6: 742.33783 | W6: 741.48614 | X6: 740.88788 | Y6: 740.5517 | Z6: 739.12549 | AA6: 737.6637 | AB6: 736.20465 | AC6: 737.94757 | AD6: 738.86261 | AE6: 741.01337 | AF6: 744.24585 | AG6: -0.001
A7: Inputs to Distillation Units
A8: (million barrels per day) | B8: Refining Industry: Inputs to Distillation Units: Alternative Transportation | C8: AEO.2025.ALTTRNP.IN_DIST_IDAL_REF_CR_NA_NA_MILLBRLPDY.A | D8: MMb/d | F8: 16.848057 | G8: 16.738653 | H8: 16.722189 | I8: 16.734415 | J8: 16.842148 | K8: 16.98263 | L8: 17.008272 | M8: 17.1639 | N8: 17.180298 | O8: 17.099449 | P8: 17.157427 | Q8: 17.0958 | R8: 17.039782 | S8: 16.96682 | T8: 16.987518 | U8: 17.091673 | V8: 17.039431 | W8: 16.988409 | X8: 16.839998 | Y8: 16.894266 | Z8: 16.901186 | AA8: 16.965046 | AB8: 16.934122 | AC8: 16.922188 | AD8: 16.941267 | AE8: 16.933884 | AF8: 17.01231 | AG8: 0
A9: Total Energy Consumption (trillion Btu)
A10: Residual Fuel Oil | B10: Refining Industry: Total Energy Use: Residual Fuel Oil: Alternative Transportation | C10: AEO.2025.ALTTRNP.CNSM_NA_IDAL_REFLIQ_RFO_NA_NA_TRLBTU.A | D10: trillion Btu | F10: 0.288 | G10: 0.288 | H10: 0 | I10: 0 | J10: 0 | K10: 0 | L10: 0 | M10: 0 | N10: 0 | O10: 0 | P10: 0 | Q10: 0 | R10: 0 | S10: 0 | T10: 0 | U10: 0 | V10: 0 | W10: 0 | X10: 0 | Y10: 0 | Z10: 0 | AA10: 0 | AB10: 0 | AC10: 0 | AD10: 0 | AE10: 0 | AF10: 0 | AG10: -1
A11: Distillate Fuel Oil | B11: Refining Industry: Total Energy Use: Distillate Fuel Oil: Alternative Transportation | C11: AEO.2025.ALTTRNP.CNSM_NA_IDAL_REFLIQ_DFO_NA_NA_TRLBTU.A | D11: trillion Btu | F11: 1.574 | G11: 1.574 | H11: 0 | I11: 0 | J11: 0 | K11: 0 | L11: 0 | M11: 0 | N11: 0 | O11: 0 | P11: 0 | Q11: 0 | R11: 0 | S11: 0 | T11: 0 | U11: 0 | V11: 0 | W11: 0 | X11: 0 | Y11: 0 | Z11: 0 | AA11: 0 | AB11: 0 | AC11: 0 | AD11: 0 | AE11: 0 | AF11: 0 | AG11: -1
A12: Liquefied Petroleum Gas Heat and Power | B12: Refining Industry: Total Energy Use: Liquefied Petroleum Gases: Alternative Transportation | C12: AEO.2025.ALTTRNP.CNSM_NA_IDAL_REFLIQ_LPG_NA_NA_TRLBTU.A | D12: trillion Btu | F12: 6.789 | G12: 6.789 | H12: 0 | I12: 0 | J12: 0 | K12: 0 | L12: 0 | M12: 0 | N12: 0 | O12: 0 | P12: 0 | Q12: 0 | R12: 0 | S12: 0 | T12: 0 | U12: 0 | V12: 0 | W12: 0 | X12: 0 | Y12: 0 | Z12: 0 | AA12: 0 | AB12: 0 | AC12: 0 | AD12: 0 | AE12: 0 | AF12: 0 | AG12: -1
A13: Petroleum Coke | B13: Refining Industry: Total Energy Use: Petroleum Coke: Alternative Transportation | C13: AEO.2025.ALTTRNP.CNSM_NA_IDAL_REFLIQ_PCK_NA_NA_TRLBTU.A | D13: trillion Btu | F13: 451 | G13: 474 | H13: 486.20065 | I13: 483.74756 | J13: 490.34976 | K13: 492.25888 | L13: 492.62241 | M13: 494.92432 | N13: 490.86194 | O13: 489.46631 | P13: 496.12726 | Q13: 491.00287 | R13: 493.41675 | S13: 493.38968 | T13: 492.19797 | U13: 493.08524 | V13: 491.63504 | W13: 491.6618 | X13: 489.4292 | Y13: 489.91248 | Z13: 488.48138 | AA13: 489.76041 | AB13: 490.83139 | AC13: 492.59686 | AD13: 494.7594 | AE13: 490.1915 | AF13: 493.41516 | AG13: 0.003
A14: Still Gas | B14: Refining Industry: Total Energy Use: Still Gas: Alternative Transportation | C14: AEO.2025.ALTTRNP.CNSM_NA_IDAL_REFLIQ_SLG_NA_NA_TRLBTU.A | D14: trillion Btu | F14: 1391.026 | G14: 1391.026 | H14: 1323.4628 | I14: 1310.1118 | J14: 1363.3091 | K14: 1370.7123 | L14: 1371.5575 | M14: 1385.0876 | N14: 1409.2587 | O14: 1400.8381 | P14: 1415.644 | Q14: 1414.0172 | R14: 1423.7493 | S14: 1432.6365 | T14: 1431.3408 | U14: 1442.8116 | V14: 1444.0347 | W14: 1438.6699 | X14: 1421.8981 | Y14: 1434.576 | Z14: 1433.7826 | AA14: 1440.428 | AB14: 1431.8506 | AC14: 1425.0454 | AD14: 1420.5372 | AE14: 1419.891 | AF14: 1425.0227 | AG14: 0.001
A15: Other Petroleum | B15: Refining Industry: Total Energy Use: Other Petroleum: Alternative Transportation | C15: AEO.2025.ALTTRNP.CNSM_NA_IDAL_REFLIQ_ONP_NA_NA_TRLBTU.A | D15: trillion Btu | F15: 6.113 | G15: 6.113 | H15: 5.833968 | I15: 5.877283 | J15: 5.681673 | K15: 4.229258 | L15: 3.376377 | M15: 2.924395 | N15: 2.586175 | O15: 2.354666 | P15: 2.210732 | Q15: 4.678841 | R15: 5.126453 | S15: 4.315352 | T15: 4.291104 | U15: 4.816897 | V15: 6.522789 | W15: 6.297829 | X15: 6.574095 | Y15: 6.753811 | Z15: 5.457685 | AA15: 5.868826 | AB15: 6.885268 | AC15: 7.422028 | AD15: 8.089056 | AE15: 8.451115 | AF15: 8.151185 | AG15: 0.011
A16: Petroleum and Other Liquids Subtotal | B16: Refining Industry: Total Energy Use: Petroleum Subtotal: Alternative Transportation | C16: AEO.2025.ALTTRNP.CNSM_NA_IDAL_REFLIQ_PET_NA_NA_TRLBTU.A | D16: trillion Btu | F16: 1856.79 | G16: 1879.79 | H16: 1815.4974 | I16: 1799.7367 | J16: 1859.3405 | K16: 1867.2004 | L16: 1867.5563 | M16: 1882.9364 | N16: 1902.7068 | O16: 1892.6591 | P16: 1913.9819 | Q16: 1909.6989 | R16: 1922.2925 | S16: 1930.3414 | T16: 1927.83 | U16: 1940.7137 | V16: 1942.1925 | W16: 1936.6296 | X16: 1917.9014 | Y16: 1931.2423 | Z16: 1927.7216 | AA16: 1936.0571 | AB16: 1929.5673 | AC16: 1925.0643 | AD16: 1923.3857 | AE16: 1918.5337 | AF16: 1926.5891 | AG16: 0.001
A17: Natural Gas | B17: Refining Industry: Total Energy Use: Natural Gas: Alternative Transportation | C17: AEO.2025.ALTTRNP.CNSM_NA_IDAL_REFLIQ_NG_NA_NA_TRLBTU.A | D17: trillion Btu | F17: 1323.9661 | G17: 1323.9661 | H17: 1062.9296 | I17: 1073.686 | J17: 1047.1814 | K17: 1061.3569 | L17: 1071.8081 | M17: 1069.7634 | N17: 1067.0209 | O17: 1071.188 | P17: 1061.9846 | Q17: 1059.5316 | R17: 1048.5593 | S17: 1039.0363 | T17: 1045.0566 | U17: 1050.2699 | V17: 1048.0364 | W17: 1050.7719 | X17: 1058.4512 | Y17: 1059.9369 | Z17: 1065.2886 | AA17: 1072.6115 | AB17: 1079.2428 | AC17: 1090.7336 | AD17: 1102.186 | AE17: 1105.8815 | AF17: 1117.6824 | AG17: -0.006
A18: of which: Heat and Power | B18: Refining Industry: Total Energy Use: Natural Gas: Heat and Power: Alternative Transportation | C18: AEO.2025.ALTTRNP.CNSM_NA_IDAL_REFLIQ_NG_HAP_NA_TRLBTU.A | D18: trillion Btu | F18: 1323.9661 | G18: 1323.9661 | H18: 1062.9296 | I18: 1073.686 | J18: 1047.1814 | K18: 1061.3569 | L18: 1071.8081 | M18: 1069.7634 | N18: 1067.0209 | O18: 1071.188 | P18: 1061.9846 | Q18: 1059.5316 | R18: 1048.5593 | S18: 1039.0363 | T18: 1045.0566 | U18: 1050.2699 | V18: 1048.0364 | W18: 1050.7719 | X18: 1058.4512 | Y18: 1059.9369 | Z18: 1065.2886 | AA18: 1072.6115 | AB18: 1079.2428 | AC18: 1090.7336 | AD18: 1102.186 | AE18: 1105.8815 | AF18: 1117.6824 | AG18: -0.006
A19: of which: Feedstocks | B19: Refining Industry: Total Energy Use: Natural Gas: Feedstocks: Alternative Transportation | C19: AEO.2025.ALTTRNP.CNSM_NA_IDAL_REFLIQ_NG_FSK_NA_TRLBTU.A | D19: trillion Btu | F19: 0 | G19: 0 | H19: 0 | I19: 0 | J19: 0 | K19: 0 | L19: 0 | M19: 0 | N19: 0 | O19: 0 | P19: 0 | Q19: 0 | R19: 0 | S19: 0 | T19: 0 | U19: 0 | V19: 0 | W19: 0 | X19: 0 | Y19: 0 | Z19: 0 | AA19: 0 | AB19: 0 | AC19: 0 | AD19: 0 | AE19: 0 | AF19: 0 | AG19: - -
A20: Steam Coal | B20: Refining Industry: Total Energy Use: Steam Coal: Alternative Transportation | C20: AEO.2025.ALTTRNP.CNSM_NA_IDAL_REFLIQ_STC_NA_NA_TRLBTU.A | D20: trillion Btu | F20: 124.711 | G20: 124.711 | H20: 124.711 | I20: 124.711 | J20: 124.711 | K20: 124.711 | L20: 124.711 | M20: 124.711 | N20: 124.711 | O20: 124.711 | P20: 124.711 | Q20: 124.711 | R20: 124.711 | S20: 124.711 | T20: 124.711 | U20: 124.711 | V20: 124.711 | W20: 124.711 | X20: 124.711 | Y20: 124.711 | Z20: 124.711 | AA20: 124.711 | AB20: 124.711 | AC20: 124.711 | AD20: 124.711 | AE20: 124.711 | AF20: 124.711 | AG20: 0
A21: Biofuels Heat and Coproducts | B21: Refining Industry: Total Energy Use: Biofuels Heat and Coproducts: Alternative Transportation | C21: AEO.2025.ALTTRNP.CNSM_NA_IDAL_REFLIQ_BFH_NA_NA_TRLBTU.A | D21: trillion Btu | F21: 893.86113 | G21: 915.74153 | H21: 915.86486 | I21: 917.10213 | J21: 916.26924 | K21: 917.41387 | L21: 916.96018 | M21: 916.783 | N21: 916.89136 | O21: 917.63763 | P21: 918.07899 | Q21: 917.75251 | R21: 919.55857 | S21: 921.86931 | T21: 922.41843 | U21: 926.1476 | V21: 931.41394 | W21: 933.78431 | X21: 935.36781 | Y21: 946.35736 | Z21: 950.26712 | AA21: 954.73333 | AB21: 958.18237 | AC21: 963.57021 | AD21: 967.55059 | AE21: 972.35691 | AF21: 972.75927 | AG21: 0.003
A22: Purchased Electricity | B22: Refining Industry: Total Energy Use: Purchased Electricity: Alternative Transportation | C22: AEO.2025.ALTTRNP.CNSM_NA_IDAL_REFLIQ_PRC_NA_NA_TRLBTU.A | D22: trillion Btu | F22: 178.51601 | G22: 178.51601 | H22: 176.31662 | I22: 176.67641 | J22: 177.57729 | K22: 179.42639 | L22: 180.81592 | M22: 181.62707 | N22: 182.19148 | O22: 182.16025 | P22: 183.53548 | Q22: 182.82712 | R22: 183.36214 | S22: 183.30934 | T22: 183.43364 | U22: 185.23369 | V22: 185.59866 | W22: 185.28073 | X22: 184.56509 | Y22: 185.9061 | Z22: 185.97168 | AA22: 187.55859 | AB22: 187.8275 | AC22: 189.00555 | AD22: 189.93939 | AE22: 189.67049 | AF22: 191.38377 | AG22: 0.003
A23: Total | B23: Refining Industry: Total Energy Use: Total: Alternative Transportation | C23: AEO.2025.ALTTRNP.CNSM_NA_IDAL_REFLIQ_NA_NA_NA_TRLBTU.A | D23: trillion Btu | F23: 4377.8443 | G23: 4422.7247 | H23: 4095.3194 | I23: 4091.9124 | J23: 4125.0795 | K23: 4150.1087 | L23: 4161.8513 | M23: 4175.8206 | N23: 4193.5212 | O23: 4188.3559 | P23: 4202.2919 | Q23: 4194.5211 | R23: 4198.4834 | S23: 4199.2673 | T23: 4203.4497 | U23: 4227.0758 | V23: 4231.9525 | W23: 4231.1774 | X23: 4220.9965 | Y23: 4248.1535 | Z23: 4253.96 | AA23: 4275.6713 | AB23: 4279.5308 | AC23: 4293.0846 | AD23: 4307.7728 | AE23: 4311.1533 | AF23: 4333.1255 | AG23: 0
A24: Carbon Dioxide Emissions
A25: (million metric tons CO2) | B25: Refining Industry: Carbon Dioxide Emissions: Alternative Transportation | C25: AEO.2025.ALTTRNP.EMI_CO2_IDAL_REFLIQ_NA_NA_NA_METNCO2.A | D25: MMmt carbon dioxide | F25: 238.31757 | G25: 240.10014 | H25: 220.16097 | I25: 218.22972 | J25: 220.64476 | K25: 221.38361 | L25: 220.7097 | M25: 220.6656 | N25: 218.89671 | O25: 217.65579 | P25: 218.09587 | Q25: 216.93048 | R25: 216.64603 | S25: 216.21854 | T25: 216.14064 | U25: 216.95471 | V25: 216.80495 | W25: 216.58307 | X25: 215.66394 | Y25: 216.72922 | Z25: 216.78101 | AA25: 217.76518 | AB25: 217.64328 | AC25: 217.95607 | AD25: 218.4511 | AE25: 218.16045 | AF25: 219.48138 | AG25: -0.003
A26: Energy Related to Refining Activity Only
A27: Energy Consumption
A28: Residual Fuel Oil | B28: Refining Industry: Refinery Only Energy: Use: Residual Fuel Oil: Alternative Transportation | C28: AEO.2025.ALTTRNP.CNSM_NA_IDAL_REF_RFO_NA_NA_TRLBTU.A | D28: trillion Btu | F28: 0.288 | G28: 0.288 | H28: 0 | I28: 0 | J28: 0 | K28: 0 | L28: 0 | M28: 0 | N28: 0 | O28: 0 | P28: 0 | Q28: 0 | R28: 0 | S28: 0 | T28: 0 | U28: 0 | V28: 0 | W28: 0 | X28: 0 | Y28: 0 | Z28: 0 | AA28: 0 | AB28: 0 | AC28: 0 | AD28: 0 | AE28: 0 | AF28: 0 | AG28: -1
A29: Distillate Fuel Oil | B29: Refining Industry: Refinery Only Energy: Use: Distillate Fuel Oil: Alternative Transportation | C29: AEO.2025.ALTTRNP.CNSM_NA_IDAL_REF_DFO_NA_NA_TRLBTU.A | D29: trillion Btu | F29: 1.574 | G29: 1.574 | H29: 0 | I29: 0 | J29: 0 | K29: 0 | L29: 0 | M29: 0 | N29: 0 | O29: 0 | P29: 0 | Q29: 0 | R29: 0 | S29: 0 | T29: 0 | U29: 0 | V29: 0 | W29: 0 | X29: 0 | Y29: 0 | Z29: 0 | AA29: 0 | AB29: 0 | AC29: 0 | AD29: 0 | AE29: 0 | AF29: 0 | AG29: -1
A30: Liquefied Petroleum Gas Heat and Power | B30: Refining Industry: Refinery Only Energy: Use: Liquefied Petroleum Gases: Alternative Transportation | C30: AEO.2025.ALTTRNP.CNSM_NA_IDAL_REF_LPG_NA_NA_TRLBTU.A | D30: trillion Btu | F30: 6.789 | G30: 6.789 | H30: 0 | I30: 0 | J30: 0 | K30: 0 | L30: 0 | M30: 0 | N30: 0 | O30: 0 | P30: 0 | Q30: 0 | R30: 0 | S30: 0 | T30: 0 | U30: 0 | V30: 0 | W30: 0 | X30: 0 | Y30: 0 | Z30: 0 | AA30: 0 | AB30: 0 | AC30: 0 | AD30: 0 | AE30: 0 | AF30: 0 | AG30: -1
A31: Petroleum Coke | B31: Refining Industry: Refinery Only Energy: Use: Petroleum Coke: Alternative Transportation | C31: AEO.2025.ALTTRNP.CNSM_NA_IDAL_REF_PCK_NA_NA_TRLBTU.A | D31: trillion Btu | F31: 449.26001 | G31: 472.26001 | H31: 486.20065 | I31: 483.74756 | J31: 490.34976 | K31: 492.25888 | L31: 492.62241 | M31: 494.92432 | N31: 490.86194 | O31: 489.46631 | P31: 496.12726 | Q31: 491.00287 | R31: 493.41675 | S31: 493.38968 | T31: 492.19797 | U31: 493.08524 | V31: 491.63504 | W31: 491.6618 | X31: 489.4292 | Y31: 489.91248 | Z31: 488.48138 | AA31: 489.76041 | AB31: 490.83139 | AC31: 492.59686 | AD31: 494.7594 | AE31: 490.1915 | AF31: 493.41516 | AG31: 0.004
A32: Still Gas | B32: Refining Industry: Refinery Only Energy: Use: Still Gas: Alternative Transportation | C32: AEO.2025.ALTTRNP.CNSM_NA_IDAL_REF_SLG_NA_NA_TRLBTU.A | D32: trillion Btu | F32: 1366.646 | G32: 1366.7061 | H32: 1274.4293 | I32: 1260.9409 | J32: 1314.0837 | K32: 1321.4869 | L32: 1322.3322 | M32: 1335.8623 | N32: 1360.0353 | O32: 1351.7081 | P32: 1366.4187 | Q32: 1364.9149 | R32: 1374.5624 | S32: 1383.4111 | T32: 1382.1155 | U32: 1393.5863 | V32: 1394.8093 | W32: 1389.4446 | X32: 1372.6727 | Y32: 1385.3507 | Z32: 1384.5573 | AA32: 1391.2026 | AB32: 1382.6252 | AC32: 1375.8201 | AD32: 1371.3119 | AE32: 1370.6656 | AF32: 1375.7974 | AG32: 0
A33: Other Petroleum | B33: Refining Industry: Refinery Only Energy: Use: Other Petroleum: Alternative Transportation | C33: AEO.2025.ALTTRNP.CNSM_NA_IDAL_REF_ONP_NA_NA_TRLBTU.A | D33: trillion Btu | F33: 6.113 | G33: 6.113 | H33: 5.833968 | I33: 5.877283 | J33: 5.681673 | K33: 4.229258 | L33: 3.376377 | M33: 2.924395 | N33: 2.586175 | O33: 2.354666 | P33: 2.210732 | Q33: 4.678841 | R33: 5.126453 | S33: 4.315352 | T33: 4.291104 | U33: 4.816897 | V33: 6.522789 | W33: 6.297829 | X33: 6.574095 | Y33: 6.753811 | Z33: 5.457685 | AA33: 5.868826 | AB33: 6.885268 | AC33: 7.422028 | AD33: 8.089056 | AE33: 8.451115 | AF33: 8.151185 | AG33: 0.011
A34: Petroleum and Other Liquids Subtotal | B34: Refining Industry: Refinery Only Energy: Use: Petroleum Subtotal: Alternative Transportation | C34: AEO.2025.ALTTRNP.CNSM_NA_IDAL_REF_PET_NA_NA_TRLBTU.A | D34: trillion Btu | F34: 1830.67 | G34: 1853.7301 | H34: 1766.464 | I34: 1750.5658 | J34: 1810.1151 | K34: 1817.9751 | L34: 1818.3309 | M34: 1833.7111 | N34: 1853.4834 | O34: 1843.5291 | P34: 1864.7566 | Q34: 1860.5966 | R34: 1873.1056 | S34: 1881.1161 | T34: 1878.6046 | U34: 1891.4884 | V34: 1892.9672 | W34: 1887.4043 | X34: 1868.676 | Y34: 1882.017 | Z34: 1878.4962 | AA34: 1886.8318 | AB34: 1880.3419 | AC34: 1875.839 | AD34: 1874.1604 | AE34: 1869.3084 | AF34: 1877.3638 | AG34: 0.001
A35: Natural Gas | B35: Refining Industry: Refinery Only Energy: Use: Natural Gas: Alternative Transportation | C35: AEO.2025.ALTTRNP.CNSM_NA_IDAL_REF_NG_NA_NA_TRLBTU.A | D35: trillion Btu | F35: 808.56604 | G35: 808.56604 | H35: 427.22208 | I35: 436.82562 | J35: 410.0712 | K35: 424.00134 | L35: 434.68335 | M35: 432.75714 | N35: 430.05325 | O35: 434.41937 | P35: 424.8028 | Q35: 423.08664 | R35: 411.42645 | S35: 401.33829 | T35: 407.19852 | U35: 411.71152 | V35: 408.42349 | W35: 410.69241 | X35: 418.06561 | Y35: 417.27274 | Z35: 421.862 | AA35: 428.28018 | AB35: 432.82687 | AC35: 441.98639 | AD35: 452.26132 | AE35: 454.82437 | AF35: 465.87308 | AG35: -0.021
A36: Steam Coal | B36: Refining Industry: Refinery Only Energy: Use: Steam Coal: Alternative Transportation | C36: AEO.2025.ALTTRNP.CNSM_NA_IDAL_REF_STC_NA_NA_TRLBTU.A | D36: trillion Btu | F36: 0 | G36: 0 | H36: 0 | I36: 0 | J36: 0 | K36: 0 | L36: 0 | M36: 0 | N36: 0 | O36: 0 | P36: 0 | Q36: 0 | R36: 0 | S36: 0 | T36: 0 | U36: 0 | V36: 0 | W36: 0 | X36: 0 | Y36: 0 | Z36: 0 | AA36: 0 | AB36: 0 | AC36: 0 | AD36: 0 | AE36: 0 | AF36: 0 | AG36: - -
A37: Purchased Electricity | B37: Refining Industry: Refinery Only Energy: Use: Purchased Electricity: Alternative Transportation | C37: AEO.2025.ALTTRNP.CNSM_NA_IDAL_REF_PRC_NA_NA_TRLBTU.A | D37: trillion Btu | F37: 141.51601 | G37: 141.51601 | H37: 134.14038 | I37: 134.43617 | J37: 135.33226 | K37: 137.14908 | L37: 138.56081 | M37: 139.388 | N37: 139.95592 | O37: 139.89941 | P37: 141.26739 | Q37: 140.50139 | R37: 140.96152 | S37: 140.81674 | T37: 140.91992 | U37: 142.55022 | V37: 142.67261 | W37: 142.24824 | X37: 141.46324 | Y37: 142.30307 | Z37: 142.19241 | AA37: 143.57486 | AB37: 143.66319 | AC37: 144.57217 | AD37: 145.31825 | AE37: 144.79637 | AF37: 146.42419 | AG37: 0.001
A38: Total | B38: Refining Industry: Refinery Only Energy: Use: Total: Alternative Transportation | C38: AEO.2025.ALTTRNP.CNSM_NA_IDAL_REF_TOT_NA_NA_TRLBTU.A | D38: trillion Btu | F38: 2780.7522 | G38: 2803.8123 | H38: 2327.8264 | I38: 2321.8276 | J38: 2355.5186 | K38: 2379.1257 | L38: 2391.575 | M38: 2405.8562 | N38: 2423.4924 | O38: 2417.8479 | P38: 2430.8267 | Q38: 2424.1846 | R38: 2425.4934 | S38: 2423.271 | T38: 2426.7231 | U38: 2445.7502 | V38: 2444.0632 | W38: 2440.345 | X38: 2428.2048 | Y38: 2441.5928 | Z38: 2442.5505 | AA38: 2458.687 | AB38: 2456.8318 | AC38: 2462.3977 | AD38: 2471.74 | AE38: 2468.9292 | AF38: 2489.6611 | AG38: -0.004
A39: Carbon Dioxide Emissions
A40: (million metric tons CO2) | B40: Refining Industry: Refinery Only Energy: Carbon Dioxide Emissions: Alternative Transportation | C40: AEO.2025.ALTTRNP.EMI_CO2_IDAL_REF_NA_NA_NA_METNCO2.A | D40: MMmt carbon dioxide | F40: 193.35005 | G40: 195.12502 | H40: 167.3913 | I40: 165.72898 | J40: 168.22646 | K40: 169.14714 | L40: 168.8363 | M40: 169.06985 | N40: 168.00544 | O40: 166.94281 | P40: 167.54579 | Q40: 166.53698 | R40: 166.35403 | S40: 165.99975 | T40: 165.95673 | U40: 166.82062 | V40: 166.61604 | W40: 166.3658 | X40: 165.41694 | Y40: 166.33234 | Z40: 166.33766 | AA40: 167.27556 | AB40: 167.05114 | AC40: 167.24423 | AD40: 167.6849 | AE40: 167.33479 | AF40: 168.60823 | AG40: -0.005
...

Sheet AEO 2025 Table 34 High Cost
A1: Table 34. Nonmanufacturing Sector Energy Consumption
A2: https://www.eia.gov/outlooks/aeo/data/browser/#/?id=43-AEO2025&region=0-0&cases=highZTC&start=2023&end=2050&f=A&sourcekey=0
A3: Mon Dec 22 2025 13:49:03 GMT-0800 (Pacific Standard Time)
A4: Source: U.S. Energy Information Administration
B5: full name | C5: api key | D5: units | E5: 2023 | F5: 2024 | G5: 2025 | H5: 2026 | I5: 2027 | J5: 2028 | K5: 2029 | L5: 2030 | M5: 2031 | N5: 2032 | O5: 2033 | P5: 2034 | Q5: 2035 | R5: 2036 | S5: 2037 | T5: 2038 | U5: 2039 | V5: 2040 | W5: 2041 | X5: 2042 | Y5: 2043 | Z5: 2044 | AA5: 2045 | AB5: 2046 | AC5: 2047 | AD5: 2048 | AE5: 2049 | AF5: 2050 | AG5: Growth (2024-2050)
A6: Energy Consumption (trillion Btu)
A7: Agriculture
A8: Residual Fuel Oil | B8: Nonmanufacturing: Energy Use: Agriculture: Residual Fuel Oil: High Zero-Carbon Technology Cost | C8: AEO.2025.HIGHZTC.CNSM_NA_IDAL_AGG_RFO_NA_NA_TRLBTU.A | D8: trillion Btu | F8: 0.007151 | G8: 0.007195 | H8: 0.007237 | I8: 0.007279 | J8: 0.007318 | K8: 0.007354 | L8: 0.007386 | M8: 0.007415 | N8: 0.007439 | O8: 0.007458 | P8: 0.007472 | Q8: 0.007481 | R8: 0.007484 | S8: 0.007484 | T8: 0.007484 | U8: 0.007484 | V8: 0.007484 | W8: 0.007484 | X8: 0.007484 | Y8: 0.007484 | Z8: 0.007484 | AA8: 0.007484 | AB8: 0.007484 | AC8: 0.007484 | AD8: 0.007484 | AE8: 0.007484 | AF8: 0.007484 | AG8: 0.002
A9: Distillate Fuel Oil | B9: Nonmanufacturing: Energy Use: Agriculture: Distillate Fuel Oil: High Zero-Carbon Technology Cost | C9: AEO.2025.HIGHZTC.CNSM_NA_IDAL_AGG_DFO_NA_NA_TRLBTU.A | D9: trillion Btu | F9: 452.83762 | G9: 458.29614 | H9: 465.19879 | I9: 471.97595 | J9: 477.90424 | K9: 485.47 | L9: 492.16901 | M9: 497.75558 | N9: 505.66394 | O9: 509.75311 | P9: 515.32288 | Q9: 520.79834 | R9: 526.69922 | S9: 532.43048 | T9: 537.54034 | U9: 542.58954 | V9: 547.11218 | W9: 550.05554 | X9: 553.27753 | Y9: 556.7544 | Z9: 560.48663 | AA9: 564.7442 | AB9: 569.61731 | AC9: 574.45471 | AD9: 578.8053 | AE9: 583.81451 | AF9: 588.63025 | AG9: 0.01
A10: Propane | B10: Nonmanufacturing: Energy Use: Agriculture: Propane: High Zero-Carbon Technology Cost | C10: AEO.2025.HIGHZTC.CNSM_NA_IDAL_AGG_PROP_NA_NA_TRLBTU.A | D10: trillion Btu | F10: 41.404037 | G10: 80.855927 | H10: 81.774956 | I10: 82.713669 | J10: 83.310661 | K10: 84.381516 | L10: 85.223122 | M10: 85.808968 | N10: 87.626282 | O10: 87.947159 | P10: 88.669144 | Q10: 89.425743 | R10: 90.341187 | S10: 91.51889 | T10: 92.626541 | U10: 93.642433 | V10: 94.467255 | W10: 94.872864 | X10: 95.377594 | Y10: 95.886169 | Z10: 96.424637 | AA10: 97.057343 | AB10: 97.74086 | AC10: 98.410957 | AD10: 99.036865 | AE10: 99.719421 | AF10: 100.34543 | AG10: 0.035
A11: Motor Gasoline | B11: Nonmanufacturing: Energy Use: Agriculture: Motor Gasoline: High Zero-Carbon Technology Cost | C11: AEO.2025.HIGHZTC.CNSM_NA_IDAL_AGG_MGS_NA_NA_TRLBTU.A | D11: trillion Btu | F11: 112.12957 | G11: 113.45358 | H11: 115.07301 | I11: 116.68591 | J11: 118.0397 | K11: 119.8076 | L11: 121.4303 | M11: 122.7054 | N11: 123.95003 | O11: 125.09918 | P11: 126.50211 | Q11: 127.9128 | R11: 129.52899 | S11: 130.81549 | T11: 131.93413 | U11: 133.15097 | V11: 134.23576 | W11: 135.05588 | X11: 136.03784 | Y11: 137.02133 | Z11: 138.10562 | AA11: 139.44562 | AB11: 140.83327 | AC11: 142.20737 | AD11: 143.56061 | AE11: 144.97232 | AF11: 146.34283 | AG11: 0.01
A12: Other Petroleum | B12: Nonmanufacturing: Energy Use: Agriculture: Other Petroleum: High Zero-Carbon Technology Cost | C12: AEO.2025.HIGHZTC.CNSM_NA_IDAL_AGG_ONP_NA_NA_TRLBTU.A | D12: trillion Btu | F12: 9.245264 | G12: 9.737392 | H12: 10.261007 | I12: 10.781988 | J12: 11.256981 | K12: 11.763462 | L12: 12.234728 | M12: 12.626682 | N12: 12.98722 | O12: 13.298818 | P12: 13.589292 | Q12: 13.836977 | R12: 14.059357 | S12: 14.21764 | T12: 14.362858 | U12: 14.516664 | V12: 14.650713 | W12: 14.75922 | X12: 14.889067 | Y12: 15.018761 | Z12: 15.158793 | AA12: 15.323853 | AB12: 15.493307 | AC12: 15.660235 | AD12: 15.825542 | AE12: 15.997446 | AF12: 16.165174 | AG12: 0.022
A13: Petroleum and Other Liquids Subtotal | B13: Nonmanufacturing: Energy Use: Agriculture: Petroleum Subtotal: High Zero-Carbon Technology Cost | C13: AEO.2025.HIGHZTC.CNSM_NA_IDAL_AGG_PET_NA_NA_TRLBTU.A | D13: trillion Btu | F13: 615.6236 | G13: 662.35022 | H13: 672.315 | I13: 682.1648 | J13: 690.51886 | K13: 701.42993 | L13: 711.06457 | M13: 718.90405 | N13: 730.23492 | O13: 736.10571 | P13: 744.09088 | Q13: 751.98132 | R13: 760.63629 | S13: 768.98999 | T13: 776.47137 | U13: 783.9071 | V13: 790.47345 | W13: 794.75098 | X13: 799.58954 | Y13: 804.68811 | Z13: 810.18317 | AA13: 816.57849 | AB13: 823.6922 | AC13: 830.74072 | AD13: 837.23584 | AE13: 844.51117 | AF13: 851.49121 | AG13: 0.013
A14: Natural Gas | B14: Nonmanufacturing: Energy Use: Agriculture: Natural Gas: High Zero-Carbon Technology Cost | C14: AEO.2025.HIGHZTC.CNSM_NA_IDAL_AGG_NG_NA_NA_TRLBTU.A | D14: trillion Btu | F14: 122.34796 | G14: 124.1658 | H14: 126.29595 | I14: 128.44269 | J14: 130.17386 | K14: 132.43704 | L14: 134.40065 | M14: 135.93582 | N14: 138.45021 | O14: 139.04538 | P14: 139.77579 | Q14: 140.38768 | R14: 141.17102 | S14: 142.14377 | T14: 143.08174 | U14: 144.08902 | V14: 144.83972 | W14: 145.03836 | X14: 145.33452 | Y14: 145.54581 | Z14: 145.77357 | AA14: 146.16974 | AB14: 146.59885 | AC14: 147.03268 | AD14: 147.46091 | AE14: 147.89938 | AF14: 148.26309 | AG14: 0.007
A15: Steam Coal | B15: Nonmanufacturing: Energy Use: Agriculture: Steam Coal: High Zero-Carbon Technology Cost | C15: AEO.2025.HIGHZTC.CNSM_NA_IDAL_AGG_STC_NA_NA_TRLBTU.A | D15: trillion Btu | F15: 0 | G15: 0 | H15: 0 | I15: 0 | J15: 0 | K15: 0 | L15: 0 | M15: 0 | N15: 0 | O15: 0 | P15: 0 | Q15: 0 | R15: 0 | S15: 0 | T15: 0 | U15: 0 | V15: 0 | W15: 0 | X15: 0 | Y15: 0 | Z15: 0 | AA15: 0 | AB15: 0 | AC15: 0 | AD15: 0 | AE15: 0 | AF15: 0 | AG15: - -
