Workbook
Name billion_kw_to_MW: About!$B$30
Name CH4_to_CO2e: '[1]Cross-Page Data'!$C$12
Name cpi_2010to2012: #REF!
Name cpi_2013to2012: #REF!
Name cpi_2014to2012: #REF!
Name cpi_2016to2012: #REF!
Name dollars_2020_2012: [2]About!$A$113
Name dollars_2022_2012: [2]About!$A$111
Name gigwatt_to_megawatt: About!$B$31
Name gigwatts_to_megawatts: [3]About!$A$31
Name N2O_to_CO2e: '[1]Cross-Page Data'!$C$13
Name Percent_rural: About!$A$28
Name Percent_Urban: About!$A$27
Name unit_conv: [4]About!$A$123

Sheet About
A1: CiDESCTY Change in Distributed Electricity Source Capacities This Year
A3: Sources: | B3: Distributed Generation and Capacity - 2021-2050
B4: Energy Information Administration
B5: 2023, 2025
B6: Annual Energy Outlook 2023
B7: Annual Energy Outlook 2025
B8: Scenario: High zero-carbon technology cost
B9: https://www.eia.gov/outlooks/aeo/tables_side_xls.php
B10: Table 21 and Table 22
B12: Urban vs. Rural Residential Households
B13: Energy Information Administration
B14: 2020
B15: Residential Energy Consumption Survey (RECS)
B16: https://www.eia.gov/consumption/residential/data/2020/?src=%E2%80%B9%20Consumption%20%20%20%20%20%20Residential%20Energy%20Consumption%20Survey%20(RECS)-f1
B17: https://www.eia.gov/consumption/residential/data/2020/hc/xls/HC%202.1.xlsx
B18: Table HC2.1
A20: Notes
A21: This file can be used to test an alternate distributed solar additions schedule.
A22: We use it to incorporate additional distributed solar capacity associated with the
A23: Solar for All campaign of the Inflation Reduction Act.
A26: Urban Rural Split
A27: ='RECS HC2.1'!B24/SUM('RECS HC2.1'!B24,'RECS HC2.1'!B27) -> 0.81308184 | B27: Urban
A28: ='RECS HC2.1'!B27/SUM('RECS HC2.1'!B24,'RECS HC2.1'!B27) -> 0.18691816 | B28: Rural
A30: Conversion from billion kilowatthours to megawatthours | B30: =10^6 -> 1000000
A31: Conversion from gigawatts to megawatts | B31: 1000
A33: Data centers | B33: Data centers are a separate building type. There are no policy-mandated changes in distributed capacity at data centers, so their export tab is zero.

Sheet Source Data>

Sheet AEO23_Table_21._Residential
A1: Table 21. Residential Sector Equipment Stock and Efficiency, and Distributed Generation
A2: https://www.eia.gov/outlooks/aeo/data/browser/#/?id=30-AEO2023&sourcekey=0
A3: Sun May 04 2025 20:12:23 GMT-0700 (Pacific Daylight Time)
A4: Source: U.S. Energy Information Administration
B5: full name | C5: api key | D5: units | E5: 2021 | F5: 2022 | G5: 2023 | H5: 2024 | I5: 2025 | J5: 2026 | K5: 2027 | L5: 2028 | M5: 2029 | N5: 2030 | O5: 2031 | P5: 2032 | Q5: 2033 | R5: 2034 | S5: 2035 | T5: 2036 | U5: 2037 | V5: 2038 | W5: 2039 | X5: 2040 | Y5: 2041 | Z5: 2042 | AA5: 2043 | AB5: 2044 | AC5: 2045 | AD5: 2046 | AE5: 2047 | AF5: 2048 | AG5: 2049 | AH5: 2050 | AI5: Growth (2022-2050)
A6: Equipment Stock (million units)
A7: Main Space Heaters
A8: Electric Heat Pumps | B8: Residential Equipment: Equipment Stock: Main Space Heaters: Electric Heat Pumps: Reference case | C8: AEO.2023.REF2023.EQNR_STK_RESD_MSHR_EHP_NA_NA_MILL.A | D8: millions | F8: 13.315578 | G8: 13.570746 | H8: 13.822851 | I8: 14.081017 | J8: 14.338543 | K8: 14.596683 | L8: 14.856007 | M8: 15.113205 | N8: 15.364176 | O8: 15.610795 | P8: 15.855648 | Q8: 16.095499 | R8: 16.328896 | S8: 16.560501 | T8: 16.79364 | U8: 17.026976 | V8: 17.2586 | W8: 17.487827 | X8: 17.718792 | Y8: 17.949728 | Z8: 18.178337 | AA8: 18.406141 | AB8: 18.633221 | AC8: 18.859972 | AD8: 19.086086 | AE8: 19.312725 | AF8: 19.538191 | AG8: 19.762444 | AH8: 19.985924 | AI8: 0.015
A9: Electric Other | B9: Residential Equipment: Equipment Stock: Main Space Heaters: Electric Other: Reference case | C9: AEO.2023.REF2023.EQNR_STK_RESD_MSHR_ELO_NA_NA_MILL.A | D9: millions | F9: 31.010973 | G9: 31.191193 | H9: 31.367004 | I9: 31.545937 | J9: 31.728054 | K9: 31.914146 | L9: 32.103336 | M9: 32.291443 | N9: 32.472885 | O9: 32.650379 | P9: 32.828148 | Q9: 33.003277 | R9: 33.172894 | S9: 33.339802 | T9: 33.508488 | U9: 33.676701 | V9: 33.844833 | W9: 34.012619 | X9: 34.183968 | Y9: 34.355839 | Z9: 34.525658 | AA9: 34.694195 | AB9: 34.861164 | AC9: 35.026974 | AD9: 35.191212 | AE9: 35.356567 | AF9: 35.521111 | AG9: 35.685036 | AH9: 35.849113 | AI9: 0.005
A10: Natural Gas Heat Pumps | B10: Residential Equipment: Equipment Stock: Main Space Heaters: Natural Gas Heat Pumps: Reference case | C10: AEO.2023.REF2023.EQNR_STK_RESD_MSHR_NHU_NA_NA_MILL.A | D10: millions | F10: 1.321198 | G10: 1.319243 | H10: 1.317296 | I10: 1.315357 | J10: 1.313426 | K10: 1.311503 | L10: 1.309587 | M10: 1.307679 | N10: 1.30578 | O10: 1.303886 | P10: 1.302001 | Q10: 1.300122 | R10: 1.298251 | S10: 1.296387 | T10: 1.29453 | U10: 1.29268 | V10: 1.290837 | W10: 1.289001 | X10: 1.287171 | Y10: 1.285348 | Z10: 1.283531 | AA10: 1.281721 | AB10: 1.279918 | AC10: 1.27812 | AD10: 1.27633 | AE10: 1.274545 | AF10: 1.272766 | AG10: 1.270993 | AH10: 1.269227 | AI10: -0.001
A11: Natural Gas Other | B11: Residential Equipment: Equipment Stock: Main Space Heaters: Natural Gas Other: Reference case | C11: AEO.2023.REF2023.EQNR_STK_RESD_MSHR_NGO_NA_NA_MILL.A | D11: millions | F11: 62.066788 | G11: 62.86874 | H11: 63.678131 | I11: 64.503296 | J11: 65.32177 | K11: 66.136948 | L11: 66.951584 | M11: 67.756226 | N11: 68.541176 | O11: 69.310356 | P11: 70.070587 | Q11: 70.812531 | R11: 71.531357 | S11: 72.239449 | T11: 72.944847 | U11: 73.64325 | V11: 74.338699 | W11: 75.029205 | X11: 75.724937 | Y11: 76.420006 | Z11: 77.106728 | AA11: 77.789856 | AB11: 78.469795 | AC11: 79.146408 | AD11: 79.816353 | AE11: 80.482452 | AF11: 81.140999 | AG11: 81.790314 | AH11: 82.431442 | AI11: 0.01
A12: Distillate Fuel Oil | B12: Residential Equipment: Equipment Stock: Main Space Heaters: Distillate Fuel Oil: Reference case | C12: AEO.2023.REF2023.EQNR_STK_RESD_MSHR_DFO_NA_NA_MILL.A | D12: millions | F12: 5.454962 | G12: 5.405786 | H12: 5.357452 | I12: 5.309505 | J12: 5.261883 | K12: 5.215992 | L12: 5.1721 | M12: 5.130489 | N12: 5.09118 | O12: 5.053465 | P12: 5.01742 | Q12: 4.982733 | R12: 4.949076 | S12: 4.916341 | T12: 4.884336 | U12: 4.853684 | V12: 4.824137 | W12: 4.795379 | X12: 4.767413 | Y12: 4.739604 | Z12: 4.710267 | AA12: 4.679461 | AB12: 4.647407 | AC12: 4.614363 | AD12: 4.580481 | AE12: 4.545176 | AF12: 4.508846 | AG12: 4.471894 | AH12: 4.43473 | AI12: -0.007
A13: Propane | B13: Residential Equipment: Equipment Stock: Main Space Heaters: Propane: Reference case | C13: AEO.2023.REF2023.EQNR_STK_RESD_MSHR_PROP_NA_NA_MILL.A | D13: millions | F13: 5.292898 | G13: 5.283106 | H13: 5.272407 | I13: 5.26181 | J13: 5.251935 | K13: 5.245102 | L13: 5.240705 | M13: 5.238044 | N13: 5.235492 | O13: 5.233078 | P13: 5.23132 | Q13: 5.229799 | R13: 5.228008 | S13: 5.225996 | T13: 5.224109 | U13: 5.221475 | V13: 5.218017 | W13: 5.213948 | X13: 5.210232 | Y13: 5.207039 | Z13: 5.202483 | AA13: 5.196987 | AB13: 5.190924 | AC13: 5.184589 | AD13: 5.177998 | AE13: 5.171618 | AF13: 5.165352 | AG13: 5.159314 | AH13: 5.153788 | AI13: -0.001
A14: Kerosene | B14: Residential Equipment: Equipment Stock: Main Space Heaters: Kerosene: Reference case | C14: AEO.2023.REF2023.EQNR_STK_RESD_MSHR_KRS_NA_NA_MILL.A | D14: millions | F14: 0.003901 | G14: 0.00709 | H14: 0.009997 | I14: 0.012783 | J14: 0.015616 | K14: 0.01846 | L14: 0.021282 | M14: 0.024013 | N14: 0.026531 | O14: 0.028897 | P14: 0.031215 | Q14: 0.033522 | R14: 0.035761 | S14: 0.037892 | T14: 0.039987 | U14: 0.041972 | V14: 0.043841 | W14: 0.045631 | X14: 0.047425 | Y14: 0.049189 | Z14: 0.050905 | AA14: 0.052555 | AB14: 0.05413 | AC14: 0.055631 | AD14: 0.057045 | AE14: 0.058409 | AF14: 0.059716 | AG14: 0.060958 | AH14: 0.062151 | AI14: 0.104
A15: Wood Stoves | B15: Residential Equipment: Equipment Stock: Main Space Heaters: Wood Stoves: Reference case | C15: AEO.2023.REF2023.EQNR_STK_RESD_MSHR_WDS_NA_NA_MILL.A | D15: millions | F15: 3.297239 | G15: 3.265615 | H15: 3.237753 | I15: 3.211385 | J15: 3.186906 | K15: 3.163538 | L15: 3.140653 | M15: 3.117714 | N15: 3.094777 | O15: 3.071414 | P15: 3.047546 | Q15: 3.023053 | R15: 2.997959 | S15: 2.972195 | T15: 2.94591 | U15: 2.920416 | V15: 2.895695 | W15: 2.871994 | X15: 2.848303 | Y15: 2.825649 | Z15: 2.804177 | AA15: 2.783932 | AB15: 2.765052 | AC15: 2.747301 | AD15: 2.730428 | AE15: 2.713511 | AF15: 2.69659 | AG15: 2.679538 | AH15: 2.662318 | AI15: -0.008
A16: Geothermal Heat Pumps | B16: Residential Equipment: Equipment Stock: Main Space Heaters: Geothermal Heat Pumps: Reference case | C16: AEO.2023.REF2023.EQNR_STK_RESD_MSHR_GEHP_NA_NA_MILL.A | D16: millions | F16: 0.716036 | G16: 0.778759 | H16: 0.840134 | I16: 0.901506 | J16: 0.960455 | K16: 1.018172 | L16: 1.07555 | M16: 1.132757 | N16: 1.189252 | O16: 1.245527 | P16: 1.301907 | Q16: 1.358019 | R16: 1.41364 | S16: 1.469565 | T16: 1.525942 | U16: 1.581249 | V16: 1.635567 | W16: 1.68851 | X16: 1.741698 | Y16: 1.793962 | Z16: 1.844503 | AA16: 1.893613 | AB16: 1.941229 | AC16: 1.987597 | AD16: 2.03283 | AE16: 2.077793 | AF16: 2.122324 | AG16: 2.166456 | AH16: 2.210309 | AI16: 0.041
A17: Total | B17: Residential Equipment: Equipment Stock: Main Space Heaters: Total: Reference case | C17: AEO.2023.REF2023.EQNR_STK_RESD_MSHR_TOT_NA_NA_MILL.A | D17: millions | F17: 122.47958 | G17: 123.69027 | H17: 124.90303 | I17: 126.14259 | J17: 127.3786 | K17: 128.62054 | L17: 129.87079 | M17: 131.11156 | N17: 132.32124 | O17: 133.5078 | P17: 134.68579 | Q17: 135.83856 | R17: 136.95584 | S17: 138.05812 | T17: 139.16179 | U17: 140.25841 | V17: 141.35023 | W17: 142.4341 | X17: 143.52994 | Y17: 144.62639 | Z17: 145.70659 | AA17: 146.77846 | AB17: 147.8428 | AC17: 148.90096 | AD17: 149.94875 | AE17: 150.9928 | AF17: 152.02593 | AG17: 153.04695 | AH17: 154.05901 | AI17: 0.008
A18: Space Cooling (million units)
A19: Electric Heat Pumps | B19: Residential Equipment: Equipment Stock: Space Cooling: Electric Heat Pumps: Reference case | C19: AEO.2023.REF2023.EQNR_STK_RESD_SPC_EHP_NA_NA_MILL.A | D19: millions | F19: 13.315581 | G19: 13.570746 | H19: 13.82285 | I19: 14.081021 | J19: 14.338547 | K19: 14.596686 | L19: 14.856006 | M19: 15.113201 | N19: 15.364179 | O19: 15.610802 | P19: 15.855643 | Q19: 16.095505 | R19: 16.328897 | S19: 16.560503 | T19: 16.793638 | U19: 17.026976 | V19: 17.258608 | W19: 17.487829 | X19: 17.718796 | Y19: 17.949732 | Z19: 18.178335 | AA19: 18.406145 | AB19: 18.633224 | AC19: 18.859974 | AD19: 19.086088 | AE19: 19.312731 | AF19: 19.538191 | AG19: 19.762447 | AH19: 19.985924 | AI19: 0.015
A20: Natural Gas Heat Pumps | B20: Residential Equipment: Equipment Stock: Space Cooling: Natural Gas Heat Pumps: Reference case | C20: AEO.2023.REF2023.EQNR_STK_RESD_SPC_NHU_NA_NA_MILL.A | D20: millions | F20: 1.321198 | G20: 1.319242 | H20: 1.317296 | I20: 1.315357 | J20: 1.313426 | K20: 1.311503 | L20: 1.309587 | M20: 1.307679 | N20: 1.305779 | O20: 1.303886 | P20: 1.302001 | Q20: 1.300122 | R20: 1.298251 | S20: 1.296387 | T20: 1.29453 | U20: 1.29268 | V20: 1.290837 | W20: 1.289001 | X20: 1.287171 | Y20: 1.285348 | Z20: 1.283531 | AA20: 1.281721 | AB20: 1.279918 | AC20: 1.27812 | AD20: 1.276329 | AE20: 1.274545 | AF20: 1.272766 | AG20: 1.270993 | AH20: 1.269227 | AI20: -0.001
A21: Geothermal Heat Pumps | B21: Residential Equipment: Equipment Stock: Space Cooling: Geothermal Heat Pumps: Reference case | C21: AEO.2023.REF2023.EQNR_STK_RESD_SPC_GEHP_NA_NA_MILL.A | D21: millions | F21: 0.716036 | G21: 0.778759 | H21: 0.840134 | I21: 0.901506 | J21: 0.960454 | K21: 1.018172 | L21: 1.075549 | M21: 1.132756 | N21: 1.189252 | O21: 1.245526 | P21: 1.301908 | Q21: 1.35802 | R21: 1.41364 | S21: 1.469566 | T21: 1.525942 | U21: 1.581248 | V21: 1.635567 | W21: 1.688511 | X21: 1.741697 | Y21: 1.793962 | Z21: 1.844503 | AA21: 1.893613 | AB21: 1.941229 | AC21: 1.987596 | AD21: 2.03283 | AE21: 2.077794 | AF21: 2.122325 | AG21: 2.166455 | AH21: 2.210309 | AI21: 0.041
A22: Central Air Conditioners | B22: Residential Equipment: Equipment Stock: Space Cooling: Central Air Conditioners: Reference case | C22: AEO.2023.REF2023.EQNR_STK_RESD_SPC_CAC_NA_NA_MILL.A | D22: millions | F22: 65.952873 | G22: 67.531487 | H22: 69.112846 | I22: 70.710129 | J22: 72.30307 | K22: 73.89785 | L22: 75.496254 | M22: 77.087234 | N22: 78.657112 | O22: 80.210655 | P22: 81.756866 | Q22: 83.285324 | R22: 84.789772 | S22: 86.282951 | T22: 87.774986 | U22: 89.260513 | V22: 90.740982 | W22: 92.214447 | X22: 93.693588 | Y22: 95.171677 | Z22: 96.63768 | AA22: 98.096832 | AB22: 99.549744 | AC22: 100.99702 | AD22: 102.43625 | AE22: 103.87109 | AF22: 105.29724 | AG22: 106.71379 | AH22: 108.12277 | AI22: 0.018
A23: Room Air Conditioners | B23: Residential Equipment: Equipment Stock: Space Cooling: Room Air Conditioners: Reference case | C23: AEO.2023.REF2023.EQNR_STK_RESD_SPC_RAC_NA_NA_MILL.A | D23: millions | F23: 58.086197 | G23: 58.099602 | H23: 58.113243 | I23: 58.130096 | J23: 58.148983 | K23: 58.170322 | L23: 58.193909 | M23: 58.21701 | N23: 58.235847 | O23: 58.251923 | P23: 58.267937 | Q23: 58.282757 | R23: 58.294533 | S23: 58.304741 | T23: 58.315868 | U23: 58.326084 | V23: 58.335472 | W23: 58.3442 | X23: 58.355373 | Y23: 58.36763 | Z23: 58.379017 | AA23: 58.390129 | AB23: 58.400814 | AC23: 58.41119 | AD23: 58.42065 | AE23: 58.430313 | AF23: 58.439327 | AG23: 58.447399 | AH23: 58.45509 | AI23: 0
A24: Total | B24: Residential Equipment: Equipment Stock: Space Cooling: Total: Reference case | C24: AEO.2023.REF2023.EQNR_STK_RESD_SPC_TOT_NA_NA_MILL.A | D24: millions | F24: 139.39188 | G24: 141.29984 | H24: 143.20636 | I24: 145.13811 | J24: 147.06448 | K24: 148.99454 | L24: 150.93131 | M24: 152.85788 | N24: 154.75217 | O24: 156.62279 | P24: 158.48434 | Q24: 160.32173 | R24: 162.12509 | S24: 163.91415 | T24: 165.70497 | U24: 167.4875 | V24: 169.26147 | W24: 171.02399 | X24: 172.79663 | Y24: 174.56834 | Z24: 176.32306 | AA24: 178.06845 | AB24: 179.80493 | AC24: 181.53391 | AD24: 183.25215 | AE24: 184.96646 | AF24: 186.66986 | AG24: 188.36108 | AH24: 190.04332 | AI24: 0.011
A25: Water Heaters (million units)
A26: Electric | B26: Residential Equipment: Equipment Stock: Water Heaters: Electric: Reference case | C26: AEO.2023.REF2023.EQNR_STK_RESD_WHT_ELE_NA_NA_MILL.A | D26: millions | F26: 60.580669 | G26: 60.983253 | H26: 61.337627 | I26: 61.675991 | J26: 61.982437 | K26: 62.286163 | L26: 62.581848 | M26: 62.861568 | N26: 63.111282 | O26: 63.367752 | P26: 63.636322 | Q26: 63.985218 | R26: 64.382027 | S26: 64.897079 | T26: 65.400185 | U26: 65.903778 | V26: 66.40728 | W26: 66.89624 | X26: 67.381805 | Y26: 67.859169 | Z26: 68.323227 | AA26: 68.776733 | AB26: 69.220825 | AC26: 69.659088 | AD26: 70.099632 | AE26: 70.538925 | AF26: 70.972908 | AG26: 71.406891 | AH26: 71.842628 | AI26: 0.006
A27: Natural Gas | B27: Residential Equipment: Equipment Stock: Water Heaters: Natural Gas: Reference case | C27: AEO.2023.REF2023.EQNR_STK_RESD_WHT_NG_NA_NA_MILL.A | D27: millions | F27: 61.25243 | G27: 61.855328 | H27: 62.501675 | I27: 63.183994 | J27: 63.881008 | K27: 64.589165 | L27: 65.313995 | M27: 66.041458 | N27: 66.761238 | O27: 67.455582 | P27: 68.133423 | Q27: 68.80352 | R27: 69.458298 | S27: 70.120712 | T27: 70.7752 | U27: 71.421005 | V27: 72.060173 | W27: 72.70253 | X27: 73.355804 | Y27: 74.013893 | Z27: 74.66552 | AA27: 75.31604 | AB27: 75.965561 | AC27: 76.611816 | AD27: 77.243378 | AE27: 77.870567 | AF27: 78.490524 | AG27: 79.097527 | AH27: 79.692604 | AI27: 0.009
A28: Distillate Fuel Oil | B28: Residential Equipment: Equipment Stock: Water Heaters: Distillate Fuel Oil: Reference case | C28: AEO.2023.REF2023.EQNR_STK_RESD_WHT_DFO_NA_NA_MILL.A | D28: millions | F28: 2.542532 | G28: 2.484457 | H28: 2.431864 | I28: 2.385705 | J28: 2.343567 | K28: 2.305742 | L28: 2.272055 | M28: 2.242364 | N28: 2.216697 | O28: 2.188768 | P28: 2.159277 | Q28: 2.128753 | R28: 2.098122 | S28: 2.066852 | T28: 2.036216 | U28: 2.006083 | V28: 1.976985 | W28: 1.948926 | X28: 1.922033 | Y28: 1.896241 | Z28: 1.871523 | AA28: 1.847718 | AB28: 1.824666 | AC28: 1.80236 | AD28: 1.780556 | AE28: 1.759241 | AF28: 1.738419 | AG28: 1.717659 | AH28: 1.697292 | AI28: -0.014
A29: Propane | B29: Residential Equipment: Equipment Stock: Water Heaters: Propane: Reference case | C29: AEO.2023.REF2023.EQNR_STK_RESD_WHT_PROP_NA_NA_MILL.A | D29: millions | F29: 3.944016 | G29: 3.844217 | H29: 3.754283 | I29: 3.67485 | J29: 3.605606 | K29: 3.545926 | L29: 3.495781 | M29: 3.454613 | N29: 3.421728 | O29: 3.383463 | P29: 3.341427 | Q29: 3.296932 | R29: 3.250626 | S29: 3.203295 | T29: 3.156687 | U29: 3.1109 | V29: 3.066498 | W29: 3.024202 | X29: 2.984899 | Y29: 2.94847 | Z29: 2.914493 | AA29: 2.882922 | AB29: 2.853478 | AC29: 2.825944 | AD29: 2.799708 | AE29: 2.775011 | AF29: 2.751561 | AG29: 2.729004 | AH29: 2.707524 | AI29: -0.013
A30: Solar Thermal | B30: Residential Equipment: Equipment Stock: Water Heaters: Solar Thermal: Reference case | C30: AEO.2023.REF2023.EQNR_STK_RESD_WHT_SLR_THERM_NA_MILL.A | D30: millions | F30: 2.232774 | G30: 2.576883 | H30: 2.912508 | I30: 3.238233 | J30: 3.563558 | K30: 3.872656 | L30: 4.167933 | M30: 4.454165 | N30: 4.734822 | O30: 5.018878 | P30: 5.304139 | Q30: 5.495253 | R30: 5.620392 | S30: 5.606394 | T30: 5.612399 | U30: 5.618275 | V30: 5.623932 | W30: 5.629901 | X30: 5.636178 | Y30: 5.642672 | Z30: 5.649299 | AA30: 5.656049 | AB30: 5.662947 | AC30: 5.670003 | AD30: 5.677579 | AE30: 5.685092 | AF30: 5.692599 | AG30: 5.700052 | AH30: 5.707356 | AI30: 0.034
A31: Total | B31: Residential Equipment: Equipment Stock: Water Heaters: Total: Reference case | C31: AEO.2023.REF2023.EQNR_STK_RESD_WHT_TOT_NA_NA_MILL.A | D31: millions | F31: 130.55243 | G31: 131.74414 | H31: 132.93796 | I31: 134.15877 | J31: 135.37617 | K31: 136.59966 | L31: 137.8316 | M31: 139.05418 | N31: 140.24576 | O31: 141.41444 | P31: 142.57459 | Q31: 143.70969 | R31: 144.80948 | S31: 145.89433 | T31: 146.98068 | U31: 148.06004 | V31: 149.13487 | W31: 150.2018 | X31: 151.28072 | Y31: 152.36044 | Z31: 153.42404 | AA31: 154.47946 | AB31: 155.52748 | AC31: 156.5692 | AD31: 157.60088 | AE31: 158.62883 | AF31: 159.64601 | AG31: 160.65115 | AH31: 161.6474 | AI31: 0.008
A32: Cooking Equipment (million units)
A33: Electric | B33: Residential Equipment: Equipment Stock: Cooking Equipment: Electric: Reference case | C33: AEO.2023.REF2023.EQNR_STK_RESD_CER_ELE_NA_NA_MILL.A | D33: millions | F33: 98.268684 | G33: 98.918465 | H33: 99.554741 | I33: 100.19855 | J33: 100.82862 | K33: 101.44907 | L33: 102.06017 | M33: 102.62416 | N33: 103.12352 | O33: 103.55598 | P33: 103.92822 | Q33: 104.31216 | R33: 104.7261 | S33: 105.18793 | T33: 105.71883 | U33: 106.31783 | V33: 106.90277 | W33: 107.47091 | X33: 108.03522 | Y33: 108.58673 | Z33: 109.11317 | AA33: 109.61954 | AB33: 110.10674 | AC33: 110.57737 | AD33: 111.03217 | AE33: 111.47945 | AF33: 111.91858 | AG33: 112.35443 | AH33: 112.79388 | AI33: 0.005
A34: Natural Gas | B34: Residential Equipment: Equipment Stock: Cooking Equipment: Natural Gas: Reference case | C34: AEO.2023.REF2023.EQNR_STK_RESD_CER_NG_NA_NA_MILL.A | D34: millions | F34: 48.883518 | G34: 49.409149 | H34: 49.952679 | I34: 50.517521 | J34: 51.095181 | K34: 51.691891 | L34: 52.309582 | M34: 52.968777 | N34: 53.66621 | O34: 54.41114 | P34: 55.209866 | Q34: 55.967617 | R34: 56.656403 | S34: 57.278698 | T34: 57.828838 | U34: 58.300526 | V34: 58.784473 | W34: 59.280293 | X34: 59.794044 | Y34: 60.32373 | Z34: 60.864475 | AA34: 61.418552 | AB34: 61.984871 | AC34: 62.561092 | AD34: 63.141663 | AE34: 63.723984 | AF34: 64.30146 | AG34: 64.868683 | AH34: 65.422531 | AI34: 0.01
A35: Propane | B35: Residential Equipment: Equipment Stock: Cooking Equipment: Propane: Reference case | C35: AEO.2023.REF2023.EQNR_STK_RESD_CER_PROP_NA_NA_MILL.A | D35: millions | F35: 7.251641 | G35: 7.235342 | H35: 7.217015 | I35: 7.196943 | J35: 7.174531 | K35: 7.148907 | L35: 7.120317 | M35: 7.088118 | N35: 7.051433 | O35: 7.011372 | P35: 6.969453 | Q35: 6.931829 | R35: 6.898018 | S35: 6.868111 | T35: 6.842745 | U35: 6.821068 | V35: 6.79666 | W35: 6.769514 | X35: 6.740311 | Y35: 6.708988 | Z35: 6.67562 | AA35: 6.640938 | AB35: 6.605863 | AC35: 6.571425 | AD35: 6.53839 | AE35: 6.507637 | AF35: 6.479108 | AG35: 6.452258 | AH35: 6.426418 | AI35: -0.004
A36: Total | B36: Residential Equipment: Equipment Stock: Cooking Equipment: Total: Reference case | C36: AEO.2023.REF2023.EQNR_STK_RESD_CER_TOT_NA_NA_MILL.A | D36: millions | F36: 154.40385 | G36: 155.56294 | H36: 156.72443 | I36: 157.91303 | J36: 159.09833 | K36: 160.28987 | L36: 161.49007 | M36: 162.68106 | N36: 163.84117 | O36: 164.97849 | P36: 166.10754 | Q36: 167.21159 | R36: 168.28052 | S36: 169.33475 | T36: 170.39041 | U36: 171.43942 | V36: 172.4839 | W36: 173.52072 | X36: 174.56958 | Y36: 175.61945 | Z36: 176.65326 | AA36: 177.67902 | AB36: 178.69748 | AC36: 179.70989 | AD36: 180.71222 | AE36: 181.71106 | AF36: 182.69914 | AG36: 183.67537 | AH36: 184.64282 | AI36: 0.006
A37: Clothes Dryers (million units)
A38: Electric | B38: Residential Equipment: Equipment Stock: Clothes Dryers: Electric: Reference case | C38: AEO.2023.REF2023.EQNR_STK_RESD_CDR_ELE_NA_NA_MILL.A | D38: millions | F38: 86.664726 | G38: 88.297852 | H38: 89.928329 | I38: 91.593002 | J38: 93.232185 | K38: 94.86705 | L38: 96.512413 | M38: 98.151497 | N38: 99.765617 | O38: 101.36159 | P38: 102.95294 | Q38: 104.52692 | R38: 106.11953 | S38: 107.71137 | T38: 109.31779 | U38: 110.90412 | V38: 112.47349 | W38: 114.02781 | X38: 115.58364 | Y38: 117.13265 | Z38: 118.66014 | AA38: 120.17596 | AB38: 121.68253 | AC38: 123.18261 | AD38: 124.6744 | AE38: 126.16296 | AF38: 127.6415 | AG38: 129.10883 | AH38: 130.56717 | AI38: 0.015
A39: Natural Gas | B39: Residential Equipment: Equipment Stock: Clothes Dryers: Natural Gas: Reference case | C39: AEO.2023.REF2023.EQNR_STK_RESD_CDR_NG_NA_NA_MILL.A | D39: millions | F39: 20.076683 | G39: 20.41683 | H39: 20.774427 | I39: 21.150564 | J39: 21.546068 | K39: 21.964548 | L39: 22.379805 | M39: 22.792025 | N39: 23.198757 | O39: 23.600092 | P39: 23.995813 | Q39: 24.382277 | R39: 24.755445 | S39: 25.112667 | T39: 25.454254 | U39: 25.806086 | V39: 26.167633 | W39: 26.537321 | X39: 26.915823 | Y39: 27.30057 | Z39: 27.687328 | AA39: 28.075541 | AB39: 28.46377 | AC39: 28.850496 | AD39: 29.233149 | AE39: 29.61228 | AF39: 29.987488 | AG39: 30.358225 | AH39: 30.725327 | AI39: 0.015
A40: Total | B40: Residential Equipment: Equipment Stock: Clothes Dryers: Total: Reference case | C40: AEO.2023.REF2023.EQNR_STK_RESD_CDR_TOT_NA_NA_MILL.A | D40: millions | F40: 106.74141 | G40: 108.71468 | H40: 110.70276 | I40: 112.74357 | J40: 114.77825 | K40: 116.8316 | L40: 118.89222 | M40: 120.94352 | N40: 122.96437 | O40: 124.96168 | P40: 126.94875 | Q40: 128.9092 | R40: 130.87497 | S40: 132.82404 | T40: 134.77203 | U40: 136.71021 | V40: 138.64113 | W40: 140.56512 | X40: 142.49947 | Y40: 144.43323 | Z40: 146.34747 | AA40: 148.25151 | AB40: 150.1463 | AC40: 152.03311 | AD40: 153.90755 | AE40: 155.77524 | AF40: 157.629 | AG40: 159.46706 | AH40: 161.2925 | AI40: 0.015
...

Sheet AEO25_Table_21._Residential
A1: Table 21. Residential Sector Equipment Stock and Efficiency, and Distributed Generation
A2: https://www.eia.gov/outlooks/aeo/data/browser/#/?id=30-AEO2025&cases=highZTC&sourcekey=0
A3: Tue Dec 02 2025 13:21:44 GMT-0800 (Pacific Standard Time)
A4: Source: U.S. Energy Information Administration
B5: full name | C5: api key | D5: units | E5: 2023 | F5: 2024 | G5: 2025 | H5: 2026 | I5: 2027 | J5: 2028 | K5: 2029 | L5: 2030 | M5: 2031 | N5: 2032 | O5: 2033 | P5: 2034 | Q5: 2035 | R5: 2036 | S5: 2037 | T5: 2038 | U5: 2039 | V5: 2040 | W5: 2041 | X5: 2042 | Y5: 2043 | Z5: 2044 | AA5: 2045 | AB5: 2046 | AC5: 2047 | AD5: 2048 | AE5: 2049 | AF5: 2050 | AG5: Growth (2024-2050)
A6: Equipment Stock (million units)
A7: Main Space Heaters
A8: Electric Heat Pumps | B8: Residential Equipment: Equipment Stock: Main Space Heaters: Electric Heat Pumps: High Zero-Carbon Technology Cost | C8: AEO.2025.HIGHZTC.EQNR_STK_RESD_MSHR_EHP_NA_NA_MILL.A | D8: millions | F8: 16.645529 | G8: 16.962238 | H8: 17.297937 | I8: 17.63735 | J8: 17.975958 | K8: 18.323191 | L8: 18.671122 | M8: 19.020292 | N8: 19.366976 | O8: 19.701832 | P8: 20.022341 | Q8: 20.338335 | R8: 20.648127 | S8: 20.94591 | T8: 21.232155 | U8: 21.506626 | V8: 21.772039 | W8: 22.026169 | X8: 22.27137 | Y8: 22.506741 | Z8: 22.737045 | AA8: 22.966516 | AB8: 23.194811 | AC8: 23.422667 | AD8: 23.650106 | AE8: 23.877323 | AF8: 24.103533 | AG8: 0.014
A9: Electric Other | B9: Residential Equipment: Equipment Stock: Main Space Heaters: Electric Other: High Zero-Carbon Technology Cost | C9: AEO.2025.HIGHZTC.EQNR_STK_RESD_MSHR_ELO_NA_NA_MILL.A | D9: millions | F9: 26.605318 | G9: 26.78159 | H9: 26.987282 | I9: 27.200581 | J9: 27.420454 | K9: 27.653374 | L9: 27.889208 | M9: 28.127293 | N9: 28.362696 | O9: 28.587048 | P9: 28.798485 | Q9: 29.005108 | R9: 29.206934 | S9: 29.397682 | T9: 29.579088 | U9: 29.751591 | V9: 29.918131 | W9: 30.076429 | X9: 30.228321 | Y9: 30.375742 | Z9: 30.522755 | AA9: 30.670509 | AB9: 30.818306 | AC9: 30.9662 | AD9: 31.114233 | AE9: 31.262747 | AF9: 31.41095 | AG9: 0.006
A10: Natural Gas Heat Pumps | B10: Residential Equipment: Equipment Stock: Main Space Heaters: Natural Gas Heat Pumps: High Zero-Carbon Technology Cost | C10: AEO.2025.HIGHZTC.EQNR_STK_RESD_MSHR_NHU_NA_NA_MILL.A | D10: millions | F10: 1.335856 | G10: 1.335485 | H10: 1.335121 | I10: 1.334763 | J10: 1.334411 | K10: 1.334067 | L10: 1.333728 | M10: 1.333394 | N10: 1.333067 | O10: 1.332746 | P10: 1.332431 | Q10: 1.33212 | R10: 1.331816 | S10: 1.331517 | T10: 1.331223 | U10: 1.330934 | V10: 1.330651 | W10: 1.330373 | X10: 1.330099 | Y10: 1.329831 | Z10: 1.329567 | AA10: 1.329308 | AB10: 1.329053 | AC10: 1.328804 | AD10: 1.328558 | AE10: 1.328316 | AF10: 1.328079 | AG10: 0
A11: Natural Gas Other | B11: Residential Equipment: Equipment Stock: Main Space Heaters: Natural Gas Other: High Zero-Carbon Technology Cost | C11: AEO.2025.HIGHZTC.EQNR_STK_RESD_MSHR_NGO_NA_NA_MILL.A | D11: millions | F11: 65.614693 | G11: 66.503311 | H11: 67.422646 | I11: 68.347206 | J11: 69.275345 | K11: 70.215851 | L11: 71.155624 | M11: 72.095222 | N11: 73.022018 | O11: 73.917961 | P11: 74.776138 | Q11: 75.619469 | R11: 76.443016 | S11: 77.232452 | T11: 77.991676 | U11: 78.71611 | V11: 79.412209 | W11: 80.076683 | X11: 80.717903 | Y11: 81.333214 | Z11: 81.934601 | AA11: 82.534103 | AB11: 83.129738 | AC11: 83.72612 | AD11: 84.322975 | AE11: 84.920403 | AF11: 85.516907 | AG11: 0.01
A12: Distillate Fuel Oil | B12: Residential Equipment: Equipment Stock: Main Space Heaters: Distillate Fuel Oil: High Zero-Carbon Technology Cost | C12: AEO.2025.HIGHZTC.EQNR_STK_RESD_MSHR_DFO_NA_NA_MILL.A | D12: millions | F12: 4.76794 | G12: 4.7259 | H12: 4.684821 | I12: 4.644579 | J12: 4.60502 | K12: 4.565969 | L12: 4.526826 | M12: 4.487612 | N12: 4.449521 | O12: 4.412687 | P12: 4.377314 | Q12: 4.343427 | R12: 4.310317 | S12: 4.277948 | T12: 4.246086 | U12: 4.214488 | V12: 4.183174 | W12: 4.152061 | X12: 4.122024 | Y12: 4.093054 | Z12: 4.065121 | AA12: 4.0385 | AB12: 4.012821 | AC12: 3.986746 | AD12: 3.960447 | AE12: 3.934162 | AF12: 3.908093 | AG12: -0.008
A13: Propane | B13: Residential Equipment: Equipment Stock: Main Space Heaters: Propane: High Zero-Carbon Technology Cost | C13: AEO.2025.HIGHZTC.EQNR_STK_RESD_MSHR_PROP_NA_NA_MILL.A | D13: millions | F13: 5.242597 | G13: 5.231007 | H13: 5.222726 | I13: 5.213856 | J13: 5.201762 | K13: 5.192317 | L13: 5.180441 | M13: 5.167188 | N13: 5.155312 | O13: 5.143894 | P13: 5.132373 | Q13: 5.121347 | R13: 5.111237 | S13: 5.101963 | T13: 5.09299 | U13: 5.084504 | V13: 5.077328 | W13: 5.070891 | X13: 5.064682 | Y13: 5.058537 | Z13: 5.052648 | AA13: 5.047476 | AB13: 5.043245 | AC13: 5.03766 | AD13: 5.030745 | AE13: 5.022702 | AF13: 5.01332 | AG13: -0.002
A14: Kerosene | B14: Residential Equipment: Equipment Stock: Main Space Heaters: Kerosene: High Zero-Carbon Technology Cost | C14: AEO.2025.HIGHZTC.EQNR_STK_RESD_MSHR_KRS_NA_NA_MILL.A | D14: millions | F14: 0.004925 | G14: 0.007897 | H14: 0.011523 | I14: 0.015072 | J14: 0.018269 | K14: 0.02133 | L14: 0.02419 | M14: 0.027018 | N14: 0.029863 | O14: 0.032679 | P14: 0.035394 | Q14: 0.038013 | R14: 0.040598 | S14: 0.043115 | T14: 0.045557 | U14: 0.047931 | V14: 0.050323 | W14: 0.052708 | X14: 0.055048 | Y14: 0.057337 | Z14: 0.059592 | AA14: 0.06182 | AB14: 0.063984 | AC14: 0.066125 | AD14: 0.068224 | AE14: 0.0703 | AF14: 0.072325 | AG14: 0.109
A15: Wood Stoves | B15: Residential Equipment: Equipment Stock: Main Space Heaters: Wood Stoves: High Zero-Carbon Technology Cost | C15: AEO.2025.HIGHZTC.EQNR_STK_RESD_MSHR_WDS_NA_NA_MILL.A | D15: millions | F15: 2.220637 | G15: 2.212639 | H15: 2.204829 | I15: 2.197059 | J15: 2.189375 | K15: 2.181753 | L15: 2.174187 | M15: 2.166692 | N15: 2.159028 | O15: 2.151248 | P15: 2.1434 | Q15: 2.135421 | R15: 2.127357 | S15: 2.119169 | T15: 2.11095 | U15: 2.102684 | V15: 2.094329 | W15: 2.085804 | X15: 2.077575 | Y15: 2.069646 | Z15: 2.062065 | AA15: 2.054862 | AB15: 2.048036 | AC15: 2.041663 | AD15: 2.035719 | AE15: 2.030173 | AF15: 2.025021 | AG15: -0.004
A16: Geothermal Heat Pumps | B16: Residential Equipment: Equipment Stock: Main Space Heaters: Geothermal Heat Pumps: High Zero-Carbon Technology Cost | C16: AEO.2025.HIGHZTC.EQNR_STK_RESD_MSHR_GEHP_NA_NA_MILL.A | D16: millions | F16: 1.360675 | G16: 1.408181 | H16: 1.455492 | I16: 1.50272 | J16: 1.549133 | K16: 1.595817 | L16: 1.642325 | M16: 1.688836 | N16: 1.73555 | O16: 1.781672 | P16: 1.826767 | Q16: 1.871948 | R16: 1.916753 | S16: 1.960757 | T16: 2.003791 | U16: 2.045475 | V16: 2.086105 | W16: 2.125625 | X16: 2.164013 | Y16: 2.200763 | Z16: 2.236357 | AA16: 2.271668 | AB16: 2.306613 | AC16: 2.34118 | AD16: 2.37536 | AE16: 2.409184 | AF16: 2.442582 | AG16: 0.023
A17: Total | B17: Residential Equipment: Equipment Stock: Main Space Heaters: Total: High Zero-Carbon Technology Cost | C17: AEO.2025.HIGHZTC.EQNR_STK_RESD_MSHR_TOT_NA_NA_MILL.A | D17: millions | F17: 123.79816 | G17: 125.16825 | H17: 126.62237 | I17: 128.09319 | J17: 129.56972 | K17: 131.08366 | L17: 132.59764 | M17: 134.11356 | N17: 135.61403 | O17: 137.06177 | P17: 138.44466 | Q17: 139.80519 | R17: 141.13614 | S17: 142.41052 | T17: 143.6335 | U17: 144.80035 | V17: 145.9243 | W17: 146.99674 | X17: 148.03105 | Y17: 149.02486 | Z17: 149.99976 | AA17: 150.97473 | AB17: 151.94659 | AC17: 152.91716 | AD17: 153.88637 | AE17: 154.8553 | AF17: 155.82082 | AG17: 0.009
A18: Space Cooling (million units)
A19: Electric Heat Pumps | B19: Residential Equipment: Equipment Stock: Space Cooling: Electric Heat Pumps: High Zero-Carbon Technology Cost | C19: AEO.2025.HIGHZTC.EQNR_STK_RESD_SPC_EHP_NA_NA_MILL.A | D19: millions | F19: 16.645529 | G19: 16.962236 | H19: 17.297932 | I19: 17.637352 | J19: 17.975958 | K19: 18.323191 | L19: 18.671116 | M19: 19.02029 | N19: 19.36697 | O19: 19.701841 | P19: 20.022339 | Q19: 20.338339 | R19: 20.648117 | S19: 20.945915 | T19: 21.232161 | U19: 21.506636 | V19: 21.772034 | W19: 22.026175 | X19: 22.271376 | Y19: 22.506746 | Z19: 22.737047 | AA19: 22.966528 | AB19: 23.194815 | AC19: 23.422672 | AD19: 23.650103 | AE19: 23.87734 | AF19: 24.103531 | AG19: 0.014
A20: Natural Gas Heat Pumps | B20: Residential Equipment: Equipment Stock: Space Cooling: Natural Gas Heat Pumps: High Zero-Carbon Technology Cost | C20: AEO.2025.HIGHZTC.EQNR_STK_RESD_SPC_NHU_NA_NA_MILL.A | D20: millions | F20: 1.335856 | G20: 1.335485 | H20: 1.335121 | I20: 1.334763 | J20: 1.334412 | K20: 1.334066 | L20: 1.333727 | M20: 1.333394 | N20: 1.333067 | O20: 1.332746 | P20: 1.33243 | Q20: 1.33212 | R20: 1.331816 | S20: 1.331517 | T20: 1.331223 | U20: 1.330934 | V20: 1.330651 | W20: 1.330372 | X20: 1.330099 | Y20: 1.329831 | Z20: 1.329567 | AA20: 1.329308 | AB20: 1.329053 | AC20: 1.328803 | AD20: 1.328558 | AE20: 1.328316 | AF20: 1.32808 | AG20: 0
A21: Geothermal Heat Pumps | B21: Residential Equipment: Equipment Stock: Space Cooling: Geothermal Heat Pumps: High Zero-Carbon Technology Cost | C21: AEO.2025.HIGHZTC.EQNR_STK_RESD_SPC_GEHP_NA_NA_MILL.A | D21: millions | F21: 1.360675 | G21: 1.40818 | H21: 1.455491 | I21: 1.50272 | J21: 1.549134 | K21: 1.595817 | L21: 1.642326 | M21: 1.688836 | N21: 1.73555 | O21: 1.781671 | P21: 1.826768 | Q21: 1.871948 | R21: 1.916753 | S21: 1.960756 | T21: 2.00379 | U21: 2.045475 | V21: 2.086105 | W21: 2.125626 | X21: 2.164013 | Y21: 2.200764 | Z21: 2.236356 | AA21: 2.271667 | AB21: 2.306613 | AC21: 2.341179 | AD21: 2.37536 | AE21: 2.409185 | AF21: 2.442581 | AG21: 0.023
A22: Central Air Conditioners | B22: Residential Equipment: Equipment Stock: Space Cooling: Central Air Conditioners: High Zero-Carbon Technology Cost | C22: AEO.2025.HIGHZTC.EQNR_STK_RESD_SPC_CAC_NA_NA_MILL.A | D22: millions | F22: 79.649452 | G22: 80.900047 | H22: 82.197365 | I22: 83.50415 | J22: 84.811256 | K22: 86.135658 | L22: 87.457458 | M22: 88.779007 | N22: 90.091568 | O22: 91.374115 | P22: 92.619194 | Q22: 93.851295 | R22: 95.065895 | S22: 96.248184 | T22: 97.400749 | U22: 98.520065 | V22: 99.614029 | W22: 100.67795 | X22: 101.7196 | Y22: 102.7365 | Z22: 103.74096 | AA22: 104.74514 | AB22: 105.74709 | AC22: 106.74812 | AD22: 107.74809 | AE22: 108.7477 | AF22: 109.74496 | AG22: 0.012
A23: Room Air Conditioners | B23: Residential Equipment: Equipment Stock: Space Cooling: Room Air Conditioners: High Zero-Carbon Technology Cost | C23: AEO.2025.HIGHZTC.EQNR_STK_RESD_SPC_RAC_NA_NA_MILL.A | D23: millions | F23: 43.140507 | G23: 43.232368 | H23: 43.345276 | I23: 43.46328 | J23: 43.586712 | K23: 43.719509 | L23: 43.854378 | M23: 43.990795 | N23: 44.124844 | O23: 44.250751 | P23: 44.367279 | Q23: 44.480221 | R23: 44.589432 | S23: 44.690407 | T23: 44.784588 | U23: 44.872437 | V23: 44.956017 | W23: 45.033756 | X23: 45.107018 | Y23: 45.177341 | Z23: 45.247604 | AA23: 45.318493 | AB23: 45.389637 | AC23: 45.461102 | AD23: 45.53299 | AE23: 45.605553 | AF23: 45.678272 | AG23: 0.002
A24: Total | B24: Residential Equipment: Equipment Stock: Space Cooling: Total: High Zero-Carbon Technology Cost | C24: AEO.2025.HIGHZTC.EQNR_STK_RESD_SPC_TOT_NA_NA_MILL.A | D24: millions | F24: 142.13202 | G24: 143.83832 | H24: 145.63118 | I24: 147.44226 | J24: 149.25748 | K24: 151.10825 | L24: 152.95901 | M24: 154.81233 | N24: 156.65199 | O24: 158.44113 | P24: 160.16801 | Q24: 161.87393 | R24: 163.55202 | S24: 165.17679 | T24: 166.75252 | U24: 168.27554 | V24: 169.75884 | W24: 171.19388 | X24: 172.5921 | Y24: 173.95119 | Z24: 175.29153 | AA24: 176.63113 | AB24: 177.96719 | AC24: 179.30188 | AD24: 180.6351 | AE24: 181.96808 | AF24: 183.29742 | AG24: 0.01
A25: Water Heaters (million units)
A26: Electric | B26: Residential Equipment: Equipment Stock: Water Heaters: Electric: High Zero-Carbon Technology Cost | C26: AEO.2025.HIGHZTC.EQNR_STK_RESD_WHT_ELE_NA_NA_MILL.A | D26: millions | F26: 62.064091 | G26: 62.296463 | H26: 62.600315 | I26: 62.92688 | J26: 63.228168 | K26: 64.053841 | L26: 64.829208 | M26: 65.567513 | N26: 66.280678 | O26: 66.984314 | P26: 67.653503 | Q26: 68.314453 | R26: 68.97834 | S26: 69.632027 | T26: 70.273941 | U26: 70.902107 | V26: 71.522514 | W26: 72.129929 | X26: 72.728317 | Y26: 73.317879 | Z26: 73.899185 | AA26: 74.478477 | AB26: 75.054726 | AC26: 75.626358 | AD26: 76.193161 | AE26: 76.757141 | AF26: 77.316254 | AG26: 0.008
A27: Natural Gas | B27: Residential Equipment: Equipment Stock: Water Heaters: Natural Gas: High Zero-Carbon Technology Cost | C27: AEO.2025.HIGHZTC.EQNR_STK_RESD_WHT_NG_NA_NA_MILL.A | D27: millions | F27: 64.896248 | G27: 65.896965 | H27: 66.916298 | I27: 67.939789 | J27: 68.981888 | K27: 69.718719 | L27: 70.479591 | M27: 71.256226 | N27: 72.025871 | O27: 72.786705 | P27: 73.528267 | Q27: 74.274551 | R27: 74.990112 | S27: 75.663231 | T27: 76.299583 | U27: 76.895554 | V27: 77.45697 | W27: 77.980125 | X27: 78.47403 | Y27: 78.935936 | Z27: 79.385979 | AA27: 79.836296 | AB27: 80.28476 | AC27: 80.734146 | AD27: 81.184738 | AE27: 81.635727 | AF27: 82.086113 | AG27: 0.009
A28: Distillate Fuel Oil | B28: Residential Equipment: Equipment Stock: Water Heaters: Distillate Fuel Oil: High Zero-Carbon Technology Cost | C28: AEO.2025.HIGHZTC.EQNR_STK_RESD_WHT_DFO_NA_NA_MILL.A | D28: millions | F28: 2.328812 | G28: 2.229761 | H28: 2.137233 | I28: 2.050461 | J28: 1.970477 | K28: 1.896038 | L28: 1.830604 | M28: 1.773455 | N28: 1.724959 | O28: 1.685178 | P28: 1.65441 | Q28: 1.632862 | R28: 1.610081 | S28: 1.586346 | T28: 1.561976 | U28: 1.537204 | V28: 1.512282 | W28: 1.487386 | X28: 1.462679 | Y28: 1.438287 | Z28: 1.414327 | AA28: 1.390946 | AB28: 1.368182 | AC28: 1.346109 | AD28: 1.32476 | AE28: 1.304158 | AF28: 1.284297 | AG28: -0.023
A29: Propane | B29: Residential Equipment: Equipment Stock: Water Heaters: Propane: High Zero-Carbon Technology Cost | C29: AEO.2025.HIGHZTC.EQNR_STK_RESD_WHT_PROP_NA_NA_MILL.A | D29: millions | F29: 3.994673 | G29: 3.890314 | H29: 3.796247 | I29: 3.708011 | J29: 3.626368 | K29: 3.531686 | L29: 3.447552 | M29: 3.374222 | N29: 3.31144 | O29: 3.259597 | P29: 3.218467 | Q29: 3.18944 | R29: 3.157171 | S29: 3.122084 | T29: 3.084893 | U29: 3.04617 | V29: 3.007124 | W29: 2.967928 | X29: 2.928841 | Y29: 2.889926 | Z29: 2.851814 | AA29: 2.814927 | AB29: 2.779243 | AC29: 2.745224 | AD29: 2.712765 | AE29: 2.681901 | AF29: 2.652292 | AG29: -0.016
A30: Solar Thermal | B30: Residential Equipment: Equipment Stock: Water Heaters: Solar Thermal: High Zero-Carbon Technology Cost | C30: AEO.2025.HIGHZTC.EQNR_STK_RESD_WHT_SLR_THERM_NA_MILL.A | D30: millions | F30: 1.564945 | G30: 1.899681 | H30: 2.211646 | I30: 2.501981 | J30: 2.791456 | K30: 2.906761 | L30: 3.028901 | M30: 3.155326 | N30: 3.279312 | O30: 3.349281 | P30: 3.38851 | Q30: 3.387712 | R30: 3.389602 | S30: 3.391462 | T30: 3.393306 | U30: 3.395105 | V30: 3.396857 | W30: 3.398571 | X30: 3.400233 | Y30: 3.401839 | Z30: 3.403495 | AA30: 3.405192 | AB30: 3.40693 | AC30: 3.408704 | AD30: 3.410507 | AE30: 3.412341 | AF30: 3.414205 | AG30: 0.03
A31: Total | B31: Residential Equipment: Equipment Stock: Water Heaters: Total: High Zero-Carbon Technology Cost | C31: AEO.2025.HIGHZTC.EQNR_STK_RESD_WHT_TOT_NA_NA_MILL.A | D31: millions | F31: 134.84877 | G31: 136.21318 | H31: 137.66174 | I31: 139.12712 | J31: 140.59836 | K31: 142.10706 | L31: 143.61586 | M31: 145.12672 | N31: 146.62227 | O31: 148.06508 | P31: 149.44313 | Q31: 150.79901 | R31: 152.12529 | S31: 153.39516 | T31: 154.61371 | U31: 155.77615 | V31: 156.89575 | W31: 157.96393 | X31: 158.99411 | Y31: 159.98387 | Z31: 160.95477 | AA31: 161.92584 | AB31: 162.89384 | AC31: 163.86055 | AD31: 164.82593 | AE31: 165.79126 | AF31: 166.75317 | AG31: 0.008
A32: Cooking Equipment (million units)
A33: Electric | B33: Residential Equipment: Equipment Stock: Cooking Equipment: Electric: High Zero-Carbon Technology Cost | C33: AEO.2025.HIGHZTC.EQNR_STK_RESD_CER_ELE_NA_NA_MILL.A | D33: millions | F33: 100.27812 | G33: 101.10259 | H33: 101.98053 | I33: 102.8632 | J33: 103.74537 | K33: 104.65044 | L33: 105.55076 | M33: 106.44516 | N33: 107.31894 | O33: 108.1434 | P33: 108.88472 | Q33: 109.57114 | R33: 110.1867 | S33: 110.70435 | T33: 111.20811 | U33: 111.71865 | V33: 112.24985 | W33: 112.80871 | X33: 113.41383 | Y33: 113.98341 | Z33: 114.53365 | AA33: 115.07655 | AB33: 115.60883 | AC33: 116.13017 | AD33: 116.6391 | AE33: 117.13462 | AF33: 117.61186 | AG33: 0.006
A34: Natural Gas | B34: Residential Equipment: Equipment Stock: Cooking Equipment: Natural Gas: High Zero-Carbon Technology Cost | C34: AEO.2025.HIGHZTC.EQNR_STK_RESD_CER_NG_NA_NA_MILL.A | D34: millions | F34: 53.97237 | G34: 54.503727 | H34: 55.061764 | I34: 55.632816 | J34: 56.213551 | K34: 56.80965 | L34: 57.412582 | M34: 58.02486 | N34: 58.644409 | O34: 59.262939 | P34: 59.903133 | Q34: 60.579704 | R34: 61.301079 | S34: 62.067856 | T34: 62.795506 | U34: 63.458031 | V34: 64.053505 | W34: 64.565849 | X34: 64.989624 | Y34: 65.410423 | Z34: 65.83329 | AA34: 66.264915 | AB34: 66.705818 | AC34: 67.157867 | AD34: 67.622643 | AE34: 68.102386 | AF34: 68.598465 | AG34: 0.009
A35: Propane | B35: Residential Equipment: Equipment Stock: Cooking Equipment: Propane: High Zero-Carbon Technology Cost | C35: AEO.2025.HIGHZTC.EQNR_STK_RESD_CER_PROP_NA_NA_MILL.A | D35: millions | F35: 6.249792 | G35: 6.24914 | H35: 6.252706 | I35: 6.255498 | J35: 6.255161 | K35: 6.254043 | L35: 6.251281 | M35: 6.247181 | N35: 6.241242 | O35: 6.233177 | P35: 6.221874 | Q35: 6.207108 | R35: 6.1889 | S35: 6.166887 | T35: 6.14676 | U35: 6.128918 | V35: 6.114851 | W35: 6.104977 | X35: 6.099405 | Y35: 6.092152 | Z35: 6.083468 | AA35: 6.07354 | AB35: 6.062016 | AC35: 6.049131 | AD35: 6.034698 | AE35: 6.018864 | AF35: 6.001561 | AG35: -0.002
A36: Total | B36: Residential Equipment: Equipment Stock: Cooking Equipment: Total: High Zero-Carbon Technology Cost | C36: AEO.2025.HIGHZTC.EQNR_STK_RESD_CER_TOT_NA_NA_MILL.A | D36: millions | F36: 160.50027 | G36: 161.85547 | H36: 163.295 | I36: 164.75151 | J36: 166.21408 | K36: 167.71414 | L36: 169.21463 | M36: 170.71719 | N36: 172.20459 | O36: 173.63953 | P36: 175.00974 | Q36: 176.35796 | R36: 177.67668 | S36: 178.93909 | T36: 180.15037 | U36: 181.3056 | V36: 182.41821 | W36: 183.47954 | X36: 184.50285 | Y36: 185.48598 | Z36: 186.45041 | AA36: 187.41501 | AB36: 188.37665 | AC36: 189.33717 | AD36: 190.29645 | AE36: 191.25586 | AF36: 192.21188 | AG36: 0.007
A37: Clothes Dryers (million units)
A38: Electric | B38: Residential Equipment: Equipment Stock: Clothes Dryers: Electric: High Zero-Carbon Technology Cost | C38: AEO.2025.HIGHZTC.EQNR_STK_RESD_CDR_ELE_NA_NA_MILL.A | D38: millions | F38: 92.221107 | G38: 94.908974 | H38: 97.661568 | I38: 100.4443 | J38: 103.24648 | K38: 106.05999 | L38: 108.87318 | M38: 111.66229 | N38: 114.41385 | O38: 117.12387 | P38: 119.78091 | Q38: 122.4272 | R38: 125.05272 | S38: 127.63446 | T38: 130.17616 | U38: 132.67476 | V38: 135.14604 | W38: 137.59196 | X38: 139.98711 | Y38: 142.33012 | Z38: 144.64094 | AA38: 146.94054 | AB38: 149.23036 | AC38: 151.51019 | AD38: 153.78226 | AE38: 156.04994 | AF38: 158.30891 | AG38: 0.021
A39: Natural Gas | B39: Residential Equipment: Equipment Stock: Clothes Dryers: Natural Gas: High Zero-Carbon Technology Cost | C39: AEO.2025.HIGHZTC.EQNR_STK_RESD_CDR_NG_NA_NA_MILL.A | D39: millions | F39: 20.353802 | G39: 20.727465 | H39: 21.108976 | I39: 21.498468 | J39: 21.905369 | K39: 22.331652 | L39: 22.776669 | M39: 23.24667 | N39: 23.740404 | O39: 24.225313 | P39: 24.699818 | Q39: 25.166246 | R39: 25.623446 | S39: 26.068548 | T39: 26.501984 | U39: 26.919897 | V39: 27.319826 | W39: 27.699757 | X39: 28.090372 | Y39: 28.489046 | Z39: 28.897078 | AA39: 29.31538 | AB39: 29.741957 | AC39: 30.175976 | AD39: 30.615866 | AE39: 31.060276 | AF39: 31.508205 | AG39: 0.017
A40: Total | B40: Residential Equipment: Equipment Stock: Clothes Dryers: Total: High Zero-Carbon Technology Cost | C40: AEO.2025.HIGHZTC.EQNR_STK_RESD_CDR_TOT_NA_NA_MILL.A | D40: millions | F40: 112.57491 | G40: 115.63644 | H40: 118.77055 | I40: 121.94276 | J40: 125.15185 | K40: 128.39165 | L40: 131.64984 | M40: 134.90897 | N40: 138.15425 | O40: 141.34918 | P40: 144.48073 | Q40: 147.59345 | R40: 150.67616 | S40: 153.703 | T40: 156.67815 | U40: 159.59465 | V40: 162.46587 | W40: 165.29172 | X40: 168.07748 | Y40: 170.81917 | Z40: 173.53803 | AA40: 176.25592 | AB40: 178.97232 | AC40: 181.68617 | AD40: 184.39812 | AE40: 187.11021 | AF40: 189.81712 | AG40: 0.02
...

Sheet AEO23_table_22._Comm
A1: Table 22. Commercial Sector Energy Consumption, Floorspace, Equipment Efficiency, and Distributed Generation
A2: https://www.eia.gov/outlooks/aeo/data/browser/#/?id=32-AEO2023&cases=ref2023&sourcekey=0
A3: Sun May 04 2025 20:16:27 GMT-0700 (Pacific Daylight Time)
A4: Source: U.S. Energy Information Administration
B5: full name | C5: api key | D5: units | E5: 2021 | F5: 2022 | G5: 2023 | H5: 2024 | I5: 2025 | J5: 2026 | K5: 2027 | L5: 2028 | M5: 2029 | N5: 2030 | O5: 2031 | P5: 2032 | Q5: 2033 | R5: 2034 | S5: 2035 | T5: 2036 | U5: 2037 | V5: 2038 | W5: 2039 | X5: 2040 | Y5: 2041 | Z5: 2042 | AA5: 2043 | AB5: 2044 | AC5: 2045 | AD5: 2046 | AE5: 2047 | AF5: 2048 | AG5: 2049 | AH5: 2050 | AI5: Growth (2022-2050)
A6: Commercial Building Delivered
A7: Energy Consumption (quadrillion Btu)
A8: Assembly | B8: Commercial: Gross End-use: Assembly: Reference case | C8: AEO.2023.REF2023.#N/A.A | D8: quads | F8: 0.645733 | G8: 0.628144 | H8: 0.62174 | I8: 0.627551 | J8: 0.631386 | K8: 0.633341 | L8: 0.634329 | M8: 0.634228 | N8: 0.633376 | O8: 0.632204 | P8: 0.631712 | Q8: 0.629789 | R8: 0.62738 | S8: 0.624869 | T8: 0.622415 | U8: 0.619707 | V8: 0.616438 | W8: 0.613268 | X8: 0.609889 | Y8: 0.60662 | Z8: 0.603497 | AA8: 0.600765 | AB8: 0.598298 | AC8: 0.595616 | AD8: 0.592323 | AE8: 0.589637 | AF8: 0.587393 | AG8: 0.585342 | AH8: 0.583169 | AI8: -0.004
A9: Education | B9: Commercial: Gross End-use: Education: Reference case | C9: AEO.2023.REF2023.#N/A.A | D9: quads | F9: 1.023192 | G9: 1.003815 | H9: 1.000211 | I9: 1.013541 | J9: 1.024501 | K9: 1.032973 | L9: 1.040353 | M9: 1.045932 | N9: 1.049982 | O9: 1.053062 | P9: 1.057371 | Q9: 1.059303 | R9: 1.060372 | S9: 1.061235 | T9: 1.06226 | U9: 1.062465 | V9: 1.061857 | W9: 1.061067 | X9: 1.060739 | Y9: 1.060583 | Z9: 1.06075 | AA9: 1.061631 | AB9: 1.062934 | AC9: 1.064115 | AD9: 1.065007 | AE9: 1.066551 | AF9: 1.06862 | AG9: 1.070613 | AH9: 1.072455 | AI9: 0.002
A10: Food Sales | B10: Commercial: Gross End-use: Food Sales: Reference case | C10: AEO.2023.REF2023.#N/A.A | D10: quads | F10: 0.376753 | G10: 0.374265 | H10: 0.375342 | I10: 0.378536 | J10: 0.381119 | K10: 0.382864 | L10: 0.384441 | M10: 0.385803 | N10: 0.386818 | O10: 0.388211 | P10: 0.389563 | Q10: 0.39031 | R10: 0.390741 | S10: 0.391055 | T10: 0.391202 | U10: 0.391069 | V10: 0.39059 | W10: 0.389942 | X10: 0.389324 | Y10: 0.389086 | Z10: 0.388913 | AA10: 0.388801 | AB10: 0.388769 | AC10: 0.388698 | AD10: 0.388394 | AE10: 0.388341 | AF10: 0.388475 | AG10: 0.388726 | AH10: 0.388975 | AI10: 0.001
A11: Food Service | B11: Commercial: Gross End-use: Food Service: Reference case | C11: AEO.2023.REF2023.#N/A.A | D11: quads | F11: 0.559557 | G11: 0.551407 | H11: 0.557413 | I11: 0.565627 | J11: 0.572108 | K11: 0.576674 | L11: 0.580489 | M11: 0.583597 | N11: 0.585853 | O11: 0.588401 | P11: 0.590744 | Q11: 0.592037 | R11: 0.592774 | S11: 0.593398 | T11: 0.594019 | U11: 0.594302 | V11: 0.593912 | W11: 0.593581 | X11: 0.59289 | Y11: 0.592554 | Z11: 0.592391 | AA11: 0.592601 | AB11: 0.593097 | AC11: 0.593406 | AD11: 0.592836 | AE11: 0.592862 | AF11: 0.593445 | AG11: 0.594274 | AH11: 0.595011 | AI11: 0.002
A12: Health Care | B12: Commercial: Gross End-use: Health Care: Reference case | C12: AEO.2023.REF2023.#N/A.A | D12: quads | F12: 0.537446 | G12: 0.525337 | H12: 0.528509 | I12: 0.538635 | J12: 0.547313 | K12: 0.554273 | L12: 0.560439 | M12: 0.56541 | N12: 0.569363 | O12: 0.573106 | P12: 0.576964 | Q12: 0.579783 | R12: 0.582157 | S12: 0.584465 | T12: 0.586925 | U12: 0.589071 | V12: 0.590614 | W12: 0.592249 | X12: 0.593927 | Y12: 0.595674 | Z12: 0.597665 | AA12: 0.600155 | AB12: 0.603081 | AC12: 0.605845 | AD12: 0.608112 | AE12: 0.610984 | AF12: 0.614403 | AG12: 0.617943 | AH12: 0.621364 | AI12: 0.005
A13: Lodging | B13: Commercial: Gross End-use: Lodging: Reference case | C13: AEO.2023.REF2023.#N/A.A | D13: quads | F13: 0.596199 | G13: 0.589345 | H13: 0.595147 | I13: 0.604807 | J13: 0.613311 | K13: 0.620434 | L13: 0.627071 | M13: 0.633023 | N13: 0.63844 | O13: 0.643374 | P13: 0.649181 | Q13: 0.65363 | R13: 0.657586 | S13: 0.661524 | T13: 0.66545 | U13: 0.669019 | V13: 0.67191 | W13: 0.674736 | X13: 0.677333 | Y13: 0.679942 | Z13: 0.68261 | AA13: 0.685634 | AB13: 0.688987 | AC13: 0.691996 | AD13: 0.694103 | AE13: 0.696796 | AF13: 0.699991 | AG13: 0.703246 | AH13: 0.706087 | AI13: 0.006
A14: Office - Large | B14: Commercial: Gross End-use: Office - Large: Reference case | C14: AEO.2023.REF2023.#N/A.A | D14: quads | F14: 0.906171 | G14: 0.890402 | H14: 0.889829 | I14: 0.899311 | J14: 0.907485 | K14: 0.913852 | L14: 0.919879 | M14: 0.924673 | N14: 0.928521 | O14: 0.932099 | P14: 0.936194 | Q14: 0.938945 | R14: 0.941428 | S14: 0.944112 | T14: 0.947333 | U14: 0.950204 | V14: 0.952675 | W14: 0.955222 | X14: 0.958763 | Y14: 0.962846 | Z14: 0.967718 | AA14: 0.97365 | AB14: 0.98056 | AC14: 0.987933 | AD14: 0.995871 | AE14: 1.005302 | AF14: 1.016063 | AG14: 1.027597 | AH14: 1.039765 | AI14: 0.005
A15: Office - Small | B15: Commercial: Gross End-use: Office - Small: Reference case | C15: AEO.2023.REF2023.#N/A.A | D15: quads | F15: 0.620077 | G15: 0.609582 | H15: 0.607109 | I15: 0.613284 | J15: 0.618099 | K15: 0.621356 | L15: 0.624245 | M15: 0.626456 | N15: 0.62797 | O15: 0.628755 | P15: 0.630648 | Q15: 0.63105 | R15: 0.631021 | S15: 0.630952 | T15: 0.630982 | U15: 0.630597 | V15: 0.629736 | W15: 0.628835 | X15: 0.628013 | Y15: 0.627388 | Z15: 0.62698 | AA15: 0.6269 | AB15: 0.626923 | AC15: 0.626934 | AD15: 0.626788 | AE15: 0.626966 | AF15: 0.627466 | AG15: 0.62805 | AH15: 0.628609 | AI15: 0
A16: Mercantile/Service | B16: Commercial: Gross End-use: Mercantile/Service: Reference case | C16: AEO.2023.REF2023.#N/A.A | D16: quads | F16: 1.411627 | G16: 1.386703 | H16: 1.377442 | I16: 1.392811 | J16: 1.404702 | K16: 1.412897 | L16: 1.419597 | M16: 1.424017 | N16: 1.425929 | O16: 1.427025 | P16: 1.429976 | Q16: 1.429622 | R16: 1.428147 | S16: 1.426421 | T16: 1.424619 | U16: 1.421674 | V16: 1.417378 | W16: 1.412856 | X16: 1.408803 | Y16: 1.405292 | Z16: 1.402139 | AA16: 1.399782 | AB16: 1.398019 | AC16: 1.395774 | AD16: 1.3922 | AE16: 1.389886 | AF16: 1.388586 | AG16: 1.387521 | AH16: 1.386141 | AI16: -0.001
A17: Warehouse | B17: Commercial: Gross End-use: Warehouse: Reference case | C17: AEO.2023.REF2023.#N/A.A | D17: quads | F17: 0.450864 | G17: 0.451145 | H17: 0.454155 | I17: 0.463089 | J17: 0.471026 | K17: 0.478129 | L17: 0.485102 | M17: 0.491822 | N17: 0.497912 | O17: 0.50345 | P17: 0.510037 | Q17: 0.515355 | R17: 0.520313 | S17: 0.525204 | T17: 0.53007 | U17: 0.534572 | V17: 0.538516 | W17: 0.542437 | X17: 0.546601 | Y17: 0.550947 | Z17: 0.555398 | AA17: 0.56006 | AB17: 0.564801 | AC17: 0.569487 | AD17: 0.573914 | AE17: 0.578711 | AF17: 0.583712 | AG17: 0.58879 | AH17: 0.593861 | AI17: 0.01
A18: Other | B18: Commercial: Gross End-use: Other: Reference case | C18: AEO.2023.REF2023.#N/A.A | D18: quads | F18: 0.403793 | G18: 0.400096 | H18: 0.395901 | I18: 0.402047 | J18: 0.407493 | K18: 0.412239 | L18: 0.41679 | M18: 0.420545 | N18: 0.423651 | O18: 0.426308 | P18: 0.429258 | Q18: 0.431418 | R18: 0.433246 | S18: 0.434947 | T18: 0.436626 | U18: 0.438 | V18: 0.439043 | W18: 0.439929 | X18: 0.441081 | Y18: 0.442205 | Z18: 0.443411 | AA18: 0.444822 | AB18: 0.446439 | AC18: 0.448004 | AD18: 0.449416 | AE18: 0.451156 | AF18: 0.453161 | AG18: 0.455199 | AH18: 0.457203 | AI18: 0.004
A19: Total | B19: Commercial: Gross End-use: Total: Reference case | C19: AEO.2023.REF2023.#N/A.A | D19: quads | F19: 7.531413 | G19: 7.410243 | H19: 7.4028 | I19: 7.499238 | J19: 7.578544 | K19: 7.639032 | L19: 7.692736 | M19: 7.735506 | N19: 7.767814 | O19: 7.795995 | P19: 7.831648 | Q19: 7.851241 | R19: 7.865163 | S19: 7.878181 | T19: 7.891899 | U19: 7.900681 | V19: 7.902669 | W19: 7.904121 | X19: 7.907362 | Y19: 7.913136 | Z19: 7.92147 | AA19: 7.934801 | AB19: 7.951907 | AC19: 7.96781 | AD19: 7.978965 | AE19: 7.997193 | AF19: 8.021315 | AG19: 8.047301 | AH19: 8.07264 | AI19: 0.002
A20: Commercial Building Floorspace
A21: (billion square feet)
A22: Assembly | B22: Commercial: Floorspace: Assembly: Reference case | C22: AEO.2023.REF2023.KEI_FLR_COMM_ASB_NA_NA_NA_BLNSQFT.A | D22: billion sq ft | F22: 10.400917 | G22: 10.436387 | H22: 10.496305 | I22: 10.57352 | J22: 10.640577 | K22: 10.701997 | L22: 10.772717 | M22: 10.853343 | N22: 10.941223 | O22: 11.033052 | P22: 11.121057 | Q22: 11.20028 | R22: 11.270812 | S22: 11.332419 | T22: 11.38581 | U22: 11.432502 | V22: 11.472919 | W22: 11.507771 | X22: 11.538272 | Y22: 11.565514 | Z22: 11.59073 | AA22: 11.615142 | AB22: 11.639624 | AC22: 11.664806 | AD22: 11.691126 | AE22: 11.718759 | AF22: 11.747728 | AG22: 11.777931 | AH22: 11.809135 | AI22: 0.005
A23: Education | B23: Commercial: Floorspace: Education: Reference case | C23: AEO.2023.REF2023.KEI_FLR_COMM_EDD_NA_NA_NA_BLNSQFT.A | D23: billion sq ft | F23: 13.515454 | G23: 13.643662 | H23: 13.780691 | I23: 13.941533 | J23: 14.090282 | K23: 14.232786 | L23: 14.388822 | M23: 14.559372 | N23: 14.74106 | O23: 14.929582 | P23: 15.114496 | Q23: 15.289021 | R23: 15.453143 | S23: 15.606402 | T23: 15.749625 | U23: 15.884776 | V23: 16.012333 | W23: 16.133186 | X23: 16.24894 | Y23: 16.361061 | Z23: 16.471249 | AA23: 16.581207 | AB23: 16.692177 | AC23: 16.80508 | AD23: 16.920567 | AE23: 17.038923 | AF23: 17.160229 | AG23: 17.28437 | AH23: 17.411037 | AI23: 0.009
A24: Food Sales | B24: Commercial: Floorspace: Food Sales: Reference case | C24: AEO.2023.REF2023.KEI_FLR_COMM_FDSA_NA_NA_NA_BLNSQFT.A | D24: billion sq ft | F24: 1.291462 | G24: 1.296816 | H24: 1.305836 | I24: 1.317039 | J24: 1.32701 | K24: 1.336312 | L24: 1.346806 | M24: 1.358573 | N24: 1.371286 | O24: 1.384535 | P24: 1.397346 | Q24: 1.409095 | R24: 1.419791 | S24: 1.429398 | T24: 1.438004 | U24: 1.445796 | V24: 1.452825 | W24: 1.459178 | X24: 1.465006 | Y24: 1.470445 | Z24: 1.475653 | AA24: 1.480783 | AB24: 1.485946 | AC24: 1.491223 | AD24: 1.496672 | AE24: 1.502314 | AF24: 1.508155 | AG24: 1.514183 | AH24: 1.520367 | AI24: 0.006
A25: Food Service | B25: Commercial: Floorspace: Food Service: Reference case | C25: AEO.2023.REF2023.KEI_FLR_COMM_FSC_NA_NA_NA_BLNSQFT.A | D25: billion sq ft | F25: 1.888346 | G25: 1.896453 | H25: 1.909625 | I25: 1.925987 | J25: 1.940549 | K25: 1.954131 | L25: 1.969456 | M25: 1.986643 | N25: 2.005212 | O25: 2.024564 | P25: 2.043276 | Q25: 2.060434 | R25: 2.07605 | S25: 2.090076 | T25: 2.102637 | U25: 2.114007 | V25: 2.124261 | W25: 2.133526 | X25: 2.142023 | Y25: 2.149953 | Z25: 2.157542 | AA25: 2.165018 | AB25: 2.172542 | AC25: 2.180233 | AD25: 2.188173 | AE25: 2.196398 | AF25: 2.204911 | AG25: 2.213697 | AH25: 2.222713 | AI25: 0.006
A26: Health Care | B26: Commercial: Floorspace: Health Care: Reference case | C26: AEO.2023.REF2023.KEI_FLR_COMM_HLC_NA_NA_NA_BLNSQFT.A | D26: billion sq ft | F26: 2.701855 | G26: 2.733213 | H26: 2.769319 | I26: 2.81037 | J26: 2.849174 | K26: 2.886892 | L26: 2.927522 | M26: 2.971289 | N26: 3.017531 | O26: 3.065386 | P26: 3.112723 | Q26: 3.15814 | R26: 3.201612 | S26: 3.243025 | T26: 3.282532 | U26: 3.320521 | V26: 3.357078 | W26: 3.392376 | X26: 3.426738 | Y26: 3.460464 | Z26: 3.493907 | AA26: 3.527425 | AB26: 3.561281 | AC26: 3.595673 | AD26: 3.630744 | AE26: 3.66656 | AF26: 3.70314 | AG26: 3.740469 | AH26: 3.778483 | AI26: 0.012
A27: Lodging | B27: Commercial: Floorspace: Lodging: Reference case | C27: AEO.2023.REF2023.KEI_FLR_COMM_LGC_NA_NA_NA_BLNSQFT.A | D27: billion sq ft | F27: 6.687417 | G27: 6.7613 | H27: 6.851435 | I27: 6.953804 | J27: 7.050617 | K27: 7.144745 | L27: 7.246084 | M27: 7.35519 | N27: 7.470426 | O27: 7.589662 | P27: 7.707621 | Q27: 7.820828 | R27: 7.929226 | S27: 8.032525 | T27: 8.131104 | U27: 8.225924 | V27: 8.317192 | W27: 8.405338 | X27: 8.491166 | Y27: 8.575415 | Z27: 8.658957 | AA27: 8.742681 | AB27: 8.827238 | AC27: 8.91312 | AD27: 9.000679 | AE27: 9.090082 | AF27: 9.181379 | AG27: 9.274526 | AH27: 9.369368 | AI27: 0.012
A28: Office - Large | B28: Commercial: Floorspace: Office - Large: Reference case | C28: AEO.2023.REF2023.KEI_FLR_COMM_OFLC_NA_NA_NA_BLNSQFT.A | D28: billion sq ft | F28: 9.603739 | G28: 9.659845 | H28: 9.72727 | I28: 9.810922 | J28: 9.885389 | K28: 9.954844 | L28: 10.033158 | M28: 10.120936 | N28: 10.215735 | O28: 10.314505 | P28: 10.409986 | Q28: 10.497533 | R28: 10.577204 | S28: 10.648745 | T28: 10.712796 | U28: 10.770758 | V28: 10.823006 | W28: 10.870186 | X28: 10.913433 | Y28: 10.953755 | Z28: 10.99232 | AA28: 11.030277 | AB28: 11.068451 | AC28: 11.107449 | AD28: 11.147686 | AE28: 11.189342 | AF28: 11.232442 | AG28: 11.276896 | AH28: 11.322491 | AI28: 0.006
A29: Office - Small | B29: Commercial: Floorspace: Office - Small: Reference case | C29: AEO.2023.REF2023.KEI_FLR_COMM_OFSC_NA_NA_NA_BLNSQFT.A | D29: billion sq ft | F29: 9.134697 | G29: 9.196621 | H29: 9.27128 | I29: 9.361578 | J29: 9.443316 | K29: 9.52045 | L29: 9.606236 | M29: 9.70128 | N29: 9.803274 | O29: 9.909311 | P29: 10.012436 | Q29: 10.108168 | R29: 10.196538 | S29: 10.277281 | T29: 10.350986 | U29: 10.418979 | V29: 10.481609 | W29: 10.539486 | X29: 10.593686 | Y29: 10.645185 | Z29: 10.6951 | AA29: 10.744549 | AB29: 10.794334 | AC29: 10.84505 | AD29: 10.897103 | AE29: 10.950674 | AF29: 11.005796 | AG29: 11.062386 | AH29: 11.120239 | AI29: 0.007
A30: Mercantile/Service | B30: Commercial: Floorspace: Mercantile/Service: Reference case | C30: AEO.2023.REF2023.KEI_FLR_COMM_MCSC_NA_NA_NA_BLNSQFT.A | D30: billion sq ft | F30: 17.156851 | G30: 17.261364 | H30: 17.402252 | I30: 17.572483 | J30: 17.726637 | K30: 17.872143 | L30: 18.033882 | M30: 18.21299 | N30: 18.405138 | O30: 18.60487 | P30: 18.799126 | Q30: 18.979485 | R30: 19.146017 | S30: 19.29821 | T30: 19.437168 | U30: 19.565395 | V30: 19.683525 | W30: 19.792713 | X30: 19.894976 | Y30: 19.992142 | Z30: 20.086315 | AA30: 20.179588 | AB30: 20.273474 | AC30: 20.36908 | AD30: 20.467176 | AE30: 20.568098 | AF30: 20.671907 | AG30: 20.778452 | AH30: 20.887339 | AI30: 0.007
A31: Warehouse | B31: Commercial: Floorspace: Warehouse: Reference case | C31: AEO.2023.REF2023.KEI_FLR_COMM_WHRC_NA_NA_NA_BLNSQFT.A | D31: billion sq ft | F31: 15.59821 | G31: 15.909663 | H31: 16.170263 | I31: 16.460665 | J31: 16.739002 | K31: 17.01198 | L31: 17.303083 | M31: 17.613777 | N31: 17.940296 | O31: 18.277628 | P31: 18.613136 | Q31: 18.938387 | R31: 19.253145 | S31: 19.556597 | T31: 19.849546 | U31: 20.134249 | V31: 20.411131 | W31: 20.68116 | X31: 20.946251 | Y31: 21.208176 | Z31: 21.469057 | AA31: 21.731073 | AB31: 21.995848 | AC31: 22.264605 | AD31: 22.538246 | AE31: 22.817213 | AF31: 23.101664 | AG31: 23.3915 | AH31: 23.686375 | AI31: 0.015
A32: Other | B32: Commercial: Floorspace: Other: Reference case | C32: AEO.2023.REF2023.KEI_FLR_COMM_OTHU_NA_NA_NA_BLNSQFT.A | D32: billion sq ft | F32: 7.492591 | G32: 7.58013 | H32: 7.672274 | I32: 7.77797 | J32: 7.877273 | K32: 7.973412 | L32: 8.07744 | M32: 8.189959 | N32: 8.309116 | O32: 8.432521 | P32: 8.554302 | Q32: 8.670608 | R32: 8.781395 | S32: 8.886363 | T32: 8.985946 | U32: 9.08123 | V32: 9.172462 | W32: 9.260121 | X32: 9.345108 | Y32: 9.428247 | Z32: 9.510506 | AA32: 9.592859 | AB32: 9.676027 | AC32: 9.760542 | AD32: 9.84679 | AE32: 9.934951 | AF32: 10.025074 | AG32: 10.117102 | AH32: 10.210867 | AI32: 0.011
A33: Total | B33: Commercial: Floorspace: Total: Reference case | C33: AEO.2023.REF2023.KEI_FLR_COMM_NA_NA_NA_NA_BLNSQFT.A | D33: billion sq ft | F33: 95.471542 | G33: 96.37545 | H33: 97.356552 | I33: 98.505859 | J33: 99.569824 | K33: 100.58969 | L33: 101.7052 | M33: 102.92335 | N33: 104.22029 | O33: 105.56561 | P33: 106.88551 | Q33: 108.13197 | R33: 109.30492 | S33: 110.40104 | T33: 111.42615 | U33: 112.39414 | V33: 113.30834 | W33: 114.17503 | X33: 115.0056 | Y33: 115.81035 | Z33: 116.60134 | AA33: 117.3906 | AB33: 118.18694 | AC33: 118.99686 | AD33: 119.82497 | AE33: 120.67332 | AF33: 121.54242 | AG33: 122.43151 | AH33: 123.33842 | AI33: 0.009
A34: Stock Average Equipment Efficiency
A35: Space Heating
A36: Electricity | B36: Commercial: Stock Average Efficiency: Space Heating: Electricity: Reference case | C36: AEO.2023.REF2023.EFF_STKE_COMM_SPH_ELC_NA_NA_BTUOTPBTUIN.A | D36: Btu Out/Btu In | F36: 1.600274 | G36: 1.594243 | H36: 1.587098 | I36: 1.578912 | J36: 1.570767 | K36: 1.563012 | L36: 1.555431 | M36: 1.548036 | N36: 1.540515 | O36: 1.532912 | P36: 1.525505 | Q36: 1.517811 | R36: 1.510503 | S36: 1.503626 | T36: 1.496855 | U36: 1.49042 | V36: 1.48431 | W36: 1.478547 | X36: 1.47299 | Y36: 1.467513 | Z36: 1.462165 | AA36: 1.456975 | AB36: 1.451967 | AC36: 1.447101 | AD36: 1.442009 | AE36: 1.437024 | AF36: 1.43215 | AG36: 1.427428 | AH36: 1.422603 | AI36: -0.004
