Workbook
Name btu_per_kwh: 'Conversion Factors'!$A$3
Name hours_per_year: 'Conversion Factors'!$A$1
Name usd_year_conv: 'Conversion Factors'!$A$5

Sheet About
A1: HPEC Hydrogen Production Equipment CapEx
A2: HPEC Hydrogen Production Equipment OpEx
A6: Source: | B6: International Energy Agency
B7: 2019
B8: The Future of Hydrogen
B9: https://www.iea.org/media/publications/hydrogen/IEA-The-Future-of-Hydrogen-Assumptions-Annex.pdf
B10: Assumptions annex, Page 3
B12: Department of Energy
B13: 2024
B14: Clean Hydrogen Production Cost PEM Electrolyzer
B15: https://www.hydrogen.energy.gov/docs/hydrogenprogramlibraries/pdfs/24005-clean-hydrogen-production-cost-pem-electrolyzer.pdf
B16: Table 2
B18: Cleaner Engineering and Technology
B19: 2022
B20: Analysis of hydrogen production costs in Steam-Methane Reforming considering integration with electrolysis and CO2 capture
B21: https://www.sciencedirect.com/science/article/pii/S2666790822001574
B22: Table 3
A25: Notes
A26: We average the use of the hydrogen plant out over the
A27: course of a year to convert between kW and kWh,
A28: necessary to convert BTU/yr of hydrogen production
A29: capacity to $ of CapEx using the $/kW conversion factor.
A31: The costs entered in this variable should be for a 100% capacity factor.
A32: In other words, this variable should contain the CapEx
A33: and OpEx costs to produce a certain amount of hydrogen
A34: per year, if the production plant were to run constantly
A35: at its design capacity.
A36: In reality, plants do not run all the time, so they require
A37: excess capacity to produce a given amount of hydrogen
... A50: for biomass gasification.
B51: Acar, Canan and Dincer, Ibrahim
B52: 2014
B53: Comparative assessment of hydrogen production methods from renewable and non-renewable sources
B54: https://doi.org/10.1016/j.ijhydene.2013.10.060
B55: Page 7, Table 3
A57: Partial Oxidation of Hydrocarbons
A58: According to ICF, POx reactors are essentially equivalent to autothermal
A59: reformers (ATRs) but without a catalyst bed. For lack of economic data,
A60: we assume that the costs mirror those of ATRs, which, per ICF,
A61: have ~15% lower capital costs and ~5% lower production costs than SMRs.
...

Sheet IEA Data
A1: Technology | B1: Parameter | C1: Units | D1: Today | E1: 2030 | F1: Long Term | H1: For electrolyzers, assume 264 kg H2/kW of production.
A2: electrolysis | B2: CAPEX | C2: USD/kWe | D2: 900 | E2: 700 | F2: 450 | H2: See hydgn/EHPpUC
B3: Efficiency (LHV) | C3: % | D3: 0.64 | E3: 0.69 | F3: 0.74 | H3: 264 | I3: kg H2/kW
B4: Annual OPEX | C4: % of CAPEX | D4: 0.015 | E4: 0.015 | F4: 0.015
B5: Stack Lifetime | C5: operating hours | D5: 95000 | E5: 95000 | F5: 100000 | H5: =D2*usd_year_conv/'IEA Data'!B20/H3 -> 4.257288 | J5: =D2/$H$3 -> 3.4090909 | K5: =E2/$H$3 -> 2.6515152 | L5: =F2/$H$3 -> 1.7045455
A6: natural gas reforming | B6: CAPEX | C6: USD/kWH2 | D6: 910 | E6: 910 | F6: 910 | H6: =HPEC!H2*'IEA Data'!B21 -> 14.592874 | J6: =J5*usd_year_conv/'IEA Data'!$B$20 -> 4.257288 | K6: =K5*usd_year_conv/'IEA Data'!$B$20 -> 3.311224 | L6: =L5*usd_year_conv/'IEA Data'!$B$20 -> 2.128644
B7: Efficiency (LHV) | C7: % | D7: 0.76 | E7: 0.76 | F7: 0.76
B8: Annual OPEX | C8: % of CAPEX | D8: 0.047 | E8: 0.047 | F8: 0.047 | H8: =D6/8760 -> 0.10388128
B9: Emission factor | C9: kgCO2/kgH2 | D9: 8.9 | E9: 8.9 | F9: 8.9
A10: coal gasification | B10: CAPEX | C10: USD/kWH2 | D10: 2670 | E10: 2670 | F10: 2670
B11: Efficiency (LHV) | C11: % | D11: 0.6 | E11: 0.6 | F11: 0.6
B12: Annual OPEX | C12: % of CAPEX | D12: 0.05 | E12: 0.05 | F12: 0.05
B13: Emission factor | C13: kgCO2/kgH2 | D13: 20.2 | E13: 20.2 | F13: 20.2
A15: Mapped Year | D15: 2017 | E15: 2030 | F15: 2050
B18: =134500000000000 -> 134500000000000 | C18: BTU/Mt
B19: =1000000000 -> 1000000000 | C19: kg/Mt
B20: 0.7319 | C20: 2012/2024USD
B21: =B18/B19/B20 -> 183768.27 | C21: $/BTU -> 2024$/kg | D21: =HPEC!I2*'IEA Data'!B21 -> 14.0717
B23: 3.12e-06 | C23: $/BTU NG
B24: 1.3729 | C24: intensity NG
B25: 1.86e-05 | C25: $/BTU elec
B26: 0.0169 | C26: intensity elec
B28: 0.25 | C28: adder
A30: =B30/B21 -> 1.0053674e-05 | B30: =HPEC!B3*B21*(1+B28) -> 1.8475464 | C30: capital cost | H30: =0.15/B21 -> 8.1624535e-07
A31: =B31/B21 -> 4.597788e-06 | B31: =B23*B24*B21+B25*B26*B21 -> 0.84492757 | C31: fuel cost | N31: =200*8760/20000 -> 87.6
A32: =B32/B21 -> 8.6767529e-07 | B32: =HPEO!B3*B21*(1+B28) -> 0.15945119 | C32: opex cost
A33: =SUM(A30:A32) -> 1.5519137e-05

Sheet Reformer data
B2: From Katebah et al.
B3: Table 3. Summary of the main results for SMR plant.
B4: Parameter | C4: Unit | D4: Value
B5: Hydrogen Production | C5: kg H2/yr | D5: =500000*365 -> 182500000
B6: NG Consumption | C6: kg NG/kg H2 | D6: 3.16
B7: NG Price | C7: $/GJ | D7: 3.7
B8: Water Consumption | C8: kg H2O/kg H2 | D8: 9.74
B9: Specific CO2 Emissions | C9: kg CO2/kg H2 | D9: 8.47 | F9: $/kg (2012 USD) | G9: $/BTU (2012 USD)
B10: CAPEX | C10: $/kg H2 | D10: 0.15 | F10: =D10*About!$A$75 -> 0.1371 | G10: =D10*About!$A$75/'IEA Data'!$B$18*'IEA Data'!$B$19 -> 1.0193309e-06
B11: OPEX | C11: $/kg H2 | D11: 0.81 | F11: =D11*About!$A$75 -> 0.74034 | G11: =D11*About!$A$75/'IEA Data'!$B$18*'IEA Data'!$B$19 -> 5.5043866e-06
B12: Hydrogen Production Cost | C12: $/kg H2 | D12: 0.96 | F12: =D12*About!$A$75 -> 0.87744 | G12: =D12*About!$A$75/'IEA Data'!$B$18*'IEA Data'!$B$19 -> 6.5237175e-06
B13: *all in 2018 USD
B15: From Figure 3:
B31: OpEx
B32: 0.751 | C32: feedstock
B33: =1-B32 -> 0.249 | C33: other
B35: =F11*B33 -> 0.18434466 | C35: other OpEx / kg
B36: =G11*B33 -> 1.3705923e-06 | C36: other OpEx / BTU
B38: Table 2. Design and Economic Assumptions for SMR plant. | G38: non-levelized CapEx
B39: Property | C39: Unit | D39: Value | E39: Reference | G39: 216000000 | H39: $ capex
B40: Pre-reformer: | G40: =G39/D5 -> 1.1835616 | H40: $/annual kg
B41: Temperature | C41: ⁰C | D41: 500 | E41: Salem et al. (2021) | G41: =G40/'IEA Data'!B18*'IEA Data'!B19*About!A75 -> 8.0429393e-06 | H41: $/BTU
B42: Pressure | C42: bar | D42: 25 | E42: IEAGHG (2017)
B43: S/C Ratio | C43: – | D43: 2.7 | E43: IEAGHG (2017)
B44: Reference capacity | C44: MWLHV NG feed | D44: 1800 | E44: Spallina et al. (2016)
B45: Reference costa | C45: M$b | D45: 24.8 | E45: Spallina et al. (2016)
B46: Scaling factor | C46: – | D46: 0.75 | E46: Spallina et al. (2016)
B47: Reformer:
B48: Temperature | C48: ⁰C | D48: 700 | E48: Salem et al. (2021)
B49: Pressure | C49: Bar | D49: 24 | E49: Jakobsen and Atland (2016)
B50: S/C ratio | C50: – | D50: 3 | E50: IEAGHG (2017)
B51: Reference capacity | C51: MWLHV NG feed | D51: 1246 | E51: Spallina et al. (2016)
B52: Reference costa | C52: M$b | D52: 34.3 | E52: Spallina et al. (2016)
B53: Scaling factor | C53: – | D53: 0.75 | E53: Spallina et al. (2016)
B54: WGS Reactors
B55: High-temperature WGS
B56: Temperature | C56: ⁰C | D56: 320 | E56: Liu et al. (2009)
B57: Pressure | C57: Bar | D57: 23 | E57: Jakobsen and Atland (2016)
B58: Low-temperature WGS
B59: Temperature | C59: ⁰C | D59: 190 | E59: Liu et al. (2009)
...

Sheet DoE Data
B17: 2024 cost:
B18: 2000 | C18: $/kW | D18: 2022 USD
B20: Cost trends:
B21: Assumes similar rate of decline to IEA data
B22: 2024 | C22: 2030 | D22: 2050
B23: =B18 -> 2000 | C23: =B23*'IEA Data'!E2/'IEA Data'!D2 -> 1555.5556 | D23: =B23*'IEA Data'!F2/'IEA Data'!D2 -> 1000 | E23: $/kW | F23: CapEx
B24: =B23*$B$36 -> 212000000 | C24: =C23*$B$36 -> 1.6488889e+08 | D24: =D23*$B$36 -> 106000000 | E24: $
B25: =B23*$B$41/hours_per_year -> 13.127854 | C25: =C23*$B$41/hours_per_year -> 10.210553 | D25: =D23*$B$41/hours_per_year -> 6.5639269 | E25: 2022$ per annual kg of full-load (100% CF) capacity: $/kW x kWh/kg / 8760 h
B26: =B25/'IEA Data'!$B$18*'IEA Data'!$B$19*About!$A$72 -> 7.6573066e-05 | C26: =C25/'IEA Data'!$B$18*'IEA Data'!$B$19*About!$A$72 -> 5.9556829e-05 | D26: =D25/'IEA Data'!$B$18*'IEA Data'!$B$19*About!$A$72 -> 3.8286533e-05 | E26: 2012$/BTU
B27: =B24*$B$87 -> 10600000 | C27: =C24*$B$87 -> 8244444.4 | D27: =D24*$B$87 -> 5300000 | E27: $ | F27: Annual OpEx
B28: =B25*$B$87 -> 0.65639269 | C28: =C25*$B$87 -> 0.51052765 | D28: =D25*$B$87 -> 0.32819635 | E28: 2022$ per annual kg of full-load capacity, per year (fixed O&M excl. stack replacement)
B29: =B28/'IEA Data'!$B$18*'IEA Data'!$B$19*About!$A$72 -> 3.8286533e-06 | C29: =C28/'IEA Data'!$B$18*'IEA Data'!$B$19*About!$A$72 -> 2.9778414e-06 | D29: =D28/'IEA Data'!$B$18*'IEA Data'!$B$19*About!$A$72 -> 1.9143266e-06 | E29: 2012$/BTU
B32: Value being studied:
B33: 2000 | C33: $/kW | D33: 2022 USD | E33: <-- adjust value to match future prices from "Cost trends" section below to get CapEx contribution to LCOH in future years
B35: =50000*365 -> 18250000 | C35: kg/yr production
B36: 106000 | C36: kW assumption (106 MW plant)
B37: =B35/B36 -> 172.16981 | C37: kg/kW
B39: =B18/B37 -> 11.616438 | I39: =B18*B36/B35 -> 11.616438
B41: =57.5 -> 57.5 | C41: kwh/kg | D41: system elec consumption
B42: 0.033 | C42: $/kWh | D42: renewables assumption
B43: 0.51 | C43: % | D43: capacity factor
B45: =B41*B42 -> 1.8975 | C45: $/kg | D45: fuel cost
B46: 0.1 | D46: WACC
A48: =B27/SUM(B64:AE64)/B53 -> 0.056011957 | B48: =0.11 -> 0.11 | C48: % | D48: of installed cost for electrolyzer replacement
B49: 40000 | C49: hours | D49: replacement timeline
B52: 1 | C52: 2 | D52: 3 | E52: 4 | F52: 5 | G52: 6 | H52: 7 | I52: 8 | J52: 9 | K52: 10 | L52: 11 | M52: 12 | N52: 13 | O52: 14 | P52: 15 | Q52: 16 | R52: 17 | S52: 18 | T52: 19 | U52: 20 | V52: 21 | W52: 22 | X52: 23 | Y52: 24 | Z52: 25 | AA52: 26 | AB52: 27 | AC52: 28 | AD52: 29 | AE52: 30
A53: production (kg) | B53: =$B$35 -> 18250000 | C53: =$B$35 -> 18250000 | D53: =$B$35 -> 18250000 | E53: =$B$35 -> 18250000 | F53: =$B$35 -> 18250000 | G53: =$B$35 -> 18250000 | H53: =$B$35 -> 18250000 | I53: =$B$35 -> 18250000 | ... AE53: =$B$35 -> 18250000
A54: effective operating hours | B54: =hours_per_year*'DoE Data'!$B$43 -> 4467.6 | C54: =hours_per_year*'DoE Data'!$B$43 -> 4467.6 | D54: =hours_per_year*'DoE Data'!$B$43 -> 4467.6 | E54: =hours_per_year*'DoE Data'!$B$43 -> 4467.6 | F54: =hours_per_year*'DoE Data'!$B$43 -> 4467.6 | G54: =hours_per_year*'DoE Data'!$B$43 -> 4467.6 | H54: =hours_per_year*'DoE Data'!$B$43 -> 4467.6 | I54: =hours_per_year*'DoE Data'!$B$43 -> 4467.6 | ... AE54: =hours_per_year*'DoE Data'!$B$43 -> 4467.6
A55: hours on this electrolyzer | B55: =MOD(SUM(B54:$B$54),$B$49) -> 4467.6 | C55: =MOD(SUM($B54:C$54),$B$49) -> 8935.2 | D55: =MOD(SUM($B54:D$54),$B$49) -> 13402.8 | E55: =MOD(SUM($B54:E$54),$B$49) -> 17870.4 | F55: =MOD(SUM($B54:F$54),$B$49) -> 22338 | G55: =MOD(SUM($B54:G$54),$B$49) -> 26805.6 | H55: =MOD(SUM($B54:H$54),$B$49) -> 31273.2 | I55: =MOD(SUM($B54:I$54),$B$49) -> 35740.8 | J55: =MOD(SUM($B54:J$54),$B$49) -> 208.4 | ... AE55: =MOD(SUM($B54:AE$54),$B$49) -> 14028
A56: fuel costs | B56: =$B$45*B53 -> 34629375 | C56: =$B$45*C53 -> 34629375 | D56: =$B$45*D53 -> 34629375 | E56: =$B$45*E53 -> 34629375 | F56: =$B$45*F53 -> 34629375 | G56: =$B$45*G53 -> 34629375 | H56: =$B$45*H53 -> 34629375 | I56: =$B$45*I53 -> 34629375 | ... AE56: =$B$45*AE53 -> 34629375
A57: capital cost | B57: =B36*B33/B43 -> 4.1568627e+08
A58: opex | B58: =5%*$B$57 -> 20784314 | C58: =5%*$B$57 -> 20784314 | D58: =5%*$B$57 -> 20784314 | E58: =5%*$B$57 -> 20784314 | F58: =5%*$B$57 -> 20784314 | G58: =5%*$B$57 -> 20784314 | H58: =5%*$B$57 -> 20784314 | I58: =5%*$B$57 -> 20784314 | ... AE58: =5%*$B$57 -> 20784314
A59: electrolyzer replacement | C59: =IF(C55<B55,$B$57*0.11,0) -> 0 | D59: =IF(D55<C55,$B$57*0.11,0) -> 0 | E59: =IF(E55<D55,$B$57*0.11,0) -> 0 | F59: =IF(F55<E55,$B$57*0.11,0) -> 0 | G59: =IF(G55<F55,$B$57*0.11,0) -> 0 | H59: =IF(H55<G55,$B$57*0.11,0) -> 0 | I59: =IF(I55<H55,$B$57*0.11,0) -> 0 | J59: =IF(J55<I55,$B$57*0.11,0) -> 45725490 | ... AE59: =IF(AE55<AD55,$B$57*0.11,0) -> 0
A61: discounted costs | B61: =SUM(B56:B59)/(1+$B$46)^(B52-1) -> 4.7109996e+08 | C61: =SUM(C56:C59)/(1+$B$46)^(C52-1) -> 50376081 | D61: =SUM(D56:D59)/(1+$B$46)^(D52-1) -> 45796437 | E61: =SUM(E56:E59)/(1+$B$46)^(E52-1) -> 41633125 | F61: =SUM(F56:F59)/(1+$B$46)^(F52-1) -> 37848295 | G61: =SUM(G56:G59)/(1+$B$46)^(G52-1) -> 34407541 | H61: =SUM(H56:H59)/(1+$B$46)^(H52-1) -> 31279583 | I61: =SUM(I56:I59)/(1+$B$46)^(I52-1) -> 28435984 | ... AE61: =SUM(AE56:AE59)/(1+$B$46)^(AE52-1) -> 3493246.2
A62: discounted capex costs | B62: =(B57+B59)/(1+$B$46)^(B52-1) -> 4.1568627e+08 | C62: =(C57+C59)/(1+$B$46)^(C52-1) -> 0 | D62: =(D57+D59)/(1+$B$46)^(D52-1) -> 0 | E62: =(E57+E59)/(1+$B$46)^(E52-1) -> 0 | F62: =(F57+F59)/(1+$B$46)^(F52-1) -> 0 | G62: =(G57+G59)/(1+$B$46)^(G52-1) -> 0 | H62: =(H57+H59)/(1+$B$46)^(H52-1) -> 0 | I62: =(I57+I59)/(1+$B$46)^(I52-1) -> 0 | ... AE62: =(AE57+AE59)/(1+$B$46)^(AE52-1) -> 0
A63: discounted opex costs | B63: =B58/(1+$B$46)^(B52-1) -> 20784314 | C63: =C58/(1+$B$46)^(C52-1) -> 18894831 | D63: =D58/(1+$B$46)^(D52-1) -> 17177119 | E63: =E58/(1+$B$46)^(E52-1) -> 15615563 | F63: =F58/(1+$B$46)^(F52-1) -> 14195966 | G63: =G58/(1+$B$46)^(G52-1) -> 12905424 | H63: =H58/(1+$B$46)^(H52-1) -> 11732203 | I63: =I58/(1+$B$46)^(I52-1) -> 10665639 | ... AE63: =AE58/(1+$B$46)^(AE52-1) -> 1310230.8
B64: =1/((1+$B$46)^(B52-1)) -> 1 | C64: =1/((1+$B$46)^(C52-1)) -> 0.90909091 | D64: =1/((1+$B$46)^(D52-1)) -> 0.82644628 | E64: =1/((1+$B$46)^(E52-1)) -> 0.7513148 | F64: =1/((1+$B$46)^(F52-1)) -> 0.68301346 | G64: =1/((1+$B$46)^(G52-1)) -> 0.62092132 | H64: =1/((1+$B$46)^(H52-1)) -> 0.56447393 | I64: =1/((1+$B$46)^(I52-1)) -> 0.51315812 | ... AE64: =1/((1+$B$46)^(AE52-1)) -> 0.063039409
B66: =SUM(B61:AE61)/SUM(B64:AE64)/B53 -> 5.413708 | C66: Total LCOH
B67: =SUM(B62:AE62)/SUM(B64:AE64)/B53 -> 2.3773415 | C67: CapEx contribution to LCOH | E67: <- resulting data | G67: =SUM(B63:J63)/SUM(B64:J64) -> 20784314
B68: =SUM(B63:AE63)/SUM(B64:AE64)/B53 -> 1.1388665 | C68: OpEx contribution to LCOH | E68: <- resulting data | H68: =SUM(B64:AE64) -> 10.369606
...

Sheet OM Split
A1: Fixed and variable O&M by pathway (added 2026-10-23)
A2: Source: NETL, Comparison of Commercial, State-of-the-Art, Fossil-Based Hydrogen Production Technologies, DOE/NETL-2022/3241 (2022), Exhibits 3-15 (Case 1 SMR) and 4-31 (Case 4 coal gasification), Dec 2018$
A3: Purchased electricity is removed from NETL's variable O&M because EPS charges electricity through FIoHP. Fuel is likewise charged through FIoHP.
B5: NETL Case 1 SMR | C5: NETL Case 4 coal gasification
A6: Plant size (kg H2/day, full load) | B6: 483014 | C6: 659947
A7: Fixed operating costs ($/yr) | B7: 10633798 | C7: 101984658
A8: Variable operating costs total ($/kg H2) | B8: 0.0869 | C8: 0.43269
A9: of which purchased electricity ($/kg H2) | B9: 0.04507 | C9: 0.06516
A10: Fixed O&M ($ per kg/yr of full-load capacity, 2018$) | B10: =B7/(B6*365) -> 0.060316457 | C10: =C7/(C6*365) -> 0.42338252
A11: Variable O&M excl. electricity ($ per kg produced, 2018$) | B11: =B8-B9 -> 0.04183 | C11: =C8-C9 -> 0.36753
A12: HPEO = fixed + variable at full load ($ per kg/yr of capacity, 2018$) | B12: =B10+B11 -> 0.10214646 | C12: =C10+C11 -> 0.79091252
A13: HPEO (2012$ per BTU/yr of capacity) | B13: =B12*About!$A$75/'IEA Data'!$B$18*'IEA Data'!$B$19 -> 6.9414024e-07 | C13: =C12*About!$A$75/'IEA Data'!$B$18*'IEA Data'!$B$19 -> 5.3746769e-06
A14: Variable share of HPEO (HPVOS) | B14: =B11/B12 -> 0.40951004 | C14: =C11/C12 -> 0.46469109
A16: Electrolysis (DOE 24005): fixed O&M = 5% of installed capex/yr; stack replacement is a variable cost (it scales with operating hours).
A17: Stack replacement per unit produced at full load = levelized replacement share ('DoE Data' B97, B105) / CF ('DoE Data' B88, B89).
B19: Grid electrolysis | C19: Green electrolysis
A20: Fixed O&M share of capex per year | B20: ='DoE Data'!$B$87 -> 0.05 | C20: ='DoE Data'!$B$87 -> 0.05
A21: Stack replacement share of capex per unit of full-load output | B21: ='DoE Data'!$B$97/'DoE Data'!$B$88 -> 0.018933753 | C21: ='DoE Data'!$B$105/'DoE Data'!$B$89 -> 0.015906258
A22: Variable share of HPEO (HPVOS) | B22: =B21/(B20+B21) -> 0.27466592 | C22: =C21/(C20+C21) -> 0.2413467
A24: Other pathways: biomass gasification uses coal gasification (as for capex); hydrocarbon partial oxidation uses SMR (85% of SMR cost, as for capex; NETL has no POx case); SMR with CCS uses SMR, with the CCS O&M carried separately in CC CCS Total OM Cost per Hydrogen Sector Ton Sequestered.

Sheet Conversion Factors
A1: =24*365 -> 8760 | B1: hours per year
A3: 3412.14 | B3: BTU/kWh
A5: 0.914 | B5: 2018 USD/2012 USD

Sheet HPEC
A1: CapEx Cost ($/BTU) | B1: 2017 | C1: 2018 | D1: 2019 | E1: 2020 | F1: 2021 | G1: 2022 | H1: 2023 | I1: 2024 | J1: 2025 | K1: 2026 | L1: 2027 | M1: 2028 | N1: 2029 | O1: 2030 | P1: 2031 | Q1: 2032 | R1: 2033 | S1: 2034 | T1: 2035 | U1: 2036 | V1: 2037 | W1: 2038 | X1: 2039 | Y1: 2040 | Z1: 2041 | AA1: 2042 | AB1: 2043 | AC1: 2044 | AD1: 2045 | AE1: 2046 | AF1: 2047 | AG1: 2048 | AH1: 2049 | AI1: 2050
A2: electrolysis | B2: =TREND('DoE Data'!$B$26:$C$26,'DoE Data'!$B$22:$C$22,B$1) -> 9.6425342e-05 | C2: =TREND('DoE Data'!$B$26:$C$26,'DoE Data'!$B$22:$C$22,C$1) -> 9.3589303e-05 | D2: =TREND('DoE Data'!$B$26:$C$26,'DoE Data'!$B$22:$C$22,D$1) -> 9.0753263e-05 | E2: =TREND('DoE Data'!$B$26:$C$26,'DoE Data'!$B$22:$C$22,E$1) -> 8.7917224e-05 | F2: =TREND('DoE Data'!$B$26:$C$26,'DoE Data'!$B$22:$C$22,F$1) -> 8.5081184e-05 | G2: =TREND('DoE Data'!$B$26:$C$26,'DoE Data'!$B$22:$C$22,G$1) -> 8.2245145e-05 | H2: =TREND('DoE Data'!$B$26:$C$26,'DoE Data'!$B$22:$C$22,H$1) -> 7.9409105e-05 | I2: =TREND('DoE Data'!$B$26:$C$26,'DoE Data'!$B$22:$C$22,I$1) -> 7.6573066e-05 | ... O2: =TREND('DoE Data'!$B$26:$C$26,'DoE Data'!$B$22:$C$22,O$1) -> 5.9556829e-05 | P2: =TREND('DoE Data'!$C$26:$D$26,'DoE Data'!$C$22:$D$22,P$1) -> 5.8493314e-05 | Q2: =TREND('DoE Data'!$C$26:$D$26,'DoE Data'!$C$22:$D$22,Q$1) -> 5.7429799e-05 | R2: =TREND('DoE Data'!$C$26:$D$26,'DoE Data'!$C$22:$D$22,R$1) -> 5.6366285e-05 | S2: =TREND('DoE Data'!$C$26:$D$26,'DoE Data'!$C$22:$D$22,S$1) -> 5.530277e-05 | T2: =TREND('DoE Data'!$C$26:$D$26,'DoE Data'!$C$22:$D$22,T$1) -> 5.4239255e-05 | U2: =TREND('DoE Data'!$C$26:$D$26,'DoE Data'!$C$22:$D$22,U$1) -> 5.317574e-05 | V2: =TREND('DoE Data'!$C$26:$D$26,'DoE Data'!$C$22:$D$22,V$1) -> 5.2112225e-05 | W2: =TREND('DoE Data'!$C$26:$D$26,'DoE Data'!$C$22:$D$22,W$1) -> 5.1048711e-05 | ... AI2: =TREND('DoE Data'!$C$26:$D$26,'DoE Data'!$C$22:$D$22,AI$1) -> 3.8286533e-05
A3: natural gas reforming | B3: ='Reformer data'!G41 -> 8.0429393e-06 | C3: =$B$3 -> 8.0429393e-06 | D3: =$B$3 -> 8.0429393e-06 | E3: =$B$3 -> 8.0429393e-06 | F3: =$B$3 -> 8.0429393e-06 | G3: =$B$3 -> 8.0429393e-06 | H3: =$B$3 -> 8.0429393e-06 | I3: =$B$3 -> 8.0429393e-06 | J3: =$B$3 -> 8.0429393e-06 | ... AI3: =$B$3 -> 8.0429393e-06
A4: coal gasification | B4: =B3*'IEA Data'!$D$10/'IEA Data'!$D$6 -> 2.3598514e-05 | C4: =C3*'IEA Data'!$D$10/'IEA Data'!$D$6 -> 2.3598514e-05 | D4: =D3*'IEA Data'!$D$10/'IEA Data'!$D$6 -> 2.3598514e-05 | E4: =E3*'IEA Data'!$D$10/'IEA Data'!$D$6 -> 2.3598514e-05 | F4: =F3*'IEA Data'!$D$10/'IEA Data'!$D$6 -> 2.3598514e-05 | G4: =G3*'IEA Data'!$D$10/'IEA Data'!$D$6 -> 2.3598514e-05 | H4: =H3*'IEA Data'!$D$10/'IEA Data'!$D$6 -> 2.3598514e-05 | I4: =I3*'IEA Data'!$D$10/'IEA Data'!$D$6 -> 2.3598514e-05 | ... AI4: =AI3*'IEA Data'!$D$10/'IEA Data'!$D$6 -> 2.3598514e-05
A5: biomass gasification | B5: =B4 -> 2.3598514e-05 | C5: =C4 -> 2.3598514e-05 | D5: =D4 -> 2.3598514e-05 | E5: =E4 -> 2.3598514e-05 | F5: =F4 -> 2.3598514e-05 | G5: =G4 -> 2.3598514e-05 | H5: =H4 -> 2.3598514e-05 | I5: =I4 -> 2.3598514e-05 | ... AI5: =AI4 -> 2.3598514e-05
A6: hydrocarbon partial oxidation | B6: =B3*0.85 -> 6.8364984e-06 | C6: =$B6 -> 6.8364984e-06 | D6: =$B6 -> 6.8364984e-06 | E6: =$B6 -> 6.8364984e-06 | F6: =$B6 -> 6.8364984e-06 | G6: =$B6 -> 6.8364984e-06 | H6: =$B6 -> 6.8364984e-06 | I6: =$B6 -> 6.8364984e-06 | J6: =$B6 -> 6.8364984e-06 | ... AI6: =$B6 -> 6.8364984e-06
A7: electrolysis with guaranteed clean electricity | B7: =B2 -> 9.6425342e-05 | C7: =C2 -> 9.3589303e-05 | D7: =D2 -> 9.0753263e-05 | E7: =E2 -> 8.7917224e-05 | F7: =F2 -> 8.5081184e-05 | G7: =G2 -> 8.2245145e-05 | H7: =H2 -> 7.9409105e-05 | I7: =I2 -> 7.6573066e-05 | ... AI7: =AI2 -> 3.8286533e-05
A8: natural gas reforming with CCS | B8: =B3 -> 8.0429393e-06 | C8: =C3 -> 8.0429393e-06 | D8: =D3 -> 8.0429393e-06 | E8: =E3 -> 8.0429393e-06 | F8: =F3 -> 8.0429393e-06 | G8: =G3 -> 8.0429393e-06 | H8: =H3 -> 8.0429393e-06 | I8: =I3 -> 8.0429393e-06 | ... AI8: =AI3 -> 8.0429393e-06

Sheet HPEO
A1: OpEx Cost ($/BTU) | B1: 2017 | C1: 2018 | D1: 2019 | E1: 2020 | F1: 2021 | G1: 2022 | H1: 2023 | I1: 2024 | J1: 2025 | K1: 2026 | L1: 2027 | M1: 2028 | N1: 2029 | O1: 2030 | P1: 2031 | Q1: 2032 | R1: 2033 | S1: 2034 | T1: 2035 | U1: 2036 | V1: 2037 | W1: 2038 | X1: 2039 | Y1: 2040 | Z1: 2041 | AA1: 2042 | AB1: 2043 | AC1: 2044 | AD1: 2045 | AE1: 2046 | AF1: 2047 | AG1: 2048 | AH1: 2049 | AI1: 2050
A2: electrolysis | B2: =HPEC!B2*('OM Split'!$B$20+'OM Split'!$B$21) -> 6.6469607e-06 | C2: =HPEC!C2*('OM Split'!$B$20+'OM Split'!$B$21) -> 6.4514619e-06 | D2: =HPEC!D2*('OM Split'!$B$20+'OM Split'!$B$21) -> 6.255963e-06 | E2: =HPEC!E2*('OM Split'!$B$20+'OM Split'!$B$21) -> 6.0604642e-06 | F2: =HPEC!F2*('OM Split'!$B$20+'OM Split'!$B$21) -> 5.8649653e-06 | G2: =HPEC!G2*('OM Split'!$B$20+'OM Split'!$B$21) -> 5.6694665e-06 | H2: =HPEC!H2*('OM Split'!$B$20+'OM Split'!$B$21) -> 5.4739676e-06 | I2: =HPEC!I2*('OM Split'!$B$20+'OM Split'!$B$21) -> 5.2784688e-06 | ... AI2: =HPEC!AI2*('OM Split'!$B$20+'OM Split'!$B$21) -> 2.6392344e-06
A3: natural gas reforming | B3: ='OM Split'!$B$13 -> 6.9414024e-07 | C3: ='OM Split'!$B$13 -> 6.9414024e-07 | D3: ='OM Split'!$B$13 -> 6.9414024e-07 | E3: ='OM Split'!$B$13 -> 6.9414024e-07 | F3: ='OM Split'!$B$13 -> 6.9414024e-07 | G3: ='OM Split'!$B$13 -> 6.9414024e-07 | H3: ='OM Split'!$B$13 -> 6.9414024e-07 | I3: ='OM Split'!$B$13 -> 6.9414024e-07 | ... AI3: ='OM Split'!$B$13 -> 6.9414024e-07
A4: coal gasification | B4: ='OM Split'!$C$13 -> 5.3746769e-06 | C4: ='OM Split'!$C$13 -> 5.3746769e-06 | D4: ='OM Split'!$C$13 -> 5.3746769e-06 | E4: ='OM Split'!$C$13 -> 5.3746769e-06 | F4: ='OM Split'!$C$13 -> 5.3746769e-06 | G4: ='OM Split'!$C$13 -> 5.3746769e-06 | H4: ='OM Split'!$C$13 -> 5.3746769e-06 | I4: ='OM Split'!$C$13 -> 5.3746769e-06 | ... AI4: ='OM Split'!$C$13 -> 5.3746769e-06
A5: biomass gasification | B5: =B4 -> 5.3746769e-06 | C5: =C4 -> 5.3746769e-06 | D5: =D4 -> 5.3746769e-06 | E5: =E4 -> 5.3746769e-06 | F5: =F4 -> 5.3746769e-06 | G5: =G4 -> 5.3746769e-06 | H5: =H4 -> 5.3746769e-06 | I5: =I4 -> 5.3746769e-06 | ... AI5: =AI4 -> 5.3746769e-06
A6: hydrocarbon partial oxidation | B6: =B3*0.85 -> 5.900192e-07 | C6: =C3*0.85 -> 5.900192e-07 | D6: =D3*0.85 -> 5.900192e-07 | E6: =E3*0.85 -> 5.900192e-07 | F6: =F3*0.85 -> 5.900192e-07 | G6: =G3*0.85 -> 5.900192e-07 | H6: =H3*0.85 -> 5.900192e-07 | I6: =I3*0.85 -> 5.900192e-07 | ... AI6: =AI3*0.85 -> 5.900192e-07
A7: electrolysis with guaranteed clean electricity | B7: =HPEC!B7*('OM Split'!$C$20+'OM Split'!$C$21) -> 6.3550334e-06 | C7: =HPEC!C7*('OM Split'!$C$20+'OM Split'!$C$21) -> 6.1681207e-06 | D7: =HPEC!D7*('OM Split'!$C$20+'OM Split'!$C$21) -> 5.9812079e-06 | E7: =HPEC!E7*('OM Split'!$C$20+'OM Split'!$C$21) -> 5.7942952e-06 | F7: =HPEC!F7*('OM Split'!$C$20+'OM Split'!$C$21) -> 5.6073824e-06 | G7: =HPEC!G7*('OM Split'!$C$20+'OM Split'!$C$21) -> 5.4204697e-06 | H7: =HPEC!H7*('OM Split'!$C$20+'OM Split'!$C$21) -> 5.233557e-06 | I7: =HPEC!I7*('OM Split'!$C$20+'OM Split'!$C$21) -> 5.0466442e-06 | ... AI7: =HPEC!AI7*('OM Split'!$C$20+'OM Split'!$C$21) -> 2.5233221e-06
A8: natural gas reforming with CCS | B8: =B3 -> 6.9414024e-07 | C8: =C3 -> 6.9414024e-07 | D8: =D3 -> 6.9414024e-07 | E8: =E3 -> 6.9414024e-07 | F8: =F3 -> 6.9414024e-07 | G8: =G3 -> 6.9414024e-07 | H8: =H3 -> 6.9414024e-07 | I8: =I3 -> 6.9414024e-07 | ... AI8: =AI3 -> 6.9414024e-07

Sheet HPVOS
A1: Unit: dimensionless (share of HPEO that is variable) | B1: share
A2: electrolysis | B2: ='OM Split'!$B$22 -> 0.27466592
A3: natural gas reforming | B3: ='OM Split'!$B$14 -> 0.40951004
A4: coal gasification | B4: ='OM Split'!$C$14 -> 0.46469109
A5: biomass gasification | B5: ='OM Split'!$C$14 -> 0.46469109
A6: hydrocarbon partial oxidation | B6: ='OM Split'!$B$14 -> 0.40951004
A7: electrolysis with guaranteed clean electricity | B7: ='OM Split'!$C$22 -> 0.2413467
A8: natural gas reforming with CCS | B8: ='OM Split'!$B$14 -> 0.40951004
