Workbook
Name dollars_2018_to_2012: About!$A$140
Name dollars_2019_2012: About!$A$139
Name dollars_2020_2012: About!$A$138
Name dollars_2021_2012: About!$A$137
Name dollars_2022_2012: About!$A$136
Name dollars_2023_2012: About!$A$135
Name dollars_2024_to_2012: About!$A$134
Name dollars_2025_to_2012: About!$A$133
Name lignite_multiplier: 'Hard Coal and Lig Multipliers'!$N$15
Name nonlignite_multiplier: 'Hard Coal and Lig Multipliers'!$N$16

Sheet About
A1: BFPaT BAU Pretax Fuel Price by Sector
A2: BFPaT BAU Fuel Tax by Sector
A4: Sources: | B4: most fuels and growth rates | D4: Tax on Petroleum Gasoline, Petroleum Diesel, Jet Fuel
B5: Energy Information Administration | D5: Energy Information Administration
B6: 2026 | D6: 2026
B7: Annual Energy Outlook 2026, "Alternative Electricity and Transportation" scenario | D7: Annual Energy Outlook 2026, "Alternative Electricity and Transportation" scenario
B8: https://www.eia.gov/outlooks/aeo/tables_side.php | D8: https://www.eia.gov/outlooks/aeo/tables_side.php
B9: Table 3 (and Table 2 for industrial coal consumption fractions by coal type) | D9: Table 57
B11: 2025-2027 prices and start year tax | D11: Tax on Non-Liquid Fuels
B12: Energy Information Administration | D12: The Sales Tax Clearinghouse
B13: 2026 | D13: n/a
B14: Short Term Energy Outlook | D14: FAQ
B15: https://www.eia.gov/outlooks/steo/data/browser/#/?v=8 | D15: https://thestc.com/FAQ.stm
B16: Table 2 | D16: Question "What is the average sales tax nationally?"
B17: October release data
D18: green hydrogen
B19: biomass | D19: Department of Energy
B20: Energy Information Administraton | D20: 2024
B21: 2025 | D21: DOE Pathways to Commercial Liftoff: Clean Hydrogen
B22: State Energy Data System (SEDS): 1960-2023 (complete) | D22: https://climateprogramportal.org/wp-content/uploads/2025/02/Pathways-to-Commercial-Liftoff_Clean-Hydrogen_December-2024-Update.pdf
B23: https://www.eia.gov/state/seds/archive/seper2018.pdf | D23: Figure 10
B24: Tables ET3, ET4, ET5, and ET7
B26: biofuel diesel
B27: DOE Alternative Fuels Data Center
B28: 2025
B29: Clean Cities Alternative Fuel Price Report
B30: https://afdc.energy.gov/files/u/publication/alternative_fuel_price_report_july_2025.pdf
B31: Table 2
B33: heat
B34: Euroheat & Power
B35: n/a
B36: DHC & Statistics: United States
B37: http://www.euroheat.org/United-States-156.aspx
B38: "Average District Heating price in 2011" (using "Steam" rather than "Water" because most U.S. district heating systems use steam)
B40: Gas future prices
B41: CME Group
B42: 2026
B43: Henry Hub Natural Gas Futures - Quotes
B44: https://www.cmegroup.com/trading/energy/natural-gas/natural-gas_quotes_globex.html
B46: ICF
...

Sheet Gas Futures
A1: Month | B1: Options | C1: Chart | D1: Last | E1: Change | F1: Prior | G1: Open | H1: High | I1: Low | J1: Volume | K1: Updated | L1: Month.year
B2: Opt | D2: 4.036 | E2: -0.077 (-1.87%) | F2: - | G2: 4.171 | H2: 4.218 | I2: 3.993 | J2: 154446 | K2: 15:59:59 CT
A3: 46296 | B3: Opt | D3: 3.298 | E3: - | F3: 3.023 | G3: 3.037 | H3: 3.317 | I3: 2.979 | J3: 104473 | K3: 14:32 CT | L3: =CONCATENATE(MONTH(A3),".",YEAR(A3)) -> 10.2026
A4: NGV26 | K4: 46289.534
A5: 46327 | B5: Opt | D5: 3.382 | E5: - | F5: 3.153 | G5: 3.169 | H5: 3.395 | I5: 3.124 | J5: 369118 | K5: 14:32 CT | L5: =CONCATENATE(MONTH(A5),".",YEAR(A5)) -> 11.2026
A6: NGX26 | K6: 46289.534
A7: 46357 | B7: Opt | D7: 3.7 | E7: - | F7: 3.493 | G7: 3.504 | H7: 3.704 | I7: 3.486 | J7: 138989 | K7: 14:32 CT | L7: =CONCATENATE(MONTH(A7),".",YEAR(A7)) -> 12.2026
A8: NGZ26 | K8: 46289.534
A9: 46388 | B9: Opt | D9: 4.061 | E9: - | F9: 3.86 | G9: 3.877 | H9: 4.066 | I9: 3.865 | J9: 82351 | K9: 14:32 CT | L9: =CONCATENATE(MONTH(A9),".",YEAR(A9)) -> 1.2027
A10: NGF27 | K10: 46289.534
A11: 46419 | B11: Opt | D11: 3.702 | E11: - | F11: 3.528 | G11: 3.542 | H11: 3.707 | I11: 3.532 | J11: 49503 | K11: 14:32 CT | L11: =CONCATENATE(MONTH(A11),".",YEAR(A11)) -> 2.2027
A12: NGG27 | K12: 46289.534
A13: 46447 | B13: Opt | D13: 2.919 | E13: - | F13: 2.851 | G13: 2.857 | H13: 2.929 | I13: 2.841 | J13: 75569 | K13: 14:32 CT | L13: =CONCATENATE(MONTH(A13),".",YEAR(A13)) -> 3.2027
A14: NGH27 | K14: 46289.534
A15: 46478 | B15: Opt | D15: 2.782 | E15: - | F15: 2.731 | G15: 2.734 | H15: 2.791 | I15: 2.729 | J15: 48722 | K15: 14:32 CT | L15: =CONCATENATE(MONTH(A15),".",YEAR(A15)) -> 4.2027
A16: NGJ27 | K16: 46289.534
A17: 46508 | B17: Opt | D17: 2.799 | E17: - | F17: 2.756 | G17: 2.765 | H17: 2.81 | I17: 2.755 | J17: 26296 | K17: 14:32 CT | L17: =CONCATENATE(MONTH(A17),".",YEAR(A17)) -> 5.2027
A18: NGK27 | K18: 46289.534
A19: 46539 | B19: Opt | D19: 2.949 | E19: - | F19: 2.913 | G19: 2.922 | H19: 2.959 | I19: 2.913 | J19: 12975 | K19: 14:32 CT | L19: =CONCATENATE(MONTH(A19),".",YEAR(A19)) -> 6.2027
A20: NGM27 | K20: 46289.534
A21: 46569 | B21: Opt | D21: 3.168 | E21: - | F21: 3.138 | G21: 3.149 | H21: 3.181 | I21: 3.14 | J21: 13735 | K21: 14:32 CT | L21: =CONCATENATE(MONTH(A21),".",YEAR(A21)) -> 7.2027
A22: NGN27 | K22: 46289.534
A23: 46600 | B23: Opt | D23: 3.241 | E23: - | F23: 3.212 | G23: 3.223 | H23: 3.252 | I23: 3.216 | J23: 7099 | K23: 14:32 CT | L23: =CONCATENATE(MONTH(A23),".",YEAR(A23)) -> 8.2027
A24: NGQ27 | K24: 46289.534
A25: 46631 | B25: Opt | D25: 3.223 | E25: - | F25: 3.197 | G25: 3.209 | H25: 3.238 | I25: 3.2 | J25: 8204 | K25: 14:32 CT | L25: =CONCATENATE(MONTH(A25),".",YEAR(A25)) -> 9.2027
A26: NGU27 | K26: 46289.534
A27: 46661 | B27: Opt | D27: 3.308 | E27: - | F27: 3.284 | G27: 3.29 | H27: 3.324 | I27: 3.287 | J27: 14448 | K27: 14:32 CT | L27: =CONCATENATE(MONTH(A27),".",YEAR(A27)) -> 10.2027
A28: NGV27 | K28: 46289.534
A29: 46692 | B29: Opt | D29: 3.585 | E29: - | F29: 3.568 | G29: 3.576 | H29: 3.601 | I29: 3.571 | J29: 3284 | K29: 14:32 CT | L29: =CONCATENATE(MONTH(A29),".",YEAR(A29)) -> 11.2027
A30: NGX27 | K30: 46289.534
A31: 46722 | B31: Opt | D31: 4.193 | E31: - | F31: 4.18 | G31: 4.188 | H31: 4.204 | I31: 4.181 | J31: 2295 | K31: 14:32 CT | L31: =CONCATENATE(MONTH(A31),".",YEAR(A31)) -> 12.2027
A32: NGZ27 | K32: 46289.534
A33: 46753 | B33: Opt | D33: 4.622 | E33: - | F33: 4.609 | G33: 4.613 | H33: 4.632 | I33: 4.608 | J33: 3983 | K33: 14:32 CT | L33: =CONCATENATE(MONTH(A33),".",YEAR(A33)) -> 1.2028
A34: NGF28 | K34: 46289.534
A35: 46784 | B35: Opt | D35: 4.22 | E35: - | F35: 4.207 | G35: 4.212 | H35: 4.226 | I35: 4.208 | J35: 1952 | K35: 14:32 CT | L35: =CONCATENATE(MONTH(A35),".",YEAR(A35)) -> 2.2028
A36: NGG28 | K36: 46289.534
A37: 46813 | B37: Opt | D37: 3.492 | E37: - | F37: 3.477 | G37: 3.486 | H37: 3.498 | I37: 3.482 | J37: 2601 | K37: 14:32 CT | L37: =CONCATENATE(MONTH(A37),".",YEAR(A37)) -> 3.2028
A38: NGH28 | K38: 46289.534
A39: 46844 | B39: Opt | D39: 3.253 | E39: - | F39: 3.246 | G39: 3.255 | H39: 3.261 | I39: 3.243 | J39: 2043 | K39: 14:32 CT | L39: =CONCATENATE(MONTH(A39),".",YEAR(A39)) -> 4.2028
A40: NGJ28 | K40: 46289.534
...

Sheet Henry Hub Historicals
A1: Back to Contents | B1: Data 1: Spot Price
A2: Sourcekey | B2: RNGWHHD
A3: 35445 | B3: 3.45 | C3: Month.year
A4: 35476 | B4: 2.15 | C4: =CONCATENATE(MONTH(A4),".",YEAR(A4)) -> 2.1997
A5: 35504 | B5: 1.89 | C5: =CONCATENATE(MONTH(A5),".",YEAR(A5)) -> 3.1997
A6: 35535 | B6: 2.03 | C6: =CONCATENATE(MONTH(A6),".",YEAR(A6)) -> 4.1997
A7: 35565 | B7: 2.25 | C7: =CONCATENATE(MONTH(A7),".",YEAR(A7)) -> 5.1997
A8: 35596 | B8: 2.2 | C8: =CONCATENATE(MONTH(A8),".",YEAR(A8)) -> 6.1997
A9: 35626 | B9: 2.19 | C9: =CONCATENATE(MONTH(A9),".",YEAR(A9)) -> 7.1997
A10: 35657 | B10: 2.49 | C10: =CONCATENATE(MONTH(A10),".",YEAR(A10)) -> 8.1997
A11: 35688 | B11: 2.88 | C11: =CONCATENATE(MONTH(A11),".",YEAR(A11)) -> 9.1997
A12: 35718 | B12: 3.07 | C12: =CONCATENATE(MONTH(A12),".",YEAR(A12)) -> 10.1997
A13: 35749 | B13: 3.01 | C13: =CONCATENATE(MONTH(A13),".",YEAR(A13)) -> 11.1997
A14: 35779 | B14: 2.35 | C14: =CONCATENATE(MONTH(A14),".",YEAR(A14)) -> 12.1997
A15: 35810 | B15: 2.09 | C15: =CONCATENATE(MONTH(A15),".",YEAR(A15)) -> 1.1998
... A358: 46249.534 | B358: 2.78 | C358: =CONCATENATE(MONTH(A358),".",YEAR(A358)) -> 8.2026
A360: Back to Contents | B360: Data 1: Spot Price
A361: Sourcekey | B361: RNGWHHD
A362: Date | B362: Henry Hub Natural Gas Spot Price (Dollars per Million Btu)
A363: 35611 | B363: 2.49 | C363: 1997
A364: 35976 | B364: 2.09 | C364: 1998
A365: 36341 | B365: 2.27 | C365: 1999
A366: 36707 | B366: 4.31 | C366: 2000
A367: 37072 | B367: 3.96 | C367: 2001
A368: 37437 | B368: 3.38 | C368: 2002
A369: 37802 | B369: 5.47 | C369: 2003
A370: 38168 | B370: 5.89 | C370: 2004
A371: 38533 | B371: 8.69 | C371: 2005
A372: 38898 | B372: 6.73 | C372: 2006
A373: 39263 | B373: 6.97 | C373: 2007
A374: 39629 | B374: 8.86 | C374: 2008
... A391: 45838 | B391: 3.52 | C391: 2025

Sheet NG Sector Price Historicals
A1: Back to Contents | B1: Data 1: U.S. Natural Gas Prices
A2: Sourcekey | B2: N9190US3 | C2: N9100US3 | D2: N9102US3 | E2: N9103US3 | F2: N9130US3 | G2: N9132US3 | H2: N9133US3 | I2: NA1480_NUS_3 | J2: N3050US3 | K2: N3010US3 | L2: NA1504_NUS_4 | M2: N3020US3 | N2: N3020US4 | O2: N3035US3 | P2: N3035US4 | Q2: NA1570_NUS_3 | R2: N3045US3
A3: Date | B3: U.S. Natural Gas Wellhead Price (Dollars per Thousand Cubic Feet) | C3: Price of U.S. Natural Gas Imports (Dollars per Thousand Cubic Feet) | D3: U.S. Natural Gas Pipeline Imports Price (Dollars per Thousand Cubic Feet) | E3: Price of U.S. Natural Gas LNG Imports (Dollars per Thousand Cubic Feet) | F3: Price of U.S. Natural Gas Exports (Dollars per Thousand Cubic Feet) | G3: Price of U.S. Natural Gas Pipeline Exports (Dollars per Thousand Cubic Feet) | H3: Price of Liquefied U.S. Natural Gas Exports (Dollars per Thousand Cubic Feet) | I3: U.S. Natural Gas Pipeline and Distribution Use Price (Dollars per Thousand Cubic Feet) | J3: U.S. Natural Gas Citygate Price (Dollars per Thousand Cubic Feet) | K3: U.S. Price of Natural Gas Delivered to Residential Consumers (Dollars per Thousand Cubic Feet) | L3: U.S. Natural Gas % of Total Residential - Sales (%) | M3: U.S. Price of Natural Gas Sold to Commercial Consumers (Dollars per Thousand Cubic Feet) | N3: Percent of Commercial Natural Gas Deliveries in U.S. Total Represented by the Price (%) | O3: United States Natural Gas Industrial Price (Dollars per Thousand Cubic Feet) | P3: Percent of Industrial Natural Gas Deliveries in U.S. Total Represented by the Price (%) | Q3: U.S. Natural Gas Vehicle Fuel Price (Dollars per Thousand Cubic Feet) | R3: U.S. Natural Gas Electric Power Price (Dollars per Thousand Cubic Feet) | S3: Year
A4: 8217 | B4: 0.11 | S4: =YEAR(A4) -> 1922
A5: 8582 | B5: 0.1 | S5: =YEAR(A5) -> 1923
A6: 8948 | B6: 0.09 | S6: =YEAR(A6) -> 1924
A7: 9313 | B7: 0.09 | S7: =YEAR(A7) -> 1925
A8: 9678 | B8: 0.1 | S8: =YEAR(A8) -> 1926
A9: 10043 | B9: 0.09 | S9: =YEAR(A9) -> 1927
A10: 10409 | B10: 0.09 | S10: =YEAR(A10) -> 1928
A11: 10774 | B11: 0.08 | S11: =YEAR(A11) -> 1929
A12: 11139 | B12: 0.08 | S12: =YEAR(A12) -> 1930
A13: 11504 | B13: 0.07 | S13: =YEAR(A13) -> 1931
A14: 11870 | B14: 0.06 | S14: =YEAR(A14) -> 1932
A15: 12235 | B15: 0.06 | S15: =YEAR(A15) -> 1933
... A48: 24288 | B48: 0.16 | S48: =YEAR(A48) -> 1966
A49: 24653 | B49: 0.16 | I49: 0.2 | K49: 1.04 | M49: 0.74 | S49: =YEAR(A49) -> 1967
A50: 25019 | B50: 0.16 | I50: 0.2 | K50: 1.04 | M50: 0.73 | S50: =YEAR(A50) -> 1968
A51: 25384 | B51: 0.17 | I51: 0.21 | K51: 1.05 | M51: 0.74 | S51: =YEAR(A51) -> 1969
A52: 25749 | B52: 0.17 | I52: 0.21 | K52: 1.09 | M52: 0.77 | S52: =YEAR(A52) -> 1970
A53: 26114 | B53: 0.18 | I53: 0.22 | K53: 1.15 | M53: 0.82 | S53: =YEAR(A53) -> 1971
A54: 26480 | B54: 0.19 | I54: 0.23 | K54: 1.21 | M54: 0.88 | S54: =YEAR(A54) -> 1972
A55: 26845 | B55: 0.22 | I55: 0.25 | K55: 1.29 | M55: 0.94 | S55: =YEAR(A55) -> 1973
A56: 27210 | B56: 0.3 | I56: 0.3 | K56: 1.43 | M56: 1.07 | S56: =YEAR(A56) -> 1974
A57: 27575 | B57: 0.44 | I57: 0.4 | K57: 1.71 | M57: 1.35 | S57: =YEAR(A57) -> 1975
A58: 27941 | B58: 0.58 | I58: 0.51 | K58: 1.98 | M58: 1.64 | S58: =YEAR(A58) -> 1976
A59: 28306 | B59: 0.79 | I59: 0.77 | K59: 2.35 | M59: 2.04 | S59: =YEAR(A59) -> 1977
A60: 28671 | B60: 0.91 | I60: 0.9 | K60: 2.56 | M60: 2.23 | S60: =YEAR(A60) -> 1978
... A65: 30497 | B65: 2.59 | I65: 3.15 | K65: 6.06 | M65: 5.59 | S65: =YEAR(A65) -> 1983
A66: 30863 | B66: 2.66 | I66: 3.04 | J66: 3.95 | K66: 6.12 | M66: 5.55 | S66: =YEAR(A66) -> 1984
A67: 31228 | B67: 2.51 | C67: 3.21 | D67: 3.17 | E67: 4.6 | F67: 4.77 | G67: 3.92 | H67: 4.81 | I67: 2.92 | J67: 3.75 | K67: 6.12 | M67: 5.5 | S67: =YEAR(A67) -> 1985
A68: 31593 | B68: 1.94 | C68: 2.43 | D68: 2.42 | E68: 4.62 | F68: 2.81 | G68: 2.35 | H68: 2.91 | I68: 2.52 | J68: 3.22 | K68: 5.83 | M68: 5.08 | S68: =YEAR(A68) -> 1986
A69: 31958 | B69: 1.67 | C69: 1.95 | D69: 1.95 | F69: 3.07 | G69: 2.35 | H69: 3.15 | I69: 2.17 | J69: 2.87 | K69: 5.54 | M69: 4.77 | N69: 93.1 | S69: =YEAR(A69) -> 1987
A70: 32324 | B70: 1.69 | C70: 1.84 | D70: 1.83 | E70: 2.71 | F70: 2.74 | G70: 2.14 | H70: 2.98 | I70: 2.1 | J70: 2.92 | K70: 5.47 | M70: 4.63 | N70: 90.8 | S70: =YEAR(A70) -> 1988
A71: 32689 | B71: 1.69 | C71: 1.82 | D71: 1.81 | E71: 2.22 | F71: 2.51 | G71: 2.05 | H71: 3.01 | I71: 2.01 | J71: 3.01 | K71: 5.64 | L71: 99.9 | M71: 4.74 | N71: 89.1 | Q71: 4.17 | S71: =YEAR(A71) -> 1989
A72: 33054 | B72: 1.71 | C72: 1.94 | D72: 1.91 | E72: 2.47 | F72: 3.1 | G72: 2.31 | H72: 3.59 | I72: 1.95 | J72: 3.03 | K72: 5.8 | L72: 99.2 | M72: 4.83 | N72: 86.6 | Q72: 3.39 | S72: =YEAR(A72) -> 1990
A73: 33419 | B73: 1.64 | C73: 1.83 | D73: 1.81 | E73: 2.36 | F73: 2.59 | G73: 1.79 | H73: 3.71 | I73: 1.87 | J73: 2.9 | K73: 5.82 | L73: 99.2 | M73: 4.81 | N73: 85.1 | Q73: 3.96 | S73: =YEAR(A73) -> 1991
A74: 33785 | B74: 1.74 | C74: 1.85 | D74: 1.84 | E74: 2.54 | F74: 2.25 | G74: 1.88 | H74: 3.43 | I74: 2.07 | J74: 3.01 | K74: 5.89 | L74: 99.1 | M74: 4.88 | N74: 83.2 | Q74: 4.05 | S74: =YEAR(A74) -> 1992
A75: 34150 | B75: 2.04 | C75: 2.03 | D75: 2.02 | E75: 2.2 | F75: 2.59 | G75: 2.08 | H75: 3.34 | I75: 1.97 | J75: 3.21 | K75: 6.16 | L75: 99.1 | M75: 5.22 | N75: 83.9 | Q75: 4.27 | S75: =YEAR(A75) -> 1993
A76: 34515 | B76: 1.85 | C76: 1.87 | D76: 1.86 | E76: 2.28 | F76: 2.5 | G76: 2.08 | H76: 3.18 | I76: 1.7 | J76: 3.07 | K76: 6.41 | L76: 99.1 | M76: 5.44 | N76: 79.3 | Q76: 4.11 | S76: =YEAR(A76) -> 1994
...

Sheet Historical Monthly Gas Cons
A1: Back to Contents | B1: Data 1: Natural Gas Delivered to Consumers in the U.S. (MMcf)
A2: Sourcekey | B2: N3060US2
A3: Date | B3: Natural Gas Delivered to Consumers in the U.S. (MMcf)
A4: 36906 | B4: 2505011 | C4: =MONTH(A4) -> 1 | D4: =YEAR(A4) -> 2001
A5: 36937 | B5: 2156873 | C5: =MONTH(A5) -> 2 | D5: =YEAR(A5) -> 2001
A6: 36965 | B6: 2086568 | C6: =MONTH(A6) -> 3 | D6: =YEAR(A6) -> 2001
A7: 36996 | B7: 1663832 | C7: =MONTH(A7) -> 4 | D7: =YEAR(A7) -> 2001
A8: 37026 | B8: 1385163 | C8: =MONTH(A8) -> 5 | D8: =YEAR(A8) -> 2001
A9: 37057 | B9: 1313119 | C9: =MONTH(A9) -> 6 | D9: =YEAR(A9) -> 2001
A10: 37087 | B10: 1459919 | C10: =MONTH(A10) -> 7 | D10: =YEAR(A10) -> 2001
A11: 37118 | B11: 1528483 | C11: =MONTH(A11) -> 8 | D11: =YEAR(A11) -> 2001
A12: 37149 | B12: 1360871 | C12: =MONTH(A12) -> 9 | D12: =YEAR(A12) -> 2001
A13: 37179 | B13: 1507428 | C13: =MONTH(A13) -> 10 | D13: =YEAR(A13) -> 2001
A14: 37210 | B14: 1561970 | C14: =MONTH(A14) -> 11 | D14: =YEAR(A14) -> 2001
A15: 37240 | B15: 1965873 | C15: =MONTH(A15) -> 12 | D15: =YEAR(A15) -> 2001
... A300: 45915 | B300: 2162772 | C300: =MONTH(A300) -> 9 | D300: =YEAR(A300) -> 2025

Sheet NG Calcs
A1: Historical Monthly Consumption Average
A2: 1 | B2: {=SUMPRODUCT(IF('Historical Monthly Gas Cons'!$C:$C='NG Calcs'!A2,IF('Historical Monthly Gas Cons'!$D:$D>2021,'Historical Monthly Gas Cons'!$B:$B))/SUMPRODUCT(IF('Historical Monthly Gas Cons'!$D:$D>2021,'Historical Monthly Gas Cons'!$B:$B)))} -> 0.12049594
A3: 2 | B3: {=SUMPRODUCT(IF('Historical Monthly Gas Cons'!$C:$C='NG Calcs'!A3,IF('Historical Monthly Gas Cons'!$D:$D>2021,'Historical Monthly Gas Cons'!$B:$B))/SUMPRODUCT(IF('Historical Monthly Gas Cons'!$D:$D>2021,'Historical Monthly Gas Cons'!$B:$B)))} -> 0.10070617
A4: 3 | B4: {=SUMPRODUCT(IF('Historical Monthly Gas Cons'!$C:$C='NG Calcs'!A4,IF('Historical Monthly Gas Cons'!$D:$D>2021,'Historical Monthly Gas Cons'!$B:$B))/SUMPRODUCT(IF('Historical Monthly Gas Cons'!$D:$D>2021,'Historical Monthly Gas Cons'!$B:$B)))} -> 0.092746038
A5: 4 | B5: {=SUMPRODUCT(IF('Historical Monthly Gas Cons'!$C:$C='NG Calcs'!A5,IF('Historical Monthly Gas Cons'!$D:$D>2021,'Historical Monthly Gas Cons'!$B:$B))/SUMPRODUCT(IF('Historical Monthly Gas Cons'!$D:$D>2021,'Historical Monthly Gas Cons'!$B:$B)))} -> 0.07732915
A6: 5 | B6: {=SUMPRODUCT(IF('Historical Monthly Gas Cons'!$C:$C='NG Calcs'!A6,IF('Historical Monthly Gas Cons'!$D:$D>2021,'Historical Monthly Gas Cons'!$B:$B))/SUMPRODUCT(IF('Historical Monthly Gas Cons'!$D:$D>2021,'Historical Monthly Gas Cons'!$B:$B)))} -> 0.074025061
A7: 6 | B7: {=SUMPRODUCT(IF('Historical Monthly Gas Cons'!$C:$C='NG Calcs'!A7,IF('Historical Monthly Gas Cons'!$D:$D>2021,'Historical Monthly Gas Cons'!$B:$B))/SUMPRODUCT(IF('Historical Monthly Gas Cons'!$D:$D>2021,'Historical Monthly Gas Cons'!$B:$B)))} -> 0.076988667
A8: 7 | B8: {=SUMPRODUCT(IF('Historical Monthly Gas Cons'!$C:$C='NG Calcs'!A8,IF('Historical Monthly Gas Cons'!$D:$D>2021,'Historical Monthly Gas Cons'!$B:$B))/SUMPRODUCT(IF('Historical Monthly Gas Cons'!$D:$D>2021,'Historical Monthly Gas Cons'!$B:$B)))} -> 0.087090362
A9: 8 | B9: {=SUMPRODUCT(IF('Historical Monthly Gas Cons'!$C:$C='NG Calcs'!A9,IF('Historical Monthly Gas Cons'!$D:$D>2021,'Historical Monthly Gas Cons'!$B:$B))/SUMPRODUCT(IF('Historical Monthly Gas Cons'!$D:$D>2021,'Historical Monthly Gas Cons'!$B:$B)))} -> 0.086091328
A10: 9 | B10: {=SUMPRODUCT(IF('Historical Monthly Gas Cons'!$C:$C='NG Calcs'!A10,IF('Historical Monthly Gas Cons'!$D:$D>2021,'Historical Monthly Gas Cons'!$B:$B))/SUMPRODUCT(IF('Historical Monthly Gas Cons'!$D:$D>2021,'Historical Monthly Gas Cons'!$B:$B)))} -> 0.076769349
A11: 10 | B11: {=SUMPRODUCT(IF('Historical Monthly Gas Cons'!$C:$C='NG Calcs'!A11,IF('Historical Monthly Gas Cons'!$D:$D>2021,'Historical Monthly Gas Cons'!$B:$B))/SUMPRODUCT(IF('Historical Monthly Gas Cons'!$D:$D>2021,'Historical Monthly Gas Cons'!$B:$B)))} -> 0.058411579
A12: 11 | B12: {=SUMPRODUCT(IF('Historical Monthly Gas Cons'!$C:$C='NG Calcs'!A12,IF('Historical Monthly Gas Cons'!$D:$D>2021,'Historical Monthly Gas Cons'!$B:$B))/SUMPRODUCT(IF('Historical Monthly Gas Cons'!$D:$D>2021,'Historical Monthly Gas Cons'!$B:$B)))} -> 0.067770673
A13: 12 | B13: {=SUMPRODUCT(IF('Historical Monthly Gas Cons'!$C:$C='NG Calcs'!A13,IF('Historical Monthly Gas Cons'!$D:$D>2021,'Historical Monthly Gas Cons'!$B:$B))/SUMPRODUCT(IF('Historical Monthly Gas Cons'!$D:$D>2021,'Historical Monthly Gas Cons'!$B:$B)))} -> 0.081575676
A15: Future Prices | B15: 2021 | C15: 2022 | D15: 2023 | E15: 2024 | F15: 2025 | G15: 2026 | H15: 2027 | I15: 2028 | J15: 2029 | K15: 2030 | L15: 2031 | M15: 2032 | N15: 2033 | O15: 2034 | P15: 2035 | Q15: 2036
A16: 1 | B16: =INDEX('Henry Hub Historicals'!$B$4:$B$389,MATCH(CONCATENATE('NG Calcs'!$A16,".",'NG Calcs'!B$15),'Henry Hub Historicals'!$C$4:$C$389,0),1) -> 2.71 | C16: =INDEX('Henry Hub Historicals'!$B$4:$B$389,MATCH(CONCATENATE('NG Calcs'!$A16,".",'NG Calcs'!C$15),'Henry Hub Historicals'!$C$4:$C$389,0),1) -> 4.38 | D16: =INDEX('Henry Hub Historicals'!$B$4:$B$389,MATCH(CONCATENATE('NG Calcs'!$A16,".",'NG Calcs'!D$15),'Henry Hub Historicals'!$C$4:$C$389,0),1) -> 3.27 | E16: =INDEX('Henry Hub Historicals'!$B$4:$B$389,MATCH(CONCATENATE('NG Calcs'!$A16,".",'NG Calcs'!E$15),'Henry Hub Historicals'!$C$4:$C$389,0),1) -> 3.18 | F16: =INDEX('Henry Hub Historicals'!$B$4:$B$389,MATCH(CONCATENATE('NG Calcs'!$A16,".",'NG Calcs'!F$15),'Henry Hub Historicals'!$C$4:$C$389,0),1) -> 4.13 | G16: =INDEX('Henry Hub Historicals'!$B$4:$B$389,MATCH(CONCATENATE('NG Calcs'!$A16,".",'NG Calcs'!G$15),'Henry Hub Historicals'!$C$4:$C$389,0),1) -> 7.72 | H16: =INDEX('Gas Futures'!$G:$G,MATCH(CONCATENATE('NG Calcs'!$A16,".",'NG Calcs'!H$15),'Gas Futures'!$L:$L,0)) -> 3.877 | I16: =INDEX('Gas Futures'!$G:$G,MATCH(CONCATENATE('NG Calcs'!$A16,".",'NG Calcs'!I$15),'Gas Futures'!$L:$L,0)) -> 4.613 | J16: =INDEX('Gas Futures'!$G:$G,MATCH(CONCATENATE('NG Calcs'!$A16,".",'NG Calcs'!J$15),'Gas Futures'!$L:$L,0)) -> 4.838 | K16: =INDEX('Gas Futures'!$G:$G,MATCH(CONCATENATE('NG Calcs'!$A16,".",'NG Calcs'!K$15),'Gas Futures'!$L:$L,0)) -> - | L16: =INDEX('Gas Futures'!$G:$G,MATCH(CONCATENATE('NG Calcs'!$A16,".",'NG Calcs'!L$15),'Gas Futures'!$L:$L,0)) -> - | M16: =INDEX('Gas Futures'!$G:$G,MATCH(CONCATENATE('NG Calcs'!$A16,".",'NG Calcs'!M$15),'Gas Futures'!$L:$L,0)) -> - | N16: =INDEX('Gas Futures'!$G:$G,MATCH(CONCATENATE('NG Calcs'!$A16,".",'NG Calcs'!N$15),'Gas Futures'!$L:$L,0)) -> - | O16: =INDEX('Gas Futures'!$G:$G,MATCH(CONCATENATE('NG Calcs'!$A16,".",'NG Calcs'!O$15),'Gas Futures'!$L:$L,0)) -> - | ... Q16: =INDEX('Gas Futures'!$G:$G,MATCH(CONCATENATE('NG Calcs'!$A16,".",'NG Calcs'!Q$15),'Gas Futures'!$L:$L,0)) -> -
A17: 2 | B17: =INDEX('Henry Hub Historicals'!$B$4:$B$389,MATCH(CONCATENATE('NG Calcs'!$A17,".",'NG Calcs'!B$15),'Henry Hub Historicals'!$C$4:$C$389,0),1) -> 5.35 | C17: =INDEX('Henry Hub Historicals'!$B$4:$B$389,MATCH(CONCATENATE('NG Calcs'!$A17,".",'NG Calcs'!C$15),'Henry Hub Historicals'!$C$4:$C$389,0),1) -> 4.69 | D17: =INDEX('Henry Hub Historicals'!$B$4:$B$389,MATCH(CONCATENATE('NG Calcs'!$A17,".",'NG Calcs'!D$15),'Henry Hub Historicals'!$C$4:$C$389,0),1) -> 2.38 | E17: =INDEX('Henry Hub Historicals'!$B$4:$B$389,MATCH(CONCATENATE('NG Calcs'!$A17,".",'NG Calcs'!E$15),'Henry Hub Historicals'!$C$4:$C$389,0),1) -> 1.72 | F17: =INDEX('Henry Hub Historicals'!$B$4:$B$389,MATCH(CONCATENATE('NG Calcs'!$A17,".",'NG Calcs'!F$15),'Henry Hub Historicals'!$C$4:$C$389,0),1) -> 4.19 | G17: =INDEX('Henry Hub Historicals'!$B$4:$B$389,MATCH(CONCATENATE('NG Calcs'!$A17,".",'NG Calcs'!G$15),'Henry Hub Historicals'!$C$4:$C$389,0),1) -> 3.62 | H17: =INDEX('Gas Futures'!$G:$G,MATCH(CONCATENATE('NG Calcs'!$A17,".",'NG Calcs'!H$15),'Gas Futures'!$L:$L,0)) -> 3.542 | I17: =INDEX('Gas Futures'!$G:$G,MATCH(CONCATENATE('NG Calcs'!$A17,".",'NG Calcs'!I$15),'Gas Futures'!$L:$L,0)) -> 4.212 | J17: =INDEX('Gas Futures'!$G:$G,MATCH(CONCATENATE('NG Calcs'!$A17,".",'NG Calcs'!J$15),'Gas Futures'!$L:$L,0)) -> 4.38 | K17: =INDEX('Gas Futures'!$G:$G,MATCH(CONCATENATE('NG Calcs'!$A17,".",'NG Calcs'!K$15),'Gas Futures'!$L:$L,0)) -> 4.342 | L17: =INDEX('Gas Futures'!$G:$G,MATCH(CONCATENATE('NG Calcs'!$A17,".",'NG Calcs'!L$15),'Gas Futures'!$L:$L,0)) -> - | M17: =INDEX('Gas Futures'!$G:$G,MATCH(CONCATENATE('NG Calcs'!$A17,".",'NG Calcs'!M$15),'Gas Futures'!$L:$L,0)) -> - | N17: =INDEX('Gas Futures'!$G:$G,MATCH(CONCATENATE('NG Calcs'!$A17,".",'NG Calcs'!N$15),'Gas Futures'!$L:$L,0)) -> - | O17: =INDEX('Gas Futures'!$G:$G,MATCH(CONCATENATE('NG Calcs'!$A17,".",'NG Calcs'!O$15),'Gas Futures'!$L:$L,0)) -> - | ... Q17: =INDEX('Gas Futures'!$G:$G,MATCH(CONCATENATE('NG Calcs'!$A17,".",'NG Calcs'!Q$15),'Gas Futures'!$L:$L,0)) -> -
A18: 3 | B18: =INDEX('Henry Hub Historicals'!$B$4:$B$389,MATCH(CONCATENATE('NG Calcs'!$A18,".",'NG Calcs'!B$15),'Henry Hub Historicals'!$C$4:$C$389,0),1) -> 2.62 | C18: =INDEX('Henry Hub Historicals'!$B$4:$B$389,MATCH(CONCATENATE('NG Calcs'!$A18,".",'NG Calcs'!C$15),'Henry Hub Historicals'!$C$4:$C$389,0),1) -> 4.9 | D18: =INDEX('Henry Hub Historicals'!$B$4:$B$389,MATCH(CONCATENATE('NG Calcs'!$A18,".",'NG Calcs'!D$15),'Henry Hub Historicals'!$C$4:$C$389,0),1) -> 2.31 | E18: =INDEX('Henry Hub Historicals'!$B$4:$B$389,MATCH(CONCATENATE('NG Calcs'!$A18,".",'NG Calcs'!E$15),'Henry Hub Historicals'!$C$4:$C$389,0),1) -> 1.49 | F18: =INDEX('Henry Hub Historicals'!$B$4:$B$389,MATCH(CONCATENATE('NG Calcs'!$A18,".",'NG Calcs'!F$15),'Henry Hub Historicals'!$C$4:$C$389,0),1) -> 4.12 | G18: =INDEX('Henry Hub Historicals'!$B$4:$B$389,MATCH(CONCATENATE('NG Calcs'!$A18,".",'NG Calcs'!G$15),'Henry Hub Historicals'!$C$4:$C$389,0),1) -> 3.04 | H18: =INDEX('Gas Futures'!$G:$G,MATCH(CONCATENATE('NG Calcs'!$A18,".",'NG Calcs'!H$15),'Gas Futures'!$L:$L,0)) -> 2.857 | I18: =INDEX('Gas Futures'!$G:$G,MATCH(CONCATENATE('NG Calcs'!$A18,".",'NG Calcs'!I$15),'Gas Futures'!$L:$L,0)) -> 3.486 | J18: =INDEX('Gas Futures'!$G:$G,MATCH(CONCATENATE('NG Calcs'!$A18,".",'NG Calcs'!J$15),'Gas Futures'!$L:$L,0)) -> 3.45 | K18: =INDEX('Gas Futures'!$G:$G,MATCH(CONCATENATE('NG Calcs'!$A18,".",'NG Calcs'!K$15),'Gas Futures'!$L:$L,0)) -> - | L18: =INDEX('Gas Futures'!$G:$G,MATCH(CONCATENATE('NG Calcs'!$A18,".",'NG Calcs'!L$15),'Gas Futures'!$L:$L,0)) -> - | M18: =INDEX('Gas Futures'!$G:$G,MATCH(CONCATENATE('NG Calcs'!$A18,".",'NG Calcs'!M$15),'Gas Futures'!$L:$L,0)) -> - | N18: =INDEX('Gas Futures'!$G:$G,MATCH(CONCATENATE('NG Calcs'!$A18,".",'NG Calcs'!N$15),'Gas Futures'!$L:$L,0)) -> - | O18: =INDEX('Gas Futures'!$G:$G,MATCH(CONCATENATE('NG Calcs'!$A18,".",'NG Calcs'!O$15),'Gas Futures'!$L:$L,0)) -> - | ... Q18: =INDEX('Gas Futures'!$G:$G,MATCH(CONCATENATE('NG Calcs'!$A18,".",'NG Calcs'!Q$15),'Gas Futures'!$L:$L,0)) -> -
A19: 4 | B19: =INDEX('Henry Hub Historicals'!$B$4:$B$389,MATCH(CONCATENATE('NG Calcs'!$A19,".",'NG Calcs'!B$15),'Henry Hub Historicals'!$C$4:$C$389,0),1) -> 2.66 | C19: =INDEX('Henry Hub Historicals'!$B$4:$B$389,MATCH(CONCATENATE('NG Calcs'!$A19,".",'NG Calcs'!C$15),'Henry Hub Historicals'!$C$4:$C$389,0),1) -> 6.6 | D19: =INDEX('Henry Hub Historicals'!$B$4:$B$389,MATCH(CONCATENATE('NG Calcs'!$A19,".",'NG Calcs'!D$15),'Henry Hub Historicals'!$C$4:$C$389,0),1) -> 2.16 | E19: =INDEX('Henry Hub Historicals'!$B$4:$B$389,MATCH(CONCATENATE('NG Calcs'!$A19,".",'NG Calcs'!E$15),'Henry Hub Historicals'!$C$4:$C$389,0),1) -> 1.6 | F19: =INDEX('Henry Hub Historicals'!$B$4:$B$389,MATCH(CONCATENATE('NG Calcs'!$A19,".",'NG Calcs'!F$15),'Henry Hub Historicals'!$C$4:$C$389,0),1) -> 3.42 | G19: =INDEX('Henry Hub Historicals'!$B$4:$B$389,MATCH(CONCATENATE('NG Calcs'!$A19,".",'NG Calcs'!G$15),'Henry Hub Historicals'!$C$4:$C$389,0),1) -> 2.77 | H19: =INDEX('Gas Futures'!$G:$G,MATCH(CONCATENATE('NG Calcs'!$A19,".",'NG Calcs'!H$15),'Gas Futures'!$L:$L,0)) -> 2.734 | I19: =INDEX('Gas Futures'!$G:$G,MATCH(CONCATENATE('NG Calcs'!$A19,".",'NG Calcs'!I$15),'Gas Futures'!$L:$L,0)) -> 3.255 | J19: =INDEX('Gas Futures'!$G:$G,MATCH(CONCATENATE('NG Calcs'!$A19,".",'NG Calcs'!J$15),'Gas Futures'!$L:$L,0)) -> 3.178 | K19: =INDEX('Gas Futures'!$G:$G,MATCH(CONCATENATE('NG Calcs'!$A19,".",'NG Calcs'!K$15),'Gas Futures'!$L:$L,0)) -> - | L19: =INDEX('Gas Futures'!$G:$G,MATCH(CONCATENATE('NG Calcs'!$A19,".",'NG Calcs'!L$15),'Gas Futures'!$L:$L,0)) -> 3.05 | M19: =INDEX('Gas Futures'!$G:$G,MATCH(CONCATENATE('NG Calcs'!$A19,".",'NG Calcs'!M$15),'Gas Futures'!$L:$L,0)) -> 3.02 | N19: =INDEX('Gas Futures'!$G:$G,MATCH(CONCATENATE('NG Calcs'!$A19,".",'NG Calcs'!N$15),'Gas Futures'!$L:$L,0)) -> - | O19: =INDEX('Gas Futures'!$G:$G,MATCH(CONCATENATE('NG Calcs'!$A19,".",'NG Calcs'!O$15),'Gas Futures'!$L:$L,0)) -> - | ... Q19: =INDEX('Gas Futures'!$G:$G,MATCH(CONCATENATE('NG Calcs'!$A19,".",'NG Calcs'!Q$15),'Gas Futures'!$L:$L,0)) -> -
A20: 5 | B20: =INDEX('Henry Hub Historicals'!$B$4:$B$389,MATCH(CONCATENATE('NG Calcs'!$A20,".",'NG Calcs'!B$15),'Henry Hub Historicals'!$C$4:$C$389,0),1) -> 2.91 | C20: =INDEX('Henry Hub Historicals'!$B$4:$B$389,MATCH(CONCATENATE('NG Calcs'!$A20,".",'NG Calcs'!C$15),'Henry Hub Historicals'!$C$4:$C$389,0),1) -> 8.14 | D20: =INDEX('Henry Hub Historicals'!$B$4:$B$389,MATCH(CONCATENATE('NG Calcs'!$A20,".",'NG Calcs'!D$15),'Henry Hub Historicals'!$C$4:$C$389,0),1) -> 2.15 | E20: =INDEX('Henry Hub Historicals'!$B$4:$B$389,MATCH(CONCATENATE('NG Calcs'!$A20,".",'NG Calcs'!E$15),'Henry Hub Historicals'!$C$4:$C$389,0),1) -> 2.12 | F20: =INDEX('Henry Hub Historicals'!$B$4:$B$389,MATCH(CONCATENATE('NG Calcs'!$A20,".",'NG Calcs'!F$15),'Henry Hub Historicals'!$C$4:$C$389,0),1) -> 3.12 | G20: =INDEX('Henry Hub Historicals'!$B$4:$B$389,MATCH(CONCATENATE('NG Calcs'!$A20,".",'NG Calcs'!G$15),'Henry Hub Historicals'!$C$4:$C$389,0),1) -> 2.94 | H20: =INDEX('Gas Futures'!$G:$G,MATCH(CONCATENATE('NG Calcs'!$A20,".",'NG Calcs'!H$15),'Gas Futures'!$L:$L,0)) -> 2.765 | I20: =INDEX('Gas Futures'!$G:$G,MATCH(CONCATENATE('NG Calcs'!$A20,".",'NG Calcs'!I$15),'Gas Futures'!$L:$L,0)) -> 3.252 | J20: =INDEX('Gas Futures'!$G:$G,MATCH(CONCATENATE('NG Calcs'!$A20,".",'NG Calcs'!J$15),'Gas Futures'!$L:$L,0)) -> 3.16 | K20: =INDEX('Gas Futures'!$G:$G,MATCH(CONCATENATE('NG Calcs'!$A20,".",'NG Calcs'!K$15),'Gas Futures'!$L:$L,0)) -> - | L20: =INDEX('Gas Futures'!$G:$G,MATCH(CONCATENATE('NG Calcs'!$A20,".",'NG Calcs'!L$15),'Gas Futures'!$L:$L,0)) -> - | M20: =INDEX('Gas Futures'!$G:$G,MATCH(CONCATENATE('NG Calcs'!$A20,".",'NG Calcs'!M$15),'Gas Futures'!$L:$L,0)) -> - | N20: =INDEX('Gas Futures'!$G:$G,MATCH(CONCATENATE('NG Calcs'!$A20,".",'NG Calcs'!N$15),'Gas Futures'!$L:$L,0)) -> 2.9 | O20: =INDEX('Gas Futures'!$G:$G,MATCH(CONCATENATE('NG Calcs'!$A20,".",'NG Calcs'!O$15),'Gas Futures'!$L:$L,0)) -> - | ... Q20: =INDEX('Gas Futures'!$G:$G,MATCH(CONCATENATE('NG Calcs'!$A20,".",'NG Calcs'!Q$15),'Gas Futures'!$L:$L,0)) -> -
A21: 6 | B21: =INDEX('Henry Hub Historicals'!$B$4:$B$389,MATCH(CONCATENATE('NG Calcs'!$A21,".",'NG Calcs'!B$15),'Henry Hub Historicals'!$C$4:$C$389,0),1) -> 3.26 | C21: =INDEX('Henry Hub Historicals'!$B$4:$B$389,MATCH(CONCATENATE('NG Calcs'!$A21,".",'NG Calcs'!C$15),'Henry Hub Historicals'!$C$4:$C$389,0),1) -> 7.7 | D21: =INDEX('Henry Hub Historicals'!$B$4:$B$389,MATCH(CONCATENATE('NG Calcs'!$A21,".",'NG Calcs'!D$15),'Henry Hub Historicals'!$C$4:$C$389,0),1) -> 2.18 | E21: =INDEX('Henry Hub Historicals'!$B$4:$B$389,MATCH(CONCATENATE('NG Calcs'!$A21,".",'NG Calcs'!E$15),'Henry Hub Historicals'!$C$4:$C$389,0),1) -> 2.54 | F21: =INDEX('Henry Hub Historicals'!$B$4:$B$389,MATCH(CONCATENATE('NG Calcs'!$A21,".",'NG Calcs'!F$15),'Henry Hub Historicals'!$C$4:$C$389,0),1) -> 3.02 | G21: =INDEX('Henry Hub Historicals'!$B$4:$B$389,MATCH(CONCATENATE('NG Calcs'!$A21,".",'NG Calcs'!G$15),'Henry Hub Historicals'!$C$4:$C$389,0),1) -> 3.15 | H21: =INDEX('Gas Futures'!$G:$G,MATCH(CONCATENATE('NG Calcs'!$A21,".",'NG Calcs'!H$15),'Gas Futures'!$L:$L,0)) -> 2.922 | I21: =INDEX('Gas Futures'!$G:$G,MATCH(CONCATENATE('NG Calcs'!$A21,".",'NG Calcs'!I$15),'Gas Futures'!$L:$L,0)) -> 3.412 | J21: =INDEX('Gas Futures'!$G:$G,MATCH(CONCATENATE('NG Calcs'!$A21,".",'NG Calcs'!J$15),'Gas Futures'!$L:$L,0)) -> 3.285 | K21: =INDEX('Gas Futures'!$G:$G,MATCH(CONCATENATE('NG Calcs'!$A21,".",'NG Calcs'!K$15),'Gas Futures'!$L:$L,0)) -> - | L21: =INDEX('Gas Futures'!$G:$G,MATCH(CONCATENATE('NG Calcs'!$A21,".",'NG Calcs'!L$15),'Gas Futures'!$L:$L,0)) -> - | M21: =INDEX('Gas Futures'!$G:$G,MATCH(CONCATENATE('NG Calcs'!$A21,".",'NG Calcs'!M$15),'Gas Futures'!$L:$L,0)) -> - | N21: =INDEX('Gas Futures'!$G:$G,MATCH(CONCATENATE('NG Calcs'!$A21,".",'NG Calcs'!N$15),'Gas Futures'!$L:$L,0)) -> - | O21: =INDEX('Gas Futures'!$G:$G,MATCH(CONCATENATE('NG Calcs'!$A21,".",'NG Calcs'!O$15),'Gas Futures'!$L:$L,0)) -> - | ... Q21: =INDEX('Gas Futures'!$G:$G,MATCH(CONCATENATE('NG Calcs'!$A21,".",'NG Calcs'!Q$15),'Gas Futures'!$L:$L,0)) -> -
A22: 7 | B22: =INDEX('Henry Hub Historicals'!$B$4:$B$389,MATCH(CONCATENATE('NG Calcs'!$A22,".",'NG Calcs'!B$15),'Henry Hub Historicals'!$C$4:$C$389,0),1) -> 3.84 | C22: =INDEX('Henry Hub Historicals'!$B$4:$B$389,MATCH(CONCATENATE('NG Calcs'!$A22,".",'NG Calcs'!C$15),'Henry Hub Historicals'!$C$4:$C$389,0),1) -> 7.28 | D22: =INDEX('Henry Hub Historicals'!$B$4:$B$389,MATCH(CONCATENATE('NG Calcs'!$A22,".",'NG Calcs'!D$15),'Henry Hub Historicals'!$C$4:$C$389,0),1) -> 2.55 | E22: =INDEX('Henry Hub Historicals'!$B$4:$B$389,MATCH(CONCATENATE('NG Calcs'!$A22,".",'NG Calcs'!E$15),'Henry Hub Historicals'!$C$4:$C$389,0),1) -> 2.07 | F22: =INDEX('Henry Hub Historicals'!$B$4:$B$389,MATCH(CONCATENATE('NG Calcs'!$A22,".",'NG Calcs'!F$15),'Henry Hub Historicals'!$C$4:$C$389,0),1) -> 3.2 | G22: =INDEX('Henry Hub Historicals'!$B$4:$B$389,MATCH(CONCATENATE('NG Calcs'!$A22,".",'NG Calcs'!G$15),'Henry Hub Historicals'!$C$4:$C$389,0),1) -> 2.89 | H22: =INDEX('Gas Futures'!$G:$G,MATCH(CONCATENATE('NG Calcs'!$A22,".",'NG Calcs'!H$15),'Gas Futures'!$L:$L,0)) -> 3.149 | I22: =INDEX('Gas Futures'!$G:$G,MATCH(CONCATENATE('NG Calcs'!$A22,".",'NG Calcs'!I$15),'Gas Futures'!$L:$L,0)) -> 3.622 | J22: =INDEX('Gas Futures'!$G:$G,MATCH(CONCATENATE('NG Calcs'!$A22,".",'NG Calcs'!J$15),'Gas Futures'!$L:$L,0)) -> 3.492 | K22: =INDEX('Gas Futures'!$G:$G,MATCH(CONCATENATE('NG Calcs'!$A22,".",'NG Calcs'!K$15),'Gas Futures'!$L:$L,0)) -> 3.46 | L22: =INDEX('Gas Futures'!$G:$G,MATCH(CONCATENATE('NG Calcs'!$A22,".",'NG Calcs'!L$15),'Gas Futures'!$L:$L,0)) -> - | M22: =INDEX('Gas Futures'!$G:$G,MATCH(CONCATENATE('NG Calcs'!$A22,".",'NG Calcs'!M$15),'Gas Futures'!$L:$L,0)) -> - | N22: =INDEX('Gas Futures'!$G:$G,MATCH(CONCATENATE('NG Calcs'!$A22,".",'NG Calcs'!N$15),'Gas Futures'!$L:$L,0)) -> - | O22: =INDEX('Gas Futures'!$G:$G,MATCH(CONCATENATE('NG Calcs'!$A22,".",'NG Calcs'!O$15),'Gas Futures'!$L:$L,0)) -> - | ... Q22: =INDEX('Gas Futures'!$G:$G,MATCH(CONCATENATE('NG Calcs'!$A22,".",'NG Calcs'!Q$15),'Gas Futures'!$L:$L,0)) -> -
A23: 8 | B23: =INDEX('Henry Hub Historicals'!$B$4:$B$389,MATCH(CONCATENATE('NG Calcs'!$A23,".",'NG Calcs'!B$15),'Henry Hub Historicals'!$C$4:$C$389,0),1) -> 4.07 | C23: =INDEX('Henry Hub Historicals'!$B$4:$B$389,MATCH(CONCATENATE('NG Calcs'!$A23,".",'NG Calcs'!C$15),'Henry Hub Historicals'!$C$4:$C$389,0),1) -> 8.81 | D23: =INDEX('Henry Hub Historicals'!$B$4:$B$389,MATCH(CONCATENATE('NG Calcs'!$A23,".",'NG Calcs'!D$15),'Henry Hub Historicals'!$C$4:$C$389,0),1) -> 2.58 | E23: =INDEX('Henry Hub Historicals'!$B$4:$B$389,MATCH(CONCATENATE('NG Calcs'!$A23,".",'NG Calcs'!E$15),'Henry Hub Historicals'!$C$4:$C$389,0),1) -> 1.99 | F23: =INDEX('Henry Hub Historicals'!$B$4:$B$389,MATCH(CONCATENATE('NG Calcs'!$A23,".",'NG Calcs'!F$15),'Henry Hub Historicals'!$C$4:$C$389,0),1) -> 2.91 | G23: =INDEX('Henry Hub Historicals'!$B$4:$B$389,MATCH(CONCATENATE('NG Calcs'!$A23,".",'NG Calcs'!G$15),'Henry Hub Historicals'!$C$4:$C$389,0),1) -> 2.78 | H23: =INDEX('Gas Futures'!$G:$G,MATCH(CONCATENATE('NG Calcs'!$A23,".",'NG Calcs'!H$15),'Gas Futures'!$L:$L,0)) -> 3.223 | I23: =INDEX('Gas Futures'!$G:$G,MATCH(CONCATENATE('NG Calcs'!$A23,".",'NG Calcs'!I$15),'Gas Futures'!$L:$L,0)) -> 3.68 | J23: =INDEX('Gas Futures'!$G:$G,MATCH(CONCATENATE('NG Calcs'!$A23,".",'NG Calcs'!J$15),'Gas Futures'!$L:$L,0)) -> - | K23: =INDEX('Gas Futures'!$G:$G,MATCH(CONCATENATE('NG Calcs'!$A23,".",'NG Calcs'!K$15),'Gas Futures'!$L:$L,0)) -> - | L23: =INDEX('Gas Futures'!$G:$G,MATCH(CONCATENATE('NG Calcs'!$A23,".",'NG Calcs'!L$15),'Gas Futures'!$L:$L,0)) -> - | M23: =INDEX('Gas Futures'!$G:$G,MATCH(CONCATENATE('NG Calcs'!$A23,".",'NG Calcs'!M$15),'Gas Futures'!$L:$L,0)) -> - | N23: =INDEX('Gas Futures'!$G:$G,MATCH(CONCATENATE('NG Calcs'!$A23,".",'NG Calcs'!N$15),'Gas Futures'!$L:$L,0)) -> - | O23: =INDEX('Gas Futures'!$G:$G,MATCH(CONCATENATE('NG Calcs'!$A23,".",'NG Calcs'!O$15),'Gas Futures'!$L:$L,0)) -> - | ... Q23: =INDEX('Gas Futures'!$G:$G,MATCH(CONCATENATE('NG Calcs'!$A23,".",'NG Calcs'!Q$15),'Gas Futures'!$L:$L,0)) -> -
A24: 9 | B24: =INDEX('Henry Hub Historicals'!$B$4:$B$389,MATCH(CONCATENATE('NG Calcs'!$A24,".",'NG Calcs'!B$15),'Henry Hub Historicals'!$C$4:$C$389,0),1) -> 5.16 | C24: =INDEX('Henry Hub Historicals'!$B$4:$B$389,MATCH(CONCATENATE('NG Calcs'!$A24,".",'NG Calcs'!C$15),'Henry Hub Historicals'!$C$4:$C$389,0),1) -> 7.88 | D24: =INDEX('Henry Hub Historicals'!$B$4:$B$389,MATCH(CONCATENATE('NG Calcs'!$A24,".",'NG Calcs'!D$15),'Henry Hub Historicals'!$C$4:$C$389,0),1) -> 2.64 | E24: =INDEX('Henry Hub Historicals'!$B$4:$B$389,MATCH(CONCATENATE('NG Calcs'!$A24,".",'NG Calcs'!E$15),'Henry Hub Historicals'!$C$4:$C$389,0),1) -> 2.28 | F24: =INDEX('Henry Hub Historicals'!$B$4:$B$389,MATCH(CONCATENATE('NG Calcs'!$A24,".",'NG Calcs'!F$15),'Henry Hub Historicals'!$C$4:$C$389,0),1) -> 2.97 | G24: =AVERAGE(G23,G25) -> 2.9085 | H24: =INDEX('Gas Futures'!$G:$G,MATCH(CONCATENATE('NG Calcs'!$A24,".",'NG Calcs'!H$15),'Gas Futures'!$L:$L,0)) -> 3.209 | I24: =INDEX('Gas Futures'!$G:$G,MATCH(CONCATENATE('NG Calcs'!$A24,".",'NG Calcs'!I$15),'Gas Futures'!$L:$L,0)) -> 3.638 | J24: =INDEX('Gas Futures'!$G:$G,MATCH(CONCATENATE('NG Calcs'!$A24,".",'NG Calcs'!J$15),'Gas Futures'!$L:$L,0)) -> - | K24: =INDEX('Gas Futures'!$G:$G,MATCH(CONCATENATE('NG Calcs'!$A24,".",'NG Calcs'!K$15),'Gas Futures'!$L:$L,0)) -> - | L24: =INDEX('Gas Futures'!$G:$G,MATCH(CONCATENATE('NG Calcs'!$A24,".",'NG Calcs'!L$15),'Gas Futures'!$L:$L,0)) -> - | M24: =INDEX('Gas Futures'!$G:$G,MATCH(CONCATENATE('NG Calcs'!$A24,".",'NG Calcs'!M$15),'Gas Futures'!$L:$L,0)) -> - | N24: =INDEX('Gas Futures'!$G:$G,MATCH(CONCATENATE('NG Calcs'!$A24,".",'NG Calcs'!N$15),'Gas Futures'!$L:$L,0)) -> - | O24: =INDEX('Gas Futures'!$G:$G,MATCH(CONCATENATE('NG Calcs'!$A24,".",'NG Calcs'!O$15),'Gas Futures'!$L:$L,0)) -> - | ... Q24: =INDEX('Gas Futures'!$G:$G,MATCH(CONCATENATE('NG Calcs'!$A24,".",'NG Calcs'!Q$15),'Gas Futures'!$L:$L,0)) -> -
A25: 10 | B25: =INDEX('Henry Hub Historicals'!$B$4:$B$389,MATCH(CONCATENATE('NG Calcs'!$A25,".",'NG Calcs'!B$15),'Henry Hub Historicals'!$C$4:$C$389,0),1) -> 5.51 | C25: =INDEX('Henry Hub Historicals'!$B$4:$B$389,MATCH(CONCATENATE('NG Calcs'!$A25,".",'NG Calcs'!C$15),'Henry Hub Historicals'!$C$4:$C$389,0),1) -> 5.66 | D25: =INDEX('Henry Hub Historicals'!$B$4:$B$389,MATCH(CONCATENATE('NG Calcs'!$A25,".",'NG Calcs'!D$15),'Henry Hub Historicals'!$C$4:$C$389,0),1) -> 2.98 | E25: =INDEX('Henry Hub Historicals'!$B$4:$B$389,MATCH(CONCATENATE('NG Calcs'!$A25,".",'NG Calcs'!E$15),'Henry Hub Historicals'!$C$4:$C$389,0),1) -> 2.2 | F25: =INDEX('Henry Hub Historicals'!$B$4:$B$389,MATCH(CONCATENATE('NG Calcs'!$A25,".",'NG Calcs'!F$15),'Henry Hub Historicals'!$C$4:$C$389,0),1) -> 3.19 | G25: =INDEX('Gas Futures'!$G:$G,MATCH(CONCATENATE('NG Calcs'!$A25,".",'NG Calcs'!G$15),'Gas Futures'!$L:$L,0)) -> 3.037 | H25: =INDEX('Gas Futures'!$G:$G,MATCH(CONCATENATE('NG Calcs'!$A25,".",'NG Calcs'!H$15),'Gas Futures'!$L:$L,0)) -> 3.29 | I25: =INDEX('Gas Futures'!$G:$G,MATCH(CONCATENATE('NG Calcs'!$A25,".",'NG Calcs'!I$15),'Gas Futures'!$L:$L,0)) -> 3.704 | J25: =INDEX('Gas Futures'!$G:$G,MATCH(CONCATENATE('NG Calcs'!$A25,".",'NG Calcs'!J$15),'Gas Futures'!$L:$L,0)) -> 3.59 | K25: =INDEX('Gas Futures'!$G:$G,MATCH(CONCATENATE('NG Calcs'!$A25,".",'NG Calcs'!K$15),'Gas Futures'!$L:$L,0)) -> - | L25: =INDEX('Gas Futures'!$G:$G,MATCH(CONCATENATE('NG Calcs'!$A25,".",'NG Calcs'!L$15),'Gas Futures'!$L:$L,0)) -> - | M25: =INDEX('Gas Futures'!$G:$G,MATCH(CONCATENATE('NG Calcs'!$A25,".",'NG Calcs'!M$15),'Gas Futures'!$L:$L,0)) -> - | N25: =INDEX('Gas Futures'!$G:$G,MATCH(CONCATENATE('NG Calcs'!$A25,".",'NG Calcs'!N$15),'Gas Futures'!$L:$L,0)) -> - | ... Q25: =INDEX('Gas Futures'!$G:$G,MATCH(CONCATENATE('NG Calcs'!$A25,".",'NG Calcs'!Q$15),'Gas Futures'!$L:$L,0)) -> -
A26: 11 | B26: =INDEX('Henry Hub Historicals'!$B$4:$B$389,MATCH(CONCATENATE('NG Calcs'!$A26,".",'NG Calcs'!B$15),'Henry Hub Historicals'!$C$4:$C$389,0),1) -> 5.05 | C26: =INDEX('Henry Hub Historicals'!$B$4:$B$389,MATCH(CONCATENATE('NG Calcs'!$A26,".",'NG Calcs'!C$15),'Henry Hub Historicals'!$C$4:$C$389,0),1) -> 5.45 | D26: =INDEX('Henry Hub Historicals'!$B$4:$B$389,MATCH(CONCATENATE('NG Calcs'!$A26,".",'NG Calcs'!D$15),'Henry Hub Historicals'!$C$4:$C$389,0),1) -> 2.71 | E26: =INDEX('Henry Hub Historicals'!$B$4:$B$389,MATCH(CONCATENATE('NG Calcs'!$A26,".",'NG Calcs'!E$15),'Henry Hub Historicals'!$C$4:$C$389,0),1) -> 2.12 | F26: =INDEX('Henry Hub Historicals'!$B$4:$B$389,MATCH(CONCATENATE('NG Calcs'!$A26,".",'NG Calcs'!F$15),'Henry Hub Historicals'!$C$4:$C$389,0),1) -> 3.79 | G26: =INDEX('Gas Futures'!$G:$G,MATCH(CONCATENATE('NG Calcs'!$A26,".",'NG Calcs'!G$15),'Gas Futures'!$L:$L,0)) -> 3.169 | H26: =INDEX('Gas Futures'!$G:$G,MATCH(CONCATENATE('NG Calcs'!$A26,".",'NG Calcs'!H$15),'Gas Futures'!$L:$L,0)) -> 3.576 | I26: =INDEX('Gas Futures'!$G:$G,MATCH(CONCATENATE('NG Calcs'!$A26,".",'NG Calcs'!I$15),'Gas Futures'!$L:$L,0)) -> 3.875 | J26: =INDEX('Gas Futures'!$G:$G,MATCH(CONCATENATE('NG Calcs'!$A26,".",'NG Calcs'!J$15),'Gas Futures'!$L:$L,0)) -> 3.722 | K26: =INDEX('Gas Futures'!$G:$G,MATCH(CONCATENATE('NG Calcs'!$A26,".",'NG Calcs'!K$15),'Gas Futures'!$L:$L,0)) -> - | L26: =INDEX('Gas Futures'!$G:$G,MATCH(CONCATENATE('NG Calcs'!$A26,".",'NG Calcs'!L$15),'Gas Futures'!$L:$L,0)) -> - | M26: =INDEX('Gas Futures'!$G:$G,MATCH(CONCATENATE('NG Calcs'!$A26,".",'NG Calcs'!M$15),'Gas Futures'!$L:$L,0)) -> - | N26: =INDEX('Gas Futures'!$G:$G,MATCH(CONCATENATE('NG Calcs'!$A26,".",'NG Calcs'!N$15),'Gas Futures'!$L:$L,0)) -> - | ... Q26: =INDEX('Gas Futures'!$G:$G,MATCH(CONCATENATE('NG Calcs'!$A26,".",'NG Calcs'!Q$15),'Gas Futures'!$L:$L,0)) -> -
A27: 12 | B27: =INDEX('Henry Hub Historicals'!$B$4:$B$389,MATCH(CONCATENATE('NG Calcs'!$A27,".",'NG Calcs'!B$15),'Henry Hub Historicals'!$C$4:$C$389,0),1) -> 3.76 | C27: =INDEX('Henry Hub Historicals'!$B$4:$B$389,MATCH(CONCATENATE('NG Calcs'!$A27,".",'NG Calcs'!C$15),'Henry Hub Historicals'!$C$4:$C$389,0),1) -> 5.53 | D27: =INDEX('Henry Hub Historicals'!$B$4:$B$389,MATCH(CONCATENATE('NG Calcs'!$A27,".",'NG Calcs'!D$15),'Henry Hub Historicals'!$C$4:$C$389,0),1) -> 2.52 | E27: =INDEX('Henry Hub Historicals'!$B$4:$B$389,MATCH(CONCATENATE('NG Calcs'!$A27,".",'NG Calcs'!E$15),'Henry Hub Historicals'!$C$4:$C$389,0),1) -> 3.01 | F27: =INDEX('Henry Hub Historicals'!$B$4:$B$389,MATCH(CONCATENATE('NG Calcs'!$A27,".",'NG Calcs'!F$15),'Henry Hub Historicals'!$C$4:$C$389,0),1) -> 4.26 | G27: =INDEX('Gas Futures'!$G:$G,MATCH(CONCATENATE('NG Calcs'!$A27,".",'NG Calcs'!G$15),'Gas Futures'!$L:$L,0)) -> 3.504 | H27: =INDEX('Gas Futures'!$G:$G,MATCH(CONCATENATE('NG Calcs'!$A27,".",'NG Calcs'!H$15),'Gas Futures'!$L:$L,0)) -> 4.188 | I27: =INDEX('Gas Futures'!$G:$G,MATCH(CONCATENATE('NG Calcs'!$A27,".",'NG Calcs'!I$15),'Gas Futures'!$L:$L,0)) -> 4.409 | J27: =INDEX('Gas Futures'!$G:$G,MATCH(CONCATENATE('NG Calcs'!$A27,".",'NG Calcs'!J$15),'Gas Futures'!$L:$L,0)) -> - | K27: =INDEX('Gas Futures'!$G:$G,MATCH(CONCATENATE('NG Calcs'!$A27,".",'NG Calcs'!K$15),'Gas Futures'!$L:$L,0)) -> - | L27: =INDEX('Gas Futures'!$G:$G,MATCH(CONCATENATE('NG Calcs'!$A27,".",'NG Calcs'!L$15),'Gas Futures'!$L:$L,0)) -> - | M27: =INDEX('Gas Futures'!$G:$G,MATCH(CONCATENATE('NG Calcs'!$A27,".",'NG Calcs'!M$15),'Gas Futures'!$L:$L,0)) -> - | N27: =INDEX('Gas Futures'!$G:$G,MATCH(CONCATENATE('NG Calcs'!$A27,".",'NG Calcs'!N$15),'Gas Futures'!$L:$L,0)) -> - | ... Q27: =INDEX('Gas Futures'!$G:$G,MATCH(CONCATENATE('NG Calcs'!$A27,".",'NG Calcs'!Q$15),'Gas Futures'!$L:$L,0)) -> -
A29: key: | B29: henry hub historicals | C29: estim. | D29: futures
I30: uses ICF forecast (2030 base case Q4 2025: 3.97 real 2024$ = 4.07 in 2025$; entered in 2025$ to match the 2025-to-2012 deflator)
A31: Annual Average | B31: 2021 | C31: 2022 | D31: 2023 | E31: 2024 | F31: 2025 | G31: 2026 | H31: 2027 | I31: 2028 | J31: 2029 | K31: 2030 | L31: 2031 | M31: 2032 | N31: 2033 | O31: 2034 | P31: 2035 | Q31: 2036
B32: =SUMPRODUCT(B16:B27,$B$2:$B$13) -> 3.832171 | C32: =SUMPRODUCT(C16:C27,$B$2:$B$13) -> 6.308787 | D32: =SUMPRODUCT(D16:D27,$B$2:$B$13) -> 2.5521288 | E32: =SUMPRODUCT(E16:E27,$B$2:$B$13) -> 2.2151493 | F32: =SUMPRODUCT(F16:F27,$B$2:$B$13) -> 3.5775665 | G32: =SUMPRODUCT(G16:G27,$B$2:$B$13) -> 3.6433938 | H32: =SUMPRODUCT(H16:H27,$B$2:$B$13) -> 3.3041312 | I32: 4.07 | J32: 4.07 | K32: 4.07
A34: Henry Hub: Sector Price Ratio | B34: 2010 | C34: 2011 | D34: 2012 | E34: 2013 | F34: 2014 | G34: 2015 | H34: 2016 | I34: 2017 | J34: 2018 | K34: 2019 | L34: 2020 | M34: 2021 | N34: 2022 | O34: 2023 | P34: 2024 | Q34: 2025
A35: Residential | B35: =INDEX('NG Sector Price Historicals'!$K:$K,MATCH('NG Calcs'!B$34,'NG Sector Price Historicals'!$S:$S,0),1)/INDEX('Henry Hub Historicals'!$B$363:$B$390,MATCH('NG Calcs'!B$34,'Henry Hub Historicals'!$C$363:$C$390,0),1) -> 2.6064073 | C35: =INDEX('NG Sector Price Historicals'!$K:$K,MATCH('NG Calcs'!C$34,'NG Sector Price Historicals'!$S:$S,0),1)/INDEX('Henry Hub Historicals'!$B$363:$B$390,MATCH('NG Calcs'!C$34,'Henry Hub Historicals'!$C$363:$C$390,0),1) -> 2.7575 | D35: =INDEX('NG Sector Price Historicals'!$K:$K,MATCH('NG Calcs'!D$34,'NG Sector Price Historicals'!$S:$S,0),1)/INDEX('Henry Hub Historicals'!$B$363:$B$390,MATCH('NG Calcs'!D$34,'Henry Hub Historicals'!$C$363:$C$390,0),1) -> 3.8727273 | E35: =INDEX('NG Sector Price Historicals'!$K:$K,MATCH('NG Calcs'!E$34,'NG Sector Price Historicals'!$S:$S,0),1)/INDEX('Henry Hub Historicals'!$B$363:$B$390,MATCH('NG Calcs'!E$34,'Henry Hub Historicals'!$C$363:$C$390,0),1) -> 2.766756 | F35: =INDEX('NG Sector Price Historicals'!$K:$K,MATCH('NG Calcs'!F$34,'NG Sector Price Historicals'!$S:$S,0),1)/INDEX('Henry Hub Historicals'!$B$363:$B$390,MATCH('NG Calcs'!F$34,'Henry Hub Historicals'!$C$363:$C$390,0),1) -> 2.5102975 | G35: =INDEX('NG Sector Price Historicals'!$K:$K,MATCH('NG Calcs'!G$34,'NG Sector Price Historicals'!$S:$S,0),1)/INDEX('Henry Hub Historicals'!$B$363:$B$390,MATCH('NG Calcs'!G$34,'Henry Hub Historicals'!$C$363:$C$390,0),1) -> 3.9618321 | H35: =INDEX('NG Sector Price Historicals'!$K:$K,MATCH('NG Calcs'!H$34,'NG Sector Price Historicals'!$S:$S,0),1)/INDEX('Henry Hub Historicals'!$B$363:$B$390,MATCH('NG Calcs'!H$34,'Henry Hub Historicals'!$C$363:$C$390,0),1) -> 3.9880952 | I35: =INDEX('NG Sector Price Historicals'!$K:$K,MATCH('NG Calcs'!I$34,'NG Sector Price Historicals'!$S:$S,0),1)/INDEX('Henry Hub Historicals'!$B$363:$B$390,MATCH('NG Calcs'!I$34,'Henry Hub Historicals'!$C$363:$C$390,0),1) -> 3.6488294 | ... K35: =INDEX('NG Sector Price Historicals'!$K:$K,MATCH('NG Calcs'!K$34,'NG Sector Price Historicals'!$S:$S,0),1)/INDEX('Henry Hub Historicals'!$B$363:$B$390,MATCH('NG Calcs'!K$34,'Henry Hub Historicals'!$C$363:$C$390,0),1) -> 4.1054688 | L35: =INDEX('NG Sector Price Historicals'!$K:$K,MATCH('NG Calcs'!L$34,'NG Sector Price Historicals'!$S:$S,0),1)/INDEX('Henry Hub Historicals'!$B$363:$B$391,MATCH('NG Calcs'!L$34,'Henry Hub Historicals'!$C$363:$C$391,0),1) -> 5.3103448 | M35: =INDEX('NG Sector Price Historicals'!$K:$K,MATCH('NG Calcs'!M$34,'NG Sector Price Historicals'!$S:$S,0),1)/INDEX('Henry Hub Historicals'!$B$363:$B$391,MATCH('NG Calcs'!M$34,'Henry Hub Historicals'!$C$363:$C$391,0),1) -> 3.1311054 | N35: =INDEX('NG Sector Price Historicals'!$K:$K,MATCH('NG Calcs'!N$34,'NG Sector Price Historicals'!$S:$S,0),1)/INDEX('Henry Hub Historicals'!$B$363:$B$391,MATCH('NG Calcs'!N$34,'Henry Hub Historicals'!$C$363:$C$391,0),1) -> 2.2868217 | O35: =INDEX('NG Sector Price Historicals'!$K:$K,MATCH('NG Calcs'!O$34,'NG Sector Price Historicals'!$S:$S,0),1)/INDEX('Henry Hub Historicals'!$B$363:$B$391,MATCH('NG Calcs'!O$34,'Henry Hub Historicals'!$C$363:$C$391,0),1) -> 6.083004 | P35: =INDEX('NG Sector Price Historicals'!$K:$K,MATCH('NG Calcs'!P$34,'NG Sector Price Historicals'!$S:$S,0),1)/INDEX('Henry Hub Historicals'!$B$363:$B$391,MATCH('NG Calcs'!P$34,'Henry Hub Historicals'!$C$363:$C$391,0),1) -> 6.6210046 | Q35: =INDEX('NG Sector Price Historicals'!$K:$K,MATCH('NG Calcs'!Q$34,'NG Sector Price Historicals'!$S:$S,0),1)/INDEX('Henry Hub Historicals'!$B$363:$B$391,MATCH('NG Calcs'!Q$34,'Henry Hub Historicals'!$C$363:$C$391,0),1) -> 4.3579545
A36: Commercial | B36: =INDEX('NG Sector Price Historicals'!$M:$M,MATCH('NG Calcs'!B$34,'NG Sector Price Historicals'!$S:$S,0),1)/INDEX('Henry Hub Historicals'!$B363:$B$390,MATCH('NG Calcs'!B$34,'Henry Hub Historicals'!$C$363:$C$390,0),1) -> 2.1670481 | C36: =INDEX('NG Sector Price Historicals'!$M:$M,MATCH('NG Calcs'!C$34,'NG Sector Price Historicals'!$S:$S,0),1)/INDEX('Henry Hub Historicals'!$B363:$B$390,MATCH('NG Calcs'!C$34,'Henry Hub Historicals'!$C$363:$C$390,0),1) -> 2.2275 | D36: =INDEX('NG Sector Price Historicals'!$M:$M,MATCH('NG Calcs'!D$34,'NG Sector Price Historicals'!$S:$S,0),1)/INDEX('Henry Hub Historicals'!$B363:$B$390,MATCH('NG Calcs'!D$34,'Henry Hub Historicals'!$C$363:$C$390,0),1) -> 2.9454545 | E36: =INDEX('NG Sector Price Historicals'!$M:$M,MATCH('NG Calcs'!E$34,'NG Sector Price Historicals'!$S:$S,0),1)/INDEX('Henry Hub Historicals'!$B363:$B$390,MATCH('NG Calcs'!E$34,'Henry Hub Historicals'!$C$363:$C$390,0),1) -> 2.1662198 | F36: =INDEX('NG Sector Price Historicals'!$M:$M,MATCH('NG Calcs'!F$34,'NG Sector Price Historicals'!$S:$S,0),1)/INDEX('Henry Hub Historicals'!$B363:$B$390,MATCH('NG Calcs'!F$34,'Henry Hub Historicals'!$C$363:$C$390,0),1) -> 2.0366133 | G36: =INDEX('NG Sector Price Historicals'!$M:$M,MATCH('NG Calcs'!G$34,'NG Sector Price Historicals'!$S:$S,0),1)/INDEX('Henry Hub Historicals'!$B363:$B$390,MATCH('NG Calcs'!G$34,'Henry Hub Historicals'!$C$363:$C$390,0),1) -> 3.019084 | H36: =INDEX('NG Sector Price Historicals'!$M:$M,MATCH('NG Calcs'!H$34,'NG Sector Price Historicals'!$S:$S,0),1)/INDEX('Henry Hub Historicals'!$B363:$B$390,MATCH('NG Calcs'!H$34,'Henry Hub Historicals'!$C$363:$C$390,0),1) -> 2.8888889 | I36: =INDEX('NG Sector Price Historicals'!$M:$M,MATCH('NG Calcs'!I$34,'NG Sector Price Historicals'!$S:$S,0),1)/INDEX('Henry Hub Historicals'!$B363:$B$390,MATCH('NG Calcs'!I$34,'Henry Hub Historicals'!$C$363:$C$390,0),1) -> 2.6354515 | ... K36: =INDEX('NG Sector Price Historicals'!$M:$M,MATCH('NG Calcs'!K$34,'NG Sector Price Historicals'!$S:$S,0),1)/INDEX('Henry Hub Historicals'!$B363:$B$390,MATCH('NG Calcs'!K$34,'Henry Hub Historicals'!$C$363:$C$390,0),1) -> 2.9726562 | L36: =INDEX('NG Sector Price Historicals'!$M:$M,MATCH('NG Calcs'!L$34,'NG Sector Price Historicals'!$S:$S,0),1)/INDEX('Henry Hub Historicals'!$B$363:$B$391,MATCH('NG Calcs'!L$34,'Henry Hub Historicals'!$C$363:$C$391,0),1) -> 3.6847291 | M36: =INDEX('NG Sector Price Historicals'!$M:$M,MATCH('NG Calcs'!M$34,'NG Sector Price Historicals'!$S:$S,0),1)/INDEX('Henry Hub Historicals'!$B$363:$B$391,MATCH('NG Calcs'!M$34,'Henry Hub Historicals'!$C$363:$C$391,0),1) -> 2.2596401 | N36: =INDEX('NG Sector Price Historicals'!$M:$M,MATCH('NG Calcs'!N$34,'NG Sector Price Historicals'!$S:$S,0),1)/INDEX('Henry Hub Historicals'!$B$363:$B$391,MATCH('NG Calcs'!N$34,'Henry Hub Historicals'!$C$363:$C$391,0),1) -> 1.7550388 | O36: =INDEX('NG Sector Price Historicals'!$M:$M,MATCH('NG Calcs'!O$34,'NG Sector Price Historicals'!$S:$S,0),1)/INDEX('Henry Hub Historicals'!$B$363:$B$391,MATCH('NG Calcs'!O$34,'Henry Hub Historicals'!$C$363:$C$391,0),1) -> 4.3754941 | P36: =INDEX('NG Sector Price Historicals'!$M:$M,MATCH('NG Calcs'!P$34,'NG Sector Price Historicals'!$S:$S,0),1)/INDEX('Henry Hub Historicals'!$B$363:$B$391,MATCH('NG Calcs'!P$34,'Henry Hub Historicals'!$C$363:$C$391,0),1) -> 4.5981735 | Q36: =INDEX('NG Sector Price Historicals'!$M:$M,MATCH('NG Calcs'!Q$34,'NG Sector Price Historicals'!$S:$S,0),1)/INDEX('Henry Hub Historicals'!$B$363:$B$391,MATCH('NG Calcs'!Q$34,'Henry Hub Historicals'!$C$363:$C$391,0),1) -> 3.1164773
A37: Industry | B37: =INDEX('NG Sector Price Historicals'!$O:$O,MATCH('NG Calcs'!B$34,'NG Sector Price Historicals'!$S:$S,0),1)/INDEX('Henry Hub Historicals'!$B$363:$B$390,MATCH('NG Calcs'!B$34,'Henry Hub Historicals'!$C$363:$C$390,0),1) -> 1.2562929 | C37: =INDEX('NG Sector Price Historicals'!$O:$O,MATCH('NG Calcs'!C$34,'NG Sector Price Historicals'!$S:$S,0),1)/INDEX('Henry Hub Historicals'!$B$363:$B$390,MATCH('NG Calcs'!C$34,'Henry Hub Historicals'!$C$363:$C$390,0),1) -> 1.2825 | D37: =INDEX('NG Sector Price Historicals'!$O:$O,MATCH('NG Calcs'!D$34,'NG Sector Price Historicals'!$S:$S,0),1)/INDEX('Henry Hub Historicals'!$B$363:$B$390,MATCH('NG Calcs'!D$34,'Henry Hub Historicals'!$C$363:$C$390,0),1) -> 1.4109091 | E37: =INDEX('NG Sector Price Historicals'!$O:$O,MATCH('NG Calcs'!E$34,'NG Sector Price Historicals'!$S:$S,0),1)/INDEX('Henry Hub Historicals'!$B$363:$B$390,MATCH('NG Calcs'!E$34,'Henry Hub Historicals'!$C$363:$C$390,0),1) -> 1.2439678 | F37: =INDEX('NG Sector Price Historicals'!$O:$O,MATCH('NG Calcs'!F$34,'NG Sector Price Historicals'!$S:$S,0),1)/INDEX('Henry Hub Historicals'!$B$363:$B$390,MATCH('NG Calcs'!F$34,'Henry Hub Historicals'!$C$363:$C$390,0),1) -> 1.2860412 | G37: =INDEX('NG Sector Price Historicals'!$O:$O,MATCH('NG Calcs'!G$34,'NG Sector Price Historicals'!$S:$S,0),1)/INDEX('Henry Hub Historicals'!$B$363:$B$390,MATCH('NG Calcs'!G$34,'Henry Hub Historicals'!$C$363:$C$390,0),1) -> 1.5 | H37: =INDEX('NG Sector Price Historicals'!$O:$O,MATCH('NG Calcs'!H$34,'NG Sector Price Historicals'!$S:$S,0),1)/INDEX('Henry Hub Historicals'!$B$363:$B$390,MATCH('NG Calcs'!H$34,'Henry Hub Historicals'!$C$363:$C$390,0),1) -> 1.3928571 | I37: =INDEX('NG Sector Price Historicals'!$O:$O,MATCH('NG Calcs'!I$34,'NG Sector Price Historicals'!$S:$S,0),1)/INDEX('Henry Hub Historicals'!$B$363:$B$390,MATCH('NG Calcs'!I$34,'Henry Hub Historicals'!$C$363:$C$390,0),1) -> 1.3645485 | ... K37: =INDEX('NG Sector Price Historicals'!$O:$O,MATCH('NG Calcs'!K$34,'NG Sector Price Historicals'!$S:$S,0),1)/INDEX('Henry Hub Historicals'!$B$363:$B$390,MATCH('NG Calcs'!K$34,'Henry Hub Historicals'!$C$363:$C$390,0),1) -> 1.5234375 | L37: =INDEX('NG Sector Price Historicals'!$O:$O,MATCH('NG Calcs'!L$34,'NG Sector Price Historicals'!$S:$S,0),1)/INDEX('Henry Hub Historicals'!$B$363:$B$391,MATCH('NG Calcs'!L$34,'Henry Hub Historicals'!$C$363:$C$391,0),1) -> 1.635468 | M37: =INDEX('NG Sector Price Historicals'!$O:$O,MATCH('NG Calcs'!M$34,'NG Sector Price Historicals'!$S:$S,0),1)/INDEX('Henry Hub Historicals'!$B$363:$B$391,MATCH('NG Calcs'!M$34,'Henry Hub Historicals'!$C$363:$C$391,0),1) -> 1.3984576 | N37: =INDEX('NG Sector Price Historicals'!$O:$O,MATCH('NG Calcs'!N$34,'NG Sector Price Historicals'!$S:$S,0),1)/INDEX('Henry Hub Historicals'!$B$363:$B$391,MATCH('NG Calcs'!N$34,'Henry Hub Historicals'!$C$363:$C$391,0),1) -> 1.1922481 | O37: =INDEX('NG Sector Price Historicals'!$O:$O,MATCH('NG Calcs'!O$34,'NG Sector Price Historicals'!$S:$S,0),1)/INDEX('Henry Hub Historicals'!$B$363:$B$391,MATCH('NG Calcs'!O$34,'Henry Hub Historicals'!$C$363:$C$391,0),1) -> 1.7905138 | P37: =INDEX('NG Sector Price Historicals'!$O:$O,MATCH('NG Calcs'!P$34,'NG Sector Price Historicals'!$S:$S,0),1)/INDEX('Henry Hub Historicals'!$B$363:$B$391,MATCH('NG Calcs'!P$34,'Henry Hub Historicals'!$C$363:$C$391,0),1) -> 1.8584475 | Q37: =INDEX('NG Sector Price Historicals'!$O:$O,MATCH('NG Calcs'!Q$34,'NG Sector Price Historicals'!$S:$S,0),1)/INDEX('Henry Hub Historicals'!$B$363:$B$391,MATCH('NG Calcs'!Q$34,'Henry Hub Historicals'!$C$363:$C$391,0),1) -> 1.4857955
A38: Electricity | B38: =INDEX('NG Sector Price Historicals'!$R:$R,MATCH('NG Calcs'!B$34,'NG Sector Price Historicals'!$S:$S,0),1)/INDEX('Henry Hub Historicals'!$B$363:$B$390,MATCH('NG Calcs'!B$34,'Henry Hub Historicals'!$C$363:$C$390,0),1) -> 1.2059497 | C38: =INDEX('NG Sector Price Historicals'!$R:$R,MATCH('NG Calcs'!C$34,'NG Sector Price Historicals'!$S:$S,0),1)/INDEX('Henry Hub Historicals'!$B$363:$B$390,MATCH('NG Calcs'!C$34,'Henry Hub Historicals'!$C$363:$C$390,0),1) -> 1.2225 | D38: =INDEX('NG Sector Price Historicals'!$R:$R,MATCH('NG Calcs'!D$34,'NG Sector Price Historicals'!$S:$S,0),1)/INDEX('Henry Hub Historicals'!$B$363:$B$390,MATCH('NG Calcs'!D$34,'Henry Hub Historicals'!$C$363:$C$390,0),1) -> 1.2872727 | E38: =INDEX('NG Sector Price Historicals'!$R:$R,MATCH('NG Calcs'!E$34,'NG Sector Price Historicals'!$S:$S,0),1)/INDEX('Henry Hub Historicals'!$B$363:$B$390,MATCH('NG Calcs'!E$34,'Henry Hub Historicals'!$C$363:$C$390,0),1) -> 1.2037534 | F38: =INDEX('NG Sector Price Historicals'!$R:$R,MATCH('NG Calcs'!F$34,'NG Sector Price Historicals'!$S:$S,0),1)/INDEX('Henry Hub Historicals'!$B$363:$B$390,MATCH('NG Calcs'!F$34,'Henry Hub Historicals'!$C$363:$C$390,0),1) -> 1.187643 | G38: =INDEX('NG Sector Price Historicals'!$R:$R,MATCH('NG Calcs'!G$34,'NG Sector Price Historicals'!$S:$S,0),1)/INDEX('Henry Hub Historicals'!$B$363:$B$390,MATCH('NG Calcs'!G$34,'Henry Hub Historicals'!$C$363:$C$390,0),1) -> 1.2900763 | H38: =INDEX('NG Sector Price Historicals'!$R:$R,MATCH('NG Calcs'!H$34,'NG Sector Price Historicals'!$S:$S,0),1)/INDEX('Henry Hub Historicals'!$B$363:$B$390,MATCH('NG Calcs'!H$34,'Henry Hub Historicals'!$C$363:$C$390,0),1) -> 1.1865079 | I38: =INDEX('NG Sector Price Historicals'!$R:$R,MATCH('NG Calcs'!I$34,'NG Sector Price Historicals'!$S:$S,0),1)/INDEX('Henry Hub Historicals'!$B$363:$B$390,MATCH('NG Calcs'!I$34,'Henry Hub Historicals'!$C$363:$C$390,0),1) -> 1.173913 | ... K38: =INDEX('NG Sector Price Historicals'!$R:$R,MATCH('NG Calcs'!K$34,'NG Sector Price Historicals'!$S:$S,0),1)/INDEX('Henry Hub Historicals'!$B$363:$B$390,MATCH('NG Calcs'!K$34,'Henry Hub Historicals'!$C$363:$C$390,0),1) -> 1.1679688 | L38: =INDEX('NG Sector Price Historicals'!$R:$R,MATCH('NG Calcs'!L$34,'NG Sector Price Historicals'!$S:$S,0),1)/INDEX('Henry Hub Historicals'!$B$363:$B$391,MATCH('NG Calcs'!L$34,'Henry Hub Historicals'!$C$363:$C$391,0),1) -> 1.226601 | M38: =INDEX('NG Sector Price Historicals'!$R:$R,MATCH('NG Calcs'!M$34,'NG Sector Price Historicals'!$S:$S,0),1)/INDEX('Henry Hub Historicals'!$B$363:$B$391,MATCH('NG Calcs'!M$34,'Henry Hub Historicals'!$C$363:$C$391,0),1) -> 1.3958869 | N38: =INDEX('NG Sector Price Historicals'!$R:$R,MATCH('NG Calcs'!N$34,'NG Sector Price Historicals'!$S:$S,0),1)/INDEX('Henry Hub Historicals'!$B$363:$B$391,MATCH('NG Calcs'!N$34,'Henry Hub Historicals'!$C$363:$C$391,0),1) -> 1.1643411 | O38: =INDEX('NG Sector Price Historicals'!$R:$R,MATCH('NG Calcs'!O$34,'NG Sector Price Historicals'!$S:$S,0),1)/INDEX('Henry Hub Historicals'!$B$363:$B$391,MATCH('NG Calcs'!O$34,'Henry Hub Historicals'!$C$363:$C$391,0),1) -> 1.3833992 | P38: =INDEX('NG Sector Price Historicals'!$R:$R,MATCH('NG Calcs'!P$34,'NG Sector Price Historicals'!$S:$S,0),1)/INDEX('Henry Hub Historicals'!$B$363:$B$391,MATCH('NG Calcs'!P$34,'Henry Hub Historicals'!$C$363:$C$391,0),1) -> 1.3105023 | Q38: =INDEX('NG Sector Price Historicals'!$R:$R,MATCH('NG Calcs'!Q$34,'NG Sector Price Historicals'!$S:$S,0),1)/INDEX('Henry Hub Historicals'!$B$363:$B$391,MATCH('NG Calcs'!Q$34,'Henry Hub Historicals'!$C$363:$C$391,0),1) -> 1.1420455
