Workbook
Name Fraction_coal: About!$C$53
Name Fraction_coal: About!$C$53
Name gal_per_barrel: #REF!
Name Percent_rural: About!$A$75
Name Percent_rural: About!$A$75
Name Percent_urban: About!$A$74
Name Percent_urban: About!$A$74
Name quadrillion: About!$B$77
Name quadrillion: About!$B$77
Name Table4: #REF!
Name Table4_1: #REF!
Name Table4_1_22: #REF!
Name Table4_22: #REF!
Name Table4_A: #REF!
Name Table4_A_22: #REF!
Name Table5: #REF!
Name Table5_1: #REF!
Name Table5_1_22: #REF!
Name Table5_22: #REF!
Name Table5_A: #REF!
Name Table5_A_22: #REF!

Sheet About
A1: BCEU BAU Components Energy Use
A3: Sources: | B3: Residential
B4: U.S. Energy Information Administration
B5: 2026
B6: Annual Energy Outlook 2026
B7: Alternative electricity and transportation: Table 4
B8: https://www.eia.gov/outlooks/aeo/tables_side_xls.php
B11: Commercial
B12: U.S. Energy Information Administration
B13: 2026
B14: Annual Energy Outlook 2026
B15: Alternative electricity and transportation: Table 5
B16: https://www.eia.gov/outlooks/aeo/tables_side_xls.php
B19: Urban vs. Rural Residential Households
B20: Energy Information Administration
B21: 2020
B22: Residential Energy Consumption Survey (RECS)
B23: https://www.eia.gov/consumption/residential/data/2020/?src=%E2%80%B9%20Consumption%20%20%20%20%20%20Residential%20Energy%20Consumption%20Survey%20(RECS)-f1
B24: https://www.eia.gov/consumption/residential/data/2020/hc/xls/HC%202.1.xlsx
B25: Table HC2.1
B27: Historic Data Center Demand
B28: EPRI
B29: 2026
B30: Powering Intelligence 2026
B31: https://powering-intelligence.epri.com/
B32: U.S. National data download
A34: Notes:
A36: Notes on Component Categorization
A37: Water heaters are categorized as appliances, not as part of the "heating"
A38: component. The "heating" component refers to heating of air and is affected by
A39: the building envelope, whereas appliances are not affected by envelope.
A41: The two plug load categories ("televisions and related equipment" and
A42: "computers and related equipment" in Table 4, "office equipment (PC)" and
A43: office equipment (non-PC)" in Table 5) are assigned to the
A44: "other component" category, not to appliances.
A46: Notes on Coal
A47: The AEO tables do not include a breakdown of coal or where it is used.
A48: Table 5 (commercial buildings), footnote 5 indicates that "other fuels" includes
... A50: Accordingly, we make the following assumptions based on comparing emissions
B51: Coal is only used in commercial buildings.
...

Sheet Source Data>

Sheet RECS HC2.1
A1: Preliminary data release date: March 2022
A2: Table HC2.1 Structural and geographic characteristics of U.S. homes, by housing unit type, 2020
B3: Number of housing units (million)
C4: Housing unit type
B5: Total U.S.a | C5: Single-family detached | D5: Single-family attached | E5: Apartments (2–4 unit building) | F5: Apartments (5 or more unit building) | G5: Mobile home
A6: All homes | B6: 123.53 | C6: 77.07 | D6: 7.45 | E6: 9.34 | F6: 22.84 | G6: 6.83
A7: Census region and division
A8: Northeast | B8: 21.92 | C8: 11.23 | D8: 1.95 | E8: 3.15 | F8: 5.1 | G8: 0.5
A9: New England | B9: 5.88 | C9: 3.34 | D9: 0.3 | E9: 0.99 | F9: 1.1 | G9: 0.14
A10: Middle Atlantic | B10: 16.04 | C10: 7.89 | D10: 1.65 | E10: 2.15 | F10: 3.99 | G10: 0.36
A11: Midwest | B11: 27.04 | C11: 18.58 | D11: 1.33 | E11: 1.95 | F11: 4.2 | G11: 0.97
A12: East North Central | B12: 18.55 | C12: 12.59 | D12: 0.91 | E12: 1.49 | F12: 2.94 | G12: 0.63
A13: West North Central | B13: 8.5 | C13: 5.99 | D13: 0.43 | E13: 0.47 | F13: 1.26 | G13: 0.35
A14: South | B14: 46.84 | C14: 30.29 | D14: 2.48 | E14: 2.36 | F14: 7.83 | G14: 3.89
A15: South Atlantic | B15: 24.84 | C15: 15.25 | D15: 1.92 | E15: 1.17 | F15: 4.51 | G15: 2
A16: East South Central | B16: 7.38 | C16: 5.17 | D16: 0.19 | E16: 0.41 | F16: 0.84 | G16: 0.77
A17: West South Central | B17: 14.62 | C17: 9.87 | D17: 0.36 | E17: 0.78 | F17: 2.48 | G17: 1.12
A18: West | B18: 27.72 | C18: 16.97 | D18: 1.69 | E18: 1.89 | F18: 5.7 | G18: 1.47
A19: Mountain | B19: 9.22 | C19: 6.06 | D19: 0.5 | E19: 0.52 | F19: 1.47 | G19: 0.67
... A22: Pacific | B22: 18.51 | C22: 10.91 | D22: 1.19 | E22: 1.36 | F22: 4.24 | G22: 0.8
A23: Census urban-rural classificationb
A24: Urban | B24: 100.44 | C24: 58.8 | D24: 7.04 | E24: 9.02 | F24: 22.27 | G24: 3.31
A25: Urbanized area | B25: 89.24 | C25: 50.99 | D25: 6.57 | E25: 7.95 | F25: 21.2 | G25: 2.53
A26: Urban cluster | B26: 11.2 | C26: 7.82 | D26: 0.47 | E26: 1.07 | F26: 1.07 | G26: 0.77
A27: Rural | B27: 23.09 | C27: 18.27 | D27: 0.41 | E27: 0.32 | F27: 0.57 | G27: 3.52
A28: Climate regionc
A29: Very cold/Cold | B29: 42.5 | C29: 28.04 | D29: 2.43 | E29: 3.78 | F29: 6.74 | G29: 1.52
A30: Mixed-humid | B30: 36.79 | C30: 21.89 | D30: 2.8 | E30: 2.72 | F30: 7.03 | G30: 2.35
A31: Mixed-dry/Hot-dry | B31: 15.06 | C31: 9.07 | D31: 0.9 | E31: 1.12 | F31: 3.12 | G31: 0.83
A32: Hot-humid | B32: 22.31 | C32: 13.98 | D32: 0.92 | E32: 1.25 | F32: 4.37 | G32: 1.8
A33: Marine | B33: 6.87 | C33: 4.09 | D33: 0.4 | E33: 0.48 | F33: 1.57 | G33: 0.34
A34: Year of construction
A35: Before 1950 | B35: 20.26 | C35: 13.58 | D35: 1.14 | E35: 2.36 | F35: 3.08 | G35: 0.09
A36: 1950 to 1959 | B36: 12.48 | C36: 9.9 | D36: 0.4 | E36: 0.77 | F36: 1.25 | G36: 0.16
A37: 1960 to 1969 | B37: 12.76 | C37: 8.23 | D37: 0.63 | E37: 1.12 | F37: 2.41 | G37: 0.37
A38: 1970 to 1979 | B38: 18.34 | C38: 10.46 | D38: 0.97 | E38: 1.56 | F38: 4.01 | G38: 1.34
A39: 1980 to 1989 | B39: 16.3 | C39: 8.67 | D39: 1.26 | E39: 1.43 | F39: 3.6 | G39: 1.33
A40: 1990 to 1999 | B40: 17.16 | C40: 10.65 | D40: 1.08 | E40: 0.95 | F40: 2.55 | G40: 1.92
A41: 2000 to 2009 | B41: 16.16 | C41: 9.98 | D41: 1.31 | E41: 0.72 | F41: 3.17 | G41: 0.98
A42: 2010 to 2015 | B42: 5.53 | C42: 3.05 | D42: 0.37 | E42: 0.26 | F42: 1.52 | G42: 0.32
...

Sheet Table_4._Residential_Sector_Key
A1: Table 4. Residential Sector Key Indicators and Consumption
A2: https://www.eia.gov/outlooks/aeo/data/browser/#/?id=4-AEO2025&cases=highZTC&sourcekey=0
A3: Tue Dec 02 2025 13:13:01 GMT-0800 (Pacific Standard Time)
A4: Source: U.S. Energy Information Administration
B5: full name | C5: api key | D5: units | E5: 2023 | F5: 2024 | G5: 2025 | H5: 2026 | I5: 2027 | J5: 2028 | K5: 2029 | L5: 2030 | M5: 2031 | N5: 2032 | O5: 2033 | P5: 2034 | Q5: 2035 | R5: 2036 | S5: 2037 | T5: 2038 | U5: 2039 | V5: 2040 | W5: 2041 | X5: 2042 | Y5: 2043 | Z5: 2044 | AA5: 2045 | AB5: 2046 | AC5: 2047 | AD5: 2048 | AE5: 2049 | AF5: 2050 | AG5: Growth (2024-2050)
A6: Key Indicators
A7: Households (millions)
A8: Single-Family | B8: Residential: Key Indicators: Households: Single-Family: High Zero-Carbon Technology Cost | C8: AEO.2025.HIGHZTC.KEI_HHD_RESD_SFR_NA_NA_USA_MILL.A | D8: millions | F8: 88.609744 | G8: 89.620168 | H8: 90.63056 | I8: 91.639144 | J8: 92.631344 | K8: 93.625568 | L8: 94.61288 | M8: 95.59792 | N8: 96.579056 | O8: 97.53976 | P8: 98.471496 | Q8: 99.397144 | R8: 100.30808 | S8: 101.19444 | T8: 102.05506 | U8: 102.88178 | V8: 103.68032 | W8: 104.44803 | X8: 105.19444 | Y8: 105.90901 | Z8: 106.60332 | AA8: 107.29699 | AB8: 107.98818 | AC8: 108.67842 | AD8: 109.36732 | AE8: 110.05501 | AF8: 110.7399 | AG8: 0.009
A9: Multifamily | B9: Residential: Key Indicators: Households: Multifamily: High Zero-Carbon Technology Cost | C9: AEO.2025.HIGHZTC.KEI_HHD_RESD_MFR_NA_NA_USA_MILL.A | D9: millions | F9: 34.017912 | G9: 34.38036 | H9: 34.797956 | I9: 35.233648 | J9: 35.702292 | K9: 36.208236 | L9: 36.726044 | M9: 37.24678 | N9: 37.753312 | O9: 38.226856 | P9: 38.666984 | Q9: 39.093076 | R9: 39.503836 | S9: 39.883568 | T9: 40.239072 | U9: 40.573248 | V9: 40.890328 | W9: 41.185544 | X9: 41.464128 | Y9: 41.734528 | Z9: 42.00598 | AA9: 42.277656 | AB9: 42.549808 | AC9: 42.820992 | AD9: 43.09248 | AE9: 43.364628 | AF9: 43.636816 | AG9: 0.01
A10: Mobile Homes | B10: Residential: Key Indicators: Households: Mobile Homes: High Zero-Carbon Technology Cost | C10: AEO.2025.HIGHZTC.KEI_HHD_RESD_MBH_NA_NA_USA_MILL.A | D10: millions | F10: 6.755902 | G10: 6.748634 | H10: 6.770403 | I10: 6.792666 | J10: 6.804218 | K10: 6.813859 | L10: 6.818653 | M10: 6.824849 | N10: 6.833779 | O10: 6.843395 | P10: 6.850643 | Q10: 6.855789 | R10: 6.86137 | S10: 6.866089 | T10: 6.869494 | U10: 6.871957 | V10: 6.87686 | W10: 6.883047 | X10: 6.889117 | Y10: 6.89479 | Z10: 6.900812 | AA10: 6.907353 | AB10: 6.912851 | AC10: 6.918932 | AD10: 6.924763 | AE10: 6.931044 | AF10: 6.936647 | AG10: 0.001
A11: Total | B11: Residential: Key Indicators: Households: Total: High Zero-Carbon Technology Cost | C11: AEO.2025.HIGHZTC.KEI_HHD_RESD_TEN_NA_NA_USA_MILL.A | D11: millions | F11: 129.38356 | G11: 130.74916 | H11: 132.19892 | I11: 133.66546 | J11: 135.13785 | K11: 136.64766 | L11: 138.15758 | M11: 139.66955 | N11: 141.16615 | O11: 142.61001 | P11: 143.98912 | Q11: 145.34601 | R11: 146.67328 | S11: 147.9441 | T11: 149.16362 | U11: 150.32698 | V11: 151.44751 | W11: 152.51662 | X11: 153.54769 | Y11: 154.53833 | Z11: 155.51011 | AA11: 156.482 | AB11: 157.45084 | AC11: 158.41834 | AD11: 159.38456 | AE11: 160.35068 | AF11: 161.31337 | AG11: 0.009
A12: Average House Square Footage | B12: Residential: Key Indicators: Average House Square Footage: High Zero-Carbon Technology Cost | C12: AEO.2025.HIGHZTC.KEI_HHD_RESD_NA_NA_NA_USA_SQFT.A | D12: sq ft | F12: 1643.9569 | G12: 1650.5161 | H12: 1656.462 | I12: 1662.1603 | J12: 1667.5287 | K12: 1672.5446 | L12: 1677.3794 | M12: 1682.076 | N12: 1686.7471 | O12: 1691.495 | P12: 1696.3218 | Q12: 1701.146 | R12: 1705.9552 | S12: 1710.8412 | T12: 1715.7644 | U12: 1720.6978 | V12: 1725.6134 | W12: 1730.5463 | X12: 1735.4882 | Y12: 1740.3724 | Z12: 1745.155 | AA12: 1749.8751 | AB12: 1754.5343 | AC12: 1759.1407 | AD12: 1763.6879 | AE12: 1768.1737 | AF12: 1772.6058 | AG12: 0.003
A13: Energy Intensity
A14: (MMBtu per household)
A15: Gross End-use Consumption | B15: Residential: Household Energy Intensity: Gross End-use Consumption: High Zero-Carbon Technology Cost | C15: AEO.2025.HIGHZTC.INY_HHD_RESD_DELE_NA_NA_USA_MILLBTUPHOSD.A | D15: MMBtu/household | F15: 85.992244 | G15: 87.9766 | H15: 87.58989 | I15: 87.167932 | J15: 86.534193 | K15: 85.477507 | L15: 84.242287 | M15: 82.878242 | N15: 81.472909 | O15: 80.23763 | P15: 79.124025 | Q15: 78.223224 | R15: 77.510909 | S15: 76.934631 | T15: 76.394609 | U15: 75.9338 | V15: 75.490184 | W15: 75.046198 | X15: 74.63335 | Y15: 74.262238 | Z15: 73.916539 | AA15: 73.581211 | AB15: 73.25364 | AC15: 72.937099 | AD15: 72.637647 | AE15: 72.361427 | AF15: 72.093053 | AG15: -0.007
A16: Delivered Energy Consumption | B16: Residential: Household Energy Intensity: Delivered Energy Consumption: High Zero-Carbon Technology Cost | C16: AEO.2025.HIGHZTC.INY_HHD_RESD_TEN_NA_NA_USA_MILLBTUPHOSD.A | D16: MMBtu/household | F16: 84.632913 | G16: 86.447232 | H16: 85.892414 | I16: 85.317887 | J16: 84.531319 | K16: 83.322996 | L16: 81.928291 | M16: 80.396377 | N16: 78.827237 | O16: 77.431217 | P16: 76.162388 | Q16: 75.148382 | R16: 74.320522 | S16: 73.627571 | T16: 72.966007 | U16: 72.382382 | V16: 71.813781 | W16: 71.24327 | X16: 70.700708 | Y16: 70.198181 | Z16: 69.719191 | AA16: 69.247444 | AB16: 68.781064 | AC16: 68.323618 | AD16: 67.880286 | AE16: 67.458633 | AF16: 67.043821 | AG16: -0.009
A17: (thousand Btu per square foot)
A18: Gross End-use Consumption | B18: Residential: Energy Intensity per Square Foot: Gross End-use Consumption: High Zero-Carbon Technology Cost | C18: AEO.2025.HIGHZTC.INY_HHD_RESD_DELE_NA_NA_USA_THBTUPSQFT.A | D18: thousand Btu/sq ft | F18: 52.308089 | G18: 53.302479 | H18: 52.877692 | I18: 52.442555 | J18: 51.893676 | K18: 51.106266 | L18: 50.22256 | M18: 49.2714 | N18: 48.301794 | O18: 47.435925 | P18: 46.644467 | Q18: 45.982663 | R18: 45.435489 | S18: 44.968891 | T18: 44.525116 | U18: 44.129656 | V18: 43.74687 | W18: 43.365612 | X18: 43.00424 | Y18: 42.670314 | Z18: 42.355285 | AA18: 42.049407 | AB18: 41.751045 | AC18: 41.461776 | AD18: 41.185092 | AE18: 40.924388 | AF18: 40.670662 | AG18: -0.01
A19: Delivered Energy Consumption | B19: Residential: Energy Intensity per Square Foot: Delivered Energy Consumption: High Zero-Carbon Technology Cost | C19: AEO.2025.HIGHZTC.INY_HHD_RESD_TEN_NA_NA_USA_THBTUPSQFT.A | D19: thousand Btu/sq ft | F19: 51.481224 | G19: 52.375879 | H19: 51.852933 | I19: 51.329518 | J19: 50.692573 | K19: 49.818103 | L19: 48.843029 | M19: 47.795923 | N19: 46.733288 | O19: 45.776794 | P19: 44.89855 | Q19: 44.175151 | R19: 43.565342 | S19: 43.035889 | T19: 42.526822 | U19: 42.065715 | V19: 41.616379 | W19: 41.168082 | X19: 40.738225 | Y19: 40.335149 | Z19: 39.950142 | AA19: 39.572792 | AB19: 39.201892 | AC19: 38.839199 | AD19: 38.487698 | AE19: 38.151587 | AF19: 37.822182 | AG19: -0.012
A20: Energy Consumption by Fuel
A21: Electricity
A22: Space Heating | B22: Residential: Electricity: Space Heating: High Zero-Carbon Technology Cost | C22: AEO.2025.HIGHZTC.CNSM_HHD_RESD_SPH_ELC_NA_USA_QBTU.A | D22: quads | F22: 0.528061 | G22: 0.582562 | H22: 0.585545 | I22: 0.589188 | J22: 0.589904 | K22: 0.586412 | L22: 0.580551 | M22: 0.573595 | N22: 0.566739 | O22: 0.560726 | P22: 0.554572 | Q22: 0.550309 | R22: 0.547657 | S22: 0.545295 | T22: 0.542041 | U22: 0.538591 | V22: 0.534952 | W22: 0.530828 | X22: 0.526828 | Y22: 0.522867 | Z22: 0.518328 | AA22: 0.513525 | AB22: 0.508348 | AC22: 0.502928 | AD22: 0.497403 | AE22: 0.492208 | AF22: 0.4868 | AG22: -0.003
A23: Space Cooling | B23: Residential: Electricity: Space Cooling: High Zero-Carbon Technology Cost | C23: AEO.2025.HIGHZTC.CNSM_NA_RESD_SPC_ELC_NA_USA_QBTU.A | D23: quads | F23: 0.997081 | G23: 0.952473 | H23: 0.971354 | I23: 0.98971 | J23: 1.002009 | K23: 1.00703 | L23: 1.009506 | M23: 1.010393 | N23: 1.012497 | O23: 1.019494 | P23: 1.028533 | Q23: 1.041697 | R23: 1.058786 | S23: 1.078113 | T23: 1.096537 | U23: 1.115933 | V23: 1.135576 | W23: 1.155665 | X23: 1.175584 | Y23: 1.195868 | Z23: 1.215889 | AA23: 1.235434 | AB23: 1.254577 | AC23: 1.273539 | AD23: 1.292448 | AE23: 1.311621 | AF23: 1.330636 | AG23: 0.011
A24: Water Heating | B24: Residential: Electricity: Water Heating: High Zero-Carbon Technology Cost | C24: AEO.2025.HIGHZTC.CNSM_NA_RESD_WTHT_ELC_NA_USA_QBTU.A | D24: quads | F24: 0.472693 | G24: 0.459259 | H24: 0.449699 | I24: 0.440442 | J24: 0.428544 | K24: 0.408148 | L24: 0.384946 | M24: 0.360722 | N24: 0.33842 | O24: 0.318282 | P24: 0.300561 | Q24: 0.285426 | R24: 0.272802 | S24: 0.262211 | T24: 0.253048 | U24: 0.245594 | V24: 0.239892 | W24: 0.23575 | X24: 0.233312 | Y24: 0.23256 | Z24: 0.231527 | AA24: 0.230325 | AB24: 0.228973 | AC24: 0.227549 | AD24: 0.226177 | AE24: 0.224938 | AF24: 0.223821 | AG24: -0.028
A25: Refrigeration | B25: Residential: Electricity: Refrigeration: High Zero-Carbon Technology Cost | C25: AEO.2025.HIGHZTC.CNSM_NA_RESD_REFR_ELC_NA_USA_QBTU.A | D25: quads | F25: 0.351479 | G25: 0.349737 | H25: 0.34897 | I25: 0.348118 | J25: 0.347168 | K25: 0.346545 | L25: 0.343717 | M25: 0.341147 | N25: 0.338816 | O25: 0.336635 | P25: 0.334581 | Q25: 0.332782 | R25: 0.331396 | S25: 0.330414 | T25: 0.32985 | U25: 0.329701 | V25: 0.329972 | W25: 0.33064 | X25: 0.331706 | Y25: 0.333167 | Z25: 0.335038 | AA25: 0.337389 | AB25: 0.340228 | AC25: 0.343544 | AD25: 0.346847 | AE25: 0.350126 | AF25: 0.353358 | AG25: 0
A26: Cooking | B26: Residential: Electricity: Cooking: High Zero-Carbon Technology Cost | C26: AEO.2025.HIGHZTC.CNSM_NA_RESD_CGR_ELC_NA_USA_QBTU.A | D26: quads | F26: 0.067364 | G26: 0.067851 | H26: 0.068571 | I26: 0.069303 | J26: 0.07004 | K26: 0.070797 | L26: 0.071554 | M26: 0.072311 | N26: 0.07306 | O26: 0.073778 | P26: 0.074459 | Q26: 0.075123 | R26: 0.075764 | S26: 0.076366 | T26: 0.076926 | U26: 0.077443 | V26: 0.077925 | W26: 0.078369 | X26: 0.078785 | Y26: 0.079176 | Z26: 0.079553 | AA26: 0.079923 | AB26: 0.080284 | AC26: 0.080637 | AD26: 0.080982 | AE26: 0.081316 | AF26: 0.081638 | AG26: 0.007
A27: Clothes Dryers | B27: Residential: Electricity: Clothes Dryers: High Zero-Carbon Technology Cost | C27: AEO.2025.HIGHZTC.CNSM_NA_RESD_CDR_ELC_NA_USA_QBTU.A | D27: quads | F27: 0.191812 | G27: 0.193075 | H27: 0.196545 | I27: 0.200855 | J27: 0.204061 | K27: 0.20567 | L27: 0.206345 | M27: 0.206255 | N27: 0.205808 | O27: 0.205284 | P27: 0.205276 | Q27: 0.206284 | R27: 0.208278 | S27: 0.210919 | T27: 0.213722 | U27: 0.216924 | V27: 0.220611 | W27: 0.224674 | X27: 0.228576 | Y27: 0.232386 | Z27: 0.235967 | AA27: 0.239332 | AB27: 0.242476 | AC27: 0.245414 | AD27: 0.248235 | AE27: 0.250977 | AF27: 0.253559 | AG27: 0.011
A28: Freezers | B28: Residential: Electricity: Freezers: High Zero-Carbon Technology Cost | C28: AEO.2025.HIGHZTC.CNSM_NA_RESD_FRZ_ELC_NA_USA_QBTU.A | D28: quads | F28: 0.079548 | G28: 0.079317 | H28: 0.079323 | I28: 0.079324 | J28: 0.079287 | K28: 0.079225 | L28: 0.07876 | M28: 0.078245 | N28: 0.07769 | O28: 0.077149 | P28: 0.076617 | Q28: 0.076115 | R28: 0.075638 | S28: 0.075175 | T28: 0.074736 | U28: 0.07432 | V28: 0.073932 | W28: 0.073581 | X28: 0.073268 | Y28: 0.072993 | Z28: 0.072761 | AA28: 0.072582 | AB28: 0.072468 | AC28: 0.072415 | AD28: 0.072435 | AE28: 0.072536 | AF28: 0.072717 | AG28: -0.003
A29: Lighting | B29: Residential: Electricity: Lighting: High Zero-Carbon Technology Cost | C29: AEO.2025.HIGHZTC.CNSM_NA_RESD_LGHTNG_ELC_NA_USA_QBTU.A | D29: quads | F29: 0.187371 | G29: 0.18539 | H29: 0.186964 | I29: 0.190632 | J29: 0.193727 | K29: 0.195604 | L29: 0.195166 | M29: 0.194531 | N29: 0.19432 | O29: 0.194149 | P29: 0.194404 | Q29: 0.195278 | R29: 0.196599 | S29: 0.198067 | T29: 0.199294 | U29: 0.200681 | V29: 0.198798 | W29: 0.197172 | X29: 0.195941 | Y29: 0.19514 | Z29: 0.194706 | AA29: 0.194468 | AB29: 0.194278 | AC29: 0.194106 | AD29: 0.194081 | AE29: 0.194207 | AF29: 0.194363 | AG29: 0.001
A30: Clothes Washers | B30: Residential: Electricity: Clothes Washers: High Zero-Carbon Technology Cost | C30: AEO.2025.HIGHZTC.CNSM_NA_RESD_CLW_ELC_NA_USA_QBTU.A | D30: quads | F30: 0.041807 | G30: 0.040731 | H30: 0.039766 | I30: 0.038787 | J30: 0.037633 | K30: 0.036454 | L30: 0.035086 | M30: 0.033659 | N30: 0.032143 | O30: 0.030826 | P30: 0.02971 | Q30: 0.028801 | R30: 0.028112 | S30: 0.027655 | T30: 0.027453 | U30: 0.027522 | V30: 0.02759 | W30: 0.027658 | X30: 0.027733 | Y30: 0.027815 | Z30: 0.027908 | AA30: 0.028016 | AB30: 0.028138 | AC30: 0.028273 | AD30: 0.02842 | AE30: 0.028576 | AF30: 0.028739 | AG30: -0.014
A31: Dishwashers | B31: Residential: Electricity: Dishwashers: High Zero-Carbon Technology Cost | C31: AEO.2025.HIGHZTC.CNSM_NA_RESD_DSW_ELC_NA_USA_QBTU.A | D31: quads | F31: 0.036367 | G31: 0.037219 | H31: 0.038216 | I31: 0.038546 | J31: 0.038751 | K31: 0.038915 | L31: 0.039032 | M31: 0.039101 | N31: 0.039118 | O31: 0.039202 | P31: 0.039359 | Q31: 0.039601 | R31: 0.039936 | S31: 0.040364 | T31: 0.040896 | U31: 0.041538 | V31: 0.042178 | W31: 0.042812 | X31: 0.043444 | Y31: 0.044074 | Z31: 0.044708 | AA31: 0.045349 | AB31: 0.045998 | AC31: 0.046655 | AD31: 0.047318 | AE31: 0.047988 | AF31: 0.048663 | AG31: 0.011
A32: Televisions and Related Equipment | B32: Residential: Electricity: Televisions: High Zero-Carbon Technology Cost | C32: AEO.2025.HIGHZTC.CNSM_NA_RESD_TVR_ELC_NA_USA_QBTU.A | D32: quads | F32: 0.129374 | G32: 0.126544 | H32: 0.125215 | I32: 0.124316 | J32: 0.122902 | K32: 0.120777 | L32: 0.118375 | M32: 0.115926 | N32: 0.113659 | O32: 0.11144 | P32: 0.1095 | Q32: 0.10799 | R32: 0.106861 | S32: 0.105954 | T32: 0.105066 | U32: 0.104306 | V32: 0.103691 | W32: 0.103142 | X32: 0.102677 | Y32: 0.102345 | Z32: 0.102119 | AA32: 0.102036 | AB32: 0.102082 | AC32: 0.102176 | AD32: 0.10236 | AE32: 0.102613 | AF32: 0.102926 | AG32: -0.009
A33: Computers and Related Equipment | B33: Residential: Electricity: Computers: High Zero-Carbon Technology Cost | C33: AEO.2025.HIGHZTC.CNSM_NA_RESD_CMPR_ELC_NA_USA_QBTU.A | D33: quads | F33: 0.100147 | G33: 0.098312 | H33: 0.097712 | I33: 0.097344 | J33: 0.096392 | K33: 0.094706 | L33: 0.092653 | M33: 0.090438 | N33: 0.088259 | O33: 0.086025 | P33: 0.083927 | Q33: 0.082077 | R33: 0.080451 | S33: 0.078944 | T33: 0.077403 | U33: 0.07593 | V33: 0.074545 | W33: 0.073196 | X33: 0.071926 | Y33: 0.070762 | Z33: 0.069712 | AA33: 0.068805 | AB33: 0.068054 | AC33: 0.067421 | AD33: 0.066941 | AE33: 0.066635 | AF33: 0.066465 | AG33: -0.016
... A39: Purchased Electricity at Residential Location | B39: Residential: Electricity: Purchased Electricity at Residential Location: High Zero-Carbon Technology Cost | C39: AEO.2025.HIGHZTC.CNSM_NA_RESD_PURCHELEC_ELC_NA_USA_QBTU.A | D39: quads | F39: 5.141959 | G39: 5.081856 | H39: 5.155061 | I39: 5.245214 | J39: 5.322819 | K39: 5.376949 | L39: 5.423333 | M39: 5.461133 | N39: 5.512463 | O39: 5.571132 | P39: 5.640814 | Q39: 5.72881 | R39: 5.829799 | S39: 5.937385 | T39: 6.039158 | U39: 6.141384 | V39: 6.238818 | W39: 6.331173 | X39: 6.419865 | Y39: 6.505672 | Z39: 6.584554 | AA39: 6.65771 | AB39: 6.726636 | AC39: 6.791243 | AD39: 6.851297 | AE39: 6.909533 | AF39: 6.964614 | AG39: 0.012
A40: Natural Gas
A41: Space Heating | B41: Residential: Natural Gas: Space Heating: High Zero-Carbon Technology Cost | C41: AEO.2025.HIGHZTC.CNSM_NA_RESD_SPH_NG_NA_USA_QBTU.A | D41: quads | F41: 2.777912 | G41: 3.12664 | H41: 3.141604 | I41: 3.146791 | J41: 3.143392 | K41: 3.126671 | L41: 3.103113 | M41: 3.069892 | N41: 3.026127 | O41: 2.987631 | P41: 2.946792 | Q41: 2.912199 | R41: 2.883551 | S41: 2.858295 | T41: 2.834296 | U41: 2.81154 | V41: 2.787776 | W41: 2.761015 | X41: 2.733698 | Y41: 2.706513 | Z41: 2.680865 | AA41: 2.657231 | AB41: 2.634207 | AC41: 2.611903 | AD41: 2.590528 | AE41: 2.569665 | AF41: 2.548368 | AG41: -0.003
A42: Space Cooling | B42: Residential: Natural Gas: Space Cooling: High Zero-Carbon Technology Cost | C42: AEO.2025.HIGHZTC.CNSM_NA_RESD_SPC_NG_NA_USA_QBTU.A | D42: quads | F42: 0.063499 | G42: 0.061038 | H42: 0.061464 | I42: 0.061531 | J42: 0.061383 | K42: 0.061147 | L42: 0.060918 | M42: 0.060665 | N42: 0.060395 | O42: 0.060147 | P42: 0.059927 | Q42: 0.059807 | R42: 0.059799 | S42: 0.059868 | T42: 0.059965 | U42: 0.060137 | V42: 0.060331 | W42: 0.060539 | X42: 0.060751 | Y42: 0.060975 | Z42: 0.061196 | AA42: 0.061401 | AB42: 0.061602 | AC42: 0.061793 | AD42: 0.061997 | AE42: 0.062199 | AF42: 0.062392 | AG42: -0.001
A43: Water Heating | B43: Residential: Natural Gas: Water Heating: High Zero-Carbon Technology Cost | C43: AEO.2025.HIGHZTC.CNSM_NA_RESD_WTHT_NG_NA_USA_QBTU.A | D43: quads | F43: 1.035874 | G43: 1.046498 | H43: 1.058767 | I43: 1.069351 | J43: 1.079818 | K43: 1.080751 | L43: 1.081037 | M43: 1.080496 | N43: 1.078113 | O43: 1.077774 | P43: 1.0797 | Q43: 1.084282 | R43: 1.088853 | S43: 1.093492 | T43: 1.09762 | U43: 1.101219 | V43: 1.10365 | W43: 1.104037 | X43: 1.102943 | Y43: 1.100647 | Z43: 1.097807 | AA43: 1.094437 | AB43: 1.09026 | AC43: 1.085951 | AD43: 1.081866 | AE43: 1.077826 | AF43: 1.074105 | AG43: 0.001
A44: Cooking | B44: Residential: Natural Gas: Cooking: High Zero-Carbon Technology Cost | C44: AEO.2025.HIGHZTC.CNSM_NA_RESD_CGR_NG_NA_USA_QBTU.A | D44: quads | F44: 0.077838 | G44: 0.077799 | H44: 0.077991 | I44: 0.078186 | J44: 0.078378 | K44: 0.078579 | L44: 0.078781 | M44: 0.078972 | N44: 0.079145 | O44: 0.079309 | P44: 0.079496 | Q44: 0.079723 | R44: 0.079999 | S44: 0.080326 | T44: 0.080726 | U44: 0.081166 | V44: 0.081648 | W44: 0.082162 | X44: 0.0827 | Y44: 0.083236 | Z44: 0.083776 | AA44: 0.084327 | AB44: 0.08489 | AC44: 0.085467 | AD44: 0.086059 | AE44: 0.08667 | AF44: 0.087302 | AG44: 0.004
A45: Clothes Dryers | B45: Residential: Natural Gas: Clothes Dryers: High Zero-Carbon Technology Cost | C45: AEO.2025.HIGHZTC.CNSM_NA_RESD_CDR_NG_NA_USA_QBTU.A | D45: quads | F45: 0.039583 | G45: 0.040486 | H45: 0.041405 | I45: 0.042257 | J45: 0.04311 | K45: 0.043956 | L45: 0.044797 | M45: 0.045565 | N45: 0.046229 | O45: 0.046833 | P45: 0.047464 | Q45: 0.048157 | R45: 0.04892 | S45: 0.049719 | T45: 0.050528 | U45: 0.051342 | V45: 0.052121 | W45: 0.052834 | X45: 0.053545 | Y45: 0.054265 | Z45: 0.055017 | AA45: 0.055794 | AB45: 0.056574 | AC45: 0.057377 | AD45: 0.058208 | AE45: 0.05904 | AF45: 0.059869 | AG45: 0.016
...

Sheet AEO 2025 Table 5
A1: Table 5. Commercial Sector Key Indicators and Consumption
A2: https://www.eia.gov/outlooks/aeo/data/browser/#/?id=5-AEO2025&cases=highZTC&sourcekey=0
A3: Tue Dec 02 2025 13:13:07 GMT-0800 (Pacific Standard Time)
A4: Source: U.S. Energy Information Administration
B5: full name | C5: api key | D5: units | E5: 2023 | F5: 2024 | G5: 2025 | H5: 2026 | I5: 2027 | J5: 2028 | K5: 2029 | L5: 2030 | M5: 2031 | N5: 2032 | O5: 2033 | P5: 2034 | Q5: 2035 | R5: 2036 | S5: 2037 | T5: 2038 | U5: 2039 | V5: 2040 | W5: 2041 | X5: 2042 | Y5: 2043 | Z5: 2044 | AA5: 2045 | AB5: 2046 | AC5: 2047 | AD5: 2048 | AE5: 2049 | AF5: 2050 | AG5: Growth (2024-2050)
A6: Key Indicators
A7: Total Floorspace (billion square feet)
A8: Surviving | B8: Commercial: Total Floorspace: Surviving: High Zero-Carbon Technology Cost | C8: AEO.2025.HIGHZTC.KEI_NA_COMM_NA_TFP_SURV_USA_BLNSQFT.A | D8: billion sq ft | F8: 100.6298 | G8: 101.84551 | H8: 102.98341 | I8: 104.38231 | J8: 105.94974 | K8: 107.60669 | L8: 109.2576 | M8: 110.865 | N8: 112.44348 | O8: 114.02752 | P8: 115.62702 | Q8: 117.23369 | R8: 118.833 | S8: 120.40864 | T8: 121.95262 | U8: 123.4675 | V8: 124.95824 | W8: 126.43023 | X8: 127.88881 | Y8: 129.33743 | Z8: 130.7792 | AA8: 132.21799 | AB8: 133.6573 | AC8: 135.10043 | AD8: 136.55005 | AE8: 138.00769 | AF8: 139.47395 | AG8: 0.013
A9: New Additions | B9: Commercial: Total Floorspace: New Additions: High Zero-Carbon Technology Cost | C9: AEO.2025.HIGHZTC.KEI_NA_COMM_NA_TFP_NADN_USA_BLNSQFT.A | D9: billion sq ft | F9: 2.742075 | G9: 2.676447 | H9: 2.951616 | I9: 3.136872 | J9: 3.245102 | K9: 3.258995 | L9: 3.235985 | M9: 3.227938 | N9: 3.254824 | O9: 3.292159 | P9: 3.321622 | Q9: 3.336882 | R9: 3.335924 | S9: 3.326909 | T9: 3.320311 | U9: 3.318532 | V9: 3.321972 | W9: 3.3306 | X9: 3.342516 | Y9: 3.357474 | Z9: 3.376159 | AA9: 3.398343 | AB9: 3.423773 | AC9: 3.451868 | AD9: 3.481559 | AE9: 3.51192 | AF9: 3.542278 | AG9: 0.01
A10: Total | B10: Commercial: Total Floorspace: Total: High Zero-Carbon Technology Cost | C10: AEO.2025.HIGHZTC.KEI_NA_COMM_NA_TFP_TOT_USA_BLNSQFT.A | D10: billion sq ft | F10: 103.37187 | G10: 104.52195 | H10: 105.93502 | I10: 107.51918 | J10: 109.19484 | K10: 110.86568 | L10: 112.49358 | M10: 114.09293 | N10: 115.6983 | O10: 117.31968 | P10: 118.94865 | Q10: 120.57057 | R10: 122.16892 | S10: 123.73555 | T10: 125.27293 | U10: 126.78603 | V10: 128.28021 | W10: 129.76083 | X10: 131.23132 | Y10: 132.6949 | Z10: 134.15536 | AA10: 135.61633 | AB10: 137.08107 | AC10: 138.55231 | AD10: 140.0316 | AE10: 141.51961 | AF10: 143.01623 | AG10: 0.013
A11: Energy Consumption Intensity
A12: (thousand Btu per square foot)
A13: Gross End-use Consumption | B13: Commercial: Energy Use Intensity: Gross End-use Consumption: High Zero-Carbon Technology Cost | C13: AEO.2025.HIGHZTC.INY_NA_COMM_NA_EUI_DLENCONS_USA_THBTUPSQFT.A | D13: thousand Btu/sq ft | F13: 91.297417 | G13: 93.06604 | H13: 92.122139 | I13: 91.445877 | J13: 90.480347 | K13: 89.907692 | L13: 89.112656 | M13: 88.37957 | N13: 87.622482 | O13: 86.837357 | P13: 86.167732 | Q13: 85.690338 | R13: 85.397949 | S13: 85.214699 | T13: 85.044395 | U13: 84.943207 | V13: 84.840546 | W13: 84.733612 | X13: 84.622826 | Y13: 84.529892 | Z13: 84.476494 | AA13: 84.450005 | AB13: 84.41684 | AC13: 84.421028 | AD13: 84.46035 | AE13: 84.503151 | AF13: 84.555496 | AG13: -0.003
A14: Delivered Energy Consumption | B14: Commercial: Energy Use Intensity: Delivered Energy Consumption: High Zero-Carbon Technology Cost | C14: AEO.2025.HIGHZTC.INY_NA_COMM_NA_EUI_ERL_USA_THBTUPSQFT.A | D14: thousand Btu/sq ft | F14: 89.926224 | G14: 91.548019 | H14: 90.468704 | I14: 89.751579 | J14: 88.74955 | K14: 88.113716 | L14: 87.240326 | M14: 86.402924 | N14: 85.555893 | O14: 84.661987 | P14: 83.932785 | Q14: 83.432762 | R14: 83.125374 | S14: 82.923317 | T14: 82.710251 | U14: 82.597198 | V14: 82.477486 | W14: 82.33297 | X14: 82.186722 | Y14: 82.053062 | Z14: 81.959312 | AA14: 81.891106 | AB14: 81.823502 | AC14: 81.784096 | AD14: 81.778503 | AE14: 81.779785 | AF14: 81.785347 | AG14: -0.004
A15: Energy Consumption by Fuel
A16: Electricity
A17: Space Heating | B17: Commercial: Purchased Electricity: Space Heating: High Zero-Carbon Technology Cost | C17: AEO.2025.HIGHZTC.CNSM_NA_COMM_NA_PRC_SPH_USA_QBTU.A | D17: quads | F17: 0.186541 | G17: 0.197985 | H17: 0.198076 | I17: 0.199054 | J17: 0.199048 | K17: 0.197891 | L17: 0.196351 | M17: 0.19459 | N17: 0.192773 | O17: 0.190066 | P17: 0.187679 | Q17: 0.186546 | R17: 0.185712 | S17: 0.184911 | T17: 0.183733 | U17: 0.182497 | V17: 0.181191 | W17: 0.179785 | X17: 0.178212 | Y17: 0.176566 | Z17: 0.174797 | AA17: 0.172949 | AB17: 0.171014 | AC17: 0.169022 | AD17: 0.166995 | AE17: 0.165017 | AF17: 0.163026 | AG17: -0.005
A18: Space Cooling 3/ | B18: Commercial: Purchased Electricity: Space Cooling: High Zero-Carbon Technology Cost | C18: AEO.2025.HIGHZTC.CNSM_NA_COMM_NA_PRC_SPC_USA_QBTU.A | D18: quads | F18: 0.572863 | G18: 0.555504 | H18: 0.567101 | I18: 0.581417 | J18: 0.593019 | K18: 0.600526 | L18: 0.605656 | M18: 0.610511 | N18: 0.615916 | O18: 0.620551 | P18: 0.626405 | Q18: 0.634237 | R18: 0.64382 | S18: 0.653979 | T18: 0.663072 | U18: 0.672389 | V18: 0.681693 | W18: 0.691424 | X18: 0.700888 | Y18: 0.710873 | Z18: 0.720879 | AA18: 0.730822 | AB18: 0.740723 | AC18: 0.750737 | AD18: 0.760976 | AE18: 0.77153 | AF18: 0.782225 | AG18: 0.012
A19: Water Heating | B19: Commercial: Purchased Electricity: Water Heating: High Zero-Carbon Technology Cost | C19: AEO.2025.HIGHZTC.CNSM_NA_COMM_NA_PRC_WTHT_USA_QBTU.A | D19: quads | F19: 0.074498 | G19: 0.074071 | H19: 0.074182 | I19: 0.074694 | J19: 0.074824 | K19: 0.074442 | L19: 0.073763 | M19: 0.072947 | N19: 0.072144 | O19: 0.07123 | P19: 0.070423 | Q19: 0.069795 | R19: 0.069306 | S19: 0.06885 | T19: 0.068283 | U19: 0.067699 | V19: 0.067105 | W19: 0.066492 | X19: 0.065852 | Y19: 0.065211 | Z19: 0.06455 | AA19: 0.063869 | AB19: 0.063171 | AC19: 0.062463 | AD19: 0.061751 | AE19: 0.061051 | AF19: 0.060345 | AG19: -0.008
A20: Ventilation | B20: Commercial: Purchased Electricity: Ventilation: High Zero-Carbon Technology Cost | C20: AEO.2025.HIGHZTC.CNSM_NA_COMM_NA_PRC_VNTC_USA_QBTU.A | D20: quads | F20: 0.744661 | G20: 0.756603 | H20: 0.773226 | I20: 0.794686 | J20: 0.812654 | K20: 0.825388 | L20: 0.832556 | M20: 0.83919 | N20: 0.846238 | O20: 0.852703 | P20: 0.860542 | Q20: 0.870582 | R20: 0.882446 | S20: 0.894907 | T20: 0.906128 | U20: 0.91749 | V20: 0.928914 | W20: 0.940408 | X20: 0.951505 | Y20: 0.962645 | Z20: 0.973623 | AA20: 0.984451 | AB20: 0.995252 | AC20: 1.006035 | AD20: 1.016947 | AE20: 1.028129 | AF20: 1.039459 | AG20: 0.013
A21: Cooking | B21: Commercial: Purchased Electricity: Cooking: High Zero-Carbon Technology Cost | C21: AEO.2025.HIGHZTC.CNSM_NA_COMM_NA_PRC_CGR_USA_QBTU.A | D21: quads | F21: 0.084363 | G21: 0.084583 | H21: 0.085052 | I21: 0.085953 | J21: 0.086428 | K21: 0.086317 | L21: 0.085872 | M21: 0.085313 | N21: 0.084775 | O21: 0.08415 | P21: 0.083641 | Q21: 0.083324 | R21: 0.083155 | S21: 0.083004 | T21: 0.082701 | U21: 0.08237 | V21: 0.08201 | W21: 0.081651 | X21: 0.081245 | Y21: 0.080829 | Z21: 0.08037 | AA21: 0.079869 | AB21: 0.079338 | AC21: 0.078786 | AD21: 0.078226 | AE21: 0.077667 | AF21: 0.077102 | AG21: -0.003
A22: Lighting | B22: Commercial: Purchased Electricity: Lighting: High Zero-Carbon Technology Cost | C22: AEO.2025.HIGHZTC.CNSM_NA_COMM_NA_PRC_LGHTNG_USA_QBTU.A | D22: quads | F22: 0.575629 | G22: 0.564073 | H22: 0.561419 | I22: 0.564836 | J22: 0.567739 | K22: 0.568038 | L22: 0.557796 | M22: 0.548668 | N22: 0.540723 | O22: 0.532836 | P22: 0.525787 | Q22: 0.520252 | R22: 0.516397 | S22: 0.513764 | T22: 0.511098 | U22: 0.509139 | V22: 0.506221 | W22: 0.504248 | X22: 0.502663 | Y22: 0.501633 | Z22: 0.500871 | AA22: 0.50037 | AB22: 0.500099 | AC22: 0.499308 | AD22: 0.498756 | AE22: 0.498499 | AF22: 0.498199 | AG22: -0.006
A23: Refrigeration | B23: Commercial: Purchased Electricity: Refrigeration: High Zero-Carbon Technology Cost | C23: AEO.2025.HIGHZTC.CNSM_NA_COMM_NA_PRC_REFR_USA_QBTU.A | D23: quads | F23: 0.367309 | G23: 0.368624 | H23: 0.370766 | I23: 0.374365 | J23: 0.377621 | K23: 0.380001 | L23: 0.380716 | M23: 0.381667 | N23: 0.382904 | O23: 0.384225 | P23: 0.385941 | Q23: 0.38814 | R23: 0.39069 | S23: 0.393327 | T23: 0.395723 | U23: 0.398099 | V23: 0.400438 | W23: 0.403045 | X23: 0.405577 | Y23: 0.408103 | Z23: 0.410566 | AA23: 0.412967 | AB23: 0.415333 | AC23: 0.417661 | AD23: 0.419969 | AE23: 0.422275 | AF23: 0.424554 | AG23: 0.006
A24: Computing | B24: Commercial: Purchased Electricity: Computing: High Zero-Carbon Technology Cost | C24: AEO.2025.HIGHZTC.CNSM_NA_COMM_NA_PRC_OTHEQPPC_USA_QBTU.A | D24: quads | F24: 0.341028 | G24: 0.357353 | H24: 0.375373 | I24: 0.394874 | J24: 0.415307 | K24: 0.435397 | L24: 0.45559 | M24: 0.476515 | N24: 0.498559 | O24: 0.521742 | P24: 0.546356 | Q24: 0.572547 | R24: 0.600297 | S24: 0.630078 | T24: 0.660603 | U24: 0.692721 | V24: 0.726536 | W24: 0.76207 | X24: 0.798772 | Y24: 0.836762 | Z24: 0.876796 | AA24: 0.918226 | AB24: 0.961156 | AC24: 1.006466 | AD24: 1.053483 | AE24: 1.101443 | AF24: 1.152105 | AG24: 0.048
A25: Office Equipment | B25: Commercial: Purchased Electricity: Office Equipment: High Zero-Carbon Technology Cost | C25: AEO.2025.HIGHZTC.CNSM_NA_COMM_NA_PRC_OTHEQPNPC_USA_QBTU.A | D25: quads | F25: 0.043232 | G25: 0.043304 | H25: 0.043522 | I25: 0.043887 | J25: 0.044332 | K25: 0.044707 | L25: 0.045026 | M25: 0.045362 | N25: 0.045696 | O25: 0.046077 | P25: 0.046523 | Q25: 0.046986 | R25: 0.047455 | S25: 0.047915 | T25: 0.048288 | U25: 0.048647 | V25: 0.048933 | W25: 0.04908 | X25: 0.049147 | Y25: 0.04914 | Z25: 0.048991 | AA25: 0.048634 | AB25: 0.048195 | AC25: 0.047543 | AD25: 0.046675 | AE25: 0.045653 | AF25: 0.044405 | AG25: 0.001
A26: Other Uses | B26: Commercial: Purchased Electricity: Other Uses: High Zero-Carbon Technology Cost | C26: AEO.2025.HIGHZTC.CNSM_NA_COMM_NA_PRC_OTHU_USA_QBTU.A | D26: quads | F26: 1.900956 | G26: 1.978316 | H26: 1.908781 | I26: 1.89502 | J26: 1.879119 | K26: 1.913518 | L26: 1.944432 | M26: 1.974445 | N26: 2.004845 | O26: 2.035856 | P26: 2.068322 | Q26: 2.102765 | R26: 2.139369 | S26: 2.1765 | T26: 2.213699 | U26: 2.251456 | V26: 2.289937 | W26: 2.329063 | X26: 2.368841 | Y26: 2.409592 | Z26: 2.451186 | AA26: 2.493665 | AB26: 2.536645 | AC26: 2.580551 | AD26: 2.62578 | AE26: 2.671892 | AF26: 2.719254 | AG26: 0.014
A27: Gross End-use Electricity Consumption | B27: Commercial: Energy Consumption by Fuel: Electricity Subtotal: High Zero-Carbon Technology Cost | C27: AEO.2025.HIGHZTC.CNSM_NA_COMM_NA_PRC_DELE_USA_QBTU.A | D27: quads | F27: 4.891081 | G27: 4.980416 | H27: 4.957498 | I27: 5.008786 | J27: 5.050092 | K27: 5.126225 | L27: 5.177759 | M27: 5.229208 | N27: 5.284572 | O27: 5.339435 | P27: 5.40162 | Q27: 5.475173 | R27: 5.558648 | S27: 5.647235 | T27: 5.733328 | U27: 5.822506 | V27: 5.912979 | W27: 6.007267 | X27: 6.102704 | Y27: 6.201353 | Z27: 6.302629 | AA27: 6.405821 | AB27: 6.510925 | AC27: 6.618572 | AD27: 6.729558 | AE27: 6.843156 | AF27: 6.960674 | AG27: 0.014
A28: Purchased Electricity for Electric Vehicle Charging | B28: Commercial: Energy Consumption by Fuel: Purchased Electricity for EV Charging: High Zero-Carbon Technology Cost | C28: AEO.2025.HIGHZTC.GEN_NA_COMM_NA_PRC_EVCHA_USA_QBTU.A | D28: quads | F28: 0.018762 | G28: 0.028121 | H28: 0.042235 | I28: 0.061641 | J28: 0.08625 | K28: 0.117048 | L28: 0.159369 | M28: 0.212916 | N28: 0.284019 | O28: 0.359777 | P28: 0.434374 | Q28: 0.506031 | R28: 0.574096 | S28: 0.638567 | T28: 0.698516 | U28: 0.754337 | V28: 0.806113 | W28: 0.85333 | X28: 0.895904 | Y28: 0.933313 | Z28: 0.966346 | AA28: 0.995626 | AB28: 1.021931 | AC28: 1.045841 | AD28: 1.066279 | AE28: 1.084419 | AF28: 1.100623 | AG28: 0.17
... A30: Purchased Electricity at Commercial Location | B30: Commercial: Energy Consumption by Fuel: Purchased Electricity: High Zero-Carbon Technology Cost | C30: AEO.2025.HIGHZTC.CNSM_NA_COMM_NA_DELE_ELC_USA_QBTU.A | D30: quads | F30: 4.7681 | G30: 4.849871 | H30: 4.824575 | I30: 4.888259 | J30: 4.947349 | K30: 5.044383 | L30: 5.126503 | M30: 5.216602 | N30: 5.329492 | O30: 5.444 | P30: 5.570151 | Q30: 5.709007 | R30: 5.855105 | S30: 6.002276 | T30: 6.139438 | U30: 6.279403 | V30: 6.415958 | W30: 6.549087 | X30: 6.678914 | Y30: 6.806004 | Z30: 6.931282 | AA30: 7.05442 | AB30: 7.177359 | AC30: 7.299059 | AD30: 7.420295 | AE30: 7.542165 | AF30: 7.665122 | AG30: 0.018
A31: Natural Gas
A32: Space Heating | B32: Commercial: Natural Gas: Space Heating: High Zero-Carbon Technology Cost | C32: AEO.2025.HIGHZTC.CNSM_NA_COMM_NA_NG_SPH_USA_QBTU.A | D32: quads | F32: 1.537413 | G32: 1.697475 | H32: 1.716881 | I32: 1.721059 | J32: 1.717088 | K32: 1.708489 | L32: 1.695878 | M32: 1.685565 | N32: 1.671333 | O32: 1.655639 | P32: 1.641919 | Q32: 1.633058 | R32: 1.628727 | S32: 1.626826 | T32: 1.625526 | U32: 1.62533 | V32: 1.623697 | W32: 1.619696 | X32: 1.614416 | Y32: 1.608446 | Z32: 1.603702 | AA32: 1.599288 | AB32: 1.593816 | AC32: 1.589346 | AD32: 1.585737 | AE32: 1.581855 | AF32: 1.577464 | AG32: 0.001
A33: Space Cooling | B33: Commercial: Natural Gas: Space Cooling: High Zero-Carbon Technology Cost | C33: AEO.2025.HIGHZTC.CNSM_NA_COMM_NA_NG_SPC_USA_QBTU.A | D33: quads | F33: 0.01832 | G33: 0.01762 | H33: 0.017856 | I33: 0.017985 | J33: 0.018026 | K33: 0.018042 | L33: 0.018032 | M33: 0.018032 | N33: 0.017987 | O33: 0.017929 | P33: 0.017896 | Q33: 0.017929 | R33: 0.018024 | S33: 0.01816 | T33: 0.01831 | U33: 0.018494 | V33: 0.018663 | W33: 0.018817 | X33: 0.018945 | Y33: 0.019081 | Z33: 0.019247 | AA33: 0.019418 | AB33: 0.019581 | AC33: 0.019763 | AD33: 0.019966 | AE33: 0.020156 | AF33: 0.020358 | AG33: 0.004
A34: Water Heating | B34: Commercial: Natural Gas: Water Heating: High Zero-Carbon Technology Cost | C34: AEO.2025.HIGHZTC.CNSM_NA_COMM_NA_NG_WTHT_USA_QBTU.A | D34: quads | F34: 0.269945 | G34: 0.282625 | H34: 0.290403 | I34: 0.2948 | J34: 0.298126 | K34: 0.300994 | L34: 0.303366 | M34: 0.305882 | N34: 0.30765 | O34: 0.309273 | P34: 0.311314 | Q34: 0.314163 | R34: 0.317874 | S34: 0.322065 | T34: 0.326389 | U34: 0.330938 | V34: 0.335197 | W34: 0.339036 | X34: 0.342592 | Y34: 0.346006 | Z34: 0.349657 | AA34: 0.353361 | AB34: 0.356839 | AC34: 0.360547 | AD34: 0.364444 | AE34: 0.368194 | AF34: 0.371812 | AG34: 0.012
A35: Cooking | B35: Commercial: Natural Gas: Cooking: High Zero-Carbon Technology Cost | C35: AEO.2025.HIGHZTC.CNSM_NA_COMM_NA_NG_CGR_USA_QBTU.A | D35: quads | F35: 0.400883 | G35: 0.418216 | H35: 0.427767 | I35: 0.434062 | J35: 0.438574 | K35: 0.442312 | L35: 0.445268 | M35: 0.448634 | N35: 0.451018 | O35: 0.453211 | P35: 0.455967 | Q35: 0.459839 | R35: 0.464891 | S35: 0.470575 | T35: 0.476397 | U35: 0.482477 | V35: 0.488085 | W35: 0.493181 | X35: 0.497859 | Y35: 0.502327 | Z35: 0.507092 | AA35: 0.511912 | AB35: 0.516398 | AC35: 0.521192 | AD35: 0.526222 | AE35: 0.531022 | AF35: 0.535618 | AG35: 0.011
A36: Other Uses | B36: Commercial: Natural Gas: Other Uses: High Zero-Carbon Technology Cost | C36: AEO.2025.HIGHZTC.CNSM_NA_COMM_NA_NG_OTHU_USA_QBTU.A | D36: quads | F36: 1.200143 | G36: 1.195241 | H36: 1.192541 | I36: 1.18453 | J36: 1.172073 | K36: 1.174134 | L36: 1.174214 | M36: 1.173943 | N36: 1.170539 | O36: 1.1664 | P36: 1.16325 | Q36: 1.162672 | R36: 1.164979 | S36: 1.16898 | T36: 1.173669 | U36: 1.179099 | V36: 1.183828 | W36: 1.186681 | X36: 1.188695 | Y36: 1.190251 | Z36: 1.192779 | AA36: 1.19538 | AB36: 1.197174 | AC36: 1.199681 | AD36: 1.202824 | AE36: 1.205542 | AF36: 1.207929 | AG36: 0
A37: Delivered Energy | B37: Commercial: Natural Gas: Delivered Energy: High Zero-Carbon Technology Cost | C37: AEO.2025.HIGHZTC.CNSM_NA_COMM_NA_NG_DELE_USA_QBTU.A | D37: quads | F37: 3.426704 | G37: 3.611178 | H37: 3.645448 | I37: 3.652436 | J37: 3.643887 | K37: 3.643972 | L37: 3.636758 | M37: 3.632056 | N37: 3.618527 | O37: 3.602453 | P37: 3.590345 | Q37: 3.58766 | R37: 3.594494 | S37: 3.606606 | T37: 3.620292 | U37: 3.636338 | V37: 3.64947 | W37: 3.657411 | X37: 3.662507 | Y37: 3.666111 | Z37: 3.672477 | AA37: 3.67936 | AB37: 3.683807 | AC37: 3.690529 | AD37: 3.699193 | AE37: 3.706769 | AF37: 3.713181 | AG37: 0.003
A38: Distillate Fuel Oil
A39: Space Heating | B39: Commercial: Distillate Fuel Oil: Space Heating: High Zero-Carbon Technology Cost | C39: AEO.2025.HIGHZTC.CNSM_NA_COMM_NA_DFO_SPH_USA_QBTU.A | D39: quads | F39: 0.069269 | G39: 0.074071 | H39: 0.073987 | I39: 0.073583 | J39: 0.072936 | K39: 0.071975 | L39: 0.070986 | M39: 0.069949 | N39: 0.068908 | O39: 0.067778 | P39: 0.066642 | Q39: 0.065496 | R39: 0.064415 | S39: 0.063298 | T39: 0.06222 | U39: 0.061174 | V39: 0.060119 | W39: 0.059095 | X39: 0.058066 | Y39: 0.057049 | Z39: 0.055952 | AA39: 0.055022 | AB39: 0.054114 | AC39: 0.053304 | AD39: 0.052548 | AE39: 0.051773 | AF39: 0.050965 | AG39: -0.012
A40: Water Heating | B40: Commercial: Distillate Fuel Oil: Water Heating: High Zero-Carbon Technology Cost | C40: AEO.2025.HIGHZTC.CNSM_NA_COMM_NA_DFO_WTHT_USA_QBTU.A | D40: quads | F40: 0.003746 | G40: 0.003811 | H40: 0.003828 | I40: 0.003833 | J40: 0.003829 | K40: 0.003819 | L40: 0.00381 | M40: 0.003796 | N40: 0.003782 | O40: 0.003765 | P40: 0.003747 | Q40: 0.003729 | R40: 0.003714 | S40: 0.003697 | T40: 0.003681 | U40: 0.003667 | V40: 0.003652 | W40: 0.003637 | X40: 0.003621 | Y40: 0.003606 | Z40: 0.003584 | AA40: 0.003572 | AB40: 0.003561 | AC40: 0.003556 | AD40: 0.003553 | AE40: 0.003548 | AF40: 0.00354 | AG40: -0.002
A41: Other Uses | B41: Commercial: Distillate Fuel Oil: Other Uses: High Zero-Carbon Technology Cost | C41: AEO.2025.HIGHZTC.CNSM_NA_COMM_NA_DFO_OTHU_USA_QBTU.A | D41: quads | F41: 0.235269 | G41: 0.238648 | H41: 0.242276 | I41: 0.244607 | J41: 0.246048 | K41: 0.247077 | L41: 0.248054 | M41: 0.248537 | N41: 0.24897 | O41: 0.248937 | P41: 0.248789 | Q41: 0.248491 | R41: 0.248383 | S41: 0.24808 | T41: 0.247905 | U41: 0.247811 | V41: 0.247625 | W41: 0.247337 | X41: 0.246923 | Y41: 0.246471 | Z41: 0.245575 | AA41: 0.245337 | AB41: 0.245137 | AC41: 0.245284 | AD41: 0.245618 | AE41: 0.24574 | AF41: 0.245625 | AG41: 0.002
...

Sheet AEO 2023 Table 5
A1: Table 5. Commercial Sector Key Indicators and Consumption
A2: https://www.eia.gov/outlooks/aeo/data/browser/#/?id=5-AEO2023&sourcekey=0
A3: Fri Jan 30 2026 11:55:45 GMT-0800 (Pacific Standard Time)
A4: Source: U.S. Energy Information Administration
B5: full name | C5: api key | D5: units | E5: 2021 | F5: 2022 | G5: 2023 | H5: 2024 | I5: 2025 | J5: 2026 | K5: 2027 | L5: 2028 | M5: 2029 | N5: 2030 | O5: 2031 | P5: 2032 | Q5: 2033 | R5: 2034 | S5: 2035 | T5: 2036 | U5: 2037 | V5: 2038 | W5: 2039 | X5: 2040 | Y5: 2041 | Z5: 2042 | AA5: 2043 | AB5: 2044 | AC5: 2045 | AD5: 2046 | AE5: 2047 | AF5: 2048 | AG5: 2049 | AH5: 2050 | AI5: Growth (2022-2050)
A6: Key Indicators
A7: Total Floorspace (billion square feet)
A8: Surviving | B8: Commercial: Total Floorspace: Surviving: Reference case | C8: AEO.2023.REF2023.KEI_NA_COMM_NA_TFP_SURV_USA_BLNSQFT.A | D8: billion sq ft | F8: 93.44426 | G8: 94.366943 | H8: 95.261948 | I8: 96.233696 | J8: 97.372681 | K8: 98.426239 | L8: 99.435837 | M8: 100.54059 | N8: 101.74724 | O8: 103.03194 | P8: 104.36439 | Q8: 105.67116 | R8: 106.90464 | S8: 108.06495 | T8: 109.14883 | U8: 110.16222 | V8: 111.119 | W8: 112.02248 | X8: 112.87895 | Y8: 113.69973 | Z8: 114.49508 | AA8: 115.27697 | AB8: 116.05735 | AC8: 116.84493 | AD8: 117.64615 | AE8: 118.46553 | AF8: 119.30512 | AG8: 120.16537 | AH8: 121.04549 | AI8: 0.009
A9: New Additions | B9: Commercial: Total Floorspace: New Additions: Reference case | C9: AEO.2023.REF2023.KEI_NA_COMM_NA_TFP_NADN_USA_BLNSQFT.A | D9: billion sq ft | F9: 2.027277 | G9: 2.008512 | H9: 2.0946 | I9: 2.272168 | J9: 2.197147 | K9: 2.163451 | L9: 2.269371 | M9: 2.382768 | N9: 2.473055 | O9: 2.533678 | P9: 2.521117 | Q9: 2.460828 | R9: 2.400291 | S9: 2.336108 | T9: 2.277334 | U9: 2.231909 | V9: 2.189344 | W9: 2.152566 | X9: 2.126638 | Y9: 2.110632 | Z9: 2.106252 | AA9: 2.113633 | AB9: 2.129588 | AC9: 2.151935 | AD9: 2.178813 | AE9: 2.207783 | AF9: 2.237309 | AG9: 2.266142 | AH9: 2.292936 | AI9: 0.004
A10: Total | B10: Commercial: Total Floorspace: Total: Reference case | C10: AEO.2023.REF2023.KEI_NA_COMM_NA_TFP_TOT_USA_BLNSQFT.A | D10: billion sq ft | F10: 95.471535 | G10: 96.375458 | H10: 97.356544 | I10: 98.505867 | J10: 99.569824 | K10: 100.58969 | L10: 101.70521 | M10: 102.92336 | N10: 104.22029 | O10: 105.56561 | P10: 106.88551 | Q10: 108.13199 | R10: 109.30493 | S10: 110.40105 | T10: 111.42616 | U10: 112.39414 | V10: 113.30834 | W10: 114.17505 | X10: 115.00559 | Y10: 115.81036 | Z10: 116.60133 | AA10: 117.3906 | AB10: 118.18694 | AC10: 118.99686 | AD10: 119.82496 | AE10: 120.67332 | AF10: 121.54242 | AG10: 122.43152 | AH10: 123.33843 | AI10: 0.009
A11: Energy Consumption Intensity
A12: (thousand Btu per square foot)
A13: Gross End-use Consumption | B13: Commercial: Energy Use Intensity: Gross End-use Consumption: Reference case | C13: AEO.2023.REF2023.INY_NA_COMM_NA_EUI_DLENCONS_USA_THBTUPSQFT.A | D13: thousand Btu/sq ft | F13: 97.783371 | G13: 96.37368 | H13: 94.586517 | I13: 93.941353 | J13: 93.461243 | K13: 92.806595 | L13: 92.461998 | M13: 91.902512 | N13: 91.177719 | O13: 90.426102 | P13: 89.704483 | Q13: 88.94278 | R13: 88.203415 | S13: 87.533478 | T13: 86.942825 | U13: 86.362343 | V13: 85.767792 | W13: 85.219444 | X13: 84.72036 | Y13: 84.269615 | Z13: 83.864128 | AA13: 83.519119 | AB13: 83.214996 | AC13: 82.896759 | AD13: 82.531181 | AE13: 82.224678 | AF13: 81.96669 | AG13: 81.719337 | AH13: 81.461876 | AI13: -0.007
A14: Delivered Energy Consumption | B14: Commercial: Energy Use Intensity: Delivered Energy Consumption: Reference case | C14: AEO.2023.REF2023.INY_NA_COMM_NA_EUI_ERL_USA_THBTUPSQFT.A | D14: thousand Btu/sq ft | F14: 96.520187 | G14: 94.9076 | H14: 92.965706 | I14: 92.204842 | J14: 91.668808 | K14: 90.94574 | L14: 90.547615 | M14: 89.89782 | N14: 89.117981 | O14: 88.313622 | P14: 87.548271 | Q14: 86.710747 | R14: 85.890129 | S14: 85.181641 | T14: 84.502602 | U14: 83.877907 | V14: 83.211494 | W14: 82.597618 | X14: 82.04258 | Y14: 81.545753 | Z14: 81.104858 | AA14: 80.731537 | AB14: 80.403252 | AC14: 80.062279 | AD14: 79.645531 | AE14: 79.335136 | AF14: 79.057587 | AG14: 78.810997 | AH14: 78.560989 | AI14: -0.007
A15: Energy Consumption by Fuel
A16: Electricity
A17: Space Heating | B17: Commercial: Purchased Electricity: Space Heating: Reference case | C17: AEO.2023.REF2023.CNSM_NA_COMM_NA_PRC_SPH_USA_QBTU.A | D17: quads | F17: 0.119273 | G17: 0.118361 | H17: 0.110862 | I17: 0.111099 | J17: 0.111147 | K17: 0.110854 | L17: 0.110384 | M17: 0.109759 | N17: 0.108987 | O17: 0.108285 | P17: 0.107479 | Q17: 0.106449 | R17: 0.105275 | S17: 0.104142 | T17: 0.102983 | U17: 0.101737 | V17: 0.100347 | W17: 0.098874 | X17: 0.097414 | Y17: 0.09606 | Z17: 0.094758 | AA17: 0.093488 | AB17: 0.092216 | AC17: 0.090939 | AD17: 0.089708 | AE17: 0.088523 | AF17: 0.087315 | AG17: 0.086134 | AH17: 0.08499 | AI17: -0.012
A18: Space Cooling | B18: Commercial: Purchased Electricity: Space Cooling: Reference case | C18: AEO.2023.REF2023.CNSM_NA_COMM_NA_PRC_SPC_USA_QBTU.A | D18: quads | F18: 0.54288 | G18: 0.477379 | H18: 0.550791 | I18: 0.560045 | J18: 0.56775 | K18: 0.575085 | L18: 0.582462 | M18: 0.589573 | N18: 0.595396 | O18: 0.601495 | P18: 0.607785 | Q18: 0.612405 | R18: 0.616628 | S18: 0.621292 | T18: 0.626046 | U18: 0.630735 | V18: 0.634936 | W18: 0.639136 | X18: 0.642875 | Y18: 0.647011 | Z18: 0.651487 | AA18: 0.656187 | AB18: 0.661275 | AC18: 0.666915 | AD18: 0.673704 | AE18: 0.681264 | AF18: 0.689054 | AG18: 0.696994 | AH18: 0.705699 | AI18: 0.009
A19: Water Heating | B19: Commercial: Purchased Electricity: Water Heating: Reference case | C19: AEO.2023.REF2023.CNSM_NA_COMM_NA_PRC_WTHT_USA_QBTU.A | D19: quads | F19: 0.024215 | G19: 0.023555 | H19: 0.02313 | I19: 0.02287 | J19: 0.022632 | K19: 0.022556 | L19: 0.022463 | M19: 0.02235 | N19: 0.022206 | O19: 0.022059 | P19: 0.021899 | Q19: 0.021688 | R19: 0.021453 | S19: 0.021236 | T19: 0.021016 | U19: 0.020783 | V19: 0.020526 | W19: 0.020267 | X19: 0.02001 | Y19: 0.019778 | Z19: 0.019556 | AA19: 0.019342 | AB19: 0.019133 | AC19: 0.01893 | AD19: 0.018741 | AE19: 0.01857 | AF19: 0.0184 | AG19: 0.018239 | AH19: 0.018094 | AI19: -0.01
A20: Ventilation | B20: Commercial: Purchased Electricity: Ventilation: Reference case | C20: AEO.2023.REF2023.CNSM_NA_COMM_NA_PRC_VNTC_USA_QBTU.A | D20: quads | F20: 0.418793 | G20: 0.407891 | H20: 0.400019 | I20: 0.394285 | J20: 0.38814 | K20: 0.381195 | L20: 0.373949 | M20: 0.366494 | N20: 0.358411 | O20: 0.350666 | P20: 0.342958 | Q20: 0.334873 | R20: 0.326773 | S20: 0.319148 | T20: 0.311811 | U20: 0.30456 | V20: 0.297195 | W20: 0.289957 | X20: 0.283031 | Y20: 0.276615 | Z20: 0.270569 | AA20: 0.264814 | AB20: 0.259292 | AC20: 0.253978 | AD20: 0.248923 | AE20: 0.244183 | AF20: 0.239593 | AG20: 0.235279 | AH20: 0.231259 | AI20: -0.021
A21: Cooking | B21: Commercial: Purchased Electricity: Cooking: Reference case | C21: AEO.2023.REF2023.CNSM_NA_COMM_NA_PRC_CGR_USA_QBTU.A | D21: quads | F21: 0.082377 | G21: 0.081711 | H21: 0.081787 | I21: 0.082301 | J21: 0.08263 | K21: 0.082722 | L21: 0.082723 | M21: 0.08264 | N21: 0.082438 | O21: 0.08224 | P21: 0.081999 | Q21: 0.081577 | R21: 0.081061 | S21: 0.080577 | T21: 0.080065 | U21: 0.079491 | V21: 0.078827 | W21: 0.07813 | X21: 0.077413 | Y21: 0.076771 | Z21: 0.076153 | AA21: 0.075557 | AB21: 0.074978 | AC21: 0.074415 | AD21: 0.073904 | AE21: 0.073456 | AF21: 0.072993 | AG21: 0.072537 | AH21: 0.072122 | AI21: -0.005
A22: Lighting | B22: Commercial: Purchased Electricity: Lighting: Reference case | C22: AEO.2023.REF2023.CNSM_NA_COMM_NA_PRC_LGHTNG_USA_QBTU.A | D22: quads | F22: 0.497281 | G22: 0.48856 | H22: 0.485795 | I22: 0.487572 | J22: 0.489366 | K22: 0.490566 | L22: 0.492025 | M22: 0.493689 | N22: 0.491019 | O22: 0.488961 | P22: 0.486973 | Q22: 0.484227 | R22: 0.480979 | S22: 0.47801 | T22: 0.474966 | U22: 0.470955 | V22: 0.46601 | W22: 0.459942 | X22: 0.457929 | Y22: 0.456811 | Z22: 0.455971 | AA22: 0.45553 | AB22: 0.455459 | AC22: 0.45568 | AD22: 0.456329 | AE22: 0.457722 | AF22: 0.459158 | AG22: 0.460843 | AH22: 0.463004 | AI22: -0.003
A23: Refrigeration | B23: Commercial: Purchased Electricity: Refrigeration: Reference case | C23: AEO.2023.REF2023.CNSM_NA_COMM_NA_PRC_REFR_USA_QBTU.A | D23: quads | F23: 0.603352 | G23: 0.601355 | H23: 0.60268 | I23: 0.606446 | J23: 0.609686 | K23: 0.612279 | L23: 0.615204 | M23: 0.618493 | N23: 0.620748 | O23: 0.6239 | P23: 0.62699 | Q23: 0.629387 | R23: 0.631325 | S23: 0.633214 | T23: 0.634855 | U23: 0.636155 | V23: 0.636938 | W23: 0.637474 | X23: 0.637919 | Y23: 0.639058 | Z23: 0.640294 | AA23: 0.641609 | AB23: 0.642984 | AC23: 0.644417 | AD23: 0.645996 | AE23: 0.647793 | AF23: 0.649657 | AG23: 0.651697 | AH23: 0.653934 | AI23: 0.003
A24: Computing | B24: Commercial: Purchased Electricity: Computing: Reference case | C24: AEO.2023.REF2023.CNSM_NA_COMM_NA_PRC_OTHEQPPC_USA_QBTU.A | D24: quads | F24: 0.430736 | G24: 0.434585 | H24: 0.439935 | I24: 0.447378 | J24: 0.454369 | K24: 0.460986 | L24: 0.468872 | M24: 0.477159 | N24: 0.486197 | O24: 0.495433 | P24: 0.505082 | Q24: 0.514312 | R24: 0.523711 | S24: 0.532915 | T24: 0.542904 | U24: 0.552165 | V24: 0.562175 | W24: 0.572007 | X24: 0.581746 | Y24: 0.591454 | Z24: 0.601737 | AA24: 0.612648 | AB24: 0.623171 | AC24: 0.634406 | AD24: 0.646435 | AE24: 0.658221 | AF24: 0.670737 | AG24: 0.683498 | AH24: 0.69654 | AI24: 0.017
A25: Office Equipment | B25: Commercial: Purchased Electricity: Office Equipment: Reference case | C25: AEO.2023.REF2023.CNSM_NA_COMM_NA_PRC_OTHEQPNPC_USA_QBTU.A | D25: quads | F25: 0.174708 | G25: 0.173262 | H25: 0.172777 | I25: 0.173193 | J25: 0.173864 | K25: 0.174594 | L25: 0.175666 | M25: 0.177107 | N25: 0.178874 | O25: 0.180673 | P25: 0.182679 | Q25: 0.184498 | R25: 0.185888 | S25: 0.187457 | T25: 0.188627 | U25: 0.189682 | V25: 0.190608 | W25: 0.190859 | X25: 0.19104 | Y25: 0.190877 | Z25: 0.19009 | AA25: 0.188979 | AB25: 0.18755 | AC25: 0.1855 | AD25: 0.183143 | AE25: 0.180174 | AF25: 0.176542 | AG25: 0.172244 | AH25: 0.166953 | AI25: -0.002
A26: Other Uses | B26: Commercial: Purchased Electricity: Other Uses: Reference case | C26: AEO.2023.REF2023.CNSM_NA_COMM_NA_PRC_OTHU_USA_QBTU.A | D26: quads | F26: 1.8215 | G26: 1.853537 | H26: 1.835454 | I26: 1.821644 | J26: 1.820174 | K26: 1.817382 | L26: 1.837756 | M26: 1.859593 | N26: 1.882188 | O26: 1.90582 | P26: 1.929482 | Q26: 1.951943 | R26: 1.973375 | S26: 1.994686 | T26: 2.015948 | U26: 2.036447 | V26: 2.056621 | W26: 2.076788 | X26: 2.096851 | Y26: 2.117749 | Z26: 2.13926 | AA26: 2.161906 | AB26: 2.185556 | AC26: 2.21069 | AD26: 2.236834 | AE26: 2.264744 | AF26: 2.293979 | AG26: 2.324365 | AH26: 2.356389 | AI26: 0.009
A27: Electricity Subtotal | B27: Commercial: Energy Consumption by Fuel: Electricity Subtotal: Reference case | C27: AEO.2023.REF2023.CNSM_NA_COMM_NA_PRC_DELE_USA_QBTU.A | D27: quads | F27: 4.715115 | G27: 4.660196 | H27: 4.703229 | I27: 4.706833 | J27: 4.719758 | K27: 4.728219 | L27: 4.761503 | M27: 4.796856 | N27: 4.826465 | O27: 4.859533 | P27: 4.893326 | Q27: 4.92136 | R27: 4.946467 | S27: 4.972676 | T27: 4.99922 | U27: 5.022711 | V27: 5.044183 | W27: 5.063434 | X27: 5.086228 | Y27: 5.112185 | Z27: 5.139875 | AA27: 5.170059 | AB27: 5.201613 | AC27: 5.235871 | AD27: 5.273718 | AE27: 5.314649 | AF27: 5.357429 | AG27: 5.401831 | AH27: 5.448982 | AI27: 0.005
A28: On-site Generation for Own Use | B28: Commercial: Energy Consumption by Fuel: Generation for Own Use: Reference case | C28: AEO.2023.REF2023.GEN_NA_COMM_NA_GFO_ELC_USA_QBTU.A | D28: quads | F28: 0.120598 | G28: 0.141293 | H28: 0.157796 | I28: 0.171057 | J28: 0.178473 | K28: 0.187182 | L28: 0.194703 | M28: 0.206329 | N28: 0.214666 | O28: 0.223006 | P28: 0.230468 | Q28: 0.241354 | R28: 0.252853 | S28: 0.259646 | T28: 0.271905 | U28: 0.279236 | V28: 0.289649 | W28: 0.299346 | X28: 0.307959 | Y28: 0.31545 | Z28: 0.321735 | AA28: 0.327236 | AB28: 0.332311 | AC28: 0.337295 | AD28: 0.345774 | AE28: 0.34869 | AF28: 0.35358 | AG28: 0.356073 | AH28: 0.357791 | AI28: 0.04
A29: Purchased Electricity | B29: Commercial: Energy Consumption by Fuel: Purchased Electricity: Reference case | C29: AEO.2023.REF2023.CNSM_NA_COMM_NA_DELE_ELC_USA_QBTU.A | D29: quads | F29: 4.594516 | G29: 4.518903 | H29: 4.545434 | I29: 4.535777 | J29: 4.541285 | K29: 4.541036 | L29: 4.5668 | M29: 4.590527 | N29: 4.611798 | O29: 4.636527 | P29: 4.662858 | Q29: 4.680006 | R29: 4.693614 | S29: 4.71303 | T29: 4.727315 | U29: 4.743475 | V29: 4.754533 | W29: 4.764088 | X29: 4.77827 | Y29: 4.796735 | Z29: 4.818141 | AA29: 4.842824 | AB29: 4.869302 | AC29: 4.898576 | AD29: 4.927944 | AE29: 4.965959 | AF29: 5.003849 | AG29: 5.045757 | AH29: 5.091191 | AI29: 0.004
A30: Natural Gas
A31: Space Heating | B31: Commercial: Natural Gas: Space Heating: Reference case | C31: AEO.2023.REF2023.CNSM_NA_COMM_NA_NG_SPH_USA_QBTU.A | D31: quads | F31: 1.825454 | G31: 1.7947 | H31: 1.706173 | I31: 1.738566 | J31: 1.76394 | K31: 1.779544 | L31: 1.788921 | M31: 1.79061 | N31: 1.7891 | O31: 1.787161 | P31: 1.78353 | Q31: 1.776289 | R31: 1.767478 | S31: 1.757646 | T31: 1.748321 | U31: 1.738137 | V31: 1.725022 | W31: 1.712733 | X31: 1.699783 | Y31: 1.686558 | Z31: 1.673985 | AA31: 1.663169 | AB31: 1.653979 | AC31: 1.642917 | AD31: 1.629286 | AE31: 1.617342 | AF31: 1.607314 | AG31: 1.597087 | AH31: 1.585169 | AI31: -0.005
A32: Space Cooling | B32: Commercial: Natural Gas: Space Cooling: Reference case | C32: AEO.2023.REF2023.CNSM_NA_COMM_NA_NG_SPC_USA_QBTU.A | D32: quads | F32: 0.024829 | G32: 0.019927 | H32: 0.025627 | I32: 0.025995 | J32: 0.026232 | K32: 0.026372 | L32: 0.026435 | M32: 0.026429 | N32: 0.026391 | O32: 0.026353 | P32: 0.026314 | Q32: 0.026221 | R32: 0.026135 | S32: 0.026053 | T32: 0.025982 | U32: 0.025909 | V32: 0.025794 | W32: 0.025696 | X32: 0.025607 | Y32: 0.025509 | Z32: 0.025444 | AA32: 0.025413 | AB32: 0.025411 | AC32: 0.025387 | AD32: 0.025342 | AE32: 0.025319 | AF32: 0.025355 | AG32: 0.025379 | AH32: 0.025378 | AI32: 0.001
A33: Water Heating | B33: Commercial: Natural Gas: Water Heating: Reference case | C33: AEO.2023.REF2023.CNSM_NA_COMM_NA_NG_WTHT_USA_QBTU.A | D33: quads | F33: 0.592038 | G33: 0.587033 | H33: 0.59738 | I33: 0.612751 | J33: 0.625663 | K33: 0.635529 | L33: 0.643779 | M33: 0.650036 | N33: 0.65564 | O33: 0.661104 | P33: 0.666126 | Q33: 0.669921 | R33: 0.673173 | S33: 0.676108 | T33: 0.679318 | U33: 0.682179 | V33: 0.683963 | W33: 0.686183 | X33: 0.688062 | Y33: 0.689956 | Z33: 0.692163 | AA33: 0.69516 | AB33: 0.698934 | AC33: 0.701843 | AD33: 0.702562 | AE33: 0.704524 | AF33: 0.707957 | AG33: 0.711782 | AH33: 0.714992 | AI33: 0.007
A34: Cooking | B34: Commercial: Natural Gas: Cooking: Reference case | C34: AEO.2023.REF2023.CNSM_NA_COMM_NA_NG_CGR_USA_QBTU.A | D34: quads | F34: 0.330657 | G34: 0.330951 | H34: 0.339432 | I34: 0.350318 | J34: 0.359456 | K34: 0.366753 | L34: 0.373101 | M34: 0.378484 | N34: 0.383503 | O34: 0.388504 | P34: 0.393151 | Q34: 0.397004 | R34: 0.400425 | S34: 0.403553 | T34: 0.406752 | U34: 0.409697 | V34: 0.411976 | W34: 0.414445 | X34: 0.416588 | Y34: 0.418795 | Z34: 0.421125 | AA34: 0.423867 | AB34: 0.426979 | AC34: 0.429664 | AD34: 0.4306 | AE34: 0.432317 | AF34: 0.434994 | AG34: 0.438022 | AH34: 0.440721 | AI34: 0.01
A35: Other Uses | B35: Commercial: Natural Gas: Other Uses: Reference case | C35: AEO.2023.REF2023.CNSM_NA_COMM_NA_NG_OTHU_USA_QBTU.A | D35: quads | F35: 0.829705 | G35: 0.877519 | H35: 0.834122 | I35: 0.813466 | J35: 0.803619 | K35: 0.790551 | L35: 0.796054 | M35: 0.799018 | N35: 0.801052 | O35: 0.802318 | P35: 0.803479 | Q35: 0.803824 | R35: 0.803934 | S35: 0.804007 | T35: 0.804495 | U35: 0.804872 | V35: 0.804778 | W35: 0.805447 | X35: 0.805684 | Y35: 0.80564 | Z35: 0.805986 | AA35: 0.807134 | AB35: 0.808823 | AC35: 0.809986 | AD35: 0.810499 | AE35: 0.811488 | AF35: 0.813177 | AG35: 0.814774 | AH35: 0.815962 | AI35: -0.001
A36: Delivered Energy | B36: Commercial: Natural Gas: Delivered Energy: Reference case | C36: AEO.2023.REF2023.CNSM_NA_COMM_NA_NG_DELE_USA_QBTU.A | D36: quads | F36: 3.602684 | G36: 3.610131 | H36: 3.502734 | I36: 3.541095 | J36: 3.578909 | K36: 3.598749 | L36: 3.628291 | M36: 3.644576 | N36: 3.655685 | O36: 3.66544 | P36: 3.672601 | Q36: 3.673259 | R36: 3.671146 | S36: 3.667367 | T36: 3.664868 | U36: 3.660794 | V36: 3.651533 | W36: 3.644504 | X36: 3.635725 | Y36: 3.626458 | Z36: 3.618704 | AA36: 3.614743 | AB36: 3.614126 | AC36: 3.609797 | AD36: 3.598289 | AE36: 3.59099 | AF36: 3.588797 | AG36: 3.587044 | AH36: 3.582223 | AI36: 0
A37: Distillate Fuel Oil
A38: Space Heating | B38: Commercial: Distillate Fuel Oil: Space Heating: Reference case | C38: AEO.2023.REF2023.CNSM_NA_COMM_NA_DFO_SPH_USA_QBTU.A | D38: quads | F38: 0.212071 | G38: 0.20616 | H38: 0.189944 | I38: 0.191777 | J38: 0.193137 | K38: 0.194076 | L38: 0.194863 | M38: 0.194118 | N38: 0.192428 | O38: 0.190378 | P38: 0.188286 | Q38: 0.186091 | R38: 0.183872 | S38: 0.181496 | T38: 0.179108 | U38: 0.176649 | V38: 0.17415 | W38: 0.171617 | X38: 0.169061 | Y38: 0.166513 | Z38: 0.164037 | AA38: 0.161519 | AB38: 0.159163 | AC38: 0.156796 | AD38: 0.154307 | AE38: 0.15187 | AF38: 0.149531 | AG38: 0.1472 | AH38: 0.144935 | AI38: -0.014
A39: Water Heating | B39: Commercial: Distillate Fuel Oil: Water Heating: Reference case | C39: AEO.2023.REF2023.CNSM_NA_COMM_NA_DFO_WTHT_USA_QBTU.A | D39: quads | F39: 0.006139 | G39: 0.005899 | H39: 0.005873 | I39: 0.00598 | J39: 0.006072 | K39: 0.006151 | L39: 0.006232 | M39: 0.006269 | N39: 0.006277 | O39: 0.00627 | P39: 0.006262 | Q39: 0.006249 | R39: 0.006235 | S39: 0.006215 | T39: 0.006193 | U39: 0.006167 | V39: 0.006139 | W39: 0.006109 | X39: 0.00608 | Y39: 0.006048 | Z39: 0.006018 | AA39: 0.005986 | AB39: 0.00596 | AC39: 0.005933 | AD39: 0.005901 | AE39: 0.005871 | AF39: 0.005839 | AG39: 0.005809 | AH39: 0.00578 | AI39: -0.002
