Workbook

Sheet About
A1: DoEbIC Demographics of Employees by ISIC Code
A3: Sources: | B3: Base-year demographics of employees by industry
B4: U.S. Bureau of Labor Statistics
B5: CPS Table 18/18b (employed persons by industry, sex, race, ethnicity, age) — tabs pasted with the stock projection machinery intact
B6: 2024
B7: https://www.bls.gov/cps/tables.htm
B8: Projected to 2050 with BLS labor-force projection ratios and S-curve trends (stock methodology, all calculation tabs preserved).
B10: Projections
B11: U.S. Bureau of Labor Statistics
B12: Labor force projections (see 'BLS LF projections' tab)
B13: 2024
B14: https://www.bls.gov/emp/
B15: S-curve convergence per demographic group.
A18: Notes:
A19: 52-code treatment | B19: The ten new child codes reference their PARENT's projected trajectory — the CPS industry tables carry no finer granularity at these splits. Refinement path: IPUMS ACS detailed-industry crosstabs per child.
A20: Export | B20: Each DoEbIC-<group>.csv = its output tab (52 rows x 2020-2050).

Sheet ISIC Code Key
A1: ISIC Code | B1: ISIC Code Meaning
A2: ISIC 01T03 | B2: Agriculture, forestry and fishing
A3: ISIC 05 | B3: Coal mining
A4: ISIC 06 | B4: Oil and gas extraction
A5: ISIC 07T08 | B5: Mining and quarrying of non-energy producing products (and uranium)
A6: ISIC 09 | B6: Mining support service activities
A7: ISIC 10T12 | B7: Food products, beverages and tobacco
A8: ISIC 13T15 | B8: Textiles, wearing apparel, leather and related products
A9: ISIC 16 | B9: Wood and products of wood and cork
A10: ISIC 17T18 | B10: Paper products and printing
A11: ISIC 19 | B11: Coke and refined petroleum products
A12: ISIC 20 | B12: Chemicals
... A43: ISIC 97T98 | B43: Private households with employed persons

Sheet BLS CPS T18
A1: HOUSEHOLD DATA ANNUAL AVERAGES 18. Employed persons by detailed industry, sex, race, and Hispanic or Latino ethnicity
A2: [Numbers in thousands]
A4: Industry | B4: 2020
B5: Total employed | C5: Percent of total employed
C6: Women | D6: White | E6: Black or African American | F6: Asian | G6: Hispanic or Latino | H6: Matching ISIC Code | I6: Other Race or 2+ Races
A8: Total, 16 years and over | B8: 147795 | C8: 46.8 | D8: 78 | E8: 12.1 | F8: 6.4 | G8: 17.6 | I8: =IF(OR(ISBLANK(D8),NOT(ISNUMBER(D8))),"",MAX(0,100-SUM(D8:F8))) -> 3.5
I9: =IF(OR(ISBLANK(D9),NOT(ISNUMBER(D9))),"",MAX(0,100-SUM(D9:F9)))
A10: Agriculture, forestry, fishing, and hunting | B10: 2349 | C10: 27.7 | D10: 92.4 | E10: 2.8 | F10: 1.2 | G10: 24.2 | H10: ISIC 01T03 | I10: =IF(OR(ISBLANK(D10),NOT(ISNUMBER(D10))),"",MAX(0,100-SUM(D10:F10))) -> 3.6
A11: Crop production | B11: 1186 | C11: 28.9 | D11: 92.7 | E11: 2.2 | F11: 1.7 | G11: 30.3 | I11: =IF(OR(ISBLANK(D11),NOT(ISNUMBER(D11))),"",MAX(0,100-SUM(D11:F11))) -> 3.4
A12: Animal production and aquaculture | B12: 832 | C12: 28.1 | D12: 92.9 | E12: 3.3 | F12: 0.4 | G12: 17.9 | I12: =IF(OR(ISBLANK(D12),NOT(ISNUMBER(D12))),"",MAX(0,100-SUM(D12:F12))) -> 3.4
A13: Support activities for agriculture and forestry | B13: 145 | C13: 33.9 | D13: 90.4 | E13: 5.7 | F13: 0.4 | G13: 26 | I13: =IF(OR(ISBLANK(D13),NOT(ISNUMBER(D13))),"",MAX(0,100-SUM(D13:F13))) -> 3.5
A14: Forestry, except logging | B14: 53 | C14: 25.5 | D14: 97.8 | E14: 0 | F14: 0.5 | G14: 9.9 | I14: =IF(OR(ISBLANK(D14),NOT(ISNUMBER(D14))),"",MAX(0,100-SUM(D14:F14))) -> 1.7
A15: Logging | B15: 88 | C15: 7.3 | D15: 89.9 | E15: 3.8 | F15: 2 | G15: 13.1 | I15: =IF(OR(ISBLANK(D15),NOT(ISNUMBER(D15))),"",MAX(0,100-SUM(D15:F15))) -> 4.3
A16: Fishing, hunting, and trapping | B16: 45 | C16: – | D16: – | E16: – | F16: – | G16: – | I16: =IF(OR(ISBLANK(D16),NOT(ISNUMBER(D16))),"",MAX(0,100-SUM(D16:F16)))
I17: =IF(OR(ISBLANK(D17),NOT(ISNUMBER(D17))),"",MAX(0,100-SUM(D17:F17)))
A18: Mining, quarrying, and oil and gas extraction | B18: 684 | C18: 14.5 | D18: 87.2 | E18: 4.6 | F18: 4.2 | G18: 17 | I18: =IF(OR(ISBLANK(D18),NOT(ISNUMBER(D18))),"",MAX(0,100-SUM(D18:F18))) -> 4
A19: Oil and gas extraction | B19: 97 | C19: 14.9 | D19: 80.6 | E19: 4.1 | F19: 10.5 | G19: 13 | H19: ISIC 06 | I19: =IF(OR(ISBLANK(D19),NOT(ISNUMBER(D19))),"",MAX(0,100-SUM(D19:F19))) -> 4.8
A20: Coal mining | B20: 51 | C20: 10.1 | D20: 93.1 | E20: 3.1 | F20: 0 | G20: 4.2 | H20: ISIC 05 | I20: =IF(OR(ISBLANK(D20),NOT(ISNUMBER(D20))),"",MAX(0,100-SUM(D20:F20))) -> 3.8
A21: Metal ore mining | B21: 36 | C21: – | D21: – | E21: – | F21: – | G21: – | I21: =IF(OR(ISBLANK(D21),NOT(ISNUMBER(D21))),"",MAX(0,100-SUM(D21:F21)))
A22: Nonmetallic mineral mining and quarrying | B22: 83 | C22: 10.7 | D22: 90.4 | E22: 0.8 | F22: 2.5 | G22: 12.7 | H22: ISIC 07T08 | I22: =IF(OR(ISBLANK(D22),NOT(ISNUMBER(D22))),"",MAX(0,100-SUM(D22:F22))) -> 6.3
A23: Not specified type of mining | B23: 0 | C23: – | D23: – | E23: – | F23: – | G23: – | I23: =IF(OR(ISBLANK(D23),NOT(ISNUMBER(D23))),"",MAX(0,100-SUM(D23:F23)))
A24: Support activities for mining | B24: 417 | C24: 15.2 | D24: 86.5 | E24: 6 | F24: 3.9 | G24: 20.7 | H24: ISIC 09 | I24: =IF(OR(ISBLANK(D24),NOT(ISNUMBER(D24))),"",MAX(0,100-SUM(D24:F24))) -> 3.6
I25: =IF(OR(ISBLANK(D25),NOT(ISNUMBER(D25))),"",MAX(0,100-SUM(D25:F25)))
A26: Construction | B26: 10786 | C26: 10.9 | D26: 88.6 | E26: 6 | F26: 2 | G26: 30 | H26: ISIC 41T43 | I26: =IF(OR(ISBLANK(D26),NOT(ISNUMBER(D26))),"",MAX(0,100-SUM(D26:F26))) -> 3.4
I27: =IF(OR(ISBLANK(D27),NOT(ISNUMBER(D27))),"",MAX(0,100-SUM(D27:F27)))
A28: Manufacturing | B28: 14550 | C28: 29.5 | D28: 79.7 | E28: 10.3 | F28: 7 | G28: 17.3 | I28: =IF(OR(ISBLANK(D28),NOT(ISNUMBER(D28))),"",MAX(0,100-SUM(D28:F28))) -> 3
A29: Durable goods manufacturing | B29: 9129 | C29: 25.4 | D29: 80.3 | E29: 9.5 | F29: 7.4 | G29: 15.5 | I29: =IF(OR(ISBLANK(D29),NOT(ISNUMBER(D29))),"",MAX(0,100-SUM(D29:F29))) -> 2.8
A30: Nonmetallic mineral products manufacturing | B30: 410 | C30: 21.3 | D30: 84 | E30: 8.8 | F30: 2.4 | G30: 24.4 | H30: see at bottom | I30: =IF(OR(ISBLANK(D30),NOT(ISNUMBER(D30))),"",MAX(0,100-SUM(D30:F30))) -> 4.8
A31: Pottery, ceramics, and plumbing fixture manufacturing | B31: 17 | C31: – | D31: – | E31: – | F31: – | G31: – | I31: =IF(OR(ISBLANK(D31),NOT(ISNUMBER(D31))),"",MAX(0,100-SUM(D31:F31)))
A32: Clay building material and refractories manufacturing | B32: 38 | C32: – | D32: – | E32: – | F32: – | G32: – | I32: =IF(OR(ISBLANK(D32),NOT(ISNUMBER(D32))),"",MAX(0,100-SUM(D32:F32)))
A33: Glass and glass product manufacturing | B33: 123 | C33: 22.9 | D33: 78.9 | E33: 10.6 | F33: 4.3 | G33: 21.8 | H33: ISIC 231 | I33: =IF(OR(ISBLANK(D33),NOT(ISNUMBER(D33))),"",MAX(0,100-SUM(D33:F33))) -> 6.2
A34: Cement, concrete, lime, and gypsum product manufacturing | B34: 157 | C34: 12.9 | D34: 89.3 | E34: 7.1 | F34: 2.1 | G34: 29.8 | I34: =IF(OR(ISBLANK(D34),NOT(ISNUMBER(D34))),"",MAX(0,100-SUM(D34:F34))) -> 1.5
A35: Miscellaneous nonmetallic mineral product manufacturing | B35: 75 | C35: 29.6 | D35: 84.5 | E35: 7.9 | F35: 1.6 | G35: 23.1 | I35: =IF(OR(ISBLANK(D35),NOT(ISNUMBER(D35))),"",MAX(0,100-SUM(D35:F35))) -> 6
A36: Primary metals and fabricated metal products manufacturing | B36: 1534 | C36: 16.4 | D36: 89.3 | E36: 5.7 | F36: 2.4 | G36: 14.9 | I36: =IF(OR(ISBLANK(D36),NOT(ISNUMBER(D36))),"",MAX(0,100-SUM(D36:F36))) -> 2.6
A37: Iron and steel mills and steel product manufacturing | B37: 256 | C37: 12.1 | D37: 87.4 | E37: 8.2 | F37: 1 | G37: 13.5 | H37: ISIC 241 | I37: =IF(OR(ISBLANK(D37),NOT(ISNUMBER(D37))),"",MAX(0,100-SUM(D37:F37))) -> 3.4
A38: Aluminum production and processing | B38: 71 | C38: 26.9 | D38: 92.2 | E38: 6.1 | F38: 0.8 | G38: 23.4 | H38: ISIC 242 | I38: =IF(OR(ISBLANK(D38),NOT(ISNUMBER(D38))),"",MAX(0,100-SUM(D38:F38))) -> 0.9
A39: Nonferrous metal (except aluminum) production and processing | B39: 31 | C39: – | D39: – | E39: – | F39: – | G39: – | I39: =IF(OR(ISBLANK(D39),NOT(ISNUMBER(D39))),"",MAX(0,100-SUM(D39:F39)))
A40: Foundries | B40: 59 | C40: 18.5 | D40: 94.6 | E40: 4.7 | F40: 0.4 | G40: 8 | H40: see at bottom | I40: =IF(OR(ISBLANK(D40),NOT(ISNUMBER(D40))),"",MAX(0,100-SUM(D40:F40))) -> 0.3
A41: Metal forgings and stampings | B41: 45 | C41: – | D41: – | E41: – | F41: – | G41: – | I41: =IF(OR(ISBLANK(D41),NOT(ISNUMBER(D41))),"",MAX(0,100-SUM(D41:F41)))
A42: Cutlery and hand tool manufacturing | B42: 46 | C42: – | D42: – | E42: – | F42: – | G42: – | I42: =IF(OR(ISBLANK(D42),NOT(ISNUMBER(D42))),"",MAX(0,100-SUM(D42:F42)))
...

Sheet BLS CPS T18b
A1: HOUSEHOLD DATA ANNUAL AVERAGES 18b. Employed persons by detailed industry and age
A2: [Numbers in thousands]
A4: Industry | B4: 2020
B5: Total, 16 years and over | C5: 16 to 19 years | D5: 20 to 24 years | E5: 25 to 34 years | F5: 35 to 44 years | G5: 45 to 54 years | H5: 55 to 64 years | I5: 65 years and over | J5: Median age | K5: Matching ISIC Code
A7: Total, 16 years and over | B7: 147795 | C7: 4695 | D7: 12497 | E7: 33426 | F7: 31807 | G7: 30099 | H7: 25454 | I7: 9818 | J7: 42.5
A9: Agriculture, forestry, fishing, and hunting | B9: 2349 | C9: 93 | D9: 161 | E9: 386 | F9: 403 | G9: 409 | H9: 462 | I9: 435 | J9: 48.5 | K9: ISIC 01T03
A10: Crop production | B10: 1186 | C10: 41 | D10: 74 | E10: 208 | F10: 199 | G10: 205 | H10: 243 | I10: 216 | J10: 48.6
A11: Animal production and aquaculture | B11: 832 | C11: 40 | D11: 63 | E11: 114 | F11: 143 | G11: 144 | H11: 148 | I11: 180 | J11: 49.2
A12: Support activities for agriculture and forestry | B12: 145 | C12: 9 | D12: 13 | E12: 28 | F12: 27 | G12: 26 | H12: 32 | I12: 11 | J12: 44.3
A13: Forestry, except logging | B13: 53 | C13: 1 | D13: 2 | E13: 9 | F13: 12 | G13: 10 | H13: 12 | I13: 5 | J13: 46.6
A14: Logging | B14: 88 | C14: 2 | D14: 7 | E14: 16 | F14: 15 | G14: 18 | H14: 18 | I14: 12 | J14: 48.7
A15: Fishing, hunting, and trapping | B15: 45 | C15: 1 | D15: 2 | E15: 11 | F15: 7 | G15: 6 | H15: 8 | I15: 11 | J15: –
A17: Mining, quarrying, and oil and gas extraction | B17: 684 | C17: 5 | D17: 41 | E17: 147 | F17: 198 | G17: 153 | H17: 107 | I17: 33 | J17: 42.8
A18: Oil and gas extraction | B18: 97 | C18: 0 | D18: 3 | E18: 23 | F18: 29 | G18: 23 | H18: 13 | I18: 7 | J18: 43.3 | K18: ISIC 06
A19: Coal mining | B19: 51 | C19: 0 | D19: 2 | E19: 10 | F19: 16 | G19: 12 | H19: 10 | I19: 1 | J19: 44.1 | K19: ISIC 05
A20: Metal ore mining | B20: 36 | C20: 0 | D20: 0 | E20: 10 | F20: 5 | G20: 12 | H20: 6 | I20: 2 | J20: –
A21: Nonmetallic mineral mining and quarrying | B21: 83 | C21: 0 | D21: 9 | E21: 12 | F21: 19 | G21: 14 | H21: 21 | I21: 7 | J21: 48 | K21: ISIC 07T08
A22: Not specified type of mining | B22: 0 | C22: 0 | D22: 0 | E22: 0 | F22: 0 | G22: 0 | H22: 0 | I22: 0 | J22: –
A23: Support activities for mining | B23: 417 | C23: 4 | D23: 27 | E23: 92 | F23: 130 | G23: 92 | H23: 57 | I23: 16 | J23: 41.8 | K23: ISIC 09
A25: Construction | B25: 10786 | C25: 199 | D25: 817 | E25: 2321 | F25: 2650 | G25: 2352 | H25: 1850 | I25: 598 | J25: 42.9 | K25: ISIC 41T43
A27: Manufacturing | B27: 14550 | C27: 169 | D27: 940 | E27: 3200 | F27: 3145 | G27: 3388 | H27: 2929 | I27: 780 | J27: 44.4
A28: Durable goods manufacturing | B28: 9129 | C28: 100 | D28: 593 | E28: 1980 | F28: 1947 | G28: 2118 | H28: 1900 | I28: 491 | J28: 44.6
A29: Nonmetallic mineral products manufacturing | B29: 410 | C29: 6 | D29: 28 | E29: 70 | F29: 96 | G29: 91 | H29: 95 | I29: 24 | J29: 45.8 | K29: see at bottom
A30: Pottery, ceramics, and plumbing fixture manufacturing | B30: 17 | C30: 0 | D30: 0 | E30: 2 | F30: 5 | G30: 4 | H30: 3 | I30: 3 | J30: –
A31: Clay building material and refractories manufacturing | B31: 38 | C31: 1 | D31: 4 | E31: 8 | F31: 6 | G31: 6 | H31: 10 | I31: 5 | J31: –
A32: Glass and glass product manufacturing | B32: 123 | C32: 2 | D32: 9 | E32: 20 | F32: 25 | G32: 31 | H32: 27 | I32: 9 | J32: 46.8 | K32: ISIC 231
A33: Cement, concrete, lime, and gypsum product manufacturing | B33: 157 | C33: 1 | D33: 11 | E33: 29 | F33: 32 | G33: 34 | H33: 44 | I33: 6 | J33: 46
A34: Miscellaneous nonmetallic mineral product manufacturing | B34: 75 | C34: 2 | D34: 4 | E34: 11 | F34: 28 | G34: 16 | H34: 12 | I34: 1 | J34: 43
A35: Primary metals and fabricated metal products manufacturing | B35: 1534 | C35: 20 | D35: 100 | E35: 320 | F35: 314 | G35: 328 | H35: 366 | I35: 85 | J35: 45.4
A36: Iron and steel mills and steel product manufacturing | B36: 256 | C36: 2 | D36: 19 | E36: 53 | F36: 55 | G36: 51 | H36: 65 | I36: 11 | J36: 45.2 | K36: ISIC 241
A37: Aluminum production and processing | B37: 71 | C37: 1 | D37: 3 | E37: 14 | F37: 13 | G37: 20 | H37: 17 | I37: 2 | J37: 47.3 | K37: ISIC 242
A38: Nonferrous metal (except aluminum) production and processing | B38: 31 | C38: 1 | D38: 0 | E38: 4 | F38: 8 | G38: 6 | H38: 8 | I38: 4 | J38: –
A39: Foundries | B39: 59 | C39: 1 | D39: 5 | E39: 14 | F39: 13 | G39: 12 | H39: 12 | I39: 3 | J39: 42.6 | K39: see at bottom
A40: Metal forgings and stampings | B40: 45 | C40: 0 | D40: 3 | E40: 9 | F40: 11 | G40: 10 | H40: 9 | I40: 3 | J40: –
A41: Cutlery and hand tool manufacturing | B41: 46 | C41: 1 | D41: 4 | E41: 11 | F41: 9 | G41: 5 | H41: 13 | I41: 4 | J41: –
A42: Structural metals, and boiler, tank, and shipping container manufacturing | B42: 304 | C42: 5 | D42: 17 | E42: 73 | F42: 66 | G42: 74 | H42: 52 | I42: 17 | J42: 43.3 | K42: see at bottom
A43: Machine shops; turned product; screw, nut, and bolt manufacturing | B43: 287 | C43: 1 | D43: 19 | E43: 51 | F43: 57 | G43: 54 | H43: 85 | I43: 20 | J43: 48.4 | K43: see at bottom
A44: Coating, engraving, heat treating, and allied activities | B44: 61 | C44: 1 | D44: 3 | E44: 17 | F44: 10 | G44: 11 | H44: 17 | I44: 1 | J44: 45 | K44: see at bottom
A45: Ordnance | B45: 46 | C45: 1 | D45: 7 | E45: 7 | F45: 10 | G45: 13 | H45: 7 | I45: 3 | J45: –
A46: Miscellaneous fabricated metal products manufacturing | B46: 310 | C46: 7 | D46: 16 | E46: 65 | F46: 58 | G46: 72 | H46: 74 | I46: 17 | J46: 45.4 | K46: see at bottom
...

Sheet BLS LF projections 2019-2029
A1: Civilian Labor Force (LF) Projections 2019-29 (numbers in thousands)
A2: This file was updated on February 24, 2021, to correct data for "all other" men.
B3: 2019 | C3: 2020 | D3: 2021 | E3: 2022 | F3: 2023 | G3: 2024 | H3: 2025 | I3: 2026 | J3: 2027 | K3: 2028 | L3: 2029 | M3: 2030 | N3: 2031 | O3: 2032 | P3: 2033 | Q3: 2034 | R3: 2035 | S3: 2036 | T3: 2037 | U3: 2038 | V3: 2039 | W3: 2040 | X3: 2041 | Y3: 2042 | Z3: 2043 | AA3: 2044 | AB3: 2045 | AC3: 2046 | AD3: 2047 | AE3: 2048 | AF3: 2049 | AG3: 2050
A4: Total Labor Force | B4: 163537 | C4: 164337 | D4: 165161 | E4: 165897 | F4: 166681 | G4: 167488 | H4: 168248 | I4: 169069 | J4: 169894 | K4: 170725 | L4: 171531 | M4: {=TREND($B4:$L4,$B$3:$L$3,M$3)} -> 172286.11 | N4: {=TREND($B4:$L4,$B$3:$L$3,N$3)} -> 173082.76 | O4: {=TREND($B4:$L4,$B$3:$L$3,O$3)} -> 173879.42 | P4: {=TREND($B4:$L4,$B$3:$L$3,P$3)} -> 174676.07 | Q4: {=TREND($B4:$L4,$B$3:$L$3,Q$3)} -> 175472.73 | R4: {=TREND($B4:$L4,$B$3:$L$3,R$3)} -> 176269.38 | S4: {=TREND($B4:$L4,$B$3:$L$3,S$3)} -> 177066.04 | T4: {=TREND($B4:$L4,$B$3:$L$3,T$3)} -> 177862.69 | ... AG4: {=TREND($B4:$L4,$B$3:$L$3,AG$3)} -> 188219.2
A5: 16 and 17 | B5: 2081 | C5: 2033 | D5: 1978 | E5: 1920 | F5: 1873 | G5: 1819 | H5: 1733 | I5: 1655 | J5: 1606 | K5: 1548 | L5: 1490 | M5: {=TREND($B5:$L5,$B$3:$L$3,M$3)} -> 1429.7636 | N5: {=TREND($B5:$L5,$B$3:$L$3,N$3)} -> 1369.0273 | O5: {=TREND($B5:$L5,$B$3:$L$3,O$3)} -> 1308.2909 | P5: {=TREND($B5:$L5,$B$3:$L$3,P$3)} -> 1247.5545 | Q5: {=TREND($B5:$L5,$B$3:$L$3,Q$3)} -> 1186.8182 | R5: {=TREND($B5:$L5,$B$3:$L$3,R$3)} -> 1126.0818 | S5: {=TREND($B5:$L5,$B$3:$L$3,S$3)} -> 1065.3455 | T5: {=TREND($B5:$L5,$B$3:$L$3,T$3)} -> 1004.6091 | ... AG5: {=TREND($B5:$L5,$B$3:$L$3,AG$3)} -> 215.03636
A6: 18 and 19 | B6: 3815 | C6: 3701 | D6: 3623 | E6: 3601 | F6: 3567 | G6: 3525 | H6: 3500 | I6: 3463 | J6: 3360 | K6: 3267 | L6: 3227 | M6: {=TREND($B6:$L6,$B$3:$L$3,M$3)} -> 3196.7455 | N6: {=TREND($B6:$L6,$B$3:$L$3,N$3)} -> 3143.9455 | O6: {=TREND($B6:$L6,$B$3:$L$3,O$3)} -> 3091.1455 | P6: {=TREND($B6:$L6,$B$3:$L$3,P$3)} -> 3038.3455 | Q6: {=TREND($B6:$L6,$B$3:$L$3,Q$3)} -> 2985.5455 | R6: {=TREND($B6:$L6,$B$3:$L$3,R$3)} -> 2932.7455 | S6: {=TREND($B6:$L6,$B$3:$L$3,S$3)} -> 2879.9455 | T6: {=TREND($B6:$L6,$B$3:$L$3,T$3)} -> 2827.1455 | ... AG6: {=TREND($B6:$L6,$B$3:$L$3,AG$3)} -> 2140.7455
A7: 20 to 24 | B7: 15195 | C7: 15159 | D7: 15134 | E7: 15054 | F7: 14989 | G7: 14943 | H7: 14843 | I7: 14794 | J7: 14835 | K7: 14849 | L7: 14755 | M7: {=TREND($B7:$L7,$B$3:$L$3,M$3)} -> 14686.2 | N7: {=TREND($B7:$L7,$B$3:$L$3,N$3)} -> 14640.718 | O7: {=TREND($B7:$L7,$B$3:$L$3,O$3)} -> 14595.236 | P7: {=TREND($B7:$L7,$B$3:$L$3,P$3)} -> 14549.755 | Q7: {=TREND($B7:$L7,$B$3:$L$3,Q$3)} -> 14504.273 | R7: {=TREND($B7:$L7,$B$3:$L$3,R$3)} -> 14458.791 | S7: {=TREND($B7:$L7,$B$3:$L$3,S$3)} -> 14413.309 | T7: {=TREND($B7:$L7,$B$3:$L$3,T$3)} -> 14367.827 | ... AG7: {=TREND($B7:$L7,$B$3:$L$3,AG$3)} -> 13776.564
A8: 25 to 29 | B8: 18991 | C8: 18817 | D8: 18555 | E8: 18329 | F8: 18183 | G8: 18083 | H8: 18097 | I8: 18123 | J8: 18086 | K8: 18064 | L8: 18067 | M8: {=TREND($B8:$L8,$B$3:$L$3,M$3)} -> 17788.436 | N8: {=TREND($B8:$L8,$B$3:$L$3,N$3)} -> 17701.736 | O8: {=TREND($B8:$L8,$B$3:$L$3,O$3)} -> 17615.036 | P8: {=TREND($B8:$L8,$B$3:$L$3,P$3)} -> 17528.336 | Q8: {=TREND($B8:$L8,$B$3:$L$3,Q$3)} -> 17441.636 | R8: {=TREND($B8:$L8,$B$3:$L$3,R$3)} -> 17354.936 | S8: {=TREND($B8:$L8,$B$3:$L$3,S$3)} -> 17268.236 | T8: {=TREND($B8:$L8,$B$3:$L$3,T$3)} -> 17181.536 | ... AG8: {=TREND($B8:$L8,$B$3:$L$3,AG$3)} -> 16054.436
A9: 30 to 34 | B9: 18200 | C9: 18565 | D9: 18972 | E9: 19333 | F9: 19542 | G9: 19611 | H9: 19455 | I9: 19209 | J9: 19000 | K9: 18868 | L9: 18779 | M9: {=TREND($B9:$L9,$B$3:$L$3,M$3)} -> 19258.873 | N9: {=TREND($B9:$L9,$B$3:$L$3,N$3)} -> 19293.927 | O9: {=TREND($B9:$L9,$B$3:$L$3,O$3)} -> 19328.982 | P9: {=TREND($B9:$L9,$B$3:$L$3,P$3)} -> 19364.036 | Q9: {=TREND($B9:$L9,$B$3:$L$3,Q$3)} -> 19399.091 | R9: {=TREND($B9:$L9,$B$3:$L$3,R$3)} -> 19434.145 | S9: {=TREND($B9:$L9,$B$3:$L$3,S$3)} -> 19469.2 | T9: {=TREND($B9:$L9,$B$3:$L$3,T$3)} -> 19504.255 | ... AG9: {=TREND($B9:$L9,$B$3:$L$3,AG$3)} -> 19959.964
A10: 35 to 39 | B10: 17736 | C10: 17821 | D10: 17959 | E10: 18053 | F10: 18218 | G10: 18533 | H10: 18895 | I10: 19301 | J10: 19660 | K10: 19868 | L10: 19936 | M10: {=TREND($B10:$L10,$B$3:$L$3,M$3)} -> 20223.491 | N10: {=TREND($B10:$L10,$B$3:$L$3,N$3)} -> 20473.164 | O10: {=TREND($B10:$L10,$B$3:$L$3,O$3)} -> 20722.836 | P10: {=TREND($B10:$L10,$B$3:$L$3,P$3)} -> 20972.509 | Q10: {=TREND($B10:$L10,$B$3:$L$3,Q$3)} -> 21222.182 | R10: {=TREND($B10:$L10,$B$3:$L$3,R$3)} -> 21471.855 | S10: {=TREND($B10:$L10,$B$3:$L$3,S$3)} -> 21721.527 | T10: {=TREND($B10:$L10,$B$3:$L$3,T$3)} -> 21971.2 | ... AG10: {=TREND($B10:$L10,$B$3:$L$3,AG$3)} -> 25216.945
A11: 40 to 44 | B11: 16321 | C11: 16652 | D11: 17016 | E11: 17329 | F11: 17619 | G11: 17801 | H11: 17887 | I11: 18024 | J11: 18116 | K11: 18275 | L11: 18584 | M11: {=TREND($B11:$L11,$B$3:$L$3,M$3)} -> 18843.909 | N11: {=TREND($B11:$L11,$B$3:$L$3,N$3)} -> 19050.864 | O11: {=TREND($B11:$L11,$B$3:$L$3,O$3)} -> 19257.818 | P11: {=TREND($B11:$L11,$B$3:$L$3,P$3)} -> 19464.773 | Q11: {=TREND($B11:$L11,$B$3:$L$3,Q$3)} -> 19671.727 | R11: {=TREND($B11:$L11,$B$3:$L$3,R$3)} -> 19878.682 | S11: {=TREND($B11:$L11,$B$3:$L$3,S$3)} -> 20085.636 | T11: {=TREND($B11:$L11,$B$3:$L$3,T$3)} -> 20292.591 | ... AG11: {=TREND($B11:$L11,$B$3:$L$3,AG$3)} -> 22983
A12: 45 to 49 | B12: 16707 | C12: 16374 | D12: 15995 | E12: 15909 | F12: 16006 | G12: 16223 | H12: 16561 | I12: 16933 | J12: 17255 | K12: 17553 | L12: 17743 | M12: {=TREND($B12:$L12,$B$3:$L$3,M$3)} -> 17547.855 | N12: {=TREND($B12:$L12,$B$3:$L$3,N$3)} -> 17695.845 | O12: {=TREND($B12:$L12,$B$3:$L$3,O$3)} -> 17843.836 | P12: {=TREND($B12:$L12,$B$3:$L$3,P$3)} -> 17991.827 | Q12: {=TREND($B12:$L12,$B$3:$L$3,Q$3)} -> 18139.818 | R12: {=TREND($B12:$L12,$B$3:$L$3,R$3)} -> 18287.809 | S12: {=TREND($B12:$L12,$B$3:$L$3,S$3)} -> 18435.8 | T12: {=TREND($B12:$L12,$B$3:$L$3,T$3)} -> 18583.791 | ... AG12: {=TREND($B12:$L12,$B$3:$L$3,AG$3)} -> 20507.673
A13: 50 to 54 | B13: 16224 | C13: 16194 | D13: 16323 | E13: 16333 | F13: 16216 | G13: 15995 | H13: 15704 | I13: 15371 | J13: 15314 | K13: 15432 | L13: 15663 | M13: {=TREND($B13:$L13,$B$3:$L$3,M$3)} -> 15270.855 | N13: {=TREND($B13:$L13,$B$3:$L$3,N$3)} -> 15167.982 | O13: {=TREND($B13:$L13,$B$3:$L$3,O$3)} -> 15065.109 | P13: {=TREND($B13:$L13,$B$3:$L$3,P$3)} -> 14962.236 | Q13: {=TREND($B13:$L13,$B$3:$L$3,Q$3)} -> 14859.364 | R13: {=TREND($B13:$L13,$B$3:$L$3,R$3)} -> 14756.491 | S13: {=TREND($B13:$L13,$B$3:$L$3,S$3)} -> 14653.618 | T13: {=TREND($B13:$L13,$B$3:$L$3,T$3)} -> 14550.745 | ... AG13: {=TREND($B13:$L13,$B$3:$L$3,AG$3)} -> 13213.4
A14: 55 to 59 | B14: 15756 | C14: 15638 | D14: 15376 | E14: 15106 | F14: 14833 | G14: 14628 | H14: 14645 | I14: 14803 | J14: 14852 | K14: 14786 | L14: 14624 | M14: {=TREND($B14:$L14,$B$3:$L$3,M$3)} -> 14380.6 | N14: {=TREND($B14:$L14,$B$3:$L$3,N$3)} -> 14276.655 | O14: {=TREND($B14:$L14,$B$3:$L$3,O$3)} -> 14172.709 | P14: {=TREND($B14:$L14,$B$3:$L$3,P$3)} -> 14068.764 | Q14: {=TREND($B14:$L14,$B$3:$L$3,Q$3)} -> 13964.818 | R14: {=TREND($B14:$L14,$B$3:$L$3,R$3)} -> 13860.873 | S14: {=TREND($B14:$L14,$B$3:$L$3,S$3)} -> 13756.927 | T14: {=TREND($B14:$L14,$B$3:$L$3,T$3)} -> 13652.982 | ... AG14: {=TREND($B14:$L14,$B$3:$L$3,AG$3)} -> 12301.691
A15: 60 to 64 | B15: 11847 | C15: 12124 | D15: 12367 | E15: 12500 | F15: 12615 | G15: 12723 | H15: 12702 | I15: 12563 | J15: 12415 | K15: 12262 | L15: 12163 | M15: {=TREND($B15:$L15,$B$3:$L$3,M$3)} -> 12524.945 | N15: {=TREND($B15:$L15,$B$3:$L$3,N$3)} -> 12547.573 | O15: {=TREND($B15:$L15,$B$3:$L$3,O$3)} -> 12570.2 | P15: {=TREND($B15:$L15,$B$3:$L$3,P$3)} -> 12592.827 | Q15: {=TREND($B15:$L15,$B$3:$L$3,Q$3)} -> 12615.455 | R15: {=TREND($B15:$L15,$B$3:$L$3,R$3)} -> 12638.082 | S15: {=TREND($B15:$L15,$B$3:$L$3,S$3)} -> 12660.709 | T15: {=TREND($B15:$L15,$B$3:$L$3,T$3)} -> 12683.336 | ... AG15: {=TREND($B15:$L15,$B$3:$L$3,AG$3)} -> 12977.491
... A20: LF Men | B20: 86685 | C20: 87014 | D20: 87352 | E20: 87638 | F20: 87951 | G20: 88277 | H20: 88574 | I20: 88898 | J20: 89217 | K20: 89533 | L20: 89838 | M20: {=TREND($B20:$L20,$B$3:$L$3,M$3)} -> 90156.764 | N20: {=TREND($B20:$L20,$B$3:$L$3,N$3)} -> 90471.118 | O20: {=TREND($B20:$L20,$B$3:$L$3,O$3)} -> 90785.473 | P20: {=TREND($B20:$L20,$B$3:$L$3,P$3)} -> 91099.827 | Q20: {=TREND($B20:$L20,$B$3:$L$3,Q$3)} -> 91414.182 | R20: {=TREND($B20:$L20,$B$3:$L$3,R$3)} -> 91728.536 | S20: {=TREND($B20:$L20,$B$3:$L$3,S$3)} -> 92042.891 | T20: {=TREND($B20:$L20,$B$3:$L$3,T$3)} -> 92357.245 | ... AG20: {=TREND($B20:$L20,$B$3:$L$3,AG$3)} -> 96443.855
A21: 16 and 17 | B21: 1027 | C21: 1001 | D21: 972 | E21: 941 | F21: 915 | G21: 886 | H21: 841 | I21: 801 | J21: 776 | K21: 746 | L21: 715
A22: 18 and 19 | B22: 1923 | C22: 1858 | D22: 1813 | E22: 1798 | F22: 1778 | G22: 1753 | H22: 1736 | I22: 1712 | J22: 1655 | K22: 1605 | L22: 1582
A23: 20 to 24 | B23: 7789 | C23: 7746 | D23: 7708 | E23: 7645 | F23: 7589 | G23: 7543 | H23: 7470 | I23: 7428 | J23: 7430 | K23: 7418 | L23: 7350
A24: 25 to 29 | B24: 10079 | C24: 9981 | D24: 9828 | E24: 9679 | F24: 9572 | G24: 9492 | H24: 9475 | I24: 9462 | J24: 9418 | K24: 9381 | L24: 9358
A25: 30 to 34 | B25: 9869 | C25: 10067 | D25: 10286 | E25: 10488 | F25: 10612 | G25: 10653 | H25: 10571 | I25: 10431 | J25: 10298 | K25: 10203 | L25: 10134
A26: 35 to 39 | B26: 9588 | C26: 9640 | D26: 9733 | E26: 9801 | F26: 9905 | G26: 10089 | H26: 10293 | I26: 10520 | J26: 10728 | K26: 10857 | L26: 10906
A27: 40 to 44 | B27: 8708 | C27: 8891 | D27: 9088 | E27: 9262 | F27: 9424 | G27: 9530 | H27: 9584 | I27: 9677 | J27: 9744 | K27: 9844 | L27: 10023
A28: 45 to 49 | B28: 8752 | C28: 8566 | D28: 8360 | E28: 8306 | F28: 8356 | G28: 8465 | H28: 8640 | I28: 8828 | J28: 8994 | K28: 9145 | L28: 9243
A29: 50 to 54 | B29: 8535 | C29: 8505 | D29: 8551 | E29: 8536 | F29: 8449 | G29: 8311 | H29: 8140 | I29: 7952 | J29: 7906 | K29: 7957 | L29: 8063
A30: 55 to 59 | B30: 8283 | C30: 8194 | D30: 8035 | E30: 7870 | F30: 7709 | G30: 7584 | H30: 7574 | I30: 7630 | J30: 7631 | K30: 7567 | L30: 7457
A31: 60 to 64 | B31: 6264 | C31: 6391 | D31: 6496 | E31: 6542 | F31: 6578 | G31: 6611 | H31: 6577 | I31: 6486 | J31: 6389 | K31: 6293 | L31: 6226
A32: 65 to 69 | B32: 3199 | C32: 3339 | D32: 3476 | E32: 3624 | F32: 3760 | G32: 3879 | H32: 4000 | I32: 4108 | J32: 4181 | K32: 4248 | L32: 4313
... A34: 75 and over | B34: 1113 | C34: 1174 | D34: 1235 | E34: 1341 | F34: 1436 | G34: 1531 | H34: 1629 | I34: 1729 | J34: 1832 | K34: 1942 | L34: 2057
A36: LF Women | B36: 76852 | C36: 77323 | D36: 77809 | E36: 78259 | F36: 78730 | G36: 79211 | H36: 79674 | I36: 80171 | J36: 80677 | K36: 81192 | L36: 81693 | M36: {=TREND($B36:$L36,$B$3:$L$3,M$3)} -> 82129.345 | N36: {=TREND($B36:$L36,$B$3:$L$3,N$3)} -> 82611.645 | O36: {=TREND($B36:$L36,$B$3:$L$3,O$3)} -> 83093.945 | P36: {=TREND($B36:$L36,$B$3:$L$3,P$3)} -> 83576.245 | Q36: {=TREND($B36:$L36,$B$3:$L$3,Q$3)} -> 84058.545 | R36: {=TREND($B36:$L36,$B$3:$L$3,R$3)} -> 84540.845 | S36: {=TREND($B36:$L36,$B$3:$L$3,S$3)} -> 85023.145 | T36: {=TREND($B36:$L36,$B$3:$L$3,T$3)} -> 85505.445 | ... AG36: {=TREND($B36:$L36,$B$3:$L$3,AG$3)} -> 91775.345
A37: 16 and 17 | B37: 1054 | C37: 1032 | D37: 1006 | E37: 979 | F37: 957 | G37: 933 | H37: 892 | I37: 854 | J37: 830 | K37: 802 | L37: 775
A38: 18 and 19 | B38: 1892 | C38: 1843 | D38: 1810 | E38: 1803 | F38: 1789 | G38: 1772 | H38: 1764 | I38: 1751 | J38: 1705 | K38: 1663 | L38: 1645
A39: 20 to 24 | B39: 7406 | C39: 7413 | D39: 7426 | E39: 7409 | F39: 7401 | G39: 7400 | H39: 7373 | I39: 7367 | J39: 7404 | K39: 7431 | L39: 7405
A40: 25 to 29 | B40: 8912 | C40: 8836 | D40: 8728 | E40: 8649 | F40: 8611 | G40: 8591 | H40: 8622 | I40: 8661 | J40: 8667 | K40: 8683 | L40: 8708
A41: 30 to 34 | B41: 8331 | C41: 8497 | D41: 8685 | E41: 8845 | F41: 8931 | G41: 8958 | H41: 8884 | I41: 8778 | J41: 8702 | K41: 8665 | L41: 8645
A42: 35 to 39 | B42: 8148 | C42: 8181 | D42: 8226 | E42: 8252 | F42: 8313 | G42: 8444 | H42: 8602 | I42: 8781 | J42: 8932 | K42: 9010 | L42: 9030
A43: 40 to 44 | B43: 7613 | C43: 7761 | D43: 7928 | E43: 8067 | F43: 8195 | G43: 8271 | H43: 8303 | I43: 8347 | J43: 8372 | K43: 8432 | L43: 8560
A44: 45 to 49 | B44: 7955 | C44: 7808 | D44: 7635 | E44: 7603 | F44: 7651 | G44: 7758 | H44: 7922 | I44: 8105 | J44: 8262 | K44: 8407 | L44: 8500
A45: 50 to 54 | B45: 7689 | C45: 7689 | D45: 7772 | E45: 7797 | F45: 7767 | G45: 7684 | H45: 7564 | I45: 7419 | J45: 7408 | K45: 7476 | L45: 7600
A46: 55 to 59 | B46: 7473 | C46: 7444 | D46: 7341 | E46: 7236 | F46: 7125 | G46: 7044 | H46: 7072 | I46: 7173 | J46: 7221 | K46: 7219 | L46: 7167
...

Sheet LF Projected Ratios
A1: Ratios of Labor Force Participants with Particular Demographic Traits
A2: Sex
B3: 2019 | C3: 2020 | D3: 2021 | E3: 2022 | F3: 2023 | G3: 2024 | H3: 2025 | I3: 2026 | J3: 2027 | K3: 2028 | L3: 2029 | M3: 2030 | N3: 2031 | O3: 2032 | P3: 2033 | Q3: 2034 | R3: 2035 | S3: 2036 | T3: 2037 | U3: 2038 | V3: 2039 | W3: 2040 | X3: 2041 | Y3: 2042 | Z3: 2043 | AA3: 2044 | AB3: 2045 | AC3: 2046 | AD3: 2047 | AE3: 2048 | AF3: 2049 | AG3: 2050
A4: Men | B4: ='BLS LF projections 2019-2029'!B20/SUM('BLS LF projections 2019-2029'!B$20,'BLS LF projections 2019-2029'!B$36) -> 0.53006353 | C4: ='BLS LF projections 2019-2029'!C20/SUM('BLS LF projections 2019-2029'!C$20,'BLS LF projections 2019-2029'!C$36) -> 0.52948514 | D4: ='BLS LF projections 2019-2029'!D20/SUM('BLS LF projections 2019-2029'!D$20,'BLS LF projections 2019-2029'!D$36) -> 0.52888999 | E4: ='BLS LF projections 2019-2029'!E20/SUM('BLS LF projections 2019-2029'!E$20,'BLS LF projections 2019-2029'!E$36) -> 0.52826754 | F4: ='BLS LF projections 2019-2029'!F20/SUM('BLS LF projections 2019-2029'!F$20,'BLS LF projections 2019-2029'!F$36) -> 0.52766062 | G4: ='BLS LF projections 2019-2029'!G20/SUM('BLS LF projections 2019-2029'!G$20,'BLS LF projections 2019-2029'!G$36) -> 0.52706463 | H4: ='BLS LF projections 2019-2029'!H20/SUM('BLS LF projections 2019-2029'!H$20,'BLS LF projections 2019-2029'!H$36) -> 0.52644905 | I4: ='BLS LF projections 2019-2029'!I20/SUM('BLS LF projections 2019-2029'!I$20,'BLS LF projections 2019-2029'!I$36) -> 0.52580899 | ... AG4: ='BLS LF projections 2019-2029'!AG20/SUM('BLS LF projections 2019-2029'!AG$20,'BLS LF projections 2019-2029'!AG$36) -> 0.51240179
A5: Women | B5: ='BLS LF projections 2019-2029'!B36/SUM('BLS LF projections 2019-2029'!B$20,'BLS LF projections 2019-2029'!B$36) -> 0.46993647 | C5: ='BLS LF projections 2019-2029'!C36/SUM('BLS LF projections 2019-2029'!C$20,'BLS LF projections 2019-2029'!C$36) -> 0.47051486 | D5: ='BLS LF projections 2019-2029'!D36/SUM('BLS LF projections 2019-2029'!D$20,'BLS LF projections 2019-2029'!D$36) -> 0.47111001 | E5: ='BLS LF projections 2019-2029'!E36/SUM('BLS LF projections 2019-2029'!E$20,'BLS LF projections 2019-2029'!E$36) -> 0.47173246 | F5: ='BLS LF projections 2019-2029'!F36/SUM('BLS LF projections 2019-2029'!F$20,'BLS LF projections 2019-2029'!F$36) -> 0.47233938 | G5: ='BLS LF projections 2019-2029'!G36/SUM('BLS LF projections 2019-2029'!G$20,'BLS LF projections 2019-2029'!G$36) -> 0.47293537 | H5: ='BLS LF projections 2019-2029'!H36/SUM('BLS LF projections 2019-2029'!H$20,'BLS LF projections 2019-2029'!H$36) -> 0.47355095 | I5: ='BLS LF projections 2019-2029'!I36/SUM('BLS LF projections 2019-2029'!I$20,'BLS LF projections 2019-2029'!I$36) -> 0.47419101 | ... AG5: ='BLS LF projections 2019-2029'!AG36/SUM('BLS LF projections 2019-2029'!AG$20,'BLS LF projections 2019-2029'!AG$36) -> 0.48759821
A7: Race
B8: 2019 | C8: 2020 | D8: 2021 | E8: 2022 | F8: 2023 | G8: 2024 | H8: 2025 | I8: 2026 | J8: 2027 | K8: 2028 | L8: 2029 | M8: 2030 | N8: 2031 | O8: 2032 | P8: 2033 | Q8: 2034 | R8: 2035 | S8: 2036 | T8: 2037 | U8: 2038 | V8: 2039 | W8: 2040 | X8: 2041 | Y8: 2042 | Z8: 2043 | AA8: 2044 | AB8: 2045 | AC8: 2046 | AD8: 2047 | AE8: 2048 | AF8: 2049 | AG8: 2050
A9: White | B9: =SUM('BLS LF projections 2019-2029'!B52,'BLS LF projections 2019-2029'!B68)/SUM('BLS LF projections 2019-2029'!B$52,'BLS LF projections 2019-2029'!B$68,'BLS LF projections 2019-2029'!B$84,'BLS LF projections 2019-2029'!B$100,'BLS LF projections 2019-2029'!B$116,'BLS LF projections 2019-2029'!B$132) -> 0.77413674 | C9: =SUM('BLS LF projections 2019-2029'!C52,'BLS LF projections 2019-2029'!C68)/SUM('BLS LF projections 2019-2029'!C$52,'BLS LF projections 2019-2029'!C$68,'BLS LF projections 2019-2029'!C$84,'BLS LF projections 2019-2029'!C$100,'BLS LF projections 2019-2029'!C$116,'BLS LF projections 2019-2029'!C$132) -> 0.7718726 | D9: =SUM('BLS LF projections 2019-2029'!D52,'BLS LF projections 2019-2029'!D68)/SUM('BLS LF projections 2019-2029'!D$52,'BLS LF projections 2019-2029'!D$68,'BLS LF projections 2019-2029'!D$84,'BLS LF projections 2019-2029'!D$100,'BLS LF projections 2019-2029'!D$116,'BLS LF projections 2019-2029'!D$132) -> 0.76960523 | E9: =SUM('BLS LF projections 2019-2029'!E52,'BLS LF projections 2019-2029'!E68)/SUM('BLS LF projections 2019-2029'!E$52,'BLS LF projections 2019-2029'!E$68,'BLS LF projections 2019-2029'!E$84,'BLS LF projections 2019-2029'!E$100,'BLS LF projections 2019-2029'!E$116,'BLS LF projections 2019-2029'!E$132) -> 0.76725177 | F9: =SUM('BLS LF projections 2019-2029'!F52,'BLS LF projections 2019-2029'!F68)/SUM('BLS LF projections 2019-2029'!F$52,'BLS LF projections 2019-2029'!F$68,'BLS LF projections 2019-2029'!F$84,'BLS LF projections 2019-2029'!F$100,'BLS LF projections 2019-2029'!F$116,'BLS LF projections 2019-2029'!F$132) -> 0.76491445 | G9: =SUM('BLS LF projections 2019-2029'!G52,'BLS LF projections 2019-2029'!G68)/SUM('BLS LF projections 2019-2029'!G$52,'BLS LF projections 2019-2029'!G$68,'BLS LF projections 2019-2029'!G$84,'BLS LF projections 2019-2029'!G$100,'BLS LF projections 2019-2029'!G$116,'BLS LF projections 2019-2029'!G$132) -> 0.76259792 | H9: =SUM('BLS LF projections 2019-2029'!H52,'BLS LF projections 2019-2029'!H68)/SUM('BLS LF projections 2019-2029'!H$52,'BLS LF projections 2019-2029'!H$68,'BLS LF projections 2019-2029'!H$84,'BLS LF projections 2019-2029'!H$100,'BLS LF projections 2019-2029'!H$116,'BLS LF projections 2019-2029'!H$132) -> 0.7602929 | I9: =SUM('BLS LF projections 2019-2029'!I52,'BLS LF projections 2019-2029'!I68)/SUM('BLS LF projections 2019-2029'!I$52,'BLS LF projections 2019-2029'!I$68,'BLS LF projections 2019-2029'!I$84,'BLS LF projections 2019-2029'!I$100,'BLS LF projections 2019-2029'!I$116,'BLS LF projections 2019-2029'!I$132) -> 0.75794193 | ... AG9: =SUM('BLS LF projections 2019-2029'!AG52,'BLS LF projections 2019-2029'!AG68)/SUM('BLS LF projections 2019-2029'!AG$52,'BLS LF projections 2019-2029'!AG$68,'BLS LF projections 2019-2029'!AG$84,'BLS LF projections 2019-2029'!AG$100,'BLS LF projections 2019-2029'!AG$116,'BLS LF projections 2019-2029'!AG$132) -> 0.70874829
A10: Black | B10: =SUM('BLS LF projections 2019-2029'!B84,'BLS LF projections 2019-2029'!B100)/SUM('BLS LF projections 2019-2029'!B$52,'BLS LF projections 2019-2029'!B$68,'BLS LF projections 2019-2029'!B$84,'BLS LF projections 2019-2029'!B$100,'BLS LF projections 2019-2029'!B$116,'BLS LF projections 2019-2029'!B$132) -> 0.12615494 | C10: =SUM('BLS LF projections 2019-2029'!C84,'BLS LF projections 2019-2029'!C100)/SUM('BLS LF projections 2019-2029'!C$52,'BLS LF projections 2019-2029'!C$68,'BLS LF projections 2019-2029'!C$84,'BLS LF projections 2019-2029'!C$100,'BLS LF projections 2019-2029'!C$116,'BLS LF projections 2019-2029'!C$132) -> 0.12658058 | D10: =SUM('BLS LF projections 2019-2029'!D84,'BLS LF projections 2019-2029'!D100)/SUM('BLS LF projections 2019-2029'!D$52,'BLS LF projections 2019-2029'!D$68,'BLS LF projections 2019-2029'!D$84,'BLS LF projections 2019-2029'!D$100,'BLS LF projections 2019-2029'!D$116,'BLS LF projections 2019-2029'!D$132) -> 0.1269799 | E10: =SUM('BLS LF projections 2019-2029'!E84,'BLS LF projections 2019-2029'!E100)/SUM('BLS LF projections 2019-2029'!E$52,'BLS LF projections 2019-2029'!E$68,'BLS LF projections 2019-2029'!E$84,'BLS LF projections 2019-2029'!E$100,'BLS LF projections 2019-2029'!E$116,'BLS LF projections 2019-2029'!E$132) -> 0.12741718 | F10: =SUM('BLS LF projections 2019-2029'!F84,'BLS LF projections 2019-2029'!F100)/SUM('BLS LF projections 2019-2029'!F$52,'BLS LF projections 2019-2029'!F$68,'BLS LF projections 2019-2029'!F$84,'BLS LF projections 2019-2029'!F$100,'BLS LF projections 2019-2029'!F$116,'BLS LF projections 2019-2029'!F$132) -> 0.1278407 | G10: =SUM('BLS LF projections 2019-2029'!G84,'BLS LF projections 2019-2029'!G100)/SUM('BLS LF projections 2019-2029'!G$52,'BLS LF projections 2019-2029'!G$68,'BLS LF projections 2019-2029'!G$84,'BLS LF projections 2019-2029'!G$100,'BLS LF projections 2019-2029'!G$116,'BLS LF projections 2019-2029'!G$132) -> 0.12825994 | H10: =SUM('BLS LF projections 2019-2029'!H84,'BLS LF projections 2019-2029'!H100)/SUM('BLS LF projections 2019-2029'!H$52,'BLS LF projections 2019-2029'!H$68,'BLS LF projections 2019-2029'!H$84,'BLS LF projections 2019-2029'!H$100,'BLS LF projections 2019-2029'!H$116,'BLS LF projections 2019-2029'!H$132) -> 0.12866203 | I10: =SUM('BLS LF projections 2019-2029'!I84,'BLS LF projections 2019-2029'!I100)/SUM('BLS LF projections 2019-2029'!I$52,'BLS LF projections 2019-2029'!I$68,'BLS LF projections 2019-2029'!I$84,'BLS LF projections 2019-2029'!I$100,'BLS LF projections 2019-2029'!I$116,'BLS LF projections 2019-2029'!I$132) -> 0.12905821 | ... AG10: =SUM('BLS LF projections 2019-2029'!AG84,'BLS LF projections 2019-2029'!AG100)/SUM('BLS LF projections 2019-2029'!AG$52,'BLS LF projections 2019-2029'!AG$68,'BLS LF projections 2019-2029'!AG$84,'BLS LF projections 2019-2029'!AG$100,'BLS LF projections 2019-2029'!AG$116,'BLS LF projections 2019-2029'!AG$132) -> 0.13776779
A11: Other (inc. Asian) | B11: =SUM('BLS LF projections 2019-2029'!B116,'BLS LF projections 2019-2029'!B132)/SUM('BLS LF projections 2019-2029'!B$52,'BLS LF projections 2019-2029'!B$68,'BLS LF projections 2019-2029'!B$84,'BLS LF projections 2019-2029'!B$100,'BLS LF projections 2019-2029'!B$116,'BLS LF projections 2019-2029'!B$132) -> 0.099708323 | C11: =SUM('BLS LF projections 2019-2029'!C116,'BLS LF projections 2019-2029'!C132)/SUM('BLS LF projections 2019-2029'!C$52,'BLS LF projections 2019-2029'!C$68,'BLS LF projections 2019-2029'!C$84,'BLS LF projections 2019-2029'!C$100,'BLS LF projections 2019-2029'!C$116,'BLS LF projections 2019-2029'!C$132) -> 0.10154681 | D11: =SUM('BLS LF projections 2019-2029'!D116,'BLS LF projections 2019-2029'!D132)/SUM('BLS LF projections 2019-2029'!D$52,'BLS LF projections 2019-2029'!D$68,'BLS LF projections 2019-2029'!D$84,'BLS LF projections 2019-2029'!D$100,'BLS LF projections 2019-2029'!D$116,'BLS LF projections 2019-2029'!D$132) -> 0.10341487 | E11: =SUM('BLS LF projections 2019-2029'!E116,'BLS LF projections 2019-2029'!E132)/SUM('BLS LF projections 2019-2029'!E$52,'BLS LF projections 2019-2029'!E$68,'BLS LF projections 2019-2029'!E$84,'BLS LF projections 2019-2029'!E$100,'BLS LF projections 2019-2029'!E$116,'BLS LF projections 2019-2029'!E$132) -> 0.10533105 | F11: =SUM('BLS LF projections 2019-2029'!F116,'BLS LF projections 2019-2029'!F132)/SUM('BLS LF projections 2019-2029'!F$52,'BLS LF projections 2019-2029'!F$68,'BLS LF projections 2019-2029'!F$84,'BLS LF projections 2019-2029'!F$100,'BLS LF projections 2019-2029'!F$116,'BLS LF projections 2019-2029'!F$132) -> 0.10724485 | G11: =SUM('BLS LF projections 2019-2029'!G116,'BLS LF projections 2019-2029'!G132)/SUM('BLS LF projections 2019-2029'!G$52,'BLS LF projections 2019-2029'!G$68,'BLS LF projections 2019-2029'!G$84,'BLS LF projections 2019-2029'!G$100,'BLS LF projections 2019-2029'!G$116,'BLS LF projections 2019-2029'!G$132) -> 0.10914215 | H11: =SUM('BLS LF projections 2019-2029'!H116,'BLS LF projections 2019-2029'!H132)/SUM('BLS LF projections 2019-2029'!H$52,'BLS LF projections 2019-2029'!H$68,'BLS LF projections 2019-2029'!H$84,'BLS LF projections 2019-2029'!H$100,'BLS LF projections 2019-2029'!H$116,'BLS LF projections 2019-2029'!H$132) -> 0.11104507 | I11: =SUM('BLS LF projections 2019-2029'!I116,'BLS LF projections 2019-2029'!I132)/SUM('BLS LF projections 2019-2029'!I$52,'BLS LF projections 2019-2029'!I$68,'BLS LF projections 2019-2029'!I$84,'BLS LF projections 2019-2029'!I$100,'BLS LF projections 2019-2029'!I$116,'BLS LF projections 2019-2029'!I$132) -> 0.11299986 | ... AG11: =SUM('BLS LF projections 2019-2029'!AG116,'BLS LF projections 2019-2029'!AG132)/SUM('BLS LF projections 2019-2029'!AG$52,'BLS LF projections 2019-2029'!AG$68,'BLS LF projections 2019-2029'!AG$84,'BLS LF projections 2019-2029'!AG$100,'BLS LF projections 2019-2029'!AG$116,'BLS LF projections 2019-2029'!AG$132) -> 0.15348393
A13: Hispanic Status
B14: 2019 | C14: 2020 | D14: 2021 | E14: 2022 | F14: 2023 | G14: 2024 | H14: 2025 | I14: 2026 | J14: 2027 | K14: 2028 | L14: 2029 | M14: 2030 | N14: 2031 | O14: 2032 | P14: 2033 | Q14: 2034 | R14: 2035 | S14: 2036 | T14: 2037 | U14: 2038 | V14: 2039 | W14: 2040 | X14: 2041 | Y14: 2042 | Z14: 2043 | AA14: 2044 | AB14: 2045 | AC14: 2046 | AD14: 2047 | AE14: 2048 | AF14: 2049 | AG14: 2050
A15: Hispanic | B15: =SUM('BLS LF projections 2019-2029'!B148,'BLS LF projections 2019-2029'!B164)/SUM('BLS LF projections 2019-2029'!B148,'BLS LF projections 2019-2029'!B164,'BLS LF projections 2019-2029'!B180,'BLS LF projections 2019-2029'!B196) -> 0.1776601 | C15: =SUM('BLS LF projections 2019-2029'!C148,'BLS LF projections 2019-2029'!C164)/SUM('BLS LF projections 2019-2029'!C148,'BLS LF projections 2019-2029'!C164,'BLS LF projections 2019-2029'!C180,'BLS LF projections 2019-2029'!C196) -> 0.18085288 | D15: =SUM('BLS LF projections 2019-2029'!D148,'BLS LF projections 2019-2029'!D164)/SUM('BLS LF projections 2019-2029'!D148,'BLS LF projections 2019-2029'!D164,'BLS LF projections 2019-2029'!D180,'BLS LF projections 2019-2029'!D196) -> 0.18404466 | E15: =SUM('BLS LF projections 2019-2029'!E148,'BLS LF projections 2019-2029'!E164)/SUM('BLS LF projections 2019-2029'!E148,'BLS LF projections 2019-2029'!E164,'BLS LF projections 2019-2029'!E180,'BLS LF projections 2019-2029'!E196) -> 0.18732218 | F15: =SUM('BLS LF projections 2019-2029'!F148,'BLS LF projections 2019-2029'!F164)/SUM('BLS LF projections 2019-2029'!F148,'BLS LF projections 2019-2029'!F164,'BLS LF projections 2019-2029'!F180,'BLS LF projections 2019-2029'!F196) -> 0.19057961 | G15: =SUM('BLS LF projections 2019-2029'!G148,'BLS LF projections 2019-2029'!G164)/SUM('BLS LF projections 2019-2029'!G148,'BLS LF projections 2019-2029'!G164,'BLS LF projections 2019-2029'!G180,'BLS LF projections 2019-2029'!G196) -> 0.19380493 | H15: =SUM('BLS LF projections 2019-2029'!H148,'BLS LF projections 2019-2029'!H164)/SUM('BLS LF projections 2019-2029'!H148,'BLS LF projections 2019-2029'!H164,'BLS LF projections 2019-2029'!H180,'BLS LF projections 2019-2029'!H196) -> 0.19702463 | I15: =SUM('BLS LF projections 2019-2029'!I148,'BLS LF projections 2019-2029'!I164)/SUM('BLS LF projections 2019-2029'!I148,'BLS LF projections 2019-2029'!I164,'BLS LF projections 2019-2029'!I180,'BLS LF projections 2019-2029'!I196) -> 0.20024369 | ... AG15: =SUM('BLS LF projections 2019-2029'!AG148,'BLS LF projections 2019-2029'!AG164)/SUM('BLS LF projections 2019-2029'!AG148,'BLS LF projections 2019-2029'!AG164,'BLS LF projections 2019-2029'!AG180,'BLS LF projections 2019-2029'!AG196) -> 0.26822829
A16: Non-Hispanic | B16: =SUM('BLS LF projections 2019-2029'!B180,'BLS LF projections 2019-2029'!B196)/SUM('BLS LF projections 2019-2029'!B148,'BLS LF projections 2019-2029'!B164,'BLS LF projections 2019-2029'!B180,'BLS LF projections 2019-2029'!B196) -> 0.8223399 | C16: =SUM('BLS LF projections 2019-2029'!C180,'BLS LF projections 2019-2029'!C196)/SUM('BLS LF projections 2019-2029'!C148,'BLS LF projections 2019-2029'!C164,'BLS LF projections 2019-2029'!C180,'BLS LF projections 2019-2029'!C196) -> 0.81914712 | D16: =SUM('BLS LF projections 2019-2029'!D180,'BLS LF projections 2019-2029'!D196)/SUM('BLS LF projections 2019-2029'!D148,'BLS LF projections 2019-2029'!D164,'BLS LF projections 2019-2029'!D180,'BLS LF projections 2019-2029'!D196) -> 0.81595534 | E16: =SUM('BLS LF projections 2019-2029'!E180,'BLS LF projections 2019-2029'!E196)/SUM('BLS LF projections 2019-2029'!E148,'BLS LF projections 2019-2029'!E164,'BLS LF projections 2019-2029'!E180,'BLS LF projections 2019-2029'!E196) -> 0.81267782 | F16: =SUM('BLS LF projections 2019-2029'!F180,'BLS LF projections 2019-2029'!F196)/SUM('BLS LF projections 2019-2029'!F148,'BLS LF projections 2019-2029'!F164,'BLS LF projections 2019-2029'!F180,'BLS LF projections 2019-2029'!F196) -> 0.80942039 | G16: =SUM('BLS LF projections 2019-2029'!G180,'BLS LF projections 2019-2029'!G196)/SUM('BLS LF projections 2019-2029'!G148,'BLS LF projections 2019-2029'!G164,'BLS LF projections 2019-2029'!G180,'BLS LF projections 2019-2029'!G196) -> 0.80619507 | H16: =SUM('BLS LF projections 2019-2029'!H180,'BLS LF projections 2019-2029'!H196)/SUM('BLS LF projections 2019-2029'!H148,'BLS LF projections 2019-2029'!H164,'BLS LF projections 2019-2029'!H180,'BLS LF projections 2019-2029'!H196) -> 0.80297537 | I16: =SUM('BLS LF projections 2019-2029'!I180,'BLS LF projections 2019-2029'!I196)/SUM('BLS LF projections 2019-2029'!I148,'BLS LF projections 2019-2029'!I164,'BLS LF projections 2019-2029'!I180,'BLS LF projections 2019-2029'!I196) -> 0.79975631 | ... AG16: =SUM('BLS LF projections 2019-2029'!AG180,'BLS LF projections 2019-2029'!AG196)/SUM('BLS LF projections 2019-2029'!AG148,'BLS LF projections 2019-2029'!AG164,'BLS LF projections 2019-2029'!AG180,'BLS LF projections 2019-2029'!AG196) -> 0.73177171
A18: Age Bracket
B19: 2019 | C19: 2020 | D19: 2021 | E19: 2022 | F19: 2023 | G19: 2024 | H19: 2025 | I19: 2026 | J19: 2027 | K19: 2028 | L19: 2029 | M19: 2030 | N19: 2031 | O19: 2032 | P19: 2033 | Q19: 2034 | R19: 2035 | S19: 2036 | T19: 2037 | U19: 2038 | V19: 2039 | W19: 2040 | X19: 2041 | Y19: 2042 | Z19: 2043 | AA19: 2044 | AB19: 2045 | AC19: 2046 | AD19: 2047 | AE19: 2048 | AF19: 2049 | AG19: 2050
A20: 16 to 19 years | B20: =SUM('BLS LF projections 2019-2029'!B5:B6)/SUM('BLS LF projections 2019-2029'!B5:B18) -> 0.036053003 | C20: =SUM('BLS LF projections 2019-2029'!C5:C6)/SUM('BLS LF projections 2019-2029'!C5:C18) -> 0.034891504 | D20: =SUM('BLS LF projections 2019-2029'!D5:D6)/SUM('BLS LF projections 2019-2029'!D5:D18) -> 0.033912159 | E20: =SUM('BLS LF projections 2019-2029'!E5:E6)/SUM('BLS LF projections 2019-2029'!E5:E18) -> 0.033279886 | F20: =SUM('BLS LF projections 2019-2029'!F5:F6)/SUM('BLS LF projections 2019-2029'!F5:F18) -> 0.032637585 | G20: =SUM('BLS LF projections 2019-2029'!G5:G6)/SUM('BLS LF projections 2019-2029'!G5:G18) -> 0.031906763 | H20: =SUM('BLS LF projections 2019-2029'!H5:H6)/SUM('BLS LF projections 2019-2029'!H5:H18) -> 0.03110345 | I20: =SUM('BLS LF projections 2019-2029'!I5:I6)/SUM('BLS LF projections 2019-2029'!I5:I18) -> 0.030271664 | ... AG20: =SUM('BLS LF projections 2019-2029'!AG5:AG6)/SUM('BLS LF projections 2019-2029'!AG5:AG18) -> 0.012516333
A21: 20 to 24 years | B21: ='BLS LF projections 2019-2029'!B7/SUM('BLS LF projections 2019-2029'!B5:B18) -> 0.092914753 | C21: ='BLS LF projections 2019-2029'!C7/SUM('BLS LF projections 2019-2029'!C5:C18) -> 0.092242817 | D21: ='BLS LF projections 2019-2029'!D7/SUM('BLS LF projections 2019-2029'!D5:D18) -> 0.091631247 | E21: ='BLS LF projections 2019-2029'!E7/SUM('BLS LF projections 2019-2029'!E5:E18) -> 0.090743598 | F21: ='BLS LF projections 2019-2029'!F7/SUM('BLS LF projections 2019-2029'!F5:F18) -> 0.089927345 | G21: ='BLS LF projections 2019-2029'!G7/SUM('BLS LF projections 2019-2029'!G5:G18) -> 0.089218332 | H21: ='BLS LF projections 2019-2029'!H7/SUM('BLS LF projections 2019-2029'!H5:H18) -> 0.088222533 | I21: ='BLS LF projections 2019-2029'!I7/SUM('BLS LF projections 2019-2029'!I5:I18) -> 0.087502736 | ... AG21: ='BLS LF projections 2019-2029'!AG7/SUM('BLS LF projections 2019-2029'!AG5:AG18) -> 0.073195256
A22: 25 to 34 years | B22: =SUM('BLS LF projections 2019-2029'!B8:B9)/SUM('BLS LF projections 2019-2029'!B5:B18) -> 0.22741643 | C22: =SUM('BLS LF projections 2019-2029'!C8:C9)/SUM('BLS LF projections 2019-2029'!C5:C18) -> 0.22747021 | D22: =SUM('BLS LF projections 2019-2029'!D8:D9)/SUM('BLS LF projections 2019-2029'!D5:D18) -> 0.22721328 | E22: =SUM('BLS LF projections 2019-2029'!E8:E9)/SUM('BLS LF projections 2019-2029'!E5:E18) -> 0.22702175 | F22: =SUM('BLS LF projections 2019-2029'!F8:F9)/SUM('BLS LF projections 2019-2029'!F5:F18) -> 0.22633325 | G22: =SUM('BLS LF projections 2019-2029'!G8:G9)/SUM('BLS LF projections 2019-2029'!G5:G18) -> 0.22505493 | H22: =SUM('BLS LF projections 2019-2029'!H8:H9)/SUM('BLS LF projections 2019-2029'!H5:H18) -> 0.22319831 | I22: =SUM('BLS LF projections 2019-2029'!I8:I9)/SUM('BLS LF projections 2019-2029'!I5:I18) -> 0.22080926 | ... AG22: =SUM('BLS LF projections 2019-2029'!AG8:AG9)/SUM('BLS LF projections 2019-2029'!AG5:AG18) -> 0.19134548
A23: 35 to 44 years | B23: =SUM('BLS LF projections 2019-2029'!B10:B11)/SUM('BLS LF projections 2019-2029'!B5:B18) -> 0.20825257 | C23: =SUM('BLS LF projections 2019-2029'!C10:C11)/SUM('BLS LF projections 2019-2029'!C5:C18) -> 0.20976889 | D23: =SUM('BLS LF projections 2019-2029'!D10:D11)/SUM('BLS LF projections 2019-2029'!D5:D18) -> 0.21176179 | E23: =SUM('BLS LF projections 2019-2029'!E10:E11)/SUM('BLS LF projections 2019-2029'!E5:E18) -> 0.2132782 | F23: =SUM('BLS LF projections 2019-2029'!F10:F11)/SUM('BLS LF projections 2019-2029'!F5:F18) -> 0.21500609 | G23: =SUM('BLS LF projections 2019-2029'!G10:G11)/SUM('BLS LF projections 2019-2029'!G5:G18) -> 0.21693494 | H23: =SUM('BLS LF projections 2019-2029'!H10:H11)/SUM('BLS LF projections 2019-2029'!H5:H18) -> 0.21862165 | I23: =SUM('BLS LF projections 2019-2029'!I10:I11)/SUM('BLS LF projections 2019-2029'!I5:I18) -> 0.22076785 | ... AG23: =SUM('BLS LF projections 2019-2029'!AG10:AG11)/SUM('BLS LF projections 2019-2029'!AG5:AG18) -> 0.25608762
A24: 45 to 54 years | B24: =SUM('BLS LF projections 2019-2029'!B12:B13)/SUM('BLS LF projections 2019-2029'!B5:B18) -> 0.20136727 | C24: =SUM('BLS LF projections 2019-2029'!C12:C13)/SUM('BLS LF projections 2019-2029'!C5:C18) -> 0.19817693 | D24: =SUM('BLS LF projections 2019-2029'!D12:D13)/SUM('BLS LF projections 2019-2029'!D5:D18) -> 0.19567455 | E24: =SUM('BLS LF projections 2019-2029'!E12:E13)/SUM('BLS LF projections 2019-2029'!E5:E18) -> 0.19435068 | F24: =SUM('BLS LF projections 2019-2029'!F12:F13)/SUM('BLS LF projections 2019-2029'!F5:F18) -> 0.19331769 | G24: =SUM('BLS LF projections 2019-2029'!G12:G13)/SUM('BLS LF projections 2019-2029'!G5:G18) -> 0.19236005 | H24: =SUM('BLS LF projections 2019-2029'!H12:H13)/SUM('BLS LF projections 2019-2029'!H5:H18) -> 0.1917739 | I24: =SUM('BLS LF projections 2019-2029'!I12:I13)/SUM('BLS LF projections 2019-2029'!I5:I18) -> 0.19106992 | ... AG24: =SUM('BLS LF projections 2019-2029'!AG12:AG13)/SUM('BLS LF projections 2019-2029'!AG5:AG18) -> 0.17916097
A25: 55 to 64 years | B25: =SUM('BLS LF projections 2019-2029'!B14:B15)/SUM('BLS LF projections 2019-2029'!B5:B18) -> 0.16878749 | C25: =SUM('BLS LF projections 2019-2029'!C14:C15)/SUM('BLS LF projections 2019-2029'!C5:C18) -> 0.16893232 | D25: =SUM('BLS LF projections 2019-2029'!D14:D15)/SUM('BLS LF projections 2019-2029'!D5:D18) -> 0.16797447 | E25: =SUM('BLS LF projections 2019-2029'!E14:E15)/SUM('BLS LF projections 2019-2029'!E5:E18) -> 0.16640546 | F25: =SUM('BLS LF projections 2019-2029'!F14:F15)/SUM('BLS LF projections 2019-2029'!F5:F18) -> 0.16467581 | G25: =SUM('BLS LF projections 2019-2029'!G14:G15)/SUM('BLS LF projections 2019-2029'!G5:G18) -> 0.16330125 | H25: =SUM('BLS LF projections 2019-2029'!H14:H15)/SUM('BLS LF projections 2019-2029'!H5:H18) -> 0.16254272 | I25: =SUM('BLS LF projections 2019-2029'!I14:I15)/SUM('BLS LF projections 2019-2029'!I5:I18) -> 0.16186291 | ... AG25: =SUM('BLS LF projections 2019-2029'!AG14:AG15)/SUM('BLS LF projections 2019-2029'!AG5:AG18) -> 0.13430898
A26: 65 years and over | B26: =SUM('BLS LF projections 2019-2029'!B16:B18)/SUM('BLS LF projections 2019-2029'!B5:B18) -> 0.065208485 | C26: =SUM('BLS LF projections 2019-2029'!C16:C18)/SUM('BLS LF projections 2019-2029'!C5:C18) -> 0.068517324 | D26: =SUM('BLS LF projections 2019-2029'!D16:D18)/SUM('BLS LF projections 2019-2029'!D5:D18) -> 0.071832504 | E26: =SUM('BLS LF projections 2019-2029'!E16:E18)/SUM('BLS LF projections 2019-2029'!E5:E18) -> 0.074920432 | F26: =SUM('BLS LF projections 2019-2029'!F16:F18)/SUM('BLS LF projections 2019-2029'!F5:F18) -> 0.07810222 | G26: =SUM('BLS LF projections 2019-2029'!G16:G18)/SUM('BLS LF projections 2019-2029'!G5:G18) -> 0.081223729 | H26: =SUM('BLS LF projections 2019-2029'!H16:H18)/SUM('BLS LF projections 2019-2029'!H5:H18) -> 0.084537431 | I26: =SUM('BLS LF projections 2019-2029'!I16:I18)/SUM('BLS LF projections 2019-2029'!I5:I18) -> 0.087715666 | ... AG26: =SUM('BLS LF projections 2019-2029'!AG16:AG18)/SUM('BLS LF projections 2019-2029'!AG5:AG18) -> 0.15338535
A29: If Positive: Fraction of Jobs Not Held by People with This Trait in 2020 Held by People with This Trait in Each Year
A30: If Negative: Fraction of Jobs Held by People with This Trait in 2020 No Longer Held by People with This Trait in Each Year
A31: Sex
C32: 2020 | D32: 2021 | E32: 2022 | F32: 2023 | G32: 2024 | H32: 2025 | I32: 2026 | J32: 2027 | K32: 2028 | L32: 2029 | M32: 2030 | N32: 2031 | O32: 2032 | P32: 2033 | Q32: 2034 | R32: 2035 | S32: 2036 | T32: 2037 | U32: 2038 | V32: 2039 | W32: 2040 | X32: 2041 | Y32: 2042 | Z32: 2043 | AA32: 2044 | AB32: 2045 | AC32: 2046 | AD32: 2047 | AE32: 2048 | AF32: 2049 | AG32: 2050
A33: Men | C33: =IF(C4>=$C4,(C4-$C4)/(1-$C4),(C4-$C4)/$C4) -> 0 | D33: =IF(D4>=$C4,(D4-$C4)/(1-$C4),(D4-$C4)/$C4) -> -0.0011240186 | E33: =IF(E4>=$C4,(E4-$C4)/(1-$C4),(E4-$C4)/$C4) -> -0.0022995996 | F33: =IF(F4>=$C4,(F4-$C4)/(1-$C4),(F4-$C4)/$C4) -> -0.003445842 | G33: =IF(G4>=$C4,(G4-$C4)/(1-$C4),(G4-$C4)/$C4) -> -0.0045714556 | H33: =IF(H4>=$C4,(H4-$C4)/(1-$C4),(H4-$C4)/$C4) -> -0.0057340456 | I33: =IF(I4>=$C4,(I4-$C4)/(1-$C4),(I4-$C4)/$C4) -> -0.0069428843 | J33: =IF(J4>=$C4,(J4-$C4)/(1-$C4),(J4-$C4)/$C4) -> -0.0082189745 | ... AG33: =IF(AG4>=$C4,(AG4-$C4)/(1-$C4),(AG4-$C4)/$C4) -> -0.032264089
A34: Women | C34: =IF(C5>=$C5,(C5-$C5)/(1-$C5),(C5-$C5)/$C5) -> 0 | D34: =IF(D5>=$C5,(D5-$C5)/(1-$C5),(D5-$C5)/$C5) -> 0.0011240186 | E34: =IF(E5>=$C5,(E5-$C5)/(1-$C5),(E5-$C5)/$C5) -> 0.0022995996 | F34: =IF(F5>=$C5,(F5-$C5)/(1-$C5),(F5-$C5)/$C5) -> 0.003445842 | G34: =IF(G5>=$C5,(G5-$C5)/(1-$C5),(G5-$C5)/$C5) -> 0.0045714556 | H34: =IF(H5>=$C5,(H5-$C5)/(1-$C5),(H5-$C5)/$C5) -> 0.0057340456 | I34: =IF(I5>=$C5,(I5-$C5)/(1-$C5),(I5-$C5)/$C5) -> 0.0069428843 | J34: =IF(J5>=$C5,(J5-$C5)/(1-$C5),(J5-$C5)/$C5) -> 0.0082189745 | ... AG34: =IF(AG5>=$C5,(AG5-$C5)/(1-$C5),(AG5-$C5)/$C5) -> 0.032264089
A36: Race
C37: 2020 | D37: 2021 | E37: 2022 | F37: 2023 | G37: 2024 | H37: 2025 | I37: 2026 | J37: 2027 | K37: 2028 | L37: 2029 | M37: 2030 | N37: 2031 | O37: 2032 | P37: 2033 | Q37: 2034 | R37: 2035 | S37: 2036 | T37: 2037 | U37: 2038 | V37: 2039 | W37: 2040 | X37: 2041 | Y37: 2042 | Z37: 2043 | AA37: 2044 | AB37: 2045 | AC37: 2046 | AD37: 2047 | AE37: 2048 | AF37: 2049 | AG37: 2050
A38: White | C38: =IF(C9>=$C9,(C9-$C9)/(1-$C9),(C9-$C9)/$C9) -> 0 | D38: =IF(D9>=$C9,(D9-$C9)/(1-$C9),(D9-$C9)/$C9) -> -0.0029374961 | E38: =IF(E9>=$C9,(E9-$C9)/(1-$C9),(E9-$C9)/$C9) -> -0.0059865214 | F38: =IF(F9>=$C9,(F9-$C9)/(1-$C9),(F9-$C9)/$C9) -> -0.0090146419 | G38: =IF(G9>=$C9,(G9-$C9)/(1-$C9),(G9-$C9)/$C9) -> -0.012015826 | H38: =IF(H9>=$C9,(H9-$C9)/(1-$C9),(H9-$C9)/$C9) -> -0.015002089 | I38: =IF(I9>=$C9,(I9-$C9)/(1-$C9),(I9-$C9)/$C9) -> -0.018047893 | J38: =IF(J9>=$C9,(J9-$C9)/(1-$C9),(J9-$C9)/$C9) -> -0.02106788 | ... AG38: =IF(AG9>=$C9,(AG9-$C9)/(1-$C9),(AG9-$C9)/$C9) -> -0.081780746
A39: Black | C39: =IF(C10>=$C10,(C10-$C10)/(1-$C10),(C10-$C10)/$C10) -> 0 | D39: =IF(D10>=$C10,(D10-$C10)/(1-$C10),(D10-$C10)/$C10) -> 0.00045718512 | E39: =IF(E10>=$C10,(E10-$C10)/(1-$C10),(E10-$C10)/$C10) -> 0.00095783663 | F39: =IF(F10>=$C10,(F10-$C10)/(1-$C10),(F10-$C10)/$C10) -> 0.001442744 | G39: =IF(G10>=$C10,(G10-$C10)/(1-$C10),(G10-$C10)/$C10) -> 0.0019227316 | H39: =IF(H10>=$C10,(H10-$C10)/(1-$C10),(H10-$C10)/$C10) -> 0.0023830965 | I39: =IF(I10>=$C10,(I10-$C10)/(1-$C10),(I10-$C10)/$C10) -> 0.0028366926 | J39: =IF(J10>=$C10,(J10-$C10)/(1-$C10),(J10-$C10)/$C10) -> 0.0033011117 | ... AG39: =IF(AG10>=$C10,(AG10-$C10)/(1-$C10),(AG10-$C10)/$C10) -> 0.012808512
A40: Other (inc. Asian) | C40: =IF(C11>=$C11,(C11-$C11)/(1-$C11),(C11-$C11)/$C11) -> 0 | D40: =IF(D11>=$C11,(D11-$C11)/(1-$C11),(D11-$C11)/$C11) -> 0.0020791939 | E40: =IF(E11>=$C11,(E11-$C11)/(1-$C11),(E11-$C11)/$C11) -> 0.0042119487 | F40: =IF(F11>=$C11,(F11-$C11)/(1-$C11),(F11-$C11)/$C11) -> 0.0063420494 | G40: =IF(G11>=$C11,(G11-$C11)/(1-$C11),(G11-$C11)/$C11) -> 0.008453791 | H40: =IF(H11>=$C11,(H11-$C11)/(1-$C11),(H11-$C11)/$C11) -> 0.01057179 | I40: =IF(I11>=$C11,(I11-$C11)/(1-$C11),(I11-$C11)/$C11) -> 0.012747522 | J40: =IF(J11>=$C11,(J11-$C11)/(1-$C11),(J11-$C11)/$C11) -> 0.014890553 | ... AG40: =IF(AG11>=$C11,(AG11-$C11)/(1-$C11),(AG11-$C11)/$C11) -> 0.057807257
A42: Hispanic Status
C43: 2020 | D43: 2021 | E43: 2022 | F43: 2023 | G43: 2024 | H43: 2025 | I43: 2026 | J43: 2027 | K43: 2028 | L43: 2029 | M43: 2030 | N43: 2031 | O43: 2032 | P43: 2033 | Q43: 2034 | R43: 2035 | S43: 2036 | T43: 2037 | U43: 2038 | V43: 2039 | W43: 2040 | X43: 2041 | Y43: 2042 | Z43: 2043 | AA43: 2044 | AB43: 2045 | AC43: 2046 | AD43: 2047 | AE43: 2048 | AF43: 2049 | AG43: 2050
A44: Hispanic | C44: =IF(C15>=$C15,(C15-$C15)/(1-$C15),(C15-$C15)/$C15) -> 0 | D44: =IF(D15>=$C15,(D15-$C15)/(1-$C15),(D15-$C15)/$C15) -> 0.0038964711 | E44: =IF(E15>=$C15,(E15-$C15)/(1-$C15),(E15-$C15)/$C15) -> 0.0078976061 | F44: =IF(F15>=$C15,(F15-$C15)/(1-$C15),(F15-$C15)/$C15) -> 0.011874221 | G44: =IF(G15>=$C15,(G15-$C15)/(1-$C15),(G15-$C15)/$C15) -> 0.015811632 | H44: =IF(H15>=$C15,(H15-$C15)/(1-$C15),(H15-$C15)/$C15) -> 0.019742185 | I44: =IF(I15>=$C15,(I15-$C15)/(1-$C15),(I15-$C15)/$C15) -> 0.023671952 | J44: =IF(J15>=$C15,(J15-$C15)/(1-$C15),(J15-$C15)/$C15) -> 0.027565075 | ... AG44: =IF(AG15>=$C15,(AG15-$C15)/(1-$C15),(AG15-$C15)/$C15) -> 0.10666632
A45: Non-Hispanic | C45: =IF(C16>=$C16,(C16-$C16)/(1-$C16),(C16-$C16)/$C16) -> 0 | D45: =IF(D16>=$C16,(D16-$C16)/(1-$C16),(D16-$C16)/$C16) -> -0.0038964711 | E45: =IF(E16>=$C16,(E16-$C16)/(1-$C16),(E16-$C16)/$C16) -> -0.0078976061 | F45: =IF(F16>=$C16,(F16-$C16)/(1-$C16),(F16-$C16)/$C16) -> -0.011874221 | G45: =IF(G16>=$C16,(G16-$C16)/(1-$C16),(G16-$C16)/$C16) -> -0.015811632 | H45: =IF(H16>=$C16,(H16-$C16)/(1-$C16),(H16-$C16)/$C16) -> -0.019742185 | I45: =IF(I16>=$C16,(I16-$C16)/(1-$C16),(I16-$C16)/$C16) -> -0.023671952 | J45: =IF(J16>=$C16,(J16-$C16)/(1-$C16),(J16-$C16)/$C16) -> -0.027565075 | ... AG45: =IF(AG16>=$C16,(AG16-$C16)/(1-$C16),(AG16-$C16)/$C16) -> -0.10666632
A47: Age Bracket
C48: 2020 | D48: 2021 | E48: 2022 | F48: 2023 | G48: 2024 | H48: 2025 | I48: 2026 | J48: 2027 | K48: 2028 | L48: 2029 | M48: 2030 | N48: 2031 | O48: 2032 | P48: 2033 | Q48: 2034 | R48: 2035 | S48: 2036 | T48: 2037 | U48: 2038 | V48: 2039 | W48: 2040 | X48: 2041 | Y48: 2042 | Z48: 2043 | AA48: 2044 | AB48: 2045 | AC48: 2046 | AD48: 2047 | AE48: 2048 | AF48: 2049 | AG48: 2050
...

Sheet S Curve Equation
A1: We model growth or shrinkage in the percentage of jobs held by people with a given demographic
A2: characteristic along an S-curve, which more realistically represents the change near the extremes.
A3: For example, suppose people with a certain characteristic are 10% of the labor force but only hold
A4: 0.1% of the jobs in a given industry. If they increase to be 15% of the labor force, a linear estimate
A5: would suggest they become around 5% of the jobs in that industry, but this growth is too rapid for
A6: starting from such a small base. An S-curve slows down the changes as they approach 0% or 100%,
A7: making for more realistic behavior that approaches asymptotes.
A9: Sigmoid Property | B9: Value | C9: Note
A10: Steepness | B10: 4.5 | C10: Only this value may be edited
A11: Horizontal Shift | B11: 1 | C11: positive is rightward
A12: Horizontal Compression | B12: 2 | C12: positive is more compressed
A13: Y-shift | B13: =-1/(1+EXP(($B$11-A17*$B$12)*$B$10)) -> -0.010986943 | C13: Calculated to align 0% X and 0% Y
A14: Y-stretch | B14: =1/(1/(1+EXP(($B$11-A67*$B$12)*$B$10))+$B$13) -> 1.0224676 | C14: Calculated to align 100% X and 100% Y
A16: % w Factor (Avg) | C16: % w Factor (This Industry)
A17: 0 | C17: =(1/(1+EXP(($B$11-A17*$B$12)*$B$10))+$B$13)*$B$14 -> 0
A18: 0.02 | C18: =(1/(1+EXP(($B$11-A18*$B$12)*$B$10))+$B$13)*$B$14 -> 0.0021864198
A19: 0.04 | C19: =(1/(1+EXP(($B$11-A19*$B$12)*$B$10))+$B$13)*$B$14 -> 0.0047916363
A20: 0.06 | C20: =(1/(1+EXP(($B$11-A20*$B$12)*$B$10))+$B$13)*$B$14 -> 0.0078930074
A21: 0.08 | C21: =(1/(1+EXP(($B$11-A21*$B$12)*$B$10))+$B$13)*$B$14 -> 0.011580975
A22: 0.1 | C22: =(1/(1+EXP(($B$11-A22*$B$12)*$B$10))+$B$13)*$B$14 -> 0.015960771
A23: 0.12 | C23: =(1/(1+EXP(($B$11-A23*$B$12)*$B$10))+$B$13)*$B$14 -> 0.021154124
A24: 0.14 | C24: =(1/(1+EXP(($B$11-A24*$B$12)*$B$10))+$B$13)*$B$14 -> 0.027300854
A25: 0.16 | C25: =(1/(1+EXP(($B$11-A25*$B$12)*$B$10))+$B$13)*$B$14 -> 0.034560182
A26: 0.18 | C26: =(1/(1+EXP(($B$11-A26*$B$12)*$B$10))+$B$13)*$B$14 -> 0.043111521
A27: 0.2 | C27: =(1/(1+EXP(($B$11-A27*$B$12)*$B$10))+$B$13)*$B$14 -> 0.053154423
A28: 0.22 | C28: =(1/(1+EXP(($B$11-A28*$B$12)*$B$10))+$B$13)*$B$14 -> 0.064907267
... A67: 1 | C67: =(1/(1+EXP(($B$11-A67*$B$12)*$B$10))+$B$13)*$B$14 -> 1

Sheet S

Sheet Calculations male
A1: Fraction of Workers with This Demographic Trait in the Year for Which We Have Present-Day Data Disaggregated by ISIC Code
B2: 2020
A3: ISIC 01T03 | B3: =1-'Calculations female'!B3 -> 0.723
A4: ISIC 05 | B4: =1-'Calculations female'!B4 -> 0.899
A5: ISIC 06 | B5: =1-'Calculations female'!B5 -> 0.851
A6: ISIC 07T08 | B6: =1-'Calculations female'!B6 -> 0.893
A7: ISIC 09 | B7: =1-'Calculations female'!B7 -> 0.848
A8: ISIC 10T12 | B8: =1-'Calculations female'!B8 -> 0.60319417
