Workbook

Sheet About
A1: CSC Capacity Supply Curve Capacity Cost Multiplier vs Share of Existing Capacity Built this Year
A2: CSC Capacity Supply Curve Minimum Buildable Capacity for Plant Types with No Existing Capacity
A3: CSC Capacity Supply Curve Share of Cost Effective Capacity Built in a Single Year
A5: Source: | B5: (none)
A7: Notes:
A8: For the Share of Cost Effective Capacity Built in a Single Year, we use a value of 1 for all resources except wind,
A9: which in recent years has faced unique siting constraints that have limited new capacity.
A10: For onshore wind, we use a long-term value of 0.8, reflecting high permitting, siting, and interconnection challenges
A11: In the near-term we limit that to 0.2 based on permitting and other challenges in the current administration (through 2029).
A12: Update 2026-09-24 (solar PV): Share of Cost Effective Capacity Built in a Single Year for solar PV set to 0.5 in all years (deployed CSV had carried 0.75 since the 2026-09-11 calibration while this workbook still showed 1.0; both now 0.5). Rationale: at 0.75 the economic channel added 38-45 GW/yr of solar in 2027-2029 on top of the mandated pipeline (52/47/42 GW/yr total; 2030 capacity 360 GW) against ICF's forecast of 34-39 GW/yr and 2025's record ~30 GW, with solar curtailment of 53-57 TWh/yr. At 0.5, additions are 41/32/28 GW/yr and 2030 capacity 313 GW, between ReEDS StdScen24 Mid (~330) and Rhodium TS2026 Mid (262). Same 'reflect real-world builds' logic as the onshore wind values. Decision: Megan, 2026-09-24. A post-2030 dip in economic solar (profitability saturation via the CSC saturation parameter) is unaffected by this share.
A15: These are calibrated variables used in establishing supply curves for resources.
A17: Supply Curve Parameters
A18: saturation | B18: 0.2
A19: scale parameter | B19: 0.6
A20: shape parameter | B20: 3
A21: location parameter | B21: 0.5
A22: cutoff parameter | B22: 30000
A23: Minimum capacity buildable for plants types with no existing capacity (share if installed) | B23: 0.004
B26: =(1-EXP(-((C26/$B$22-($B$21-0.5))/$B$19)^$B$20))*$B$18 -> 0 | C26: 0
B27: =(1-EXP(-((C27/$B$22-($B$21-0.5))/$B$19)^$B$20))*$B$18 -> 4.2866482e-06 | C27: 500
B28: =(1-EXP(-((C28/$B$22-($B$21-0.5))/$B$19)^$B$20))*$B$18 -> 3.4290613e-05 | C28: 1000
B29: =(1-EXP(-((C29/$B$22-($B$21-0.5))/$B$19)^$B$20))*$B$18 -> 0.00011570726 | C29: =C28+500 -> 1500
B30: =(1-EXP(-((C30/$B$22-($B$21-0.5))/$B$19)^$B$20))*$B$18 -> 0.00027416034 | C30: =C29+500 -> 2000
B31: =(1-EXP(-((C31/$B$22-($B$21-0.5))/$B$19)^$B$20))*$B$18 -> 0.0005351196 | C31: =C30+500 -> 2500
B32: =(1-EXP(-((C32/$B$22-($B$21-0.5))/$B$19)^$B$20))*$B$18 -> 0.00092378588 | C32: =C31+500 -> 3000
B33: =(1-EXP(-((C33/$B$22-($B$21-0.5))/$B$19)^$B$20))*$B$18 -> 0.0014649446 | C33: =C32+500 -> 3500
B34: =(1-EXP(-((C34/$B$22-($B$21-0.5))/$B$19)^$B$20))*$B$18 -> 0.0021827886 | C34: =C33+500 -> 4000
B35: =(1-EXP(-((C35/$B$22-($B$21-0.5))/$B$19)^$B$20))*$B$18 -> 0.0031007126 | C35: =C34+500 -> 4500
B36: =(1-EXP(-((C36/$B$22-($B$21-0.5))/$B$19)^$B$20))*$B$18 -> 0.0042410812 | C36: =C35+500 -> 5000
B37: =(1-EXP(-((C37/$B$22-($B$21-0.5))/$B$19)^$B$20))*$B$18 -> 0.0056249739 | C37: =C36+500 -> 5500
B38: =(1-EXP(-((C38/$B$22-($B$21-0.5))/$B$19)^$B$20))*$B$18 -> 0.0072719111 | C38: =C37+500 -> 6000
B39: =(1-EXP(-((C39/$B$22-($B$21-0.5))/$B$19)^$B$20))*$B$18 -> 0.0091995663 | C39: =C38+500 -> 6500
B40: =(1-EXP(-((C40/$B$22-($B$21-0.5))/$B$19)^$B$20))*$B$18 -> 0.011423469 | C40: =C39+500 -> 7000
... B127: =(1-EXP(-((C127/$B$22-($B$21-0.5))/$B$19)^$B$20))*$B$18 -> 0.2 | C127: =C126+500 -> 50500
A129: Added 2026-08 (seed redesign prototype):
A130: CSCSCbPT CSC Seed Capacity by Plant Type - growth basis for the annual build soft cap and entry floor.
A131: Semantics: largest recent observed annual addition (incumbent types) or typical first-project size (types never yet built).
A132: CSCPH CSC Procurement Headroom Factor - multiple of the annual build limit available for procurement on the supply curve (keeps mandates priced on the curve interior).
A133: ALL VALUES BELOW ARE DRAFT ENGINEERING PLACEHOLDERS - to be replaced by EIA-860-derived values per the build-cap-calibration plan.
A135: Electricity Source | B135: Seed (MW) | C135: Basis
...

Sheet CSC-CSCPH
A1: Multiple of annual build limit available for procurement
A2: Headroom | B2: 2

Sheet CSC-CSCP
A1: parameters | B1: value
A2: saturation | B2: =About!B18 -> 0.2
A3: scale parameter | B3: =About!B19 -> 0.6
A4: shape parameter | B4: =About!B20 -> 3
A5: location parameter | B5: =About!B21 -> 0.5
A6: cutoff parameter | B6: =About!B22 -> 30000

Sheet CSC-CSCSoCECBiaSY
A1: Time (Year) | B1: 2024 | C1: 2025 | D1: 2026 | E1: 2027 | F1: 2028 | G1: 2029 | H1: 2030 | I1: 2031 | J1: 2032 | K1: 2033 | L1: 2034 | M1: 2035 | N1: 2036 | O1: 2037 | P1: 2038 | Q1: 2039 | R1: 2040 | S1: 2041 | T1: 2042 | U1: 2043 | V1: 2044 | W1: 2045 | X1: 2046 | Y1: 2047 | Z1: 2048 | AA1: 2049 | AB1: 2050
A2: hard coal es | B2: 1 | C2: 1 | D2: 1 | E2: 1 | F2: 1 | G2: 1 | H2: 1 | I2: 1 | J2: 1 | K2: 1 | L2: 1 | M2: 1 | N2: 1 | O2: 1 | P2: 1 | Q2: 1 | R2: 1 | S2: 1 | T2: 1 | U2: 1 | V2: 1 | W2: 1 | X2: 1 | Y2: 1 | Z2: 1 | AA2: 1 | AB2: 1
A3: natural gas steam turbine es | B3: 1 | C3: 1 | D3: 1 | E3: 1 | F3: 1 | G3: 1 | H3: 1 | I3: 1 | J3: 1 | K3: 1 | L3: 1 | M3: 1 | N3: 1 | O3: 1 | P3: 1 | Q3: 1 | R3: 1 | S3: 1 | T3: 1 | U3: 1 | V3: 1 | W3: 1 | X3: 1 | Y3: 1 | Z3: 1 | AA3: 1 | AB3: 1
A4: natural gas combined cycle es | B4: 1 | C4: 1 | D4: 1 | E4: 1 | F4: 1 | G4: 1 | H4: 1 | I4: 1 | J4: 1 | K4: 1 | L4: 1 | M4: 1 | N4: 1 | O4: 1 | P4: 1 | Q4: 1 | R4: 1 | S4: 1 | T4: 1 | U4: 1 | V4: 1 | W4: 1 | X4: 1 | Y4: 1 | Z4: 1 | AA4: 1 | AB4: 1
A5: nuclear es | B5: 1 | C5: 1 | D5: 1 | E5: 1 | F5: 1 | G5: 1 | H5: 1 | I5: 1 | J5: 1 | K5: 1 | L5: 1 | M5: 1 | N5: 1 | O5: 1 | P5: 1 | Q5: 1 | R5: 1 | S5: 1 | T5: 1 | U5: 1 | V5: 1 | W5: 1 | X5: 1 | Y5: 1 | Z5: 1 | AA5: 1 | AB5: 1
A6: hydro es | B6: 1 | C6: 1 | D6: 1 | E6: 1 | F6: 1 | G6: 1 | H6: 1 | I6: 1 | J6: 1 | K6: 1 | L6: 1 | M6: 1 | N6: 1 | O6: 1 | P6: 1 | Q6: 1 | R6: 1 | S6: 1 | T6: 1 | U6: 1 | V6: 1 | W6: 1 | X6: 1 | Y6: 1 | Z6: 1 | AA6: 1 | AB6: 1
A7: onshore wind es | B7: 0.5 | C7: 0.1 | D7: 0.1 | E7: 0.1 | F7: 0.1 | G7: 0.1 | H7: =($J$7-$G$7)/3+G7 -> 0.23333333 | I7: =($J$7-$G$7)/3+H7 -> 0.36666667 | J7: 0.5 | K7: 0.5 | L7: 0.5 | M7: 0.5 | N7: 0.5 | O7: 0.5 | P7: 0.5 | Q7: 0.5 | R7: 0.5 | S7: 0.5 | T7: 0.5 | U7: 0.5 | V7: 0.5 | W7: 0.5 | X7: 0.5 | Y7: 0.5 | Z7: 0.5 | AA7: 0.5 | AB7: 0.5
A8: solar PV es | B8: 0.5 | C8: 0.5 | D8: 0.5 | E8: 0.5 | F8: 0.5 | G8: 0.5 | H8: 0.5 | I8: 0.5 | J8: 0.5 | K8: 0.5 | L8: 0.5 | M8: 0.5 | N8: 0.5 | O8: 0.5 | P8: 0.5 | Q8: 0.5 | R8: 0.5 | S8: 0.5 | T8: 0.5 | U8: 0.5 | V8: 0.5 | W8: 0.5 | X8: 0.5 | Y8: 0.5 | Z8: 0.5 | AA8: 0.5 | AB8: 0.5
A9: solar thermal es | B9: 1 | C9: 1 | D9: 1 | E9: 1 | F9: 1 | G9: 1 | H9: 1 | I9: 1 | J9: 1 | K9: 1 | L9: 1 | M9: 1 | N9: 1 | O9: 1 | P9: 1 | Q9: 1 | R9: 1 | S9: 1 | T9: 1 | U9: 1 | V9: 1 | W9: 1 | X9: 1 | Y9: 1 | Z9: 1 | AA9: 1 | AB9: 1
A10: biomass es | B10: 1 | C10: 1 | D10: 1 | E10: 1 | F10: 1 | G10: 1 | H10: 1 | I10: 1 | J10: 1 | K10: 1 | L10: 1 | M10: 1 | N10: 1 | O10: 1 | P10: 1 | Q10: 1 | R10: 1 | S10: 1 | T10: 1 | U10: 1 | V10: 1 | W10: 1 | X10: 1 | Y10: 1 | Z10: 1 | AA10: 1 | AB10: 1
A11: geothermal es | B11: 1 | C11: 1 | D11: 1 | E11: 1 | F11: 1 | G11: 1 | H11: 1 | I11: 1 | J11: 1 | K11: 1 | L11: 1 | M11: 1 | N11: 1 | O11: 1 | P11: 1 | Q11: 1 | R11: 1 | S11: 1 | T11: 1 | U11: 1 | V11: 1 | W11: 1 | X11: 1 | Y11: 1 | Z11: 1 | AA11: 1 | AB11: 1
A12: petroleum es | B12: 1 | C12: 1 | D12: 1 | E12: 1 | F12: 1 | G12: 1 | H12: 1 | I12: 1 | J12: 1 | K12: 1 | L12: 1 | M12: 1 | N12: 1 | O12: 1 | P12: 1 | Q12: 1 | R12: 1 | S12: 1 | T12: 1 | U12: 1 | V12: 1 | W12: 1 | X12: 1 | Y12: 1 | Z12: 1 | AA12: 1 | AB12: 1
A13: natural gas peaker es | B13: 1 | C13: 1 | D13: 1 | E13: 1 | F13: 1 | G13: 1 | H13: 1 | I13: 1 | J13: 1 | K13: 1 | L13: 1 | M13: 1 | N13: 1 | O13: 1 | P13: 1 | Q13: 1 | R13: 1 | S13: 1 | T13: 1 | U13: 1 | V13: 1 | W13: 1 | X13: 1 | Y13: 1 | Z13: 1 | AA13: 1 | AB13: 1
A14: lignite es | B14: 1 | C14: 1 | D14: 1 | E14: 1 | F14: 1 | G14: 1 | H14: 1 | I14: 1 | J14: 1 | K14: 1 | L14: 1 | M14: 1 | N14: 1 | O14: 1 | P14: 1 | Q14: 1 | R14: 1 | S14: 1 | T14: 1 | U14: 1 | V14: 1 | W14: 1 | X14: 1 | Y14: 1 | Z14: 1 | AA14: 1 | AB14: 1
A15: offshore wind es | B15: 1 | C15: 1 | D15: 1 | E15: 1 | F15: 1 | G15: 1 | H15: 1 | I15: 1 | J15: 1 | K15: 1 | L15: 1 | M15: 1 | N15: 1 | O15: 1 | P15: 1 | Q15: 1 | R15: 1 | S15: 1 | T15: 1 | U15: 1 | V15: 1 | W15: 1 | X15: 1 | Y15: 1 | Z15: 1 | AA15: 1 | AB15: 1
A16: crude oil es | B16: 1 | C16: 1 | D16: 1 | E16: 1 | F16: 1 | G16: 1 | H16: 1 | I16: 1 | J16: 1 | K16: 1 | L16: 1 | M16: 1 | N16: 1 | O16: 1 | P16: 1 | Q16: 1 | R16: 1 | S16: 1 | T16: 1 | U16: 1 | V16: 1 | W16: 1 | X16: 1 | Y16: 1 | Z16: 1 | AA16: 1 | AB16: 1
A17: heavy or residual fuel oil es | B17: 1 | C17: 1 | D17: 1 | E17: 1 | F17: 1 | G17: 1 | H17: 1 | I17: 1 | J17: 1 | K17: 1 | L17: 1 | M17: 1 | N17: 1 | O17: 1 | P17: 1 | Q17: 1 | R17: 1 | S17: 1 | T17: 1 | U17: 1 | V17: 1 | W17: 1 | X17: 1 | Y17: 1 | Z17: 1 | AA17: 1 | AB17: 1
A18: municipal solid waste es | B18: 1 | C18: 1 | D18: 1 | E18: 1 | F18: 1 | G18: 1 | H18: 1 | I18: 1 | J18: 1 | K18: 1 | L18: 1 | M18: 1 | N18: 1 | O18: 1 | P18: 1 | Q18: 1 | R18: 1 | S18: 1 | T18: 1 | U18: 1 | V18: 1 | W18: 1 | X18: 1 | Y18: 1 | Z18: 1 | AA18: 1 | AB18: 1
A19: hard coal w CCS es | B19: 1 | C19: 1 | D19: 1 | E19: 1 | F19: 1 | G19: 1 | H19: 1 | I19: 1 | J19: 1 | K19: 1 | L19: 1 | M19: 1 | N19: 1 | O19: 1 | P19: 1 | Q19: 1 | R19: 1 | S19: 1 | T19: 1 | U19: 1 | V19: 1 | W19: 1 | X19: 1 | Y19: 1 | Z19: 1 | AA19: 1 | AB19: 1
... A25: hydrogen combined cycle es | B25: 1 | C25: 1 | D25: 1 | E25: 1 | F25: 1 | G25: 1 | H25: 1 | I25: 1 | J25: 1 | K25: 1 | L25: 1 | M25: 1 | N25: 1 | O25: 1 | P25: 1 | Q25: 1 | R25: 1 | S25: 1 | T25: 1 | U25: 1 | V25: 1 | W25: 1 | X25: 1 | Y25: 1 | Z25: 1 | AA25: 1 | AB25: 1

Sheet CSC-CSCSCbPT
B1: Seed Capacity (MW)
A2: hard coal | B2: 1300
A3: natural gas steam turbine | B3: 600
A4: natural gas combined cycle | B4: 10000
A5: nuclear | B5: 2200
A6: hydro | B6: 500
A7: onshore wind | B7: 15000
A8: solar PV | B8: 30000
A9: solar thermal | B9: 400
A10: biomass | B10: 500
A11: geothermal | B11: 150
A12: petroleum | B12: 200
A13: natural gas peaker | B13: 5000
... A25: hydrogen combined cycle | B25: 800

Sheet CSC-ACSCSoCECBiaSY
A1: Time (Year) | B1: 2024 | C1: 2025 | D1: 2026 | E1: 2027 | F1: 2028 | G1: 2029 | H1: 2030 | I1: 2031 | J1: 2032 | K1: 2033 | L1: 2034 | M1: 2035 | N1: 2036 | O1: 2037 | P1: 2038 | Q1: 2039 | R1: 2040 | S1: 2041 | T1: 2042 | U1: 2043 | V1: 2044 | W1: 2045 | X1: 2046 | Y1: 2047 | Z1: 2048 | AA1: 2049 | AB1: 2050
A2: hard coal es | B2: 1 | C2: 1 | D2: 1 | E2: 1 | F2: 1 | G2: 1 | H2: 1 | I2: 1 | J2: 1 | K2: 1 | L2: 1 | M2: 1 | N2: 1 | O2: 1 | P2: 1 | Q2: 1 | R2: 1 | S2: 1 | T2: 1 | U2: 1 | V2: 1 | W2: 1 | X2: 1 | Y2: 1 | Z2: 1 | AA2: 1 | AB2: 1
A3: natural gas steam turbine es | B3: 1 | C3: 1 | D3: 1 | E3: 1 | F3: 1 | G3: 1 | H3: 1 | I3: 1 | J3: 1 | K3: 1 | L3: 1 | M3: 1 | N3: 1 | O3: 1 | P3: 1 | Q3: 1 | R3: 1 | S3: 1 | T3: 1 | U3: 1 | V3: 1 | W3: 1 | X3: 1 | Y3: 1 | Z3: 1 | AA3: 1 | AB3: 1
A4: natural gas combined cycle es | B4: 1 | C4: 1 | D4: 1 | E4: 1 | F4: 1 | G4: 1 | H4: 1 | I4: 1 | J4: 1 | K4: 1 | L4: 1 | M4: 1 | N4: 1 | O4: 1 | P4: 1 | Q4: 1 | R4: 1 | S4: 1 | T4: 1 | U4: 1 | V4: 1 | W4: 1 | X4: 1 | Y4: 1 | Z4: 1 | AA4: 1 | AB4: 1
A5: nuclear es | B5: 1 | C5: 1 | D5: 1 | E5: 1 | F5: 1 | G5: 1 | H5: 1 | I5: 1 | J5: 1 | K5: 1 | L5: 1 | M5: 1 | N5: 1 | O5: 1 | P5: 1 | Q5: 1 | R5: 1 | S5: 1 | T5: 1 | U5: 1 | V5: 1 | W5: 1 | X5: 1 | Y5: 1 | Z5: 1 | AA5: 1 | AB5: 1
A6: hydro es | B6: 1 | C6: 1 | D6: 1 | E6: 1 | F6: 1 | G6: 1 | H6: 1 | I6: 1 | J6: 1 | K6: 1 | L6: 1 | M6: 1 | N6: 1 | O6: 1 | P6: 1 | Q6: 1 | R6: 1 | S6: 1 | T6: 1 | U6: 1 | V6: 1 | W6: 1 | X6: 1 | Y6: 1 | Z6: 1 | AA6: 1 | AB6: 1
A7: onshore wind es | B7: 0.5 | C7: 0.5 | D7: 0.5 | E7: 0.5 | F7: 0.5 | G7: 0.5 | H7: 0.5 | I7: 0.5 | J7: 0.5 | K7: 0.5 | L7: 0.5 | M7: 0.5 | N7: 0.5 | O7: 0.5 | P7: 0.5 | Q7: 0.5 | R7: 0.5 | S7: 0.5 | T7: 0.5 | U7: 0.5 | V7: 0.5 | W7: 0.5 | X7: 0.5 | Y7: 0.5 | Z7: 0.5 | AA7: 0.5 | AB7: 0.5
A8: solar PV es | B8: 1 | C8: 1 | D8: 1 | E8: 1 | F8: 1 | G8: 1 | H8: 1 | I8: 1 | J8: 1 | K8: 1 | L8: 1 | M8: 1 | N8: 1 | O8: 1 | P8: 1 | Q8: 1 | R8: 1 | S8: 1 | T8: 1 | U8: 1 | V8: 1 | W8: 1 | X8: 1 | Y8: 1 | Z8: 1 | AA8: 1 | AB8: 1
A9: solar thermal es | B9: 1 | C9: 1 | D9: 1 | E9: 1 | F9: 1 | G9: 1 | H9: 1 | I9: 1 | J9: 1 | K9: 1 | L9: 1 | M9: 1 | N9: 1 | O9: 1 | P9: 1 | Q9: 1 | R9: 1 | S9: 1 | T9: 1 | U9: 1 | V9: 1 | W9: 1 | X9: 1 | Y9: 1 | Z9: 1 | AA9: 1 | AB9: 1
A10: biomass es | B10: 1 | C10: 1 | D10: 1 | E10: 1 | F10: 1 | G10: 1 | H10: 1 | I10: 1 | J10: 1 | K10: 1 | L10: 1 | M10: 1 | N10: 1 | O10: 1 | P10: 1 | Q10: 1 | R10: 1 | S10: 1 | T10: 1 | U10: 1 | V10: 1 | W10: 1 | X10: 1 | Y10: 1 | Z10: 1 | AA10: 1 | AB10: 1
A11: geothermal es | B11: 1 | C11: 1 | D11: 1 | E11: 1 | F11: 1 | G11: 1 | H11: 1 | I11: 1 | J11: 1 | K11: 1 | L11: 1 | M11: 1 | N11: 1 | O11: 1 | P11: 1 | Q11: 1 | R11: 1 | S11: 1 | T11: 1 | U11: 1 | V11: 1 | W11: 1 | X11: 1 | Y11: 1 | Z11: 1 | AA11: 1 | AB11: 1
A12: petroleum es | B12: 1 | C12: 1 | D12: 1 | E12: 1 | F12: 1 | G12: 1 | H12: 1 | I12: 1 | J12: 1 | K12: 1 | L12: 1 | M12: 1 | N12: 1 | O12: 1 | P12: 1 | Q12: 1 | R12: 1 | S12: 1 | T12: 1 | U12: 1 | V12: 1 | W12: 1 | X12: 1 | Y12: 1 | Z12: 1 | AA12: 1 | AB12: 1
... A25: hydrogen combined cycle es | B25: 1 | C25: 1 | D25: 1 | E25: 1 | F25: 1 | G25: 1 | H25: 1 | I25: 1 | J25: 1 | K25: 1 | L25: 1 | M25: 1 | N25: 1 | O25: 1 | P25: 1 | Q25: 1 | R25: 1 | S25: 1 | T25: 1 | U25: 1 | V25: 1 | W25: 1 | X25: 1 | Y25: 1 | Z25: 1 | AA25: 1 | AB25: 1
