Workbook
Name dollars_2020_2012: [1]About!$A$104
Name dollars_2021_2012: [1]About!$A$103
Name lignite_multiplier: '[1]Hard Coal and Lig Multipliers'!$N$15
Name nonlignite_multiplier: '[1]Hard Coal and Lig Multipliers'!$N$16
Name nonlignite_multiplier: '[1]Hard Coal and Lig Multipliers'!$N$16
Name nonlignite_multiplier: '[1]Hard Coal and Lig Multipliers'!$N$16
Name nonlignite_multiplier: '[2]Hard Coal and Lig Multipliers'!$N$15

Sheet About
A1: IMFPbFT International Market Fuel Price by Fuel Type
A3: Source: | B3: see fuels/BFPaT and EPS outputs referenced in BAU Fuel Use by Sector tab
A4: Natural Gas Price Source:
B5: AEO Table 60 | C5: https://www.eia.gov/outlooks/aeo/data/browser/#/?id=76-AEO2021&region=0-0&cases=highogs&start=2019&end=2050&f=A&sourcekey=0
B6: AEO Table 13 | C6: https://www.eia.gov/outlooks/aeo/data/browser/#/?id=13-AEO2021&cases=ref2021&sourcekey=0
B7: EIA Natural Gas Prices | C7: https://www.eia.gov/dnav/ng/ng_pri_sum_dcu_nus_m.htm
B8: Henry Hub Prices | C8: https://www.eia.gov/dnav/ng/hist/rngwhhdA.htm
A9: Notes
A10: The prices in this variable should include export taxes, if any. In other words, they should be
A11: the prices paid on the global market. For more details on export taxes, see variable fuels/ETRbF.
A13: Electricity exports are handled separately (in the power sector), not in this variable.
A15: Nuclear here refers to nuclear fuel, i.e. uranium oxide, not electricity from nuclear plants.
A17: We estimate this value based on the prices seen within the United States.
A18: For fuels that vary by sector, we take a weighted average based on the first year consumption in the model.
A20: Natural gas prices
A21: Estimated by creating an average multiplier for pipeline and lng gas compared to henry hub prices.
A22: Use futures prices forecast of henry hub prices multiplied by pipeline and lng multiplier to get forecasted natural gas export prices for 2022-2025.
A23: Linearly interpolated between 2025 and 2030.
A24: Use AEO forecast of henry hub prices multiplied by pipeline and lng multiplier to get forecasted natural gas export prices for 2030-2050.
A25: Created weighted total natural gas export price based on forecasted export volumes of pipeline and lng (AEO 60).
A27: mmbtu per thousand cubic feet | B27: 1.037
A28: 2020 to 2012 $ | B28: 0.887
A29: 2021 to 2012 $ | B29: =0.847 -> 0.847
A30: 2022 to 2012 $ | B30: 0.785
A31: 2024 to 2012 $ | B31: 0.73191601

Sheet AEO 2022 Table 13
A1: Table 13. Natural Gas Supply, Disposition, and Prices
A2: https://www.eia.gov/outlooks/aeo/data/browser/#/?id=13-AEO2022&region=0-0&cases=ref2022&start=2020&end=2050&f=A&sourcekey=0
A3: Fri Jun 03 2022 14:36:16 GMT-0700 (Pacific Daylight Time)
A4: Source: U.S. Energy Information Administration
B5: full name | C5: api key | D5: units | E5: 2020 | F5: 2021 | G5: 2022 | H5: 2023 | I5: 2024 | J5: 2025 | K5: 2026 | L5: 2027 | M5: 2028 | N5: 2029 | O5: 2030 | P5: 2031 | Q5: 2032 | R5: 2033 | S5: 2034 | T5: 2035 | U5: 2036 | V5: 2037 | W5: 2038 | X5: 2039 | Y5: 2040 | Z5: 2041 | AA5: 2042 | AB5: 2043 | AC5: 2044 | AD5: 2045 | AE5: 2046 | AF5: 2047 | AG5: 2048 | AH5: 2049 | AI5: 2050 | AJ5: Growth (2021-2050)
A6: Production | C6: 13-AEO2022.2.
A7: Dry Gas Production | B7: Natural Gas: Production: Dry Gas Production: Low economic growth | C7: 13-AEO2022.3.lowmacro-d011222a | D7: Tcf | F7: 34.409626 | G7: 35.322708 | H7: 35.604687 | I7: 35.806705 | J7: 35.905468 | K7: 35.882885 | L7: 35.810017 | M7: 36.400112 | N7: 36.655968 | O7: 36.721214 | P7: 36.966469 | Q7: 37.231819 | R7: 37.474743 | S7: 37.30827 | T7: 37.172085 | U7: 37.122219 | V7: 37.233501 | W7: 37.447079 | X7: 37.700321 | Y7: 37.972595 | Z7: 38.092804 | AA7: 38.278564 | AB7: 38.60881 | AC7: 38.921223 | AD7: 39.147614 | AE7: 39.39146 | AF7: 39.666965 | AG7: 39.861118 | AH7: 40.032658 | AI7: 40.400124 | AJ7: 0.006
A8: Supplemental Natural Gas | B8: Natural Gas: Production: Supplemental Natural Gas: Low economic growth | C8: 13-AEO2022.4.lowmacro-d011222a | D8: Tcf | F8: 0.05953 | G8: 0.06312 | H8: 0.062993 | I8: 0.062865 | J8: 0.062738 | K8: 0.062611 | L8: 0.062483 | M8: 0.062483 | N8: 0.062483 | O8: 0.062483 | P8: 0.062483 | Q8: 0.062483 | R8: 0.062483 | S8: 0.062483 | T8: 0.062483 | U8: 0.062483 | V8: 0.062483 | W8: 0.062483 | X8: 0.062483 | Y8: 0.062483 | Z8: 0.062483 | AA8: 0.062483 | AB8: 0.062483 | AC8: 0.062483 | AD8: 0.062483 | AE8: 0.062483 | AF8: 0.062483 | AG8: 0.062483 | AH8: 0.062483 | AI8: 0.062483 | AJ8: 0.002
A9: Net Imports | B9: Natural Gas: Net Imports: Low economic growth | C9: 13-AEO2022.6.lowmacro-d011222a | D9: Tcf | F9: -4.018888 | G9: -5.032922 | H9: -5.319394 | I9: -5.505922 | J9: -5.795665 | K9: -5.835703 | L9: -6.007035 | M9: -6.346346 | N9: -6.726242 | O9: -7.007736 | P9: -7.372563 | Q9: -7.634319 | R9: -7.706789 | S9: -7.787818 | T9: -7.890796 | U9: -7.918286 | V9: -7.883421 | W9: -7.908661 | X9: -7.962761 | Y9: -8.031993 | Z9: -8.043514 | AA9: -8.068309 | AB9: -8.137873 | AC9: -8.294017 | AD9: -8.36681 | AE9: -8.370378 | AF9: -8.386253 | AG9: -8.38794 | AH9: -8.39177 | AI9: -8.429087 | AJ9: 0.026
A10: Pipeline | B10: Natural Gas: Net Imports: Pipeline: Low economic growth | C10: 13-AEO2022.7.lowmacro-d011222a | D10: Tcf | F10: -0.476819 | G10: -0.916066 | H10: -0.959442 | I10: -1.099447 | J10: -1.217244 | K10: -1.243205 | L10: -1.312514 | M10: -1.43905 | N10: -1.631721 | O10: -1.713215 | P10: -1.878042 | Q10: -1.927022 | R10: -1.912268 | S10: -1.993297 | T10: -2.096275 | U10: -2.11099 | V10: -2.088901 | W10: -2.11414 | X10: -2.16824 | Y10: -2.224696 | Z10: -2.248994 | AA10: -2.273788 | AB10: -2.343352 | AC10: -2.486721 | AD10: -2.572289 | AE10: -2.575856 | AF10: -2.591733 | AG10: -2.580644 | AH10: -2.59725 | AI10: -2.634566 | AJ10: 0.061
A11: Liquefied Natural Gas | B11: Natural Gas: Net Imports: Liquefied Natural Gas: Low economic growth | C11: 13-AEO2022.8.lowmacro-d011222a | D11: Tcf | F11: -3.542069 | G11: -4.116855 | H11: -4.359952 | I11: -4.406474 | J11: -4.578421 | K11: -4.592499 | L11: -4.694521 | M11: -4.907297 | N11: -5.094521 | O11: -5.294521 | P11: -5.494521 | Q11: -5.707297 | R11: -5.794521 | S11: -5.794521 | T11: -5.794521 | U11: -5.807297 | V11: -5.794521 | W11: -5.794521 | X11: -5.794521 | Y11: -5.807297 | Z11: -5.794521 | AA11: -5.794521 | AB11: -5.794521 | AC11: -5.807297 | AD11: -5.794521 | AE11: -5.794521 | AF11: -5.794521 | AG11: -5.807297 | AH11: -5.794521 | AI11: -5.794521 | AJ11: 0.017
A12: Total Supply | B12: Natural Gas: Total Supply: Low economic growth | C12: 13-AEO2022.10.lowmacro-d011222a | D12: Tcf | F12: 30.450266 | G12: 30.352909 | H12: 30.348286 | I12: 30.363649 | J12: 30.172539 | K12: 30.109793 | L12: 29.865467 | M12: 30.116251 | N12: 29.99221 | O12: 29.775963 | P12: 29.656391 | Q12: 29.659985 | R12: 29.830439 | S12: 29.582935 | T12: 29.343773 | U12: 29.266418 | V12: 29.412565 | W12: 29.600903 | X12: 29.800045 | Y12: 30.003086 | Z12: 30.111774 | AA12: 30.272739 | AB12: 30.533422 | AC12: 30.68969 | AD12: 30.843288 | AE12: 31.083569 | AF12: 31.343197 | AG12: 31.535664 | AH12: 31.703373 | AI12: 32.033524 | AJ12: 0.002
A13: Consumption by Sector | B13: Natural Gas: Use by Sector: Total: Low economic growth | C13: 13-AEO2022.12.lowmacro-d011222a | D13: Tcf | F13: 30.242594 | G13: 30.085173 | H13: 30.064831 | I13: 30.056604 | J13: 29.859272 | K13: 29.777143 | L13: 29.518978 | M13: 29.768036 | N13: 29.655115 | O13: 29.44602 | P13: 29.328667 | Q13: 29.327215 | R13: 29.514547 | S13: 29.269196 | T13: 29.029827 | U13: 28.959255 | V13: 29.105549 | W13: 29.295654 | X13: 29.500248 | Y13: 29.703928 | Z13: 29.806578 | AA13: 29.968973 | AB13: 30.229542 | AC13: 30.386457 | AD13: 30.550423 | AE13: 30.797487 | AF13: 31.028425 | AG13: 31.22183 | AH13: 31.388659 | AI13: 31.717159 | AJ13: 0.002
A14: Residential | B14: Natural Gas: Use by Sector: Residential: Low economic growth | C14: 13-AEO2022.13.lowmacro-d011222a | D14: Tcf | F14: 4.819419 | G14: 4.87988 | H14: 4.803436 | I14: 4.816045 | J14: 4.830301 | K14: 4.835493 | L14: 4.835128 | M14: 4.826184 | N14: 4.811259 | O14: 4.796466 | P14: 4.782578 | Q14: 4.765706 | R14: 4.748952 | S14: 4.735481 | T14: 4.726693 | U14: 4.720163 | V14: 4.712776 | W14: 4.704755 | X14: 4.69628 | Y14: 4.689078 | Z14: 4.680464 | AA14: 4.673137 | AB14: 4.667832 | AC14: 4.663457 | AD14: 4.659014 | AE14: 4.653883 | AF14: 4.647811 | AG14: 4.64085 | AH14: 4.632444 | AI14: 4.623201 | AJ14: -0.001
A15: Commercial | B15: Natural Gas: Use by Sector: Commercial: Low economic growth | C15: 13-AEO2022.14.lowmacro-d011222a | D15: Tcf | F15: 3.350484 | G15: 3.482587 | H15: 3.428924 | I15: 3.434704 | J15: 3.444488 | K15: 3.443654 | L15: 3.458211 | M15: 3.461361 | N15: 3.456904 | O15: 3.452962 | P15: 3.453952 | Q15: 3.451528 | R15: 3.448314 | S15: 3.448515 | T15: 3.454259 | U15: 3.462657 | V15: 3.468118 | W15: 3.470585 | X15: 3.471409 | Y15: 3.472769 | Z15: 3.472588 | AA15: 3.475296 | AB15: 3.481176 | AC15: 3.487429 | AD15: 3.493799 | AE15: 3.499022 | AF15: 3.502862 | AG15: 3.505532 | AH15: 3.505991 | AI15: 3.505614 | AJ15: 0.002
A16: Industrial | B16: Natural Gas: Use by Sector: Industrial: Low economic growth | C16: 13-AEO2022.15.lowmacro-d011222a | D16: Tcf | F16: 10.38806 | G16: 10.575246 | H16: 10.486811 | I16: 10.540606 | J16: 10.645499 | K16: 10.709901 | L16: 10.719416 | M16: 10.767504 | N16: 10.779654 | O16: 10.815272 | P16: 10.848524 | Q16: 10.876146 | R16: 10.905524 | S16: 10.913145 | T16: 10.922623 | U16: 10.966375 | V16: 10.982613 | W16: 11.020459 | X16: 11.064152 | Y16: 11.106756 | Z16: 11.119011 | AA16: 11.164563 | AB16: 11.248596 | AC16: 11.29722 | AD16: 11.350711 | AE16: 11.430659 | AF16: 11.498 | AG16: 11.531771 | AH16: 11.566927 | AI16: 11.694829 | AJ16: 0.004
A17: Other Industrial | B17: Natural Gas: Use by Sector: Industrial: Other: Low economic growth | C17: 13-AEO2022.16.lowmacro-d011222a | D17: Tcf | F17: 8.25777 | G17: 8.328052 | H17: 8.209694 | I17: 8.235285 | J17: 8.295445 | K17: 8.354473 | L17: 8.355721 | M17: 8.349208 | N17: 8.332207 | O17: 8.328288 | P17: 8.329494 | Q17: 8.313449 | R17: 8.315689 | S17: 8.332453 | T17: 8.340832 | U17: 8.390054 | V17: 8.412317 | W17: 8.446038 | X17: 8.472146 | Y17: 8.496502 | Z17: 8.513413 | AA17: 8.551575 | AB17: 8.608138 | AC17: 8.642073 | AD17: 8.672221 | AE17: 8.737638 | AF17: 8.794087 | AG17: 8.814433 | AH17: 8.846367 | AI17: 8.932115 | AJ17: 0.003
A18: Lease and Plant Fuel | B18: Natural Gas: Use by Sector: Industrial: Lease and Plant Fuel: Low economic growth | C18: 13-AEO2022.17.lowmacro-d011222a | D18: Tcf | F18: 1.840362 | G18: 1.90736 | H18: 1.917754 | I18: 1.942354 | J18: 1.973323 | K18: 1.97772 | L18: 1.977887 | M18: 2.015253 | N18: 2.029239 | O18: 2.052577 | P18: 2.068422 | Q18: 2.094856 | R18: 2.114927 | S18: 2.105785 | T18: 2.106883 | U18: 2.100379 | V18: 2.095387 | W18: 2.099513 | X18: 2.117098 | Y18: 2.134312 | Z18: 2.130689 | AA18: 2.138081 | AB18: 2.16555 | AC18: 2.179204 | AD18: 2.203582 | AE18: 2.218113 | AF18: 2.229005 | AG18: 2.241395 | AH18: 2.245652 | AI18: 2.287807 | AJ18: 0.008
A19: Fuel Used to Liquefy Gas for Export | B19: Natural Gas: Use by Sector: Industrial: Liquefaction for Export: Low economic growth | C19: 13-AEO2022.18.lowmacro-d011222a | D19: Tcf | F19: 0.289928 | G19: 0.339835 | H19: 0.359363 | I19: 0.362967 | J19: 0.376731 | K19: 0.377708 | L19: 0.385808 | M19: 0.403042 | N19: 0.418208 | O19: 0.434408 | P19: 0.450608 | Q19: 0.467842 | R19: 0.474908 | S19: 0.474908 | T19: 0.474908 | U19: 0.475942 | V19: 0.474908 | W19: 0.474908 | X19: 0.474908 | Y19: 0.475942 | Z19: 0.474908 | AA19: 0.474908 | AB19: 0.474908 | AC19: 0.475942 | AD19: 0.474908 | AE19: 0.474908 | AF19: 0.474908 | AG19: 0.475942 | AH19: 0.474908 | AI19: 0.474908 | AJ19: 0.017
A20: Natural Gas-to-Liquids Heat and Power | B20: Natural Gas: Use by Sector: Industrial: GTL Heat and Power: Low economic growth | C20: 13-AEO2022.19.lowmacro-d011222a | D20: Tcf | F20: 0 | G20: 0 | H20: 0 | I20: 0 | J20: 0 | K20: 0 | L20: 0 | M20: 0 | N20: 0 | O20: 0 | P20: 0 | Q20: 0 | R20: 0 | S20: 0 | T20: 0 | U20: 0 | V20: 0 | W20: 0 | X20: 0 | Y20: 0 | Z20: 0 | AA20: 0 | AB20: 0 | AC20: 0 | AD20: 0 | AE20: 0 | AF20: 0 | AG20: 0 | AH20: 0 | AI20: 0 | AJ20: - -
A21: Natural Gas to Liquids Production | B21: Natural Gas: Use by Sector: Industrial: GTL Liquids: Low economic growth | C21: 13-AEO2022.20.lowmacro-d011222a | D21: Tcf | F21: 0 | G21: 0 | H21: 0 | I21: 0 | J21: 0 | K21: 0 | L21: 0 | M21: 0 | N21: 0 | O21: 0 | P21: 0 | Q21: 0 | R21: 0 | S21: 0 | T21: 0 | U21: 0 | V21: 0 | W21: 0 | X21: 0 | Y21: 0 | Z21: 0 | AA21: 0 | AB21: 0 | AC21: 0 | AD21: 0 | AE21: 0 | AF21: 0 | AG21: 0 | AH21: 0 | AI21: 0 | AJ21: - -
A22: Transportation | B22: Natural Gas: Use by Sector: Transportation: Low economic growth | C22: 13-AEO2022.21.lowmacro-d011222a | D22: Tcf | F22: 0.82787 | G22: 0.770456 | H22: 0.769016 | I22: 0.759091 | J22: 0.754646 | K22: 0.751995 | L22: 0.746852 | M22: 0.759835 | N22: 0.761848 | O22: 0.761588 | P22: 0.766947 | Q22: 0.773339 | R22: 0.783053 | S22: 0.781493 | T22: 0.786302 | U22: 0.794828 | V22: 0.808952 | W22: 0.8245 | X22: 0.837743 | Y22: 0.857536 | Z22: 0.870359 | AA22: 0.884783 | AB22: 0.901461 | AC22: 0.921563 | AD22: 0.930299 | AE22: 0.946389 | AF22: 0.964842 | AG22: 0.981295 | AH22: 0.998166 | AI22: 1.012687 | AJ22: 0.007
A23: Motor Vehicles | B23: Trains | C23: and Ships | D23: Natural Gas: Use by Sector: Transportation: Vehicles: Low economic growth | E23: 13-AEO2022.22.lowmacro-d011222a | F23: Tcf | H23: 0.10664 | I23: 0.096182 | J23: 0.113294 | K23: 0.119665 | L23: 0.126026 | M23: 0.135944 | N23: 0.146969 | O23: 0.154949 | P23: 0.162695 | Q23: 0.171487 | R23: 0.180423 | S23: 0.184107 | T23: 0.191779 | U23: 0.199366 | V23: 0.206543 | W23: 0.214237 | X23: 0.222566 | Y23: 0.231628 | Z23: 0.239112 | AA23: 0.253512 | AB23: 0.263027 | AC23: 0.272002 | AD23: 0.284502 | AE23: 0.297652 | AF23: 0.308227 | AG23: 0.321112 | AH23: 0.331511 | AI23: 0.340022 | AJ23: 0.349799 | AK23: 0.405344 | AL23: 0.047
A24: Pipeline and Distribution Fuel | B24: Natural Gas: Use by Sector: Transportation: Pipeline Fuel: Low economic growth | C24: 13-AEO2022.23.lowmacro-d011222a | D24: Tcf | F24: 0.72123 | G24: 0.674274 | H24: 0.655722 | I24: 0.639426 | J24: 0.62862 | K24: 0.616051 | L24: 0.599883 | M24: 0.604886 | N24: 0.599153 | O24: 0.590101 | P24: 0.586524 | Q24: 0.589232 | R24: 0.591273 | S24: 0.582127 | T24: 0.57976 | U24: 0.580591 | V24: 0.586386 | W24: 0.592872 | X24: 0.598631 | Y24: 0.604024 | Z24: 0.607332 | AA24: 0.61278 | AB24: 0.616958 | AC24: 0.623911 | AD24: 0.622073 | AE24: 0.625277 | AF24: 0.633331 | AG24: 0.641273 | AH24: 0.648367 | AI24: 0.653551 | AJ24: -0.003
A25: Electric Power | B25: Natural Gas: Use by Sector: Electric Power: Low economic growth | C25: 13-AEO2022.24.lowmacro-d011222a | D25: Tcf | F25: 10.85676 | G25: 10.377003 | H25: 10.576644 | I25: 10.506159 | J25: 10.184333 | K25: 10.036098 | L25: 9.759375 | M25: 9.953151 | N25: 9.845448 | O25: 9.61973 | P25: 9.476666 | Q25: 9.460497 | R25: 9.628703 | S25: 9.390562 | T25: 9.139952 | U25: 9.015231 | V25: 9.13309 | W25: 9.275352 | X25: 9.430664 | Y25: 9.577788 | Z25: 9.664156 | AA25: 9.771195 | AB25: 9.930477 | AC25: 10.016788 | AD25: 10.116599 | AE25: 10.267536 | AF25: 10.414912 | AG25: 10.56238 | AH25: 10.685132 | AI25: 10.88083 | AJ25: 0
A26: Discrepancy | B26: Natural Gas: Discrepancy: Low economic growth | C26: 13-AEO2022.26.lowmacro-d011222a | D26: Tcf | F26: 0.207672 | G26: 0.267736 | H26: 0.283455 | I26: 0.307045 | J26: 0.313267 | K26: 0.332649 | L26: 0.346489 | M26: 0.348215 | N26: 0.337095 | O26: 0.329943 | P26: 0.327724 | Q26: 0.332769 | R26: 0.315891 | S26: 0.31374 | T26: 0.313946 | U26: 0.307163 | V26: 0.307016 | W26: 0.305248 | X26: 0.299797 | Y26: 0.299158 | Z26: 0.305197 | AA26: 0.303766 | AB26: 0.303881 | AC26: 0.303232 | AD26: 0.292866 | AE26: 0.286081 | AF26: 0.314772 | AG26: 0.313833 | AH26: 0.314714 | AI26: 0.316364 | AJ26: - -
A27: Natural Gas Prices | C27: 13-AEO2022.28.
A28: Natural Gas Spot Price at Henry Hub | C28: 13-AEO2022.30.
A29: (2021 dollars per million Btu) | B29: Natural Gas: Henry Hub Spot Price: Low economic growth | C29: 13-AEO2022.31.lowmacro-d011222a | D29: 2021 $/MMBtu | F29: 4.115437 | G29: 3.837557 | H29: 3.471147 | I29: 3.126585 | J29: 2.953741 | K29: 2.906966 | L29: 2.954549 | M29: 3.136157 | N29: 3.292231 | O29: 3.388971 | P29: 3.454448 | Q29: 3.491858 | R29: 3.59329 | S29: 3.594153 | T29: 3.524364 | U29: 3.485305 | V29: 3.48693 | W29: 3.51827 | X29: 3.545613 | Y29: 3.577658 | Z29: 3.63465 | AA29: 3.652029 | AB29: 3.589562 | AC29: 3.561126 | AD29: 3.469676 | AE29: 3.425366 | AF29: 3.400315 | AG29: 3.392432 | AH29: 3.403568 | AI29: 3.409512 | AJ29: -0.006
A30: Delivered Prices | C30: 13-AEO2022.33.
A31: (2021 dollars per thousand cubic feet) | C31: 13-AEO2022.34.
A32: Residential | B32: Natural Gas: Delivered Prices: Residential: Low economic growth | C32: 13-AEO2022.35.lowmacro-d011222a | D32: 2021 $/Mcf | F32: 12.171644 | G32: 12.625865 | H32: 11.979866 | I32: 11.480213 | J32: 11.157559 | K32: 10.968821 | L32: 10.837678 | M32: 10.981541 | N32: 11.152151 | O32: 11.246775 | P32: 11.342472 | Q32: 11.68836 | R32: 11.833169 | S32: 11.888336 | T32: 11.88853 | U32: 11.856069 | V32: 11.895705 | W32: 11.930015 | X32: 11.970271 | Y32: 12.000363 | Z32: 12.084126 | AA32: 12.079756 | AB32: 12.043774 | AC32: 12.028834 | AD32: 11.998742 | AE32: 11.996384 | AF32: 12.001075 | AG32: 12.006783 | AH32: 12.045881 | AI32: 12.069625 | AJ32: 0
A33: Commercial | B33: Natural Gas: Delivered Prices: Commercial: Low economic growth | C33: 13-AEO2022.36.lowmacro-d011222a | D33: 2021 $/Mcf | F33: 8.771839 | G33: 9.162567 | H33: 8.828384 | I33: 8.499667 | J33: 8.33059 | K33: 8.281426 | L33: 8.273354 | M33: 8.399084 | N33: 8.544633 | O33: 8.616765 | P33: 8.690123 | Q33: 8.905362 | R33: 9.008744 | S33: 9.037756 | T33: 9.009416 | U33: 8.96355 | V33: 8.989129 | W33: 9.011681 | X33: 9.040559 | Y33: 9.060416 | Z33: 9.132076 | AA33: 9.116379 | AB33: 9.069324 | AC33: 9.045333 | AD33: 9.007052 | AE33: 8.995634 | AF33: 8.99243 | AG33: 8.990973 | AH33: 9.022299 | AI33: 9.039542 | AJ33: 0.001
A34: Industrial | B34: Natural Gas: Delivered Prices: Industrial: Low economic growth | C34: 13-AEO2022.37.lowmacro-d011222a | D34: 2021 $/Mcf | F34: 5.269056 | G34: 5.03236 | H34: 4.688 | I34: 4.317468 | J34: 4.135796 | K34: 4.079431 | L34: 4.111363 | M34: 4.275023 | N34: 4.428134 | O34: 4.517744 | P34: 4.577354 | Q34: 4.57688 | R34: 4.677366 | S34: 4.682547 | T34: 4.609011 | U34: 4.556269 | V34: 4.554906 | W34: 4.577663 | X34: 4.599112 | Y34: 4.622378 | Z34: 4.678865 | AA34: 4.686431 | AB34: 4.620964 | AC34: 4.584721 | AD34: 4.508954 | AE34: 4.477705 | AF34: 4.458506 | AG34: 4.452824 | AH34: 4.463304 | AI34: 4.471565 | AJ34: -0.006
A35: Transportation | B35: Natural Gas: Delivered Prices: Transportation: Low economic growth | C35: 13-AEO2022.38.lowmacro-d011222a | D35: 2021 $/Mcf | F35: 15.22551 | G35: 15.189867 | H35: 14.413707 | I35: 13.82573 | J35: 13.402384 | K35: 13.030856 | L35: 12.741631 | M35: 12.603173 | N35: 12.474068 | O35: 12.308931 | P35: 12.141323 | Q35: 12.813327 | R35: 12.722208 | S35: 12.575328 | T35: 12.46647 | U35: 12.278451 | V35: 12.158415 | W35: 12.07103 | X35: 11.987044 | Y35: 11.964777 | Z35: 11.952209 | AA35: 11.886301 | AB35: 11.783961 | AC35: 11.709952 | AD35: 11.603604 | AE35: 11.546721 | AF35: 11.496274 | AG35: 11.448224 | AH35: 11.422692 | AI35: 11.379571 | AJ35: -0.01
A36: Electric Power | B36: Natural Gas: Delivered Prices: Electric Power: Low economic growth | C36: 13-AEO2022.39.lowmacro-d011222a | D36: 2021 $/Mcf | F36: 5.332857 | G36: 4.178648 | H36: 3.885905 | I36: 3.547021 | J36: 3.377793 | K36: 3.342421 | L36: 3.381722 | M36: 3.556563 | N36: 3.688859 | O36: 3.763834 | P36: 3.807873 | Q36: 3.82572 | R36: 3.921008 | S36: 3.904177 | T36: 3.798467 | U36: 3.750271 | V36: 3.744769 | W36: 3.767939 | X36: 3.793509 | Y36: 3.829679 | Z36: 3.882215 | AA36: 3.881239 | AB36: 3.803053 | AC36: 3.765003 | AD36: 3.692361 | AE36: 3.66632 | AF36: 3.650438 | AG36: 3.654424 | AH36: 3.66035 | AI36: 3.687017 | AJ36: -0.013
A37: Average | B37: Natural Gas: Delivered Prices: Average: Low economic growth | C37: 13-AEO2022.40.lowmacro-d011222a | D37: 2021 $/Mcf | F37: 6.975946 | G37: 6.635291 | H37: 6.229839 | I37: 5.862714 | J37: 5.690771 | K37: 5.630795 | L37: 5.656798 | M37: 5.799069 | N37: 5.953547 | O37: 6.053108 | P37: 6.125708 | Q37: 6.227705 | R37: 6.316007 | S37: 6.343978 | T37: 6.301665 | U37: 6.264091 | V37: 6.259395 | W37: 6.268137 | X37: 6.278011 | Y37: 6.292707 | Z37: 6.344999 | AA37: 6.332001 | AB37: 6.253158 | AC37: 6.213667 | AD37: 6.142462 | AE37: 6.105012 | AF37: 6.077645 | AG37: 6.06405 | AH37: 6.067497 | AI37: 6.06418 | AJ37: -0.005
A38: Natural Gas Spot Price at Henry Hub | C38: 13-AEO2022.59.
A39: (nominal dollars per million Btu) | B39: Natural Gas: Henry Hub Spot Price: Low economic growth | C39: 13-AEO2022.60.lowmacro-d011222a | D39: nom $/MMBtu | F39: 4.115437 | G39: 3.961129 | H39: 3.67353 | I39: 3.407579 | J39: 3.321223 | K39: 3.380046 | L39: 3.55681 | M39: 3.909547 | N39: 4.247153 | O39: 4.519075 | P39: 4.759894 | Q39: 4.967306 | R39: 5.278396 | S39: 5.456114 | T39: 5.532805 | U39: 5.659725 | V39: 5.858712 | W39: 6.116162 | X39: 6.373682 | Y39: 6.653007 | Z39: 6.991181 | AA39: 7.266311 | AB39: 7.385303 | AC39: 7.573573 | AD39: 7.62625 | AE39: 7.781052 | AF39: 7.982764 | AG39: 8.228611 | AH39: 8.525277 | AI39: 8.814068 | AJ39: 0.027
A40: Delivered Prices | C40: 13-AEO2022.66.
...

Sheet AEO 2023 Table 13
A1: Table 13. Natural Gas Supply, Disposition, and Prices
A2: https://www.eia.gov/outlooks/aeo/data/browser/#/?id=13-AEO2023&cases=ref2023&sourcekey=0
A3: Thu Apr 13 2023 09:58:18 GMT-0400 (Eastern Daylight Time)
A4: Source: U.S. Energy Information Administration
B5: full name | C5: api key | D5: units | E5: 2021 | F5: 2022 | G5: 2023 | H5: 2024 | I5: 2025 | J5: 2026 | K5: 2027 | L5: 2028 | M5: 2029 | N5: 2030 | O5: 2031 | P5: 2032 | Q5: 2033 | R5: 2034 | S5: 2035 | T5: 2036 | U5: 2037 | V5: 2038 | W5: 2039 | X5: 2040 | Y5: 2041 | Z5: 2042 | AA5: 2043 | AB5: 2044 | AC5: 2045 | AD5: 2046 | AE5: 2047 | AF5: 2048 | AG5: 2049 | AH5: 2050 | AI5: Growth (2022-2050)
A6: Production
A7: Dry Gas Production | B7: Natural Gas: Production: Dry Gas Production: Reference case | C7: AEO.2023.REF2023.SUP_PRD_NA_NA_NG_DNG_USA_TRLCF.A | D7: Tcf | F7: 36.465069 | G7: 36.485851 | H7: 35.567017 | I7: 35.725479 | J7: 36.183468 | K7: 36.13615 | L7: 36.43782 | M7: 36.679688 | N7: 37.035736 | O7: 37.466896 | P7: 37.973099 | Q7: 38.551033 | R7: 39.045914 | S7: 39.497391 | T7: 39.857361 | U7: 40.219318 | V7: 40.491047 | W7: 40.733463 | X7: 40.870892 | Y7: 40.98983 | Z7: 41.16486 | AA7: 41.277199 | AB7: 41.354496 | AC7: 41.505783 | AD7: 41.340649 | AE7: 41.544994 | AF7: 41.613247 | AG7: 41.692951 | AH7: 42.065376 | AI7: 0.005
A8: Supplemental Natural Gas | B8: Natural Gas: Production: Supplemental Natural Gas: Reference case | C8: AEO.2023.REF2023.SUP_PRD_NA_NA_NG_SPNG_USA_TRLCF.A | D8: Tcf | F8: 0.066783 | G8: 0.068295 | H8: 0.067215 | I8: 0.066134 | J8: 0.065053 | K8: 0.063973 | L8: 0.062892 | M8: 0.062892 | N8: 0.062892 | O8: 0.062892 | P8: 0.062892 | Q8: 0.062892 | R8: 0.062892 | S8: 0.062892 | T8: 0.062892 | U8: 0.062892 | V8: 0.062892 | W8: 0.062892 | X8: 0.062892 | Y8: 0.062892 | Z8: 0.062892 | AA8: 0.062892 | AB8: 0.062892 | AC8: 0.062892 | AD8: 0.062892 | AE8: 0.062892 | AF8: 0.062892 | AG8: 0.062892 | AH8: 0.062892 | AI8: -0.002
A9: Net Imports | B9: Natural Gas: Net Imports: Reference case | C9: AEO.2023.REF2023.TRAD_NETIMP_NA_NA_NG_NA_USA_TRLCF.A | D9: Tcf | F9: -4.184249 | G9: -5.135025 | H9: -5.471915 | I9: -5.969136 | J9: -6.566689 | K9: -7.050437 | L9: -7.555391 | M9: -7.942295 | N9: -8.553591 | O9: -9.253424 | P9: -9.895041 | Q9: -10.548451 | R9: -11.116964 | S9: -11.524033 | T9: -11.819523 | U9: -12.03135 | V9: -12.089127 | W9: -12.149171 | X9: -12.05528 | Y9: -12.019996 | Z9: -12.016218 | AA9: -11.976196 | AB9: -11.936414 | AC9: -11.84736 | AD9: -11.800188 | AE9: -11.753365 | AF9: -11.711053 | AG9: -11.659772 | AH9: -11.61386 | AI9: 0.037
A10: Pipeline | B10: Natural Gas: Net Imports: Pipeline: Reference case | C10: AEO.2023.REF2023.TRAD_NETIMP_NA_NA_NG_PIPL_USA_TRLCF.A | D10: Tcf | F10: -0.251181 | G10: -0.656535 | H10: -0.92837 | I10: -1.137381 | J10: -1.295535 | K10: -1.418052 | L10: -1.615046 | M10: -1.716692 | N10: -1.727988 | O10: -1.82782 | P10: -1.854696 | Q10: -1.922849 | R10: -1.991361 | S10: -2.098429 | T10: -2.179178 | U10: -2.205747 | V10: -2.163523 | W10: -2.223567 | X10: -2.114935 | Y10: -2.094392 | Z10: -2.090615 | AA10: -2.050593 | AB10: -1.996069 | AC10: -1.921756 | AD10: -1.874585 | AE10: -1.827761 | AF10: -1.770708 | AG10: -1.734168 | AH10: -1.688256 | AI10: 0.07
A11: Liquefied Natural Gas | B11: Natural Gas: Net Imports: Liquefied Natural Gas: Reference case | C11: AEO.2023.REF2023.TRAD_NETIMP_NA_NA_NG_LNG_USA_TRLCF.A | D11: Tcf | F11: -3.933068 | G11: -4.47849 | H11: -4.543546 | I11: -4.831755 | J11: -5.271153 | K11: -5.632385 | L11: -5.940345 | M11: -6.225603 | N11: -6.825603 | O11: -7.425603 | P11: -8.040345 | Q11: -8.625603 | R11: -9.125603 | S11: -9.425603 | T11: -9.640346 | U11: -9.825603 | V11: -9.925603 | W11: -9.925603 | X11: -9.940345 | Y11: -9.925603 | Z11: -9.925603 | AA11: -9.925603 | AB11: -9.940345 | AC11: -9.925603 | AD11: -9.925603 | AE11: -9.925603 | AF11: -9.940345 | AG11: -9.925603 | AH11: -9.925603 | AI11: 0.034
A12: Total Supply | B12: Natural Gas: Total Supply: Reference case | C12: AEO.2023.REF2023.SUP_NA_TOT_NA_NG_NA_USA_TRLCF.A | D12: Tcf | F12: 32.347603 | G12: 31.419121 | H12: 30.162315 | I12: 29.822479 | J12: 29.681831 | K12: 29.149685 | L12: 28.945322 | M12: 28.800285 | N12: 28.545038 | O12: 28.276365 | P12: 28.140951 | Q12: 28.065475 | R12: 27.991842 | S12: 28.036251 | T12: 28.100731 | U12: 28.250862 | V12: 28.464813 | W12: 28.647186 | X12: 28.878506 | Y12: 29.032726 | Z12: 29.211535 | AA12: 29.363895 | AB12: 29.480976 | AC12: 29.721317 | AD12: 29.603354 | AE12: 29.854523 | AF12: 29.965088 | AG12: 30.096073 | AH12: 30.514408 | AI12: -0.002
A13: Consumption by Sector | B13: Natural Gas: Use by Sector: Total: Reference case | C13: AEO.2023.REF2023.CNSM_NA_ALLS_NA_NG_TOT_USA_TRLCF.A | D13: Tcf | F13: 32.0019 | G13: 30.83448 | H13: 29.646107 | I13: 29.365435 | J13: 29.27512 | K13: 28.788441 | L13: 28.623919 | M13: 28.478455 | N13: 28.230896 | O13: 27.957972 | P13: 27.826681 | Q13: 27.740482 | R13: 27.671423 | S13: 27.676506 | T13: 27.779486 | U13: 27.932875 | V13: 28.156765 | W13: 28.337158 | X13: 28.564293 | Y13: 28.715166 | Z13: 28.903845 | AA13: 29.067936 | AB13: 29.189127 | AC13: 29.33363 | AD13: 29.315384 | AE13: 29.439484 | AF13: 29.640429 | AG13: 29.790031 | AH13: 30.00979 | AI13: -0.002
A14: Residential | B14: Natural Gas: Use by Sector: Residential: Reference case | C14: AEO.2023.REF2023.CNSM_NA_RESD_NA_NG_NA_USA_TRLCF.A | D14: Tcf | F14: 4.956103 | G14: 4.991772 | H14: 4.758877 | I14: 4.787258 | J14: 4.812247 | K14: 4.827975 | L14: 4.836563 | M14: 4.83274 | N14: 4.822402 | O14: 4.807221 | P14: 4.791358 | Q14: 4.783406 | R14: 4.772306 | S14: 4.761995 | T14: 4.754158 | U14: 4.747469 | V14: 4.739067 | W14: 4.733147 | X14: 4.728353 | Y14: 4.723671 | Z14: 4.719968 | AA14: 4.718853 | AB14: 4.720119 | AC14: 4.719804 | AD14: 4.71269 | AE14: 4.708236 | AF14: 4.70734 | AG14: 4.707267 | AH14: 4.705333 | AI14: -0.002
A15: Commercial | B15: Natural Gas: Use by Sector: Commercial: Reference case | C15: AEO.2023.REF2023.CNSM_NA_COMM_NA_NG_NA_USA_TRLCF.A | D15: Tcf | F15: 3.467453 | G15: 3.474621 | H15: 3.371255 | I15: 3.408176 | J15: 3.444571 | K15: 3.463666 | L15: 3.492099 | M15: 3.507773 | N15: 3.518465 | O15: 3.527853 | P15: 3.534745 | Q15: 3.535379 | R15: 3.533345 | S15: 3.529708 | T15: 3.527303 | U15: 3.523382 | V15: 3.514469 | W15: 3.507703 | X15: 3.499254 | Y15: 3.490335 | Z15: 3.482872 | AA15: 3.47906 | AB15: 3.478466 | AC15: 3.474299 | AD15: 3.463223 | AE15: 3.456198 | AF15: 3.454088 | AG15: 3.4524 | AH15: 3.44776 | AI15: 0
A16: Industrial | B16: Natural Gas: Use by Sector: Industrial: Reference case | C16: AEO.2023.REF2023.CNSM_NA_IDAL_NA_NG_NA_USA_TRLCF.A | D16: Tcf | F16: 10.480146 | G16: 10.226862 | H16: 10.131637 | I16: 10.278058 | J16: 10.51756 | K16: 10.654901 | L16: 10.790815 | M16: 10.848591 | N16: 10.895127 | O16: 10.918686 | P16: 10.984386 | Q16: 11.023491 | R16: 11.092604 | S16: 11.149645 | T16: 11.237076 | U16: 11.30991 | V16: 11.372004 | W16: 11.465014 | X16: 11.521564 | Y16: 11.596119 | Z16: 11.678681 | AA16: 11.764809 | AB16: 11.847437 | AC16: 11.907819 | AD16: 11.919591 | AE16: 12.003326 | AF16: 12.115173 | AG16: 12.20997 | AH16: 12.331114 | AI16: 0.006
A17: Other Industrial | B17: Natural Gas: Use by Sector: Industrial: Other: Reference case | C17: AEO.2023.REF2023.CNSM_NA_IDAL_OTH_NG_NA_USA_TRLCF.A | D17: Tcf | F17: 8.49547 | G17: 8.208763 | H17: 8.124475 | I17: 8.262086 | J17: 8.473062 | K17: 8.609991 | L17: 8.714933 | M17: 8.767846 | N17: 8.803032 | O17: 8.814925 | P17: 8.852177 | Q17: 8.873966 | R17: 8.926038 | S17: 8.972638 | T17: 9.032281 | U17: 9.087664 | V17: 9.140488 | W17: 9.213684 | X17: 9.271225 | Y17: 9.343618 | Z17: 9.409446 | AA17: 9.478456 | AB17: 9.536632 | AC17: 9.58894 | AD17: 9.591058 | AE17: 9.673329 | AF17: 9.757198 | AG17: 9.837563 | AH17: 9.950478 | AI17: 0.006
A18: Lease and Plant Fuel | B18: Natural Gas: Use by Sector: Industrial: Lease and Plant Fuel: Reference case | C18: AEO.2023.REF2023.CNSM_NA_LAP_NA_NG_LSAPFL_USA_TRLCF.A | D18: Tcf | F18: 1.984676 | G18: 2.018099 | H18: 2.007162 | I18: 2.015972 | J18: 2.044499 | K18: 2.044909 | L18: 2.075882 | M18: 2.080745 | N18: 2.092096 | O18: 2.10376 | P18: 2.132209 | Q18: 2.149524 | R18: 2.166565 | S18: 2.177007 | T18: 2.204795 | U18: 2.222246 | V18: 2.231516 | W18: 2.251329 | X18: 2.25034 | Y18: 2.2525 | Z18: 2.269236 | AA18: 2.286354 | AB18: 2.310805 | AC18: 2.318879 | AD18: 2.328533 | AE18: 2.329997 | AF18: 2.357975 | AG18: 2.372407 | AH18: 2.380637 | AI18: 0.007
A19: Natural Gas-to-Liquids Heat and Power | B19: Natural Gas: Use by Sector: Industrial: GTL Heat and Power: Reference case | C19: AEO.2023.REF2023.CNSM_NA_IDAL_HAP_NG_FT_USA_TRLCF.A | D19: Tcf | F19: 0 | G19: 0 | H19: 0 | I19: 0 | J19: 0 | K19: 0 | L19: 0 | M19: 0 | N19: 0 | O19: 0 | P19: 0 | Q19: 0 | R19: 0 | S19: 0 | T19: 0 | U19: 0 | V19: 0 | W19: 0 | X19: 0 | Y19: 0 | Z19: 0 | AA19: 0 | AB19: 0 | AC19: 0 | AD19: 0 | AE19: 0 | AF19: 0 | AG19: 0 | AH19: 0 | AI19: - -
A20: Natural Gas to Liquids Production | B20: Natural Gas: Use by Sector: Industrial: GTL Liquids: Reference case | C20: AEO.2023.REF2023.CNSM_NA_IDAL_FSK_NG_FT_USA_TRLCF.A | D20: Tcf | F20: 0 | G20: 0 | H20: 0 | I20: 0 | J20: 0 | K20: 0 | L20: 0 | M20: 0 | N20: 0 | O20: 0 | P20: 0 | Q20: 0 | R20: 0 | S20: 0 | T20: 0 | U20: 0 | V20: 0 | W20: 0 | X20: 0 | Y20: 0 | Z20: 0 | AA20: 0 | AB20: 0 | AC20: 0 | AD20: 0 | AE20: 0 | AF20: 0 | AG20: 0 | AH20: 0 | AI20: - -
A21: Transportation | B21: Natural Gas: Use by Sector: Transportation: Reference case | C21: AEO.2023.REF2023.CNSM_NA_TRN_NA_NG_NA_USA_TRLCF.A | D21: Tcf | F21: 1.298378 | G21: 1.266994 | H21: 1.225015 | I21: 1.213742 | J21: 1.23106 | K21: 1.222495 | L21: 1.214443 | M21: 1.239322 | N21: 1.28755 | O21: 1.338387 | P21: 1.394878 | Q21: 1.451291 | R21: 1.498329 | S21: 1.52884 | T21: 1.552042 | U21: 1.571726 | V21: 1.589475 | W21: 1.596188 | X21: 1.612993 | Y21: 1.626597 | Z21: 1.640996 | AA21: 1.654405 | AB21: 1.669935 | AC21: 1.683864 | AD21: 1.697575 | AE21: 1.718812 | AF21: 1.742685 | AG21: 1.759869 | AH21: 1.780975 | AI21: 0.011
A22: Motor Vehicles | B22: Trains | C22: and Ships | D22: Natural Gas: Use by Sector: Transportation: Vehicles: Reference case | E22: AEO.2023.REF2023.CNSM_NA_MVF_NA_NG_NA_USA_TRLCF.A | F22: Tcf | H22: 0.104304 | I22: 0.111244 | J22: 0.120881 | K22: 0.118723 | L22: 0.1297 | M22: 0.131696 | N22: 0.136779 | O22: 0.140379 | P22: 0.141662 | Q22: 0.142376 | R22: 0.143415 | S22: 0.144205 | T22: 0.146421 | U22: 0.150018 | V22: 0.155319 | W22: 0.160994 | X22: 0.165954 | Y22: 0.173789 | Z22: 0.180587 | AA22: 0.189002 | AB22: 0.197866 | AC22: 0.208548 | AD22: 0.218929 | AE22: 0.230091 | AF22: 0.238662 | AG22: 0.252568 | AH22: 0.268154 | AI22: 0.284226 | AJ22: 0.300612 | AK22: 0.039
A23: Pipeline and Distribution Fuel | B23: Natural Gas: Use by Sector: Transportation: Pipeline Fuel: Reference case | C23: AEO.2023.REF2023.CNSM_NA_PIPL_NA_NG_PFT_USA_TRLCF.A | D23: Tcf | F23: 0.873416 | G23: 0.791266 | H23: 0.733831 | I23: 0.700822 | J23: 0.671022 | K23: 0.630651 | L23: 0.592023 | M23: 0.590196 | N23: 0.58854 | O23: 0.590064 | P23: 0.595722 | Q23: 0.603939 | R23: 0.608261 | S23: 0.610875 | T23: 0.611382 | U23: 0.610384 | V23: 0.615074 | W23: 0.613952 | X23: 0.622765 | Y23: 0.629148 | Z23: 0.634683 | AA23: 0.63741 | AB23: 0.641364 | AC23: 0.645326 | AD23: 0.650466 | AE23: 0.657796 | AF23: 0.66489 | AG23: 0.667196 | AH23: 0.671916 | AI23: -0.009
A24: Fuel Used to Liquefy Gas for Export | B24: Natural Gas: Use by Sector: Transportation: Liquefaction for Export: Reference case | C24: AEO.2023.REF2023.CNSM_NA_LQFCT_NA_NG_LQFCT_USA_TRLCF.A | D24: Tcf | F24: 0.320659 | G24: 0.364485 | H24: 0.370303 | I24: 0.394198 | J24: 0.430338 | K24: 0.460147 | L24: 0.485641 | M24: 0.508747 | N24: 0.557347 | O24: 0.605947 | P24: 0.655741 | Q24: 0.703147 | R24: 0.743647 | S24: 0.767947 | T24: 0.785341 | U24: 0.800347 | V24: 0.808447 | W24: 0.808447 | X24: 0.809641 | Y24: 0.808447 | Z24: 0.808447 | AA24: 0.808447 | AB24: 0.809641 | AC24: 0.808447 | AD24: 0.808447 | AE24: 0.808447 | AF24: 0.809641 | AG24: 0.808447 | AH24: 0.808447 | AI24: 0.034
A25: Electric Power | B25: Natural Gas: Use by Sector: Electric Power: Reference case | C25: AEO.2023.REF2023.CNSM_NA_ELEP_NA_NG_NA_USA_TRLCF.A | D25: Tcf | F25: 11.799821 | G25: 10.874231 | H25: 10.15932 | I25: 9.678199 | J25: 9.269681 | K25: 8.619404 | L25: 8.289996 | M25: 8.050027 | N25: 7.707353 | O25: 7.365824 | P25: 7.121314 | Q25: 6.946913 | R25: 6.77484 | S25: 6.706319 | T25: 6.708906 | U25: 6.78039 | V25: 6.941749 | W25: 7.035107 | X25: 7.202128 | Y25: 7.278445 | Z25: 7.381327 | AA25: 7.45081 | AB25: 7.473168 | AC25: 7.547843 | AD25: 7.522304 | AE25: 7.552913 | AF25: 7.621141 | AG25: 7.660525 | AH25: 7.744609 | AI25: -0.015
A26: Discrepancy | B26: Natural Gas: Discrepancy: Reference case | C26: AEO.2023.REF2023.UNC_DESCR_NA_NA_NG_NA_USA_TRLCF.A | D26: Tcf | F26: 0.345703 | G26: 0.584641 | H26: 0.516209 | I26: 0.457045 | J26: 0.406712 | K26: 0.361244 | L26: 0.321404 | M26: 0.321831 | N26: 0.314142 | O26: 0.318394 | P26: 0.31427 | Q26: 0.324993 | R26: 0.320419 | S26: 0.359745 | T26: 0.321245 | U26: 0.317987 | V26: 0.308048 | W26: 0.310028 | X26: 0.314213 | Y26: 0.31756 | Z26: 0.30769 | AA26: 0.295959 | AB26: 0.291849 | AC26: 0.387688 | AD26: 0.28797 | AE26: 0.415039 | AF26: 0.324659 | AG26: 0.306042 | AH26: 0.504618 | AI26: - -
A27: Natural Gas Prices
A28: Natural Gas Spot Price at Henry Hub
A29: (2022 dollars per million Btu) | B29: Natural Gas: Henry Hub Spot Price: Reference case | C29: AEO.2023.REF2023.PRCE_HHP_NA_NA_NG_NA_USA_Y13DLRPMMBTU.A | D29: 2022 $/MMBtu | F29: 6.523997 | G29: 5.266376 | H29: 4.072381 | I29: 3.489514 | J29: 3.065508 | K29: 2.853001 | L29: 2.799904 | M29: 2.825097 | N29: 2.91248 | O29: 3.043758 | P29: 3.208004 | Q29: 3.416918 | R29: 3.56943 | S29: 3.681824 | T29: 3.694155 | U29: 3.737596 | V29: 3.866561 | W29: 3.78878 | X29: 3.938065 | Y29: 4.022155 | Z29: 4.014737 | AA29: 3.950616 | AB29: 3.913768 | AC29: 3.910706 | AD29: 3.907083 | AE29: 3.870706 | AF29: 3.849094 | AG29: 3.783895 | AH29: 3.771015 | AI29: -0.019
A30: Delivered Prices
A31: (2022 dollars per thousand cubic feet)
A32: Residential | B32: Natural Gas: Delivered Prices: Residential: Reference case | C32: AEO.2023.REF2023.PRCE_NA_RESD_NA_NG_NA_USA_Y13DLRPMCF.A | D32: 2022 $/Mcf | F32: 14.851385 | G32: 14.613103 | H32: 13.320674 | I32: 12.568542 | J32: 11.938526 | K32: 11.516709 | L32: 11.244637 | M32: 11.297374 | N32: 11.341838 | O32: 11.448148 | P32: 11.542928 | Q32: 11.695349 | R32: 11.820528 | S32: 11.932122 | T32: 11.985453 | U32: 12.072364 | V32: 12.21761 | W32: 12.224497 | X32: 12.320653 | Y32: 12.420988 | Z32: 12.447018 | AA32: 12.433571 | AB32: 12.389417 | AC32: 12.451289 | AD32: 12.773996 | AE32: 12.757806 | AF32: 12.723811 | AG32: 12.728624 | AH32: 12.764476 | AI32: -0.005
A33: Commercial | B33: Natural Gas: Delivered Prices: Commercial: Reference case | C33: AEO.2023.REF2023.PRCE_NA_COMM_NA_NG_NA_USA_Y13DLRPMCF.A | D33: 2022 $/Mcf | F33: 11.415294 | G33: 10.728111 | H33: 9.689114 | I33: 9.191208 | J33: 8.786163 | K33: 8.566701 | L33: 8.471746 | M33: 8.510685 | N33: 8.536977 | O33: 8.619786 | P33: 8.694034 | Q33: 8.831333 | R33: 8.936175 | S33: 9.027164 | T33: 9.064223 | U33: 9.135649 | V33: 9.26419 | W33: 9.26075 | X33: 9.346378 | Y33: 9.434954 | Z33: 9.451041 | AA33: 9.430367 | AB33: 9.382954 | AC33: 9.433675 | AD33: 9.638147 | AE33: 9.596008 | AF33: 9.551413 | AG33: 9.551454 | AH33: 9.584112 | AI33: -0.006
A34: Industrial | B34: Natural Gas: Delivered Prices: Industrial: Reference case | C34: AEO.2023.REF2023.PRCE_NA_IDAL_NA_NG_NA_USA_Y13DLRPMCF.A | D34: 2022 $/Mcf | F34: 7.616823 | G34: 6.514565 | H34: 5.361677 | I34: 4.771115 | J34: 4.321446 | K34: 4.073116 | L34: 3.986617 | M34: 4.002231 | N34: 4.062998 | O34: 4.172425 | P34: 4.287567 | Q34: 4.451732 | R34: 4.582922 | S34: 4.698439 | T34: 4.718104 | U34: 4.7644 | V34: 4.893519 | W34: 4.836315 | X34: 4.960828 | Y34: 5.040644 | Z34: 5.034396 | AA34: 4.981189 | AB34: 4.929628 | AC34: 4.927132 | AD34: 4.889997 | AE34: 4.854081 | AF34: 4.818973 | AG34: 4.775721 | AH34: 4.771768 | AI34: -0.017
A35: Transportation | B35: Natural Gas: Delivered Prices: Transportation: Reference case | C35: AEO.2023.REF2023.PRCE_NA_TRN_NA_NG_NA_USA_Y13DLRPMCF.A | D35: 2022 $/Mcf | F35: 18.233704 | G35: 16.934088 | H35: 15.467999 | I35: 14.862036 | J35: 14.140349 | K35: 13.775438 | L35: 13.516741 | M35: 13.379853 | N35: 13.303586 | O35: 13.292125 | P35: 13.270398 | Q35: 13.314075 | R35: 13.310819 | S35: 13.281555 | T35: 13.144871 | U35: 13.03176 | V35: 13.025172 | W35: 12.814609 | X35: 12.791951 | Y35: 12.729706 | Z35: 12.588048 | AA35: 12.407153 | AB35: 12.225408 | AC35: 12.150856 | AD35: 12.777818 | AE35: 12.609349 | AF35: 12.449089 | AG35: 12.321486 | AH35: 12.23544 | AI35: -0.014
A36: Electric Power | B36: Natural Gas: Delivered Prices: Electric Power: Reference case | C36: AEO.2023.REF2023.PRCE_NA_ELEP_NA_NG_NA_USA_Y13DLRPMCF.A | D36: 2022 $/Mcf | F36: 7.258743 | G36: 5.812993 | H36: 4.63491 | I36: 3.999119 | J36: 3.50011 | K36: 3.19096 | L36: 3.068681 | M36: 3.063734 | N36: 3.101904 | O36: 3.175818 | P36: 3.259538 | Q36: 3.393531 | R36: 3.506565 | S36: 3.630531 | T36: 3.666931 | U36: 3.715862 | V36: 3.860356 | W36: 3.830414 | X36: 3.974774 | Y36: 4.050839 | Z36: 4.031197 | AA36: 3.977907 | AB36: 3.906839 | AC36: 3.898304 | AD36: 3.873679 | AE36: 3.840307 | AF36: 3.823201 | AG36: 3.766449 | AH36: 3.764557 | AI36: -0.023
A37: Average | B37: Natural Gas: Delivered Prices: Average: Reference case | C37: AEO.2023.REF2023.PRCE_NA_NA_NA_NG_NA_USA_Y13DLRPMCF.A | D37: 2022 $/Mcf | F37: 9.209998 | G37: 8.271177 | H37: 7.106081 | I37: 6.526754 | J37: 6.0689 | K37: 5.83237 | L37: 5.730124 | M37: 5.772043 | N37: 5.850703 | O37: 5.979175 | P37: 6.097002 | Q37: 6.262642 | R37: 6.397126 | S37: 6.512626 | T37: 6.539738 | U37: 6.584328 | V37: 6.695644 | W37: 6.649044 | X37: 6.744039 | Y37: 6.813235 | Z37: 6.795757 | AA37: 6.742805 | AB37: 6.682416 | AC37: 6.686844 | AD37: 6.760439 | AE37: 6.718736 | AF37: 6.676045 | AG37: 6.635656 | AH37: 6.628702 | AI37: -0.012
A38: Natural Gas Spot Price at Henry Hub
A39: (nominal dollars per million Btu) | B39: Natural Gas: Henry Hub Spot Price: Reference case | C39: AEO.2023.REF2023.PRCE_HHP_NA_NA_NG_NA_USA_NDLRPMBTU.A | D39: nom $/MMBtu | F39: 6.523997 | G39: 5.48408 | H39: 4.344237 | I39: 3.803406 | J39: 3.4125 | K39: 3.244545 | L39: 3.252955 | M39: 3.354208 | N39: 3.535144 | O39: 3.779019 | P39: 4.074234 | Q39: 4.442329 | R39: 4.751782 | S39: 5.016179 | T39: 5.148898 | U39: 5.326049 | V39: 5.631648 | W39: 5.639552 | X39: 5.992483 | Y39: 6.257671 | Z39: 6.387211 | AA39: 6.429273 | AB39: 6.516381 | AC39: 6.663004 | AD39: 6.813882 | AE39: 6.910819 | AF39: 7.036972 | AG39: 7.083812 | AH39: 7.230118 | AI39: 0.004
A40: Delivered Prices
...

Sheet AEO 2025 Table 13
A1: Table 13. Natural Gas Supply, Disposition, and Prices
A2: https://www.eia.gov/outlooks/aeo/data/browser/#/?id=13-AEO2025&cases=highZTC&sourcekey=0
A3: Tue Dec 02 2025 13:20:31 GMT-0800 (Pacific Standard Time)
A4: Source: U.S. Energy Information Administration
B5: full name | C5: api key | D5: units | E5: 2023 | F5: 2024 | G5: 2025 | H5: 2026 | I5: 2027 | J5: 2028 | K5: 2029 | L5: 2030 | M5: 2031 | N5: 2032 | O5: 2033 | P5: 2034 | Q5: 2035 | R5: 2036 | S5: 2037 | T5: 2038 | U5: 2039 | V5: 2040 | W5: 2041 | X5: 2042 | Y5: 2043 | Z5: 2044 | AA5: 2045 | AB5: 2046 | AC5: 2047 | AD5: 2048 | AE5: 2049 | AF5: 2050 | AG5: Growth (2024-2050)
A6: Production
A7: Dry Gas Production | B7: Natural Gas: Production: Dry Gas Production: High Zero-Carbon Technology Cost | C7: AEO.2025.HIGHZTC.SUP_PRD_NA_NA_NG_DNG_USA_TRLCF.A | D7: Tcf | F7: 38.395714 | G7: 38.575592 | H7: 38.973137 | I7: 39.201183 | J7: 40.363079 | K7: 41.169594 | L7: 42.049503 | M7: 42.139233 | N7: 43.939369 | O7: 43.920151 | P7: 43.910572 | Q7: 43.515194 | R7: 43.168228 | S7: 42.547188 | T7: 42.325035 | U7: 41.954548 | V7: 42.21479 | W7: 42.761806 | X7: 42.998825 | Y7: 43.180714 | Z7: 43.340855 | AA7: 43.59359 | AB7: 43.969772 | AC7: 44.232101 | AD7: 44.389687 | AE7: 44.596985 | AF7: 44.749317 | AG7: 0.006
A8: Supplemental Natural Gas | B8: Natural Gas: Production: Supplemental Natural Gas: High Zero-Carbon Technology Cost | C8: AEO.2025.HIGHZTC.SUP_PRD_NA_NA_NG_SPNG_USA_TRLCF.A | D8: Tcf | F8: 0.1159 | G8: 0.1038 | H8: 0.098233 | I8: 0.092666 | J8: 0.087099 | K8: 0.081532 | L8: 0.075964 | M8: 0.075964 | N8: 0.075964 | O8: 0.075964 | P8: 0.075964 | Q8: 0.075964 | R8: 0.075964 | S8: 0.075964 | T8: 0.075964 | U8: 0.075964 | V8: 0.075964 | W8: 0.075964 | X8: 0.075964 | Y8: 0.075964 | Z8: 0.075964 | AA8: 0.075964 | AB8: 0.075964 | AC8: 0.075964 | AD8: 0.075964 | AE8: 0.075964 | AF8: 0.075964 | AG8: -0.016
A9: Renewable Natural Gas | B9: Natural Gas: Production: Renewable Natural Gas: High Zero-Carbon Technology Cost | C9: AEO.2025.HIGHZTC.SUP_PRD_NA_NA_NG_RNG_USA_TRLCF.A | D9: Tcf | F9: 0.09652 | G9: 0.104645 | H9: 0.104645 | I9: 0.11496 | J9: 0.11496 | K9: 0.11496 | L9: 0.11496 | M9: 0.11496 | N9: 0.11496 | O9: 0.11496 | P9: 0.11496 | Q9: 0.11496 | R9: 0.11496 | S9: 0.11496 | T9: 0.11496 | U9: 0.11496 | V9: 0.11496 | W9: 0.11496 | X9: 0.11496 | Y9: 0.11496 | Z9: 0.11496 | AA9: 0.11496 | AB9: 0.11496 | AC9: 0.11496 | AD9: 0.11496 | AE9: 0.11496 | AF9: 0.115501 | AG9: 0.007
A10: Net Imports | B10: Natural Gas: Net Imports: High Zero-Carbon Technology Cost | C10: AEO.2025.HIGHZTC.TRAD_NETIMP_NA_NA_NG_NA_USA_TRLCF.A | D10: Tcf | F10: -4.73696 | G10: -5.657986 | H10: -6.638683 | I10: -6.303125 | J10: -7.369331 | K10: -7.94297 | L10: -8.510733 | M10: -8.761023 | N10: -9.030772 | O10: -9.428055 | P10: -9.84154 | Q10: -9.98183 | R10: -10.124131 | S10: -10.227389 | T10: -10.250424 | U10: -10.291261 | V10: -10.438177 | W10: -10.616791 | X10: -10.646292 | Y10: -10.566377 | Z10: -10.494195 | AA10: -10.52496 | AB10: -10.717752 | AC10: -10.773986 | AD10: -10.725961 | AE10: -10.625355 | AF10: -10.590052 | AG10: 0.031
A11: Pipeline | B11: Natural Gas: Net Imports: Pipeline: High Zero-Carbon Technology Cost | C11: AEO.2025.HIGHZTC.TRAD_NETIMP_NA_NA_NG_PIPL_USA_TRLCF.A | D11: Tcf | F11: -0.371399 | G11: -0.669318 | H11: -1.327138 | I11: -0.984286 | J11: -1.021896 | K11: -0.87573 | L11: -0.695118 | M11: -0.742396 | N11: -0.7931 | O11: -1.009427 | P11: -1.223377 | Q11: -1.26367 | R11: -1.28646 | S11: -1.308762 | T11: -1.331797 | U11: -1.372633 | V11: -1.500507 | W11: -1.698164 | X11: -1.728665 | Y11: -1.687564 | Z11: -1.638133 | AA11: -1.690658 | AB11: -1.916426 | AC11: -1.968033 | AD11: -1.930123 | AE11: -1.853135 | AF11: -1.781184 | AG11: 0.062
A12: Liquefied Natural Gas | B12: Natural Gas: Net Imports: Liquefied Natural Gas: High Zero-Carbon Technology Cost | C12: AEO.2025.HIGHZTC.TRAD_NETIMP_NA_NA_NG_LNG_USA_TRLCF.A | D12: Tcf | F12: -4.36556 | G12: -4.988667 | H12: -5.311545 | I12: -5.318838 | J12: -6.347436 | K12: -7.06724 | L12: -7.815614 | M12: -8.018627 | N12: -8.23767 | O12: -8.418627 | P12: -8.618162 | Q12: -8.718159 | R12: -8.83767 | S12: -8.918627 | T12: -8.918627 | U12: -8.918627 | V12: -8.937671 | W12: -8.918627 | X12: -8.917626 | Y12: -8.878812 | Z12: -8.856062 | AA12: -8.834302 | AB12: -8.801325 | AC12: -8.805953 | AD12: -8.795837 | AE12: -8.772219 | AF12: -8.808866 | AG12: 0.027
A13: Total Supply | B13: Natural Gas: Total Supply: High Zero-Carbon Technology Cost | C13: AEO.2025.HIGHZTC.SUP_NA_TOT_NA_NG_NA_USA_TRLCF.A | D13: Tcf | F13: 33.774651 | G13: 33.021408 | H13: 32.432686 | I13: 32.990723 | J13: 33.080845 | K13: 33.308155 | L13: 33.614738 | M13: 33.454178 | N13: 34.984562 | O13: 34.568062 | P13: 34.144997 | Q13: 33.609329 | R13: 33.120064 | S13: 32.395763 | T13: 32.150578 | U13: 31.739254 | V13: 31.852579 | W13: 32.220982 | X13: 32.428497 | Y13: 32.690304 | Z13: 32.922626 | AA13: 33.144596 | AB13: 33.327988 | AC13: 33.534081 | AD13: 33.739693 | AE13: 34.047596 | AF13: 34.235229 | AG13: 0.001
A14: Consumption by Sector | B14: Natural Gas: Use by Sector: Total: High Zero-Carbon Technology Cost | C14: AEO.2025.HIGHZTC.CNSM_NA_ALLS_NA_NG_TOT_USA_TRLCF.A | D14: Tcf | F14: 33.066139 | G14: 32.79578 | H14: 32.182739 | I14: 32.67984 | J14: 32.748764 | K14: 32.915066 | L14: 33.15255 | M14: 33.052132 | N14: 34.631451 | O14: 34.222492 | P14: 33.80769 | Q14: 33.263802 | R14: 32.840008 | S14: 32.067276 | T14: 31.844267 | U14: 31.377337 | V14: 31.456423 | W14: 31.834995 | X14: 32.177868 | Y14: 32.423691 | Z14: 32.669796 | AA14: 32.850601 | AB14: 33.113304 | AC14: 33.340969 | AD14: 33.559128 | AE14: 33.8125 | AF14: 33.88002 | AG14: 0.001
A15: Residential | B15: Natural Gas: Use by Sector: Residential: High Zero-Carbon Technology Cost | C15: AEO.2025.HIGHZTC.CNSM_NA_RESD_NA_NG_NA_USA_TRLCF.A | D15: Tcf | F15: 4.434913 | G15: 4.784401 | H15: 4.816495 | I15: 4.835759 | J15: 4.84548 | K15: 4.832474 | L15: 4.811677 | M15: 4.779337 | N15: 4.733211 | O15: 4.693446 | P15: 4.654109 | Q15: 4.62436 | R15: 4.601415 | S15: 4.582486 | T15: 4.564576 | U15: 4.547687 | V15: 4.52856 | W15: 4.504055 | X15: 4.477375 | Y15: 4.449614 | Z15: 4.423026 | AA15: 4.39795 | AB15: 4.372572 | AC15: 4.347918 | AD15: 4.324595 | AE15: 4.301747 | AF15: 4.278714 | AG15: -0.001
A16: Commercial | B16: Natural Gas: Use by Sector: Commercial: High Zero-Carbon Technology Cost | C16: AEO.2025.HIGHZTC.CNSM_NA_COMM_NA_NG_NA_USA_TRLCF.A | D16: Tcf | F16: 3.301256 | G16: 3.478977 | H16: 3.511993 | I16: 3.518725 | J16: 3.510489 | K16: 3.510571 | L16: 3.50362 | M16: 3.499091 | N16: 3.486057 | O16: 3.470571 | P16: 3.458906 | Q16: 3.45632 | R16: 3.462904 | S16: 3.474572 | T16: 3.487757 | U16: 3.503216 | V16: 3.515867 | W16: 3.523517 | X16: 3.528426 | Y16: 3.531899 | Z16: 3.538031 | AA16: 3.544663 | AB16: 3.548947 | AC16: 3.555423 | AD16: 3.563769 | AE16: 3.571068 | AF16: 3.577246 | AG16: 0.003
A17: Industrial | B17: Natural Gas: Use by Sector: Industrial: High Zero-Carbon Technology Cost | C17: AEO.2025.HIGHZTC.CNSM_NA_IDAL_NA_NG_NA_USA_TRLCF.A | D17: Tcf | F17: 10.513494 | G17: 10.645778 | H17: 10.550887 | I17: 10.57701 | J17: 10.633311 | K17: 10.684954 | L17: 10.737125 | M17: 10.809804 | N17: 10.954347 | O17: 11.016701 | P17: 11.073318 | Q17: 11.108751 | R17: 11.155025 | S17: 11.190754 | T17: 11.270637 | U17: 11.343785 | V17: 11.436538 | W17: 11.504867 | X17: 11.572164 | Y17: 11.65315 | Z17: 11.718382 | AA17: 11.782353 | AB17: 11.846175 | AC17: 11.928168 | AD17: 11.992293 | AE17: 12.046882 | AF17: 12.096884 | AG17: 0.005
A18: Other Industrial | B18: Natural Gas: Use by Sector: Industrial: Other: High Zero-Carbon Technology Cost | C18: AEO.2025.HIGHZTC.CNSM_NA_IDAL_OTH_NG_NA_USA_TRLCF.A | D18: Tcf | F18: 7.667322 | G18: 7.777962 | H18: 7.561479 | I18: 7.566178 | J18: 7.570857 | K18: 7.591291 | L18: 7.609484 | M18: 7.650037 | N18: 7.67195 | O18: 7.653161 | P18: 7.631577 | Q18: 7.615146 | R18: 7.61292 | S18: 7.622569 | T18: 7.661403 | U18: 7.710259 | V18: 7.758837 | W18: 7.778039 | X18: 7.800282 | Y18: 7.842208 | Z18: 7.867923 | AA18: 7.894856 | AB18: 7.924067 | AC18: 7.977438 | AD18: 8.017321 | AE18: 8.049789 | AF18: 8.073728 | AG18: 0.002
... A21: Transportation | B21: Natural Gas: Use by Sector: Transportation: High Zero-Carbon Technology Cost | C21: AEO.2025.HIGHZTC.CNSM_NA_TRN_NA_NG_NA_USA_TRLCF.A | D21: Tcf | F21: 1.33269 | G21: 1.338906 | H21: 1.365317 | I21: 1.343246 | J21: 1.392562 | K21: 1.424122 | L21: 1.451179 | M21: 1.456405 | N21: 1.482111 | O21: 1.489917 | P21: 1.50517 | Q21: 1.515141 | R21: 1.5277 | S21: 1.53456 | T21: 1.538752 | U21: 1.545519 | V21: 1.561324 | W21: 1.575612 | X21: 1.594359 | Y21: 1.613225 | Z21: 1.636034 | AA21: 1.659127 | AB21: 1.678597 | AC21: 1.702153 | AD21: 1.726235 | AE21: 1.75111 | AF21: 1.783635 | AG21: 0.011
A22: Motor Vehicles | B22: Trains | C22: and Ships | D22: Natural Gas: Use by Sector: Transportation: Vehicles: High Zero-Carbon Technology Cost | E22: AEO.2025.HIGHZTC.CNSM_NA_MVF_NA_NG_NA_USA_TRLCF.A | F22: Tcf | H22: 0.085414 | I22: 0.092895 | J22: 0.098795 | K22: 0.103331 | L22: 0.10687 | M22: 0.109881 | N22: 0.112021 | O22: 0.113371 | P22: 0.113184 | Q22: 0.112656 | R22: 0.112681 | S22: 0.113227 | T22: 0.11434 | U22: 0.116177 | V22: 0.119021 | W22: 0.123052 | X22: 0.129217 | Y22: 0.136248 | Z22: 0.144318 | AA22: 0.153423 | AB22: 0.162919 | AC22: 0.17303 | AD22: 0.18404 | AE22: 0.195253 | AF22: 0.206759 | AG22: 0.218776 | AH22: 0.23118 | AI22: 0.039
A23: Pipeline and Distribution Fuel | B23: Natural Gas: Use by Sector: Transportation: Pipeline Fuel: High Zero-Carbon Technology Cost | C23: AEO.2025.HIGHZTC.CNSM_NA_PIPL_NA_NG_PFT_USA_TRLCF.A | D23: Tcf | F23: 0.892073 | G23: 0.840209 | H23: 0.834385 | I23: 0.807006 | J23: 0.769286 | K23: 0.739349 | L23: 0.703466 | M23: 0.690898 | N23: 0.699048 | O23: 0.692725 | P23: 0.69179 | Q23: 0.693116 | R23: 0.694881 | S23: 0.693348 | T23: 0.694695 | U23: 0.69743 | V23: 0.705528 | W23: 0.714328 | X23: 0.725086 | Y23: 0.737991 | Z23: 0.753147 | AA23: 0.767891 | AB23: 0.779023 | AC23: 0.79099 | AD23: 0.804386 | AE23: 0.819157 | AF23: 0.83631 | AG23: -0.002
A24: Fuel Used to Liquefy Gas for Export | B24: Natural Gas: Use by Sector: Transportation: Liquefaction for Export: High Zero-Carbon Technology Cost | C24: AEO.2025.HIGHZTC.CNSM_NA_LQFCT_NA_NG_LQFCT_USA_TRLCF.A | D24: Tcf | F24: 0.355203 | G24: 0.405802 | H24: 0.432136 | I24: 0.432909 | J24: 0.516407 | K24: 0.574892 | L24: 0.635692 | M24: 0.652136 | N24: 0.669878 | O24: 0.684536 | P24: 0.700698 | Q24: 0.708798 | R24: 0.718478 | S24: 0.725036 | T24: 0.725036 | U24: 0.725036 | V24: 0.726578 | W24: 0.725036 | X24: 0.724955 | Y24: 0.721811 | Z24: 0.719968 | AA24: 0.718206 | AB24: 0.715534 | AC24: 0.715909 | AD24: 0.71509 | AE24: 0.713177 | AF24: 0.716145 | AG24: 0.027
A25: Electric Power | B25: Natural Gas: Use by Sector: Electric Power: High Zero-Carbon Technology Cost | C25: AEO.2025.HIGHZTC.CNSM_NA_ELEP_NA_NG_NA_USA_TRLCF.A | D25: Tcf | F25: 13.483787 | G25: 12.547716 | H25: 11.93805 | I25: 12.405101 | J25: 12.366923 | K25: 12.462942 | L25: 12.64895 | M25: 12.507499 | N25: 13.97573 | O25: 13.551859 | P25: 13.116185 | Q25: 12.559227 | R25: 12.092962 | S25: 11.284903 | T25: 10.982544 | U25: 10.437131 | V25: 10.414136 | W25: 10.726946 | X25: 11.005544 | Y25: 11.175805 | Z25: 11.354323 | AA25: 11.466511 | AB25: 11.667014 | AC25: 11.807306 | AD25: 11.952235 | AE25: 12.141692 | AF25: 12.143543 | AG25: -0.004
A26: Discrepancy | B26: Natural Gas: Discrepancy: High Zero-Carbon Technology Cost | C26: AEO.2025.HIGHZTC.UNC_DESCR_NA_NA_NG_NA_USA_TRLCF.A | D26: Tcf | F26: 0.708511 | G26: 0.225628 | H26: 0.249947 | I26: 0.310883 | J26: 0.332081 | K26: 0.393089 | L26: 0.462189 | M26: 0.402046 | N26: 0.353111 | O26: 0.34557 | P26: 0.337307 | Q26: 0.345528 | R26: 0.280056 | S26: 0.328487 | T26: 0.306311 | U26: 0.361917 | V26: 0.396156 | W26: 0.385986 | X26: 0.250629 | Y26: 0.266613 | Z26: 0.252831 | AA26: 0.293995 | AB26: 0.214684 | AC26: 0.193111 | AD26: 0.180565 | AE26: 0.235096 | AF26: 0.355209 | AG26: -0.026
A27: Natural Gas Prices
A28: Natural Gas Spot Price at Henry Hub
A29: (2024 dollars per MMBtu) | B29: Natural Gas: Henry Hub Spot Price: High Zero-Carbon Technology Cost | C29: AEO.2025.HIGHZTC.PRCE_HHP_NA_NA_NG_NA_USA_Y13DLRPMMBTU.A | D29: 2024 $/MMBtu | F29: 2.191582 | G29: 2.883112 | H29: 2.74762 | I29: 2.637806 | J29: 2.748927 | K29: 2.919188 | L29: 3.159309 | M29: 3.320045 | N29: 3.767092 | O29: 4.157829 | P29: 4.435957 | Q29: 4.524341 | R29: 4.54022 | S29: 4.508521 | T29: 4.457513 | U29: 4.400403 | V29: 4.435027 | W29: 4.522207 | X29: 4.606845 | Y29: 4.711344 | Z29: 4.796789 | AA29: 4.847375 | AB29: 4.8777 | AC29: 4.887398 | AD29: 4.920235 | AE29: 5.013657 | AF29: 5.126889 | AG29: 0.033
A30: Delivered Prices
A31: (2024 dollars per thousand cubic feet)
A32: Residential | B32: Natural Gas: Delivered Prices: Residential: High Zero-Carbon Technology Cost | C32: AEO.2025.HIGHZTC.PRCE_NA_RESD_NA_NG_NA_USA_Y13DLRPMCF.A | D32: 2024 $/Mcf | F32: 14.461629 | G32: 13.17666 | H32: 12.95107 | I32: 12.530008 | J32: 12.274893 | K32: 12.153533 | L32: 12.0699 | M32: 12.278881 | N32: 12.725538 | O32: 13.122069 | P32: 13.391861 | Q32: 13.542139 | R32: 13.557489 | S32: 13.544172 | T32: 13.521586 | U32: 13.461446 | V32: 13.494338 | W32: 13.624146 | X32: 13.737558 | Y32: 13.83361 | Z32: 13.893803 | AA32: 13.983382 | AB32: 14.083962 | AC32: 14.129821 | AD32: 14.159422 | AE32: 14.244238 | AF32: 14.31883 | AG32: 0
A33: Commercial | B33: Natural Gas: Delivered Prices: Commercial: High Zero-Carbon Technology Cost | C33: AEO.2025.HIGHZTC.PRCE_NA_COMM_NA_NG_NA_USA_Y13DLRPMCF.A | D33: 2024 $/Mcf | F33: 9.91898 | G33: 8.795626 | H33: 8.897083 | I33: 8.83655 | J33: 8.919644 | K33: 9.100629 | L33: 9.317294 | M33: 9.467894 | N33: 9.832458 | O33: 10.159771 | P33: 10.368036 | Q33: 10.468319 | R33: 10.449934 | S33: 10.407696 | T33: 10.357066 | U33: 10.270552 | V33: 10.270808 | W33: 10.360629 | X33: 10.434948 | Y33: 10.495902 | Z33: 10.522658 | AA33: 10.578819 | AB33: 10.648362 | AC33: 10.665274 | AD33: 10.670247 | AE33: 10.729241 | AF33: 10.778672 | AG33: 0.003
A34: Industrial | B34: Natural Gas: Delivered Prices: Industrial: High Zero-Carbon Technology Cost | C34: AEO.2025.HIGHZTC.PRCE_NA_IDAL_NA_NG_NA_USA_Y13DLRPMCF.A | D34: 2024 $/Mcf | F34: 3.463878 | G34: 4.163002 | H34: 4.060122 | I34: 3.935598 | J34: 4.016657 | K34: 4.173019 | L34: 4.391423 | M34: 4.556916 | N34: 5.014323 | O34: 5.375893 | P34: 5.618011 | Q34: 5.702828 | R34: 5.689706 | S34: 5.637167 | T34: 5.574771 | U34: 5.491282 | V34: 5.512477 | W34: 5.608978 | X34: 5.69496 | Y34: 5.772568 | Z34: 5.829073 | AA34: 5.880927 | AB34: 5.934381 | AC34: 5.94011 | AD34: 5.954903 | AE34: 6.018018 | AF34: 6.085726 | AG34: 0.022
A35: Transportation | B35: Natural Gas: Delivered Prices: Transportation: High Zero-Carbon Technology Cost | C35: AEO.2025.HIGHZTC.PRCE_NA_TRN_NA_NG_NA_USA_Y13DLRPMCF.A | D35: 2024 $/Mcf | F35: 15.065847 | G35: 15.617211 | H35: 15.54682 | I35: 15.422724 | J35: 15.475124 | K35: 15.612073 | L35: 15.763506 | M35: 15.880778 | N35: 16.262199 | O35: 16.507532 | P35: 16.626369 | Q35: 16.624754 | R35: 16.512358 | S35: 16.371016 | T35: 16.24568 | U35: 16.063837 | V35: 15.988713 | W35: 16.00351 | X35: 16.001871 | Y35: 16.000423 | Z35: 15.969303 | AA35: 15.945396 | AB35: 15.937248 | AC35: 15.86247 | AD35: 15.79395 | AE35: 15.784898 | AF35: 15.768268 | AG35: 0.002
A36: Electric Power | B36: Natural Gas: Delivered Prices: Electric Power: High Zero-Carbon Technology Cost | C36: AEO.2025.HIGHZTC.PRCE_NA_ELEP_NA_NG_NA_USA_Y13DLRPMCF.A | D36: 2024 $/Mcf | F36: 2.809139 | G36: 3.234845 | H36: 3.169723 | I36: 3.095491 | J36: 3.2292 | K36: 3.437231 | L36: 3.72268 | M36: 3.817652 | N36: 4.33585 | O36: 4.656738 | P36: 4.873566 | Q36: 4.94741 | R36: 4.942368 | S36: 4.906366 | T36: 4.871217 | U36: 4.813748 | V36: 4.845653 | W36: 4.926926 | X36: 5.002026 | Y36: 5.092052 | Z36: 5.180276 | AA36: 5.226538 | AB36: 5.285358 | AC36: 5.293941 | AD36: 5.317598 | AE36: 5.389843 | AF36: 5.472437 | AG36: 0.026
A37: Average | B37: Natural Gas: Delivered Prices: Average: High Zero-Carbon Technology Cost | C37: AEO.2025.HIGHZTC.PRCE_NA_NA_NA_NG_NA_USA_Y13DLRPMCF.A | D37: 2024 $/Mcf | F37: 5.550955 | G37: 5.809318 | H37: 5.8052 | I37: 5.624908 | J37: 5.677902 | K37: 5.801815 | L37: 5.977849 | M37: 6.118377 | N37: 6.46763 | O37: 6.829228 | P37: 7.079875 | Q37: 7.204213 | R37: 7.226892 | S37: 7.246867 | T37: 7.221004 | U37: 7.189759 | V37: 7.209283 | W37: 7.272129 | X37: 7.327355 | Y37: 7.389088 | Z37: 7.43451 | AA37: 7.47609 | AB37: 7.520052 | AC37: 7.517616 | AD37: 7.521401 | AE37: 7.57298 | AF37: 7.641388 | AG37: 0.012
A38: Natural Gas Spot Price at Henry Hub
A39: (nominal dollars per MMBtu) | B39: Natural Gas: Henry Hub Spot Price: High Zero-Carbon Technology Cost | C39: AEO.2025.HIGHZTC.PRCE_HHP_NA_NA_NG_NA_USA_NDLRPMBTU.A | D39: nom $/MMBtu | F39: 2.191582 | G39: 2.942171 | H39: 2.851325 | I39: 2.783173 | J39: 2.955328 | K39: 3.194383 | L39: 3.522112 | M39: 3.777838 | N39: 4.378026 | O39: 4.938162 | P39: 5.38605 | Q39: 5.612916 | R39: 5.749376 | S39: 5.828076 | T39: 5.882189 | U39: 5.926426 | V39: 6.098291 | W39: 6.350842 | X39: 6.609289 | Y39: 6.907372 | Z39: 7.188035 | AA39: 7.425647 | AB39: 7.638891 | AC39: 7.827547 | AD39: 8.059517 | AE39: 8.400294 | AF39: 8.787301 | AG39: 0.055
A40: Delivered Prices
A41: (nominal dollars per thousand cubic feet)
A42: Residential | B42: Natural Gas: Delivered Prices: Residential: High Zero-Carbon Technology Cost | C42: AEO.2025.HIGHZTC.PRCE_DELV_RESD_NA_NG_NA_USA_NDLRPMCF.A | D42: nom $/Mcf | F42: 14.461629 | G42: 13.446575 | H42: 13.439891 | I42: 13.220521 | J42: 13.196542 | K42: 13.29926 | L42: 13.45596 | M42: 13.971986 | N42: 14.78932 | O42: 15.584794 | P42: 16.26013 | Q42: 16.800436 | R42: 17.168133 | S42: 17.508286 | T42: 17.84325 | U42: 18.129765 | V42: 18.555111 | W42: 19.133314 | X42: 19.708822 | Y42: 20.281662 | Z42: 20.82 | AA42: 21.421007 | AB42: 22.056677 | AC42: 22.630005 | AD42: 23.193628 | AE42: 23.865969 | AF42: 24.541954 | AG42: 0.021
...

Sheet AEO 2022 Table 60
A1: Table 60. Natural Gas Imports and Exports
A2: https://www.eia.gov/outlooks/aeo/data/browser/#/?id=76-AEO2022&region=0-0&cases=ref2022&start=2020&end=2050&f=A&linechart=&ctype=linechart&sourcekey=0
A3: Fri Jun 03 2022 14:37:41 GMT-0700 (Pacific Daylight Time)
A4: Source: U.S. Energy Information Administration
B5: full name | C5: api key | D5: units | E5: 2020 | F5: 2021 | G5: 2022 | H5: 2023 | I5: 2024 | J5: 2025 | K5: 2026 | L5: 2027 | M5: 2028 | N5: 2029 | O5: 2030 | P5: 2031 | Q5: 2032 | R5: 2033 | S5: 2034 | T5: 2035 | U5: 2036 | V5: 2037 | W5: 2038 | X5: 2039 | Y5: 2040 | Z5: 2041 | AA5: 2042 | AB5: 2043 | AC5: 2044 | AD5: 2045 | AE5: 2046 | AF5: 2047 | AG5: 2048 | AH5: 2049 | AI5: 2050 | AJ5: Growth (2021-2050)
A6: Volumes (trillion cubic feet) | C6: 76-AEO2022.2.
A7: Imports | B7: Natural Gas: Volumes: Imports: Low economic growth | C7: 76-AEO2022.3.lowmacro-d011222a | D7: Tcf | F7: 2.730044 | G7: 2.478948 | H7: 2.399872 | I7: 2.299369 | J7: 2.227211 | K7: 2.201699 | L7: 2.167048 | M7: 2.117685 | N7: 1.987127 | O7: 1.935035 | P7: 1.844631 | Q7: 1.832976 | R7: 1.877825 | S7: 1.8405 | T7: 1.799475 | U7: 1.794174 | V7: 1.827648 | W7: 1.824522 | X7: 1.795108 | Y7: 1.761056 | Z7: 1.736678 | AA7: 1.728937 | AB7: 1.669057 | AC7: 1.548609 | AD7: 1.472641 | AE7: 1.452845 | AF7: 1.425173 | AG7: 1.428671 | AH7: 1.39673 | AI7: 1.353371 | AJ7: -0.024
