Workbook
Name gal_per_barrel: [1]About!$A$63

Sheet About
A1: BPCiObIC BAU Percent Change in Output by ISIC Code
A3: Source: | B3: Future Year Projected Changes in Output by ISIC Code
B4: U.S. EIA
B5: 2025
B6: Annual Energy Outlook 2025
B7: https://www.eia.gov/outlooks/aeo/tables_ref.php
B8: Table 23: Industrial Sector Macroeconomic Indicators
B10: U.S. Bureau of Labor Statistics
B11: 2024
B12: Industry Output and Employment
B13: https://www.bls.gov/emp/tables/industry-employment-and-output.htm
B14: Table 2.11: Output and Employment by Industry
B16: GDP Projection (see BGDP)
B17: U.S. EIA
B18: 2025
B19: Annual Energy Outlook 2025
B20: High Zero-Carbon Technology Cost
B21: https://www.eia.gov/outlooks/aeo/tables_ref.php
B22: Table 23: Industrial Sector Macroeconomic Indicators
A24: Notes
A26: We need a set of scaling factors to convert the I/O variables that contain static data (for one historical year)
A27: to future time series data.
A29: We base these scaling factors on the projected change in output for each ISIC code, which is readily
A30: available disaggregated by ISIC code. It is crucial for these projections to be disaggregated by ISIC code,
A31: because we need to know how industries grow or shrink relative to one-another, not just how they
A32: grow or shrink overall to fit GDP growth.
A34: For the U.S., we use projections from the BLS and EIA AEO. The BLS has growth rates for all ISIC codes,
A35: but only out to 2029. The EIA has projections for only certain ISIC codes, but out to 2050.
A36: Because energy demand projections for those ISIC codes come directly from EIA (see indst/BIFUbC),
A37: we use those growth rates directly. For all others, we use BLS and rescale the growth rates such that,
A38: when applied to Value Added quantities,
... A54: value added, employment, etc.).

Sheet source data>

Sheet BLS Table 2.11
A1: Table 2.11 Employment and output by industry (Employment in thousands; Output in billion of chained 2017 dollars)
A2: 2024 National Employment Matrix title | B2: 2024 National Employment Matrix code | C2: Industry type | D2: Employment, 2024 | E2: Employment, 2034 | F2: Employment change, numeric, 2024–34 | G2: Employment change, percent, 2024–34 | H2: Compound annual rate of change, employment, 2024–34 | I2: Output, 2024 | J2: Output, 2034 | K2: Compound annual rate of change, output, 2024–34 | L2: Assigned ISIC Code
A3: Total, all industries | B3: TE1000 | C3: Summary | D3: 169956.1 | E3: 175167.9 | F3: 5211.8 | G3: 3.1 | H3: 0.3 | I3: 40174.8 | J3: 48622.4 | K3: 1.9
A4: Self-employed workers | B4: TE1100 | C4: Line item | D4: 9906.4 | E4: 10122.8 | F4: 216.4 | G4: 2.2 | H4: 0.2 | I4: — | J4: — | K4: —
A5: Total wage and salary employment | B5: TE1200 | C5: Summary | D5: 160049.7 | E5: 165045.1 | F5: 4995.4 | G5: 3.1 | H5: 0.3 | I5: — | J5: — | K5: —
A6: Agriculture, forestry, fishing, and hunting | B6: 110000 | C6: Summary | D6: 1480.7 | E6: 1482.1 | F6: 1.4 | G6: 0.1 | H6: 0 | I6: 447.9 | J6: 538.8 | K6: 1.9 | L6: ISIC 01T03
A7: Crop production | B7: 111000 | C7: Line item | D7: 863.9 | E7: 881.2 | F7: 17.3 | G7: 2 | H7: 0.2 | I7: 175.8 | J7: 201.8 | K7: 1.4
A8: Animal production and aquaculture | B8: 112000 | C8: Line item | D8: 442.4 | E8: 427.6 | F8: -14.8 | G8: -3.3 | H8: -0.3 | I8: 220 | J8: 277.6 | K8: 2.4
A9: Forestry and logging | B9: 113000 | C9: Summary | D9: 47.2 | E9: 45.1 | F9: -2.1 | G9: -4.4 | H9: -0.5 | I9: — | J9: — | K9: —
A10: Forestry | B10: 1131-2 | C10: Line item | D10: 7 | E10: 6.9 | F10: -0.1 | G10: -2 | H10: -0.1 | I10: 3.9 | J10: 4.6 | K10: 1.6
A11: Logging | B11: 113300 | C11: Line item | D11: 40.2 | E11: 38.2 | F11: -2 | G11: -4.9 | H11: -0.5 | I11: 18.9 | J11: 22.1 | K11: 1.6
A12: Fishing, hunting and trapping | B12: 114000 | C12: Line item | D12: 20.9 | E12: 20.8 | F12: -0.1 | G12: -0.3 | H12: 0 | I12: 7.4 | J12: 8.6 | K12: 1.5
A13: Support activities for agriculture and forestry | B13: 115000 | C13: Line item | D13: 106.2 | E13: 107.3 | F13: 1.1 | G13: 1 | H13: 0.1 | I13: 23.6 | J13: 27.6 | K13: 1.6
A14: Mining, quarrying, and oil and gas extraction | B14: 210000 | C14: Summary | D14: 586.1 | E14: 576.8 | F14: -9.3 | G14: -1.6 | H14: -0.2 | I14: 564.6 | J14: 634.5 | K14: 1.2
A15: Oil and gas extraction | B15: 211000 | C15: Line item | D15: 122.5 | E15: 115.7 | F15: -6.8 | G15: -5.5 | H15: -0.6 | I15: 383.8 | J15: 450.7 | K15: 1.6 | L15: ISIC 06
A16: Mining (except oil and gas) | B16: 212000 | C16: Summary | D16: 191.7 | E16: 182.6 | F16: -9.1 | G16: -4.7 | H16: -0.5 | I16: 92.8 | J16: 99.9 | K16: 0.7
A17: Coal mining | B17: 212100 | C17: Line item | D17: 42.5 | E17: 23.2 | F17: -19.3 | G17: -45.3 | H17: -5.9 | I17: 29.8 | J17: 24.6 | K17: -1.9 | L17: ISIC 05
A18: Metal ore mining | B18: 212200 | C18: Line item | D18: 44.9 | E18: 48.4 | F18: 3.5 | G18: 7.9 | H18: 0.8 | I18: 26 | J18: 33.5 | K18: 2.6 | L18: ISIC 07T08
A19: Nonmetallic mineral mining and quarrying | B19: 212300 | C19: Line item | D19: 104.3 | E19: 111 | F19: 6.7 | G19: 6.4 | H19: 0.6 | I19: 36.9 | J19: 41.5 | K19: 1.2 | L19: ISIC 07T08
A20: Support activities for mining | B20: 213000 | C20: Line item | D20: 271.9 | E20: 278.4 | F20: 6.5 | G20: 2.4 | H20: 0.2 | I20: 95.6 | J20: 90.6 | K20: -0.5 | L20: ISIC 09
A21: Utilities | B21: 220000 | C21: Summary | D21: 591.3 | E21: 620 | F21: 28.7 | G21: 4.9 | H21: 0.5 | I21: 507.1 | J21: 602.2 | K21: 1.7
A22: Utilities | B22: 221000 | C22: Summary | D22: 591.3 | E22: 620 | F22: 28.7 | G22: 4.9 | H22: 0.5 | I22: 507.1 | J22: 602.2 | K22: 1.7
A23: Electric power generation, transmission and distribution | B23: 221100 | C23: Summary | D23: 413.1 | E23: 445.6 | F23: 32.5 | G23: 7.9 | H23: 0.8 | I23: 411.4 | J23: 501.2 | K23: 2 | L23: ISIC 351
A24: Electric power generation | B24: 221110 | C24: Summary | D24: 157.3 | E24: 169.2 | F24: 11.9 | G24: 7.6 | H24: 0.7 | I24: — | J24: — | K24: —
A25: Hydroelectric power generation | B25: 221111 | C25: Line item | D25: 8.2 | E25: 8.2 | F25: 0 | G25: 0.4 | H25: 0 | I25: — | J25: — | K25: —
A26: Fossil fuel electric power generation | B26: 221112 | C26: Line item | D26: 74.5 | E26: 51.5 | F26: -23 | G26: -30.9 | H26: -3.6 | I26: — | J26: — | K26: —
A27: Nuclear electric power generation | B27: 221113 | C27: Line item | D27: 38.2 | E27: 31.5 | F27: -6.7 | G27: -17.6 | H27: -1.9 | I27: — | J27: — | K27: —
A28: Solar electric power generation | B28: 221114 | C28: Line item | D28: 16.9 | E28: 47.2 | F28: 30.4 | G28: 180.2 | H28: 10.8 | I28: — | J28: — | K28: —
A29: Wind electric power generation | B29: 221115 | C29: Line item | D29: 11.2 | E29: 20.4 | F29: 9.2 | G29: 81.4 | H29: 6.2 | I29: — | J29: — | K29: —
A30: Geothermal electric power generation | B30: 221116 | C30: Line item | D30: 1.2 | E30: 1.6 | F30: 0.5 | G30: 41.4 | H30: 2.9 | I30: — | J30: — | K30: —
A31: Biomass electric power generation | B31: 221117 | C31: Line item | D31: 2.4 | E31: 2.5 | F31: 0 | G31: 1.9 | H31: 0.4 | I31: — | J31: — | K31: —
A32: Other electric power generation | B32: 221118 | C32: Line item | D32: 4.7 | E32: 6.2 | F32: 1.5 | G32: 32.9 | H32: 2.8 | I32: — | J32: — | K32: —
A33: Natural gas distribution | B33: 221200 | C33: Line item | D33: 116.1 | E33: 112.4 | F33: -3.7 | G33: -3.2 | H33: -0.3 | I33: 80.4 | J33: 86.5 | K33: 0.7 | L33: ISIC 352T353
A34: Water, sewage and other systems | B34: 221300 | C34: Line item | D34: 62.1 | E34: 62 | F34: -0.1 | G34: -0.1 | H34: 0 | I34: 15.6 | J34: 16.3 | K34: 0.5 | L34: ISIC 36T39
A35: Construction | B35: 230000 | C35: Summary | D35: 8211.7 | E35: 8572.2 | F35: 360.5 | G35: 4.4 | H35: 0.4 | I35: 1720.9 | J35: 1874.7 | K35: 0.9 | L35: ISIC 41T43
A36: Construction of buildings | B36: 236000 | C36: Summary | D36: 1853.6 | E36: 1938.2 | F36: 84.6 | G36: 4.6 | H36: 0.4 | I36: — | J36: — | K36: —
A37: Residential building construction | B37: 236100 | C37: Line item | D37: 943.1 | E37: 982.4 | F37: 39.3 | G37: 4.2 | H37: 0.4 | I37: — | J37: — | K37: —
A38: Nonresidential building construction | B38: 236200 | C38: Line item | D38: 910.5 | E38: 955.8 | F38: 45.3 | G38: 5 | H38: 0.5 | I38: — | J38: — | K38: —
A39: Heavy and civil engineering construction | B39: 237000 | C39: Summary | D39: 1154.4 | E39: 1206.1 | F39: 51.7 | G39: 4.5 | H39: 0.4 | I39: — | J39: — | K39: —
A40: Utility system construction | B40: 237100 | C40: Summary | D40: 602.8 | E40: 634.3 | F40: 31.5 | G40: 5.2 | H40: 0.5 | I40: — | J40: — | K40: —
...

Sheet AEO25 Table 23
C1: Table 23. Industrial Sector Macroeconomic Indicators
C2: https://www.eia.gov/outlooks/aeo/data/browser/#/?id=34-AEO2025&cases=highZTC&sourcekey=0
C3: Tue Dec 02 2025 13:21:59 GMT-0800 (Pacific Standard Time)
C4: Source: U.S. Energy Information Administration
D5: full name | E5: api key | F5: units | G5: 2023 | H5: 2024 | I5: 2025 | J5: 2026 | K5: 2027 | L5: 2028 | M5: 2029 | N5: 2030 | O5: 2031 | P5: 2032 | Q5: 2033 | R5: 2034 | S5: 2035 | T5: 2036 | U5: 2037 | V5: 2038 | W5: 2039 | X5: 2040 | Y5: 2041 | Z5: 2042 | AA5: 2043 | AB5: 2044 | AC5: 2045 | AD5: 2046 | AE5: 2047 | AF5: 2048 | AG5: 2049 | AH5: 2050 | AI5: Growth (2024-2050)
A6: ISM000:ba_GDP(billionm_ | C6: Gross Domestic Product (billion 2012 dollars) | D6: Industrial Macroeconomic: Gross Domestic Product: High Zero-Carbon Technology Cost | E6: AEO.2025.HIGHZTC.ECI_GDP_NA_NA_NA_NA_NA_BLNY09DLR.A | F6: billion 2012 $ | H6: 21699.672 | I6: 22171.93 | J6: 22685.953 | K6: 23162.596 | L6: 23590.016 | M6: 24042.869 | N6: 24479.318 | O6: 24877.939 | P6: 25299.824 | Q6: 25731.902 | R6: 26166.297 | S6: 26621.836 | T6: 27077.875 | U6: 27546.342 | V6: 28018.711 | W6: 28503.035 | X6: 29003.939 | Y6: 29486.92 | Z6: 29991.914 | AA6: 30494.672 | AB6: 30998.293 | AC6: 31501.85 | AD6: 32021.367 | AE6: 32546.51 | AF6: 33074.625 | AG6: 33617.656 | AH6: 34162.723 | AI6: 0.018
A7: ISM000:ca_NonfarmEmploy | C7: Nonfarm Employment (millions) | D7: Industrial Macroeconomic: Employment, Nonfarm: High Zero-Carbon Technology Cost | E7: AEO.2025.HIGHZTC.ECI_NFE_NA_NA_NA_NA_NA_MILL.A | F7: millions | H7: 159.5452 | I7: 160.89847 | J7: 161.43066 | K7: 161.69711 | L7: 161.99791 | M7: 162.5314 | N7: 163.24155 | O7: 163.92671 | P7: 164.54892 | Q7: 164.98477 | R7: 165.29776 | S7: 165.56593 | T7: 166.08339 | U7: 166.7914 | V7: 167.5314 | W7: 168.18655 | X7: 169.00385 | Y7: 169.65865 | Z7: 170.29732 | AA7: 170.74045 | AB7: 171.20613 | AC7: 171.65497 | AD7: 172.12753 | AE7: 172.64163 | AF7: 173.16328 | AG7: 173.71744 | AH7: 174.28783 | AI7: 0.003
C8: Value of Shipments (billion 2012 dollars)
C9: Nonmanufacturing Sector
A10: ISM000:ea_Agricultural | B10: ISIC 01T03 | C10: Agriculture/Forestry/Fishing/Hunting | D10: Industrial Macroeconomic: Nonmanufacturing: Agriculture/Forestry/Fishing/Hunting: High Zero-Carbon Technology Cost | E10: AEO.2025.HIGHZTC.ECI_VOS_NMFG_AFF_NA_NA_NA_BLNY09DLR.A | F10: billion 2012 $ | H10: 538.8266 | I10: 544.76807 | J10: 552.01935 | K10: 559.25311 | L10: 565.51892 | M10: 573.79547 | N10: 581.47052 | O10: 587.56146 | P10: 593.56909 | Q10: 599.28235 | R10: 606.56781 | S10: 614.13873 | T10: 623.17743 | U10: 630.44727 | V10: 636.67987 | W10: 643.48901 | X10: 649.69403 | Y10: 654.328 | Z10: 659.78339 | AA10: 665.28345 | AB10: 671.34363 | AC10: 678.96008 | AD10: 686.82513 | AE10: 694.61627 | AF10: 702.28125 | AG10: 710.2558 | AH10: 718.01489 | AI10: 0.011
A11: ISM000:ea_Mining | B11: ISIC 05, ISIC 06, ISIC 07T08 | C11: Mining | D11: Industrial Macroeconomic: Nonmanufacturing: Mining: High Zero-Carbon Technology Cost | E11: AEO.2025.HIGHZTC.ECI_VOS_NMFG_MING_NA_NA_NA_BLNY09DLR.A | F11: billion 2012 $ | H11: 738.6261 | I11: 800.09271 | J11: 807.26276 | K11: 812.87158 | L11: 822.88531 | M11: 830.664 | N11: 837.44684 | O11: 834.11847 | P11: 842.65662 | Q11: 842.87884 | R11: 843.77454 | S11: 839.43475 | T11: 833.55817 | U11: 824.76233 | V11: 820.58246 | W11: 815.21143 | X11: 817.20264 | Y11: 820.17926 | Z11: 823.91998 | AA11: 823.77704 | AB11: 825.68115 | AC11: 828.09149 | AD11: 834.33093 | AE11: 835.11914 | AF11: 834.69672 | AG11: 836.80615 | AH11: 839.41028 | AI11: 0.005
A12: ISM000:ea_Construction | B12: ISIC 41T43 | C12: Construction | D12: Industrial Macroeconomic: Nonmanufacturing: Construction: High Zero-Carbon Technology Cost | E12: AEO.2025.HIGHZTC.ECI_VOS_NMFG_CNS_NA_NA_NA_BLNY09DLR.A | F12: billion 2012 $ | H12: 1440.7977 | I12: 1433.0573 | J12: 1444.2264 | K12: 1467.1532 | L12: 1502.7834 | M12: 1544.0198 | N12: 1573.1925 | O12: 1598.66 | P12: 1617.2603 | Q12: 1624.0387 | R12: 1624.3893 | S12: 1639.5165 | T12: 1660.5125 | U12: 1673.6357 | V12: 1687.7023 | W12: 1700.454 | X12: 1710.2748 | Y12: 1717.3003 | Z12: 1728.8163 | AA12: 1737.1105 | AB12: 1744.9568 | AC12: 1762.099 | AD12: 1781.2562 | AE12: 1803.2469 | AF12: 1826.4515 | AG12: 1851.1388 | AH12: 1872.7469 | AI12: 0.01
C13: Manufacturing Sector
A14: ISM000:fa_FoodandKindre | B14: ISIC 10T12 | C14: Food Products | D14: Industrial Macroeconomic: Manufacturing: Food Products: High Zero-Carbon Technology Cost | E14: AEO.2025.HIGHZTC.ECI_VOS_MANF_FPA_NA_NA_NA_BLNY09DLR.A | F14: billion 2012 $ | H14: 821.565 | I14: 826.25629 | J14: 829.60242 | K14: 837.90674 | L14: 844.65008 | M14: 853.04797 | N14: 861.58227 | O14: 869.4892 | P14: 877.76154 | Q14: 885.73114 | R14: 894.01611 | S14: 901.54547 | T14: 911.37494 | U14: 920.41272 | V14: 929.09497 | W14: 938.25281 | X14: 947.32989 | Y14: 956.4433 | Z14: 965.737 | AA14: 974.68512 | AB14: 983.68793 | AC14: 992.50006 | AD14: 1001.4976 | AE14: 1010.5715 | AF14: 1019.6702 | AG14: 1029.1584 | AH14: 1038.4718 | AI14: 0.009
A15: ISM000:fa_BeveragesandT | B15: ISIC 10T12 | C15: Beverages and Tobacco Products | D15: Industrial Macroeconomic: Manufacturing: Beverages and Tobacco Products: High Zero-Carbon Technology Cost | E15: AEO.2025.HIGHZTC.ECI_VOS_MANF_BVTP_NA_NA_NA_BLNY09DLR.A | F15: billion 2012 $ | H15: 141.90608 | I15: 139.8526 | J15: 138.7114 | K15: 138.03377 | L15: 137.52714 | M15: 136.83862 | N15: 136.09837 | O15: 135.32722 | P15: 134.48689 | Q15: 133.75133 | R15: 133.0681 | S15: 132.55055 | T15: 131.98662 | U15: 131.44885 | V15: 130.93477 | W15: 130.42633 | X15: 129.9326 | Y15: 129.43793 | Z15: 128.93127 | AA15: 128.3781 | AB15: 127.79433 | AC15: 127.17438 | AD15: 126.60002 | AE15: 126.07458 | AF15: 125.57433 | AG15: 125.09577 | AH15: 124.58905 | AI15: -0.005
A16: ISM000:fa_TextileMillPr | B16: ISIC 13T15 | C16: Textile Mills and Products | D16: Industrial Macroeconomic: Manufacturing: Textile Mills and Products: High Zero-Carbon Technology Cost | E16: AEO.2025.HIGHZTC.ECI_VOS_MANF_TMP_NA_NA_NA_BLNY09DLR.A | F16: billion 2012 $ | H16: 66.089165 | I16: 66.538513 | J16: 65.8992 | K16: 65.924271 | L16: 64.83783 | M16: 64.166801 | N16: 63.704239 | O16: 63.158009 | P16: 62.414116 | Q16: 61.727993 | R16: 61.319778 | S16: 60.568184 | T16: 59.831409 | U16: 59.532326 | V16: 59.14883 | W16: 58.90044 | X16: 58.791424 | Y16: 58.565128 | Z16: 58.345596 | AA16: 57.977749 | AB16: 57.632816 | AC16: 57.247356 | AD16: 56.93322 | AE16: 56.724243 | AF16: 56.464836 | AG16: 56.23605 | AH16: 55.887161 | AI16: -0.006
A17: ISM000:fa_LumberandWood | B17: ISIC 16 | C17: Wood Products | D17: Industrial Macroeconomic: Manufacturing: Wood Products: High Zero-Carbon Technology Cost | E17: AEO.2025.HIGHZTC.ECI_VOS_MANF_WDP_NA_NA_NA_BLNY09DLR.A | F17: billion 2012 $ | H17: 98.40712 | I17: 99.04071 | J17: 101.04065 | K17: 102.24693 | L17: 103.98792 | M17: 107.2435 | N17: 109.76388 | O17: 111.44402 | P17: 112.56998 | Q17: 112.37907 | R17: 113.57045 | S17: 115.05647 | T17: 118.32752 | U17: 120.52498 | V17: 121.29505 | W17: 122.2 | X17: 122.0394 | Y17: 119.66293 | Z17: 118.0938 | AA17: 115.15807 | AB17: 113.1279 | AC17: 113.01455 | AD17: 113.40658 | AE17: 114.63775 | AF17: 115.77583 | AG17: 117.22973 | AH17: 118.1262 | AI17: 0.007
A18: ISM000:fa_FurnitureandF | B18: ISIC 31T33 | C18: Furniture and Related Products | D18: Industrial Macroeconomic: Manufacturing: Furniture and Related Products: High Zero-Carbon Technology Cost | E18: AEO.2025.HIGHZTC.ECI_VOS_MANF_FRP_NA_NA_NA_BLNY09DLR.A | F18: billion 2012 $ | H18: 53.271854 | I18: 52.269444 | J18: 53.980427 | K18: 55.926292 | L18: 56.093472 | M18: 56.599045 | N18: 58.34198 | O18: 58.92627 | P18: 59.556118 | Q18: 59.890476 | R18: 61.148804 | S18: 61.658676 | T18: 62.141407 | U18: 63.414036 | V18: 64.388123 | W18: 65.334251 | X18: 66.700745 | Y18: 67.731552 | Z18: 68.640739 | AA18: 69.677574 | AB18: 70.932808 | AC18: 71.805748 | AD18: 72.815346 | AE18: 74.188431 | AF18: 74.879402 | AG18: 76.066422 | AH18: 76.886627 | AI18: 0.014
A19: ISM000:fa_PaperandAllie | B19: ISIC 17T18 | C19: Paper Products | D19: Industrial Macroeconomic: Manufacturing: Paper Products: High Zero-Carbon Technology Cost | E19: AEO.2025.HIGHZTC.ECI_VOS_MANF_PPM_NA_NA_NA_BLNY09DLR.A | F19: billion 2012 $ | H19: 161.46919 | I19: 162.7692 | J19: 164.02576 | K19: 162.47028 | L19: 161.55638 | M19: 161.47072 | N19: 161.8098 | O19: 162.97775 | P19: 163.75282 | Q19: 164.06697 | R19: 165.19106 | S19: 166.25287 | T19: 167.39653 | U19: 168.34885 | V19: 169.4716 | W19: 171.07837 | X19: 172.76543 | Y19: 174.02237 | Z19: 175.34892 | AA19: 176.49817 | AB19: 178.14328 | AC19: 179.31845 | AD19: 180.70677 | AE19: 182.0945 | AF19: 183.34045 | AG19: 184.40793 | AH19: 185.49396 | AI19: 0.005
A20: ISM000:fa_PrintingandPu | B20: ISIC 17T18 | C20: Printing | D20: Industrial Macroeconomic: Manufacturing: Printing: High Zero-Carbon Technology Cost | E20: AEO.2025.HIGHZTC.ECI_VOS_MANF_PRN_NA_NA_NA_BLNY09DLR.A | F20: billion 2012 $ | H20: 60.525852 | I20: 57.448959 | J20: 56.292637 | K20: 54.877972 | L20: 53.651821 | M20: 52.613571 | N20: 51.594307 | O20: 50.581692 | P20: 49.633221 | Q20: 48.66946 | R20: 47.801643 | S20: 46.996117 | T20: 46.399475 | U20: 45.814659 | V20: 45.239269 | W20: 44.861446 | X20: 44.471886 | Y20: 44.081989 | Z20: 43.735256 | AA20: 43.354687 | AB20: 43.027943 | AC20: 42.731819 | AD20: 42.579571 | AE20: 42.327194 | AF20: 42.10128 | AG20: 41.857502 | AH20: 41.633499 | AI20: -0.014
A21: ISM000:fa_ChemicalandAl | B21: ISIC 20 | C21: Chemical Manufacturing | D21: Industrial Macroeconomic: Manufacturing: Chemical Manufacturing: High Zero-Carbon Technology Cost | E21: AEO.2025.HIGHZTC.ECI_VOS_MANF_CHE_NA_NA_NA_BLNY09DLR.A | F21: billion 2012 $ | H21: 808.21368 | I21: 812.38934 | J21: 806.69074 | K21: 804.93176 | L21: 803.34943 | M21: 806.09863 | N21: 813.56812 | O21: 823.25134 | P21: 834.16455 | Q21: 843.79175 | R21: 855.42957 | S21: 865.72815 | T21: 874.20136 | U21: 885.51782 | V21: 896.98572 | W21: 909.44946 | X21: 923.43683 | Y21: 936.80664 | Z21: 950.84143 | AA21: 963.14319 | AB21: 974.9859 | AC21: 984.60706 | AD21: 994.83899 | AE21: 1008.811 | AF21: 1020.662 | AG21: 1031.7502 | AH21: 1041.1604 | AI21: 0.01
A22: ISM000:fa_BulkChemicals | C22: Bulk Chemicals | D22: Industrial Macroeconomic: Manufacturing: Chemicals: Bulk Chemicals: High Zero-Carbon Technology Cost | E22: AEO.2025.HIGHZTC.ECI_VOS_MANF_BCH_NA_NA_NA_BLNY09DLR.A | F22: billion 2012 $ | H22: 367.32217 | I22: 372.95435 | J22: 365.47006 | K22: 360.02753 | L22: 354.24496 | M22: 352.82477 | N22: 355.28152 | O22: 359.69891 | P22: 364.24594 | Q22: 367.19061 | R22: 373.40387 | S22: 379.88586 | T22: 384.06592 | U22: 389.13483 | V22: 394.53491 | W22: 400.9906 | X22: 408.14343 | Y22: 414.30145 | Z22: 420.51334 | AA22: 425.35037 | AB22: 430.8327 | AC22: 435.23618 | AD22: 439.59573 | AE22: 446.34097 | AF22: 451.72757 | AG22: 456.2446 | AH22: 460.80216 | AI22: 0.009
A23: ISM000:fa_Inorganic | C23: Inorganic | D23: Industrial Macroeconomic: Manufacturing: Chemicals: Bulk Chemicals: Inorganic: High Zero-Carbon Technology Cost | E23: AEO.2025.HIGHZTC.ECI_VOS_MANF_CHEIN_NA_NA_NA_BLNY09DLR.A | F23: billion 2012 $ | H23: 50.760822 | I23: 51.478336 | J23: 52.328194 | K23: 52.508663 | L23: 52.006046 | M23: 51.169857 | N23: 51.473831 | O23: 51.551136 | P23: 51.466038 | Q23: 51.676189 | R23: 51.725769 | S23: 52.104076 | T23: 52.200466 | U23: 51.96347 | V23: 52.269703 | W23: 52.373104 | X23: 52.339554 | Y23: 52.473537 | Z23: 52.384289 | AA23: 52.293137 | AB23: 52.097511 | AC23: 51.880245 | AD23: 51.748787 | AE23: 51.814064 | AF23: 51.907967 | AG23: 51.836624 | AH23: 51.954746 | AI23: 0.001
A24: ISM000:fa_Organic | C24: Organic | D24: Industrial Macroeconomic: Manufacturing: Chemicals: Bulk Chemicals: Organic: High Zero-Carbon Technology Cost | E24: AEO.2025.HIGHZTC.ECI_VOS_MANF_CHEOR_NA_NA_NA_BLNY09DLR.A | F24: billion 2012 $ | H24: 179.6485 | I24: 184.1534 | J24: 172.36072 | K24: 167.71588 | L24: 163.97459 | M24: 162.34164 | N24: 162.01833 | O24: 164.70097 | P24: 167.63568 | Q24: 169.28833 | R24: 172.1774 | S24: 176.19098 | T24: 179.03477 | U24: 181.7184 | V24: 185.00465 | W24: 189.10175 | X24: 193.48135 | Y24: 197.50008 | Z24: 201.28572 | AA24: 205.21362 | AB24: 209.58937 | AC24: 213.81535 | AD24: 216.95627 | AE24: 221.06383 | AF24: 224.53114 | AG24: 227.09778 | AH24: 230.2061 | AI24: 0.01
A25: ISM000:fa_Resins | C25: Resin | D25: Synthetic Rubber | E25: and Fibers | F25: Industrial Macroeconomic: Manufacturing: Chemicals: Bulk Chemicals: Resin, Synthetic Rubber, and Fibers: High Zero-Carbon Technology Cost | G25: AEO.2025.HIGHZTC.ECI_VOS_MANF_CHEBR_NA_NA_NA_BLNY09DLR.A | H25: 98.834442 | I25: 97.966858 | J25: 99.326225 | K25: 97.665497 | L25: 95.804192 | M25: 96.423264 | N25: 98.262207 | O25: 99.258095 | P25: 100.285 | Q25: 100.9119 | R25: 103.31385 | S25: 104.717 | T25: 105.34988 | U25: 107.17442 | V25: 108.3623 | W25: 110.00505 | X25: 112.15402 | Y25: 113.5902 | Z25: 115.5398 | AA25: 116.0079 | AB25: 116.68415 | AC25: 116.62328 | AD25: 117.465 | AE25: 119.5488 | AF25: 120.94505 | AG25: 122.55138 | AH25: 123.52005 | AI25: 0.009
A26: ISM000:fa_AgriculturalC | C26: Agricultural Chemicals | D26: Industrial Macroeconomic: Manufacturing: Chemicals: Bulk Chemicals: Agricultural Chemicals: High Zero-Carbon Technology Cost | E26: AEO.2025.HIGHZTC.ECI_VOS_MANF_AGC_NA_NA_NA_BLNY09DLR.A | F26: billion 2012 $ | H26: 38.078388 | I26: 39.355778 | J26: 41.454929 | K26: 42.137497 | L26: 42.460148 | M26: 42.890003 | N26: 43.527168 | O26: 44.188728 | P26: 44.859222 | Q26: 45.314175 | R26: 46.186852 | S26: 46.873821 | T26: 47.480816 | U26: 48.278534 | V26: 48.898262 | W26: 49.510666 | X26: 50.168533 | Y26: 50.737656 | Z26: 51.303539 | AA26: 51.835686 | AB26: 52.461685 | AC26: 52.917336 | AD26: 53.425697 | AE26: 53.914276 | AF26: 54.343407 | AG26: 54.758823 | AH26: 55.121239 | AI26: 0.014
A27: ISM000:fa_OtherChemical | C27: Other Chemical Products | D27: Industrial Macroeconomic: Manufacturing: Chemicals: Other Chemical Products: High Zero-Carbon Technology Cost | E27: AEO.2025.HIGHZTC.ECI_VOS_MANF_CHEO_NA_NA_NA_BLNY09DLR.A | F27: billion 2012 $ | H27: 440.89151 | I27: 439.435 | J27: 441.22067 | K27: 444.9042 | L27: 449.10446 | M27: 453.27383 | N27: 458.28656 | O27: 463.5524 | P27: 469.91864 | Q27: 476.60113 | R27: 482.02567 | S27: 485.84226 | T27: 490.13544 | U27: 496.383 | V27: 502.45084 | W27: 508.45886 | X27: 515.2934 | Y27: 522.50519 | Z27: 530.32806 | AA27: 537.79279 | AB27: 544.1532 | AC27: 549.37085 | AD27: 555.24323 | AE27: 562.47003 | AF27: 568.93445 | AG27: 575.50562 | AH27: 580.35828 | AI27: 0.011
A28: ISM000:fa_PetroleumandC | C28: Petroleum and Coal Products | D28: Industrial Macroeconomic: Manufacturing: Petroleum and Coal Products: High Zero-Carbon Technology Cost | E28: AEO.2025.HIGHZTC.ECI_VOS_MANF_PCL_NA_NA_NA_BLNY09DLR.A | F28: billion 2012 $ | H28: 816.09601 | I28: 829.73065 | J28: 826.35809 | K28: 822.63525 | L28: 818.11365 | M28: 811.7898 | N28: 801.87268 | O28: 790.94 | P28: 777.92773 | Q28: 764.57977 | R28: 753.02173 | S28: 741.50934 | T28: 729.7876 | U28: 718.6405 | V28: 709.41724 | W28: 702.5293 | X28: 697.51465 | Y28: 692.16034 | Z28: 686.87671 | AA28: 682.12921 | AB28: 678.85687 | AC28: 674.4317 | AD28: 672.45917 | AE28: 673.33466 | AF28: 671.36792 | AG28: 672.13104 | AH28: 673.04504 | AI28: -0.007
A29: ISM000:fa_PetroleumRefi | B29: ISIC 19 | C29: Petroleum Refineries | D29: Industrial Macroeconomic: Manufacturing: Petroleum and Coal: Petroleum Refineries: High Zero-Carbon Technology Cost | E29: AEO.2025.HIGHZTC.ECI_VOS_MANF_REF_NA_NA_NA_BLNY09DLR.A | F29: billion 2012 $ | H29: 773.8219 | I29: 786.61841 | J29: 783.18323 | K29: 779.68903 | L29: 775.45001 | M29: 769.39807 | N29: 759.90216 | O29: 749.35315 | P29: 736.87854 | Q29: 724.18066 | R29: 713.24438 | S29: 702.289 | T29: 691.01855 | U29: 680.32849 | V29: 671.50891 | W29: 664.93426 | X29: 660.10657 | Y29: 654.97394 | Z29: 650.02429 | AA29: 645.57031 | AB29: 642.4895 | AC29: 638.2727 | AD29: 636.51154 | AE29: 637.53351 | AF29: 635.75726 | AG29: 636.62994 | AH29: 637.6333 | AI29: -0.007
A30: ISM000:fa_OtherPetroleu | B30: ISIC 241 | C30: Other Petroleum and Coal Products | D30: Industrial Macroeconomic: Manufacturing: Petroleum and Coal: Other Petroleum & Coal Products: High Zero-Carbon Technology Cost | E30: AEO.2025.HIGHZTC.ECI_VOS_MANF_PCLO_NA_NA_NA_BLNY09DLR.A | F30: billion 2012 $ | H30: 42.27409 | I30: 43.112217 | J30: 43.174866 | K30: 42.94622 | L30: 42.663628 | M30: 42.391701 | N30: 41.970547 | O30: 41.586861 | P30: 41.049202 | Q30: 40.399086 | R30: 39.777332 | S30: 39.220341 | T30: 38.769024 | U30: 38.312031 | V30: 37.90834 | W30: 37.595055 | X30: 37.408058 | Y30: 37.186394 | Z30: 36.85239 | AA30: 36.558922 | AB30: 36.367348 | AC30: 36.158981 | AD30: 35.947632 | AE30: 35.801125 | AF30: 35.610645 | AG30: 35.501125 | AH30: 35.411743 | AI30: -0.007
A31: ISM000:fa_RubberandMisc | B31: ISIC 22 | C31: Plastics and Rubber Products | D31: Industrial Macroeconomic: Manufacturing: Plastics and Rubber Products: High Zero-Carbon Technology Cost | E31: AEO.2025.HIGHZTC.ECI_VOS_MANF_PRP_NA_NA_NA_BLNY09DLR.A | F31: billion 2012 $ | H31: 212.32913 | I31: 217.69611 | J31: 224.71417 | K31: 228.99838 | L31: 231.00073 | M31: 233.92827 | N31: 237.69215 | O31: 241.49115 | P31: 245.09897 | Q31: 248.24377 | R31: 252.30617 | S31: 255.40613 | T31: 257.66836 | U31: 260.66455 | V31: 263.21542 | W31: 265.90036 | X31: 268.94296 | Y31: 271.58008 | Z31: 274.43543 | AA31: 276.42465 | AB31: 278.5116 | AC31: 280.17221 | AD31: 282.02731 | AE31: 284.19464 | AF31: 286.12378 | AG31: 288.19809 | AH31: 289.85263 | AI31: 0.012
A32: ISM000:fa_Stone,Clay,an | C32: Non-metallic minerals | D32: Industrial Macroeconomic: Manufacturing: Stone, Clay, and Glass Products: High Zero-Carbon Technology Cost | E32: AEO.2025.HIGHZTC.ECI_VOS_MANF_SCG_NA_NA_NA_BLNY09DLR.A | F32: billion 2012 $ | H32: 111.54769 | I32: 111.64612 | J32: 111.83931 | K32: 112.53001 | L32: 113.1917 | M32: 113.50225 | N32: 114.45515 | O32: 115.9222 | P32: 117.23323 | Q32: 118.13599 | R32: 118.88231 | S32: 119.85504 | T32: 120.86804 | U32: 121.95155 | V32: 123.17243 | W32: 124.29541 | X32: 125.05119 | Y32: 125.54099 | Z32: 125.83267 | AA32: 125.66972 | AB32: 125.18317 | AC32: 125.38245 | AD32: 126.04735 | AE32: 126.8273 | AF32: 127.72215 | AG32: 128.63948 | AH32: 129.61243 | AI32: 0.006
A33: ISM000:fa_GlassandGlass | B33: ISIC 231 | C33: Glass and Glass Products | D33: Industrial Macroeconomic: Manufacturing: Stone, Clay, and Glass: Glass and Glass Products: High Zero-Carbon Technology Cost | E33: AEO.2025.HIGHZTC.ECI_VOS_MANF_SCGG_NA_NA_NA_BLNY09DLR.A | F33: billion 2012 $ | H33: 21.45093 | I33: 21.290245 | J33: 21.242983 | K33: 21.230724 | L33: 21.263985 | M33: 21.310061 | N33: 21.371811 | O33: 21.476692 | P33: 21.61256 | Q33: 21.745703 | R33: 21.89089 | S33: 22.055412 | T33: 22.216677 | U33: 22.39768 | V33: 22.595711 | W33: 22.798956 | X33: 23.015873 | Y33: 23.23588 | Z33: 23.452274 | AA33: 23.653669 | AB33: 23.834209 | AC33: 23.998465 | AD33: 24.153 | AE33: 24.320282 | AF33: 24.498272 | AG33: 24.677088 | AH33: 24.843611 | AI33: 0.006
A34: ISM000:fa_CementandHydr | B34: ISIC 239 | C34: Cement and Lime | D34: Industrial Macroeconomic: Manufacturing: Stone, Clay, and Glass: Cement and Lime: High Zero-Carbon Technology Cost | E34: AEO.2025.HIGHZTC.ECI_VOS_MANF_SCGCL_NA_NA_NA_BLNY09DLR.A | F34: billion 2012 $ | H34: 9.305412 | I34: 9.341552 | J34: 9.271192 | K34: 9.279629 | L34: 9.351248 | M34: 9.433073 | N34: 9.557519 | O34: 9.703686 | P34: 9.855732 | Q34: 9.999584 | R34: 10.13154 | S34: 10.260571 | T34: 10.38773 | U34: 10.523909 | V34: 10.673493 | W34: 10.821849 | X34: 10.946848 | Y34: 11.046646 | Z34: 11.118332 | AA34: 11.14825 | AB34: 11.14453 | AC34: 11.16645 | AD34: 11.222955 | AE34: 11.310638 | AF34: 11.422865 | AG34: 11.550447 | AH34: 11.685319 | AI34: 0.009
A35: ISM000:fa_OtherStone,Cl | B35: ISIC 239 | C35: Other Nonmetallic Mineral Products | D35: Industrial Macroeconomic: Manufacturing: Stone, Clay, and Glass: Other Nonmetallic Mineral Products: High Zero-Carbon Technology Cost | E35: AEO.2025.HIGHZTC.ECI_VOS_MANF_SCGOM_NA_NA_NA_BLNY09DLR.A | F35: billion 2012 $ | H35: 80.791351 | I35: 81.01432 | J35: 81.325134 | K35: 82.019653 | L35: 82.576469 | M35: 82.759117 | N35: 83.525826 | O35: 84.741814 | P35: 85.764938 | Q35: 86.390701 | R35: 86.859879 | S35: 87.539062 | T35: 88.263634 | U35: 89.029968 | V35: 89.903229 | W35: 90.674606 | X35: 91.088463 | Y35: 91.258469 | Z35: 91.26207 | AA35: 90.867805 | AB35: 90.204437 | AC35: 90.217529 | AD35: 90.671394 | AE35: 91.196381 | AF35: 91.801018 | AG35: 92.411949 | AH35: 93.083488 | AI35: 0.005
A36: ISM000:ga_PrimaryMetals | C36: Primary Metals Industry | D36: Industrial Macroeconomic: Manufacturing: Primary Metals Industry: High Zero-Carbon Technology Cost | E36: AEO.2025.HIGHZTC.ECI_VOS_MANF_PMM_NA_NA_NA_BLNY09DLR.A | F36: billion 2012 $ | H36: 244.86504 | I36: 248.52803 | J36: 255.5425 | K36: 258.2749 | L36: 258.45053 | M36: 259.36414 | N36: 262.41397 | O36: 266.26843 | P36: 270.27884 | Q36: 271.53186 | R36: 274.66315 | S36: 277.69369 | T36: 280.42725 | U36: 284.75626 | V36: 288.45294 | W36: 292.01385 | X36: 297.0069 | Y36: 300.80423 | Z36: 303.9722 | AA36: 308.31238 | AB36: 311.88547 | AC36: 314.56079 | AD36: 316.64414 | AE36: 319.67554 | AF36: 321.56711 | AG36: 322.92242 | AH36: 324.23212 | AI36: 0.011
A37: ISM000:ga_BlastFurnacea | B37: ISIC 241 | C37: Iron and Steel Mills and Products | D37: Industrial Macroeconomic: Manufacturing: Primary Metals: Iron and Steel Mills and Products: High Zero-Carbon Technology Cost | E37: AEO.2025.HIGHZTC.ECI_VOS_MANF_ISM_NA_NA_NA_BLNY09DLR.A | F37: billion 2012 $ | H37: 131.32573 | I37: 134.93411 | J37: 141.45989 | K37: 142.77377 | L37: 141.88794 | M37: 141.74979 | N37: 143.73824 | O37: 146.53499 | P37: 149.38496 | Q37: 149.45511 | R37: 151.37814 | S37: 153.10629 | T37: 154.5363 | U37: 157.53503 | V37: 159.87338 | W37: 162.08472 | X37: 165.73244 | Y37: 168.19681 | Z37: 170.0643 | AA37: 173.14265 | AB37: 175.5089 | AC37: 177.0495 | AD37: 178.07887 | AE37: 180.09767 | AF37: 181.03627 | AG37: 181.49979 | AH37: 181.98811 | AI37: 0.013
A38: ISM000:ga_Aluminum | B38: ISIC 242 | C38: Alumina and Aluminum Products | D38: Industrial Macroeconomic: Manufacturing: Primary Metals: Alumina and Aluminum Products: High Zero-Carbon Technology Cost | E38: AEO.2025.HIGHZTC.ECI_VOS_MANF_AAP_NA_NA_NA_BLNY09DLR.A | F38: billion 2012 $ | H38: 34.597599 | I38: 34.167324 | J38: 34.714939 | K38: 35.325741 | L38: 35.804806 | M38: 36.362534 | N38: 36.869461 | O38: 37.424278 | P38: 38.041748 | Q38: 38.662601 | R38: 39.322857 | S38: 40.049435 | T38: 40.793427 | U38: 41.567074 | V38: 42.354301 | W38: 43.131817 | X38: 43.905979 | Y38: 44.671326 | Z38: 45.415844 | AA38: 46.116341 | AB38: 46.751091 | AC38: 47.299404 | AD38: 47.767883 | AE38: 48.191673 | AF38: 48.568092 | AG38: 48.904499 | AH38: 49.198971 | AI38: 0.014
A39: ISM000:ga_OtherPrimaryM | B39: ISIC 242 | C39: Other Primary Metal Products | D39: Industrial Macroeconomic: Manufacturing: Primary Metals: Other Primary Metal Products: High Zero-Carbon Technology Cost | E39: AEO.2025.HIGHZTC.ECI_VOS_MANF_PMO_NA_NA_NA_BLNY09DLR.A | F39: billion 2012 $ | H39: 78.941711 | I39: 79.426582 | J39: 79.367668 | K39: 80.175369 | L39: 80.75779 | M39: 81.251801 | N39: 81.806282 | O39: 82.309166 | P39: 82.852135 | Q39: 83.414146 | R39: 83.962135 | S39: 84.537956 | T39: 85.097519 | U39: 85.654175 | V39: 86.225258 | W39: 86.797302 | X39: 87.368469 | Y39: 87.936096 | Z39: 88.492043 | AA39: 89.053383 | AB39: 89.625504 | AC39: 90.211868 | AD39: 90.797394 | AE39: 91.3862 | AF39: 91.962723 | AG39: 92.518127 | AH39: 93.045013 | AI39: 0.006
A40: ISM000:ga_FabricatedMet | B40: ISIC 25 | C40: Fabricated Metal Products | D40: Industrial Macroeconomic: Manufacturing: Fabricated Metal Products: High Zero-Carbon Technology Cost | E40: AEO.2025.HIGHZTC.ECI_VOS_MANF_FBP_NA_NA_NA_BLNY09DLR.A | F40: billion 2012 $ | H40: 302.45358 | I40: 308.42365 | J40: 320.7533 | K40: 328.51697 | L40: 329.17981 | M40: 329.98978 | N40: 332.51956 | O40: 335.4873 | P40: 338.85028 | Q40: 339.64154 | R40: 343.30469 | S40: 344.99402 | T40: 347.50638 | U40: 351.45007 | V40: 354.34689 | W40: 357.36279 | X40: 361.16931 | Y40: 363.91495 | Z40: 366.68784 | AA40: 368.30096 | AB40: 371.01907 | AC40: 372.19131 | AD40: 374.32022 | AE40: 376.14328 | AF40: 377.55277 | AG40: 379.67996 | AH40: 379.72183 | AI40: 0.009
...

Sheet Data from BVAbIC
A1: Unit: $ | B1: ISIC 01T03 | C1: ISIC 05 | D1: ISIC 06 | E1: ISIC 07T08 | F1: ISIC 09 | G1: ISIC 10T12 | H1: ISIC 13T15 | I1: ISIC 16 | J1: ISIC 17T18 | K1: ISIC 19 | L1: ISIC 20 | M1: ISIC 21 | N1: ISIC 22 | O1: ISIC 231 | P1: ISIC 239 | Q1: ISIC 241 | R1: ISIC 242 | S1: ISIC 25 | T1: ISIC 26 | U1: ISIC 27 | V1: ISIC 28 | W1: ISIC 29 | X1: ISIC 30 | Y1: ISIC 31T33 | Z1: ISIC 351 | AA1: ISIC 352T353 | AB1: ISIC 36T39 | AC1: ISIC 41T43 | AD1: ISIC 45T47 | AE1: ISIC 49T53 | AF1: ISIC 55T56 | AG1: ISIC 58T60 | AH1: ISIC 61 | AI1: ISIC 62T63 | AJ1: ISIC 64T66 | AK1: ISIC 68 | AL1: ISIC 69T82 | AM1: ISIC 84 | AN1: ISIC 85 | AO1: ISIC 86T88 | AP1: ISIC 90T96 | AQ1: ISIC 97T98
A2: Employee Compensation | B2: 1.973875e+11 | C2: 1.9459681e+10 | D2: 1.8488784e+11 | E2: 3.96784e+10 | F2: 5.184893e+10 | G2: 2.6361858e+11 | H2: 2.1056492e+10 | I2: 4.4040118e+10 | J2: 8.4707567e+10 | K2: 1.3780782e+11 | L2: 2.6974052e+11 | M2: 1.3575632e+11 | N2: 7.4268249e+10 | O2: 1.0908275e+10 | P2: 4.5826926e+10 | Q2: 4.2096268e+10 | R2: 1.9343938e+10 | S2: 1.3945562e+11 | T2: 2.1941598e+11 | U2: 5.8678438e+10 | V2: 1.5269305e+11 | W2: 1.3602952e+11 | X2: 1.4442899e+11 | Y2: 1.3467252e+11 | Z2: 2.5998899e+11 | AA2: 6.1106674e+10 | AB2: 7.6303988e+10 | AC2: 9.5544462e+11 | AD2: 2.6956973e+12 | AE2: 7.2262214e+11 | AF2: 7.0289993e+11 | AG2: 5.0207783e+11 | AH2: 2.7641438e+11 | AI2: 7.6946696e+11 | AJ2: 1.6315542e+12 | AK2: 2.9660164e+12 | AL2: 2.3423179e+12 | AM2: 2.4126455e+12 | AN2: 2.450345e+11 | AO2: 1.6170813e+12 | AP2: 5.6771546e+11 | AQ2: 1.1489045e+10

Sheet GDP Forecast
B1: Value (2012 USD)
A2: 2024 | B2: 21444000000000
A3: 2025 | B3: 21910000000000
A4: 2026 | B4: 22418000000000
A5: 2027 | B5: 22889000000000
A6: 2028 | B6: 23312000000000
A7: 2029 | B7: 23759000000000
A8: 2030 | B8: 24191000000000
A9: 2031 | B9: 24584000000000
A10: 2032 | B10: 25001000000000
A11: 2033 | B11: 25428000000000
A12: 2034 | B12: 25858000000000
A13: 2035 | B13: 26308000000000
... A28: 2050 | B28: 33760000000000

Sheet calcs>

Sheet Rescale to Fit GDP Proj
A1: Now that we have growth rates by ISIC code, we rescale all growth rates together such that BAU Value Added
A2: (summed across ISIC codes) reflects the BAU GDP projection in the final year of the model run.
C4: 2024 | D4: 2025 | E4: 2026 | F4: 2027 | G4: 2028 | H4: 2029 | I4: 2030 | J4: 2031 | K4: 2032 | L4: 2033 | M4: 2034 | N4: 2035 | O4: 2036 | P4: 2037 | Q4: 2038 | R4: 2039 | S4: 2040 | T4: 2041 | U4: 2042 | V4: 2043 | W4: 2044 | X4: 2045 | Y4: 2046 | Z4: 2047 | AA4: 2048 | AB4: 2049 | AC4: 2050
A5: AEO | B5: ISIC 01T03 | C5: {=TRANSPOSE('Data from BVAbIC'!B2:AQ2)} -> 1.973875e+11 | D5: =C5*(1+'Growth Rates'!C51) -> 1.9956403e+11 | E5: =D5*(1+'Growth Rates'!D51) -> 2.0222038e+11 | F5: =E5*(1+'Growth Rates'!E51) -> 2.0487031e+11 | G5: =F5*(1+'Growth Rates'!F51) -> 2.0716566e+11 | H5: =G5*(1+'Growth Rates'!G51) -> 2.1019759e+11 | I5: =H5*(1+'Growth Rates'!H51) -> 2.1300918e+11 | J5: =I5*(1+'Growth Rates'!I51) -> 2.1524047e+11 | K5: =J5*(1+'Growth Rates'!J51) -> 2.1744123e+11 | ... AC5: =AB5*(1+'Growth Rates'!AB51) -> 2.6302927e+11
A6: AEO | B6: ISIC 05 | C6: 1.9459681e+10 | D6: =C6*(1+'Growth Rates'!C52) -> 2.1079067e+10 | E6: =D6*(1+'Growth Rates'!D52) -> 2.1267968e+10 | F6: =E6*(1+'Growth Rates'!E52) -> 2.1415737e+10 | G6: =F6*(1+'Growth Rates'!F52) -> 2.1679556e+10 | H6: =G6*(1+'Growth Rates'!G52) -> 2.1884492e+10 | I6: =H6*(1+'Growth Rates'!H52) -> 2.2063191e+10 | J6: =I6*(1+'Growth Rates'!I52) -> 2.1975502e+10 | K6: =J6*(1+'Growth Rates'!J52) -> 2.2200447e+10 | ... AC6: =AB6*(1+'Growth Rates'!AB52) -> 2.2114919e+10
A7: AEO | B7: ISIC 06 | C7: 1.8488784e+11 | D7: =C7*(1+'Growth Rates'!C53) -> 2.0027374e+11 | E7: =D7*(1+'Growth Rates'!D53) -> 2.020685e+11 | F7: =E7*(1+'Growth Rates'!E53) -> 2.0347246e+11 | G7: =F7*(1+'Growth Rates'!F53) -> 2.0597903e+11 | H7: =G7*(1+'Growth Rates'!G53) -> 2.0792614e+11 | I7: =H7*(1+'Growth Rates'!H53) -> 2.0962397e+11 | J7: =I7*(1+'Growth Rates'!I53) -> 2.0879084e+11 | K7: =J7*(1+'Growth Rates'!J53) -> 2.1092805e+11 | ... AC7: =AB7*(1+'Growth Rates'!AB53) -> 2.1011545e+11
A8: AEO | B8: ISIC 07T08 | C8: 3.96784e+10 | D8: =C8*(1+'Growth Rates'!C54) -> 4.2980337e+10 | E8: =D8*(1+'Growth Rates'!D54) -> 4.3365506e+10 | F8: =E8*(1+'Growth Rates'!E54) -> 4.3666808e+10 | G8: =F8*(1+'Growth Rates'!F54) -> 4.4204737e+10 | H8: =G8*(1+'Growth Rates'!G54) -> 4.4622602e+10 | I8: =H8*(1+'Growth Rates'!H54) -> 4.4986971e+10 | J8: =I8*(1+'Growth Rates'!I54) -> 4.4808173e+10 | K8: =J8*(1+'Growth Rates'!J54) -> 4.5266836e+10 | ... AC8: =AB8*(1+'Growth Rates'!AB54) -> 4.5092445e+10
B9: ISIC 09 | C9: 5.184893e+10 | D9: =C9*(1+'Growth Rates'!C55) -> 5.1589685e+10 | E9: =D9*(1+'Growth Rates'!D55) -> 5.1331737e+10 | F9: =E9*(1+'Growth Rates'!E55) -> 5.1075078e+10 | G9: =F9*(1+'Growth Rates'!F55) -> 5.0819703e+10 | H9: =G9*(1+'Growth Rates'!G55) -> 5.0565604e+10 | I9: =H9*(1+'Growth Rates'!H55) -> 5.0312776e+10 | J9: =I9*(1+'Growth Rates'!I55) -> 5.0061212e+10 | K9: =J9*(1+'Growth Rates'!J55) -> 4.9810906e+10 | ... AC9: =AB9*(1+'Growth Rates'!AB55) -> 4.5513465e+10
A10: AEO | B10: ISIC 10T12 | C10: 2.6361858e+11 | D10: =C10*(1+'Growth Rates'!C56) -> 2.6434032e+11 | E10: =D10*(1+'Growth Rates'!D56) -> 2.6494361e+11 | F10: =E10*(1+'Growth Rates'!E56) -> 2.6703038e+11 | G10: =F10*(1+'Growth Rates'!F56) -> 2.6873683e+11 | H10: =G10*(1+'Growth Rates'!G56) -> 2.7084622e+11 | I10: =H10*(1+'Growth Rates'!H56) -> 2.7297877e+11 | J10: =I10*(1+'Growth Rates'!I56) -> 2.7493122e+11 | K10: =J10*(1+'Growth Rates'!J56) -> 2.7696471e+11 | ... AC10: =AB10*(1+'Growth Rates'!AB56) -> 3.1822901e+11
A11: AEO | B11: ISIC 13T15 | C11: 2.1056492e+10 | D11: =C11*(1+'Growth Rates'!C57) -> 2.1199657e+10 | E11: =D11*(1+'Growth Rates'!D57) -> 2.0995967e+10 | F11: =E11*(1+'Growth Rates'!E57) -> 2.1003955e+10 | G11: =F11*(1+'Growth Rates'!F57) -> 2.0657807e+10 | H11: =G11*(1+'Growth Rates'!G57) -> 2.0444012e+10 | I11: =H11*(1+'Growth Rates'!H57) -> 2.0296637e+10 | J11: =I11*(1+'Growth Rates'!I57) -> 2.0122604e+10 | K11: =J11*(1+'Growth Rates'!J57) -> 1.9885594e+10 | ... AC11: =AB11*(1+'Growth Rates'!AB57) -> 1.7806058e+10
A12: AEO | B12: ISIC 16 | C12: 4.4040118e+10 | D12: =C12*(1+'Growth Rates'!C58) -> 4.4323668e+10 | E12: =D12*(1+'Growth Rates'!D58) -> 4.5218701e+10 | F12: =E12*(1+'Growth Rates'!E58) -> 4.5758545e+10 | G12: =F12*(1+'Growth Rates'!F58) -> 4.6537694e+10 | H12: =G12*(1+'Growth Rates'!G58) -> 4.7994661e+10 | I12: =H12*(1+'Growth Rates'!H58) -> 4.9122606e+10 | J12: =I12*(1+'Growth Rates'!I58) -> 4.987452e+10 | K12: =J12*(1+'Growth Rates'!J58) -> 5.0378418e+10 | ... AC12: =AB12*(1+'Growth Rates'!AB58) -> 5.2864993e+10
A13: AEO | B13: ISIC 17T18 | C13: 8.4707567e+10 | D13: =C13*(1+'Growth Rates'!C59) -> 8.4029552e+10 | E13: =D13*(1+'Growth Rates'!D59) -> 8.40678e+10 | F13: =E13*(1+'Growth Rates'!E59) -> 8.2934469e+10 | G13: =F13*(1+'Growth Rates'!F59) -> 8.2117883e+10 | H13: =G13*(1+'Growth Rates'!G59) -> 8.1689027e+10 | I13: =H13*(1+'Growth Rates'!H59) -> 8.1429487e+10 | J13: =I13*(1+'Growth Rates'!I59) -> 8.148876e+10 | K13: =J13*(1+'Growth Rates'!J59) -> 8.1422595e+10 | ... AC13: =AB13*(1+'Growth Rates'!AB59) -> 8.6665963e+10
A14: AEO | B14: ISIC 19 | C14: 1.3780782e+11 | D14: =C14*(1+'Growth Rates'!C60) -> 1.4008672e+11 | E14: =D14*(1+'Growth Rates'!D60) -> 1.3947496e+11 | F14: =E14*(1+'Growth Rates'!E60) -> 1.3885269e+11 | G14: =F14*(1+'Growth Rates'!F60) -> 1.3809777e+11 | H14: =G14*(1+'Growth Rates'!G60) -> 1.3702e+11 | I14: =H14*(1+'Growth Rates'!H60) -> 1.353289e+11 | J14: =I14*(1+'Growth Rates'!I60) -> 1.3345025e+11 | K14: =J14*(1+'Growth Rates'!J60) -> 1.3122868e+11 | ... AC14: =AB14*(1+'Growth Rates'!AB60) -> 1.1355437e+11
A15: AEO | B15: ISIC 20 | C15: 2.6974052e+11 | D15: =C15*(1+'Growth Rates'!C61) -> 2.7113414e+11 | E15: =D15*(1+'Growth Rates'!D61) -> 2.6923223e+11 | F15: =E15*(1+'Growth Rates'!E61) -> 2.6864518e+11 | G15: =F15*(1+'Growth Rates'!F61) -> 2.6811708e+11 | H15: =G15*(1+'Growth Rates'!G61) -> 2.6903462e+11 | I15: =H15*(1+'Growth Rates'!H61) -> 2.7152755e+11 | J15: =I15*(1+'Growth Rates'!I61) -> 2.7475932e+11 | K15: =J15*(1+'Growth Rates'!J61) -> 2.7840159e+11 | ... AC15: =AB15*(1+'Growth Rates'!AB61) -> 3.4748625e+11
B16: ISIC 21 | C16: 1.3575632e+11 | D16: =C16*(1+'Growth Rates'!C62) -> 1.3901447e+11 | E16: =D16*(1+'Growth Rates'!D62) -> 1.4235082e+11 | F16: =E16*(1+'Growth Rates'!E62) -> 1.4576724e+11 | G16: =F16*(1+'Growth Rates'!F62) -> 1.4926565e+11 | H16: =G16*(1+'Growth Rates'!G62) -> 1.5284803e+11 | I16: =H16*(1+'Growth Rates'!H62) -> 1.5651638e+11 | J16: =I16*(1+'Growth Rates'!I62) -> 1.6027277e+11 | K16: =J16*(1+'Growth Rates'!J62) -> 1.6411932e+11 | ... AC16: =AB16*(1+'Growth Rates'!AB62) -> 2.5151213e+11
A17: AEO | B17: ISIC 22 | C17: 7.4268249e+10 | D17: =C17*(1+'Growth Rates'!C63) -> 7.6145503e+10 | E17: =D17*(1+'Growth Rates'!D63) -> 7.8600275e+10 | F17: =E17*(1+'Growth Rates'!E63) -> 8.0098801e+10 | G17: =F17*(1+'Growth Rates'!F63) -> 8.0799181e+10 | H17: =G17*(1+'Growth Rates'!G63) -> 8.1823171e+10 | I17: =H17*(1+'Growth Rates'!H63) -> 8.3139699e+10 | J17: =I17*(1+'Growth Rates'!I63) -> 8.4468507e+10 | K17: =J17*(1+'Growth Rates'!J63) -> 8.5730446e+10 | ... AC17: =AB17*(1+'Growth Rates'!AB63) -> 1.0138433e+11
A18: AEO | B18: ISIC 231 | C18: 1.0908275e+10 | D18: =C18*(1+'Growth Rates'!C64) -> 1.0826563e+10 | E18: =D18*(1+'Growth Rates'!D64) -> 1.080253e+10 | F18: =E18*(1+'Growth Rates'!E64) -> 1.0796296e+10 | G18: =F18*(1+'Growth Rates'!F64) -> 1.081321e+10 | H18: =G18*(1+'Growth Rates'!G64) -> 1.083664e+10 | I18: =H18*(1+'Growth Rates'!H64) -> 1.0868041e+10 | J18: =I18*(1+'Growth Rates'!I64) -> 1.0921376e+10 | K18: =J18*(1+'Growth Rates'!J64) -> 1.0990468e+10 | ... AC18: =AB18*(1+'Growth Rates'!AB64) -> 1.2633529e+10
A19: AEO | B19: ISIC 239 | C19: 4.5826926e+10 | D19: =C19*(1+'Growth Rates'!C65) -> 4.5958719e+10 | E19: =D19*(1+'Growth Rates'!D65) -> 4.6081024e+10 | F19: =E19*(1+'Growth Rates'!E65) -> 4.6438577e+10 | G19: =F19*(1+'Growth Rates'!F65) -> 4.6758225e+10 | H19: =G19*(1+'Growth Rates'!G65) -> 4.6892746e+10 | I19: =H19*(1+'Growth Rates'!H65) -> 4.7346025e+10 | J19: =I19*(1+'Growth Rates'!I65) -> 4.8038873e+10 | K19: =J19*(1+'Growth Rates'!J65) -> 4.8636613e+10 | ... AC19: =AB19*(1+'Growth Rates'!AB65) -> 5.3289732e+10
A20: AEO | B20: ISIC 241 | C20: 4.2096268e+10 | D20: =C20*(1+'Growth Rates'!C66) -> 4.3174503e+10 | E20: =D20*(1+'Growth Rates'!D66) -> 4.4772131e+10 | F20: =E20*(1+'Growth Rates'!E66) -> 4.5035292e+10 | G20: =F20*(1+'Growth Rates'!F66) -> 4.475196e+10 | H20: =G20*(1+'Growth Rates'!G66) -> 4.465252e+10 | I20: =H20*(1+'Growth Rates'!H66) -> 4.5032574e+10 | J20: =I20*(1+'Growth Rates'!I66) -> 4.5617719e+10 | K20: =J20*(1+'Growth Rates'!J66) -> 4.6178433e+10 | ... AC20: =AB20*(1+'Growth Rates'!AB66) -> 5.2717351e+10
A21: AEO | B21: ISIC 242 | C21: 1.9343938e+10 | D21: =C21*(1+'Growth Rates'!C67) -> 1.9353239e+10 | E21: =D21*(1+'Growth Rates'!D67) -> 1.94365e+10 | F21: =E21*(1+'Growth Rates'!E67) -> 1.9678174e+10 | G21: =F21*(1+'Growth Rates'!F67) -> 1.9859022e+10 | H21: =G21*(1+'Growth Rates'!G67) -> 2.0038209e+10 | I21: =H21*(1+'Growth Rates'!H67) -> 2.0219043e+10 | J21: =I21*(1+'Growth Rates'!I67) -> 2.0399246e+10 | K21: =J21*(1+'Growth Rates'!J67) -> 2.0596952e+10 | ... AC21: =AB21*(1+'Growth Rates'!AB67) -> 2.4234415e+10
A22: AEO | B22: ISIC 25 | C22: 1.3945562e+11 | D22: =C22*(1+'Growth Rates'!C68) -> 1.422083e+11 | E22: =D22*(1+'Growth Rates'!D68) -> 1.4789327e+11 | F22: =E22*(1+'Growth Rates'!E68) -> 1.5147295e+11 | G22: =F22*(1+'Growth Rates'!F68) -> 1.5177857e+11 | H22: =G22*(1+'Growth Rates'!G68) -> 1.5215203e+11 | I22: =H22*(1+'Growth Rates'!H68) -> 1.5331847e+11 | J22: =I22*(1+'Growth Rates'!I68) -> 1.5468684e+11 | K22: =J22*(1+'Growth Rates'!J68) -> 1.5623744e+11 | ... AC22: =AB22*(1+'Growth Rates'!AB68) -> 1.7508254e+11
A23: AEO | B23: ISIC 26 | C23: 2.1941598e+11 | D23: =C23*(1+'Growth Rates'!C69) -> 2.2826765e+11 | E23: =D23*(1+'Growth Rates'!D69) -> 2.3299219e+11 | F23: =E23*(1+'Growth Rates'!E69) -> 2.4214829e+11 | G23: =F23*(1+'Growth Rates'!F69) -> 2.5211912e+11 | H23: =G23*(1+'Growth Rates'!G69) -> 2.6018402e+11 | I23: =H23*(1+'Growth Rates'!H69) -> 2.6791778e+11 | J23: =I23*(1+'Growth Rates'!I69) -> 2.7526832e+11 | K23: =J23*(1+'Growth Rates'!J69) -> 2.8308757e+11 | ... AC23: =AB23*(1+'Growth Rates'!AB69) -> 4.7413871e+11
A24: AEO | B24: ISIC 27 | C24: 5.8678438e+10 | D24: =C24*(1+'Growth Rates'!C70) -> 5.903686e+10 | E24: =D24*(1+'Growth Rates'!D70) -> 5.8619409e+10 | F24: =E24*(1+'Growth Rates'!E70) -> 5.9411029e+10 | G24: =F24*(1+'Growth Rates'!F70) -> 6.0670074e+10 | H24: =G24*(1+'Growth Rates'!G70) -> 6.1590652e+10 | I24: =H24*(1+'Growth Rates'!H70) -> 6.2417299e+10 | J24: =I24*(1+'Growth Rates'!I70) -> 6.2924198e+10 | K24: =J24*(1+'Growth Rates'!J70) -> 6.3487902e+10 | ... AC24: =AB24*(1+'Growth Rates'!AB70) -> 6.9088501e+10
A25: AEO | B25: ISIC 28 | C25: 1.5269305e+11 | D25: =C25*(1+'Growth Rates'!C71) -> 1.5446604e+11 | E25: =D25*(1+'Growth Rates'!D71) -> 1.5761673e+11 | F25: =E25*(1+'Growth Rates'!E71) -> 1.6363704e+11 | G25: =F25*(1+'Growth Rates'!F71) -> 1.6710221e+11 | H25: =G25*(1+'Growth Rates'!G71) -> 1.7006543e+11 | I25: =H25*(1+'Growth Rates'!H71) -> 1.7351554e+11 | J25: =I25*(1+'Growth Rates'!I71) -> 1.761188e+11 | K25: =J25*(1+'Growth Rates'!J71) -> 1.7845883e+11 | ... AC25: =AB25*(1+'Growth Rates'!AB71) -> 1.905738e+11
A26: AEO | B26: ISIC 29 | C26: 1.3602952e+11 | D26: =C26*(1+'Growth Rates'!C72) -> 1.4461741e+11 | E26: =D26*(1+'Growth Rates'!D72) -> 1.5435903e+11 | F26: =E26*(1+'Growth Rates'!E72) -> 1.5730929e+11 | G26: =F26*(1+'Growth Rates'!F72) -> 1.6061062e+11 | H26: =G26*(1+'Growth Rates'!G72) -> 1.6361227e+11 | I26: =H26*(1+'Growth Rates'!H72) -> 1.6541836e+11 | J26: =I26*(1+'Growth Rates'!I72) -> 1.6557962e+11 | K26: =J26*(1+'Growth Rates'!J72) -> 1.6692913e+11 | ... AC26: =AB26*(1+'Growth Rates'!AB72) -> 2.0249704e+11
A27: AEO | B27: ISIC 30 | C27: 1.4442899e+11 | D27: =C27*(1+'Growth Rates'!C73) -> 1.5354716e+11 | E27: =D27*(1+'Growth Rates'!D73) -> 1.638903e+11 | F27: =E27*(1+'Growth Rates'!E73) -> 1.6702273e+11 | G27: =F27*(1+'Growth Rates'!F73) -> 1.7052791e+11 | H27: =G27*(1+'Growth Rates'!G73) -> 1.737149e+11 | I27: =H27*(1+'Growth Rates'!H73) -> 1.7563251e+11 | J27: =I27*(1+'Growth Rates'!I73) -> 1.7580373e+11 | K27: =J27*(1+'Growth Rates'!J73) -> 1.7723657e+11 | ... AC27: =AB27*(1+'Growth Rates'!AB73) -> 2.1500071e+11
A28: AEO | B28: ISIC 31T33 | C28: 1.3467252e+11 | D28: =C28*(1+'Growth Rates'!C74) -> 1.365977e+11 | E28: =D28*(1+'Growth Rates'!D74) -> 1.4042816e+11 | F28: =E28*(1+'Growth Rates'!E74) -> 1.447181e+11 | G28: =F28*(1+'Growth Rates'!F74) -> 1.4737998e+11 | H28: =G28*(1+'Growth Rates'!G74) -> 1.4914462e+11 | I28: =H28*(1+'Growth Rates'!H74) -> 1.5206278e+11 | J28: =I28*(1+'Growth Rates'!I74) -> 1.5423432e+11 | K28: =J28*(1+'Growth Rates'!J74) -> 1.5690774e+11 | ... AC28: =AB28*(1+'Growth Rates'!AB74) -> 1.901019e+11
B29: ISIC 351 | C29: 2.5998899e+11 | D29: =C29*(1+'Growth Rates'!C75) -> 2.6518877e+11 | E29: =D29*(1+'Growth Rates'!D75) -> 2.7049254e+11 | F29: =E29*(1+'Growth Rates'!E75) -> 2.7590239e+11 | G29: =F29*(1+'Growth Rates'!F75) -> 2.8142044e+11 | H29: =G29*(1+'Growth Rates'!G75) -> 2.8704885e+11 | I29: =H29*(1+'Growth Rates'!H75) -> 2.9278983e+11 | J29: =I29*(1+'Growth Rates'!I75) -> 2.9864563e+11 | K29: =J29*(1+'Growth Rates'!J75) -> 3.0461854e+11 | ... AC29: =AB29*(1+'Growth Rates'!AB75) -> 4.3507028e+11
B30: ISIC 352T353 | C30: 6.1106674e+10 | D30: =C30*(1+'Growth Rates'!C76) -> 6.1534421e+10 | E30: =D30*(1+'Growth Rates'!D76) -> 6.1965162e+10 | F30: =E30*(1+'Growth Rates'!E76) -> 6.2398918e+10 | G30: =F30*(1+'Growth Rates'!F76) -> 6.283571e+10 | H30: =G30*(1+'Growth Rates'!G76) -> 6.327556e+10 | I30: =H30*(1+'Growth Rates'!H76) -> 6.3718489e+10 | J30: =I30*(1+'Growth Rates'!I76) -> 6.4164518e+10 | K30: =J30*(1+'Growth Rates'!J76) -> 6.461367e+10 | ... AC30: =AB30*(1+'Growth Rates'!AB76) -> 7.325797e+10
B31: ISIC 36T39 | C31: 7.6303988e+10 | D31: =C31*(1+'Growth Rates'!C77) -> 7.7440763e+10 | E31: =D31*(1+'Growth Rates'!D77) -> 7.8594473e+10 | F31: =E31*(1+'Growth Rates'!E77) -> 7.9765371e+10 | G31: =F31*(1+'Growth Rates'!F77) -> 8.0953714e+10 | H31: =G31*(1+'Growth Rates'!G77) -> 8.215976e+10 | I31: =H31*(1+'Growth Rates'!H77) -> 8.3383773e+10 | J31: =I31*(1+'Growth Rates'!I77) -> 8.4626023e+10 | K31: =J31*(1+'Growth Rates'!J77) -> 8.5886779e+10 | ... AC31: =AB31*(1+'Growth Rates'!AB77) -> 1.1208029e+11
A32: AEO | B32: ISIC 41T43 | C32: 9.5544462e+11 | D32: =C32*(1+'Growth Rates'!C78) -> 9.5031163e+11 | E32: =D32*(1+'Growth Rates'!D78) -> 9.5771832e+11 | F32: =E32*(1+'Growth Rates'!E78) -> 9.7292187e+11 | G32: =F32*(1+'Growth Rates'!F78) -> 9.9654957e+11 | H32: =G32*(1+'Growth Rates'!G78) -> 1.0238949e+12 | I32: =H32*(1+'Growth Rates'!H78) -> 1.0432403e+12 | J32: =I32*(1+'Growth Rates'!I78) -> 1.0601288e+12 | K32: =J32*(1+'Growth Rates'!J78) -> 1.0724632e+12 | ... AC32: =AB32*(1+'Growth Rates'!AB78) -> 1.2418856e+12
B33: ISIC 45T47 | C33: 2.6956973e+12 | D33: =C33*(1+'Growth Rates'!C79) -> 2.7638259e+12 | E33: =D33*(1+'Growth Rates'!D79) -> 2.8336762e+12 | F33: =E33*(1+'Growth Rates'!E79) -> 2.9052919e+12 | G33: =F33*(1+'Growth Rates'!F79) -> 2.9787176e+12 | H33: =G33*(1+'Growth Rates'!G79) -> 3.0539989e+12 | I33: =H33*(1+'Growth Rates'!H79) -> 3.1311828e+12 | J33: =I33*(1+'Growth Rates'!I79) -> 3.2103174e+12 | K33: =J33*(1+'Growth Rates'!J79) -> 3.291452e+12 | ... AC33: =AB33*(1+'Growth Rates'!AB79) -> 5.1582147e+12
B34: ISIC 49T53 | C34: 7.2262214e+11 | D34: =C34*(1+'Growth Rates'!C80) -> 7.3851982e+11 | E34: =D34*(1+'Growth Rates'!D80) -> 7.5476726e+11 | F34: =E34*(1+'Growth Rates'!E80) -> 7.7137214e+11 | G34: =F34*(1+'Growth Rates'!F80) -> 7.8834233e+11 | H34: =G34*(1+'Growth Rates'!G80) -> 8.0568586e+11 | I34: =H34*(1+'Growth Rates'!H80) -> 8.2341095e+11 | J34: =I34*(1+'Growth Rates'!I80) -> 8.4152599e+11 | K34: =J34*(1+'Growth Rates'!J80) -> 8.6003956e+11 | ... AC34: =AB34*(1+'Growth Rates'!AB80) -> 1.2724319e+12
B35: ISIC 55T56 | C35: 7.0289993e+11 | D35: =C35*(1+'Growth Rates'!C81) -> 7.1906663e+11 | E35: =D35*(1+'Growth Rates'!D81) -> 7.3560516e+11 | F35: =E35*(1+'Growth Rates'!E81) -> 7.5252408e+11 | G35: =F35*(1+'Growth Rates'!F81) -> 7.6983213e+11 | H35: =G35*(1+'Growth Rates'!G81) -> 7.8753827e+11 | I35: =H35*(1+'Growth Rates'!H81) -> 8.0565165e+11 | J35: =I35*(1+'Growth Rates'!I81) -> 8.2418164e+11 | K35: =J35*(1+'Growth Rates'!J81) -> 8.4313782e+11 | ... AC35: =AB35*(1+'Growth Rates'!AB81) -> 1.2695797e+12
B36: ISIC 58T60 | C36: 5.0207783e+11 | D36: =C36*(1+'Growth Rates'!C82) -> 5.2049057e+11 | E36: =D36*(1+'Growth Rates'!D82) -> 5.3957857e+11 | F36: =E36*(1+'Growth Rates'!E82) -> 5.5936658e+11 | G36: =F36*(1+'Growth Rates'!F82) -> 5.7988027e+11 | H36: =G36*(1+'Growth Rates'!G82) -> 6.0114627e+11 | I36: =H36*(1+'Growth Rates'!H82) -> 6.2319215e+11 | J36: =I36*(1+'Growth Rates'!I82) -> 6.4604653e+11 | K36: =J36*(1+'Growth Rates'!J82) -> 6.6973905e+11 | ... AC36: =AB36*(1+'Growth Rates'!AB82) -> 1.2807324e+12
B37: ISIC 61 | C37: 2.7641438e+11 | D37: =C37*(1+'Growth Rates'!C83) -> 2.8387757e+11 | E37: =D37*(1+'Growth Rates'!D83) -> 2.9154226e+11 | F37: =E37*(1+'Growth Rates'!E83) -> 2.994139e+11 | G37: =F37*(1+'Growth Rates'!F83) -> 3.0749808e+11 | H37: =G37*(1+'Growth Rates'!G83) -> 3.1580053e+11 | I37: =H37*(1+'Growth Rates'!H83) -> 3.2432714e+11 | J37: =I37*(1+'Growth Rates'!I83) -> 3.3308397e+11 | K37: =J37*(1+'Growth Rates'!J83) -> 3.4207724e+11 | ... AC37: =AB37*(1+'Growth Rates'!AB83) -> 5.5257619e+11
B38: ISIC 62T63 | C38: 7.6946696e+11 | D38: =C38*(1+'Growth Rates'!C84) -> 7.987067e+11 | E38: =D38*(1+'Growth Rates'!D84) -> 8.2905756e+11 | F38: =E38*(1+'Growth Rates'!E84) -> 8.6056174e+11 | G38: =F38*(1+'Growth Rates'!F84) -> 8.9326309e+11 | H38: =G38*(1+'Growth Rates'!G84) -> 9.2720709e+11 | I38: =H38*(1+'Growth Rates'!H84) -> 9.6244096e+11 | J38: =I38*(1+'Growth Rates'!I84) -> 9.9901371e+11 | K38: =J38*(1+'Growth Rates'!J84) -> 1.0369762e+12 | ... AC38: =AB38*(1+'Growth Rates'!AB84) -> 2.0291828e+12
B39: ISIC 64T66 | C39: 1.6315542e+12 | D39: =C39*(1+'Growth Rates'!C85) -> 1.6641853e+12 | E39: =D39*(1+'Growth Rates'!D85) -> 1.697469e+12 | F39: =E39*(1+'Growth Rates'!E85) -> 1.7314184e+12 | G39: =F39*(1+'Growth Rates'!F85) -> 1.7660468e+12 | H39: =G39*(1+'Growth Rates'!G85) -> 1.8013677e+12 | I39: =H39*(1+'Growth Rates'!H85) -> 1.8373951e+12 | J39: =I39*(1+'Growth Rates'!I85) -> 1.874143e+12 | K39: =J39*(1+'Growth Rates'!J85) -> 1.9116258e+12 | ... AC39: =AB39*(1+'Growth Rates'!AB85) -> 2.7302724e+12
B40: ISIC 68 | C40: 2.9660164e+12 | D40: =C40*(1+'Growth Rates'!C86) -> 3.0223707e+12 | E40: =D40*(1+'Growth Rates'!D86) -> 3.0797958e+12 | F40: =E40*(1+'Growth Rates'!E86) -> 3.1383119e+12 | G40: =F40*(1+'Growth Rates'!F86) -> 3.1979398e+12 | H40: =G40*(1+'Growth Rates'!G86) -> 3.2587007e+12 | I40: =H40*(1+'Growth Rates'!H86) -> 3.320616e+12 | J40: =I40*(1+'Growth Rates'!I86) -> 3.3837077e+12 | K40: =J40*(1+'Growth Rates'!J86) -> 3.4479981e+12 | ... AC40: =AB40*(1+'Growth Rates'!AB86) -> 4.8384063e+12
B41: ISIC 69T82 | C41: 2.3423179e+12 | D41: =C41*(1+'Growth Rates'!C87) -> 2.3968946e+12 | E41: =D41*(1+'Growth Rates'!D87) -> 2.452743e+12 | F41: =E41*(1+'Growth Rates'!E87) -> 2.5098926e+12 | G41: =F41*(1+'Growth Rates'!F87) -> 2.5683739e+12 | H41: =G41*(1+'Growth Rates'!G87) -> 2.6282178e+12 | I41: =H41*(1+'Growth Rates'!H87) -> 2.6894561e+12 | J41: =I41*(1+'Growth Rates'!I87) -> 2.7521213e+12 | K41: =J41*(1+'Growth Rates'!J87) -> 2.8162465e+12 | ... AC41: =AB41*(1+'Growth Rates'!AB87) -> 4.2631102e+12
...

Sheet Growth Rates
A1: BLS Data | G1: 3 | H1: 4 | I1: 5 | J1: 6 | K1: 7 | L1: 8 | M1: 9 | N1: 10 | O1: 11 | P1: 12 | Q1: 13 | R1: 14 | S1: 15 | T1: 16 | U1: 17 | V1: 18 | W1: 19 | X1: 20 | Y1: 21 | Z1: 22 | AA1: 23 | AB1: 24 | AC1: 25 | AD1: 26 | AE1: 27 | AF1: 28 | AG1: 29 | AH1: 30 | AI1: 31
B2: Compound Growth Rate (output-weighted average of components of each ISIC code)
B3: 2024-2034 | F3: 2025 | G3: 2026 | H3: 2027 | I3: 2028 | J3: 2029 | K3: 2030 | L3: 2031 | M3: 2032 | N3: 2033 | O3: 2034 | P3: 2035 | Q3: 2036 | R3: 2037 | S3: 2038 | T3: 2039 | U3: 2040 | V3: 2041 | W3: 2042 | X3: 2043 | Y3: 2044 | Z3: 2045 | AA3: 2046 | AB3: 2047 | AC3: 2048 | AD3: 2049 | AE3: 2050
