Workbook

Sheet About
A1: CPCC Cement Pathway Capital Cost per Unit Annual Capacity
A3: Sources: | B3: Conventional dry kiln cost (starting point) | D3: Demonstration-scale alternative cement plants (context only)
B4: European Cement Research Academy (ECRA) | D4: U.S. Department of Energy, Office of Clean Energy Demonstrations (with company disclosures for Brimstone and Sublime Systems)
B5: Technical Report TR-042/2009: Development of State of the Art Techniques in Cement Manufacturing | D5: Cement and concrete industrial demonstrations
B6: 2009 | D6: 2024
B7: https://www.wbcsdcement.org/pdf/technology/ECRA%20Technical%20Report%20on%20State%20of%20the%20Art%20Techniques.pdf | D7: https://www.energy.gov/oced/oced-cement-and-concrete-industrial-demonstrations
B8: As summarized in secondary literature, ECRA gives $180-350 per metric ton of annual capacity (2009 dollars, depending on plant size) for a new dry-process plant with a precalciner. We could not read the ECRA report itself, so the range is second-hand. The low and high ends are on the 'Source Data' tab. | D8: Brimstone: about $378 million for about 140,000 metric tons per year (roughly $2,700 per metric ton). Sublime Systems, Holyoke: about $150 million for about 30,000 metric tons per year (roughly $5,000 per metric ton). Both are first-of-a-kind demonstration plants and neither feeds the shipped value; they sit on the 'Source Data' and 'Calc' tabs to show how far demonstration costs are above the assumption we use.
B10: Cross-check on the dry kiln cost | D10: Cost of individual kiln-line upgrades
B11: International Energy Agency (IEA) | D11: European Cement Research Academy (ECRA) and Cement Sustainability Initiative (CSI)
B12: Cement Technology Roadmap | D12: Development of State of the Art Techniques in Cement Manufacturing: Trying to Look Ahead (CSI/ECRA Technology Papers 2017)
B13: 2010 | D13: 2017
B14: (no public link) | D14: https://archive.wbcsd.org/contentwbc/download/3604/47080/1
B15: A cited figure of about EUR 263 per metric ton of annual capacity (2010, plant of about 1 million metric tons per year). It is shown on the 'Source Data' tab for context and is not converted or used in the calculation; we only checked that it is broadly consistent with ECRA's range. The figure comes from secondary citations of the roadmap. | D15: For a 2 million metric ton per year line in 2015 euros: replacing three preheater cyclone stages 8-10 million euros (about $4-5 per metric ton of annual capacity in 2012 dollars), a full clinker cooler replacement 15-20 million euros ($8-11), a new burner about $0.3 and a controls upgrade $0.1-2.7. ECRA also notes that most original equipment is replaced within 20-30 years.
B17: Converting 2009 dollars to the model's 2012 dollars | D17: Cross-check on component costs
B18: Engineering News-Record (ENR) | D18: U.S. Environmental Protection Agency ENERGY STAR (prepared by Lawrence Berkeley National Laboratory)
B19: Construction Cost Index, annual values for 2009 and 2012 | D19: Energy Efficiency Improvement and Cost Saving Opportunities for Cement Making: An ENERGY STAR Guide
B20: 2012 | D20: 2013
B21: (subscription data) | D21: https://www.energystar.gov/sites/default/files/buildings/tools/ENERGY%20STAR%20Guide%20for%20the%20Cement%20Industry%2028_08_2013%20Final.pdf
B22: The index moves from 8,570 to 9,308 between 2009 and 2012, a factor of 1.086, on the 'Source Data' tab. | D22: Cyclone ($6-7) and cooler ($11-15) costs consistent with ECRA. Converting a long dry kiln to a preheater-precalciner costs $24-133, which is a larger job than an overhaul and serves only as an upper bound.
B24: Electric kiln cost, and a check on the dry kiln cost | D24: Air-compliance retrofit costs
B25: Vattenfall and Cementa (Heidelberg Materials) | D25: U.S. Environmental Protection Agency
B26: CemZero: A feasibility study evaluating ways to reach sustainable cement production via the use of electricity | D26: Regulatory Impact Analysis: Amendments to the NESHAP and NSPS for the Portland Cement Manufacturing Industry
B27: 2018 | D27: 2010
B28: https://www.cement.heidelbergmaterials.se/sites/default/files/assets/document/65/de/final_cemzero_2018_public_version_2.0.pdf.pdf | D28: https://19january2021snapshot.epa.gov/sites/static/files/2020-07/documents/nonmetallic-minerals_ria_final-cement-neshap-nsps_2010-08.pdf
B29: Greenfield 1 million metric ton per year clinker plant, whole plant, 2018 euros, accuracy about +/-25% (Tables 9 and 13, pp. 59-61). The plasma (electric) kiln plant costs 204.4 million euros installed plus a 47.5 million euro plasma system, plus 10% owner's cost and contingency: 277.1 million euros, or $299 per metric ton of annual capacity in 2012 dollars. The conventional reference plant (231 million euros) works out to $249, close to the $250 dry-kiln value, so the electric plant is about 1.2 times a conventional one. The figures are on the 'Source Data' tab. | D29: $2.2 billion of capital (2005 dollars) for existing kilns across 104 million metric tons of clinker capacity: about $25 per metric ton in total, or about $7 without the wet scrubbers EPA assumed for hydrogen chloride.
B31: Alternative chemistry plant cost | D31: A U.S. cooler replacement
B32: U.S. Department of Energy | D32: CalPortland (U.S. DOE Better Buildings case study)
B33: Pathways to Commercial Liftoff: Low-Carbon Cement | D33: CalPortland Invests for Energy Efficiency (Rillito, Arizona)
B34: 2023 | D34: 2016
B35: https://liftoff.energy.gov/wp-content/uploads/2023/12/LIFTOFF_Cement_Updated-2.6.25.pdf | D35: https://betterbuildingssolutioncenter.energy.gov/sites/default/files/CalPortland%20Invests%20for%20Energy%20Efficiency.pdf
B36: For alternative production methods (the category that includes Sublime Systems and Brimstone), DOE puts a commercial greenfield plant at about $0.5-1.0 billion. At DOE's representative 1.5 million metric ton per year plant size that is $251-502 per metric ton of annual capacity in 2012 dollars. | D36: A new clinker cooler cost $9 million, against $1.1 million to rebuild the old one: roughly $10-14 per metric ton of annual capacity (capacity estimated from the plant's fuel use).
B38: Plant-level cost with carbon capture (cross-check only)
B39: Princeton University, Net-Zero America (NZA) project
B40: Net-Zero America, Annex K, Table 3
B41: 2021
B42: https://netzeroamerica.princeton.edu/img/Princeton_NZA_Annex_K.pdf
B43: Total capital cost of $3.5 billion for a 3.75 million metric tons per year clinker plant with CO2 capture, about $933 per metric ton of annual capacity in NZA's dollars. The 'Calc' tab shows this division for comparison. It is not used in the export, because the model prices capture equipment separately.
A46: Notes:
A47: Purpose and layout | B47: This file gives two capital costs for each cement production pathway, in the model's 2012 U.S. dollars per metric ton of annual clinker capacity: the cost of building a new kiln, and the cost of overhauling an existing kiln line for one more campaign (kiln shell, tyres and drive, cooler, preheater and precalciner refurbishment, burner and controls, and air-compliance work). The model turns the new-build cost into a yearly capital charge (over the asset life in the CPAL file) and compares it across pathways to decide which kind of kiln to build. When a kiln reaches the end of a campaign, the model compares overhauling it, at the overhaul cost paid back over the campaign length in the CPPL file, with retiring and replacing it. Both costs cover the kiln only. For the CCS pathway, capture equipment is added inside the model from the CCS sector's own capital cost inputs, so the CCS pathway here costs the same as a conventional kiln. 'Source Data' holds the published figures and conversion factors and 'Calc' works out the new-build cost of each pathway. 'Overhaul' builds up the overhaul share from component costs and applies it to the new-build costs, reading them directly so the two can't get out of step. The 'CPCaOC-new' and 'CPCaOC-overhaul' tabs are exported to CPCaOC-new.csv and CPCaOC-overhaul.csv.
A48: Dry kiln with precalciner and with CCS | B48: $255.21 per metric ton of annual capacity: a 2009-dollar starting point of $235 (our blend of the low end of ECRA's range and the IEA figure) times 1.086 to move from 2009 to 2012 dollars. The CemZero study's conventional reference plant comes out at $249, which supports this value. The CCS pathway uses the same value, since only the kiln is priced here.
...

Sheet Source Data
A1: NZA Annex K Table 3 - Dry kiln with CCS
A2: Total capital cost ($) | B2: 3500000000
A3: Plant clinker capacity (metric tons/yr) | B3: 3750000
A5: ECRA 2009 / IEA - Dry kiln with precalciner base range (2009$/t)
A6: ECRA low end | B6: 180
A7: ECRA high end | B7: 350
A8: IEA-cited figure (EUR263/t, 2010, ~1 Mt/yr plant; contextual, not separately FX-converted here) | B8: 263 | C8: EUR/t, 2010 - shown for context only; not used numerically in the Calc tab formula
A9: EI-synthesized 2009$ base point (judgment blend of ECRA low end + IEA-implied figure) | B9: 235
A10: Construction-cost index, 2009$ -> 2012$ (ENR CCI 8570 -> 9308); the model runs in 2012 USD | B10: 1.086
A12: FOAK alternative-chemistry actuals (context only)
A13: Brimstone total award/project cost ($) | B13: 378000000
A14: Brimstone capacity (t/yr) | B14: 140000
A15: Sublime Holyoke total project cost ($) | B15: 150000000
A16: Sublime Holyoke capacity (t/yr) | B16: 30000
A18: CemZero feasibility study (Vattenfall/Cementa 2018, Tables 9 and 13) - 1 Mt clinker/yr greenfield plant, 2018 EUR
A19: Plasma (electric) kiln plant: installed cost excluding carbon capture (M EUR) | B19: 204.4
A20: Plasma system (M EUR) | B20: 47.5
A21: Owner's cost + contingency factor (5% + 5%) | B21: 1.1
A22: Conventional reference plant: total capital required (M EUR) | B22: 231
A23: Plant clinker capacity (metric tons/yr) | B23: 1000000
A24: Exchange rate, 2018 annual average ($ per EUR) | B24: 1.181
A25: CPI-U annual average, 2018 | B25: 251.107
A26: CPI-U annual average, 2012 | B26: 229.594
A28: DOE Pathways to Commercial Liftoff: Low-Carbon Cement (2023) - alternative production methods
A29: Greenfield plant capex, high end of the ~$0.5-1.0B range (2023 $) | B29: 1000000000
A30: Greenfield plant capex, low end (2023 $) | B30: 500000000
A31: Representative commercial plant capacity (metric tons/yr) | B31: 1500000
A32: CPI-U annual average, 2023 | B32: 304.702

Sheet Calc
A1: Dry kiln with CCS: KILN ONLY (= dry kiln). Capture equipment priced in-model from the CCS sector (CC Capital Cost ... per t CO2/yr x captured t CO2 per t clinker). NZA $933/(t/yr) kept below as a plant-level cross-check.
A2: NZA plant-level cross-check ($/(t/yr), NZA dollars, not used) | B2: ='Source Data'!B2/'Source Data'!B3 -> 933.33333
A3: Kiln-only value used (= dry kiln) | B3: =B7 -> 255.21
A5: Dry kiln with precalciner: 2009$ base x 2009->2012 construction index
A6: Inflated value ($/(t/yr)) | B6: ='Source Data'!B9*'Source Data'!B10 -> 255.21
A7: Dry kiln value used ($/(t/yr)) | B7: =(B6) -> 255.21
A9: FOAK alternative-chemistry actuals (context only, not used in export)
A10: Brimstone $/t | B10: ='Source Data'!B13/'Source Data'!B14 -> 2700
A11: Sublime Holyoke $/t | B11: ='Source Data'!B15/'Source Data'!B16 -> 5000
A13: Electric kiln: CemZero plasma plant, converted to 2012 $
A14: Plasma plant ($/(t/yr), 2012 $) | B14: =('Source Data'!B19+'Source Data'!B20)*'Source Data'!B21*1000000/'Source Data'!B23*'Source Data'!B24*'Source Data'!B26/'Source Data'!B25 -> 299.20749
A15: Conventional reference plant, cross-check against the dry kiln value ($/(t/yr), 2012 $) | B15: ='Source Data'!B22*1000000/'Source Data'!B23*'Source Data'!B24*'Source Data'!B26/'Source Data'!B25 -> 249.43856
A16: Electric kiln value used | B16: =(B14) -> 299.20749
A18: Alternative chemistry cement: DOE Liftoff greenfield capex, converted to 2012 $
A19: High end ($/(t/yr), 2012 $) | B19: ='Source Data'!B29/'Source Data'!B31*'Source Data'!B26/'Source Data'!B32 -> 502.33562
A20: Low end ($/(t/yr), 2012 $) | B20: ='Source Data'!B30/'Source Data'!B31*'Source Data'!B26/'Source Data'!B32 -> 251.16781
A21: Alternative chemistry value used (high end, since demonstration costs sit far above the range) | B21: =(B19) -> 502.33562

Sheet Overhaul
A1: Overhaul capital cost = overhaul share x new-build capital cost
A3: Pathway | B3: New-build cost ($/(t/yr)) | C3: Overhaul cost ($/(t/yr))
A4: dry kiln with precalciner | B4: ='CPCaOC-new'!B2 -> 255.21 | C4: =B4*$B$9 -> 35.75
A5: dry kiln with CCS | B5: ='CPCaOC-new'!B3 -> 255.21 | C5: =B5*$B$9 -> 35.75
A6: electric kiln | B6: ='CPCaOC-new'!B4 -> 299.20749 | C6: =B6*$B$9 -> 41.9132
A7: alternative chemistry cement | B7: ='CPCaOC-new'!B6 -> 502.33562 | C7: =B7*$B$9 -> 70.367534
A9: Overhaul share of new-build cost (= the component build-up below) | B9: =B20 -> 0.14008072
A11: Component build-up, $/(t/yr) in 2012 $ (ECRA/CSI 2017, ENERGY STAR 2013, EPA 2010 cement NESHAP)
A12: Clinker cooler replacement | B12: 10
A13: Preheater cyclone refurbishment | B13: 5
A14: Precalciner partial upgrade | B14: 4
A15: Kiln shell, tyres, rollers and drive | B15: 5
A16: Burner and controls | B16: 1.5
A17: Air-compliance work (dust collection, monitoring) | B17: 7
A18: U.S. cost uplift (10%) | B18: =0.1*SUM(B12:B17) -> 3.25
A19: Total, $/(t/yr) | B19: =SUM(B12:B18) -> 35.75
A20: Share of the dry kiln new-build cost | B20: =B19/B4 -> 0.14008072

Sheet CPCaOC-new
A1: Unit: 2012 USD per (metric ton clinker/year) | B1: New Build Capital Cost
A2: dry kiln with precalciner | B2: =Calc!B7 -> 255.21
A3: dry kiln with CCS | B3: =Calc!B3 -> 255.21
A4: electric kiln | B4: =Calc!B16 -> 299.20749
A5: electric kiln with CCS | B5: =B4 -> 299.20749
A6: alternative chemistry cement | B6: =Calc!B21 -> 502.33562

Sheet CPCaOC-overhaul
A1: Unit: 2012 USD per (metric ton clinker/year) | B1: Overhaul Capital Cost
A2: dry kiln with precalciner | B2: =Overhaul!C4 -> 35.75
A3: dry kiln with CCS | B3: =Overhaul!C5 -> 35.75
A4: electric kiln | B4: =Overhaul!C6 -> 41.9132
A5: electric kiln with CCS | B5: =B4 -> 41.9132
A6: alternative chemistry cement | B6: =Overhaul!C7 -> 70.367534
