Workbook
Name cpi_2016_to_2012: #REF!
Name cpi_2019_to_2012: #REF!
Name cpi_2020_to_2012: #REF!
Name cpi_2022_to_2012: #REF!
Name cpi_2025_to_2012: #REF!

Sheet About
A1: BAU Tariff Cost Multipliers
A3: Variables in this workbook (BTCM = BAU Tariff Cost Multiplier):
A4: BTCM-EC | B4: Electricity Capacity — tariff cost multiplier by Electricity Source (Pattern A)
A5: BTCM-GB | B5: Grid Battery storage (standalone + hybrid) — scalar (Pattern B)
A6: BTCM-EVB-LDVs-psgr | B6: EV Battery — LDVs passenger, by Vehicle Technology (Pattern A)
A7: BTCM-EVB-LDVs-frgt | B7: EV Battery — LDVs freight, by Vehicle Technology (Pattern A)
A8: BTCM-EVB-HDVs-psgr | B8: EV Battery — HDVs passenger, by Vehicle Technology (Pattern A)
A9: BTCM-EVB-HDVs-frgt | B9: EV Battery — HDVs freight, by Vehicle Technology (Pattern A)
A10: BTCM-VNB-LDVs-psgr | B10: Vehicle Non-Battery — LDVs passenger, by Vehicle Technology (Pattern A)
A11: BTCM-VNB-LDVs-frgt | B11: Vehicle Non-Battery — LDVs freight, by Vehicle Technology (Pattern A)
A12: BTCM-VNB-HDVs-psgr | B12: Vehicle Non-Battery — HDVs passenger, by Vehicle Technology (Pattern A)
A13: BTCM-VNB-HDVs-frgt | B13: Vehicle Non-Battery — HDVs freight, by Vehicle Technology (Pattern A)
A14: BTCM-T | B14: Transmission — scalar (Pattern B)
A15: BTCM-D | B15: Distribution — scalar (Pattern B)
A17: Units and conventions
A18: All values are dimensionless multipliers expressed as fractional cost increase.
A19: Example: 0.13 = a +13% cost increase. Unit: Dmnl.
A20: Year horizon: 2025–2050 (26 columns). Trailing comma is preserved on CSV export per EPS convention.
A21: Subscripted files (Pattern A): row 1 = Unit string + years 2025–2050. Data rows = subscript element + 26 values.
A22: Scalar files (Pattern B): col A = Year (2025–2050), col B = Tariff Multiplier, 5 trailing comma columns.
A23: Subscript element names must match Vensim source exactly — case and spaces preserved.
A25: Methodology
A26: Each output tab has key-year anchor values (per the build plan) and linearly interpolated annual values.
A27: Output tabs hold the interpolated annual values laid out as Vensim will read them.
A28: Calculations tab is embedded inline above each Output block (key-year anchors with linear interpolation formulas).
A29: Linear interpolation formula: between two anchor years y1 (v1) and y2 (v2), value at year y = v1 + (y - y1) * (v2 - v1) / (y2 - y1).
... A38: Solar PV (utility + distributed)
A39: Wood Mackenzie | B39: Tariffs to increase costs and slow down development for US power industry | C39: https://www.woodmac.com/press-releases/tariffs-to-increase-costs-and-slow-down-development-for-us-power-industry/
A40: FTI Consulting | B40: Solar Shock: How New Tariffs Could Reshape US Utility-Scale Deployment | C40: https://www.fticonsulting.com/insights/articles/solar-shock-how-new-tariffs-could-reshape-us-utility-scale-deployment
A41: SEIA / Wood Mackenzie | B41: US Solar Market Insight (quarterly)
A42: CSIS | B42: The Impacts of Tariffs on Clean Energy Technologies | C42: https://www.csis.org/analysis/impacts-tariffs-clean-energy-technologies
A43: Aurora Solar | B43: How the latest tariffs could impact solar energy in 2025 | C43: https://aurorasolar.com/home-solar/blog/solar-101/solar-tariffs
A44: Solar.com | B44: Residential cost-stack analysis | C44: https://www.solar.com/learn/how-tariffs-might-impact-solar/
A45: White & Case LLP | B45: Trump administration initiates Section 232 investigations on polysilicon (Jul 2025) | C45: https://www.whitecase.com/insight-alert/trump-administration-initiates-section-232-investigations-polysilicon-and-unmanned
A47: Onshore / offshore wind
A48: American Action Forum | B48: President Trump Gears Up to Levy Tariffs on Wind Turbine Imports | C48: https://www.americanactionforum.org/insight/president-trump-gears-up-to-levy-tariffs-on-wind-turbine-imports/
A49: PwC | B49: Steel and aluminum goods under Section 232 tariff coverage expanded | C49: https://www.pwc.com/us/en/services/tax/library/pwc-steel-and-aluminum-goods-subject-to-section-232-tariffs-expanded.html
A50: US Tariff Rates | B50: Section 232 Tariffs: Steel & Aluminum 25-50% | C50: https://ustariffrates.com/section-232-tariffs
A51: APPA | B51: New Report Sees Increase in Cost of Power Generation Technologies Due to Tariff Policies | C51: https://www.publicpower.org/periodical/article/new-report-sees-increase-cost-power-generation-technologies-due-tariff-policies
A52: ACP | B52: American Clean Power Association annual supply chain reports
...

Sheet Calc-Solar-PV
A1: BTCM-Calc-Solar-PV — Bottom-up calculation of solar PV tariff cost multiplier
A2: Multiplier = tariff_rate × import_share × cost_component_share × pass_through, summed across cost components.
A4: 1. TARIFF RATE INPUTS (effective ad valorem rate on imported good)
A5: Tariff lever | B5: 2025 | C5: 2026 | D5: 2027 onward | E5: Source / Note
A6: Section 201 safeguard (modules/cells, most countries) | B6: 0.14 | C6: 0 | D6: 0 | E6: USTR: 14.25% Feb24-Feb25, 14% Feb25-Feb26, expires Feb 7, 2026 (sched.)
A7: Section 301 modules/cells (China-origin) | B7: 0.5 | C7: 0.5 | D7: 0.5 | E7: USTR Sept 2024 review: raised from 25% to 50% effective Sept 27, 2024
A8: Section 301 polysilicon/wafers (China-origin) | B8: 0.5 | C8: 0.5 | D8: 0.5 | E8: USTR: 50% effective Jan 1, 2025
A9: AD/CVD on SE Asia modules (Cambodia/Malaysia/Thailand/Vietnam, weighted avg) | B9: 0.4 | C9: 0.4 | D9: 0.3 | E9: Commerce April 2025 final: rates up to 271% for Vietnam; weighted by trade flow ~30-40%
A10: Section 232 steel/aluminum derivatives (applies to structural+electrical BOS) | B10: 0.5 | C10: 0.5 | D10: 0.5 | E10: S232 25% in Feb 2025, doubled to 50% in June 2025
A11: Reciprocal 'energy resource' tariff (China-origin) | B11: 0.1 | C11: 0.1 | D11: 0.1 | E11: Feb 2025 executive order: +10% on Chinese polysilicon/wafers/cells
A13: 2. SYSTEM COST STRUCTURE & IMPORT SHARES (utility-scale solar PV)
A14: Cost component | B14: % of system CAPEX | C14: Import share (China-origin) | D14: Import share (SE Asia) | E14: Pass-through | F14: Source / Note
A15: Modules (cells+assembly) | B15: 0.3 | C15: 0.1 | D15: 0.5 | E15: 0.8 | F15: NREL Q1 2024 benchmark, Wood Mac SEIA Q4 2024; ~50-60 GW US assembly capacity by 2025 but production well below demand
A16: Polysilicon / wafers | B16: 0.05 | C16: 0.85 | D16: 0 | E16: 0.8 | F16: China 98% of ingot/wafer & 92% of polysilicon capacity end-2023 (IEA-PVPS/SolarPower Europe via PV-Tech)
A17: Inverters / electrical BOS | B17: 0.1 | C17: 0.05 | D17: 0.05 | E17: 0.7 | F17: Domestic+SE Asia mix; steel/aluminum/copper content exposes to S232
A18: Structural BOS (racking/trackers) | B18: 0.1 | C18: 0 | D18: 0 | E18: 1 | F18: Steel-intensive; 100% pass-through of S232 steel tariff via cost-plus pricing
A19: EPC labor / overhead / margin | B19: 0.3 | C19: 0 | D19: 0 | E19: 0 | F19: Domestic labor; no direct tariff exposure
A20: Land / development / interconnection | B20: 0.15 | C20: 0 | D20: 0 | E20: 0 | F20: Domestic; no tariff exposure
A21: Sum of cost shares (should = 100%): | B21: =SUM(B15:B20) -> 1
A23: 3. CALCULATED TARIFF MULTIPLIER (key years; output tab pulls from row 31)
A24: For each component: contribution = cost_share × pass_through × (China_imp_share × China_tariff_stack + SEAsia_imp_share × SEAsia_tariff_stack + non_China_imp_share × non_China_tariff_stack)
A26: Component contribution | B26: 2025 | C26: 2026 | D26: 2027 | E26: 2028 | F26: 2029 | G26: 2030 | H26: 2035 | I26: 2040 | J26: 2050
A27: Tariff-exposure decline factor (vs 2026 peak) | B27: 0.7 | C27: 1 | D27: 0.95 | E27: 0.85 | F27: 0.7 | G27: 0.55 | H27: 0.4 | I27: 0.3 | J27: 0.3
A28: China-origin module tariff stack (S201 + S301 + reciprocal) | B28: =B6+B7+B11 -> 0.74 | C28: =C6+C7+C11 -> 0.6 | D28: =D6+D7+D11 -> 0.6 | E28: =D6+D7+D11 -> 0.6 | F28: =D6+D7+D11 -> 0.6 | G28: =D6+D7+D11 -> 0.6 | H28: =D6+D7+D11 -> 0.6 | I28: =D6+D7+D11 -> 0.6 | J28: =D6+D7+D11 -> 0.6
A29: SE Asia module tariff stack (S201 + AD/CVD) | B29: =B6+B9 -> 0.54 | C29: =C6+C9 -> 0.4 | D29: =D6+D9 -> 0.3 | E29: =D6+D9 -> 0.3 | F29: =D6+D9 -> 0.3 | G29: =D6+D9 -> 0.3 | H29: =D6+D9 -> 0.3 | I29: =D6+D9 -> 0.3 | J29: =D6+D9 -> 0.3
A30: Steel/aluminum derivative tariff (applies to structural BOS, all sources) | B30: =B10 -> 0.5 | C30: =C10 -> 0.5 | D30: =D10 -> 0.5 | E30: =D10 -> 0.5 | F30: =D10 -> 0.5 | G30: =D10 -> 0.5 | H30: =D10 -> 0.5 | I30: =D10 -> 0.5 | J30: =D10 -> 0.5
A31: TOTAL Solar PV Cost Multiplier (→ feeds BTCM-EC 'solar PV' row) | B31: =B27*($B$15*$E$15*($C$15*B28+$D$15*B29)+$B$16*$E$16*$C$16*$B$7+$B$17*$E$17*$C$17*B28+$B$18*$E$18*B30) -> 0.106505 | C31: =C27*($B$15*$E$15*($C$15*C28+$D$15*C29)+$B$16*$E$16*$C$16*$B$7+$B$17*$E$17*$C$17*C28+$B$18*$E$18*C30) -> 0.1315 | D31: =D27*($B$15*$E$15*($C$15*D28+$D$15*D29)+$B$16*$E$16*$C$16*$B$7+$B$17*$E$17*$C$17*D28+$B$18*$E$18*D30) -> 0.113525 | E31: =E27*($B$15*$E$15*($C$15*E28+$D$15*E29)+$B$16*$E$16*$C$16*$B$7+$B$17*$E$17*$C$17*E28+$B$18*$E$18*E30) -> 0.101575 | F31: =F27*($B$15*$E$15*($C$15*F28+$D$15*F29)+$B$16*$E$16*$C$16*$B$7+$B$17*$E$17*$C$17*F28+$B$18*$E$18*F30) -> 0.08365 | G31: =G27*($B$15*$E$15*($C$15*G28+$D$15*G29)+$B$16*$E$16*$C$16*$B$7+$B$17*$E$17*$C$17*G28+$B$18*$E$18*G30) -> 0.065725 | H31: =H27*($B$15*$E$15*($C$15*H28+$D$15*H29)+$B$16*$E$16*$C$16*$B$7+$B$17*$E$17*$C$17*H28+$B$18*$E$18*H30) -> 0.0478 | I31: =I27*($B$15*$E$15*($C$15*I28+$D$15*I29)+$B$16*$E$16*$C$16*$B$7+$B$17*$E$17*$C$17*I28+$B$18*$E$18*I30) -> 0.03585 | J31: =J27*($B$15*$E$15*($C$15*J28+$D$15*J29)+$B$16*$E$16*$C$16*$B$7+$B$17*$E$17*$C$17*J28+$B$18*$E$18*J30) -> 0.03585

Sheet Calc-Solar-Thermal
A1: BTCM-Calc-Solar-Thermal — Bottom-up calculation of solar thermal (CSP) tariff cost multiplier
A2: Multiplier = sum over components of (cost_share × import_share × tariff_stack × pass_through)
A4: 1. TARIFF RATE INPUTS
A5: Tariff lever | B5: 2025 | C5: 2026 | D5: 2027 onward | E5: Source
A6: Section 232 steel/aluminum (50%) | B6: 0.5 | C6: 0.5 | D6: 0.5 | E6: CFR: S232 doubled to 50% June 2025
A7: Section 232 copper derivatives | B7: 0.5 | C7: 0.5 | D7: 0.5 | E7: Aug 2025 expansion to derivatives
A8: S301 China-origin electronics/controls | B8: 0.25 | C8: 0.25 | D8: 0.25 | E8: USTR baseline rate
A10: 2. CSP COST STRUCTURE (NREL ATB 2024 power tower)
A11: Component | B11: % of CAPEX | C11: Steel/al exposure | D11: S301 China exposure | E11: Pass-through | F11: Source
A12: Solar field (heliostats, structural steel) | B12: 0.45 | C12: 1 | D12: 0 | E12: 0.8 | F12: NREL ATB 2024 CSP page; mostly domestic steel structure
A13: Receiver/tower (steel) | B13: 0.1 | C13: 1 | D13: 0 | E13: 0.8 | F13: Steel-intensive
A14: Thermal storage (molten salt tanks) | B14: 0.1 | C14: 0.5 | D14: 0 | E14: 0.7 | F14: Steel tanks; some specialty alloys
A15: Power block (turbine/generator) | B15: 0.15 | C15: 0.2 | D15: 0.1 | E15: 0.5 | F15: Mostly domestic mfg; minor copper exposure
A16: BOP, EPC, contingency | B16: 0.2 | C16: 0.1 | D16: 0.05 | E16: 0.3 | F16: Mostly labor/services
A17: Sum check | B17: =SUM(B12:B16) -> 1
A19: 3. CALCULATED MULTIPLIER (key years; output is row 22)
B20: 2025 | C20: 2026 | D20: 2027 | E20: 2028 | F20: 2029 | G20: 2030 | H20: 2035 | I20: 2040 | J20: 2050
A21: Decline factor (IRA + domestic ramp) | B21: 0.7 | C21: 1 | D21: 0.95 | E21: 0.85 | F21: 0.7 | G21: 0.55 | H21: 0.4 | I21: 0.3 | J21: 0.3
A22: TOTAL Solar Thermal Multiplier (→ BTCM-EC 'solar thermal' row) | B22: {=B21*SUMPRODUCT($B$12:$B$16, $E$12:$E$16, ($C$12:$C$16*B$6+$D$12:$D$16*B$8))} -> 0.1754375 | C22: {=C21*SUMPRODUCT($B$12:$B$16, $E$12:$E$16, ($C$12:$C$16*C$6+$D$12:$D$16*C$8))} -> 0.250625 | D22: {=D21*SUMPRODUCT($B$12:$B$16, $E$12:$E$16, ($C$12:$C$16*D$6+$D$12:$D$16*D$8))} -> 0.23809375 | E22: {=E21*SUMPRODUCT($B$12:$B$16, $E$12:$E$16, ($C$12:$C$16*D$6+$D$12:$D$16*D$8))} -> 0.21303125 | F22: {=F21*SUMPRODUCT($B$12:$B$16, $E$12:$E$16, ($C$12:$C$16*D$6+$D$12:$D$16*D$8))} -> 0.1754375 | G22: {=G21*SUMPRODUCT($B$12:$B$16, $E$12:$E$16, ($C$12:$C$16*D$6+$D$12:$D$16*D$8))} -> 0.13784375 | H22: {=H21*SUMPRODUCT($B$12:$B$16, $E$12:$E$16, ($C$12:$C$16*D$6+$D$12:$D$16*D$8))} -> 0.10025 | I22: {=I21*SUMPRODUCT($B$12:$B$16, $E$12:$E$16, ($C$12:$C$16*D$6+$D$12:$D$16*D$8))} -> 0.0751875 | J22: {=J21*SUMPRODUCT($B$12:$B$16, $E$12:$E$16, ($C$12:$C$16*D$6+$D$12:$D$16*D$8))} -> 0.0751875

Sheet Calc-Wind-Onshore
A1: BTCM-Calc-Wind-Onshore — Bottom-up calculation of onshore wind tariff cost multiplier
A2: Multiplier = sum over components of (cost_share × import_share × tariff_stack × pass_through)
A4: 1. TARIFF RATE INPUTS
A5: Tariff lever | B5: 2025 | C5: 2026 | D5: 2027 onward | E5: Source
A6: Section 232 steel/aluminum (50%, applies to towers/blades/nacelles content) | B6: 0.5 | C6: 0.5 | D6: 0.5 | E6: S232 doubled to 50% June 2025; Aug 2025 expansion to derivative goods incl wind turbines
A7: Reciprocal/MFN rate on imported turbine components (avg) | B7: 0.1 | C7: 0.1 | D7: 0.1 | E7: Avg reciprocal rate; turbine OEMs Vestas/Siemens Gamesa/GE source globally
A9: 2. ONSHORE WIND COST STRUCTURE (LBNL Land-Based Wind Market Report 2023)
A10: Component | B10: % of project CAPEX | C10: Steel/aluminum content | D10: Import share | E10: Pass-through | F10: Source
A11: Nacelle (gearbox, generator) | B11: 0.2 | C11: 0.3 | D11: 0.15 | E11: 0.8 | F11: LBNL Land-Based Wind 2023: over 85% nacelle assembly domestic in 2022
A12: Blades | B12: 0.15 | C12: 0.1 | D12: 0.8 | E12: 0.8 | F12: LBNL Land-Based Wind 2023: blade domestic content just 5-25% in 2022
A13: Tower | B13: 0.15 | C13: 1 | D13: 0.25 | E13: 0.9 | F13: LBNL: 70-85% tower mfg domestic, but tower is ~100% steel → S232 fully passes through
A14: Foundation, BOP, electrical, installation | B14: 0.3 | C14: 0.5 | D14: 0.05 | E14: 0.5 | F14: Domestic labor + steel; S232 hits steel content
A15: Development, interconnection, overhead | B15: 0.2 | C15: 0.05 | D15: 0 | E15: 0.1 | F15: Domestic services
A16: Sum check | B16: =SUM(B11:B15) -> 1
A18: 3. CALCULATED MULTIPLIER
B19: 2025 | C19: 2026 | D19: 2027 | E19: 2028 | F19: 2029 | G19: 2030 | H19: 2035 | I19: 2040 | J19: 2050
A20: Decline factor (IRA + domestic ramp) | B20: 0.7 | C20: 1 | D20: 0.95 | E20: 0.85 | F20: 0.7 | G20: 0.55 | H20: 0.4 | I20: 0.3 | J20: 0.3
A21: TOTAL Onshore Wind Multiplier (→ BTCM-EC 'onshore wind' row) | B21: {=B20*SUMPRODUCT($B$11:$B$15, $E$11:$E$15, ($C$11:$C$15*B$6+$D$11:$D$15*B$7))} -> 0.1061375 | C21: {=C20*SUMPRODUCT($B$11:$B$15, $E$11:$E$15, ($C$11:$C$15*C$6+$D$11:$D$15*C$7))} -> 0.151625 | D21: {=D20*SUMPRODUCT($B$11:$B$15, $E$11:$E$15, ($C$11:$C$15*D$6+$D$11:$D$15*D$7))} -> 0.14404375 | E21: {=E20*SUMPRODUCT($B$11:$B$15, $E$11:$E$15, ($C$11:$C$15*D$6+$D$11:$D$15*D$7))} -> 0.12888125 | F21: {=F20*SUMPRODUCT($B$11:$B$15, $E$11:$E$15, ($C$11:$C$15*D$6+$D$11:$D$15*D$7))} -> 0.1061375 | G21: {=G20*SUMPRODUCT($B$11:$B$15, $E$11:$E$15, ($C$11:$C$15*D$6+$D$11:$D$15*D$7))} -> 0.08339375 | H21: {=H20*SUMPRODUCT($B$11:$B$15, $E$11:$E$15, ($C$11:$C$15*D$6+$D$11:$D$15*D$7))} -> 0.06065 | I21: {=I20*SUMPRODUCT($B$11:$B$15, $E$11:$E$15, ($C$11:$C$15*D$6+$D$11:$D$15*D$7))} -> 0.0454875 | J21: {=J20*SUMPRODUCT($B$11:$B$15, $E$11:$E$15, ($C$11:$C$15*D$6+$D$11:$D$15*D$7))} -> 0.0454875

Sheet Calc-Wind-Offshore
A1: BTCM-Calc-Wind-Offshore — Bottom-up calculation of offshore wind tariff cost multiplier
A2: Multiplier = sum over components of (cost_share × import_share × tariff_stack × pass_through)
A4: 1. TARIFF RATE INPUTS
A5: Tariff lever | B5: 2025 | C5: 2026 | D5: 2027 onward | E5: Source
A6: Section 232 steel/aluminum (50%) | B6: 0.5 | C6: 0.5 | D6: 0.5 | E6: S232 doubled to 50% June 2025; impacts steel-intensive monopiles, jackets, towers
A7: Reciprocal/MFN on imported turbine components (avg) | B7: 0.1 | C7: 0.1 | D7: 0.1 | E7: OEM turbines (Vestas/Siemens/GE Vernova) sourced from Europe + emerging US plants
A9: 2. OFFSHORE WIND CAPEX STRUCTURE (NREL 2024 Cost of Offshore Wind; Kikuchi & Ishihara 2023)
A10: Component | B10: % of CAPEX | C10: Steel/aluminum content | D10: Import share | E10: Pass-through | F10: Source
A11: Wind turbine (nacelle, blades, tower) | B11: 0.42 | C11: 0.3 | D11: 0.85 | E11: 0.85 | F11: Kikuchi & Ishihara 2023; minimal US offshore turbine mfg; mostly imported from Europe (Vestas/Siemens)
A12: Balance of plant (monopile, cables, substation) | B12: 0.25 | C12: 0.7 | D12: 0.5 | E12: 0.85 | F12: Steel-intensive monopiles, much imported; subsea cables predominantly imported
A13: Installation (vessels, marine services) | B13: 0.27 | C13: 0.15 | D13: 0.6 | E13: 0.5 | F13: Jones Act vessels limited; many installation vessels foreign-flagged
A14: Development, project management | B14: 0.05 | C14: 0 | D14: 0.05 | E14: 0.2 | F14: Domestic services
A15: Sum check | B15: =SUM(B11:B14) -> 0.99
A17: 3. CALCULATED MULTIPLIER
B18: 2025 | C18: 2026 | D18: 2027 | E18: 2028 | F18: 2029 | G18: 2030 | H18: 2035 | I18: 2040 | J18: 2050
A19: Decline factor (IRA + domestic ramp — slower for offshore due to nascent US supply chain) | B19: 0.7 | C19: 1 | D19: 0.98 | E19: 0.92 | F19: 0.82 | G19: 0.7 | H19: 0.55 | I19: 0.45 | J19: 0.4
A20: TOTAL Offshore Wind Multiplier (→ BTCM-EC 'offshore wind' row) | B20: {=B19*SUMPRODUCT($B$11:$B$14, $E$11:$E$14, ($C$11:$C$14*B$6+$D$11:$D$14*B$7))} -> 0.131019 | C20: {=C19*SUMPRODUCT($B$11:$B$14, $E$11:$E$14, ($C$11:$C$14*C$6+$D$11:$D$14*C$7))} -> 0.18717 | D20: {=D19*SUMPRODUCT($B$11:$B$14, $E$11:$E$14, ($C$11:$C$14*D$6+$D$11:$D$14*D$7))} -> 0.1834266 | E20: {=E19*SUMPRODUCT($B$11:$B$14, $E$11:$E$14, ($C$11:$C$14*D$6+$D$11:$D$14*D$7))} -> 0.1721964 | F20: {=F19*SUMPRODUCT($B$11:$B$14, $E$11:$E$14, ($C$11:$C$14*D$6+$D$11:$D$14*D$7))} -> 0.1534794 | G20: {=G19*SUMPRODUCT($B$11:$B$14, $E$11:$E$14, ($C$11:$C$14*D$6+$D$11:$D$14*D$7))} -> 0.131019 | H20: {=H19*SUMPRODUCT($B$11:$B$14, $E$11:$E$14, ($C$11:$C$14*D$6+$D$11:$D$14*D$7))} -> 0.1029435 | I20: {=I19*SUMPRODUCT($B$11:$B$14, $E$11:$E$14, ($C$11:$C$14*D$6+$D$11:$D$14*D$7))} -> 0.0842265 | J20: {=J19*SUMPRODUCT($B$11:$B$14, $E$11:$E$14, ($C$11:$C$14*D$6+$D$11:$D$14*D$7))} -> 0.074868

Sheet Calc-Battery
A1: BTCM-Calc-Battery — Bottom-up calc for grid battery (BTCM-GB) and EV battery (BTCM-EVB) multipliers
A2: Both stationary BESS and EV battery packs share a similar cell-cost structure; this tab calcs both and feeds 5 output tabs.
A4: 1. TARIFF RATE INPUTS
A5: Tariff lever | B5: 2025 | C5: 2026 | D5: 2027 onward | E5: Source
A6: Section 301 EV batteries (China) | B6: 0.25 | C6: 0.25 | D6: 0.25 | E6: USTR Sept 2024 review: Li-ion EV batteries raised to 25% effective 2024
A7: Section 301 non-EV (stationary) batteries (China) | B7: 0.075 | C7: 0.25 | D7: 0.25 | E7: USTR review: nonEV Li-ion batteries scheduled to rise from 7.5% to 25% in 2026
A8: Section 232 steel/aluminum (BESS containers, EV pack housing) | B8: 0.5 | C8: 0.5 | D8: 0.5 | E8: S232 50%, applies to steel content of BESS enclosures and EV pack housing
A9: Reciprocal/MFN average on non-China imports | B9: 0.1 | C9: 0.1 | D9: 0.1 | E9: Avg of reciprocal rates on Korean/Japanese cells (typically 15%)
A11: 2A. GRID BATTERY (stationary BESS) COST STRUCTURE
A12: Component | B12: % of system cost | C12: China-origin import share | D12: Steel content | E12: Pass-through | F12: Source
A13: Li-ion cells (LFP for stationary) | B13: 0.4 | C13: 0.8 | D13: 0.05 | E13: 0.9 | F13: BNEF 2025 BESS pack $70/kWh; cells ~70% of pack; China dominates LFP supply (CATL/BYD); US cell mfg nascent
A14: Pack assembly (modules, BMS) | B14: 0.15 | C14: 0.3 | D14: 0.05 | E14: 0.8 | F14: Mix of US, Korea, China
A15: Container/enclosure (steel) | B15: 0.1 | C15: 0.1 | D15: 0.9 | E15: 0.9 | F15: Steel-intensive; S232 50% pass-through
A16: Power conversion system (PCS, inverter) | B16: 0.15 | C16: 0.3 | D16: 0.05 | E16: 0.7 | F16: PCS partially imported; Tesla, Sungrow, others
A17: Site work, EPC, integration | B17: 0.2 | C17: 0 | D17: 0.05 | E17: 0.2 | F17: Domestic labor
A18: Sum check | B18: =SUM(B13:B17) -> 1
A20: 2B. EV BATTERY PACK COST STRUCTURE
A21: Component | B21: % of pack cost | C21: China-origin import share | D21: Steel content | E21: Pass-through | F21: Source
A22: EV cells (NMC + LFP mix) | B22: 0.8 | C22: 0.5 | D22: 0.05 | E22: 0.9 | F22: BNEF 2025: BEV cells avg $79/kWh = 80% of pack price; China leads but Korea/Japan/US growing
A23: Pack housing, cooling, BMS | B23: 0.15 | C23: 0.2 | D23: 0.4 | E23: 0.8 | F23: Mix of domestic and imported; steel/aluminum housing exposes to S232
A24: Pack assembly labor | B24: 0.05 | C24: 0 | D24: 0 | E24: 0.2 | F24: Increasingly US-domestic via Ford/GM/Stellantis/Tesla joint ventures
A25: Sum check | B25: =SUM(B22:B24) -> 1
A27: 3. CALCULATED MULTIPLIERS
B28: 2025 | C28: 2026 | D28: 2027 | E28: 2028 | F28: 2029 | G28: 2030 | H28: 2035 | I28: 2040 | J28: 2050
A29: Decline factor (IRA 45X cell mfg credits + domestic gigafactory ramp) | B29: 0.7 | C29: 1 | D29: 0.85 | E29: 0.65 | F29: 0.5 | G29: 0.35 | H29: 0.2 | I29: 0.15 | J29: 0.15
A30: TOTAL Grid Battery (BESS) Multiplier (→ BTCM-GB scalar) | B30: {=B29*SUMPRODUCT($B$13:$B$17, $E$13:$E$17, ($C$13:$C$17*B$7+$D$13:$D$17*B$8))} -> 0.05842375 | C30: {=C29*SUMPRODUCT($B$13:$B$17, $E$13:$E$17, ($C$13:$C$17*C$7+$D$13:$D$17*C$8))} -> 0.14725 | D30: {=D29*SUMPRODUCT($B$13:$B$17, $E$13:$E$17, ($C$13:$C$17*D$7+$D$13:$D$17*D$8))} -> 0.1251625 | E30: {=E29*SUMPRODUCT($B$13:$B$17, $E$13:$E$17, ($C$13:$C$17*D$7+$D$13:$D$17*D$8))} -> 0.0957125 | F30: {=F29*SUMPRODUCT($B$13:$B$17, $E$13:$E$17, ($C$13:$C$17*D$7+$D$13:$D$17*D$8))} -> 0.073625 | G30: {=G29*SUMPRODUCT($B$13:$B$17, $E$13:$E$17, ($C$13:$C$17*D$7+$D$13:$D$17*D$8))} -> 0.0515375 | H30: {=H29*SUMPRODUCT($B$13:$B$17, $E$13:$E$17, ($C$13:$C$17*D$7+$D$13:$D$17*D$8))} -> 0.02945 | I30: {=I29*SUMPRODUCT($B$13:$B$17, $E$13:$E$17, ($C$13:$C$17*D$7+$D$13:$D$17*D$8))} -> 0.0220875 | J30: {=J29*SUMPRODUCT($B$13:$B$17, $E$13:$E$17, ($C$13:$C$17*D$7+$D$13:$D$17*D$8))} -> 0.0220875
A31: TOTAL EV Battery (LDV BEV pack) Multiplier (→ BTCM-EVB-LDVs-* for BEV row) | B31: {=B29*SUMPRODUCT($B$22:$B$24, $E$22:$E$24, ($C$22:$C$24*B$6+$D$22:$D$24*B$8))} -> 0.0966 | C31: {=C29*SUMPRODUCT($B$22:$B$24, $E$22:$E$24, ($C$22:$C$24*C$6+$D$22:$D$24*C$8))} -> 0.138 | D31: {=D29*SUMPRODUCT($B$22:$B$24, $E$22:$E$24, ($C$22:$C$24*D$6+$D$22:$D$24*D$8))} -> 0.1173 | E31: {=E29*SUMPRODUCT($B$22:$B$24, $E$22:$E$24, ($C$22:$C$24*D$6+$D$22:$D$24*D$8))} -> 0.0897 | F31: {=F29*SUMPRODUCT($B$22:$B$24, $E$22:$E$24, ($C$22:$C$24*D$6+$D$22:$D$24*D$8))} -> 0.069 | G31: {=G29*SUMPRODUCT($B$22:$B$24, $E$22:$E$24, ($C$22:$C$24*D$6+$D$22:$D$24*D$8))} -> 0.0483 | H31: {=H29*SUMPRODUCT($B$22:$B$24, $E$22:$E$24, ($C$22:$C$24*D$6+$D$22:$D$24*D$8))} -> 0.0276 | I31: {=I29*SUMPRODUCT($B$22:$B$24, $E$22:$E$24, ($C$22:$C$24*D$6+$D$22:$D$24*D$8))} -> 0.0207 | J31: {=J29*SUMPRODUCT($B$22:$B$24, $E$22:$E$24, ($C$22:$C$24*D$6+$D$22:$D$24*D$8))} -> 0.0207
A32: EV Battery PHEV multiplier (LDV) — BEV mult × 0.65 (smaller battery share of vehicle cost) | B32: =B31*0.65 -> 0.06279 | C32: =C31*0.65 -> 0.0897 | D32: =D31*0.65 -> 0.076245 | E32: =E31*0.65 -> 0.058305 | F32: =F31*0.65 -> 0.04485 | G32: =G31*0.65 -> 0.031395 | H32: =H31*0.65 -> 0.01794 | I32: =I31*0.65 -> 0.013455 | J32: =J31*0.65 -> 0.013455
A33: H2 vehicle battery multiplier — BEV mult × 0.30 (small Li-ion + fuel cell) | B33: =B31*0.3 -> 0.02898 | C33: =C31*0.3 -> 0.0414 | D33: =D31*0.3 -> 0.03519 | E33: =E31*0.3 -> 0.02691 | F33: =F31*0.3 -> 0.0207 | G33: =G31*0.3 -> 0.01449 | H33: =H31*0.3 -> 0.00828 | I33: =I31*0.3 -> 0.00621 | J33: =J31*0.3 -> 0.00621
A35: TOTAL EV Battery (HDV BEV pack) Multiplier (→ BTCM-EVB-HDVs-*) | B35: =B31*0.7 -> 0.06762 | C35: =C31*0.7 -> 0.0966 | D35: =D31*0.7 -> 0.08211 | E35: =E31*0.7 -> 0.06279 | F35: =F31*0.7 -> 0.0483 | G35: =G31*0.7 -> 0.03381 | H35: =H31*0.7 -> 0.01932 | I35: =I31*0.7 -> 0.01449 | J35: =J31*0.7 -> 0.01449
A36: HDV PHEV multiplier | B36: =B35*0.65 -> 0.043953 | C36: =C35*0.65 -> 0.06279 | D36: =D35*0.65 -> 0.0533715 | E36: =E35*0.65 -> 0.0408135 | F36: =F35*0.65 -> 0.031395 | G36: =G35*0.65 -> 0.0219765 | H36: =H35*0.65 -> 0.012558 | I36: =I35*0.65 -> 0.0094185 | J36: =J35*0.65 -> 0.0094185
A37: HDV H2 multiplier | B37: =B35*0.3 -> 0.020286 | C37: =C35*0.3 -> 0.02898 | D37: =D35*0.3 -> 0.024633 | E37: =E35*0.3 -> 0.018837 | F37: =F35*0.3 -> 0.01449 | G37: =G35*0.3 -> 0.010143 | H37: =H35*0.3 -> 0.005796 | I37: =I35*0.3 -> 0.004347 | J37: =J35*0.3 -> 0.004347

Sheet Calc-T-and-D
A1: BTCM-Calc-T-and-D — Source-anchored calc for Transmission and Distribution tariff multipliers
A2: Approach: source-anchored. Multiplier driven by S232 derivative tariff on grid equipment (transformers, conductors).
A4: 1. TARIFF & MARKET CONTEXT
A5: Key fact | B5: Source
A6: S232 steel/aluminum tariffs at 50% (June 2025); copper derivatives added Aug 2025 with 15% transitional rate through Dec 2027 | B6: CTP Inc.: U.S. Overhauls Section 232 Tariffs. URL: https://info.ctp-inc.com/articles/u-s-overhauls-section-232-tariffs-for-steel-aluminum-and-copper-products
A7: Transformer-specific tariffs increased; transformers are a critical bottleneck with 25% YoY price surge cited by SEIA | B7: SEIA Q1 2024: 'higher transformer costs, which surged by 25% year-over-year due to transformer supply shortages'
A8: S232 expanded to derivative goods Aug 2025 (407 product categories) covering grid components | B8: PwC. URL: https://www.pwc.com/us/en/services/tax/library/pwc-steel-and-aluminum-goods-subject-to-section-232-tariffs-expanded.html
A9: April 2026: full customs value rule for S232 (vs prior content-only) | B9: GHY: U.S. Adjusts Section 232 Tariffs. URL: https://www.ghy.com/trade-compliance/us-adjusts-section-232-tariffs-on-aluminum-steel-and-copper-full-customs-value-now-applies/
A11: 2. STEEL/COPPER/ALUMINUM SHARE OF T&D CAPEX (rough decomposition)
A12: Component | B12: % of T or D capex | C12: Steel/Cu/Al content | D12: Effective tariff exposure | E12: Pass-through
A13: Transformers (steel core, copper windings) | B13: 0.2 | C13: 0.7 | D13: 0.5 | E13: 0.9
A14: Conductors (copper/aluminum cables) | B14: 0.15 | C14: 1 | D14: 0.3 | E14: 0.9
A15: Towers/poles (steel) | B15: 0.15 | C15: 1 | D15: 0.5 | E15: 0.9
A16: Substations (switchgear, breakers — steel+copper) | B16: 0.1 | C16: 0.6 | D16: 0.4 | E16: 0.8
A17: Civil works, ROW, labor | B17: 0.4 | C17: 0 | D17: 0 | E17: 0.1
A18: Sum check | B18: =SUM(B13:B17) -> 1
A20: 3. CALCULATED MULTIPLIER
B21: 2025 | C21: 2026 | D21: 2027 | E21: 2028 | F21: 2029 | G21: 2030 | H21: 2035 | I21: 2040 | J21: 2050
A22: Decline factor (some IRA support but T&D supply chain is structurally constrained — modest decline) | B22: 0.7 | C22: 1 | D22: 1 | E22: 1 | F22: 0.92 | G22: 0.83 | H22: 0.5 | I22: 0.33 | J22: 0.33
A23: TOTAL T&D Multiplier (applies to both BTCM-T and BTCM-D) | B23: =B22*SUMPRODUCT($B$13:$B$17, $C$13:$C$17, $D$13:$D$17, $E$13:$E$17) -> 0.13314 | C23: =C22*SUMPRODUCT($B$13:$B$17, $C$13:$C$17, $D$13:$D$17, $E$13:$E$17) -> 0.1902 | D23: =D22*SUMPRODUCT($B$13:$B$17, $C$13:$C$17, $D$13:$D$17, $E$13:$E$17) -> 0.1902 | E23: =E22*SUMPRODUCT($B$13:$B$17, $C$13:$C$17, $D$13:$D$17, $E$13:$E$17) -> 0.1902 | F23: =F22*SUMPRODUCT($B$13:$B$17, $C$13:$C$17, $D$13:$D$17, $E$13:$E$17) -> 0.174984 | G23: =G22*SUMPRODUCT($B$13:$B$17, $C$13:$C$17, $D$13:$D$17, $E$13:$E$17) -> 0.157866 | H23: =H22*SUMPRODUCT($B$13:$B$17, $C$13:$C$17, $D$13:$D$17, $E$13:$E$17) -> 0.0951 | I23: =I22*SUMPRODUCT($B$13:$B$17, $C$13:$C$17, $D$13:$D$17, $E$13:$E$17) -> 0.062766 | J23: =J22*SUMPRODUCT($B$13:$B$17, $C$13:$C$17, $D$13:$D$17, $E$13:$E$17) -> 0.062766

Sheet Calc-Vehicle-NonBattery
A1: BTCM-Calc-Vehicle-NonBattery — Decomposition of Section 232 autos tariff impact on vehicle structure (non-battery)
A2: Section 232 imposed Apr/May 2025: 25% on imported vehicles + parts (USMCA-compliant US content exempt).
A4: 1. TARIFF INPUTS
A5: Tariff | B5: 2025 | C5: 2026 | D5: 2027 onward | E5: Source
A6: S232 autos: 25% on imported vehicles (LDV passenger) | B6: 0.25 | C6: 0.25 | D6: 0.25 | E6: Trump Proclamation Mar 2025, effective Apr 2025. URL: https://www.federalregister.gov/documents/2025/04/03/2025-05930/
A7: S232 autos: 25% on imported auto parts | B7: 0.25 | C7: 0.25 | D7: 0.25 | E7: Effective May 3, 2025. CBP: https://www.cbp.gov/trade/programs-administration/entry-summary/section-232-additional-faqs-autos
A8: S232 MHDV: 25% on medium/heavy-duty vehicles + parts; 10% on buses | B8: 0.25 | C8: 0.25 | D8: 0.25 | E8: Trump Proclamation Oct 17, 2025, effective Nov 1, 2025. URL: https://www.whitehouse.gov/presidential-actions/2025/10/adjusting-imports-of-medium-and-heavy-duty-vehicles/
A10: 2. IMPORT SHARES & PARTS EXPOSURE BY VEHICLE CLASS
A11: Vehicle class | B11: Imported share of vehicles sold | C11: Imported parts share of US-assembled vehicles | D11: Effective non-USMCA exposure | E11: Source
A12: LDV passenger (cars/SUVs/crossovers) | B12: 0.5 | C12: 0.6 | D12: 0.4 | E12: CFR: 'US imports nearly half of all new cars sold'; 'close to 60% of parts used in American auto plants are imported'
A13: LDV freight (light trucks/pickups) | B13: 0.2 | C13: 0.4 | D13: 0.3 | E13: Pickups are 80%+ domestic (F-150, Silverado, Ram all US-assembled)
A14: HDV passenger (transit buses, motor coaches) | B14: 0.05 | C14: 0.3 | D14: 0.2 | E14: CFR: 'Just 5% of buses are imported'
A15: HDV freight (mid-heavy trucks) | B15: 0.3 | C15: 0.45 | D15: 0.3 | E15: CFR: 'US imports around 25% of mid-sized trucks and 40% of heavy trucks'
A17: 3. CALCULATED MULTIPLIER
A18: For each class: multiplier = tariff_rate × (imported_vehicle_share + imported_parts_share × (1-imported_vehicle_share)) × effective_exposure × pass_through × decline_factor
B19: 2025 | C19: 2026 | D19: 2027 | E19: 2028 | F19: 2029 | G19: 2030 | H19: 2035 | I19: 2040 | J19: 2050
A20: Decline factor (S232 autos persistent; modest decline as USMCA reshoring progresses) | B20: 0.7 | C20: 1 | D20: 0.95 | E20: 0.85 | F20: 0.75 | G20: 0.65 | H20: 0.4 | I20: 0.3 | J20: 0.3
A21: VNB LDV-psgr multiplier (→ BTCM-VNB-LDVs-psgr, uniform across techs) | B21: =B20*B$6*($B$12+(1-$B$12)*$C$12)*$D$12*0.85 -> 0.0476 | C21: =C20*C$6*($B$12+(1-$B$12)*$C$12)*$D$12*0.85 -> 0.068 | D21: =D20*D$6*($B$12+(1-$B$12)*$C$12)*$D$12*0.85 -> 0.0646 | E21: =E20*D$6*($B$12+(1-$B$12)*$C$12)*$D$12*0.85 -> 0.0578 | F21: =F20*D$6*($B$12+(1-$B$12)*$C$12)*$D$12*0.85 -> 0.051 | G21: =G20*D$6*($B$12+(1-$B$12)*$C$12)*$D$12*0.85 -> 0.0442 | H21: =H20*D$6*($B$12+(1-$B$12)*$C$12)*$D$12*0.85 -> 0.0272 | I21: =I20*D$6*($B$12+(1-$B$12)*$C$12)*$D$12*0.85 -> 0.0204 | J21: =J20*D$6*($B$12+(1-$B$12)*$C$12)*$D$12*0.85 -> 0.0204
A22: VNB LDV-frgt multiplier (→ BTCM-VNB-LDVs-frgt) | B22: =B20*B$6*($B$13+(1-$B$13)*$C$13)*$D$13*0.85 -> 0.023205 | C22: =C20*C$6*($B$13+(1-$B$13)*$C$13)*$D$13*0.85 -> 0.03315 | D22: =D20*D$6*($B$13+(1-$B$13)*$C$13)*$D$13*0.85 -> 0.0314925 | E22: =E20*D$6*($B$13+(1-$B$13)*$C$13)*$D$13*0.85 -> 0.0281775 | F22: =F20*D$6*($B$13+(1-$B$13)*$C$13)*$D$13*0.85 -> 0.0248625 | G22: =G20*D$6*($B$13+(1-$B$13)*$C$13)*$D$13*0.85 -> 0.0215475 | H22: =H20*D$6*($B$13+(1-$B$13)*$C$13)*$D$13*0.85 -> 0.01326 | I22: =I20*D$6*($B$13+(1-$B$13)*$C$13)*$D$13*0.85 -> 0.009945 | J22: =J20*D$6*($B$13+(1-$B$13)*$C$13)*$D$13*0.85 -> 0.009945
A23: VNB HDV-psgr multiplier (→ BTCM-VNB-HDVs-psgr) — buses, S232 10% | B23: =B20*B$8*($B$14+(1-$B$14)*$C$14)*$D$14*0.85 -> 0.00996625 | C23: =C20*C$8*($B$14+(1-$B$14)*$C$14)*$D$14*0.85 -> 0.0142375 | D23: =D20*D$8*($B$14+(1-$B$14)*$C$14)*$D$14*0.85 -> 0.013525625 | E23: =E20*D$8*($B$14+(1-$B$14)*$C$14)*$D$14*0.85 -> 0.012101875 | F23: =F20*D$8*($B$14+(1-$B$14)*$C$14)*$D$14*0.85 -> 0.010678125 | G23: =G20*D$8*($B$14+(1-$B$14)*$C$14)*$D$14*0.85 -> 0.009254375 | H23: =H20*D$8*($B$14+(1-$B$14)*$C$14)*$D$14*0.85 -> 0.005695 | I23: =I20*D$8*($B$14+(1-$B$14)*$C$14)*$D$14*0.85 -> 0.00427125 | J23: =J20*D$8*($B$14+(1-$B$14)*$C$14)*$D$14*0.85 -> 0.00427125
A24: VNB HDV-frgt multiplier (→ BTCM-VNB-HDVs-frgt) — mid/heavy trucks, S232 25% | B24: =B20*B$8*($B$15+(1-$B$15)*$C$15)*$D$15*0.85 -> 0.027444375 | C24: =C20*C$8*($B$15+(1-$B$15)*$C$15)*$D$15*0.85 -> 0.03920625 | D24: =D20*D$8*($B$15+(1-$B$15)*$C$15)*$D$15*0.85 -> 0.037245937 | E24: =E20*D$8*($B$15+(1-$B$15)*$C$15)*$D$15*0.85 -> 0.033325312 | F24: =F20*D$8*($B$15+(1-$B$15)*$C$15)*$D$15*0.85 -> 0.029404687 | G24: =G20*D$8*($B$15+(1-$B$15)*$C$15)*$D$15*0.85 -> 0.025484062 | H24: =H20*D$8*($B$15+(1-$B$15)*$C$15)*$D$15*0.85 -> 0.0156825 | I24: =I20*D$8*($B$15+(1-$B$15)*$C$15)*$D$15*0.85 -> 0.011761875 | J24: =J20*D$8*($B$15+(1-$B$15)*$C$15)*$D$15*0.85 -> 0.011761875

Sheet BTCM-EC
A1: Unit: Dmnl | B1: 2025 | C1: 2026 | D1: 2027 | E1: 2028 | F1: 2029 | G1: 2030 | H1: 2031 | I1: 2032 | J1: 2033 | K1: 2034 | L1: 2035 | M1: 2036 | N1: 2037 | O1: 2038 | P1: 2039 | Q1: 2040 | R1: 2041 | S1: 2042 | T1: 2043 | U1: 2044 | V1: 2045 | W1: 2046 | X1: 2047 | Y1: 2048 | Z1: 2049 | AA1: 2050
A2: hard coal | B2: 0 | C2: 0 | D2: 0 | E2: 0 | F2: 0 | G2: 0 | H2: 0 | I2: 0 | J2: 0 | K2: 0 | L2: 0 | M2: 0 | N2: 0 | O2: 0 | P2: 0 | Q2: 0 | R2: 0 | S2: 0 | T2: 0 | U2: 0 | V2: 0 | W2: 0 | X2: 0 | Y2: 0 | Z2: 0 | AA2: 0
A3: natural gas steam turbine | B3: 0 | C3: 0 | D3: 0 | E3: 0 | F3: 0 | G3: 0 | H3: 0 | I3: 0 | J3: 0 | K3: 0 | L3: 0 | M3: 0 | N3: 0 | O3: 0 | P3: 0 | Q3: 0 | R3: 0 | S3: 0 | T3: 0 | U3: 0 | V3: 0 | W3: 0 | X3: 0 | Y3: 0 | Z3: 0 | AA3: 0
A4: natural gas combined cycle | B4: 0 | C4: 0 | D4: 0 | E4: 0 | F4: 0 | G4: 0 | H4: 0 | I4: 0 | J4: 0 | K4: 0 | L4: 0 | M4: 0 | N4: 0 | O4: 0 | P4: 0 | Q4: 0 | R4: 0 | S4: 0 | T4: 0 | U4: 0 | V4: 0 | W4: 0 | X4: 0 | Y4: 0 | Z4: 0 | AA4: 0
A5: nuclear | B5: 0 | C5: 0 | D5: 0 | E5: 0 | F5: 0 | G5: 0 | H5: 0 | I5: 0 | J5: 0 | K5: 0 | L5: 0 | M5: 0 | N5: 0 | O5: 0 | P5: 0 | Q5: 0 | R5: 0 | S5: 0 | T5: 0 | U5: 0 | V5: 0 | W5: 0 | X5: 0 | Y5: 0 | Z5: 0 | AA5: 0
A6: hydro | B6: 0 | C6: 0 | D6: 0 | E6: 0 | F6: 0 | G6: 0 | H6: 0 | I6: 0 | J6: 0 | K6: 0 | L6: 0 | M6: 0 | N6: 0 | O6: 0 | P6: 0 | Q6: 0 | R6: 0 | S6: 0 | T6: 0 | U6: 0 | V6: 0 | W6: 0 | X6: 0 | Y6: 0 | Z6: 0 | AA6: 0
A7: onshore wind | B7: {=_xlfn.LET(_xlpm.t,B$1,_xlpm.yrs,'Calc-Wind-Onshore'!$B$19:$J$19,_xlpm.vals,'Calc-Wind-Onshore'!$B$21:$J$21,_xlpm.lo,MATCH(_xlpm.t,_xlpm.yrs,1),_xlpm.hi,MIN(_xlpm.lo+1,COLUMNS(_xlpm.yrs)),_xlpm.loYr,INDEX(_xlpm.yrs,1,_xlpm.lo),_xlpm.hiYr,INDEX(_xlpm.yrs,1,_xlpm.hi),_xlpm.loV,INDEX(_xlpm.vals,1,_xlpm.lo),_xlpm.hiV,INDEX(_xlpm.vals,1,_xlpm.hi),IF(_xlpm.loYr=_xlpm.hiYr,_xlpm.loV,_xlpm.loV+(_xlpm.t-_xlpm.loYr)*(_xlpm.hiV-_xlpm.loV)/(_xlpm.hiYr-_xlpm.loYr)))} -> 0.1061375 | C7: {=_xlfn.LET(_xlpm.t,C$1,_xlpm.yrs,'Calc-Wind-Onshore'!$B$19:$J$19,_xlpm.vals,'Calc-Wind-Onshore'!$B$21:$J$21,_xlpm.lo,MATCH(_xlpm.t,_xlpm.yrs,1),_xlpm.hi,MIN(_xlpm.lo+1,COLUMNS(_xlpm.yrs)),_xlpm.loYr,INDEX(_xlpm.yrs,1,_xlpm.lo),_xlpm.hiYr,INDEX(_xlpm.yrs,1,_xlpm.hi),_xlpm.loV,INDEX(_xlpm.vals,1,_xlpm.lo),_xlpm.hiV,INDEX(_xlpm.vals,1,_xlpm.hi),IF(_xlpm.loYr=_xlpm.hiYr,_xlpm.loV,_xlpm.loV+(_xlpm.t-_xlpm.loYr)*(_xlpm.hiV-_xlpm.loV)/(_xlpm.hiYr-_xlpm.loYr)))} -> 0.151625 | D7: {=_xlfn.LET(_xlpm.t,D$1,_xlpm.yrs,'Calc-Wind-Onshore'!$B$19:$J$19,_xlpm.vals,'Calc-Wind-Onshore'!$B$21:$J$21,_xlpm.lo,MATCH(_xlpm.t,_xlpm.yrs,1),_xlpm.hi,MIN(_xlpm.lo+1,COLUMNS(_xlpm.yrs)),_xlpm.loYr,INDEX(_xlpm.yrs,1,_xlpm.lo),_xlpm.hiYr,INDEX(_xlpm.yrs,1,_xlpm.hi),_xlpm.loV,INDEX(_xlpm.vals,1,_xlpm.lo),_xlpm.hiV,INDEX(_xlpm.vals,1,_xlpm.hi),IF(_xlpm.loYr=_xlpm.hiYr,_xlpm.loV,_xlpm.loV+(_xlpm.t-_xlpm.loYr)*(_xlpm.hiV-_xlpm.loV)/(_xlpm.hiYr-_xlpm.loYr)))} -> 0.14404375 | E7: {=_xlfn.LET(_xlpm.t,E$1,_xlpm.yrs,'Calc-Wind-Onshore'!$B$19:$J$19,_xlpm.vals,'Calc-Wind-Onshore'!$B$21:$J$21,_xlpm.lo,MATCH(_xlpm.t,_xlpm.yrs,1),_xlpm.hi,MIN(_xlpm.lo+1,COLUMNS(_xlpm.yrs)),_xlpm.loYr,INDEX(_xlpm.yrs,1,_xlpm.lo),_xlpm.hiYr,INDEX(_xlpm.yrs,1,_xlpm.hi),_xlpm.loV,INDEX(_xlpm.vals,1,_xlpm.lo),_xlpm.hiV,INDEX(_xlpm.vals,1,_xlpm.hi),IF(_xlpm.loYr=_xlpm.hiYr,_xlpm.loV,_xlpm.loV+(_xlpm.t-_xlpm.loYr)*(_xlpm.hiV-_xlpm.loV)/(_xlpm.hiYr-_xlpm.loYr)))} -> 0.12888125 | F7: {=_xlfn.LET(_xlpm.t,F$1,_xlpm.yrs,'Calc-Wind-Onshore'!$B$19:$J$19,_xlpm.vals,'Calc-Wind-Onshore'!$B$21:$J$21,_xlpm.lo,MATCH(_xlpm.t,_xlpm.yrs,1),_xlpm.hi,MIN(_xlpm.lo+1,COLUMNS(_xlpm.yrs)),_xlpm.loYr,INDEX(_xlpm.yrs,1,_xlpm.lo),_xlpm.hiYr,INDEX(_xlpm.yrs,1,_xlpm.hi),_xlpm.loV,INDEX(_xlpm.vals,1,_xlpm.lo),_xlpm.hiV,INDEX(_xlpm.vals,1,_xlpm.hi),IF(_xlpm.loYr=_xlpm.hiYr,_xlpm.loV,_xlpm.loV+(_xlpm.t-_xlpm.loYr)*(_xlpm.hiV-_xlpm.loV)/(_xlpm.hiYr-_xlpm.loYr)))} -> 0.1061375 | G7: {=_xlfn.LET(_xlpm.t,G$1,_xlpm.yrs,'Calc-Wind-Onshore'!$B$19:$J$19,_xlpm.vals,'Calc-Wind-Onshore'!$B$21:$J$21,_xlpm.lo,MATCH(_xlpm.t,_xlpm.yrs,1),_xlpm.hi,MIN(_xlpm.lo+1,COLUMNS(_xlpm.yrs)),_xlpm.loYr,INDEX(_xlpm.yrs,1,_xlpm.lo),_xlpm.hiYr,INDEX(_xlpm.yrs,1,_xlpm.hi),_xlpm.loV,INDEX(_xlpm.vals,1,_xlpm.lo),_xlpm.hiV,INDEX(_xlpm.vals,1,_xlpm.hi),IF(_xlpm.loYr=_xlpm.hiYr,_xlpm.loV,_xlpm.loV+(_xlpm.t-_xlpm.loYr)*(_xlpm.hiV-_xlpm.loV)/(_xlpm.hiYr-_xlpm.loYr)))} -> 0.08339375 | H7: {=_xlfn.LET(_xlpm.t,H$1,_xlpm.yrs,'Calc-Wind-Onshore'!$B$19:$J$19,_xlpm.vals,'Calc-Wind-Onshore'!$B$21:$J$21,_xlpm.lo,MATCH(_xlpm.t,_xlpm.yrs,1),_xlpm.hi,MIN(_xlpm.lo+1,COLUMNS(_xlpm.yrs)),_xlpm.loYr,INDEX(_xlpm.yrs,1,_xlpm.lo),_xlpm.hiYr,INDEX(_xlpm.yrs,1,_xlpm.hi),_xlpm.loV,INDEX(_xlpm.vals,1,_xlpm.lo),_xlpm.hiV,INDEX(_xlpm.vals,1,_xlpm.hi),IF(_xlpm.loYr=_xlpm.hiYr,_xlpm.loV,_xlpm.loV+(_xlpm.t-_xlpm.loYr)*(_xlpm.hiV-_xlpm.loV)/(_xlpm.hiYr-_xlpm.loYr)))} -> 0.078845 | I7: {=_xlfn.LET(_xlpm.t,I$1,_xlpm.yrs,'Calc-Wind-Onshore'!$B$19:$J$19,_xlpm.vals,'Calc-Wind-Onshore'!$B$21:$J$21,_xlpm.lo,MATCH(_xlpm.t,_xlpm.yrs,1),_xlpm.hi,MIN(_xlpm.lo+1,COLUMNS(_xlpm.yrs)),_xlpm.loYr,INDEX(_xlpm.yrs,1,_xlpm.lo),_xlpm.hiYr,INDEX(_xlpm.yrs,1,_xlpm.hi),_xlpm.loV,INDEX(_xlpm.vals,1,_xlpm.lo),_xlpm.hiV,INDEX(_xlpm.vals,1,_xlpm.hi),IF(_xlpm.loYr=_xlpm.hiYr,_xlpm.loV,_xlpm.loV+(_xlpm.t-_xlpm.loYr)*(_xlpm.hiV-_xlpm.loV)/(_xlpm.hiYr-_xlpm.loYr)))} -> 0.07429625 | ... AA7: {=_xlfn.LET(_xlpm.t,AA$1,_xlpm.yrs,'Calc-Wind-Onshore'!$B$19:$J$19,_xlpm.vals,'Calc-Wind-Onshore'!$B$21:$J$21,_xlpm.lo,MATCH(_xlpm.t,_xlpm.yrs,1),_xlpm.hi,MIN(_xlpm.lo+1,COLUMNS(_xlpm.yrs)),_xlpm.loYr,INDEX(_xlpm.yrs,1,_xlpm.lo),_xlpm.hiYr,INDEX(_xlpm.yrs,1,_xlpm.hi),_xlpm.loV,INDEX(_xlpm.vals,1,_xlpm.lo),_xlpm.hiV,INDEX(_xlpm.vals,1,_xlpm.hi),IF(_xlpm.loYr=_xlpm.hiYr,_xlpm.loV,_xlpm.loV+(_xlpm.t-_xlpm.loYr)*(_xlpm.hiV-_xlpm.loV)/(_xlpm.hiYr-_xlpm.loYr)))} -> 0.0454875
A8: solar PV | B8: {=_xlfn.LET(_xlpm.t,B$1,_xlpm.yrs,'Calc-Solar-PV'!$B$26:$J$26,_xlpm.vals,'Calc-Solar-PV'!$B$31:$J$31,_xlpm.lo,MATCH(_xlpm.t,_xlpm.yrs,1),_xlpm.hi,MIN(_xlpm.lo+1,COLUMNS(_xlpm.yrs)),_xlpm.loYr,INDEX(_xlpm.yrs,1,_xlpm.lo),_xlpm.hiYr,INDEX(_xlpm.yrs,1,_xlpm.hi),_xlpm.loV,INDEX(_xlpm.vals,1,_xlpm.lo),_xlpm.hiV,INDEX(_xlpm.vals,1,_xlpm.hi),IF(_xlpm.loYr=_xlpm.hiYr,_xlpm.loV,_xlpm.loV+(_xlpm.t-_xlpm.loYr)*(_xlpm.hiV-_xlpm.loV)/(_xlpm.hiYr-_xlpm.loYr)))} -> 0.106505 | C8: {=_xlfn.LET(_xlpm.t,C$1,_xlpm.yrs,'Calc-Solar-PV'!$B$26:$J$26,_xlpm.vals,'Calc-Solar-PV'!$B$31:$J$31,_xlpm.lo,MATCH(_xlpm.t,_xlpm.yrs,1),_xlpm.hi,MIN(_xlpm.lo+1,COLUMNS(_xlpm.yrs)),_xlpm.loYr,INDEX(_xlpm.yrs,1,_xlpm.lo),_xlpm.hiYr,INDEX(_xlpm.yrs,1,_xlpm.hi),_xlpm.loV,INDEX(_xlpm.vals,1,_xlpm.lo),_xlpm.hiV,INDEX(_xlpm.vals,1,_xlpm.hi),IF(_xlpm.loYr=_xlpm.hiYr,_xlpm.loV,_xlpm.loV+(_xlpm.t-_xlpm.loYr)*(_xlpm.hiV-_xlpm.loV)/(_xlpm.hiYr-_xlpm.loYr)))} -> 0.1315 | D8: {=_xlfn.LET(_xlpm.t,D$1,_xlpm.yrs,'Calc-Solar-PV'!$B$26:$J$26,_xlpm.vals,'Calc-Solar-PV'!$B$31:$J$31,_xlpm.lo,MATCH(_xlpm.t,_xlpm.yrs,1),_xlpm.hi,MIN(_xlpm.lo+1,COLUMNS(_xlpm.yrs)),_xlpm.loYr,INDEX(_xlpm.yrs,1,_xlpm.lo),_xlpm.hiYr,INDEX(_xlpm.yrs,1,_xlpm.hi),_xlpm.loV,INDEX(_xlpm.vals,1,_xlpm.lo),_xlpm.hiV,INDEX(_xlpm.vals,1,_xlpm.hi),IF(_xlpm.loYr=_xlpm.hiYr,_xlpm.loV,_xlpm.loV+(_xlpm.t-_xlpm.loYr)*(_xlpm.hiV-_xlpm.loV)/(_xlpm.hiYr-_xlpm.loYr)))} -> 0.113525 | E8: {=_xlfn.LET(_xlpm.t,E$1,_xlpm.yrs,'Calc-Solar-PV'!$B$26:$J$26,_xlpm.vals,'Calc-Solar-PV'!$B$31:$J$31,_xlpm.lo,MATCH(_xlpm.t,_xlpm.yrs,1),_xlpm.hi,MIN(_xlpm.lo+1,COLUMNS(_xlpm.yrs)),_xlpm.loYr,INDEX(_xlpm.yrs,1,_xlpm.lo),_xlpm.hiYr,INDEX(_xlpm.yrs,1,_xlpm.hi),_xlpm.loV,INDEX(_xlpm.vals,1,_xlpm.lo),_xlpm.hiV,INDEX(_xlpm.vals,1,_xlpm.hi),IF(_xlpm.loYr=_xlpm.hiYr,_xlpm.loV,_xlpm.loV+(_xlpm.t-_xlpm.loYr)*(_xlpm.hiV-_xlpm.loV)/(_xlpm.hiYr-_xlpm.loYr)))} -> 0.101575 | F8: {=_xlfn.LET(_xlpm.t,F$1,_xlpm.yrs,'Calc-Solar-PV'!$B$26:$J$26,_xlpm.vals,'Calc-Solar-PV'!$B$31:$J$31,_xlpm.lo,MATCH(_xlpm.t,_xlpm.yrs,1),_xlpm.hi,MIN(_xlpm.lo+1,COLUMNS(_xlpm.yrs)),_xlpm.loYr,INDEX(_xlpm.yrs,1,_xlpm.lo),_xlpm.hiYr,INDEX(_xlpm.yrs,1,_xlpm.hi),_xlpm.loV,INDEX(_xlpm.vals,1,_xlpm.lo),_xlpm.hiV,INDEX(_xlpm.vals,1,_xlpm.hi),IF(_xlpm.loYr=_xlpm.hiYr,_xlpm.loV,_xlpm.loV+(_xlpm.t-_xlpm.loYr)*(_xlpm.hiV-_xlpm.loV)/(_xlpm.hiYr-_xlpm.loYr)))} -> 0.08365 | G8: {=_xlfn.LET(_xlpm.t,G$1,_xlpm.yrs,'Calc-Solar-PV'!$B$26:$J$26,_xlpm.vals,'Calc-Solar-PV'!$B$31:$J$31,_xlpm.lo,MATCH(_xlpm.t,_xlpm.yrs,1),_xlpm.hi,MIN(_xlpm.lo+1,COLUMNS(_xlpm.yrs)),_xlpm.loYr,INDEX(_xlpm.yrs,1,_xlpm.lo),_xlpm.hiYr,INDEX(_xlpm.yrs,1,_xlpm.hi),_xlpm.loV,INDEX(_xlpm.vals,1,_xlpm.lo),_xlpm.hiV,INDEX(_xlpm.vals,1,_xlpm.hi),IF(_xlpm.loYr=_xlpm.hiYr,_xlpm.loV,_xlpm.loV+(_xlpm.t-_xlpm.loYr)*(_xlpm.hiV-_xlpm.loV)/(_xlpm.hiYr-_xlpm.loYr)))} -> 0.065725 | H8: {=_xlfn.LET(_xlpm.t,H$1,_xlpm.yrs,'Calc-Solar-PV'!$B$26:$J$26,_xlpm.vals,'Calc-Solar-PV'!$B$31:$J$31,_xlpm.lo,MATCH(_xlpm.t,_xlpm.yrs,1),_xlpm.hi,MIN(_xlpm.lo+1,COLUMNS(_xlpm.yrs)),_xlpm.loYr,INDEX(_xlpm.yrs,1,_xlpm.lo),_xlpm.hiYr,INDEX(_xlpm.yrs,1,_xlpm.hi),_xlpm.loV,INDEX(_xlpm.vals,1,_xlpm.lo),_xlpm.hiV,INDEX(_xlpm.vals,1,_xlpm.hi),IF(_xlpm.loYr=_xlpm.hiYr,_xlpm.loV,_xlpm.loV+(_xlpm.t-_xlpm.loYr)*(_xlpm.hiV-_xlpm.loV)/(_xlpm.hiYr-_xlpm.loYr)))} -> 0.06214 | I8: {=_xlfn.LET(_xlpm.t,I$1,_xlpm.yrs,'Calc-Solar-PV'!$B$26:$J$26,_xlpm.vals,'Calc-Solar-PV'!$B$31:$J$31,_xlpm.lo,MATCH(_xlpm.t,_xlpm.yrs,1),_xlpm.hi,MIN(_xlpm.lo+1,COLUMNS(_xlpm.yrs)),_xlpm.loYr,INDEX(_xlpm.yrs,1,_xlpm.lo),_xlpm.hiYr,INDEX(_xlpm.yrs,1,_xlpm.hi),_xlpm.loV,INDEX(_xlpm.vals,1,_xlpm.lo),_xlpm.hiV,INDEX(_xlpm.vals,1,_xlpm.hi),IF(_xlpm.loYr=_xlpm.hiYr,_xlpm.loV,_xlpm.loV+(_xlpm.t-_xlpm.loYr)*(_xlpm.hiV-_xlpm.loV)/(_xlpm.hiYr-_xlpm.loYr)))} -> 0.058555 | ... AA8: {=_xlfn.LET(_xlpm.t,AA$1,_xlpm.yrs,'Calc-Solar-PV'!$B$26:$J$26,_xlpm.vals,'Calc-Solar-PV'!$B$31:$J$31,_xlpm.lo,MATCH(_xlpm.t,_xlpm.yrs,1),_xlpm.hi,MIN(_xlpm.lo+1,COLUMNS(_xlpm.yrs)),_xlpm.loYr,INDEX(_xlpm.yrs,1,_xlpm.lo),_xlpm.hiYr,INDEX(_xlpm.yrs,1,_xlpm.hi),_xlpm.loV,INDEX(_xlpm.vals,1,_xlpm.lo),_xlpm.hiV,INDEX(_xlpm.vals,1,_xlpm.hi),IF(_xlpm.loYr=_xlpm.hiYr,_xlpm.loV,_xlpm.loV+(_xlpm.t-_xlpm.loYr)*(_xlpm.hiV-_xlpm.loV)/(_xlpm.hiYr-_xlpm.loYr)))} -> 0.03585
A9: solar thermal | B9: {=_xlfn.LET(_xlpm.t,B$1,_xlpm.yrs,'Calc-Solar-Thermal'!$B$20:$J$20,_xlpm.vals,'Calc-Solar-Thermal'!$B$22:$J$22,_xlpm.lo,MATCH(_xlpm.t,_xlpm.yrs,1),_xlpm.hi,MIN(_xlpm.lo+1,COLUMNS(_xlpm.yrs)),_xlpm.loYr,INDEX(_xlpm.yrs,1,_xlpm.lo),_xlpm.hiYr,INDEX(_xlpm.yrs,1,_xlpm.hi),_xlpm.loV,INDEX(_xlpm.vals,1,_xlpm.lo),_xlpm.hiV,INDEX(_xlpm.vals,1,_xlpm.hi),IF(_xlpm.loYr=_xlpm.hiYr,_xlpm.loV,_xlpm.loV+(_xlpm.t-_xlpm.loYr)*(_xlpm.hiV-_xlpm.loV)/(_xlpm.hiYr-_xlpm.loYr)))} -> 0.1754375 | C9: {=_xlfn.LET(_xlpm.t,C$1,_xlpm.yrs,'Calc-Solar-Thermal'!$B$20:$J$20,_xlpm.vals,'Calc-Solar-Thermal'!$B$22:$J$22,_xlpm.lo,MATCH(_xlpm.t,_xlpm.yrs,1),_xlpm.hi,MIN(_xlpm.lo+1,COLUMNS(_xlpm.yrs)),_xlpm.loYr,INDEX(_xlpm.yrs,1,_xlpm.lo),_xlpm.hiYr,INDEX(_xlpm.yrs,1,_xlpm.hi),_xlpm.loV,INDEX(_xlpm.vals,1,_xlpm.lo),_xlpm.hiV,INDEX(_xlpm.vals,1,_xlpm.hi),IF(_xlpm.loYr=_xlpm.hiYr,_xlpm.loV,_xlpm.loV+(_xlpm.t-_xlpm.loYr)*(_xlpm.hiV-_xlpm.loV)/(_xlpm.hiYr-_xlpm.loYr)))} -> 0.250625 | D9: {=_xlfn.LET(_xlpm.t,D$1,_xlpm.yrs,'Calc-Solar-Thermal'!$B$20:$J$20,_xlpm.vals,'Calc-Solar-Thermal'!$B$22:$J$22,_xlpm.lo,MATCH(_xlpm.t,_xlpm.yrs,1),_xlpm.hi,MIN(_xlpm.lo+1,COLUMNS(_xlpm.yrs)),_xlpm.loYr,INDEX(_xlpm.yrs,1,_xlpm.lo),_xlpm.hiYr,INDEX(_xlpm.yrs,1,_xlpm.hi),_xlpm.loV,INDEX(_xlpm.vals,1,_xlpm.lo),_xlpm.hiV,INDEX(_xlpm.vals,1,_xlpm.hi),IF(_xlpm.loYr=_xlpm.hiYr,_xlpm.loV,_xlpm.loV+(_xlpm.t-_xlpm.loYr)*(_xlpm.hiV-_xlpm.loV)/(_xlpm.hiYr-_xlpm.loYr)))} -> 0.23809375 | E9: {=_xlfn.LET(_xlpm.t,E$1,_xlpm.yrs,'Calc-Solar-Thermal'!$B$20:$J$20,_xlpm.vals,'Calc-Solar-Thermal'!$B$22:$J$22,_xlpm.lo,MATCH(_xlpm.t,_xlpm.yrs,1),_xlpm.hi,MIN(_xlpm.lo+1,COLUMNS(_xlpm.yrs)),_xlpm.loYr,INDEX(_xlpm.yrs,1,_xlpm.lo),_xlpm.hiYr,INDEX(_xlpm.yrs,1,_xlpm.hi),_xlpm.loV,INDEX(_xlpm.vals,1,_xlpm.lo),_xlpm.hiV,INDEX(_xlpm.vals,1,_xlpm.hi),IF(_xlpm.loYr=_xlpm.hiYr,_xlpm.loV,_xlpm.loV+(_xlpm.t-_xlpm.loYr)*(_xlpm.hiV-_xlpm.loV)/(_xlpm.hiYr-_xlpm.loYr)))} -> 0.21303125 | F9: {=_xlfn.LET(_xlpm.t,F$1,_xlpm.yrs,'Calc-Solar-Thermal'!$B$20:$J$20,_xlpm.vals,'Calc-Solar-Thermal'!$B$22:$J$22,_xlpm.lo,MATCH(_xlpm.t,_xlpm.yrs,1),_xlpm.hi,MIN(_xlpm.lo+1,COLUMNS(_xlpm.yrs)),_xlpm.loYr,INDEX(_xlpm.yrs,1,_xlpm.lo),_xlpm.hiYr,INDEX(_xlpm.yrs,1,_xlpm.hi),_xlpm.loV,INDEX(_xlpm.vals,1,_xlpm.lo),_xlpm.hiV,INDEX(_xlpm.vals,1,_xlpm.hi),IF(_xlpm.loYr=_xlpm.hiYr,_xlpm.loV,_xlpm.loV+(_xlpm.t-_xlpm.loYr)*(_xlpm.hiV-_xlpm.loV)/(_xlpm.hiYr-_xlpm.loYr)))} -> 0.1754375 | G9: {=_xlfn.LET(_xlpm.t,G$1,_xlpm.yrs,'Calc-Solar-Thermal'!$B$20:$J$20,_xlpm.vals,'Calc-Solar-Thermal'!$B$22:$J$22,_xlpm.lo,MATCH(_xlpm.t,_xlpm.yrs,1),_xlpm.hi,MIN(_xlpm.lo+1,COLUMNS(_xlpm.yrs)),_xlpm.loYr,INDEX(_xlpm.yrs,1,_xlpm.lo),_xlpm.hiYr,INDEX(_xlpm.yrs,1,_xlpm.hi),_xlpm.loV,INDEX(_xlpm.vals,1,_xlpm.lo),_xlpm.hiV,INDEX(_xlpm.vals,1,_xlpm.hi),IF(_xlpm.loYr=_xlpm.hiYr,_xlpm.loV,_xlpm.loV+(_xlpm.t-_xlpm.loYr)*(_xlpm.hiV-_xlpm.loV)/(_xlpm.hiYr-_xlpm.loYr)))} -> 0.13784375 | H9: {=_xlfn.LET(_xlpm.t,H$1,_xlpm.yrs,'Calc-Solar-Thermal'!$B$20:$J$20,_xlpm.vals,'Calc-Solar-Thermal'!$B$22:$J$22,_xlpm.lo,MATCH(_xlpm.t,_xlpm.yrs,1),_xlpm.hi,MIN(_xlpm.lo+1,COLUMNS(_xlpm.yrs)),_xlpm.loYr,INDEX(_xlpm.yrs,1,_xlpm.lo),_xlpm.hiYr,INDEX(_xlpm.yrs,1,_xlpm.hi),_xlpm.loV,INDEX(_xlpm.vals,1,_xlpm.lo),_xlpm.hiV,INDEX(_xlpm.vals,1,_xlpm.hi),IF(_xlpm.loYr=_xlpm.hiYr,_xlpm.loV,_xlpm.loV+(_xlpm.t-_xlpm.loYr)*(_xlpm.hiV-_xlpm.loV)/(_xlpm.hiYr-_xlpm.loYr)))} -> 0.130325 | I9: {=_xlfn.LET(_xlpm.t,I$1,_xlpm.yrs,'Calc-Solar-Thermal'!$B$20:$J$20,_xlpm.vals,'Calc-Solar-Thermal'!$B$22:$J$22,_xlpm.lo,MATCH(_xlpm.t,_xlpm.yrs,1),_xlpm.hi,MIN(_xlpm.lo+1,COLUMNS(_xlpm.yrs)),_xlpm.loYr,INDEX(_xlpm.yrs,1,_xlpm.lo),_xlpm.hiYr,INDEX(_xlpm.yrs,1,_xlpm.hi),_xlpm.loV,INDEX(_xlpm.vals,1,_xlpm.lo),_xlpm.hiV,INDEX(_xlpm.vals,1,_xlpm.hi),IF(_xlpm.loYr=_xlpm.hiYr,_xlpm.loV,_xlpm.loV+(_xlpm.t-_xlpm.loYr)*(_xlpm.hiV-_xlpm.loV)/(_xlpm.hiYr-_xlpm.loYr)))} -> 0.12280625 | ... AA9: {=_xlfn.LET(_xlpm.t,AA$1,_xlpm.yrs,'Calc-Solar-Thermal'!$B$20:$J$20,_xlpm.vals,'Calc-Solar-Thermal'!$B$22:$J$22,_xlpm.lo,MATCH(_xlpm.t,_xlpm.yrs,1),_xlpm.hi,MIN(_xlpm.lo+1,COLUMNS(_xlpm.yrs)),_xlpm.loYr,INDEX(_xlpm.yrs,1,_xlpm.lo),_xlpm.hiYr,INDEX(_xlpm.yrs,1,_xlpm.hi),_xlpm.loV,INDEX(_xlpm.vals,1,_xlpm.lo),_xlpm.hiV,INDEX(_xlpm.vals,1,_xlpm.hi),IF(_xlpm.loYr=_xlpm.hiYr,_xlpm.loV,_xlpm.loV+(_xlpm.t-_xlpm.loYr)*(_xlpm.hiV-_xlpm.loV)/(_xlpm.hiYr-_xlpm.loYr)))} -> 0.0751875
A10: biomass | B10: 0 | C10: 0 | D10: 0 | E10: 0 | F10: 0 | G10: 0 | H10: 0 | I10: 0 | J10: 0 | K10: 0 | L10: 0 | M10: 0 | N10: 0 | O10: 0 | P10: 0 | Q10: 0 | R10: 0 | S10: 0 | T10: 0 | U10: 0 | V10: 0 | W10: 0 | X10: 0 | Y10: 0 | Z10: 0 | AA10: 0
A11: geothermal | B11: 0 | C11: 0 | D11: 0 | E11: 0 | F11: 0 | G11: 0 | H11: 0 | I11: 0 | J11: 0 | K11: 0 | L11: 0 | M11: 0 | N11: 0 | O11: 0 | P11: 0 | Q11: 0 | R11: 0 | S11: 0 | T11: 0 | U11: 0 | V11: 0 | W11: 0 | X11: 0 | Y11: 0 | Z11: 0 | AA11: 0
A12: petroleum | B12: 0 | C12: 0 | D12: 0 | E12: 0 | F12: 0 | G12: 0 | H12: 0 | I12: 0 | J12: 0 | K12: 0 | L12: 0 | M12: 0 | N12: 0 | O12: 0 | P12: 0 | Q12: 0 | R12: 0 | S12: 0 | T12: 0 | U12: 0 | V12: 0 | W12: 0 | X12: 0 | Y12: 0 | Z12: 0 | AA12: 0
A13: natural gas peaker | B13: 0 | C13: 0 | D13: 0 | E13: 0 | F13: 0 | G13: 0 | H13: 0 | I13: 0 | J13: 0 | K13: 0 | L13: 0 | M13: 0 | N13: 0 | O13: 0 | P13: 0 | Q13: 0 | R13: 0 | S13: 0 | T13: 0 | U13: 0 | V13: 0 | W13: 0 | X13: 0 | Y13: 0 | Z13: 0 | AA13: 0
A14: lignite | B14: 0 | C14: 0 | D14: 0 | E14: 0 | F14: 0 | G14: 0 | H14: 0 | I14: 0 | J14: 0 | K14: 0 | L14: 0 | M14: 0 | N14: 0 | O14: 0 | P14: 0 | Q14: 0 | R14: 0 | S14: 0 | T14: 0 | U14: 0 | V14: 0 | W14: 0 | X14: 0 | Y14: 0 | Z14: 0 | AA14: 0
A15: offshore wind | B15: {=_xlfn.LET(_xlpm.t,B$1,_xlpm.yrs,'Calc-Wind-Offshore'!$B$18:$J$18,_xlpm.vals,'Calc-Wind-Offshore'!$B$20:$J$20,_xlpm.lo,MATCH(_xlpm.t,_xlpm.yrs,1),_xlpm.hi,MIN(_xlpm.lo+1,COLUMNS(_xlpm.yrs)),_xlpm.loYr,INDEX(_xlpm.yrs,1,_xlpm.lo),_xlpm.hiYr,INDEX(_xlpm.yrs,1,_xlpm.hi),_xlpm.loV,INDEX(_xlpm.vals,1,_xlpm.lo),_xlpm.hiV,INDEX(_xlpm.vals,1,_xlpm.hi),IF(_xlpm.loYr=_xlpm.hiYr,_xlpm.loV,_xlpm.loV+(_xlpm.t-_xlpm.loYr)*(_xlpm.hiV-_xlpm.loV)/(_xlpm.hiYr-_xlpm.loYr)))} -> 0.131019 | C15: {=_xlfn.LET(_xlpm.t,C$1,_xlpm.yrs,'Calc-Wind-Offshore'!$B$18:$J$18,_xlpm.vals,'Calc-Wind-Offshore'!$B$20:$J$20,_xlpm.lo,MATCH(_xlpm.t,_xlpm.yrs,1),_xlpm.hi,MIN(_xlpm.lo+1,COLUMNS(_xlpm.yrs)),_xlpm.loYr,INDEX(_xlpm.yrs,1,_xlpm.lo),_xlpm.hiYr,INDEX(_xlpm.yrs,1,_xlpm.hi),_xlpm.loV,INDEX(_xlpm.vals,1,_xlpm.lo),_xlpm.hiV,INDEX(_xlpm.vals,1,_xlpm.hi),IF(_xlpm.loYr=_xlpm.hiYr,_xlpm.loV,_xlpm.loV+(_xlpm.t-_xlpm.loYr)*(_xlpm.hiV-_xlpm.loV)/(_xlpm.hiYr-_xlpm.loYr)))} -> 0.18717 | D15: {=_xlfn.LET(_xlpm.t,D$1,_xlpm.yrs,'Calc-Wind-Offshore'!$B$18:$J$18,_xlpm.vals,'Calc-Wind-Offshore'!$B$20:$J$20,_xlpm.lo,MATCH(_xlpm.t,_xlpm.yrs,1),_xlpm.hi,MIN(_xlpm.lo+1,COLUMNS(_xlpm.yrs)),_xlpm.loYr,INDEX(_xlpm.yrs,1,_xlpm.lo),_xlpm.hiYr,INDEX(_xlpm.yrs,1,_xlpm.hi),_xlpm.loV,INDEX(_xlpm.vals,1,_xlpm.lo),_xlpm.hiV,INDEX(_xlpm.vals,1,_xlpm.hi),IF(_xlpm.loYr=_xlpm.hiYr,_xlpm.loV,_xlpm.loV+(_xlpm.t-_xlpm.loYr)*(_xlpm.hiV-_xlpm.loV)/(_xlpm.hiYr-_xlpm.loYr)))} -> 0.1834266 | E15: {=_xlfn.LET(_xlpm.t,E$1,_xlpm.yrs,'Calc-Wind-Offshore'!$B$18:$J$18,_xlpm.vals,'Calc-Wind-Offshore'!$B$20:$J$20,_xlpm.lo,MATCH(_xlpm.t,_xlpm.yrs,1),_xlpm.hi,MIN(_xlpm.lo+1,COLUMNS(_xlpm.yrs)),_xlpm.loYr,INDEX(_xlpm.yrs,1,_xlpm.lo),_xlpm.hiYr,INDEX(_xlpm.yrs,1,_xlpm.hi),_xlpm.loV,INDEX(_xlpm.vals,1,_xlpm.lo),_xlpm.hiV,INDEX(_xlpm.vals,1,_xlpm.hi),IF(_xlpm.loYr=_xlpm.hiYr,_xlpm.loV,_xlpm.loV+(_xlpm.t-_xlpm.loYr)*(_xlpm.hiV-_xlpm.loV)/(_xlpm.hiYr-_xlpm.loYr)))} -> 0.1721964 | F15: {=_xlfn.LET(_xlpm.t,F$1,_xlpm.yrs,'Calc-Wind-Offshore'!$B$18:$J$18,_xlpm.vals,'Calc-Wind-Offshore'!$B$20:$J$20,_xlpm.lo,MATCH(_xlpm.t,_xlpm.yrs,1),_xlpm.hi,MIN(_xlpm.lo+1,COLUMNS(_xlpm.yrs)),_xlpm.loYr,INDEX(_xlpm.yrs,1,_xlpm.lo),_xlpm.hiYr,INDEX(_xlpm.yrs,1,_xlpm.hi),_xlpm.loV,INDEX(_xlpm.vals,1,_xlpm.lo),_xlpm.hiV,INDEX(_xlpm.vals,1,_xlpm.hi),IF(_xlpm.loYr=_xlpm.hiYr,_xlpm.loV,_xlpm.loV+(_xlpm.t-_xlpm.loYr)*(_xlpm.hiV-_xlpm.loV)/(_xlpm.hiYr-_xlpm.loYr)))} -> 0.1534794 | G15: {=_xlfn.LET(_xlpm.t,G$1,_xlpm.yrs,'Calc-Wind-Offshore'!$B$18:$J$18,_xlpm.vals,'Calc-Wind-Offshore'!$B$20:$J$20,_xlpm.lo,MATCH(_xlpm.t,_xlpm.yrs,1),_xlpm.hi,MIN(_xlpm.lo+1,COLUMNS(_xlpm.yrs)),_xlpm.loYr,INDEX(_xlpm.yrs,1,_xlpm.lo),_xlpm.hiYr,INDEX(_xlpm.yrs,1,_xlpm.hi),_xlpm.loV,INDEX(_xlpm.vals,1,_xlpm.lo),_xlpm.hiV,INDEX(_xlpm.vals,1,_xlpm.hi),IF(_xlpm.loYr=_xlpm.hiYr,_xlpm.loV,_xlpm.loV+(_xlpm.t-_xlpm.loYr)*(_xlpm.hiV-_xlpm.loV)/(_xlpm.hiYr-_xlpm.loYr)))} -> 0.131019 | H15: {=_xlfn.LET(_xlpm.t,H$1,_xlpm.yrs,'Calc-Wind-Offshore'!$B$18:$J$18,_xlpm.vals,'Calc-Wind-Offshore'!$B$20:$J$20,_xlpm.lo,MATCH(_xlpm.t,_xlpm.yrs,1),_xlpm.hi,MIN(_xlpm.lo+1,COLUMNS(_xlpm.yrs)),_xlpm.loYr,INDEX(_xlpm.yrs,1,_xlpm.lo),_xlpm.hiYr,INDEX(_xlpm.yrs,1,_xlpm.hi),_xlpm.loV,INDEX(_xlpm.vals,1,_xlpm.lo),_xlpm.hiV,INDEX(_xlpm.vals,1,_xlpm.hi),IF(_xlpm.loYr=_xlpm.hiYr,_xlpm.loV,_xlpm.loV+(_xlpm.t-_xlpm.loYr)*(_xlpm.hiV-_xlpm.loV)/(_xlpm.hiYr-_xlpm.loYr)))} -> 0.1254039 | I15: {=_xlfn.LET(_xlpm.t,I$1,_xlpm.yrs,'Calc-Wind-Offshore'!$B$18:$J$18,_xlpm.vals,'Calc-Wind-Offshore'!$B$20:$J$20,_xlpm.lo,MATCH(_xlpm.t,_xlpm.yrs,1),_xlpm.hi,MIN(_xlpm.lo+1,COLUMNS(_xlpm.yrs)),_xlpm.loYr,INDEX(_xlpm.yrs,1,_xlpm.lo),_xlpm.hiYr,INDEX(_xlpm.yrs,1,_xlpm.hi),_xlpm.loV,INDEX(_xlpm.vals,1,_xlpm.lo),_xlpm.hiV,INDEX(_xlpm.vals,1,_xlpm.hi),IF(_xlpm.loYr=_xlpm.hiYr,_xlpm.loV,_xlpm.loV+(_xlpm.t-_xlpm.loYr)*(_xlpm.hiV-_xlpm.loV)/(_xlpm.hiYr-_xlpm.loYr)))} -> 0.1197888 | ... AA15: {=_xlfn.LET(_xlpm.t,AA$1,_xlpm.yrs,'Calc-Wind-Offshore'!$B$18:$J$18,_xlpm.vals,'Calc-Wind-Offshore'!$B$20:$J$20,_xlpm.lo,MATCH(_xlpm.t,_xlpm.yrs,1),_xlpm.hi,MIN(_xlpm.lo+1,COLUMNS(_xlpm.yrs)),_xlpm.loYr,INDEX(_xlpm.yrs,1,_xlpm.lo),_xlpm.hiYr,INDEX(_xlpm.yrs,1,_xlpm.hi),_xlpm.loV,INDEX(_xlpm.vals,1,_xlpm.lo),_xlpm.hiV,INDEX(_xlpm.vals,1,_xlpm.hi),IF(_xlpm.loYr=_xlpm.hiYr,_xlpm.loV,_xlpm.loV+(_xlpm.t-_xlpm.loYr)*(_xlpm.hiV-_xlpm.loV)/(_xlpm.hiYr-_xlpm.loYr)))} -> 0.074868
A16: crude oil | B16: 0 | C16: 0 | D16: 0 | E16: 0 | F16: 0 | G16: 0 | H16: 0 | I16: 0 | J16: 0 | K16: 0 | L16: 0 | M16: 0 | N16: 0 | O16: 0 | P16: 0 | Q16: 0 | R16: 0 | S16: 0 | T16: 0 | U16: 0 | V16: 0 | W16: 0 | X16: 0 | Y16: 0 | Z16: 0 | AA16: 0
A17: heavy or residual fuel oil | B17: 0 | C17: 0 | D17: 0 | E17: 0 | F17: 0 | G17: 0 | H17: 0 | I17: 0 | J17: 0 | K17: 0 | L17: 0 | M17: 0 | N17: 0 | O17: 0 | P17: 0 | Q17: 0 | R17: 0 | S17: 0 | T17: 0 | U17: 0 | V17: 0 | W17: 0 | X17: 0 | Y17: 0 | Z17: 0 | AA17: 0
A18: municipal solid waste | B18: 0 | C18: 0 | D18: 0 | E18: 0 | F18: 0 | G18: 0 | H18: 0 | I18: 0 | J18: 0 | K18: 0 | L18: 0 | M18: 0 | N18: 0 | O18: 0 | P18: 0 | Q18: 0 | R18: 0 | S18: 0 | T18: 0 | U18: 0 | V18: 0 | W18: 0 | X18: 0 | Y18: 0 | Z18: 0 | AA18: 0
A19: hard coal w CCS | B19: 0 | C19: 0 | D19: 0 | E19: 0 | F19: 0 | G19: 0 | H19: 0 | I19: 0 | J19: 0 | K19: 0 | L19: 0 | M19: 0 | N19: 0 | O19: 0 | P19: 0 | Q19: 0 | R19: 0 | S19: 0 | T19: 0 | U19: 0 | V19: 0 | W19: 0 | X19: 0 | Y19: 0 | Z19: 0 | AA19: 0
A20: natural gas combined cycle w CCS | B20: 0 | C20: 0 | D20: 0 | E20: 0 | F20: 0 | G20: 0 | H20: 0 | I20: 0 | J20: 0 | K20: 0 | L20: 0 | M20: 0 | N20: 0 | O20: 0 | P20: 0 | Q20: 0 | R20: 0 | S20: 0 | T20: 0 | U20: 0 | V20: 0 | W20: 0 | X20: 0 | Y20: 0 | Z20: 0 | AA20: 0
A21: biomass w CCS | B21: 0 | C21: 0 | D21: 0 | E21: 0 | F21: 0 | G21: 0 | H21: 0 | I21: 0 | J21: 0 | K21: 0 | L21: 0 | M21: 0 | N21: 0 | O21: 0 | P21: 0 | Q21: 0 | R21: 0 | S21: 0 | T21: 0 | U21: 0 | V21: 0 | W21: 0 | X21: 0 | Y21: 0 | Z21: 0 | AA21: 0
A22: lignite w CCS | B22: 0 | C22: 0 | D22: 0 | E22: 0 | F22: 0 | G22: 0 | H22: 0 | I22: 0 | J22: 0 | K22: 0 | L22: 0 | M22: 0 | N22: 0 | O22: 0 | P22: 0 | Q22: 0 | R22: 0 | S22: 0 | T22: 0 | U22: 0 | V22: 0 | W22: 0 | X22: 0 | Y22: 0 | Z22: 0 | AA22: 0
A23: small modular reactor | B23: 0 | C23: 0 | D23: 0 | E23: 0 | F23: 0 | G23: 0 | H23: 0 | I23: 0 | J23: 0 | K23: 0 | L23: 0 | M23: 0 | N23: 0 | O23: 0 | P23: 0 | Q23: 0 | R23: 0 | S23: 0 | T23: 0 | U23: 0 | V23: 0 | W23: 0 | X23: 0 | Y23: 0 | Z23: 0 | AA23: 0
A24: hydrogen combustion turbine | B24: 0 | C24: 0 | D24: 0 | E24: 0 | F24: 0 | G24: 0 | H24: 0 | I24: 0 | J24: 0 | K24: 0 | L24: 0 | M24: 0 | N24: 0 | O24: 0 | P24: 0 | Q24: 0 | R24: 0 | S24: 0 | T24: 0 | U24: 0 | V24: 0 | W24: 0 | X24: 0 | Y24: 0 | Z24: 0 | AA24: 0
A25: hydrogen combined cycle | B25: 0 | C25: 0 | D25: 0 | E25: 0 | F25: 0 | G25: 0 | H25: 0 | I25: 0 | J25: 0 | K25: 0 | L25: 0 | M25: 0 | N25: 0 | O25: 0 | P25: 0 | Q25: 0 | R25: 0 | S25: 0 | T25: 0 | U25: 0 | V25: 0 | W25: 0 | X25: 0 | Y25: 0 | Z25: 0 | AA25: 0

Sheet BTCM-GB
A1: Unit: Dmnl | B1: 2025 | C1: 2026 | D1: 2027 | E1: 2028 | F1: 2029 | G1: 2030 | H1: 2031 | I1: 2032 | J1: 2033 | K1: 2034 | L1: 2035 | M1: 2036 | N1: 2037 | O1: 2038 | P1: 2039 | Q1: 2040 | R1: 2041 | S1: 2042 | T1: 2043 | U1: 2044 | V1: 2045 | W1: 2046 | X1: 2047 | Y1: 2048 | Z1: 2049 | AA1: 2050
A2: Tariff Multiplier | B2: {=_xlfn.LET(_xlpm.t,B$1,_xlpm.yrs,'Calc-Battery'!$B$28:$J$28,_xlpm.vals,'Calc-Battery'!$B$30:$J$30,_xlpm.lo,MATCH(_xlpm.t,_xlpm.yrs,1),_xlpm.hi,MIN(_xlpm.lo+1,COLUMNS(_xlpm.yrs)),_xlpm.loYr,INDEX(_xlpm.yrs,1,_xlpm.lo),_xlpm.hiYr,INDEX(_xlpm.yrs,1,_xlpm.hi),_xlpm.loV,INDEX(_xlpm.vals,1,_xlpm.lo),_xlpm.hiV,INDEX(_xlpm.vals,1,_xlpm.hi),IF(_xlpm.loYr=_xlpm.hiYr,_xlpm.loV,_xlpm.loV+(_xlpm.t-_xlpm.loYr)*(_xlpm.hiV-_xlpm.loV)/(_xlpm.hiYr-_xlpm.loYr)))} -> 0.05842375 | C2: {=_xlfn.LET(_xlpm.t,C$1,_xlpm.yrs,'Calc-Battery'!$B$28:$J$28,_xlpm.vals,'Calc-Battery'!$B$30:$J$30,_xlpm.lo,MATCH(_xlpm.t,_xlpm.yrs,1),_xlpm.hi,MIN(_xlpm.lo+1,COLUMNS(_xlpm.yrs)),_xlpm.loYr,INDEX(_xlpm.yrs,1,_xlpm.lo),_xlpm.hiYr,INDEX(_xlpm.yrs,1,_xlpm.hi),_xlpm.loV,INDEX(_xlpm.vals,1,_xlpm.lo),_xlpm.hiV,INDEX(_xlpm.vals,1,_xlpm.hi),IF(_xlpm.loYr=_xlpm.hiYr,_xlpm.loV,_xlpm.loV+(_xlpm.t-_xlpm.loYr)*(_xlpm.hiV-_xlpm.loV)/(_xlpm.hiYr-_xlpm.loYr)))} -> 0.14725 | D2: {=_xlfn.LET(_xlpm.t,D$1,_xlpm.yrs,'Calc-Battery'!$B$28:$J$28,_xlpm.vals,'Calc-Battery'!$B$30:$J$30,_xlpm.lo,MATCH(_xlpm.t,_xlpm.yrs,1),_xlpm.hi,MIN(_xlpm.lo+1,COLUMNS(_xlpm.yrs)),_xlpm.loYr,INDEX(_xlpm.yrs,1,_xlpm.lo),_xlpm.hiYr,INDEX(_xlpm.yrs,1,_xlpm.hi),_xlpm.loV,INDEX(_xlpm.vals,1,_xlpm.lo),_xlpm.hiV,INDEX(_xlpm.vals,1,_xlpm.hi),IF(_xlpm.loYr=_xlpm.hiYr,_xlpm.loV,_xlpm.loV+(_xlpm.t-_xlpm.loYr)*(_xlpm.hiV-_xlpm.loV)/(_xlpm.hiYr-_xlpm.loYr)))} -> 0.1251625 | E2: {=_xlfn.LET(_xlpm.t,E$1,_xlpm.yrs,'Calc-Battery'!$B$28:$J$28,_xlpm.vals,'Calc-Battery'!$B$30:$J$30,_xlpm.lo,MATCH(_xlpm.t,_xlpm.yrs,1),_xlpm.hi,MIN(_xlpm.lo+1,COLUMNS(_xlpm.yrs)),_xlpm.loYr,INDEX(_xlpm.yrs,1,_xlpm.lo),_xlpm.hiYr,INDEX(_xlpm.yrs,1,_xlpm.hi),_xlpm.loV,INDEX(_xlpm.vals,1,_xlpm.lo),_xlpm.hiV,INDEX(_xlpm.vals,1,_xlpm.hi),IF(_xlpm.loYr=_xlpm.hiYr,_xlpm.loV,_xlpm.loV+(_xlpm.t-_xlpm.loYr)*(_xlpm.hiV-_xlpm.loV)/(_xlpm.hiYr-_xlpm.loYr)))} -> 0.0957125 | F2: {=_xlfn.LET(_xlpm.t,F$1,_xlpm.yrs,'Calc-Battery'!$B$28:$J$28,_xlpm.vals,'Calc-Battery'!$B$30:$J$30,_xlpm.lo,MATCH(_xlpm.t,_xlpm.yrs,1),_xlpm.hi,MIN(_xlpm.lo+1,COLUMNS(_xlpm.yrs)),_xlpm.loYr,INDEX(_xlpm.yrs,1,_xlpm.lo),_xlpm.hiYr,INDEX(_xlpm.yrs,1,_xlpm.hi),_xlpm.loV,INDEX(_xlpm.vals,1,_xlpm.lo),_xlpm.hiV,INDEX(_xlpm.vals,1,_xlpm.hi),IF(_xlpm.loYr=_xlpm.hiYr,_xlpm.loV,_xlpm.loV+(_xlpm.t-_xlpm.loYr)*(_xlpm.hiV-_xlpm.loV)/(_xlpm.hiYr-_xlpm.loYr)))} -> 0.073625 | G2: {=_xlfn.LET(_xlpm.t,G$1,_xlpm.yrs,'Calc-Battery'!$B$28:$J$28,_xlpm.vals,'Calc-Battery'!$B$30:$J$30,_xlpm.lo,MATCH(_xlpm.t,_xlpm.yrs,1),_xlpm.hi,MIN(_xlpm.lo+1,COLUMNS(_xlpm.yrs)),_xlpm.loYr,INDEX(_xlpm.yrs,1,_xlpm.lo),_xlpm.hiYr,INDEX(_xlpm.yrs,1,_xlpm.hi),_xlpm.loV,INDEX(_xlpm.vals,1,_xlpm.lo),_xlpm.hiV,INDEX(_xlpm.vals,1,_xlpm.hi),IF(_xlpm.loYr=_xlpm.hiYr,_xlpm.loV,_xlpm.loV+(_xlpm.t-_xlpm.loYr)*(_xlpm.hiV-_xlpm.loV)/(_xlpm.hiYr-_xlpm.loYr)))} -> 0.0515375 | H2: {=_xlfn.LET(_xlpm.t,H$1,_xlpm.yrs,'Calc-Battery'!$B$28:$J$28,_xlpm.vals,'Calc-Battery'!$B$30:$J$30,_xlpm.lo,MATCH(_xlpm.t,_xlpm.yrs,1),_xlpm.hi,MIN(_xlpm.lo+1,COLUMNS(_xlpm.yrs)),_xlpm.loYr,INDEX(_xlpm.yrs,1,_xlpm.lo),_xlpm.hiYr,INDEX(_xlpm.yrs,1,_xlpm.hi),_xlpm.loV,INDEX(_xlpm.vals,1,_xlpm.lo),_xlpm.hiV,INDEX(_xlpm.vals,1,_xlpm.hi),IF(_xlpm.loYr=_xlpm.hiYr,_xlpm.loV,_xlpm.loV+(_xlpm.t-_xlpm.loYr)*(_xlpm.hiV-_xlpm.loV)/(_xlpm.hiYr-_xlpm.loYr)))} -> 0.04712 | I2: {=_xlfn.LET(_xlpm.t,I$1,_xlpm.yrs,'Calc-Battery'!$B$28:$J$28,_xlpm.vals,'Calc-Battery'!$B$30:$J$30,_xlpm.lo,MATCH(_xlpm.t,_xlpm.yrs,1),_xlpm.hi,MIN(_xlpm.lo+1,COLUMNS(_xlpm.yrs)),_xlpm.loYr,INDEX(_xlpm.yrs,1,_xlpm.lo),_xlpm.hiYr,INDEX(_xlpm.yrs,1,_xlpm.hi),_xlpm.loV,INDEX(_xlpm.vals,1,_xlpm.lo),_xlpm.hiV,INDEX(_xlpm.vals,1,_xlpm.hi),IF(_xlpm.loYr=_xlpm.hiYr,_xlpm.loV,_xlpm.loV+(_xlpm.t-_xlpm.loYr)*(_xlpm.hiV-_xlpm.loV)/(_xlpm.hiYr-_xlpm.loYr)))} -> 0.0427025 | ... AA2: {=_xlfn.LET(_xlpm.t,AA$1,_xlpm.yrs,'Calc-Battery'!$B$28:$J$28,_xlpm.vals,'Calc-Battery'!$B$30:$J$30,_xlpm.lo,MATCH(_xlpm.t,_xlpm.yrs,1),_xlpm.hi,MIN(_xlpm.lo+1,COLUMNS(_xlpm.yrs)),_xlpm.loYr,INDEX(_xlpm.yrs,1,_xlpm.lo),_xlpm.hiYr,INDEX(_xlpm.yrs,1,_xlpm.hi),_xlpm.loV,INDEX(_xlpm.vals,1,_xlpm.lo),_xlpm.hiV,INDEX(_xlpm.vals,1,_xlpm.hi),IF(_xlpm.loYr=_xlpm.hiYr,_xlpm.loV,_xlpm.loV+(_xlpm.t-_xlpm.loYr)*(_xlpm.hiV-_xlpm.loV)/(_xlpm.hiYr-_xlpm.loYr)))} -> 0.0220875

Sheet BTCM-EVB-LDVs-psgr
A1: Unit: Dmnl | B1: 2025 | C1: 2026 | D1: 2027 | E1: 2028 | F1: 2029 | G1: 2030 | H1: 2031 | I1: 2032 | J1: 2033 | K1: 2034 | L1: 2035 | M1: 2036 | N1: 2037 | O1: 2038 | P1: 2039 | Q1: 2040 | R1: 2041 | S1: 2042 | T1: 2043 | U1: 2044 | V1: 2045 | W1: 2046 | X1: 2047 | Y1: 2048 | Z1: 2049 | AA1: 2050
