Workbook
Name gal_per_barrel: About!$A$75

Sheet About
A1: BCF BTU per Small Fuel Output Unit
A2: BCF BTU per Large Fuel Output Unit
A3: BCF Vehicle Fuel Economy Unit Conversion Factors
A4: BCF BTU per Energy Import Export Output Unit
A5: BCF BTU per MMT Hydrogen
A7: Source: | B7: hard coal, natural gas, petroleum fuels, liquid biofuels
B8: Energy Information Administration
B9: 2025
B10: Annual Energy Outlook 2025
B11: https://www.eia.gov/outlooks/aeo/tables_ref.php
B12: Table 69
B14: Lignite, Biomass, LPG, municipal solid waste, hydrogen
B15: Argonne National Laboratory
B16: 2019
B17: GREET1 2019
B18: https://greet.es.anl.gov/
B19: Tab "Fuel_Specs"
B21: Hydrogen Energy Density
B22: DOE
B23: 2021
B24: Alternative Fuels Data Center Fuel Properties Comparison
B25: https://afdc.energy.gov/files/u/publication/fuel_comparison_chart.pdf
B26: Higher heating value energy content
A29: Notes
A30: EIA uses higher heating values of fuels in the Annual Energy Outlook, so we
A31: use the higher heating value (HHV) for lignite from the GREET1 model.
A33: The Fuel Economy Output Unit is used to help compare fuel economy of different technologies of the same vehicle
A34: type (e.g. electric vs. gasoline LDVs). They will use a common unit, such as miles per gallon, even though electric
A35: LDVs do not use liquid fuel. The only fuel types that need data for Fuel Economy Output Unit are the "reference"
A36: fuel types that are used as the basis for comparing all of the vehicles of a given type, across technologies.
A37: This could be: petroleum gasoline (for LDVs and motorbikes), jet fuel (for aircraft), and petroleum diesel
A38: (for other vehicle types).
A40: The Energy Import Export Output Unit is used to compare all import energy flows on the same graph and to
A41: compare all export energy flows on the same graph, so it should be smaller than web-app/BpTPEU, but like BpTPEU,
A42: it should be a common unit that works for all energy types.
... A49: Large Fuel Output Units
A50: electricity, district heat | B50: TWh | C50: large output unit not used for these fuels
A51: hard coal, lignite, biomass, municipal solid waste | B51: millions of short tons
A52: natural gas | B52: trillion cubic feet
A53: hydrogen | B53: thousand metric tons
...

Sheet AEO Table 73
B1: ref2025.d032025a
C3: Report | D3: Annual Energy Outlook 2025
C4: Scenario | D4: ref2025 | F4: Reference
C5: Datekey | D5: d032025a
C6: Release Date | E6: April 2025
B10: 69. Conversion Factors
B11: (from physical units to MMBtu)
AD12: Avg Annual Change
C13: 2024 | D13: 2025 | E13: 2026 | F13: 2027 | G13: 2028 | H13: 2029 | I13: 2030 | J13: 2031 | K13: 2032 | L13: 2033 | M13: 2034 | N13: 2035 | O13: 2036 | P13: 2037 | Q13: 2038 | R13: 2039 | S13: 2040 | T13: 2041 | U13: 2042 | V13: 2043 | W13: 2044 | X13: 2045 | Y13: 2046 | Z13: 2047 | AA13: 2048 | AB13: 2049 | AC13: 2050 | AD13: 2024-2050
B14: Petroleum and Other Liquids
B15: (MMBtu per barrel)
A16: CNV000:aa_AsphaltandRoa | B16: Asphalt and Road Oil | C16: 6.6360002 | D16: 6.6360002 | E16: 6.6360002 | F16: 6.6360002 | G16: 6.6360002 | H16: 6.6360002 | I16: 6.6360002 | J16: 6.6360002 | K16: 6.6360002 | L16: 6.6360002 | M16: 6.6360002 | N16: 6.6360002 | O16: 6.6360002 | P16: 6.6360002 | Q16: 6.6360002 | R16: 6.6360002 | S16: 6.6360002 | T16: 6.6360002 | U16: 6.6360002 | V16: 6.6360002 | W16: 6.6360002 | X16: 6.6360002 | Y16: 6.6360002 | Z16: 6.6360002 | AA16: 6.6360002 | AB16: 6.6360002 | AC16: 6.6360002 | AD16: 0
A17: CNV000:aa_AviationGasol | B17: Aviation Gasoline | C17: 5.0479999 | D17: 5.0479999 | E17: 5.0479999 | F17: 5.0479999 | G17: 5.0479999 | H17: 5.0479999 | I17: 5.0479999 | J17: 5.0479999 | K17: 5.0479999 | L17: 5.0479999 | M17: 5.0479999 | N17: 5.0479999 | O17: 5.0479999 | P17: 5.0479999 | Q17: 5.0479999 | R17: 5.0479999 | S17: 5.0479999 | T17: 5.0479999 | U17: 5.0479999 | V17: 5.0479999 | W17: 5.0479999 | X17: 5.0479999 | Y17: 5.0479999 | Z17: 5.0479999 | AA17: 5.0479999 | AB17: 5.0479999 | AC17: 5.0479999 | AD17: 0
A18: CNV000:ea_Biodiesel | B18: Biodiesel | C18: 5.3590002 | D18: 5.3590002 | E18: 5.3590002 | F18: 5.3590002 | G18: 5.3590002 | H18: 5.3590002 | I18: 5.3590002 | J18: 5.3590002 | K18: 5.3590002 | L18: 5.3590002 | M18: 5.3590002 | N18: 5.3590002 | O18: 5.3590002 | P18: 5.3590002 | Q18: 5.3590002 | R18: 5.3590002 | S18: 5.3590002 | T18: 5.3590002 | U18: 5.3590002 | V18: 5.3590002 | W18: 5.3590002 | X18: 5.3590002 | Y18: 5.3590002 | Z18: 5.3590002 | AA18: 5.3590002 | AB18: 5.3590002 | AC18: 5.3590002 | AD18: 0
A19: CNV000:aa_Distillate | B19: Distillate Fuel Oil | C19: 5.8249998 | D19: 5.8249998 | E19: 5.8249998 | F19: 5.8249998 | G19: 5.8249998 | H19: 5.8249998 | I19: 5.8249998 | J19: 5.8249998 | K19: 5.8249998 | L19: 5.8249998 | M19: 5.8249998 | N19: 5.8249998 | O19: 5.8249998 | P19: 5.8249998 | Q19: 5.8249998 | R19: 5.8249998 | S19: 5.8249998 | T19: 5.8249998 | U19: 5.8249998 | V19: 5.8249998 | W19: 5.8249998 | X19: 5.8249998 | Y19: 5.8249998 | Z19: 5.8249998 | AA19: 5.8249998 | AB19: 5.8249998 | AC19: 5.8249998 | AD19: 0
A20: CNV000:aa_Residential | B20: Residential | C20: 5.7755923 | D20: 5.7757983 | E20: 5.7763596 | F20: 5.7769084 | G20: 5.776597 | H20: 5.7766476 | I20: 5.7765045 | J20: 5.7767425 | K20: 5.7769532 | L20: 5.7770152 | M20: 5.7770848 | N20: 5.7772822 | O20: 5.7772651 | P20: 5.7773728 | Q20: 5.7773809 | R20: 5.7774129 | S20: 5.7774544 | T20: 5.777524 | U20: 5.7776356 | V20: 5.7776852 | W20: 5.7776523 | X20: 5.7776871 | Y20: 5.7776413 | Z20: 5.7775741 | AA20: 5.7776489 | AB20: 5.7776256 | AC20: 5.7775879 | AD20: 1.3286896e-05
A21: CNV000:aa_Commercial | B21: Commercial | C21: 5.7755923 | D21: 5.7757983 | E21: 5.7763596 | F21: 5.7769084 | G21: 5.776597 | H21: 5.7766476 | I21: 5.7765045 | J21: 5.7767425 | K21: 5.7769532 | L21: 5.7770152 | M21: 5.7770848 | N21: 5.7772822 | O21: 5.7772651 | P21: 5.7773728 | Q21: 5.7773809 | R21: 5.7774129 | S21: 5.7774544 | T21: 5.777524 | U21: 5.7776356 | V21: 5.7776852 | W21: 5.7776523 | X21: 5.7776871 | Y21: 5.7776413 | Z21: 5.7775741 | AA21: 5.7776489 | AB21: 5.7776256 | AC21: 5.7775879 | AD21: 1.3286896e-05
A22: CNV000:aa_Transportatio | B22: Transportation | C22: 5.7755923 | D22: 5.7757983 | E22: 5.7763596 | F22: 5.7769084 | G22: 5.776597 | H22: 5.7766476 | I22: 5.7765045 | J22: 5.7767425 | K22: 5.7769532 | L22: 5.7770152 | M22: 5.7770848 | N22: 5.7772822 | O22: 5.7772651 | P22: 5.7773728 | Q22: 5.7773809 | R22: 5.7774129 | S22: 5.7774544 | T22: 5.777524 | U22: 5.7776356 | V22: 5.7776852 | W22: 5.7776523 | X22: 5.7776871 | Y22: 5.7776413 | Z22: 5.7775741 | AA22: 5.7776489 | AB22: 5.7776256 | AC22: 5.7775879 | AD22: 1.3286896e-05
A23: CNV000:aa_Industrial | B23: Industrial | C23: 5.7755923 | D23: 5.7757983 | E23: 5.7763596 | F23: 5.7769084 | G23: 5.776597 | H23: 5.7766476 | I23: 5.7765045 | J23: 5.7767425 | K23: 5.7769532 | L23: 5.7770152 | M23: 5.7770848 | N23: 5.7772822 | O23: 5.7772651 | P23: 5.7773728 | Q23: 5.7773809 | R23: 5.7774129 | S23: 5.7774544 | T23: 5.777524 | U23: 5.7776356 | V23: 5.7776852 | W23: 5.7776523 | X23: 5.7776871 | Y23: 5.7776413 | Z23: 5.7775741 | AA23: 5.7776489 | AB23: 5.7776256 | AC23: 5.7775879 | AD23: 1.3286896e-05
A24: CNV000:aa_ElectricPower | B24: Electric Power | C24: 5.7755923 | D24: 5.7757983 | E24: 5.7763596 | F24: 5.7769084 | G24: 5.776597 | H24: 5.7766476 | I24: 5.7765045 | J24: 5.7767425 | K24: 5.7769532 | L24: 5.7770152 | M24: 5.7770848 | N24: 5.7772822 | O24: 5.7772651 | P24: 5.7773728 | Q24: 5.7773809 | R24: 5.7774129 | S24: 5.7774544 | T24: 5.777524 | U24: 5.7776356 | V24: 5.7776852 | W24: 5.7776523 | X24: 5.7776871 | Y24: 5.7776413 | Z24: 5.7775741 | AA24: 5.7776489 | AB24: 5.7776256 | AC24: 5.7775879 | AD24: 1.3286896e-05
A25: CNV000:aa_TotalDistilla | B25: Total Distillate | C25: 5.7755923 | D25: 5.7757988 | E25: 5.7763596 | F25: 5.7769089 | G25: 5.7765975 | H25: 5.7766476 | I25: 5.7765045 | J25: 5.7767425 | K25: 5.7769537 | L25: 5.7770147 | M25: 5.7770839 | N25: 5.7772822 | O25: 5.7772651 | P25: 5.7773728 | Q25: 5.7773809 | R25: 5.7774134 | S25: 5.7774544 | T25: 5.7775245 | U25: 5.7776351 | V25: 5.7776856 | W25: 5.7776527 | X25: 5.7776875 | Y25: 5.7776413 | Z25: 5.7775736 | AA25: 5.7776484 | AB25: 5.7776256 | AC25: 5.7775879 | AD25: 1.3286896e-05
A26: CNV000:aa_DistLowSulf | B26: Distillate Fuel Oil - Low Sulfur Diesel | C26: 5.8169999 | D26: 5.8169999 | E26: 5.8169999 | F26: 5.8169999 | G26: 5.8169999 | H26: 5.8169999 | I26: 5.8169999 | J26: 5.8169999 | K26: 5.8169999 | L26: 5.8169999 | M26: 5.8169999 | N26: 5.8169999 | O26: 5.8169999 | P26: 5.8169999 | Q26: 5.8169999 | R26: 5.8169999 | S26: 5.8169999 | T26: 5.8169999 | U26: 5.8169999 | V26: 5.8169999 | W26: 5.8169999 | X26: 5.8169999 | Y26: 5.8169999 | Z26: 5.8169999 | AA26: 5.8169999 | AB26: 5.8169999 | AC26: 5.8169999 | AD26: 0
A27: CNV000:aa_DistUltraLow | B27: Distillate Fuel Oil - Ultra Low Sulfur Diesel | C27: 5.77 | D27: 5.77 | E27: 5.77 | F27: 5.77 | G27: 5.77 | H27: 5.77 | I27: 5.77 | J27: 5.77 | K27: 5.77 | L27: 5.77 | M27: 5.77 | N27: 5.77 | O27: 5.77 | P27: 5.77 | Q27: 5.77 | R27: 5.77 | S27: 5.77 | T27: 5.77 | U27: 5.77 | V27: 5.77 | W27: 5.77 | X27: 5.77 | Y27: 5.77 | Z27: 5.77 | AA27: 5.77 | AB27: 5.77 | AC27: 5.77 | AD27: 0
... A46: CNV000:aa_Exports | B46: Petroleum Product Exports | C46: 4.9778066 | D46: 5.0571795 | E46: 4.8657002 | F46: 4.8269815 | G46: 4.8110781 | H46: 4.8033814 | I46: 4.7998724 | J46: 4.829298 | K46: 4.8448181 | L46: 4.8458347 | M46: 4.8520894 | N46: 4.8538675 | O46: 4.8541937 | P46: 4.8758259 | Q46: 4.8941693 | R46: 4.9231071 | S46: 4.9604688 | T46: 4.9841819 | U46: 4.9958472 | V46: 5.0106225 | W46: 5.0007915 | X46: 4.9804125 | Y46: 4.9765944 | Z46: 4.9863768 | AA46: 4.9984708 | AB46: 5.0013475 | AC46: 4.9966674 | AD46: 0.00014546525
B47: Crude Oil
A48: CNV000:aa_CrudeOilProdu | B48: Production | C48: 5.6718836 | D48: 5.6544743 | E48: 5.6519918 | F48: 5.6493263 | G48: 5.6487727 | H48: 5.6491818 | I48: 5.6493139 | J48: 5.6481771 | K48: 5.6463475 | L48: 5.6454072 | M48: 5.6438169 | N48: 5.6415157 | O48: 5.6399322 | P48: 5.6388917 | Q48: 5.6373215 | R48: 5.6360483 | S48: 5.6351128 | T48: 5.6349845 | U48: 5.6346445 | V48: 5.6338644 | W48: 5.6332345 | X48: 5.6326957 | Y48: 5.6318951 | Z48: 5.6307178 | AA48: 5.6279407 | AB48: 5.6278853 | AC48: 5.6268964 | AD48: -0.0003062315
A49: CNV000:aa_CrudeOilImpor | B49: Imports | C49: 6.0371513 | D49: 6.0394158 | E49: 6.063992 | F49: 6.0575299 | G49: 6.0694408 | H49: 6.067462 | I49: 6.0692587 | J49: 6.0777578 | K49: 6.0875287 | L49: 6.0830536 | M49: 6.0917192 | N49: 6.0896082 | O49: 6.0988235 | P49: 6.110703 | Q49: 6.1158199 | R49: 6.1119924 | S49: 6.1124606 | T49: 6.11833 | U49: 6.1123786 | V49: 6.112277 | W49: 6.115294 | X49: 6.1151466 | Y49: 6.1146221 | Z49: 6.110785 | AA49: 6.1133351 | AB49: 6.1106172 | AC49: 6.1120543 | AD49: 0.00047436925
A50: CNV000:aa_CrudeOilExpor | B50: Exports | C50: 5.5800977 | D50: 5.5956593 | E50: 5.5872884 | F50: 5.5813761 | G50: 5.5769868 | H50: 5.5765958 | I50: 5.5815945 | J50: 5.5824208 | K50: 5.5884156 | L50: 5.5852947 | M50: 5.5885353 | N50: 5.5873609 | O50: 5.5936003 | P50: 5.5935845 | Q50: 5.5935178 | R50: 5.5934668 | S50: 5.5934043 | T50: 5.5933113 | U50: 5.5878687 | V50: 5.5861359 | W50: 5.5839605 | X50: 5.5834017 | Y50: 5.5831046 | Z50: 5.5805097 | AA50: 5.5765672 | AB50: 5.5778594 | AC50: 5.5782318 | AD50: -1.2862773e-05
A51: CNV000:aa_NaturalGasPla | B51: Natural Gas Plant Liquids | C51: 3.5781934 | D51: 3.5825648 | E51: 3.5525672 | F51: 3.5440955 | G51: 3.5313861 | H51: 3.5250974 | I51: 3.52636 | J51: 3.5151105 | K51: 3.518549 | L51: 3.5119145 | M51: 3.4979987 | N51: 3.5005653 | O51: 3.4908521 | P51: 3.4919038 | Q51: 3.4997211 | R51: 3.4978683 | S51: 3.4975557 | T51: 3.4975252 | U51: 3.4972908 | V51: 3.4950893 | W51: 3.4939315 | X51: 3.4920561 | Y51: 3.4908259 | Z51: 3.4894567 | AA51: 3.4881761 | AB51: 3.4871325 | AC51: 3.4856052 | AD51: -0.0010078128
B53: Natural Gas (thousand Btu per cubic foot)
A54: CNV000:ba_Consumption | B54: Consumption | C54: 1.036 | D54: 1.036 | E54: 1.036 | F54: 1.036 | G54: 1.036 | H54: 1.036 | I54: 1.036 | J54: 1.036 | K54: 1.036 | L54: 1.036 | M54: 1.036 | N54: 1.036 | O54: 1.036 | P54: 1.036 | Q54: 1.036 | R54: 1.036 | S54: 1.036 | T54: 1.036 | U54: 1.036 | V54: 1.036 | W54: 1.036 | X54: 1.036 | Y54: 1.036 | Z54: 1.036 | AA54: 1.036 | AB54: 1.036 | AC54: 1.036 | AD54: 0
A55: CNV000:ba_Utility | B55: Electric Power Sector 2/ | C55: 1.033 | D55: 1.033 | E55: 1.033 | F55: 1.033 | G55: 1.033 | H55: 1.033 | I55: 1.033 | J55: 1.033 | K55: 1.033 | L55: 1.033 | M55: 1.033 | N55: 1.033 | O55: 1.033 | P55: 1.033 | Q55: 1.033 | R55: 1.033 | S55: 1.033 | T55: 1.033 | U55: 1.033 | V55: 1.033 | W55: 1.033 | X55: 1.033 | Y55: 1.033 | Z55: 1.033 | AA55: 1.033 | AB55: 1.033 | AC55: 1.033 | AD55: 0
A56: CNV000:ba_Nonutility | B56: End-use Sector | C56: 1.038 | D56: 1.038 | E56: 1.038 | F56: 1.038 | G56: 1.038 | H56: 1.038 | I56: 1.038 | J56: 1.038 | K56: 1.038 | L56: 1.038 | M56: 1.038 | N56: 1.038 | O56: 1.038 | P56: 1.038 | Q56: 1.038 | R56: 1.038 | S56: 1.038 | T56: 1.038 | U56: 1.038 | V56: 1.038 | W56: 1.038 | X56: 1.038 | Y56: 1.038 | Z56: 1.038 | AA56: 1.038 | AB56: 1.038 | AC56: 1.038 | AD56: 0
A57: CNV000:ba_Production | B57: Production | C57: 1.036 | D57: 1.036 | E57: 1.036 | F57: 1.036 | G57: 1.036 | H57: 1.036 | I57: 1.036 | J57: 1.036 | K57: 1.036 | L57: 1.036 | M57: 1.036 | N57: 1.036 | O57: 1.036 | P57: 1.036 | Q57: 1.036 | R57: 1.036 | S57: 1.036 | T57: 1.036 | U57: 1.036 | V57: 1.036 | W57: 1.036 | X57: 1.036 | Y57: 1.036 | Z57: 1.036 | AA57: 1.036 | AB57: 1.036 | AC57: 1.036 | AD57: 0
A58: CNV000:ba_Imports | B58: Imports | C58: 1.025 | D58: 1.025 | E58: 1.025 | F58: 1.025 | G58: 1.025 | H58: 1.025 | I58: 1.025 | J58: 1.025 | K58: 1.025 | L58: 1.025 | M58: 1.025 | N58: 1.025 | O58: 1.025 | P58: 1.025 | Q58: 1.025 | R58: 1.025 | S58: 1.025 | T58: 1.025 | U58: 1.025 | V58: 1.025 | W58: 1.025 | X58: 1.025 | Y58: 1.025 | Z58: 1.025 | AA58: 1.025 | AB58: 1.025 | AC58: 1.025 | AD58: 0
A59: CNV000:ba_Exports | B59: Exports | C59: 1.0089999 | D59: 1.0089999 | E59: 1.0089999 | F59: 1.0089999 | G59: 1.0089999 | H59: 1.0089999 | I59: 1.0089999 | J59: 1.0089999 | K59: 1.0089999 | L59: 1.0089999 | M59: 1.0089999 | N59: 1.0089999 | O59: 1.0089999 | P59: 1.0089999 | Q59: 1.0089999 | R59: 1.0089999 | S59: 1.0089999 | T59: 1.0089999 | U59: 1.0089999 | V59: 1.0089999 | W59: 1.0089999 | X59: 1.0089999 | Y59: 1.0089999 | Z59: 1.0089999 | AA59: 1.0089999 | AB59: 1.0089999 | AC59: 1.0089999 | AD59: 0
A60: CNV000:ba_CompressedNat | B60: Compressed/Liquefied Natural Gas | C60: 0.95999998 | D60: 0.95999998 | E60: 0.95999998 | F60: 0.95999998 | G60: 0.95999998 | H60: 0.95999998 | I60: 0.95999998 | J60: 0.95999998 | K60: 0.95999998 | L60: 0.95999998 | M60: 0.95999998 | N60: 0.95999998 | O60: 0.95999998 | P60: 0.95999998 | Q60: 0.95999998 | R60: 0.95999998 | S60: 0.95999998 | T60: 0.95999998 | U60: 0.95999998 | V60: 0.95999998 | W60: 0.95999998 | X60: 0.95999998 | Y60: 0.95999998 | Z60: 0.95999998 | AA60: 0.95999998 | AB60: 0.95999998 | AC60: 0.95999998 | AD60: 0
B62: Coal (MMBtu per short ton)
A63: CNV000:ca_Production | B63: Production | C63: 21.11474 | D63: 21.042957 | E63: 21.124723 | F63: 21.361576 | G63: 21.523605 | H63: 21.362909 | I63: 21.862711 | J63: 21.889633 | K63: 23.731817 | L63: 23.729841 | M63: 24.369764 | N63: 24.670118 | O63: 24.752544 | P63: 24.846464 | Q63: 24.579657 | R63: 25.281843 | S63: 25.410069 | T63: 25.613623 | U63: 25.618439 | V63: 25.582069 | W63: 25.669821 | X63: 25.620913 | Y63: 25.910242 | Z63: 25.792461 | AA63: 25.723293 | AB63: 25.665987 | AC63: 25.775942 | AD63: 0.0077014346
A64: CNV000:ca_EastoftheMiss | B64: East of the Mississippi | C64: 24.214159 | D64: 24.321152 | E64: 24.097973 | F64: 24.022566 | G64: 24.1607 | H64: 24.042328 | I64: 24.056908 | J64: 24.119301 | K64: 26.897493 | L64: 26.903408 | M64: 26.733852 | N64: 26.74704 | O64: 26.769777 | P64: 26.779171 | Q64: 26.852098 | R64: 26.821299 | S64: 26.807011 | T64: 26.756493 | U64: 26.741901 | V64: 26.692907 | W64: 26.690603 | X64: 26.673883 | Y64: 26.650208 | Z64: 26.663301 | AA64: 26.671719 | AB64: 26.69985 | AC64: 26.704647 | AD64: 0.0037724846
...

Sheet GREET1 Fuel_Specs
A1: Specifications of Fuels, Global Warming Potentials of Greenhouse Gases, and Carbon and Sulfur Ratios of Pollutants
A2: 1) Specifications of Fuels
A3: Fuel | B3: Heating Value | E3: Density | F3: C ratio | G3: S ratio | H3: S ratio
B4: Calculation: LHV | C4: LHV | D4: HHV | F4: (% by wt) | G4: (ppm by wt) | H4: Actual ratio by wt | I4: LHV/HHV
A5: Use LHV or HHV in calculations? | B5: 1 | C5: 1 -- LHV; 2 -- HHV
A6: Liquid Fuels: | B6: Btu/gal | C6: Btu/gal | D6: Btu/gal | E6: grams/gal
A7: Crude oil | B7: 129670 | C7: 129670 | D7: 138350 | E7: 3205 | F7: 0.853 | G7: 16000 | H7: 0.016 | I7: 0.93726057
A8: Synthetic crude oil (SCO) | B8: 135084.91 | C8: 135084.91 | D8: 144475.84 | E8: 3266 | F8: 0.85562069 | G8: 1800 | H8: 0.0018 | I8: 0.935
A9: Bitumen | B9: 152370.9 | C9: 152370.9 | D9: 162963.53 | E9: 3839.6821 | F9: 0.83 | G9: 48000 | H9: 0.048 | I9: 0.935
A10: Dilbit (After Recovery) | B10: 152370.9 | C10: 152370.9 | D10: 162963.53 | E10: 3839.6821 | F10: 0.83 | G10: 48000 | H10: 0.048 | I10: 0.935
A11: Dilbit (Before Recovery) | B11: 145194.19 | C11: 145194.19 | D11: 155287.9 | E11: 3500.4775 | F11: 0.83245886 | G11: 37227.39 | H11: 0.03722739 | I11: 0.935
A12: Diluent | B12: 128448.53 | C12: 128448.53 | D12: 137378.1 | E12: 2709 | F12: 0.84059084 | G12: 1600 | H12: 0.0016 | I12: 0.935
A13: Shale Oil (Bakken) | B13: 125600.91 | C13: 125600.91 | D13: 134008.53 | E13: 3087.2372 | F13: 0.853 | G13: 16000 | H13: 0.016 | I13: 0.93726057
A14: Shale Oil (Eagle Ford) | B14: 122492.61 | C14: 122492.61 | D14: 130692.16 | E14: 2984.0427 | F14: 0.853 | G14: 16000 | H14: 0.016 | I14: 0.93726057
A15: Gasoline blendstock | B15: 116090 | C15: 116090 | D15: 124340 | E15: 2819 | F15: 0.863 | G15: 10 | H15: 1e-05 | I15: 0.93364967
A16: Gasoline | B16: 112193.52 | C16: 112193.52 | D16: 120438.62 | E16: 2835.562 | F16: 0.82778547 | G16: 9.0261788 | H16: 9.0261788e-06 | I16: 0.93154106
A17: CA gasoline | B17: 112193.52 | C17: 112193.52 | D17: 120438.62 | E17: 2835.562 | F17: 0.82778547 | G17: 9.0261788 | H17: 9.0261788e-06 | I17: 0.93154106
A18: High Octane Fuel (E25) | B18: 106150 | C18: 106150 | D18: 114387.5 | E18: 2861.25 | F18: 0.77775 | G18: 7.6425 | H18: 7.6425e-06 | I18: 0.92798601
... A20: U.S. conventional diesel | B20: 128450 | C20: 128450 | D20: 137380 | E20: 3167 | F20: 0.865 | G20: 200 | H20: 0.0002 | I20: 0.93499782
A21: CA diesel | B21: 129487.85 | C21: 129487.85 | D21: 138490 | E21: 3206 | F21: 0.871 | G21: 11 | H21: 1.1e-05
A22: Diesel for non-road engines | B22: 128450 | C22: 128450 | D22: 137380 | E22: 3167 | F22: 0.865 | G22: 11 | H22: 1.1e-05 | I22: 0.93499782
A23: Low-sulfur diesel | B23: 129487.85 | C23: 129487.85 | D23: 138490 | E23: 3206 | F23: 0.871 | G23: 11 | H23: 1.1e-05 | I23: 0.93499782
A24: Petroleum naphtha | B24: 116920 | C24: 116920 | D24: 125080 | E24: 2745 | F24: 0.85 | G24: 1 | H24: 1e-06 | I24: 0.93476175
A25: Low Octane Gasoline-Like Fuel (LOF) | B25: 118237.43 | C25: 118237.43 | D25: 126586.16 | E25: 2833.857 | F25: 0.85315639 | G25: 10 | H25: 1e-05 | I25: 0.93404711
A26: Conventional Jet Fuel | B26: 124307.03 | C26: 124307.03 | D26: 132948.69 | E26: 3035.8996 | F26: 0.862 | G26: 700 | H26: 0.0007 | I26: 0.93500004
A27: ULS Jet Fuel | B27: 123041.23 | C27: 123041.23 | D27: 131594.89 | E27: 2998.0455 | F27: 0.86 | G27: 11 | H27: 1.1e-05 | I27: 0.93500004
A28: NG-based FT naphtha | B28: 111520 | C28: 111520 | D28: 119740 | E28: 2651 | F28: 0.842 | G28: 0 | H28: 0 | I28: 0.93135126
A29: Residual oil | B29: 140352.52 | C29: 140352.52 | D29: 150110 | E29: 3752 | F29: 0.868 | G29: 5000 | H29: 0.005 | I29: 0.93499782
A30: Bunker fuel for ocean tanker | B30: 140352.52 | C30: 140352.52 | D30: 150110 | E30: 3752 | F30: 0.868 | G30: 27000 | H30: 0.027 | I30: 0.93499782
A31: Methanol | B31: 57250 | C31: 57250 | D31: 65200 | E31: 3006 | F31: 0.375 | G31: 0 | H31: 0 | I31: 0.87806748
A32: Ethanol | B32: 76330 | C32: 76330 | D32: 84530 | E32: 2988 | F32: 0.522 | G32: 0.57000011 | H32: 5.7000011e-07 | I32: 0.90299302
A33: Butanol | B33: 99837 | C33: 99837 | D33: 108458 | E33: 3065 | F33: 0.6486 | G33: 0 | H33: 0 | I33: 0.92051301
... A56: Propane | B56: 84250 | C56: 84250 | D56: 91420 | E56: 1920 | F56: 0.818 | G56: 0 | H56: 0 | I56: 0.92157077
A57: Natural gas liquids | B57: 83686.112 | C57: 83686.112 | D57: 90050 | E57: 2532 | G57: 0 | H57: 0 | I57: 0.9293294
A58: n-Hexane | B58: 105124.8 | C58: 105124.8 | D58: 112166.3 | E58: 2478.7 | F58: 0.836251 | G58: 0 | H58: 0 | I58: 0.93722268
A59: Gaseous Fuels (at 32F and 1atm): | B59: Btu/ft3 | C59: Btu/ft3 | D59: Btu/ft3 | E59: gms/ft3 | I59: LHV/HHV
A60: Natural gas | B60: 983 | C60: 983 | D60: 1089 | E60: 22 | F60: 0.724 | G60: 6 | H60: 6e-06 | I60: 0.90266299
A61: Pure Methane | B61: 962.18505 | C61: 962.18505 | D61: 1068.0254 | E61: 20.303179 | F61: 0.75 | G61: 0 | H61: 0 | I61: 0.9009009
A62: Gaseous hydrogen | B62: 290 | C62: 290 | D62: 343 | E62: 2.55 | F62: 0 | G62: 0 | H62: 0 | I62: 0.84548105
A63: Carbon Dioxide | E63: 55.97783 | F63: 0.27272727 | G63: 0 | H63: 0
...

Sheet BCF-BpLFOU
A1: BTU/large fuel output unit | B1: 2024 | C1: 2025 | D1: 2026 | E1: 2027 | F1: 2028 | G1: 2029 | H1: 2030 | I1: 2031 | J1: 2032 | K1: 2033 | L1: 2034 | M1: 2035 | N1: 2036 | O1: 2037 | P1: 2038 | Q1: 2039 | R1: 2040 | S1: 2041 | T1: 2042 | U1: 2043 | V1: 2044 | W1: 2045 | X1: 2046 | Y1: 2047 | Z1: 2048 | AA1: 2049 | AB1: 2050
A2: electricity (not used) | B2: =About!$A$76*10^6 -> 3412140000000 | C2: =About!$A$76*10^6 -> 3412140000000 | D2: =About!$A$76*10^6 -> 3412140000000 | E2: =About!$A$76*10^6 -> 3412140000000 | F2: =About!$A$76*10^6 -> 3412140000000 | G2: =About!$A$76*10^6 -> 3412140000000 | H2: =About!$A$76*10^6 -> 3412140000000 | I2: =About!$A$76*10^6 -> 3412140000000 | ... AB2: =About!$A$76*10^6 -> 3412140000000
A3: hard coal | B3: ='AEO Table 73'!C66*10^12 -> 1.9939119e+13 | C3: ='AEO Table 73'!D66*10^12 -> 1.9975201e+13 | D3: ='AEO Table 73'!E66*10^12 -> 1.9849455e+13 | E3: ='AEO Table 73'!F66*10^12 -> 1.9910885e+13 | F3: ='AEO Table 73'!G66*10^12 -> 1.9778658e+13 | G3: ='AEO Table 73'!H66*10^12 -> 1.9802286e+13 | H3: ='AEO Table 73'!I66*10^12 -> 2.0229092e+13 | I3: ='AEO Table 73'!J66*10^12 -> 2.0271645e+13 | ... AB3: ='AEO Table 73'!AC66*10^12 -> 2.4554193e+13
A4: natural gas | B4: ='AEO Table 73'!C54*10^15 -> 1.036e+15 | C4: ='AEO Table 73'!D54*10^15 -> 1.036e+15 | D4: ='AEO Table 73'!E54*10^15 -> 1.036e+15 | E4: ='AEO Table 73'!F54*10^15 -> 1.036e+15 | F4: ='AEO Table 73'!G54*10^15 -> 1.036e+15 | G4: ='AEO Table 73'!H54*10^15 -> 1.036e+15 | H4: ='AEO Table 73'!I54*10^15 -> 1.036e+15 | I4: ='AEO Table 73'!J54*10^15 -> 1.036e+15 | ... AB4: ='AEO Table 73'!AC54*10^15 -> 1.036e+15
A5: nuclear (not used) | B5: =10^12 -> 1000000000000 | C5: =10^12 -> 1000000000000 | D5: =10^12 -> 1000000000000 | E5: =10^12 -> 1000000000000 | F5: =10^12 -> 1000000000000 | G5: =10^12 -> 1000000000000 | H5: =10^12 -> 1000000000000 | I5: =10^12 -> 1000000000000 | ... AB5: =10^12 -> 1000000000000
A6: hydro (not used) | B6: 0 | C6: 0 | D6: 0 | E6: 0 | F6: 0 | G6: 0 | H6: 0 | I6: 0 | J6: 0 | K6: 0 | L6: 0 | M6: 0 | N6: 0 | O6: 0 | P6: 0 | Q6: 0 | R6: 0 | S6: 0 | T6: 0 | U6: 0 | V6: 0 | W6: 0 | X6: 0 | Y6: 0 | Z6: 0 | AA6: 0 | AB6: 0
A7: wind (not used) | B7: 0 | C7: 0 | D7: 0 | E7: 0 | F7: 0 | G7: 0 | H7: 0 | I7: 0 | J7: 0 | K7: 0 | L7: 0 | M7: 0 | N7: 0 | O7: 0 | P7: 0 | Q7: 0 | R7: 0 | S7: 0 | T7: 0 | U7: 0 | V7: 0 | W7: 0 | X7: 0 | Y7: 0 | Z7: 0 | AA7: 0 | AB7: 0
A8: solar (not used) | B8: 0 | C8: 0 | D8: 0 | E8: 0 | F8: 0 | G8: 0 | H8: 0 | I8: 0 | J8: 0 | K8: 0 | L8: 0 | M8: 0 | N8: 0 | O8: 0 | P8: 0 | Q8: 0 | R8: 0 | S8: 0 | T8: 0 | U8: 0 | V8: 0 | W8: 0 | X8: 0 | Y8: 0 | Z8: 0 | AA8: 0 | AB8: 0
A9: biomass | B9: ='GREET1 Fuel_Specs'!$D$81*10^6 -> 17906000000000 | C9: ='GREET1 Fuel_Specs'!$D$81*10^6 -> 17906000000000 | D9: ='GREET1 Fuel_Specs'!$D$81*10^6 -> 17906000000000 | E9: ='GREET1 Fuel_Specs'!$D$81*10^6 -> 17906000000000 | F9: ='GREET1 Fuel_Specs'!$D$81*10^6 -> 17906000000000 | G9: ='GREET1 Fuel_Specs'!$D$81*10^6 -> 17906000000000 | H9: ='GREET1 Fuel_Specs'!$D$81*10^6 -> 17906000000000 | I9: ='GREET1 Fuel_Specs'!$D$81*10^6 -> 17906000000000 | ... AB9: ='GREET1 Fuel_Specs'!$D$81*10^6 -> 17906000000000
A10: petroleum gasoline | B10: ='GREET1 Fuel_Specs'!$D$7*gal_per_barrel*10^6 -> 5810700000000 | C10: ='GREET1 Fuel_Specs'!$D$7*gal_per_barrel*10^6 -> 5810700000000 | D10: ='GREET1 Fuel_Specs'!$D$7*gal_per_barrel*10^6 -> 5810700000000 | E10: ='GREET1 Fuel_Specs'!$D$7*gal_per_barrel*10^6 -> 5810700000000 | F10: ='GREET1 Fuel_Specs'!$D$7*gal_per_barrel*10^6 -> 5810700000000 | G10: ='GREET1 Fuel_Specs'!$D$7*gal_per_barrel*10^6 -> 5810700000000 | H10: ='GREET1 Fuel_Specs'!$D$7*gal_per_barrel*10^6 -> 5810700000000 | I10: ='GREET1 Fuel_Specs'!$D$7*gal_per_barrel*10^6 -> 5810700000000 | ... AB10: ='GREET1 Fuel_Specs'!$D$7*gal_per_barrel*10^6 -> 5810700000000
A11: petroleum diesel | B11: ='GREET1 Fuel_Specs'!$D$7*gal_per_barrel*10^6 -> 5810700000000 | C11: ='GREET1 Fuel_Specs'!$D$7*gal_per_barrel*10^6 -> 5810700000000 | D11: ='GREET1 Fuel_Specs'!$D$7*gal_per_barrel*10^6 -> 5810700000000 | E11: ='GREET1 Fuel_Specs'!$D$7*gal_per_barrel*10^6 -> 5810700000000 | F11: ='GREET1 Fuel_Specs'!$D$7*gal_per_barrel*10^6 -> 5810700000000 | G11: ='GREET1 Fuel_Specs'!$D$7*gal_per_barrel*10^6 -> 5810700000000 | H11: ='GREET1 Fuel_Specs'!$D$7*gal_per_barrel*10^6 -> 5810700000000 | I11: ='GREET1 Fuel_Specs'!$D$7*gal_per_barrel*10^6 -> 5810700000000 | ... AB11: ='GREET1 Fuel_Specs'!$D$7*gal_per_barrel*10^6 -> 5810700000000
A12: biofuel gasoline | B12: ='GREET1 Fuel_Specs'!$D$7*gal_per_barrel*10^6 -> 5810700000000 | C12: ='GREET1 Fuel_Specs'!$D$7*gal_per_barrel*10^6 -> 5810700000000 | D12: ='GREET1 Fuel_Specs'!$D$7*gal_per_barrel*10^6 -> 5810700000000 | E12: ='GREET1 Fuel_Specs'!$D$7*gal_per_barrel*10^6 -> 5810700000000 | F12: ='GREET1 Fuel_Specs'!$D$7*gal_per_barrel*10^6 -> 5810700000000 | G12: ='GREET1 Fuel_Specs'!$D$7*gal_per_barrel*10^6 -> 5810700000000 | H12: ='GREET1 Fuel_Specs'!$D$7*gal_per_barrel*10^6 -> 5810700000000 | I12: ='GREET1 Fuel_Specs'!$D$7*gal_per_barrel*10^6 -> 5810700000000 | ... AB12: ='GREET1 Fuel_Specs'!$D$7*gal_per_barrel*10^6 -> 5810700000000
A13: biofuel diesel | B13: ='GREET1 Fuel_Specs'!$D$7*gal_per_barrel*10^6 -> 5810700000000 | C13: ='GREET1 Fuel_Specs'!$D$7*gal_per_barrel*10^6 -> 5810700000000 | D13: ='GREET1 Fuel_Specs'!$D$7*gal_per_barrel*10^6 -> 5810700000000 | E13: ='GREET1 Fuel_Specs'!$D$7*gal_per_barrel*10^6 -> 5810700000000 | F13: ='GREET1 Fuel_Specs'!$D$7*gal_per_barrel*10^6 -> 5810700000000 | G13: ='GREET1 Fuel_Specs'!$D$7*gal_per_barrel*10^6 -> 5810700000000 | H13: ='GREET1 Fuel_Specs'!$D$7*gal_per_barrel*10^6 -> 5810700000000 | I13: ='GREET1 Fuel_Specs'!$D$7*gal_per_barrel*10^6 -> 5810700000000 | ... AB13: ='GREET1 Fuel_Specs'!$D$7*gal_per_barrel*10^6 -> 5810700000000
A14: jet fuel or kerosene | B14: ='GREET1 Fuel_Specs'!$D$7*gal_per_barrel*10^6 -> 5810700000000 | C14: ='GREET1 Fuel_Specs'!$D$7*gal_per_barrel*10^6 -> 5810700000000 | D14: ='GREET1 Fuel_Specs'!$D$7*gal_per_barrel*10^6 -> 5810700000000 | E14: ='GREET1 Fuel_Specs'!$D$7*gal_per_barrel*10^6 -> 5810700000000 | F14: ='GREET1 Fuel_Specs'!$D$7*gal_per_barrel*10^6 -> 5810700000000 | G14: ='GREET1 Fuel_Specs'!$D$7*gal_per_barrel*10^6 -> 5810700000000 | H14: ='GREET1 Fuel_Specs'!$D$7*gal_per_barrel*10^6 -> 5810700000000 | I14: ='GREET1 Fuel_Specs'!$D$7*gal_per_barrel*10^6 -> 5810700000000 | ... AB14: ='GREET1 Fuel_Specs'!$D$7*gal_per_barrel*10^6 -> 5810700000000
A15: heat (not used) | B15: =About!$A$76*10^6 -> 3412140000000 | C15: =About!$A$76*10^6 -> 3412140000000 | D15: =About!$A$76*10^6 -> 3412140000000 | E15: =About!$A$76*10^6 -> 3412140000000 | F15: =About!$A$76*10^6 -> 3412140000000 | G15: =About!$A$76*10^6 -> 3412140000000 | H15: =About!$A$76*10^6 -> 3412140000000 | I15: =About!$A$76*10^6 -> 3412140000000 | ... AB15: =About!$A$76*10^6 -> 3412140000000
A16: geothermal (not used) | B16: 0 | C16: 0 | D16: 0 | E16: 0 | F16: 0 | G16: 0 | H16: 0 | I16: 0 | J16: 0 | K16: 0 | L16: 0 | M16: 0 | N16: 0 | O16: 0 | P16: 0 | Q16: 0 | R16: 0 | S16: 0 | T16: 0 | U16: 0 | V16: 0 | W16: 0 | X16: 0 | Y16: 0 | Z16: 0 | AA16: 0 | AB16: 0
A17: lignite | B17: ='GREET1 Fuel_Specs'!$D$69*10^6 -> 1.2992302e+13 | C17: ='GREET1 Fuel_Specs'!$D$69*10^6 -> 1.2992302e+13 | D17: ='GREET1 Fuel_Specs'!$D$69*10^6 -> 1.2992302e+13 | E17: ='GREET1 Fuel_Specs'!$D$69*10^6 -> 1.2992302e+13 | F17: ='GREET1 Fuel_Specs'!$D$69*10^6 -> 1.2992302e+13 | G17: ='GREET1 Fuel_Specs'!$D$69*10^6 -> 1.2992302e+13 | H17: ='GREET1 Fuel_Specs'!$D$69*10^6 -> 1.2992302e+13 | I17: ='GREET1 Fuel_Specs'!$D$69*10^6 -> 1.2992302e+13 | ... AB17: ='GREET1 Fuel_Specs'!$D$69*10^6 -> 1.2992302e+13
A18: crude oil | B18: ='GREET1 Fuel_Specs'!$D$7*gal_per_barrel*10^6 -> 5810700000000 | C18: ='GREET1 Fuel_Specs'!$D$7*gal_per_barrel*10^6 -> 5810700000000 | D18: ='GREET1 Fuel_Specs'!$D$7*gal_per_barrel*10^6 -> 5810700000000 | E18: ='GREET1 Fuel_Specs'!$D$7*gal_per_barrel*10^6 -> 5810700000000 | F18: ='GREET1 Fuel_Specs'!$D$7*gal_per_barrel*10^6 -> 5810700000000 | G18: ='GREET1 Fuel_Specs'!$D$7*gal_per_barrel*10^6 -> 5810700000000 | H18: ='GREET1 Fuel_Specs'!$D$7*gal_per_barrel*10^6 -> 5810700000000 | I18: ='GREET1 Fuel_Specs'!$D$7*gal_per_barrel*10^6 -> 5810700000000 | ... AB18: ='GREET1 Fuel_Specs'!$D$7*gal_per_barrel*10^6 -> 5810700000000
A19: heavy fuel oil | B19: ='GREET1 Fuel_Specs'!$D$7*gal_per_barrel*10^6 -> 5810700000000 | C19: ='GREET1 Fuel_Specs'!$D$7*gal_per_barrel*10^6 -> 5810700000000 | D19: ='GREET1 Fuel_Specs'!$D$7*gal_per_barrel*10^6 -> 5810700000000 | E19: ='GREET1 Fuel_Specs'!$D$7*gal_per_barrel*10^6 -> 5810700000000 | F19: ='GREET1 Fuel_Specs'!$D$7*gal_per_barrel*10^6 -> 5810700000000 | G19: ='GREET1 Fuel_Specs'!$D$7*gal_per_barrel*10^6 -> 5810700000000 | H19: ='GREET1 Fuel_Specs'!$D$7*gal_per_barrel*10^6 -> 5810700000000 | I19: ='GREET1 Fuel_Specs'!$D$7*gal_per_barrel*10^6 -> 5810700000000 | ... AB19: ='GREET1 Fuel_Specs'!$D$7*gal_per_barrel*10^6 -> 5810700000000
A20: LPG propane or butane | B20: ='GREET1 Fuel_Specs'!$D$36*10^6 -> 91410000000 | C20: ='GREET1 Fuel_Specs'!$D$36*10^6 -> 91410000000 | D20: ='GREET1 Fuel_Specs'!$D$36*10^6 -> 91410000000 | E20: ='GREET1 Fuel_Specs'!$D$36*10^6 -> 91410000000 | F20: ='GREET1 Fuel_Specs'!$D$36*10^6 -> 91410000000 | G20: ='GREET1 Fuel_Specs'!$D$36*10^6 -> 91410000000 | H20: ='GREET1 Fuel_Specs'!$D$36*10^6 -> 91410000000 | I20: ='GREET1 Fuel_Specs'!$D$36*10^6 -> 91410000000 | ... AB20: ='GREET1 Fuel_Specs'!$D$36*10^6 -> 91410000000
A21: municipal solid waste | B21: ='GREET1 Fuel_Specs'!$D$90*10^6 -> 1.3583445e+13 | C21: ='GREET1 Fuel_Specs'!$D$90*10^6 -> 1.3583445e+13 | D21: ='GREET1 Fuel_Specs'!$D$90*10^6 -> 1.3583445e+13 | E21: ='GREET1 Fuel_Specs'!$D$90*10^6 -> 1.3583445e+13 | F21: ='GREET1 Fuel_Specs'!$D$90*10^6 -> 1.3583445e+13 | G21: ='GREET1 Fuel_Specs'!$D$90*10^6 -> 1.3583445e+13 | H21: ='GREET1 Fuel_Specs'!$D$90*10^6 -> 1.3583445e+13 | I21: ='GREET1 Fuel_Specs'!$D$90*10^6 -> 1.3583445e+13 | ... AB21: ='GREET1 Fuel_Specs'!$D$90*10^6 -> 1.3583445e+13
A22: hydrogen | B22: ='GREET1 Fuel_Specs'!$D$62/'GREET1 Fuel_Specs'!$E$62*10^9 -> 1.345098e+11 | C22: ='GREET1 Fuel_Specs'!$D$62/'GREET1 Fuel_Specs'!$E$62*10^9 -> 1.345098e+11 | D22: ='GREET1 Fuel_Specs'!$D$62/'GREET1 Fuel_Specs'!$E$62*10^9 -> 1.345098e+11 | E22: ='GREET1 Fuel_Specs'!$D$62/'GREET1 Fuel_Specs'!$E$62*10^9 -> 1.345098e+11 | F22: ='GREET1 Fuel_Specs'!$D$62/'GREET1 Fuel_Specs'!$E$62*10^9 -> 1.345098e+11 | G22: ='GREET1 Fuel_Specs'!$D$62/'GREET1 Fuel_Specs'!$E$62*10^9 -> 1.345098e+11 | H22: ='GREET1 Fuel_Specs'!$D$62/'GREET1 Fuel_Specs'!$E$62*10^9 -> 1.345098e+11 | I22: ='GREET1 Fuel_Specs'!$D$62/'GREET1 Fuel_Specs'!$E$62*10^9 -> 1.345098e+11 | ... AB22: ='GREET1 Fuel_Specs'!$D$62/'GREET1 Fuel_Specs'!$E$62*10^9 -> 1.345098e+11

Sheet BCF-BpSFOU
A1: BTU/small fuel output unit | B1: 2024 | C1: 2025 | D1: 2026 | E1: 2027 | F1: 2028 | G1: 2029 | H1: 2030 | I1: 2031 | J1: 2032 | K1: 2033 | L1: 2034 | M1: 2035 | N1: 2036 | O1: 2037 | P1: 2038 | Q1: 2039 | R1: 2040 | S1: 2041 | T1: 2042 | U1: 2043 | V1: 2044 | W1: 2045 | X1: 2046 | Y1: 2047 | Z1: 2048 | AA1: 2049 | AB1: 2050
A2: electricity | B2: =About!$A$76 -> 3412140 | C2: =About!$A$76 -> 3412140 | D2: =About!$A$76 -> 3412140 | E2: =About!$A$76 -> 3412140 | F2: =About!$A$76 -> 3412140 | G2: =About!$A$76 -> 3412140 | H2: =About!$A$76 -> 3412140 | I2: =About!$A$76 -> 3412140 | ... AB2: =About!$A$76 -> 3412140
A3: hard coal | B3: ='AEO Table 73'!C66*10^6 -> 19939119 | C3: ='AEO Table 73'!D66*10^6 -> 19975201 | D3: ='AEO Table 73'!E66*10^6 -> 19849455 | E3: ='AEO Table 73'!F66*10^6 -> 19910885 | F3: ='AEO Table 73'!G66*10^6 -> 19778658 | G3: ='AEO Table 73'!H66*10^6 -> 19802286 | H3: ='AEO Table 73'!I66*10^6 -> 20229092 | I3: ='AEO Table 73'!J66*10^6 -> 20271645 | ... AB3: ='AEO Table 73'!AC66*10^6 -> 24554193
A4: natural gas | B4: ='AEO Table 73'!C54*10^6 -> 1036000 | C4: ='AEO Table 73'!D54*10^6 -> 1036000 | D4: ='AEO Table 73'!E54*10^6 -> 1036000 | E4: ='AEO Table 73'!F54*10^6 -> 1036000 | F4: ='AEO Table 73'!G54*10^6 -> 1036000 | G4: ='AEO Table 73'!H54*10^6 -> 1036000 | H4: ='AEO Table 73'!I54*10^6 -> 1036000 | I4: ='AEO Table 73'!J54*10^6 -> 1036000 | ... AB4: ='AEO Table 73'!AC54*10^6 -> 1036000
A5: nuclear | B5: =10^6 -> 1000000 | C5: =10^6 -> 1000000 | D5: =10^6 -> 1000000 | E5: =10^6 -> 1000000 | F5: =10^6 -> 1000000 | G5: =10^6 -> 1000000 | H5: =10^6 -> 1000000 | I5: =10^6 -> 1000000 | ... AB5: =10^6 -> 1000000
A6: hydro (not used) | B6: 0 | C6: 0 | D6: 0 | E6: 0 | F6: 0 | G6: 0 | H6: 0 | I6: 0 | J6: 0 | K6: 0 | L6: 0 | M6: 0 | N6: 0 | O6: 0 | P6: 0 | Q6: 0 | R6: 0 | S6: 0 | T6: 0 | U6: 0 | V6: 0 | W6: 0 | X6: 0 | Y6: 0 | Z6: 0 | AA6: 0 | AB6: 0
A7: wind (not used) | B7: 0 | C7: 0 | D7: 0 | E7: 0 | F7: 0 | G7: 0 | H7: 0 | I7: 0 | J7: 0 | K7: 0 | L7: 0 | M7: 0 | N7: 0 | O7: 0 | P7: 0 | Q7: 0 | R7: 0 | S7: 0 | T7: 0 | U7: 0 | V7: 0 | W7: 0 | X7: 0 | Y7: 0 | Z7: 0 | AA7: 0 | AB7: 0
A8: solar (not used) | B8: 0 | C8: 0 | D8: 0 | E8: 0 | F8: 0 | G8: 0 | H8: 0 | I8: 0 | J8: 0 | K8: 0 | L8: 0 | M8: 0 | N8: 0 | O8: 0 | P8: 0 | Q8: 0 | R8: 0 | S8: 0 | T8: 0 | U8: 0 | V8: 0 | W8: 0 | X8: 0 | Y8: 0 | Z8: 0 | AA8: 0 | AB8: 0
A9: biomass | B9: ='GREET1 Fuel_Specs'!$D$81 -> 17906000 | C9: ='GREET1 Fuel_Specs'!$D$81 -> 17906000 | D9: ='GREET1 Fuel_Specs'!$D$81 -> 17906000 | E9: ='GREET1 Fuel_Specs'!$D$81 -> 17906000 | F9: ='GREET1 Fuel_Specs'!$D$81 -> 17906000 | G9: ='GREET1 Fuel_Specs'!$D$81 -> 17906000 | H9: ='GREET1 Fuel_Specs'!$D$81 -> 17906000 | I9: ='GREET1 Fuel_Specs'!$D$81 -> 17906000 | ... AB9: ='GREET1 Fuel_Specs'!$D$81 -> 17906000
A10: petroleum gasoline | B10: ='AEO Table 73'!C32*10^6/gal_per_barrel -> 120223.06 | C10: ='AEO Table 73'!D32*10^6/gal_per_barrel -> 120195.14 | D10: ='AEO Table 73'!E32*10^6/gal_per_barrel -> 120166.69 | E10: ='AEO Table 73'!F32*10^6/gal_per_barrel -> 120138.07 | F10: ='AEO Table 73'!G32*10^6/gal_per_barrel -> 120109.29 | G10: ='AEO Table 73'!H32*10^6/gal_per_barrel -> 120080.4 | H10: ='AEO Table 73'!I32*10^6/gal_per_barrel -> 120051.26 | I10: ='AEO Table 73'!J32*10^6/gal_per_barrel -> 120022.1 | ... AB10: ='AEO Table 73'!AC32*10^6/gal_per_barrel -> 119565.13
A11: petroleum diesel | B11: ='AEO Table 73'!C19*10^6/gal_per_barrel -> 138690.47 | C11: ='AEO Table 73'!D19*10^6/gal_per_barrel -> 138690.47 | D11: ='AEO Table 73'!E19*10^6/gal_per_barrel -> 138690.47 | E11: ='AEO Table 73'!F19*10^6/gal_per_barrel -> 138690.47 | F11: ='AEO Table 73'!G19*10^6/gal_per_barrel -> 138690.47 | G11: ='AEO Table 73'!H19*10^6/gal_per_barrel -> 138690.47 | H11: ='AEO Table 73'!I19*10^6/gal_per_barrel -> 138690.47 | I11: ='AEO Table 73'!J19*10^6/gal_per_barrel -> 138690.47 | ... AB11: ='AEO Table 73'!AC19*10^6/gal_per_barrel -> 138690.47
A12: biofuel gasoline | B12: ='AEO Table 73'!C29*10^6/gal_per_barrel -> 95105.069 | C12: ='AEO Table 73'!D29*10^6/gal_per_barrel -> 95105.069 | D12: ='AEO Table 73'!E29*10^6/gal_per_barrel -> 95105.069 | E12: ='AEO Table 73'!F29*10^6/gal_per_barrel -> 95105.069 | F12: ='AEO Table 73'!G29*10^6/gal_per_barrel -> 95105.069 | G12: ='AEO Table 73'!H29*10^6/gal_per_barrel -> 95105.069 | H12: ='AEO Table 73'!I29*10^6/gal_per_barrel -> 95105.069 | I12: ='AEO Table 73'!J29*10^6/gal_per_barrel -> 95105.069 | ... AB12: ='AEO Table 73'!AC29*10^6/gal_per_barrel -> 95105.069
A13: biofuel diesel | B13: ='AEO Table 73'!C18*10^6/gal_per_barrel -> 127595.24 | C13: ='AEO Table 73'!D18*10^6/gal_per_barrel -> 127595.24 | D13: ='AEO Table 73'!E18*10^6/gal_per_barrel -> 127595.24 | E13: ='AEO Table 73'!F18*10^6/gal_per_barrel -> 127595.24 | F13: ='AEO Table 73'!G18*10^6/gal_per_barrel -> 127595.24 | G13: ='AEO Table 73'!H18*10^6/gal_per_barrel -> 127595.24 | H13: ='AEO Table 73'!I18*10^6/gal_per_barrel -> 127595.24 | I13: ='AEO Table 73'!J18*10^6/gal_per_barrel -> 127595.24 | ... AB13: ='AEO Table 73'!AC18*10^6/gal_per_barrel -> 127595.24
A14: jet fuel or kerosene | B14: ='AEO Table 73'!C30*10^6/gal_per_barrel -> 135000 | C14: ='AEO Table 73'!D30*10^6/gal_per_barrel -> 135000 | D14: ='AEO Table 73'!E30*10^6/gal_per_barrel -> 135000 | E14: ='AEO Table 73'!F30*10^6/gal_per_barrel -> 135000 | F14: ='AEO Table 73'!G30*10^6/gal_per_barrel -> 135000 | G14: ='AEO Table 73'!H30*10^6/gal_per_barrel -> 135000 | H14: ='AEO Table 73'!I30*10^6/gal_per_barrel -> 135000 | I14: ='AEO Table 73'!J30*10^6/gal_per_barrel -> 135000 | ... AB14: ='AEO Table 73'!AC30*10^6/gal_per_barrel -> 135000
A15: heat | B15: =About!$A$76 -> 3412140 | C15: =About!$A$76 -> 3412140 | D15: =About!$A$76 -> 3412140 | E15: =About!$A$76 -> 3412140 | F15: =About!$A$76 -> 3412140 | G15: =About!$A$76 -> 3412140 | H15: =About!$A$76 -> 3412140 | I15: =About!$A$76 -> 3412140 | ... AB15: =About!$A$76 -> 3412140
A16: geothermal (not used) | B16: 0 | C16: 0 | D16: 0 | E16: 0 | F16: 0 | G16: 0 | H16: 0 | I16: 0 | J16: 0 | K16: 0 | L16: 0 | M16: 0 | N16: 0 | O16: 0 | P16: 0 | Q16: 0 | R16: 0 | S16: 0 | T16: 0 | U16: 0 | V16: 0 | W16: 0 | X16: 0 | Y16: 0 | Z16: 0 | AA16: 0 | AB16: 0
A17: lignite | B17: ='GREET1 Fuel_Specs'!$D$69 -> 12992302 | C17: ='GREET1 Fuel_Specs'!$D$69 -> 12992302 | D17: ='GREET1 Fuel_Specs'!$D$69 -> 12992302 | E17: ='GREET1 Fuel_Specs'!$D$69 -> 12992302 | F17: ='GREET1 Fuel_Specs'!$D$69 -> 12992302 | G17: ='GREET1 Fuel_Specs'!$D$69 -> 12992302 | H17: ='GREET1 Fuel_Specs'!$D$69 -> 12992302 | I17: ='GREET1 Fuel_Specs'!$D$69 -> 12992302 | ... AB17: ='GREET1 Fuel_Specs'!$D$69 -> 12992302
A18: crude oil | B18: ='GREET1 Fuel_Specs'!$D$7*gal_per_barrel -> 5810700 | C18: ='GREET1 Fuel_Specs'!$D$7*gal_per_barrel -> 5810700 | D18: ='GREET1 Fuel_Specs'!$D$7*gal_per_barrel -> 5810700 | E18: ='GREET1 Fuel_Specs'!$D$7*gal_per_barrel -> 5810700 | F18: ='GREET1 Fuel_Specs'!$D$7*gal_per_barrel -> 5810700 | G18: ='GREET1 Fuel_Specs'!$D$7*gal_per_barrel -> 5810700 | H18: ='GREET1 Fuel_Specs'!$D$7*gal_per_barrel -> 5810700 | I18: ='GREET1 Fuel_Specs'!$D$7*gal_per_barrel -> 5810700 | ... AB18: ='GREET1 Fuel_Specs'!$D$7*gal_per_barrel -> 5810700
A19: heavy fuel oil | B19: ='GREET1 Fuel_Specs'!$D$7*gal_per_barrel -> 5810700 | C19: ='GREET1 Fuel_Specs'!$D$7*gal_per_barrel -> 5810700 | D19: ='GREET1 Fuel_Specs'!$D$7*gal_per_barrel -> 5810700 | E19: ='GREET1 Fuel_Specs'!$D$7*gal_per_barrel -> 5810700 | F19: ='GREET1 Fuel_Specs'!$D$7*gal_per_barrel -> 5810700 | G19: ='GREET1 Fuel_Specs'!$D$7*gal_per_barrel -> 5810700 | H19: ='GREET1 Fuel_Specs'!$D$7*gal_per_barrel -> 5810700 | I19: ='GREET1 Fuel_Specs'!$D$7*gal_per_barrel -> 5810700 | ... AB19: ='GREET1 Fuel_Specs'!$D$7*gal_per_barrel -> 5810700
A20: LPG propane or butane | B20: ='GREET1 Fuel_Specs'!$D$36 -> 91410 | C20: ='GREET1 Fuel_Specs'!$D$36 -> 91410 | D20: ='GREET1 Fuel_Specs'!$D$36 -> 91410 | E20: ='GREET1 Fuel_Specs'!$D$36 -> 91410 | F20: ='GREET1 Fuel_Specs'!$D$36 -> 91410 | G20: ='GREET1 Fuel_Specs'!$D$36 -> 91410 | H20: ='GREET1 Fuel_Specs'!$D$36 -> 91410 | I20: ='GREET1 Fuel_Specs'!$D$36 -> 91410 | ... AB20: ='GREET1 Fuel_Specs'!$D$36 -> 91410
A21: municipal solid waste | B21: ='GREET1 Fuel_Specs'!$D$90 -> 13583445 | C21: ='GREET1 Fuel_Specs'!$D$90 -> 13583445 | D21: ='GREET1 Fuel_Specs'!$D$90 -> 13583445 | E21: ='GREET1 Fuel_Specs'!$D$90 -> 13583445 | F21: ='GREET1 Fuel_Specs'!$D$90 -> 13583445 | G21: ='GREET1 Fuel_Specs'!$D$90 -> 13583445 | H21: ='GREET1 Fuel_Specs'!$D$90 -> 13583445 | I21: ='GREET1 Fuel_Specs'!$D$90 -> 13583445 | ... AB21: ='GREET1 Fuel_Specs'!$D$90 -> 13583445
A22: hydrogen | B22: ='GREET1 Fuel_Specs'!$D$62/'GREET1 Fuel_Specs'!$E$62*10^3 -> 134509.8 | C22: ='GREET1 Fuel_Specs'!$D$62/'GREET1 Fuel_Specs'!$E$62*10^3 -> 134509.8 | D22: ='GREET1 Fuel_Specs'!$D$62/'GREET1 Fuel_Specs'!$E$62*10^3 -> 134509.8 | E22: ='GREET1 Fuel_Specs'!$D$62/'GREET1 Fuel_Specs'!$E$62*10^3 -> 134509.8 | F22: ='GREET1 Fuel_Specs'!$D$62/'GREET1 Fuel_Specs'!$E$62*10^3 -> 134509.8 | G22: ='GREET1 Fuel_Specs'!$D$62/'GREET1 Fuel_Specs'!$E$62*10^3 -> 134509.8 | H22: ='GREET1 Fuel_Specs'!$D$62/'GREET1 Fuel_Specs'!$E$62*10^3 -> 134509.8 | I22: ='GREET1 Fuel_Specs'!$D$62/'GREET1 Fuel_Specs'!$E$62*10^3 -> 134509.8 | ... AB22: ='GREET1 Fuel_Specs'!$D$62/'GREET1 Fuel_Specs'!$E$62*10^3 -> 134509.8

Sheet BCF-VFEUCF
A1: Conversion Factor (output fuel economy unit/(miles/BTU)) | B1: 2024 | C1: 2025 | D1: 2026 | E1: 2027 | F1: 2028 | G1: 2029 | H1: 2030 | I1: 2031 | J1: 2032 | K1: 2033 | L1: 2034 | M1: 2035 | N1: 2036 | O1: 2037 | P1: 2038 | Q1: 2039 | R1: 2040 | S1: 2041 | T1: 2042 | U1: 2043 | V1: 2044 | W1: 2045 | X1: 2046 | Y1: 2047 | Z1: 2048 | AA1: 2049
A2: Electricity | B2: 0 | C2: 0 | D2: 0 | E2: 0 | F2: 0 | G2: 0 | H2: 0 | I2: 0 | J2: 0 | K2: 0 | L2: 0 | M2: 0 | N2: 0 | O2: 0 | P2: 0 | Q2: 0 | R2: 0 | S2: 0 | T2: 0 | U2: 0 | V2: 0 | W2: 0 | X2: 0 | Y2: 0 | Z2: 0 | AA2: 0 | AC2: 0
A3: Natural Gas | B3: 0 | C3: 0 | D3: 0 | E3: 0 | F3: 0 | G3: 0 | H3: 0 | I3: 0 | J3: 0 | K3: 0 | L3: 0 | M3: 0 | N3: 0 | O3: 0 | P3: 0 | Q3: 0 | R3: 0 | S3: 0 | T3: 0 | U3: 0 | V3: 0 | W3: 0 | X3: 0 | Y3: 0 | Z3: 0 | AA3: 0 | AC3: 0
A4: Petroleum Gasoline (fuel economy units) | B4: ='AEO Table 73'!C32*10^6/gal_per_barrel -> 120223.06 | C4: ='AEO Table 73'!D32*10^6/gal_per_barrel -> 120195.14 | D4: ='AEO Table 73'!E32*10^6/gal_per_barrel -> 120166.69 | E4: ='AEO Table 73'!F32*10^6/gal_per_barrel -> 120138.07 | F4: ='AEO Table 73'!G32*10^6/gal_per_barrel -> 120109.29 | G4: ='AEO Table 73'!H32*10^6/gal_per_barrel -> 120080.4 | H4: ='AEO Table 73'!I32*10^6/gal_per_barrel -> 120051.26 | I4: ='AEO Table 73'!J32*10^6/gal_per_barrel -> 120022.1 | ... AA4: ='AEO Table 73'!AB32*10^6/gal_per_barrel -> 119586.73 | AC4: ='AEO Table 73'!AD32*10^6/gal_per_barrel -> -5.0246876
A5: Petroleum Diesel (fuel economy units) | B5: ='AEO Table 73'!C19*10^6/gal_per_barrel -> 138690.47 | C5: ='AEO Table 73'!D19*10^6/gal_per_barrel -> 138690.47 | D5: ='AEO Table 73'!E19*10^6/gal_per_barrel -> 138690.47 | E5: ='AEO Table 73'!F19*10^6/gal_per_barrel -> 138690.47 | F5: ='AEO Table 73'!G19*10^6/gal_per_barrel -> 138690.47 | G5: ='AEO Table 73'!H19*10^6/gal_per_barrel -> 138690.47 | H5: ='AEO Table 73'!I19*10^6/gal_per_barrel -> 138690.47 | I5: ='AEO Table 73'!J19*10^6/gal_per_barrel -> 138690.47 | ... AA5: ='AEO Table 73'!AB19*10^6/gal_per_barrel -> 138690.47 | AC5: ='AEO Table 73'!AD19*10^6/gal_per_barrel -> 0
A6: Biofuel Gasoline | B6: 0 | C6: 0 | D6: 0 | E6: 0 | F6: 0 | G6: 0 | H6: 0 | I6: 0 | J6: 0 | K6: 0 | L6: 0 | M6: 0 | N6: 0 | O6: 0 | P6: 0 | Q6: 0 | R6: 0 | S6: 0 | T6: 0 | U6: 0 | V6: 0 | W6: 0 | X6: 0 | Y6: 0 | Z6: 0 | AA6: 0 | AC6: 0
A7: Biofuel Diesel | B7: 0 | C7: 0 | D7: 0 | E7: 0 | F7: 0 | G7: 0 | H7: 0 | I7: 0 | J7: 0 | K7: 0 | L7: 0 | M7: 0 | N7: 0 | O7: 0 | P7: 0 | Q7: 0 | R7: 0 | S7: 0 | T7: 0 | U7: 0 | V7: 0 | W7: 0 | X7: 0 | Y7: 0 | Z7: 0 | AA7: 0 | AC7: 0
A8: Jet Fuel (fuel economy units) | B8: ='AEO Table 73'!C30*10^6/gal_per_barrel -> 135000 | C8: ='AEO Table 73'!D30*10^6/gal_per_barrel -> 135000 | D8: ='AEO Table 73'!E30*10^6/gal_per_barrel -> 135000 | E8: ='AEO Table 73'!F30*10^6/gal_per_barrel -> 135000 | F8: ='AEO Table 73'!G30*10^6/gal_per_barrel -> 135000 | G8: ='AEO Table 73'!H30*10^6/gal_per_barrel -> 135000 | H8: ='AEO Table 73'!I30*10^6/gal_per_barrel -> 135000 | I8: ='AEO Table 73'!J30*10^6/gal_per_barrel -> 135000 | ... AA8: ='AEO Table 73'!AB30*10^6/gal_per_barrel -> 135000 | AC8: ='AEO Table 73'!AD30*10^6/gal_per_barrel -> 0
A9: heavy or residual fuel oil | B9: 0 | C9: 0 | D9: 0 | E9: 0 | F9: 0 | G9: 0 | H9: 0 | I9: 0 | J9: 0 | K9: 0 | L9: 0 | M9: 0 | N9: 0 | O9: 0 | P9: 0 | Q9: 0 | R9: 0 | S9: 0 | T9: 0 | U9: 0 | V9: 0 | W9: 0 | X9: 0 | Y9: 0 | Z9: 0 | AA9: 0 | AC9: 0
A10: LPG propane or butane | B10: 0 | C10: 0 | D10: 0 | E10: 0 | F10: 0 | G10: 0 | H10: 0 | I10: 0 | J10: 0 | K10: 0 | L10: 0 | M10: 0 | N10: 0 | O10: 0 | P10: 0 | Q10: 0 | R10: 0 | S10: 0 | T10: 0 | U10: 0 | V10: 0 | W10: 0 | X10: 0 | Y10: 0 | Z10: 0 | AA10: 0 | AC10: 0
A11: hydrogen | B11: 0 | C11: 0 | D11: 0 | E11: 0 | F11: 0 | G11: 0 | H11: 0 | I11: 0 | J11: 0 | K11: 0 | L11: 0 | M11: 0 | N11: 0 | O11: 0 | P11: 0 | Q11: 0 | R11: 0 | S11: 0 | T11: 0 | U11: 0 | V11: 0 | W11: 0 | X11: 0 | Y11: 0 | Z11: 0 | AA11: 0 | AC11: 0

Sheet BCF-BpEIEOU
B1: Energy Import Export Output Unit (BTU/energy output unit)
A2: BTU | B2: =CONVERT(About!A77,"kg","lbm")*1000000000 -> 1.3451064e+14

Sheet BCF-BpMMTH
A1: btu/MMT
A2: =CONVERT(About!A77,"kg","lbm")*1000000000 -> 1.3451064e+14
