Workbook
Name acres_per_hectare: #REF!
Name acres_per_hectare: #REF!
Name acres_per_million_hectares: #REF!
Name acres_per_million_hectares: #REF!
Name acres_per_million_hectares: #REF!
Name C_to_CO2: #REF!
Name CH4_Ar4_to_AR5: #REF!
Name CH4_Ar4_to_AR5: #REF!
Name CH4_to_CO2e: #REF!
Name dollars_2009_2012: #REF!
Name gal_per_barrel: #REF!
Name grams_per_ton: #REF!
Name grams_per_ton: #REF!
Name HHV_Adjust: #REF!
Name IQ_CH: 110000
Name IQ_CQ: 5000
Name IQ_CY: 10000
Name IQ_DAILY: 500000
Name IQ_FH: 100000
Name IQ_FQ: 500
Name IQ_FY: 1000
Name IQ_LTM: 2000
Name IQ_MONTH: 15000
Name IQ_NTM: 6000
Name IQ_WEEK: 50000
Name IQ_YTD: 3000
Name metricton_to_shortton: #REF!
Name million: #REF!
Name N2O_to_CO2e: #REF!
Name unit_conv: #REF!

Sheet About
A1: PLANAbPiaSY Potential Land Area Newly Affected by Policy in a Single Year
A3: Sources: | B3: Forest management and afforestation/reforestation potential CO2 abatement
B4: EPA
B5: 2024
B6: Forestry and Agriculture Sector Mitigation Analysis
B7: https://www.epa.gov/climate-change/climate-economic-analysis#Forestry%20and%20Agriculture%20Mitigation
B8: Figure 3-8
B10: CO2 per land unit: reforestation and grasslands
B11: Nature4Climate
B12: US Carbon Mapper
B13: https://nature4climate.org/u-s-carbon-mapper/
B14: Data underlying the online mapper send by Joe Fargione upon request September 22, 2021
B16: Peatland Restoration
B17: ICF International
B18: 2016
B19: Managing Agricultural Land for Greenhouse Gas Mitigation within the United States
B20: https://www.usda.gov/sites/default/files/documents/White_Paper_WEB71816.pdf
B21: pages 36-37
B23: other: see file CApULAbIFM for forest management CO2 per acre and BLAPE for IRA impacts
A25: Notes
A26: Our main data source is EPA's 2024 report which compiles an integrated abatement potential
A27: across the agriculture and forestry sectors. We map their abatement activities to the forest
A28: management and afforestation/reforestation levers. We do not use the forest set aside or
A29: deforestation levers. The EPA does not cover grasslands or wetlands, so we use separate TNC
A30: and ICF data for those ecosystems.
A32: We also adjust this variable to remove the potential implemented as part of Inflation Reduction Act
A33: calculations (see file land/BLAPE for methodology).

Sheet EPA land and ag potential
A1: Average annual change in GHG flux in the land sector from the baseline across scenarios and models by GHG category. Results are presented in MtCO2e yr-1 from 2025 to 2050. Baseline GHG emissions from the land sector by GHG category are presented in Figure 31. GHG categories are described in Figure 23. FASOMGHG includes all GHG categories, while GLOBIOM does not include forest products, forest soils, or cropland CO2. As the results are presented in atmospheric accounting terms, negative values equal more mitigation than the Baseline. GTM is not included because it does not explicitly model emissions from agriculture. Initial values differ between models because they measure the change from baseline values and models respond differently to different GHG prices. See Box 2 for further discussion on movement of soil carbon across land use categories when LUC land use change occurs in FASOMGHG.
A2: Figure | B2: Position | C2: Year | D2: Model | E2: Group | F2: Growth.Rate | G2: Starting.Price | H2: Value | I2: Units | K2: EPS Map
A3: Fig_3.8 | B3: Bar | C3: 2025 | D3: FASOMGHG | E3: Ag Soils | F3: 3% Growth | G3: $50 | H3: 126.9 | I3: MtCO2e/yr | K3: =INDEX('EPA land and ag calcs'!$G$7:$G$14,MATCH('EPA land and ag potential'!E3,'EPA land and ag calcs'!$A$7:$A$15,0)) -> afforestation and reforestation
A4: Fig_3.8 | B4: Bar | C4: 2035 | D4: FASOMGHG | E4: Ag Soils | F4: 3% Growth | G4: $50 | H4: 116.2 | I4: MtCO2e/yr | K4: =INDEX('EPA land and ag calcs'!$G$7:$G$14,MATCH('EPA land and ag potential'!E4,'EPA land and ag calcs'!$A$7:$A$15,0)) -> afforestation and reforestation
A5: Fig_3.8 | B5: Bar | C5: 2045 | D5: FASOMGHG | E5: Ag Soils | F5: 3% Growth | G5: $50 | H5: 78.6 | I5: MtCO2e/yr | K5: =INDEX('EPA land and ag calcs'!$G$7:$G$14,MATCH('EPA land and ag potential'!E5,'EPA land and ag calcs'!$A$7:$A$15,0)) -> afforestation and reforestation
A6: Fig_3.8 | B6: Bar | C6: 2055 | D6: FASOMGHG | E6: Ag Soils | F6: 3% Growth | G6: $50 | H6: 49.6 | I6: MtCO2e/yr | K6: =INDEX('EPA land and ag calcs'!$G$7:$G$14,MATCH('EPA land and ag potential'!E6,'EPA land and ag calcs'!$A$7:$A$15,0)) -> afforestation and reforestation
A7: Fig_3.8 | B7: Bar | C7: 2025 | D7: FASOMGHG | E7: Ag Soils | F7: 1% Growth | G7: $50 | H7: 39.4 | I7: MtCO2e/yr
A8: Fig_3.8 | B8: Bar | C8: 2035 | D8: FASOMGHG | E8: Ag Soils | F8: 1% Growth | G8: $50 | H8: 17.1 | I8: MtCO2e/yr
A9: Fig_3.8 | B9: Bar | C9: 2045 | D9: FASOMGHG | E9: Ag Soils | F9: 1% Growth | G9: $50 | H9: 8.9 | I9: MtCO2e/yr
A10: Fig_3.8 | B10: Bar | C10: 2055 | D10: FASOMGHG | E10: Ag Soils | F10: 1% Growth | G10: $50 | H10: 4.2 | I10: MtCO2e/yr
A11: Fig_3.8 | B11: Bar | C11: 2025 | D11: FASOMGHG | E11: Ag Soils | F11: 3% Growth | G11: $5 | H11: 24 | I11: MtCO2e/yr | K11: =INDEX('EPA land and ag calcs'!$G$7:$G$14,MATCH('EPA land and ag potential'!E11,'EPA land and ag calcs'!$A$7:$A$15,0)) -> afforestation and reforestation
A12: Fig_3.8 | B12: Bar | C12: 2035 | D12: FASOMGHG | E12: Ag Soils | F12: 3% Growth | G12: $5 | H12: 38.8 | I12: MtCO2e/yr | K12: =INDEX('EPA land and ag calcs'!$G$7:$G$14,MATCH('EPA land and ag potential'!E12,'EPA land and ag calcs'!$A$7:$A$15,0)) -> afforestation and reforestation
A13: Fig_3.8 | B13: Bar | C13: 2025 | D13: FASOMGHG | E13: Cropland Non-CO2 | F13: 3% Growth | G13: $50 | H13: -2.9 | I13: MtCO2e/yr | K13: =INDEX('EPA land and ag calcs'!$G$7:$G$14,MATCH('EPA land and ag potential'!E13,'EPA land and ag calcs'!$A$7:$A$15,0)) -> *handled in agriculture files
A14: Fig_3.8 | B14: Bar | C14: 2035 | D14: FASOMGHG | E14: Cropland Non-CO2 | F14: 3% Growth | G14: $50 | H14: -6.6 | I14: MtCO2e/yr | K14: =INDEX('EPA land and ag calcs'!$G$7:$G$14,MATCH('EPA land and ag potential'!E14,'EPA land and ag calcs'!$A$7:$A$15,0)) -> *handled in agriculture files
A15: Fig_3.8 | B15: Bar | C15: 2045 | D15: FASOMGHG | E15: Cropland Non-CO2 | F15: 3% Growth | G15: $50 | H15: -9.2 | I15: MtCO2e/yr | K15: =INDEX('EPA land and ag calcs'!$G$7:$G$14,MATCH('EPA land and ag potential'!E15,'EPA land and ag calcs'!$A$7:$A$15,0)) -> *handled in agriculture files
A16: Fig_3.8 | B16: Bar | C16: 2055 | D16: FASOMGHG | E16: Cropland Non-CO2 | F16: 3% Growth | G16: $50 | H16: -11.1 | I16: MtCO2e/yr | K16: =INDEX('EPA land and ag calcs'!$G$7:$G$14,MATCH('EPA land and ag potential'!E16,'EPA land and ag calcs'!$A$7:$A$15,0)) -> *handled in agriculture files
A17: Fig_3.8 | B17: Bar | C17: 2025 | D17: FASOMGHG | E17: Cropland Non-CO2 | F17: 1% Growth | G17: $50 | H17: -4.5 | I17: MtCO2e/yr
A18: Fig_3.8 | B18: Bar | C18: 2035 | D18: FASOMGHG | E18: Cropland Non-CO2 | F18: 1% Growth | G18: $50 | H18: -7.4 | I18: MtCO2e/yr
A19: Fig_3.8 | B19: Bar | C19: 2045 | D19: FASOMGHG | E19: Cropland Non-CO2 | F19: 1% Growth | G19: $50 | H19: -9.7 | I19: MtCO2e/yr
A20: Fig_3.8 | B20: Bar | C20: 2055 | D20: FASOMGHG | E20: Cropland Non-CO2 | F20: 1% Growth | G20: $50 | H20: -11.2 | I20: MtCO2e/yr
A21: Fig_3.8 | B21: Bar | C21: 2025 | D21: FASOMGHG | E21: Cropland Non-CO2 | F21: 3% Growth | G21: $5 | H21: -0.2 | I21: MtCO2e/yr | K21: =INDEX('EPA land and ag calcs'!$G$7:$G$14,MATCH('EPA land and ag potential'!E21,'EPA land and ag calcs'!$A$7:$A$15,0)) -> *handled in agriculture files
A22: Fig_3.8 | B22: Bar | C22: 2035 | D22: FASOMGHG | E22: Cropland Non-CO2 | F22: 3% Growth | G22: $5 | H22: -0.9 | I22: MtCO2e/yr | K22: =INDEX('EPA land and ag calcs'!$G$7:$G$14,MATCH('EPA land and ag potential'!E22,'EPA land and ag calcs'!$A$7:$A$15,0)) -> *handled in agriculture files
A23: Fig_3.8 | B23: Bar | C23: 2025 | D23: FASOMGHG | E23: Cropland CO2 | F23: 3% Growth | G23: $50 | H23: -0.9 | I23: MtCO2e/yr | K23: =INDEX('EPA land and ag calcs'!$G$7:$G$14,MATCH('EPA land and ag potential'!E23,'EPA land and ag calcs'!$A$7:$A$15,0)) -> *handled in agriculture files
A24: Fig_3.8 | B24: Bar | C24: 2035 | D24: FASOMGHG | E24: Cropland CO2 | F24: 3% Growth | G24: $50 | H24: -4.8 | I24: MtCO2e/yr | K24: =INDEX('EPA land and ag calcs'!$G$7:$G$14,MATCH('EPA land and ag potential'!E24,'EPA land and ag calcs'!$A$7:$A$15,0)) -> *handled in agriculture files
A25: Fig_3.8 | B25: Bar | C25: 2045 | D25: FASOMGHG | E25: Cropland CO2 | F25: 3% Growth | G25: $50 | H25: -9.3 | I25: MtCO2e/yr | K25: =INDEX('EPA land and ag calcs'!$G$7:$G$14,MATCH('EPA land and ag potential'!E25,'EPA land and ag calcs'!$A$7:$A$15,0)) -> *handled in agriculture files
A26: Fig_3.8 | B26: Bar | C26: 2055 | D26: FASOMGHG | E26: Cropland CO2 | F26: 3% Growth | G26: $50 | H26: -12.5 | I26: MtCO2e/yr | K26: =INDEX('EPA land and ag calcs'!$G$7:$G$14,MATCH('EPA land and ag potential'!E26,'EPA land and ag calcs'!$A$7:$A$15,0)) -> *handled in agriculture files
A27: Fig_3.8 | B27: Bar | C27: 2025 | D27: FASOMGHG | E27: Cropland CO2 | F27: 1% Growth | G27: $50 | H27: -3.5 | I27: MtCO2e/yr
A28: Fig_3.8 | B28: Bar | C28: 2035 | D28: FASOMGHG | E28: Cropland CO2 | F28: 1% Growth | G28: $50 | H28: -6 | I28: MtCO2e/yr
A29: Fig_3.8 | B29: Bar | C29: 2045 | D29: FASOMGHG | E29: Cropland CO2 | F29: 1% Growth | G29: $50 | H29: -9.3 | I29: MtCO2e/yr
A30: Fig_3.8 | B30: Bar | C30: 2055 | D30: FASOMGHG | E30: Cropland CO2 | F30: 1% Growth | G30: $50 | H30: -11.9 | I30: MtCO2e/yr
A31: Fig_3.8 | B31: Bar | C31: 2025 | D31: FASOMGHG | E31: Cropland CO2 | F31: 3% Growth | G31: $5 | H31: -0.4 | I31: MtCO2e/yr | K31: =INDEX('EPA land and ag calcs'!$G$7:$G$14,MATCH('EPA land and ag potential'!E31,'EPA land and ag calcs'!$A$7:$A$15,0)) -> *handled in agriculture files
A32: Fig_3.8 | B32: Bar | C32: 2035 | D32: FASOMGHG | E32: Cropland CO2 | F32: 3% Growth | G32: $5 | H32: -0.6 | I32: MtCO2e/yr | K32: =INDEX('EPA land and ag calcs'!$G$7:$G$14,MATCH('EPA land and ag potential'!E32,'EPA land and ag calcs'!$A$7:$A$15,0)) -> *handled in agriculture files
A33: Fig_3.8 | B33: Bar | C33: 2025 | D33: FASOMGHG | E33: Forest (Existing forests) | F33: 3% Growth | G33: $50 | H33: -19 | I33: MtCO2e/yr | K33: =INDEX('EPA land and ag calcs'!$G$7:$G$14,MATCH('EPA land and ag potential'!E33,'EPA land and ag calcs'!$A$7:$A$15,0)) -> forest management
A34: Fig_3.8 | B34: Bar | C34: 2035 | D34: FASOMGHG | E34: Forest (Existing forests) | F34: 3% Growth | G34: $50 | H34: -54.9 | I34: MtCO2e/yr | K34: =INDEX('EPA land and ag calcs'!$G$7:$G$14,MATCH('EPA land and ag potential'!E34,'EPA land and ag calcs'!$A$7:$A$15,0)) -> forest management
A35: Fig_3.8 | B35: Bar | C35: 2045 | D35: FASOMGHG | E35: Forest (Existing forests) | F35: 3% Growth | G35: $50 | H35: -65.7 | I35: MtCO2e/yr | K35: =INDEX('EPA land and ag calcs'!$G$7:$G$14,MATCH('EPA land and ag potential'!E35,'EPA land and ag calcs'!$A$7:$A$15,0)) -> forest management
A36: Fig_3.8 | B36: Bar | C36: 2055 | D36: FASOMGHG | E36: Forest (Existing forests) | F36: 3% Growth | G36: $50 | H36: -78 | I36: MtCO2e/yr | K36: =INDEX('EPA land and ag calcs'!$G$7:$G$14,MATCH('EPA land and ag potential'!E36,'EPA land and ag calcs'!$A$7:$A$15,0)) -> forest management
A37: Fig_3.8 | B37: Bar | C37: 2025 | D37: FASOMGHG | E37: Forest (Existing forests) | F37: 1% Growth | G37: $50 | H37: -36.5 | I37: MtCO2e/yr
A38: Fig_3.8 | B38: Bar | C38: 2035 | D38: FASOMGHG | E38: Forest (Existing forests) | F38: 1% Growth | G38: $50 | H38: -61.2 | I38: MtCO2e/yr
A39: Fig_3.8 | B39: Bar | C39: 2045 | D39: FASOMGHG | E39: Forest (Existing forests) | F39: 1% Growth | G39: $50 | H39: -62.5 | I39: MtCO2e/yr
A40: Fig_3.8 | B40: Bar | C40: 2055 | D40: FASOMGHG | E40: Forest (Existing forests) | F40: 1% Growth | G40: $50 | H40: -61.3 | I40: MtCO2e/yr
...

Sheet EPA land and ag calcs
A1: Model | B1: FASOMGHG
A2: Growth.Rate | B2: 3% Growth
A3: Starting.Price | B3: $100
A5: Sum of Value | B5: Column Labels
A6: Row Labels | B6: 2025 | C6: 2035 | D6: 2045 | E6: 2055 | F6: Grand Total
A7: Ag Soils | B7: 124.1 | C7: 109.7 | D7: 73.5 | E7: 45.3 | F7: 352.6 | G7: afforestation and reforestation
A8: Cropland CO2 | B8: -4 | C8: -8.8 | D8: -13 | E8: -15.8 | F8: -41.6 | G8: *handled in agriculture files
A9: Cropland Non-CO2 | B9: -3.8 | C9: -7.6 | D9: -10.2 | E9: -12 | F9: -33.6 | G9: *handled in agriculture files
A10: Forest (Existing forests) | B10: -30.3 | C10: -67.1 | D10: -77.8 | E10: -91.9 | F10: -267.1 | G10: forest management
A11: Forest (New forests) | C11: -59 | D11: -77.6 | E11: -107 | F11: -243.6 | G11: afforestation and reforestation
A12: Forest Products | B12: 3.6 | C12: 3 | D12: 2.6 | E12: 2.4 | F12: 11.6 | G12: forest management
A13: Forest Soils | B13: -153.2 | C13: -173.5 | D13: -154.1 | E13: -130.2 | F13: -611 | G13: afforestation and reforestation
A14: Livestock Non-CO2 | B14: -33.3 | C14: -44.3 | D14: -51.2 | E14: -59.2 | F14: -188 | G14: *handled in agriculture files
A15: Total | B15: -96.9 | C15: -247.6 | D15: -307.8 | E15: -368.4 | F15: -1020.7
A16: Grand Total | B16: -193.8 | C16: -495.2 | D16: -615.6 | E16: -736.8 | F16: -2041.4
A18: Check on Total | B18: =SUM(B7:B14) -> -96.9 | C18: =SUM(C7:C14) -> -247.6 | D18: =SUM(D7:D14) -> -307.8 | E18: =SUM(E7:E14) -> -368.4
A20: forest management
B21: cumulative | H21: broken out | M21: amount spent | S21: cumulative amount spent | Y21: annual target | Z21: 1.0205e+08 | AB21: used in IRA scenario | AE21: potential remaining in IRA scenario
B22: 2025 | C22: 2035 | D22: 2045 | E22: 2055 | H22: 2025 | I22: 2035 | J22: 2045 | K22: 2055 | N22: 2025 | O22: 2035 | P22: 2045 | Q22: 2055 | T22: 2025 | U22: 2035 | V22: 2045 | W22: 2055 | Y22: 2025 | Z22: 2035 | AB22: 2025 | AC22: 2035 | AE22: 2025 | AF22: 2035
A23: 5 | B23: =SUMIFS('EPA land and ag potential'!$H:$H,'EPA land and ag potential'!$C:$C,'EPA land and ag calcs'!B$22,'EPA land and ag potential'!$G:$G,'EPA land and ag calcs'!$A23,'EPA land and ag potential'!$D:$D,"FASOMGHG",'EPA land and ag potential'!$F:$F,"3% Growth",'EPA land and ag potential'!$K:$K,'EPA land and ag calcs'!$A$20) -> -6.2 | C23: =SUMIFS('EPA land and ag potential'!$H:$H,'EPA land and ag potential'!$C:$C,'EPA land and ag calcs'!C$22,'EPA land and ag potential'!$G:$G,'EPA land and ag calcs'!$A23,'EPA land and ag potential'!$D:$D,"FASOMGHG",'EPA land and ag potential'!$F:$F,"3% Growth",'EPA land and ag potential'!$K:$K,'EPA land and ag calcs'!$A$20) -> -15.7 | D23: =SUMIFS('EPA land and ag potential'!$H:$H,'EPA land and ag potential'!$C:$C,'EPA land and ag calcs'!D$22,'EPA land and ag potential'!$G:$G,'EPA land and ag calcs'!$A23,'EPA land and ag potential'!$D:$D,"FASOMGHG",'EPA land and ag potential'!$F:$F,"3% Growth",'EPA land and ag potential'!$K:$K,'EPA land and ag calcs'!$A$20) -> -21.9 | E23: =SUMIFS('EPA land and ag potential'!$H:$H,'EPA land and ag potential'!$C:$C,'EPA land and ag calcs'!E$22,'EPA land and ag potential'!$G:$G,'EPA land and ag calcs'!$A23,'EPA land and ag potential'!$D:$D,"FASOMGHG",'EPA land and ag potential'!$F:$F,"3% Growth",'EPA land and ag potential'!$K:$K,'EPA land and ag calcs'!$A$20) -> -27.9 | G23: 5 | H23: =SUMIFS('EPA land and ag potential'!$H:$H,'EPA land and ag potential'!$C:$C,'EPA land and ag calcs'!B$22,'EPA land and ag potential'!$G:$G,'EPA land and ag calcs'!$A23,'EPA land and ag potential'!$K:$K,'EPA land and ag calcs'!$A$20,'EPA land and ag potential'!$D:$D,"FASOMGHG",'EPA land and ag potential'!$F:$F,"3% Growth") -> -6.2 | I23: =SUMIFS('EPA land and ag potential'!$H:$H,'EPA land and ag potential'!$C:$C,'EPA land and ag calcs'!C$22,'EPA land and ag potential'!$G:$G,'EPA land and ag calcs'!$A23,'EPA land and ag potential'!$K:$K,'EPA land and ag calcs'!$A$20,'EPA land and ag potential'!$D:$D,"FASOMGHG",'EPA land and ag potential'!$F:$F,"3% Growth") -> -15.7 | J23: =SUMIFS('EPA land and ag potential'!$H:$H,'EPA land and ag potential'!$C:$C,'EPA land and ag calcs'!D$22,'EPA land and ag potential'!$G:$G,'EPA land and ag calcs'!$A23,'EPA land and ag potential'!$K:$K,'EPA land and ag calcs'!$A$20,'EPA land and ag potential'!$D:$D,"FASOMGHG",'EPA land and ag potential'!$F:$F,"3% Growth") -> -21.9 | K23: =SUMIFS('EPA land and ag potential'!$H:$H,'EPA land and ag potential'!$C:$C,'EPA land and ag calcs'!E$22,'EPA land and ag potential'!$G:$G,'EPA land and ag calcs'!$A23,'EPA land and ag potential'!$K:$K,'EPA land and ag calcs'!$A$20,'EPA land and ag potential'!$D:$D,"FASOMGHG",'EPA land and ag potential'!$F:$F,"3% Growth") -> -27.9 | M23: 5 | N23: 27500431 | O23: 69638188 | P23: 97138619 | Q23: 1.2375194e+08 | S23: 5 | T23: =N23 -> 27500431 | U23: =O23 -> 69638188 | V23: =P23 -> 97138619 | W23: =Q23 -> 1.2375194e+08 | Y23: =T23/$Z$21 -> 0.26947997 | Z23: =U23/$Z$21 -> 0.68239282 | AB23: 1 | AC23: 1 | AE23: =AB23*H23*-1 -> 6.2 | AF23: =AC23*I23*-1 -> 15.7
A24: 20 | B24: =SUMIFS('EPA land and ag potential'!$H:$H,'EPA land and ag potential'!$C:$C,'EPA land and ag calcs'!B$22,'EPA land and ag potential'!$G:$G,'EPA land and ag calcs'!$A24,'EPA land and ag potential'!$D:$D,"FASOMGHG",'EPA land and ag potential'!$F:$F,"3% Growth",'EPA land and ag potential'!$K:$K,'EPA land and ag calcs'!$A$20) -> -12.3 | C24: =SUMIFS('EPA land and ag potential'!$H:$H,'EPA land and ag potential'!$C:$C,'EPA land and ag calcs'!C$22,'EPA land and ag potential'!$G:$G,'EPA land and ag calcs'!$A24,'EPA land and ag potential'!$D:$D,"FASOMGHG",'EPA land and ag potential'!$F:$F,"3% Growth",'EPA land and ag potential'!$K:$K,'EPA land and ag calcs'!$A$20) -> -39.1 | D24: =SUMIFS('EPA land and ag potential'!$H:$H,'EPA land and ag potential'!$C:$C,'EPA land and ag calcs'!D$22,'EPA land and ag potential'!$G:$G,'EPA land and ag calcs'!$A24,'EPA land and ag potential'!$D:$D,"FASOMGHG",'EPA land and ag potential'!$F:$F,"3% Growth",'EPA land and ag potential'!$K:$K,'EPA land and ag calcs'!$A$20) -> -48.1 | E24: =SUMIFS('EPA land and ag potential'!$H:$H,'EPA land and ag potential'!$C:$C,'EPA land and ag calcs'!E$22,'EPA land and ag potential'!$G:$G,'EPA land and ag calcs'!$A24,'EPA land and ag potential'!$D:$D,"FASOMGHG",'EPA land and ag potential'!$F:$F,"3% Growth",'EPA land and ag potential'!$K:$K,'EPA land and ag calcs'!$A$20) -> -58.3 | G24: 20 | H24: =B24-B23 -> -6.1 | I24: =C24-C23 -> -23.4 | J24: =D24-D23 -> -26.2 | K24: =E24-E23 -> -30.4 | M24: 20 | N24: 1.082275e+08 | O24: 4.1516779e+08 | P24: 4.6484599e+08 | Q24: 5.3936329e+08 | S24: 20 | T24: =T23+N24 -> 1.3572793e+08 | U24: =U23+O24 -> 4.8480598e+08 | V24: =V23+P24 -> 5.6198461e+08 | W24: =W23+Q24 -> 6.6311523e+08 | Y24: =T24/$Z$21 -> 1.330014 | Z24: =U24/$Z$21 -> 4.7506711 | AB24: =(Z21-N23)/N24 -> 0.68882278 | AC24: =1-(U24-U23)/U24 -> 0.14364135 | AE24: =AB24*H24*-1 -> 4.201819 | AF24: =AC24*I24*-1 -> 3.3612077
A25: 35 | B25: =SUMIFS('EPA land and ag potential'!$H:$H,'EPA land and ag potential'!$C:$C,'EPA land and ag calcs'!B$22,'EPA land and ag potential'!$G:$G,'EPA land and ag calcs'!$A25,'EPA land and ag potential'!$D:$D,"FASOMGHG",'EPA land and ag potential'!$F:$F,"3% Growth",'EPA land and ag potential'!$K:$K,'EPA land and ag calcs'!$A$20) -> -14.8 | C25: =SUMIFS('EPA land and ag potential'!$H:$H,'EPA land and ag potential'!$C:$C,'EPA land and ag calcs'!C$22,'EPA land and ag potential'!$G:$G,'EPA land and ag calcs'!$A25,'EPA land and ag potential'!$D:$D,"FASOMGHG",'EPA land and ag potential'!$F:$F,"3% Growth",'EPA land and ag potential'!$K:$K,'EPA land and ag calcs'!$A$20) -> -49.5 | D25: =SUMIFS('EPA land and ag potential'!$H:$H,'EPA land and ag potential'!$C:$C,'EPA land and ag calcs'!D$22,'EPA land and ag potential'!$G:$G,'EPA land and ag calcs'!$A25,'EPA land and ag potential'!$D:$D,"FASOMGHG",'EPA land and ag potential'!$F:$F,"3% Growth",'EPA land and ag potential'!$K:$K,'EPA land and ag calcs'!$A$20) -> -59.9 | E25: =SUMIFS('EPA land and ag potential'!$H:$H,'EPA land and ag potential'!$C:$C,'EPA land and ag calcs'!E$22,'EPA land and ag potential'!$G:$G,'EPA land and ag calcs'!$A25,'EPA land and ag potential'!$D:$D,"FASOMGHG",'EPA land and ag potential'!$F:$F,"3% Growth",'EPA land and ag potential'!$K:$K,'EPA land and ag calcs'!$A$20) -> -72 | G25: 35 | H25: =B25-B24 -> -2.5 | I25: =C25-C24 -> -10.4 | J25: =D25-D24 -> -11.8 | K25: =E25-E24 -> -13.7 | M25: 35 | N25: 77622184 | O25: 3.2290828e+08 | P25: 3.6637671e+08 | Q25: 4.2536957e+08 | S25: 35 | T25: =T24+N25 -> 2.1335012e+08 | U25: =U24+O25 -> 8.0771427e+08 | V25: =V24+P25 -> 9.2836132e+08 | W25: =W24+Q25 -> 1.0884848e+09 | AB25: 0 | AC25: 0
A26: 50 | B26: =SUMIFS('EPA land and ag potential'!$H:$H,'EPA land and ag potential'!$C:$C,'EPA land and ag calcs'!B$22,'EPA land and ag potential'!$G:$G,'EPA land and ag calcs'!$A26,'EPA land and ag potential'!$D:$D,"FASOMGHG",'EPA land and ag potential'!$F:$F,"3% Growth",'EPA land and ag potential'!$K:$K,'EPA land and ag calcs'!$A$20) -> -17.4 | C26: =SUMIFS('EPA land and ag potential'!$H:$H,'EPA land and ag potential'!$C:$C,'EPA land and ag calcs'!C$22,'EPA land and ag potential'!$G:$G,'EPA land and ag calcs'!$A26,'EPA land and ag potential'!$D:$D,"FASOMGHG",'EPA land and ag potential'!$F:$F,"3% Growth",'EPA land and ag potential'!$K:$K,'EPA land and ag calcs'!$A$20) -> -53.3 | D26: =SUMIFS('EPA land and ag potential'!$H:$H,'EPA land and ag potential'!$C:$C,'EPA land and ag calcs'!D$22,'EPA land and ag potential'!$G:$G,'EPA land and ag calcs'!$A26,'EPA land and ag potential'!$D:$D,"FASOMGHG",'EPA land and ag potential'!$F:$F,"3% Growth",'EPA land and ag potential'!$K:$K,'EPA land and ag calcs'!$A$20) -> -64.1 | E26: =SUMIFS('EPA land and ag potential'!$H:$H,'EPA land and ag potential'!$C:$C,'EPA land and ag calcs'!E$22,'EPA land and ag potential'!$G:$G,'EPA land and ag calcs'!$A26,'EPA land and ag potential'!$D:$D,"FASOMGHG",'EPA land and ag potential'!$F:$F,"3% Growth",'EPA land and ag potential'!$K:$K,'EPA land and ag calcs'!$A$20) -> -76.7 | G26: 50 | H26: =B26-B25 -> -2.6 | I26: =C26-C25 -> -3.8 | J26: =D26-D25 -> -4.2 | K26: =E26-E25 -> -4.7 | M26: 50 | N26: 1.1532439e+08 | O26: 1.6855103e+08 | P26: 1.8629324e+08 | Q26: 2.0847101e+08 | S26: 50 | T26: =T25+N26 -> 3.286745e+08 | U26: =U25+O26 -> 9.7626529e+08 | V26: =V25+P26 -> 1.1146546e+09 | W26: =W25+Q26 -> 1.2969558e+09 | AB26: 0 | AC26: 0
A27: 100 | B27: =SUMIFS('EPA land and ag potential'!$H:$H,'EPA land and ag potential'!$C:$C,'EPA land and ag calcs'!B$22,'EPA land and ag potential'!$G:$G,'EPA land and ag calcs'!$A27,'EPA land and ag potential'!$D:$D,"FASOMGHG",'EPA land and ag potential'!$F:$F,"3% Growth",'EPA land and ag potential'!$K:$K,'EPA land and ag calcs'!$A$20) -> -26.7 | C27: =SUMIFS('EPA land and ag potential'!$H:$H,'EPA land and ag potential'!$C:$C,'EPA land and ag calcs'!C$22,'EPA land and ag potential'!$G:$G,'EPA land and ag calcs'!$A27,'EPA land and ag potential'!$D:$D,"FASOMGHG",'EPA land and ag potential'!$F:$F,"3% Growth",'EPA land and ag potential'!$K:$K,'EPA land and ag calcs'!$A$20) -> -64.1 | D27: =SUMIFS('EPA land and ag potential'!$H:$H,'EPA land and ag potential'!$C:$C,'EPA land and ag calcs'!D$22,'EPA land and ag potential'!$G:$G,'EPA land and ag calcs'!$A27,'EPA land and ag potential'!$D:$D,"FASOMGHG",'EPA land and ag potential'!$F:$F,"3% Growth",'EPA land and ag potential'!$K:$K,'EPA land and ag calcs'!$A$20) -> -75.2 | E27: =SUMIFS('EPA land and ag potential'!$H:$H,'EPA land and ag potential'!$C:$C,'EPA land and ag calcs'!E$22,'EPA land and ag potential'!$G:$G,'EPA land and ag calcs'!$A27,'EPA land and ag potential'!$D:$D,"FASOMGHG",'EPA land and ag potential'!$F:$F,"3% Growth",'EPA land and ag potential'!$K:$K,'EPA land and ag calcs'!$A$20) -> -89.5 | G27: 100 | H27: =B27-B26 -> -9.3 | I27: =C27-C26 -> -10.8 | J27: =D27-D26 -> -11.1 | K27: =E27-E26 -> -12.8 | M27: 100 | N27: 8.2501292e+08 | O27: 9.5807953e+08 | P27: 9.8469285e+08 | Q27: 1.1355017e+09 | S27: 100 | T27: =T26+N27 -> 1.1536874e+09 | U27: =U26+O27 -> 1.9343448e+09 | V27: =V26+P27 -> 2.0993474e+09 | W27: =W26+Q27 -> 2.4324575e+09 | AB27: 0 | AC27: 0
AD28: total (g) | AE28: =SUM(AE23:AE27)*10^12 -> 1.0401819e+13 | AF28: =SUM(AF23:AF27)*10^12 -> 1.9061208e+13
A29: afforestation and reforestation
B30: cumulative | H30: broken out | M30: amount spent | S30: cumulative amount spent | Y30: annual target | Z30: 150000000 | AB30: used in IRA scenario | AE30: potential remaining in IRA scenario
B31: 2025 | C31: 2035 | D31: 2045 | E31: 2055 | H31: 2025 | I31: 2035 | J31: 2045 | K31: 2055 | N31: 2025 | O31: 2035 | P31: 2045 | Q31: 2055 | T31: 2025 | U31: 2035 | V31: 2045 | W31: 2055 | Y31: 2025 | Z31: 2035 | AB31: 2025 | AC31: 2035 | AE31: 2025 | AF31: 2035
A32: 5 | B32: =SUMIFS('EPA land and ag potential'!$H:$H,'EPA land and ag potential'!$C:$C,'EPA land and ag calcs'!B$22,'EPA land and ag potential'!$G:$G,'EPA land and ag calcs'!$A23,'EPA land and ag potential'!$D:$D,"FASOMGHG",'EPA land and ag potential'!$F:$F,"3% Growth",'EPA land and ag potential'!$K:$K,'EPA land and ag calcs'!$A$29) -> 15.6 | C32: =SUMIFS('EPA land and ag potential'!$H:$H,'EPA land and ag potential'!$C:$C,'EPA land and ag calcs'!C$22,'EPA land and ag potential'!$G:$G,'EPA land and ag calcs'!$A23,'EPA land and ag potential'!$D:$D,"FASOMGHG",'EPA land and ag potential'!$F:$F,"3% Growth",'EPA land and ag potential'!$K:$K,'EPA land and ag calcs'!$A$29) -> 1.7 | D32: =SUMIFS('EPA land and ag potential'!$H:$H,'EPA land and ag potential'!$C:$C,'EPA land and ag calcs'!D$22,'EPA land and ag potential'!$G:$G,'EPA land and ag calcs'!$A23,'EPA land and ag potential'!$D:$D,"FASOMGHG",'EPA land and ag potential'!$F:$F,"3% Growth",'EPA land and ag potential'!$K:$K,'EPA land and ag calcs'!$A$29) -> -1.5 | E32: =SUMIFS('EPA land and ag potential'!$H:$H,'EPA land and ag potential'!$C:$C,'EPA land and ag calcs'!E$22,'EPA land and ag potential'!$G:$G,'EPA land and ag calcs'!$A23,'EPA land and ag potential'!$D:$D,"FASOMGHG",'EPA land and ag potential'!$F:$F,"3% Growth",'EPA land and ag potential'!$K:$K,'EPA land and ag calcs'!$A$29) -> -0.6 | G32: 5 | H32: =SUMIFS('EPA land and ag potential'!$H:$H,'EPA land and ag potential'!$C:$C,'EPA land and ag calcs'!B$22,'EPA land and ag potential'!$G:$G,'EPA land and ag calcs'!$A32,'EPA land and ag potential'!$K:$K,'EPA land and ag calcs'!$A$29,'EPA land and ag potential'!$D:$D,"FASOMGHG",'EPA land and ag potential'!$F:$F,"3% Growth") -> 15.6 | I32: =SUMIFS('EPA land and ag potential'!$H:$H,'EPA land and ag potential'!$C:$C,'EPA land and ag calcs'!C$22,'EPA land and ag potential'!$G:$G,'EPA land and ag calcs'!$A32,'EPA land and ag potential'!$K:$K,'EPA land and ag calcs'!$A$29,'EPA land and ag potential'!$D:$D,"FASOMGHG",'EPA land and ag potential'!$F:$F,"3% Growth") -> 1.7 | J32: =SUMIFS('EPA land and ag potential'!$H:$H,'EPA land and ag potential'!$C:$C,'EPA land and ag calcs'!D$22,'EPA land and ag potential'!$G:$G,'EPA land and ag calcs'!$A32,'EPA land and ag potential'!$K:$K,'EPA land and ag calcs'!$A$29,'EPA land and ag potential'!$D:$D,"FASOMGHG",'EPA land and ag potential'!$F:$F,"3% Growth") -> -1.5 | K32: =SUMIFS('EPA land and ag potential'!$H:$H,'EPA land and ag potential'!$C:$C,'EPA land and ag calcs'!E$22,'EPA land and ag potential'!$G:$G,'EPA land and ag calcs'!$A32,'EPA land and ag potential'!$K:$K,'EPA land and ag calcs'!$A$29,'EPA land and ag potential'!$D:$D,"FASOMGHG",'EPA land and ag potential'!$F:$F,"3% Growth") -> -0.6 | M32: 5 | N32: 0 | O32: 0 | P32: 6653330 | Q32: 2661332 | S32: 5 | T32: =N32 -> 0 | U32: =O32 -> 0 | V32: =P32 -> 6653330 | W32: =Q32 -> 2661332 | Y32: =T32/$Z$21 -> 0 | Z32: =U32/$Z$21 -> 0 | AB32: 1 | AC32: 1 | AE32: =IF(AB32*H32*-1<0,0,AB32*H32*-1) -> 0 | AF32: =IF(AC32*I32*-1<0,0,AC32*I32*-1) -> 0
A33: 20 | B33: =SUMIFS('EPA land and ag potential'!$H:$H,'EPA land and ag potential'!$C:$C,'EPA land and ag calcs'!B$22,'EPA land and ag potential'!$G:$G,'EPA land and ag calcs'!$A24,'EPA land and ag potential'!$D:$D,"FASOMGHG",'EPA land and ag potential'!$F:$F,"3% Growth",'EPA land and ag potential'!$K:$K,'EPA land and ag calcs'!$A$29) -> 15.1 | C33: =SUMIFS('EPA land and ag potential'!$H:$H,'EPA land and ag potential'!$C:$C,'EPA land and ag calcs'!C$22,'EPA land and ag potential'!$G:$G,'EPA land and ag calcs'!$A24,'EPA land and ag potential'!$D:$D,"FASOMGHG",'EPA land and ag potential'!$F:$F,"3% Growth",'EPA land and ag potential'!$K:$K,'EPA land and ag calcs'!$A$29) -> -25.5 | D33: =SUMIFS('EPA land and ag potential'!$H:$H,'EPA land and ag potential'!$C:$C,'EPA land and ag calcs'!D$22,'EPA land and ag potential'!$G:$G,'EPA land and ag calcs'!$A24,'EPA land and ag potential'!$D:$D,"FASOMGHG",'EPA land and ag potential'!$F:$F,"3% Growth",'EPA land and ag potential'!$K:$K,'EPA land and ag calcs'!$A$29) -> -40.1 | E33: =SUMIFS('EPA land and ag potential'!$H:$H,'EPA land and ag potential'!$C:$C,'EPA land and ag calcs'!E$22,'EPA land and ag potential'!$G:$G,'EPA land and ag calcs'!$A24,'EPA land and ag potential'!$D:$D,"FASOMGHG",'EPA land and ag potential'!$F:$F,"3% Growth",'EPA land and ag potential'!$K:$K,'EPA land and ag calcs'!$A$29) -> -62.5 | G33: 20 | H33: =B33-B32 -> -0.5 | I33: =C33-C32 -> -27.2 | J33: =D33-D32 -> -38.6 | K33: =E33-E32 -> -61.9 | M33: 20 | N33: 8871106.7 | O33: 4.8258821e+08 | P33: 6.8484944e+08 | Q33: 1.098243e+09 | S33: 20 | T33: =T32+N33 -> 8871106.7 | U33: =U32+O33 -> 4.8258821e+08 | V33: =V32+P33 -> 6.9150277e+08 | W33: =W32+Q33 -> 1.1009043e+09 | Y33: =T33/$Z$21 -> 0.086929022 | Z33: =U33/$Z$21 -> 4.7289388 | AB33: 1 | AC33: =(Z30-U32)/O33 -> 0.31082401 | AE33: =IF(AB33*H33*-1<0,0,AB33*H33*-1) -> 0.5 | AF33: =IF(AC33*I33*-1<0,0,AC33*I33*-1) -> 8.454413
A34: 35 | B34: =SUMIFS('EPA land and ag potential'!$H:$H,'EPA land and ag potential'!$C:$C,'EPA land and ag calcs'!B$22,'EPA land and ag potential'!$G:$G,'EPA land and ag calcs'!$A25,'EPA land and ag potential'!$D:$D,"FASOMGHG",'EPA land and ag potential'!$F:$F,"3% Growth",'EPA land and ag potential'!$K:$K,'EPA land and ag calcs'!$A$29) -> 20.5 | C34: =SUMIFS('EPA land and ag potential'!$H:$H,'EPA land and ag potential'!$C:$C,'EPA land and ag calcs'!C$22,'EPA land and ag potential'!$G:$G,'EPA land and ag calcs'!$A25,'EPA land and ag potential'!$D:$D,"FASOMGHG",'EPA land and ag potential'!$F:$F,"3% Growth",'EPA land and ag potential'!$K:$K,'EPA land and ag calcs'!$A$29) -> -59.3 | D34: =SUMIFS('EPA land and ag potential'!$H:$H,'EPA land and ag potential'!$C:$C,'EPA land and ag calcs'!D$22,'EPA land and ag potential'!$G:$G,'EPA land and ag calcs'!$A25,'EPA land and ag potential'!$D:$D,"FASOMGHG",'EPA land and ag potential'!$F:$F,"3% Growth",'EPA land and ag potential'!$K:$K,'EPA land and ag calcs'!$A$29) -> -99.2 | E34: =SUMIFS('EPA land and ag potential'!$H:$H,'EPA land and ag potential'!$C:$C,'EPA land and ag calcs'!E$22,'EPA land and ag potential'!$G:$G,'EPA land and ag calcs'!$A25,'EPA land and ag potential'!$D:$D,"FASOMGHG",'EPA land and ag potential'!$F:$F,"3% Growth",'EPA land and ag potential'!$K:$K,'EPA land and ag calcs'!$A$29) -> -124.1 | G34: 35 | H34: =B34-B33 -> 5.4 | I34: =C34-C33 -> -33.8 | J34: =D34-D33 -> -59.1 | K34: =E34-E33 -> -61.6 | M34: 35 | N34: 0 | O34: 1.0494519e+09 | P34: 1.8349884e+09 | Q34: 1.9126106e+09 | S34: 35 | T34: =T33+N34 -> 8871106.7 | U34: =U33+O34 -> 1.5320401e+09 | V34: =V33+P34 -> 2.5264912e+09 | W34: =W33+Q34 -> 3.013515e+09 | Y34: =T34/$Z$21 -> 0.086929022 | Z34: =U34/$Z$21 -> 15.012642 | AB34: 1 | AC34: 0 | AE34: =IF(AB34*H34*-1<0,0,AB34*H34*-1) -> 0 | AF34: =IF(AC34*I34*-1<0,0,AC34*I34*-1) -> 0
A35: 50 | B35: =SUMIFS('EPA land and ag potential'!$H:$H,'EPA land and ag potential'!$C:$C,'EPA land and ag calcs'!B$22,'EPA land and ag potential'!$G:$G,'EPA land and ag calcs'!$A26,'EPA land and ag potential'!$D:$D,"FASOMGHG",'EPA land and ag potential'!$F:$F,"3% Growth",'EPA land and ag potential'!$K:$K,'EPA land and ag calcs'!$A$29) -> -26.5 | C35: =SUMIFS('EPA land and ag potential'!$H:$H,'EPA land and ag potential'!$C:$C,'EPA land and ag calcs'!C$22,'EPA land and ag potential'!$G:$G,'EPA land and ag calcs'!$A26,'EPA land and ag potential'!$D:$D,"FASOMGHG",'EPA land and ag potential'!$F:$F,"3% Growth",'EPA land and ag potential'!$K:$K,'EPA land and ag calcs'!$A$29) -> -103.5 | D35: =SUMIFS('EPA land and ag potential'!$H:$H,'EPA land and ag potential'!$C:$C,'EPA land and ag calcs'!D$22,'EPA land and ag potential'!$G:$G,'EPA land and ag calcs'!$A26,'EPA land and ag potential'!$D:$D,"FASOMGHG",'EPA land and ag potential'!$F:$F,"3% Growth",'EPA land and ag potential'!$K:$K,'EPA land and ag calcs'!$A$29) -> -141.9 | E35: =SUMIFS('EPA land and ag potential'!$H:$H,'EPA land and ag potential'!$C:$C,'EPA land and ag calcs'!E$22,'EPA land and ag potential'!$G:$G,'EPA land and ag calcs'!$A26,'EPA land and ag potential'!$D:$D,"FASOMGHG",'EPA land and ag potential'!$F:$F,"3% Growth",'EPA land and ag potential'!$K:$K,'EPA land and ag calcs'!$A$29) -> -168.4 | G35: 50 | H35: =B35-B34 -> -47 | I35: =C35-C34 -> -44.2 | J35: =D35-D34 -> -42.7 | K35: =E35-E34 -> -44.3 | M35: 50 | N35: 2.0847101e+09 | O35: 1.9605146e+09 | P35: 1.8939813e+09 | Q35: 1.9649501e+09 | S35: 50 | T35: =T34+N35 -> 2.0935812e+09 | U35: =U34+O35 -> 3.4925547e+09 | V35: =V34+P35 -> 4.4204725e+09 | W35: =W34+Q35 -> 4.9784651e+09 | Y35: =T35/$Z$21 -> 20.515249 | Z35: =U35/$Z$21 -> 34.223956 | AB35: =(Z30-T34)/N35 -> 0.067697132 | AC35: 0 | AE35: =IF(AB35*H35*-1<0,0,AB35*H35*-1) -> 3.1817652 | AF35: =IF(AC35*I35*-1<0,0,AC35*I35*-1) -> 0
A36: 100 | B36: =SUMIFS('EPA land and ag potential'!$H:$H,'EPA land and ag potential'!$C:$C,'EPA land and ag calcs'!B$22,'EPA land and ag potential'!$G:$G,'EPA land and ag calcs'!$A27,'EPA land and ag potential'!$D:$D,"FASOMGHG",'EPA land and ag potential'!$F:$F,"3% Growth",'EPA land and ag potential'!$K:$K,'EPA land and ag calcs'!$A$29) -> -29.1 | C36: =SUMIFS('EPA land and ag potential'!$H:$H,'EPA land and ag potential'!$C:$C,'EPA land and ag calcs'!C$22,'EPA land and ag potential'!$G:$G,'EPA land and ag calcs'!$A27,'EPA land and ag potential'!$D:$D,"FASOMGHG",'EPA land and ag potential'!$F:$F,"3% Growth",'EPA land and ag potential'!$K:$K,'EPA land and ag calcs'!$A$29) -> -122.8 | D36: =SUMIFS('EPA land and ag potential'!$H:$H,'EPA land and ag potential'!$C:$C,'EPA land and ag calcs'!D$22,'EPA land and ag potential'!$G:$G,'EPA land and ag calcs'!$A27,'EPA land and ag potential'!$D:$D,"FASOMGHG",'EPA land and ag potential'!$F:$F,"3% Growth",'EPA land and ag potential'!$K:$K,'EPA land and ag calcs'!$A$29) -> -158.2 | E36: =SUMIFS('EPA land and ag potential'!$H:$H,'EPA land and ag potential'!$C:$C,'EPA land and ag calcs'!E$22,'EPA land and ag potential'!$G:$G,'EPA land and ag calcs'!$A27,'EPA land and ag potential'!$D:$D,"FASOMGHG",'EPA land and ag potential'!$F:$F,"3% Growth",'EPA land and ag potential'!$K:$K,'EPA land and ag calcs'!$A$29) -> -191.9 | G36: 100 | H36: =B36-B35 -> -2.6 | I36: =C36-C35 -> -19.3 | J36: =D36-D35 -> -16.3 | K36: =E36-E35 -> -23.5 | M36: 100 | N36: 2.3064877e+08 | O36: 1.7121236e+09 | P36: 1.4459904e+09 | Q36: 2.0847101e+09 | S36: 100 | T36: =T35+N36 -> 2.32423e+09 | U36: =U35+O36 -> 5.2046783e+09 | V36: =V35+P36 -> 5.8664629e+09 | W36: =W35+Q36 -> 7.0631752e+09 | AB36: 0 | AC36: 0 | AE36: =IF(AB36*H36*-1<0,0,AB36*H36*-1) -> 0 | AF36: =IF(AC36*I36*-1<0,0,AC36*I36*-1) -> 0
AD37: total (g) | AE37: =SUM(AE32:AE36)*10^12 -> 3.6817652e+12 | AF37: =SUM(AF32:AF36)*10^12 -> 8.454413e+12
A38: interpolated potential achieved in IRA (see land/BLAPE)
B39: 2021 | C39: 2022 | D39: 2023 | E39: 2024 | F39: 2025 | G39: 2026 | H39: 2027 | I39: 2028 | J39: 2029 | K39: 2030 | L39: 2031 | M39: 2032 | N39: 2033 | O39: 2034 | P39: 2035 | Q39: 2036 | R39: 2037 | S39: 2038 | T39: 2039 | U39: 2040 | V39: 2041 | W39: 2042 | X39: 2043 | Y39: 2044 | Z39: 2045 | AA39: 2046 | AB39: 2047 | AC39: 2048 | AD39: 2049 | AE39: 2050
A40: forest management | B40: 0 | C40: 0 | D40: 4.9574094e+12 | E40: 8.926839e+12 | F40: 1.2203305e+13 | G40: 1.5384377e+13 | H40: 17578198294243 | I40: 1.7459142e+13 | J40: 1.5815565e+13 | K40: 1.4795656e+13 | L40: 1.2251226e+13 | M40: 9.978678e+12 | N40: 6.652452e+12 | O40: 3.326226e+12 | P40: 0 | Q40: 0 | R40: 0 | S40: 0 | T40: 0 | U40: 0 | V40: 0 | W40: 0 | X40: 0 | Y40: 0 | Z40: 0 | AA40: 0 | AB40: 0 | AC40: 0 | AD40: 0 | AE40: 0
A41: afforestation and reforestation | B41: 0 | C41: 0 | D41: 0 | E41: 0 | F41: 0 | G41: 0 | H41: 5.0829325e+11 | I41: 7.0535348e+12 | J41: 1.0179858e+13 | K41: 1.0179858e+13 | L41: 1.0179858e+13 | M41: 1.0179858e+13 | N41: 1.0179858e+13 | O41: 1.0179858e+13 | P41: 1.0179858e+13 | Q41: =P41 -> 1.0179858e+13 | R41: =Q41 -> 1.0179858e+13 | S41: =R41 -> 1.0179858e+13 | T41: =S41 -> 1.0179858e+13 | U41: =T41 -> 1.0179858e+13 | V41: =U41 -> 1.0179858e+13 | W41: =V41 -> 1.0179858e+13 | X41: =W41 -> 1.0179858e+13 | ... AE41: =AD41 -> 1.0179858e+13
A43: interpolated total potential before IRA
B44: 2021 | C44: 2022 | D44: 2023 | E44: 2024 | F44: 2025 | G44: 2026 | H44: 2027 | I44: 2028 | J44: 2029 | K44: 2030 | L44: 2031 | M44: 2032 | N44: 2033 | O44: 2034 | P44: 2035 | Q44: 2036 | R44: 2037 | S44: 2038 | T44: 2039 | U44: 2040 | V44: 2041 | W44: 2042 | X44: 2043 | Y44: 2044 | Z44: 2045 | AA44: 2046 | AB44: 2047 | AC44: 2048 | AD44: 2049 | AE44: 2050
...

Sheet CApULAbIFM
B1: Per Acre
A2: CO2 Abated (g) | B2: =1.5*10^6 -> 1500000
A4: Source: | B4: consultation with American Forest Foundation
A5: see file land/CApULAbIFM

Sheet TNC Data
G1: 0-10 $/ton | H1: 0-50 $/ton | I1: 0-100 $/ton | J1: max $ton | K1: IGNORE - zero | O1: IGNORE-max | P1: REFORESTATION | Q1: Average CO2/Acre | R1: Total acres | AC1: Avoided forest conversion | AD1: Average CO2/Acre | AE1: Total acres | AP1: RICE | AQ1: Average CO2/Acre | AR1: Total acres | BC1: FIRE | BD1: Average CO2/Acre | BE1: Total acres | CT1: Avoided Grassland Conversion | CU1: Average CO2/Acre | CV1: Total acres | DG1: Grassland Restoration | DH1: Average CO2/Acre | DI1: Total acres
A3: state_name | B3: State_abv | C3: state_fips | D3: emis_tot | E3: emis_xlulc | F3: refor_0 | G3: refor_1 | H3: refor_2 | I3: refor_3 | J3: refor_4 | K3: refor_area_0 | L3: refor_area_1 | M3: refor_area_2 | N3: refor_area_3 | O3: refor_area_4 | P3: $/ton/yr | Q3: tons/acre | R3: acres (0-100) | S3: defor_0 | T3: defor_1 | U3: defor_2 | V3: defor_3 | W3: defor_4 | X3: defor_area_0 | Y3: defor_area_1 | Z3: defor_area_2 | AA3: defor_area_3 | AB3: defor_area_4 | AC3: average $/MTCO2/yr | AD3: MTCO2/million acres | AE3: acres (0-100) | AF3: rice_0 | AG3: rice_1 | AH3: rice_2 | AI3: rice_3 | AJ3: rice_4 | AK3: rice_area_0 | AL3: rice_area_1 | AM3: rice_area_2 | AN3: rice_area_3 | AO3: rice_area_4 | AP3: average $/MTCO2/yr | AQ3: MTCO2/million acres | AR3: acres (0-100) | AS3: fire_0 | AT3: fire_1 | AU3: fire_2 | AV3: fire_3 | AW3: fire_4 | AX3: fire_area_0 | AY3: fire_area_1 | AZ3: fire_area_2 | BA3: fire_area_3 | BB3: fire_area_4 | BC3: average $/MTCO2/yr | BD3: MTCO2/million acres | BE3: acres (0-100) | BF3: urban_0 | BG3: urban_1 | BH3: urban_2 | BI3: urban_3 | BJ3: urban_4 | BK3: urban_area_0 | BL3: urban_area_1 | BM3: urban_area_2 | BN3: urban_area_3 | BO3: urban_area_4 | BP3: cov_crop_0 | BQ3: cov_crop_1 | BR3: cov_crop_2 | BS3: cov_crop_3 | BT3: cov_crop_4 | BU3: cov_crop_area_0 | BV3: cov_crop_area_1 | BW3: cov_crop_area_2 | BX3: cov_crop_area_3 | BY3: cov_crop_area_4 | BZ3: aly_crop_0 | CA3: aly_crop_1 | CB3: aly_crop_2 | CC3: aly_crop_3 | CD3: aly_crop_4 | CE3: aly_crop_area_0 | CF3: aly_crop_area_1 | CG3: aly_crop_area_2 | CH3: aly_crop_area_3 | CI3: aly_crop_area_4 | CJ3: grass_con_0 | CK3: grass_con_1 | CL3: grass_con_2 | CM3: grass_con_3 | CN3: grass_con_4 | CO3: grass_con_area_0 | CP3: grass_con_area_1 | CQ3: grass_con_area_2 | CR3: grass_con_area_3 | CS3: grass_con_area_4 | CT3: average $/MTCO2/yr | CU3: MTCO2/million acres | CV3: acres (0-100) | CW3: grass_res_0 | CX3: grass_res_1 | CY3: grass_res_2 | CZ3: grass_res_3 | DA3: grass_res_4 | DB3: grass_res_area_0 | DC3: grass_res_area_1 | DD3: grass_res_area_2 | DE3: grass_res_area_3 | DF3: grass_res_area_4 | DG3: average $/MTCO2/yr | DH3: MTCO2/million acres | DI3: acres (0-100) | DJ3: nut_mgt_0 | DK3: nut_mgt_1 | DL3: nut_mgt_2 | DM3: nut_mgt_3 | DN3: nut_mgt_4 | DO3: nut_mgt_area_0 | DP3: nut_mgt_area_1 | DQ3: nut_mgt_area_2 | DR3: nut_mgt_area_3 | DS3: nut_mgt_area_4 | DT3: manure_0 | DU3: manure_1 | DV3: manure_2 | DW3: manure_3 | DX3: manure_4 | DY3: manure_area_0 | DZ3: manure_area_1 | EA3: manure_area_2 | EB3: manure_area_3 | EC3: manure_area_4
A4: Alabama | B4: AL | C4: 1 | D4: 1.5133086e+08 | E4: 98863107 | G4: 500021.36 | H4: 11757645 | I4: 11757645 | J4: 14286325 | L4: 155206.13 | M4: 3649561.2 | N4: 3649561.2 | O4: 4434460.7 | P4: =((G4*10+(H4-G4)*50+(I4-H4)*100)/I4) -> 48.298906 | Q4: =I4/N4 -> 3.22166 | R4: =N4 -> 3649561.2 | T4: 2113474 | U4: 2201535.5 | V4: 2201535.5 | W4: 2201535.5 | Y4: 415964.4 | Z4: 433296.25 | AA4: 433296.25 | AB4: 433296.25 | AC4: =((T4*10+(U4-T4)*50+(V4-U4)*100)/V4) -> 11.6 | AD4: =V4/AA4 -> 5.0809013 | AE4: =AA4 -> 433296.25 | AF4: -9999 | AG4: -9999 | AH4: -9999 | AI4: -9999 | AJ4: -9999 | AK4: -9999 | AL4: -9999 | AM4: -9999 | AN4: -9999 | AO4: 0 | AP4: =(IF(AK4=-9999,0,(AG4*10+(AH4-AG4)*50+(AI4-AH4)*100)/AI4)) -> 0 | AQ4: =IF(AK4=-9999,0,AI4/AN4) -> 0 | AR4: =IF(AK4=-9999,0,AN4) -> 0 | AS4: -9999 | AT4: -9999 | AU4: -9999 | AV4: -9999 | AW4: -9999 | AX4: -9999 | AY4: -9999 | AZ4: -9999 | BA4: -9999 | BB4: -9999 | BC4: =(IF(AY4=-9999,0,(AT4*10+(AU4-AT4)*50+(AV4-AU4)*100)/AV4)) -> 0 | BD4: =IF(AY4=-9999,0,AV4/BA4) -> 0 | BE4: =IF(AY4=-9999,0,BA4) -> 0 | BF4: 0 | BG4: 0 | BH4: 0 | BI4: 0 | BJ4: 521818.15 | BK4: 0 | BL4: 0 | BM4: 0 | BN4: 0 | BO4: 145838.12 | BQ4: 732209.45 | BR4: 732209.45 | BS4: 755634.11 | BT4: 755634.11 | BV4: 1542008.1 | BW4: 1542008.1 | BX4: 1591339.7 | BY4: 1591339.7 | CA4: 29891.776 | CB4: 478268.42 | CC4: 597835.52 | CD4: 597835.52 | CF4: 13892.648 | CG4: 222282.37 | CH4: 277852.96 | CI4: 277852.96 | CK4: 151246.23 | CL4: 1279373 | CM4: 1159706.4 | CN4: 1159706.4 | CP4: 699.26671 | CQ4: 19062.678 | CR4: 19062.678 | CS4: 19062.678 | CT4: =(IF(CP4=-9999,0,(CK4*10+(CL4-CK4)*50+(CM4-CL4)*100)/CM4)) -> 39.623941 | CU4: =IF(CP4=-9999,0,CM4/CR4) -> 60.836489 | CV4: =IF(CP4=-9999,0,CR4) -> 19062.678 | CX4: 1973.6581 | CY4: 94481.312 | CZ4: 119436.58 | DA4: 121083.32 | DC4: 1211.6188 | DD4: 45882.656 | DE4: 57212.783 | DF4: 58001.605 | DG4: =(IF(DC4=-9999,0,(CX4*10+(CY4-CX4)*50+(CZ4-CY4)*100)/CZ4)) -> 59.786091 | DH4: =IF(DC4=-9999,0,CZ4/DE4) -> 2.0875856 | DI4: =IF(DC4=-9999,0,DE4) -> 57212.783 | DK4: 163418.85 | DL4: 184504.92 | DM4: 197615.71 | DN4: 247552.05 | DO4: -9999 | DP4: -9999 | DQ4: -9999 | DR4: -9999 | DS4: -9999 | DU4: 7127 | DV4: 20108 | DW4: 25903 | DX4: 25903 | DY4: -9999 | DZ4: -9999 | EA4: -9999 | EB4: -9999 | EC4: -9999
A5: Arizona | B5: AR | C5: 4 | D5: 91536412 | E5: 55797032 | G5: 39172.044 | H5: 921102.63 | I5: 921102.63 | J5: 1119201.3 | L5: 87162.765 | M5: 2049570.2 | N5: 2049570.2 | O5: 2490364.7 | P5: =((G5*10+(H5-G5)*50+(I5-H5)*100)/I5) -> 48.298906 | Q5: =I5/N5 -> 0.44941259 | R5: =N5 -> 2049570.2 | T5: 85449.954 | U5: 89010.369 | V5: 89010.369 | W5: 89010.369 | Y5: 41397.659 | Z5: 43122.561 | AA5: 43122.561 | AB5: 43122.561 | AC5: =((T5*10+(U5-T5)*50+(V5-U5)*100)/V5) -> 11.6 | AD5: =V5/AA5 -> 2.0641253 | AE5: =AA5 -> 43122.561 | AF5: -9999 | AG5: -9999 | AH5: -9999 | AI5: -9999 | AJ5: -9999 | AK5: -9999 | AL5: -9999 | AM5: -9999 | AN5: -9999 | AO5: -9999 | AP5: =(IF(AK5=-9999,0,(AG5*10+(AH5-AG5)*50+(AI5-AH5)*100)/AI5)) -> 0 | AQ5: =IF(AK5=-9999,0,AI5/AN5) -> 0 | AR5: =IF(AK5=-9999,0,AN5) -> 0 | AS5: 0 | AT5: 0 | AU5: 1808984 | AV5: 1808984 | AW5: 1808984 | AX5: -9999 | AY5: 0 | AZ5: 2830272.6 | BA5: 2830272.6 | BB5: 2830272.6 | BC5: =(IF(AY5=-9999,0,(AT5*10+(AU5-AT5)*50+(AV5-AU5)*100)/AV5)) -> 50 | BD5: =IF(AY5=-9999,0,AV5/BA5) -> 0.63915537 | BE5: =IF(AY5=-9999,0,BA5) -> 2830272.6 | BF5: 0 | BG5: 0 | BH5: 0 | BI5: 0 | BJ5: 497483.95 | BK5: 0 | BL5: 0 | BM5: 0 | BN5: 0 | BO5: 134716.81 | BQ5: 220294.05 | BR5: 220294.05 | BS5: 227341.64 | BT5: 227341.64 | BV5: 463931.76 | BW5: 463931.76 | BX5: 478773.75 | BY5: 478773.75 | CA5: 8993.3016 | CB5: 143892.83 | CC5: 179866.03 | CD5: 179866.03 | CF5: 4179.7708 | CG5: 66876.333 | CH5: 83595.416 | CI5: 83595.416 | CK5: 87136.651 | CL5: 128053.36 | CM5: 116076.7 | CN5: 116076.7 | CP5: 10.346468 | CQ5: 3957.2497 | CR5: 4200.1309 | CS5: 4227.3038 | CT5: =(IF(CP5=-9999,0,(CK5*10+(CL5-CK5)*50+(CM5-CL5)*100)/CM5)) -> 14.813788 | CU5: =IF(CP5=-9999,0,CM5/CR5) -> 27.636448 | CV5: =IF(CP5=-9999,0,CR5) -> 4200.1309 | CX5: 106.96426 | CY5: 5120.504 | CZ5: 6472.9785 | DA5: 6562.2247 | DC5: 268.68632 | DD5: 10174.852 | DE5: 12687.4 | DF5: 12862.327 | DG5: =(IF(DC5=-9999,0,(CX5*10+(CY5-CX5)*50+(CZ5-CY5)*100)/CZ5)) -> 59.786091 | DH5: =IF(DC5=-9999,0,CZ5/DE5) -> 0.51018953 | DI5: =IF(DC5=-9999,0,DE5) -> 12687.4 | DK5: 173735.03 | DL5: 196142.32 | DM5: 213151.23 | DN5: 266173.04 | DO5: -9999 | DP5: -9999 | DQ5: -9999 | DR5: -9999 | DS5: -9999 | DU5: 11962 | DV5: 48324 | DW5: 61252 | DX5: 61252 | DY5: -9999 | DZ5: -9999 | EA5: -9999 | EB5: -9999 | EC5: -9999
A6: Arkansas | B6: AZ | C6: 5 | D6: 1.054362e+08 | E6: 1.0726192e+08 | G6: 427670.46 | H6: 10056365 | I6: 10056365 | J6: 12219156 | L6: 136499.75 | M6: 3209694.1 | N6: 3209694.1 | O6: 3899992.8 | P6: =((G6*10+(H6-G6)*50+(I6-H6)*100)/I6) -> 48.298906 | Q6: =I6/N6 -> 3.1331227 | R6: =N6 -> 3209694.1 | T6: 1467744.9 | U6: 1528901 | V6: 1528901 | W6: 1528901 | Y6: 280617.98 | Z6: 292310.39 | AA6: 292310.39 | AB6: 292310.39 | AC6: =((T6*10+(U6-T6)*50+(V6-U6)*100)/V6) -> 11.6 | AD6: =V6/AA6 -> 5.2304024 | AE6: =AA6 -> 292310.39 | AF6: 0 | AG6: 631622.97 | AH6: 1316897.3 | AI6: 1609541.2 | AJ6: 1804637 | AK6: 0 | AL6: 1339333.3 | AM6: 1339333.3 | AN6: 1339333.3 | AO6: 1339333.3 | AP6: =(IF(AK6=-9999,0,(AG6*10+(AH6-AG6)*50+(AI6-AH6)*100)/AI6)) -> 43.393939 | AQ6: =IF(AK6=-9999,0,AI6/AN6) -> 1.201748 | AR6: =IF(AK6=-9999,0,AN6) -> 1339333.3 | AS6: -9999 | AT6: -9999 | AU6: -9999 | AV6: -9999 | AW6: -9999 | AX6: -9999 | AY6: -9999 | AZ6: -9999 | BA6: -9999 | BB6: -9999 | BC6: =(IF(AY6=-9999,0,(AT6*10+(AU6-AT6)*50+(AV6-AU6)*100)/AV6)) -> 0 | BD6: =IF(AY6=-9999,0,AV6/BA6) -> 0 | BE6: =IF(AY6=-9999,0,BA6) -> 0 | BF6: 0 | BG6: 0 | BH6: 0 | BI6: 0 | BJ6: 249732.81 | BK6: 0 | BL6: 0 | BM6: 0 | BN6: 0 | BO6: 72325.86 | BQ6: 2270585.7 | BR6: 2270585.7 | BS6: 2343225.7 | BT6: 2343225.7 | BV6: 4781776.1 | BW6: 4781776.1 | BX6: 4934753.5 | BY6: 4934753.5 | CA6: 92694.569 | CB6: 1483113.1 | CC6: 1853891.4 | CD6: 1853891.4 | CF6: 43081.181 | CG6: 689298.9 | CH6: 861623.62 | CI6: 861623.62 | CK6: 242199.15 | CL6: 447446.3 | CM6: 405594.24 | CN6: 405594.24 | CP6: 30.363846 | CQ6: 6628.1551 | CR6: 6628.1551 | CS6: 6628.1551 | CT6: =(IF(CP6=-9999,0,(CK6*10+(CL6-CK6)*50+(CM6-CL6)*100)/CM6)) -> 20.954791 | CU6: =IF(CP6=-9999,0,CM6/CR6) -> 61.19263 | CV6: =IF(CP6=-9999,0,CR6) -> 6628.1551 | CX6: 607.60662 | CY6: 29086.837 | CZ6: 36769.52 | DA6: 37276.48 | DC6: 421.2838 | DD6: 15953.549 | DE6: 19893.071 | DF6: 20167.347 | DG6: =(IF(DC6=-9999,0,(CX6*10+(CY6-CX6)*50+(CZ6-CY6)*100)/CZ6)) -> 59.786091 | DH6: =IF(DC6=-9999,0,CZ6/DE6) -> 1.8483582 | DI6: =IF(DC6=-9999,0,DE6) -> 19893.071 | DK6: 705625.2 | DL6: 796694.32 | DM6: 846553.69 | DN6: 1062320.5 | DO6: -9999 | DP6: -9999 | DQ6: -9999 | DR6: -9999 | DS6: -9999 | DU6: 276204 | DV6: 523790 | DW6: 551481 | DX6: 551481 | DY6: -9999 | DZ6: -9999 | EA6: -9999 | EB6: -9999 | EC6: -9999
A7: California | B7: CA | C7: 6 | D7: 4.5452145e+08 | E7: 427693094 | F7: 0 | G7: 194039.57 | H7: 4562702 | I7: 4562702 | J7: 5543987.8 | K7: 0 | L7: 288428.71 | M7: 6782195.1 | N7: 6782195.1 | O7: 8240820.2 | P7: =((G7*10+(H7-G7)*50+(I7-H7)*100)/I7) -> 48.298906 | Q7: =I7/N7 -> 0.67274709 | R7: =N7 -> 6782195.1 | S7: 0 | T7: 1536798.8 | U7: 1600832.1 | V7: 1600832.1 | W7: 1600832.1 | X7: 0 | Y7: 208118.11 | Z7: 216789.7 | AA7: 216789.7 | AB7: 216789.7 | AC7: =((T7*10+(U7-T7)*50+(V7-U7)*100)/V7) -> 11.6 | AD7: =V7/AA7 -> 7.3842629 | AE7: =AA7 -> 216789.7 | AF7: 0 | AG7: 222435.66 | AH7: 463765.48 | AI7: 566824.47 | AJ7: 635530.47 | AK7: 0 | AL7: 471666.67 | AM7: 471666.67 | AN7: 471666.67 | AO7: 471666.67 | AP7: =(IF(AK7=-9999,0,(AG7*10+(AH7-AG7)*50+(AI7-AH7)*100)/AI7)) -> 43.393939 | AQ7: =IF(AK7=-9999,0,AI7/AN7) -> 1.201748 | AR7: =IF(AK7=-9999,0,AN7) -> 471666.67 | AS7: 0 | AT7: 0 | AU7: 3187496.4 | AV7: 5109342 | AW7: 5109342 | AX7: -9999 | AY7: 0 | AZ7: 16636427 | BA7: 20091506 | BB7: 20091506 | BC7: =(IF(AY7=-9999,0,(AT7*10+(AU7-AT7)*50+(AV7-AU7)*100)/AV7)) -> 68.807173 | BD7: =IF(AY7=-9999,0,AV7/BA7) -> 0.25430358 | BE7: =IF(AY7=-9999,0,BA7) -> 20091506 | BF7: 0 | BG7: 0 | BH7: 0 | BI7: 0 | BJ7: 1814651.1 | BK7: 0 | BL7: 0 | BM7: 0 | BN7: 0 | BO7: 447187.36 | BQ7: 984485.07 | BR7: 984485.07 | BS7: 1015980.5 | BT7: 1015980.5 | BV7: 2073292 | BW7: 2073292 | BX7: 2139620.2 | BY7: 2139620.2 | CA7: 40190.695 | CB7: 643051.13 | CC7: 803813.91 | CD7: 803813.91 | CF7: 18679.224 | CG7: 298867.59 | CH7: 373584.48 | CI7: 373584.48 | CJ7: 0 | CK7: 615968.76 | CL7: 2545068.7 | CM7: 2352081.1 | CN7: 2352081.1 | CO7: 0 | CP7: 3446.6088 | CQ7: 50091.674 | CR7: 50475.812 | CS7: 50481.032 | CT7: =(IF(CP7=-9999,0,(CK7*10+(CL7-CK7)*50+(CM7-CL7)*100)/CM7)) -> 35.422216 | CU7: =IF(CP7=-9999,0,CM7/CR7) -> 46.598183 | CV7: =IF(CP7=-9999,0,CR7) -> 50475.812 | CX7: 3109.9094 | CY7: 148874.99 | CZ7: 188197.22 | DA7: 190791.99 | DC7: 3208.5611 | DD7: 121504.64 | DE7: 151508.64 | DF7: 153597.56 | DG7: =(IF(DC7=-9999,0,(CX7*10+(CY7-CX7)*50+(CZ7-CY7)*100)/CZ7)) -> 59.786091 | DH7: =IF(DC7=-9999,0,CZ7/DE7) -> 1.242155 | DI7: =IF(DC7=-9999,0,DE7) -> 151508.64 | DJ7: 1232971.2 | DK7: 1274395.6 | DL7: 1437329.9 | DM7: 2006307 | DN7: 2385561.9 | DO7: -9999 | DP7: -9999 | DQ7: -9999 | DR7: -9999 | DS7: -9999 | DT7: 0 | DU7: 2327889 | DV7: 4475325 | DW7: 4766315 | DX7: 4766315 | DY7: -9999 | DZ7: -9999 | EA7: -9999 | EB7: -9999 | EC7: -9999
A8: Colorado | B8: CO | C8: 8 | D8: 1.2724922e+08 | E8: 1.1820659e+08 | F8: 0 | G8: 156714.81 | H8: 3685036.7 | I8: 3685036.7 | J8: 4477565.9 | K8: 0 | L8: 280035.75 | M8: 6584840.6 | N8: 6584840.6 | O8: 8001021.3 | P8: =((G8*10+(H8-G8)*50+(I8-H8)*100)/I8) -> 48.298906 | Q8: =I8/N8 -> 0.55962429 | R8: =N8 -> 6584840.6 | S8: 0 | T8: 165798.02 | U8: 172706.27 | V8: 172706.27 | W8: 172706.27 | X8: 0 | Y8: 52078.227 | Z8: 54248.153 | AA8: 54248.153 | AB8: 54248.153 | AC8: =((T8*10+(U8-T8)*50+(V8-U8)*100)/V8) -> 11.6 | AD8: =V8/AA8 -> 3.1836341 | AE8: =AA8 -> 54248.153 | AF8: -9999 | AG8: -9999 | AH8: -9999 | AI8: -9999 | AJ8: -9999 | AK8: -9999 | AL8: -9999 | AM8: -9999 | AN8: -9999 | AO8: -9999 | AP8: =(IF(AK8=-9999,0,(AG8*10+(AH8-AG8)*50+(AI8-AH8)*100)/AI8)) -> 0 | AQ8: =IF(AK8=-9999,0,AI8/AN8) -> 0 | AR8: =IF(AK8=-9999,0,AN8) -> 0 | AS8: 0 | AT8: 0 | AU8: 1098.3728 | AV8: 1098.3728 | AW8: 38947.483 | AX8: -9999 | AY8: 0 | AZ8: 1718.4754 | BA8: 1718.4754 | BB8: 2945355.4 | BC8: =(IF(AY8=-9999,0,(AT8*10+(AU8-AT8)*50+(AV8-AU8)*100)/AV8)) -> 50 | BD8: =IF(AY8=-9999,0,AV8/BA8) -> 0.63915537 | BE8: =IF(AY8=-9999,0,BA8) -> 1718.4754 | BF8: 0 | BG8: 0 | BH8: 0 | BI8: 0 | BJ8: 221528.89 | BK8: 0 | BL8: 0 | BM8: 0 | BN8: 0 | BO8: 107797.86 | BQ8: 1941301.9 | BR8: 1941301.9 | BS8: 2003407.5 | BT8: 2003407.5 | BV8: 4088315.6 | BW8: 4088315.6 | BX8: 4219107.9 | BY8: 4219107.9 | CA8: 79251.86 | CB8: 1268029.8 | CC8: 1585037.2 | CD8: 1585037.2 | CF8: 36833.482 | CG8: 589335.71 | CH8: 736669.64 | CI8: 736669.64 | CJ8: 0 | CK8: 1851913.1 | CL8: 4129008 | CM8: 3742799.7 | CN8: 3742799.7 | CO8: 0 | CP8: 5463.0051 | CQ8: 74410.31 | CR8: 74410.31 | CS8: 74410.31 | CT8: =(IF(CP8=-9999,0,(CK8*10+(CL8-CK8)*50+(CM8-CL8)*100)/CM8)) -> 25.048907 | CU8: =IF(CP8=-9999,0,CM8/CR8) -> 50.299477 | CV8: =IF(CP8=-9999,0,CR8) -> 74410.31 | CX8: 4701.8756 | CY8: 225084.27 | CZ8: 284535.59 | DA8: 288458.63 | DC8: 4729.4998 | DD8: 179100.9 | DE8: 223327.54 | DF8: 226406.67 | DG8: =(IF(DC8=-9999,0,(CX8*10+(CY8-CX8)*50+(CZ8-CY8)*100)/CZ8)) -> 59.786091 | DH8: =IF(DC8=-9999,0,CZ8/DE8) -> 1.274073 | DI8: =IF(DC8=-9999,0,DE8) -> 223327.54 | DJ8: 324336.54 | DK8: 335399.82 | DL8: 378502.41 | DM8: 459579.7 | DN8: 560888.92 | DO8: -9999 | DP8: -9999 | DQ8: -9999 | DR8: -9999 | DS8: -9999 | DT8: 0 | DU8: 193218 | DV8: 389298 | DW8: 455516 | DX8: 455516 | DY8: -9999 | DZ8: -9999 | EA8: -9999 | EB8: -9999 | EC8: -9999
A9: Connecticut | B9: CT | C9: 9 | D9: 40713158 | E9: 35152743 | F9: 0 | G9: 19744.635 | H9: 464280.98 | I9: 464280.98 | J9: 564132.42 | K9: 0 | L9: 4423.6865 | M9: 104019.83 | N9: 104019.83 | O9: 126391.04 | P9: =((G9*10+(H9-G9)*50+(I9-H9)*100)/I9) -> 48.298906 | Q9: =I9/N9 -> 4.4633893 | R9: =N9 -> 104019.83 | S9: 0 | T9: 172451.82 | U9: 179637.32 | V9: 179637.32 | W9: 179637.32 | X9: 0 | Y9: 17425.287 | Z9: 18151.34 | AA9: 18151.34 | AB9: 18151.34 | AC9: =((T9*10+(U9-T9)*50+(V9-U9)*100)/V9) -> 11.6 | AD9: =V9/AA9 -> 9.8966421 | AE9: =AA9 -> 18151.34 | AF9: -9999 | AG9: -9999 | AH9: -9999 | AI9: -9999 | AJ9: -9999 | AK9: -9999 | AL9: -9999 | AM9: -9999 | AN9: -9999 | AO9: -9999 | AP9: =(IF(AK9=-9999,0,(AG9*10+(AH9-AG9)*50+(AI9-AH9)*100)/AI9)) -> 0 | AQ9: =IF(AK9=-9999,0,AI9/AN9) -> 0 | AR9: =IF(AK9=-9999,0,AN9) -> 0 | AS9: -9999 | AT9: -9999 | AU9: -9999 | AV9: -9999 | AW9: -9999 | AX9: -9999 | AY9: -9999 | AZ9: -9999 | BA9: -9999 | BB9: -9999 | BC9: =(IF(AY9=-9999,0,(AT9*10+(AU9-AT9)*50+(AV9-AU9)*100)/AV9)) -> 0 | BD9: =IF(AY9=-9999,0,AV9/BA9) -> 0 | BE9: =IF(AY9=-9999,0,BA9) -> 0 | BF9: 0 | BG9: 0 | BH9: 0 | BI9: 0 | BJ9: 325993.86 | BK9: 0 | BL9: 0 | BM9: 0 | BN9: 0 | BO9: 130754.76 | BQ9: 23144.552 | BR9: 23144.552 | BS9: 23884.986 | BT9: 23884.986 | BV9: 48741.637 | BW9: 48741.637 | BX9: 50300.967 | BY9: 50300.967 | CA9: 944.85499 | CB9: 15117.68 | CC9: 18897.1 | CD9: 18897.1 | CF9: 439.13542 | CG9: 7026.1668 | CH9: 8782.7085 | CI9: 8782.7085 | CJ9: 0 | CK9: 0 | CL9: 2696.9799 | CM9: 2444.7168 | CN9: 2444.7168 | CO9: 0 | CP9: 0 | CQ9: 28.284054 | CR9: 28.284054 | CS9: 28.284054 | CT9: =(IF(CP9=-9999,0,(CK9*10+(CL9-CK9)*50+(CM9-CL9)*100)/CM9)) -> 44.840649 | CU9: =IF(CP9=-9999,0,CM9/CR9) -> 86.434455 | CV9: =IF(CP9=-9999,0,CR9) -> 28.284054 | CX9: 3.3966874 | CY9: 162.60339 | CZ9: 205.55168 | DA9: 208.38573 | DC9: 1.7977271 | DD9: 68.077925 | DE9: 84.888885 | DF9: 86.059291 | DG9: =(IF(DC9=-9999,0,(CX9*10+(CY9-CX9)*50+(CZ9-CY9)*100)/CZ9)) -> 59.786091 | DH9: =IF(DC9=-9999,0,CZ9/DE9) -> 2.4214205 | DI9: =IF(DC9=-9999,0,DE9) -> 84.888885 | DJ9: 13142.727 | DK9: 13596.588 | DL9: 15351.271 | DM9: 16347.452 | DN9: 20504.259 | DO9: -9999 | DP9: -9999 | DQ9: -9999 | DR9: -9999 | DS9: -9999 | DT9: 0 | DU9: 0 | DV9: 1776 | DW9: 1776 | DX9: 1776 | DY9: -9999 | DZ9: -9999 | EA9: -9999 | EB9: -9999 | EC9: -9999
A10: Delaware | B10: DE | C10: 10 | D10: 14913536 | E10: 13717565 | F10: 0 | G10: 15489.023 | H10: 364213.31 | I10: 364213.31 | J10: 442543.52 | K10: 0 | L10: 3838.283 | M10: 90254.482 | N10: 90254.482 | O10: 109665.23 | P10: =((G10*10+(H10-G10)*50+(I10-H10)*100)/I10) -> 48.298906 | Q10: =I10/N10 -> 4.0354042 | R10: =N10 -> 90254.482 | S10: 0 | T10: 56029.702 | U10: 58364.273 | V10: 58364.273 | W10: 58364.273 | X10: 0 | Y10: 6290.631 | Z10: 6552.7407 | AA10: 6552.7407 | AB10: 6552.7407 | AC10: =((T10*10+(U10-T10)*50+(V10-U10)*100)/V10) -> 11.6 | AD10: =V10/AA10 -> 8.9068492 | AE10: =AA10 -> 6552.7407 | AF10: -9999 | AG10: -9999 | AH10: -9999 | AI10: -9999 | AJ10: -9999 | AK10: -9999 | AL10: -9999 | AM10: -9999 | AN10: -9999 | AO10: -9999 | AP10: =(IF(AK10=-9999,0,(AG10*10+(AH10-AG10)*50+(AI10-AH10)*100)/AI10)) -> 0 | AQ10: =IF(AK10=-9999,0,AI10/AN10) -> 0 | AR10: =IF(AK10=-9999,0,AN10) -> 0 | AS10: -9999 | AT10: -9999 | AU10: -9999 | AV10: -9999 | AW10: -9999 | AX10: -9999 | AY10: -9999 | AZ10: -9999 | BA10: -9999 | BB10: -9999 | BC10: =(IF(AY10=-9999,0,(AT10*10+(AU10-AT10)*50+(AV10-AU10)*100)/AV10)) -> 0 | BD10: =IF(AY10=-9999,0,AV10/BA10) -> 0 | BE10: =IF(AY10=-9999,0,BA10) -> 0 | BF10: 0 | BG10: 0 | BH10: 0 | BI10: 0 | BJ10: 45662.07 | BK10: 0 | BL10: 0 | BM10: 0 | BN10: 0 | BO10: 13066.425 | BQ10: 145495.07 | BR10: 145495.07 | BS10: 150149.71 | BT10: 150149.71 | BV10: 306407.65 | BW10: 306407.65 | BX10: 316210.17 | BY10: 316210.17 | CA10: 5939.702 | CB10: 95035.233 | CC10: 118794.04 | CD10: 118794.04 | CF10: 2760.565 | CG10: 44169.039 | CH10: 55211.299 | CI10: 55211.299 | CJ10: 0 | CK10: 889.61154 | CL10: 11469.964 | CM10: 10397.116 | CN10: 10397.116 | CO10: 0 | CP10: 0 | CQ10: 142.3889 | CR10: 142.3889 | CS10: 142.3889 | CT10: =(IF(CP10=-9999,0,(CK10*10+(CL10-CK10)*50+(CM10-CL10)*100)/CM10)) -> 41.418117 | CU10: =IF(CP10=-9999,0,CM10/CR10) -> 73.019145 | CV10: =IF(CP10=-9999,0,CR10) -> 142.3889 | CX10: 13.264913 | CY10: 635.00686 | CZ10: 802.7307 | DA10: 813.79836 | DC10: 9.0502015 | DD10: 342.72106 | DE10: 427.35158 | DF10: 433.24369 | DG10: =(IF(DC10=-9999,0,(CX10*10+(CY10-CX10)*50+(CZ10-CY10)*100)/CZ10)) -> 59.786091 | DH10: =IF(DC10=-9999,0,CZ10/DE10) -> 1.8783848 | DI10: =IF(DC10=-9999,0,DE10) -> 427.35158 | DJ10: 44876.666 | DK10: 46426.81 | DL10: 52418.88 | DM10: 55652.179 | DN10: 69849.647 | DO10: -9999 | DP10: -9999 | DQ10: -9999 | DR10: -9999 | DS10: -9999 | DT10: 0 | DU10: 0 | DV10: 247 | DW10: 247 | DX10: 247 | DY10: -9999 | DZ10: -9999 | EA10: -9999 | EB10: -9999 | EC10: -9999
A11: Florida | B11: FL | C11: 12 | D11: 2.6823182e+08 | E11: 2.3344256e+08 | G11: 277530.89 | H11: 6525940.7 | I11: 6525940.7 | J11: 7929454 | L11: 126629.58 | M11: 2977604.1 | N11: 2977604.1 | O11: 3617988 | P11: =((G11*10+(H11-G11)*50+(I11-H11)*100)/I11) -> 48.298906 | Q11: =I11/N11 -> 2.191675 | R11: =N11 -> 2977604.1 | T11: 1019621 | U11: 1062105.2 | V11: 1062105.2 | W11: 1062105.2 | Y11: 263558.23 | Z11: 274539.82 | AA11: 274539.82 | AB11: 274539.82 | AC11: =((T11*10+(U11-T11)*50+(V11-U11)*100)/V11) -> 11.6 | AD11: =V11/AA11 -> 3.8686745 | AE11: =AA11 -> 274539.82 | AF11: -9999 | AG11: -9999 | AH11: -9999 | AI11: -9999 | AJ11: -9999 | AK11: -9999 | AL11: -9999 | AM11: -9999 | AN11: -9999 | AO11: -9999 | AP11: =(IF(AK11=-9999,0,(AG11*10+(AH11-AG11)*50+(AI11-AH11)*100)/AI11)) -> 0 | AQ11: =IF(AK11=-9999,0,AI11/AN11) -> 0 | AR11: =IF(AK11=-9999,0,AN11) -> 0 | AS11: -9999 | AT11: -9999 | AU11: -9999 | AV11: -9999 | AW11: -9999 | AX11: -9999 | AY11: -9999 | AZ11: -9999 | BA11: -9999 | BB11: -9999 | BC11: =(IF(AY11=-9999,0,(AT11*10+(AU11-AT11)*50+(AV11-AU11)*100)/AV11)) -> 0 | BD11: =IF(AY11=-9999,0,AV11/BA11) -> 0 | BE11: =IF(AY11=-9999,0,BA11) -> 0 | BF11: 0 | BG11: 0 | BH11: 0 | BI11: 0 | BJ11: 2333798.8 | BK11: 0 | BL11: 0 | BM11: 0 | BN11: 0 | BO11: 470994.45 | BQ11: 360423.79 | BR11: 360423.79 | BS11: 371954.38 | BT11: 371954.38 | BV11: 759040.22 | BW11: 759040.22 | BX11: 783323.24 | BY11: 783323.24 | CA11: 14713.969 | CB11: 235423.5 | CC11: 294279.38 | CD11: 294279.38 | CF11: 6838.5362 | CG11: 109416.58 | CH11: 136770.72 | CI11: 136770.72 | CK11: 724484.78 | CL11: 1346897 | CM11: 1220914.4 | CN11: 1220914.4 | CP11: 8889.5278 | CQ11: 12325.261 | CR11: 12325.261 | CS11: 12325.261 | CT11: =(IF(CP11=-9999,0,(CK11*10+(CL11-CK11)*50+(CM11-CL11)*100)/CM11)) -> 21.10484 | CU11: =IF(CP11=-9999,0,CM11/CR11) -> 99.057898 | CV11: =IF(CP11=-9999,0,CR11) -> 12325.261 | CX11: 4238.94 | CY11: 202923 | CZ11: 256520.88 | DA11: 260057.67 | DC11: 783.39036 | DD11: 29666.121 | DE11: 36991.785 | DF11: 37501.81 | DG11: =(IF(DC11=-9999,0,(CX11*10+(CY11-CX11)*50+(CZ11-CY11)*100)/CZ11)) -> 59.786091 | DH11: =IF(DC11=-9999,0,CZ11/DE11) -> 6.9345364 | DI11: =IF(DC11=-9999,0,DE11) -> 36991.785 | DK11: 322463.88 | DL11: 364064.22 | DM11: 392246.3 | DN11: 490732.11 | DO11: -9999 | DP11: -9999 | DQ11: -9999 | DR11: -9999 | DS11: -9999 | DU11: 17130 | DV11: 34271 | DW11: 34923 | DX11: 34923 | DY11: -9999 | DZ11: -9999 | EA11: -9999 | EB11: -9999 | EC11: -9999
